{'type': 'l2update', 'product_id': 'BTC-USD', 'changes': [['sell', '38310.49', '0.05488740']], 'time': '2021-05-20T03:54:45.601205Z'}
{'type': 'l2update', 'product_id': 'BTC-USD', 'changes': [['buy', '38270.13', '0.05488740']], 'time': '2021-05-20T03:54:45.608770Z'}
{'type': 'l2update', 'product_id': 'BTC-USD', 'changes': [['buy', '38283.95', '0.07174783']], 'time': '2021-05-20T03:54:45.624428Z'}
{'type': 'l2update', 'product_id': 'BTC-USD', 'changes': [['buy', '38190.42', '0.00000000']], 'time': '2021-05-20T03:54:45.691649Z'}
{'type': 'l2update', 'product_id': 'BTC-USD', 'changes': [['buy', '38270.12', '0.00000000']], 'time': '2021-05-20T03:54:45.697719Z'}
{'type': 'l2update', 'product_id': 'BTC-USD', 'changes': [['sell', '38381.26', '0.01000000']], 'time': '2021-05-20T03:54:45.697879Z'}
{'type': 'l2update', 'product_id': 'BTC-USD', 'changes': [['buy', '38253.49', '0.00000000']], 'time': '2021-05-20T03:54:45.698729Z'}
{'type': 'l2update', 'product_id': 'BTC-USD', 'changes': [['buy', '38189.16', '0.26185436']], 'time': '2021-05-20T03:54:45.704867Z'}
{'type': 'l2update', 'product_id': 'BTC-USD', 'changes': [['buy', '38256.01', '0.02400000']], 'time': '2021-05-20T03:54:45.711994Z'}
{'type': 'l2update', 'product_id': 'BTC-USD', 'changes': [['sell', '38315.03', '0.00000000']], 'time': '2021-05-20T03:54:45.713409Z'}
{'type': 'l2update', 'product_id': 'BTC-USD', 'changes': [['buy', '38270.14', '0.21575391']], 'time': '2021-05-20T03:54:45.720134Z'}
{'type': 'l2update', 'product_id': 'BTC-USD', 'changes': [['sell', '38316.18', '0.44860000']], 'time': '2021-05-20T03:54:45.725038Z'}
{'type': 'l2update', 'product_id': 'BTC-USD', 'changes': [['sell', '38315.02', '0.00000000']], 'time': '2021-05-20T03:54:45.732169Z'}
{'type': 'l2update', 'product_id': 'BTC-USD', 'changes': [['sell', '49118.66', '0.01078900']], 'time': '2021-05-20T03:54:45.735783Z'}
{'type': 'l2update', 'product_id': 'BTC-USD', 'changes': [['sell', '38316.17', '0.05000000']], 'time': '2021-05-20T03:54:45.739391Z'}
{'type': 'l2update', 'product_id': 'BTC-USD', 'changes': [['sell', '38370.35', '0.00000000']], 'time': '2021-05-20T03:54:45.753306Z'}
{'type': 'l2update', 'product_id': 'BTC-USD', 'changes': [['sell', '38400.61', '0.01589000']], 'time': '2021-05-20T03:54:45.766724Z'}
{'type': 'l2update', 'product_id': 'BTC-USD', 'changes': [['buy', '38257.11', '0.04873693']], 'time': '2021-05-20T03:54:45.768848Z'}
{'type': 'l2update', 'product_id': 'BTC-USD', 'changes': [['buy', '38257.11', '0.00000000']], 'time': '2021-05-20T03:54:45.768848Z'}
{'type': 'l2update', 'product_id': 'BTC-USD', 'changes': [['sell', '38297.68', '0.00000000']], 'time': '2021-05-20T03:54:45.768848Z'}
{'type': 'l2update', 'product_id': 'BTC-USD', 'changes': [['sell', '38294.71', '0.00939912']], 'time': '2021-05-20T03:54:45.791608Z'}
{'type': 'l2update', 'product_id': 'BTC-USD', 'changes': [['buy', '38257.11', '0.04400659']], 'time': '2021-05-20T03:54:45.791747Z'}
{'type': 'l2update', 'product_id': 'BTC-USD', 'changes': [['sell', '38300.71', '0.06088542']], 'time': '2021-05-20T03:54:45.791747Z'}
{'type': 'l2update', 'product_id': 'BTC-USD', 'changes': [['buy', '38288.48', '0.00956129']], 'time': '2021-05-20T03:54:45.794454Z'}
{'type': 'l2update', 'product_id': 'BTC-USD', 'changes': [['sell', '38331.14', '0.00000000']], 'time': '2021-05-20T03:54:45.809969Z'}
{'type': 'l2update', 'product_id': 'BTC-USD', 'changes': [['sell', '38294.71', '0.00000000']], 'time': '2021-05-20T03:54:45.815994Z'}
{'type': 'l2update', 'product_id': 'BTC-USD', 'changes': [['buy', '38270.15', '0.05488740']], 'time': '2021-05-20T03:54:45.818120Z'}
{'type': 'l2update', 'product_id': 'BTC-USD', 'changes': [['sell', '39767.56', '0.00000000']], 'time': '2021-05-20T03:54:45.821750Z'}
{'type': 'l2update', 'product_id': 'BTC-USD', 'changes': [['buy', '38270.13', '0.00000000']], 'time': '2021-05-20T03:54:45.824406Z'}
{'type': 'l2update', 'product_id': 'BTC-USD', 'changes': [['buy', '38270.14', '0.00000000']], 'time': '2021-05-20T03:54:45.828383Z'}
{'type': 'l2update', 'product_id': 'BTC-USD', 'changes': [['sell', '38290.47', '0.00000000']], 'time': '2021-05-20T03:54:45.829879Z'}
{'type': 'l2update', 'product_id': 'BTC-USD', 'changes': [['sell', '38294.47', '0.00000000']], 'time': '2021-05-20T03:54:45.833417Z'}
{'type': 'l2update', 'product_id': 'BTC-USD', 'changes': [['buy', '38256.01', '0.00000000']], 'time': '2021-05-20T03:54:45.838142Z'}
{'type': 'l2update', 'product_id': 'BTC-USD', 'changes': [['buy', '38255.10', '0.00000000']], 'time': '2021-05-20T03:54:45.838142Z'}
{'type': 'l2update', 'product_id': 'BTC-USD', 'changes': [['buy', '38254.21', '0.00000000']], 'time': '2021-05-20T03:54:45.838142Z'}
{'type': 'l2update', 'product_id': 'BTC-USD', 'changes': [['sell', '38291.80', '2.48969908']], 'time': '2021-05-20T03:54:45.844210Z'}
{'type': 'l2update', 'product_id': 'BTC-USD', 'changes': [['sell', '38296.98', '0.00000000']], 'time': '2021-05-20T03:54:45.846716Z'}
{'type': 'l2update', 'product_id': 'BTC-USD', 'changes': [['buy', '38270.16', '0.21575391']], 'time': '2021-05-20T03:54:45.847676Z'}
{'type': 'l2update', 'product_id': 'BTC-USD', 'changes': [['sell', '38300.66', '0.61200000']], 'time': '2021-05-20T03:54:45.849654Z'}
{'type': 'l2update', 'product_id': 'BTC-USD', 'changes': [['sell', '38307.75', '0.00000000']], 'time': '2021-05-20T03:54:45.857554Z'}
{'type': 'l2update', 'product_id': 'BTC-USD', 'changes': [['sell', '38291.80', '0.00000000']], 'time': '2021-05-20T03:54:45.858027Z'}
{'type': 'l2update', 'product_id': 'BTC-USD', 'changes': [['buy', '38282.46', '0.05025743']], 'time': '2021-05-20T03:54:45.860627Z'}
{'type': 'l2update', 'product_id': 'BTC-USD', 'changes': [['buy', '38259.18', '0.02400000']], 'time': '2021-05-20T03:54:45.860822Z'}
{'type': 'l2update', 'product_id': 'BTC-USD', 'changes': [['buy', '38258.37', '0.02400000']], 'time': '2021-05-20T03:54:45.860822Z'}
{'type': 'l2update', 'product_id': 'BTC-USD', 'changes': [['buy', '38257.57', '0.02400000']], 'time': '2021-05-20T03:54:45.860822Z'}
{'type': 'l2update', 'product_id': 'BTC-USD', 'changes': [['buy', '38116.74', '0.05021893']], 'time': '2021-05-20T03:54:45.863718Z'}
{'type': 'l2update', 'product_id': 'BTC-USD', 'changes': [['buy', '38270.15', '0.00000000']], 'time': '2021-05-20T03:54:45.864406Z'}
{'type': 'l2update', 'product_id': 'BTC-USD', 'changes': [['sell', '38300.70', '1.10200000']], 'time': '2021-05-20T03:54:45.867243Z'}
{'type': 'l2update', 'product_id': 'BTC-USD', 'changes': [['buy', '38270.17', '0.05488740']], 'time': '2021-05-20T03:54:45.871946Z'}
{'type': 'l2update', 'product_id': 'BTC-USD', 'changes': [['buy', '38259.18', '0.00000000']], 'time': '2021-05-20T03:54:45.889146Z'}
{'type': 'l2update', 'product_id': 'BTC-USD', 'changes': [['buy', '38258.37', '0.00000000']], 'time': '2021-05-20T03:54:45.889146Z'}
{'type': 'l2update', 'product_id': 'BTC-USD', 'changes': [['buy', '38257.57', '0.00000000']], 'time': '2021-05-20T03:54:45.889146Z'}
{'type': 'l2update', 'product_id': 'BTC-USD', 'changes': [['sell', '38297.04', '0.00000000']], 'time': '2021-05-20T03:54:45.889742Z'}
{'type': 'l2update', 'product_id': 'BTC-USD', 'changes': [['sell', '38292.98', '2.48969908']], 'time': '2021-05-20T03:54:45.892171Z'}
{'type': 'l2update', 'product_id': 'BTC-USD', 'changes': [['sell', '38297.39', '0.00000000']], 'time': '2021-05-20T03:54:45.893278Z'}
{'type': 'l2update', 'product_id': 'BTC-USD', 'changes': [['buy', '38278.05', '0.00000000']], 'time': '2021-05-20T03:54:45.893542Z'}
{'type': 'l2update', 'product_id': 'BTC-USD', 'changes': [['buy', '37500.01', '0.13960000']], 'time': '2021-05-20T03:54:45.895754Z'}
{'type': 'l2update', 'product_id': 'BTC-USD', 'changes': [['buy', '38257.11', '0.00000000']], 'time': '2021-05-20T03:54:45.898782Z'}
{'type': 'l2update', 'product_id': 'BTC-USD', 'changes': [['sell', '38300.71', '0.00000000']], 'time': '2021-05-20T03:54:45.898782Z'}
{'type': 'l2update', 'product_id': 'BTC-USD', 'changes': [['buy', '37500.01', '0.19730000']], 'time': '2021-05-20T03:54:45.899674Z'}
{'type': 'l2update', 'product_id': 'BTC-USD', 'changes': [['sell', '38314.47', '0.05148579']], 'time': '2021-05-20T03:54:45.900196Z'}
{'type': 'l2update', 'product_id': 'BTC-USD', 'changes': [['sell', '49118.88', '0.00413800']], 'time': '2021-05-20T03:54:45.900879Z'}
{'type': 'l2update', 'product_id': 'BTC-USD', 'changes': [['buy', '38283.95', '0.00000000']], 'time': '2021-05-20T03:54:45.906775Z'}
{'type': 'l2update', 'product_id': 'BTC-USD', 'changes': [['buy', '38270.16', '0.00000000']], 'time': '2021-05-20T03:54:45.921585Z'}
{'type': 'l2update', 'product_id': 'BTC-USD', 'changes': [['sell', '38292.98', '0.00000000']], 'time': '2021-05-20T03:54:45.926885Z'}
{'type': 'l2update', 'product_id': 'BTC-USD', 'changes': [['sell', '38300.66', '1.22400000']], 'time': '2021-05-20T03:54:45.928916Z'}
{'type': 'l2update', 'product_id': 'BTC-USD', 'changes': [['sell', '38317.57', '0.05000000']], 'time': '2021-05-20T03:54:45.933139Z'}
{'type': 'l2update', 'product_id': 'BTC-USD', 'changes': [['sell', '38324.75', '0.10000000']], 'time': '2021-05-20T03:54:45.934150Z'}
{'type': 'l2update', 'product_id': 'BTC-USD', 'changes': [['sell', '38437.76', '0.00000000']], 'time': '2021-05-20T03:54:45.956816Z'}
{'type': 'l2update', 'product_id': 'BTC-USD', 'changes': [['buy', '38282.74', '0.06274942']], 'time': '2021-05-20T03:54:45.960391Z'}
{'type': 'l2update', 'product_id': 'BTC-USD', 'changes': [['buy', '38288.49', '0.07240138']], 'time': '2021-05-20T03:54:45.972535Z'}
{'type': 'l2update', 'product_id': 'BTC-USD', 'changes': [['buy', '38256.36', '0.02400000']], 'time': '2021-05-20T03:54:45.972679Z'}
{'type': 'l2update', 'product_id': 'BTC-USD', 'changes': [['buy', '38255.56', '0.02400000']], 'time': '2021-05-20T03:54:45.972679Z'}
{'type': 'l2update', 'product_id': 'BTC-USD', 'changes': [['buy', '38254.75', '0.02400000']], 'time': '2021-05-20T03:54:45.972679Z'}
{'type': 'l2update', 'product_id': 'BTC-USD', 'changes': [['sell', '38297.11', '2.48969908']], 'time': '2021-05-20T03:54:45.975493Z'}
{'type': 'l2update', 'product_id': 'BTC-USD', 'changes': [['buy', '38230.54', '0.00000000']], 'time': '2021-05-20T03:54:45.976631Z'}
{'type': 'l2update', 'product_id': 'BTC-USD', 'changes': [['sell', '38374.02', '0.10970000']], 'time': '2021-05-20T03:54:45.976659Z'}
{'type': 'l2update', 'product_id': 'BTC-USD', 'changes': [['sell', '38453.76', '0.00000000']], 'time': '2021-05-20T03:54:45.984826Z'}
{'type': 'l2update', 'product_id': 'BTC-USD', 'changes': [['buy', '38270.18', '0.21575391']], 'time': '2021-05-20T03:54:45.999814Z'}
{'type': 'l2update', 'product_id': 'BTC-USD', 'changes': [['sell', '38316.18', '0.00000000']], 'time': '2021-05-20T03:54:46.001328Z'}
{'type': 'l2update', 'product_id': 'BTC-USD', 'changes': [['sell', '38423.91', '0.01000000']], 'time': '2021-05-20T03:54:46.004423Z'}
{'type': 'l2update', 'product_id': 'BTC-USD', 'changes': [['buy', '38282.74', '0.00000000']], 'time': '2021-05-20T03:54:46.006391Z'}
{'type': 'l2update', 'product_id': 'BTC-USD', 'changes': [['sell', '38290.46', '0.36761294']], 'time': '2021-05-20T03:54:46.024739Z'}
{'type': 'l2update', 'product_id': 'BTC-USD', 'changes': [['buy', '38109.84', '0.00000000']], 'time': '2021-05-20T03:54:46.024803Z'}
{'type': 'l2update', 'product_id': 'BTC-USD', 'changes': [['sell', '38302.48', '0.04933649']], 'time': '2021-05-20T03:54:46.027877Z'}
{'type': 'l2update', 'product_id': 'BTC-USD', 'changes': [['buy', '38290.45', '0.01492000']], 'time': '2021-05-20T03:54:46.027945Z'}
{'type': 'l2update', 'product_id': 'BTC-USD', 'changes': [['buy', '38231.54', '0.10000000']], 'time': '2021-05-20T03:54:46.035026Z'}
{'type': 'l2update', 'product_id': 'BTC-USD', 'changes': [['buy', '38258.82', '0.06477965']], 'time': '2021-05-20T03:54:46.036410Z'}
{'type': 'l2update', 'product_id': 'BTC-USD', 'changes': [['sell', '38303.97', '0.05885375']], 'time': '2021-05-20T03:54:46.036410Z'}
{'type': 'l2update', 'product_id': 'BTC-USD', 'changes': [['sell', '38438.69', '0.01000000']], 'time': '2021-05-20T03:54:46.040508Z'}
{'type': 'l2update', 'product_id': 'BTC-USD', 'changes': [['sell', '38317.62', '0.43230000']], 'time': '2021-05-20T03:54:46.053144Z'}
{'type': 'l2update', 'product_id': 'BTC-USD', 'changes': [['buy', '38272.43', '0.52250913']], 'time': '2021-05-20T03:54:46.053412Z'}
{'type': 'l2update', 'product_id': 'BTC-USD', 'changes': [['buy', '32000.00', '202.53972397']], 'time': '2021-05-20T03:54:46.061234Z'}
{'type': 'l2update', 'product_id': 'BTC-USD', 'changes': [['buy', '38270.19', '0.05488740']], 'time': '2021-05-20T03:54:46.071674Z'}
{'type': 'l2update', 'product_id': 'BTC-USD', 'changes': [['sell', '38294.52', '0.00000000']], 'time': '2021-05-20T03:54:46.074581Z'}
{'type': 'l2update', 'product_id': 'BTC-USD', 'changes': [['buy', '37500.01', '0.20160000']], 'time': '2021-05-20T03:54:46.076756Z'}
{'type': 'l2update', 'product_id': 'BTC-USD', 'changes': [['sell', '38314.47', '0.00000000']], 'time': '2021-05-20T03:54:46.078014Z'}
{'type': 'l2update', 'product_id': 'BTC-USD', 'changes': [['buy', '38282.03', '0.00000000']], 'time': '2021-05-20T03:54:46.083378Z'}
{'type': 'l2update', 'product_id': 'BTC-USD', 'changes': [['buy', '38275.73', '0.14500000']], 'time': '2021-05-20T03:54:46.093761Z'}
{'type': 'l2update', 'product_id': 'BTC-USD', 'changes': [['buy', '38120.87', '0.05087207']], 'time': '2021-05-20T03:54:46.094922Z'}
{'type': 'l2update', 'product_id': 'BTC-USD', 'changes': [['sell', '49125.69', '0.02146900']], 'time': '2021-05-20T03:54:46.098588Z'}
{'type': 'l2update', 'product_id': 'BTC-USD', 'changes': [['buy', '38270.17', '0.00000000']], 'time': '2021-05-20T03:54:46.100059Z'}
{'type': 'l2update', 'product_id': 'BTC-USD', 'changes': [['sell', '38328.41', '0.00000000']], 'time': '2021-05-20T03:54:46.100284Z'}
{'type': 'l2update', 'product_id': 'BTC-USD', 'changes': [['buy', '38261.58', '0.00000000']], 'time': '2021-05-20T03:54:46.104395Z'}
{'type': 'l2update', 'product_id': 'BTC-USD', 'changes': [['buy', '38288.48', '0.00000000']], 'time': '2021-05-20T03:54:46.105952Z'}
{'type': 'l2update', 'product_id': 'BTC-USD', 'changes': [['sell', '38316.17', '0.00000000']], 'time': '2021-05-20T03:54:46.112330Z'}
{'type': 'l2update', 'product_id': 'BTC-USD', 'changes': [['buy', '38272.48', '0.52100000']], 'time': '2021-05-20T03:54:46.115384Z'}
{'type': 'l2update', 'product_id': 'BTC-USD', 'changes': [['buy', '38272.48', '1.36900000']], 'time': '2021-05-20T03:54:46.121230Z'}
{'type': 'l2update', 'product_id': 'BTC-USD', 'changes': [['buy', '38270.19', '0.00000000']], 'time': '2021-05-20T03:54:46.128250Z'}
{'type': 'l2update', 'product_id': 'BTC-USD', 'changes': [['sell', '38290.46', '0.36249352']], 'time': '2021-05-20T03:54:46.136070Z'}
{'type': 'l2update', 'product_id': 'BTC-USD', 'changes': [['buy', '38270.18', '0.00000000']], 'time': '2021-05-20T03:54:46.144101Z'}
{'type': 'l2update', 'product_id': 'BTC-USD', 'changes': [['buy', '38262.92', '0.41830000']], 'time': '2021-05-20T03:54:46.146702Z'}
{'type': 'l2update', 'product_id': 'BTC-USD', 'changes': [['buy', '38248.23', '0.01000000']], 'time': '2021-05-20T03:54:46.147420Z'}
{'type': 'l2update', 'product_id': 'BTC-USD', 'changes': [['sell', '38300.81', '0.00000000']], 'time': '2021-05-20T03:54:46.157430Z'}
{'type': 'l2update', 'product_id': 'BTC-USD', 'changes': [['sell', '38300.70', '0.00000000']], 'time': '2021-05-20T03:54:46.157933Z'}
{'type': 'l2update', 'product_id': 'BTC-USD', 'changes': [['sell', '38357.74', '0.00000000']], 'time': '2021-05-20T03:54:46.158393Z'}
{'type': 'l2update', 'product_id': 'BTC-USD', 'changes': [['sell', '38317.61', '0.05000000']], 'time': '2021-05-20T03:54:46.158796Z'}
{'type': 'l2update', 'product_id': 'BTC-USD', 'changes': [['buy', '38272.44', '0.05488740']], 'time': '2021-05-20T03:54:46.164196Z'}
{'type': 'l2update', 'product_id': 'BTC-USD', 'changes': [['buy', '38185.56', '0.00000000']], 'time': '2021-05-20T03:54:46.176529Z'}
{'type': 'l2update', 'product_id': 'BTC-USD', 'changes': [['buy', '38275.78', '0.52100000']], 'time': '2021-05-20T03:54:46.184375Z'}
{'type': 'l2update', 'product_id': 'BTC-USD', 'changes': [['sell', '38336.93', '0.69701634']], 'time': '2021-05-20T03:54:46.188822Z'}
{'type': 'l2update', 'product_id': 'BTC-USD', 'changes': [['buy', '38116.74', '0.00000000']], 'time': '2021-05-20T03:54:46.189953Z'}
{'type': 'l2update', 'product_id': 'BTC-USD', 'changes': [['buy', '38272.49', '0.05488740']], 'time': '2021-05-20T03:54:46.192245Z'}
{'type': 'l2update', 'product_id': 'BTC-USD', 'changes': [['buy', '38286.89', '0.04918652']], 'time': '2021-05-20T03:54:46.192549Z'}
{'type': 'l2update', 'product_id': 'BTC-USD', 'changes': [['sell', '38324.75', '0.00000000']], 'time': '2021-05-20T03:54:46.193637Z'}
{'type': 'l2update', 'product_id': 'BTC-USD', 'changes': [['sell', '38317.62', '0.00000000']], 'time': '2021-05-20T03:54:46.193875Z'}
{'type': 'l2update', 'product_id': 'BTC-USD', 'changes': [['sell', '38331.21', '0.10000000']], 'time': '2021-05-20T03:54:46.196407Z'}
{'type': 'l2update', 'product_id': 'BTC-USD', 'changes': [['sell', '38290.46', '0.00000000']], 'time': '2021-05-20T03:54:46.199312Z'}
{'type': 'l2update', 'product_id': 'BTC-USD', 'changes': [['sell', '38381.26', '0.00000000']], 'time': '2021-05-20T03:54:46.205344Z'}
{'type': 'l2update', 'product_id': 'BTC-USD', 'changes': [['buy', '38290.45', '0.16492000']], 'time': '2021-05-20T03:54:46.211647Z'}
{'type': 'l2update', 'product_id': 'BTC-USD', 'changes': [['sell', '43100.00', '1.09530000']], 'time': '2021-05-20T03:54:46.215286Z'}
{'type': 'l2update', 'product_id': 'BTC-USD', 'changes': [['buy', '38265.33', '0.00000000']], 'time': '2021-05-20T03:54:46.217316Z'}
{'type': 'l2update', 'product_id': 'BTC-USD', 'changes': [['buy', '38272.44', '0.00000000']], 'time': '2021-05-20T03:54:46.217393Z'}
{'type': 'l2update', 'product_id': 'BTC-USD', 'changes': [['sell', '38290.49', '0.00000000']], 'time': '2021-05-20T03:54:46.221956Z'}
{'type': 'l2update', 'product_id': 'BTC-USD', 'changes': [['buy', '38258.82', '0.00000000']], 'time': '2021-05-20T03:54:46.225042Z'}
{'type': 'l2update', 'product_id': 'BTC-USD', 'changes': [['sell', '38303.97', '0.00000000']], 'time': '2021-05-20T03:54:46.225042Z'}
{'type': 'l2update', 'product_id': 'BTC-USD', 'changes': [['buy', '38262.92', '0.00000000']], 'time': '2021-05-20T03:54:46.225615Z'}
{'type': 'l2update', 'product_id': 'BTC-USD', 'changes': [['sell', '38317.57', '0.00000000']], 'time': '2021-05-20T03:54:46.228038Z'}
{'type': 'l2update', 'product_id': 'BTC-USD', 'changes': [['buy', '38290.45', '0.15000000']], 'time': '2021-05-20T03:54:46.230406Z'}
{'type': 'l2update', 'product_id': 'BTC-USD', 'changes': [['sell', '38302.48', '0.00000000']], 'time': '2021-05-20T03:54:46.231919Z'}
{'type': 'l2update', 'product_id': 'BTC-USD', 'changes': [['buy', '38272.49', '0.28355944']], 'time': '2021-05-20T03:54:46.232691Z'}
{'type': 'l2update', 'product_id': 'BTC-USD', 'changes': [['buy', '38282.46', '0.00000000']], 'time': '2021-05-20T03:54:46.232931Z'}
{'type': 'l2update', 'product_id': 'BTC-USD', 'changes': [['sell', '38324.03', '0.05000000']], 'time': '2021-05-20T03:54:46.233147Z'}
{'type': 'l2update', 'product_id': 'BTC-USD', 'changes': [['sell', '38317.61', '0.00000000']], 'time': '2021-05-20T03:54:46.233534Z'}
{'type': 'l2update', 'product_id': 'BTC-USD', 'changes': [['buy', '38272.49', '0.22867204']], 'time': '2021-05-20T03:54:46.234513Z'}
{'type': 'l2update', 'product_id': 'BTC-USD', 'changes': [['buy', '38268.81', '0.00000000']], 'time': '2021-05-20T03:54:46.236022Z'}
{'type': 'l2update', 'product_id': 'BTC-USD', 'changes': [['sell', '38392.88', '0.01898000']], 'time': '2021-05-20T03:54:46.236808Z'}
{'type': 'l2update', 'product_id': 'BTC-USD', 'changes': [['sell', '43100.00', '2.43820000']], 'time': '2021-05-20T03:54:46.239917Z'}
{'type': 'l2update', 'product_id': 'BTC-USD', 'changes': [['sell', '38297.11', '0.00000000']], 'time': '2021-05-20T03:54:46.241929Z'}
{'type': 'l2update', 'product_id': 'BTC-USD', 'changes': [['sell', '38310.44', '1.45800000']], 'time': '2021-05-20T03:54:46.244885Z'}
{'type': 'l2update', 'product_id': 'BTC-USD', 'changes': [['buy', '38179.71', '0.00000000']], 'time': '2021-05-20T03:54:46.246293Z'}
{'type': 'l2update', 'product_id': 'BTC-USD', 'changes': [['sell', '38438.69', '0.00000000']], 'time': '2021-05-20T03:54:46.251566Z'}
{'type': 'l2update', 'product_id': 'BTC-USD', 'changes': [['sell', '38297.10', '0.36249352']], 'time': '2021-05-20T03:54:46.255587Z'}
{'type': 'l2update', 'product_id': 'BTC-USD', 'changes': [['buy', '38275.79', '0.05488740']], 'time': '2021-05-20T03:54:46.255634Z'}
{'type': 'l2update', 'product_id': 'BTC-USD', 'changes': [['buy', '38291.80', '0.02590000']], 'time': '2021-05-20T03:54:46.255699Z'}
{'type': 'l2update', 'product_id': 'BTC-USD', 'changes': [['sell', '38291.81', '0.20000000']], 'time': '2021-05-20T03:54:46.256274Z'}
{'type': 'l2update', 'product_id': 'BTC-USD', 'changes': [['sell', '38325.82', '0.05000000']], 'time': '2021-05-20T03:54:46.256294Z'}
{'type': 'l2update', 'product_id': 'BTC-USD', 'changes': [['sell', '38297.10', '0.86249352']], 'time': '2021-05-20T03:54:46.256312Z'}
{'type': 'l2update', 'product_id': 'BTC-USD', 'changes': [['sell', '38310.49', '0.00000000']], 'time': '2021-05-20T03:54:46.261649Z'}
{'type': 'l2update', 'product_id': 'BTC-USD', 'changes': [['buy', '38260.83', '0.01230000']], 'time': '2021-05-20T03:54:46.267693Z'}
{'type': 'l2update', 'product_id': 'BTC-USD', 'changes': [['sell', '38297.10', '0.36249352']], 'time': '2021-05-20T03:54:46.269124Z'}
{'type': 'l2update', 'product_id': 'BTC-USD', 'changes': [['sell', '38455.64', '0.01000000']], 'time': '2021-05-20T03:54:46.271026Z'}
{'type': 'l2update', 'product_id': 'BTC-USD', 'changes': [['sell', '38310.43', '0.05488740']], 'time': '2021-05-20T03:54:46.271188Z'}
{'type': 'l2update', 'product_id': 'BTC-USD', 'changes': [['buy', '38193.13', '0.01000000']], 'time': '2021-05-20T03:54:46.271448Z'}
{'type': 'l2update', 'product_id': 'BTC-USD', 'changes': [['buy', '38275.84', '0.84800000']], 'time': '2021-05-20T03:54:46.274871Z'}
{'type': 'l2update', 'product_id': 'BTC-USD', 'changes': [['sell', '38292.99', '0.00000000']], 'time': '2021-05-20T03:54:46.274991Z'}
{'type': 'l2update', 'product_id': 'BTC-USD', 'changes': [['sell', '38291.81', '0.40000000']], 'time': '2021-05-20T03:54:46.275099Z'}
{'type': 'l2update', 'product_id': 'BTC-USD', 'changes': [['sell', '38300.65', '2.48969908']], 'time': '2021-05-20T03:54:46.277825Z'}
{'type': 'l2update', 'product_id': 'BTC-USD', 'changes': [['buy', '38271.96', '0.52700000']], 'time': '2021-05-20T03:54:46.280149Z'}
{'type': 'l2update', 'product_id': 'BTC-USD', 'changes': [['buy', '38254.20', '0.00000000']], 'time': '2021-05-20T03:54:46.281451Z'}
{'type': 'l2update', 'product_id': 'BTC-USD', 'changes': [['buy', '38261.88', '0.05166406']], 'time': '2021-05-20T03:54:46.283807Z'}
{'type': 'l2update', 'product_id': 'BTC-USD', 'changes': [['sell', '38305.78', '0.04161354']], 'time': '2021-05-20T03:54:46.283807Z'}
{'type': 'l2update', 'product_id': 'BTC-USD', 'changes': [['buy', '38269.92', '0.00000000']], 'time': '2021-05-20T03:54:46.284425Z'}
{'type': 'l2update', 'product_id': 'BTC-USD', 'changes': [['sell', '38300.65', '2.98969908']], 'time': '2021-05-20T03:54:46.288235Z'}
{'type': 'l2update', 'product_id': 'BTC-USD', 'changes': [['sell', '49129.41', '0.00413800']], 'time': '2021-05-20T03:54:46.293835Z'}
{'type': 'l2update', 'product_id': 'BTC-USD', 'changes': [['buy', '38275.85', '0.05488740']], 'time': '2021-05-20T03:54:46.293969Z'}
{'type': 'l2update', 'product_id': 'BTC-USD', 'changes': [['buy', '38275.79', '0.00000000']], 'time': '2021-05-20T03:54:46.300451Z'}
{'type': 'l2update', 'product_id': 'BTC-USD', 'changes': [['sell', '38523.47', '0.00000000']], 'time': '2021-05-20T03:54:46.304401Z'}
{'type': 'l2update', 'product_id': 'BTC-USD', 'changes': [['buy', '38275.85', '0.00000000']], 'time': '2021-05-20T03:54:46.304990Z'}
{'type': 'l2update', 'product_id': 'BTC-USD', 'changes': [['buy', '38272.49', '0.00000000']], 'time': '2021-05-20T03:54:46.307679Z'}
{'type': 'l2update', 'product_id': 'BTC-USD', 'changes': [['sell', '38297.10', '0.00000000']], 'time': '2021-05-20T03:54:46.313125Z'}
{'type': 'l2update', 'product_id': 'BTC-USD', 'changes': [['sell', '38319.88', '0.41600000']], 'time': '2021-05-20T03:54:46.313275Z'}
{'type': 'l2update', 'product_id': 'BTC-USD', 'changes': [['buy', '38272.50', '0.05488740']], 'time': '2021-05-20T03:54:46.318233Z'}
{'type': 'l2update', 'product_id': 'BTC-USD', 'changes': [['sell', '38598.45', '0.01295389']], 'time': '2021-05-20T03:54:46.318302Z'}
{'type': 'l2update', 'product_id': 'BTC-USD', 'changes': [['buy', '38291.80', '0.00000000']], 'time': '2021-05-20T03:54:46.318338Z'}
{'type': 'l2update', 'product_id': 'BTC-USD', 'changes': [['buy', '38288.49', '0.00000000']], 'time': '2021-05-20T03:54:46.320093Z'}
{'type': 'l2update', 'product_id': 'BTC-USD', 'changes': [['sell', '38325.82', '0.00000000']], 'time': '2021-05-20T03:54:46.322001Z'}
{'type': 'l2update', 'product_id': 'BTC-USD', 'changes': [['buy', '38272.50', '0.00000000']], 'time': '2021-05-20T03:54:46.327066Z'}
{'type': 'l2update', 'product_id': 'BTC-USD', 'changes': [['buy', '38275.85', '0.22867204']], 'time': '2021-05-20T03:54:46.327526Z'}
{'type': 'l2update', 'product_id': 'BTC-USD', 'changes': [['buy', '38275.74', '0.05488740']], 'time': '2021-05-20T03:54:46.332563Z'}
{'type': 'l2update', 'product_id': 'BTC-USD', 'changes': [['sell', '38319.87', '0.05000000']], 'time': '2021-05-20T03:54:46.337116Z'}
{'type': 'l2update', 'product_id': 'BTC-USD', 'changes': [['sell', '38290.46', '0.10000000']], 'time': '2021-05-20T03:54:46.337137Z'}
{'type': 'l2update', 'product_id': 'BTC-USD', 'changes': [['buy', '38263.63', '0.42020000']], 'time': '2021-05-20T03:54:46.337183Z'}
{'type': 'l2update', 'product_id': 'BTC-USD', 'changes': [['sell', '38300.64', '0.36249352']], 'time': '2021-05-20T03:54:46.337279Z'}
{'type': 'l2update', 'product_id': 'BTC-USD', 'changes': [['sell', '38341.16', '0.20400000']], 'time': '2021-05-20T03:54:46.339282Z'}
{'type': 'l2update', 'product_id': 'BTC-USD', 'changes': [['buy', '38275.74', '0.00000000']], 'time': '2021-05-20T03:54:46.340189Z'}
{'type': 'l2update', 'product_id': 'BTC-USD', 'changes': [['buy', '38272.49', '0.05488740']], 'time': '2021-05-20T03:54:46.348133Z'}
{'type': 'l2update', 'product_id': 'BTC-USD', 'changes': [['sell', '38290.46', '0.30000000']], 'time': '2021-05-20T03:54:46.355735Z'}
{'type': 'l2update', 'product_id': 'BTC-USD', 'changes': [['buy', '38290.45', '0.15051367']], 'time': '2021-05-20T03:54:46.356281Z'}
{'type': 'l2update', 'product_id': 'BTC-USD', 'changes': [['sell', '38291.81', '0.30000000']], 'time': '2021-05-20T03:54:46.363518Z'}
{'type': 'l2update', 'product_id': 'BTC-USD', 'changes': [['buy', '38261.88', '0.00000000']], 'time': '2021-05-20T03:54:46.367500Z'}
{'type': 'l2update', 'product_id': 'BTC-USD', 'changes': [['sell', '38305.78', '0.00000000']], 'time': '2021-05-20T03:54:46.367500Z'}
{'type': 'l2update', 'product_id': 'BTC-USD', 'changes': [['buy', '38263.63', '0.00000000']], 'time': '2021-05-20T03:54:46.368638Z'}
{'type': 'l2update', 'product_id': 'BTC-USD', 'changes': [['sell', '38291.81', '0.10000000']], 'time': '2021-05-20T03:54:46.370419Z'}
{'type': 'l2update', 'product_id': 'BTC-USD', 'changes': [['sell', '38300.65', '2.48969908']], 'time': '2021-05-20T03:54:46.371356Z'}
{'type': 'l2update', 'product_id': 'BTC-USD', 'changes': [['buy', '38248.23', '0.00000000']], 'time': '2021-05-20T03:54:46.379960Z'}
{'type': 'l2update', 'product_id': 'BTC-USD', 'changes': [['sell', '38598.45', '0.00000000']], 'time': '2021-05-20T03:54:46.381976Z'}
{'type': 'l2update', 'product_id': 'BTC-USD', 'changes': [['sell', '38455.64', '0.00000000']], 'time': '2021-05-20T03:54:46.384055Z'}
{'type': 'l2update', 'product_id': 'BTC-USD', 'changes': [['sell', '38297.11', '0.50000000']], 'time': '2021-05-20T03:54:46.386632Z'}
{'type': 'l2update', 'product_id': 'BTC-USD', 'changes': [['buy', '38260.37', '0.05446958']], 'time': '2021-05-20T03:54:46.390214Z'}
{'type': 'l2update', 'product_id': 'BTC-USD', 'changes': [['sell', '38302.24', '0.04342493']], 'time': '2021-05-20T03:54:46.390214Z'}
{'type': 'l2update', 'product_id': 'BTC-USD', 'changes': [['sell', '38328.86', '0.01000000']], 'time': '2021-05-20T03:54:46.390436Z'}
{'type': 'l2update', 'product_id': 'BTC-USD', 'changes': [['sell', '38300.64', '0.00000000']], 'time': '2021-05-20T03:54:46.392943Z'}
{'type': 'l2update', 'product_id': 'BTC-USD', 'changes': [['sell', '38583.45', '0.01295892']], 'time': '2021-05-20T03:54:46.393592Z'}
{'type': 'l2update', 'product_id': 'BTC-USD', 'changes': [['sell', '38442.46', '0.01000000']], 'time': '2021-05-20T03:54:46.406409Z'}
{'type': 'l2update', 'product_id': 'BTC-USD', 'changes': [['sell', '38328.86', '0.00000000']], 'time': '2021-05-20T03:54:46.406953Z'}
{'type': 'l2update', 'product_id': 'BTC-USD', 'changes': [['sell', '38297.10', '0.36249352']], 'time': '2021-05-20T03:54:46.413579Z'}
{'type': 'l2update', 'product_id': 'BTC-USD', 'changes': [['buy', '38245.99', '0.01000000']], 'time': '2021-05-20T03:54:46.425084Z'}
{'type': 'l2update', 'product_id': 'BTC-USD', 'changes': [['buy', '38260.37', '0.00000000']], 'time': '2021-05-20T03:54:46.431602Z'}
{'type': 'l2update', 'product_id': 'BTC-USD', 'changes': [['sell', '38302.24', '0.00000000']], 'time': '2021-05-20T03:54:46.431602Z'}
{'type': 'l2update', 'product_id': 'BTC-USD', 'changes': [['sell', '38442.46', '0.00000000']], 'time': '2021-05-20T03:54:46.434243Z'}
{'type': 'l2update', 'product_id': 'BTC-USD', 'changes': [['sell', '38457.52', '0.01000000']], 'time': '2021-05-20T03:54:46.445222Z'}
{'type': 'l2update', 'product_id': 'BTC-USD', 'changes': [['sell', '49136.22', '0.02146900']], 'time': '2021-05-20T03:54:46.457688Z'}
{'type': 'l2update', 'product_id': 'BTC-USD', 'changes': [['buy', '38262.92', '0.40400000']], 'time': '2021-05-20T03:54:46.457757Z'}
{'type': 'l2update', 'product_id': 'BTC-USD', 'changes': [['buy', '38257.34', '0.06342453']], 'time': '2021-05-20T03:54:46.462863Z'}
{'type': 'l2update', 'product_id': 'BTC-USD', 'changes': [['sell', '38300.95', '0.06475516']], 'time': '2021-05-20T03:54:46.462863Z'}
{'type': 'l2update', 'product_id': 'BTC-USD', 'changes': [['buy', '38270.04', '0.00000000']], 'time': '2021-05-20T03:54:46.466930Z'}
{'type': 'l2update', 'product_id': 'BTC-USD', 'changes': [['buy', '38255.56', '0.00000000']], 'time': '2021-05-20T03:54:46.469946Z'}
{'type': 'l2update', 'product_id': 'BTC-USD', 'changes': [['buy', '38254.75', '0.00000000']], 'time': '2021-05-20T03:54:46.469946Z'}
{'type': 'l2update', 'product_id': 'BTC-USD', 'changes': [['sell', '38457.52', '0.00000000']], 'time': '2021-05-20T03:54:46.470632Z'}
{'type': 'l2update', 'product_id': 'BTC-USD', 'changes': [['buy', '38256.36', '0.00000000']], 'time': '2021-05-20T03:54:46.473787Z'}
{'type': 'l2update', 'product_id': 'BTC-USD', 'changes': [['sell', '38400.61', '0.00000000']], 'time': '2021-05-20T03:54:46.474450Z'}
{'type': 'l2update', 'product_id': 'BTC-USD', 'changes': [['buy', '38275.86', '0.58716278']], 'time': '2021-05-20T03:54:46.484941Z'}
{'type': 'l2update', 'product_id': 'BTC-USD', 'changes': [['sell', '38444.34', '0.01000000']], 'time': '2021-05-20T03:54:46.485065Z'}
{'type': 'l2update', 'product_id': 'BTC-USD', 'changes': [['sell', '38388.63', '0.01000000']], 'time': '2021-05-20T03:54:46.488879Z'}
{'type': 'l2update', 'product_id': 'BTC-USD', 'changes': [['buy', '38260.42', '0.02400000']], 'time': '2021-05-20T03:54:46.488922Z'}
{'type': 'l2update', 'product_id': 'BTC-USD', 'changes': [['buy', '38259.61', '0.02400000']], 'time': '2021-05-20T03:54:46.488922Z'}
{'type': 'l2update', 'product_id': 'BTC-USD', 'changes': [['buy', '38258.81', '0.02400000']], 'time': '2021-05-20T03:54:46.488922Z'}
{'type': 'l2update', 'product_id': 'BTC-USD', 'changes': [['buy', '38275.85', '0.00000000']], 'time': '2021-05-20T03:54:46.490949Z'}
{'type': 'l2update', 'product_id': 'BTC-USD', 'changes': [['sell', '38290.46', '0.33600000']], 'time': '2021-05-20T03:54:46.492458Z'}
{'type': 'l2update', 'product_id': 'BTC-USD', 'changes': [['buy', '38189.16', '0.00000000']], 'time': '2021-05-20T03:54:46.494892Z'}
{'type': 'l2update', 'product_id': 'BTC-USD', 'changes': [['buy', '38258.81', '0.00000000']], 'time': '2021-05-20T03:54:46.495333Z'}
{'type': 'l2update', 'product_id': 'BTC-USD', 'changes': [['buy', '38286.89', '0.00000000']], 'time': '2021-05-20T03:54:46.498625Z'}
{'type': 'l2update', 'product_id': 'BTC-USD', 'changes': [['buy', '38259.61', '0.00000000']], 'time': '2021-05-20T03:54:46.500168Z'}
{'type': 'l2update', 'product_id': 'BTC-USD', 'changes': [['sell', '38297.09', '1.42474045']], 'time': '2021-05-20T03:54:46.503288Z'}
{'type': 'l2update', 'product_id': 'BTC-USD', 'changes': [['buy', '38120.87', '0.00000000']], 'time': '2021-05-20T03:54:46.503534Z'}
{'type': 'l2update', 'product_id': 'BTC-USD', 'changes': [['buy', '38170.33', '0.01144565']], 'time': '2021-05-20T03:54:46.510241Z'}
{'type': 'l2update', 'product_id': 'BTC-USD', 'changes': [['sell', '38297.10', '0.00000000']], 'time': '2021-05-20T03:54:46.511711Z'}
{'type': 'l2update', 'product_id': 'BTC-USD', 'changes': [['buy', '38275.86', '0.00000000']], 'time': '2021-05-20T03:54:46.511770Z'}
{'type': 'l2update', 'product_id': 'BTC-USD', 'changes': [['buy', '38275.87', '0.22867204']], 'time': '2021-05-20T03:54:46.515117Z'}
{'type': 'l2update', 'product_id': 'BTC-USD', 'changes': [['sell', '38319.88', '0.00000000']], 'time': '2021-05-20T03:54:46.521311Z'}
{'type': 'l2update', 'product_id': 'BTC-USD', 'changes': [['sell', '38297.11', '0.00000000']], 'time': '2021-05-20T03:54:46.528568Z'}
{'type': 'l2update', 'product_id': 'BTC-USD', 'changes': [['buy', '38275.78', '0.00000000']], 'time': '2021-05-20T03:54:46.528611Z'}
{'type': 'l2update', 'product_id': 'BTC-USD', 'changes': [['buy', '38262.64', '0.02400000']], 'time': '2021-05-20T03:54:46.530703Z'}
{'type': 'l2update', 'product_id': 'BTC-USD', 'changes': [['buy', '38261.83', '0.02400000']], 'time': '2021-05-20T03:54:46.530703Z'}
{'type': 'l2update', 'product_id': 'BTC-USD', 'changes': [['sell', '38297.04', '0.60600000']], 'time': '2021-05-20T03:54:46.530721Z'}
{'type': 'l2update', 'product_id': 'BTC-USD', 'changes': [['sell', '38297.09', '0.00000000']], 'time': '2021-05-20T03:54:46.533244Z'}
{'type': 'l2update', 'product_id': 'BTC-USD', 'changes': [['buy', '38275.84', '0.00000000']], 'time': '2021-05-20T03:54:46.533270Z'}
{'type': 'l2update', 'product_id': 'BTC-USD', 'changes': [['sell', '38318.11', '0.42170000']], 'time': '2021-05-20T03:54:46.535730Z'}
{'type': 'l2update', 'product_id': 'BTC-USD', 'changes': [['sell', '38297.08', '0.36249352']], 'time': '2021-05-20T03:54:46.535793Z'}
{'type': 'l2update', 'product_id': 'BTC-USD', 'changes': [['buy', '38262.64', '0.00000000']], 'time': '2021-05-20T03:54:46.536769Z'}
{'type': 'l2update', 'product_id': 'BTC-USD', 'changes': [['sell', '38318.11', '0.00000000']], 'time': '2021-05-20T03:54:46.539674Z'}
{'type': 'l2update', 'product_id': 'BTC-USD', 'changes': [['sell', '38301.58', '0.00000000']], 'time': '2021-05-20T03:54:46.540901Z'}
{'type': 'l2update', 'product_id': 'BTC-USD', 'changes': [['buy', '38257.34', '0.00000000']], 'time': '2021-05-20T03:54:46.541373Z'}
{'type': 'l2update', 'product_id': 'BTC-USD', 'changes': [['sell', '38300.95', '0.00000000']], 'time': '2021-05-20T03:54:46.541373Z'}
{'type': 'l2update', 'product_id': 'BTC-USD', 'changes': [['sell', '38319.87', '0.00000000']], 'time': '2021-05-20T03:54:46.541445Z'}
{'type': 'l2update', 'product_id': 'BTC-USD', 'changes': [['buy', '38272.01', '0.52100000']], 'time': '2021-05-20T03:54:46.542866Z'}
{'type': 'l2update', 'product_id': 'BTC-USD', 'changes': [['sell', '38297.08', '1.92970802']], 'time': '2021-05-20T03:54:46.547656Z'}
{'type': 'l2update', 'product_id': 'BTC-USD', 'changes': [['buy', '38272.50', '0.58716278']], 'time': '2021-05-20T03:54:46.548154Z'}
{'type': 'l2update', 'product_id': 'BTC-USD', 'changes': [['sell', '38291.80', '0.50000000']], 'time': '2021-05-20T03:54:46.548219Z'}
{'type': 'l2update', 'product_id': 'BTC-USD', 'changes': [['sell', '38328.09', '0.03207306']], 'time': '2021-05-20T03:54:46.548274Z'}
{'type': 'l2update', 'product_id': 'BTC-USD', 'changes': [['sell', '38318.10', '0.05000000']], 'time': '2021-05-20T03:54:46.552501Z'}
{'type': 'l2update', 'product_id': 'BTC-USD', 'changes': [['buy', '38259.44', '0.02400000']], 'time': '2021-05-20T03:54:46.552638Z'}
{'type': 'l2update', 'product_id': 'BTC-USD', 'changes': [['sell', '38310.43', '0.00000000']], 'time': '2021-05-20T03:54:46.557560Z'}
{'type': 'l2update', 'product_id': 'BTC-USD', 'changes': [['buy', '38272.50', '0.00000000']], 'time': '2021-05-20T03:54:46.557946Z'}
{'type': 'l2update', 'product_id': 'BTC-USD', 'changes': [['buy', '38245.99', '0.00000000']], 'time': '2021-05-20T03:54:46.559110Z'}
{'type': 'l2update', 'product_id': 'BTC-USD', 'changes': [['buy', '38261.83', '0.00000000']], 'time': '2021-05-20T03:54:46.559764Z'}
{'type': 'l2update', 'product_id': 'BTC-USD', 'changes': [['sell', '38297.03', '1.31392731']], 'time': '2021-05-20T03:54:46.559888Z'}
{'type': 'l2update', 'product_id': 'BTC-USD', 'changes': [['buy', '38262.92', '0.00000000']], 'time': '2021-05-20T03:54:46.565404Z'}
{'type': 'l2update', 'product_id': 'BTC-USD', 'changes': [['buy', '38290.45', '0.00051367']], 'time': '2021-05-20T03:54:46.565516Z'}
{'type': 'l2update', 'product_id': 'BTC-USD', 'changes': [['buy', '38290.45', '0.00001367']], 'time': '2021-05-20T03:54:46.565516Z'}
{'type': 'l2update', 'product_id': 'BTC-USD', 'changes': [['buy', '38272.01', '0.00000000']], 'time': '2021-05-20T03:54:46.570640Z'}
{'type': 'l2update', 'product_id': 'BTC-USD', 'changes': [['sell', '38397.70', '0.00000000']], 'time': '2021-05-20T03:54:46.574071Z'}
{'type': 'l2update', 'product_id': 'BTC-USD', 'changes': [['buy', '38272.48', '0.52100000']], 'time': '2021-05-20T03:54:46.575287Z'}
{'type': 'l2update', 'product_id': 'BTC-USD', 'changes': [['buy', '38272.51', '0.05206770']], 'time': '2021-05-20T03:54:46.575553Z'}
{'type': 'l2update', 'product_id': 'BTC-USD', 'changes': [['sell', '38290.46', '1.61826641']], 'time': '2021-05-20T03:54:46.575682Z'}
{'type': 'l2update', 'product_id': 'BTC-USD', 'changes': [['buy', '38258.40', '0.02400000']], 'time': '2021-05-20T03:54:46.576313Z'}
{'type': 'l2update', 'product_id': 'BTC-USD', 'changes': [['sell', '38290.46', '1.62173419']], 'time': '2021-05-20T03:54:46.576605Z'}
{'type': 'l2update', 'product_id': 'BTC-USD', 'changes': [['sell', '38321.00', '0.01000000']], 'time': '2021-05-20T03:54:46.576826Z'}
{'type': 'l2update', 'product_id': 'BTC-USD', 'changes': [['buy', '38261.17', '0.44580000']], 'time': '2021-05-20T03:54:46.576968Z'}
{'type': 'l2update', 'product_id': 'BTC-USD', 'changes': [['buy', '38270.10', '0.00000000']], 'time': '2021-05-20T03:54:46.576990Z'}
{'type': 'l2update', 'product_id': 'BTC-USD', 'changes': [['buy', '38275.73', '0.00000000']], 'time': '2021-05-20T03:54:46.578497Z'}
{'type': 'l2update', 'product_id': 'BTC-USD', 'changes': [['buy', '38290.45', '0.00000000']], 'time': '2021-05-20T03:54:46.580198Z'}
{'type': 'l2update', 'product_id': 'BTC-USD', 'changes': [['sell', '38290.45', '0.19998633']], 'time': '2021-05-20T03:54:46.580198Z'}
{'type': 'l2update', 'product_id': 'BTC-USD', 'changes': [['buy', '38276.20', '0.06274942']], 'time': '2021-05-20T03:54:46.580330Z'}
{'type': 'l2update', 'product_id': 'BTC-USD', 'changes': [['sell', '38279.88', '0.03880000']], 'time': '2021-05-20T03:54:46.580609Z'}
{'type': 'l2update', 'product_id': 'BTC-USD', 'changes': [['buy', '38276.54', '0.01492000']], 'time': '2021-05-20T03:54:46.580696Z'}
{'type': 'l2update', 'product_id': 'BTC-USD', 'changes': [['buy', '38272.51', '0.00000000']], 'time': '2021-05-20T03:54:46.582220Z'}
{'type': 'l2update', 'product_id': 'BTC-USD', 'changes': [['sell', '38290.46', '0.33946778']], 'time': '2021-05-20T03:54:46.583724Z'}
{'type': 'l2update', 'product_id': 'BTC-USD', 'changes': [['buy', '38260.42', '0.00000000']], 'time': '2021-05-20T03:54:46.583763Z'}
{'type': 'l2update', 'product_id': 'BTC-USD', 'changes': [['buy', '38272.48', '0.00000000']], 'time': '2021-05-20T03:54:46.583979Z'}
{'type': 'l2update', 'product_id': 'BTC-USD', 'changes': [['buy', '38270.09', '0.00000000']], 'time': '2021-05-20T03:54:46.584078Z'}
{'type': 'l2update', 'product_id': 'BTC-USD', 'changes': [['buy', '38275.87', '0.00000000']], 'time': '2021-05-20T03:54:46.584688Z'}
{'type': 'l2update', 'product_id': 'BTC-USD', 'changes': [['buy', '38272.49', '0.00000000']], 'time': '2021-05-20T03:54:46.585013Z'}
{'type': 'l2update', 'product_id': 'BTC-USD', 'changes': [['buy', '38261.17', '0.00000000']], 'time': '2021-05-20T03:54:46.586260Z'}
{'type': 'l2update', 'product_id': 'BTC-USD', 'changes': [['buy', '38266.82', '0.58716278']], 'time': '2021-05-20T03:54:46.587600Z'}
{'type': 'l2update', 'product_id': 'BTC-USD', 'changes': [['buy', '38276.16', '0.01185058']], 'time': '2021-05-20T03:54:46.587703Z'}
{'type': 'l2update', 'product_id': 'BTC-USD', 'changes': [['buy', '38276.20', '0.00000000']], 'time': '2021-05-20T03:54:46.588900Z'}
{'type': 'l2update', 'product_id': 'BTC-USD', 'changes': [['sell', '38290.46', '0.30346778']], 'time': '2021-05-20T03:54:46.590253Z'}
{'type': 'l2update', 'product_id': 'BTC-USD', 'changes': [['buy', '38259.44', '0.00000000']], 'time': '2021-05-20T03:54:46.590311Z'}
{'type': 'l2update', 'product_id': 'BTC-USD', 'changes': [['buy', '38238.70', '0.01000000']], 'time': '2021-05-20T03:54:46.593416Z'}
{'type': 'l2update', 'product_id': 'BTC-USD', 'changes': [['sell', '38290.45', '0.20248215']], 'time': '2021-05-20T03:54:46.594160Z'}
{'type': 'l2update', 'product_id': 'BTC-USD', 'changes': [['buy', '38248.57', '0.05775561']], 'time': '2021-05-20T03:54:46.594314Z'}
{'type': 'l2update', 'product_id': 'BTC-USD', 'changes': [['sell', '38297.69', '0.05245282']], 'time': '2021-05-20T03:54:46.594314Z'}
{'type': 'l2update', 'product_id': 'BTC-USD', 'changes': [['sell', '38413.23', '0.01000000']], 'time': '2021-05-20T03:54:46.594447Z'}
{'type': 'l2update', 'product_id': 'BTC-USD', 'changes': [['sell', '38297.08', '1.56721450']], 'time': '2021-05-20T03:54:46.594628Z'}
{'type': 'l2update', 'product_id': 'BTC-USD', 'changes': [['buy', '38251.21', '0.00000000']], 'time': '2021-05-20T03:54:46.595621Z'}
{'type': 'l2update', 'product_id': 'BTC-USD', 'changes': [['buy', '38272.43', '0.00000000']], 'time': '2021-05-20T03:54:46.596903Z'}
{'type': 'l2update', 'product_id': 'BTC-USD', 'changes': [['buy', '38258.40', '0.00000000']], 'time': '2021-05-20T03:54:46.597782Z'}
{'type': 'l2update', 'product_id': 'BTC-USD', 'changes': [['sell', '38290.45', '0.85248215']], 'time': '2021-05-20T03:54:46.600130Z'}
{'type': 'l2update', 'product_id': 'BTC-USD', 'changes': [['sell', '38290.45', '0.95248215']], 'time': '2021-05-20T03:54:46.600223Z'}
{'type': 'l2update', 'product_id': 'BTC-USD', 'changes': [['sell', '38288.54', '0.03600000']], 'time': '2021-05-20T03:54:46.600241Z'}
{'type': 'l2update', 'product_id': 'BTC-USD', 'changes': [['sell', '38289.89', '0.01492000']], 'time': '2021-05-20T03:54:46.600487Z'}
{'type': 'l2update', 'product_id': 'BTC-USD', 'changes': [['buy', '38261.18', '0.05206770']], 'time': '2021-05-20T03:54:46.601192Z'}
{'type': 'l2update', 'product_id': 'BTC-USD', 'changes': [['sell', '38290.07', '0.07460000']], 'time': '2021-05-20T03:54:46.602065Z'}
{'type': 'l2update', 'product_id': 'BTC-USD', 'changes': [['sell', '38290.46', '2.09230857']], 'time': '2021-05-20T03:54:46.602097Z'}
{'type': 'l2update', 'product_id': 'BTC-USD', 'changes': [['buy', '38231.54', '0.00000000']], 'time': '2021-05-20T03:54:46.602865Z'}
{'type': 'l2update', 'product_id': 'BTC-USD', 'changes': [['sell', '38279.88', '0.07480000']], 'time': '2021-05-20T03:54:46.605735Z'}
{'type': 'l2update', 'product_id': 'BTC-USD', 'changes': [['sell', '38279.88', '0.72480000']], 'time': '2021-05-20T03:54:46.605952Z'}
{'type': 'l2update', 'product_id': 'BTC-USD', 'changes': [['sell', '38386.10', '0.00000000']], 'time': '2021-05-20T03:54:46.606335Z'}
{'type': 'l2update', 'product_id': 'BTC-USD', 'changes': [['buy', '38272.44', '0.22867204']], 'time': '2021-05-20T03:54:46.609410Z'}
{'type': 'l2update', 'product_id': 'BTC-USD', 'changes': [['buy', '38276.54', '0.00000000']], 'time': '2021-05-20T03:54:46.610266Z'}
{'type': 'l2update', 'product_id': 'BTC-USD', 'changes': [['sell', '38289.89', '0.00000000']], 'time': '2021-05-20T03:54:46.610372Z'}
{'type': 'l2update', 'product_id': 'BTC-USD', 'changes': [['buy', '38261.18', '0.00000000']], 'time': '2021-05-20T03:54:46.610456Z'}
{'type': 'l2update', 'product_id': 'BTC-USD', 'changes': [['sell', '38288.54', '0.00000000']], 'time': '2021-05-20T03:54:46.610685Z'}
{'type': 'l2update', 'product_id': 'BTC-USD', 'changes': [['sell', '38290.46', '1.99230857']], 'time': '2021-05-20T03:54:46.610903Z'}
{'type': 'l2update', 'product_id': 'BTC-USD', 'changes': [['buy', '38266.82', '0.00000000']], 'time': '2021-05-20T03:54:46.611394Z'}
{'type': 'l2update', 'product_id': 'BTC-USD', 'changes': [['buy', '38276.16', '0.00000000']], 'time': '2021-05-20T03:54:46.612432Z'}
{'type': 'l2update', 'product_id': 'BTC-USD', 'changes': [['sell', '38290.07', '0.00000000']], 'time': '2021-05-20T03:54:46.613152Z'}
{'type': 'l2update', 'product_id': 'BTC-USD', 'changes': [['sell', '38290.46', '1.99457079']], 'time': '2021-05-20T03:54:46.613754Z'}
{'type': 'l2update', 'product_id': 'BTC-USD', 'changes': [['sell', '38323.12', '0.20700000']], 'time': '2021-05-20T03:54:46.614292Z'}
{'type': 'l2update', 'product_id': 'BTC-USD', 'changes': [['sell', '38318.10', '0.00000000']], 'time': '2021-05-20T03:54:46.615636Z'}
{'type': 'l2update', 'product_id': 'BTC-USD', 'changes': [['buy', '38258.39', '0.05206770']], 'time': '2021-05-20T03:54:46.619593Z'}
{'type': 'l2update', 'product_id': 'BTC-USD', 'changes': [['sell', '49143.45', '0.00413800']], 'time': '2021-05-20T03:54:46.619614Z'}
{'type': 'l2update', 'product_id': 'BTC-USD', 'changes': [['buy', '38253.78', '0.02400000']], 'time': '2021-05-20T03:54:46.620234Z'}
{'type': 'l2update', 'product_id': 'BTC-USD', 'changes': [['buy', '38252.97', '0.02400000']], 'time': '2021-05-20T03:54:46.620234Z'}
{'type': 'l2update', 'product_id': 'BTC-USD', 'changes': [['buy', '38252.17', '0.02400000']], 'time': '2021-05-20T03:54:46.620234Z'}
{'type': 'l2update', 'product_id': 'BTC-USD', 'changes': [['sell', '38290.46', '1.79457079']], 'time': '2021-05-20T03:54:46.622721Z'}
{'type': 'l2update', 'product_id': 'BTC-USD', 'changes': [['sell', '38378.77', '0.00000000']], 'time': '2021-05-20T03:54:46.626345Z'}
{'type': 'l2update', 'product_id': 'BTC-USD', 'changes': [['sell', '38367.56', '0.00000000']], 'time': '2021-05-20T03:54:46.626345Z'}
{'type': 'l2update', 'product_id': 'BTC-USD', 'changes': [['sell', '38357.11', '0.00000000']], 'time': '2021-05-20T03:54:46.626345Z'}
{'type': 'l2update', 'product_id': 'BTC-USD', 'changes': [['sell', '38352.17', '0.00000000']], 'time': '2021-05-20T03:54:46.626345Z'}
{'type': 'l2update', 'product_id': 'BTC-USD', 'changes': [['sell', '38347.42', '0.00000000']], 'time': '2021-05-20T03:54:46.626345Z'}
{'type': 'l2update', 'product_id': 'BTC-USD', 'changes': [['sell', '38334.31', '0.00000000']], 'time': '2021-05-20T03:54:46.626345Z'}
{'type': 'l2update', 'product_id': 'BTC-USD', 'changes': [['buy', '38228.90', '0.00000000']], 'time': '2021-05-20T03:54:46.626345Z'}
{'type': 'l2update', 'product_id': 'BTC-USD', 'changes': [['sell', '38325.83', '0.00000000']], 'time': '2021-05-20T03:54:46.627015Z'}
{'type': 'l2update', 'product_id': 'BTC-USD', 'changes': [['buy', '38265.25', '0.00000000']], 'time': '2021-05-20T03:54:46.629092Z'}
{'type': 'l2update', 'product_id': 'BTC-USD', 'changes': [['sell', '38415.85', '0.00000000']], 'time': '2021-05-20T03:54:46.629137Z'}
{'type': 'l2update', 'product_id': 'BTC-USD', 'changes': [['sell', '38478.55', '0.00000000']], 'time': '2021-05-20T03:54:46.629308Z'}
{'type': 'l2update', 'product_id': 'BTC-USD', 'changes': [['buy', '38258.39', '0.00000000']], 'time': '2021-05-20T03:54:46.630382Z'}
{'type': 'l2update', 'product_id': 'BTC-USD', 'changes': [['buy', '38235.54', '0.10000000']], 'time': '2021-05-20T03:54:46.631959Z'}
{'type': 'l2update', 'product_id': 'BTC-USD', 'changes': [['buy', '38253.78', '0.00000000']], 'time': '2021-05-20T03:54:46.632195Z'}
{'type': 'l2update', 'product_id': 'BTC-USD', 'changes': [['buy', '38258.39', '0.58716278']], 'time': '2021-05-20T03:54:46.637830Z'}
{'type': 'l2update', 'product_id': 'BTC-USD', 'changes': [['buy', '35000.00', '210.93898450']], 'time': '2021-05-20T03:54:46.638030Z'}
{'type': 'l2update', 'product_id': 'BTC-USD', 'changes': [['sell', '38290.06', '0.36249352']], 'time': '2021-05-20T03:54:46.638049Z'}
{'type': 'l2update', 'product_id': 'BTC-USD', 'changes': [['sell', '38310.43', '0.05000000']], 'time': '2021-05-20T03:54:46.638358Z'}
{'type': 'l2update', 'product_id': 'BTC-USD', 'changes': [['sell', '38290.45', '0.95571633']], 'time': '2021-05-20T03:54:46.638412Z'}
{'type': 'l2update', 'product_id': 'BTC-USD', 'changes': [['buy', '38261.19', '0.05206770']], 'time': '2021-05-20T03:54:46.638488Z'}
{'type': 'l2update', 'product_id': 'BTC-USD', 'changes': [['sell', '38312.13', '0.48800000']], 'time': '2021-05-20T03:54:46.638662Z'}
{'type': 'l2update', 'product_id': 'BTC-USD', 'changes': [['sell', '38433.19', '0.00000000']], 'time': '2021-05-20T03:54:46.641993Z'}
{'type': 'l2update', 'product_id': 'BTC-USD', 'changes': [['buy', '38252.97', '0.00000000']], 'time': '2021-05-20T03:54:46.642983Z'}
{'type': 'l2update', 'product_id': 'BTC-USD', 'changes': [['buy', '38252.17', '0.00000000']], 'time': '2021-05-20T03:54:46.642983Z'}
{'type': 'l2update', 'product_id': 'BTC-USD', 'changes': [['sell', '38279.88', '0.82480000']], 'time': '2021-05-20T03:54:46.644013Z'}
{'type': 'l2update', 'product_id': 'BTC-USD', 'changes': [['sell', '38402.84', '0.13019871']], 'time': '2021-05-20T03:54:46.644498Z'}
{'type': 'l2update', 'product_id': 'BTC-USD', 'changes': [['sell', '38312.13', '0.00000000']], 'time': '2021-05-20T03:54:46.651164Z'}
{'type': 'l2update', 'product_id': 'BTC-USD', 'changes': [['buy', '38269.51', '0.00000000']], 'time': '2021-05-20T03:54:46.651186Z'}
{'type': 'l2update', 'product_id': 'BTC-USD', 'changes': [['sell', '38290.46', '1.79110301']], 'time': '2021-05-20T03:54:46.651709Z'}
{'type': 'l2update', 'product_id': 'BTC-USD', 'changes': [['sell', '38444.34', '0.00000000']], 'time': '2021-05-20T03:54:46.652826Z'}
{'type': 'l2update', 'product_id': 'BTC-USD', 'changes': [['sell', '38306.95', '0.05000000']], 'time': '2021-05-20T03:54:46.656230Z'}
{'type': 'l2update', 'product_id': 'BTC-USD', 'changes': [['sell', '38291.49', '0.00600000']], 'time': '2021-05-20T03:54:46.656811Z'}
{'type': 'l2update', 'product_id': 'BTC-USD', 'changes': [['sell', '38420.19', '0.01301399']], 'time': '2021-05-20T03:54:46.660446Z'}
{'type': 'l2update', 'product_id': 'BTC-USD', 'changes': [['sell', '38290.45', '0.95322051']], 'time': '2021-05-20T03:54:46.661054Z'}
{'type': 'l2update', 'product_id': 'BTC-USD', 'changes': [['sell', '38432.32', '0.00000000']], 'time': '2021-05-20T03:54:46.662138Z'}
{'type': 'l2update', 'product_id': 'BTC-USD', 'changes': [['sell', '38410.77', '0.01000000']], 'time': '2021-05-20T03:54:46.664896Z'}
{'type': 'l2update', 'product_id': 'BTC-USD', 'changes': [['sell', '38316.94', '0.10000000']], 'time': '2021-05-20T03:54:46.665062Z'}
{'type': 'l2update', 'product_id': 'BTC-USD', 'changes': [['sell', '38279.88', '1.02480000']], 'time': '2021-05-20T03:54:46.665088Z'}
{'type': 'l2update', 'product_id': 'BTC-USD', 'changes': [['sell', '38300.65', '0.00000000']], 'time': '2021-05-20T03:54:46.667180Z'}
{'type': 'l2update', 'product_id': 'BTC-USD', 'changes': [['sell', '38297.12', '0.00000000']], 'time': '2021-05-20T03:54:46.668697Z'}
{'type': 'l2update', 'product_id': 'BTC-USD', 'changes': [['sell', '38444.20', '0.00000000']], 'time': '2021-05-20T03:54:46.669829Z'}
{'type': 'l2update', 'product_id': 'BTC-USD', 'changes': [['sell', '38349.64', '0.00000000']], 'time': '2021-05-20T03:54:46.669829Z'}
{'type': 'l2update', 'product_id': 'BTC-USD', 'changes': [['buy', '38258.38', '0.00000000']], 'time': '2021-05-20T03:54:46.673469Z'}
{'type': 'l2update', 'product_id': 'BTC-USD', 'changes': [['buy', '38272.44', '0.00000000']], 'time': '2021-05-20T03:54:46.673887Z'}
{'type': 'l2update', 'product_id': 'BTC-USD', 'changes': [['sell', '38290.46', '1.78884079']], 'time': '2021-05-20T03:54:46.674036Z'}
{'type': 'l2update', 'product_id': 'BTC-USD', 'changes': [['sell', '38290.45', '0.75323418']], 'time': '2021-05-20T03:54:46.676496Z'}
{'type': 'l2update', 'product_id': 'BTC-USD', 'changes': [['buy', '38153.84', '0.03221511']], 'time': '2021-05-20T03:54:46.677222Z'}
{'type': 'l2update', 'product_id': 'BTC-USD', 'changes': [['sell', '38290.01', '1.39200000']], 'time': '2021-05-20T03:54:46.677369Z'}
{'type': 'l2update', 'product_id': 'BTC-USD', 'changes': [['sell', '38457.52', '0.01000000']], 'time': '2021-05-20T03:54:46.677933Z'}
{'type': 'l2update', 'product_id': 'BTC-USD', 'changes': [['buy', '38258.39', '0.00000000']], 'time': '2021-05-20T03:54:46.678981Z'}
{'type': 'l2update', 'product_id': 'BTC-USD', 'changes': [['sell', '38324.76', '0.00000000']], 'time': '2021-05-20T03:54:46.682327Z'}
{'type': 'l2update', 'product_id': 'BTC-USD', 'changes': [['sell', '38312.31', '0.14263608']], 'time': '2021-05-20T03:54:46.682746Z'}
{'type': 'l2update', 'product_id': 'BTC-USD', 'changes': [['sell', '38418.80', '0.01000000']], 'time': '2021-05-20T03:54:46.682959Z'}
{'type': 'l2update', 'product_id': 'BTC-USD', 'changes': [['buy', '38261.19', '0.00000000']], 'time': '2021-05-20T03:54:46.683101Z'}
{'type': 'l2update', 'product_id': 'BTC-USD', 'changes': [['sell', '38290.45', '0.75000000']], 'time': '2021-05-20T03:54:46.685641Z'}
{'type': 'l2update', 'product_id': 'BTC-USD', 'changes': [['sell', '38290.45', '0.65000000']], 'time': '2021-05-20T03:54:46.686927Z'}
{'type': 'l2update', 'product_id': 'BTC-USD', 'changes': [['buy', '38239.28', '0.00000000']], 'time': '2021-05-20T03:54:46.687615Z'}
{'type': 'l2update', 'product_id': 'BTC-USD', 'changes': [['sell', '38356.31', '0.13670000']], 'time': '2021-05-20T03:54:46.688396Z'}
{'type': 'l2update', 'product_id': 'BTC-USD', 'changes': [['buy', '38254.72', '0.41530000']], 'time': '2021-05-20T03:54:46.688444Z'}
{'type': 'l2update', 'product_id': 'BTC-USD', 'changes': [['buy', '38258.40', '0.05206770']], 'time': '2021-05-20T03:54:46.688491Z'}
{'type': 'l2update', 'product_id': 'BTC-USD', 'changes': [['buy', '38271.96', '0.00000000']], 'time': '2021-05-20T03:54:46.692822Z'}
{'type': 'l2update', 'product_id': 'BTC-USD', 'changes': [['buy', '38246.90', '0.02400000']], 'time': '2021-05-20T03:54:46.692867Z'}
{'type': 'l2update', 'product_id': 'BTC-USD', 'changes': [['buy', '38246.10', '0.02400000']], 'time': '2021-05-20T03:54:46.692867Z'}
{'type': 'l2update', 'product_id': 'BTC-USD', 'changes': [['buy', '38245.29', '0.02400000']], 'time': '2021-05-20T03:54:46.692867Z'}
{'type': 'l2update', 'product_id': 'BTC-USD', 'changes': [['sell', '38376.16', '0.00000000']], 'time': '2021-05-20T03:54:46.696770Z'}
{'type': 'l2update', 'product_id': 'BTC-USD', 'changes': [['sell', '38353.83', '0.00000000']], 'time': '2021-05-20T03:54:46.696770Z'}
{'type': 'l2update', 'product_id': 'BTC-USD', 'changes': [['sell', '38348.89', '0.00000000']], 'time': '2021-05-20T03:54:46.696770Z'}
{'type': 'l2update', 'product_id': 'BTC-USD', 'changes': [['sell', '38339.58', '0.00000000']], 'time': '2021-05-20T03:54:46.696770Z'}
{'type': 'l2update', 'product_id': 'BTC-USD', 'changes': [['sell', '38335.22', '0.00000000']], 'time': '2021-05-20T03:54:46.696770Z'}
{'type': 'l2update', 'product_id': 'BTC-USD', 'changes': [['sell', '38330.01', '0.29485155']], 'time': '2021-05-20T03:54:46.696770Z'}
{'type': 'l2update', 'product_id': 'BTC-USD', 'changes': [['sell', '38330.01', '0.00000000']], 'time': '2021-05-20T03:54:46.696770Z'}
{'type': 'l2update', 'product_id': 'BTC-USD', 'changes': [['sell', '38325.84', '0.39186277']], 'time': '2021-05-20T03:54:46.696770Z'}
{'type': 'l2update', 'product_id': 'BTC-USD', 'changes': [['sell', '38325.84', '0.03527257']], 'time': '2021-05-20T03:54:46.696770Z'}
{'type': 'l2update', 'product_id': 'BTC-USD', 'changes': [['sell', '38290.05', '2.48969908']], 'time': '2021-05-20T03:54:46.703497Z'}
{'type': 'l2update', 'product_id': 'BTC-USD', 'changes': [['buy', '38266.81', '0.00000000']], 'time': '2021-05-20T03:54:46.704909Z'}
{'type': 'l2update', 'product_id': 'BTC-USD', 'changes': [['sell', '38553.56', '0.00000000']], 'time': '2021-05-20T03:54:46.707955Z'}
{'type': 'l2update', 'product_id': 'BTC-USD', 'changes': [['buy', '38228.55', '0.00000000']], 'time': '2021-05-20T03:54:46.709621Z'}
{'type': 'l2update', 'product_id': 'BTC-USD', 'changes': [['buy', '38250.01', '0.22867204']], 'time': '2021-05-20T03:54:46.711429Z'}
{'type': 'l2update', 'product_id': 'BTC-USD', 'changes': [['sell', '38290.06', '0.00000000']], 'time': '2021-05-20T03:54:46.712088Z'}
{'type': 'l2update', 'product_id': 'BTC-USD', 'changes': [['sell', '38336.08', '0.00000000']], 'time': '2021-05-20T03:54:46.712105Z'}
{'type': 'l2update', 'product_id': 'BTC-USD', 'changes': [['buy', '38231.95', '0.00000000']], 'time': '2021-05-20T03:54:46.712308Z'}
{'type': 'l2update', 'product_id': 'BTC-USD', 'changes': [['buy', '38246.90', '0.00000000']], 'time': '2021-05-20T03:54:46.716715Z'}
{'type': 'l2update', 'product_id': 'BTC-USD', 'changes': [['buy', '38124.76', '0.32361428']], 'time': '2021-05-20T03:54:46.716973Z'}
{'type': 'l2update', 'product_id': 'BTC-USD', 'changes': [['sell', '38351.57', '0.03536309']], 'time': '2021-05-20T03:54:46.717078Z'}
{'type': 'l2update', 'product_id': 'BTC-USD', 'changes': [['sell', '38341.50', '0.03210155']], 'time': '2021-05-20T03:54:46.717078Z'}
{'type': 'l2update', 'product_id': 'BTC-USD', 'changes': [['sell', '38336.76', '0.02642858']], 'time': '2021-05-20T03:54:46.717078Z'}
{'type': 'l2update', 'product_id': 'BTC-USD', 'changes': [['sell', '38327.85', '0.03291880']], 'time': '2021-05-20T03:54:46.717078Z'}
{'type': 'l2update', 'product_id': 'BTC-USD', 'changes': [['sell', '38319.70', '0.03534523']], 'time': '2021-05-20T03:54:46.717078Z'}
{'type': 'l2update', 'product_id': 'BTC-USD', 'changes': [['sell', '38312.31', '0.18146432']], 'time': '2021-05-20T03:54:46.717078Z'}
{'type': 'l2update', 'product_id': 'BTC-USD', 'changes': [['sell', '38336.94', '0.00000000']], 'time': '2021-05-20T03:54:46.717444Z'}
{'type': 'l2update', 'product_id': 'BTC-USD', 'changes': [['sell', '38323.11', '0.45541209']], 'time': '2021-05-20T03:54:46.721314Z'}
{'type': 'l2update', 'product_id': 'BTC-USD', 'changes': [['buy', '38279.87', '0.00001000']], 'time': '2021-05-20T03:54:46.721682Z'}
{'type': 'l2update', 'product_id': 'BTC-USD', 'changes': [['buy', '38253.23', '0.58716278']], 'time': '2021-05-20T03:54:46.726427Z'}
{'type': 'l2update', 'product_id': 'BTC-USD', 'changes': [['sell', '38575.19', '0.00648085']], 'time': '2021-05-20T03:54:46.727297Z'}
{'type': 'l2update', 'product_id': 'BTC-USD', 'changes': [['buy', '38277.20', '0.07241467']], 'time': '2021-05-20T03:54:46.727971Z'}
{'type': 'l2update', 'product_id': 'BTC-USD', 'changes': [['buy', '38269.19', '0.06274942']], 'time': '2021-05-20T03:54:46.728055Z'}
{'type': 'l2update', 'product_id': 'BTC-USD', 'changes': [['buy', '38246.10', '0.00000000']], 'time': '2021-05-20T03:54:46.729385Z'}
{'type': 'l2update', 'product_id': 'BTC-USD', 'changes': [['buy', '38245.29', '0.00000000']], 'time': '2021-05-20T03:54:46.729385Z'}
{'type': 'l2update', 'product_id': 'BTC-USD', 'changes': [['buy', '38269.10', '0.01492000']], 'time': '2021-05-20T03:54:46.732512Z'}
{'type': 'l2update', 'product_id': 'BTC-USD', 'changes': [['buy', '38197.09', '0.43433512']], 'time': '2021-05-20T03:54:46.732745Z'}
{'type': 'l2update', 'product_id': 'BTC-USD', 'changes': [['sell', '38392.88', '0.00000000']], 'time': '2021-05-20T03:54:46.738002Z'}
{'type': 'l2update', 'product_id': 'BTC-USD', 'changes': [['buy', '38258.40', '0.00000000']], 'time': '2021-05-20T03:54:46.739750Z'}
{'type': 'l2update', 'product_id': 'BTC-USD', 'changes': [['buy', '38250.01', '0.28073974']], 'time': '2021-05-20T03:54:46.742943Z'}
{'type': 'l2update', 'product_id': 'BTC-USD', 'changes': [['sell', '38279.88', '1.03053000']], 'time': '2021-05-20T03:54:46.744192Z'}
{'type': 'l2update', 'product_id': 'BTC-USD', 'changes': [['sell', '38328.50', '0.32000000']], 'time': '2021-05-20T03:54:46.747404Z'}
{'type': 'l2update', 'product_id': 'BTC-USD', 'changes': [['sell', '38423.01', '0.80000000']], 'time': '2021-05-20T03:54:46.747404Z'}
{'type': 'l2update', 'product_id': 'BTC-USD', 'changes': [['sell', '38308.21', '0.49940000']], 'time': '2021-05-20T03:54:46.747829Z'}
{'type': 'l2update', 'product_id': 'BTC-USD', 'changes': [['sell', '38323.11', '0.00000000']], 'time': '2021-05-20T03:54:46.749226Z'}
{'type': 'l2update', 'product_id': 'BTC-USD', 'changes': [['sell', '38336.93', '0.00000000']], 'time': '2021-05-20T03:54:46.750380Z'}
{'type': 'l2update', 'product_id': 'BTC-USD', 'changes': [['buy', '38269.19', '0.00000000']], 'time': '2021-05-20T03:54:46.752400Z'}
{'type': 'l2update', 'product_id': 'BTC-USD', 'changes': [['sell', '38312.31', '0.19557335']], 'time': '2021-05-20T03:54:46.752457Z'}
{'type': 'l2update', 'product_id': 'BTC-USD', 'changes': [['buy', '38146.85', '0.03536309']], 'time': '2021-05-20T03:54:46.752457Z'}
{'type': 'l2update', 'product_id': 'BTC-USD', 'changes': [['sell', '38388.63', '0.00000000']], 'time': '2021-05-20T03:54:46.753099Z'}
{'type': 'l2update', 'product_id': 'BTC-USD', 'changes': [['buy', '38277.20', '0.00000000']], 'time': '2021-05-20T03:54:46.754293Z'}
{'type': 'l2update', 'product_id': 'BTC-USD', 'changes': [['sell', '38457.52', '0.00000000']], 'time': '2021-05-20T03:54:46.756811Z'}
{'type': 'l2update', 'product_id': 'BTC-USD', 'changes': [['sell', '38375.30', '0.01000000']], 'time': '2021-05-20T03:54:46.759023Z'}
{'type': 'l2update', 'product_id': 'BTC-USD', 'changes': [['sell', '38290.00', '0.36249352']], 'time': '2021-05-20T03:54:46.759124Z'}
{'type': 'l2update', 'product_id': 'BTC-USD', 'changes': [['buy', '38269.10', '0.00000000']], 'time': '2021-05-20T03:54:46.759716Z'}
{'type': 'l2update', 'product_id': 'BTC-USD', 'changes': [['buy', '38199.18', '1.15941735']], 'time': '2021-05-20T03:54:46.759775Z'}
{'type': 'l2update', 'product_id': 'BTC-USD', 'changes': [['buy', '38248.57', '0.00000000']], 'time': '2021-05-20T03:54:46.762006Z'}
{'type': 'l2update', 'product_id': 'BTC-USD', 'changes': [['sell', '38310.43', '0.00000000']], 'time': '2021-05-20T03:54:46.762424Z'}
{'type': 'l2update', 'product_id': 'BTC-USD', 'changes': [['sell', '38410.12', '0.00000000']], 'time': '2021-05-20T03:54:46.765193Z'}
{'type': 'l2update', 'product_id': 'BTC-USD', 'changes': [['sell', '38403.47', '0.00000000']], 'time': '2021-05-20T03:54:46.765193Z'}
{'type': 'l2update', 'product_id': 'BTC-USD', 'changes': [['sell', '38397.01', '0.00000000']], 'time': '2021-05-20T03:54:46.765193Z'}
{'type': 'l2update', 'product_id': 'BTC-USD', 'changes': [['sell', '38390.74', '0.00000000']], 'time': '2021-05-20T03:54:46.765193Z'}
{'type': 'l2update', 'product_id': 'BTC-USD', 'changes': [['sell', '38384.66', '0.00000000']], 'time': '2021-05-20T03:54:46.765193Z'}
{'type': 'l2update', 'product_id': 'BTC-USD', 'changes': [['sell', '38325.84', '0.00000000']], 'time': '2021-05-20T03:54:46.765193Z'}
{'type': 'l2update', 'product_id': 'BTC-USD', 'changes': [['buy', '38233.48', '0.00000000']], 'time': '2021-05-20T03:54:46.765193Z'}
{'type': 'l2update', 'product_id': 'BTC-USD', 'changes': [['buy', '38010.00', '0.29888104']], 'time': '2021-05-20T03:54:46.766146Z'}
{'type': 'l2update', 'product_id': 'BTC-USD', 'changes': [['sell', '38303.63', '0.02000000']], 'time': '2021-05-20T03:54:46.766309Z'}
{'type': 'l2update', 'product_id': 'BTC-USD', 'changes': [['sell', '38324.03', '0.00000000']], 'time': '2021-05-20T03:54:46.768862Z'}
{'type': 'l2update', 'product_id': 'BTC-USD', 'changes': [['buy', '38250.01', '0.05206770']], 'time': '2021-05-20T03:54:46.770054Z'}
{'type': 'l2update', 'product_id': 'BTC-USD', 'changes': [['sell', '38308.21', '0.00000000']], 'time': '2021-05-20T03:54:46.773641Z'}
{'type': 'l2update', 'product_id': 'BTC-USD', 'changes': [['sell', '38341.50', '0.38321368']], 'time': '2021-05-20T03:54:46.773698Z'}
{'type': 'l2update', 'product_id': 'BTC-USD', 'changes': [['sell', '38332.21', '0.38374672']], 'time': '2021-05-20T03:54:46.773698Z'}
{'type': 'l2update', 'product_id': 'BTC-USD', 'changes': [['sell', '38323.68', '0.32076250']], 'time': '2021-05-20T03:54:46.773698Z'}
{'type': 'l2update', 'product_id': 'BTC-USD', 'changes': [['sell', '38315.91', '0.33246963']], 'time': '2021-05-20T03:54:46.773698Z'}
{'type': 'l2update', 'product_id': 'BTC-USD', 'changes': [['sell', '38312.31', '0.53023504']], 'time': '2021-05-20T03:54:46.773698Z'}
{'type': 'l2update', 'product_id': 'BTC-USD', 'changes': [['sell', '38308.90', '0.29874039']], 'time': '2021-05-20T03:54:46.773698Z'}
{'type': 'l2update', 'product_id': 'BTC-USD', 'changes': [['sell', '38356.48', '0.01000000']], 'time': '2021-05-20T03:54:46.774685Z'}
{'type': 'l2update', 'product_id': 'BTC-USD', 'changes': [['buy', '38240.85', '0.02400000']], 'time': '2021-05-20T03:54:46.774784Z'}
{'type': 'l2update', 'product_id': 'BTC-USD', 'changes': [['buy', '38240.04', '0.02400000']], 'time': '2021-05-20T03:54:46.774784Z'}
{'type': 'l2update', 'product_id': 'BTC-USD', 'changes': [['buy', '38239.24', '0.02400000']], 'time': '2021-05-20T03:54:46.774784Z'}
{'type': 'l2update', 'product_id': 'BTC-USD', 'changes': [['buy', '38205.74', '0.02400000']], 'time': '2021-05-20T03:54:46.775063Z'}
{'type': 'l2update', 'product_id': 'BTC-USD', 'changes': [['sell', '38297.69', '0.00000000']], 'time': '2021-05-20T03:54:46.777160Z'}
{'type': 'l2update', 'product_id': 'BTC-USD', 'changes': [['sell', '38433.04', '0.01000000']], 'time': '2021-05-20T03:54:46.779837Z'}
{'type': 'l2update', 'product_id': 'BTC-USD', 'changes': [['buy', '38269.55', '0.06274942']], 'time': '2021-05-20T03:54:46.779967Z'}
{'type': 'l2update', 'product_id': 'BTC-USD', 'changes': [['sell', '38306.94', '0.48774822']], 'time': '2021-05-20T03:54:46.780127Z'}
{'type': 'l2update', 'product_id': 'BTC-USD', 'changes': [['buy', '38250.01', '0.00000000']], 'time': '2021-05-20T03:54:46.780623Z'}
{'type': 'l2update', 'product_id': 'BTC-USD', 'changes': [['buy', '38223.98', '0.00000000']], 'time': '2021-05-20T03:54:46.781281Z'}
{'type': 'l2update', 'product_id': 'BTC-USD', 'changes': [['sell', '38326.69', '0.68230703']], 'time': '2021-05-20T03:54:46.783921Z'}
{'type': 'l2update', 'product_id': 'BTC-USD', 'changes': [['sell', '38308.20', '0.05000000']], 'time': '2021-05-20T03:54:46.789462Z'}
{'type': 'l2update', 'product_id': 'BTC-USD', 'changes': [['sell', '49150.26', '0.02146900']], 'time': '2021-05-20T03:54:46.789713Z'}
{'type': 'l2update', 'product_id': 'BTC-USD', 'changes': [['sell', '38291.80', '0.00000000']], 'time': '2021-05-20T03:54:46.798245Z'}
{'type': 'l2update', 'product_id': 'BTC-USD', 'changes': [['sell', '38308.90', '0.62858312']], 'time': '2021-05-20T03:54:46.798775Z'}
{'type': 'l2update', 'product_id': 'BTC-USD', 'changes': [['sell', '38340.62', '2.16932808']], 'time': '2021-05-20T03:54:46.798844Z'}
{'type': 'l2update', 'product_id': 'BTC-USD', 'changes': [['buy', '38254.73', '0.22867204']], 'time': '2021-05-20T03:54:46.804035Z'}
{'type': 'l2update', 'product_id': 'BTC-USD', 'changes': [['sell', '38308.20', '0.00000000']], 'time': '2021-05-20T03:54:46.805139Z'}
{'type': 'l2update', 'product_id': 'BTC-USD', 'changes': [['sell', '38310.44', '0.00000000']], 'time': '2021-05-20T03:54:46.806445Z'}
{'type': 'l2update', 'product_id': 'BTC-USD', 'changes': [['buy', '38259.13', '0.84800000']], 'time': '2021-05-20T03:54:46.809771Z'}
{'type': 'l2update', 'product_id': 'BTC-USD', 'changes': [['buy', '38255.83', '0.48600000']], 'time': '2021-05-20T03:54:46.810048Z'}
{'type': 'l2update', 'product_id': 'BTC-USD', 'changes': [['sell', '38305.42', '0.21700000']], 'time': '2021-05-20T03:54:46.810181Z'}
{'type': 'l2update', 'product_id': 'BTC-USD', 'changes': [['buy', '38205.74', '0.00000000']], 'time': '2021-05-20T03:54:46.815407Z'}
{'type': 'l2update', 'product_id': 'BTC-USD', 'changes': [['buy', '38254.72', '0.00000000']], 'time': '2021-05-20T03:54:46.816898Z'}
{'type': 'l2update', 'product_id': 'BTC-USD', 'changes': [['sell', '38418.80', '0.00000000']], 'time': '2021-05-20T03:54:46.817141Z'}
{'type': 'l2update', 'product_id': 'BTC-USD', 'changes': [['sell', '38374.02', '0.00000000']], 'time': '2021-05-20T03:54:46.820235Z'}
{'type': 'l2update', 'product_id': 'BTC-USD', 'changes': [['buy', '38185.98', '0.00000000']], 'time': '2021-05-20T03:54:46.821915Z'}
{'type': 'l2update', 'product_id': 'BTC-USD', 'changes': [['sell', '38402.84', '0.00000000']], 'time': '2021-05-20T03:54:46.825051Z'}
{'type': 'l2update', 'product_id': 'BTC-USD', 'changes': [['sell', '38301.63', '0.00000000']], 'time': '2021-05-20T03:54:46.826218Z'}
{'type': 'l2update', 'product_id': 'BTC-USD', 'changes': [['sell', '38290.01', '0.00000000']], 'time': '2021-05-20T03:54:46.830085Z'}
{'type': 'l2update', 'product_id': 'BTC-USD', 'changes': [['sell', '38308.89', '0.05000000']], 'time': '2021-05-20T03:54:46.830616Z'}
{'type': 'l2update', 'product_id': 'BTC-USD', 'changes': [['sell', '38308.90', '1.01195881']], 'time': '2021-05-20T03:54:46.831671Z'}
{'type': 'l2update', 'product_id': 'BTC-USD', 'changes': [['sell', '38305.68', '0.16482467']], 'time': '2021-05-20T03:54:46.831671Z'}
{'type': 'l2update', 'product_id': 'BTC-USD', 'changes': [['sell', '38279.88', '1.53053000']], 'time': '2021-05-20T03:54:46.832254Z'}
{'type': 'l2update', 'product_id': 'BTC-USD', 'changes': [['sell', '38340.62', '0.00000000']], 'time': '2021-05-20T03:54:46.832526Z'}
{'type': 'l2update', 'product_id': 'BTC-USD', 'changes': [['buy', '38248.64', '0.44240000']], 'time': '2021-05-20T03:54:46.838449Z'}
{'type': 'l2update', 'product_id': 'BTC-USD', 'changes': [['sell', '38351.57', '0.07188809']], 'time': '2021-05-20T03:54:46.838496Z'}
{'type': 'l2update', 'product_id': 'BTC-USD', 'changes': [['buy', '38146.85', '0.07188809']], 'time': '2021-05-20T03:54:46.838496Z'}
{'type': 'l2update', 'product_id': 'BTC-USD', 'changes': [['buy', '38254.73', '0.28073974']], 'time': '2021-05-20T03:54:46.838575Z'}
{'type': 'l2update', 'product_id': 'BTC-USD', 'changes': [['buy', '38259.13', '0.00000000']], 'time': '2021-05-20T03:54:46.839727Z'}
{'type': 'l2update', 'product_id': 'BTC-USD', 'changes': [['buy', '38219.13', '0.00000000']], 'time': '2021-05-20T03:54:46.841961Z'}
{'type': 'l2update', 'product_id': 'BTC-USD', 'changes': [['sell', '38308.89', '0.00000000']], 'time': '2021-05-20T03:54:46.842507Z'}
{'type': 'l2update', 'product_id': 'BTC-USD', 'changes': [['sell', '38404.59', '0.01000000']], 'time': '2021-05-20T03:54:46.844866Z'}
{'type': 'l2update', 'product_id': 'BTC-USD', 'changes': [['sell', '38423.27', '0.00000000']], 'time': '2021-05-20T03:54:46.847305Z'}
{'type': 'l2update', 'product_id': 'BTC-USD', 'changes': [['sell', '38416.04', '0.00000000']], 'time': '2021-05-20T03:54:46.847305Z'}
{'type': 'l2update', 'product_id': 'BTC-USD', 'changes': [['sell', '38409.00', '0.00000000']], 'time': '2021-05-20T03:54:46.847305Z'}
{'type': 'l2update', 'product_id': 'BTC-USD', 'changes': [['sell', '38402.16', '0.00000000']], 'time': '2021-05-20T03:54:46.847305Z'}
{'type': 'l2update', 'product_id': 'BTC-USD', 'changes': [['sell', '38395.51', '0.00000000']], 'time': '2021-05-20T03:54:46.847305Z'}
{'type': 'l2update', 'product_id': 'BTC-USD', 'changes': [['sell', '38389.05', '0.00000000']], 'time': '2021-05-20T03:54:46.847305Z'}
{'type': 'l2update', 'product_id': 'BTC-USD', 'changes': [['sell', '38376.70', '0.00000000']], 'time': '2021-05-20T03:54:46.847305Z'}
{'type': 'l2update', 'product_id': 'BTC-USD', 'changes': [['sell', '38359.06', '0.00000000']], 'time': '2021-05-20T03:54:46.847305Z'}
{'type': 'l2update', 'product_id': 'BTC-USD', 'changes': [['buy', '38279.87', '0.00058059']], 'time': '2021-05-20T03:54:46.852463Z'}
{'type': 'l2update', 'product_id': 'BTC-USD', 'changes': [['buy', '38248.64', '0.00000000']], 'time': '2021-05-20T03:54:46.854610Z'}
{'type': 'l2update', 'product_id': 'BTC-USD', 'changes': [['buy', '38248.15', '0.00000000']], 'time': '2021-05-20T03:54:46.854649Z'}
{'type': 'l2update', 'product_id': 'BTC-USD', 'changes': [['sell', '38389.83', '0.13024283']], 'time': '2021-05-20T03:54:46.858360Z'}
{'type': 'l2update', 'product_id': 'BTC-USD', 'changes': [['sell', '38321.00', '0.00000000']], 'time': '2021-05-20T03:54:46.861974Z'}
{'type': 'l2update', 'product_id': 'BTC-USD', 'changes': [['sell', '38356.89', '0.02694681']], 'time': '2021-05-20T03:54:46.864089Z'}
{'type': 'l2update', 'product_id': 'BTC-USD', 'changes': [['buy', '38139.67', '0.02694681']], 'time': '2021-05-20T03:54:46.864089Z'}
{'type': 'l2update', 'product_id': 'BTC-USD', 'changes': [['sell', '38306.93', '0.05000000']], 'time': '2021-05-20T03:54:46.865120Z'}
{'type': 'l2update', 'product_id': 'BTC-USD', 'changes': [['buy', '38279.87', '0.07299526']], 'time': '2021-05-20T03:54:46.865438Z'}
{'type': 'l2update', 'product_id': 'BTC-USD', 'changes': [['sell', '38338.45', '0.00000000']], 'time': '2021-05-20T03:54:46.867684Z'}
{'type': 'l2update', 'product_id': 'BTC-USD', 'changes': [['sell', '38279.88', '1.57972062']], 'time': '2021-05-20T03:54:46.869346Z'}
{'type': 'l2update', 'product_id': 'BTC-USD', 'changes': [['sell', '38293.05', '0.04935866']], 'time': '2021-05-20T03:54:46.869721Z'}
{'type': 'l2update', 'product_id': 'BTC-USD', 'changes': [['buy', '38070.66', '0.05355389']], 'time': '2021-05-20T03:54:46.869763Z'}
{'type': 'l2update', 'product_id': 'BTC-USD', 'changes': [['buy', '38279.87', '0.07298526']], 'time': '2021-05-20T03:54:46.873178Z'}
{'type': 'l2update', 'product_id': 'BTC-USD', 'changes': [['buy', '38279.87', '0.07249526']], 'time': '2021-05-20T03:54:46.873178Z'}
{'type': 'l2update', 'product_id': 'BTC-USD', 'changes': [['buy', '38238.70', '0.00000000']], 'time': '2021-05-20T03:54:46.877670Z'}
{'type': 'l2update', 'product_id': 'BTC-USD', 'changes': [['sell', '38299.23', '0.05000000']], 'time': '2021-05-20T03:54:46.879437Z'}
{'type': 'l2update', 'product_id': 'BTC-USD', 'changes': [['sell', '38306.93', '0.00000000']], 'time': '2021-05-20T03:54:46.880776Z'}
{'type': 'l2update', 'product_id': 'BTC-USD', 'changes': [['buy', '38253.23', '0.00000000']], 'time': '2021-05-20T03:54:46.882940Z'}
{'type': 'l2update', 'product_id': 'BTC-USD', 'changes': [['buy', '38184.58', '0.50000000']], 'time': '2021-05-20T03:54:46.884603Z'}
{'type': 'l2update', 'product_id': 'BTC-USD', 'changes': [['buy', '38279.87', '0.07241467']], 'time': '2021-05-20T03:54:46.884668Z'}
{'type': 'l2update', 'product_id': 'BTC-USD', 'changes': [['buy', '38279.87', '0.07191468']], 'time': '2021-05-20T03:54:46.884668Z'}
{'type': 'l2update', 'product_id': 'BTC-USD', 'changes': [['sell', '38309.22', '0.48080000']], 'time': '2021-05-20T03:54:46.884700Z'}
{'type': 'l2update', 'product_id': 'BTC-USD', 'changes': [['buy', '38269.55', '0.00000000']], 'time': '2021-05-20T03:54:46.884985Z'}
{'type': 'l2update', 'product_id': 'BTC-USD', 'changes': [['sell', '38421.64', '0.00000000']], 'time': '2021-05-20T03:54:46.885505Z'}
{'type': 'l2update', 'product_id': 'BTC-USD', 'changes': [['sell', '38410.77', '0.00000000']], 'time': '2021-05-20T03:54:46.888255Z'}
{'type': 'l2update', 'product_id': 'BTC-USD', 'changes': [['sell', '38362.40', '0.02729036']], 'time': '2021-05-20T03:54:46.894006Z'}
{'type': 'l2update', 'product_id': 'BTC-USD', 'changes': [['sell', '38331.21', '0.00000000']], 'time': '2021-05-20T03:54:46.894348Z'}
{'type': 'l2update', 'product_id': 'BTC-USD', 'changes': [['sell', '38316.93', '0.02609812']], 'time': '2021-05-20T03:54:46.895082Z'}
{'type': 'l2update', 'product_id': 'BTC-USD', 'changes': [['sell', '38328.09', '0.00000000']], 'time': '2021-05-20T03:54:46.895648Z'}
{'type': 'l2update', 'product_id': 'BTC-USD', 'changes': [['sell', '38309.22', '0.00000000']], 'time': '2021-05-20T03:54:46.897083Z'}
{'type': 'l2update', 'product_id': 'BTC-USD', 'changes': [['buy', '38279.87', '0.00000000']], 'time': '2021-05-20T03:54:46.901472Z'}
{'type': 'l2update', 'product_id': 'BTC-USD', 'changes': [['sell', '38279.87', '0.00048532']], 'time': '2021-05-20T03:54:46.901472Z'}
{'type': 'l2update', 'product_id': 'BTC-USD', 'changes': [['buy', '38254.73', '0.05206770']], 'time': '2021-05-20T03:54:46.903359Z'}
{'type': 'l2update', 'product_id': 'BTC-USD', 'changes': [['buy', '38233.45', '0.05157949']], 'time': '2021-05-20T03:54:46.906114Z'}
{'type': 'l2update', 'product_id': 'BTC-USD', 'changes': [['sell', '38278.19', '0.11380000']], 'time': '2021-05-20T03:54:46.906482Z'}
{'type': 'l2update', 'product_id': 'BTC-USD', 'changes': [['sell', '38279.87', '0.00621532']], 'time': '2021-05-20T03:54:46.906500Z'}
{'type': 'l2update', 'product_id': 'BTC-USD', 'changes': [['sell', '38412.09', '0.00000000']], 'time': '2021-05-20T03:54:46.907453Z'}
{'type': 'l2update', 'product_id': 'BTC-USD', 'changes': [['sell', '38306.95', '0.00000000']], 'time': '2021-05-20T03:54:46.908160Z'}
{'type': 'l2update', 'product_id': 'BTC-USD', 'changes': [['sell', '38317.34', '0.01000000']], 'time': '2021-05-20T03:54:46.908619Z'}
{'type': 'l2update', 'product_id': 'BTC-USD', 'changes': [['sell', '38305.41', '0.05000000']], 'time': '2021-05-20T03:54:46.911767Z'}
{'type': 'l2update', 'product_id': 'BTC-USD', 'changes': [['sell', '38404.74', '0.01240630']], 'time': '2021-05-20T03:54:46.911857Z'}
{'type': 'l2update', 'product_id': 'BTC-USD', 'changes': [['sell', '38346.44', '0.31268568']], 'time': '2021-05-20T03:54:46.914681Z'}
{'type': 'l2update', 'product_id': 'BTC-USD', 'changes': [['sell', '38279.87', '0.00671532']], 'time': '2021-05-20T03:54:46.914715Z'}
{'type': 'l2update', 'product_id': 'BTC-USD', 'changes': [['buy', '38250.79', '0.58716278']], 'time': '2021-05-20T03:54:46.915436Z'}
{'type': 'l2update', 'product_id': 'BTC-USD', 'changes': [['sell', '38290.00', '0.00000000']], 'time': '2021-05-20T03:54:46.918998Z'}
{'type': 'l2update', 'product_id': 'BTC-USD', 'changes': [['sell', '38279.88', '1.54092062']], 'time': '2021-05-20T03:54:46.923172Z'}
{'type': 'l2update', 'product_id': 'BTC-USD', 'changes': [['sell', '38356.48', '0.00000000']], 'time': '2021-05-20T03:54:46.923238Z'}
{'type': 'l2update', 'product_id': 'BTC-USD', 'changes': [['sell', '38278.19', '0.12872000']], 'time': '2021-05-20T03:54:46.923894Z'}
{'type': 'l2update', 'product_id': 'BTC-USD', 'changes': [['sell', '38278.19', '0.20332000']], 'time': '2021-05-20T03:54:46.923933Z'}
{'type': 'l2update', 'product_id': 'BTC-USD', 'changes': [['buy', '38226.12', '0.00000000']], 'time': '2021-05-20T03:54:46.925804Z'}
{'type': 'l2update', 'product_id': 'BTC-USD', 'changes': [['sell', '38438.50', '0.01000000']], 'time': '2021-05-20T03:54:46.936038Z'}
{'type': 'l2update', 'product_id': 'BTC-USD', 'changes': [['sell', '38278.19', '0.21532000']], 'time': '2021-05-20T03:54:46.936257Z'}
{'type': 'l2update', 'product_id': 'BTC-USD', 'changes': [['sell', '38278.19', '0.26629201']], 'time': '2021-05-20T03:54:46.936276Z'}
{'type': 'l2update', 'product_id': 'BTC-USD', 'changes': [['sell', '38278.19', '0.27202201']], 'time': '2021-05-20T03:54:46.936611Z'}
{'type': 'l2update', 'product_id': 'BTC-USD', 'changes': [['sell', '38368.10', '0.02733122']], 'time': '2021-05-20T03:54:46.936658Z'}
{'type': 'l2update', 'product_id': 'BTC-USD', 'changes': [['sell', '38278.19', '0.37202201']], 'time': '2021-05-20T03:54:46.936954Z'}
{'type': 'l2update', 'product_id': 'BTC-USD', 'changes': [['sell', '38278.19', '0.39792201']], 'time': '2021-05-20T03:54:46.937193Z'}
{'type': 'l2update', 'product_id': 'BTC-USD', 'changes': [['sell', '38356.89', '0.45776631']], 'time': '2021-05-20T03:54:46.942546Z'}
{'type': 'l2update', 'product_id': 'BTC-USD', 'changes': [['buy', '38236.28', '0.04938585']], 'time': '2021-05-20T03:54:46.943289Z'}
{'type': 'l2update', 'product_id': 'BTC-USD', 'changes': [['sell', '38289.08', '0.05422317']], 'time': '2021-05-20T03:54:46.943289Z'}
{'type': 'l2update', 'product_id': 'BTC-USD', 'changes': [['buy', '38254.74', '0.05206770']], 'time': '2021-05-20T03:54:46.943323Z'}
{'type': 'l2update', 'product_id': 'BTC-USD', 'changes': [['buy', '38239.27', '0.22867204']], 'time': '2021-05-20T03:54:46.943843Z'}
{'type': 'l2update', 'product_id': 'BTC-USD', 'changes': [['sell', '38279.87', '0.07761532']], 'time': '2021-05-20T03:54:46.943863Z'}
{'type': 'l2update', 'product_id': 'BTC-USD', 'changes': [['buy', '38240.85', '0.00000000']], 'time': '2021-05-20T03:54:46.944731Z'}
{'type': 'l2update', 'product_id': 'BTC-USD', 'changes': [['sell', '38279.88', '1.53519062']], 'time': '2021-05-20T03:54:46.948676Z'}
{'type': 'l2update', 'product_id': 'BTC-USD', 'changes': [['buy', '38240.90', '0.84800000']], 'time': '2021-05-20T03:54:46.956503Z'}
{'type': 'l2update', 'product_id': 'BTC-USD', 'changes': [['buy', '38212.65', '0.12270886']], 'time': '2021-05-20T03:54:46.956627Z'}
{'type': 'l2update', 'product_id': 'BTC-USD', 'changes': [['sell', '38399.56', '0.01000000']], 'time': '2021-05-20T03:54:46.956733Z'}
{'type': 'l2update', 'product_id': 'BTC-USD', 'changes': [['buy', '38278.18', '0.00000000']], 'time': '2021-05-20T03:54:46.956841Z'}
{'type': 'l2update', 'product_id': 'BTC-USD', 'changes': [['sell', '38278.19', '0.59792201']], 'time': '2021-05-20T03:54:46.956936Z'}
{'type': 'l2update', 'product_id': 'BTC-USD', 'changes': [['sell', '38279.86', '0.36249352']], 'time': '2021-05-20T03:54:46.956972Z'}
{'type': 'l2update', 'product_id': 'BTC-USD', 'changes': [['buy', '38254.73', '0.00000000']], 'time': '2021-05-20T03:54:46.957228Z'}
{'type': 'l2update', 'product_id': 'BTC-USD', 'changes': [['sell', '38279.87', '0.07188532']], 'time': '2021-05-20T03:54:46.961512Z'}
{'type': 'l2update', 'product_id': 'BTC-USD', 'changes': [['sell', '38420.19', '0.00000000']], 'time': '2021-05-20T03:54:46.964979Z'}
{'type': 'l2update', 'product_id': 'BTC-USD', 'changes': [['sell', '38326.69', '0.00000000']], 'time': '2021-05-20T03:54:46.965852Z'}
{'type': 'l2update', 'product_id': 'BTC-USD', 'changes': [['sell', '38380.07', '0.03411533']], 'time': '2021-05-20T03:54:46.966413Z'}
{'type': 'l2update', 'product_id': 'BTC-USD', 'changes': [['sell', '49304.80', '0.00248100']], 'time': '2021-05-20T03:54:46.966473Z'}
{'type': 'l2update', 'product_id': 'BTC-USD', 'changes': [['sell', '38366.40', '0.36832139']], 'time': '2021-05-20T03:54:46.966950Z'}
{'type': 'l2update', 'product_id': 'BTC-USD', 'changes': [['sell', '38309.20', '0.10000000']], 'time': '2021-05-20T03:54:46.967420Z'}
{'type': 'l2update', 'product_id': 'BTC-USD', 'changes': [['sell', '38326.70', '0.00000000']], 'time': '2021-05-20T03:54:46.968199Z'}
{'type': 'l2update', 'product_id': 'BTC-USD', 'changes': [['buy', '38238.17', '0.02400000']], 'time': '2021-05-20T03:54:46.971933Z'}
{'type': 'l2update', 'product_id': 'BTC-USD', 'changes': [['buy', '38184.58', '0.00000000']], 'time': '2021-05-20T03:54:46.972466Z'}
{'type': 'l2update', 'product_id': 'BTC-USD', 'changes': [['sell', '38279.88', '1.33519062']], 'time': '2021-05-20T03:54:46.973541Z'}
{'type': 'l2update', 'product_id': 'BTC-USD', 'changes': [['sell', '38278.19', '0.58300201']], 'time': '2021-05-20T03:54:46.974091Z'}
{'type': 'l2update', 'product_id': 'BTC-USD', 'changes': [['sell', '38278.19', '0.50840201']], 'time': '2021-05-20T03:54:46.974139Z'}
{'type': 'l2update', 'product_id': 'BTC-USD', 'changes': [['sell', '38305.41', '0.00000000']], 'time': '2021-05-20T03:54:46.975759Z'}
{'type': 'l2update', 'product_id': 'BTC-USD', 'changes': [['sell', '38378.74', '0.01811971']], 'time': '2021-05-20T03:54:46.979483Z'}
{'type': 'l2update', 'product_id': 'BTC-USD', 'changes': [['sell', '38438.50', '0.00000000']], 'time': '2021-05-20T03:54:46.979974Z'}
{'type': 'l2update', 'product_id': 'BTC-USD', 'changes': [['sell', '38279.88', '1.28600000']], 'time': '2021-05-20T03:54:46.980210Z'}
{'type': 'l2update', 'product_id': 'BTC-USD', 'changes': [['sell', '38278.18', '0.00573000']], 'time': '2021-05-20T03:54:46.983439Z'}
{'type': 'l2update', 'product_id': 'BTC-USD', 'changes': [['sell', '38407.43', '0.01000000']], 'time': '2021-05-20T03:54:46.986608Z'}
{'type': 'l2update', 'product_id': 'BTC-USD', 'changes': [['sell', '38378.37', '0.03627905']], 'time': '2021-05-20T03:54:46.987039Z'}
{'type': 'l2update', 'product_id': 'BTC-USD', 'changes': [['buy', '38263.84', '0.04565774']], 'time': '2021-05-20T03:54:46.987077Z'}
{'type': 'l2update', 'product_id': 'BTC-USD', 'changes': [['buy', '38239.26', '0.00000000']], 'time': '2021-05-20T03:54:46.994397Z'}
{'type': 'l2update', 'product_id': 'BTC-USD', 'changes': [['sell', '38277.78', '0.07460000']], 'time': '2021-05-20T03:54:46.999571Z'}
{'type': 'l2update', 'product_id': 'BTC-USD', 'changes': [['sell', '38270.04', '0.01492000']], 'time': '2021-05-20T03:54:46.999599Z'}
{'type': 'l2update', 'product_id': 'BTC-USD', 'changes': [['sell', '38297.02', '0.05000000']], 'time': '2021-05-20T03:54:46.999975Z'}
{'type': 'l2update', 'product_id': 'BTC-USD', 'changes': [['sell', '38279.87', '0.17188532']], 'time': '2021-05-20T03:54:47.000018Z'}
{'type': 'l2update', 'product_id': 'BTC-USD', 'changes': [['sell', '38372.29', '0.33513961']], 'time': '2021-05-20T03:54:47.000293Z'}
{'type': 'l2update', 'product_id': 'BTC-USD', 'changes': [['sell', '38278.19', '0.50267201']], 'time': '2021-05-20T03:54:47.002754Z'}
{'type': 'l2update', 'product_id': 'BTC-USD', 'changes': [['sell', '38453.91', '0.01000000']], 'time': '2021-05-20T03:54:47.005610Z'}
{'type': 'l2update', 'product_id': 'BTC-USD', 'changes': [['sell', '38291.49', '0.00000000']], 'time': '2021-05-20T03:54:47.007081Z'}
{'type': 'l2update', 'product_id': 'BTC-USD', 'changes': [['sell', '38438.66', '0.00000000']], 'time': '2021-05-20T03:54:47.009662Z'}
{'type': 'l2update', 'product_id': 'BTC-USD', 'changes': [['buy', '38232.11', '1.20000000']], 'time': '2021-05-20T03:54:47.010710Z'}
{'type': 'l2update', 'product_id': 'BTC-USD', 'changes': [['buy', '38201.44', '0.00000000']], 'time': '2021-05-20T03:54:47.011404Z'}
{'type': 'l2update', 'product_id': 'BTC-USD', 'changes': [['sell', '38277.78', '0.00000000']], 'time': '2021-05-20T03:54:47.013834Z'}
{'type': 'l2update', 'product_id': 'BTC-USD', 'changes': [['sell', '38270.04', '0.00000000']], 'time': '2021-05-20T03:54:47.014038Z'}
{'type': 'l2update', 'product_id': 'BTC-USD', 'changes': [['sell', '38278.19', '0.38887201']], 'time': '2021-05-20T03:54:47.014768Z'}
{'type': 'l2update', 'product_id': 'BTC-USD', 'changes': [['sell', '38278.19', '0.36297201']], 'time': '2021-05-20T03:54:47.015254Z'}
{'type': 'l2update', 'product_id': 'BTC-USD', 'changes': [['sell', '38279.88', '1.18600000']], 'time': '2021-05-20T03:54:47.016192Z'}
{'type': 'l2update', 'product_id': 'BTC-USD', 'changes': [['sell', '38278.18', '0.00000000']], 'time': '2021-05-20T03:54:47.018655Z'}
{'type': 'l2update', 'product_id': 'BTC-USD', 'changes': [['buy', '38239.27', '0.00000000']], 'time': '2021-05-20T03:54:47.022242Z'}
{'type': 'l2update', 'product_id': 'BTC-USD', 'changes': [['sell', '38270.04', '0.02590000']], 'time': '2021-05-20T03:54:47.022272Z'}
{'type': 'l2update', 'product_id': 'BTC-USD', 'changes': [['buy', '38237.83', '0.00000000']], 'time': '2021-05-20T03:54:47.022555Z'}
{'type': 'l2update', 'product_id': 'BTC-USD', 'changes': [['sell', '38317.34', '0.00000000']], 'time': '2021-05-20T03:54:47.025153Z'}
{'type': 'l2update', 'product_id': 'BTC-USD', 'changes': [['sell', '38279.86', '0.00000000']], 'time': '2021-05-20T03:54:47.026182Z'}
{'type': 'l2update', 'product_id': 'BTC-USD', 'changes': [['sell', '38376.45', '0.37977419']], 'time': '2021-05-20T03:54:47.026781Z'}
{'type': 'l2update', 'product_id': 'BTC-USD', 'changes': [['sell', '38406.08', '0.00000000']], 'time': '2021-05-20T03:54:47.027849Z'}
{'type': 'l2update', 'product_id': 'BTC-USD', 'changes': [['sell', '38407.43', '0.00000000']], 'time': '2021-05-20T03:54:47.034486Z'}
{'type': 'l2update', 'product_id': 'BTC-USD', 'changes': [['buy', '38191.05', '0.00000000']], 'time': '2021-05-20T03:54:47.039248Z'}
{'type': 'l2update', 'product_id': 'BTC-USD', 'changes': [['buy', '38263.84', '0.00000000']], 'time': '2021-05-20T03:54:47.040340Z'}
{'type': 'l2update', 'product_id': 'BTC-USD', 'changes': [['buy', '38255.84', '0.05206770']], 'time': '2021-05-20T03:54:47.046405Z'}
{'type': 'l2update', 'product_id': 'BTC-USD', 'changes': [['sell', '38270.08', '0.15000000']], 'time': '2021-05-20T03:54:47.046655Z'}
{'type': 'l2update', 'product_id': 'BTC-USD', 'changes': [['sell', '38277.87', '0.07460000']], 'time': '2021-05-20T03:54:47.047840Z'}
{'type': 'l2update', 'product_id': 'BTC-USD', 'changes': [['sell', '38270.04', '0.04082000']], 'time': '2021-05-20T03:54:47.047862Z'}
{'type': 'l2update', 'product_id': 'BTC-USD', 'changes': [['sell', '38278.18', '0.20000000']], 'time': '2021-05-20T03:54:47.047943Z'}
{'type': 'l2update', 'product_id': 'BTC-USD', 'changes': [['sell', '38366.94', '1.20000000']], 'time': '2021-05-20T03:54:47.047962Z'}
{'type': 'l2update', 'product_id': 'BTC-USD', 'changes': [['sell', '38395.23', '0.01000000']], 'time': '2021-05-20T03:54:47.057253Z'}
{'type': 'l2update', 'product_id': 'BTC-USD', 'changes': [['sell', '38421.77', '0.01259168']], 'time': '2021-05-20T03:54:47.057376Z'}
{'type': 'l2update', 'product_id': 'BTC-USD', 'changes': [['sell', '38270.04', '0.02590000']], 'time': '2021-05-20T03:54:47.057862Z'}
{'type': 'l2update', 'product_id': 'BTC-USD', 'changes': [['sell', '38277.87', '0.00000000']], 'time': '2021-05-20T03:54:47.058904Z'}
{'type': 'l2update', 'product_id': 'BTC-USD', 'changes': [['buy', '38255.83', '0.00000000']], 'time': '2021-05-20T03:54:47.059224Z'}
{'type': 'l2update', 'product_id': 'BTC-USD', 'changes': [['sell', '38278.19', '0.26297201']], 'time': '2021-05-20T03:54:47.059592Z'}
{'type': 'l2update', 'product_id': 'BTC-USD', 'changes': [['buy', '38232.11', '0.00000000']], 'time': '2021-05-20T03:54:47.059612Z'}
{'type': 'l2update', 'product_id': 'BTC-USD', 'changes': [['buy', '38236.76', '0.00000000']], 'time': '2021-05-20T03:54:47.060553Z'}
{'type': 'l2update', 'product_id': 'BTC-USD', 'changes': [['buy', '38250.79', '0.00000000']], 'time': '2021-05-20T03:54:47.061099Z'}
{'type': 'l2update', 'product_id': 'BTC-USD', 'changes': [['buy', '38240.51', '0.00000000']], 'time': '2021-05-20T03:54:47.061700Z'}
{'type': 'l2update', 'product_id': 'BTC-USD', 'changes': [['buy', '38240.90', '0.00000000']], 'time': '2021-05-20T03:54:47.062385Z'}
{'type': 'l2update', 'product_id': 'BTC-USD', 'changes': [['sell', '38278.18', '0.56249352']], 'time': '2021-05-20T03:54:47.063945Z'}
{'type': 'l2update', 'product_id': 'BTC-USD', 'changes': [['buy', '38255.84', '0.28073974']], 'time': '2021-05-20T03:54:47.065046Z'}
{'type': 'l2update', 'product_id': 'BTC-USD', 'changes': [['sell', '38382.91', '0.32940900']], 'time': '2021-05-20T03:54:47.065219Z'}
{'type': 'l2update', 'product_id': 'BTC-USD', 'changes': [['sell', '38279.88', '1.15000000']], 'time': '2021-05-20T03:54:47.067440Z'}
{'type': 'l2update', 'product_id': 'BTC-USD', 'changes': [['sell', '38277.82', '1.30000000']], 'time': '2021-05-20T03:54:47.071070Z'}
{'type': 'l2update', 'product_id': 'BTC-USD', 'changes': [['sell', '38366.94', '0.00000000']], 'time': '2021-05-20T03:54:47.072240Z'}
{'type': 'l2update', 'product_id': 'BTC-USD', 'changes': [['sell', '38270.04', '0.06190000']], 'time': '2021-05-20T03:54:47.072437Z'}
{'type': 'l2update', 'product_id': 'BTC-USD', 'changes': [['buy', '38254.74', '0.00000000']], 'time': '2021-05-20T03:54:47.072888Z'}
{'type': 'l2update', 'product_id': 'BTC-USD', 'changes': [['sell', '38278.19', '0.06297201']], 'time': '2021-05-20T03:54:47.073310Z'}
{'type': 'l2update', 'product_id': 'BTC-USD', 'changes': [['sell', '38340.86', '0.00000000']], 'time': '2021-05-20T03:54:47.075437Z'}
{'type': 'l2update', 'product_id': 'BTC-USD', 'changes': [['buy', '38093.15', '0.00000000']], 'time': '2021-05-20T03:54:47.075861Z'}
{'type': 'l2update', 'product_id': 'BTC-USD', 'changes': [['buy', '38240.52', '0.00000000']], 'time': '2021-05-20T03:54:47.076864Z'}
{'type': 'l2update', 'product_id': 'BTC-USD', 'changes': [['sell', '38320.96', '0.69055060']], 'time': '2021-05-20T03:54:47.077381Z'}
{'type': 'l2update', 'product_id': 'BTC-USD', 'changes': [['sell', '38316.94', '0.00000000']], 'time': '2021-05-20T03:54:47.079656Z'}
{'type': 'l2update', 'product_id': 'BTC-USD', 'changes': [['sell', '38374.68', '0.01302942']], 'time': '2021-05-20T03:54:47.082522Z'}
{'type': 'l2update', 'product_id': 'BTC-USD', 'changes': [['sell', '38270.08', '0.00000000']], 'time': '2021-05-20T03:54:47.083639Z'}
{'type': 'l2update', 'product_id': 'BTC-USD', 'changes': [['sell', '38287.84', '0.05190453']], 'time': '2021-05-20T03:54:47.083661Z'}
{'type': 'l2update', 'product_id': 'BTC-USD', 'changes': [['sell', '38583.45', '0.00000000']], 'time': '2021-05-20T03:54:47.085542Z'}
{'type': 'l2update', 'product_id': 'BTC-USD', 'changes': [['sell', '38396.40', '0.30127768']], 'time': '2021-05-20T03:54:47.091183Z'}
{'type': 'l2update', 'product_id': 'BTC-USD', 'changes': [['sell', '38270.04', '0.06763000']], 'time': '2021-05-20T03:54:47.091433Z'}
{'type': 'l2update', 'product_id': 'BTC-USD', 'changes': [['buy', '38236.28', '0.00000000']], 'time': '2021-05-20T03:54:47.092713Z'}
{'type': 'l2update', 'product_id': 'BTC-USD', 'changes': [['sell', '38289.08', '0.00000000']], 'time': '2021-05-20T03:54:47.092713Z'}
{'type': 'l2update', 'product_id': 'BTC-USD', 'changes': [['sell', '38270.04', '0.16763000']], 'time': '2021-05-20T03:54:47.095653Z'}
{'type': 'l2update', 'product_id': 'BTC-USD', 'changes': [['buy', '38259.12', '0.00000000']], 'time': '2021-05-20T03:54:47.096580Z'}
{'type': 'l2update', 'product_id': 'BTC-USD', 'changes': [['sell', '38297.04', '0.00000000']], 'time': '2021-05-20T03:54:47.099969Z'}
{'type': 'l2update', 'product_id': 'BTC-USD', 'changes': [['sell', '38282.19', '0.00600000']], 'time': '2021-05-20T03:54:47.102138Z'}
{'type': 'l2update', 'product_id': 'BTC-USD', 'changes': [['buy', '38240.05', '0.58716278']], 'time': '2021-05-20T03:54:47.105130Z'}
{'type': 'l2update', 'product_id': 'BTC-USD', 'changes': [['buy', '38259.50', '0.01043054']], 'time': '2021-05-20T03:54:47.106189Z'}
{'type': 'l2update', 'product_id': 'BTC-USD', 'changes': [['sell', '38553.46', '0.01296900']], 'time': '2021-05-20T03:54:47.112783Z'}
{'type': 'l2update', 'product_id': 'BTC-USD', 'changes': [['buy', '38178.56', '0.00000000']], 'time': '2021-05-20T03:54:47.115352Z'}
{'type': 'l2update', 'product_id': 'BTC-USD', 'changes': [['sell', '38300.66', '0.61200000']], 'time': '2021-05-20T03:54:47.116867Z'}
{'type': 'l2update', 'product_id': 'BTC-USD', 'changes': [['sell', '38290.05', '0.00000000']], 'time': '2021-05-20T03:54:47.117100Z'}
{'type': 'l2update', 'product_id': 'BTC-USD', 'changes': [['sell', '38270.04', '0.36763000']], 'time': '2021-05-20T03:54:47.117454Z'}
{'type': 'l2update', 'product_id': 'BTC-USD', 'changes': [['buy', '38260.62', '0.04565774']], 'time': '2021-05-20T03:54:47.118631Z'}
{'type': 'l2update', 'product_id': 'BTC-USD', 'changes': [['sell', '38270.04', '0.37742072']], 'time': '2021-05-20T03:54:47.118924Z'}
{'type': 'l2update', 'product_id': 'BTC-USD', 'changes': [['buy', '38240.04', '0.00000000']], 'time': '2021-05-20T03:54:47.119107Z'}
{'type': 'l2update', 'product_id': 'BTC-USD', 'changes': [['buy', '38239.24', '0.00000000']], 'time': '2021-05-20T03:54:47.119107Z'}
{'type': 'l2update', 'product_id': 'BTC-USD', 'changes': [['sell', '38421.77', '0.00000000']], 'time': '2021-05-20T03:54:47.119479Z'}
{'type': 'l2update', 'product_id': 'BTC-USD', 'changes': [['sell', '38411.38', '0.00000000']], 'time': '2021-05-20T03:54:47.119643Z'}
{'type': 'l2update', 'product_id': 'BTC-USD', 'changes': [['sell', '38299.04', '0.11949616']], 'time': '2021-05-20T03:54:47.123668Z'}
{'type': 'l2update', 'product_id': 'BTC-USD', 'changes': [['buy', '38124.76', '0.70461769']], 'time': '2021-05-20T03:54:47.123668Z'}
{'type': 'l2update', 'product_id': 'BTC-USD', 'changes': [['sell', '38278.18', '0.20000000']], 'time': '2021-05-20T03:54:47.129649Z'}
{'type': 'l2update', 'product_id': 'BTC-USD', 'changes': [['buy', '38255.84', '0.05206770']], 'time': '2021-05-20T03:54:47.131087Z'}
{'type': 'l2update', 'product_id': 'BTC-USD', 'changes': [['sell', '38300.66', '0.00000000']], 'time': '2021-05-20T03:54:47.131918Z'}
{'type': 'l2update', 'product_id': 'BTC-USD', 'changes': [['buy', '38170.33', '0.00000000']], 'time': '2021-05-20T03:54:47.132726Z'}
{'type': 'l2update', 'product_id': 'BTC-USD', 'changes': [['sell', '38279.87', '0.07188532']], 'time': '2021-05-20T03:54:47.133693Z'}
{'type': 'l2update', 'product_id': 'BTC-USD', 'changes': [['sell', '38399.56', '0.00000000']], 'time': '2021-05-20T03:54:47.134725Z'}
{'type': 'l2update', 'product_id': 'BTC-USD', 'changes': [['buy', '38255.84', '0.00000000']], 'time': '2021-05-20T03:54:47.136119Z'}
{'type': 'l2update', 'product_id': 'BTC-USD', 'changes': [['buy', '38238.17', '0.00000000']], 'time': '2021-05-20T03:54:47.136175Z'}
{'type': 'l2update', 'product_id': 'BTC-USD', 'changes': [['sell', '38308.90', '0.68211608']], 'time': '2021-05-20T03:54:47.141525Z'}
{'type': 'l2update', 'product_id': 'BTC-USD', 'changes': [['sell', '38308.90', '0.38337569']], 'time': '2021-05-20T03:54:47.141525Z'}
{'type': 'l2update', 'product_id': 'BTC-USD', 'changes': [['buy', '38197.09', '0.03533740']], 'time': '2021-05-20T03:54:47.141525Z'}
{'type': 'l2update', 'product_id': 'BTC-USD', 'changes': [['sell', '38392.87', '0.01000000']], 'time': '2021-05-20T03:54:47.145782Z'}
{'type': 'l2update', 'product_id': 'BTC-USD', 'changes': [['sell', '49308.33', '0.00239500']], 'time': '2021-05-20T03:54:47.146153Z'}
{'type': 'l2update', 'product_id': 'BTC-USD', 'changes': [['sell', '38408.33', '0.01192532']], 'time': '2021-05-20T03:54:47.146274Z'}
{'type': 'l2update', 'product_id': 'BTC-USD', 'changes': [['sell', '38299.89', '0.39490432']], 'time': '2021-05-20T03:54:47.146307Z'}
{'type': 'l2update', 'product_id': 'BTC-USD', 'changes': [['sell', '38299.04', '0.13502746']], 'time': '2021-05-20T03:54:47.146832Z'}
{'type': 'l2update', 'product_id': 'BTC-USD', 'changes': [['sell', '38433.04', '0.00000000']], 'time': '2021-05-20T03:54:47.148609Z'}
{'type': 'l2update', 'product_id': 'BTC-USD', 'changes': [['sell', '38291.62', '0.05000000']], 'time': '2021-05-20T03:54:47.152565Z'}
{'type': 'l2update', 'product_id': 'BTC-USD', 'changes': [['buy', '38180.66', '0.00000000']], 'time': '2021-05-20T03:54:47.153417Z'}
{'type': 'l2update', 'product_id': 'BTC-USD', 'changes': [['sell', '38391.64', '0.00000000']], 'time': '2021-05-20T03:54:47.153736Z'}
{'type': 'l2update', 'product_id': 'BTC-USD', 'changes': [['buy', '38144.58', '0.01000000']], 'time': '2021-05-20T03:54:47.157744Z'}
{'type': 'l2update', 'product_id': 'BTC-USD', 'changes': [['buy', '38176.55', '2.55020000']], 'time': '2021-05-20T03:54:47.157762Z'}
{'type': 'l2update', 'product_id': 'BTC-USD', 'changes': [['sell', '38341.50', '0.35111213']], 'time': '2021-05-20T03:54:47.160274Z'}
{'type': 'l2update', 'product_id': 'BTC-USD', 'changes': [['sell', '38336.76', '0.00000000']], 'time': '2021-05-20T03:54:47.160274Z'}
{'type': 'l2update', 'product_id': 'BTC-USD', 'changes': [['sell', '38327.85', '0.00000000']], 'time': '2021-05-20T03:54:47.160274Z'}
{'type': 'l2update', 'product_id': 'BTC-USD', 'changes': [['sell', '38319.70', '0.00000000']], 'time': '2021-05-20T03:54:47.160274Z'}
{'type': 'l2update', 'product_id': 'BTC-USD', 'changes': [['sell', '38312.31', '0.51612601']], 'time': '2021-05-20T03:54:47.160274Z'}
{'type': 'l2update', 'product_id': 'BTC-USD', 'changes': [['sell', '38312.31', '0.47729777']], 'time': '2021-05-20T03:54:47.160274Z'}
{'type': 'l2update', 'product_id': 'BTC-USD', 'changes': [['sell', '38386.86', '0.03054428']], 'time': '2021-05-20T03:54:47.163157Z'}
{'type': 'l2update', 'product_id': 'BTC-USD', 'changes': [['buy', '38228.39', '0.02400000']], 'time': '2021-05-20T03:54:47.163239Z'}
{'type': 'l2update', 'product_id': 'BTC-USD', 'changes': [['buy', '38227.58', '0.02400000']], 'time': '2021-05-20T03:54:47.163239Z'}
{'type': 'l2update', 'product_id': 'BTC-USD', 'changes': [['buy', '38226.78', '0.02400000']], 'time': '2021-05-20T03:54:47.163239Z'}
{'type': 'l2update', 'product_id': 'BTC-USD', 'changes': [['sell', '38278.18', '0.00000000']], 'time': '2021-05-20T03:54:47.164263Z'}
{'type': 'l2update', 'product_id': 'BTC-USD', 'changes': [['sell', '38279.88', '0.65000000']], 'time': '2021-05-20T03:54:47.166676Z'}
{'type': 'l2update', 'product_id': 'BTC-USD', 'changes': [['buy', '38230.86', '0.22867204']], 'time': '2021-05-20T03:54:47.170292Z'}
{'type': 'l2update', 'product_id': 'BTC-USD', 'changes': [['buy', '38240.05', '0.00000000']], 'time': '2021-05-20T03:54:47.171860Z'}
{'type': 'l2update', 'product_id': 'BTC-USD', 'changes': [['sell', '38301.60', '0.10000000']], 'time': '2021-05-20T03:54:47.180338Z'}
{'type': 'l2update', 'product_id': 'BTC-USD', 'changes': [['sell', '38277.47', '0.04958462']], 'time': '2021-05-20T03:54:47.180807Z'}
{'type': 'l2update', 'product_id': 'BTC-USD', 'changes': [['buy', '38168.43', '0.01000000']], 'time': '2021-05-20T03:54:47.180905Z'}
{'type': 'l2update', 'product_id': 'BTC-USD', 'changes': [['sell', '38378.28', '0.11559600']], 'time': '2021-05-20T03:54:47.180926Z'}
{'type': 'l2update', 'product_id': 'BTC-USD', 'changes': [['sell', '38299.04', '0.46968915']], 'time': '2021-05-20T03:54:47.180958Z'}
{'type': 'l2update', 'product_id': 'BTC-USD', 'changes': [['sell', '38295.82', '0.38337569']], 'time': '2021-05-20T03:54:47.180958Z'}
{'type': 'l2update', 'product_id': 'BTC-USD', 'changes': [['sell', '38292.79', '0.16482467']], 'time': '2021-05-20T03:54:47.180958Z'}
{'type': 'l2update', 'product_id': 'BTC-USD', 'changes': [['sell', '38293.05', '0.00000000']], 'time': '2021-05-20T03:54:47.181014Z'}
{'type': 'l2update', 'product_id': 'BTC-USD', 'changes': [['sell', '38277.81', '0.36249352']], 'time': '2021-05-20T03:54:47.181110Z'}
{'type': 'l2update', 'product_id': 'BTC-USD', 'changes': [['buy', '38218.14', '0.19100000']], 'time': '2021-05-20T03:54:47.181217Z'}
{'type': 'l2update', 'product_id': 'BTC-USD', 'changes': [['sell', '38307.91', '0.03207306']], 'time': '2021-05-20T03:54:47.181320Z'}
{'type': 'l2update', 'product_id': 'BTC-USD', 'changes': [['sell', '38417.97', '0.01000000']], 'time': '2021-05-20T03:54:47.181910Z'}
{'type': 'l2update', 'product_id': 'BTC-USD', 'changes': [['buy', '38228.39', '0.00000000']], 'time': '2021-05-20T03:54:47.182038Z'}
{'type': 'l2update', 'product_id': 'BTC-USD', 'changes': [['buy', '38230.74', '0.00000000']], 'time': '2021-05-20T03:54:47.198431Z'}
{'type': 'l2update', 'product_id': 'BTC-USD', 'changes': [['sell', '38299.23', '0.00000000']], 'time': '2021-05-20T03:54:47.198618Z'}
{'type': 'l2update', 'product_id': 'BTC-USD', 'changes': [['sell', '38312.31', '0.14263608']], 'time': '2021-05-20T03:54:47.198691Z'}
{'type': 'l2update', 'product_id': 'BTC-USD', 'changes': [['sell', '38308.90', '0.00000000']], 'time': '2021-05-20T03:54:47.198691Z'}
{'type': 'l2update', 'product_id': 'BTC-USD', 'changes': [['sell', '38305.68', '0.00000000']], 'time': '2021-05-20T03:54:47.198691Z'}
{'type': 'l2update', 'product_id': 'BTC-USD', 'changes': [['buy', '38184.80', '0.00000000']], 'time': '2021-05-20T03:54:47.198691Z'}
{'type': 'l2update', 'product_id': 'BTC-USD', 'changes': [['sell', '38270.04', '0.87742072']], 'time': '2021-05-20T03:54:47.202676Z'}
{'type': 'l2update', 'product_id': 'BTC-USD', 'changes': [['sell', '38270.04', '3.36711980']], 'time': '2021-05-20T03:54:47.203213Z'}
{'type': 'l2update', 'product_id': 'BTC-USD', 'changes': [['sell', '38422.31', '0.00000000']], 'time': '2021-05-20T03:54:47.203438Z'}
{'type': 'l2update', 'product_id': 'BTC-USD', 'changes': [['sell', '38297.02', '0.00000000']], 'time': '2021-05-20T03:54:47.203576Z'}
{'type': 'l2update', 'product_id': 'BTC-USD', 'changes': [['sell', '38633.31', '0.00000000']], 'time': '2021-05-20T03:54:47.206678Z'}
{'type': 'l2update', 'product_id': 'BTC-USD', 'changes': [['sell', '38423.01', '0.00000000']], 'time': '2021-05-20T03:54:47.206678Z'}
{'type': 'l2update', 'product_id': 'BTC-USD', 'changes': [['sell', '38328.50', '0.00000000']], 'time': '2021-05-20T03:54:47.206678Z'}
{'type': 'l2update', 'product_id': 'BTC-USD', 'changes': [['buy', '38239.30', '0.84900000']], 'time': '2021-05-20T03:54:47.213112Z'}
{'type': 'l2update', 'product_id': 'BTC-USD', 'changes': [['sell', '38380.07', '0.00000000']], 'time': '2021-05-20T03:54:47.214673Z'}
{'type': 'l2update', 'product_id': 'BTC-USD', 'changes': [['sell', '38378.37', '0.00000000']], 'time': '2021-05-20T03:54:47.214673Z'}
{'type': 'l2update', 'product_id': 'BTC-USD', 'changes': [['sell', '38368.10', '0.00000000']], 'time': '2021-05-20T03:54:47.214673Z'}
{'type': 'l2update', 'product_id': 'BTC-USD', 'changes': [['sell', '38362.40', '0.00000000']], 'time': '2021-05-20T03:54:47.214673Z'}
{'type': 'l2update', 'product_id': 'BTC-USD', 'changes': [['sell', '38356.89', '0.43081950']], 'time': '2021-05-20T03:54:47.214673Z'}
{'type': 'l2update', 'product_id': 'BTC-USD', 'changes': [['sell', '38351.57', '0.03652500']], 'time': '2021-05-20T03:54:47.214673Z'}
{'type': 'l2update', 'product_id': 'BTC-USD', 'changes': [['sell', '38351.57', '0.00000000']], 'time': '2021-05-20T03:54:47.214673Z'}
{'type': 'l2update', 'product_id': 'BTC-USD', 'changes': [['sell', '43100.00', '1.09530000']], 'time': '2021-05-20T03:54:47.214825Z'}
{'type': 'l2update', 'product_id': 'BTC-USD', 'changes': [['sell', '38302.36', '0.01000000']], 'time': '2021-05-20T03:54:47.217272Z'}
{'type': 'l2update', 'product_id': 'BTC-USD', 'changes': [['sell', '38303.63', '0.00000000']], 'time': '2021-05-20T03:54:47.223402Z'}
{'type': 'l2update', 'product_id': 'BTC-USD', 'changes': [['buy', '38250.01', '0.05206770']], 'time': '2021-05-20T03:54:47.227486Z'}
{'type': 'l2update', 'product_id': 'BTC-USD', 'changes': [['buy', '38006.35', '0.00000000']], 'time': '2021-05-20T03:54:47.228097Z'}
{'type': 'l2update', 'product_id': 'BTC-USD', 'changes': [['buy', '38239.26', '0.58716278']], 'time': '2021-05-20T03:54:47.228241Z'}
{'type': 'l2update', 'product_id': 'BTC-USD', 'changes': [['buy', '38259.50', '0.00000000']], 'time': '2021-05-20T03:54:47.230170Z'}
{'type': 'l2update', 'product_id': 'BTC-USD', 'changes': [['sell', '38295.81', '0.05000000']], 'time': '2021-05-20T03:54:47.234483Z'}
{'type': 'l2update', 'product_id': 'BTC-USD', 'changes': [['sell', '38409.69', '0.01959195']], 'time': '2021-05-20T03:54:47.234720Z'}
{'type': 'l2update', 'product_id': 'BTC-USD', 'changes': [['sell', '38301.68', '0.00000000']], 'time': '2021-05-20T03:54:47.236590Z'}
{'type': 'l2update', 'product_id': 'BTC-USD', 'changes': [['sell', '38287.84', '0.00000000']], 'time': '2021-05-20T03:54:47.242685Z'}
{'type': 'l2update', 'product_id': 'BTC-USD', 'changes': [['buy', '38235.55', '0.13000000']], 'time': '2021-05-20T03:54:47.243466Z'}
{'type': 'l2update', 'product_id': 'BTC-USD', 'changes': [['buy', '38225.51', '0.02400000']], 'time': '2021-05-20T03:54:47.243556Z'}
{'type': 'l2update', 'product_id': 'BTC-USD', 'changes': [['buy', '38220.10', '0.01000000']], 'time': '2021-05-20T03:54:47.245886Z'}
{'type': 'l2update', 'product_id': 'BTC-USD', 'changes': [['buy', '38168.43', '0.00000000']], 'time': '2021-05-20T03:54:47.251146Z'}
{'type': 'l2update', 'product_id': 'BTC-USD', 'changes': [['sell', '38347.00', '0.03867605']], 'time': '2021-05-20T03:54:47.251694Z'}
{'type': 'l2update', 'product_id': 'BTC-USD', 'changes': [['buy', '37954.83', '0.06469700']], 'time': '2021-05-20T03:54:47.266498Z'}
{'type': 'l2update', 'product_id': 'BTC-USD', 'changes': [['buy', '38181.87', '0.02400000']], 'time': '2021-05-20T03:54:47.268027Z'}
{'type': 'l2update', 'product_id': 'BTC-USD', 'changes': [['buy', '38227.58', '0.00000000']], 'time': '2021-05-20T03:54:47.269089Z'}
{'type': 'l2update', 'product_id': 'BTC-USD', 'changes': [['buy', '38226.78', '0.00000000']], 'time': '2021-05-20T03:54:47.269089Z'}
{'type': 'l2update', 'product_id': 'BTC-USD', 'changes': [['buy', '38225.51', '0.00000000']], 'time': '2021-05-20T03:54:47.269089Z'}
{'type': 'l2update', 'product_id': 'BTC-USD', 'changes': [['buy', '38230.86', '0.00000000']], 'time': '2021-05-20T03:54:47.269182Z'}
{'type': 'l2update', 'product_id': 'BTC-USD', 'changes': [['sell', '38295.82', '0.71584532']], 'time': '2021-05-20T03:54:47.280401Z'}
{'type': 'l2update', 'product_id': 'BTC-USD', 'changes': [['buy', '38251.97', '0.05045891']], 'time': '2021-05-20T03:54:47.284688Z'}
{'type': 'l2update', 'product_id': 'BTC-USD', 'changes': [['sell', '38270.04', '3.41607981']], 'time': '2021-05-20T03:54:47.290514Z'}
{'type': 'l2update', 'product_id': 'BTC-USD', 'changes': [['buy', '38231.18', '0.04635475']], 'time': '2021-05-20T03:54:47.291012Z'}
{'type': 'l2update', 'product_id': 'BTC-USD', 'changes': [['sell', '38271.73', '0.05923326']], 'time': '2021-05-20T03:54:47.291012Z'}
{'type': 'l2update', 'product_id': 'BTC-USD', 'changes': [['buy', '38233.39', '0.52200000']], 'time': '2021-05-20T03:54:47.291200Z'}
{'type': 'l2update', 'product_id': 'BTC-USD', 'changes': [['sell', '38351.57', '0.02987631']], 'time': '2021-05-20T03:54:47.291227Z'}
{'type': 'l2update', 'product_id': 'BTC-USD', 'changes': [['sell', '38408.33', '0.00000000']], 'time': '2021-05-20T03:54:47.292995Z'}
{'type': 'l2update', 'product_id': 'BTC-USD', 'changes': [['sell', '38316.67', '2.16932808']], 'time': '2021-05-20T03:54:47.295042Z'}
{'type': 'l2update', 'product_id': 'BTC-USD', 'changes': [['buy', '38246.40', '0.52286815']], 'time': '2021-05-20T03:54:47.295609Z'}
{'type': 'l2update', 'product_id': 'BTC-USD', 'changes': [['sell', '38302.36', '0.00000000']], 'time': '2021-05-20T03:54:47.298349Z'}
{'type': 'l2update', 'product_id': 'BTC-USD', 'changes': [['buy', '38212.65', '0.00000000']], 'time': '2021-05-20T03:54:47.299784Z'}
{'type': 'l2update', 'product_id': 'BTC-USD', 'changes': [['buy', '38239.31', '0.05206770']], 'time': '2021-05-20T03:54:47.303484Z'}
{'type': 'l2update', 'product_id': 'BTC-USD', 'changes': [['sell', '38295.82', '0.85848140']], 'time': '2021-05-20T03:54:47.306963Z'}
{'type': 'l2update', 'product_id': 'BTC-USD', 'changes': [['buy', '38114.97', '0.33244095']], 'time': '2021-05-20T03:54:47.306963Z'}
{'type': 'l2update', 'product_id': 'BTC-USD', 'changes': [['buy', '38217.37', '0.02727510']], 'time': '2021-05-20T03:54:47.311967Z'}
{'type': 'l2update', 'product_id': 'BTC-USD', 'changes': [['buy', '38220.10', '0.00000000']], 'time': '2021-05-20T03:54:47.314760Z'}
{'type': 'l2update', 'product_id': 'BTC-USD', 'changes': [['buy', '38223.98', '0.02400000']], 'time': '2021-05-20T03:54:47.315610Z'}
{'type': 'l2update', 'product_id': 'BTC-USD', 'changes': [['buy', '38223.18', '0.02400000']], 'time': '2021-05-20T03:54:47.315610Z'}
{'type': 'l2update', 'product_id': 'BTC-USD', 'changes': [['buy', '38222.37', '0.02400000']], 'time': '2021-05-20T03:54:47.315610Z'}
{'type': 'l2update', 'product_id': 'BTC-USD', 'changes': [['buy', '38215.81', '0.05455019']], 'time': '2021-05-20T03:54:47.315828Z'}
{'type': 'l2update', 'product_id': 'BTC-USD', 'changes': [['sell', '38313.82', '0.03144430']], 'time': '2021-05-20T03:54:47.316471Z'}
{'type': 'l2update', 'product_id': 'BTC-USD', 'changes': [['sell', '38278.19', '0.01200000']], 'time': '2021-05-20T03:54:47.321579Z'}
{'type': 'l2update', 'product_id': 'BTC-USD', 'changes': [['sell', '49311.86', '0.00256700']], 'time': '2021-05-20T03:54:47.322907Z'}
{'type': 'l2update', 'product_id': 'BTC-USD', 'changes': [['sell', '38320.97', '0.00000000']], 'time': '2021-05-20T03:54:47.323242Z'}
{'type': 'l2update', 'product_id': 'BTC-USD', 'changes': [['buy', '38260.62', '0.00000000']], 'time': '2021-05-20T03:54:47.325337Z'}
{'type': 'l2update', 'product_id': 'BTC-USD', 'changes': [['sell', '38372.29', '0.00000000']], 'time': '2021-05-20T03:54:47.325421Z'}
{'type': 'l2update', 'product_id': 'BTC-USD', 'changes': [['sell', '38366.40', '0.00000000']], 'time': '2021-05-20T03:54:47.325421Z'}
{'type': 'l2update', 'product_id': 'BTC-USD', 'changes': [['sell', '38356.89', '0.00000000']], 'time': '2021-05-20T03:54:47.325421Z'}
{'type': 'l2update', 'product_id': 'BTC-USD', 'changes': [['sell', '38346.44', '0.00000000']], 'time': '2021-05-20T03:54:47.325421Z'}
{'type': 'l2update', 'product_id': 'BTC-USD', 'changes': [['sell', '38341.50', '0.00000000']], 'time': '2021-05-20T03:54:47.325421Z'}
{'type': 'l2update', 'product_id': 'BTC-USD', 'changes': [['sell', '38332.21', '0.00000000']], 'time': '2021-05-20T03:54:47.325421Z'}
{'type': 'l2update', 'product_id': 'BTC-USD', 'changes': [['sell', '38323.68', '0.00000000']], 'time': '2021-05-20T03:54:47.325421Z'}
{'type': 'l2update', 'product_id': 'BTC-USD', 'changes': [['sell', '38315.91', '0.00000000']], 'time': '2021-05-20T03:54:47.325421Z'}
{'type': 'l2update', 'product_id': 'BTC-USD', 'changes': [['sell', '38312.31', '0.00000000']], 'time': '2021-05-20T03:54:47.325421Z'}
{'type': 'l2update', 'product_id': 'BTC-USD', 'changes': [['buy', '38242.49', '0.78406572']], 'time': '2021-05-20T03:54:47.331359Z'}
{'type': 'l2update', 'product_id': 'BTC-USD', 'changes': [['sell', '38404.59', '0.00000000']], 'time': '2021-05-20T03:54:47.331725Z'}
{'type': 'l2update', 'product_id': 'BTC-USD', 'changes': [['buy', '38181.68', '0.01000000']], 'time': '2021-05-20T03:54:47.332091Z'}
{'type': 'l2update', 'product_id': 'BTC-USD', 'changes': [['sell', '38304.75', '0.32000000']], 'time': '2021-05-20T03:54:47.338129Z'}
{'type': 'l2update', 'product_id': 'BTC-USD', 'changes': [['sell', '38399.19', '0.80000000']], 'time': '2021-05-20T03:54:47.338129Z'}
{'type': 'l2update', 'product_id': 'BTC-USD', 'changes': [['sell', '38588.07', '5.00000000']], 'time': '2021-05-20T03:54:47.338129Z'}
{'type': 'l2update', 'product_id': 'BTC-USD', 'changes': [['sell', '38270.04', '3.56607981']], 'time': '2021-05-20T03:54:47.338258Z'}
{'type': 'l2update', 'product_id': 'BTC-USD', 'changes': [['sell', '38388.20', '0.01272967']], 'time': '2021-05-20T03:54:47.338856Z'}
{'type': 'l2update', 'product_id': 'BTC-USD', 'changes': [['sell', '38322.35', '0.02823810']], 'time': '2021-05-20T03:54:47.345164Z'}
{'type': 'l2update', 'product_id': 'BTC-USD', 'changes': [['sell', '38306.05', '0.03867605']], 'time': '2021-05-20T03:54:47.345164Z'}
{'type': 'l2update', 'product_id': 'BTC-USD', 'changes': [['buy', '38270.03', '0.00000000']], 'time': '2021-05-20T03:54:47.345364Z'}
{'type': 'l2update', 'product_id': 'BTC-USD', 'changes': [['buy', '38268.76', '0.00200085']], 'time': '2021-05-20T03:54:47.345364Z'}
{'type': 'l2update', 'product_id': 'BTC-USD', 'changes': [['buy', '38236.99', '0.78417688']], 'time': '2021-05-20T03:54:47.353899Z'}
{'type': 'l2update', 'product_id': 'BTC-USD', 'changes': [['sell', '38277.47', '0.00000000']], 'time': '2021-05-20T03:54:47.357127Z'}
{'type': 'l2update', 'product_id': 'BTC-USD', 'changes': [['sell', '38392.87', '0.00000000']], 'time': '2021-05-20T03:54:47.358163Z'}
{'type': 'l2update', 'product_id': 'BTC-USD', 'changes': [['sell', '38385.31', '0.01000000']], 'time': '2021-05-20T03:54:47.359808Z'}
{'type': 'l2update', 'product_id': 'BTC-USD', 'changes': [['buy', '38250.02', '0.22867204']], 'time': '2021-05-20T03:54:47.360124Z'}
{'type': 'l2update', 'product_id': 'BTC-USD', 'changes': [['sell', '38347.00', '0.00000000']], 'time': '2021-05-20T03:54:47.360277Z'}
{'type': 'l2update', 'product_id': 'BTC-USD', 'changes': [['sell', '38270.04', '3.53007981']], 'time': '2021-05-20T03:54:47.362195Z'}
{'type': 'l2update', 'product_id': 'BTC-USD', 'changes': [['sell', '38278.19', '0.00000000']], 'time': '2021-05-20T03:54:47.363126Z'}
{'type': 'l2update', 'product_id': 'BTC-USD', 'changes': [['sell', '38277.81', '0.00000000']], 'time': '2021-05-20T03:54:47.363502Z'}
{'type': 'l2update', 'product_id': 'BTC-USD', 'changes': [['sell', '38279.89', '0.02000000']], 'time': '2021-05-20T03:54:47.364463Z'}
{'type': 'l2update', 'product_id': 'BTC-USD', 'changes': [['buy', '38255.17', '0.01565774']], 'time': '2021-05-20T03:54:47.366689Z'}
{'type': 'l2update', 'product_id': 'BTC-USD', 'changes': [['sell', '38309.20', '0.00000000']], 'time': '2021-05-20T03:54:47.367288Z'}
{'type': 'l2update', 'product_id': 'BTC-USD', 'changes': [['buy', '38250.01', '0.00000000']], 'time': '2021-05-20T03:54:47.367395Z'}
{'type': 'l2update', 'product_id': 'BTC-USD', 'changes': [['sell', '38268.77', '0.02590000']], 'time': '2021-05-20T03:54:47.370354Z'}
{'type': 'l2update', 'product_id': 'BTC-USD', 'changes': [['sell', '38268.77', '0.03163000']], 'time': '2021-05-20T03:54:47.370478Z'}
{'type': 'l2update', 'product_id': 'BTC-USD', 'changes': [['sell', '38268.77', '0.06763000']], 'time': '2021-05-20T03:54:47.370512Z'}
{'type': 'l2update', 'product_id': 'BTC-USD', 'changes': [['sell', '38268.77', '0.14223000']], 'time': '2021-05-20T03:54:47.370775Z'}
{'type': 'l2update', 'product_id': 'BTC-USD', 'changes': [['sell', '38268.77', '0.15715000']], 'time': '2021-05-20T03:54:47.370804Z'}
{'type': 'l2update', 'product_id': 'BTC-USD', 'changes': [['sell', '38320.96', '0.00000000']], 'time': '2021-05-20T03:54:47.373067Z'}
{'type': 'l2update', 'product_id': 'BTC-USD', 'changes': [['buy', '38239.31', '0.00000000']], 'time': '2021-05-20T03:54:47.374473Z'}
{'type': 'l2update', 'product_id': 'BTC-USD', 'changes': [['buy', '38233.47', '0.78425170']], 'time': '2021-05-20T03:54:47.375535Z'}
{'type': 'l2update', 'product_id': 'BTC-USD', 'changes': [['sell', '38396.40', '0.00000000']], 'time': '2021-05-20T03:54:47.376026Z'}
{'type': 'l2update', 'product_id': 'BTC-USD', 'changes': [['sell', '38382.91', '0.00000000']], 'time': '2021-05-20T03:54:47.376026Z'}
{'type': 'l2update', 'product_id': 'BTC-USD', 'changes': [['sell', '38376.45', '0.00000000']], 'time': '2021-05-20T03:54:47.376026Z'}
{'type': 'l2update', 'product_id': 'BTC-USD', 'changes': [['sell', '38595.59', '0.64576018']], 'time': '2021-05-20T03:54:47.380893Z'}
{'type': 'l2update', 'product_id': 'BTC-USD', 'changes': [['sell', '38595.60', '5.81200940']], 'time': '2021-05-20T03:54:47.380893Z'}
{'type': 'l2update', 'product_id': 'BTC-USD', 'changes': [['sell', '38268.77', '0.25715000']], 'time': '2021-05-20T03:54:47.381023Z'}
{'type': 'l2update', 'product_id': 'BTC-USD', 'changes': [['buy', '38200.01', '0.09500828']], 'time': '2021-05-20T03:54:47.381208Z'}
{'type': 'l2update', 'product_id': 'BTC-USD', 'changes': [['sell', '38420.65', '0.01000000']], 'time': '2021-05-20T03:54:47.385698Z'}
{'type': 'l2update', 'product_id': 'BTC-USD', 'changes': [['sell', '38336.57', '0.03853620']], 'time': '2021-05-20T03:54:47.385941Z'}
{'type': 'l2update', 'product_id': 'BTC-USD', 'changes': [['buy', '38268.76', '0.00000000']], 'time': '2021-05-20T03:54:47.386033Z'}
{'type': 'l2update', 'product_id': 'BTC-USD', 'changes': [['sell', '38291.00', '0.50000000']], 'time': '2021-05-20T03:54:47.386116Z'}
{'type': 'l2update', 'product_id': 'BTC-USD', 'changes': [['sell', '38306.94', '0.00000000']], 'time': '2021-05-20T03:54:47.388191Z'}
{'type': 'l2update', 'product_id': 'BTC-USD', 'changes': [['sell', '38270.04', '3.52434981']], 'time': '2021-05-20T03:54:47.388300Z'}
{'type': 'l2update', 'product_id': 'BTC-USD', 'changes': [['sell', '38270.04', '3.49844981']], 'time': '2021-05-20T03:54:47.389599Z'}
{'type': 'l2update', 'product_id': 'BTC-USD', 'changes': [['sell', '38270.03', '0.36249352']], 'time': '2021-05-20T03:54:47.399087Z'}
{'type': 'l2update', 'product_id': 'BTC-USD', 'changes': [['buy', '38214.51', '2.61336720']], 'time': '2021-05-20T03:54:47.403633Z'}
{'type': 'l2update', 'product_id': 'BTC-USD', 'changes': [['sell', '38268.77', '0.18255000']], 'time': '2021-05-20T03:54:47.404020Z'}
{'type': 'l2update', 'product_id': 'BTC-USD', 'changes': [['sell', '38268.77', '0.16763000']], 'time': '2021-05-20T03:54:47.404955Z'}
{'type': 'l2update', 'product_id': 'BTC-USD', 'changes': [['sell', '38268.77', '0.36763000']], 'time': '2021-05-20T03:54:47.407670Z'}
{'type': 'l2update', 'product_id': 'BTC-USD', 'changes': [['buy', '38255.17', '0.00000000']], 'time': '2021-05-20T03:54:47.408296Z'}
{'type': 'l2update', 'product_id': 'BTC-USD', 'changes': [['sell', '38453.91', '0.00000000']], 'time': '2021-05-20T03:54:47.409921Z'}
{'type': 'l2update', 'product_id': 'BTC-USD', 'changes': [['sell', '38351.57', '0.05712409']], 'time': '2021-05-20T03:54:47.410102Z'}
{'type': 'l2update', 'product_id': 'BTC-USD', 'changes': [['buy', '38204.36', '0.00000000']], 'time': '2021-05-20T03:54:47.410294Z'}
{'type': 'l2update', 'product_id': 'BTC-USD', 'changes': [['sell', '38268.76', '0.00573000']], 'time': '2021-05-20T03:54:47.417039Z'}
{'type': 'l2update', 'product_id': 'BTC-USD', 'changes': [['sell', '38409.69', '0.00000000']], 'time': '2021-05-20T03:54:47.418488Z'}
{'type': 'l2update', 'product_id': 'BTC-USD', 'changes': [['sell', '38260.84', '0.06027652']], 'time': '2021-05-20T03:54:47.428185Z'}
{'type': 'l2update', 'product_id': 'BTC-USD', 'changes': [['buy', '38250.02', '0.00000000']], 'time': '2021-05-20T03:54:47.431429Z'}
{'type': 'l2update', 'product_id': 'BTC-USD', 'changes': [['sell', '38268.77', '0.36190000']], 'time': '2021-05-20T03:54:47.432667Z'}
{'type': 'l2update', 'product_id': 'BTC-USD', 'changes': [['sell', '38282.19', '0.00000000']], 'time': '2021-05-20T03:54:47.432741Z'}
{'type': 'l2update', 'product_id': 'BTC-USD', 'changes': [['buy', '38209.49', '2.61372111']], 'time': '2021-05-20T03:54:47.434929Z'}
{'type': 'l2update', 'product_id': 'BTC-USD', 'changes': [['buy', '38187.50', '0.02618658']], 'time': '2021-05-20T03:54:47.439030Z'}
{'type': 'l2update', 'product_id': 'BTC-USD', 'changes': [['sell', '38356.94', '0.03397456']], 'time': '2021-05-20T03:54:47.439117Z'}
{'type': 'l2update', 'product_id': 'BTC-USD', 'changes': [['sell', '38595.60', '2.58310520']], 'time': '2021-05-20T03:54:47.441394Z'}
{'type': 'l2update', 'product_id': 'BTC-USD', 'changes': [['sell', '38270.04', '3.29844981']], 'time': '2021-05-20T03:54:47.443611Z'}
{'type': 'l2update', 'product_id': 'BTC-USD', 'changes': [['sell', '38260.84', '0.06479418']], 'time': '2021-05-20T03:54:47.446912Z'}
{'type': 'l2update', 'product_id': 'BTC-USD', 'changes': [['buy', '38246.41', '0.05206770']], 'time': '2021-05-20T03:54:47.446984Z'}
{'type': 'l2update', 'product_id': 'BTC-USD', 'changes': [['buy', '38252.03', '0.01565774']], 'time': '2021-05-20T03:54:47.447243Z'}
{'type': 'l2update', 'product_id': 'BTC-USD', 'changes': [['sell', '38268.77', '0.33600000']], 'time': '2021-05-20T03:54:47.447951Z'}
{'type': 'l2update', 'product_id': 'BTC-USD', 'changes': [['sell', '38395.06', '0.01061181']], 'time': '2021-05-20T03:54:47.448244Z'}
{'type': 'l2update', 'product_id': 'BTC-USD', 'changes': [['sell', '38417.97', '0.00000000']], 'time': '2021-05-20T03:54:47.449484Z'}
{'type': 'l2update', 'product_id': 'BTC-USD', 'changes': [['sell', '38299.89', '0.00000000']], 'time': '2021-05-20T03:54:47.449715Z'}
{'type': 'l2update', 'product_id': 'BTC-USD', 'changes': [['sell', '38268.76', '0.00000000']], 'time': '2021-05-20T03:54:47.449945Z'}
{'type': 'l2update', 'product_id': 'BTC-USD', 'changes': [['sell', '38260.84', '0.06884915']], 'time': '2021-05-20T03:54:47.454192Z'}
{'type': 'l2update', 'product_id': 'BTC-USD', 'changes': [['sell', '38352.28', '0.00000000']], 'time': '2021-05-20T03:54:47.454450Z'}
{'type': 'l2update', 'product_id': 'BTC-USD', 'changes': [['sell', '38270.04', '3.19844981']], 'time': '2021-05-20T03:54:47.458133Z'}
{'type': 'l2update', 'product_id': 'BTC-USD', 'changes': [['sell', '38260.84', '0.08317263']], 'time': '2021-05-20T03:54:47.460053Z'}
{'type': 'l2update', 'product_id': 'BTC-USD', 'changes': [['sell', '38260.84', '0.73317263']], 'time': '2021-05-20T03:54:47.465037Z'}
{'type': 'l2update', 'product_id': 'BTC-USD', 'changes': [['buy', '38206.46', '2.61392293']], 'time': '2021-05-20T03:54:47.465902Z'}
{'type': 'l2update', 'product_id': 'BTC-USD', 'changes': [['sell', '38260.84', '0.73952000']], 'time': '2021-05-20T03:54:47.466080Z'}
{'type': 'l2update', 'product_id': 'BTC-USD', 'changes': [['sell', '38290.44', '0.46320331']], 'time': '2021-05-20T03:54:47.466958Z'}
{'type': 'l2update', 'product_id': 'BTC-USD', 'changes': [['buy', '38242.50', '0.22867204']], 'time': '2021-05-20T03:54:47.466988Z'}
{'type': 'l2update', 'product_id': 'BTC-USD', 'changes': [['buy', '38144.58', '0.00000000']], 'time': '2021-05-20T03:54:47.467008Z'}
{'type': 'l2update', 'product_id': 'BTC-USD', 'changes': [['sell', '38270.03', '0.00000000']], 'time': '2021-05-20T03:54:47.470482Z'}
{'type': 'l2update', 'product_id': 'BTC-USD', 'changes': [['sell', '38295.81', '0.00000000']], 'time': '2021-05-20T03:54:47.473017Z'}
{'type': 'l2update', 'product_id': 'BTC-USD', 'changes': [['buy', '38235.54', '0.00000000']], 'time': '2021-05-20T03:54:47.473977Z'}
{'type': 'l2update', 'product_id': 'BTC-USD', 'changes': [['sell', '38268.77', '0.23600000']], 'time': '2021-05-20T03:54:47.474768Z'}
{'type': 'l2update', 'product_id': 'BTC-USD', 'changes': [['sell', '38430.84', '0.00000000']], 'time': '2021-05-20T03:54:47.475120Z'}
{'type': 'l2update', 'product_id': 'BTC-USD', 'changes': [['buy', '38242.50', '0.28073974']], 'time': '2021-05-20T03:54:47.477633Z'}
{'type': 'l2update', 'product_id': 'BTC-USD', 'changes': [['buy', '38237.04', '0.52100000']], 'time': '2021-05-20T03:54:47.477682Z'}
{'type': 'l2update', 'product_id': 'BTC-USD', 'changes': [['sell', '38438.69', '0.01000000']], 'time': '2021-05-20T03:54:47.479050Z'}
{'type': 'l2update', 'product_id': 'BTC-USD', 'changes': [['sell', '38277.46', '0.16000000']], 'time': '2021-05-20T03:54:47.483060Z'}
{'type': 'l2update', 'product_id': 'BTC-USD', 'changes': [['sell', '38260.84', '0.08952000']], 'time': '2021-05-20T03:54:47.483828Z'}
{'type': 'l2update', 'product_id': 'BTC-USD', 'changes': [['buy', '38251.97', '0.00000000']], 'time': '2021-05-20T03:54:47.485727Z'}
{'type': 'l2update', 'product_id': 'BTC-USD', 'changes': [['buy', '38246.41', '0.00000000']], 'time': '2021-05-20T03:54:47.487114Z'}
{'type': 'l2update', 'product_id': 'BTC-USD', 'changes': [['sell', '38304.74', '0.69834446']], 'time': '2021-05-20T03:54:47.489286Z'}
{'type': 'l2update', 'product_id': 'BTC-USD', 'changes': [['sell', '38291.00', '0.00000000']], 'time': '2021-05-20T03:54:47.491094Z'}
{'type': 'l2update', 'product_id': 'BTC-USD', 'changes': [['sell', '38385.31', '0.00000000']], 'time': '2021-05-20T03:54:47.492779Z'}
{'type': 'l2update', 'product_id': 'BTC-USD', 'changes': [['sell', '38268.77', '0.03600000']], 'time': '2021-05-20T03:54:47.492921Z'}
{'type': 'l2update', 'product_id': 'BTC-USD', 'changes': [['sell', '49315.38', '0.00248100']], 'time': '2021-05-20T03:54:47.495551Z'}
{'type': 'l2update', 'product_id': 'BTC-USD', 'changes': [['sell', '38260.84', '0.08702083']], 'time': '2021-05-20T03:54:47.495626Z'}
{'type': 'l2update', 'product_id': 'BTC-USD', 'changes': [['buy', '38193.13', '0.00000000']], 'time': '2021-05-20T03:54:47.498413Z'}
{'type': 'l2update', 'product_id': 'BTC-USD', 'changes': [['sell', '38290.44', '0.51320331']], 'time': '2021-05-20T03:54:47.499860Z'}
{'type': 'l2update', 'product_id': 'BTC-USD', 'changes': [['buy', '38198.57', '0.10000000']], 'time': '2021-05-20T03:54:47.499931Z'}
{'type': 'l2update', 'product_id': 'BTC-USD', 'changes': [['sell', '38260.84', '0.28702083']], 'time': '2021-05-20T03:54:47.518639Z'}
{'type': 'l2update', 'product_id': 'BTC-USD', 'changes': [['sell', '38268.76', '0.36249352']], 'time': '2021-05-20T03:54:47.524421Z'}
{'type': 'l2update', 'product_id': 'BTC-USD', 'changes': [['buy', '38239.30', '0.00000000']], 'time': '2021-05-20T03:54:47.528114Z'}
{'type': 'l2update', 'product_id': 'BTC-USD', 'changes': [['buy', '38231.18', '0.00000000']], 'time': '2021-05-20T03:54:47.528966Z'}
{'type': 'l2update', 'product_id': 'BTC-USD', 'changes': [['sell', '38271.73', '0.00000000']], 'time': '2021-05-20T03:54:47.528966Z'}
{'type': 'l2update', 'product_id': 'BTC-USD', 'changes': [['buy', '38174.35', '0.01000000']], 'time': '2021-05-20T03:54:47.531454Z'}
{'type': 'l2update', 'product_id': 'BTC-USD', 'changes': [['buy', '38130.14', '0.07235357']], 'time': '2021-05-20T03:54:47.535680Z'}
{'type': 'l2update', 'product_id': 'BTC-USD', 'changes': [['sell', '38375.30', '0.00000000']], 'time': '2021-05-20T03:54:47.538059Z'}
{'type': 'l2update', 'product_id': 'BTC-USD', 'changes': [['buy', '38242.50', '0.05206770']], 'time': '2021-05-20T03:54:47.539986Z'}
{'type': 'l2update', 'product_id': 'BTC-USD', 'changes': [['sell', '38423.91', '0.00000000']], 'time': '2021-05-20T03:54:47.540902Z'}
{'type': 'l2update', 'product_id': 'BTC-USD', 'changes': [['sell', '38404.74', '0.00000000']], 'time': '2021-05-20T03:54:47.540926Z'}
{'type': 'l2update', 'product_id': 'BTC-USD', 'changes': [['sell', '38260.84', '0.38702083']], 'time': '2021-05-20T03:54:47.545042Z'}
{'type': 'l2update', 'product_id': 'BTC-USD', 'changes': [['sell', '38417.66', '0.01000000']], 'time': '2021-05-20T03:54:47.545220Z'}
{'type': 'l2update', 'product_id': 'BTC-USD', 'changes': [['sell', '38384.37', '0.01000000']], 'time': '2021-05-20T03:54:47.546696Z'}
{'type': 'l2update', 'product_id': 'BTC-USD', 'changes': [['sell', '38413.23', '0.00000000']], 'time': '2021-05-20T03:54:47.548628Z'}
{'type': 'l2update', 'product_id': 'BTC-USD', 'changes': [['sell', '38297.08', '0.00000000']], 'time': '2021-05-20T03:54:47.549384Z'}
{'type': 'l2update', 'product_id': 'BTC-USD', 'changes': [['sell', '38363.16', '0.01329300']], 'time': '2021-05-20T03:54:47.559590Z'}
{'type': 'l2update', 'product_id': 'BTC-USD', 'changes': [['sell', '38297.03', '0.00000000']], 'time': '2021-05-20T03:54:47.561540Z'}
{'type': 'l2update', 'product_id': 'BTC-USD', 'changes': [['sell', '38409.29', '0.07326517']], 'time': '2021-05-20T03:54:47.563110Z'}
{'type': 'l2update', 'product_id': 'BTC-USD', 'changes': [['sell', '38389.74', '0.01241115']], 'time': '2021-05-20T03:54:47.563177Z'}
{'type': 'l2update', 'product_id': 'BTC-USD', 'changes': [['buy', '38242.51', '0.05206770']], 'time': '2021-05-20T03:54:47.563456Z'}
{'type': 'l2update', 'product_id': 'BTC-USD', 'changes': [['sell', '38393.15', '0.01000000']], 'time': '2021-05-20T03:54:47.568675Z'}
{'type': 'l2update', 'product_id': 'BTC-USD', 'changes': [['buy', '38242.51', '0.28073974']], 'time': '2021-05-20T03:54:47.568736Z'}
{'type': 'l2update', 'product_id': 'BTC-USD', 'changes': [['buy', '38242.50', '0.00000000']], 'time': '2021-05-20T03:54:47.575118Z'}
{'type': 'l2update', 'product_id': 'BTC-USD', 'changes': [['sell', '38277.45', '0.06460106']], 'time': '2021-05-20T03:54:47.580829Z'}
{'type': 'l2update', 'product_id': 'BTC-USD', 'changes': [['sell', '38268.75', '1.28791283']], 'time': '2021-05-20T03:54:47.583278Z'}
{'type': 'l2update', 'product_id': 'BTC-USD', 'changes': [['sell', '38268.76', '0.00000000']], 'time': '2021-05-20T03:54:47.584573Z'}
{'type': 'l2update', 'product_id': 'BTC-USD', 'changes': [['sell', '38417.66', '0.00000000']], 'time': '2021-05-20T03:54:47.585262Z'}
{'type': 'l2update', 'product_id': 'BTC-USD', 'changes': [['sell', '38438.69', '0.00000000']], 'time': '2021-05-20T03:54:47.588007Z'}
{'type': 'l2update', 'product_id': 'BTC-USD', 'changes': [['sell', '38339.89', '0.17190000']], 'time': '2021-05-20T03:54:47.592914Z'}
{'type': 'l2update', 'product_id': 'BTC-USD', 'changes': [['sell', '38490.86', '0.00649504']], 'time': '2021-05-20T03:54:47.598367Z'}
{'type': 'l2update', 'product_id': 'BTC-USD', 'changes': [['buy', '38116.54', '0.00000000']], 'time': '2021-05-20T03:54:47.603348Z'}
{'type': 'l2update', 'product_id': 'BTC-USD', 'changes': [['buy', '38224.75', '0.04558641']], 'time': '2021-05-20T03:54:47.606445Z'}
{'type': 'l2update', 'product_id': 'BTC-USD', 'changes': [['sell', '38265.29', '0.05428038']], 'time': '2021-05-20T03:54:47.606445Z'}
{'type': 'l2update', 'product_id': 'BTC-USD', 'changes': [['sell', '38268.70', '1.07600000']], 'time': '2021-05-20T03:54:47.606480Z'}
{'type': 'l2update', 'product_id': 'BTC-USD', 'changes': [['sell', '38472.98', '0.01000000']], 'time': '2021-05-20T03:54:47.611024Z'}
{'type': 'l2update', 'product_id': 'BTC-USD', 'changes': [['sell', '38588.06', '3.22888725']], 'time': '2021-05-20T03:54:47.611387Z'}
{'type': 'l2update', 'product_id': 'BTC-USD', 'changes': [['buy', '38163.70', '0.00000000']], 'time': '2021-05-20T03:54:47.612663Z'}
{'type': 'l2update', 'product_id': 'BTC-USD', 'changes': [['sell', '38268.74', '0.36249352']], 'time': '2021-05-20T03:54:47.615932Z'}
{'type': 'l2update', 'product_id': 'BTC-USD', 'changes': [['sell', '38374.68', '0.00000000']], 'time': '2021-05-20T03:54:47.620132Z'}
{'type': 'l2update', 'product_id': 'BTC-USD', 'changes': [['sell', '38553.46', '0.00000000']], 'time': '2021-05-20T03:54:47.621590Z'}
{'type': 'l2update', 'product_id': 'BTC-USD', 'changes': [['buy', '38158.24', '0.50000000']], 'time': '2021-05-20T03:54:47.634657Z'}
{'type': 'l2update', 'product_id': 'BTC-USD', 'changes': [['sell', '38265.28', '1.56286052']], 'time': '2021-05-20T03:54:47.634864Z'}
{'type': 'l2update', 'product_id': 'BTC-USD', 'changes': [['sell', '38450.49', '0.01237346']], 'time': '2021-05-20T03:54:47.635343Z'}
{'type': 'l2update', 'product_id': 'BTC-USD', 'changes': [['sell', '38595.59', '0.00000000']], 'time': '2021-05-20T03:54:47.649369Z'}
{'type': 'l2update', 'product_id': 'BTC-USD', 'changes': [['sell', '38595.60', '0.00000000']], 'time': '2021-05-20T03:54:47.649369Z'}
{'type': 'l2update', 'product_id': 'BTC-USD', 'changes': [['sell', '38395.06', '0.00000000']], 'time': '2021-05-20T03:54:47.649847Z'}
{'type': 'l2update', 'product_id': 'BTC-USD', 'changes': [['buy', '38242.51', '0.22867204']], 'time': '2021-05-20T03:54:47.649999Z'}
{'type': 'l2update', 'product_id': 'BTC-USD', 'changes': [['sell', '38270.04', '2.69844981']], 'time': '2021-05-20T03:54:47.651664Z'}
{'type': 'l2update', 'product_id': 'BTC-USD', 'changes': [['buy', '38239.26', '0.00000000']], 'time': '2021-05-20T03:54:47.656801Z'}
{'type': 'l2update', 'product_id': 'BTC-USD', 'changes': [['buy', '38242.52', '0.06460106']], 'time': '2021-05-20T03:54:47.659209Z'}
{'type': 'l2update', 'product_id': 'BTC-USD', 'changes': [['sell', '38351.57', '0.08423489']], 'time': '2021-05-20T03:54:47.659777Z'}
{'type': 'l2update', 'product_id': 'BTC-USD', 'changes': [['sell', '38363.15', '0.01303334']], 'time': '2021-05-20T03:54:47.660021Z'}
{'type': 'l2update', 'product_id': 'BTC-USD', 'changes': [['buy', '38242.51', '0.00000000']], 'time': '2021-05-20T03:54:47.665429Z'}
{'type': 'l2update', 'product_id': 'BTC-USD', 'changes': [['sell', '38538.46', '0.01258823']], 'time': '2021-05-20T03:54:47.670788Z'}
{'type': 'l2update', 'product_id': 'BTC-USD', 'changes': [['sell', '38381.10', '0.01291043']], 'time': '2021-05-20T03:54:47.671268Z'}
{'type': 'l2update', 'product_id': 'BTC-USD', 'changes': [['buy', '38224.75', '0.00000000']], 'time': '2021-05-20T03:54:47.674393Z'}
{'type': 'l2update', 'product_id': 'BTC-USD', 'changes': [['sell', '38265.29', '0.00000000']], 'time': '2021-05-20T03:54:47.674393Z'}
{'type': 'l2update', 'product_id': 'BTC-USD', 'changes': [['sell', '38268.74', '0.00000000']], 'time': '2021-05-20T03:54:47.677623Z'}
{'type': 'l2update', 'product_id': 'BTC-USD', 'changes': [['sell', '38265.28', '2.06286052']], 'time': '2021-05-20T03:54:47.679545Z'}
{'type': 'l2update', 'product_id': 'BTC-USD', 'changes': [['sell', '38308.78', '0.34356779']], 'time': '2021-05-20T03:54:47.680247Z'}
{'type': 'l2update', 'product_id': 'BTC-USD', 'changes': [['buy', '38242.52', '0.65176384']], 'time': '2021-05-20T03:54:47.686577Z'}
{'type': 'l2update', 'product_id': 'BTC-USD', 'changes': [['sell', '38360.95', '0.03874802']], 'time': '2021-05-20T03:54:47.690653Z'}
{'type': 'l2update', 'product_id': 'BTC-USD', 'changes': [['sell', '49318.91', '0.00248100']], 'time': '2021-05-20T03:54:47.694587Z'}
{'type': 'l2update', 'product_id': 'BTC-USD', 'changes': [['sell', '38356.31', '0.00000000']], 'time': '2021-05-20T03:54:47.698405Z'}
{'type': 'l2update', 'product_id': 'BTC-USD', 'changes': [['buy', '38252.03', '0.00000000']], 'time': '2021-05-20T03:54:47.699871Z'}
{'type': 'l2update', 'product_id': 'BTC-USD', 'changes': [['sell', '38317.69', '0.34766668']], 'time': '2021-05-20T03:54:47.703788Z'}
{'type': 'l2update', 'product_id': 'BTC-USD', 'changes': [['sell', '38363.15', '0.00000000']], 'time': '2021-05-20T03:54:47.709776Z'}
{'type': 'l2update', 'product_id': 'BTC-USD', 'changes': [['buy', '38237.05', '0.22867204']], 'time': '2021-05-20T03:54:47.712095Z'}
{'type': 'l2update', 'product_id': 'BTC-USD', 'changes': [['buy', '38242.52', '0.58716278']], 'time': '2021-05-20T03:54:47.714465Z'}
{'type': 'l2update', 'product_id': 'BTC-USD', 'changes': [['sell', '38472.98', '0.00000000']], 'time': '2021-05-20T03:54:47.715906Z'}
{'type': 'l2update', 'product_id': 'BTC-USD', 'changes': [['sell', '38322.43', '0.39961346']], 'time': '2021-05-20T03:54:47.723980Z'}
{'type': 'l2update', 'product_id': 'BTC-USD', 'changes': [['sell', '38384.71', '0.01302602']], 'time': '2021-05-20T03:54:47.724041Z'}
{'type': 'l2update', 'product_id': 'BTC-USD', 'changes': [['sell', '38367.22', '0.03536245']], 'time': '2021-05-20T03:54:47.724900Z'}
{'type': 'l2update', 'product_id': 'BTC-USD', 'changes': [['sell', '38265.27', '0.36249352']], 'time': '2021-05-20T03:54:47.728702Z'}
{'type': 'l2update', 'product_id': 'BTC-USD', 'changes': [['buy', '38239.27', '0.06460106']], 'time': '2021-05-20T03:54:47.732575Z'}
{'type': 'l2update', 'product_id': 'BTC-USD', 'changes': [['sell', '38459.78', '0.01000000']], 'time': '2021-05-20T03:54:47.734599Z'}
{'type': 'l2update', 'product_id': 'BTC-USD', 'changes': [['sell', '38378.74', '0.00000000']], 'time': '2021-05-20T03:54:47.736534Z'}
{'type': 'l2update', 'product_id': 'BTC-USD', 'changes': [['buy', '38256.82', '0.01565774']], 'time': '2021-05-20T03:54:47.740194Z'}
{'type': 'l2update', 'product_id': 'BTC-USD', 'changes': [['sell', '38332.48', '0.41632480']], 'time': '2021-05-20T03:54:47.744136Z'}
{'type': 'l2update', 'product_id': 'BTC-USD', 'changes': [['sell', '38378.28', '0.00000000']], 'time': '2021-05-20T03:54:47.751718Z'}
{'type': 'l2update', 'product_id': 'BTC-USD', 'changes': [['buy', '38237.06', '0.06460106']], 'time': '2021-05-20T03:54:47.753827Z'}
{'type': 'l2update', 'product_id': 'BTC-USD', 'changes': [['sell', '38386.86', '0.00000000']], 'time': '2021-05-20T03:54:47.756431Z'}
{'type': 'l2update', 'product_id': 'BTC-USD', 'changes': [['sell', '38373.68', '0.03720862']], 'time': '2021-05-20T03:54:47.757610Z'}
{'type': 'l2update', 'product_id': 'BTC-USD', 'changes': [['sell', '38365.49', '0.01811971']], 'time': '2021-05-20T03:54:47.758104Z'}
{'type': 'l2update', 'product_id': 'BTC-USD', 'changes': [['buy', '37500.02', '0.00000000']], 'time': '2021-05-20T03:54:47.759659Z'}
{'type': 'l2update', 'product_id': 'BTC-USD', 'changes': [['buy', '37500.01', '0.13350000']], 'time': '2021-05-20T03:54:47.759659Z'}
{'type': 'l2update', 'product_id': 'BTC-USD', 'changes': [['buy', '37469.35', '0.05430000']], 'time': '2021-05-20T03:54:47.769016Z'}
{'type': 'l2update', 'product_id': 'BTC-USD', 'changes': [['buy', '37471.32', '0.01360000']], 'time': '2021-05-20T03:54:47.769016Z'}
{'type': 'l2update', 'product_id': 'BTC-USD', 'changes': [['buy', '37475.72', '0.00190000']], 'time': '2021-05-20T03:54:47.769016Z'}
{'type': 'l2update', 'product_id': 'BTC-USD', 'changes': [['buy', '38237.05', '0.00000000']], 'time': '2021-05-20T03:54:47.769523Z'}
{'type': 'l2update', 'product_id': 'BTC-USD', 'changes': [['sell', '38393.15', '0.00000000']], 'time': '2021-05-20T03:54:47.769792Z'}
{'type': 'l2update', 'product_id': 'BTC-USD', 'changes': [['buy', '38205.10', '0.12277433']], 'time': '2021-05-20T03:54:47.777388Z'}
{'type': 'l2update', 'product_id': 'BTC-USD', 'changes': [['sell', '38366.75', '0.03054428']], 'time': '2021-05-20T03:54:47.777784Z'}
{'type': 'l2update', 'product_id': 'BTC-USD', 'changes': [['buy', '38246.45', '0.84900000']], 'time': '2021-05-20T03:54:47.781087Z'}
{'type': 'l2update', 'product_id': 'BTC-USD', 'changes': [['buy', '38224.75', '0.04558641']], 'time': '2021-05-20T03:54:47.781225Z'}
{'type': 'l2update', 'product_id': 'BTC-USD', 'changes': [['sell', '38266.84', '0.06409775']], 'time': '2021-05-20T03:54:47.781225Z'}
{'type': 'l2update', 'product_id': 'BTC-USD', 'changes': [['sell', '38361.39', '0.06660835']], 'time': '2021-05-20T03:54:47.787581Z'}
{'type': 'l2update', 'product_id': 'BTC-USD', 'changes': [['sell', '38407.74', '0.01000000']], 'time': '2021-05-20T03:54:47.787673Z'}
{'type': 'l2update', 'product_id': 'BTC-USD', 'changes': [['sell', '38343.29', '0.33727563']], 'time': '2021-05-20T03:54:47.791681Z'}
{'type': 'l2update', 'product_id': 'BTC-USD', 'changes': [['buy', '38260.83', '0.00217420']], 'time': '2021-05-20T03:54:47.792261Z'}
{'type': 'l2update', 'product_id': 'BTC-USD', 'changes': [['sell', '38270.04', '0.20875073']], 'time': '2021-05-20T03:54:47.792487Z'}
{'type': 'l2update', 'product_id': 'BTC-USD', 'changes': [['buy', '38246.45', '0.00000000']], 'time': '2021-05-20T03:54:47.795512Z'}
{'type': 'l2update', 'product_id': 'BTC-USD', 'changes': [['buy', '38242.53', '0.22867204']], 'time': '2021-05-20T03:54:47.796287Z'}
{'type': 'l2update', 'product_id': 'BTC-USD', 'changes': [['buy', '38225.38', '0.00000000']], 'time': '2021-05-20T03:54:47.797463Z'}
{'type': 'l2update', 'product_id': 'BTC-USD', 'changes': [['sell', '38345.97', '0.00000000']], 'time': '2021-05-20T03:54:47.802641Z'}
{'type': 'l2update', 'product_id': 'BTC-USD', 'changes': [['buy', '38239.27', '0.00000000']], 'time': '2021-05-20T03:54:47.807006Z'}
{'type': 'l2update', 'product_id': 'BTC-USD', 'changes': [['buy', '38233.86', '0.46280000']], 'time': '2021-05-20T03:54:47.809914Z'}
{'type': 'l2update', 'product_id': 'BTC-USD', 'changes': [['sell', '38365.49', '0.00000000']], 'time': '2021-05-20T03:54:47.811035Z'}
{'type': 'l2update', 'product_id': 'BTC-USD', 'changes': [['sell', '38265.26', '2.48969908']], 'time': '2021-05-20T03:54:47.821423Z'}
{'type': 'l2update', 'product_id': 'BTC-USD', 'changes': [['sell', '38348.98', '0.39246150']], 'time': '2021-05-20T03:54:47.821476Z'}
{'type': 'l2update', 'product_id': 'BTC-USD', 'changes': [['sell', '38351.62', '0.01000000']], 'time': '2021-05-20T03:54:47.827526Z'}
{'type': 'l2update', 'product_id': 'BTC-USD', 'changes': [['sell', '38266.84', '0.00000000']], 'time': '2021-05-20T03:54:47.829245Z'}
{'type': 'l2update', 'product_id': 'BTC-USD', 'changes': [['sell', '38265.27', '0.00000000']], 'time': '2021-05-20T03:54:47.830288Z'}
{'type': 'l2update', 'product_id': 'BTC-USD', 'changes': [['sell', '38475.01', '0.00000000']], 'time': '2021-05-20T03:54:47.833661Z'}
{'type': 'l2update', 'product_id': 'BTC-USD', 'changes': [['sell', '38459.78', '0.00000000']], 'time': '2021-05-20T03:54:47.834026Z'}
{'type': 'l2update', 'product_id': 'BTC-USD', 'changes': [['sell', '38409.29', '0.00000000']], 'time': '2021-05-20T03:54:47.835495Z'}
{'type': 'l2update', 'product_id': 'BTC-USD', 'changes': [['buy', '38223.18', '0.00000000']], 'time': '2021-05-20T03:54:47.841755Z'}
{'type': 'l2update', 'product_id': 'BTC-USD', 'changes': [['buy', '38222.37', '0.00000000']], 'time': '2021-05-20T03:54:47.841755Z'}
{'type': 'l2update', 'product_id': 'BTC-USD', 'changes': [['sell', '38354.87', '0.41068430']], 'time': '2021-05-20T03:54:47.846010Z'}
{'type': 'l2update', 'product_id': 'BTC-USD', 'changes': [['buy', '38223.98', '0.00000000']], 'time': '2021-05-20T03:54:47.847022Z'}
{'type': 'l2update', 'product_id': 'BTC-USD', 'changes': [['buy', '38235.55', '0.00000000']], 'time': '2021-05-20T03:54:47.850297Z'}
{'type': 'l2update', 'product_id': 'BTC-USD', 'changes': [['sell', '38395.42', '0.03035199']], 'time': '2021-05-20T03:54:47.850884Z'}
{'type': 'l2update', 'product_id': 'BTC-USD', 'changes': [['sell', '38446.58', '0.01000000']], 'time': '2021-05-20T03:54:47.851562Z'}
{'type': 'l2update', 'product_id': 'BTC-USD', 'changes': [['sell', '38461.51', '0.01000000']], 'time': '2021-05-20T03:54:47.851811Z'}
{'type': 'l2update', 'product_id': 'BTC-USD', 'changes': [['sell', '38450.49', '0.00000000']], 'time': '2021-05-20T03:54:47.853278Z'}
{'type': 'l2update', 'product_id': 'BTC-USD', 'changes': [['sell', '38265.25', '0.36249352']], 'time': '2021-05-20T03:54:47.856574Z'}
{'type': 'l2update', 'product_id': 'BTC-USD', 'changes': [['sell', '38288.53', '0.45230000']], 'time': '2021-05-20T03:54:47.856796Z'}
{'type': 'l2update', 'product_id': 'BTC-USD', 'changes': [['buy', '38036.24', '0.00000000']], 'time': '2021-05-20T03:54:47.864081Z'}
{'type': 'l2update', 'product_id': 'BTC-USD', 'changes': [['sell', '38316.94', '0.61482417']], 'time': '2021-05-20T03:54:47.868481Z'}
{'type': 'l2update', 'product_id': 'BTC-USD', 'changes': [['sell', '38411.19', '0.01000000']], 'time': '2021-05-20T03:54:47.868900Z'}
{'type': 'l2update', 'product_id': 'BTC-USD', 'changes': [['buy', '38228.53', '0.02400000']], 'time': '2021-05-20T03:54:47.868916Z'}
{'type': 'l2update', 'product_id': 'BTC-USD', 'changes': [['buy', '38227.72', '0.02400000']], 'time': '2021-05-20T03:54:47.868916Z'}
{'type': 'l2update', 'product_id': 'BTC-USD', 'changes': [['buy', '38226.92', '0.02400000']], 'time': '2021-05-20T03:54:47.868916Z'}
{'type': 'l2update', 'product_id': 'BTC-USD', 'changes': [['sell', '38265.50', '0.06036972']], 'time': '2021-05-20T03:54:47.869206Z'}
{'type': 'l2update', 'product_id': 'BTC-USD', 'changes': [['buy', '38196.44', '1.28378287']], 'time': '2021-05-20T03:54:47.869405Z'}
{'type': 'l2update', 'product_id': 'BTC-USD', 'changes': [['sell', '49325.96', '0.00248100']], 'time': '2021-05-20T03:54:47.869415Z'}
{'type': 'l2update', 'product_id': 'BTC-USD', 'changes': [['sell', '38290.44', '0.46320331']], 'time': '2021-05-20T03:54:47.870341Z'}
{'type': 'l2update', 'product_id': 'BTC-USD', 'changes': [['buy', '38002.43', '0.95284709']], 'time': '2021-05-20T03:54:47.875947Z'}
{'type': 'l2update', 'product_id': 'BTC-USD', 'changes': [['sell', '38380.33', '0.02682805']], 'time': '2021-05-20T03:54:47.879634Z'}
{'type': 'l2update', 'product_id': 'BTC-USD', 'changes': [['sell', '38268.70', '1.66900000']], 'time': '2021-05-20T03:54:47.879882Z'}
{'type': 'l2update', 'product_id': 'BTC-USD', 'changes': [['sell', '38288.52', '0.05000000']], 'time': '2021-05-20T03:54:47.888752Z'}
{'type': 'l2update', 'product_id': 'BTC-USD', 'changes': [['sell', '38565.50', '3.22888320']], 'time': '2021-05-20T03:54:47.893857Z'}
{'type': 'l2update', 'product_id': 'BTC-USD', 'changes': [['buy', '38233.86', '0.00000000']], 'time': '2021-05-20T03:54:47.897288Z'}
{'type': 'l2update', 'product_id': 'BTC-USD', 'changes': [['sell', '38588.06', '0.00000000']], 'time': '2021-05-20T03:54:47.900985Z'}
{'type': 'l2update', 'product_id': 'BTC-USD', 'changes': [['buy', '38225.18', '0.49170000']], 'time': '2021-05-20T03:54:47.910708Z'}
{'type': 'l2update', 'product_id': 'BTC-USD', 'changes': [['buy', '38225.18', '0.00000000']], 'time': '2021-05-20T03:54:47.915983Z'}
{'type': 'l2update', 'product_id': 'BTC-USD', 'changes': [['buy', '38209.50', '0.02617150']], 'time': '2021-05-20T03:54:47.916215Z'}
{'type': 'l2update', 'product_id': 'BTC-USD', 'changes': [['buy', '38215.81', '0.00000000']], 'time': '2021-05-20T03:54:47.917297Z'}
{'type': 'l2update', 'product_id': 'BTC-USD', 'changes': [['buy', '38217.37', '0.00000000']], 'time': '2021-05-20T03:54:47.922520Z'}
{'type': 'l2update', 'product_id': 'BTC-USD', 'changes': [['sell', '38260.84', '0.39275083']], 'time': '2021-05-20T03:54:47.941826Z'}
{'type': 'l2update', 'product_id': 'BTC-USD', 'changes': [['sell', '38265.28', '1.56286052']], 'time': '2021-05-20T03:54:47.944767Z'}
{'type': 'l2update', 'product_id': 'BTC-USD', 'changes': [['buy', '38180.80', '0.00000000']], 'time': '2021-05-20T03:54:47.947678Z'}
{'type': 'l2update', 'product_id': 'BTC-USD', 'changes': [['sell', '38367.22', '0.36959275']], 'time': '2021-05-20T03:54:47.950090Z'}
{'type': 'l2update', 'product_id': 'BTC-USD', 'changes': [['buy', '38166.54', '0.01000000']], 'time': '2021-05-20T03:54:47.958128Z'}
{'type': 'l2update', 'product_id': 'BTC-USD', 'changes': [['sell', '38260.84', '0.89275083']], 'time': '2021-05-20T03:54:47.958483Z'}
{'type': 'l2update', 'product_id': 'BTC-USD', 'changes': [['buy', '38242.52', '0.00000000']], 'time': '2021-05-20T03:54:47.974044Z'}
{'type': 'l2update', 'product_id': 'BTC-USD', 'changes': [['sell', '38373.68', '0.33123855']], 'time': '2021-05-20T03:54:47.975363Z'}
{'type': 'l2update', 'product_id': 'BTC-USD', 'changes': [['sell', '38446.58', '0.00000000']], 'time': '2021-05-20T03:54:47.975800Z'}
{'type': 'l2update', 'product_id': 'BTC-USD', 'changes': [['buy', '38228.53', '0.00000000']], 'time': '2021-05-20T03:54:47.976555Z'}
{'type': 'l2update', 'product_id': 'BTC-USD', 'changes': [['buy', '38242.53', '0.00000000']], 'time': '2021-05-20T03:54:47.981514Z'}
{'type': 'l2update', 'product_id': 'BTC-USD', 'changes': [['sell', '38290.46', '0.00000000']], 'time': '2021-05-20T03:54:47.988023Z'}
{'type': 'l2update', 'product_id': 'BTC-USD', 'changes': [['sell', '38491.24', '0.01000000']], 'time': '2021-05-20T03:54:47.989742Z'}
{'type': 'l2update', 'product_id': 'BTC-USD', 'changes': [['buy', '38239.26', '0.58716278']], 'time': '2021-05-20T03:54:47.989909Z'}
{'type': 'l2update', 'product_id': 'BTC-USD', 'changes': [['buy', '38225.89', '0.02400000']], 'time': '2021-05-20T03:54:47.994329Z'}
{'type': 'l2update', 'product_id': 'BTC-USD', 'changes': [['sell', '38260.84', '0.88754956']], 'time': '2021-05-20T03:54:47.994396Z'}
{'type': 'l2update', 'product_id': 'BTC-USD', 'changes': [['buy', '38227.72', '0.00000000']], 'time': '2021-05-20T03:54:48.000011Z'}
{'type': 'l2update', 'product_id': 'BTC-USD', 'changes': [['buy', '38237.07', '0.22867204']], 'time': '2021-05-20T03:54:48.005051Z'}
{'type': 'l2update', 'product_id': 'BTC-USD', 'changes': [['sell', '38297.37', '0.10000000']], 'time': '2021-05-20T03:54:48.005225Z'}
{'type': 'l2update', 'product_id': 'BTC-USD', 'changes': [['buy', '38246.45', '0.84800000']], 'time': '2021-05-20T03:54:48.005400Z'}
{'type': 'l2update', 'product_id': 'BTC-USD', 'changes': [['sell', '38260.84', '2.17546239']], 'time': '2021-05-20T03:54:48.005541Z'}
{'type': 'l2update', 'product_id': 'BTC-USD', 'changes': [['sell', '38380.33', '0.39388295']], 'time': '2021-05-20T03:54:48.005727Z'}
{'type': 'l2update', 'product_id': 'BTC-USD', 'changes': [['buy', '38226.42', '0.43980000']], 'time': '2021-05-20T03:54:48.010153Z'}
{'type': 'l2update', 'product_id': 'BTC-USD', 'changes': [['sell', '38351.57', '0.05712409']], 'time': '2021-05-20T03:54:48.010585Z'}
{'type': 'l2update', 'product_id': 'BTC-USD', 'changes': [['buy', '38224.71', '0.02400000']], 'time': '2021-05-20T03:54:48.015198Z'}
{'type': 'l2update', 'product_id': 'BTC-USD', 'changes': [['buy', '38239.27', '0.06460106']], 'time': '2021-05-20T03:54:48.015580Z'}
{'type': 'l2update', 'product_id': 'BTC-USD', 'changes': [['sell', '38265.00', '0.05139670']], 'time': '2021-05-20T03:54:48.016344Z'}
{'type': 'l2update', 'product_id': 'BTC-USD', 'changes': [['buy', '38247.53', '0.04986300']], 'time': '2021-05-20T03:54:48.016481Z'}
{'type': 'l2update', 'product_id': 'BTC-USD', 'changes': [['sell', '38281.68', '0.04815623']], 'time': '2021-05-20T03:54:48.016729Z'}
{'type': 'l2update', 'product_id': 'BTC-USD', 'changes': [['buy', '38226.42', '0.00000000']], 'time': '2021-05-20T03:54:48.017009Z'}
{'type': 'l2update', 'product_id': 'BTC-USD', 'changes': [['buy', '38237.06', '0.00000000']], 'time': '2021-05-20T03:54:48.018627Z'}
{'type': 'l2update', 'product_id': 'BTC-USD', 'changes': [['buy', '38181.87', '0.00000000']], 'time': '2021-05-20T03:54:48.023590Z'}
{'type': 'l2update', 'product_id': 'BTC-USD', 'changes': [['sell', '38288.53', '0.00000000']], 'time': '2021-05-20T03:54:48.025097Z'}
{'type': 'l2update', 'product_id': 'BTC-USD', 'changes': [['sell', '38316.67', '0.00000000']], 'time': '2021-05-20T03:54:48.030694Z'}
{'type': 'l2update', 'product_id': 'BTC-USD', 'changes': [['sell', '38288.52', '0.00000000']], 'time': '2021-05-20T03:54:48.033257Z'}
{'type': 'l2update', 'product_id': 'BTC-USD', 'changes': [['sell', '38387.17', '0.40040932']], 'time': '2021-05-20T03:54:48.033536Z'}
{'type': 'l2update', 'product_id': 'BTC-USD', 'changes': [['sell', '49336.53', '0.00248100']], 'time': '2021-05-20T03:54:48.033884Z'}
{'type': 'l2update', 'product_id': 'BTC-USD', 'changes': [['sell', '38265.50', '0.00000000']], 'time': '2021-05-20T03:54:48.036188Z'}
{'type': 'l2update', 'product_id': 'BTC-USD', 'changes': [['sell', '38286.96', '0.43500000']], 'time': '2021-05-20T03:54:48.038374Z'}
{'type': 'l2update', 'product_id': 'BTC-USD', 'changes': [['buy', '38205.10', '0.00000000']], 'time': '2021-05-20T03:54:48.039391Z'}
{'type': 'l2update', 'product_id': 'BTC-USD', 'changes': [['buy', '38260.83', '0.00007420']], 'time': '2021-05-20T03:54:48.041906Z'}
{'type': 'l2update', 'product_id': 'BTC-USD', 'changes': [['sell', '38290.43', '0.05000000']], 'time': '2021-05-20T03:54:48.052888Z'}
{'type': 'l2update', 'product_id': 'BTC-USD', 'changes': [['buy', '38246.40', '0.00000000']], 'time': '2021-05-20T03:54:48.053241Z'}
{'type': 'l2update', 'product_id': 'BTC-USD', 'changes': [['buy', '38233.45', '0.00000000']], 'time': '2021-05-20T03:54:48.055795Z'}
{'type': 'l2update', 'product_id': 'BTC-USD', 'changes': [['sell', '38270.04', '0.15979072']], 'time': '2021-05-20T03:54:48.055818Z'}
{'type': 'l2update', 'product_id': 'BTC-USD', 'changes': [['sell', '38307.91', '0.00000000']], 'time': '2021-05-20T03:54:48.059257Z'}
{'type': 'l2update', 'product_id': 'BTC-USD', 'changes': [['sell', '38290.43', '0.00000000']], 'time': '2021-05-20T03:54:48.060315Z'}
{'type': 'l2update', 'product_id': 'BTC-USD', 'changes': [['buy', '38230.73', '0.00000000']], 'time': '2021-05-20T03:54:48.062126Z'}
{'type': 'l2update', 'product_id': 'BTC-USD', 'changes': [['buy', '38246.45', '0.00000000']], 'time': '2021-05-20T03:54:48.062827Z'}
{'type': 'l2update', 'product_id': 'BTC-USD', 'changes': [['buy', '38239.26', '0.00000000']], 'time': '2021-05-20T03:54:48.063828Z'}
{'type': 'l2update', 'product_id': 'BTC-USD', 'changes': [['buy', '38237.07', '0.00000000']], 'time': '2021-05-20T03:54:48.069281Z'}
{'type': 'l2update', 'product_id': 'BTC-USD', 'changes': [['sell', '38351.57', '0.02987631']], 'time': '2021-05-20T03:54:48.071633Z'}
{'type': 'l2update', 'product_id': 'BTC-USD', 'changes': [['sell', '38296.33', '0.03207306']], 'time': '2021-05-20T03:54:48.077844Z'}
{'type': 'l2update', 'product_id': 'BTC-USD', 'changes': [['sell', '38282.73', '0.05000000']], 'time': '2021-05-20T03:54:48.078346Z'}
{'type': 'l2update', 'product_id': 'BTC-USD', 'changes': [['sell', '38520.00', '0.19720000']], 'time': '2021-05-20T03:54:48.078492Z'}
{'type': 'l2update', 'product_id': 'BTC-USD', 'changes': [['sell', '38286.95', '0.05000000']], 'time': '2021-05-20T03:54:48.078868Z'}
{'type': 'l2update', 'product_id': 'BTC-USD', 'changes': [['buy', '38226.92', '0.00000000']], 'time': '2021-05-20T03:54:48.080359Z'}
{'type': 'l2update', 'product_id': 'BTC-USD', 'changes': [['buy', '38225.89', '0.00000000']], 'time': '2021-05-20T03:54:48.080359Z'}
{'type': 'l2update', 'product_id': 'BTC-USD', 'changes': [['buy', '38247.53', '0.00000000']], 'time': '2021-05-20T03:54:48.080407Z'}
{'type': 'l2update', 'product_id': 'BTC-USD', 'changes': [['sell', '38286.96', '0.00000000']], 'time': '2021-05-20T03:54:48.081877Z'}
{'type': 'l2update', 'product_id': 'BTC-USD', 'changes': [['sell', '38301.60', '0.00000000']], 'time': '2021-05-20T03:54:48.082756Z'}
{'type': 'l2update', 'product_id': 'BTC-USD', 'changes': [['buy', '38237.05', '0.58716278']], 'time': '2021-05-20T03:54:48.085654Z'}
{'type': 'l2update', 'product_id': 'BTC-USD', 'changes': [['buy', '38159.08', '0.64718833']], 'time': '2021-05-20T03:54:48.086158Z'}
{'type': 'l2update', 'product_id': 'BTC-USD', 'changes': [['sell', '38265.50', '0.04465876']], 'time': '2021-05-20T03:54:48.088190Z'}
{'type': 'l2update', 'product_id': 'BTC-USD', 'changes': [['buy', '38224.71', '0.00000000']], 'time': '2021-05-20T03:54:48.089856Z'}
{'type': 'l2update', 'product_id': 'BTC-USD', 'changes': [['buy', '38239.27', '0.00000000']], 'time': '2021-05-20T03:54:48.094654Z'}
{'type': 'l2update', 'product_id': 'BTC-USD', 'changes': [['sell', '38491.24', '0.00000000']], 'time': '2021-05-20T03:54:48.094827Z'}
{'type': 'l2update', 'product_id': 'BTC-USD', 'changes': [['buy', '38237.08', '0.06460106']], 'time': '2021-05-20T03:54:48.100153Z'}
{'type': 'l2update', 'product_id': 'BTC-USD', 'changes': [['buy', '38237.05', '0.81583482']], 'time': '2021-05-20T03:54:48.100583Z'}
{'type': 'l2update', 'product_id': 'BTC-USD', 'changes': [['sell', '38270.03', '0.06460106']], 'time': '2021-05-20T03:54:48.100609Z'}
{'type': 'l2update', 'product_id': 'BTC-USD', 'changes': [['sell', '38291.62', '0.00000000']], 'time': '2021-05-20T03:54:48.102188Z'}
{'type': 'l2update', 'product_id': 'BTC-USD', 'changes': [['buy', '38224.75', '0.00000000']], 'time': '2021-05-20T03:54:48.103685Z'}
{'type': 'l2update', 'product_id': 'BTC-USD', 'changes': [['sell', '38277.45', '0.00000000']], 'time': '2021-05-20T03:54:48.106407Z'}
{'type': 'l2update', 'product_id': 'BTC-USD', 'changes': [['sell', '38270.03', '0.00000000']], 'time': '2021-05-20T03:54:48.114620Z'}
{'type': 'l2update', 'product_id': 'BTC-USD', 'changes': [['buy', '38181.68', '0.00000000']], 'time': '2021-05-20T03:54:48.114840Z'}
{'type': 'l2update', 'product_id': 'BTC-USD', 'changes': [['sell', '38268.77', '0.00000000']], 'time': '2021-05-20T03:54:48.115488Z'}
{'type': 'l2update', 'product_id': 'BTC-USD', 'changes': [['buy', '38221.46', '0.47860000']], 'time': '2021-05-20T03:54:48.115700Z'}
{'type': 'l2update', 'product_id': 'BTC-USD', 'changes': [['buy', '38221.64', '0.02400000']], 'time': '2021-05-20T03:54:48.116408Z'}
{'type': 'l2update', 'product_id': 'BTC-USD', 'changes': [['buy', '38220.83', '0.02400000']], 'time': '2021-05-20T03:54:48.116408Z'}
{'type': 'l2update', 'product_id': 'BTC-USD', 'changes': [['buy', '38220.03', '0.02400000']], 'time': '2021-05-20T03:54:48.116408Z'}
{'type': 'l2update', 'product_id': 'BTC-USD', 'changes': [['sell', '38478.03', '0.01000000']], 'time': '2021-05-20T03:54:48.116604Z'}
{'type': 'l2update', 'product_id': 'BTC-USD', 'changes': [['buy', '38260.83', '0.00183936']], 'time': '2021-05-20T03:54:48.116794Z'}
{'type': 'l2update', 'product_id': 'BTC-USD', 'changes': [['sell', '38380.33', '0.43115571']], 'time': '2021-05-20T03:54:48.116877Z'}
{'type': 'l2update', 'product_id': 'BTC-USD', 'changes': [['buy', '38199.18', '0.49441735']], 'time': '2021-05-20T03:54:48.122699Z'}
{'type': 'l2update', 'product_id': 'BTC-USD', 'changes': [['buy', '38230.85', '0.00000000']], 'time': '2021-05-20T03:54:48.122699Z'}
{'type': 'l2update', 'product_id': 'BTC-USD', 'changes': [['buy', '38249.99', '0.00000000']], 'time': '2021-05-20T03:54:48.122699Z'}
{'type': 'l2update', 'product_id': 'BTC-USD', 'changes': [['sell', '38260.84', '2.21146239']], 'time': '2021-05-20T03:54:48.127969Z'}
{'type': 'l2update', 'product_id': 'BTC-USD', 'changes': [['sell', '38270.03', '0.06460106']], 'time': '2021-05-20T03:54:48.132059Z'}
{'type': 'l2update', 'product_id': 'BTC-USD', 'changes': [['buy', '38242.49', '0.00000000']], 'time': '2021-05-20T03:54:48.132775Z'}
{'type': 'l2update', 'product_id': 'BTC-USD', 'changes': [['sell', '38292.71', '0.10000000']], 'time': '2021-05-20T03:54:48.133890Z'}
{'type': 'l2update', 'product_id': 'BTC-USD', 'changes': [['sell', '38324.08', '0.50000000']], 'time': '2021-05-20T03:54:48.134429Z'}
{'type': 'l2update', 'product_id': 'BTC-USD', 'changes': [['buy', '38221.46', '0.00000000']], 'time': '2021-05-20T03:54:48.138947Z'}
{'type': 'l2update', 'product_id': 'BTC-USD', 'changes': [['sell', '38360.95', '0.00000000']], 'time': '2021-05-20T03:54:48.140595Z'}
{'type': 'l2update', 'product_id': 'BTC-USD', 'changes': [['sell', '38356.94', '0.00000000']], 'time': '2021-05-20T03:54:48.140595Z'}
{'type': 'l2update', 'product_id': 'BTC-USD', 'changes': [['sell', '38351.57', '0.00000000']], 'time': '2021-05-20T03:54:48.140595Z'}
{'type': 'l2update', 'product_id': 'BTC-USD', 'changes': [['sell', '38336.57', '0.00000000']], 'time': '2021-05-20T03:54:48.140595Z'}
{'type': 'l2update', 'product_id': 'BTC-USD', 'changes': [['sell', '38322.35', '0.00000000']], 'time': '2021-05-20T03:54:48.140595Z'}
{'type': 'l2update', 'product_id': 'BTC-USD', 'changes': [['sell', '38313.82', '0.00000000']], 'time': '2021-05-20T03:54:48.140595Z'}
{'type': 'l2update', 'product_id': 'BTC-USD', 'changes': [['sell', '38306.05', '0.00000000']], 'time': '2021-05-20T03:54:48.140595Z'}
{'type': 'l2update', 'product_id': 'BTC-USD', 'changes': [['buy', '38196.55', '0.00000000']], 'time': '2021-05-20T03:54:48.140595Z'}
{'type': 'l2update', 'product_id': 'BTC-USD', 'changes': [['sell', '38595.61', '0.00000000']], 'time': '2021-05-20T03:54:48.141696Z'}
{'type': 'l2update', 'product_id': 'BTC-USD', 'changes': [['sell', '38264.95', '0.60200000']], 'time': '2021-05-20T03:54:48.142501Z'}
{'type': 'l2update', 'product_id': 'BTC-USD', 'changes': [['buy', '38167.55', '0.01000000']], 'time': '2021-05-20T03:54:48.147190Z'}
{'type': 'l2update', 'product_id': 'BTC-USD', 'changes': [['sell', '38478.03', '0.00000000']], 'time': '2021-05-20T03:54:48.148077Z'}
{'type': 'l2update', 'product_id': 'BTC-USD', 'changes': [['sell', '38395.42', '0.00000000']], 'time': '2021-05-20T03:54:48.150474Z'}
{'type': 'l2update', 'product_id': 'BTC-USD', 'changes': [['sell', '38411.19', '0.00000000']], 'time': '2021-05-20T03:54:48.153153Z'}
{'type': 'l2update', 'product_id': 'BTC-USD', 'changes': [['sell', '38295.82', '1.20204919']], 'time': '2021-05-20T03:54:48.154076Z'}
{'type': 'l2update', 'product_id': 'BTC-USD', 'changes': [['buy', '38237.05', '0.58716278']], 'time': '2021-05-20T03:54:48.154736Z'}
{'type': 'l2update', 'product_id': 'BTC-USD', 'changes': [['sell', '38265.25', '0.00000000']], 'time': '2021-05-20T03:54:48.155248Z'}
{'type': 'l2update', 'product_id': 'BTC-USD', 'changes': [['buy', '38219.61', '0.04781696']], 'time': '2021-05-20T03:54:48.158121Z'}
{'type': 'l2update', 'product_id': 'BTC-USD', 'changes': [['buy', '38256.82', '0.00000000']], 'time': '2021-05-20T03:54:48.158237Z'}
{'type': 'l2update', 'product_id': 'BTC-USD', 'changes': [['sell', '38270.03', '0.00000000']], 'time': '2021-05-20T03:54:48.158806Z'}
{'type': 'l2update', 'product_id': 'BTC-USD', 'changes': [['sell', '38308.78', '0.00000000']], 'time': '2021-05-20T03:54:48.164461Z'}
{'type': 'l2update', 'product_id': 'BTC-USD', 'changes': [['sell', '38381.56', '0.02168000']], 'time': '2021-05-20T03:54:48.166225Z'}
{'type': 'l2update', 'product_id': 'BTC-USD', 'changes': [['sell', '38441.84', '0.01000000']], 'time': '2021-05-20T03:54:48.166693Z'}
{'type': 'l2update', 'product_id': 'BTC-USD', 'changes': [['sell', '38277.45', '0.06460106']], 'time': '2021-05-20T03:54:48.166711Z'}
{'type': 'l2update', 'product_id': 'BTC-USD', 'changes': [['sell', '38260.84', '2.21078729']], 'time': '2021-05-20T03:54:48.175102Z'}
{'type': 'l2update', 'product_id': 'BTC-USD', 'changes': [['sell', '38538.46', '0.00000000']], 'time': '2021-05-20T03:54:48.178949Z'}
{'type': 'l2update', 'product_id': 'BTC-USD', 'changes': [['sell', '38277.45', '0.00000000']], 'time': '2021-05-20T03:54:48.179745Z'}
{'type': 'l2update', 'product_id': 'BTC-USD', 'changes': [['sell', '38286.61', '0.49940000']], 'time': '2021-05-20T03:54:48.180112Z'}
{'type': 'l2update', 'product_id': 'BTC-USD', 'changes': [['buy', '38194.75', '0.20400000']], 'time': '2021-05-20T03:54:48.180583Z'}
{'type': 'l2update', 'product_id': 'BTC-USD', 'changes': [['buy', '38213.88', '0.06600000']], 'time': '2021-05-20T03:54:48.180583Z'}
{'type': 'l2update', 'product_id': 'BTC-USD', 'changes': [['buy', '38156.50', '0.66500000']], 'time': '2021-05-20T03:54:48.180583Z'}
{'type': 'l2update', 'product_id': 'BTC-USD', 'changes': [['sell', '38260.84', '0.92287446']], 'time': '2021-05-20T03:54:48.181284Z'}
{'type': 'l2update', 'product_id': 'BTC-USD', 'changes': [['sell', '38270.03', '0.06460106']], 'time': '2021-05-20T03:54:48.184176Z'}
{'type': 'l2update', 'product_id': 'BTC-USD', 'changes': [['sell', '38323.65', '0.13870000']], 'time': '2021-05-20T03:54:48.184271Z'}
{'type': 'l2update', 'product_id': 'BTC-USD', 'changes': [['sell', '38264.94', '0.36249352']], 'time': '2021-05-20T03:54:48.184396Z'}
{'type': 'l2update', 'product_id': 'BTC-USD', 'changes': [['buy', '38237.09', '0.22867204']], 'time': '2021-05-20T03:54:48.185896Z'}
{'type': 'l2update', 'product_id': 'BTC-USD', 'changes': [['sell', '38363.16', '0.00000000']], 'time': '2021-05-20T03:54:48.187471Z'}
{'type': 'l2update', 'product_id': 'BTC-USD', 'changes': [['sell', '38316.93', '0.00000000']], 'time': '2021-05-20T03:54:48.189056Z'}
{'type': 'l2update', 'product_id': 'BTC-USD', 'changes': [['sell', '38426.55', '0.01237351']], 'time': '2021-05-20T03:54:48.189402Z'}
{'type': 'l2update', 'product_id': 'BTC-USD', 'changes': [['buy', '38181.87', '0.02400000']], 'time': '2021-05-20T03:54:48.189508Z'}
{'type': 'l2update', 'product_id': 'BTC-USD', 'changes': [['sell', '49350.63', '0.00248100']], 'time': '2021-05-20T03:54:48.189669Z'}
{'type': 'l2update', 'product_id': 'BTC-USD', 'changes': [['sell', '38286.95', '0.00000000']], 'time': '2021-05-20T03:54:48.190354Z'}
{'type': 'l2update', 'product_id': 'BTC-USD', 'changes': [['sell', '38568.45', '0.01296396']], 'time': '2021-05-20T03:54:48.193892Z'}
{'type': 'l2update', 'product_id': 'BTC-USD', 'changes': [['sell', '38270.03', '0.00000000']], 'time': '2021-05-20T03:54:48.194749Z'}
{'type': 'l2update', 'product_id': 'BTC-USD', 'changes': [['sell', '38265.28', '0.00000000']], 'time': '2021-05-20T03:54:48.194943Z'}
{'type': 'l2update', 'product_id': 'BTC-USD', 'changes': [['sell', '38317.69', '0.38134239']], 'time': '2021-05-20T03:54:48.201810Z'}
{'type': 'l2update', 'product_id': 'BTC-USD', 'changes': [['sell', '38313.14', '0.02682805']], 'time': '2021-05-20T03:54:48.201810Z'}
{'type': 'l2update', 'product_id': 'BTC-USD', 'changes': [['sell', '38304.61', '0.03727276']], 'time': '2021-05-20T03:54:48.201810Z'}
{'type': 'l2update', 'product_id': 'BTC-USD', 'changes': [['sell', '38296.84', '0.03720862']], 'time': '2021-05-20T03:54:48.201810Z'}
{'type': 'l2update', 'product_id': 'BTC-USD', 'changes': [['sell', '38293.24', '0.01414498']], 'time': '2021-05-20T03:54:48.201810Z'}
{'type': 'l2update', 'product_id': 'BTC-USD', 'changes': [['buy', '38127.87', '0.03367571']], 'time': '2021-05-20T03:54:48.201810Z'}
{'type': 'l2update', 'product_id': 'BTC-USD', 'changes': [['buy', '38070.66', '0.00000000']], 'time': '2021-05-20T03:54:48.203859Z'}
{'type': 'l2update', 'product_id': 'BTC-USD', 'changes': [['sell', '38286.60', '0.05000000']], 'time': '2021-05-20T03:54:48.206674Z'}
{'type': 'l2update', 'product_id': 'BTC-USD', 'changes': [['sell', '38351.56', '0.02943450']], 'time': '2021-05-20T03:54:48.206856Z'}
{'type': 'l2update', 'product_id': 'BTC-USD', 'changes': [['sell', '38316.67', '2.16932808']], 'time': '2021-05-20T03:54:48.207160Z'}
{'type': 'l2update', 'product_id': 'BTC-USD', 'changes': [['sell', '38270.66', '0.04999781']], 'time': '2021-05-20T03:54:48.207661Z'}
{'type': 'l2update', 'product_id': 'BTC-USD', 'changes': [['buy', '38048.39', '0.04575777']], 'time': '2021-05-20T03:54:48.207743Z'}
{'type': 'l2update', 'product_id': 'BTC-USD', 'changes': [['sell', '38268.75', '0.00000000']], 'time': '2021-05-20T03:54:48.209340Z'}
{'type': 'l2update', 'product_id': 'BTC-USD', 'changes': [['sell', '38380.33', '0.40432766']], 'time': '2021-05-20T03:54:48.210390Z'}
{'type': 'l2update', 'product_id': 'BTC-USD', 'changes': [['sell', '38380.33', '0.36705490']], 'time': '2021-05-20T03:54:48.210390Z'}
{'type': 'l2update', 'product_id': 'BTC-USD', 'changes': [['sell', '38373.68', '0.29402993']], 'time': '2021-05-20T03:54:48.210390Z'}
{'type': 'l2update', 'product_id': 'BTC-USD', 'changes': [['sell', '38367.22', '0.33423030']], 'time': '2021-05-20T03:54:48.210390Z'}
{'type': 'l2update', 'product_id': 'BTC-USD', 'changes': [['sell', '38277.15', '0.05000000']], 'time': '2021-05-20T03:54:48.211772Z'}
{'type': 'l2update', 'product_id': 'BTC-USD', 'changes': [['sell', '38263.75', '0.05139526']], 'time': '2021-05-20T03:54:48.215878Z'}
{'type': 'l2update', 'product_id': 'BTC-USD', 'changes': [['buy', '38198.57', '0.00000000']], 'time': '2021-05-20T03:54:48.217400Z'}
{'type': 'l2update', 'product_id': 'BTC-USD', 'changes': [['buy', '38247.29', '0.01565774']], 'time': '2021-05-20T03:54:48.218393Z'}
{'type': 'l2update', 'product_id': 'BTC-USD', 'changes': [['sell', '38568.45', '0.00000000']], 'time': '2021-05-20T03:54:48.220158Z'}
{'type': 'l2update', 'product_id': 'BTC-USD', 'changes': [['sell', '38354.87', '0.44143833']], 'time': '2021-05-20T03:54:48.223363Z'}
{'type': 'l2update', 'product_id': 'BTC-USD', 'changes': [['buy', '38203.57', '0.10000000']], 'time': '2021-05-20T03:54:48.229359Z'}
{'type': 'l2update', 'product_id': 'BTC-USD', 'changes': [['buy', '38220.93', '0.43020000']], 'time': '2021-05-20T03:54:48.238108Z'}
{'type': 'l2update', 'product_id': 'BTC-USD', 'changes': [['buy', '38255.99', '0.01045686']], 'time': '2021-05-20T03:54:48.243890Z'}
{'type': 'l2update', 'product_id': 'BTC-USD', 'changes': [['sell', '38441.84', '0.00000000']], 'time': '2021-05-20T03:54:48.246129Z'}
{'type': 'l2update', 'product_id': 'BTC-USD', 'changes': [['sell', '38553.46', '0.01296900']], 'time': '2021-05-20T03:54:48.248853Z'}
{'type': 'l2update', 'product_id': 'BTC-USD', 'changes': [['buy', '38207.28', '0.05457141']], 'time': '2021-05-20T03:54:48.249098Z'}
{'type': 'l2update', 'product_id': 'BTC-USD', 'changes': [['sell', '38262.22', '0.01040661']], 'time': '2021-05-20T03:54:48.250632Z'}
{'type': 'l2update', 'product_id': 'BTC-USD', 'changes': [['sell', '38332.48', '0.44718769']], 'time': '2021-05-20T03:54:48.250727Z'}
{'type': 'l2update', 'product_id': 'BTC-USD', 'changes': [['buy', '38209.49', '2.64100682']], 'time': '2021-05-20T03:54:48.255291Z'}
{'type': 'l2update', 'product_id': 'BTC-USD', 'changes': [['sell', '38263.75', '0.00000000']], 'time': '2021-05-20T03:54:48.263159Z'}
{'type': 'l2update', 'product_id': 'BTC-USD', 'changes': [['sell', '38281.68', '0.00000000']], 'time': '2021-05-20T03:54:48.263226Z'}
{'type': 'l2update', 'product_id': 'BTC-USD', 'changes': [['sell', '38456.92', '0.01000000']], 'time': '2021-05-20T03:54:48.265386Z'}
{'type': 'l2update', 'product_id': 'BTC-USD', 'changes': [['buy', '38219.61', '0.00000000']], 'time': '2021-05-20T03:54:48.268423Z'}
{'type': 'l2update', 'product_id': 'BTC-USD', 'changes': [['sell', '38270.04', '0.15000000']], 'time': '2021-05-20T03:54:48.271116Z'}
{'type': 'l2update', 'product_id': 'BTC-USD', 'changes': [['buy', '38181.87', '0.00000000']], 'time': '2021-05-20T03:54:48.274568Z'}
{'type': 'l2update', 'product_id': 'BTC-USD', 'changes': [['buy', '38255.99', '0.00000000']], 'time': '2021-05-20T03:54:48.278163Z'}
{'type': 'l2update', 'product_id': 'BTC-USD', 'changes': [['sell', '38316.67', '0.00000000']], 'time': '2021-05-20T03:54:48.280131Z'}
{'type': 'l2update', 'product_id': 'BTC-USD', 'changes': [['sell', '38265.26', '0.00000000']], 'time': '2021-05-20T03:54:48.281450Z'}
{'type': 'l2update', 'product_id': 'BTC-USD', 'changes': [['sell', '38337.79', '0.03677873']], 'time': '2021-05-20T03:54:48.282399Z'}
{'type': 'l2update', 'product_id': 'BTC-USD', 'changes': [['sell', '38381.56', '0.00000000']], 'time': '2021-05-20T03:54:48.282509Z'}
{'type': 'l2update', 'product_id': 'BTC-USD', 'changes': [['sell', '38456.92', '0.00000000']], 'time': '2021-05-20T03:54:48.283016Z'}
{'type': 'l2update', 'product_id': 'BTC-USD', 'changes': [['sell', '38265.50', '0.00000000']], 'time': '2021-05-20T03:54:48.288482Z'}
{'type': 'l2update', 'product_id': 'BTC-USD', 'changes': [['sell', '38262.22', '0.00000000']], 'time': '2021-05-20T03:54:48.288570Z'}
{'type': 'l2update', 'product_id': 'BTC-USD', 'changes': [['buy', '38239.30', '0.84900000']], 'time': '2021-05-20T03:54:48.291088Z'}
{'type': 'l2update', 'product_id': 'BTC-USD', 'changes': [['sell', '38438.08', '0.01000000']], 'time': '2021-05-20T03:54:48.294575Z'}
{'type': 'l2update', 'product_id': 'BTC-USD', 'changes': [['sell', '38264.94', '0.00000000']], 'time': '2021-05-20T03:54:48.297701Z'}
{'type': 'l2update', 'product_id': 'BTC-USD', 'changes': [['buy', '38220.93', '0.00000000']], 'time': '2021-05-20T03:54:48.298304Z'}
{'type': 'l2update', 'product_id': 'BTC-USD', 'changes': [['buy', '38237.09', '0.00000000']], 'time': '2021-05-20T03:54:48.300936Z'}
{'type': 'l2update', 'product_id': 'BTC-USD', 'changes': [['sell', '38260.84', '3.41257354']], 'time': '2021-05-20T03:54:48.302685Z'}
{'type': 'l2update', 'product_id': 'BTC-USD', 'changes': [['sell', '38367.70', '0.02168000']], 'time': '2021-05-20T03:54:48.303349Z'}
{'type': 'l2update', 'product_id': 'BTC-USD', 'changes': [['buy', '38220.28', '0.04912078']], 'time': '2021-05-20T03:54:48.303543Z'}
{'type': 'l2update', 'product_id': 'BTC-USD', 'changes': [['sell', '38265.27', '0.06474287']], 'time': '2021-05-20T03:54:48.303543Z'}
{'type': 'l2update', 'product_id': 'BTC-USD', 'changes': [['sell', '38348.98', '0.42692310']], 'time': '2021-05-20T03:54:48.306965Z'}
{'type': 'l2update', 'product_id': 'BTC-USD', 'changes': [['buy', '38167.55', '0.00000000']], 'time': '2021-05-20T03:54:48.309431Z'}
{'type': 'l2update', 'product_id': 'BTC-USD', 'changes': [['sell', '38260.84', '0.92287446']], 'time': '2021-05-20T03:54:48.310362Z'}
{'type': 'l2update', 'product_id': 'BTC-USD', 'changes': [['sell', '38264.94', '0.36249352']], 'time': '2021-05-20T03:54:48.318479Z'}
{'type': 'l2update', 'product_id': 'BTC-USD', 'changes': [['sell', '38339.89', '0.00000000']], 'time': '2021-05-20T03:54:48.320653Z'}
{'type': 'l2update', 'product_id': 'BTC-USD', 'changes': [['buy', '38239.31', '0.22867204']], 'time': '2021-05-20T03:54:48.323057Z'}
{'type': 'l2update', 'product_id': 'BTC-USD', 'changes': [['buy', '38247.29', '0.00000000']], 'time': '2021-05-20T03:54:48.326015Z'}
{'type': 'l2update', 'product_id': 'BTC-USD', 'changes': [['sell', '38270.04', '0.00000000']], 'time': '2021-05-20T03:54:48.331741Z'}
{'type': 'l2update', 'product_id': 'BTC-USD', 'changes': [['sell', '38317.68', '0.02609761']], 'time': '2021-05-20T03:54:48.334680Z'}
{'type': 'l2update', 'product_id': 'BTC-USD', 'changes': [['sell', '38264.94', '2.85219260']], 'time': '2021-05-20T03:54:48.334816Z'}
{'type': 'l2update', 'product_id': 'BTC-USD', 'changes': [['buy', '38151.65', '0.01000000']], 'time': '2021-05-20T03:54:48.335739Z'}
{'type': 'l2update', 'product_id': 'BTC-USD', 'changes': [['sell', '38360.95', '0.02653759']], 'time': '2021-05-20T03:54:48.335773Z'}
{'type': 'l2update', 'product_id': 'BTC-USD', 'changes': [['sell', '38277.15', '0.00000000']], 'time': '2021-05-20T03:54:48.336516Z'}
{'type': 'l2update', 'product_id': 'BTC-USD', 'changes': [['buy', '38242.29', '0.01565774']], 'time': '2021-05-20T03:54:48.347629Z'}
{'type': 'l2update', 'product_id': 'BTC-USD', 'changes': [['sell', '38270.66', '0.00000000']], 'time': '2021-05-20T03:54:48.360601Z'}
{'type': 'l2update', 'product_id': 'BTC-USD', 'changes': [['buy', '38054.70', '0.00000000']], 'time': '2021-05-20T03:54:48.360698Z'}
{'type': 'l2update', 'product_id': 'BTC-USD', 'changes': [['sell', '38264.95', '0.00000000']], 'time': '2021-05-20T03:54:48.363188Z'}
{'type': 'l2update', 'product_id': 'BTC-USD', 'changes': [['buy', '38199.36', '0.12278909']], 'time': '2021-05-20T03:54:48.364556Z'}
{'type': 'l2update', 'product_id': 'BTC-USD', 'changes': [['buy', '38260.83', '0.01183936']], 'time': '2021-05-20T03:54:48.364593Z'}
{'type': 'l2update', 'product_id': 'BTC-USD', 'changes': [['buy', '38248.03', '0.05023522']], 'time': '2021-05-20T03:54:48.364610Z'}
{'type': 'l2update', 'product_id': 'BTC-USD', 'changes': [['buy', '38223.16', '0.04853847']], 'time': '2021-05-20T03:54:48.368277Z'}
{'type': 'l2update', 'product_id': 'BTC-USD', 'changes': [['sell', '38367.22', '0.37303707']], 'time': '2021-05-20T03:54:48.368774Z'}
{'type': 'l2update', 'product_id': 'BTC-USD', 'changes': [['sell', '38264.94', '2.48969908']], 'time': '2021-05-20T03:54:48.370954Z'}
{'type': 'l2update', 'product_id': 'BTC-USD', 'changes': [['sell', '38384.71', '0.00000000']], 'time': '2021-05-20T03:54:48.372445Z'}
{'type': 'l2update', 'product_id': 'BTC-USD', 'changes': [['sell', '49354.51', '0.00544700']], 'time': '2021-05-20T03:54:48.375115Z'}
{'type': 'l2update', 'product_id': 'BTC-USD', 'changes': [['buy', '38010.00', '0.31203546']], 'time': '2021-05-20T03:54:48.375362Z'}
{'type': 'l2update', 'product_id': 'BTC-USD', 'changes': [['buy', '38260.83', '0.03183936']], 'time': '2021-05-20T03:54:48.379878Z'}
{'type': 'l2update', 'product_id': 'BTC-USD', 'changes': [['sell', '38260.84', '0.42287446']], 'time': '2021-05-20T03:54:48.381439Z'}
{'type': 'l2update', 'product_id': 'BTC-USD', 'changes': [['buy', '38220.28', '0.00000000']], 'time': '2021-05-20T03:54:48.387149Z'}
{'type': 'l2update', 'product_id': 'BTC-USD', 'changes': [['sell', '38265.27', '0.00000000']], 'time': '2021-05-20T03:54:48.387149Z'}
{'type': 'l2update', 'product_id': 'BTC-USD', 'changes': [['sell', '38370.96', '0.01303069']], 'time': '2021-05-20T03:54:48.388892Z'}
{'type': 'l2update', 'product_id': 'BTC-USD', 'changes': [['buy', '38225.24', '0.40150000']], 'time': '2021-05-20T03:54:48.388926Z'}
{'type': 'l2update', 'product_id': 'BTC-USD', 'changes': [['sell', '38268.70', '0.59300000']], 'time': '2021-05-20T03:54:48.393925Z'}
{'type': 'l2update', 'product_id': 'BTC-USD', 'changes': [['buy', '38260.83', '0.06183936']], 'time': '2021-05-20T03:54:48.394410Z'}
{'type': 'l2update', 'product_id': 'BTC-USD', 'changes': [['sell', '38268.70', '0.00000000']], 'time': '2021-05-20T03:54:48.396130Z'}
{'type': 'l2update', 'product_id': 'BTC-USD', 'changes': [['sell', '38373.68', '0.32667125']], 'time': '2021-05-20T03:54:48.398724Z'}
{'type': 'l2update', 'product_id': 'BTC-USD', 'changes': [['sell', '38264.93', '0.36249352']], 'time': '2021-05-20T03:54:48.398775Z'}
{'type': 'l2update', 'product_id': 'BTC-USD', 'changes': [['sell', '38296.33', '0.00000000']], 'time': '2021-05-20T03:54:48.399616Z'}
{'type': 'l2update', 'product_id': 'BTC-USD', 'changes': [['sell', '38265.00', '0.00000000']], 'time': '2021-05-20T03:54:48.400059Z'}
{'type': 'l2update', 'product_id': 'BTC-USD', 'changes': [['sell', '38264.94', '0.00000000']], 'time': '2021-05-20T03:54:48.401761Z'}
{'type': 'l2update', 'product_id': 'BTC-USD', 'changes': [['sell', '38264.93', '0.86249352']], 'time': '2021-05-20T03:54:48.402705Z'}
{'type': 'l2update', 'product_id': 'BTC-USD', 'changes': [['buy', '38250.05', '0.84800000']], 'time': '2021-05-20T03:54:48.402928Z'}
{'type': 'l2update', 'product_id': 'BTC-USD', 'changes': [['sell', '38282.73', '0.00000000']], 'time': '2021-05-20T03:54:48.404008Z'}
{'type': 'l2update', 'product_id': 'BTC-USD', 'changes': [['buy', '38260.83', '0.10183936']], 'time': '2021-05-20T03:54:48.407148Z'}
{'type': 'l2update', 'product_id': 'BTC-USD', 'changes': [['buy', '38130.14', '0.00000000']], 'time': '2021-05-20T03:54:48.409779Z'}
{'type': 'l2update', 'product_id': 'BTC-USD', 'changes': [['sell', '38367.70', '0.00000000']], 'time': '2021-05-20T03:54:48.410779Z'}
{'type': 'l2update', 'product_id': 'BTC-USD', 'changes': [['buy', '38151.65', '0.00000000']], 'time': '2021-05-20T03:54:48.411991Z'}
{'type': 'l2update', 'product_id': 'BTC-USD', 'changes': [['sell', '38289.01', '0.05000000']], 'time': '2021-05-20T03:54:48.412770Z'}
{'type': 'l2update', 'product_id': 'BTC-USD', 'changes': [['sell', '38260.84', '0.32287446']], 'time': '2021-05-20T03:54:48.413868Z'}
{'type': 'l2update', 'product_id': 'BTC-USD', 'changes': [['sell', '38305.42', '0.00000000']], 'time': '2021-05-20T03:54:48.414139Z'}
{'type': 'l2update', 'product_id': 'BTC-USD', 'changes': [['sell', '38264.93', '0.36249352']], 'time': '2021-05-20T03:54:48.415842Z'}
{'type': 'l2update', 'product_id': 'BTC-USD', 'changes': [['buy', '38224.95', '0.04287494']], 'time': '2021-05-20T03:54:48.416537Z'}
{'type': 'l2update', 'product_id': 'BTC-USD', 'changes': [['sell', '38272.66', '0.06285480']], 'time': '2021-05-20T03:54:48.416537Z'}
{'type': 'l2update', 'product_id': 'BTC-USD', 'changes': [['sell', '38260.84', '0.12287446']], 'time': '2021-05-20T03:54:48.419960Z'}
{'type': 'l2update', 'product_id': 'BTC-USD', 'changes': [['buy', '38142.70', '0.03577500']], 'time': '2021-05-20T03:54:48.420516Z'}
{'type': 'l2update', 'product_id': 'BTC-USD', 'changes': [['buy', '38260.83', '0.15183936']], 'time': '2021-05-20T03:54:48.422861Z'}
{'type': 'l2update', 'product_id': 'BTC-USD', 'changes': [['buy', '38225.24', '0.00000000']], 'time': '2021-05-20T03:54:48.424630Z'}
{'type': 'l2update', 'product_id': 'BTC-USD', 'changes': [['sell', '38426.55', '0.00000000']], 'time': '2021-05-20T03:54:48.424851Z'}
{'type': 'l2update', 'product_id': 'BTC-USD', 'changes': [['sell', '38260.84', '0.07097348']], 'time': '2021-05-20T03:54:48.425895Z'}
{'type': 'l2update', 'product_id': 'BTC-USD', 'changes': [['buy', '38167.55', '0.01000000']], 'time': '2021-05-20T03:54:48.426610Z'}
{'type': 'l2update', 'product_id': 'BTC-USD', 'changes': [['sell', '38286.61', '0.00000000']], 'time': '2021-05-20T03:54:48.429667Z'}
{'type': 'l2update', 'product_id': 'BTC-USD', 'changes': [['sell', '38385.41', '0.01000000']], 'time': '2021-05-20T03:54:48.432495Z'}
{'type': 'l2update', 'product_id': 'BTC-USD', 'changes': [['sell', '38277.45', '0.50000000']], 'time': '2021-05-20T03:54:48.432584Z'}
{'type': 'l2update', 'product_id': 'BTC-USD', 'changes': [['buy', '38189.27', '0.03747740']], 'time': '2021-05-20T03:54:48.432632Z'}
{'type': 'l2update', 'product_id': 'BTC-USD', 'changes': [['sell', '38277.45', '2.98969908']], 'time': '2021-05-20T03:54:48.432672Z'}
{'type': 'l2update', 'product_id': 'BTC-USD', 'changes': [['buy', '38233.47', '0.00000000']], 'time': '2021-05-20T03:54:48.432993Z'}
{'type': 'l2update', 'product_id': 'BTC-USD', 'changes': [['sell', '38260.84', '0.05665000']], 'time': '2021-05-20T03:54:48.435931Z'}
{'type': 'l2update', 'product_id': 'BTC-USD', 'changes': [['sell', '38260.84', '0.05213234']], 'time': '2021-05-20T03:54:48.436352Z'}
{'type': 'l2update', 'product_id': 'BTC-USD', 'changes': [['buy', '38260.83', '0.25183936']], 'time': '2021-05-20T03:54:48.436699Z'}
{'type': 'l2update', 'product_id': 'BTC-USD', 'changes': [['buy', '38239.31', '0.00000000']], 'time': '2021-05-20T03:54:48.438311Z'}
{'type': 'l2update', 'product_id': 'BTC-USD', 'changes': [['buy', '38162.80', '0.00000000']], 'time': '2021-05-20T03:54:48.438747Z'}
{'type': 'l2update', 'product_id': 'BTC-USD', 'changes': [['sell', '38282.34', '0.01000000']], 'time': '2021-05-20T03:54:48.438756Z'}
{'type': 'l2update', 'product_id': 'BTC-USD', 'changes': [['sell', '38288.19', '0.46610000']], 'time': '2021-05-20T03:54:48.443790Z'}
{'type': 'l2update', 'product_id': 'BTC-USD', 'changes': [['buy', '38225.61', '1.20000000']], 'time': '2021-05-20T03:54:48.446786Z'}
{'type': 'l2update', 'product_id': 'BTC-USD', 'changes': [['buy', '37954.83', '0.00000000']], 'time': '2021-05-20T03:54:48.448147Z'}
{'type': 'l2update', 'product_id': 'BTC-USD', 'changes': [['buy', '38260.83', '0.45183936']], 'time': '2021-05-20T03:54:48.451100Z'}
{'type': 'l2update', 'product_id': 'BTC-USD', 'changes': [['sell', '38385.41', '0.00000000']], 'time': '2021-05-20T03:54:48.451890Z'}
{'type': 'l2update', 'product_id': 'BTC-USD', 'changes': [['sell', '38288.19', '0.00000000']], 'time': '2021-05-20T03:54:48.452356Z'}
{'type': 'l2update', 'product_id': 'BTC-USD', 'changes': [['sell', '38286.60', '0.00000000']], 'time': '2021-05-20T03:54:48.452741Z'}
{'type': 'l2update', 'product_id': 'BTC-USD', 'changes': [['sell', '38264.93', '0.00000000']], 'time': '2021-05-20T03:54:48.452896Z'}
{'type': 'l2update', 'product_id': 'BTC-USD', 'changes': [['sell', '38401.42', '0.37486228']], 'time': '2021-05-20T03:54:48.455573Z'}
{'type': 'l2update', 'product_id': 'BTC-USD', 'changes': [['sell', '38282.38', '0.02000000']], 'time': '2021-05-20T03:54:48.455706Z'}
{'type': 'l2update', 'product_id': 'BTC-USD', 'changes': [['sell', '38260.84', '0.01613234']], 'time': '2021-05-20T03:54:48.458116Z'}
{'type': 'l2update', 'product_id': 'BTC-USD', 'changes': [['sell', '38299.04', '0.35019299']], 'time': '2021-05-20T03:54:48.462137Z'}
{'type': 'l2update', 'product_id': 'BTC-USD', 'changes': [['sell', '38410.85', '0.01000000']], 'time': '2021-05-20T03:54:48.462463Z'}
{'type': 'l2update', 'product_id': 'BTC-USD', 'changes': [['sell', '38360.41', '1.20000000']], 'time': '2021-05-20T03:54:48.464193Z'}
{'type': 'l2update', 'product_id': 'BTC-USD', 'changes': [['buy', '38236.99', '0.00000000']], 'time': '2021-05-20T03:54:48.466173Z'}
{'type': 'l2update', 'product_id': 'BTC-USD', 'changes': [['buy', '38217.08', '0.01042704']], 'time': '2021-05-20T03:54:48.467066Z'}
{'type': 'l2update', 'product_id': 'BTC-USD', 'changes': [['sell', '38288.18', '0.05000000']], 'time': '2021-05-20T03:54:48.467893Z'}
{'type': 'l2update', 'product_id': 'BTC-USD', 'changes': [['buy', '37967.71', '0.04431450']], 'time': '2021-05-20T03:54:48.469408Z'}
{'type': 'l2update', 'product_id': 'BTC-USD', 'changes': [['buy', '38250.06', '0.22867204']], 'time': '2021-05-20T03:54:48.469872Z'}
{'type': 'l2update', 'product_id': 'BTC-USD', 'changes': [['sell', '38416.24', '0.07316379']], 'time': '2021-05-20T03:54:48.471866Z'}
{'type': 'l2update', 'product_id': 'BTC-USD', 'changes': [['buy', '38202.41', '0.00000000']], 'time': '2021-05-20T03:54:48.472755Z'}
{'type': 'l2update', 'product_id': 'BTC-USD', 'changes': [['sell', '38260.84', '0.00978497']], 'time': '2021-05-20T03:54:48.474835Z'}
{'type': 'l2update', 'product_id': 'BTC-USD', 'changes': [['sell', '38260.84', '0.00573000']], 'time': '2021-05-20T03:54:48.475194Z'}
{'type': 'l2update', 'product_id': 'BTC-USD', 'changes': [['sell', '38283.94', '0.03000000']], 'time': '2021-05-20T03:54:48.476118Z'}
{'type': 'l2update', 'product_id': 'BTC-USD', 'changes': [['buy', '37469.35', '0.05440000']], 'time': '2021-05-20T03:54:48.479837Z'}
{'type': 'l2update', 'product_id': 'BTC-USD', 'changes': [['sell', '38277.44', '0.36249352']], 'time': '2021-05-20T03:54:48.480109Z'}
{'type': 'l2update', 'product_id': 'BTC-USD', 'changes': [['sell', '38272.06', '0.00451766']], 'time': '2021-05-20T03:54:48.480285Z'}
{'type': 'l2update', 'product_id': 'BTC-USD', 'changes': [['sell', '38303.73', '0.01000000']], 'time': '2021-05-20T03:54:48.491201Z'}
{'type': 'l2update', 'product_id': 'BTC-USD', 'changes': [['sell', '38285.09', '0.04000000']], 'time': '2021-05-20T03:54:48.491217Z'}
{'type': 'l2update', 'product_id': 'BTC-USD', 'changes': [['sell', '38387.17', '0.42653272']], 'time': '2021-05-20T03:54:48.499581Z'}
{'type': 'l2update', 'product_id': 'BTC-USD', 'changes': [['buy', '38183.98', '0.03507022']], 'time': '2021-05-20T03:54:48.499581Z'}
{'type': 'l2update', 'product_id': 'BTC-USD', 'changes': [['sell', '38272.33', '0.07460000']], 'time': '2021-05-20T03:54:48.499673Z'}
{'type': 'l2update', 'product_id': 'BTC-USD', 'changes': [['sell', '38285.42', '0.05000000']], 'time': '2021-05-20T03:54:48.504255Z'}
{'type': 'l2update', 'product_id': 'BTC-USD', 'changes': [['sell', '38272.33', '0.00000000']], 'time': '2021-05-20T03:54:48.508048Z'}
{'type': 'l2update', 'product_id': 'BTC-USD', 'changes': [['sell', '38293.24', '0.00000000']], 'time': '2021-05-20T03:54:48.508396Z'}
{'type': 'l2update', 'product_id': 'BTC-USD', 'changes': [['buy', '38157.73', '0.02741397']], 'time': '2021-05-20T03:54:48.508396Z'}
{'type': 'l2update', 'product_id': 'BTC-USD', 'changes': [['buy', '38221.47', '0.01000000']], 'time': '2021-05-20T03:54:48.508579Z'}
{'type': 'l2update', 'product_id': 'BTC-USD', 'changes': [['sell', '38389.74', '0.00000000']], 'time': '2021-05-20T03:54:48.509014Z'}
{'type': 'l2update', 'product_id': 'BTC-USD', 'changes': [['sell', '38416.24', '0.00000000']], 'time': '2021-05-20T03:54:48.513269Z'}
{'type': 'l2update', 'product_id': 'BTC-USD', 'changes': [['sell', '38272.06', '0.01492000']], 'time': '2021-05-20T03:54:48.513507Z'}
{'type': 'l2update', 'product_id': 'BTC-USD', 'changes': [['sell', '38295.82', '0.81867350']], 'time': '2021-05-20T03:54:48.513804Z'}
{'type': 'l2update', 'product_id': 'BTC-USD', 'changes': [['sell', '38295.82', '0.67603742']], 'time': '2021-05-20T03:54:48.513804Z'}
{'type': 'l2update', 'product_id': 'BTC-USD', 'changes': [['buy', '38226.07', '0.44210000']], 'time': '2021-05-20T03:54:48.516768Z'}
{'type': 'l2update', 'product_id': 'BTC-USD', 'changes': [['sell', '38296.84', '0.00000000']], 'time': '2021-05-20T03:54:48.517225Z'}
{'type': 'l2update', 'product_id': 'BTC-USD', 'changes': [['buy', '38199.17', '0.00000000']], 'time': '2021-05-20T03:54:48.517225Z'}
{'type': 'l2update', 'product_id': 'BTC-USD', 'changes': [['buy', '38260.83', '0.45756936']], 'time': '2021-05-20T03:54:48.520715Z'}
{'type': 'l2update', 'product_id': 'BTC-USD', 'changes': [['buy', '38237.05', '0.00000000']], 'time': '2021-05-20T03:54:48.521524Z'}
{'type': 'l2update', 'product_id': 'BTC-USD', 'changes': [['sell', '38303.73', '0.00000000']], 'time': '2021-05-20T03:54:48.524087Z'}
{'type': 'l2update', 'product_id': 'BTC-USD', 'changes': [['sell', '38271.39', '0.07460000']], 'time': '2021-05-20T03:54:48.527557Z'}
{'type': 'l2update', 'product_id': 'BTC-USD', 'changes': [['buy', '38221.47', '0.00000000']], 'time': '2021-05-20T03:54:48.527646Z'}
{'type': 'l2update', 'product_id': 'BTC-USD', 'changes': [['sell', '38429.36', '0.01000000']], 'time': '2021-05-20T03:54:48.527715Z'}
{'type': 'l2update', 'product_id': 'BTC-USD', 'changes': [['sell', '38277.45', '2.48969908']], 'time': '2021-05-20T03:54:48.532023Z'}
{'type': 'l2update', 'product_id': 'BTC-USD', 'changes': [['sell', '38272.06', '0.01040234']], 'time': '2021-05-20T03:54:48.540293Z'}
{'type': 'l2update', 'product_id': 'BTC-USD', 'changes': [['sell', '38366.76', '0.01241600']], 'time': '2021-05-20T03:54:48.542324Z'}
{'type': 'l2update', 'product_id': 'BTC-USD', 'changes': [['sell', '38277.39', '0.58900000']], 'time': '2021-05-20T03:54:48.542379Z'}
{'type': 'l2update', 'product_id': 'BTC-USD', 'changes': [['buy', '38242.29', '0.00000000']], 'time': '2021-05-20T03:54:48.543458Z'}
{'type': 'l2update', 'product_id': 'BTC-USD', 'changes': [['sell', '38272.06', '0.00000000']], 'time': '2021-05-20T03:54:48.544367Z'}
{'type': 'l2update', 'product_id': 'BTC-USD', 'changes': [['buy', '38146.85', '0.03536309']], 'time': '2021-05-20T03:54:48.546813Z'}
{'type': 'l2update', 'product_id': 'BTC-USD', 'changes': [['buy', '38153.84', '0.00000000']], 'time': '2021-05-20T03:54:48.546813Z'}
{'type': 'l2update', 'product_id': 'BTC-USD', 'changes': [['buy', '38157.73', '0.00000000']], 'time': '2021-05-20T03:54:48.546813Z'}
{'type': 'l2update', 'product_id': 'BTC-USD', 'changes': [['buy', '38189.27', '0.00000000']], 'time': '2021-05-20T03:54:48.546813Z'}
{'type': 'l2update', 'product_id': 'BTC-USD', 'changes': [['buy', '38197.09', '0.00000000']], 'time': '2021-05-20T03:54:48.546813Z'}
{'type': 'l2update', 'product_id': 'BTC-USD', 'changes': [['sell', '38401.42', '0.71853604']], 'time': '2021-05-20T03:54:48.546869Z'}
{'type': 'l2update', 'product_id': 'BTC-USD', 'changes': [['sell', '38296.44', '0.45340000']], 'time': '2021-05-20T03:54:48.547003Z'}
{'type': 'l2update', 'product_id': 'BTC-USD', 'changes': [['sell', '38272.05', '0.50000000']], 'time': '2021-05-20T03:54:48.547116Z'}
{'type': 'l2update', 'product_id': 'BTC-USD', 'changes': [['buy', '38250.79', '0.58716278']], 'time': '2021-05-20T03:54:48.547195Z'}
{'type': 'l2update', 'product_id': 'BTC-USD', 'changes': [['sell', '38277.44', '0.00000000']], 'time': '2021-05-20T03:54:48.549064Z'}
{'type': 'l2update', 'product_id': 'BTC-USD', 'changes': [['buy', '38226.07', '0.00000000']], 'time': '2021-05-20T03:54:48.551523Z'}
{'type': 'l2update', 'product_id': 'BTC-USD', 'changes': [['sell', '38299.04', '0.01553130']], 'time': '2021-05-20T03:54:48.551795Z'}
{'type': 'l2update', 'product_id': 'BTC-USD', 'changes': [['buy', '38250.06', '0.00000000']], 'time': '2021-05-20T03:54:48.555669Z'}
{'type': 'l2update', 'product_id': 'BTC-USD', 'changes': [['sell', '49358.03', '0.00544700']], 'time': '2021-05-20T03:54:48.556970Z'}
{'type': 'l2update', 'product_id': 'BTC-USD', 'changes': [['sell', '38296.44', '0.00000000']], 'time': '2021-05-20T03:54:48.557327Z'}
{'type': 'l2update', 'product_id': 'BTC-USD', 'changes': [['sell', '38323.65', '0.00000000']], 'time': '2021-05-20T03:54:48.564824Z'}
{'type': 'l2update', 'product_id': 'BTC-USD', 'changes': [['sell', '38277.38', '0.36249352']], 'time': '2021-05-20T03:54:48.572855Z'}
{'type': 'l2update', 'product_id': 'BTC-USD', 'changes': [['buy', '38245.45', '0.02027558']], 'time': '2021-05-20T03:54:48.572905Z'}
{'type': 'l2update', 'product_id': 'BTC-USD', 'changes': [['buy', '38127.87', '0.00000000']], 'time': '2021-05-20T03:54:48.575251Z'}
{'type': 'l2update', 'product_id': 'BTC-USD', 'changes': [['buy', '38139.67', '0.00000000']], 'time': '2021-05-20T03:54:48.575251Z'}
{'type': 'l2update', 'product_id': 'BTC-USD', 'changes': [['buy', '38146.85', '0.00000000']], 'time': '2021-05-20T03:54:48.575251Z'}
{'type': 'l2update', 'product_id': 'BTC-USD', 'changes': [['buy', '38183.98', '0.00000000']], 'time': '2021-05-20T03:54:48.575251Z'}
{'type': 'l2update', 'product_id': 'BTC-USD', 'changes': [['buy', '38250.80', '0.22867204']], 'time': '2021-05-20T03:54:48.581117Z'}
{'type': 'l2update', 'product_id': 'BTC-USD', 'changes': [['sell', '38266.66', '0.52288421']], 'time': '2021-05-20T03:54:48.581368Z'}
{'type': 'l2update', 'product_id': 'BTC-USD', 'changes': [['sell', '38270.85', '0.01492000']], 'time': '2021-05-20T03:54:48.582550Z'}
{'type': 'l2update', 'product_id': 'BTC-USD', 'changes': [['buy', '38260.83', '0.60756936']], 'time': '2021-05-20T03:54:48.587989Z'}
{'type': 'l2update', 'product_id': 'BTC-USD', 'changes': [['sell', '38357.65', '0.12277556']], 'time': '2021-05-20T03:54:48.592177Z'}
{'type': 'l2update', 'product_id': 'BTC-USD', 'changes': [['sell', '38271.39', '0.00000000']], 'time': '2021-05-20T03:54:48.595673Z'}
{'type': 'l2update', 'product_id': 'BTC-USD', 'changes': [['sell', '38277.82', '0.00000000']], 'time': '2021-05-20T03:54:48.596545Z'}
{'type': 'l2update', 'product_id': 'BTC-USD', 'changes': [['buy', '38245.89', '0.52287827']], 'time': '2021-05-20T03:54:48.598801Z'}
{'type': 'l2update', 'product_id': 'BTC-USD', 'changes': [['sell', '38345.98', '0.02728346']], 'time': '2021-05-20T03:54:48.598858Z'}
{'type': 'l2update', 'product_id': 'BTC-USD', 'changes': [['sell', '38299.04', '0.00000000']], 'time': '2021-05-20T03:54:48.600423Z'}
{'type': 'l2update', 'product_id': 'BTC-USD', 'changes': [['buy', '38260.83', '0.60580420']], 'time': '2021-05-20T03:54:48.601884Z'}
{'type': 'l2update', 'product_id': 'BTC-USD', 'changes': [['sell', '38343.29', '0.00000000']], 'time': '2021-05-20T03:54:48.602095Z'}
{'type': 'l2update', 'product_id': 'BTC-USD', 'changes': [['sell', '38332.48', '0.03086289']], 'time': '2021-05-20T03:54:48.602095Z'}
{'type': 'l2update', 'product_id': 'BTC-USD', 'changes': [['sell', '38292.79', '0.00000000']], 'time': '2021-05-20T03:54:48.602095Z'}
{'type': 'l2update', 'product_id': 'BTC-USD', 'changes': [['sell', '38347.54', '0.05456692']], 'time': '2021-05-20T03:54:48.602350Z'}
{'type': 'l2update', 'product_id': 'BTC-USD', 'changes': [['sell', '38270.85', '0.00000000']], 'time': '2021-05-20T03:54:48.605985Z'}
{'type': 'l2update', 'product_id': 'BTC-USD', 'changes': [['sell', '38270.24', '0.52283447']], 'time': '2021-05-20T03:54:48.611535Z'}
{'type': 'l2update', 'product_id': 'BTC-USD', 'changes': [['buy', '38224.95', '0.00000000']], 'time': '2021-05-20T03:54:48.614632Z'}
{'type': 'l2update', 'product_id': 'BTC-USD', 'changes': [['sell', '38272.66', '0.00000000']], 'time': '2021-05-20T03:54:48.614632Z'}
{'type': 'l2update', 'product_id': 'BTC-USD', 'changes': [['sell', '38323.12', '0.00000000']], 'time': '2021-05-20T03:54:48.625308Z'}
{'type': 'l2update', 'product_id': 'BTC-USD', 'changes': [['buy', '38242.91', '0.52291828']], 'time': '2021-05-20T03:54:48.627488Z'}
{'type': 'l2update', 'product_id': 'BTC-USD', 'changes': [['sell', '38394.20', '0.29287476']], 'time': '2021-05-20T03:54:48.632756Z'}
{'type': 'l2update', 'product_id': 'BTC-USD', 'changes': [['sell', '38553.46', '0.00000000']], 'time': '2021-05-20T03:54:48.638831Z'}
{'type': 'l2update', 'product_id': 'BTC-USD', 'changes': [['sell', '38295.82', '0.34356779']], 'time': '2021-05-20T03:54:48.639802Z'}
{'type': 'l2update', 'product_id': 'BTC-USD', 'changes': [['sell', '38274.58', '0.78448173']], 'time': '2021-05-20T03:54:48.640496Z'}
{'type': 'l2update', 'product_id': 'BTC-USD', 'changes': [['buy', '38229.84', '0.41960000']], 'time': '2021-05-20T03:54:48.645635Z'}
{'type': 'l2update', 'product_id': 'BTC-USD', 'changes': [['buy', '38245.45', '0.00000000']], 'time': '2021-05-20T03:54:48.649352Z'}
{'type': 'l2update', 'product_id': 'BTC-USD', 'changes': [['buy', '38260.83', '0.60756949']], 'time': '2021-05-20T03:54:48.656585Z'}
{'type': 'l2update', 'product_id': 'BTC-USD', 'changes': [['sell', '38306.45', '0.45410000']], 'time': '2021-05-20T03:54:48.656777Z'}
{'type': 'l2update', 'product_id': 'BTC-USD', 'changes': [['buy', '38240.26', '0.52295262']], 'time': '2021-05-20T03:54:48.657605Z'}
{'type': 'l2update', 'product_id': 'BTC-USD', 'changes': [['sell', '38538.46', '0.01297405']], 'time': '2021-05-20T03:54:48.657778Z'}
{'type': 'l2update', 'product_id': 'BTC-USD', 'changes': [['sell', '38387.17', '0.02612340']], 'time': '2021-05-20T03:54:48.658380Z'}
{'type': 'l2update', 'product_id': 'BTC-USD', 'changes': [['sell', '38380.33', '0.00000000']], 'time': '2021-05-20T03:54:48.658380Z'}
{'type': 'l2update', 'product_id': 'BTC-USD', 'changes': [['sell', '38373.68', '0.03264132']], 'time': '2021-05-20T03:54:48.658380Z'}
{'type': 'l2update', 'product_id': 'BTC-USD', 'changes': [['sell', '38367.22', '0.03880677']], 'time': '2021-05-20T03:54:48.658380Z'}
{'type': 'l2update', 'product_id': 'BTC-USD', 'changes': [['sell', '38354.87', '0.03075403']], 'time': '2021-05-20T03:54:48.658380Z'}
{'type': 'l2update', 'product_id': 'BTC-USD', 'changes': [['sell', '38348.98', '0.03446160']], 'time': '2021-05-20T03:54:48.658380Z'}
{'type': 'l2update', 'product_id': 'BTC-USD', 'changes': [['sell', '38292.71', '0.00000000']], 'time': '2021-05-20T03:54:48.661784Z'}
{'type': 'l2update', 'product_id': 'BTC-USD', 'changes': [['buy', '38229.84', '0.00000000']], 'time': '2021-05-20T03:54:48.663581Z'}
{'type': 'l2update', 'product_id': 'BTC-USD', 'changes': [['sell', '38306.45', '0.00000000']], 'time': '2021-05-20T03:54:48.671230Z'}
{'type': 'l2update', 'product_id': 'BTC-USD', 'changes': [['sell', '38284.68', '1.30738625']], 'time': '2021-05-20T03:54:48.672657Z'}
{'type': 'l2update', 'product_id': 'BTC-USD', 'changes': [['buy', '38232.11', '0.06102027']], 'time': '2021-05-20T03:54:48.673166Z'}
{'type': 'l2update', 'product_id': 'BTC-USD', 'changes': [['sell', '38276.55', '0.05285505']], 'time': '2021-05-20T03:54:48.673166Z'}
{'type': 'l2update', 'product_id': 'BTC-USD', 'changes': [['sell', '38288.18', '0.00000000']], 'time': '2021-05-20T03:54:48.679612Z'}
{'type': 'l2update', 'product_id': 'BTC-USD', 'changes': [['sell', '38277.38', '0.00000000']], 'time': '2021-05-20T03:54:48.682067Z'}
{'type': 'l2update', 'product_id': 'BTC-USD', 'changes': [['buy', '38227.34', '0.78438195']], 'time': '2021-05-20T03:54:48.686045Z'}
{'type': 'l2update', 'product_id': 'BTC-USD', 'changes': [['buy', '38257.53', '0.02027558']], 'time': '2021-05-20T03:54:48.686273Z'}
{'type': 'l2update', 'product_id': 'BTC-USD', 'changes': [['sell', '38389.83', '0.00000000']], 'time': '2021-05-20T03:54:48.686783Z'}
{'type': 'l2update', 'product_id': 'BTC-USD', 'changes': [['buy', '38160.00', '0.00000000']], 'time': '2021-05-20T03:54:48.691179Z'}
{'type': 'l2update', 'product_id': 'BTC-USD', 'changes': [['sell', '38284.67', '0.05000000']], 'time': '2021-05-20T03:54:48.691625Z'}
{'type': 'l2update', 'product_id': 'BTC-USD', 'changes': [['sell', '39035.61', '0.00000000']], 'time': '2021-05-20T03:54:48.696949Z'}
