{'type': 'l2update', 'product_id': 'BTC-USD', 'changes': [['sell', '38398.94', '1.13200000']], 'time': '2021-05-20T03:56:22.277008Z'}
{'type': 'l2update', 'product_id': 'BTC-USD', 'changes': [['buy', '37950.00', '0.11676777']], 'time': '2021-05-20T03:56:22.279985Z'}
{'type': 'l2update', 'product_id': 'BTC-USD', 'changes': [['buy', '38199.57', '0.00000000']], 'time': '2021-05-20T03:56:22.280542Z'}
{'type': 'l2update', 'product_id': 'BTC-USD', 'changes': [['buy', '38370.37', '0.00000000']], 'time': '2021-05-20T03:56:22.281536Z'}
{'type': 'l2update', 'product_id': 'BTC-USD', 'changes': [['buy', '38371.55', '0.00000000']], 'time': '2021-05-20T03:56:22.281536Z'}
{'type': 'l2update', 'product_id': 'BTC-USD', 'changes': [['buy', '38373.91', '0.00000000']], 'time': '2021-05-20T03:56:22.281536Z'}
{'type': 'l2update', 'product_id': 'BTC-USD', 'changes': [['buy', '38377.45', '0.00000000']], 'time': '2021-05-20T03:56:22.281536Z'}
{'type': 'l2update', 'product_id': 'BTC-USD', 'changes': [['sell', '38515.69', '0.00000000']], 'time': '2021-05-20T03:56:22.290193Z'}
{'type': 'l2update', 'product_id': 'BTC-USD', 'changes': [['buy', '38339.63', '1.30320645']], 'time': '2021-05-20T03:56:22.299816Z'}
{'type': 'l2update', 'product_id': 'BTC-USD', 'changes': [['buy', '38241.67', '0.00000000']], 'time': '2021-05-20T03:56:22.304769Z'}
{'type': 'l2update', 'product_id': 'BTC-USD', 'changes': [['sell', '38431.03', '0.00000000']], 'time': '2021-05-20T03:56:22.306573Z'}
{'type': 'l2update', 'product_id': 'BTC-USD', 'changes': [['sell', '38496.98', '0.41751524']], 'time': '2021-05-20T03:56:22.308998Z'}
{'type': 'l2update', 'product_id': 'BTC-USD', 'changes': [['buy', '38241.10', '0.41568849']], 'time': '2021-05-20T03:56:22.308998Z'}
{'type': 'l2update', 'product_id': 'BTC-USD', 'changes': [['buy', '38382.14', '0.21690000']], 'time': '2021-05-20T03:56:22.310906Z'}
{'type': 'l2update', 'product_id': 'BTC-USD', 'changes': [['buy', '38379.14', '0.09420323']], 'time': '2021-05-20T03:56:22.315371Z'}
{'type': 'l2update', 'product_id': 'BTC-USD', 'changes': [['buy', '38317.75', '1.28010652']], 'time': '2021-05-20T03:56:22.317373Z'}
{'type': 'l2update', 'product_id': 'BTC-USD', 'changes': [['sell', '38510.14', '0.00000000']], 'time': '2021-05-20T03:56:22.317708Z'}
{'type': 'l2update', 'product_id': 'BTC-USD', 'changes': [['buy', '37548.82', '0.00000000']], 'time': '2021-05-20T03:56:22.318680Z'}
{'type': 'l2update', 'product_id': 'BTC-USD', 'changes': [['buy', '38213.69', '0.01000000']], 'time': '2021-05-20T03:56:22.322833Z'}
{'type': 'l2update', 'product_id': 'BTC-USD', 'changes': [['buy', '38262.76', '0.02873335']], 'time': '2021-05-20T03:56:22.328402Z'}
{'type': 'l2update', 'product_id': 'BTC-USD', 'changes': [['sell', '38533.95', '0.01000000']], 'time': '2021-05-20T03:56:22.333339Z'}
{'type': 'l2update', 'product_id': 'BTC-USD', 'changes': [['buy', '38241.30', '0.12000000']], 'time': '2021-05-20T03:56:22.337346Z'}
{'type': 'l2update', 'product_id': 'BTC-USD', 'changes': [['sell', '38542.63', '0.00000000']], 'time': '2021-05-20T03:56:22.343045Z'}
{'type': 'l2update', 'product_id': 'BTC-USD', 'changes': [['buy', '38382.19', '0.04330000']], 'time': '2021-05-20T03:56:22.344261Z'}
{'type': 'l2update', 'product_id': 'BTC-USD', 'changes': [['buy', '38337.11', '2.60614942']], 'time': '2021-05-20T03:56:22.344784Z'}
{'type': 'l2update', 'product_id': 'BTC-USD', 'changes': [['buy', '38210.13', '0.00000000']], 'time': '2021-05-20T03:56:22.350758Z'}
{'type': 'l2update', 'product_id': 'BTC-USD', 'changes': [['sell', '38427.48', '0.00000000']], 'time': '2021-05-20T03:56:22.351088Z'}
{'type': 'l2update', 'product_id': 'BTC-USD', 'changes': [['buy', '38379.85', '0.20854523']], 'time': '2021-05-20T03:56:22.352985Z'}
{'type': 'l2update', 'product_id': 'BTC-USD', 'changes': [['sell', '38418.59', '0.03207306']], 'time': '2021-05-20T03:56:22.353158Z'}
{'type': 'l2update', 'product_id': 'BTC-USD', 'changes': [['sell', '39187.40', '0.00000000']], 'time': '2021-05-20T03:56:22.353618Z'}
{'type': 'l2update', 'product_id': 'BTC-USD', 'changes': [['buy', '38362.76', '0.45130000']], 'time': '2021-05-20T03:56:22.357126Z'}
{'type': 'l2update', 'product_id': 'BTC-USD', 'changes': [['sell', '38416.90', '0.00000000']], 'time': '2021-05-20T03:56:22.363322Z'}
{'type': 'l2update', 'product_id': 'BTC-USD', 'changes': [['buy', '38255.68', '0.03155230']], 'time': '2021-05-20T03:56:22.367235Z'}
{'type': 'l2update', 'product_id': 'BTC-USD', 'changes': [['buy', '38241.30', '0.09000000']], 'time': '2021-05-20T03:56:22.368279Z'}
{'type': 'l2update', 'product_id': 'BTC-USD', 'changes': [['sell', '38507.45', '0.00000000']], 'time': '2021-05-20T03:56:22.377870Z'}
{'type': 'l2update', 'product_id': 'BTC-USD', 'changes': [['buy', '38327.61', '2.63073811']], 'time': '2021-05-20T03:56:22.380495Z'}
{'type': 'l2update', 'product_id': 'BTC-USD', 'changes': [['buy', '38256.36', '0.68988304']], 'time': '2021-05-20T03:56:22.381038Z'}
{'type': 'l2update', 'product_id': 'BTC-USD', 'changes': [['buy', '38224.56', '0.00000000']], 'time': '2021-05-20T03:56:22.382677Z'}
{'type': 'l2update', 'product_id': 'BTC-USD', 'changes': [['sell', '38425.25', '0.48150000']], 'time': '2021-05-20T03:56:22.391494Z'}
{'type': 'l2update', 'product_id': 'BTC-USD', 'changes': [['buy', '37920.00', '0.00000000']], 'time': '2021-05-20T03:56:22.392180Z'}
{'type': 'l2update', 'product_id': 'BTC-USD', 'changes': [['buy', '38379.85', '0.30854523']], 'time': '2021-05-20T03:56:22.392275Z'}
{'type': 'l2update', 'product_id': 'BTC-USD', 'changes': [['sell', '38550.22', '0.00000000']], 'time': '2021-05-20T03:56:22.393323Z'}
{'type': 'l2update', 'product_id': 'BTC-USD', 'changes': [['sell', '38504.80', '0.00000000']], 'time': '2021-05-20T03:56:22.395372Z'}
{'type': 'l2update', 'product_id': 'BTC-USD', 'changes': [['sell', '38485.83', '0.01203948']], 'time': '2021-05-20T03:56:22.395866Z'}
{'type': 'l2update', 'product_id': 'BTC-USD', 'changes': [['sell', '38533.95', '0.00000000']], 'time': '2021-05-20T03:56:22.396866Z'}
{'type': 'l2update', 'product_id': 'BTC-USD', 'changes': [['buy', '38241.30', '0.05000000']], 'time': '2021-05-20T03:56:22.396949Z'}
{'type': 'l2update', 'product_id': 'BTC-USD', 'changes': [['sell', '38772.08', '0.01289587']], 'time': '2021-05-20T03:56:22.401370Z'}
{'type': 'l2update', 'product_id': 'BTC-USD', 'changes': [['sell', '38413.95', '0.00000000']], 'time': '2021-05-20T03:56:22.403971Z'}
{'type': 'l2update', 'product_id': 'BTC-USD', 'changes': [['sell', '38453.32', '0.00000000']], 'time': '2021-05-20T03:56:22.408388Z'}
{'type': 'l2update', 'product_id': 'BTC-USD', 'changes': [['sell', '38398.58', '0.05032748']], 'time': '2021-05-20T03:56:22.413817Z'}
{'type': 'l2update', 'product_id': 'BTC-USD', 'changes': [['buy', '38221.73', '0.01000000']], 'time': '2021-05-20T03:56:22.413865Z'}
{'type': 'l2update', 'product_id': 'BTC-USD', 'changes': [['buy', '38317.53', '2.60664009']], 'time': '2021-05-20T03:56:22.414735Z'}
{'type': 'l2update', 'product_id': 'BTC-USD', 'changes': [['buy', '38329.13', '0.00000000']], 'time': '2021-05-20T03:56:22.417646Z'}
{'type': 'l2update', 'product_id': 'BTC-USD', 'changes': [['sell', '38389.09', '0.00000000']], 'time': '2021-05-20T03:56:22.417989Z'}
{'type': 'l2update', 'product_id': 'BTC-USD', 'changes': [['buy', '38271.13', '0.00000000']], 'time': '2021-05-20T03:56:22.418859Z'}
{'type': 'l2update', 'product_id': 'BTC-USD', 'changes': [['buy', '38237.94', '0.01000000']], 'time': '2021-05-20T03:56:22.419319Z'}
{'type': 'l2update', 'product_id': 'BTC-USD', 'changes': [['sell', '38471.56', '0.02846767']], 'time': '2021-05-20T03:56:22.419436Z'}
{'type': 'l2update', 'product_id': 'BTC-USD', 'changes': [['sell', '38450.62', '0.00000000']], 'time': '2021-05-20T03:56:22.419436Z'}
{'type': 'l2update', 'product_id': 'BTC-USD', 'changes': [['buy', '38241.30', '0.00000000']], 'time': '2021-05-20T03:56:22.422853Z'}
{'type': 'l2update', 'product_id': 'BTC-USD', 'changes': [['sell', '38520.26', '0.01000000']], 'time': '2021-05-20T03:56:22.431985Z'}
{'type': 'l2update', 'product_id': 'BTC-USD', 'changes': [['buy', '38382.20', '0.06573000']], 'time': '2021-05-20T03:56:22.432006Z'}
{'type': 'l2update', 'product_id': 'BTC-USD', 'changes': [['sell', '38658.97', '0.01000000']], 'time': '2021-05-20T03:56:22.432833Z'}
{'type': 'l2update', 'product_id': 'BTC-USD', 'changes': [['sell', '38537.06', '0.01000000']], 'time': '2021-05-20T03:56:22.433544Z'}
{'type': 'l2update', 'product_id': 'BTC-USD', 'changes': [['sell', '38467.16', '0.05438620']], 'time': '2021-05-20T03:56:22.436178Z'}
{'type': 'l2update', 'product_id': 'BTC-USD', 'changes': [['buy', '38282.56', '0.07700000']], 'time': '2021-05-20T03:56:22.436773Z'}
{'type': 'l2update', 'product_id': 'BTC-USD', 'changes': [['sell', '38554.00', '0.00000000']], 'time': '2021-05-20T03:56:22.437143Z'}
{'type': 'l2update', 'product_id': 'BTC-USD', 'changes': [['buy', '38361.08', '0.00000000']], 'time': '2021-05-20T03:56:22.438290Z'}
{'type': 'l2update', 'product_id': 'BTC-USD', 'changes': [['sell', '38418.42', '0.50000000']], 'time': '2021-05-20T03:56:22.442184Z'}
{'type': 'l2update', 'product_id': 'BTC-USD', 'changes': [['buy', '38248.82', '0.38999964']], 'time': '2021-05-20T03:56:22.443007Z'}
{'type': 'l2update', 'product_id': 'BTC-USD', 'changes': [['buy', '38339.41', '1.20000000']], 'time': '2021-05-20T03:56:22.443051Z'}
{'type': 'l2update', 'product_id': 'BTC-USD', 'changes': [['sell', '38522.28', '0.00000000']], 'time': '2021-05-20T03:56:22.443455Z'}
{'type': 'l2update', 'product_id': 'BTC-USD', 'changes': [['sell', '38389.51', '0.05000000']], 'time': '2021-05-20T03:56:22.445468Z'}
{'type': 'l2update', 'product_id': 'BTC-USD', 'changes': [['sell', '38397.28', '0.59100000']], 'time': '2021-05-20T03:56:22.448454Z'}
{'type': 'l2update', 'product_id': 'BTC-USD', 'changes': [['buy', '38382.14', '0.31690000']], 'time': '2021-05-20T03:56:22.448585Z'}
{'type': 'l2update', 'product_id': 'BTC-USD', 'changes': [['buy', '38333.46', '0.02608687']], 'time': '2021-05-20T03:56:22.448602Z'}
{'type': 'l2update', 'product_id': 'BTC-USD', 'changes': [['buy', '38329.20', '0.05448625']], 'time': '2021-05-20T03:56:22.448723Z'}
{'type': 'l2update', 'product_id': 'BTC-USD', 'changes': [['buy', '38284.28', '0.01000000']], 'time': '2021-05-20T03:56:22.455191Z'}
{'type': 'l2update', 'product_id': 'BTC-USD', 'changes': [['sell', '38499.73', '0.03104534']], 'time': '2021-05-20T03:56:22.455376Z'}
{'type': 'l2update', 'product_id': 'BTC-USD', 'changes': [['buy', '38269.51', '0.09342759']], 'time': '2021-05-20T03:56:22.455376Z'}
{'type': 'l2update', 'product_id': 'BTC-USD', 'changes': [['sell', '38578.88', '0.00000000']], 'time': '2021-05-20T03:56:22.455485Z'}
{'type': 'l2update', 'product_id': 'BTC-USD', 'changes': [['buy', '38359.05', '0.06020080']], 'time': '2021-05-20T03:56:22.461431Z'}
{'type': 'l2update', 'product_id': 'BTC-USD', 'changes': [['buy', '38357.48', '0.00000000']], 'time': '2021-05-20T03:56:22.463522Z'}
{'type': 'l2update', 'product_id': 'BTC-USD', 'changes': [['sell', '38413.94', '0.00000000']], 'time': '2021-05-20T03:56:22.467430Z'}
{'type': 'l2update', 'product_id': 'BTC-USD', 'changes': [['sell', '38542.17', '0.00000000']], 'time': '2021-05-20T03:56:22.469347Z'}
{'type': 'l2update', 'product_id': 'BTC-USD', 'changes': [['sell', '38541.03', '0.00000000']], 'time': '2021-05-20T03:56:22.469347Z'}
{'type': 'l2update', 'product_id': 'BTC-USD', 'changes': [['sell', '38490.25', '0.00000000']], 'time': '2021-05-20T03:56:22.469347Z'}
{'type': 'l2update', 'product_id': 'BTC-USD', 'changes': [['sell', '38389.51', '0.00000000']], 'time': '2021-05-20T03:56:22.470051Z'}
{'type': 'l2update', 'product_id': 'BTC-USD', 'changes': [['sell', '38485.17', '0.01000000']], 'time': '2021-05-20T03:56:22.472876Z'}
{'type': 'l2update', 'product_id': 'BTC-USD', 'changes': [['sell', '38529.71', '0.01000000']], 'time': '2021-05-20T03:56:22.473045Z'}
{'type': 'l2update', 'product_id': 'BTC-USD', 'changes': [['buy', '38351.32', '0.00000000']], 'time': '2021-05-20T03:56:22.473882Z'}
{'type': 'l2update', 'product_id': 'BTC-USD', 'changes': [['sell', '38474.61', '1.20000000']], 'time': '2021-05-20T03:56:22.476778Z'}
{'type': 'l2update', 'product_id': 'BTC-USD', 'changes': [['sell', '38772.08', '0.00000000']], 'time': '2021-05-20T03:56:22.477610Z'}
{'type': 'l2update', 'product_id': 'BTC-USD', 'changes': [['sell', '38467.99', '0.02599564']], 'time': '2021-05-20T03:56:22.481037Z'}
{'type': 'l2update', 'product_id': 'BTC-USD', 'changes': [['buy', '38382.14', '0.51690000']], 'time': '2021-05-20T03:56:22.481242Z'}
{'type': 'l2update', 'product_id': 'BTC-USD', 'changes': [['sell', '38534.51', '0.01000000']], 'time': '2021-05-20T03:56:22.481591Z'}
{'type': 'l2update', 'product_id': 'BTC-USD', 'changes': [['sell', '38548.91', '0.00000000']], 'time': '2021-05-20T03:56:22.481892Z'}
{'type': 'l2update', 'product_id': 'BTC-USD', 'changes': [['buy', '38224.49', '0.00000000']], 'time': '2021-05-20T03:56:22.482253Z'}
{'type': 'l2update', 'product_id': 'BTC-USD', 'changes': [['buy', '38352.50', '0.00000000']], 'time': '2021-05-20T03:56:22.491583Z'}
{'type': 'l2update', 'product_id': 'BTC-USD', 'changes': [['buy', '38269.27', '0.03456308']], 'time': '2021-05-20T03:56:22.492947Z'}
{'type': 'l2update', 'product_id': 'BTC-USD', 'changes': [['buy', '38320.46', '0.03487620']], 'time': '2021-05-20T03:56:22.492947Z'}
{'type': 'l2update', 'product_id': 'BTC-USD', 'changes': [['buy', '38329.75', '0.03546148']], 'time': '2021-05-20T03:56:22.492947Z'}
{'type': 'l2update', 'product_id': 'BTC-USD', 'changes': [['sell', '38413.94', '0.06020080']], 'time': '2021-05-20T03:56:22.493148Z'}
{'type': 'l2update', 'product_id': 'BTC-USD', 'changes': [['buy', '38382.20', '0.06833709']], 'time': '2021-05-20T03:56:22.497605Z'}
{'type': 'l2update', 'product_id': 'BTC-USD', 'changes': [['sell', '38508.91', '0.00000000']], 'time': '2021-05-20T03:56:22.498657Z'}
{'type': 'l2update', 'product_id': 'BTC-USD', 'changes': [['sell', '38382.21', '0.35000000']], 'time': '2021-05-20T03:56:22.501452Z'}
{'type': 'l2update', 'product_id': 'BTC-USD', 'changes': [['buy', '38364.81', '0.59116555']], 'time': '2021-05-20T03:56:22.501510Z'}
{'type': 'l2update', 'product_id': 'BTC-USD', 'changes': [['sell', '38418.41', '0.05000000']], 'time': '2021-05-20T03:56:22.501801Z'}
{'type': 'l2update', 'product_id': 'BTC-USD', 'changes': [['buy', '38379.14', '0.00000000']], 'time': '2021-05-20T03:56:22.502577Z'}
{'type': 'l2update', 'product_id': 'BTC-USD', 'changes': [['buy', '38248.82', '0.71871073']], 'time': '2021-05-20T03:56:22.507075Z'}
{'type': 'l2update', 'product_id': 'BTC-USD', 'changes': [['sell', '38485.17', '0.00000000']], 'time': '2021-05-20T03:56:22.508745Z'}
{'type': 'l2update', 'product_id': 'BTC-USD', 'changes': [['buy', '38288.04', '0.00000000']], 'time': '2021-05-20T03:56:22.511944Z'}
{'type': 'l2update', 'product_id': 'BTC-USD', 'changes': [['buy', '38327.61', '2.60673811']], 'time': '2021-05-20T03:56:22.513494Z'}
{'type': 'l2update', 'product_id': 'BTC-USD', 'changes': [['sell', '38537.06', '0.00000000']], 'time': '2021-05-20T03:56:22.515475Z'}
{'type': 'l2update', 'product_id': 'BTC-USD', 'changes': [['buy', '38382.20', '0.16673709']], 'time': '2021-05-20T03:56:22.517988Z'}
{'type': 'l2update', 'product_id': 'BTC-USD', 'changes': [['sell', '38428.91', '0.01000000']], 'time': '2021-05-20T03:56:22.518303Z'}
{'type': 'l2update', 'product_id': 'BTC-USD', 'changes': [['sell', '38759.77', '0.01289997']], 'time': '2021-05-20T03:56:22.518945Z'}
{'type': 'l2update', 'product_id': 'BTC-USD', 'changes': [['buy', '38339.63', '0.00000000']], 'time': '2021-05-20T03:56:22.519566Z'}
{'type': 'l2update', 'product_id': 'BTC-USD', 'changes': [['buy', '38273.06', '0.00000000']], 'time': '2021-05-20T03:56:22.519781Z'}
{'type': 'l2update', 'product_id': 'BTC-USD', 'changes': [['buy', '38294.91', '0.00000000']], 'time': '2021-05-20T03:56:22.520691Z'}
{'type': 'l2update', 'product_id': 'BTC-USD', 'changes': [['buy', '38306.48', '0.00000000']], 'time': '2021-05-20T03:56:22.520691Z'}
{'type': 'l2update', 'product_id': 'BTC-USD', 'changes': [['buy', '38250.00', '0.71820000']], 'time': '2021-05-20T03:56:22.522102Z'}
{'type': 'l2update', 'product_id': 'BTC-USD', 'changes': [['buy', '31000.00', '165.05838784']], 'time': '2021-05-20T03:56:22.525138Z'}
{'type': 'l2update', 'product_id': 'BTC-USD', 'changes': [['sell', '38418.42', '0.00000000']], 'time': '2021-05-20T03:56:22.525641Z'}
{'type': 'l2update', 'product_id': 'BTC-USD', 'changes': [['sell', '38599.99', '3.22892558']], 'time': '2021-05-20T03:56:22.526054Z'}
{'type': 'l2update', 'product_id': 'BTC-USD', 'changes': [['sell', '38418.43', '0.00000000']], 'time': '2021-05-20T03:56:22.528467Z'}
{'type': 'l2update', 'product_id': 'BTC-USD', 'changes': [['sell', '38382.21', '0.39000000']], 'time': '2021-05-20T03:56:22.533257Z'}
{'type': 'l2update', 'product_id': 'BTC-USD', 'changes': [['buy', '38328.42', '0.00000000']], 'time': '2021-05-20T03:56:22.538236Z'}
{'type': 'l2update', 'product_id': 'BTC-USD', 'changes': [['buy', '38376.05', '0.09420323']], 'time': '2021-05-20T03:56:22.544463Z'}
{'type': 'l2update', 'product_id': 'BTC-USD', 'changes': [['buy', '38288.03', '0.31367179']], 'time': '2021-05-20T03:56:22.544903Z'}
{'type': 'l2update', 'product_id': 'BTC-USD', 'changes': [['buy', '38310.41', '0.16154872']], 'time': '2021-05-20T03:56:22.544903Z'}
{'type': 'l2update', 'product_id': 'BTC-USD', 'changes': [['sell', '38493.12', '0.01202765']], 'time': '2021-05-20T03:56:22.545627Z'}
{'type': 'l2update', 'product_id': 'BTC-USD', 'changes': [['sell', '38570.63', '0.01000000']], 'time': '2021-05-20T03:56:22.549032Z'}
{'type': 'l2update', 'product_id': 'BTC-USD', 'changes': [['buy', '38346.38', '0.01000000']], 'time': '2021-05-20T03:56:22.549108Z'}
{'type': 'l2update', 'product_id': 'BTC-USD', 'changes': [['buy', '38382.19', '0.14330000']], 'time': '2021-05-20T03:56:22.549651Z'}
{'type': 'l2update', 'product_id': 'BTC-USD', 'changes': [['buy', '38284.94', '0.01133744']], 'time': '2021-05-20T03:56:22.555445Z'}
{'type': 'l2update', 'product_id': 'BTC-USD', 'changes': [['sell', '38457.07', '0.02744305']], 'time': '2021-05-20T03:56:22.555622Z'}
{'type': 'l2update', 'product_id': 'BTC-USD', 'changes': [['buy', '38356.53', '0.00000000']], 'time': '2021-05-20T03:56:22.555850Z'}
{'type': 'l2update', 'product_id': 'BTC-USD', 'changes': [['sell', '38533.87', '0.01297559']], 'time': '2021-05-20T03:56:22.555937Z'}
{'type': 'l2update', 'product_id': 'BTC-USD', 'changes': [['buy', '38356.23', '0.00000000']], 'time': '2021-05-20T03:56:22.557835Z'}
{'type': 'l2update', 'product_id': 'BTC-USD', 'changes': [['sell', '38397.33', '0.00000000']], 'time': '2021-05-20T03:56:22.557835Z'}
{'type': 'l2update', 'product_id': 'BTC-USD', 'changes': [['sell', '38413.95', '0.50000000']], 'time': '2021-05-20T03:56:22.560487Z'}
{'type': 'l2update', 'product_id': 'BTC-USD', 'changes': [['buy', '38329.22', '0.00000000']], 'time': '2021-05-20T03:56:22.563282Z'}
{'type': 'l2update', 'product_id': 'BTC-USD', 'changes': [['buy', '38362.76', '0.00000000']], 'time': '2021-05-20T03:56:22.563676Z'}
{'type': 'l2update', 'product_id': 'BTC-USD', 'changes': [['buy', '38239.04', '0.01000000']], 'time': '2021-05-20T03:56:22.567301Z'}
{'type': 'l2update', 'product_id': 'BTC-USD', 'changes': [['sell', '38612.70', '0.01754830']], 'time': '2021-05-20T03:56:22.568931Z'}
{'type': 'l2update', 'product_id': 'BTC-USD', 'changes': [['buy', '38256.36', '0.37621125']], 'time': '2021-05-20T03:56:22.568986Z'}
{'type': 'l2update', 'product_id': 'BTC-USD', 'changes': [['buy', '38282.00', '0.00000000']], 'time': '2021-05-20T03:56:22.568986Z'}
{'type': 'l2update', 'product_id': 'BTC-USD', 'changes': [['buy', '38327.61', '0.00000000']], 'time': '2021-05-20T03:56:22.570047Z'}
{'type': 'l2update', 'product_id': 'BTC-USD', 'changes': [['buy', '38271.83', '0.00000000']], 'time': '2021-05-20T03:56:22.573443Z'}
{'type': 'l2update', 'product_id': 'BTC-USD', 'changes': [['sell', '38528.67', '0.00000000']], 'time': '2021-05-20T03:56:22.573555Z'}
{'type': 'l2update', 'product_id': 'BTC-USD', 'changes': [['sell', '38382.21', '0.29000000']], 'time': '2021-05-20T03:56:22.577825Z'}
{'type': 'l2update', 'product_id': 'BTC-USD', 'changes': [['sell', '38483.20', '0.03118890']], 'time': '2021-05-20T03:56:22.579622Z'}
{'type': 'l2update', 'product_id': 'BTC-USD', 'changes': [['sell', '38425.25', '0.00000000']], 'time': '2021-05-20T03:56:22.588521Z'}
{'type': 'l2update', 'product_id': 'BTC-USD', 'changes': [['sell', '38534.51', '0.00000000']], 'time': '2021-05-20T03:56:22.588952Z'}
{'type': 'l2update', 'product_id': 'BTC-USD', 'changes': [['sell', '38418.41', '0.00000000']], 'time': '2021-05-20T03:56:22.589457Z'}
{'type': 'l2update', 'product_id': 'BTC-USD', 'changes': [['buy', '38340.71', '0.65760668']], 'time': '2021-05-20T03:56:22.593466Z'}
{'type': 'l2update', 'product_id': 'BTC-USD', 'changes': [['buy', '38376.10', '0.84500000']], 'time': '2021-05-20T03:56:22.593812Z'}
{'type': 'l2update', 'product_id': 'BTC-USD', 'changes': [['buy', '38317.53', '0.00000000']], 'time': '2021-05-20T03:56:22.595904Z'}
{'type': 'l2update', 'product_id': 'BTC-USD', 'changes': [['sell', '38382.21', '0.09000000']], 'time': '2021-05-20T03:56:22.603437Z'}
{'type': 'l2update', 'product_id': 'BTC-USD', 'changes': [['buy', '38229.03', '0.00000000']], 'time': '2021-05-20T03:56:22.607613Z'}
{'type': 'l2update', 'product_id': 'BTC-USD', 'changes': [['buy', '38238.70', '0.02000000']], 'time': '2021-05-20T03:56:22.610668Z'}
{'type': 'l2update', 'product_id': 'BTC-USD', 'changes': [['buy', '38359.28', '0.02390000']], 'time': '2021-05-20T03:56:22.610969Z'}
{'type': 'l2update', 'product_id': 'BTC-USD', 'changes': [['buy', '38358.47', '0.02390000']], 'time': '2021-05-20T03:56:22.610969Z'}
{'type': 'l2update', 'product_id': 'BTC-USD', 'changes': [['buy', '38357.67', '0.02390000']], 'time': '2021-05-20T03:56:22.610969Z'}
{'type': 'l2update', 'product_id': 'BTC-USD', 'changes': [['sell', '38528.33', '0.40497775']], 'time': '2021-05-20T03:56:22.616853Z'}
{'type': 'l2update', 'product_id': 'BTC-USD', 'changes': [['sell', '38477.55', '0.69883481']], 'time': '2021-05-20T03:56:22.616853Z'}
{'type': 'l2update', 'product_id': 'BTC-USD', 'changes': [['sell', '38436.89', '0.30838260']], 'time': '2021-05-20T03:56:22.616853Z'}
{'type': 'l2update', 'product_id': 'BTC-USD', 'changes': [['sell', '38558.65', '0.01783423']], 'time': '2021-05-20T03:56:22.617137Z'}
{'type': 'l2update', 'product_id': 'BTC-USD', 'changes': [['sell', '38413.94', '0.11020080']], 'time': '2021-05-20T03:56:22.621769Z'}
{'type': 'l2update', 'product_id': 'BTC-USD', 'changes': [['sell', '38759.77', '0.00000000']], 'time': '2021-05-20T03:56:22.622570Z'}
{'type': 'l2update', 'product_id': 'BTC-USD', 'changes': [['buy', '38376.10', '0.00000000']], 'time': '2021-05-20T03:56:22.626418Z'}
{'type': 'l2update', 'product_id': 'BTC-USD', 'changes': [['sell', '38413.93', '0.65676518']], 'time': '2021-05-20T03:56:22.626865Z'}
{'type': 'l2update', 'product_id': 'BTC-USD', 'changes': [['buy', '38373.96', '0.00000000']], 'time': '2021-05-20T03:56:22.626961Z'}
{'type': 'l2update', 'product_id': 'BTC-USD', 'changes': [['sell', '38517.72', '0.01000000']], 'time': '2021-05-20T03:56:22.627743Z'}
{'type': 'l2update', 'product_id': 'BTC-USD', 'changes': [['buy', '38357.67', '0.00000000']], 'time': '2021-05-20T03:56:22.631872Z'}
{'type': 'l2update', 'product_id': 'BTC-USD', 'changes': [['sell', '38485.83', '0.00000000']], 'time': '2021-05-20T03:56:22.632438Z'}
{'type': 'l2update', 'product_id': 'BTC-USD', 'changes': [['buy', '38382.20', '0.26673709']], 'time': '2021-05-20T03:56:22.635283Z'}
{'type': 'l2update', 'product_id': 'BTC-USD', 'changes': [['sell', '38441.65', '0.01138707']], 'time': '2021-05-20T03:56:22.635310Z'}
{'type': 'l2update', 'product_id': 'BTC-USD', 'changes': [['buy', '38280.05', '0.50000000']], 'time': '2021-05-20T03:56:22.635351Z'}
{'type': 'l2update', 'product_id': 'BTC-USD', 'changes': [['buy', '34700.00', '2.87579514']], 'time': '2021-05-20T03:56:22.635646Z'}
{'type': 'l2update', 'product_id': 'BTC-USD', 'changes': [['buy', '38238.70', '0.05000000']], 'time': '2021-05-20T03:56:22.639737Z'}
{'type': 'l2update', 'product_id': 'BTC-USD', 'changes': [['buy', '38364.81', '0.00000000']], 'time': '2021-05-20T03:56:22.642594Z'}
{'type': 'l2update', 'product_id': 'BTC-USD', 'changes': [['sell', '38610.00', '0.19720000']], 'time': '2021-05-20T03:56:22.646229Z'}
{'type': 'l2update', 'product_id': 'BTC-USD', 'changes': [['buy', '38357.99', '0.05411128']], 'time': '2021-05-20T03:56:22.646849Z'}
{'type': 'l2update', 'product_id': 'BTC-USD', 'changes': [['sell', '38401.10', '0.04261099']], 'time': '2021-05-20T03:56:22.646849Z'}
{'type': 'l2update', 'product_id': 'BTC-USD', 'changes': [['sell', '38413.94', '0.06020080']], 'time': '2021-05-20T03:56:22.648461Z'}
{'type': 'l2update', 'product_id': 'BTC-USD', 'changes': [['sell', '38738.17', '0.01290716']], 'time': '2021-05-20T03:56:22.651488Z'}
{'type': 'l2update', 'product_id': 'BTC-USD', 'changes': [['buy', '38359.28', '0.00000000']], 'time': '2021-05-20T03:56:22.652008Z'}
{'type': 'l2update', 'product_id': 'BTC-USD', 'changes': [['buy', '38358.47', '0.00000000']], 'time': '2021-05-20T03:56:22.652008Z'}
{'type': 'l2update', 'product_id': 'BTC-USD', 'changes': [['sell', '38382.21', '0.06000000']], 'time': '2021-05-20T03:56:22.652328Z'}
{'type': 'l2update', 'product_id': 'BTC-USD', 'changes': [['sell', '38382.21', '0.04000000']], 'time': '2021-05-20T03:56:22.652328Z'}
{'type': 'l2update', 'product_id': 'BTC-USD', 'changes': [['sell', '38382.21', '0.00000000']], 'time': '2021-05-20T03:56:22.652328Z'}
{'type': 'l2update', 'product_id': 'BTC-USD', 'changes': [['sell', '38436.89', '0.61235471']], 'time': '2021-05-20T03:56:22.652477Z'}
{'type': 'l2update', 'product_id': 'BTC-USD', 'changes': [['sell', '38432.32', '0.12546872']], 'time': '2021-05-20T03:56:22.652477Z'}
{'type': 'l2update', 'product_id': 'BTC-USD', 'changes': [['sell', '38471.56', '0.00000000']], 'time': '2021-05-20T03:56:22.655790Z'}
{'type': 'l2update', 'product_id': 'BTC-USD', 'changes': [['sell', '38414.85', '0.00000000']], 'time': '2021-05-20T03:56:22.656529Z'}
{'type': 'l2update', 'product_id': 'BTC-USD', 'changes': [['buy', '38379.85', '0.10854523']], 'time': '2021-05-20T03:56:22.656665Z'}
{'type': 'l2update', 'product_id': 'BTC-USD', 'changes': [['sell', '38413.95', '0.00000000']], 'time': '2021-05-20T03:56:22.657567Z'}
{'type': 'l2update', 'product_id': 'BTC-USD', 'changes': [['sell', '38517.72', '0.00000000']], 'time': '2021-05-20T03:56:22.660492Z'}
{'type': 'l2update', 'product_id': 'BTC-USD', 'changes': [['buy', '38238.70', '0.09000000']], 'time': '2021-05-20T03:56:22.670023Z'}
{'type': 'l2update', 'product_id': 'BTC-USD', 'changes': [['buy', '38115.83', '0.00000000']], 'time': '2021-05-20T03:56:22.673160Z'}
{'type': 'l2update', 'product_id': 'BTC-USD', 'changes': [['sell', '38413.92', '0.05000000']], 'time': '2021-05-20T03:56:22.675023Z'}
{'type': 'l2update', 'product_id': 'BTC-USD', 'changes': [['sell', '38522.90', '0.00000000']], 'time': '2021-05-20T03:56:22.675459Z'}
{'type': 'l2update', 'product_id': 'BTC-USD', 'changes': [['sell', '38477.55', '0.39045221']], 'time': '2021-05-20T03:56:22.675459Z'}
{'type': 'l2update', 'product_id': 'BTC-USD', 'changes': [['sell', '38460.99', '0.00000000']], 'time': '2021-05-20T03:56:22.675459Z'}
{'type': 'l2update', 'product_id': 'BTC-USD', 'changes': [['sell', '38450.90', '0.14024231']], 'time': '2021-05-20T03:56:22.675459Z'}
{'type': 'l2update', 'product_id': 'BTC-USD', 'changes': [['buy', '38382.20', '0.26100709']], 'time': '2021-05-20T03:56:22.676255Z'}
{'type': 'l2update', 'product_id': 'BTC-USD', 'changes': [['buy', '38379.85', '0.00854523']], 'time': '2021-05-20T03:56:22.678262Z'}
{'type': 'l2update', 'product_id': 'BTC-USD', 'changes': [['buy', '38363.27', '0.48890000']], 'time': '2021-05-20T03:56:22.679827Z'}
{'type': 'l2update', 'product_id': 'BTC-USD', 'changes': [['buy', '38382.71', '0.01492000']], 'time': '2021-05-20T03:56:22.680803Z'}
{'type': 'l2update', 'product_id': 'BTC-USD', 'changes': [['sell', '38487.44', '0.00000000']], 'time': '2021-05-20T03:56:22.685096Z'}
{'type': 'l2update', 'product_id': 'BTC-USD', 'changes': [['buy', '38382.70', '0.07460000']], 'time': '2021-05-20T03:56:22.688767Z'}
{'type': 'l2update', 'product_id': 'BTC-USD', 'changes': [['buy', '38305.05', '0.02846767']], 'time': '2021-05-20T03:56:22.688897Z'}
{'type': 'l2update', 'product_id': 'BTC-USD', 'changes': [['buy', '38359.05', '0.00000000']], 'time': '2021-05-20T03:56:22.689131Z'}
{'type': 'l2update', 'product_id': 'BTC-USD', 'changes': [['buy', '38239.04', '0.00000000']], 'time': '2021-05-20T03:56:22.689720Z'}
{'type': 'l2update', 'product_id': 'BTC-USD', 'changes': [['sell', '38418.43', '0.50000000']], 'time': '2021-05-20T03:56:22.694303Z'}
{'type': 'l2update', 'product_id': 'BTC-USD', 'changes': [['sell', '38418.41', '0.05721617']], 'time': '2021-05-20T03:56:22.694354Z'}
{'type': 'l2update', 'product_id': 'BTC-USD', 'changes': [['sell', '38509.79', '0.01203479']], 'time': '2021-05-20T03:56:22.694854Z'}
{'type': 'l2update', 'product_id': 'BTC-USD', 'changes': [['sell', '38497.35', '0.01000000']], 'time': '2021-05-20T03:56:22.694916Z'}
{'type': 'l2update', 'product_id': 'BTC-USD', 'changes': [['buy', '38364.85', '0.84500000']], 'time': '2021-05-20T03:56:22.694950Z'}
{'type': 'l2update', 'product_id': 'BTC-USD', 'changes': [['buy', '38382.25', '0.01800000']], 'time': '2021-05-20T03:56:22.695523Z'}
{'type': 'l2update', 'product_id': 'BTC-USD', 'changes': [['buy', '38162.23', '0.00000000']], 'time': '2021-05-20T03:56:22.695775Z'}
{'type': 'l2update', 'product_id': 'BTC-USD', 'changes': [['buy', '38382.14', '0.41690000']], 'time': '2021-05-20T03:56:22.696882Z'}
{'type': 'l2update', 'product_id': 'BTC-USD', 'changes': [['buy', '38382.14', '0.38800000']], 'time': '2021-05-20T03:56:22.701489Z'}
{'type': 'l2update', 'product_id': 'BTC-USD', 'changes': [['buy', '38382.19', '0.10000000']], 'time': '2021-05-20T03:56:22.701927Z'}
{'type': 'l2update', 'product_id': 'BTC-USD', 'changes': [['buy', '38382.70', '0.00000000']], 'time': '2021-05-20T03:56:22.706136Z'}
{'type': 'l2update', 'product_id': 'BTC-USD', 'changes': [['buy', '38276.14', '0.00000000']], 'time': '2021-05-20T03:56:22.707585Z'}
{'type': 'l2update', 'product_id': 'BTC-USD', 'changes': [['buy', '38238.70', '0.07000000']], 'time': '2021-05-20T03:56:22.707941Z'}
{'type': 'l2update', 'product_id': 'BTC-USD', 'changes': [['sell', '38425.02', '0.44110000']], 'time': '2021-05-20T03:56:22.709776Z'}
{'type': 'l2update', 'product_id': 'BTC-USD', 'changes': [['sell', '38520.26', '0.00000000']], 'time': '2021-05-20T03:56:22.709949Z'}
{'type': 'l2update', 'product_id': 'BTC-USD', 'changes': [['buy', '38376.05', '0.00000000']], 'time': '2021-05-20T03:56:22.713061Z'}
{'type': 'l2update', 'product_id': 'BTC-USD', 'changes': [['buy', '38382.14', '0.18800000']], 'time': '2021-05-20T03:56:22.716576Z'}
{'type': 'l2update', 'product_id': 'BTC-USD', 'changes': [['sell', '38529.71', '0.00000000']], 'time': '2021-05-20T03:56:22.717843Z'}
{'type': 'l2update', 'product_id': 'BTC-USD', 'changes': [['sell', '38398.99', '0.00000000']], 'time': '2021-05-20T03:56:22.718859Z'}
{'type': 'l2update', 'product_id': 'BTC-USD', 'changes': [['buy', '38367.08', '0.02390000']], 'time': '2021-05-20T03:56:22.719787Z'}
{'type': 'l2update', 'product_id': 'BTC-USD', 'changes': [['buy', '38366.28', '0.02390000']], 'time': '2021-05-20T03:56:22.719787Z'}
{'type': 'l2update', 'product_id': 'BTC-USD', 'changes': [['buy', '38365.47', '0.02390000']], 'time': '2021-05-20T03:56:22.719787Z'}
{'type': 'l2update', 'product_id': 'BTC-USD', 'changes': [['sell', '38470.66', '0.40431494']], 'time': '2021-05-20T03:56:22.720194Z'}
{'type': 'l2update', 'product_id': 'BTC-USD', 'changes': [['sell', '38432.32', '0.26571103']], 'time': '2021-05-20T03:56:22.720194Z'}
{'type': 'l2update', 'product_id': 'BTC-USD', 'changes': [['buy', '38386.26', '0.04916581']], 'time': '2021-05-20T03:56:22.724214Z'}
{'type': 'l2update', 'product_id': 'BTC-USD', 'changes': [['buy', '38238.70', '0.04000000']], 'time': '2021-05-20T03:56:22.725559Z'}
{'type': 'l2update', 'product_id': 'BTC-USD', 'changes': [['sell', '38484.44', '0.18490000']], 'time': '2021-05-20T03:56:22.730089Z'}
{'type': 'l2update', 'product_id': 'BTC-USD', 'changes': [['sell', '38400.54', '0.00600000']], 'time': '2021-05-20T03:56:22.730397Z'}
{'type': 'l2update', 'product_id': 'BTC-USD', 'changes': [['buy', '38382.19', '0.00000000']], 'time': '2021-05-20T03:56:22.732219Z'}
{'type': 'l2update', 'product_id': 'BTC-USD', 'changes': [['buy', '38357.49', '0.06020080']], 'time': '2021-05-20T03:56:22.735069Z'}
{'type': 'l2update', 'product_id': 'BTC-USD', 'changes': [['buy', '38364.80', '0.00000000']], 'time': '2021-05-20T03:56:22.736894Z'}
{'type': 'l2update', 'product_id': 'BTC-USD', 'changes': [['buy', '38382.97', '0.07460000']], 'time': '2021-05-20T03:56:22.739747Z'}
{'type': 'l2update', 'product_id': 'BTC-USD', 'changes': [['sell', '38508.99', '0.00000000']], 'time': '2021-05-20T03:56:22.741365Z'}
{'type': 'l2update', 'product_id': 'BTC-USD', 'changes': [['sell', '38450.90', '0.00000000']], 'time': '2021-05-20T03:56:22.741365Z'}
{'type': 'l2update', 'product_id': 'BTC-USD', 'changes': [['buy', '38364.86', '0.59116555']], 'time': '2021-05-20T03:56:22.741703Z'}
{'type': 'l2update', 'product_id': 'BTC-USD', 'changes': [['sell', '38553.97', '0.01000000']], 'time': '2021-05-20T03:56:22.741947Z'}
{'type': 'l2update', 'product_id': 'BTC-USD', 'changes': [['sell', '38570.63', '0.00000000']], 'time': '2021-05-20T03:56:22.747232Z'}
{'type': 'l2update', 'product_id': 'BTC-USD', 'changes': [['buy', '38382.71', '0.00000000']], 'time': '2021-05-20T03:56:22.747559Z'}
{'type': 'l2update', 'product_id': 'BTC-USD', 'changes': [['buy', '38238.70', '0.00000000']], 'time': '2021-05-20T03:56:22.748613Z'}
{'type': 'l2update', 'product_id': 'BTC-USD', 'changes': [['buy', '38382.10', '0.00000000']], 'time': '2021-05-20T03:56:22.752044Z'}
{'type': 'l2update', 'product_id': 'BTC-USD', 'changes': [['sell', '38413.96', '0.00000000']], 'time': '2021-05-20T03:56:22.752146Z'}
{'type': 'l2update', 'product_id': 'BTC-USD', 'changes': [['buy', '38382.20', '0.16260709']], 'time': '2021-05-20T03:56:22.752707Z'}
{'type': 'l2update', 'product_id': 'BTC-USD', 'changes': [['sell', '38432.81', '0.49333810']], 'time': '2021-05-20T03:56:22.752755Z'}
{'type': 'l2update', 'product_id': 'BTC-USD', 'changes': [['sell', '38450.62', '0.03493920']], 'time': '2021-05-20T03:56:22.753177Z'}
{'type': 'l2update', 'product_id': 'BTC-USD', 'changes': [['sell', '38738.17', '0.00000000']], 'time': '2021-05-20T03:56:22.754239Z'}
{'type': 'l2update', 'product_id': 'BTC-USD', 'changes': [['sell', '38493.06', '0.03220499']], 'time': '2021-05-20T03:56:22.755256Z'}
{'type': 'l2update', 'product_id': 'BTC-USD', 'changes': [['buy', '38378.40', '0.09420323']], 'time': '2021-05-20T03:56:22.755440Z'}
{'type': 'l2update', 'product_id': 'BTC-USD', 'changes': [['buy', '38313.13', '1.80210000']], 'time': '2021-05-20T03:56:22.755748Z'}
{'type': 'l2update', 'product_id': 'BTC-USD', 'changes': [['sell', '38428.91', '0.00000000']], 'time': '2021-05-20T03:56:22.756535Z'}
{'type': 'l2update', 'product_id': 'BTC-USD', 'changes': [['buy', '38382.97', '0.00000000']], 'time': '2021-05-20T03:56:22.758385Z'}
{'type': 'l2update', 'product_id': 'BTC-USD', 'changes': [['sell', '38418.43', '0.00000000']], 'time': '2021-05-20T03:56:22.759177Z'}
{'type': 'l2update', 'product_id': 'BTC-USD', 'changes': [['buy', '38375.96', '0.00300000']], 'time': '2021-05-20T03:56:22.759966Z'}
{'type': 'l2update', 'product_id': 'BTC-USD', 'changes': [['sell', '38421.08', '0.04967905']], 'time': '2021-05-20T03:56:22.760017Z'}
{'type': 'l2update', 'product_id': 'BTC-USD', 'changes': [['buy', '38222.79', '0.04948003']], 'time': '2021-05-20T03:56:22.760044Z'}
{'type': 'l2update', 'product_id': 'BTC-USD', 'changes': [['sell', '38397.27', '2.48969908']], 'time': '2021-05-20T03:56:22.765632Z'}
{'type': 'l2update', 'product_id': 'BTC-USD', 'changes': [['buy', '38381.71', '0.06000000']], 'time': '2021-05-20T03:56:22.765698Z'}
{'type': 'l2update', 'product_id': 'BTC-USD', 'changes': [['buy', '38382.20', '0.06260709']], 'time': '2021-05-20T03:56:22.770454Z'}
{'type': 'l2update', 'product_id': 'BTC-USD', 'changes': [['sell', '38477.55', '0.35551301']], 'time': '2021-05-20T03:56:22.774174Z'}
{'type': 'l2update', 'product_id': 'BTC-USD', 'changes': [['buy', '38299.61', '0.41050817']], 'time': '2021-05-20T03:56:22.774521Z'}
{'type': 'l2update', 'product_id': 'BTC-USD', 'changes': [['buy', '38382.25', '0.00000000']], 'time': '2021-05-20T03:56:22.775762Z'}
{'type': 'l2update', 'product_id': 'BTC-USD', 'changes': [['sell', '38413.94', '0.00000000']], 'time': '2021-05-20T03:56:22.778291Z'}
{'type': 'l2update', 'product_id': 'BTC-USD', 'changes': [['buy', '38346.38', '0.00000000']], 'time': '2021-05-20T03:56:22.778447Z'}
{'type': 'l2update', 'product_id': 'BTC-USD', 'changes': [['sell', '38557.46', '0.01000000']], 'time': '2021-05-20T03:56:22.779528Z'}
{'type': 'l2update', 'product_id': 'BTC-USD', 'changes': [['sell', '38397.28', '0.64100000']], 'time': '2021-05-20T03:56:22.779582Z'}
{'type': 'l2update', 'product_id': 'BTC-USD', 'changes': [['sell', '38502.71', '0.03632110']], 'time': '2021-05-20T03:56:22.782445Z'}
{'type': 'l2update', 'product_id': 'BTC-USD', 'changes': [['sell', '38716.56', '0.01291437']], 'time': '2021-05-20T03:56:22.783018Z'}
{'type': 'l2update', 'product_id': 'BTC-USD', 'changes': [['buy', '38367.08', '0.00000000']], 'time': '2021-05-20T03:56:22.789394Z'}
{'type': 'l2update', 'product_id': 'BTC-USD', 'changes': [['buy', '38366.28', '0.00000000']], 'time': '2021-05-20T03:56:22.789394Z'}
{'type': 'l2update', 'product_id': 'BTC-USD', 'changes': [['sell', '38418.59', '0.00000000']], 'time': '2021-05-20T03:56:22.790269Z'}
{'type': 'l2update', 'product_id': 'BTC-USD', 'changes': [['buy', '38357.99', '0.00000000']], 'time': '2021-05-20T03:56:22.791122Z'}
{'type': 'l2update', 'product_id': 'BTC-USD', 'changes': [['sell', '38401.10', '0.00000000']], 'time': '2021-05-20T03:56:22.791122Z'}
{'type': 'l2update', 'product_id': 'BTC-USD', 'changes': [['buy', '38370.43', '1.46756192']], 'time': '2021-05-20T03:56:22.794812Z'}
{'type': 'l2update', 'product_id': 'BTC-USD', 'changes': [['buy', '38386.60', '0.01492000']], 'time': '2021-05-20T03:56:22.795173Z'}
{'type': 'l2update', 'product_id': 'BTC-USD', 'changes': [['sell', '38397.27', '2.98969908']], 'time': '2021-05-20T03:56:22.795473Z'}
{'type': 'l2update', 'product_id': 'BTC-USD', 'changes': [['buy', '38262.69', '0.00000000']], 'time': '2021-05-20T03:56:22.796167Z'}
{'type': 'l2update', 'product_id': 'BTC-USD', 'changes': [['sell', '38482.96', '0.00000000']], 'time': '2021-05-20T03:56:22.799239Z'}
{'type': 'l2update', 'product_id': 'BTC-USD', 'changes': [['buy', '38386.80', '0.07460000']], 'time': '2021-05-20T03:56:22.800749Z'}
{'type': 'l2update', 'product_id': 'BTC-USD', 'changes': [['buy', '38331.45', '0.00000000']], 'time': '2021-05-20T03:56:22.802426Z'}
{'type': 'l2update', 'product_id': 'BTC-USD', 'changes': [['buy', '38359.06', '0.05721617']], 'time': '2021-05-20T03:56:22.802580Z'}
{'type': 'l2update', 'product_id': 'BTC-USD', 'changes': [['sell', '38421.08', '0.00000000']], 'time': '2021-05-20T03:56:22.808461Z'}
{'type': 'l2update', 'product_id': 'BTC-USD', 'changes': [['sell', '38497.35', '0.00000000']], 'time': '2021-05-20T03:56:22.808533Z'}
{'type': 'l2update', 'product_id': 'BTC-USD', 'changes': [['sell', '38508.96', '0.03459727']], 'time': '2021-05-20T03:56:22.810842Z'}
{'type': 'l2update', 'product_id': 'BTC-USD', 'changes': [['sell', '38457.07', '0.05863195']], 'time': '2021-05-20T03:56:22.810842Z'}
{'type': 'l2update', 'product_id': 'BTC-USD', 'changes': [['buy', '38246.10', '0.05000000']], 'time': '2021-05-20T03:56:22.810870Z'}
{'type': 'l2update', 'product_id': 'BTC-USD', 'changes': [['buy', '38364.86', '0.00000000']], 'time': '2021-05-20T03:56:22.817290Z'}
{'type': 'l2update', 'product_id': 'BTC-USD', 'changes': [['sell', '38557.46', '0.00000000']], 'time': '2021-05-20T03:56:22.817970Z'}
{'type': 'l2update', 'product_id': 'BTC-USD', 'changes': [['buy', '38364.32', '0.02390000']], 'time': '2021-05-20T03:56:22.826246Z'}
{'type': 'l2update', 'product_id': 'BTC-USD', 'changes': [['buy', '38363.51', '0.02390000']], 'time': '2021-05-20T03:56:22.826246Z'}
{'type': 'l2update', 'product_id': 'BTC-USD', 'changes': [['buy', '38386.60', '0.00000000']], 'time': '2021-05-20T03:56:22.826296Z'}
{'type': 'l2update', 'product_id': 'BTC-USD', 'changes': [['sell', '38418.41', '0.00000000']], 'time': '2021-05-20T03:56:22.828484Z'}
{'type': 'l2update', 'product_id': 'BTC-USD', 'changes': [['sell', '38483.20', '0.00000000']], 'time': '2021-05-20T03:56:22.834536Z'}
{'type': 'l2update', 'product_id': 'BTC-USD', 'changes': [['sell', '38502.71', '0.00000000']], 'time': '2021-05-20T03:56:22.837946Z'}
{'type': 'l2update', 'product_id': 'BTC-USD', 'changes': [['sell', '38424.03', '0.05155702']], 'time': '2021-05-20T03:56:22.838060Z'}
{'type': 'l2update', 'product_id': 'BTC-USD', 'changes': [['sell', '38502.10', '0.41989879']], 'time': '2021-05-20T03:56:22.838938Z'}
{'type': 'l2update', 'product_id': 'BTC-USD', 'changes': [['sell', '38464.95', '0.41751524']], 'time': '2021-05-20T03:56:22.838938Z'}
{'type': 'l2update', 'product_id': 'BTC-USD', 'changes': [['buy', '38370.48', '0.84600000']], 'time': '2021-05-20T03:56:22.839004Z'}
{'type': 'l2update', 'product_id': 'BTC-USD', 'changes': [['buy', '38340.71', '0.00000000']], 'time': '2021-05-20T03:56:22.843331Z'}
{'type': 'l2update', 'product_id': 'BTC-USD', 'changes': [['sell', '38397.28', '0.65100000']], 'time': '2021-05-20T03:56:22.845254Z'}
{'type': 'l2update', 'product_id': 'BTC-USD', 'changes': [['buy', '38330.45', '0.10000000']], 'time': '2021-05-20T03:56:22.847787Z'}
{'type': 'l2update', 'product_id': 'BTC-USD', 'changes': [['sell', '38716.56', '0.00000000']], 'time': '2021-05-20T03:56:22.853555Z'}
{'type': 'l2update', 'product_id': 'BTC-USD', 'changes': [['sell', '38572.51', '0.01000000']], 'time': '2021-05-20T03:56:22.853674Z'}
{'type': 'l2update', 'product_id': 'BTC-USD', 'changes': [['buy', '38329.14', '0.00000000']], 'time': '2021-05-20T03:56:22.858580Z'}
{'type': 'l2update', 'product_id': 'BTC-USD', 'changes': [['sell', '38515.13', '0.01000000']], 'time': '2021-05-20T03:56:22.862695Z'}
{'type': 'l2update', 'product_id': 'BTC-USD', 'changes': [['sell', '38496.98', '0.00000000']], 'time': '2021-05-20T03:56:22.863608Z'}
{'type': 'l2update', 'product_id': 'BTC-USD', 'changes': [['buy', '38299.61', '0.44155351']], 'time': '2021-05-20T03:56:22.871006Z'}
{'type': 'l2update', 'product_id': 'BTC-USD', 'changes': [['buy', '38310.42', '0.02669354']], 'time': '2021-05-20T03:56:22.871006Z'}
{'type': 'l2update', 'product_id': 'BTC-USD', 'changes': [['buy', '38342.29', '0.03487620']], 'time': '2021-05-20T03:56:22.871006Z'}
{'type': 'l2update', 'product_id': 'BTC-USD', 'changes': [['buy', '38346.09', '0.01418459']], 'time': '2021-05-20T03:56:22.871006Z'}
{'type': 'l2update', 'product_id': 'BTC-USD', 'changes': [['sell', '38530.09', '0.09391856']], 'time': '2021-05-20T03:56:22.871087Z'}
{'type': 'l2update', 'product_id': 'BTC-USD', 'changes': [['sell', '39449.99', '0.00000000']], 'time': '2021-05-20T03:56:22.872685Z'}
{'type': 'l2update', 'product_id': 'BTC-USD', 'changes': [['sell', '39499.99', '0.04970000']], 'time': '2021-05-20T03:56:22.872685Z'}
{'type': 'l2update', 'product_id': 'BTC-USD', 'changes': [['buy', '38378.40', '0.00000000']], 'time': '2021-05-20T03:56:22.873175Z'}
{'type': 'l2update', 'product_id': 'BTC-USD', 'changes': [['sell', '38397.28', '0.67100000']], 'time': '2021-05-20T03:56:22.876074Z'}
{'type': 'l2update', 'product_id': 'BTC-USD', 'changes': [['buy', '38035.80', '1.57900000']], 'time': '2021-05-20T03:56:22.876094Z'}
{'type': 'l2update', 'product_id': 'BTC-USD', 'changes': [['sell', '38517.72', '0.01000000']], 'time': '2021-05-20T03:56:22.876497Z'}
{'type': 'l2update', 'product_id': 'BTC-USD', 'changes': [['buy', '38381.71', '0.00000000']], 'time': '2021-05-20T03:56:22.878779Z'}
{'type': 'l2update', 'product_id': 'BTC-USD', 'changes': [['sell', '39499.99', '0.11610000']], 'time': '2021-05-20T03:56:22.880476Z'}
{'type': 'l2update', 'product_id': 'BTC-USD', 'changes': [['buy', '38057.88', '0.00000000']], 'time': '2021-05-20T03:56:22.881912Z'}
{'type': 'l2update', 'product_id': 'BTC-USD', 'changes': [['buy', '38370.44', '0.59116555']], 'time': '2021-05-20T03:56:22.885269Z'}
{'type': 'l2update', 'product_id': 'BTC-USD', 'changes': [['sell', '38694.96', '0.01292158']], 'time': '2021-05-20T03:56:22.885388Z'}
{'type': 'l2update', 'product_id': 'BTC-USD', 'changes': [['buy', '38269.51', '0.06238225']], 'time': '2021-05-20T03:56:22.893292Z'}
{'type': 'l2update', 'product_id': 'BTC-USD', 'changes': [['buy', '38282.28', '0.00000000']], 'time': '2021-05-20T03:56:22.893292Z'}
{'type': 'l2update', 'product_id': 'BTC-USD', 'changes': [['buy', '38320.46', '0.00000000']], 'time': '2021-05-20T03:56:22.893292Z'}
{'type': 'l2update', 'product_id': 'BTC-USD', 'changes': [['buy', '38329.75', '0.00000000']], 'time': '2021-05-20T03:56:22.893292Z'}
{'type': 'l2update', 'product_id': 'BTC-USD', 'changes': [['buy', '38356.52', '0.00000000']], 'time': '2021-05-20T03:56:22.893329Z'}
{'type': 'l2update', 'product_id': 'BTC-USD', 'changes': [['buy', '38387.49', '0.01492000']], 'time': '2021-05-20T03:56:22.903426Z'}
{'type': 'l2update', 'product_id': 'BTC-USD', 'changes': [['sell', '38522.90', '0.43621273']], 'time': '2021-05-20T03:56:22.903463Z'}
{'type': 'l2update', 'product_id': 'BTC-USD', 'changes': [['buy', '38359.60', '0.04885972']], 'time': '2021-05-20T03:56:22.904176Z'}
{'type': 'l2update', 'product_id': 'BTC-USD', 'changes': [['sell', '38402.65', '0.05880542']], 'time': '2021-05-20T03:56:22.904176Z'}
{'type': 'l2update', 'product_id': 'BTC-USD', 'changes': [['sell', '38397.28', '0.70100000']], 'time': '2021-05-20T03:56:22.907896Z'}
{'type': 'l2update', 'product_id': 'BTC-USD', 'changes': [['buy', '38375.92', '0.09420323']], 'time': '2021-05-20T03:56:22.908461Z'}
{'type': 'l2update', 'product_id': 'BTC-USD', 'changes': [['buy', '38376.06', '0.12122745']], 'time': '2021-05-20T03:56:22.913528Z'}
{'type': 'l2update', 'product_id': 'BTC-USD', 'changes': [['buy', '38045.00', '0.05144450']], 'time': '2021-05-20T03:56:22.913794Z'}
{'type': 'l2update', 'product_id': 'BTC-USD', 'changes': [['buy', '38386.80', '0.00000000']], 'time': '2021-05-20T03:56:22.923482Z'}
{'type': 'l2update', 'product_id': 'BTC-USD', 'changes': [['sell', '38423.18', '0.04904838']], 'time': '2021-05-20T03:56:22.923510Z'}
{'type': 'l2update', 'product_id': 'BTC-USD', 'changes': [['sell', '38508.96', '0.06127402']], 'time': '2021-05-20T03:56:22.925781Z'}
{'type': 'l2update', 'product_id': 'BTC-USD', 'changes': [['buy', '38359.06', '0.00000000']], 'time': '2021-05-20T03:56:22.931577Z'}
{'type': 'l2update', 'product_id': 'BTC-USD', 'changes': [['sell', '38397.28', '0.74100000']], 'time': '2021-05-20T03:56:22.936914Z'}
{'type': 'l2update', 'product_id': 'BTC-USD', 'changes': [['sell', '38502.10', '0.71840692']], 'time': '2021-05-20T03:56:22.938295Z'}
{'type': 'l2update', 'product_id': 'BTC-USD', 'changes': [['sell', '38448.96', '0.35551301']], 'time': '2021-05-20T03:56:22.938295Z'}
{'type': 'l2update', 'product_id': 'BTC-USD', 'changes': [['buy', '38357.49', '0.00000000']], 'time': '2021-05-20T03:56:22.942918Z'}
{'type': 'l2update', 'product_id': 'BTC-USD', 'changes': [['buy', '38376.11', '0.84600000']], 'time': '2021-05-20T03:56:22.959183Z'}
{'type': 'l2update', 'product_id': 'BTC-USD', 'changes': [['sell', '38477.55', '0.00000000']], 'time': '2021-05-20T03:56:22.963019Z'}
{'type': 'l2update', 'product_id': 'BTC-USD', 'changes': [['sell', '38508.96', '0.08932092']], 'time': '2021-05-20T03:56:22.967796Z'}
{'type': 'l2update', 'product_id': 'BTC-USD', 'changes': [['sell', '38434.36', '0.01397568']], 'time': '2021-05-20T03:56:22.967796Z'}
{'type': 'l2update', 'product_id': 'BTC-USD', 'changes': [['buy', '38246.41', '0.01000000']], 'time': '2021-05-20T03:56:22.968170Z'}
{'type': 'l2update', 'product_id': 'BTC-USD', 'changes': [['buy', '38230.56', '0.00000000']], 'time': '2021-05-20T03:56:22.972767Z'}
{'type': 'l2update', 'product_id': 'BTC-USD', 'changes': [['buy', '38363.27', '0.00000000']], 'time': '2021-05-20T03:56:22.973591Z'}
{'type': 'l2update', 'product_id': 'BTC-USD', 'changes': [['sell', '39152.26', '0.00175825']], 'time': '2021-05-20T03:56:22.975904Z'}
{'type': 'l2update', 'product_id': 'BTC-USD', 'changes': [['sell', '38418.42', '0.05721617']], 'time': '2021-05-20T03:56:22.978692Z'}
{'type': 'l2update', 'product_id': 'BTC-USD', 'changes': [['buy', '38370.44', '0.00000000']], 'time': '2021-05-20T03:56:22.984236Z'}
{'type': 'l2update', 'product_id': 'BTC-USD', 'changes': [['sell', '38450.62', '0.00000000']], 'time': '2021-05-20T03:56:22.987700Z'}
{'type': 'l2update', 'product_id': 'BTC-USD', 'changes': [['sell', '38432.81', '0.52541116']], 'time': '2021-05-20T03:56:22.995545Z'}
{'type': 'l2update', 'product_id': 'BTC-USD', 'changes': [['sell', '38516.52', '0.37322205']], 'time': '2021-05-20T03:56:22.995639Z'}
{'type': 'l2update', 'product_id': 'BTC-USD', 'changes': [['sell', '38694.96', '0.00000000']], 'time': '2021-05-20T03:56:22.996838Z'}
{'type': 'l2update', 'product_id': 'BTC-USD', 'changes': [['sell', '38533.87', '0.00000000']], 'time': '2021-05-20T03:56:22.999236Z'}
{'type': 'l2update', 'product_id': 'BTC-USD', 'changes': [['buy', '38246.10', '0.07000000']], 'time': '2021-05-20T03:56:23.000437Z'}
{'type': 'l2update', 'product_id': 'BTC-USD', 'changes': [['buy', '38284.94', '0.00000000']], 'time': '2021-05-20T03:56:23.003615Z'}
{'type': 'l2update', 'product_id': 'BTC-USD', 'changes': [['buy', '38364.47', '0.48380000']], 'time': '2021-05-20T03:56:23.007392Z'}
{'type': 'l2update', 'product_id': 'BTC-USD', 'changes': [['buy', '38387.49', '0.00000000']], 'time': '2021-05-20T03:56:23.009555Z'}
{'type': 'l2update', 'product_id': 'BTC-USD', 'changes': [['sell', '38418.40', '0.05721617']], 'time': '2021-05-20T03:56:23.010944Z'}
{'type': 'l2update', 'product_id': 'BTC-USD', 'changes': [['buy', '38213.69', '0.00000000']], 'time': '2021-05-20T03:56:23.016260Z'}
{'type': 'l2update', 'product_id': 'BTC-USD', 'changes': [['sell', '38483.88', '0.03256779']], 'time': '2021-05-20T03:56:23.019619Z'}
{'type': 'l2update', 'product_id': 'BTC-USD', 'changes': [['sell', '38396.68', '0.00809877']], 'time': '2021-05-20T03:56:23.024223Z'}
{'type': 'l2update', 'product_id': 'BTC-USD', 'changes': [['buy', '38375.92', '0.00000000']], 'time': '2021-05-20T03:56:23.025021Z'}
{'type': 'l2update', 'product_id': 'BTC-USD', 'changes': [['buy', '38246.10', '0.10000000']], 'time': '2021-05-20T03:56:23.028563Z'}
{'type': 'l2update', 'product_id': 'BTC-USD', 'changes': [['sell', '38480.90', '0.00000000']], 'time': '2021-05-20T03:56:23.028642Z'}
{'type': 'l2update', 'product_id': 'BTC-USD', 'changes': [['sell', '38678.16', '0.01292719']], 'time': '2021-05-20T03:56:23.028678Z'}
{'type': 'l2update', 'product_id': 'BTC-USD', 'changes': [['sell', '38527.32', '0.34796176']], 'time': '2021-05-20T03:56:23.028862Z'}
{'type': 'l2update', 'product_id': 'BTC-USD', 'changes': [['sell', '38443.31', '0.40431494']], 'time': '2021-05-20T03:56:23.028862Z'}
{'type': 'l2update', 'product_id': 'BTC-USD', 'changes': [['buy', '38388.18', '0.07460000']], 'time': '2021-05-20T03:56:23.029399Z'}
{'type': 'l2update', 'product_id': 'BTC-USD', 'changes': [['buy', '38364.47', '0.00000000']], 'time': '2021-05-20T03:56:23.031499Z'}
{'type': 'l2update', 'product_id': 'BTC-USD', 'changes': [['sell', '38518.83', '0.01000000']], 'time': '2021-05-20T03:56:23.040427Z'}
{'type': 'l2update', 'product_id': 'BTC-USD', 'changes': [['buy', '38177.51', '0.01000000']], 'time': '2021-05-20T03:56:23.045306Z'}
{'type': 'l2update', 'product_id': 'BTC-USD', 'changes': [['buy', '38386.93', '0.01492000']], 'time': '2021-05-20T03:56:23.045838Z'}
{'type': 'l2update', 'product_id': 'BTC-USD', 'changes': [['sell', '38470.66', '0.00000000']], 'time': '2021-05-20T03:56:23.048599Z'}
{'type': 'l2update', 'product_id': 'BTC-USD', 'changes': [['buy', '38364.86', '0.05721617']], 'time': '2021-05-20T03:56:23.050189Z'}
{'type': 'l2update', 'product_id': 'BTC-USD', 'changes': [['buy', '38388.18', '0.00000000']], 'time': '2021-05-20T03:56:23.050380Z'}
{'type': 'l2update', 'product_id': 'BTC-USD', 'changes': [['sell', '38425.02', '0.00000000']], 'time': '2021-05-20T03:56:23.052662Z'}
{'type': 'l2update', 'product_id': 'BTC-USD', 'changes': [['sell', '38572.51', '0.00000000']], 'time': '2021-05-20T03:56:23.056497Z'}
{'type': 'l2update', 'product_id': 'BTC-USD', 'changes': [['sell', '38396.68', '0.01149928']], 'time': '2021-05-20T03:56:23.059613Z'}
{'type': 'l2update', 'product_id': 'BTC-USD', 'changes': [['sell', '38453.45', '0.07800000']], 'time': '2021-05-20T03:56:23.059749Z'}
{'type': 'l2update', 'product_id': 'BTC-USD', 'changes': [['sell', '38396.89', '0.00439632']], 'time': '2021-05-20T03:56:23.059840Z'}
{'type': 'l2update', 'product_id': 'BTC-USD', 'changes': [['sell', '38467.89', '0.01299760']], 'time': '2021-05-20T03:56:23.059877Z'}
{'type': 'l2update', 'product_id': 'BTC-USD', 'changes': [['buy', '38246.10', '0.14000000']], 'time': '2021-05-20T03:56:23.060424Z'}
{'type': 'l2update', 'product_id': 'BTC-USD', 'changes': [['buy', '38376.12', '0.59116555']], 'time': '2021-05-20T03:56:23.060471Z'}
{'type': 'l2update', 'product_id': 'BTC-USD', 'changes': [['buy', '38284.30', '0.03378072']], 'time': '2021-05-20T03:56:23.064626Z'}
{'type': 'l2update', 'product_id': 'BTC-USD', 'changes': [['buy', '38297.00', '0.02873335']], 'time': '2021-05-20T03:56:23.064626Z'}
{'type': 'l2update', 'product_id': 'BTC-USD', 'changes': [['buy', '38305.05', '0.06303075']], 'time': '2021-05-20T03:56:23.064626Z'}
{'type': 'l2update', 'product_id': 'BTC-USD', 'changes': [['buy', '38310.42', '0.05413659']], 'time': '2021-05-20T03:56:23.064626Z'}
{'type': 'l2update', 'product_id': 'BTC-USD', 'changes': [['buy', '38320.14', '0.03493920']], 'time': '2021-05-20T03:56:23.064626Z'}
{'type': 'l2update', 'product_id': 'BTC-USD', 'changes': [['buy', '38325.45', '0.03104534']], 'time': '2021-05-20T03:56:23.064626Z'}
{'type': 'l2update', 'product_id': 'BTC-USD', 'changes': [['buy', '38330.57', '0.02846767']], 'time': '2021-05-20T03:56:23.064626Z'}
{'type': 'l2update', 'product_id': 'BTC-USD', 'changes': [['buy', '38335.50', '0.02669354']], 'time': '2021-05-20T03:56:23.064626Z'}
{'type': 'l2update', 'product_id': 'BTC-USD', 'changes': [['buy', '38386.93', '0.00000000']], 'time': '2021-05-20T03:56:23.066112Z'}
{'type': 'l2update', 'product_id': 'BTC-USD', 'changes': [['buy', '38379.70', '0.09420323']], 'time': '2021-05-20T03:56:23.069040Z'}
{'type': 'l2update', 'product_id': 'BTC-USD', 'changes': [['sell', '38396.89', '0.00000000']], 'time': '2021-05-20T03:56:23.076640Z'}
{'type': 'l2update', 'product_id': 'BTC-USD', 'changes': [['sell', '38443.31', '0.82183018']], 'time': '2021-05-20T03:56:23.077211Z'}
{'type': 'l2update', 'product_id': 'BTC-USD', 'changes': [['sell', '38397.28', '0.69100000']], 'time': '2021-05-20T03:56:23.077363Z'}
{'type': 'l2update', 'product_id': 'BTC-USD', 'changes': [['sell', '38426.96', '0.01000000']], 'time': '2021-05-20T03:56:23.078082Z'}
{'type': 'l2update', 'product_id': 'BTC-USD', 'changes': [['buy', '38262.76', '0.00000000']], 'time': '2021-05-20T03:56:23.080983Z'}
{'type': 'l2update', 'product_id': 'BTC-USD', 'changes': [['buy', '38269.27', '0.00000000']], 'time': '2021-05-20T03:56:23.080983Z'}
{'type': 'l2update', 'product_id': 'BTC-USD', 'changes': [['buy', '38269.51', '0.03493920']], 'time': '2021-05-20T03:56:23.080983Z'}
{'type': 'l2update', 'product_id': 'BTC-USD', 'changes': [['buy', '38269.51', '0.00000000']], 'time': '2021-05-20T03:56:23.080983Z'}
{'type': 'l2update', 'product_id': 'BTC-USD', 'changes': [['buy', '38299.61', '0.41050817']], 'time': '2021-05-20T03:56:23.080983Z'}
{'type': 'l2update', 'product_id': 'BTC-USD', 'changes': [['buy', '38305.05', '0.03456308']], 'time': '2021-05-20T03:56:23.080983Z'}
{'type': 'l2update', 'product_id': 'BTC-USD', 'changes': [['buy', '38310.42', '0.02744305']], 'time': '2021-05-20T03:56:23.080983Z'}
{'type': 'l2update', 'product_id': 'BTC-USD', 'changes': [['buy', '38290.19', '0.50300000']], 'time': '2021-05-20T03:56:23.081841Z'}
{'type': 'l2update', 'product_id': 'BTC-USD', 'changes': [['sell', '38396.68', '0.07460000']], 'time': '2021-05-20T03:56:23.082155Z'}
{'type': 'l2update', 'product_id': 'BTC-USD', 'changes': [['buy', '38227.29', '0.05058084']], 'time': '2021-05-20T03:56:23.082365Z'}
{'type': 'l2update', 'product_id': 'BTC-USD', 'changes': [['sell', '38559.34', '0.01000000']], 'time': '2021-05-20T03:56:23.082404Z'}
{'type': 'l2update', 'product_id': 'BTC-USD', 'changes': [['sell', '38397.28', '0.68100000']], 'time': '2021-05-20T03:56:23.090613Z'}
{'type': 'l2update', 'product_id': 'BTC-USD', 'changes': [['buy', '38359.03', '0.51900000']], 'time': '2021-05-20T03:56:23.091125Z'}
{'type': 'l2update', 'product_id': 'BTC-USD', 'changes': [['sell', '38464.95', '0.00000000']], 'time': '2021-05-20T03:56:23.091482Z'}
{'type': 'l2update', 'product_id': 'BTC-USD', 'changes': [['buy', '38386.89', '0.01492000']], 'time': '2021-05-20T03:56:23.095395Z'}
{'type': 'l2update', 'product_id': 'BTC-USD', 'changes': [['sell', '38418.42', '0.00000000']], 'time': '2021-05-20T03:56:23.097487Z'}
{'type': 'l2update', 'product_id': 'BTC-USD', 'changes': [['buy', '38347.28', '0.00000000']], 'time': '2021-05-20T03:56:23.099982Z'}
{'type': 'l2update', 'product_id': 'BTC-USD', 'changes': [['buy', '38387.46', '0.07460000']], 'time': '2021-05-20T03:56:23.103189Z'}
{'type': 'l2update', 'product_id': 'BTC-USD', 'changes': [['buy', '38344.43', '0.01000000']], 'time': '2021-05-20T03:56:23.105462Z'}
{'type': 'l2update', 'product_id': 'BTC-USD', 'changes': [['sell', '38553.97', '0.00000000']], 'time': '2021-05-20T03:56:23.105850Z'}
{'type': 'l2update', 'product_id': 'BTC-USD', 'changes': [['sell', '38559.34', '0.00000000']], 'time': '2021-05-20T03:56:23.105913Z'}
{'type': 'l2update', 'product_id': 'BTC-USD', 'changes': [['sell', '38421.80', '0.00000000']], 'time': '2021-05-20T03:56:23.109760Z'}
{'type': 'l2update', 'product_id': 'BTC-USD', 'changes': [['sell', '38460.17', '0.00000000']], 'time': '2021-05-20T03:56:23.109760Z'}
{'type': 'l2update', 'product_id': 'BTC-USD', 'changes': [['sell', '38418.44', '0.00000000']], 'time': '2021-05-20T03:56:23.109760Z'}
{'type': 'l2update', 'product_id': 'BTC-USD', 'changes': [['buy', '38036.23', '0.00000000']], 'time': '2021-05-20T03:56:23.109760Z'}
{'type': 'l2update', 'product_id': 'BTC-USD', 'changes': [['sell', '38423.18', '0.00000000']], 'time': '2021-05-20T03:56:23.110904Z'}
{'type': 'l2update', 'product_id': 'BTC-USD', 'changes': [['sell', '38396.68', '0.12460000']], 'time': '2021-05-20T03:56:23.115148Z'}
{'type': 'l2update', 'product_id': 'BTC-USD', 'changes': [['buy', '38387.46', '0.00000000']], 'time': '2021-05-20T03:56:23.116674Z'}
{'type': 'l2update', 'product_id': 'BTC-USD', 'changes': [['buy', '38222.79', '0.00000000']], 'time': '2021-05-20T03:56:23.118106Z'}
{'type': 'l2update', 'product_id': 'BTC-USD', 'changes': [['buy', '38386.89', '0.00000000']], 'time': '2021-05-20T03:56:23.118695Z'}
{'type': 'l2update', 'product_id': 'BTC-USD', 'changes': [['buy', '38289.04', '0.00100000']], 'time': '2021-05-20T03:56:23.119591Z'}
{'type': 'l2update', 'product_id': 'BTC-USD', 'changes': [['buy', '38288.03', '0.64238288']], 'time': '2021-05-20T03:56:23.119678Z'}
{'type': 'l2update', 'product_id': 'BTC-USD', 'changes': [['buy', '38297.00', '0.40494460']], 'time': '2021-05-20T03:56:23.119678Z'}
{'type': 'l2update', 'product_id': 'BTC-USD', 'changes': [['sell', '38623.28', '0.01000000']], 'time': '2021-05-20T03:56:23.130972Z'}
{'type': 'l2update', 'product_id': 'BTC-USD', 'changes': [['sell', '38507.39', '0.02766021']], 'time': '2021-05-20T03:56:23.132792Z'}
{'type': 'l2update', 'product_id': 'BTC-USD', 'changes': [['sell', '38459.39', '0.03256779']], 'time': '2021-05-20T03:56:23.132792Z'}
{'type': 'l2update', 'product_id': 'BTC-USD', 'changes': [['buy', '38248.82', '0.38999964']], 'time': '2021-05-20T03:56:23.136041Z'}
{'type': 'l2update', 'product_id': 'BTC-USD', 'changes': [['buy', '38256.36', '0.00000000']], 'time': '2021-05-20T03:56:23.136041Z'}
{'type': 'l2update', 'product_id': 'BTC-USD', 'changes': [['buy', '38337.51', '0.00000000']], 'time': '2021-05-20T03:56:23.136439Z'}
{'type': 'l2update', 'product_id': 'BTC-USD', 'changes': [['sell', '38441.01', '0.50000000']], 'time': '2021-05-20T03:56:23.138247Z'}
{'type': 'l2update', 'product_id': 'BTC-USD', 'changes': [['sell', '38426.96', '0.00000000']], 'time': '2021-05-20T03:56:23.144206Z'}
{'type': 'l2update', 'product_id': 'BTC-USD', 'changes': [['sell', '38396.68', '0.13460000']], 'time': '2021-05-20T03:56:23.146609Z'}
{'type': 'l2update', 'product_id': 'BTC-USD', 'changes': [['buy', '38387.38', '0.07460000']], 'time': '2021-05-20T03:56:23.146692Z'}
{'type': 'l2update', 'product_id': 'BTC-USD', 'changes': [['buy', '38386.88', '0.01492000']], 'time': '2021-05-20T03:56:23.147307Z'}
{'type': 'l2update', 'product_id': 'BTC-USD', 'changes': [['buy', '38364.43', '0.47820000']], 'time': '2021-05-20T03:56:23.147607Z'}
{'type': 'l2update', 'product_id': 'BTC-USD', 'changes': [['sell', '38483.88', '0.00000000']], 'time': '2021-05-20T03:56:23.149475Z'}
{'type': 'l2update', 'product_id': 'BTC-USD', 'changes': [['buy', '38396.63', '0.15000000']], 'time': '2021-05-20T03:56:23.150484Z'}
{'type': 'l2update', 'product_id': 'BTC-USD', 'changes': [['buy', '38344.43', '0.00000000']], 'time': '2021-05-20T03:56:23.157809Z'}
{'type': 'l2update', 'product_id': 'BTC-USD', 'changes': [['sell', '38418.40', '0.00000000']], 'time': '2021-05-20T03:56:23.158024Z'}
{'type': 'l2update', 'product_id': 'BTC-USD', 'changes': [['buy', '38166.80', '1.00900000']], 'time': '2021-05-20T03:56:23.159607Z'}
{'type': 'l2update', 'product_id': 'BTC-USD', 'changes': [['sell', '38429.50', '0.07800000']], 'time': '2021-05-20T03:56:23.160446Z'}
{'type': 'l2update', 'product_id': 'BTC-USD', 'changes': [['buy', '38356.20', '0.01193666']], 'time': '2021-05-20T03:56:23.163789Z'}
{'type': 'l2update', 'product_id': 'BTC-USD', 'changes': [['buy', '38387.38', '0.00000000']], 'time': '2021-05-20T03:56:23.164396Z'}
{'type': 'l2update', 'product_id': 'BTC-USD', 'changes': [['buy', '38386.88', '0.00000000']], 'time': '2021-05-20T03:56:23.166875Z'}
{'type': 'l2update', 'product_id': 'BTC-USD', 'changes': [['sell', '38396.68', '0.12650123']], 'time': '2021-05-20T03:56:23.170722Z'}
{'type': 'l2update', 'product_id': 'BTC-USD', 'changes': [['sell', '38413.92', '0.00000000']], 'time': '2021-05-20T03:56:23.171286Z'}
{'type': 'l2update', 'product_id': 'BTC-USD', 'changes': [['buy', '38359.04', '0.05721617']], 'time': '2021-05-20T03:56:23.172449Z'}
{'type': 'l2update', 'product_id': 'BTC-USD', 'changes': [['sell', '38527.32', '0.65823773']], 'time': '2021-05-20T03:56:23.172493Z'}
{'type': 'l2update', 'product_id': 'BTC-USD', 'changes': [['sell', '38423.29', '0.46230000']], 'time': '2021-05-20T03:56:23.173339Z'}
{'type': 'l2update', 'product_id': 'BTC-USD', 'changes': [['sell', '38403.43', '0.00000000']], 'time': '2021-05-20T03:56:23.174325Z'}
{'type': 'l2update', 'product_id': 'BTC-USD', 'changes': [['sell', '38398.58', '0.00000000']], 'time': '2021-05-20T03:56:23.177751Z'}
{'type': 'l2update', 'product_id': 'BTC-USD', 'changes': [['sell', '38396.64', '0.10000000']], 'time': '2021-05-20T03:56:23.181953Z'}
{'type': 'l2update', 'product_id': 'BTC-USD', 'changes': [['sell', '38446.47', '0.06600000']], 'time': '2021-05-20T03:56:23.182513Z'}
{'type': 'l2update', 'product_id': 'BTC-USD', 'changes': [['sell', '38465.68', '0.20400000']], 'time': '2021-05-20T03:56:23.182513Z'}
{'type': 'l2update', 'product_id': 'BTC-USD', 'changes': [['sell', '38504.09', '0.66500000']], 'time': '2021-05-20T03:56:23.182513Z'}
{'type': 'l2update', 'product_id': 'BTC-USD', 'changes': [['buy', '38129.88', '6.73100000']], 'time': '2021-05-20T03:56:23.182513Z'}
{'type': 'l2update', 'product_id': 'BTC-USD', 'changes': [['buy', '38342.30', '0.09515682']], 'time': '2021-05-20T03:56:23.182694Z'}
{'type': 'l2update', 'product_id': 'BTC-USD', 'changes': [['buy', '38364.86', '0.00000000']], 'time': '2021-05-20T03:56:23.183687Z'}
{'type': 'l2update', 'product_id': 'BTC-USD', 'changes': [['sell', '38396.68', '0.12310072']], 'time': '2021-05-20T03:56:23.183708Z'}
{'type': 'l2update', 'product_id': 'BTC-USD', 'changes': [['sell', '38457.07', '0.02744305']], 'time': '2021-05-20T03:56:23.186725Z'}
{'type': 'l2update', 'product_id': 'BTC-USD', 'changes': [['buy', '38390.95', '0.05056830']], 'time': '2021-05-20T03:56:23.186808Z'}
{'type': 'l2update', 'product_id': 'BTC-USD', 'changes': [['sell', '38396.68', '0.06000000']], 'time': '2021-05-20T03:56:23.188737Z'}
{'type': 'l2update', 'product_id': 'BTC-USD', 'changes': [['sell', '38427.26', '0.01000000']], 'time': '2021-05-20T03:56:23.192220Z'}
{'type': 'l2update', 'product_id': 'BTC-USD', 'changes': [['sell', '38438.59', '0.07800000']], 'time': '2021-05-20T03:56:23.192249Z'}
{'type': 'l2update', 'product_id': 'BTC-USD', 'changes': [['sell', '38432.31', '0.05000000']], 'time': '2021-05-20T03:56:23.199322Z'}
{'type': 'l2update', 'product_id': 'BTC-USD', 'changes': [['buy', '38347.05', '0.63928218']], 'time': '2021-05-20T03:56:23.199371Z'}
{'type': 'l2update', 'product_id': 'BTC-USD', 'changes': [['sell', '38397.27', '2.48969908']], 'time': '2021-05-20T03:56:23.203203Z'}
{'type': 'l2update', 'product_id': 'BTC-USD', 'changes': [['sell', '38535.99', '0.30897594']], 'time': '2021-05-20T03:56:23.205498Z'}
{'type': 'l2update', 'product_id': 'BTC-USD', 'changes': [['sell', '38432.31', '0.14430186']], 'time': '2021-05-20T03:56:23.208640Z'}
{'type': 'l2update', 'product_id': 'BTC-USD', 'changes': [['sell', '38396.64', '0.30000000']], 'time': '2021-05-20T03:56:23.208828Z'}
{'type': 'l2update', 'product_id': 'BTC-USD', 'changes': [['buy', '38386.26', '0.00000000']], 'time': '2021-05-20T03:56:23.211489Z'}
{'type': 'l2update', 'product_id': 'BTC-USD', 'changes': [['buy', '38277.08', '0.03543107']], 'time': '2021-05-20T03:56:23.212335Z'}
{'type': 'l2update', 'product_id': 'BTC-USD', 'changes': [['sell', '43100.00', '1.09530000']], 'time': '2021-05-20T03:56:23.215610Z'}
{'type': 'l2update', 'product_id': 'BTC-USD', 'changes': [['sell', '38432.31', '0.09430186']], 'time': '2021-05-20T03:56:23.217873Z'}
{'type': 'l2update', 'product_id': 'BTC-USD', 'changes': [['sell', '38400.54', '0.00000000']], 'time': '2021-05-20T03:56:23.219949Z'}
{'type': 'l2update', 'product_id': 'BTC-USD', 'changes': [['sell', '38413.93', '0.00000000']], 'time': '2021-05-20T03:56:23.220064Z'}
{'type': 'l2update', 'product_id': 'BTC-USD', 'changes': [['buy', '38304.95', '0.01133744']], 'time': '2021-05-20T03:56:23.220195Z'}
{'type': 'l2update', 'product_id': 'BTC-USD', 'changes': [['buy', '38344.73', '0.01000000']], 'time': '2021-05-20T03:56:23.221753Z'}
{'type': 'l2update', 'product_id': 'BTC-USD', 'changes': [['sell', '38658.97', '0.00000000']], 'time': '2021-05-20T03:56:23.226449Z'}
{'type': 'l2update', 'product_id': 'BTC-USD', 'changes': [['buy', '38221.73', '0.00000000']], 'time': '2021-05-20T03:56:23.226935Z'}
{'type': 'l2update', 'product_id': 'BTC-USD', 'changes': [['sell', '38410.98', '0.50000000']], 'time': '2021-05-20T03:56:23.232821Z'}
{'type': 'l2update', 'product_id': 'BTC-USD', 'changes': [['sell', '38623.28', '0.00000000']], 'time': '2021-05-20T03:56:23.235734Z'}
{'type': 'l2update', 'product_id': 'BTC-USD', 'changes': [['sell', '38534.76', '0.41670907']], 'time': '2021-05-20T03:56:23.240846Z'}
{'type': 'l2update', 'product_id': 'BTC-USD', 'changes': [['sell', '38464.95', '0.29850813']], 'time': '2021-05-20T03:56:23.240846Z'}
{'type': 'l2update', 'product_id': 'BTC-USD', 'changes': [['sell', '38508.96', '0.06127402']], 'time': '2021-05-20T03:56:23.243475Z'}
{'type': 'l2update', 'product_id': 'BTC-USD', 'changes': [['sell', '38507.39', '0.00000000']], 'time': '2021-05-20T03:56:23.243475Z'}
{'type': 'l2update', 'product_id': 'BTC-USD', 'changes': [['sell', '38499.73', '0.00000000']], 'time': '2021-05-20T03:56:23.243475Z'}
{'type': 'l2update', 'product_id': 'BTC-USD', 'changes': [['sell', '38496.27', '0.00000000']], 'time': '2021-05-20T03:56:23.243475Z'}
{'type': 'l2update', 'product_id': 'BTC-USD', 'changes': [['buy', '38379.90', '0.84500000']], 'time': '2021-05-20T03:56:23.244504Z'}
{'type': 'l2update', 'product_id': 'BTC-USD', 'changes': [['sell', '38423.28', '0.05000000']], 'time': '2021-05-20T03:56:23.248114Z'}
{'type': 'l2update', 'product_id': 'BTC-USD', 'changes': [['buy', '38376.17', '0.52000000']], 'time': '2021-05-20T03:56:23.248370Z'}
{'type': 'l2update', 'product_id': 'BTC-USD', 'changes': [['sell', '43100.00', '2.31590000']], 'time': '2021-05-20T03:56:23.248636Z'}
{'type': 'l2update', 'product_id': 'BTC-USD', 'changes': [['sell', '38510.24', '0.01000000']], 'time': '2021-05-20T03:56:23.252300Z'}
{'type': 'l2update', 'product_id': 'BTC-USD', 'changes': [['sell', '38678.16', '0.00000000']], 'time': '2021-05-20T03:56:23.264971Z'}
{'type': 'l2update', 'product_id': 'BTC-USD', 'changes': [['sell', '38640.99', '0.00646981']], 'time': '2021-05-20T03:56:23.265588Z'}
{'type': 'l2update', 'product_id': 'BTC-USD', 'changes': [['sell', '38502.10', '0.41989879']], 'time': '2021-05-20T03:56:23.268696Z'}
{'type': 'l2update', 'product_id': 'BTC-USD', 'changes': [['sell', '38597.46', '0.01000000']], 'time': '2021-05-20T03:56:23.272617Z'}
{'type': 'l2update', 'product_id': 'BTC-USD', 'changes': [['sell', '38610.00', '0.00000000']], 'time': '2021-05-20T03:56:23.272923Z'}
{'type': 'l2update', 'product_id': 'BTC-USD', 'changes': [['sell', '38397.28', '0.09000000']], 'time': '2021-05-20T03:56:23.273542Z'}
{'type': 'l2update', 'product_id': 'BTC-USD', 'changes': [['sell', '38493.12', '0.00000000']], 'time': '2021-05-20T03:56:23.274870Z'}
{'type': 'l2update', 'product_id': 'BTC-USD', 'changes': [['sell', '38440.56', '0.02744305']], 'time': '2021-05-20T03:56:23.276804Z'}
{'type': 'l2update', 'product_id': 'BTC-USD', 'changes': [['sell', '38398.94', '0.00000000']], 'time': '2021-05-20T03:56:23.277112Z'}
{'type': 'l2update', 'product_id': 'BTC-USD', 'changes': [['sell', '38410.98', '0.00000000']], 'time': '2021-05-20T03:56:23.281620Z'}
{'type': 'l2update', 'product_id': 'BTC-USD', 'changes': [['buy', '38177.51', '0.00000000']], 'time': '2021-05-20T03:56:23.285554Z'}
{'type': 'l2update', 'product_id': 'BTC-USD', 'changes': [['sell', '38516.52', '0.00000000']], 'time': '2021-05-20T03:56:23.293306Z'}
{'type': 'l2update', 'product_id': 'BTC-USD', 'changes': [['sell', '38502.10', '0.00000000']], 'time': '2021-05-20T03:56:23.293306Z'}
{'type': 'l2update', 'product_id': 'BTC-USD', 'changes': [['buy', '38339.41', '0.00000000']], 'time': '2021-05-20T03:56:23.293574Z'}
{'type': 'l2update', 'product_id': 'BTC-USD', 'changes': [['buy', '38370.43', '0.00000000']], 'time': '2021-05-20T03:56:23.293638Z'}
{'type': 'l2update', 'product_id': 'BTC-USD', 'changes': [['buy', '38364.85', '0.00000000']], 'time': '2021-05-20T03:56:23.294318Z'}
{'type': 'l2update', 'product_id': 'BTC-USD', 'changes': [['buy', '38379.70', '0.00000000']], 'time': '2021-05-20T03:56:23.295334Z'}
{'type': 'l2update', 'product_id': 'BTC-USD', 'changes': [['sell', '38457.07', '0.00000000']], 'time': '2021-05-20T03:56:23.297232Z'}
{'type': 'l2update', 'product_id': 'BTC-USD', 'changes': [['buy', '38376.12', '0.00000000']], 'time': '2021-05-20T03:56:23.301607Z'}
{'type': 'l2update', 'product_id': 'BTC-USD', 'changes': [['sell', '38664.09', '0.01000000']], 'time': '2021-05-20T03:56:23.304748Z'}
{'type': 'l2update', 'product_id': 'BTC-USD', 'changes': [['sell', '38520.75', '0.01000000']], 'time': '2021-05-20T03:56:23.305830Z'}
{'type': 'l2update', 'product_id': 'BTC-USD', 'changes': [['sell', '38474.61', '0.00000000']], 'time': '2021-05-20T03:56:23.306423Z'}
{'type': 'l2update', 'product_id': 'BTC-USD', 'changes': [['sell', '38421.79', '0.05721617']], 'time': '2021-05-20T03:56:23.306582Z'}
{'type': 'l2update', 'product_id': 'BTC-USD', 'changes': [['sell', '38397.27', '0.00000000']], 'time': '2021-05-20T03:56:23.310173Z'}
{'type': 'l2update', 'product_id': 'BTC-USD', 'changes': [['sell', '38418.48', '0.50000000']], 'time': '2021-05-20T03:56:23.316550Z'}
{'type': 'l2update', 'product_id': 'BTC-USD', 'changes': [['buy', '38197.50', '0.01000000']], 'time': '2021-05-20T03:56:23.316792Z'}
{'type': 'l2update', 'product_id': 'BTC-USD', 'changes': [['buy', '38359.60', '0.00000000']], 'time': '2021-05-20T03:56:23.324402Z'}
{'type': 'l2update', 'product_id': 'BTC-USD', 'changes': [['sell', '38507.39', '0.03416540']], 'time': '2021-05-20T03:56:23.331745Z'}
{'type': 'l2update', 'product_id': 'BTC-USD', 'changes': [['buy', '38376.18', '1.46756192']], 'time': '2021-05-20T03:56:23.333203Z'}
{'type': 'l2update', 'product_id': 'BTC-USD', 'changes': [['buy', '38382.20', '0.06000000']], 'time': '2021-05-20T03:56:23.341290Z'}
{'type': 'l2update', 'product_id': 'BTC-USD', 'changes': [['sell', '38432.31', '0.15151803']], 'time': '2021-05-20T03:56:23.345142Z'}
{'type': 'l2update', 'product_id': 'BTC-USD', 'changes': [['sell', '38423.29', '0.00000000']], 'time': '2021-05-20T03:56:23.348904Z'}
{'type': 'l2update', 'product_id': 'BTC-USD', 'changes': [['sell', '38427.26', '0.00000000']], 'time': '2021-05-20T03:56:23.355620Z'}
{'type': 'l2update', 'product_id': 'BTC-USD', 'changes': [['buy', '38359.04', '0.00000000']], 'time': '2021-05-20T03:56:23.356115Z'}
{'type': 'l2update', 'product_id': 'BTC-USD', 'changes': [['buy', '38355.99', '0.05721617']], 'time': '2021-05-20T03:56:23.358156Z'}
{'type': 'l2update', 'product_id': 'BTC-USD', 'changes': [['sell', '38491.02', '0.03705627']], 'time': '2021-05-20T03:56:23.358280Z'}
{'type': 'l2update', 'product_id': 'BTC-USD', 'changes': [['sell', '38479.40', '0.02802275']], 'time': '2021-05-20T03:56:23.358280Z'}
{'type': 'l2update', 'product_id': 'BTC-USD', 'changes': [['sell', '38473.88', '0.03459727']], 'time': '2021-05-20T03:56:23.358280Z'}
{'type': 'l2update', 'product_id': 'BTC-USD', 'changes': [['sell', '38468.55', '0.02667675']], 'time': '2021-05-20T03:56:23.358280Z'}
{'type': 'l2update', 'product_id': 'BTC-USD', 'changes': [['buy', '38382.18', '0.09420323']], 'time': '2021-05-20T03:56:23.359446Z'}
{'type': 'l2update', 'product_id': 'BTC-USD', 'changes': [['sell', '38534.76', '0.77125576']], 'time': '2021-05-20T03:56:23.359496Z'}
{'type': 'l2update', 'product_id': 'BTC-USD', 'changes': [['sell', '38491.02', '0.34733224']], 'time': '2021-05-20T03:56:23.359496Z'}
{'type': 'l2update', 'product_id': 'BTC-USD', 'changes': [['sell', '38479.40', '0.46423548']], 'time': '2021-05-20T03:56:23.359496Z'}
{'type': 'l2update', 'product_id': 'BTC-USD', 'changes': [['sell', '38398.99', '2.48969908']], 'time': '2021-05-20T03:56:23.359625Z'}
{'type': 'l2update', 'product_id': 'BTC-USD', 'changes': [['sell', '38664.09', '0.00000000']], 'time': '2021-05-20T03:56:23.364001Z'}
{'type': 'l2update', 'product_id': 'BTC-USD', 'changes': [['buy', '38347.05', '0.00000000']], 'time': '2021-05-20T03:56:23.367141Z'}
{'type': 'l2update', 'product_id': 'BTC-USD', 'changes': [['sell', '38405.80', '1.14000000']], 'time': '2021-05-20T03:56:23.367302Z'}
{'type': 'l2update', 'product_id': 'BTC-USD', 'changes': [['buy', '38197.50', '0.00000000']], 'time': '2021-05-20T03:56:23.367336Z'}
{'type': 'l2update', 'product_id': 'BTC-USD', 'changes': [['buy', '38344.73', '0.00000000']], 'time': '2021-05-20T03:56:23.368783Z'}
{'type': 'l2update', 'product_id': 'BTC-USD', 'changes': [['sell', '38530.09', '0.00000000']], 'time': '2021-05-20T03:56:23.370414Z'}
{'type': 'l2update', 'product_id': 'BTC-USD', 'changes': [['sell', '38421.79', '0.00000000']], 'time': '2021-05-20T03:56:23.372650Z'}
{'type': 'l2update', 'product_id': 'BTC-USD', 'changes': [['sell', '38511.66', '0.00000000']], 'time': '2021-05-20T03:56:23.372723Z'}
{'type': 'l2update', 'product_id': 'BTC-USD', 'changes': [['sell', '38508.96', '0.02667675']], 'time': '2021-05-20T03:56:23.372723Z'}
{'type': 'l2update', 'product_id': 'BTC-USD', 'changes': [['sell', '38508.96', '0.00000000']], 'time': '2021-05-20T03:56:23.372723Z'}
{'type': 'l2update', 'product_id': 'BTC-USD', 'changes': [['sell', '38426.03', '0.47870000']], 'time': '2021-05-20T03:56:23.373551Z'}
{'type': 'l2update', 'product_id': 'BTC-USD', 'changes': [['buy', '38379.91', '0.59116555']], 'time': '2021-05-20T03:56:23.374190Z'}
{'type': 'l2update', 'product_id': 'BTC-USD', 'changes': [['buy', '38376.18', '0.00000000']], 'time': '2021-05-20T03:56:23.375151Z'}
{'type': 'l2update', 'product_id': 'BTC-USD', 'changes': [['sell', '38527.32', '0.34796176']], 'time': '2021-05-20T03:56:23.376062Z'}
{'type': 'l2update', 'product_id': 'BTC-USD', 'changes': [['sell', '38522.90', '0.00000000']], 'time': '2021-05-20T03:56:23.376062Z'}
{'type': 'l2update', 'product_id': 'BTC-USD', 'changes': [['buy', '38342.30', '0.00000000']], 'time': '2021-05-20T03:56:23.378881Z'}
{'type': 'l2update', 'product_id': 'BTC-USD', 'changes': [['buy', '38376.11', '0.00000000']], 'time': '2021-05-20T03:56:23.379885Z'}
{'type': 'l2update', 'product_id': 'BTC-USD', 'changes': [['buy', '38227.29', '0.00000000']], 'time': '2021-05-20T03:56:23.381585Z'}
{'type': 'l2update', 'product_id': 'BTC-USD', 'changes': [['buy', '38193.14', '0.00000000']], 'time': '2021-05-20T03:56:23.382529Z'}
{'type': 'l2update', 'product_id': 'BTC-USD', 'changes': [['buy', '38396.63', '0.00000000']], 'time': '2021-05-20T03:56:23.383654Z'}
{'type': 'l2update', 'product_id': 'BTC-USD', 'changes': [['sell', '38396.63', '0.05000000']], 'time': '2021-05-20T03:56:23.383654Z'}
{'type': 'l2update', 'product_id': 'BTC-USD', 'changes': [['buy', '38376.17', '0.00000000']], 'time': '2021-05-20T03:56:23.384393Z'}
{'type': 'l2update', 'product_id': 'BTC-USD', 'changes': [['buy', '38359.04', '0.05721617']], 'time': '2021-05-20T03:56:23.384689Z'}
{'type': 'l2update', 'product_id': 'BTC-USD', 'changes': [['buy', '38379.90', '0.00000000']], 'time': '2021-05-20T03:56:23.385543Z'}
{'type': 'l2update', 'product_id': 'BTC-USD', 'changes': [['sell', '38426.03', '0.00000000']], 'time': '2021-05-20T03:56:23.387310Z'}
{'type': 'l2update', 'product_id': 'BTC-USD', 'changes': [['buy', '38382.18', '0.00000000']], 'time': '2021-05-20T03:56:23.388621Z'}
{'type': 'l2update', 'product_id': 'BTC-USD', 'changes': [['sell', '38396.64', '1.46052079']], 'time': '2021-05-20T03:56:23.388967Z'}
{'type': 'l2update', 'product_id': 'BTC-USD', 'changes': [['sell', '38644.89', '0.01000000']], 'time': '2021-05-20T03:56:23.389080Z'}
{'type': 'l2update', 'product_id': 'BTC-USD', 'changes': [['sell', '38423.28', '0.00000000']], 'time': '2021-05-20T03:56:23.390275Z'}
{'type': 'l2update', 'product_id': 'BTC-USD', 'changes': [['buy', '38363.51', '0.00000000']], 'time': '2021-05-20T03:56:23.392180Z'}
{'type': 'l2update', 'product_id': 'BTC-USD', 'changes': [['sell', '38432.31', '0.05721617']], 'time': '2021-05-20T03:56:23.394046Z'}
{'type': 'l2update', 'product_id': 'BTC-USD', 'changes': [['buy', '38370.48', '0.00000000']], 'time': '2021-05-20T03:56:23.394378Z'}
{'type': 'l2update', 'product_id': 'BTC-USD', 'changes': [['buy', '38347.04', '0.00000000']], 'time': '2021-05-20T03:56:23.395635Z'}
{'type': 'l2update', 'product_id': 'BTC-USD', 'changes': [['sell', '38507.39', '0.06480730']], 'time': '2021-05-20T03:56:23.396001Z'}
{'type': 'l2update', 'product_id': 'BTC-USD', 'changes': [['sell', '38516.40', '0.03432409']], 'time': '2021-05-20T03:56:23.396776Z'}
{'type': 'l2update', 'product_id': 'BTC-USD', 'changes': [['sell', '38396.64', '1.36052079']], 'time': '2021-05-20T03:56:23.400191Z'}
{'type': 'l2update', 'product_id': 'BTC-USD', 'changes': [['buy', '38355.99', '0.00000000']], 'time': '2021-05-20T03:56:23.400953Z'}
{'type': 'l2update', 'product_id': 'BTC-USD', 'changes': [['sell', '38432.81', '0.03207306']], 'time': '2021-05-20T03:56:23.403179Z'}
{'type': 'l2update', 'product_id': 'BTC-USD', 'changes': [['buy', '38390.95', '0.00000000']], 'time': '2021-05-20T03:56:23.405829Z'}
{'type': 'l2update', 'product_id': 'BTC-USD', 'changes': [['buy', '38375.96', '0.00000000']], 'time': '2021-05-20T03:56:23.407321Z'}
{'type': 'l2update', 'product_id': 'BTC-USD', 'changes': [['sell', '38396.63', '0.65000000']], 'time': '2021-05-20T03:56:23.407599Z'}
{'type': 'l2update', 'product_id': 'BTC-USD', 'changes': [['buy', '38370.42', '0.00000000']], 'time': '2021-05-20T03:56:23.408270Z'}
{'type': 'l2update', 'product_id': 'BTC-USD', 'changes': [['sell', '38432.31', '0.00000000']], 'time': '2021-05-20T03:56:23.408970Z'}
{'type': 'l2update', 'product_id': 'BTC-USD', 'changes': [['sell', '38400.12', '0.05038140']], 'time': '2021-05-20T03:56:23.409020Z'}
{'type': 'l2update', 'product_id': 'BTC-USD', 'changes': [['buy', '38299.77', '0.01000000']], 'time': '2021-05-20T03:56:23.409232Z'}
{'type': 'l2update', 'product_id': 'BTC-USD', 'changes': [['buy', '38364.32', '0.00000000']], 'time': '2021-05-20T03:56:23.410862Z'}
{'type': 'l2update', 'product_id': 'BTC-USD', 'changes': [['sell', '38396.62', '1.33906246']], 'time': '2021-05-20T03:56:23.414286Z'}
{'type': 'l2update', 'product_id': 'BTC-USD', 'changes': [['sell', '38396.64', '1.16052079']], 'time': '2021-05-20T03:56:23.415156Z'}
{'type': 'l2update', 'product_id': 'BTC-USD', 'changes': [['buy', '38364.43', '0.00000000']], 'time': '2021-05-20T03:56:23.417015Z'}
{'type': 'l2update', 'product_id': 'BTC-USD', 'changes': [['sell', '38447.12', '0.00000000']], 'time': '2021-05-20T03:56:23.417486Z'}
{'type': 'l2update', 'product_id': 'BTC-USD', 'changes': [['buy', '38197.48', '0.00000000']], 'time': '2021-05-20T03:56:23.418683Z'}
{'type': 'l2update', 'product_id': 'BTC-USD', 'changes': [['sell', '38426.02', '0.05000000']], 'time': '2021-05-20T03:56:23.418930Z'}
{'type': 'l2update', 'product_id': 'BTC-USD', 'changes': [['buy', '38385.74', '0.09420323']], 'time': '2021-05-20T03:56:23.419492Z'}
{'type': 'l2update', 'product_id': 'BTC-USD', 'changes': [['buy', '38382.14', '0.00000000']], 'time': '2021-05-20T03:56:23.422111Z'}
{'type': 'l2update', 'product_id': 'BTC-USD', 'changes': [['buy', '38365.47', '0.00000000']], 'time': '2021-05-20T03:56:23.429223Z'}
{'type': 'l2update', 'product_id': 'BTC-USD', 'changes': [['sell', '38516.56', '0.03010725']], 'time': '2021-05-20T03:56:23.430298Z'}
{'type': 'l2update', 'product_id': 'BTC-USD', 'changes': [['sell', '38396.63', '0.60000000']], 'time': '2021-05-20T03:56:23.433317Z'}
{'type': 'l2update', 'product_id': 'BTC-USD', 'changes': [['buy', '38382.76', '0.01492000']], 'time': '2021-05-20T03:56:23.434711Z'}
{'type': 'l2update', 'product_id': 'BTC-USD', 'changes': [['sell', '38395.97', '0.07460000']], 'time': '2021-05-20T03:56:23.434911Z'}
{'type': 'l2update', 'product_id': 'BTC-USD', 'changes': [['buy', '38290.20', '0.09062903']], 'time': '2021-05-20T03:56:23.435023Z'}
{'type': 'l2update', 'product_id': 'BTC-USD', 'changes': [['buy', '38370.49', '1.46756192']], 'time': '2021-05-20T03:56:23.435120Z'}
{'type': 'l2update', 'product_id': 'BTC-USD', 'changes': [['sell', '38426.02', '0.00000000']], 'time': '2021-05-20T03:56:23.436474Z'}
{'type': 'l2update', 'product_id': 'BTC-USD', 'changes': [['buy', '38379.91', '0.00000000']], 'time': '2021-05-20T03:56:23.436886Z'}
{'type': 'l2update', 'product_id': 'BTC-USD', 'changes': [['buy', '38355.98', '0.00000000']], 'time': '2021-05-20T03:56:23.436936Z'}
{'type': 'l2update', 'product_id': 'BTC-USD', 'changes': [['sell', '38443.30', '0.48308538']], 'time': '2021-05-20T03:56:23.439942Z'}
{'type': 'l2update', 'product_id': 'BTC-USD', 'changes': [['sell', '38429.49', '0.05721617']], 'time': '2021-05-20T03:56:23.440049Z'}
{'type': 'l2update', 'product_id': 'BTC-USD', 'changes': [['buy', '38382.20', '0.00000000']], 'time': '2021-05-20T03:56:23.444253Z'}
{'type': 'l2update', 'product_id': 'BTC-USD', 'changes': [['sell', '38534.76', '1.08316405']], 'time': '2021-05-20T03:56:23.444882Z'}
{'type': 'l2update', 'product_id': 'BTC-USD', 'changes': [['sell', '38491.02', '0.69529400']], 'time': '2021-05-20T03:56:23.444882Z'}
{'type': 'l2update', 'product_id': 'BTC-USD', 'changes': [['sell', '38395.97', '0.05948819']], 'time': '2021-05-20T03:56:23.445560Z'}
{'type': 'l2update', 'product_id': 'BTC-USD', 'changes': [['buy', '38363.21', '0.45310000']], 'time': '2021-05-20T03:56:23.445702Z'}
{'type': 'l2update', 'product_id': 'BTC-USD', 'changes': [['buy', '38382.76', '0.00000000']], 'time': '2021-05-20T03:56:23.449601Z'}
{'type': 'l2update', 'product_id': 'BTC-USD', 'changes': [['sell', '38401.07', '0.00600000']], 'time': '2021-05-20T03:56:23.450186Z'}
{'type': 'l2update', 'product_id': 'BTC-USD', 'changes': [['sell', '38395.98', '0.01492000']], 'time': '2021-05-20T03:56:23.456735Z'}
{'type': 'l2update', 'product_id': 'BTC-USD', 'changes': [['sell', '38503.41', '0.02970825']], 'time': '2021-05-20T03:56:23.456799Z'}
{'type': 'l2update', 'product_id': 'BTC-USD', 'changes': [['sell', '38418.47', '0.05000000']], 'time': '2021-05-20T03:56:23.456845Z'}
{'type': 'l2update', 'product_id': 'BTC-USD', 'changes': [['sell', '38462.45', '0.09069974']], 'time': '2021-05-20T03:56:23.456882Z'}
{'type': 'l2update', 'product_id': 'BTC-USD', 'changes': [['buy', '38353.79', '0.02390000']], 'time': '2021-05-20T03:56:23.458342Z'}
{'type': 'l2update', 'product_id': 'BTC-USD', 'changes': [['buy', '38352.99', '0.02390000']], 'time': '2021-05-20T03:56:23.458342Z'}
{'type': 'l2update', 'product_id': 'BTC-USD', 'changes': [['buy', '38352.18', '0.02390000']], 'time': '2021-05-20T03:56:23.458342Z'}
{'type': 'l2update', 'product_id': 'BTC-USD', 'changes': [['sell', '38527.32', '0.00000000']], 'time': '2021-05-20T03:56:23.460401Z'}
{'type': 'l2update', 'product_id': 'BTC-USD', 'changes': [['buy', '38363.21', '0.00000000']], 'time': '2021-05-20T03:56:23.461175Z'}
{'type': 'l2update', 'product_id': 'BTC-USD', 'changes': [['buy', '38360.88', '0.05079797']], 'time': '2021-05-20T03:56:23.462683Z'}
{'type': 'l2update', 'product_id': 'BTC-USD', 'changes': [['sell', '38395.96', '1.14776782']], 'time': '2021-05-20T03:56:23.468078Z'}
{'type': 'l2update', 'product_id': 'BTC-USD', 'changes': [['sell', '38395.98', '0.00000000']], 'time': '2021-05-20T03:56:23.472833Z'}
{'type': 'l2update', 'product_id': 'BTC-USD', 'changes': [['sell', '38418.47', '0.00000000']], 'time': '2021-05-20T03:56:23.473214Z'}
{'type': 'l2update', 'product_id': 'BTC-USD', 'changes': [['buy', '38370.49', '0.00000000']], 'time': '2021-05-20T03:56:23.473246Z'}
{'type': 'l2update', 'product_id': 'BTC-USD', 'changes': [['sell', '38442.46', '0.00000000']], 'time': '2021-05-20T03:56:23.473655Z'}
{'type': 'l2update', 'product_id': 'BTC-USD', 'changes': [['buy', '38353.79', '0.00000000']], 'time': '2021-05-20T03:56:23.478433Z'}
{'type': 'l2update', 'product_id': 'BTC-USD', 'changes': [['sell', '38396.57', '1.41500000']], 'time': '2021-05-20T03:56:23.479159Z'}
{'type': 'l2update', 'product_id': 'BTC-USD', 'changes': [['buy', '38376.85', '0.52114772']], 'time': '2021-05-20T03:56:23.479307Z'}
{'type': 'l2update', 'product_id': 'BTC-USD', 'changes': [['sell', '38491.02', '0.65823773']], 'time': '2021-05-20T03:56:23.479545Z'}
{'type': 'l2update', 'product_id': 'BTC-USD', 'changes': [['sell', '38473.88', '0.00000000']], 'time': '2021-05-20T03:56:23.479545Z'}
{'type': 'l2update', 'product_id': 'BTC-USD', 'changes': [['sell', '38468.55', '0.00000000']], 'time': '2021-05-20T03:56:23.479545Z'}
{'type': 'l2update', 'product_id': 'BTC-USD', 'changes': [['sell', '38459.39', '0.00000000']], 'time': '2021-05-20T03:56:23.479545Z'}
{'type': 'l2update', 'product_id': 'BTC-USD', 'changes': [['buy', '38386.21', '0.01559088']], 'time': '2021-05-20T03:56:23.479906Z'}
{'type': 'l2update', 'product_id': 'BTC-USD', 'changes': [['sell', '38528.33', '0.00000000']], 'time': '2021-05-20T03:56:23.482595Z'}
{'type': 'l2update', 'product_id': 'BTC-USD', 'changes': [['sell', '38397.27', '0.00128419']], 'time': '2021-05-20T03:56:23.483405Z'}
{'type': 'l2update', 'product_id': 'BTC-USD', 'changes': [['buy', '37000.00', '9.26842899']], 'time': '2021-05-20T03:56:23.483477Z'}
{'type': 'l2update', 'product_id': 'BTC-USD', 'changes': [['buy', '38370.50', '0.59116555']], 'time': '2021-05-20T03:56:23.483812Z'}
{'type': 'l2update', 'product_id': 'BTC-USD', 'changes': [['sell', '38395.97', '0.00000000']], 'time': '2021-05-20T03:56:23.484395Z'}
{'type': 'l2update', 'product_id': 'BTC-USD', 'changes': [['buy', '38386.21', '0.00000000']], 'time': '2021-05-20T03:56:23.492118Z'}
{'type': 'l2update', 'product_id': 'BTC-USD', 'changes': [['buy', '38385.74', '0.01559411']], 'time': '2021-05-20T03:56:23.492118Z'}
{'type': 'l2update', 'product_id': 'BTC-USD', 'changes': [['sell', '38412.15', '0.40990000']], 'time': '2021-05-20T03:56:23.494136Z'}
{'type': 'l2update', 'product_id': 'BTC-USD', 'changes': [['sell', '38405.79', '0.05000000']], 'time': '2021-05-20T03:56:23.494303Z'}
{'type': 'l2update', 'product_id': 'BTC-USD', 'changes': [['sell', '38418.48', '0.52602914']], 'time': '2021-05-20T03:56:23.494503Z'}
{'type': 'l2update', 'product_id': 'BTC-USD', 'changes': [['sell', '38413.05', '0.39490432']], 'time': '2021-05-20T03:56:23.494724Z'}
{'type': 'l2update', 'product_id': 'BTC-USD', 'changes': [['sell', '38402.65', '0.00000000']], 'time': '2021-05-20T03:56:23.500612Z'}
{'type': 'l2update', 'product_id': 'BTC-USD', 'changes': [['buy', '38334.42', '0.00000000']], 'time': '2021-05-20T03:56:23.504869Z'}
{'type': 'l2update', 'product_id': 'BTC-USD', 'changes': [['sell', '38418.48', '0.02602914']], 'time': '2021-05-20T03:56:23.505021Z'}
{'type': 'l2update', 'product_id': 'BTC-USD', 'changes': [['sell', '38395.58', '0.01511181']], 'time': '2021-05-20T03:56:23.511157Z'}
{'type': 'l2update', 'product_id': 'BTC-USD', 'changes': [['sell', '38395.30', '0.01492000']], 'time': '2021-05-20T03:56:23.511646Z'}
{'type': 'l2update', 'product_id': 'BTC-USD', 'changes': [['buy', '38385.74', '0.00000000']], 'time': '2021-05-20T03:56:23.511702Z'}
{'type': 'l2update', 'product_id': 'BTC-USD', 'changes': [['sell', '38418.47', '0.64666871']], 'time': '2021-05-20T03:56:23.511741Z'}
{'type': 'l2update', 'product_id': 'BTC-USD', 'changes': [['sell', '38412.15', '0.00000000']], 'time': '2021-05-20T03:56:23.512846Z'}
{'type': 'l2update', 'product_id': 'BTC-USD', 'changes': [['buy', '38352.99', '0.00000000']], 'time': '2021-05-20T03:56:23.517574Z'}
{'type': 'l2update', 'product_id': 'BTC-USD', 'changes': [['buy', '38373.09', '0.52119885']], 'time': '2021-05-20T03:56:23.518777Z'}
{'type': 'l2update', 'product_id': 'BTC-USD', 'changes': [['buy', '38364.44', '0.05721617']], 'time': '2021-05-20T03:56:23.519215Z'}
{'type': 'l2update', 'product_id': 'BTC-USD', 'changes': [['sell', '38423.28', '0.05721617']], 'time': '2021-05-20T03:56:23.519295Z'}
{'type': 'l2update', 'product_id': 'BTC-USD', 'changes': [['buy', '38360.89', '1.46756192']], 'time': '2021-05-20T03:56:23.519308Z'}
{'type': 'l2update', 'product_id': 'BTC-USD', 'changes': [['buy', '38313.13', '0.00000000']], 'time': '2021-05-20T03:56:23.519451Z'}
{'type': 'l2update', 'product_id': 'BTC-USD', 'changes': [['sell', '38396.63', '0.00000000']], 'time': '2021-05-20T03:56:23.520352Z'}
{'type': 'l2update', 'product_id': 'BTC-USD', 'changes': [['sell', '38405.79', '0.00000000']], 'time': '2021-05-20T03:56:23.525256Z'}
{'type': 'l2update', 'product_id': 'BTC-USD', 'changes': [['sell', '38385.75', '0.02890000']], 'time': '2021-05-20T03:56:23.528579Z'}
{'type': 'l2update', 'product_id': 'BTC-USD', 'changes': [['sell', '38519.55', '0.30186394']], 'time': '2021-05-20T03:56:23.530347Z'}
{'type': 'l2update', 'product_id': 'BTC-USD', 'changes': [['sell', '38491.02', '0.97014602']], 'time': '2021-05-20T03:56:23.530347Z'}
{'type': 'l2update', 'product_id': 'BTC-USD', 'changes': [['sell', '38462.97', '0.34796176']], 'time': '2021-05-20T03:56:23.530347Z'}
{'type': 'l2update', 'product_id': 'BTC-USD', 'changes': [['buy', '38372.46', '0.49400000']], 'time': '2021-05-20T03:56:23.530570Z'}
{'type': 'l2update', 'product_id': 'BTC-USD', 'changes': [['sell', '38429.49', '0.00000000']], 'time': '2021-05-20T03:56:23.531480Z'}
{'type': 'l2update', 'product_id': 'BTC-USD', 'changes': [['buy', '38330.45', '0.00000000']], 'time': '2021-05-20T03:56:23.531497Z'}
{'type': 'l2update', 'product_id': 'BTC-USD', 'changes': [['sell', '38432.81', '0.00000000']], 'time': '2021-05-20T03:56:23.531863Z'}
{'type': 'l2update', 'product_id': 'BTC-USD', 'changes': [['buy', '38352.18', '0.00000000']], 'time': '2021-05-20T03:56:23.533269Z'}
{'type': 'l2update', 'product_id': 'BTC-USD', 'changes': [['sell', '38520.75', '0.00000000']], 'time': '2021-05-20T03:56:23.533884Z'}
{'type': 'l2update', 'product_id': 'BTC-USD', 'changes': [['sell', '38395.58', '0.07460000']], 'time': '2021-05-20T03:56:23.535792Z'}
{'type': 'l2update', 'product_id': 'BTC-USD', 'changes': [['sell', '38395.58', '0.05948819']], 'time': '2021-05-20T03:56:23.536123Z'}
{'type': 'l2update', 'product_id': 'BTC-USD', 'changes': [['sell', '38395.95', '0.50000000']], 'time': '2021-05-20T03:56:23.536250Z'}
{'type': 'l2update', 'product_id': 'BTC-USD', 'changes': [['buy', '38339.41', '1.20000000']], 'time': '2021-05-20T03:56:23.536693Z'}
{'type': 'l2update', 'product_id': 'BTC-USD', 'changes': [['sell', '38644.89', '0.00000000']], 'time': '2021-05-20T03:56:23.538724Z'}
{'type': 'l2update', 'product_id': 'BTC-USD', 'changes': [['buy', '38359.04', '0.00000000']], 'time': '2021-05-20T03:56:23.540095Z'}
{'type': 'l2update', 'product_id': 'BTC-USD', 'changes': [['buy', '38239.85', '0.00000000']], 'time': '2021-05-20T03:56:23.550179Z'}
{'type': 'l2update', 'product_id': 'BTC-USD', 'changes': [['sell', '38395.30', '0.00000000']], 'time': '2021-05-20T03:56:23.550356Z'}
{'type': 'l2update', 'product_id': 'BTC-USD', 'changes': [['buy', '38359.03', '0.00000000']], 'time': '2021-05-20T03:56:23.552209Z'}
{'type': 'l2update', 'product_id': 'BTC-USD', 'changes': [['sell', '38534.76', '0.77125576']], 'time': '2021-05-20T03:56:23.552515Z'}
{'type': 'l2update', 'product_id': 'BTC-USD', 'changes': [['sell', '38491.02', '0.62218426']], 'time': '2021-05-20T03:56:23.552515Z'}
{'type': 'l2update', 'product_id': 'BTC-USD', 'changes': [['sell', '38412.14', '0.05000000']], 'time': '2021-05-20T03:56:23.553365Z'}
{'type': 'l2update', 'product_id': 'BTC-USD', 'changes': [['buy', '38369.19', '0.52114852']], 'time': '2021-05-20T03:56:23.553426Z'}
{'type': 'l2update', 'product_id': 'BTC-USD', 'changes': [['buy', '38346.10', '0.06720795']], 'time': '2021-05-20T03:56:23.553559Z'}
{'type': 'l2update', 'product_id': 'BTC-USD', 'changes': [['sell', '38396.68', '0.05000000']], 'time': '2021-05-20T03:56:23.553686Z'}
{'type': 'l2update', 'product_id': 'BTC-USD', 'changes': [['buy', '38377.19', '0.01492000']], 'time': '2021-05-20T03:56:23.554997Z'}
{'type': 'l2update', 'product_id': 'BTC-USD', 'changes': [['buy', '38370.50', '0.00000000']], 'time': '2021-05-20T03:56:23.555423Z'}
{'type': 'l2update', 'product_id': 'BTC-USD', 'changes': [['sell', '38395.58', '0.00000000']], 'time': '2021-05-20T03:56:23.555912Z'}
{'type': 'l2update', 'product_id': 'BTC-USD', 'changes': [['sell', '38518.83', '0.00000000']], 'time': '2021-05-20T03:56:23.556752Z'}
{'type': 'l2update', 'product_id': 'BTC-USD', 'changes': [['buy', '38340.44', '0.10000000']], 'time': '2021-05-20T03:56:23.559988Z'}
{'type': 'l2update', 'product_id': 'BTC-USD', 'changes': [['sell', '38420.77', '0.03207306']], 'time': '2021-05-20T03:56:23.560133Z'}
{'type': 'l2update', 'product_id': 'BTC-USD', 'changes': [['buy', '38364.44', '0.00000000']], 'time': '2021-05-20T03:56:23.560250Z'}
{'type': 'l2update', 'product_id': 'BTC-USD', 'changes': [['sell', '38498.97', '0.03317846']], 'time': '2021-05-20T03:56:23.560538Z'}
{'type': 'l2update', 'product_id': 'BTC-USD', 'changes': [['sell', '38473.88', '0.02970825']], 'time': '2021-05-20T03:56:23.560538Z'}
{'type': 'l2update', 'product_id': 'BTC-USD', 'changes': [['sell', '38545.05', '0.30068599']], 'time': '2021-05-20T03:56:23.560992Z'}
{'type': 'l2update', 'product_id': 'BTC-USD', 'changes': [['sell', '38505.84', '0.01278314']], 'time': '2021-05-20T03:56:23.566067Z'}
{'type': 'l2update', 'product_id': 'BTC-USD', 'changes': [['sell', '38474.61', '1.20000000']], 'time': '2021-05-20T03:56:23.566184Z'}
{'type': 'l2update', 'product_id': 'BTC-USD', 'changes': [['buy', '38360.89', '0.00000000']], 'time': '2021-05-20T03:56:23.570556Z'}
{'type': 'l2update', 'product_id': 'BTC-USD', 'changes': [['sell', '38412.14', '0.00000000']], 'time': '2021-05-20T03:56:23.570901Z'}
{'type': 'l2update', 'product_id': 'BTC-USD', 'changes': [['buy', '38343.45', '0.40760000']], 'time': '2021-05-20T03:56:23.572407Z'}
{'type': 'l2update', 'product_id': 'BTC-USD', 'changes': [['sell', '38385.75', '0.00332997']], 'time': '2021-05-20T03:56:23.572615Z'}
{'type': 'l2update', 'product_id': 'BTC-USD', 'changes': [['sell', '38397.28', '0.07000000']], 'time': '2021-05-20T03:56:23.574290Z'}
{'type': 'l2update', 'product_id': 'BTC-USD', 'changes': [['sell', '38484.44', '0.00000000']], 'time': '2021-05-20T03:56:23.574857Z'}
{'type': 'l2update', 'product_id': 'BTC-USD', 'changes': [['sell', '38597.46', '0.00000000']], 'time': '2021-05-20T03:56:23.575558Z'}
{'type': 'l2update', 'product_id': 'BTC-USD', 'changes': [['sell', '38401.07', '0.00000000']], 'time': '2021-05-20T03:56:23.578778Z'}
{'type': 'l2update', 'product_id': 'BTC-USD', 'changes': [['sell', '38489.92', '0.01000000']], 'time': '2021-05-20T03:56:23.581939Z'}
{'type': 'l2update', 'product_id': 'BTC-USD', 'changes': [['sell', '38623.29', '0.01294555']], 'time': '2021-05-20T03:56:23.582664Z'}
{'type': 'l2update', 'product_id': 'BTC-USD', 'changes': [['sell', '38493.06', '0.00000000']], 'time': '2021-05-20T03:56:23.583505Z'}
{'type': 'l2update', 'product_id': 'BTC-USD', 'changes': [['buy', '38376.06', '0.00000000']], 'time': '2021-05-20T03:56:23.583563Z'}
{'type': 'l2update', 'product_id': 'BTC-USD', 'changes': [['sell', '38503.41', '0.00000000']], 'time': '2021-05-20T03:56:23.584382Z'}
{'type': 'l2update', 'product_id': 'BTC-USD', 'changes': [['sell', '38385.75', '0.00000000']], 'time': '2021-05-20T03:56:23.586958Z'}
{'type': 'l2update', 'product_id': 'BTC-USD', 'changes': [['sell', '38395.95', '0.47776025']], 'time': '2021-05-20T03:56:23.586958Z'}
{'type': 'l2update', 'product_id': 'BTC-USD', 'changes': [['sell', '38548.91', '0.01297053']], 'time': '2021-05-20T03:56:23.587245Z'}
{'type': 'l2update', 'product_id': 'BTC-USD', 'changes': [['sell', '38388.96', '0.06093750']], 'time': '2021-05-20T03:56:23.587301Z'}
{'type': 'l2update', 'product_id': 'BTC-USD', 'changes': [['buy', '38350.10', '1.30299712']], 'time': '2021-05-20T03:56:23.587362Z'}
{'type': 'l2update', 'product_id': 'BTC-USD', 'changes': [['buy', '38339.41', '0.00000000']], 'time': '2021-05-20T03:56:23.588552Z'}
{'type': 'l2update', 'product_id': 'BTC-USD', 'changes': [['sell', '38397.28', '0.04000000']], 'time': '2021-05-20T03:56:23.595688Z'}
{'type': 'l2update', 'product_id': 'BTC-USD', 'changes': [['sell', '38405.79', '0.05000000']], 'time': '2021-05-20T03:56:23.599840Z'}
{'type': 'l2update', 'product_id': 'BTC-USD', 'changes': [['sell', '38419.77', '0.30397211']], 'time': '2021-05-20T03:56:23.600397Z'}
{'type': 'l2update', 'product_id': 'BTC-USD', 'changes': [['sell', '38423.28', '0.00000000']], 'time': '2021-05-20T03:56:23.602715Z'}
{'type': 'l2update', 'product_id': 'BTC-USD', 'changes': [['sell', '38395.31', '0.07460000']], 'time': '2021-05-20T03:56:23.603911Z'}
{'type': 'l2update', 'product_id': 'BTC-USD', 'changes': [['sell', '38395.49', '0.01492000']], 'time': '2021-05-20T03:56:23.604285Z'}
{'type': 'l2update', 'product_id': 'BTC-USD', 'changes': [['buy', '38345.83', '0.02390000']], 'time': '2021-05-20T03:56:23.613258Z'}
{'type': 'l2update', 'product_id': 'BTC-USD', 'changes': [['buy', '38345.03', '0.02390000']], 'time': '2021-05-20T03:56:23.613258Z'}
{'type': 'l2update', 'product_id': 'BTC-USD', 'changes': [['buy', '38344.22', '0.02390000']], 'time': '2021-05-20T03:56:23.613258Z'}
{'type': 'l2update', 'product_id': 'BTC-USD', 'changes': [['sell', '38395.95', '0.00000000']], 'time': '2021-05-20T03:56:23.614809Z'}
{'type': 'l2update', 'product_id': 'BTC-USD', 'changes': [['sell', '38474.61', '0.00000000']], 'time': '2021-05-20T03:56:23.618496Z'}
{'type': 'l2update', 'product_id': 'BTC-USD', 'changes': [['buy', '38351.33', '0.84600000']], 'time': '2021-05-20T03:56:23.618513Z'}
{'type': 'l2update', 'product_id': 'BTC-USD', 'changes': [['sell', '38545.05', '0.00000000']], 'time': '2021-05-20T03:56:23.619298Z'}
{'type': 'l2update', 'product_id': 'BTC-USD', 'changes': [['buy', '38326.82', '0.00000000']], 'time': '2021-05-20T03:56:23.619960Z'}
{'type': 'l2update', 'product_id': 'BTC-USD', 'changes': [['sell', '38478.50', '0.01000000']], 'time': '2021-05-20T03:56:23.623549Z'}
{'type': 'l2update', 'product_id': 'BTC-USD', 'changes': [['sell', '38419.96', '0.20600000']], 'time': '2021-05-20T03:56:23.624375Z'}
{'type': 'l2update', 'product_id': 'BTC-USD', 'changes': [['sell', '38397.28', '0.00000000']], 'time': '2021-05-20T03:56:23.624774Z'}
{'type': 'l2update', 'product_id': 'BTC-USD', 'changes': [['buy', '38373.10', '0.59116555']], 'time': '2021-05-20T03:56:23.629137Z'}
{'type': 'l2update', 'product_id': 'BTC-USD', 'changes': [['sell', '38421.86', '0.01397568']], 'time': '2021-05-20T03:56:23.629521Z'}
{'type': 'l2update', 'product_id': 'BTC-USD', 'changes': [['sell', '38407.11', '0.48240000']], 'time': '2021-05-20T03:56:23.629729Z'}
{'type': 'l2update', 'product_id': 'BTC-USD', 'changes': [['buy', '38351.29', '1.46756192']], 'time': '2021-05-20T03:56:23.629796Z'}
{'type': 'l2update', 'product_id': 'BTC-USD', 'changes': [['buy', '38346.10', '2.67294653']], 'time': '2021-05-20T03:56:23.630384Z'}
{'type': 'l2update', 'product_id': 'BTC-USD', 'changes': [['sell', '38457.43', '0.00000000']], 'time': '2021-05-20T03:56:23.633692Z'}
{'type': 'l2update', 'product_id': 'BTC-USD', 'changes': [['buy', '38245.42', '0.00000000']], 'time': '2021-05-20T03:56:23.633969Z'}
{'type': 'l2update', 'product_id': 'BTC-USD', 'changes': [['sell', '38395.31', '0.00000000']], 'time': '2021-05-20T03:56:23.634018Z'}
{'type': 'l2update', 'product_id': 'BTC-USD', 'changes': [['sell', '38395.49', '0.00000000']], 'time': '2021-05-20T03:56:23.635168Z'}
{'type': 'l2update', 'product_id': 'BTC-USD', 'changes': [['buy', '38360.88', '0.00000000']], 'time': '2021-05-20T03:56:23.636991Z'}
{'type': 'l2update', 'product_id': 'BTC-USD', 'changes': [['buy', '38377.52', '0.00831212']], 'time': '2021-05-20T03:56:23.640897Z'}
{'type': 'l2update', 'product_id': 'BTC-USD', 'changes': [['sell', '38419.77', '0.42732515']], 'time': '2021-05-20T03:56:23.641202Z'}
{'type': 'l2update', 'product_id': 'BTC-USD', 'changes': [['sell', '38429.49', '0.05902944']], 'time': '2021-05-20T03:56:23.642032Z'}
{'type': 'l2update', 'product_id': 'BTC-USD', 'changes': [['sell', '38494.75', '0.00000000']], 'time': '2021-05-20T03:56:23.642594Z'}
{'type': 'l2update', 'product_id': 'BTC-USD', 'changes': [['sell', '38510.24', '0.00000000']], 'time': '2021-05-20T03:56:23.642920Z'}
{'type': 'l2update', 'product_id': 'BTC-USD', 'changes': [['sell', '38426.02', '0.05902944']], 'time': '2021-05-20T03:56:23.646071Z'}
{'type': 'l2update', 'product_id': 'BTC-USD', 'changes': [['buy', '38364.80', '0.05902944']], 'time': '2021-05-20T03:56:23.650566Z'}
{'type': 'l2update', 'product_id': 'BTC-USD', 'changes': [['sell', '38396.68', '0.00000000']], 'time': '2021-05-20T03:56:23.653988Z'}
{'type': 'l2update', 'product_id': 'BTC-USD', 'changes': [['sell', '38623.29', '0.00000000']], 'time': '2021-05-20T03:56:23.654082Z'}
{'type': 'l2update', 'product_id': 'BTC-USD', 'changes': [['sell', '38395.95', '0.50000000']], 'time': '2021-05-20T03:56:23.656284Z'}
{'type': 'l2update', 'product_id': 'BTC-USD', 'changes': [['sell', '38516.56', '0.00000000']], 'time': '2021-05-20T03:56:23.661414Z'}
{'type': 'l2update', 'product_id': 'BTC-USD', 'changes': [['sell', '38507.39', '0.03064190']], 'time': '2021-05-20T03:56:23.661414Z'}
{'type': 'l2update', 'product_id': 'BTC-USD', 'changes': [['sell', '38507.39', '0.00000000']], 'time': '2021-05-20T03:56:23.661414Z'}
{'type': 'l2update', 'product_id': 'BTC-USD', 'changes': [['sell', '38479.40', '0.43621273']], 'time': '2021-05-20T03:56:23.661414Z'}
{'type': 'l2update', 'product_id': 'BTC-USD', 'changes': [['sell', '38440.56', '0.00000000']], 'time': '2021-05-20T03:56:23.661414Z'}
{'type': 'l2update', 'product_id': 'BTC-USD', 'changes': [['sell', '38434.36', '0.00000000']], 'time': '2021-05-20T03:56:23.661414Z'}
{'type': 'l2update', 'product_id': 'BTC-USD', 'changes': [['buy', '38351.33', '0.00000000']], 'time': '2021-05-20T03:56:23.662366Z'}
{'type': 'l2update', 'product_id': 'BTC-USD', 'changes': [['buy', '38343.45', '0.00000000']], 'time': '2021-05-20T03:56:23.663135Z'}
{'type': 'l2update', 'product_id': 'BTC-USD', 'changes': [['sell', '38387.17', '0.15000000']], 'time': '2021-05-20T03:56:23.666912Z'}
{'type': 'l2update', 'product_id': 'BTC-USD', 'changes': [['sell', '38397.23', '0.00600000']], 'time': '2021-05-20T03:56:23.667040Z'}
{'type': 'l2update', 'product_id': 'BTC-USD', 'changes': [['sell', '38558.65', '0.00000000']], 'time': '2021-05-20T03:56:23.667060Z'}
{'type': 'l2update', 'product_id': 'BTC-USD', 'changes': [['buy', '38045.00', '0.00000000']], 'time': '2021-05-20T03:56:23.670291Z'}
{'type': 'l2update', 'product_id': 'BTC-USD', 'changes': [['sell', '38479.40', '0.00000000']], 'time': '2021-05-20T03:56:23.673137Z'}
{'type': 'l2update', 'product_id': 'BTC-USD', 'changes': [['sell', '38464.95', '0.00000000']], 'time': '2021-05-20T03:56:23.673137Z'}
{'type': 'l2update', 'product_id': 'BTC-USD', 'changes': [['sell', '38448.96', '0.00000000']], 'time': '2021-05-20T03:56:23.673137Z'}
{'type': 'l2update', 'product_id': 'BTC-USD', 'changes': [['sell', '38443.31', '0.41751524']], 'time': '2021-05-20T03:56:23.673137Z'}
{'type': 'l2update', 'product_id': 'BTC-USD', 'changes': [['sell', '38443.31', '0.00000000']], 'time': '2021-05-20T03:56:23.673137Z'}
{'type': 'l2update', 'product_id': 'BTC-USD', 'changes': [['sell', '38436.89', '0.30838260']], 'time': '2021-05-20T03:56:23.673137Z'}
{'type': 'l2update', 'product_id': 'BTC-USD', 'changes': [['sell', '38436.89', '0.00000000']], 'time': '2021-05-20T03:56:23.673137Z'}
{'type': 'l2update', 'product_id': 'BTC-USD', 'changes': [['buy', '38337.06', '2.60581977']], 'time': '2021-05-20T03:56:23.675138Z'}
{'type': 'l2update', 'product_id': 'BTC-USD', 'changes': [['buy', '38377.19', '0.00000000']], 'time': '2021-05-20T03:56:23.678069Z'}
{'type': 'l2update', 'product_id': 'BTC-USD', 'changes': [['sell', '38388.55', '0.07460000']], 'time': '2021-05-20T03:56:23.679973Z'}
{'type': 'l2update', 'product_id': 'BTC-USD', 'changes': [['sell', '38489.92', '0.00000000']], 'time': '2021-05-20T03:56:23.680494Z'}
{'type': 'l2update', 'product_id': 'BTC-USD', 'changes': [['buy', '38378.65', '0.07104600']], 'time': '2021-05-20T03:56:23.681318Z'}
{'type': 'l2update', 'product_id': 'BTC-USD', 'changes': [['sell', '38388.47', '0.01492000']], 'time': '2021-05-20T03:56:23.686115Z'}
{'type': 'l2update', 'product_id': 'BTC-USD', 'changes': [['buy', '38346.09', '0.00000000']], 'time': '2021-05-20T03:56:23.690410Z'}
{'type': 'l2update', 'product_id': 'BTC-USD', 'changes': [['sell', '38407.11', '0.00000000']], 'time': '2021-05-20T03:56:23.691192Z'}
{'type': 'l2update', 'product_id': 'BTC-USD', 'changes': [['sell', '38385.75', '0.01000000']], 'time': '2021-05-20T03:56:23.691404Z'}
{'type': 'l2update', 'product_id': 'BTC-USD', 'changes': [['sell', '38379.86', '0.00513527']], 'time': '2021-05-20T03:56:23.691614Z'}
{'type': 'l2update', 'product_id': 'BTC-USD', 'changes': [['sell', '38602.40', '0.01295256']], 'time': '2021-05-20T03:56:23.698213Z'}
{'type': 'l2update', 'product_id': 'BTC-USD', 'changes': [['buy', '38313.58', '0.00000000']], 'time': '2021-05-20T03:56:23.701031Z'}
{'type': 'l2update', 'product_id': 'BTC-USD', 'changes': [['sell', '38388.55', '0.00000000']], 'time': '2021-05-20T03:56:23.709089Z'}
{'type': 'l2update', 'product_id': 'BTC-USD', 'changes': [['buy', '38032.11', '0.03981949']], 'time': '2021-05-20T03:56:23.711192Z'}
{'type': 'l2update', 'product_id': 'BTC-USD', 'changes': [['buy', '38220.69', '0.01000000']], 'time': '2021-05-20T03:56:23.711704Z'}
{'type': 'l2update', 'product_id': 'BTC-USD', 'changes': [['buy', '38377.91', '0.01492000']], 'time': '2021-05-20T03:56:23.718731Z'}
{'type': 'l2update', 'product_id': 'BTC-USD', 'changes': [['buy', '38377.52', '0.00000000']], 'time': '2021-05-20T03:56:23.720507Z'}
{'type': 'l2update', 'product_id': 'BTC-USD', 'changes': [['sell', '38388.47', '0.00000000']], 'time': '2021-05-20T03:56:23.720939Z'}
{'type': 'l2update', 'product_id': 'BTC-USD', 'changes': [['sell', '38481.27', '0.01299333']], 'time': '2021-05-20T03:56:23.723362Z'}
{'type': 'l2update', 'product_id': 'BTC-USD', 'changes': [['sell', '38395.95', '0.00000000']], 'time': '2021-05-20T03:56:23.728459Z'}
{'type': 'l2update', 'product_id': 'BTC-USD', 'changes': [['sell', '38385.75', '0.03000000']], 'time': '2021-05-20T03:56:23.730515Z'}
{'type': 'l2update', 'product_id': 'BTC-USD', 'changes': [['sell', '38553.96', '0.01000000']], 'time': '2021-05-20T03:56:23.730729Z'}
{'type': 'l2update', 'product_id': 'BTC-USD', 'changes': [['buy', '38359.04', '0.05902944']], 'time': '2021-05-20T03:56:23.730752Z'}
{'type': 'l2update', 'product_id': 'BTC-USD', 'changes': [['sell', '38398.99', '0.00000000']], 'time': '2021-05-20T03:56:23.734669Z'}
{'type': 'l2update', 'product_id': 'BTC-USD', 'changes': [['sell', '38517.31', '0.02022999']], 'time': '2021-05-20T03:56:23.735741Z'}
{'type': 'l2update', 'product_id': 'BTC-USD', 'changes': [['buy', '38255.68', '0.06135730']], 'time': '2021-05-20T03:56:23.736208Z'}
{'type': 'l2update', 'product_id': 'BTC-USD', 'changes': [['buy', '38237.94', '0.00000000']], 'time': '2021-05-20T03:56:23.740219Z'}
{'type': 'l2update', 'product_id': 'BTC-USD', 'changes': [['sell', '38415.97', '0.14024231']], 'time': '2021-05-20T03:56:23.746675Z'}
{'type': 'l2update', 'product_id': 'BTC-USD', 'changes': [['sell', '38518.31', '0.01784768']], 'time': '2021-05-20T03:56:23.748379Z'}
{'type': 'l2update', 'product_id': 'BTC-USD', 'changes': [['sell', '38429.49', '0.00000000']], 'time': '2021-05-20T03:56:23.751229Z'}
{'type': 'l2update', 'product_id': 'BTC-USD', 'changes': [['sell', '38515.13', '0.00000000']], 'time': '2021-05-20T03:56:23.752355Z'}
{'type': 'l2update', 'product_id': 'BTC-USD', 'changes': [['buy', '38280.05', '0.00000000']], 'time': '2021-05-20T03:56:23.752378Z'}
{'type': 'l2update', 'product_id': 'BTC-USD', 'changes': [['buy', '38377.91', '0.00000000']], 'time': '2021-05-20T03:56:23.753291Z'}
{'type': 'l2update', 'product_id': 'BTC-USD', 'changes': [['buy', '38364.80', '0.00000000']], 'time': '2021-05-20T03:56:23.759648Z'}
{'type': 'l2update', 'product_id': 'BTC-USD', 'changes': [['sell', '38426.02', '0.00000000']], 'time': '2021-05-20T03:56:23.764596Z'}
{'type': 'l2update', 'product_id': 'BTC-USD', 'changes': [['buy', '38281.63', '1.75850000']], 'time': '2021-05-20T03:56:23.766430Z'}
{'type': 'l2update', 'product_id': 'BTC-USD', 'changes': [['sell', '38469.92', '0.01564266']], 'time': '2021-05-20T03:56:23.766692Z'}
{'type': 'l2update', 'product_id': 'BTC-USD', 'changes': [['buy', '38379.85', '0.01115232']], 'time': '2021-05-20T03:56:23.770832Z'}
{'type': 'l2update', 'product_id': 'BTC-USD', 'changes': [['sell', '38388.96', '0.09093750']], 'time': '2021-05-20T03:56:23.771348Z'}
{'type': 'l2update', 'product_id': 'BTC-USD', 'changes': [['buy', '38342.29', '0.00000000']], 'time': '2021-05-20T03:56:23.773627Z'}
{'type': 'l2update', 'product_id': 'BTC-USD', 'changes': [['sell', '38387.16', '0.50000000']], 'time': '2021-05-20T03:56:23.778355Z'}
{'type': 'l2update', 'product_id': 'BTC-USD', 'changes': [['sell', '38553.96', '0.00000000']], 'time': '2021-05-20T03:56:23.779251Z'}
{'type': 'l2update', 'product_id': 'BTC-USD', 'changes': [['sell', '38534.76', '0.41670907']], 'time': '2021-05-20T03:56:23.782177Z'}
{'type': 'l2update', 'product_id': 'BTC-USD', 'changes': [['sell', '38432.32', '0.14024231']], 'time': '2021-05-20T03:56:23.782177Z'}
{'type': 'l2update', 'product_id': 'BTC-USD', 'changes': [['sell', '38432.32', '0.00000000']], 'time': '2021-05-20T03:56:23.782177Z'}
{'type': 'l2update', 'product_id': 'BTC-USD', 'changes': [['buy', '38334.81', '0.42380000']], 'time': '2021-05-20T03:56:23.783538Z'}
{'type': 'l2update', 'product_id': 'BTC-USD', 'changes': [['buy', '38346.15', '0.84700000']], 'time': '2021-05-20T03:56:23.783700Z'}
{'type': 'l2update', 'product_id': 'BTC-USD', 'changes': [['sell', '38379.86', '0.10513527']], 'time': '2021-05-20T03:56:23.788357Z'}
{'type': 'l2update', 'product_id': 'BTC-USD', 'changes': [['buy', '38370.76', '0.04897881']], 'time': '2021-05-20T03:56:23.792880Z'}
{'type': 'l2update', 'product_id': 'BTC-USD', 'changes': [['sell', '38382.28', '0.05183321']], 'time': '2021-05-20T03:56:23.792913Z'}
{'type': 'l2update', 'product_id': 'BTC-USD', 'changes': [['buy', '38221.88', '0.01000000']], 'time': '2021-05-20T03:56:23.793363Z'}
{'type': 'l2update', 'product_id': 'BTC-USD', 'changes': [['sell', '38388.95', '2.48969908']], 'time': '2021-05-20T03:56:23.797967Z'}
{'type': 'l2update', 'product_id': 'BTC-USD', 'changes': [['sell', '38379.86', '0.10573000']], 'time': '2021-05-20T03:56:23.798489Z'}
{'type': 'l2update', 'product_id': 'BTC-USD', 'changes': [['sell', '38495.97', '0.01298837']], 'time': '2021-05-20T03:56:23.798821Z'}
{'type': 'l2update', 'product_id': 'BTC-USD', 'changes': [['buy', '38335.50', '0.00000000']], 'time': '2021-05-20T03:56:23.804390Z'}
{'type': 'l2update', 'product_id': 'BTC-USD', 'changes': [['buy', '38376.85', '0.00000000']], 'time': '2021-05-20T03:56:23.811445Z'}
{'type': 'l2update', 'product_id': 'BTC-USD', 'changes': [['buy', '38334.81', '0.00000000']], 'time': '2021-05-20T03:56:23.813860Z'}
{'type': 'l2update', 'product_id': 'BTC-USD', 'changes': [['sell', '38405.80', '0.00000000']], 'time': '2021-05-20T03:56:23.814261Z'}
{'type': 'l2update', 'product_id': 'BTC-USD', 'changes': [['sell', '38388.96', '0.13093750']], 'time': '2021-05-20T03:56:23.815999Z'}
{'type': 'l2update', 'product_id': 'BTC-USD', 'changes': [['buy', '38233.40', '0.36733949']], 'time': '2021-05-20T03:56:23.822168Z'}
{'type': 'l2update', 'product_id': 'BTC-USD', 'changes': [['sell', '38534.01', '0.01000000']], 'time': '2021-05-20T03:56:23.822590Z'}
{'type': 'l2update', 'product_id': 'BTC-USD', 'changes': [['sell', '38379.86', '0.30573000']], 'time': '2021-05-20T03:56:23.826659Z'}
{'type': 'l2update', 'product_id': 'BTC-USD', 'changes': [['sell', '38478.50', '0.00000000']], 'time': '2021-05-20T03:56:23.831452Z'}
{'type': 'l2update', 'product_id': 'BTC-USD', 'changes': [['sell', '38495.97', '0.00000000']], 'time': '2021-05-20T03:56:23.838041Z'}
{'type': 'l2update', 'product_id': 'BTC-USD', 'changes': [['sell', '38418.47', '0.70569815']], 'time': '2021-05-20T03:56:23.838290Z'}
{'type': 'l2update', 'product_id': 'BTC-USD', 'changes': [['buy', '38285.15', '0.02400000']], 'time': '2021-05-20T03:56:23.838378Z'}
{'type': 'l2update', 'product_id': 'BTC-USD', 'changes': [['buy', '38373.10', '0.00000000']], 'time': '2021-05-20T03:56:23.844000Z'}
{'type': 'l2update', 'product_id': 'BTC-USD', 'changes': [['buy', '38373.09', '0.00000000']], 'time': '2021-05-20T03:56:23.845193Z'}
{'type': 'l2update', 'product_id': 'BTC-USD', 'changes': [['sell', '38396.57', '0.00000000']], 'time': '2021-05-20T03:56:23.845373Z'}
{'type': 'l2update', 'product_id': 'BTC-USD', 'changes': [['buy', '38337.12', '0.05902944']], 'time': '2021-05-20T03:56:23.848814Z'}
{'type': 'l2update', 'product_id': 'BTC-USD', 'changes': [['sell', '38405.79', '0.00000000']], 'time': '2021-05-20T03:56:23.850159Z'}
{'type': 'l2update', 'product_id': 'BTC-USD', 'changes': [['sell', '38468.30', '0.02891559']], 'time': '2021-05-20T03:56:23.853870Z'}
{'type': 'l2update', 'product_id': 'BTC-USD', 'changes': [['sell', '38440.56', '0.03317846']], 'time': '2021-05-20T03:56:23.853870Z'}
{'type': 'l2update', 'product_id': 'BTC-USD', 'changes': [['sell', '38427.94', '0.02970825']], 'time': '2021-05-20T03:56:23.853870Z'}
{'type': 'l2update', 'product_id': 'BTC-USD', 'changes': [['sell', '38423.76', '0.01138707']], 'time': '2021-05-20T03:56:23.853870Z'}
{'type': 'l2update', 'product_id': 'BTC-USD', 'changes': [['buy', '38310.41', '0.00000000']], 'time': '2021-05-20T03:56:23.857276Z'}
{'type': 'l2update', 'product_id': 'BTC-USD', 'changes': [['sell', '38379.86', '0.40573000']], 'time': '2021-05-20T03:56:23.864947Z'}
{'type': 'l2update', 'product_id': 'BTC-USD', 'changes': [['buy', '38378.65', '0.00000000']], 'time': '2021-05-20T03:56:23.865052Z'}
{'type': 'l2update', 'product_id': 'BTC-USD', 'changes': [['buy', '38341.28', '0.04519590']], 'time': '2021-05-20T03:56:23.865323Z'}
{'type': 'l2update', 'product_id': 'BTC-USD', 'changes': [['sell', '38385.75', '0.08657181']], 'time': '2021-05-20T03:56:23.865323Z'}
{'type': 'l2update', 'product_id': 'BTC-USD', 'changes': [['sell', '38516.40', '0.00000000']], 'time': '2021-05-20T03:56:23.865692Z'}
{'type': 'l2update', 'product_id': 'BTC-USD', 'changes': [['buy', '38359.04', '0.00000000']], 'time': '2021-05-20T03:56:23.868564Z'}
{'type': 'l2update', 'product_id': 'BTC-USD', 'changes': [['buy', '38379.85', '0.00260709']], 'time': '2021-05-20T03:56:23.868689Z'}
{'type': 'l2update', 'product_id': 'BTC-USD', 'changes': [['buy', '38379.85', '0.00000000']], 'time': '2021-05-20T03:56:23.868689Z'}
{'type': 'l2update', 'product_id': 'BTC-USD', 'changes': [['buy', '38372.46', '0.00000000']], 'time': '2021-05-20T03:56:23.868689Z'}
{'type': 'l2update', 'product_id': 'BTC-USD', 'changes': [['buy', '38370.76', '0.00000000']], 'time': '2021-05-20T03:56:23.868689Z'}
{'type': 'l2update', 'product_id': 'BTC-USD', 'changes': [['buy', '38369.19', '0.00000000']], 'time': '2021-05-20T03:56:23.874538Z'}
{'type': 'l2update', 'product_id': 'BTC-USD', 'changes': [['sell', '38465.44', '0.01000000']], 'time': '2021-05-20T03:56:23.879925Z'}
{'type': 'l2update', 'product_id': 'BTC-USD', 'changes': [['sell', '38479.51', '0.01299393']], 'time': '2021-05-20T03:56:23.884119Z'}
{'type': 'l2update', 'product_id': 'BTC-USD', 'changes': [['sell', '38420.31', '2.16932808']], 'time': '2021-05-20T03:56:23.884835Z'}
{'type': 'l2update', 'product_id': 'BTC-USD', 'changes': [['buy', '38032.11', '0.00000000']], 'time': '2021-05-20T03:56:23.884921Z'}
{'type': 'l2update', 'product_id': 'BTC-USD', 'changes': [['sell', '38498.97', '0.00000000']], 'time': '2021-05-20T03:56:23.885007Z'}
{'type': 'l2update', 'product_id': 'BTC-USD', 'changes': [['sell', '38473.88', '0.00000000']], 'time': '2021-05-20T03:56:23.885007Z'}
{'type': 'l2update', 'product_id': 'BTC-USD', 'changes': [['sell', '38441.65', '0.00000000']], 'time': '2021-05-20T03:56:23.885007Z'}
{'type': 'l2update', 'product_id': 'BTC-USD', 'changes': [['buy', '38330.57', '0.00000000']], 'time': '2021-05-20T03:56:23.885007Z'}
{'type': 'l2update', 'product_id': 'BTC-USD', 'changes': [['sell', '38462.97', '0.00000000']], 'time': '2021-05-20T03:56:23.886642Z'}
{'type': 'l2update', 'product_id': 'BTC-USD', 'changes': [['sell', '38419.77', '0.12335304']], 'time': '2021-05-20T03:56:23.886642Z'}
{'type': 'l2update', 'product_id': 'BTC-USD', 'changes': [['buy', '38297.00', '0.02873335']], 'time': '2021-05-20T03:56:23.886642Z'}
{'type': 'l2update', 'product_id': 'BTC-USD', 'changes': [['sell', '38406.03', '0.40010000']], 'time': '2021-05-20T03:56:23.889996Z'}
{'type': 'l2update', 'product_id': 'BTC-USD', 'changes': [['sell', '38413.04', '0.05000000']], 'time': '2021-05-20T03:56:23.890292Z'}
{'type': 'l2update', 'product_id': 'BTC-USD', 'changes': [['buy', '38351.30', '0.59116555']], 'time': '2021-05-20T03:56:23.896683Z'}
{'type': 'l2update', 'product_id': 'BTC-USD', 'changes': [['sell', '38379.85', '0.00573000']], 'time': '2021-05-20T03:56:23.896957Z'}
{'type': 'l2update', 'product_id': 'BTC-USD', 'changes': [['buy', '38193.94', '0.16000000']], 'time': '2021-05-20T03:56:23.897325Z'}
{'type': 'l2update', 'product_id': 'BTC-USD', 'changes': [['buy', '38346.10', '0.06720795']], 'time': '2021-05-20T03:56:23.903974Z'}
{'type': 'l2update', 'product_id': 'BTC-USD', 'changes': [['sell', '38379.43', '0.01492000']], 'time': '2021-05-20T03:56:23.908877Z'}
{'type': 'l2update', 'product_id': 'BTC-USD', 'changes': [['sell', '38379.58', '0.07460000']], 'time': '2021-05-20T03:56:23.909336Z'}
{'type': 'l2update', 'product_id': 'BTC-USD', 'changes': [['sell', '38396.62', '0.00000000']], 'time': '2021-05-20T03:56:23.911697Z'}
{'type': 'l2update', 'product_id': 'BTC-USD', 'changes': [['buy', '38346.15', '0.00000000']], 'time': '2021-05-20T03:56:23.913324Z'}
{'type': 'l2update', 'product_id': 'BTC-USD', 'changes': [['sell', '38418.46', '0.05902944']], 'time': '2021-05-20T03:56:23.914071Z'}
{'type': 'l2update', 'product_id': 'BTC-USD', 'changes': [['buy', '38320.14', '0.00000000']], 'time': '2021-05-20T03:56:23.916511Z'}
{'type': 'l2update', 'product_id': 'BTC-USD', 'changes': [['buy', '38325.45', '0.00000000']], 'time': '2021-05-20T03:56:23.916511Z'}
{'type': 'l2update', 'product_id': 'BTC-USD', 'changes': [['sell', '38467.89', '0.00000000']], 'time': '2021-05-20T03:56:23.916541Z'}
{'type': 'l2update', 'product_id': 'BTC-USD', 'changes': [['sell', '38419.77', '0.00000000']], 'time': '2021-05-20T03:56:23.917705Z'}
{'type': 'l2update', 'product_id': 'BTC-USD', 'changes': [['buy', '38288.03', '0.32871109']], 'time': '2021-05-20T03:56:23.917705Z'}
{'type': 'l2update', 'product_id': 'BTC-USD', 'changes': [['buy', '38288.03', '0.00000000']], 'time': '2021-05-20T03:56:23.917705Z'}
{'type': 'l2update', 'product_id': 'BTC-USD', 'changes': [['buy', '38373.32', '0.07105428']], 'time': '2021-05-20T03:56:23.919545Z'}
{'type': 'l2update', 'product_id': 'BTC-USD', 'changes': [['buy', '38366.73', '0.04923752']], 'time': '2021-05-20T03:56:23.919832Z'}
{'type': 'l2update', 'product_id': 'BTC-USD', 'changes': [['buy', '38365.02', '0.07460000']], 'time': '2021-05-20T03:56:23.919845Z'}
{'type': 'l2update', 'product_id': 'BTC-USD', 'changes': [['sell', '38406.03', '0.00000000']], 'time': '2021-05-20T03:56:23.919934Z'}
{'type': 'l2update', 'product_id': 'BTC-USD', 'changes': [['buy', '38375.93', '0.15000000']], 'time': '2021-05-20T03:56:23.920001Z'}
{'type': 'l2update', 'product_id': 'BTC-USD', 'changes': [['sell', '38413.04', '0.00000000']], 'time': '2021-05-20T03:56:23.921814Z'}
{'type': 'l2update', 'product_id': 'BTC-USD', 'changes': [['buy', '38198.19', '0.00000000']], 'time': '2021-05-20T03:56:23.922201Z'}
{'type': 'l2update', 'product_id': 'BTC-USD', 'changes': [['sell', '38418.47', '0.05902944']], 'time': '2021-05-20T03:56:23.923787Z'}
{'type': 'l2update', 'product_id': 'BTC-USD', 'changes': [['buy', '38192.80', '0.05040525']], 'time': '2021-05-20T03:56:23.924853Z'}
{'type': 'l2update', 'product_id': 'BTC-USD', 'changes': [['sell', '38403.91', '0.01000000']], 'time': '2021-05-20T03:56:23.924955Z'}
{'type': 'l2update', 'product_id': 'BTC-USD', 'changes': [['sell', '38517.72', '0.00000000']], 'time': '2021-05-20T03:56:23.926299Z'}
{'type': 'l2update', 'product_id': 'BTC-USD', 'changes': [['sell', '38379.86', '0.40059473']], 'time': '2021-05-20T03:56:23.927776Z'}
{'type': 'l2update', 'product_id': 'BTC-USD', 'changes': [['sell', '38397.23', '0.00000000']], 'time': '2021-05-20T03:56:23.932322Z'}
{'type': 'l2update', 'product_id': 'BTC-USD', 'changes': [['buy', '38337.06', '0.00000000']], 'time': '2021-05-20T03:56:23.934357Z'}
{'type': 'l2update', 'product_id': 'BTC-USD', 'changes': [['sell', '38418.47', '0.00000000']], 'time': '2021-05-20T03:56:23.936853Z'}
{'type': 'l2update', 'product_id': 'BTC-USD', 'changes': [['sell', '38379.58', '0.00000000']], 'time': '2021-05-20T03:56:23.937567Z'}
{'type': 'l2update', 'product_id': 'BTC-USD', 'changes': [['sell', '38387.16', '0.00000000']], 'time': '2021-05-20T03:56:23.938867Z'}
{'type': 'l2update', 'product_id': 'BTC-USD', 'changes': [['sell', '38413.05', '0.00000000']], 'time': '2021-05-20T03:56:23.940669Z'}
{'type': 'l2update', 'product_id': 'BTC-USD', 'changes': [['buy', '38339.42', '0.05902944']], 'time': '2021-05-20T03:56:23.942219Z'}
{'type': 'l2update', 'product_id': 'BTC-USD', 'changes': [['sell', '38502.71', '0.01000000']], 'time': '2021-05-20T03:56:23.943344Z'}
{'type': 'l2update', 'product_id': 'BTC-USD', 'changes': [['sell', '38396.64', '0.00000000']], 'time': '2021-05-20T03:56:23.943598Z'}
{'type': 'l2update', 'product_id': 'BTC-USD', 'changes': [['buy', '38290.20', '0.00000000']], 'time': '2021-05-20T03:56:23.944283Z'}
{'type': 'l2update', 'product_id': 'BTC-USD', 'changes': [['buy', '38305.05', '0.00000000']], 'time': '2021-05-20T03:56:23.946369Z'}
{'type': 'l2update', 'product_id': 'BTC-USD', 'changes': [['buy', '38310.42', '0.00000000']], 'time': '2021-05-20T03:56:23.946369Z'}
{'type': 'l2update', 'product_id': 'BTC-USD', 'changes': [['sell', '38535.99', '0.00000000']], 'time': '2021-05-20T03:56:23.947418Z'}
{'type': 'l2update', 'product_id': 'BTC-USD', 'changes': [['sell', '38534.76', '0.00000000']], 'time': '2021-05-20T03:56:23.947418Z'}
{'type': 'l2update', 'product_id': 'BTC-USD', 'changes': [['sell', '38519.55', '0.00000000']], 'time': '2021-05-20T03:56:23.947418Z'}
{'type': 'l2update', 'product_id': 'BTC-USD', 'changes': [['sell', '38491.02', '0.31190829']], 'time': '2021-05-20T03:56:23.947418Z'}
{'type': 'l2update', 'product_id': 'BTC-USD', 'changes': [['sell', '38491.02', '0.00000000']], 'time': '2021-05-20T03:56:23.947418Z'}
{'type': 'l2update', 'product_id': 'BTC-USD', 'changes': [['buy', '38371.21', '0.01492000']], 'time': '2021-05-20T03:56:23.948810Z'}
{'type': 'l2update', 'product_id': 'BTC-USD', 'changes': [['buy', '38358.10', '0.00300000']], 'time': '2021-05-20T03:56:23.949293Z'}
{'type': 'l2update', 'product_id': 'BTC-USD', 'changes': [['sell', '38379.43', '0.06492000']], 'time': '2021-05-20T03:56:23.949833Z'}
{'type': 'l2update', 'product_id': 'BTC-USD', 'changes': [['buy', '38365.02', '0.00000000']], 'time': '2021-05-20T03:56:23.950034Z'}
{'type': 'l2update', 'product_id': 'BTC-USD', 'changes': [['sell', '38379.43', '0.05000000']], 'time': '2021-05-20T03:56:23.950535Z'}
{'type': 'l2update', 'product_id': 'BTC-USD', 'changes': [['sell', '38379.86', '0.20059473']], 'time': '2021-05-20T03:56:23.953940Z'}
{'type': 'l2update', 'product_id': 'BTC-USD', 'changes': [['buy', '38012.79', '0.13153464']], 'time': '2021-05-20T03:56:23.955126Z'}
{'type': 'l2update', 'product_id': 'BTC-USD', 'changes': [['sell', '38379.86', '0.20000000']], 'time': '2021-05-20T03:56:23.957153Z'}
{'type': 'l2update', 'product_id': 'BTC-USD', 'changes': [['sell', '38395.95', '0.05000000']], 'time': '2021-05-20T03:56:23.959419Z'}
{'type': 'l2update', 'product_id': 'BTC-USD', 'changes': [['buy', '38331.91', '0.42450000']], 'time': '2021-05-20T03:56:23.959653Z'}
{'type': 'l2update', 'product_id': 'BTC-USD', 'changes': [['buy', '38364.79', '0.00000000']], 'time': '2021-05-20T03:56:23.964825Z'}
{'type': 'l2update', 'product_id': 'BTC-USD', 'changes': [['sell', '38399.99', '0.66762817']], 'time': '2021-05-20T03:56:23.967072Z'}
{'type': 'l2update', 'product_id': 'BTC-USD', 'changes': [['sell', '38488.55', '0.01000000']], 'time': '2021-05-20T03:56:23.967748Z'}
{'type': 'l2update', 'product_id': 'BTC-USD', 'changes': [['buy', '38321.43', '0.01000000']], 'time': '2021-05-20T03:56:23.967944Z'}
{'type': 'l2update', 'product_id': 'BTC-USD', 'changes': [['sell', '38395.96', '0.00000000']], 'time': '2021-05-20T03:56:23.975402Z'}
{'type': 'l2update', 'product_id': 'BTC-USD', 'changes': [['buy', '38299.77', '0.00000000']], 'time': '2021-05-20T03:56:23.975905Z'}
{'type': 'l2update', 'product_id': 'BTC-USD', 'changes': [['sell', '38421.86', '0.00000000']], 'time': '2021-05-20T03:56:23.976226Z'}
{'type': 'l2update', 'product_id': 'BTC-USD', 'changes': [['buy', '38297.00', '0.00000000']], 'time': '2021-05-20T03:56:23.976226Z'}
{'type': 'l2update', 'product_id': 'BTC-USD', 'changes': [['buy', '38371.21', '0.00000000']], 'time': '2021-05-20T03:56:23.978454Z'}
{'type': 'l2update', 'product_id': 'BTC-USD', 'changes': [['sell', '38379.84', '0.50000000']], 'time': '2021-05-20T03:56:23.980690Z'}
{'type': 'l2update', 'product_id': 'BTC-USD', 'changes': [['sell', '38385.75', '0.07657181']], 'time': '2021-05-20T03:56:23.980779Z'}
{'type': 'l2update', 'product_id': 'BTC-USD', 'changes': [['sell', '38379.86', '0.10000000']], 'time': '2021-05-20T03:56:23.981026Z'}
{'type': 'l2update', 'product_id': 'BTC-USD', 'changes': [['sell', '38379.85', '0.00000000']], 'time': '2021-05-20T03:56:23.986497Z'}
{'type': 'l2update', 'product_id': 'BTC-USD', 'changes': [['sell', '38395.95', '0.00000000']], 'time': '2021-05-20T03:56:23.987583Z'}
{'type': 'l2update', 'product_id': 'BTC-USD', 'changes': [['buy', '38331.91', '0.00000000']], 'time': '2021-05-20T03:56:23.987804Z'}
{'type': 'l2update', 'product_id': 'BTC-USD', 'changes': [['buy', '38350.10', '0.00000000']], 'time': '2021-05-20T03:56:23.992887Z'}
{'type': 'l2update', 'product_id': 'BTC-USD', 'changes': [['sell', '38454.88', '0.01299760']], 'time': '2021-05-20T03:56:23.994060Z'}
{'type': 'l2update', 'product_id': 'BTC-USD', 'changes': [['sell', '38457.07', '0.29644697']], 'time': '2021-05-20T03:56:23.994980Z'}
{'type': 'l2update', 'product_id': 'BTC-USD', 'changes': [['sell', '38465.44', '0.00000000']], 'time': '2021-05-20T03:56:23.996228Z'}
{'type': 'l2update', 'product_id': 'BTC-USD', 'changes': [['sell', '38548.91', '0.00000000']], 'time': '2021-05-20T03:56:23.996258Z'}
{'type': 'l2update', 'product_id': 'BTC-USD', 'changes': [['buy', '38339.42', '0.00000000']], 'time': '2021-05-20T03:56:23.996939Z'}
{'type': 'l2update', 'product_id': 'BTC-USD', 'changes': [['buy', '38337.12', '0.00000000']], 'time': '2021-05-20T03:56:24.002910Z'}
{'type': 'l2update', 'product_id': 'BTC-USD', 'changes': [['sell', '38385.75', '0.05657181']], 'time': '2021-05-20T03:56:24.007577Z'}
{'type': 'l2update', 'product_id': 'BTC-USD', 'changes': [['sell', '38379.86', '0.00000000']], 'time': '2021-05-20T03:56:24.007933Z'}
{'type': 'l2update', 'product_id': 'BTC-USD', 'changes': [['sell', '38379.42', '1.10969492']], 'time': '2021-05-20T03:56:24.010418Z'}
{'type': 'l2update', 'product_id': 'BTC-USD', 'changes': [['buy', '38250.00', '0.52100000']], 'time': '2021-05-20T03:56:24.011189Z'}
{'type': 'l2update', 'product_id': 'BTC-USD', 'changes': [['sell', '38379.84', '0.00000000']], 'time': '2021-05-20T03:56:24.011407Z'}
{'type': 'l2update', 'product_id': 'BTC-USD', 'changes': [['sell', '38509.79', '0.00000000']], 'time': '2021-05-20T03:56:24.012524Z'}
{'type': 'l2update', 'product_id': 'BTC-USD', 'changes': [['sell', '38469.92', '0.00000000']], 'time': '2021-05-20T03:56:24.014150Z'}
{'type': 'l2update', 'product_id': 'BTC-USD', 'changes': [['sell', '38388.94', '0.05000000']], 'time': '2021-05-20T03:56:24.019834Z'}
{'type': 'l2update', 'product_id': 'BTC-USD', 'changes': [['sell', '38375.94', '0.00573000']], 'time': '2021-05-20T03:56:24.020110Z'}
{'type': 'l2update', 'product_id': 'BTC-USD', 'changes': [['buy', '38346.15', '0.52000000']], 'time': '2021-05-20T03:56:24.024311Z'}
{'type': 'l2update', 'product_id': 'BTC-USD', 'changes': [['sell', '38451.74', '0.03392128']], 'time': '2021-05-20T03:56:24.024478Z'}
{'type': 'l2update', 'product_id': 'BTC-USD', 'changes': [['sell', '38452.07', '0.03699412']], 'time': '2021-05-20T03:56:24.026287Z'}
{'type': 'l2update', 'product_id': 'BTC-USD', 'changes': [['sell', '38403.91', '0.00000000']], 'time': '2021-05-20T03:56:24.027942Z'}
{'type': 'l2update', 'product_id': 'BTC-USD', 'changes': [['sell', '38465.68', '0.00000000']], 'time': '2021-05-20T03:56:24.028714Z'}
{'type': 'l2update', 'product_id': 'BTC-USD', 'changes': [['sell', '38446.47', '0.00000000']], 'time': '2021-05-20T03:56:24.028714Z'}
{'type': 'l2update', 'product_id': 'BTC-USD', 'changes': [['sell', '38602.40', '0.00000000']], 'time': '2021-05-20T03:56:24.030365Z'}
{'type': 'l2update', 'product_id': 'BTC-USD', 'changes': [['sell', '38462.59', '0.41795500']], 'time': '2021-05-20T03:56:24.030601Z'}
{'type': 'l2update', 'product_id': 'BTC-USD', 'changes': [['sell', '38533.87', '0.01297559']], 'time': '2021-05-20T03:56:24.030872Z'}
{'type': 'l2update', 'product_id': 'BTC-USD', 'changes': [['buy', '38220.69', '0.00000000']], 'time': '2021-05-20T03:56:24.031063Z'}
{'type': 'l2update', 'product_id': 'BTC-USD', 'changes': [['sell', '38388.96', '0.10093750']], 'time': '2021-05-20T03:56:24.032373Z'}
{'type': 'l2update', 'product_id': 'BTC-USD', 'changes': [['buy', '38293.73', '0.07800000']], 'time': '2021-05-20T03:56:24.036820Z'}
{'type': 'l2update', 'product_id': 'BTC-USD', 'changes': [['sell', '38379.43', '0.15000000']], 'time': '2021-05-20T03:56:24.040226Z'}
{'type': 'l2update', 'product_id': 'BTC-USD', 'changes': [['sell', '38404.86', '0.44990000']], 'time': '2021-05-20T03:56:24.040338Z'}
{'type': 'l2update', 'product_id': 'BTC-USD', 'changes': [['sell', '38388.94', '0.00000000']], 'time': '2021-05-20T03:56:24.043222Z'}
{'type': 'l2update', 'product_id': 'BTC-USD', 'changes': [['buy', '38321.43', '0.00000000']], 'time': '2021-05-20T03:56:24.048581Z'}
{'type': 'l2update', 'product_id': 'BTC-USD', 'changes': [['sell', '38385.74', '0.50000000']], 'time': '2021-05-20T03:56:24.049947Z'}
{'type': 'l2update', 'product_id': 'BTC-USD', 'changes': [['sell', '38375.94', '0.03463000']], 'time': '2021-05-20T03:56:24.054995Z'}
{'type': 'l2update', 'product_id': 'BTC-USD', 'changes': [['sell', '38462.59', '0.45547544']], 'time': '2021-05-20T03:56:24.055345Z'}
{'type': 'l2update', 'product_id': 'BTC-USD', 'changes': [['sell', '38388.96', '0.06093750']], 'time': '2021-05-20T03:56:24.055698Z'}
{'type': 'l2update', 'product_id': 'BTC-USD', 'changes': [['sell', '38385.75', '0.00000000']], 'time': '2021-05-20T03:56:24.056407Z'}
{'type': 'l2update', 'product_id': 'BTC-USD', 'changes': [['sell', '38580.81', '0.01295981']], 'time': '2021-05-20T03:56:24.060839Z'}
{'type': 'l2update', 'product_id': 'BTC-USD', 'changes': [['sell', '38474.20', '0.34681464']], 'time': '2021-05-20T03:56:24.062197Z'}
{'type': 'l2update', 'product_id': 'BTC-USD', 'changes': [['buy', '38228.41', '0.01000000']], 'time': '2021-05-20T03:56:24.067488Z'}
{'type': 'l2update', 'product_id': 'BTC-USD', 'changes': [['sell', '38487.51', '0.01000000']], 'time': '2021-05-20T03:56:24.067808Z'}
{'type': 'l2update', 'product_id': 'BTC-USD', 'changes': [['sell', '38379.42', '0.00000000']], 'time': '2021-05-20T03:56:24.072089Z'}
{'type': 'l2update', 'product_id': 'BTC-USD', 'changes': [['sell', '38379.43', '0.35000000']], 'time': '2021-05-20T03:56:24.072861Z'}
{'type': 'l2update', 'product_id': 'BTC-USD', 'changes': [['sell', '38396.63', '0.05000000']], 'time': '2021-05-20T03:56:24.073369Z'}
{'type': 'l2update', 'product_id': 'BTC-USD', 'changes': [['sell', '38523.35', '0.01244995']], 'time': '2021-05-20T03:56:24.073616Z'}
{'type': 'l2update', 'product_id': 'BTC-USD', 'changes': [['sell', '38379.43', '0.36000000']], 'time': '2021-05-20T03:56:24.083726Z'}
{'type': 'l2update', 'product_id': 'BTC-USD', 'changes': [['sell', '38453.22', '0.03865622']], 'time': '2021-05-20T03:56:24.084277Z'}
{'type': 'l2update', 'product_id': 'BTC-USD', 'changes': [['buy', '38260.30', '0.03865622']], 'time': '2021-05-20T03:56:24.084277Z'}
{'type': 'l2update', 'product_id': 'BTC-USD', 'changes': [['sell', '38454.88', '0.00000000']], 'time': '2021-05-20T03:56:24.086800Z'}
{'type': 'l2update', 'product_id': 'BTC-USD', 'changes': [['buy', '38373.32', '0.00000000']], 'time': '2021-05-20T03:56:24.087830Z'}
{'type': 'l2update', 'product_id': 'BTC-USD', 'changes': [['buy', '38293.73', '0.00000000']], 'time': '2021-05-20T03:56:24.092808Z'}
{'type': 'l2update', 'product_id': 'BTC-USD', 'changes': [['sell', '38474.20', '0.66693484']], 'time': '2021-05-20T03:56:24.094378Z'}
{'type': 'l2update', 'product_id': 'BTC-USD', 'changes': [['sell', '38442.11', '0.20400000']], 'time': '2021-05-20T03:56:24.095627Z'}
{'type': 'l2update', 'product_id': 'BTC-USD', 'changes': [['sell', '38422.92', '0.06600000']], 'time': '2021-05-20T03:56:24.095627Z'}
{'type': 'l2update', 'product_id': 'BTC-USD', 'changes': [['sell', '38379.43', '0.26000000']], 'time': '2021-05-20T03:56:24.096192Z'}
{'type': 'l2update', 'product_id': 'BTC-USD', 'changes': [['sell', '38396.63', '0.00000000']], 'time': '2021-05-20T03:56:24.096379Z'}
{'type': 'l2update', 'product_id': 'BTC-USD', 'changes': [['buy', '38285.15', '0.00000000']], 'time': '2021-05-20T03:56:24.100052Z'}
{'type': 'l2update', 'product_id': 'BTC-USD', 'changes': [['buy', '38345.24', '0.41930000']], 'time': '2021-05-20T03:56:24.103626Z'}
{'type': 'l2update', 'product_id': 'BTC-USD', 'changes': [['buy', '38200.32', '0.05074629']], 'time': '2021-05-20T03:56:24.104636Z'}
{'type': 'l2update', 'product_id': 'BTC-USD', 'changes': [['sell', '38398.50', '0.04901772']], 'time': '2021-05-20T03:56:24.108784Z'}
{'type': 'l2update', 'product_id': 'BTC-USD', 'changes': [['buy', '38345.83', '0.00000000']], 'time': '2021-05-20T03:56:24.108901Z'}
{'type': 'l2update', 'product_id': 'BTC-USD', 'changes': [['buy', '38345.03', '0.00000000']], 'time': '2021-05-20T03:56:24.108901Z'}
{'type': 'l2update', 'product_id': 'BTC-USD', 'changes': [['buy', '38344.22', '0.00000000']], 'time': '2021-05-20T03:56:24.108901Z'}
{'type': 'l2update', 'product_id': 'BTC-USD', 'changes': [['buy', '38351.34', '0.05902944']], 'time': '2021-05-20T03:56:24.112017Z'}
{'type': 'l2update', 'product_id': 'BTC-USD', 'changes': [['sell', '38379.43', '0.28000000']], 'time': '2021-05-20T03:56:24.112044Z'}
{'type': 'l2update', 'product_id': 'BTC-USD', 'changes': [['sell', '38441.87', '0.01155000']], 'time': '2021-05-20T03:56:24.116484Z'}
{'type': 'l2update', 'product_id': 'BTC-USD', 'changes': [['sell', '38420.31', '0.00000000']], 'time': '2021-05-20T03:56:24.122784Z'}
{'type': 'l2update', 'product_id': 'BTC-USD', 'changes': [['buy', '38341.28', '0.00000000']], 'time': '2021-05-20T03:56:24.124111Z'}
{'type': 'l2update', 'product_id': 'BTC-USD', 'changes': [['sell', '38462.59', '0.48617257']], 'time': '2021-05-20T03:56:24.126400Z'}
{'type': 'l2update', 'product_id': 'BTC-USD', 'changes': [['sell', '38423.76', '0.04456553']], 'time': '2021-05-20T03:56:24.126400Z'}
{'type': 'l2update', 'product_id': 'BTC-USD', 'changes': [['buy', '38272.95', '0.03069713']], 'time': '2021-05-20T03:56:24.126400Z'}
{'type': 'l2update', 'product_id': 'BTC-USD', 'changes': [['buy', '38310.42', '0.03378072']], 'time': '2021-05-20T03:56:24.126400Z'}
{'type': 'l2update', 'product_id': 'BTC-USD', 'changes': [['sell', '38518.31', '0.00000000']], 'time': '2021-05-20T03:56:24.127171Z'}
{'type': 'l2update', 'product_id': 'BTC-USD', 'changes': [['sell', '38404.86', '0.00000000']], 'time': '2021-05-20T03:56:24.128460Z'}
{'type': 'l2update', 'product_id': 'BTC-USD', 'changes': [['sell', '38399.99', '0.71762817']], 'time': '2021-05-20T03:56:24.129100Z'}
{'type': 'l2update', 'product_id': 'BTC-USD', 'changes': [['buy', '38370.02', '0.07105428']], 'time': '2021-05-20T03:56:24.129720Z'}
{'type': 'l2update', 'product_id': 'BTC-USD', 'changes': [['sell', '38375.94', '0.23463000']], 'time': '2021-05-20T03:56:24.130135Z'}
{'type': 'l2update', 'product_id': 'BTC-USD', 'changes': [['buy', '38193.94', '0.00000000']], 'time': '2021-05-20T03:56:24.130177Z'}
{'type': 'l2update', 'product_id': 'BTC-USD', 'changes': [['sell', '38462.59', '0.89089715']], 'time': '2021-05-20T03:56:24.133465Z'}
{'type': 'l2update', 'product_id': 'BTC-USD', 'changes': [['buy', '38239.28', '0.40472458']], 'time': '2021-05-20T03:56:24.133465Z'}
{'type': 'l2update', 'product_id': 'BTC-USD', 'changes': [['buy', '38346.10', '0.00000000']], 'time': '2021-05-20T03:56:24.146686Z'}
{'type': 'l2update', 'product_id': 'BTC-USD', 'changes': [['sell', '38440.56', '0.00000000']], 'time': '2021-05-20T03:56:24.148598Z'}
{'type': 'l2update', 'product_id': 'BTC-USD', 'changes': [['buy', '38284.30', '0.00000000']], 'time': '2021-05-20T03:56:24.148598Z'}
{'type': 'l2update', 'product_id': 'BTC-USD', 'changes': [['sell', '38375.94', '0.26463000']], 'time': '2021-05-20T03:56:24.150391Z'}
{'type': 'l2update', 'product_id': 'BTC-USD', 'changes': [['sell', '38382.23', '1.08700000']], 'time': '2021-05-20T03:56:24.150490Z'}
{'type': 'l2update', 'product_id': 'BTC-USD', 'changes': [['buy', '38350.49', '0.02390000']], 'time': '2021-05-20T03:56:24.150520Z'}
{'type': 'l2update', 'product_id': 'BTC-USD', 'changes': [['buy', '38349.68', '0.02390000']], 'time': '2021-05-20T03:56:24.150520Z'}
{'type': 'l2update', 'product_id': 'BTC-USD', 'changes': [['buy', '38348.87', '0.02390000']], 'time': '2021-05-20T03:56:24.150520Z'}
{'type': 'l2update', 'product_id': 'BTC-USD', 'changes': [['sell', '38379.43', '0.08000000']], 'time': '2021-05-20T03:56:24.152929Z'}
{'type': 'l2update', 'product_id': 'BTC-USD', 'changes': [['sell', '38543.21', '0.01000000']], 'time': '2021-05-20T03:56:24.155814Z'}
{'type': 'l2update', 'product_id': 'BTC-USD', 'changes': [['buy', '38248.82', '0.00000000']], 'time': '2021-05-20T03:56:24.156059Z'}
{'type': 'l2update', 'product_id': 'BTC-USD', 'changes': [['sell', '38400.92', '0.39490432']], 'time': '2021-05-20T03:56:24.157162Z'}
{'type': 'l2update', 'product_id': 'BTC-USD', 'changes': [['sell', '38388.95', '0.00000000']], 'time': '2021-05-20T03:56:24.158796Z'}
{'type': 'l2update', 'product_id': 'BTC-USD', 'changes': [['buy', '38351.30', '0.00000000']], 'time': '2021-05-20T03:56:24.162336Z'}
{'type': 'l2update', 'product_id': 'BTC-USD', 'changes': [['buy', '38277.08', '0.00000000']], 'time': '2021-05-20T03:56:24.167188Z'}
{'type': 'l2update', 'product_id': 'BTC-USD', 'changes': [['buy', '38349.68', '0.00000000']], 'time': '2021-05-20T03:56:24.171725Z'}
{'type': 'l2update', 'product_id': 'BTC-USD', 'changes': [['buy', '38348.87', '0.00000000']], 'time': '2021-05-20T03:56:24.171725Z'}
{'type': 'l2update', 'product_id': 'BTC-USD', 'changes': [['buy', '38346.11', '0.05902944']], 'time': '2021-05-20T03:56:24.175134Z'}
{'type': 'l2update', 'product_id': 'BTC-USD', 'changes': [['sell', '38375.94', '0.30463000']], 'time': '2021-05-20T03:56:24.179888Z'}
{'type': 'l2update', 'product_id': 'BTC-USD', 'changes': [['sell', '38375.94', '0.40463000']], 'time': '2021-05-20T03:56:24.179928Z'}
{'type': 'l2update', 'product_id': 'BTC-USD', 'changes': [['sell', '38432.97', '0.42284881']], 'time': '2021-05-20T03:56:24.189687Z'}
{'type': 'l2update', 'product_id': 'BTC-USD', 'changes': [['buy', '38248.82', '0.42284881']], 'time': '2021-05-20T03:56:24.189687Z'}
{'type': 'l2update', 'product_id': 'BTC-USD', 'changes': [['sell', '38530.04', '0.01783846']], 'time': '2021-05-20T03:56:24.189744Z'}
{'type': 'l2update', 'product_id': 'BTC-USD', 'changes': [['buy', '38352.26', '0.00050000']], 'time': '2021-05-20T03:56:24.190523Z'}
{'type': 'l2update', 'product_id': 'BTC-USD', 'changes': [['sell', '38523.35', '0.00000000']], 'time': '2021-05-20T03:56:24.191289Z'}
{'type': 'l2update', 'product_id': 'BTC-USD', 'changes': [['buy', '38255.68', '0.03155230']], 'time': '2021-05-20T03:56:24.191513Z'}
{'type': 'l2update', 'product_id': 'BTC-USD', 'changes': [['sell', '38412.92', '0.01000000']], 'time': '2021-05-20T03:56:24.195380Z'}
{'type': 'l2update', 'product_id': 'BTC-USD', 'changes': [['buy', '38350.49', '0.00000000']], 'time': '2021-05-20T03:56:24.196432Z'}
{'type': 'l2update', 'product_id': 'BTC-USD', 'changes': [['sell', '38379.42', '2.48969908']], 'time': '2021-05-20T03:56:24.200818Z'}
{'type': 'l2update', 'product_id': 'BTC-USD', 'changes': [['buy', '38370.02', '0.00000000']], 'time': '2021-05-20T03:56:24.203722Z'}
{'type': 'l2update', 'product_id': 'BTC-USD', 'changes': [['sell', '38534.01', '0.00000000']], 'time': '2021-05-20T03:56:24.204604Z'}
{'type': 'l2update', 'product_id': 'BTC-USD', 'changes': [['buy', '38281.59', '0.01000000']], 'time': '2021-05-20T03:56:24.212123Z'}
{'type': 'l2update', 'product_id': 'BTC-USD', 'changes': [['sell', '43100.00', '1.09530000']], 'time': '2021-05-20T03:56:24.215504Z'}
{'type': 'l2update', 'product_id': 'BTC-USD', 'changes': [['sell', '38437.73', '0.41678670']], 'time': '2021-05-20T03:56:24.221974Z'}
{'type': 'l2update', 'product_id': 'BTC-USD', 'changes': [['sell', '38415.85', '0.11857879']], 'time': '2021-05-20T03:56:24.221974Z'}
{'type': 'l2update', 'product_id': 'BTC-USD', 'changes': [['buy', '38330.42', '0.01000000']], 'time': '2021-05-20T03:56:24.229924Z'}
{'type': 'l2update', 'product_id': 'BTC-USD', 'changes': [['sell', '38476.37', '0.03811543']], 'time': '2021-05-20T03:56:24.231265Z'}
{'type': 'l2update', 'product_id': 'BTC-USD', 'changes': [['buy', '38279.20', '0.03811543']], 'time': '2021-05-20T03:56:24.231265Z'}
{'type': 'l2update', 'product_id': 'BTC-USD', 'changes': [['buy', '38346.11', '0.00000000']], 'time': '2021-05-20T03:56:24.234357Z'}
{'type': 'l2update', 'product_id': 'BTC-USD', 'changes': [['sell', '38510.06', '0.01000000']], 'time': '2021-05-20T03:56:24.234856Z'}
{'type': 'l2update', 'product_id': 'BTC-USD', 'changes': [['sell', '38419.35', '0.48470000']], 'time': '2021-05-20T03:56:24.236037Z'}
{'type': 'l2update', 'product_id': 'BTC-USD', 'changes': [['sell', '43100.00', '1.52260000']], 'time': '2021-05-20T03:56:24.244196Z'}
{'type': 'l2update', 'product_id': 'BTC-USD', 'changes': [['sell', '38457.07', '0.00000000']], 'time': '2021-05-20T03:56:24.246877Z'}
{'type': 'l2update', 'product_id': 'BTC-USD', 'changes': [['buy', '38362.37', '0.07113237']], 'time': '2021-05-20T03:56:24.247911Z'}
{'type': 'l2update', 'product_id': 'BTC-USD', 'changes': [['buy', '38351.34', '0.00000000']], 'time': '2021-05-20T03:56:24.250216Z'}
{'type': 'l2update', 'product_id': 'BTC-USD', 'changes': [['sell', '38493.36', '0.01203948']], 'time': '2021-05-20T03:56:24.258972Z'}
{'type': 'l2update', 'product_id': 'BTC-USD', 'changes': [['buy', '38351.24', '0.02390000']], 'time': '2021-05-20T03:56:24.259184Z'}
{'type': 'l2update', 'product_id': 'BTC-USD', 'changes': [['buy', '38350.43', '0.02390000']], 'time': '2021-05-20T03:56:24.259184Z'}
{'type': 'l2update', 'product_id': 'BTC-USD', 'changes': [['buy', '38349.62', '0.02390000']], 'time': '2021-05-20T03:56:24.259184Z'}
{'type': 'l2update', 'product_id': 'BTC-USD', 'changes': [['sell', '38415.96', '0.05902944']], 'time': '2021-05-20T03:56:24.259442Z'}
{'type': 'l2update', 'product_id': 'BTC-USD', 'changes': [['sell', '38467.99', '0.00000000']], 'time': '2021-05-20T03:56:24.265046Z'}
{'type': 'l2update', 'product_id': 'BTC-USD', 'changes': [['sell', '38489.14', '0.02681954']], 'time': '2021-05-20T03:56:24.265662Z'}
{'type': 'l2update', 'product_id': 'BTC-USD', 'changes': [['buy', '38272.95', '0.05751667']], 'time': '2021-05-20T03:56:24.265662Z'}
{'type': 'l2update', 'product_id': 'BTC-USD', 'changes': [['sell', '38462.59', '0.47294215']], 'time': '2021-05-20T03:56:24.269251Z'}
{'type': 'l2update', 'product_id': 'BTC-USD', 'changes': [['buy', '38317.75', '0.00000000']], 'time': '2021-05-20T03:56:24.269634Z'}
{'type': 'l2update', 'product_id': 'BTC-USD', 'changes': [['buy', '38221.88', '0.00000000']], 'time': '2021-05-20T03:56:24.270920Z'}
{'type': 'l2update', 'product_id': 'BTC-USD', 'changes': [['buy', '38345.24', '0.00000000']], 'time': '2021-05-20T03:56:24.272537Z'}
{'type': 'l2update', 'product_id': 'BTC-USD', 'changes': [['buy', '38344.64', '0.05022044']], 'time': '2021-05-20T03:56:24.277365Z'}
{'type': 'l2update', 'product_id': 'BTC-USD', 'changes': [['sell', '38388.88', '0.04893097']], 'time': '2021-05-20T03:56:24.277365Z'}
{'type': 'l2update', 'product_id': 'BTC-USD', 'changes': [['buy', '38351.35', '0.59116555']], 'time': '2021-05-20T03:56:24.277834Z'}
{'type': 'l2update', 'product_id': 'BTC-USD', 'changes': [['buy', '38357.43', '0.84500000']], 'time': '2021-05-20T03:56:24.281528Z'}
{'type': 'l2update', 'product_id': 'BTC-USD', 'changes': [['buy', '38351.24', '0.00000000']], 'time': '2021-05-20T03:56:24.284359Z'}
{'type': 'l2update', 'product_id': 'BTC-USD', 'changes': [['buy', '38350.43', '0.00000000']], 'time': '2021-05-20T03:56:24.284359Z'}
{'type': 'l2update', 'product_id': 'BTC-USD', 'changes': [['buy', '38349.62', '0.00000000']], 'time': '2021-05-20T03:56:24.284359Z'}
{'type': 'l2update', 'product_id': 'BTC-USD', 'changes': [['sell', '38474.20', '0.32012020']], 'time': '2021-05-20T03:56:24.296310Z'}
{'type': 'l2update', 'product_id': 'BTC-USD', 'changes': [['sell', '38533.87', '0.00000000']], 'time': '2021-05-20T03:56:24.296830Z'}
{'type': 'l2update', 'product_id': 'BTC-USD', 'changes': [['sell', '38418.46', '0.00000000']], 'time': '2021-05-20T03:56:24.301489Z'}
{'type': 'l2update', 'product_id': 'BTC-USD', 'changes': [['sell', '38510.06', '0.00000000']], 'time': '2021-05-20T03:56:24.302607Z'}
{'type': 'l2update', 'product_id': 'BTC-USD', 'changes': [['buy', '38192.80', '0.00000000']], 'time': '2021-05-20T03:56:24.305964Z'}
{'type': 'l2update', 'product_id': 'BTC-USD', 'changes': [['sell', '38495.81', '0.02958142']], 'time': '2021-05-20T03:56:24.308622Z'}
{'type': 'l2update', 'product_id': 'BTC-USD', 'changes': [['buy', '38263.03', '0.02958142']], 'time': '2021-05-20T03:56:24.308622Z'}
{'type': 'l2update', 'product_id': 'BTC-USD', 'changes': [['buy', '38195.12', '0.01000000']], 'time': '2021-05-20T03:56:24.309153Z'}
{'type': 'l2update', 'product_id': 'BTC-USD', 'changes': [['buy', '38338.95', '0.46820000']], 'time': '2021-05-20T03:56:24.309172Z'}
{'type': 'l2update', 'product_id': 'BTC-USD', 'changes': [['sell', '38451.73', '0.02600663']], 'time': '2021-05-20T03:56:24.309545Z'}
{'type': 'l2update', 'product_id': 'BTC-USD', 'changes': [['sell', '38400.92', '0.00000000']], 'time': '2021-05-20T03:56:24.314061Z'}
{'type': 'l2update', 'product_id': 'BTC-USD', 'changes': [['buy', '38282.56', '0.00000000']], 'time': '2021-05-20T03:56:24.314371Z'}
{'type': 'l2update', 'product_id': 'BTC-USD', 'changes': [['sell', '38457.07', '0.40765096']], 'time': '2021-05-20T03:56:24.323821Z'}
{'type': 'l2update', 'product_id': 'BTC-USD', 'changes': [['sell', '38518.83', '0.01298066']], 'time': '2021-05-20T03:56:24.323837Z'}
{'type': 'l2update', 'product_id': 'BTC-USD', 'changes': [['buy', '38338.95', '0.00000000']], 'time': '2021-05-20T03:56:24.323885Z'}
{'type': 'l2update', 'product_id': 'BTC-USD', 'changes': [['buy', '38272.95', '0.02681954']], 'time': '2021-05-20T03:56:24.324149Z'}
{'type': 'l2update', 'product_id': 'BTC-USD', 'changes': [['buy', '38310.42', '0.00000000']], 'time': '2021-05-20T03:56:24.324149Z'}
{'type': 'l2update', 'product_id': 'BTC-USD', 'changes': [['sell', '38385.74', '0.00000000']], 'time': '2021-05-20T03:56:24.324679Z'}
{'type': 'l2update', 'product_id': 'BTC-USD', 'changes': [['sell', '38494.42', '0.01000000']], 'time': '2021-05-20T03:56:24.335009Z'}
{'type': 'l2update', 'product_id': 'BTC-USD', 'changes': [['buy', '38329.01', '1.20000000']], 'time': '2021-05-20T03:56:24.339538Z'}
{'type': 'l2update', 'product_id': 'BTC-USD', 'changes': [['buy', '38260.30', '0.00000000']], 'time': '2021-05-20T03:56:24.340186Z'}
{'type': 'l2update', 'product_id': 'BTC-USD', 'changes': [['buy', '38284.28', '0.00000000']], 'time': '2021-05-20T03:56:24.340319Z'}
{'type': 'l2update', 'product_id': 'BTC-USD', 'changes': [['sell', '38438.63', '0.00000000']], 'time': '2021-05-20T03:56:24.341885Z'}
{'type': 'l2update', 'product_id': 'BTC-USD', 'changes': [['buy', '38351.29', '0.00000000']], 'time': '2021-05-20T03:56:24.342189Z'}
{'type': 'l2update', 'product_id': 'BTC-USD', 'changes': [['buy', '37279.26', '0.00530000']], 'time': '2021-05-20T03:56:24.342455Z'}
{'type': 'l2update', 'product_id': 'BTC-USD', 'changes': [['buy', '37281.28', '0.00000000']], 'time': '2021-05-20T03:56:24.342455Z'}
{'type': 'l2update', 'product_id': 'BTC-USD', 'changes': [['sell', '39779.99', '0.00000000']], 'time': '2021-05-20T03:56:24.342455Z'}
{'type': 'l2update', 'product_id': 'BTC-USD', 'changes': [['buy', '37283.80', '0.00000000']], 'time': '2021-05-20T03:56:24.342455Z'}
{'type': 'l2update', 'product_id': 'BTC-USD', 'changes': [['sell', '38415.96', '0.00000000']], 'time': '2021-05-20T03:56:24.351497Z'}
{'type': 'l2update', 'product_id': 'BTC-USD', 'changes': [['sell', '38388.87', '0.50000000']], 'time': '2021-05-20T03:56:24.358059Z'}
{'type': 'l2update', 'product_id': 'BTC-USD', 'changes': [['sell', '39431.86', '0.04080000']], 'time': '2021-05-20T03:56:24.358559Z'}
{'type': 'l2update', 'product_id': 'BTC-USD', 'changes': [['sell', '39430.75', '0.01930000']], 'time': '2021-05-20T03:56:24.358559Z'}
{'type': 'l2update', 'product_id': 'BTC-USD', 'changes': [['sell', '38464.38', '0.29756958']], 'time': '2021-05-20T03:56:24.358624Z'}
{'type': 'l2update', 'product_id': 'BTC-USD', 'changes': [['sell', '38447.82', '0.32012020']], 'time': '2021-05-20T03:56:24.358624Z'}
{'type': 'l2update', 'product_id': 'BTC-USD', 'changes': [['buy', '38342.03', '0.02390000']], 'time': '2021-05-20T03:56:24.359490Z'}
{'type': 'l2update', 'product_id': 'BTC-USD', 'changes': [['buy', '38341.22', '0.02390000']], 'time': '2021-05-20T03:56:24.359490Z'}
{'type': 'l2update', 'product_id': 'BTC-USD', 'changes': [['buy', '38340.42', '0.02390000']], 'time': '2021-05-20T03:56:24.359490Z'}
{'type': 'l2update', 'product_id': 'BTC-USD', 'changes': [['buy', '38351.35', '0.00000000']], 'time': '2021-05-20T03:56:24.361871Z'}
{'type': 'l2update', 'product_id': 'BTC-USD', 'changes': [['sell', '38464.18', '1.20000000']], 'time': '2021-05-20T03:56:24.364546Z'}
{'type': 'l2update', 'product_id': 'BTC-USD', 'changes': [['buy', '38346.16', '0.05902944']], 'time': '2021-05-20T03:56:24.371487Z'}
{'type': 'l2update', 'product_id': 'BTC-USD', 'changes': [['sell', '38399.99', '0.77665761']], 'time': '2021-05-20T03:56:24.372278Z'}
{'type': 'l2update', 'product_id': 'BTC-USD', 'changes': [['buy', '38265.77', '0.01000000']], 'time': '2021-05-20T03:56:24.372448Z'}
{'type': 'l2update', 'product_id': 'BTC-USD', 'changes': [['sell', '38474.20', '0.00000000']], 'time': '2021-05-20T03:56:24.374289Z'}
{'type': 'l2update', 'product_id': 'BTC-USD', 'changes': [['sell', '38419.35', '0.00000000']], 'time': '2021-05-20T03:56:24.375602Z'}
{'type': 'l2update', 'product_id': 'BTC-USD', 'changes': [['buy', '38270.30', '0.50000000']], 'time': '2021-05-20T03:56:24.380719Z'}
{'type': 'l2update', 'product_id': 'BTC-USD', 'changes': [['buy', '38358.11', '1.46756192']], 'time': '2021-05-20T03:56:24.382161Z'}
{'type': 'l2update', 'product_id': 'BTC-USD', 'changes': [['sell', '38487.51', '0.00000000']], 'time': '2021-05-20T03:56:24.385293Z'}
{'type': 'l2update', 'product_id': 'BTC-USD', 'changes': [['sell', '38495.81', '0.06793179']], 'time': '2021-05-20T03:56:24.387802Z'}
{'type': 'l2update', 'product_id': 'BTC-USD', 'changes': [['buy', '38281.78', '0.03835037']], 'time': '2021-05-20T03:56:24.387802Z'}
{'type': 'l2update', 'product_id': 'BTC-USD', 'changes': [['buy', '38287.66', '0.03155230']], 'time': '2021-05-20T03:56:24.387802Z'}
{'type': 'l2update', 'product_id': 'BTC-USD', 'changes': [['sell', '38580.81', '0.00000000']], 'time': '2021-05-20T03:56:24.390060Z'}
{'type': 'l2update', 'product_id': 'BTC-USD', 'changes': [['sell', '38462.59', '0.06821757']], 'time': '2021-05-20T03:56:24.390286Z'}
{'type': 'l2update', 'product_id': 'BTC-USD', 'changes': [['sell', '38432.96', '0.61482417']], 'time': '2021-05-20T03:56:24.397076Z'}
{'type': 'l2update', 'product_id': 'BTC-USD', 'changes': [['buy', '38255.68', '0.00000000']], 'time': '2021-05-20T03:56:24.404416Z'}
{'type': 'l2update', 'product_id': 'BTC-USD', 'changes': [['buy', '38312.10', '1.28020447']], 'time': '2021-05-20T03:56:24.406626Z'}
{'type': 'l2update', 'product_id': 'BTC-USD', 'changes': [['sell', '38417.95', '0.45080000']], 'time': '2021-05-20T03:56:24.406829Z'}
{'type': 'l2update', 'product_id': 'BTC-USD', 'changes': [['buy', '38241.10', '0.00000000']], 'time': '2021-05-20T03:56:24.406848Z'}
{'type': 'l2update', 'product_id': 'BTC-USD', 'changes': [['buy', '38248.48', '0.00000000']], 'time': '2021-05-20T03:56:24.406848Z'}
{'type': 'l2update', 'product_id': 'BTC-USD', 'changes': [['sell', '38382.23', '1.67900000']], 'time': '2021-05-20T03:56:24.406917Z'}
{'type': 'l2update', 'product_id': 'BTC-USD', 'changes': [['buy', '38358.12', '0.59116555']], 'time': '2021-05-20T03:56:24.413012Z'}
{'type': 'l2update', 'product_id': 'BTC-USD', 'changes': [['sell', '38399.99', '0.71762817']], 'time': '2021-05-20T03:56:24.416489Z'}
{'type': 'l2update', 'product_id': 'BTC-USD', 'changes': [['sell', '38502.71', '0.00000000']], 'time': '2021-05-20T03:56:24.418438Z'}
{'type': 'l2update', 'product_id': 'BTC-USD', 'changes': [['sell', '38493.36', '0.00000000']], 'time': '2021-05-20T03:56:24.418472Z'}
{'type': 'l2update', 'product_id': 'BTC-USD', 'changes': [['sell', '38417.95', '0.00000000']], 'time': '2021-05-20T03:56:24.424622Z'}
{'type': 'l2update', 'product_id': 'BTC-USD', 'changes': [['buy', '38248.82', '0.00000000']], 'time': '2021-05-20T03:56:24.425534Z'}
{'type': 'l2update', 'product_id': 'BTC-USD', 'changes': [['buy', '38344.64', '0.00000000']], 'time': '2021-05-20T03:56:24.426012Z'}
{'type': 'l2update', 'product_id': 'BTC-USD', 'changes': [['sell', '38388.88', '0.00000000']], 'time': '2021-05-20T03:56:24.426012Z'}
{'type': 'l2update', 'product_id': 'BTC-USD', 'changes': [['buy', '38357.39', '0.16000000']], 'time': '2021-05-20T03:56:24.428631Z'}
{'type': 'l2update', 'product_id': 'BTC-USD', 'changes': [['sell', '38559.22', '0.01296706']], 'time': '2021-05-20T03:56:24.428683Z'}
{'type': 'l2update', 'product_id': 'BTC-USD', 'changes': [['sell', '38502.67', '0.03054604']], 'time': '2021-05-20T03:56:24.429415Z'}
{'type': 'l2update', 'product_id': 'BTC-USD', 'changes': [['buy', '38269.47', '0.03054604']], 'time': '2021-05-20T03:56:24.429415Z'}
{'type': 'l2update', 'product_id': 'BTC-USD', 'changes': [['sell', '38481.27', '0.00000000']], 'time': '2021-05-20T03:56:24.429459Z'}
{'type': 'l2update', 'product_id': 'BTC-USD', 'changes': [['sell', '38437.73', '0.00000000']], 'time': '2021-05-20T03:56:24.436806Z'}
{'type': 'l2update', 'product_id': 'BTC-USD', 'changes': [['buy', '38279.20', '0.00000000']], 'time': '2021-05-20T03:56:24.439257Z'}
{'type': 'l2update', 'product_id': 'BTC-USD', 'changes': [['buy', '38340.45', '0.05902944']], 'time': '2021-05-20T03:56:24.439638Z'}
{'type': 'l2update', 'product_id': 'BTC-USD', 'changes': [['buy', '38340.44', '0.00000000']], 'time': '2021-05-20T03:56:24.439733Z'}
{'type': 'l2update', 'product_id': 'BTC-USD', 'changes': [['sell', '38388.87', '0.00000000']], 'time': '2021-05-20T03:56:24.444766Z'}
{'type': 'l2update', 'product_id': 'BTC-USD', 'changes': [['buy', '38346.16', '0.00000000']], 'time': '2021-05-20T03:56:24.446128Z'}
{'type': 'l2update', 'product_id': 'BTC-USD', 'changes': [['sell', '38502.49', '0.01000000']], 'time': '2021-05-20T03:56:24.447676Z'}
{'type': 'l2update', 'product_id': 'BTC-USD', 'changes': [['sell', '38461.63', '0.01299997']], 'time': '2021-05-20T03:56:24.448317Z'}
{'type': 'l2update', 'product_id': 'BTC-USD', 'changes': [['buy', '38345.99', '0.48270000']], 'time': '2021-05-20T03:56:24.448445Z'}
{'type': 'l2update', 'product_id': 'BTC-USD', 'changes': [['buy', '38345.99', '0.00000000']], 'time': '2021-05-20T03:56:24.455906Z'}
{'type': 'l2update', 'product_id': 'BTC-USD', 'changes': [['sell', '38453.15', '0.34580473']], 'time': '2021-05-20T03:56:24.459768Z'}
{'type': 'l2update', 'product_id': 'BTC-USD', 'changes': [['buy', '38249.58', '0.34580473']], 'time': '2021-05-20T03:56:24.459768Z'}
{'type': 'l2update', 'product_id': 'BTC-USD', 'changes': [['buy', '38316.47', '0.10000000']], 'time': '2021-05-20T03:56:24.463051Z'}
{'type': 'l2update', 'product_id': 'BTC-USD', 'changes': [['buy', '38260.30', '0.02856602']], 'time': '2021-05-20T03:56:24.463234Z'}
{'type': 'l2update', 'product_id': 'BTC-USD', 'changes': [['buy', '38298.85', '0.02681954']], 'time': '2021-05-20T03:56:24.463234Z'}
{'type': 'l2update', 'product_id': 'BTC-USD', 'changes': [['sell', '38485.17', '0.01000000']], 'time': '2021-05-20T03:56:24.463291Z'}
{'type': 'l2update', 'product_id': 'BTC-USD', 'changes': [['sell', '38397.26', '0.50000000']], 'time': '2021-05-20T03:56:24.463462Z'}
{'type': 'l2update', 'product_id': 'BTC-USD', 'changes': [['sell', '38478.38', '0.01204417']], 'time': '2021-05-20T03:56:24.463613Z'}
{'type': 'l2update', 'product_id': 'BTC-USD', 'changes': [['sell', '38457.07', '0.00000000']], 'time': '2021-05-20T03:56:24.469339Z'}
{'type': 'l2update', 'product_id': 'BTC-USD', 'changes': [['sell', '38432.97', '0.00000000']], 'time': '2021-05-20T03:56:24.469339Z'}
{'type': 'l2update', 'product_id': 'BTC-USD', 'changes': [['buy', '38272.95', '0.00000000']], 'time': '2021-05-20T03:56:24.474297Z'}
{'type': 'l2update', 'product_id': 'BTC-USD', 'changes': [['sell', '38415.96', '0.05902944']], 'time': '2021-05-20T03:56:24.479149Z'}
{'type': 'l2update', 'product_id': 'BTC-USD', 'changes': [['sell', '38447.82', '0.00000000']], 'time': '2021-05-20T03:56:24.480761Z'}
{'type': 'l2update', 'product_id': 'BTC-USD', 'changes': [['buy', '38337.12', '0.65579097']], 'time': '2021-05-20T03:56:24.484992Z'}
{'type': 'l2update', 'product_id': 'BTC-USD', 'changes': [['buy', '38152.17', '0.80355629']], 'time': '2021-05-20T03:56:24.485684Z'}
{'type': 'l2update', 'product_id': 'BTC-USD', 'changes': [['sell', '38451.74', '0.00000000']], 'time': '2021-05-20T03:56:24.488575Z'}
{'type': 'l2update', 'product_id': 'BTC-USD', 'changes': [['buy', '38344.64', '0.05022044']], 'time': '2021-05-20T03:56:24.491813Z'}
{'type': 'l2update', 'product_id': 'BTC-USD', 'changes': [['sell', '38386.76', '0.04792890']], 'time': '2021-05-20T03:56:24.491813Z'}
{'type': 'l2update', 'product_id': 'BTC-USD', 'changes': [['sell', '38404.85', '0.05902944']], 'time': '2021-05-20T03:56:24.496957Z'}
{'type': 'l2update', 'product_id': 'BTC-USD', 'changes': [['sell', '38442.68', '0.39349360']], 'time': '2021-05-20T03:56:24.502809Z'}
{'type': 'l2update', 'product_id': 'BTC-USD', 'changes': [['sell', '38437.73', '0.29756958']], 'time': '2021-05-20T03:56:24.502809Z'}
{'type': 'l2update', 'product_id': 'BTC-USD', 'changes': [['sell', '38404.85', '0.00000000']], 'time': '2021-05-20T03:56:24.508845Z'}
{'type': 'l2update', 'product_id': 'BTC-USD', 'changes': [['buy', '38263.03', '0.06215372']], 'time': '2021-05-20T03:56:24.513913Z'}
{'type': 'l2update', 'product_id': 'BTC-USD', 'changes': [['sell', '38464.38', '0.00000000']], 'time': '2021-05-20T03:56:24.514124Z'}
{'type': 'l2update', 'product_id': 'BTC-USD', 'changes': [['buy', '38358.11', '0.00000000']], 'time': '2021-05-20T03:56:24.517761Z'}
{'type': 'l2update', 'product_id': 'BTC-USD', 'changes': [['sell', '38415.96', '0.00000000']], 'time': '2021-05-20T03:56:24.523764Z'}
{'type': 'l2update', 'product_id': 'BTC-USD', 'changes': [['buy', '38340.45', '0.00000000']], 'time': '2021-05-20T03:56:24.525389Z'}
{'type': 'l2update', 'product_id': 'BTC-USD', 'changes': [['buy', '38358.12', '0.00000000']], 'time': '2021-05-20T03:56:24.530095Z'}
{'type': 'l2update', 'product_id': 'BTC-USD', 'changes': [['buy', '38346.16', '0.05902944']], 'time': '2021-05-20T03:56:24.532781Z'}
{'type': 'l2update', 'product_id': 'BTC-USD', 'changes': [['sell', '38399.98', '0.05902944']], 'time': '2021-05-20T03:56:24.533935Z'}
{'type': 'l2update', 'product_id': 'BTC-USD', 'changes': [['sell', '38375.94', '0.40213466']], 'time': '2021-05-20T03:56:24.534522Z'}
{'type': 'l2update', 'product_id': 'BTC-USD', 'changes': [['sell', '38398.27', '0.40550000']], 'time': '2021-05-20T03:56:24.534689Z'}
{'type': 'l2update', 'product_id': 'BTC-USD', 'changes': [['buy', '38260.30', '0.06547321']], 'time': '2021-05-20T03:56:24.539173Z'}
{'type': 'l2update', 'product_id': 'BTC-USD', 'changes': [['buy', '38318.95', '0.03835037']], 'time': '2021-05-20T03:56:24.539173Z'}
{'type': 'l2update', 'product_id': 'BTC-USD', 'changes': [['buy', '38323.50', '0.01262092']], 'time': '2021-05-20T03:56:24.539173Z'}
{'type': 'l2update', 'product_id': 'BTC-USD', 'changes': [['buy', '38351.29', '1.46756192']], 'time': '2021-05-20T03:56:24.539214Z'}
{'type': 'l2update', 'product_id': 'BTC-USD', 'changes': [['sell', '38453.15', '0.65835802']], 'time': '2021-05-20T03:56:24.539258Z'}
{'type': 'l2update', 'product_id': 'BTC-USD', 'changes': [['buy', '38263.03', '0.37470701']], 'time': '2021-05-20T03:56:24.539258Z'}
{'type': 'l2update', 'product_id': 'BTC-USD', 'changes': [['buy', '38269.47', '0.39788553']], 'time': '2021-05-20T03:56:24.539258Z'}
{'type': 'l2update', 'product_id': 'BTC-USD', 'changes': [['buy', '38281.78', '0.44307495']], 'time': '2021-05-20T03:56:24.539258Z'}
{'type': 'l2update', 'product_id': 'BTC-USD', 'changes': [['sell', '38398.27', '0.00000000']], 'time': '2021-05-20T03:56:24.547120Z'}
{'type': 'l2update', 'product_id': 'BTC-USD', 'changes': [['buy', '38328.34', '0.00000000']], 'time': '2021-05-20T03:56:24.548417Z'}
{'type': 'l2update', 'product_id': 'BTC-USD', 'changes': [['sell', '38386.76', '0.00000000']], 'time': '2021-05-20T03:56:24.549441Z'}
{'type': 'l2update', 'product_id': 'BTC-USD', 'changes': [['sell', '38415.48', '0.10000000']], 'time': '2021-05-20T03:56:24.550333Z'}
{'type': 'l2update', 'product_id': 'BTC-USD', 'changes': [['buy', '38281.78', '0.40472458']], 'time': '2021-05-20T03:56:24.552249Z'}
{'type': 'l2update', 'product_id': 'BTC-USD', 'changes': [['buy', '38287.66', '0.00000000']], 'time': '2021-05-20T03:56:24.552249Z'}
{'type': 'l2update', 'product_id': 'BTC-USD', 'changes': [['buy', '38233.40', '0.00000000']], 'time': '2021-05-20T03:56:24.553054Z'}
{'type': 'l2update', 'product_id': 'BTC-USD', 'changes': [['buy', '38239.28', '0.00000000']], 'time': '2021-05-20T03:56:24.553054Z'}
{'type': 'l2update', 'product_id': 'BTC-USD', 'changes': [['buy', '38357.39', '0.68100000']], 'time': '2021-05-20T03:56:24.554993Z'}
{'type': 'l2update', 'product_id': 'BTC-USD', 'changes': [['sell', '38424.37', '0.05262943']], 'time': '2021-05-20T03:56:24.560950Z'}
{'type': 'l2update', 'product_id': 'BTC-USD', 'changes': [['buy', '38176.39', '0.04921210']], 'time': '2021-05-20T03:56:24.561084Z'}
{'type': 'l2update', 'product_id': 'BTC-USD', 'changes': [['sell', '38453.15', '0.31255329']], 'time': '2021-05-20T03:56:24.563823Z'}
{'type': 'l2update', 'product_id': 'BTC-USD', 'changes': [['buy', '38318.95', '0.06516991']], 'time': '2021-05-20T03:56:24.571143Z'}
{'type': 'l2update', 'product_id': 'BTC-USD', 'changes': [['buy', '38346.51', '0.42650000']], 'time': '2021-05-20T03:56:24.571245Z'}
{'type': 'l2update', 'product_id': 'BTC-USD', 'changes': [['sell', '38398.49', '0.04915733']], 'time': '2021-05-20T03:56:24.577462Z'}
{'type': 'l2update', 'product_id': 'BTC-USD', 'changes': [['buy', '38357.44', '0.59116555']], 'time': '2021-05-20T03:56:24.577480Z'}
{'type': 'l2update', 'product_id': 'BTC-USD', 'changes': [['sell', '38502.49', '0.00000000']], 'time': '2021-05-20T03:56:24.578503Z'}
{'type': 'l2update', 'product_id': 'BTC-USD', 'changes': [['buy', '38298.85', '0.00000000']], 'time': '2021-05-20T03:56:24.582476Z'}
{'type': 'l2update', 'product_id': 'BTC-USD', 'changes': [['sell', '38452.07', '0.00000000']], 'time': '2021-05-20T03:56:24.586060Z'}
{'type': 'l2update', 'product_id': 'BTC-USD', 'changes': [['sell', '38399.98', '0.00000000']], 'time': '2021-05-20T03:56:24.589611Z'}
{'type': 'l2update', 'product_id': 'BTC-USD', 'changes': [['buy', '38359.25', '0.41900000']], 'time': '2021-05-20T03:56:24.594129Z'}
{'type': 'l2update', 'product_id': 'BTC-USD', 'changes': [['sell', '38432.97', '0.35567087']], 'time': '2021-05-20T03:56:24.594768Z'}
{'type': 'l2update', 'product_id': 'BTC-USD', 'changes': [['sell', '38485.17', '0.00000000']], 'time': '2021-05-20T03:56:24.595097Z'}
{'type': 'l2update', 'product_id': 'BTC-USD', 'changes': [['sell', '38463.64', '0.01000000']], 'time': '2021-05-20T03:56:24.603499Z'}
{'type': 'l2update', 'product_id': 'BTC-USD', 'changes': [['sell', '38442.68', '0.00000000']], 'time': '2021-05-20T03:56:24.605446Z'}
{'type': 'l2update', 'product_id': 'BTC-USD', 'changes': [['sell', '38437.73', '0.00000000']], 'time': '2021-05-20T03:56:24.605446Z'}
{'type': 'l2update', 'product_id': 'BTC-USD', 'changes': [['sell', '38612.70', '0.00000000']], 'time': '2021-05-20T03:56:24.606234Z'}
{'type': 'l2update', 'product_id': 'BTC-USD', 'changes': [['sell', '38462.59', '0.03752044']], 'time': '2021-05-20T03:56:24.606767Z'}
{'type': 'l2update', 'product_id': 'BTC-USD', 'changes': [['sell', '38453.22', '0.00000000']], 'time': '2021-05-20T03:56:24.606767Z'}
{'type': 'l2update', 'product_id': 'BTC-USD', 'changes': [['sell', '38453.15', '0.00000000']], 'time': '2021-05-20T03:56:24.613964Z'}
{'type': 'l2update', 'product_id': 'BTC-USD', 'changes': [['sell', '38466.93', '0.02589698']], 'time': '2021-05-20T03:56:24.616340Z'}
{'type': 'l2update', 'product_id': 'BTC-USD', 'changes': [['sell', '38519.59', '0.02945000']], 'time': '2021-05-20T03:56:24.621115Z'}
{'type': 'l2update', 'product_id': 'BTC-USD', 'changes': [['sell', '38572.14', '0.01000000']], 'time': '2021-05-20T03:56:24.626227Z'}
{'type': 'l2update', 'product_id': 'BTC-USD', 'changes': [['buy', '38263.03', '0.40138602']], 'time': '2021-05-20T03:56:24.626537Z'}
{'type': 'l2update', 'product_id': 'BTC-USD', 'changes': [['buy', '38293.35', '0.02958142']], 'time': '2021-05-20T03:56:24.626537Z'}
{'type': 'l2update', 'product_id': 'BTC-USD', 'changes': [['buy', '38298.85', '0.03257230']], 'time': '2021-05-20T03:56:24.626537Z'}
{'type': 'l2update', 'product_id': 'BTC-USD', 'changes': [['buy', '38304.16', '0.03054604']], 'time': '2021-05-20T03:56:24.626537Z'}
{'type': 'l2update', 'product_id': 'BTC-USD', 'changes': [['sell', '38591.11', '0.01606430']], 'time': '2021-05-20T03:56:24.626645Z'}
{'type': 'l2update', 'product_id': 'BTC-USD', 'changes': [['sell', '38424.02', '0.32556707']], 'time': '2021-05-20T03:56:24.631655Z'}
{'type': 'l2update', 'product_id': 'BTC-USD', 'changes': [['buy', '38256.40', '0.32556707']], 'time': '2021-05-20T03:56:24.631655Z'}
{'type': 'l2update', 'product_id': 'BTC-USD', 'changes': [['buy', '38263.03', '0.37180460']], 'time': '2021-05-20T03:56:24.633520Z'}
{'type': 'l2update', 'product_id': 'BTC-USD', 'changes': [['buy', '38263.03', '0.33923230']], 'time': '2021-05-20T03:56:24.633520Z'}
{'type': 'l2update', 'product_id': 'BTC-USD', 'changes': [['buy', '38269.47', '0.36733949']], 'time': '2021-05-20T03:56:24.633520Z'}
{'type': 'l2update', 'product_id': 'BTC-USD', 'changes': [['sell', '38559.22', '0.00000000']], 'time': '2021-05-20T03:56:24.642623Z'}
{'type': 'l2update', 'product_id': 'BTC-USD', 'changes': [['sell', '38385.55', '0.06294756']], 'time': '2021-05-20T03:56:24.643267Z'}
{'type': 'l2update', 'product_id': 'BTC-USD', 'changes': [['sell', '38479.51', '0.00000000']], 'time': '2021-05-20T03:56:24.645168Z'}
{'type': 'l2update', 'product_id': 'BTC-USD', 'changes': [['sell', '38412.92', '0.00000000']], 'time': '2021-05-20T03:56:24.646802Z'}
{'type': 'l2update', 'product_id': 'BTC-USD', 'changes': [['sell', '38432.97', '0.71562002']], 'time': '2021-05-20T03:56:24.647495Z'}
{'type': 'l2update', 'product_id': 'BTC-USD', 'changes': [['buy', '38249.58', '0.70575388']], 'time': '2021-05-20T03:56:24.647495Z'}
{'type': 'l2update', 'product_id': 'BTC-USD', 'changes': [['sell', '38396.79', '0.05000000']], 'time': '2021-05-20T03:56:24.647745Z'}
{'type': 'l2update', 'product_id': 'BTC-USD', 'changes': [['sell', '38404.91', '0.41840000']], 'time': '2021-05-20T03:56:24.652339Z'}
{'type': 'l2update', 'product_id': 'BTC-USD', 'changes': [['buy', '38330.42', '0.00000000']], 'time': '2021-05-20T03:56:24.655262Z'}
{'type': 'l2update', 'product_id': 'BTC-USD', 'changes': [['sell', '38495.81', '0.03835037']], 'time': '2021-05-20T03:56:24.659464Z'}
{'type': 'l2update', 'product_id': 'BTC-USD', 'changes': [['sell', '38495.81', '0.00000000']], 'time': '2021-05-20T03:56:24.659464Z'}
{'type': 'l2update', 'product_id': 'BTC-USD', 'changes': [['sell', '38489.14', '0.00000000']], 'time': '2021-05-20T03:56:24.659464Z'}
{'type': 'l2update', 'product_id': 'BTC-USD', 'changes': [['sell', '38476.37', '0.00000000']], 'time': '2021-05-20T03:56:24.659464Z'}
{'type': 'l2update', 'product_id': 'BTC-USD', 'changes': [['sell', '38468.30', '0.00000000']], 'time': '2021-05-20T03:56:24.659464Z'}
{'type': 'l2update', 'product_id': 'BTC-USD', 'changes': [['sell', '38462.59', '0.00000000']], 'time': '2021-05-20T03:56:24.659464Z'}
{'type': 'l2update', 'product_id': 'BTC-USD', 'changes': [['sell', '38535.23', '0.01297514']], 'time': '2021-05-20T03:56:24.660616Z'}
{'type': 'l2update', 'product_id': 'BTC-USD', 'changes': [['sell', '38419.84', '0.39371295']], 'time': '2021-05-20T03:56:24.671713Z'}
{'type': 'l2update', 'product_id': 'BTC-USD', 'changes': [['buy', '38235.38', '0.39371295']], 'time': '2021-05-20T03:56:24.671713Z'}
{'type': 'l2update', 'product_id': 'BTC-USD', 'changes': [['sell', '38499.18', '0.01000000']], 'time': '2021-05-20T03:56:24.671899Z'}
{'type': 'l2update', 'product_id': 'BTC-USD', 'changes': [['sell', '38478.38', '0.00000000']], 'time': '2021-05-20T03:56:24.671989Z'}
{'type': 'l2update', 'product_id': 'BTC-USD', 'changes': [['sell', '38494.42', '0.00000000']], 'time': '2021-05-20T03:56:24.693549Z'}
{'type': 'l2update', 'product_id': 'BTC-USD', 'changes': [['sell', '38424.02', '0.70433877']], 'time': '2021-05-20T03:56:24.694371Z'}
{'type': 'l2update', 'product_id': 'BTC-USD', 'changes': [['sell', '38466.93', '0.00000000']], 'time': '2021-05-20T03:56:24.695347Z'}
{'type': 'l2update', 'product_id': 'BTC-USD', 'changes': [['sell', '38379.37', '1.10200000']], 'time': '2021-05-20T03:56:24.697849Z'}
{'type': 'l2update', 'product_id': 'BTC-USD', 'changes': [['sell', '38404.91', '0.00000000']], 'time': '2021-05-20T03:56:24.699847Z'}
{'type': 'l2update', 'product_id': 'BTC-USD', 'changes': [['buy', '38269.47', '0.39598024']], 'time': '2021-05-20T03:56:24.703891Z'}
{'type': 'l2update', 'product_id': 'BTC-USD', 'changes': [['buy', '38200.32', '0.00000000']], 'time': '2021-05-20T03:56:24.704087Z'}
{'type': 'l2update', 'product_id': 'BTC-USD', 'changes': [['sell', '38394.33', '0.04812759']], 'time': '2021-05-20T03:56:24.707192Z'}
{'type': 'l2update', 'product_id': 'BTC-USD', 'changes': [['sell', '38518.83', '0.00000000']], 'time': '2021-05-20T03:56:24.710529Z'}
{'type': 'l2update', 'product_id': 'BTC-USD', 'changes': [['buy', '38357.39', '0.16000000']], 'time': '2021-05-20T03:56:24.714229Z'}
{'type': 'l2update', 'product_id': 'BTC-USD', 'changes': [['sell', '38591.11', '0.00000000']], 'time': '2021-05-20T03:56:24.714356Z'}
{'type': 'l2update', 'product_id': 'BTC-USD', 'changes': [['sell', '38520.03', '0.01000000']], 'time': '2021-05-20T03:56:24.714555Z'}
{'type': 'l2update', 'product_id': 'BTC-USD', 'changes': [['sell', '38508.35', '0.01203479']], 'time': '2021-05-20T03:56:24.715623Z'}
{'type': 'l2update', 'product_id': 'BTC-USD', 'changes': [['sell', '38432.97', '1.06678313']], 'time': '2021-05-20T03:56:24.715989Z'}
{'type': 'l2update', 'product_id': 'BTC-USD', 'changes': [['buy', '38362.37', '0.00000000']], 'time': '2021-05-20T03:56:24.716523Z'}
{'type': 'l2update', 'product_id': 'BTC-USD', 'changes': [['buy', '38221.93', '0.18630000']], 'time': '2021-05-20T03:56:24.724570Z'}
{'type': 'l2update', 'product_id': 'BTC-USD', 'changes': [['sell', '38437.73', '0.03055082']], 'time': '2021-05-20T03:56:24.724727Z'}
{'type': 'l2update', 'product_id': 'BTC-USD', 'changes': [['sell', '38427.94', '0.06025429']], 'time': '2021-05-20T03:56:24.724727Z'}
{'type': 'l2update', 'product_id': 'BTC-USD', 'changes': [['buy', '38263.03', '0.36978312']], 'time': '2021-05-20T03:56:24.724727Z'}
{'type': 'l2update', 'product_id': 'BTC-USD', 'changes': [['sell', '38537.12', '0.01280106']], 'time': '2021-05-20T03:56:24.733078Z'}
{'type': 'l2update', 'product_id': 'BTC-USD', 'changes': [['sell', '38503.79', '0.01298573']], 'time': '2021-05-20T03:56:24.734108Z'}
{'type': 'l2update', 'product_id': 'BTC-USD', 'changes': [['sell', '38398.50', '0.00000000']], 'time': '2021-05-20T03:56:24.734895Z'}
{'type': 'l2update', 'product_id': 'BTC-USD', 'changes': [['sell', '38502.67', '0.00000000']], 'time': '2021-05-20T03:56:24.735382Z'}
{'type': 'l2update', 'product_id': 'BTC-USD', 'changes': [['sell', '38442.68', '0.30980891']], 'time': '2021-05-20T03:56:24.738767Z'}
{'type': 'l2update', 'product_id': 'BTC-USD', 'changes': [['buy', '38281.63', '0.00000000']], 'time': '2021-05-20T03:56:24.742303Z'}
{'type': 'l2update', 'product_id': 'BTC-USD', 'changes': [['sell', '38577.61', '0.01000000']], 'time': '2021-05-20T03:56:24.742571Z'}
{'type': 'l2update', 'product_id': 'BTC-USD', 'changes': [['sell', '38572.14', '0.00000000']], 'time': '2021-05-20T03:56:24.744537Z'}
{'type': 'l2update', 'product_id': 'BTC-USD', 'changes': [['sell', '38447.82', '0.02924881']], 'time': '2021-05-20T03:56:24.754710Z'}
{'type': 'l2update', 'product_id': 'BTC-USD', 'changes': [['buy', '38256.40', '0.35481588']], 'time': '2021-05-20T03:56:24.754710Z'}
{'type': 'l2update', 'product_id': 'BTC-USD', 'changes': [['sell', '38447.82', '0.46600240']], 'time': '2021-05-20T03:56:24.754908Z'}
{'type': 'l2update', 'product_id': 'BTC-USD', 'changes': [['sell', '38587.21', '0.01000000']], 'time': '2021-05-20T03:56:24.760555Z'}
{'type': 'l2update', 'product_id': 'BTC-USD', 'changes': [['buy', '38359.34', '0.07111902']], 'time': '2021-05-20T03:56:24.763262Z'}
{'type': 'l2update', 'product_id': 'BTC-USD', 'changes': [['sell', '38397.26', '0.00000000']], 'time': '2021-05-20T03:56:24.768012Z'}
{'type': 'l2update', 'product_id': 'BTC-USD', 'changes': [['sell', '38396.79', '0.00000000']], 'time': '2021-05-20T03:56:24.779868Z'}
{'type': 'l2update', 'product_id': 'BTC-USD', 'changes': [['sell', '38379.36', '0.50000000']], 'time': '2021-05-20T03:56:24.788696Z'}
{'type': 'l2update', 'product_id': 'BTC-USD', 'changes': [['sell', '38520.03', '0.00000000']], 'time': '2021-05-20T03:56:24.788795Z'}
{'type': 'l2update', 'product_id': 'BTC-USD', 'changes': [['sell', '38401.27', '0.05000000']], 'time': '2021-05-20T03:56:24.789687Z'}
{'type': 'l2update', 'product_id': 'BTC-USD', 'changes': [['sell', '38394.33', '0.00000000']], 'time': '2021-05-20T03:56:24.790090Z'}
{'type': 'l2update', 'product_id': 'BTC-USD', 'changes': [['sell', '38461.63', '0.00000000']], 'time': '2021-05-20T03:56:24.790406Z'}
{'type': 'l2update', 'product_id': 'BTC-USD', 'changes': [['buy', '38012.79', '0.00000000']], 'time': '2021-05-20T03:56:24.796025Z'}
{'type': 'l2update', 'product_id': 'BTC-USD', 'changes': [['sell', '38403.87', '0.41430000']], 'time': '2021-05-20T03:56:24.801330Z'}
{'type': 'l2update', 'product_id': 'BTC-USD', 'changes': [['buy', '38359.39', '0.84600000']], 'time': '2021-05-20T03:56:24.805412Z'}
{'type': 'l2update', 'product_id': 'BTC-USD', 'changes': [['sell', '38458.67', '0.29444075']], 'time': '2021-05-20T03:56:24.806312Z'}
{'type': 'l2update', 'product_id': 'BTC-USD', 'changes': [['sell', '38447.82', '0.49971929']], 'time': '2021-05-20T03:56:24.807409Z'}
{'type': 'l2update', 'product_id': 'BTC-USD', 'changes': [['sell', '38494.39', '0.01000000']], 'time': '2021-05-20T03:56:24.807679Z'}
{'type': 'l2update', 'product_id': 'BTC-USD', 'changes': [['buy', '38025.67', '0.13149009']], 'time': '2021-05-20T03:56:24.813524Z'}
{'type': 'l2update', 'product_id': 'BTC-USD', 'changes': [['buy', '38357.44', '0.00000000']], 'time': '2021-05-20T03:56:24.814846Z'}
{'type': 'l2update', 'product_id': 'BTC-USD', 'changes': [['sell', '38441.87', '0.00000000']], 'time': '2021-05-20T03:56:24.821017Z'}
{'type': 'l2update', 'product_id': 'BTC-USD', 'changes': [['sell', '38410.81', '0.10000000']], 'time': '2021-05-20T03:56:24.821797Z'}
{'type': 'l2update', 'product_id': 'BTC-USD', 'changes': [['sell', '38470.28', '0.31066420']], 'time': '2021-05-20T03:56:24.830094Z'}
{'type': 'l2update', 'product_id': 'BTC-USD', 'changes': [['sell', '38454.88', '0.01155000']], 'time': '2021-05-20T03:56:24.838984Z'}
{'type': 'l2update', 'product_id': 'BTC-USD', 'changes': [['sell', '38537.12', '0.00000000']], 'time': '2021-05-20T03:56:24.840002Z'}
{'type': 'l2update', 'product_id': 'BTC-USD', 'changes': [['buy', '38359.40', '0.59116555']], 'time': '2021-05-20T03:56:24.843825Z'}
{'type': 'l2update', 'product_id': 'BTC-USD', 'changes': [['buy', '38345.96', '0.39490431']], 'time': '2021-05-20T03:56:24.843914Z'}
{'type': 'l2update', 'product_id': 'BTC-USD', 'changes': [['buy', '38347.89', '0.41900000']], 'time': '2021-05-20T03:56:24.848851Z'}
{'type': 'l2update', 'product_id': 'BTC-USD', 'changes': [['sell', '38375.94', '0.40194164']], 'time': '2021-05-20T03:56:24.849124Z'}
{'type': 'l2update', 'product_id': 'BTC-USD', 'changes': [['buy', '38359.25', '0.00000000']], 'time': '2021-05-20T03:56:24.853867Z'}
{'type': 'l2update', 'product_id': 'BTC-USD', 'changes': [['sell', '38476.37', '0.34116439']], 'time': '2021-05-20T03:56:24.857425Z'}
{'type': 'l2update', 'product_id': 'BTC-USD', 'changes': [['sell', '38458.67', '0.32379259']], 'time': '2021-05-20T03:56:24.865180Z'}
{'type': 'l2update', 'product_id': 'BTC-USD', 'changes': [['sell', '38519.55', '0.08588270']], 'time': '2021-05-20T03:56:24.868685Z'}
{'type': 'l2update', 'product_id': 'BTC-USD', 'changes': [['buy', '38346.51', '0.00000000']], 'time': '2021-05-20T03:56:24.880732Z'}
{'type': 'l2update', 'product_id': 'BTC-USD', 'changes': [['sell', '38494.39', '0.00000000']], 'time': '2021-05-20T03:56:24.884097Z'}
{'type': 'l2update', 'product_id': 'BTC-USD', 'changes': [['buy', '38338.62', '0.42830000']], 'time': '2021-05-20T03:56:24.894734Z'}
{'type': 'l2update', 'product_id': 'BTC-USD', 'changes': [['buy', '38338.62', '0.00000000']], 'time': '2021-05-20T03:56:24.901065Z'}
{'type': 'l2update', 'product_id': 'BTC-USD', 'changes': [['sell', '38522.01', '0.01297959']], 'time': '2021-05-20T03:56:24.903632Z'}
{'type': 'l2update', 'product_id': 'BTC-USD', 'changes': [['buy', '38340.42', '0.00000000']], 'time': '2021-05-20T03:56:24.906588Z'}
{'type': 'l2update', 'product_id': 'BTC-USD', 'changes': [['sell', '38535.23', '0.00000000']], 'time': '2021-05-20T03:56:24.912159Z'}
{'type': 'l2update', 'product_id': 'BTC-USD', 'changes': [['buy', '38342.03', '0.00000000']], 'time': '2021-05-20T03:56:24.915977Z'}
{'type': 'l2update', 'product_id': 'BTC-USD', 'changes': [['buy', '38341.22', '0.00000000']], 'time': '2021-05-20T03:56:24.915977Z'}
{'type': 'l2update', 'product_id': 'BTC-USD', 'changes': [['sell', '38385.55', '0.00000000']], 'time': '2021-05-20T03:56:24.917831Z'}
{'type': 'l2update', 'product_id': 'BTC-USD', 'changes': [['sell', '38572.18', '0.01296271']], 'time': '2021-05-20T03:56:24.929277Z'}
{'type': 'l2update', 'product_id': 'BTC-USD', 'changes': [['sell', '38587.21', '0.00000000']], 'time': '2021-05-20T03:56:24.929336Z'}
{'type': 'l2update', 'product_id': 'BTC-USD', 'changes': [['buy', '38349.50', '0.02390000']], 'time': '2021-05-20T03:56:24.934727Z'}
{'type': 'l2update', 'product_id': 'BTC-USD', 'changes': [['buy', '38348.69', '0.02390000']], 'time': '2021-05-20T03:56:24.934727Z'}
{'type': 'l2update', 'product_id': 'BTC-USD', 'changes': [['buy', '38347.89', '0.44290000']], 'time': '2021-05-20T03:56:24.934727Z'}
{'type': 'l2update', 'product_id': 'BTC-USD', 'changes': [['sell', '38519.59', '0.00000000']], 'time': '2021-05-20T03:56:24.935534Z'}
{'type': 'l2update', 'product_id': 'BTC-USD', 'changes': [['sell', '38519.55', '0.00000000']], 'time': '2021-05-20T03:56:24.936547Z'}
{'type': 'l2update', 'product_id': 'BTC-USD', 'changes': [['buy', '38316.47', '0.00000000']], 'time': '2021-05-20T03:56:24.940083Z'}
{'type': 'l2update', 'product_id': 'BTC-USD', 'changes': [['sell', '38379.37', '0.00000000']], 'time': '2021-05-20T03:56:24.941741Z'}
{'type': 'l2update', 'product_id': 'BTC-USD', 'changes': [['buy', '38347.89', '0.41900000']], 'time': '2021-05-20T03:56:24.943529Z'}
{'type': 'l2update', 'product_id': 'BTC-USD', 'changes': [['sell', '38590.98', '0.01000000']], 'time': '2021-05-20T03:56:24.945605Z'}
{'type': 'l2update', 'product_id': 'BTC-USD', 'changes': [['sell', '38410.81', '0.00000000']], 'time': '2021-05-20T03:56:24.947291Z'}
{'type': 'l2update', 'product_id': 'BTC-USD', 'changes': [['sell', '38522.01', '0.00000000']], 'time': '2021-05-20T03:56:24.947419Z'}
{'type': 'l2update', 'product_id': 'BTC-USD', 'changes': [['sell', '38392.64', '0.06221545']], 'time': '2021-05-20T03:56:24.949886Z'}
{'type': 'l2update', 'product_id': 'BTC-USD', 'changes': [['sell', '38504.30', '0.01502900']], 'time': '2021-05-20T03:56:24.950220Z'}
{'type': 'l2update', 'product_id': 'BTC-USD', 'changes': [['buy', '38315.47', '0.10000000']], 'time': '2021-05-20T03:56:24.952972Z'}
{'type': 'l2update', 'product_id': 'BTC-USD', 'changes': [['sell', '38398.49', '0.00000000']], 'time': '2021-05-20T03:56:24.956222Z'}
{'type': 'l2update', 'product_id': 'BTC-USD', 'changes': [['sell', '38387.12', '1.27500000']], 'time': '2021-05-20T03:56:24.957246Z'}
{'type': 'l2update', 'product_id': 'BTC-USD', 'changes': [['sell', '38379.36', '0.00000000']], 'time': '2021-05-20T03:56:24.959881Z'}
{'type': 'l2update', 'product_id': 'BTC-USD', 'changes': [['buy', '38350.43', '0.02390000']], 'time': '2021-05-20T03:56:24.960921Z'}
{'type': 'l2update', 'product_id': 'BTC-USD', 'changes': [['sell', '38555.59', '0.01296829']], 'time': '2021-05-20T03:56:24.961050Z'}
{'type': 'l2update', 'product_id': 'BTC-USD', 'changes': [['sell', '38501.99', '0.02027234']], 'time': '2021-05-20T03:56:24.965905Z'}
{'type': 'l2update', 'product_id': 'BTC-USD', 'changes': [['sell', '38397.25', '0.04915733']], 'time': '2021-05-20T03:56:24.966176Z'}
{'type': 'l2update', 'product_id': 'BTC-USD', 'changes': [['buy', '38349.50', '0.00000000']], 'time': '2021-05-20T03:56:24.966404Z'}
{'type': 'l2update', 'product_id': 'BTC-USD', 'changes': [['buy', '38348.69', '0.00000000']], 'time': '2021-05-20T03:56:24.966404Z'}
{'type': 'l2update', 'product_id': 'BTC-USD', 'changes': [['buy', '38351.29', '0.00000000']], 'time': '2021-05-20T03:56:24.968580Z'}
{'type': 'l2update', 'product_id': 'BTC-USD', 'changes': [['sell', '38482.66', '0.34517721']], 'time': '2021-05-20T03:56:24.969521Z'}
{'type': 'l2update', 'product_id': 'BTC-USD', 'changes': [['buy', '38296.99', '1.80890000']], 'time': '2021-05-20T03:56:24.975953Z'}
{'type': 'l2update', 'product_id': 'BTC-USD', 'changes': [['sell', '38397.26', '0.50000000']], 'time': '2021-05-20T03:56:24.976291Z'}
{'type': 'l2update', 'product_id': 'BTC-USD', 'changes': [['buy', '38359.41', '1.46756192']], 'time': '2021-05-20T03:56:24.981618Z'}
{'type': 'l2update', 'product_id': 'BTC-USD', 'changes': [['buy', '38349.62', '0.02390000']], 'time': '2021-05-20T03:56:24.982221Z'}
{'type': 'l2update', 'product_id': 'BTC-USD', 'changes': [['buy', '38348.82', '0.02390000']], 'time': '2021-05-20T03:56:24.982221Z'}
{'type': 'l2update', 'product_id': 'BTC-USD', 'changes': [['buy', '38359.40', '0.00000000']], 'time': '2021-05-20T03:56:24.989373Z'}
{'type': 'l2update', 'product_id': 'BTC-USD', 'changes': [['buy', '38350.43', '0.00000000']], 'time': '2021-05-20T03:56:24.990239Z'}
{'type': 'l2update', 'product_id': 'BTC-USD', 'changes': [['sell', '38375.94', '0.39890000']], 'time': '2021-05-20T03:56:24.994438Z'}
{'type': 'l2update', 'product_id': 'BTC-USD', 'changes': [['sell', '38375.94', '0.37637161']], 'time': '2021-05-20T03:56:24.994438Z'}
{'type': 'l2update', 'product_id': 'BTC-USD', 'changes': [['sell', '38495.81', '0.40882511']], 'time': '2021-05-20T03:56:24.994812Z'}
{'type': 'l2update', 'product_id': 'BTC-USD', 'changes': [['buy', '38340.80', '0.40890000']], 'time': '2021-05-20T03:56:24.994906Z'}
{'type': 'l2update', 'product_id': 'BTC-USD', 'changes': [['sell', '38401.27', '0.00000000']], 'time': '2021-05-20T03:56:24.995087Z'}
{'type': 'l2update', 'product_id': 'BTC-USD', 'changes': [['buy', '38359.41', '0.00000000']], 'time': '2021-05-20T03:56:24.996740Z'}
{'type': 'l2update', 'product_id': 'BTC-USD', 'changes': [['sell', '38375.94', '0.37000000']], 'time': '2021-05-20T03:56:25.002902Z'}
{'type': 'l2update', 'product_id': 'BTC-USD', 'changes': [['sell', '38464.38', '0.03233729']], 'time': '2021-05-20T03:56:25.003114Z'}
{'type': 'l2update', 'product_id': 'BTC-USD', 'changes': [['buy', '38347.96', '0.02390000']], 'time': '2021-05-20T03:56:25.003324Z'}
{'type': 'l2update', 'product_id': 'BTC-USD', 'changes': [['sell', '38406.51', '0.05000000']], 'time': '2021-05-20T03:56:25.007665Z'}
{'type': 'l2update', 'product_id': 'BTC-USD', 'changes': [['buy', '38359.42', '0.59116555']], 'time': '2021-05-20T03:56:25.010968Z'}
{'type': 'l2update', 'product_id': 'BTC-USD', 'changes': [['buy', '38349.62', '0.00000000']], 'time': '2021-05-20T03:56:25.012872Z'}
{'type': 'l2update', 'product_id': 'BTC-USD', 'changes': [['buy', '38358.11', '1.46756192']], 'time': '2021-05-20T03:56:25.015790Z'}
{'type': 'l2update', 'product_id': 'BTC-USD', 'changes': [['sell', '38392.64', '0.00000000']], 'time': '2021-05-20T03:56:25.015920Z'}
{'type': 'l2update', 'product_id': 'BTC-USD', 'changes': [['sell', '38382.23', '0.59200000']], 'time': '2021-05-20T03:56:25.019920Z'}
{'type': 'l2update', 'product_id': 'BTC-USD', 'changes': [['buy', '38346.54', '0.02390000']], 'time': '2021-05-20T03:56:25.028177Z'}
{'type': 'l2update', 'product_id': 'BTC-USD', 'changes': [['buy', '38340.80', '0.00000000']], 'time': '2021-05-20T03:56:25.040401Z'}
{'type': 'l2update', 'product_id': 'BTC-USD', 'changes': [['sell', '38470.28', '0.33699773']], 'time': '2021-05-20T03:56:25.040707Z'}
{'type': 'l2update', 'product_id': 'BTC-USD', 'changes': [['sell', '38392.62', '0.04366553']], 'time': '2021-05-20T03:56:25.044677Z'}
{'type': 'l2update', 'product_id': 'BTC-USD', 'changes': [['buy', '38346.52', '0.04915733']], 'time': '2021-05-20T03:56:25.064427Z'}
{'type': 'l2update', 'product_id': 'BTC-USD', 'changes': [['buy', '38346.16', '0.00000000']], 'time': '2021-05-20T03:56:25.069395Z'}
{'type': 'l2update', 'product_id': 'BTC-USD', 'changes': [['buy', '38370.68', '0.04954009']], 'time': '2021-05-20T03:56:25.072493Z'}
{'type': 'l2update', 'product_id': 'BTC-USD', 'changes': [['sell', '38397.26', '0.00000000']], 'time': '2021-05-20T03:56:25.079604Z'}
{'type': 'l2update', 'product_id': 'BTC-USD', 'changes': [['buy', '38359.47', '0.52100000']], 'time': '2021-05-20T03:56:25.080989Z'}
{'type': 'l2update', 'product_id': 'BTC-USD', 'changes': [['buy', '38366.73', '0.00000000']], 'time': '2021-05-20T03:56:25.083938Z'}
{'type': 'l2update', 'product_id': 'BTC-USD', 'changes': [['buy', '38359.42', '0.00000000']], 'time': '2021-05-20T03:56:25.089825Z'}
{'type': 'l2update', 'product_id': 'BTC-USD', 'changes': [['sell', '38392.61', '0.50000000']], 'time': '2021-05-20T03:56:25.094781Z'}
{'type': 'l2update', 'product_id': 'BTC-USD', 'changes': [['sell', '38504.30', '0.00000000']], 'time': '2021-05-20T03:56:25.097476Z'}
{'type': 'l2update', 'product_id': 'BTC-USD', 'changes': [['sell', '38590.98', '0.00000000']], 'time': '2021-05-20T03:56:25.098278Z'}
{'type': 'l2update', 'product_id': 'BTC-USD', 'changes': [['sell', '38415.48', '0.00000000']], 'time': '2021-05-20T03:56:25.101727Z'}
{'type': 'l2update', 'product_id': 'BTC-USD', 'changes': [['sell', '38502.67', '0.42239315']], 'time': '2021-05-20T03:56:25.108229Z'}
{'type': 'l2update', 'product_id': 'BTC-USD', 'changes': [['sell', '38407.88', '0.04834389']], 'time': '2021-05-20T03:56:25.109440Z'}
{'type': 'l2update', 'product_id': 'BTC-USD', 'changes': [['buy', '38359.48', '0.59116555']], 'time': '2021-05-20T03:56:25.109675Z'}
{'type': 'l2update', 'product_id': 'BTC-USD', 'changes': [['buy', '38359.34', '0.00000000']], 'time': '2021-05-20T03:56:25.109825Z'}
{'type': 'l2update', 'product_id': 'BTC-USD', 'changes': [['sell', '38516.42', '0.02260036']], 'time': '2021-05-20T03:56:25.110106Z'}
{'type': 'l2update', 'product_id': 'BTC-USD', 'changes': [['sell', '38625.96', '0.01000000']], 'time': '2021-05-20T03:56:25.113442Z'}
{'type': 'l2update', 'product_id': 'BTC-USD', 'changes': [['buy', '38344.64', '0.00000000']], 'time': '2021-05-20T03:56:25.119879Z'}
{'type': 'l2update', 'product_id': 'BTC-USD', 'changes': [['sell', '38392.62', '0.00000000']], 'time': '2021-05-20T03:56:25.119879Z'}
{'type': 'l2update', 'product_id': 'BTC-USD', 'changes': [['sell', '38397.25', '0.00000000']], 'time': '2021-05-20T03:56:25.123580Z'}
{'type': 'l2update', 'product_id': 'BTC-USD', 'changes': [['sell', '38476.37', '0.36879151']], 'time': '2021-05-20T03:56:25.128810Z'}
{'type': 'l2update', 'product_id': 'BTC-USD', 'changes': [['sell', '38396.78', '0.04915733']], 'time': '2021-05-20T03:56:25.128888Z'}
{'type': 'l2update', 'product_id': 'BTC-USD', 'changes': [['buy', '38341.23', '0.41580000']], 'time': '2021-05-20T03:56:25.128927Z'}
{'type': 'l2update', 'product_id': 'BTC-USD', 'changes': [['sell', '38509.72', '0.42774447']], 'time': '2021-05-20T03:56:25.132463Z'}
{'type': 'l2update', 'product_id': 'BTC-USD', 'changes': [['sell', '38392.61', '0.00000000']], 'time': '2021-05-20T03:56:25.132886Z'}
{'type': 'l2update', 'product_id': 'BTC-USD', 'changes': [['buy', '38363.38', '0.52130766']], 'time': '2021-05-20T03:56:25.133620Z'}
{'type': 'l2update', 'product_id': 'BTC-USD', 'changes': [['buy', '38341.23', '0.00000000']], 'time': '2021-05-20T03:56:25.137833Z'}
{'type': 'l2update', 'product_id': 'BTC-USD', 'changes': [['buy', '38315.11', '0.00000000']], 'time': '2021-05-20T03:56:25.138385Z'}
{'type': 'l2update', 'product_id': 'BTC-USD', 'changes': [['sell', '38441.01', '0.00000000']], 'time': '2021-05-20T03:56:25.142311Z'}
{'type': 'l2update', 'product_id': 'BTC-USD', 'changes': [['buy', '38360.13', '0.52135561']], 'time': '2021-05-20T03:56:25.144217Z'}
{'type': 'l2update', 'product_id': 'BTC-USD', 'changes': [['buy', '38367.87', '0.07108668']], 'time': '2021-05-20T03:56:25.144277Z'}
{'type': 'l2update', 'product_id': 'BTC-USD', 'changes': [['buy', '38345.59', '0.05287843']], 'time': '2021-05-20T03:56:25.144505Z'}
{'type': 'l2update', 'product_id': 'BTC-USD', 'changes': [['sell', '38392.44', '0.06160611']], 'time': '2021-05-20T03:56:25.144505Z'}
{'type': 'l2update', 'product_id': 'BTC-USD', 'changes': [['sell', '38397.26', '0.50000000']], 'time': '2021-05-20T03:56:25.149219Z'}
{'type': 'l2update', 'product_id': 'BTC-USD', 'changes': [['sell', '38516.42', '0.00000000']], 'time': '2021-05-20T03:56:25.156446Z'}
{'type': 'l2update', 'product_id': 'BTC-USD', 'changes': [['buy', '38356.92', '0.78181931']], 'time': '2021-05-20T03:56:25.158328Z'}
{'type': 'l2update', 'product_id': 'BTC-USD', 'changes': [['sell', '38482.66', '0.37206866']], 'time': '2021-05-20T03:56:25.158471Z'}
{'type': 'l2update', 'product_id': 'BTC-USD', 'changes': [['sell', '38497.44', '0.01502900']], 'time': '2021-05-20T03:56:25.165448Z'}
{'type': 'l2update', 'product_id': 'BTC-USD', 'changes': [['buy', '38359.48', '0.00000000']], 'time': '2021-05-20T03:56:25.169564Z'}
{'type': 'l2update', 'product_id': 'BTC-USD', 'changes': [['sell', '38488.55', '0.00000000']], 'time': '2021-05-20T03:56:25.171209Z'}
{'type': 'l2update', 'product_id': 'BTC-USD', 'changes': [['buy', '38344.51', '0.78204755']], 'time': '2021-05-20T03:56:25.172466Z'}
{'type': 'l2update', 'product_id': 'BTC-USD', 'changes': [['sell', '38382.23', '0.00000000']], 'time': '2021-05-20T03:56:25.176744Z'}
{'type': 'l2update', 'product_id': 'BTC-USD', 'changes': [['sell', '38474.61', '0.01000000']], 'time': '2021-05-20T03:56:25.181180Z'}
{'type': 'l2update', 'product_id': 'BTC-USD', 'changes': [['buy', '38326.92', '2.60598429']], 'time': '2021-05-20T03:56:25.185790Z'}
{'type': 'l2update', 'product_id': 'BTC-USD', 'changes': [['buy', '38345.59', '0.00000000']], 'time': '2021-05-20T03:56:25.188563Z'}
{'type': 'l2update', 'product_id': 'BTC-USD', 'changes': [['buy', '38360.14', '0.59116555']], 'time': '2021-05-20T03:56:25.188852Z'}
{'type': 'l2update', 'product_id': 'BTC-USD', 'changes': [['sell', '38489.14', '0.03259646']], 'time': '2021-05-20T03:56:25.189246Z'}
{'type': 'l2update', 'product_id': 'BTC-USD', 'changes': [['buy', '38347.89', '0.00000000']], 'time': '2021-05-20T03:56:25.194052Z'}
{'type': 'l2update', 'product_id': 'BTC-USD', 'changes': [['buy', '38321.82', '2.60677805']], 'time': '2021-05-20T03:56:25.196411Z'}
{'type': 'l2update', 'product_id': 'BTC-USD', 'changes': [['sell', '38379.42', '0.00000000']], 'time': '2021-05-20T03:56:25.201323Z'}
{'type': 'l2update', 'product_id': 'BTC-USD', 'changes': [['sell', '38403.87', '0.00000000']], 'time': '2021-05-20T03:56:25.203635Z'}
{'type': 'l2update', 'product_id': 'BTC-USD', 'changes': [['buy', '38359.72', '0.53800000']], 'time': '2021-05-20T03:56:25.204497Z'}
{'type': 'l2update', 'product_id': 'BTC-USD', 'changes': [['buy', '38312.50', '2.60691987']], 'time': '2021-05-20T03:56:25.211355Z'}
{'type': 'l2update', 'product_id': 'BTC-USD', 'changes': [['sell', '38402.53', '0.45180000']], 'time': '2021-05-20T03:56:25.214330Z'}
{'type': 'l2update', 'product_id': 'BTC-USD', 'changes': [['buy', '38246.41', '0.00000000']], 'time': '2021-05-20T03:56:25.214463Z'}
{'type': 'l2update', 'product_id': 'BTC-USD', 'changes': [['sell', '43100.00', '1.09530000']], 'time': '2021-05-20T03:56:25.215862Z'}
{'type': 'l2update', 'product_id': 'BTC-USD', 'changes': [['buy', '38363.43', '0.84600000']], 'time': '2021-05-20T03:56:25.219388Z'}
{'type': 'l2update', 'product_id': 'BTC-USD', 'changes': [['buy', '38246.10', '0.12000000']], 'time': '2021-05-20T03:56:25.221136Z'}
{'type': 'l2update', 'product_id': 'BTC-USD', 'changes': [['sell', '38382.27', '2.48969908']], 'time': '2021-05-20T03:56:25.223773Z'}
{'type': 'l2update', 'product_id': 'BTC-USD', 'changes': [['buy', '38246.10', '0.09000000']], 'time': '2021-05-20T03:56:25.227028Z'}
{'type': 'l2update', 'product_id': 'BTC-USD', 'changes': [['buy', '38341.54', '0.40270000']], 'time': '2021-05-20T03:56:25.227414Z'}
{'type': 'l2update', 'product_id': 'BTC-USD', 'changes': [['buy', '38246.10', '0.05000000']], 'time': '2021-05-20T03:56:25.231754Z'}
{'type': 'l2update', 'product_id': 'BTC-USD', 'changes': [['buy', '38246.10', '0.00000000']], 'time': '2021-05-20T03:56:25.236924Z'}
{'type': 'l2update', 'product_id': 'BTC-USD', 'changes': [['sell', '38396.78', '0.00000000']], 'time': '2021-05-20T03:56:25.238911Z'}
{'type': 'l2update', 'product_id': 'BTC-USD', 'changes': [['sell', '38555.59', '0.00000000']], 'time': '2021-05-20T03:56:25.239770Z'}
{'type': 'l2update', 'product_id': 'BTC-USD', 'changes': [['sell', '43100.00', '1.29480000']], 'time': '2021-05-20T03:56:25.241094Z'}
{'type': 'l2update', 'product_id': 'BTC-USD', 'changes': [['sell', '38397.26', '0.00000000']], 'time': '2021-05-20T03:56:25.244317Z'}
{'type': 'l2update', 'product_id': 'BTC-USD', 'changes': [['buy', '38360.14', '0.00000000']], 'time': '2021-05-20T03:56:25.244514Z'}
{'type': 'l2update', 'product_id': 'BTC-USD', 'changes': [['buy', '38258.89', '0.01000000']], 'time': '2021-05-20T03:56:25.248201Z'}
{'type': 'l2update', 'product_id': 'BTC-USD', 'changes': [['sell', '38399.98', '0.04915733']], 'time': '2021-05-20T03:56:25.248573Z'}
{'type': 'l2update', 'product_id': 'BTC-USD', 'changes': [['sell', '38541.77', '0.01000000']], 'time': '2021-05-20T03:56:25.252133Z'}
{'type': 'l2update', 'product_id': 'BTC-USD', 'changes': [['sell', '38625.96', '0.00000000']], 'time': '2021-05-20T03:56:25.259678Z'}
{'type': 'l2update', 'product_id': 'BTC-USD', 'changes': [['sell', '38396.77', '0.50000000']], 'time': '2021-05-20T03:56:25.260159Z'}
{'type': 'l2update', 'product_id': 'BTC-USD', 'changes': [['buy', '38258.71', '0.02000000']], 'time': '2021-05-20T03:56:25.260234Z'}
{'type': 'l2update', 'product_id': 'BTC-USD', 'changes': [['buy', '38349.05', '0.06176519']], 'time': '2021-05-20T03:56:25.263565Z'}
{'type': 'l2update', 'product_id': 'BTC-USD', 'changes': [['buy', '38363.44', '0.59116555']], 'time': '2021-05-20T03:56:25.268068Z'}
{'type': 'l2update', 'product_id': 'BTC-USD', 'changes': [['buy', '38258.71', '0.05000000']], 'time': '2021-05-20T03:56:25.271388Z'}
{'type': 'l2update', 'product_id': 'BTC-USD', 'changes': [['sell', '38392.44', '0.00000000']], 'time': '2021-05-20T03:56:25.273042Z'}
{'type': 'l2update', 'product_id': 'BTC-USD', 'changes': [['sell', '38432.97', '0.71562002']], 'time': '2021-05-20T03:56:25.273139Z'}
