{'type': 'l2update', 'product_id': 'BTC-USD', 'changes': [['buy', '38244.06', '0.02400000']], 'time': '2021-05-20T03:54:52.781326Z'}
{'type': 'l2update', 'product_id': 'BTC-USD', 'changes': [['sell', '38392.77', '0.03613936']], 'time': '2021-05-20T03:54:52.805599Z'}
{'type': 'l2update', 'product_id': 'BTC-USD', 'changes': [['sell', '38399.42', '0.03453486']], 'time': '2021-05-20T03:54:52.836840Z'}
{'type': 'l2update', 'product_id': 'BTC-USD', 'changes': [['sell', '38288.25', '0.00000000']], 'time': '2021-05-20T03:54:52.842212Z'}
{'type': 'l2update', 'product_id': 'BTC-USD', 'changes': [['sell', '50848.10', '0.00200000']], 'time': '2021-05-20T03:54:52.857630Z'}
{'type': 'l2update', 'product_id': 'BTC-USD', 'changes': [['sell', '38290.17', '1.10700000']], 'time': '2021-05-20T03:54:52.863068Z'}
{'type': 'l2update', 'product_id': 'BTC-USD', 'changes': [['sell', '38279.85', '0.28994550']], 'time': '2021-05-20T03:54:52.878825Z'}
{'type': 'l2update', 'product_id': 'BTC-USD', 'changes': [['sell', '38290.56', '0.05439796']], 'time': '2021-05-20T03:54:52.882512Z'}
{'type': 'l2update', 'product_id': 'BTC-USD', 'changes': [['sell', '38279.85', '0.28869773']], 'time': '2021-05-20T03:54:52.931214Z'}
{'type': 'l2update', 'product_id': 'BTC-USD', 'changes': [['buy', '38222.55', '0.03041148']], 'time': '2021-05-20T03:54:52.942668Z'}
{'type': 'l2update', 'product_id': 'BTC-USD', 'changes': [['sell', '38294.13', '0.00000000']], 'time': '2021-05-20T03:54:52.948801Z'}
{'type': 'l2update', 'product_id': 'BTC-USD', 'changes': [['sell', '38283.10', '0.52276974']], 'time': '2021-05-20T03:54:52.949662Z'}
{'type': 'l2update', 'product_id': 'BTC-USD', 'changes': [['sell', '38409.35', '0.00000000']], 'time': '2021-05-20T03:54:52.949953Z'}
{'type': 'l2update', 'product_id': 'BTC-USD', 'changes': [['sell', '38284.67', '0.00000000']], 'time': '2021-05-20T03:54:52.956440Z'}
{'type': 'l2update', 'product_id': 'BTC-USD', 'changes': [['buy', '38262.59', '0.52265202']], 'time': '2021-05-20T03:54:52.964390Z'}
{'type': 'l2update', 'product_id': 'BTC-USD', 'changes': [['buy', '38226.55', '0.10000000']], 'time': '2021-05-20T03:54:52.968109Z'}
{'type': 'l2update', 'product_id': 'BTC-USD', 'changes': [['sell', '38435.36', '0.13008854']], 'time': '2021-05-20T03:54:52.968310Z'}
{'type': 'l2update', 'product_id': 'BTC-USD', 'changes': [['sell', '38285.34', '0.52273695']], 'time': '2021-05-20T03:54:52.975534Z'}
{'type': 'l2update', 'product_id': 'BTC-USD', 'changes': [['buy', '38170.92', '0.00000000']], 'time': '2021-05-20T03:54:52.976999Z'}
{'type': 'l2update', 'product_id': 'BTC-USD', 'changes': [['sell', '38283.09', '0.33808528']], 'time': '2021-05-20T03:54:52.979276Z'}
{'type': 'l2update', 'product_id': 'BTC-USD', 'changes': [['sell', '38414.70', '0.00000000']], 'time': '2021-05-20T03:54:52.979571Z'}
{'type': 'l2update', 'product_id': 'BTC-USD', 'changes': [['sell', '38296.56', '0.04201003']], 'time': '2021-05-20T03:54:52.983339Z'}
{'type': 'l2update', 'product_id': 'BTC-USD', 'changes': [['buy', '38258.93', '0.52270137']], 'time': '2021-05-20T03:54:52.986803Z'}
{'type': 'l2update', 'product_id': 'BTC-USD', 'changes': [['sell', '38402.71', '0.03573000']], 'time': '2021-05-20T03:54:52.991363Z'}
{'type': 'l2update', 'product_id': 'BTC-USD', 'changes': [['buy', '38262.64', '0.84700000']], 'time': '2021-05-20T03:54:52.995661Z'}
{'type': 'l2update', 'product_id': 'BTC-USD', 'changes': [['sell', '38287.94', '0.52270137']], 'time': '2021-05-20T03:54:52.995690Z'}
{'type': 'l2update', 'product_id': 'BTC-USD', 'changes': [['buy', '38260.47', '0.00000000']], 'time': '2021-05-20T03:54:53.001825Z'}
{'type': 'l2update', 'product_id': 'BTC-USD', 'changes': [['buy', '38245.66', '0.00000000']], 'time': '2021-05-20T03:54:53.002679Z'}
{'type': 'l2update', 'product_id': 'BTC-USD', 'changes': [['buy', '38244.86', '0.00000000']], 'time': '2021-05-20T03:54:53.002679Z'}
{'type': 'l2update', 'product_id': 'BTC-USD', 'changes': [['buy', '38244.06', '0.00000000']], 'time': '2021-05-20T03:54:53.002679Z'}
{'type': 'l2update', 'product_id': 'BTC-USD', 'changes': [['buy', '38255.06', '0.52275390']], 'time': '2021-05-20T03:54:53.006468Z'}
{'type': 'l2update', 'product_id': 'BTC-USD', 'changes': [['sell', '38284.69', '0.00000000']], 'time': '2021-05-20T03:54:53.010274Z'}
{'type': 'l2update', 'product_id': 'BTC-USD', 'changes': [['sell', '38370.96', '0.00000000']], 'time': '2021-05-20T03:54:53.011870Z'}
{'type': 'l2update', 'product_id': 'BTC-USD', 'changes': [['sell', '38298.35', '1.30692435']], 'time': '2021-05-20T03:54:53.014042Z'}
{'type': 'l2update', 'product_id': 'BTC-USD', 'changes': [['buy', '38249.09', '0.02400000']], 'time': '2021-05-20T03:54:53.017809Z'}
{'type': 'l2update', 'product_id': 'BTC-USD', 'changes': [['buy', '38248.28', '0.02400000']], 'time': '2021-05-20T03:54:53.017809Z'}
{'type': 'l2update', 'product_id': 'BTC-USD', 'changes': [['buy', '38247.47', '0.02400000']], 'time': '2021-05-20T03:54:53.017809Z'}
{'type': 'l2update', 'product_id': 'BTC-USD', 'changes': [['sell', '38389.87', '0.01000000']], 'time': '2021-05-20T03:54:53.021513Z'}
{'type': 'l2update', 'product_id': 'BTC-USD', 'changes': [['buy', '38244.88', '0.78402581']], 'time': '2021-05-20T03:54:53.021536Z'}
{'type': 'l2update', 'product_id': 'BTC-USD', 'changes': [['sell', '50862.64', '0.00114500']], 'time': '2021-05-20T03:54:53.021641Z'}
{'type': 'l2update', 'product_id': 'BTC-USD', 'changes': [['buy', '38260.29', '0.03000000']], 'time': '2021-05-20T03:54:53.027161Z'}
{'type': 'l2update', 'product_id': 'BTC-USD', 'changes': [['buy', '38262.65', '0.25308028']], 'time': '2021-05-20T03:54:53.029491Z'}
{'type': 'l2update', 'product_id': 'BTC-USD', 'changes': [['sell', '38303.19', '1.30675342']], 'time': '2021-05-20T03:54:53.029610Z'}
{'type': 'l2update', 'product_id': 'BTC-USD', 'changes': [['buy', '38249.09', '0.00000000']], 'time': '2021-05-20T03:54:53.033768Z'}
{'type': 'l2update', 'product_id': 'BTC-USD', 'changes': [['buy', '38233.40', '1.30684237']], 'time': '2021-05-20T03:54:53.038212Z'}
{'type': 'l2update', 'product_id': 'BTC-USD', 'changes': [['sell', '38304.74', '0.00000000']], 'time': '2021-05-20T03:54:53.038389Z'}
{'type': 'l2update', 'product_id': 'BTC-USD', 'changes': [['buy', '38248.84', '0.00000000']], 'time': '2021-05-20T03:54:53.040121Z'}
{'type': 'l2update', 'product_id': 'BTC-USD', 'changes': [['buy', '38262.65', '0.84024306']], 'time': '2021-05-20T03:54:53.042281Z'}
{'type': 'l2update', 'product_id': 'BTC-USD', 'changes': [['sell', '38297.76', '0.00000000']], 'time': '2021-05-20T03:54:53.044249Z'}
{'type': 'l2update', 'product_id': 'BTC-USD', 'changes': [['buy', '38246.40', '0.02400000']], 'time': '2021-05-20T03:54:53.046157Z'}
{'type': 'l2update', 'product_id': 'BTC-USD', 'changes': [['buy', '38247.59', '0.00000000']], 'time': '2021-05-20T03:54:53.050579Z'}
{'type': 'l2update', 'product_id': 'BTC-USD', 'changes': [['sell', '38290.56', '0.00000000']], 'time': '2021-05-20T03:54:53.050579Z'}
{'type': 'l2update', 'product_id': 'BTC-USD', 'changes': [['sell', '38321.27', '2.61384870']], 'time': '2021-05-20T03:54:53.051045Z'}
{'type': 'l2update', 'product_id': 'BTC-USD', 'changes': [['sell', '38303.18', '0.05000000']], 'time': '2021-05-20T03:54:53.051077Z'}
{'type': 'l2update', 'product_id': 'BTC-USD', 'changes': [['sell', '38304.75', '0.36000000']], 'time': '2021-05-20T03:54:53.057769Z'}
{'type': 'l2update', 'product_id': 'BTC-USD', 'changes': [['buy', '38224.39', '2.61376949']], 'time': '2021-05-20T03:54:53.061846Z'}
{'type': 'l2update', 'product_id': 'BTC-USD', 'changes': [['sell', '38286.65', '0.00000000']], 'time': '2021-05-20T03:54:53.065633Z'}
{'type': 'l2update', 'product_id': 'BTC-USD', 'changes': [['buy', '38253.94', '0.00000000']], 'time': '2021-05-20T03:54:53.068385Z'}
{'type': 'l2update', 'product_id': 'BTC-USD', 'changes': [['sell', '38402.71', '0.00000000']], 'time': '2021-05-20T03:54:53.071305Z'}
{'type': 'l2update', 'product_id': 'BTC-USD', 'changes': [['sell', '38338.48', '0.00000000']], 'time': '2021-05-20T03:54:53.075106Z'}
{'type': 'l2update', 'product_id': 'BTC-USD', 'changes': [['buy', '38224.38', '2.61376949']], 'time': '2021-05-20T03:54:53.076077Z'}
{'type': 'l2update', 'product_id': 'BTC-USD', 'changes': [['buy', '38255.27', '0.41790000']], 'time': '2021-05-20T03:54:53.077165Z'}
{'type': 'l2update', 'product_id': 'BTC-USD', 'changes': [['buy', '38276.21', '0.05171586']], 'time': '2021-05-20T03:54:53.077196Z'}
{'type': 'l2update', 'product_id': 'BTC-USD', 'changes': [['sell', '38279.85', '0.78869773']], 'time': '2021-05-20T03:54:53.081306Z'}
{'type': 'l2update', 'product_id': 'BTC-USD', 'changes': [['sell', '38369.28', '0.01000000']], 'time': '2021-05-20T03:54:53.081471Z'}
{'type': 'l2update', 'product_id': 'BTC-USD', 'changes': [['buy', '38262.65', '0.58716278']], 'time': '2021-05-20T03:54:53.082564Z'}
{'type': 'l2update', 'product_id': 'BTC-USD', 'changes': [['buy', '38206.58', '0.00000000']], 'time': '2021-05-20T03:54:53.085371Z'}
{'type': 'l2update', 'product_id': 'BTC-USD', 'changes': [['buy', '38244.43', '0.00000000']], 'time': '2021-05-20T03:54:53.086317Z'}
{'type': 'l2update', 'product_id': 'BTC-USD', 'changes': [['buy', '38262.70', '0.52200000']], 'time': '2021-05-20T03:54:53.089221Z'}
{'type': 'l2update', 'product_id': 'BTC-USD', 'changes': [['buy', '38269.66', '0.00000000']], 'time': '2021-05-20T03:54:53.090769Z'}
{'type': 'l2update', 'product_id': 'BTC-USD', 'changes': [['buy', '38249.92', '0.06529851']], 'time': '2021-05-20T03:54:53.093145Z'}
{'type': 'l2update', 'product_id': 'BTC-USD', 'changes': [['sell', '38294.26', '0.04389581']], 'time': '2021-05-20T03:54:53.093145Z'}
{'type': 'l2update', 'product_id': 'BTC-USD', 'changes': [['sell', '38283.09', '0.00000000']], 'time': '2021-05-20T03:54:53.094975Z'}
{'type': 'l2update', 'product_id': 'BTC-USD', 'changes': [['buy', '38255.53', '0.44100000']], 'time': '2021-05-20T03:54:53.095955Z'}
{'type': 'l2update', 'product_id': 'BTC-USD', 'changes': [['sell', '38414.65', '0.00000000']], 'time': '2021-05-20T03:54:53.103290Z'}
{'type': 'l2update', 'product_id': 'BTC-USD', 'changes': [['sell', '38297.17', '0.00000000']], 'time': '2021-05-20T03:54:53.104317Z'}
{'type': 'l2update', 'product_id': 'BTC-USD', 'changes': [['buy', '38262.71', '0.25308028']], 'time': '2021-05-20T03:54:53.104326Z'}
{'type': 'l2update', 'product_id': 'BTC-USD', 'changes': [['sell', '38298.33', '0.00000000']], 'time': '2021-05-20T03:54:53.108846Z'}
{'type': 'l2update', 'product_id': 'BTC-USD', 'changes': [['sell', '38279.85', '0.28869773']], 'time': '2021-05-20T03:54:53.109224Z'}
{'type': 'l2update', 'product_id': 'BTC-USD', 'changes': [['sell', '38428.53', '0.01000000']], 'time': '2021-05-20T03:54:53.118752Z'}
{'type': 'l2update', 'product_id': 'BTC-USD', 'changes': [['sell', '38284.67', '0.33808528']], 'time': '2021-05-20T03:54:53.119457Z'}
{'type': 'l2update', 'product_id': 'BTC-USD', 'changes': [['buy', '38209.50', '0.00000000']], 'time': '2021-05-20T03:54:53.120986Z'}
{'type': 'l2update', 'product_id': 'BTC-USD', 'changes': [['sell', '38303.46', '0.02000000']], 'time': '2021-05-20T03:54:53.121176Z'}
{'type': 'l2update', 'product_id': 'BTC-USD', 'changes': [['sell', '38287.94', '0.00000000']], 'time': '2021-05-20T03:54:53.124034Z'}
{'type': 'l2update', 'product_id': 'BTC-USD', 'changes': [['sell', '38306.00', '0.00000000']], 'time': '2021-05-20T03:54:53.126634Z'}
{'type': 'l2update', 'product_id': 'BTC-USD', 'changes': [['sell', '38283.09', '0.50000000']], 'time': '2021-05-20T03:54:53.126648Z'}
{'type': 'l2update', 'product_id': 'BTC-USD', 'changes': [['sell', '38369.28', '0.00000000']], 'time': '2021-05-20T03:54:53.127034Z'}
{'type': 'l2update', 'product_id': 'BTC-USD', 'changes': [['buy', '38231.45', '0.02615648']], 'time': '2021-05-20T03:54:53.132897Z'}
{'type': 'l2update', 'product_id': 'BTC-USD', 'changes': [['sell', '38304.35', '0.03000000']], 'time': '2021-05-20T03:54:53.132972Z'}
{'type': 'l2update', 'product_id': 'BTC-USD', 'changes': [['sell', '38387.11', '0.00000000']], 'time': '2021-05-20T03:54:53.138842Z'}
{'type': 'l2update', 'product_id': 'BTC-USD', 'changes': [['sell', '38296.56', '0.00000000']], 'time': '2021-05-20T03:54:53.139492Z'}
{'type': 'l2update', 'product_id': 'BTC-USD', 'changes': [['buy', '37469.35', '0.06120000']], 'time': '2021-05-20T03:54:53.139575Z'}
{'type': 'l2update', 'product_id': 'BTC-USD', 'changes': [['sell', '38397.03', '0.05236371']], 'time': '2021-05-20T03:54:53.140336Z'}
{'type': 'l2update', 'product_id': 'BTC-USD', 'changes': [['buy', '37485.34', '0.00010000']], 'time': '2021-05-20T03:54:53.149355Z'}
{'type': 'l2update', 'product_id': 'BTC-USD', 'changes': [['sell', '38279.85', '0.28357818']], 'time': '2021-05-20T03:54:53.149395Z'}
{'type': 'l2update', 'product_id': 'BTC-USD', 'changes': [['buy', '38249.92', '0.00000000']], 'time': '2021-05-20T03:54:53.150667Z'}
{'type': 'l2update', 'product_id': 'BTC-USD', 'changes': [['sell', '38294.26', '0.00000000']], 'time': '2021-05-20T03:54:53.150667Z'}
{'type': 'l2update', 'product_id': 'BTC-USD', 'changes': [['sell', '38374.14', '0.01302960']], 'time': '2021-05-20T03:54:53.153367Z'}
{'type': 'l2update', 'product_id': 'BTC-USD', 'changes': [['buy', '38112.69', '0.05180351']], 'time': '2021-05-20T03:54:53.161985Z'}
{'type': 'l2update', 'product_id': 'BTC-USD', 'changes': [['sell', '38299.02', '0.04201003']], 'time': '2021-05-20T03:54:53.166128Z'}
{'type': 'l2update', 'product_id': 'BTC-USD', 'changes': [['sell', '38286.60', '0.00000000']], 'time': '2021-05-20T03:54:53.182181Z'}
{'type': 'l2update', 'product_id': 'BTC-USD', 'changes': [['sell', '38299.99', '0.00000000']], 'time': '2021-05-20T03:54:53.183914Z'}
{'type': 'l2update', 'product_id': 'BTC-USD', 'changes': [['sell', '38290.45', '0.00000000']], 'time': '2021-05-20T03:54:53.187606Z'}
{'type': 'l2update', 'product_id': 'BTC-USD', 'changes': [['sell', '38284.67', '0.00000000']], 'time': '2021-05-20T03:54:53.190153Z'}
{'type': 'l2update', 'product_id': 'BTC-USD', 'changes': [['sell', '38306.36', '0.44440000']], 'time': '2021-05-20T03:54:53.195913Z'}
{'type': 'l2update', 'product_id': 'BTC-USD', 'changes': [['sell', '38306.36', '0.00000000']], 'time': '2021-05-20T03:54:53.202708Z'}
{'type': 'l2update', 'product_id': 'BTC-USD', 'changes': [['sell', '38283.09', '0.00000000']], 'time': '2021-05-20T03:54:53.204721Z'}
{'type': 'l2update', 'product_id': 'BTC-USD', 'changes': [['sell', '50921.97', '0.00562600']], 'time': '2021-05-20T03:54:53.206403Z'}
{'type': 'l2update', 'product_id': 'BTC-USD', 'changes': [['buy', '38252.34', '0.04050765']], 'time': '2021-05-20T03:54:53.207608Z'}
{'type': 'l2update', 'product_id': 'BTC-USD', 'changes': [['sell', '38293.75', '0.04490599']], 'time': '2021-05-20T03:54:53.207608Z'}
{'type': 'l2update', 'product_id': 'BTC-USD', 'changes': [['sell', '38298.76', '0.00000000']], 'time': '2021-05-20T03:54:53.208536Z'}
{'type': 'l2update', 'product_id': 'BTC-USD', 'changes': [['buy', '37274.48', '0.00000000']], 'time': '2021-05-20T03:54:53.208899Z'}
{'type': 'l2update', 'product_id': 'BTC-USD', 'changes': [['buy', '36365.80', '0.00000000']], 'time': '2021-05-20T03:54:53.208899Z'}
{'type': 'l2update', 'product_id': 'BTC-USD', 'changes': [['sell', '38283.08', '0.33808528']], 'time': '2021-05-20T03:54:53.211671Z'}
{'type': 'l2update', 'product_id': 'BTC-USD', 'changes': [['sell', '43100.00', '1.09530000']], 'time': '2021-05-20T03:54:53.214833Z'}
{'type': 'l2update', 'product_id': 'BTC-USD', 'changes': [['sell', '38451.59', '0.00000000']], 'time': '2021-05-20T03:54:53.215092Z'}
{'type': 'l2update', 'product_id': 'BTC-USD', 'changes': [['sell', '38290.16', '0.50000000']], 'time': '2021-05-20T03:54:53.220212Z'}
{'type': 'l2update', 'product_id': 'BTC-USD', 'changes': [['sell', '38279.85', '0.20671526']], 'time': '2021-05-20T03:54:53.220266Z'}
{'type': 'l2update', 'product_id': 'BTC-USD', 'changes': [['sell', '38291.76', '0.58200000']], 'time': '2021-05-20T03:54:53.220420Z'}
{'type': 'l2update', 'product_id': 'BTC-USD', 'changes': [['sell', '38305.21', '0.01000000']], 'time': '2021-05-20T03:54:53.224291Z'}
{'type': 'l2update', 'product_id': 'BTC-USD', 'changes': [['sell', '38284.68', '0.00000000']], 'time': '2021-05-20T03:54:53.231790Z'}
{'type': 'l2update', 'product_id': 'BTC-USD', 'changes': [['buy', '37293.64', '0.08380000']], 'time': '2021-05-20T03:54:53.232739Z'}
{'type': 'l2update', 'product_id': 'BTC-USD', 'changes': [['buy', '36402.69', '0.11850000']], 'time': '2021-05-20T03:54:53.232739Z'}
{'type': 'l2update', 'product_id': 'BTC-USD', 'changes': [['sell', '38279.85', '0.20000000']], 'time': '2021-05-20T03:54:53.233510Z'}
{'type': 'l2update', 'product_id': 'BTC-USD', 'changes': [['buy', '38108.74', '0.00000000']], 'time': '2021-05-20T03:54:53.237848Z'}
{'type': 'l2update', 'product_id': 'BTC-USD', 'changes': [['sell', '43100.00', '4.27430000']], 'time': '2021-05-20T03:54:53.241059Z'}
{'type': 'l2update', 'product_id': 'BTC-USD', 'changes': [['buy', '38279.84', '0.25000000']], 'time': '2021-05-20T03:54:53.247075Z'}
{'type': 'l2update', 'product_id': 'BTC-USD', 'changes': [['buy', '38252.34', '0.00000000']], 'time': '2021-05-20T03:54:53.252342Z'}
{'type': 'l2update', 'product_id': 'BTC-USD', 'changes': [['sell', '38279.85', '0.00000000']], 'time': '2021-05-20T03:54:53.252548Z'}
{'type': 'l2update', 'product_id': 'BTC-USD', 'changes': [['sell', '38310.49', '0.00000000']], 'time': '2021-05-20T03:54:53.252924Z'}
{'type': 'l2update', 'product_id': 'BTC-USD', 'changes': [['sell', '38290.16', '2.98969908']], 'time': '2021-05-20T03:54:53.255155Z'}
{'type': 'l2update', 'product_id': 'BTC-USD', 'changes': [['sell', '38307.25', '0.00000000']], 'time': '2021-05-20T03:54:53.257379Z'}
{'type': 'l2update', 'product_id': 'BTC-USD', 'changes': [['sell', '38290.22', '0.00000000']], 'time': '2021-05-20T03:54:53.263192Z'}
{'type': 'l2update', 'product_id': 'BTC-USD', 'changes': [['buy', '38223.16', '0.00000000']], 'time': '2021-05-20T03:54:53.265466Z'}
{'type': 'l2update', 'product_id': 'BTC-USD', 'changes': [['buy', '38279.88', '0.02590000']], 'time': '2021-05-20T03:54:53.268986Z'}
{'type': 'l2update', 'product_id': 'BTC-USD', 'changes': [['buy', '38279.88', '0.04795312']], 'time': '2021-05-20T03:54:53.269119Z'}
{'type': 'l2update', 'product_id': 'BTC-USD', 'changes': [['buy', '38279.88', '0.06287312']], 'time': '2021-05-20T03:54:53.269427Z'}
{'type': 'l2update', 'product_id': 'BTC-USD', 'changes': [['sell', '38283.08', '0.00000000']], 'time': '2021-05-20T03:54:53.270220Z'}
{'type': 'l2update', 'product_id': 'BTC-USD', 'changes': [['buy', '38252.00', '0.04719406']], 'time': '2021-05-20T03:54:53.270709Z'}
{'type': 'l2update', 'product_id': 'BTC-USD', 'changes': [['buy', '38253.09', '0.05878580']], 'time': '2021-05-20T03:54:53.273978Z'}
{'type': 'l2update', 'product_id': 'BTC-USD', 'changes': [['buy', '38279.84', '0.10000000']], 'time': '2021-05-20T03:54:53.277555Z'}
{'type': 'l2update', 'product_id': 'BTC-USD', 'changes': [['buy', '38279.84', '0.00000000']], 'time': '2021-05-20T03:54:53.287148Z'}
{'type': 'l2update', 'product_id': 'BTC-USD', 'changes': [['buy', '37469.35', '0.00000000']], 'time': '2021-05-20T03:54:53.288077Z'}
{'type': 'l2update', 'product_id': 'BTC-USD', 'changes': [['sell', '38319.03', '0.00000000']], 'time': '2021-05-20T03:54:53.290395Z'}
{'type': 'l2update', 'product_id': 'BTC-USD', 'changes': [['sell', '38290.15', '0.33808528']], 'time': '2021-05-20T03:54:53.291781Z'}
{'type': 'l2update', 'product_id': 'BTC-USD', 'changes': [['buy', '38236.73', '0.00000000']], 'time': '2021-05-20T03:54:53.294390Z'}
{'type': 'l2update', 'product_id': 'BTC-USD', 'changes': [['buy', '37500.01', '0.19600000']], 'time': '2021-05-20T03:54:53.297664Z'}
{'type': 'l2update', 'product_id': 'BTC-USD', 'changes': [['sell', '38293.06', '0.04841763']], 'time': '2021-05-20T03:54:53.297742Z'}
{'type': 'l2update', 'product_id': 'BTC-USD', 'changes': [['sell', '38304.79', '0.43960000']], 'time': '2021-05-20T03:54:53.297829Z'}
{'type': 'l2update', 'product_id': 'BTC-USD', 'changes': [['sell', '38313.35', '0.05093377']], 'time': '2021-05-20T03:54:53.300669Z'}
{'type': 'l2update', 'product_id': 'BTC-USD', 'changes': [['buy', '38255.27', '0.00000000']], 'time': '2021-05-20T03:54:53.303474Z'}
{'type': 'l2update', 'product_id': 'BTC-USD', 'changes': [['buy', '38222.95', '1.54270000']], 'time': '2021-05-20T03:54:53.311882Z'}
{'type': 'l2update', 'product_id': 'BTC-USD', 'changes': [['buy', '38245.90', '0.46020000']], 'time': '2021-05-20T03:54:53.311962Z'}
{'type': 'l2update', 'product_id': 'BTC-USD', 'changes': [['sell', '38474.08', '0.00000000']], 'time': '2021-05-20T03:54:53.314949Z'}
{'type': 'l2update', 'product_id': 'BTC-USD', 'changes': [['buy', '38245.90', '0.00000000']], 'time': '2021-05-20T03:54:53.316890Z'}
{'type': 'l2update', 'product_id': 'BTC-USD', 'changes': [['buy', '38279.88', '0.03697312']], 'time': '2021-05-20T03:54:53.322533Z'}
{'type': 'l2update', 'product_id': 'BTC-USD', 'changes': [['sell', '38482.04', '0.01000000']], 'time': '2021-05-20T03:54:53.331071Z'}
{'type': 'l2update', 'product_id': 'BTC-USD', 'changes': [['sell', '38285.34', '0.00000000']], 'time': '2021-05-20T03:54:53.332949Z'}
{'type': 'l2update', 'product_id': 'BTC-USD', 'changes': [['buy', '38269.72', '0.84900000']], 'time': '2021-05-20T03:54:53.339748Z'}
{'type': 'l2update', 'product_id': 'BTC-USD', 'changes': [['buy', '38279.88', '0.06287312']], 'time': '2021-05-20T03:54:53.352613Z'}
{'type': 'l2update', 'product_id': 'BTC-USD', 'changes': [['sell', '38387.13', '0.00000000']], 'time': '2021-05-20T03:54:53.376925Z'}
{'type': 'l2update', 'product_id': 'BTC-USD', 'changes': [['sell', '50925.61', '0.00562600']], 'time': '2021-05-20T03:54:53.385263Z'}
{'type': 'l2update', 'product_id': 'BTC-USD', 'changes': [['buy', '37860.00', '0.00000000']], 'time': '2021-05-20T03:54:53.393229Z'}
{'type': 'l2update', 'product_id': 'BTC-USD', 'changes': [['sell', '48800.00', '0.05667388']], 'time': '2021-05-20T03:54:53.393908Z'}
{'type': 'l2update', 'product_id': 'BTC-USD', 'changes': [['sell', '38369.94', '0.01402273']], 'time': '2021-05-20T03:54:53.394278Z'}
{'type': 'l2update', 'product_id': 'BTC-USD', 'changes': [['buy', '38279.88', '0.04082000']], 'time': '2021-05-20T03:54:53.398278Z'}
{'type': 'l2update', 'product_id': 'BTC-USD', 'changes': [['buy', '38279.88', '0.02590000']], 'time': '2021-05-20T03:54:53.398278Z'}
{'type': 'l2update', 'product_id': 'BTC-USD', 'changes': [['buy', '38279.88', '0.00000000']], 'time': '2021-05-20T03:54:53.398278Z'}
{'type': 'l2update', 'product_id': 'BTC-USD', 'changes': [['buy', '38276.21', '0.00000000']], 'time': '2021-05-20T03:54:53.398278Z'}
{'type': 'l2update', 'product_id': 'BTC-USD', 'changes': [['buy', '38275.84', '0.00000000']], 'time': '2021-05-20T03:54:53.398278Z'}
{'type': 'l2update', 'product_id': 'BTC-USD', 'changes': [['buy', '38271.51', '0.00000000']], 'time': '2021-05-20T03:54:53.398278Z'}
{'type': 'l2update', 'product_id': 'BTC-USD', 'changes': [['buy', '38269.72', '0.00000000']], 'time': '2021-05-20T03:54:53.398278Z'}
{'type': 'l2update', 'product_id': 'BTC-USD', 'changes': [['buy', '38269.67', '0.00000000']], 'time': '2021-05-20T03:54:53.398278Z'}
{'type': 'l2update', 'product_id': 'BTC-USD', 'changes': [['buy', '38262.71', '0.00000000']], 'time': '2021-05-20T03:54:53.398278Z'}
{'type': 'l2update', 'product_id': 'BTC-USD', 'changes': [['buy', '38262.70', '0.03494150']], 'time': '2021-05-20T03:54:53.398278Z'}
{'type': 'l2update', 'product_id': 'BTC-USD', 'changes': [['sell', '38290.15', '0.00000000']], 'time': '2021-05-20T03:54:53.405176Z'}
{'type': 'l2update', 'product_id': 'BTC-USD', 'changes': [['buy', '38262.64', '0.00000000']], 'time': '2021-05-20T03:54:53.405322Z'}
{'type': 'l2update', 'product_id': 'BTC-USD', 'changes': [['buy', '38260.40', '0.00000000']], 'time': '2021-05-20T03:54:53.409060Z'}
{'type': 'l2update', 'product_id': 'BTC-USD', 'changes': [['buy', '38245.26', '0.42810000']], 'time': '2021-05-20T03:54:53.412200Z'}
{'type': 'l2update', 'product_id': 'BTC-USD', 'changes': [['buy', '38263.17', '0.07460000']], 'time': '2021-05-20T03:54:53.412243Z'}
{'type': 'l2update', 'product_id': 'BTC-USD', 'changes': [['sell', '38287.98', '0.04826534']], 'time': '2021-05-20T03:54:53.416325Z'}
{'type': 'l2update', 'product_id': 'BTC-USD', 'changes': [['sell', '38279.89', '0.21875240']], 'time': '2021-05-20T03:54:53.416522Z'}
{'type': 'l2update', 'product_id': 'BTC-USD', 'changes': [['sell', '38303.18', '0.00000000']], 'time': '2021-05-20T03:54:53.416751Z'}
{'type': 'l2update', 'product_id': 'BTC-USD', 'changes': [['sell', '38290.14', '0.59116556']], 'time': '2021-05-20T03:54:53.423599Z'}
{'type': 'l2update', 'product_id': 'BTC-USD', 'changes': [['sell', '38293.06', '0.00000000']], 'time': '2021-05-20T03:54:53.428067Z'}
{'type': 'l2update', 'product_id': 'BTC-USD', 'changes': [['sell', '38279.47', '0.04674790']], 'time': '2021-05-20T03:54:53.432384Z'}
{'type': 'l2update', 'product_id': 'BTC-USD', 'changes': [['buy', '38262.72', '0.26100000']], 'time': '2021-05-20T03:54:53.432450Z'}
{'type': 'l2update', 'product_id': 'BTC-USD', 'changes': [['buy', '38253.09', '0.00000000']], 'time': '2021-05-20T03:54:53.433654Z'}
{'type': 'l2update', 'product_id': 'BTC-USD', 'changes': [['sell', '38298.34', '0.05000000']], 'time': '2021-05-20T03:54:53.434337Z'}
{'type': 'l2update', 'product_id': 'BTC-USD', 'changes': [['sell', '38279.47', '0.07460000']], 'time': '2021-05-20T03:54:53.435930Z'}
{'type': 'l2update', 'product_id': 'BTC-USD', 'changes': [['buy', '38244.11', '0.39490431']], 'time': '2021-05-20T03:54:53.436048Z'}
{'type': 'l2update', 'product_id': 'BTC-USD', 'changes': [['buy', '38263.55', '0.01492000']], 'time': '2021-05-20T03:54:53.436931Z'}
{'type': 'l2update', 'product_id': 'BTC-USD', 'changes': [['sell', '38298.34', '0.00000000']], 'time': '2021-05-20T03:54:53.439520Z'}
{'type': 'l2update', 'product_id': 'BTC-USD', 'changes': [['buy', '38263.17', '0.00000000']], 'time': '2021-05-20T03:54:53.442906Z'}
{'type': 'l2update', 'product_id': 'BTC-USD', 'changes': [['sell', '38279.65', '0.01489596']], 'time': '2021-05-20T03:54:53.448178Z'}
{'type': 'l2update', 'product_id': 'BTC-USD', 'changes': [['sell', '38290.14', '0.64116556']], 'time': '2021-05-20T03:54:53.450481Z'}
{'type': 'l2update', 'product_id': 'BTC-USD', 'changes': [['buy', '38184.94', '0.00000000']], 'time': '2021-05-20T03:54:53.450798Z'}
{'type': 'l2update', 'product_id': 'BTC-USD', 'changes': [['sell', '38279.65', '0.00000000']], 'time': '2021-05-20T03:54:53.454793Z'}
{'type': 'l2update', 'product_id': 'BTC-USD', 'changes': [['buy', '38260.29', '0.02000000']], 'time': '2021-05-20T03:54:53.455545Z'}
{'type': 'l2update', 'product_id': 'BTC-USD', 'changes': [['buy', '38258.52', '0.04000000']], 'time': '2021-05-20T03:54:53.455950Z'}
{'type': 'l2update', 'product_id': 'BTC-USD', 'changes': [['sell', '38290.14', '0.59116556']], 'time': '2021-05-20T03:54:53.456556Z'}
{'type': 'l2update', 'product_id': 'BTC-USD', 'changes': [['buy', '38260.29', '0.00000000']], 'time': '2021-05-20T03:54:53.459266Z'}
{'type': 'l2update', 'product_id': 'BTC-USD', 'changes': [['buy', '38257.84', '0.00060000']], 'time': '2021-05-20T03:54:53.459999Z'}
{'type': 'l2update', 'product_id': 'BTC-USD', 'changes': [['buy', '38257.15', '0.00000000']], 'time': '2021-05-20T03:54:53.462597Z'}
{'type': 'l2update', 'product_id': 'BTC-USD', 'changes': [['sell', '38279.89', '0.01875240']], 'time': '2021-05-20T03:54:53.462883Z'}
{'type': 'l2update', 'product_id': 'BTC-USD', 'changes': [['buy', '38254.59', '0.05000000']], 'time': '2021-05-20T03:54:53.466281Z'}
{'type': 'l2update', 'product_id': 'BTC-USD', 'changes': [['sell', '38290.15', '0.05000000']], 'time': '2021-05-20T03:54:53.468472Z'}
{'type': 'l2update', 'product_id': 'BTC-USD', 'changes': [['buy', '38247.33', '0.05445005']], 'time': '2021-05-20T03:54:53.468485Z'}
{'type': 'l2update', 'product_id': 'BTC-USD', 'changes': [['sell', '38287.93', '0.56500000']], 'time': '2021-05-20T03:54:53.468521Z'}
{'type': 'l2update', 'product_id': 'BTC-USD', 'changes': [['buy', '38254.59', '0.00000000']], 'time': '2021-05-20T03:54:53.470720Z'}
{'type': 'l2update', 'product_id': 'BTC-USD', 'changes': [['sell', '38290.15', '0.00000000']], 'time': '2021-05-20T03:54:53.471658Z'}
{'type': 'l2update', 'product_id': 'BTC-USD', 'changes': [['buy', '38164.98', '0.01000000']], 'time': '2021-05-20T03:54:53.472278Z'}
{'type': 'l2update', 'product_id': 'BTC-USD', 'changes': [['buy', '38263.98', '0.07460000']], 'time': '2021-05-20T03:54:53.475855Z'}
{'type': 'l2update', 'product_id': 'BTC-USD', 'changes': [['sell', '38279.11', '0.01492000']], 'time': '2021-05-20T03:54:53.476070Z'}
{'type': 'l2update', 'product_id': 'BTC-USD', 'changes': [['sell', '38490.86', '0.00000000']], 'time': '2021-05-20T03:54:53.478380Z'}
{'type': 'l2update', 'product_id': 'BTC-USD', 'changes': [['sell', '38290.14', '0.00000000']], 'time': '2021-05-20T03:54:53.479060Z'}
{'type': 'l2update', 'product_id': 'BTC-USD', 'changes': [['buy', '38163.42', '0.00000000']], 'time': '2021-05-20T03:54:53.479910Z'}
{'type': 'l2update', 'product_id': 'BTC-USD', 'changes': [['buy', '38240.99', '0.01000000']], 'time': '2021-05-20T03:54:53.481016Z'}
{'type': 'l2update', 'product_id': 'BTC-USD', 'changes': [['sell', '38290.13', '0.05000000']], 'time': '2021-05-20T03:54:53.481026Z'}
{'type': 'l2update', 'product_id': 'BTC-USD', 'changes': [['sell', '38279.47', '0.02785210']], 'time': '2021-05-20T03:54:53.482454Z'}
{'type': 'l2update', 'product_id': 'BTC-USD', 'changes': [['sell', '38397.03', '0.00000000']], 'time': '2021-05-20T03:54:53.483012Z'}
{'type': 'l2update', 'product_id': 'BTC-USD', 'changes': [['buy', '38263.55', '0.00000000']], 'time': '2021-05-20T03:54:53.483313Z'}
{'type': 'l2update', 'product_id': 'BTC-USD', 'changes': [['sell', '38279.47', '0.00000000']], 'time': '2021-05-20T03:54:53.483329Z'}
{'type': 'l2update', 'product_id': 'BTC-USD', 'changes': [['sell', '38279.11', '0.00000000']], 'time': '2021-05-20T03:54:53.484262Z'}
{'type': 'l2update', 'product_id': 'BTC-USD', 'changes': [['buy', '38258.52', '0.00000000']], 'time': '2021-05-20T03:54:53.486202Z'}
{'type': 'l2update', 'product_id': 'BTC-USD', 'changes': [['sell', '38290.13', '0.00000000']], 'time': '2021-05-20T03:54:53.488638Z'}
{'type': 'l2update', 'product_id': 'BTC-USD', 'changes': [['buy', '38263.98', '0.00000000']], 'time': '2021-05-20T03:54:53.490130Z'}
{'type': 'l2update', 'product_id': 'BTC-USD', 'changes': [['sell', '38503.30', '0.00649295']], 'time': '2021-05-20T03:54:53.492811Z'}
{'type': 'l2update', 'product_id': 'BTC-USD', 'changes': [['buy', '38175.35', '0.01000000']], 'time': '2021-05-20T03:54:53.492904Z'}
{'type': 'l2update', 'product_id': 'BTC-USD', 'changes': [['sell', '38299.02', '0.00000000']], 'time': '2021-05-20T03:54:53.494468Z'}
{'type': 'l2update', 'product_id': 'BTC-USD', 'changes': [['buy', '38164.98', '0.00000000']], 'time': '2021-05-20T03:54:53.496245Z'}
{'type': 'l2update', 'product_id': 'BTC-USD', 'changes': [['buy', '38264.49', '0.01492000']], 'time': '2021-05-20T03:54:53.497083Z'}
{'type': 'l2update', 'product_id': 'BTC-USD', 'changes': [['sell', '38279.43', '0.07460000']], 'time': '2021-05-20T03:54:53.497147Z'}
{'type': 'l2update', 'product_id': 'BTC-USD', 'changes': [['sell', '38287.92', '0.59116556']], 'time': '2021-05-20T03:54:53.497179Z'}
{'type': 'l2update', 'product_id': 'BTC-USD', 'changes': [['buy', '38264.49', '0.00000000']], 'time': '2021-05-20T03:54:53.502816Z'}
{'type': 'l2update', 'product_id': 'BTC-USD', 'changes': [['buy', '38153.43', '0.03364745']], 'time': '2021-05-20T03:54:53.503719Z'}
{'type': 'l2update', 'product_id': 'BTC-USD', 'changes': [['sell', '38384.42', '0.03573000']], 'time': '2021-05-20T03:54:53.503855Z'}
{'type': 'l2update', 'product_id': 'BTC-USD', 'changes': [['buy', '38263.18', '0.07460000']], 'time': '2021-05-20T03:54:53.503876Z'}
{'type': 'l2update', 'product_id': 'BTC-USD', 'changes': [['buy', '38190.00', '0.19720000']], 'time': '2021-05-20T03:54:53.503900Z'}
{'type': 'l2update', 'product_id': 'BTC-USD', 'changes': [['sell', '38287.92', '0.64116556']], 'time': '2021-05-20T03:54:53.503912Z'}
{'type': 'l2update', 'product_id': 'BTC-USD', 'changes': [['buy', '38217.08', '0.00000000']], 'time': '2021-05-20T03:54:53.509145Z'}
{'type': 'l2update', 'product_id': 'BTC-USD', 'changes': [['buy', '38263.18', '0.00000000']], 'time': '2021-05-20T03:54:53.509433Z'}
{'type': 'l2update', 'product_id': 'BTC-USD', 'changes': [['sell', '38410.85', '0.00000000']], 'time': '2021-05-20T03:54:53.510595Z'}
{'type': 'l2update', 'product_id': 'BTC-USD', 'changes': [['buy', '38263.13', '0.01492000']], 'time': '2021-05-20T03:54:53.515811Z'}
{'type': 'l2update', 'product_id': 'BTC-USD', 'changes': [['buy', '38263.21', '0.07460000']], 'time': '2021-05-20T03:54:53.518952Z'}
{'type': 'l2update', 'product_id': 'BTC-USD', 'changes': [['sell', '38278.75', '0.00870205']], 'time': '2021-05-20T03:54:53.520443Z'}
{'type': 'l2update', 'product_id': 'BTC-USD', 'changes': [['sell', '38301.54', '0.04201003']], 'time': '2021-05-20T03:54:53.520600Z'}
{'type': 'l2update', 'product_id': 'BTC-USD', 'changes': [['buy', '38263.13', '0.00000000']], 'time': '2021-05-20T03:54:53.522147Z'}
{'type': 'l2update', 'product_id': 'BTC-USD', 'changes': [['sell', '38278.75', '0.01492000']], 'time': '2021-05-20T03:54:53.527444Z'}
{'type': 'l2update', 'product_id': 'BTC-USD', 'changes': [['sell', '38279.43', '0.00000000']], 'time': '2021-05-20T03:54:53.535244Z'}
{'type': 'l2update', 'product_id': 'BTC-USD', 'changes': [['sell', '38396.22', '0.01000000']], 'time': '2021-05-20T03:54:53.535317Z'}
{'type': 'l2update', 'product_id': 'BTC-USD', 'changes': [['buy', '38226.55', '0.00000000']], 'time': '2021-05-20T03:54:53.539951Z'}
{'type': 'l2update', 'product_id': 'BTC-USD', 'changes': [['sell', '38290.16', '2.48969908']], 'time': '2021-05-20T03:54:53.540169Z'}
{'type': 'l2update', 'product_id': 'BTC-USD', 'changes': [['buy', '38263.75', '0.01492000']], 'time': '2021-05-20T03:54:53.543569Z'}
{'type': 'l2update', 'product_id': 'BTC-USD', 'changes': [['buy', '38263.21', '0.00000000']], 'time': '2021-05-20T03:54:53.549303Z'}
{'type': 'l2update', 'product_id': 'BTC-USD', 'changes': [['sell', '38278.19', '0.07460000']], 'time': '2021-05-20T03:54:53.550769Z'}
{'type': 'l2update', 'product_id': 'BTC-USD', 'changes': [['buy', '38225.55', '0.10000000']], 'time': '2021-05-20T03:54:53.550930Z'}
{'type': 'l2update', 'product_id': 'BTC-USD', 'changes': [['sell', '50929.25', '0.00562600']], 'time': '2021-05-20T03:54:53.551097Z'}
{'type': 'l2update', 'product_id': 'BTC-USD', 'changes': [['sell', '38287.92', '0.05000000']], 'time': '2021-05-20T03:54:53.551338Z'}
{'type': 'l2update', 'product_id': 'BTC-USD', 'changes': [['sell', '38283.09', '0.50000000']], 'time': '2021-05-20T03:54:53.556551Z'}
{'type': 'l2update', 'product_id': 'BTC-USD', 'changes': [['sell', '38278.75', '0.00870205']], 'time': '2021-05-20T03:54:53.556787Z'}
{'type': 'l2update', 'product_id': 'BTC-USD', 'changes': [['sell', '38278.75', '0.00000000']], 'time': '2021-05-20T03:54:53.561761Z'}
{'type': 'l2update', 'product_id': 'BTC-USD', 'changes': [['buy', '38264.43', '0.07460000']], 'time': '2021-05-20T03:54:53.565488Z'}
{'type': 'l2update', 'product_id': 'BTC-USD', 'changes': [['sell', '38278.19', '0.00000000']], 'time': '2021-05-20T03:54:53.570328Z'}
{'type': 'l2update', 'product_id': 'BTC-USD', 'changes': [['buy', '38263.75', '0.00000000']], 'time': '2021-05-20T03:54:53.571298Z'}
{'type': 'l2update', 'product_id': 'BTC-USD', 'changes': [['sell', '38283.08', '0.59116556']], 'time': '2021-05-20T03:54:53.571652Z'}
{'type': 'l2update', 'product_id': 'BTC-USD', 'changes': [['sell', '38279.24', '0.07460000']], 'time': '2021-05-20T03:54:53.583005Z'}
{'type': 'l2update', 'product_id': 'BTC-USD', 'changes': [['sell', '38277.54', '0.00382608']], 'time': '2021-05-20T03:54:53.583085Z'}
{'type': 'l2update', 'product_id': 'BTC-USD', 'changes': [['sell', '38279.43', '0.01109392']], 'time': '2021-05-20T03:54:53.586933Z'}
{'type': 'l2update', 'product_id': 'BTC-USD', 'changes': [['sell', '38277.54', '0.00000000']], 'time': '2021-05-20T03:54:53.588449Z'}
{'type': 'l2update', 'product_id': 'BTC-USD', 'changes': [['buy', '38264.43', '0.00000000']], 'time': '2021-05-20T03:54:53.588826Z'}
{'type': 'l2update', 'product_id': 'BTC-USD', 'changes': [['buy', '38245.26', '0.00000000']], 'time': '2021-05-20T03:54:53.589983Z'}
{'type': 'l2update', 'product_id': 'BTC-USD', 'changes': [['sell', '38279.43', '0.00000000']], 'time': '2021-05-20T03:54:53.592138Z'}
{'type': 'l2update', 'product_id': 'BTC-USD', 'changes': [['sell', '38700.00', '0.40651820']], 'time': '2021-05-20T03:54:53.594574Z'}
{'type': 'l2update', 'product_id': 'BTC-USD', 'changes': [['buy', '38264.68', '0.01492000']], 'time': '2021-05-20T03:54:53.594702Z'}
{'type': 'l2update', 'product_id': 'BTC-USD', 'changes': [['buy', '38254.70', '0.41360000']], 'time': '2021-05-20T03:54:53.598687Z'}
{'type': 'l2update', 'product_id': 'BTC-USD', 'changes': [['buy', '38263.23', '0.07460000']], 'time': '2021-05-20T03:54:53.598708Z'}
{'type': 'l2update', 'product_id': 'BTC-USD', 'changes': [['buy', '38264.68', '0.00000000']], 'time': '2021-05-20T03:54:53.600178Z'}
{'type': 'l2update', 'product_id': 'BTC-USD', 'changes': [['sell', '38278.58', '0.00382608']], 'time': '2021-05-20T03:54:53.602749Z'}
{'type': 'l2update', 'product_id': 'BTC-USD', 'changes': [['buy', '38263.23', '0.00000000']], 'time': '2021-05-20T03:54:53.604288Z'}
{'type': 'l2update', 'product_id': 'BTC-USD', 'changes': [['buy', '38254.70', '0.00000000']], 'time': '2021-05-20T03:54:53.604595Z'}
{'type': 'l2update', 'product_id': 'BTC-USD', 'changes': [['buy', '38264.73', '0.52200000']], 'time': '2021-05-20T03:54:53.610088Z'}
{'type': 'l2update', 'product_id': 'BTC-USD', 'changes': [['sell', '38278.58', '0.01223791']], 'time': '2021-05-20T03:54:53.610113Z'}
{'type': 'l2update', 'product_id': 'BTC-USD', 'changes': [['sell', '38278.58', '0.00841183']], 'time': '2021-05-20T03:54:53.613412Z'}
{'type': 'l2update', 'product_id': 'BTC-USD', 'changes': [['buy', '38262.70', '0.00000000']], 'time': '2021-05-20T03:54:53.613744Z'}
{'type': 'l2update', 'product_id': 'BTC-USD', 'changes': [['buy', '38263.10', '0.07460000']], 'time': '2021-05-20T03:54:53.614107Z'}
{'type': 'l2update', 'product_id': 'BTC-USD', 'changes': [['sell', '38324.89', '0.22500000']], 'time': '2021-05-20T03:54:53.614187Z'}
{'type': 'l2update', 'product_id': 'BTC-USD', 'changes': [['buy', '38260.46', '0.00000000']], 'time': '2021-05-20T03:54:53.614231Z'}
{'type': 'l2update', 'product_id': 'BTC-USD', 'changes': [['sell', '38278.79', '0.00268209']], 'time': '2021-05-20T03:54:53.614245Z'}
{'type': 'l2update', 'product_id': 'BTC-USD', 'changes': [['buy', '38263.50', '0.01492000']], 'time': '2021-05-20T03:54:53.614358Z'}
{'type': 'l2update', 'product_id': 'BTC-USD', 'changes': [['sell', '38278.58', '0.00000000']], 'time': '2021-05-20T03:54:53.616118Z'}
{'type': 'l2update', 'product_id': 'BTC-USD', 'changes': [['sell', '38279.24', '0.00000000']], 'time': '2021-05-20T03:54:53.616790Z'}
{'type': 'l2update', 'product_id': 'BTC-USD', 'changes': [['buy', '38264.73', '0.00000000']], 'time': '2021-05-20T03:54:53.618311Z'}
{'type': 'l2update', 'product_id': 'BTC-USD', 'changes': [['buy', '38263.10', '0.00000000']], 'time': '2021-05-20T03:54:53.619087Z'}
{'type': 'l2update', 'product_id': 'BTC-USD', 'changes': [['buy', '38263.50', '0.00000000']], 'time': '2021-05-20T03:54:53.619564Z'}
{'type': 'l2update', 'product_id': 'BTC-USD', 'changes': [['buy', '38247.33', '0.00000000']], 'time': '2021-05-20T03:54:53.623333Z'}
{'type': 'l2update', 'product_id': 'BTC-USD', 'changes': [['sell', '38330.65', '0.00000000']], 'time': '2021-05-20T03:54:53.627341Z'}
{'type': 'l2update', 'product_id': 'BTC-USD', 'changes': [['buy', '38183.08', '0.50000000']], 'time': '2021-05-20T03:54:53.630360Z'}
{'type': 'l2update', 'product_id': 'BTC-USD', 'changes': [['sell', '38278.79', '0.00650817']], 'time': '2021-05-20T03:54:53.630376Z'}
{'type': 'l2update', 'product_id': 'BTC-USD', 'changes': [['buy', '38263.91', '0.07460000']], 'time': '2021-05-20T03:54:53.630465Z'}
{'type': 'l2update', 'product_id': 'BTC-USD', 'changes': [['sell', '38278.79', '0.00268209']], 'time': '2021-05-20T03:54:53.635899Z'}
{'type': 'l2update', 'product_id': 'BTC-USD', 'changes': [['buy', '38246.40', '0.00000000']], 'time': '2021-05-20T03:54:53.637685Z'}
{'type': 'l2update', 'product_id': 'BTC-USD', 'changes': [['buy', '38264.27', '0.01492000']], 'time': '2021-05-20T03:54:53.642580Z'}
{'type': 'l2update', 'product_id': 'BTC-USD', 'changes': [['sell', '38278.79', '0.01109392']], 'time': '2021-05-20T03:54:53.642665Z'}
{'type': 'l2update', 'product_id': 'BTC-USD', 'changes': [['buy', '38248.28', '0.00000000']], 'time': '2021-05-20T03:54:53.642862Z'}
{'type': 'l2update', 'product_id': 'BTC-USD', 'changes': [['buy', '38247.47', '0.00000000']], 'time': '2021-05-20T03:54:53.642862Z'}
{'type': 'l2update', 'product_id': 'BTC-USD', 'changes': [['sell', '38279.62', '0.07460000']], 'time': '2021-05-20T03:54:53.642954Z'}
{'type': 'l2update', 'product_id': 'BTC-USD', 'changes': [['buy', '38245.39', '0.00000000']], 'time': '2021-05-20T03:54:53.644629Z'}
{'type': 'l2update', 'product_id': 'BTC-USD', 'changes': [['sell', '38278.79', '0.00841183']], 'time': '2021-05-20T03:54:53.648096Z'}
{'type': 'l2update', 'product_id': 'BTC-USD', 'changes': [['sell', '38380.22', '0.00000000']], 'time': '2021-05-20T03:54:53.648235Z'}
{'type': 'l2update', 'product_id': 'BTC-USD', 'changes': [['sell', '38278.79', '0.00000000']], 'time': '2021-05-20T03:54:53.648430Z'}
{'type': 'l2update', 'product_id': 'BTC-USD', 'changes': [['buy', '38263.91', '0.00000000']], 'time': '2021-05-20T03:54:53.648580Z'}
{'type': 'l2update', 'product_id': 'BTC-USD', 'changes': [['sell', '38279.62', '0.00000000']], 'time': '2021-05-20T03:54:53.648603Z'}
{'type': 'l2update', 'product_id': 'BTC-USD', 'changes': [['sell', '38290.16', '0.00000000']], 'time': '2021-05-20T03:54:53.651408Z'}
{'type': 'l2update', 'product_id': 'BTC-USD', 'changes': [['buy', '38264.27', '0.00000000']], 'time': '2021-05-20T03:54:53.655076Z'}
{'type': 'l2update', 'product_id': 'BTC-USD', 'changes': [['sell', '38293.75', '0.00000000']], 'time': '2021-05-20T03:54:53.656626Z'}
{'type': 'l2update', 'product_id': 'BTC-USD', 'changes': [['sell', '38279.41', '0.00382608']], 'time': '2021-05-20T03:54:53.658788Z'}
{'type': 'l2update', 'product_id': 'BTC-USD', 'changes': [['buy', '38264.70', '0.06924740']], 'time': '2021-05-20T03:54:53.658820Z'}
{'type': 'l2update', 'product_id': 'BTC-USD', 'changes': [['buy', '38253.94', '0.02400000']], 'time': '2021-05-20T03:54:53.659963Z'}
{'type': 'l2update', 'product_id': 'BTC-USD', 'changes': [['buy', '38253.14', '0.02400000']], 'time': '2021-05-20T03:54:53.659963Z'}
{'type': 'l2update', 'product_id': 'BTC-USD', 'changes': [['buy', '38252.33', '0.02400000']], 'time': '2021-05-20T03:54:53.659963Z'}
{'type': 'l2update', 'product_id': 'BTC-USD', 'changes': [['buy', '38262.65', '0.00000000']], 'time': '2021-05-20T03:54:53.661655Z'}
{'type': 'l2update', 'product_id': 'BTC-USD', 'changes': [['buy', '38278.79', '0.01492235']], 'time': '2021-05-20T03:54:53.662968Z'}
{'type': 'l2update', 'product_id': 'BTC-USD', 'changes': [['buy', '38264.70', '0.00000000']], 'time': '2021-05-20T03:54:53.663657Z'}
{'type': 'l2update', 'product_id': 'BTC-USD', 'changes': [['sell', '38279.41', '0.01492000']], 'time': '2021-05-20T03:54:53.666798Z'}
{'type': 'l2update', 'product_id': 'BTC-USD', 'changes': [['sell', '38279.48', '0.07460000']], 'time': '2021-05-20T03:54:53.666961Z'}
{'type': 'l2update', 'product_id': 'BTC-USD', 'changes': [['sell', '38279.41', '0.01109392']], 'time': '2021-05-20T03:54:53.669185Z'}
{'type': 'l2update', 'product_id': 'BTC-USD', 'changes': [['buy', '38244.11', '0.00000000']], 'time': '2021-05-20T03:54:53.670640Z'}
{'type': 'l2update', 'product_id': 'BTC-USD', 'changes': [['sell', '38287.92', '0.00000000']], 'time': '2021-05-20T03:54:53.671874Z'}
{'type': 'l2update', 'product_id': 'BTC-USD', 'changes': [['sell', '38279.48', '0.00000000']], 'time': '2021-05-20T03:54:53.671905Z'}
{'type': 'l2update', 'product_id': 'BTC-USD', 'changes': [['buy', '38262.97', '0.00535260']], 'time': '2021-05-20T03:54:53.672092Z'}
{'type': 'l2update', 'product_id': 'BTC-USD', 'changes': [['sell', '38279.88', '2.48969908']], 'time': '2021-05-20T03:54:53.672295Z'}
{'type': 'l2update', 'product_id': 'BTC-USD', 'changes': [['sell', '38279.41', '0.00000000']], 'time': '2021-05-20T03:54:53.673171Z'}
{'type': 'l2update', 'product_id': 'BTC-USD', 'changes': [['buy', '38262.97', '0.00000000']], 'time': '2021-05-20T03:54:53.677148Z'}
{'type': 'l2update', 'product_id': 'BTC-USD', 'changes': [['sell', '38278.80', '0.10000000']], 'time': '2021-05-20T03:54:53.677952Z'}
{'type': 'l2update', 'product_id': 'BTC-USD', 'changes': [['sell', '38283.08', '0.00000000']], 'time': '2021-05-20T03:54:53.679963Z'}
{'type': 'l2update', 'product_id': 'BTC-USD', 'changes': [['buy', '38253.94', '0.00000000']], 'time': '2021-05-20T03:54:53.680337Z'}
{'type': 'l2update', 'product_id': 'BTC-USD', 'changes': [['buy', '38253.14', '0.00000000']], 'time': '2021-05-20T03:54:53.680337Z'}
{'type': 'l2update', 'product_id': 'BTC-USD', 'changes': [['buy', '38252.33', '0.00000000']], 'time': '2021-05-20T03:54:53.680337Z'}
{'type': 'l2update', 'product_id': 'BTC-USD', 'changes': [['buy', '38262.98', '0.01492000']], 'time': '2021-05-20T03:54:53.681276Z'}
{'type': 'l2update', 'product_id': 'BTC-USD', 'changes': [['sell', '38303.18', '0.05000000']], 'time': '2021-05-20T03:54:53.685542Z'}
{'type': 'l2update', 'product_id': 'BTC-USD', 'changes': [['buy', '38260.24', '0.58716278']], 'time': '2021-05-20T03:54:53.685843Z'}
{'type': 'l2update', 'product_id': 'BTC-USD', 'changes': [['sell', '38283.09', '0.00000000']], 'time': '2021-05-20T03:54:53.688238Z'}
{'type': 'l2update', 'product_id': 'BTC-USD', 'changes': [['sell', '38278.80', '0.11492000']], 'time': '2021-05-20T03:54:53.689018Z'}
{'type': 'l2update', 'product_id': 'BTC-USD', 'changes': [['sell', '38284.13', '0.00600000']], 'time': '2021-05-20T03:54:53.689083Z'}
{'type': 'l2update', 'product_id': 'BTC-USD', 'changes': [['sell', '38278.80', '0.11367223']], 'time': '2021-05-20T03:54:53.689157Z'}
{'type': 'l2update', 'product_id': 'BTC-USD', 'changes': [['sell', '38278.80', '0.18827223']], 'time': '2021-05-20T03:54:53.689174Z'}
{'type': 'l2update', 'product_id': 'BTC-USD', 'changes': [['buy', '38262.98', '0.00000000']], 'time': '2021-05-20T03:54:53.693368Z'}
{'type': 'l2update', 'product_id': 'BTC-USD', 'changes': [['sell', '38428.53', '0.00000000']], 'time': '2021-05-20T03:54:53.693675Z'}
{'type': 'l2update', 'product_id': 'BTC-USD', 'changes': [['buy', '38254.70', '0.49840000']], 'time': '2021-05-20T03:54:53.695416Z'}
{'type': 'l2update', 'product_id': 'BTC-USD', 'changes': [['buy', '38250.51', '0.02400000']], 'time': '2021-05-20T03:54:53.695513Z'}
{'type': 'l2update', 'product_id': 'BTC-USD', 'changes': [['buy', '38249.71', '0.02400000']], 'time': '2021-05-20T03:54:53.695513Z'}
{'type': 'l2update', 'product_id': 'BTC-USD', 'changes': [['buy', '38248.90', '0.02400000']], 'time': '2021-05-20T03:54:53.695513Z'}
{'type': 'l2update', 'product_id': 'BTC-USD', 'changes': [['sell', '38278.80', '0.83827223']], 'time': '2021-05-20T03:54:53.696042Z'}
{'type': 'l2update', 'product_id': 'BTC-USD', 'changes': [['sell', '38279.41', '0.20000000']], 'time': '2021-05-20T03:54:53.696145Z'}
{'type': 'l2update', 'product_id': 'BTC-USD', 'changes': [['sell', '38279.87', '0.50000000']], 'time': '2021-05-20T03:54:53.704576Z'}
{'type': 'l2update', 'product_id': 'BTC-USD', 'changes': [['sell', '38279.87', '1.09116556']], 'time': '2021-05-20T03:54:53.704678Z'}
{'type': 'l2update', 'product_id': 'BTC-USD', 'changes': [['sell', '38410.66', '0.01491192']], 'time': '2021-05-20T03:54:53.716447Z'}
{'type': 'l2update', 'product_id': 'BTC-USD', 'changes': [['sell', '38278.80', '0.18827223']], 'time': '2021-05-20T03:54:53.716710Z'}
{'type': 'l2update', 'product_id': 'BTC-USD', 'changes': [['sell', '38305.21', '0.00000000']], 'time': '2021-05-20T03:54:53.718161Z'}
{'type': 'l2update', 'product_id': 'BTC-USD', 'changes': [['sell', '38279.41', '0.00000000']], 'time': '2021-05-20T03:54:53.719586Z'}
{'type': 'l2update', 'product_id': 'BTC-USD', 'changes': [['buy', '38260.24', '0.00000000']], 'time': '2021-05-20T03:54:53.722653Z'}
{'type': 'l2update', 'product_id': 'BTC-USD', 'changes': [['sell', '50932.89', '0.00392200']], 'time': '2021-05-20T03:54:53.729320Z'}
{'type': 'l2update', 'product_id': 'BTC-USD', 'changes': [['buy', '38240.77', '0.02000000']], 'time': '2021-05-20T03:54:53.729337Z'}
{'type': 'l2update', 'product_id': 'BTC-USD', 'changes': [['buy', '38260.28', '0.52100000']], 'time': '2021-05-20T03:54:53.733730Z'}
{'type': 'l2update', 'product_id': 'BTC-USD', 'changes': [['buy', '38258.94', '0.58716278']], 'time': '2021-05-20T03:54:53.733749Z'}
{'type': 'l2update', 'product_id': 'BTC-USD', 'changes': [['buy', '38227.67', '0.03000000']], 'time': '2021-05-20T03:54:53.740621Z'}
{'type': 'l2update', 'product_id': 'BTC-USD', 'changes': [['buy', '38226.06', '0.04000000']], 'time': '2021-05-20T03:54:53.752988Z'}
{'type': 'l2update', 'product_id': 'BTC-USD', 'changes': [['sell', '38278.80', '0.19400223']], 'time': '2021-05-20T03:54:53.756495Z'}
{'type': 'l2update', 'product_id': 'BTC-USD', 'changes': [['buy', '38246.55', '0.05424660']], 'time': '2021-05-20T03:54:53.760203Z'}
{'type': 'l2update', 'product_id': 'BTC-USD', 'changes': [['sell', '38290.78', '0.04289544']], 'time': '2021-05-20T03:54:53.760203Z'}
{'type': 'l2update', 'product_id': 'BTC-USD', 'changes': [['buy', '38219.27', '0.05000000']], 'time': '2021-05-20T03:54:53.764059Z'}
{'type': 'l2update', 'product_id': 'BTC-USD', 'changes': [['sell', '38279.87', '0.50000000']], 'time': '2021-05-20T03:54:53.767056Z'}
{'type': 'l2update', 'product_id': 'BTC-USD', 'changes': [['sell', '38298.77', '0.01000000']], 'time': '2021-05-20T03:54:53.775660Z'}
{'type': 'l2update', 'product_id': 'BTC-USD', 'changes': [['sell', '38279.88', '0.00000000']], 'time': '2021-05-20T03:54:53.779318Z'}
{'type': 'l2update', 'product_id': 'BTC-USD', 'changes': [['buy', '38278.79', '0.16492235']], 'time': '2021-05-20T03:54:53.783919Z'}
{'type': 'l2update', 'product_id': 'BTC-USD', 'changes': [['sell', '38700.00', '0.52504407']], 'time': '2021-05-20T03:54:53.784135Z'}
{'type': 'l2update', 'product_id': 'BTC-USD', 'changes': [['sell', '38279.86', '0.59116556']], 'time': '2021-05-20T03:54:53.788949Z'}
{'type': 'l2update', 'product_id': 'BTC-USD', 'changes': [['sell', '38279.87', '0.00000000']], 'time': '2021-05-20T03:54:53.792132Z'}
{'type': 'l2update', 'product_id': 'BTC-USD', 'changes': [['sell', '38283.09', '2.48969908']], 'time': '2021-05-20T03:54:53.793668Z'}
{'type': 'l2update', 'product_id': 'BTC-USD', 'changes': [['sell', '38321.26', '0.66794213']], 'time': '2021-05-20T03:54:53.797340Z'}
{'type': 'l2update', 'product_id': 'BTC-USD', 'changes': [['sell', '38283.09', '2.98969908']], 'time': '2021-05-20T03:54:53.805448Z'}
{'type': 'l2update', 'product_id': 'BTC-USD', 'changes': [['sell', '38435.36', '0.00000000']], 'time': '2021-05-20T03:54:53.813172Z'}
{'type': 'l2update', 'product_id': 'BTC-USD', 'changes': [['sell', '38290.78', '0.00000000']], 'time': '2021-05-20T03:54:53.818133Z'}
{'type': 'l2update', 'product_id': 'BTC-USD', 'changes': [['sell', '38415.85', '0.06526520']], 'time': '2021-05-20T03:54:53.826052Z'}
{'type': 'l2update', 'product_id': 'BTC-USD', 'changes': [['buy', '38245.49', '2.37600000']], 'time': '2021-05-20T03:54:53.826304Z'}
{'type': 'l2update', 'product_id': 'BTC-USD', 'changes': [['sell', '38304.79', '0.00000000']], 'time': '2021-05-20T03:54:53.828449Z'}
{'type': 'l2update', 'product_id': 'BTC-USD', 'changes': [['buy', '38262.72', '0.26276524']], 'time': '2021-05-20T03:54:53.829412Z'}
{'type': 'l2update', 'product_id': 'BTC-USD', 'changes': [['sell', '38303.56', '0.41910000']], 'time': '2021-05-20T03:54:53.837434Z'}
{'type': 'l2update', 'product_id': 'BTC-USD', 'changes': [['sell', '38380.32', '0.02400000']], 'time': '2021-05-20T03:54:53.837453Z'}
{'type': 'l2update', 'product_id': 'BTC-USD', 'changes': [['sell', '38293.28', '0.05708114']], 'time': '2021-05-20T03:54:53.840986Z'}
{'type': 'l2update', 'product_id': 'BTC-USD', 'changes': [['sell', '38279.86', '0.00000000']], 'time': '2021-05-20T03:54:53.846101Z'}
{'type': 'l2update', 'product_id': 'BTC-USD', 'changes': [['buy', '38195.17', '0.00000000']], 'time': '2021-05-20T03:54:53.854576Z'}
{'type': 'l2update', 'product_id': 'BTC-USD', 'changes': [['sell', '38304.75', '0.04000000']], 'time': '2021-05-20T03:54:53.854576Z'}
{'type': 'l2update', 'product_id': 'BTC-USD', 'changes': [['sell', '38279.89', '0.00000000']], 'time': '2021-05-20T03:54:53.858114Z'}
{'type': 'l2update', 'product_id': 'BTC-USD', 'changes': [['buy', '38220.02', '0.00000000']], 'time': '2021-05-20T03:54:53.858114Z'}
{'type': 'l2update', 'product_id': 'BTC-USD', 'changes': [['sell', '38283.08', '0.59116556']], 'time': '2021-05-20T03:54:53.869118Z'}
{'type': 'l2update', 'product_id': 'BTC-USD', 'changes': [['buy', '38246.55', '0.00000000']], 'time': '2021-05-20T03:54:53.881786Z'}
{'type': 'l2update', 'product_id': 'BTC-USD', 'changes': [['sell', '38293.28', '0.00000000']], 'time': '2021-05-20T03:54:53.881786Z'}
{'type': 'l2update', 'product_id': 'BTC-USD', 'changes': [['sell', '38284.08', '0.54700000']], 'time': '2021-05-20T03:54:53.882255Z'}
{'type': 'l2update', 'product_id': 'BTC-USD', 'changes': [['sell', '38431.77', '0.00000000']], 'time': '2021-05-20T03:54:53.891952Z'}
{'type': 'l2update', 'product_id': 'BTC-USD', 'changes': [['sell', '50932.89', '0.00562600']], 'time': '2021-05-20T03:54:53.894834Z'}
{'type': 'l2update', 'product_id': 'BTC-USD', 'changes': [['buy', '38240.99', '0.00000000']], 'time': '2021-05-20T03:54:53.900530Z'}
{'type': 'l2update', 'product_id': 'BTC-USD', 'changes': [['sell', '38418.90', '0.01000000']], 'time': '2021-05-20T03:54:53.903527Z'}
{'type': 'l2update', 'product_id': 'BTC-USD', 'changes': [['sell', '38283.09', '2.48969908']], 'time': '2021-05-20T03:54:53.905013Z'}
{'type': 'l2update', 'product_id': 'BTC-USD', 'changes': [['buy', '38240.77', '0.00000000']], 'time': '2021-05-20T03:54:53.905747Z'}
{'type': 'l2update', 'product_id': 'BTC-USD', 'changes': [['sell', '38325.31', '0.32000000']], 'time': '2021-05-20T03:54:53.907265Z'}
{'type': 'l2update', 'product_id': 'BTC-USD', 'changes': [['buy', '38215.84', '0.32000000']], 'time': '2021-05-20T03:54:53.907265Z'}
{'type': 'l2update', 'product_id': 'BTC-USD', 'changes': [['buy', '38227.67', '0.00000000']], 'time': '2021-05-20T03:54:53.909358Z'}
{'type': 'l2update', 'product_id': 'BTC-USD', 'changes': [['buy', '38246.80', '0.03967345']], 'time': '2021-05-20T03:54:53.911467Z'}
{'type': 'l2update', 'product_id': 'BTC-USD', 'changes': [['sell', '38291.30', '0.04445690']], 'time': '2021-05-20T03:54:53.911467Z'}
{'type': 'l2update', 'product_id': 'BTC-USD', 'changes': [['buy', '38226.06', '0.00000000']], 'time': '2021-05-20T03:54:53.914286Z'}
{'type': 'l2update', 'product_id': 'BTC-USD', 'changes': [['buy', '38219.27', '0.00000000']], 'time': '2021-05-20T03:54:53.917888Z'}
{'type': 'l2update', 'product_id': 'BTC-USD', 'changes': [['sell', '38278.80', '0.69400223']], 'time': '2021-05-20T03:54:53.919831Z'}
{'type': 'l2update', 'product_id': 'BTC-USD', 'changes': [['sell', '38300.44', '0.02000000']], 'time': '2021-05-20T03:54:53.919842Z'}
{'type': 'l2update', 'product_id': 'BTC-USD', 'changes': [['buy', '38240.71', '0.02000000']], 'time': '2021-05-20T03:54:53.919842Z'}
{'type': 'l2update', 'product_id': 'BTC-USD', 'changes': [['buy', '38222.95', '0.00000000']], 'time': '2021-05-20T03:54:53.924706Z'}
{'type': 'l2update', 'product_id': 'BTC-USD', 'changes': [['buy', '38256.89', '0.01000000']], 'time': '2021-05-20T03:54:53.928025Z'}
{'type': 'l2update', 'product_id': 'BTC-USD', 'changes': [['buy', '38256.89', '0.03000000']], 'time': '2021-05-20T03:54:53.940331Z'}
{'type': 'l2update', 'product_id': 'BTC-USD', 'changes': [['sell', '38301.54', '0.00000000']], 'time': '2021-05-20T03:54:53.940831Z'}
{'type': 'l2update', 'product_id': 'BTC-USD', 'changes': [['buy', '38254.70', '0.00000000']], 'time': '2021-05-20T03:54:53.945986Z'}
{'type': 'l2update', 'product_id': 'BTC-USD', 'changes': [['buy', '38246.80', '0.00000000']], 'time': '2021-05-20T03:54:53.948579Z'}
{'type': 'l2update', 'product_id': 'BTC-USD', 'changes': [['buy', '38256.89', '0.06000000']], 'time': '2021-05-20T03:54:53.952266Z'}
{'type': 'l2update', 'product_id': 'BTC-USD', 'changes': [['buy', '38251.64', '0.44930000']], 'time': '2021-05-20T03:54:53.956250Z'}
{'type': 'l2update', 'product_id': 'BTC-USD', 'changes': [['buy', '38238.61', '0.05398493']], 'time': '2021-05-20T03:54:53.960441Z'}
{'type': 'l2update', 'product_id': 'BTC-USD', 'changes': [['buy', '38251.64', '0.00000000']], 'time': '2021-05-20T03:54:53.961589Z'}
{'type': 'l2update', 'product_id': 'BTC-USD', 'changes': [['buy', '38245.49', '0.00000000']], 'time': '2021-05-20T03:54:53.962759Z'}
{'type': 'l2update', 'product_id': 'BTC-USD', 'changes': [['sell', '38307.87', '0.04953177']], 'time': '2021-05-20T03:54:53.964546Z'}
{'type': 'l2update', 'product_id': 'BTC-USD', 'changes': [['buy', '38256.89', '0.10000000']], 'time': '2021-05-20T03:54:53.964906Z'}
{'type': 'l2update', 'product_id': 'BTC-USD', 'changes': [['sell', '38380.32', '0.00000000']], 'time': '2021-05-20T03:54:53.966443Z'}
{'type': 'l2update', 'product_id': 'BTC-USD', 'changes': [['sell', '38298.94', '0.04201003']], 'time': '2021-05-20T03:54:53.968788Z'}
{'type': 'l2update', 'product_id': 'BTC-USD', 'changes': [['buy', '37310.65', '0.04190000']], 'time': '2021-05-20T03:54:53.973606Z'}
{'type': 'l2update', 'product_id': 'BTC-USD', 'changes': [['buy', '36436.28', '0.05920000']], 'time': '2021-05-20T03:54:53.973606Z'}
{'type': 'l2update', 'product_id': 'BTC-USD', 'changes': [['buy', '38256.89', '0.15000000']], 'time': '2021-05-20T03:54:53.977045Z'}
{'type': 'l2update', 'product_id': 'BTC-USD', 'changes': [['buy', '38156.42', '0.01000000']], 'time': '2021-05-20T03:54:53.981551Z'}
{'type': 'l2update', 'product_id': 'BTC-USD', 'changes': [['sell', '38436.26', '0.00000000']], 'time': '2021-05-20T03:54:53.985691Z'}
{'type': 'l2update', 'product_id': 'BTC-USD', 'changes': [['sell', '38304.75', '0.00000000']], 'time': '2021-05-20T03:54:54.004486Z'}
{'type': 'l2update', 'product_id': 'BTC-USD', 'changes': [['sell', '38418.53', '0.01000000']], 'time': '2021-05-20T03:54:54.009062Z'}
{'type': 'l2update', 'product_id': 'BTC-USD', 'changes': [['sell', '38298.77', '0.05000000']], 'time': '2021-05-20T03:54:54.016651Z'}
{'type': 'l2update', 'product_id': 'BTC-USD', 'changes': [['sell', '38313.35', '0.00000000']], 'time': '2021-05-20T03:54:54.017204Z'}
{'type': 'l2update', 'product_id': 'BTC-USD', 'changes': [['sell', '38410.62', '0.00000000']], 'time': '2021-05-20T03:54:54.031577Z'}
{'type': 'l2update', 'product_id': 'BTC-USD', 'changes': [['sell', '38298.94', '0.00000000']], 'time': '2021-05-20T03:54:54.040929Z'}
{'type': 'l2update', 'product_id': 'BTC-USD', 'changes': [['sell', '50936.54', '0.00562600']], 'time': '2021-05-20T03:54:54.049636Z'}
{'type': 'l2update', 'product_id': 'BTC-USD', 'changes': [['sell', '38287.93', '1.68100000']], 'time': '2021-05-20T03:54:54.049753Z'}
{'type': 'l2update', 'product_id': 'BTC-USD', 'changes': [['buy', '38249.91', '0.46920000']], 'time': '2021-05-20T03:54:54.053586Z'}
{'type': 'l2update', 'product_id': 'BTC-USD', 'changes': [['buy', '38262.72', '0.26100000']], 'time': '2021-05-20T03:54:54.060084Z'}
{'type': 'l2update', 'product_id': 'BTC-USD', 'changes': [['buy', '38238.61', '0.00000000']], 'time': '2021-05-20T03:54:54.062826Z'}
{'type': 'l2update', 'product_id': 'BTC-USD', 'changes': [['sell', '38293.73', '0.04201003']], 'time': '2021-05-20T03:54:54.070097Z'}
{'type': 'l2update', 'product_id': 'BTC-USD', 'changes': [['buy', '37549.81', '0.00000000']], 'time': '2021-05-20T03:54:54.070641Z'}
{'type': 'l2update', 'product_id': 'BTC-USD', 'changes': [['buy', '36916.46', '0.00000000']], 'time': '2021-05-20T03:54:54.070641Z'}
{'type': 'l2update', 'product_id': 'BTC-USD', 'changes': [['sell', '38324.08', '0.00000000']], 'time': '2021-05-20T03:54:54.073470Z'}
{'type': 'l2update', 'product_id': 'BTC-USD', 'changes': [['buy', '38183.08', '0.00000000']], 'time': '2021-05-20T03:54:54.078414Z'}
{'type': 'l2update', 'product_id': 'BTC-USD', 'changes': [['buy', '38262.59', '0.00000000']], 'time': '2021-05-20T03:54:54.090317Z'}
{'type': 'l2update', 'product_id': 'BTC-USD', 'changes': [['buy', '38239.67', '0.03948544']], 'time': '2021-05-20T03:54:54.091501Z'}
{'type': 'l2update', 'product_id': 'BTC-USD', 'changes': [['sell', '38291.30', '0.00000000']], 'time': '2021-05-20T03:54:54.100010Z'}
{'type': 'l2update', 'product_id': 'BTC-USD', 'changes': [['sell', '38280.18', '0.52270473']], 'time': '2021-05-20T03:54:54.107521Z'}
{'type': 'l2update', 'product_id': 'BTC-USD', 'changes': [['buy', '38250.95', '0.52270473']], 'time': '2021-05-20T03:54:54.120395Z'}
{'type': 'l2update', 'product_id': 'BTC-USD', 'changes': [['buy', '38245.49', '2.37600000']], 'time': '2021-05-20T03:54:54.128342Z'}
{'type': 'l2update', 'product_id': 'BTC-USD', 'changes': [['sell', '38278.80', '0.69296252']], 'time': '2021-05-20T03:54:54.128361Z'}
{'type': 'l2update', 'product_id': 'BTC-USD', 'changes': [['sell', '38287.84', '0.52265171']], 'time': '2021-05-20T03:54:54.128396Z'}
{'type': 'l2update', 'product_id': 'BTC-USD', 'changes': [['sell', '38290.67', '0.05677869']], 'time': '2021-05-20T03:54:54.128460Z'}
{'type': 'l2update', 'product_id': 'BTC-USD', 'changes': [['buy', '38258.94', '0.00000000']], 'time': '2021-05-20T03:54:54.133920Z'}
{'type': 'l2update', 'product_id': 'BTC-USD', 'changes': [['sell', '38303.56', '0.00000000']], 'time': '2021-05-20T03:54:54.134668Z'}
{'type': 'l2update', 'product_id': 'BTC-USD', 'changes': [['buy', '38256.14', '0.00000000']], 'time': '2021-05-20T03:54:54.136103Z'}
{'type': 'l2update', 'product_id': 'BTC-USD', 'changes': [['sell', '38330.96', '2.61317354']], 'time': '2021-05-20T03:54:54.140377Z'}
{'type': 'l2update', 'product_id': 'BTC-USD', 'changes': [['sell', '38380.32', '0.02400000']], 'time': '2021-05-20T03:54:54.140443Z'}
{'type': 'l2update', 'product_id': 'BTC-USD', 'changes': [['buy', '38112.69', '0.00000000']], 'time': '2021-05-20T03:54:54.141868Z'}
{'type': 'l2update', 'product_id': 'BTC-USD', 'changes': [['buy', '38245.49', '0.00000000']], 'time': '2021-05-20T03:54:54.145763Z'}
{'type': 'l2update', 'product_id': 'BTC-USD', 'changes': [['sell', '38302.12', '0.44120000']], 'time': '2021-05-20T03:54:54.148428Z'}
{'type': 'l2update', 'product_id': 'BTC-USD', 'changes': [['buy', '38270.97', '0.05165113']], 'time': '2021-05-20T03:54:54.148601Z'}
{'type': 'l2update', 'product_id': 'BTC-USD', 'changes': [['buy', '38239.67', '0.00000000']], 'time': '2021-05-20T03:54:54.149775Z'}
{'type': 'l2update', 'product_id': 'BTC-USD', 'changes': [['sell', '38380.32', '0.00000000']], 'time': '2021-05-20T03:54:54.149990Z'}
{'type': 'l2update', 'product_id': 'BTC-USD', 'changes': [['buy', '38260.29', '0.58716278']], 'time': '2021-05-20T03:54:54.152424Z'}
{'type': 'l2update', 'product_id': 'BTC-USD', 'changes': [['buy', '38205.27', '1.61730000']], 'time': '2021-05-20T03:54:54.152535Z'}
{'type': 'l2update', 'product_id': 'BTC-USD', 'changes': [['sell', '38303.18', '0.00000000']], 'time': '2021-05-20T03:54:54.154726Z'}
{'type': 'l2update', 'product_id': 'BTC-USD', 'changes': [['buy', '38278.79', '0.01492235']], 'time': '2021-05-20T03:54:54.163987Z'}
{'type': 'l2update', 'product_id': 'BTC-USD', 'changes': [['buy', '38262.77', '0.52100000']], 'time': '2021-05-20T03:54:54.164970Z'}
{'type': 'l2update', 'product_id': 'BTC-USD', 'changes': [['sell', '38302.11', '0.05000000']], 'time': '2021-05-20T03:54:54.165054Z'}
{'type': 'l2update', 'product_id': 'BTC-USD', 'changes': [['buy', '38246.11', '0.06430658']], 'time': '2021-05-20T03:54:54.177364Z'}
{'type': 'l2update', 'product_id': 'BTC-USD', 'changes': [['sell', '38290.67', '0.05959236']], 'time': '2021-05-20T03:54:54.177364Z'}
{'type': 'l2update', 'product_id': 'BTC-USD', 'changes': [['sell', '38315.66', '0.49519680']], 'time': '2021-05-20T03:54:54.182283Z'}
{'type': 'l2update', 'product_id': 'BTC-USD', 'changes': [['sell', '38418.53', '0.00000000']], 'time': '2021-05-20T03:54:54.188578Z'}
{'type': 'l2update', 'product_id': 'BTC-USD', 'changes': [['buy', '38249.91', '0.00000000']], 'time': '2021-05-20T03:54:54.194142Z'}
{'type': 'l2update', 'product_id': 'BTC-USD', 'changes': [['sell', '38396.20', '0.01000000']], 'time': '2021-05-20T03:54:54.199768Z'}
{'type': 'l2update', 'product_id': 'BTC-USD', 'changes': [['buy', '38190.00', '0.00000000']], 'time': '2021-05-20T03:54:54.199937Z'}
{'type': 'l2update', 'product_id': 'BTC-USD', 'changes': [['buy', '38245.61', '0.48050000']], 'time': '2021-05-20T03:54:54.204073Z'}
{'type': 'l2update', 'product_id': 'BTC-USD', 'changes': [['buy', '37500.01', '0.18570000']], 'time': '2021-05-20T03:54:54.204878Z'}
{'type': 'l2update', 'product_id': 'BTC-USD', 'changes': [['sell', '39443.99', '0.00000000']], 'time': '2021-05-20T03:54:54.204878Z'}
{'type': 'l2update', 'product_id': 'BTC-USD', 'changes': [['buy', '38245.61', '0.00000000']], 'time': '2021-05-20T03:54:54.209423Z'}
{'type': 'l2update', 'product_id': 'BTC-USD', 'changes': [['sell', '39249.99', '0.10910000']], 'time': '2021-05-20T03:54:54.211624Z'}
{'type': 'l2update', 'product_id': 'BTC-USD', 'changes': [['buy', '37500.01', '0.19600000']], 'time': '2021-05-20T03:54:54.211624Z'}
{'type': 'l2update', 'product_id': 'BTC-USD', 'changes': [['sell', '38302.12', '0.00000000']], 'time': '2021-05-20T03:54:54.214343Z'}
{'type': 'l2update', 'product_id': 'BTC-USD', 'changes': [['sell', '43100.00', '1.09530000']], 'time': '2021-05-20T03:54:54.215107Z'}
{'type': 'l2update', 'product_id': 'BTC-USD', 'changes': [['buy', '38225.55', '0.00000000']], 'time': '2021-05-20T03:54:54.217912Z'}
{'type': 'l2update', 'product_id': 'BTC-USD', 'changes': [['sell', '50943.82', '0.00562600']], 'time': '2021-05-20T03:54:54.222237Z'}
{'type': 'l2update', 'product_id': 'BTC-USD', 'changes': [['sell', '38283.09', '0.00000000']], 'time': '2021-05-20T03:54:54.222605Z'}
{'type': 'l2update', 'product_id': 'BTC-USD', 'changes': [['buy', '38222.55', '0.13041148']], 'time': '2021-05-20T03:54:54.225910Z'}
{'type': 'l2update', 'product_id': 'BTC-USD', 'changes': [['sell', '38384.42', '0.00000000']], 'time': '2021-05-20T03:54:54.233007Z'}
{'type': 'l2update', 'product_id': 'BTC-USD', 'changes': [['buy', '38246.11', '0.00000000']], 'time': '2021-05-20T03:54:54.234814Z'}
{'type': 'l2update', 'product_id': 'BTC-USD', 'changes': [['sell', '38290.67', '0.05677869']], 'time': '2021-05-20T03:54:54.234814Z'}
{'type': 'l2update', 'product_id': 'BTC-USD', 'changes': [['sell', '38290.67', '0.00000000']], 'time': '2021-05-20T03:54:54.234814Z'}
{'type': 'l2update', 'product_id': 'BTC-USD', 'changes': [['sell', '43100.00', '3.65240000']], 'time': '2021-05-20T03:54:54.238502Z'}
{'type': 'l2update', 'product_id': 'BTC-USD', 'changes': [['sell', '38370.54', '0.01000000']], 'time': '2021-05-20T03:54:54.242132Z'}
{'type': 'l2update', 'product_id': 'BTC-USD', 'changes': [['sell', '38278.80', '3.18266160']], 'time': '2021-05-20T03:54:54.245598Z'}
{'type': 'l2update', 'product_id': 'BTC-USD', 'changes': [['buy', '38252.01', '0.03326262']], 'time': '2021-05-20T03:54:54.257283Z'}
{'type': 'l2update', 'product_id': 'BTC-USD', 'changes': [['buy', '38107.33', '0.05035762']], 'time': '2021-05-20T03:54:54.257939Z'}
{'type': 'l2update', 'product_id': 'BTC-USD', 'changes': [['sell', '38278.80', '3.21866160']], 'time': '2021-05-20T03:54:54.273518Z'}
{'type': 'l2update', 'product_id': 'BTC-USD', 'changes': [['buy', '38270.97', '0.00000000']], 'time': '2021-05-20T03:54:54.274634Z'}
{'type': 'l2update', 'product_id': 'BTC-USD', 'changes': [['sell', '38284.08', '1.59300000']], 'time': '2021-05-20T03:54:54.277856Z'}
{'type': 'l2update', 'product_id': 'BTC-USD', 'changes': [['sell', '38281.40', '0.05190770']], 'time': '2021-05-20T03:54:54.282509Z'}
{'type': 'l2update', 'product_id': 'BTC-USD', 'changes': [['buy', '38260.29', '0.00000000']], 'time': '2021-05-20T03:54:54.283782Z'}
{'type': 'l2update', 'product_id': 'BTC-USD', 'changes': [['buy', '38278.79', '0.00000000']], 'time': '2021-05-20T03:54:54.290600Z'}
{'type': 'l2update', 'product_id': 'BTC-USD', 'changes': [['buy', '38250.51', '0.00000000']], 'time': '2021-05-20T03:54:54.290949Z'}
{'type': 'l2update', 'product_id': 'BTC-USD', 'changes': [['sell', '38278.80', '3.14406160']], 'time': '2021-05-20T03:54:54.296594Z'}
{'type': 'l2update', 'product_id': 'BTC-USD', 'changes': [['sell', '38283.08', '0.00000000']], 'time': '2021-05-20T03:54:54.297512Z'}
{'type': 'l2update', 'product_id': 'BTC-USD', 'changes': [['buy', '38246.26', '0.42600000']], 'time': '2021-05-20T03:54:54.298026Z'}
{'type': 'l2update', 'product_id': 'BTC-USD', 'changes': [['sell', '38278.80', '3.12914160']], 'time': '2021-05-20T03:54:54.298145Z'}
{'type': 'l2update', 'product_id': 'BTC-USD', 'changes': [['sell', '38278.80', '3.12341160']], 'time': '2021-05-20T03:54:54.298351Z'}
{'type': 'l2update', 'product_id': 'BTC-USD', 'changes': [['sell', '38302.11', '0.00000000']], 'time': '2021-05-20T03:54:54.299612Z'}
{'type': 'l2update', 'product_id': 'BTC-USD', 'changes': [['sell', '38287.98', '0.00000000']], 'time': '2021-05-20T03:54:54.299662Z'}
{'type': 'l2update', 'product_id': 'BTC-USD', 'changes': [['buy', '38252.01', '0.00000000']], 'time': '2021-05-20T03:54:54.299811Z'}
{'type': 'l2update', 'product_id': 'BTC-USD', 'changes': [['sell', '38503.30', '0.00000000']], 'time': '2021-05-20T03:54:54.300994Z'}
{'type': 'l2update', 'product_id': 'BTC-USD', 'changes': [['sell', '38278.79', '0.65000000']], 'time': '2021-05-20T03:54:54.302724Z'}
{'type': 'l2update', 'product_id': 'BTC-USD', 'changes': [['buy', '38247.37', '0.02400000']], 'time': '2021-05-20T03:54:54.307808Z'}
{'type': 'l2update', 'product_id': 'BTC-USD', 'changes': [['buy', '38258.94', '0.58716278']], 'time': '2021-05-20T03:54:54.308009Z'}
{'type': 'l2update', 'product_id': 'BTC-USD', 'changes': [['sell', '38304.34', '0.15900000']], 'time': '2021-05-20T03:54:54.308030Z'}
{'type': 'l2update', 'product_id': 'BTC-USD', 'changes': [['sell', '38278.80', '3.02569908']], 'time': '2021-05-20T03:54:54.309413Z'}
{'type': 'l2update', 'product_id': 'BTC-USD', 'changes': [['buy', '38250.01', '0.03326262']], 'time': '2021-05-20T03:54:54.311601Z'}
{'type': 'l2update', 'product_id': 'BTC-USD', 'changes': [['sell', '38305.40', '0.39490432']], 'time': '2021-05-20T03:54:54.311687Z'}
{'type': 'l2update', 'product_id': 'BTC-USD', 'changes': [['sell', '38522.44', '0.01000000']], 'time': '2021-05-20T03:54:54.311721Z'}
{'type': 'l2update', 'product_id': 'BTC-USD', 'changes': [['sell', '38287.83', '0.05000000']], 'time': '2021-05-20T03:54:54.311739Z'}
{'type': 'l2update', 'product_id': 'BTC-USD', 'changes': [['buy', '38235.31', '1.20000000']], 'time': '2021-05-20T03:54:54.311788Z'}
{'type': 'l2update', 'product_id': 'BTC-USD', 'changes': [['buy', '38263.13', '0.01492000']], 'time': '2021-05-20T03:54:54.311803Z'}
{'type': 'l2update', 'product_id': 'BTC-USD', 'changes': [['sell', '38305.61', '0.40940000']], 'time': '2021-05-20T03:54:54.314322Z'}
{'type': 'l2update', 'product_id': 'BTC-USD', 'changes': [['buy', '38263.78', '0.04907372']], 'time': '2021-05-20T03:54:54.314449Z'}
{'type': 'l2update', 'product_id': 'BTC-USD', 'changes': [['sell', '38278.53', '0.07460000']], 'time': '2021-05-20T03:54:54.314693Z'}
{'type': 'l2update', 'product_id': 'BTC-USD', 'changes': [['sell', '38482.04', '0.00000000']], 'time': '2021-05-20T03:54:54.316787Z'}
{'type': 'l2update', 'product_id': 'BTC-USD', 'changes': [['sell', '38278.78', '0.59116556']], 'time': '2021-05-20T03:54:54.320811Z'}
{'type': 'l2update', 'product_id': 'BTC-USD', 'changes': [['buy', '38263.13', '0.00000000']], 'time': '2021-05-20T03:54:54.321646Z'}
{'type': 'l2update', 'product_id': 'BTC-USD', 'changes': [['sell', '38278.29', '0.01492000']], 'time': '2021-05-20T03:54:54.322307Z'}
{'type': 'l2update', 'product_id': 'BTC-USD', 'changes': [['sell', '38370.15', '1.20000000']], 'time': '2021-05-20T03:54:54.322378Z'}
{'type': 'l2update', 'product_id': 'BTC-USD', 'changes': [['buy', '38238.29', '0.39490431']], 'time': '2021-05-20T03:54:54.322402Z'}
{'type': 'l2update', 'product_id': 'BTC-USD', 'changes': [['buy', '37200.00', '0.27361278']], 'time': '2021-05-20T03:54:54.322472Z'}
{'type': 'l2update', 'product_id': 'BTC-USD', 'changes': [['sell', '38469.76', '0.01000000']], 'time': '2021-05-20T03:54:54.327947Z'}
{'type': 'l2update', 'product_id': 'BTC-USD', 'changes': [['buy', '38252.00', '0.00000000']], 'time': '2021-05-20T03:54:54.328030Z'}
{'type': 'l2update', 'product_id': 'BTC-USD', 'changes': [['sell', '38278.53', '0.00000000']], 'time': '2021-05-20T03:54:54.329867Z'}
{'type': 'l2update', 'product_id': 'BTC-USD', 'changes': [['buy', '38250.01', '0.00000000']], 'time': '2021-05-20T03:54:54.331320Z'}
{'type': 'l2update', 'product_id': 'BTC-USD', 'changes': [['buy', '38175.35', '0.00000000']], 'time': '2021-05-20T03:54:54.332371Z'}
{'type': 'l2update', 'product_id': 'BTC-USD', 'changes': [['sell', '38410.29', '0.01000000']], 'time': '2021-05-20T03:54:54.332379Z'}
{'type': 'l2update', 'product_id': 'BTC-USD', 'changes': [['buy', '38264.06', '0.01492000']], 'time': '2021-05-20T03:54:54.336171Z'}
{'type': 'l2update', 'product_id': 'BTC-USD', 'changes': [['buy', '38114.98', '0.00000000']], 'time': '2021-05-20T03:54:54.344114Z'}
{'type': 'l2update', 'product_id': 'BTC-USD', 'changes': [['buy', '38239.95', '0.03326262']], 'time': '2021-05-20T03:54:54.346946Z'}
{'type': 'l2update', 'product_id': 'BTC-USD', 'changes': [['sell', '38277.70', '0.07460000']], 'time': '2021-05-20T03:54:54.347048Z'}
{'type': 'l2update', 'product_id': 'BTC-USD', 'changes': [['buy', '38163.42', '0.03577500']], 'time': '2021-05-20T03:54:54.347078Z'}
{'type': 'l2update', 'product_id': 'BTC-USD', 'changes': [['buy', '38246.26', '0.00000000']], 'time': '2021-05-20T03:54:54.349108Z'}
{'type': 'l2update', 'product_id': 'BTC-USD', 'changes': [['sell', '38278.29', '0.00000000']], 'time': '2021-05-20T03:54:54.354150Z'}
{'type': 'l2update', 'product_id': 'BTC-USD', 'changes': [['sell', '38277.70', '0.00000000']], 'time': '2021-05-20T03:54:54.361096Z'}
{'type': 'l2update', 'product_id': 'BTC-USD', 'changes': [['sell', '38303.40', '0.04889647']], 'time': '2021-05-20T03:54:54.368466Z'}
{'type': 'l2update', 'product_id': 'BTC-USD', 'changes': [['buy', '38256.89', '0.14000000']], 'time': '2021-05-20T03:54:54.375502Z'}
{'type': 'l2update', 'product_id': 'BTC-USD', 'changes': [['sell', '38522.44', '0.00000000']], 'time': '2021-05-20T03:54:54.375812Z'}
{'type': 'l2update', 'product_id': 'BTC-USD', 'changes': [['sell', '38278.18', '0.01492000']], 'time': '2021-05-20T03:54:54.377179Z'}
{'type': 'l2update', 'product_id': 'BTC-USD', 'changes': [['sell', '38278.21', '0.07460000']], 'time': '2021-05-20T03:54:54.377255Z'}
{'type': 'l2update', 'product_id': 'BTC-USD', 'changes': [['buy', '38256.89', '0.12000000']], 'time': '2021-05-20T03:54:54.379549Z'}
{'type': 'l2update', 'product_id': 'BTC-USD', 'changes': [['sell', '38278.21', '0.00000000']], 'time': '2021-05-20T03:54:54.383664Z'}
{'type': 'l2update', 'product_id': 'BTC-USD', 'changes': [['buy', '38256.89', '0.09000000']], 'time': '2021-05-20T03:54:54.385488Z'}
{'type': 'l2update', 'product_id': 'BTC-USD', 'changes': [['buy', '38129.15', '0.80355629']], 'time': '2021-05-20T03:54:54.386387Z'}
{'type': 'l2update', 'product_id': 'BTC-USD', 'changes': [['sell', '38503.30', '0.00649295']], 'time': '2021-05-20T03:54:54.387092Z'}
{'type': 'l2update', 'product_id': 'BTC-USD', 'changes': [['sell', '38307.87', '0.00000000']], 'time': '2021-05-20T03:54:54.387453Z'}
{'type': 'l2update', 'product_id': 'BTC-USD', 'changes': [['buy', '38256.89', '0.05000000']], 'time': '2021-05-20T03:54:54.389012Z'}
{'type': 'l2update', 'product_id': 'BTC-USD', 'changes': [['buy', '38156.42', '0.00000000']], 'time': '2021-05-20T03:54:54.393199Z'}
{'type': 'l2update', 'product_id': 'BTC-USD', 'changes': [['buy', '38256.89', '0.00000000']], 'time': '2021-05-20T03:54:54.394993Z'}
{'type': 'l2update', 'product_id': 'BTC-USD', 'changes': [['sell', '50954.74', '0.00582200']], 'time': '2021-05-20T03:54:54.399978Z'}
{'type': 'l2update', 'product_id': 'BTC-USD', 'changes': [['buy', '38169.73', '0.01000000']], 'time': '2021-05-20T03:54:54.403880Z'}
{'type': 'l2update', 'product_id': 'BTC-USD', 'changes': [['buy', '38226.85', '0.01000000']], 'time': '2021-05-20T03:54:54.403938Z'}
{'type': 'l2update', 'product_id': 'BTC-USD', 'changes': [['sell', '38277.75', '0.07460000']], 'time': '2021-05-20T03:54:54.407399Z'}
{'type': 'l2update', 'product_id': 'BTC-USD', 'changes': [['buy', '38235.60', '0.00000000']], 'time': '2021-05-20T03:54:54.412288Z'}
{'type': 'l2update', 'product_id': 'BTC-USD', 'changes': [['sell', '38278.18', '0.00000000']], 'time': '2021-05-20T03:54:54.413950Z'}
{'type': 'l2update', 'product_id': 'BTC-USD', 'changes': [['buy', '38226.18', '0.02000000']], 'time': '2021-05-20T03:54:54.415891Z'}
{'type': 'l2update', 'product_id': 'BTC-USD', 'changes': [['buy', '38265.99', '0.15000000']], 'time': '2021-05-20T03:54:54.419085Z'}
{'type': 'l2update', 'product_id': 'BTC-USD', 'changes': [['sell', '38305.61', '0.00000000']], 'time': '2021-05-20T03:54:54.420436Z'}
{'type': 'l2update', 'product_id': 'BTC-USD', 'changes': [['buy', '38258.94', '0.00000000']], 'time': '2021-05-20T03:54:54.422849Z'}
{'type': 'l2update', 'product_id': 'BTC-USD', 'changes': [['sell', '38277.75', '0.00000000']], 'time': '2021-05-20T03:54:54.425523Z'}
{'type': 'l2update', 'product_id': 'BTC-USD', 'changes': [['buy', '38264.06', '0.00000000']], 'time': '2021-05-20T03:54:54.425699Z'}
{'type': 'l2update', 'product_id': 'BTC-USD', 'changes': [['sell', '38287.83', '0.00000000']], 'time': '2021-05-20T03:54:54.426293Z'}
{'type': 'l2update', 'product_id': 'BTC-USD', 'changes': [['buy', '38238.93', '0.05158814']], 'time': '2021-05-20T03:54:54.426527Z'}
{'type': 'l2update', 'product_id': 'BTC-USD', 'changes': [['buy', '38226.10', '0.03000000']], 'time': '2021-05-20T03:54:54.426844Z'}
{'type': 'l2update', 'product_id': 'BTC-USD', 'changes': [['sell', '38275.68', '0.01160075']], 'time': '2021-05-20T03:54:54.426891Z'}
{'type': 'l2update', 'product_id': 'BTC-USD', 'changes': [['sell', '38304.33', '0.44050000']], 'time': '2021-05-20T03:54:54.430569Z'}
{'type': 'l2update', 'product_id': 'BTC-USD', 'changes': [['buy', '38269.67', '0.00913414']], 'time': '2021-05-20T03:54:54.430751Z'}
{'type': 'l2update', 'product_id': 'BTC-USD', 'changes': [['sell', '38277.35', '0.01492000']], 'time': '2021-05-20T03:54:54.430843Z'}
{'type': 'l2update', 'product_id': 'BTC-USD', 'changes': [['sell', '38374.14', '0.00000000']], 'time': '2021-05-20T03:54:54.434072Z'}
{'type': 'l2update', 'product_id': 'BTC-USD', 'changes': [['sell', '38281.35', '0.54800000']], 'time': '2021-05-20T03:54:54.434606Z'}
{'type': 'l2update', 'product_id': 'BTC-USD', 'changes': [['sell', '38290.16', '0.05000000']], 'time': '2021-05-20T03:54:54.434727Z'}
{'type': 'l2update', 'product_id': 'BTC-USD', 'changes': [['sell', '38277.35', '0.00000000']], 'time': '2021-05-20T03:54:54.437120Z'}
{'type': 'l2update', 'product_id': 'BTC-USD', 'changes': [['sell', '38290.16', '0.00000000']], 'time': '2021-05-20T03:54:54.438311Z'}
{'type': 'l2update', 'product_id': 'BTC-USD', 'changes': [['buy', '38255.54', '0.58716278']], 'time': '2021-05-20T03:54:54.438799Z'}
{'type': 'l2update', 'product_id': 'BTC-USD', 'changes': [['sell', '38278.10', '0.07460000']], 'time': '2021-05-20T03:54:54.438877Z'}
{'type': 'l2update', 'product_id': 'BTC-USD', 'changes': [['buy', '38226.06', '0.04000000']], 'time': '2021-05-20T03:54:54.439011Z'}
{'type': 'l2update', 'product_id': 'BTC-USD', 'changes': [['buy', '38244.41', '0.48030000']], 'time': '2021-05-20T03:54:54.442614Z'}
{'type': 'l2update', 'product_id': 'BTC-USD', 'changes': [['buy', '38266.29', '0.01492000']], 'time': '2021-05-20T03:54:54.442677Z'}
{'type': 'l2update', 'product_id': 'BTC-USD', 'changes': [['sell', '38278.10', '0.00000000']], 'time': '2021-05-20T03:54:54.443777Z'}
{'type': 'l2update', 'product_id': 'BTC-USD', 'changes': [['sell', '38298.34', '0.05000000']], 'time': '2021-05-20T03:54:54.446253Z'}
{'type': 'l2update', 'product_id': 'BTC-USD', 'changes': [['sell', '38356.00', '0.01303577']], 'time': '2021-05-20T03:54:54.446273Z'}
{'type': 'l2update', 'product_id': 'BTC-USD', 'changes': [['buy', '38221.20', '0.05000000']], 'time': '2021-05-20T03:54:54.450780Z'}
{'type': 'l2update', 'product_id': 'BTC-USD', 'changes': [['sell', '38291.76', '0.00000000']], 'time': '2021-05-20T03:54:54.451254Z'}
{'type': 'l2update', 'product_id': 'BTC-USD', 'changes': [['buy', '38262.77', '0.00000000']], 'time': '2021-05-20T03:54:54.459136Z'}
{'type': 'l2update', 'product_id': 'BTC-USD', 'changes': [['sell', '38370.54', '0.00000000']], 'time': '2021-05-20T03:54:54.471467Z'}
{'type': 'l2update', 'product_id': 'BTC-USD', 'changes': [['sell', '39495.99', '0.00000000']], 'time': '2021-05-20T03:54:54.479349Z'}
{'type': 'l2update', 'product_id': 'BTC-USD', 'changes': [['sell', '39248.48', '0.00000000']], 'time': '2021-05-20T03:54:54.479349Z'}
{'type': 'l2update', 'product_id': 'BTC-USD', 'changes': [['sell', '39249.99', '0.04790000']], 'time': '2021-05-20T03:54:54.479349Z'}
{'type': 'l2update', 'product_id': 'BTC-USD', 'changes': [['sell', '38275.68', '0.00000000']], 'time': '2021-05-20T03:54:54.481765Z'}
{'type': 'l2update', 'product_id': 'BTC-USD', 'changes': [['buy', '38169.73', '0.00000000']], 'time': '2021-05-20T03:54:54.482095Z'}
{'type': 'l2update', 'product_id': 'BTC-USD', 'changes': [['sell', '39236.99', '0.05660000']], 'time': '2021-05-20T03:54:54.485460Z'}
{'type': 'l2update', 'product_id': 'BTC-USD', 'changes': [['sell', '39235.47', '0.03630000']], 'time': '2021-05-20T03:54:54.485460Z'}
{'type': 'l2update', 'product_id': 'BTC-USD', 'changes': [['sell', '39234.16', '0.03420000']], 'time': '2021-05-20T03:54:54.485460Z'}
{'type': 'l2update', 'product_id': 'BTC-USD', 'changes': [['sell', '38393.25', '0.03573000']], 'time': '2021-05-20T03:54:54.485529Z'}
{'type': 'l2update', 'product_id': 'BTC-USD', 'changes': [['buy', '38183.04', '0.01000000']], 'time': '2021-05-20T03:54:54.493075Z'}
{'type': 'l2update', 'product_id': 'BTC-USD', 'changes': [['sell', '38278.09', '0.07460000']], 'time': '2021-05-20T03:54:54.493293Z'}
{'type': 'l2update', 'product_id': 'BTC-USD', 'changes': [['sell', '38278.25', '0.01492000']], 'time': '2021-05-20T03:54:54.497226Z'}
{'type': 'l2update', 'product_id': 'BTC-USD', 'changes': [['sell', '38278.25', '0.00000000']], 'time': '2021-05-20T03:54:54.503371Z'}
{'type': 'l2update', 'product_id': 'BTC-USD', 'changes': [['buy', '38244.41', '0.00000000']], 'time': '2021-05-20T03:54:54.503500Z'}
{'type': 'l2update', 'product_id': 'BTC-USD', 'changes': [['sell', '38304.33', '0.00000000']], 'time': '2021-05-20T03:54:54.506950Z'}
{'type': 'l2update', 'product_id': 'BTC-USD', 'changes': [['sell', '38277.40', '0.01492000']], 'time': '2021-05-20T03:54:54.531825Z'}
{'type': 'l2update', 'product_id': 'BTC-USD', 'changes': [['sell', '38418.90', '0.00000000']], 'time': '2021-05-20T03:54:54.535587Z'}
{'type': 'l2update', 'product_id': 'BTC-USD', 'changes': [['sell', '38278.09', '0.00000000']], 'time': '2021-05-20T03:54:54.537005Z'}
{'type': 'l2update', 'product_id': 'BTC-USD', 'changes': [['sell', '38441.80', '0.01000000']], 'time': '2021-05-20T03:54:54.547339Z'}
{'type': 'l2update', 'product_id': 'BTC-USD', 'changes': [['sell', '39607.33', '0.24200000']], 'time': '2021-05-20T03:54:54.563005Z'}
{'type': 'l2update', 'product_id': 'BTC-USD', 'changes': [['sell', '38379.15', '0.00000000']], 'time': '2021-05-20T03:54:54.569312Z'}
{'type': 'l2update', 'product_id': 'BTC-USD', 'changes': [['sell', '38277.40', '0.00000000']], 'time': '2021-05-20T03:54:54.570003Z'}
{'type': 'l2update', 'product_id': 'BTC-USD', 'changes': [['sell', '38278.79', '0.00000000']], 'time': '2021-05-20T03:54:54.575373Z'}
{'type': 'l2update', 'product_id': 'BTC-USD', 'changes': [['sell', '38304.34', '0.00000000']], 'time': '2021-05-20T03:54:54.575943Z'}
{'type': 'l2update', 'product_id': 'BTC-USD', 'changes': [['sell', '38565.49', '0.00000000']], 'time': '2021-05-20T03:54:54.581222Z'}
{'type': 'l2update', 'product_id': 'BTC-USD', 'changes': [['sell', '38278.51', '0.07460000']], 'time': '2021-05-20T03:54:54.582731Z'}
{'type': 'l2update', 'product_id': 'BTC-USD', 'changes': [['sell', '38278.44', '0.01492000']], 'time': '2021-05-20T03:54:54.583133Z'}
{'type': 'l2update', 'product_id': 'BTC-USD', 'changes': [['sell', '38278.51', '0.00000000']], 'time': '2021-05-20T03:54:54.589375Z'}
{'type': 'l2update', 'product_id': 'BTC-USD', 'changes': [['sell', '38278.78', '0.00000000']], 'time': '2021-05-20T03:54:54.590045Z'}
{'type': 'l2update', 'product_id': 'BTC-USD', 'changes': [['sell', '38360.53', '0.01000000']], 'time': '2021-05-20T03:54:54.591142Z'}
{'type': 'l2update', 'product_id': 'BTC-USD', 'changes': [['sell', '50969.30', '0.00562600']], 'time': '2021-05-20T03:54:54.591166Z'}
{'type': 'l2update', 'product_id': 'BTC-USD', 'changes': [['buy', '38244.76', '0.43900000']], 'time': '2021-05-20T03:54:54.594573Z'}
{'type': 'l2update', 'product_id': 'BTC-USD', 'changes': [['sell', '38588.06', '3.23362444']], 'time': '2021-05-20T03:54:54.602066Z'}
{'type': 'l2update', 'product_id': 'BTC-USD', 'changes': [['sell', '38415.85', '0.00000000']], 'time': '2021-05-20T03:54:54.603812Z'}
{'type': 'l2update', 'product_id': 'BTC-USD', 'changes': [['sell', '38277.95', '0.07460000']], 'time': '2021-05-20T03:54:54.606348Z'}
{'type': 'l2update', 'product_id': 'BTC-USD', 'changes': [['sell', '38278.79', '0.59116556']], 'time': '2021-05-20T03:54:54.610914Z'}
{'type': 'l2update', 'product_id': 'BTC-USD', 'changes': [['sell', '38278.44', '0.00000000']], 'time': '2021-05-20T03:54:54.612995Z'}
{'type': 'l2update', 'product_id': 'BTC-USD', 'changes': [['sell', '38428.86', '0.01030260']], 'time': '2021-05-20T03:54:54.614590Z'}
{'type': 'l2update', 'product_id': 'BTC-USD', 'changes': [['buy', '38163.42', '0.00000000']], 'time': '2021-05-20T03:54:54.628447Z'}
{'type': 'l2update', 'product_id': 'BTC-USD', 'changes': [['sell', '38327.31', '0.50000000']], 'time': '2021-05-20T03:54:54.630644Z'}
{'type': 'l2update', 'product_id': 'BTC-USD', 'changes': [['sell', '38304.15', '0.41050000']], 'time': '2021-05-20T03:54:54.635443Z'}
{'type': 'l2update', 'product_id': 'BTC-USD', 'changes': [['sell', '38360.53', '0.00000000']], 'time': '2021-05-20T03:54:54.636240Z'}
{'type': 'l2update', 'product_id': 'BTC-USD', 'changes': [['buy', '38142.70', '0.01000000']], 'time': '2021-05-20T03:54:54.639229Z'}
{'type': 'l2update', 'product_id': 'BTC-USD', 'changes': [['sell', '38304.15', '0.00000000']], 'time': '2021-05-20T03:54:54.640432Z'}
{'type': 'l2update', 'product_id': 'BTC-USD', 'changes': [['buy', '38170.92', '0.50000000']], 'time': '2021-05-20T03:54:54.645155Z'}
{'type': 'l2update', 'product_id': 'BTC-USD', 'changes': [['sell', '38277.60', '0.01492000']], 'time': '2021-05-20T03:54:54.651017Z'}
{'type': 'l2update', 'product_id': 'BTC-USD', 'changes': [['sell', '38393.25', '0.00000000']], 'time': '2021-05-20T03:54:54.654584Z'}
{'type': 'l2update', 'product_id': 'BTC-USD', 'changes': [['sell', '38277.95', '0.00000000']], 'time': '2021-05-20T03:54:54.656638Z'}
{'type': 'l2update', 'product_id': 'BTC-USD', 'changes': [['sell', '38379.15', '0.02941900']], 'time': '2021-05-20T03:54:54.659286Z'}
{'type': 'l2update', 'product_id': 'BTC-USD', 'changes': [['buy', '38178.56', '0.07700000']], 'time': '2021-05-20T03:54:54.668401Z'}
{'type': 'l2update', 'product_id': 'BTC-USD', 'changes': [['sell', '38380.63', '0.03573000']], 'time': '2021-05-20T03:54:54.668673Z'}
{'type': 'l2update', 'product_id': 'BTC-USD', 'changes': [['buy', '38185.98', '0.07900000']], 'time': '2021-05-20T03:54:54.671201Z'}
{'type': 'l2update', 'product_id': 'BTC-USD', 'changes': [['sell', '38321.53', '0.07700000']], 'time': '2021-05-20T03:54:54.671282Z'}
{'type': 'l2update', 'product_id': 'BTC-USD', 'changes': [['sell', '38410.29', '0.00000000']], 'time': '2021-05-20T03:54:54.676087Z'}
{'type': 'l2update', 'product_id': 'BTC-USD', 'changes': [['sell', '38398.50', '0.01000000']], 'time': '2021-05-20T03:54:54.688187Z'}
{'type': 'l2update', 'product_id': 'BTC-USD', 'changes': [['sell', '38321.53', '0.00000000']], 'time': '2021-05-20T03:54:54.697747Z'}
{'type': 'l2update', 'product_id': 'BTC-USD', 'changes': [['sell', '38392.87', '0.00000000']], 'time': '2021-05-20T03:54:54.703436Z'}
{'type': 'l2update', 'product_id': 'BTC-USD', 'changes': [['sell', '38278.80', '0.53600000']], 'time': '2021-05-20T03:54:54.707639Z'}
{'type': 'l2update', 'product_id': 'BTC-USD', 'changes': [['sell', '38277.60', '0.00000000']], 'time': '2021-05-20T03:54:54.708775Z'}
{'type': 'l2update', 'product_id': 'BTC-USD', 'changes': [['sell', '38374.38', '0.01000000']], 'time': '2021-05-20T03:54:54.716327Z'}
{'type': 'l2update', 'product_id': 'BTC-USD', 'changes': [['sell', '38278.34', '0.07460000']], 'time': '2021-05-20T03:54:54.719556Z'}
{'type': 'l2update', 'product_id': 'BTC-USD', 'changes': [['sell', '38278.26', '0.01492000']], 'time': '2021-05-20T03:54:54.719715Z'}
{'type': 'l2update', 'product_id': 'BTC-USD', 'changes': [['sell', '38277.59', '2.48969908']], 'time': '2021-05-20T03:54:54.723587Z'}
{'type': 'l2update', 'product_id': 'BTC-USD', 'changes': [['sell', '38278.34', '0.00000000']], 'time': '2021-05-20T03:54:54.725051Z'}
{'type': 'l2update', 'product_id': 'BTC-USD', 'changes': [['sell', '38278.26', '0.00000000']], 'time': '2021-05-20T03:54:54.729875Z'}
{'type': 'l2update', 'product_id': 'BTC-USD', 'changes': [['sell', '38307.72', '0.42880000']], 'time': '2021-05-20T03:54:54.731367Z'}
{'type': 'l2update', 'product_id': 'BTC-USD', 'changes': [['sell', '38278.79', '0.00000000']], 'time': '2021-05-20T03:54:54.731383Z'}
{'type': 'l2update', 'product_id': 'BTC-USD', 'changes': [['sell', '38277.59', '0.00000000']], 'time': '2021-05-20T03:54:54.733132Z'}
{'type': 'l2update', 'product_id': 'BTC-USD', 'changes': [['sell', '38278.15', '0.07460000']], 'time': '2021-05-20T03:54:54.743592Z'}
{'type': 'l2update', 'product_id': 'BTC-USD', 'changes': [['sell', '38278.37', '0.01492000']], 'time': '2021-05-20T03:54:54.743617Z'}
{'type': 'l2update', 'product_id': 'BTC-USD', 'changes': [['sell', '38278.79', '2.48969908']], 'time': '2021-05-20T03:54:54.748903Z'}
{'type': 'l2update', 'product_id': 'BTC-USD', 'changes': [['sell', '38278.37', '0.00000000']], 'time': '2021-05-20T03:54:54.749941Z'}
{'type': 'l2update', 'product_id': 'BTC-USD', 'changes': [['sell', '50973.64', '0.00394100']], 'time': '2021-05-20T03:54:54.751280Z'}
{'type': 'l2update', 'product_id': 'BTC-USD', 'changes': [['sell', '38278.79', '3.08086464']], 'time': '2021-05-20T03:54:54.751350Z'}
{'type': 'l2update', 'product_id': 'BTC-USD', 'changes': [['buy', '38242.49', '0.05923850']], 'time': '2021-05-20T03:54:54.759631Z'}
{'type': 'l2update', 'product_id': 'BTC-USD', 'changes': [['sell', '38283.14', '0.06389045']], 'time': '2021-05-20T03:54:54.759631Z'}
{'type': 'l2update', 'product_id': 'BTC-USD', 'changes': [['sell', '38277.63', '0.01492000']], 'time': '2021-05-20T03:54:54.762683Z'}
{'type': 'l2update', 'product_id': 'BTC-USD', 'changes': [['sell', '38278.15', '0.00000000']], 'time': '2021-05-20T03:54:54.768323Z'}
{'type': 'l2update', 'product_id': 'BTC-USD', 'changes': [['buy', '38263.79', '0.10000000']], 'time': '2021-05-20T03:54:54.781901Z'}
{'type': 'l2update', 'product_id': 'BTC-USD', 'changes': [['sell', '38277.63', '0.00000000']], 'time': '2021-05-20T03:54:54.813684Z'}
{'type': 'l2update', 'product_id': 'BTC-USD', 'changes': [['sell', '38278.79', '2.48969908']], 'time': '2021-05-20T03:54:54.819675Z'}
{'type': 'l2update', 'product_id': 'BTC-USD', 'changes': [['sell', '38278.43', '0.01492000']], 'time': '2021-05-20T03:54:54.826119Z'}
{'type': 'l2update', 'product_id': 'BTC-USD', 'changes': [['sell', '38278.55', '0.07460000']], 'time': '2021-05-20T03:54:54.826233Z'}
{'type': 'l2update', 'product_id': 'BTC-USD', 'changes': [['sell', '38278.43', '0.01364642']], 'time': '2021-05-20T03:54:54.830146Z'}
{'type': 'l2update', 'product_id': 'BTC-USD', 'changes': [['buy', '38264.05', '0.00176519']], 'time': '2021-05-20T03:54:54.830208Z'}
{'type': 'l2update', 'product_id': 'BTC-USD', 'changes': [['sell', '38278.55', '0.00000000']], 'time': '2021-05-20T03:54:54.832465Z'}
{'type': 'l2update', 'product_id': 'BTC-USD', 'changes': [['sell', '38278.78', '0.59116556']], 'time': '2021-05-20T03:54:54.842049Z'}
{'type': 'l2update', 'product_id': 'BTC-USD', 'changes': [['sell', '38277.81', '0.07460000']], 'time': '2021-05-20T03:54:54.850149Z'}
{'type': 'l2update', 'product_id': 'BTC-USD', 'changes': [['sell', '38278.43', '0.00000000']], 'time': '2021-05-20T03:54:54.857242Z'}
{'type': 'l2update', 'product_id': 'BTC-USD', 'changes': [['buy', '38255.54', '0.00000000']], 'time': '2021-05-20T03:54:54.860407Z'}
{'type': 'l2update', 'product_id': 'BTC-USD', 'changes': [['sell', '38277.43', '0.00127358']], 'time': '2021-05-20T03:54:54.862993Z'}
{'type': 'l2update', 'product_id': 'BTC-USD', 'changes': [['sell', '38277.81', '0.00000000']], 'time': '2021-05-20T03:54:54.873497Z'}
{'type': 'l2update', 'product_id': 'BTC-USD', 'changes': [['sell', '38277.43', '0.01492000']], 'time': '2021-05-20T03:54:54.875307Z'}
{'type': 'l2update', 'product_id': 'BTC-USD', 'changes': [['buy', '38222.55', '0.03041148']], 'time': '2021-05-20T03:54:54.876134Z'}
{'type': 'l2update', 'product_id': 'BTC-USD', 'changes': [['sell', '38277.43', '0.01364642']], 'time': '2021-05-20T03:54:54.879158Z'}
{'type': 'l2update', 'product_id': 'BTC-USD', 'changes': [['buy', '38260.29', '0.58716278']], 'time': '2021-05-20T03:54:54.879451Z'}
{'type': 'l2update', 'product_id': 'BTC-USD', 'changes': [['sell', '38277.43', '0.00000000']], 'time': '2021-05-20T03:54:54.880063Z'}
{'type': 'l2update', 'product_id': 'BTC-USD', 'changes': [['buy', '38142.70', '0.00000000']], 'time': '2021-05-20T03:54:54.882196Z'}
{'type': 'l2update', 'product_id': 'BTC-USD', 'changes': [['buy', '38218.55', '0.10000000']], 'time': '2021-05-20T03:54:54.888087Z'}
{'type': 'l2update', 'product_id': 'BTC-USD', 'changes': [['buy', '38154.63', '0.03577500']], 'time': '2021-05-20T03:54:54.891926Z'}
{'type': 'l2update', 'product_id': 'BTC-USD', 'changes': [['sell', '38278.35', '0.07460000']], 'time': '2021-05-20T03:54:54.892304Z'}
{'type': 'l2update', 'product_id': 'BTC-USD', 'changes': [['sell', '38278.42', '0.01492000']], 'time': '2021-05-20T03:54:54.896193Z'}
{'type': 'l2update', 'product_id': 'BTC-USD', 'changes': [['buy', '38247.37', '0.00000000']], 'time': '2021-05-20T03:54:54.896383Z'}
{'type': 'l2update', 'product_id': 'BTC-USD', 'changes': [['sell', '38374.38', '0.00000000']], 'time': '2021-05-20T03:54:54.898373Z'}
{'type': 'l2update', 'product_id': 'BTC-USD', 'changes': [['sell', '38278.78', '0.00000000']], 'time': '2021-05-20T03:54:54.899312Z'}
{'type': 'l2update', 'product_id': 'BTC-USD', 'changes': [['sell', '38278.42', '0.00000000']], 'time': '2021-05-20T03:54:54.901547Z'}
{'type': 'l2update', 'product_id': 'BTC-USD', 'changes': [['buy', '38250.56', '0.02400000']], 'time': '2021-05-20T03:54:54.908732Z'}
{'type': 'l2update', 'product_id': 'BTC-USD', 'changes': [['sell', '38355.90', '0.01000000']], 'time': '2021-05-20T03:54:54.912757Z'}
{'type': 'l2update', 'product_id': 'BTC-USD', 'changes': [['sell', '50980.93', '0.00394100']], 'time': '2021-05-20T03:54:54.917333Z'}
{'type': 'l2update', 'product_id': 'BTC-USD', 'changes': [['sell', '38278.34', '0.59116556']], 'time': '2021-05-20T03:54:54.917522Z'}
{'type': 'l2update', 'product_id': 'BTC-USD', 'changes': [['sell', '38277.86', '0.01492000']], 'time': '2021-05-20T03:54:54.917665Z'}
{'type': 'l2update', 'product_id': 'BTC-USD', 'changes': [['sell', '38278.35', '0.00000000']], 'time': '2021-05-20T03:54:54.923025Z'}
{'type': 'l2update', 'product_id': 'BTC-USD', 'changes': [['buy', '38269.67', '0.00571916']], 'time': '2021-05-20T03:54:54.926103Z'}
{'type': 'l2update', 'product_id': 'BTC-USD', 'changes': [['sell', '38277.40', '0.07460000']], 'time': '2021-05-20T03:54:54.939005Z'}
{'type': 'l2update', 'product_id': 'BTC-USD', 'changes': [['sell', '38277.40', '0.00000000']], 'time': '2021-05-20T03:54:54.944668Z'}
{'type': 'l2update', 'product_id': 'BTC-USD', 'changes': [['sell', '38277.86', '0.00000000']], 'time': '2021-05-20T03:54:54.946748Z'}
{'type': 'l2update', 'product_id': 'BTC-USD', 'changes': [['sell', '38307.72', '0.00000000']], 'time': '2021-05-20T03:54:54.951962Z'}
{'type': 'l2update', 'product_id': 'BTC-USD', 'changes': [['sell', '38278.34', '0.58864757']], 'time': '2021-05-20T03:54:54.954401Z'}
{'type': 'l2update', 'product_id': 'BTC-USD', 'changes': [['sell', '38278.03', '0.01492000']], 'time': '2021-05-20T03:54:54.958648Z'}
{'type': 'l2update', 'product_id': 'BTC-USD', 'changes': [['sell', '38277.86', '0.07460000']], 'time': '2021-05-20T03:54:54.958661Z'}
{'type': 'l2update', 'product_id': 'BTC-USD', 'changes': [['sell', '38306.47', '0.44100000']], 'time': '2021-05-20T03:54:54.962816Z'}
{'type': 'l2update', 'product_id': 'BTC-USD', 'changes': [['sell', '38278.34', '0.00000000']], 'time': '2021-05-20T03:54:54.964765Z'}
{'type': 'l2update', 'product_id': 'BTC-USD', 'changes': [['sell', '38278.03', '0.00000000']], 'time': '2021-05-20T03:54:54.965921Z'}
{'type': 'l2update', 'product_id': 'BTC-USD', 'changes': [['buy', '38244.76', '0.00000000']], 'time': '2021-05-20T03:54:54.966757Z'}
{'type': 'l2update', 'product_id': 'BTC-USD', 'changes': [['buy', '38226.85', '0.00000000']], 'time': '2021-05-20T03:54:54.970082Z'}
{'type': 'l2update', 'product_id': 'BTC-USD', 'changes': [['buy', '38246.73', '0.43120000']], 'time': '2021-05-20T03:54:54.980917Z'}
{'type': 'l2update', 'product_id': 'BTC-USD', 'changes': [['buy', '38226.18', '0.00000000']], 'time': '2021-05-20T03:54:54.980965Z'}
{'type': 'l2update', 'product_id': 'BTC-USD', 'changes': [['sell', '38278.78', '0.58864756']], 'time': '2021-05-20T03:54:54.984400Z'}
{'type': 'l2update', 'product_id': 'BTC-USD', 'changes': [['buy', '38226.10', '0.00000000']], 'time': '2021-05-20T03:54:54.984641Z'}
{'type': 'l2update', 'product_id': 'BTC-USD', 'changes': [['sell', '38277.51', '0.01492000']], 'time': '2021-05-20T03:54:54.984698Z'}
{'type': 'l2update', 'product_id': 'BTC-USD', 'changes': [['buy', '38246.73', '0.00000000']], 'time': '2021-05-20T03:54:54.984804Z'}
{'type': 'l2update', 'product_id': 'BTC-USD', 'changes': [['buy', '38226.06', '0.00000000']], 'time': '2021-05-20T03:54:54.988828Z'}
{'type': 'l2update', 'product_id': 'BTC-USD', 'changes': [['sell', '38277.86', '0.00000000']], 'time': '2021-05-20T03:54:54.990537Z'}
{'type': 'l2update', 'product_id': 'BTC-USD', 'changes': [['sell', '38277.51', '0.00000000']], 'time': '2021-05-20T03:54:54.991865Z'}
{'type': 'l2update', 'product_id': 'BTC-USD', 'changes': [['buy', '38221.20', '0.00000000']], 'time': '2021-05-20T03:54:54.993674Z'}
{'type': 'l2update', 'product_id': 'BTC-USD', 'changes': [['sell', '38575.19', '0.00000000']], 'time': '2021-05-20T03:54:54.996419Z'}
{'type': 'l2update', 'product_id': 'BTC-USD', 'changes': [['sell', '38398.50', '0.00000000']], 'time': '2021-05-20T03:54:54.999799Z'}
{'type': 'l2update', 'product_id': 'BTC-USD', 'changes': [['sell', '38278.48', '0.07460000']], 'time': '2021-05-20T03:54:55.004591Z'}
{'type': 'l2update', 'product_id': 'BTC-USD', 'changes': [['buy', '38244.31', '0.01000000']], 'time': '2021-05-20T03:54:55.004775Z'}
{'type': 'l2update', 'product_id': 'BTC-USD', 'changes': [['sell', '38278.22', '0.01492000']], 'time': '2021-05-20T03:54:55.007659Z'}
{'type': 'l2update', 'product_id': 'BTC-USD', 'changes': [['sell', '38410.29', '0.01000000']], 'time': '2021-05-20T03:54:55.011556Z'}
{'type': 'l2update', 'product_id': 'BTC-USD', 'changes': [['sell', '38278.48', '0.00000000']], 'time': '2021-05-20T03:54:55.013350Z'}
{'type': 'l2update', 'product_id': 'BTC-USD', 'changes': [['buy', '38239.09', '0.02000000']], 'time': '2021-05-20T03:54:55.015429Z'}
{'type': 'l2update', 'product_id': 'BTC-USD', 'changes': [['sell', '38349.26', '0.15560000']], 'time': '2021-05-20T03:54:55.015461Z'}
{'type': 'l2update', 'product_id': 'BTC-USD', 'changes': [['sell', '38522.77', '0.00648966']], 'time': '2021-05-20T03:54:55.019189Z'}
{'type': 'l2update', 'product_id': 'BTC-USD', 'changes': [['buy', '38239.09', '0.05000000']], 'time': '2021-05-20T03:54:55.027863Z'}
{'type': 'l2update', 'product_id': 'BTC-USD', 'changes': [['buy', '38239.09', '0.09000000']], 'time': '2021-05-20T03:54:55.038359Z'}
{'type': 'l2update', 'product_id': 'BTC-USD', 'changes': [['buy', '38239.09', '0.14000000']], 'time': '2021-05-20T03:54:55.048686Z'}
{'type': 'l2update', 'product_id': 'BTC-USD', 'changes': [['sell', '38277.98', '0.07460000']], 'time': '2021-05-20T03:54:55.052726Z'}
{'type': 'l2update', 'product_id': 'BTC-USD', 'changes': [['sell', '38278.22', '0.00000000']], 'time': '2021-05-20T03:54:55.059292Z'}
{'type': 'l2update', 'product_id': 'BTC-USD', 'changes': [['sell', '38278.78', '0.00000000']], 'time': '2021-05-20T03:54:55.059363Z'}
{'type': 'l2update', 'product_id': 'BTC-USD', 'changes': [['buy', '38260.29', '0.00000000']], 'time': '2021-05-20T03:54:55.073477Z'}
{'type': 'l2update', 'product_id': 'BTC-USD', 'changes': [['buy', '38248.48', '0.42250000']], 'time': '2021-05-20T03:54:55.075644Z'}
{'type': 'l2update', 'product_id': 'BTC-USD', 'changes': [['sell', '38277.48', '0.01492000']], 'time': '2021-05-20T03:54:55.075811Z'}
{'type': 'l2update', 'product_id': 'BTC-USD', 'changes': [['buy', '38264.05', '0.00000000']], 'time': '2021-05-20T03:54:55.077820Z'}
{'type': 'l2update', 'product_id': 'BTC-USD', 'changes': [['sell', '38338.48', '0.61482416']], 'time': '2021-05-20T03:54:55.079212Z'}
{'type': 'l2update', 'product_id': 'BTC-USD', 'changes': [['sell', '38278.78', '0.58864756']], 'time': '2021-05-20T03:54:55.079458Z'}
{'type': 'l2update', 'product_id': 'BTC-USD', 'changes': [['buy', '38250.56', '0.00000000']], 'time': '2021-05-20T03:54:55.079754Z'}
{'type': 'l2update', 'product_id': 'BTC-USD', 'changes': [['sell', '38277.98', '0.00000000']], 'time': '2021-05-20T03:54:55.082215Z'}
{'type': 'l2update', 'product_id': 'BTC-USD', 'changes': [['sell', '50991.86', '0.00394100']], 'time': '2021-05-20T03:54:55.083224Z'}
{'type': 'l2update', 'product_id': 'BTC-USD', 'changes': [['buy', '38247.82', '0.02400000']], 'time': '2021-05-20T03:54:55.090899Z'}
{'type': 'l2update', 'product_id': 'BTC-USD', 'changes': [['buy', '38258.94', '0.58716278']], 'time': '2021-05-20T03:54:55.094773Z'}
{'type': 'l2update', 'product_id': 'BTC-USD', 'changes': [['sell', '38277.48', '0.00000000']], 'time': '2021-05-20T03:54:55.110354Z'}
{'type': 'l2update', 'product_id': 'BTC-USD', 'changes': [['sell', '38278.78', '0.47546354']], 'time': '2021-05-20T03:54:55.110354Z'}
{'type': 'l2update', 'product_id': 'BTC-USD', 'changes': [['buy', '38269.66', '0.00176519']], 'time': '2021-05-20T03:54:55.117933Z'}
{'type': 'l2update', 'product_id': 'BTC-USD', 'changes': [['buy', '38260.29', '0.11570201']], 'time': '2021-05-20T03:54:55.121738Z'}
{'type': 'l2update', 'product_id': 'BTC-USD', 'changes': [['buy', '38239.95', '0.00000000']], 'time': '2021-05-20T03:54:55.122882Z'}
{'type': 'l2update', 'product_id': 'BTC-USD', 'changes': [['buy', '38269.68', '0.50000000']], 'time': '2021-05-20T03:54:55.125377Z'}
{'type': 'l2update', 'product_id': 'BTC-USD', 'changes': [['sell', '38278.51', '0.01492000']], 'time': '2021-05-20T03:54:55.125560Z'}
{'type': 'l2update', 'product_id': 'BTC-USD', 'changes': [['sell', '38278.49', '0.07460000']], 'time': '2021-05-20T03:54:55.125641Z'}
{'type': 'l2update', 'product_id': 'BTC-USD', 'changes': [['buy', '38266.29', '0.00000000']], 'time': '2021-05-20T03:54:55.131312Z'}
{'type': 'l2update', 'product_id': 'BTC-USD', 'changes': [['sell', '38278.51', '0.00000000']], 'time': '2021-05-20T03:54:55.133479Z'}
{'type': 'l2update', 'product_id': 'BTC-USD', 'changes': [['buy', '38235.32', '0.04714832']], 'time': '2021-05-20T03:54:55.135294Z'}
{'type': 'l2update', 'product_id': 'BTC-USD', 'changes': [['buy', '38249.85', '0.20100000']], 'time': '2021-05-20T03:54:55.137574Z'}
{'type': 'l2update', 'product_id': 'BTC-USD', 'changes': [['sell', '38278.78', '0.00000000']], 'time': '2021-05-20T03:54:55.137808Z'}
{'type': 'l2update', 'product_id': 'BTC-USD', 'changes': [['buy', '38235.32', '0.00000000']], 'time': '2021-05-20T03:54:55.143366Z'}
{'type': 'l2update', 'product_id': 'BTC-USD', 'changes': [['buy', '38238.30', '0.04714832']], 'time': '2021-05-20T03:54:55.145706Z'}
{'type': 'l2update', 'product_id': 'BTC-USD', 'changes': [['buy', '38238.30', '0.00000000']], 'time': '2021-05-20T03:54:55.150995Z'}
{'type': 'l2update', 'product_id': 'BTC-USD', 'changes': [['sell', '38366.08', '0.00000000']], 'time': '2021-05-20T03:54:55.157579Z'}
{'type': 'l2update', 'product_id': 'BTC-USD', 'changes': [['sell', '38278.48', '0.47546355']], 'time': '2021-05-20T03:54:55.158203Z'}
{'type': 'l2update', 'product_id': 'BTC-USD', 'changes': [['buy', '38270.03', '0.01492000']], 'time': '2021-05-20T03:54:55.158351Z'}
{'type': 'l2update', 'product_id': 'BTC-USD', 'changes': [['sell', '38278.49', '0.00000000']], 'time': '2021-05-20T03:54:55.164396Z'}
{'type': 'l2update', 'product_id': 'BTC-USD', 'changes': [['buy', '38269.69', '0.10000000']], 'time': '2021-05-20T03:54:55.167822Z'}
{'type': 'l2update', 'product_id': 'BTC-USD', 'changes': [['buy', '38239.10', '0.04714832']], 'time': '2021-05-20T03:54:55.173002Z'}
{'type': 'l2update', 'product_id': 'BTC-USD', 'changes': [['sell', '38278.13', '0.01492000']], 'time': '2021-05-20T03:54:55.173488Z'}
{'type': 'l2update', 'product_id': 'BTC-USD', 'changes': [['sell', '38277.81', '0.07460000']], 'time': '2021-05-20T03:54:55.183683Z'}
{'type': 'l2update', 'product_id': 'BTC-USD', 'changes': [['sell', '38277.81', '0.00000000']], 'time': '2021-05-20T03:54:55.188792Z'}
{'type': 'l2update', 'product_id': 'BTC-USD', 'changes': [['sell', '38278.13', '0.00000000']], 'time': '2021-05-20T03:54:55.189716Z'}
{'type': 'l2update', 'product_id': 'BTC-USD', 'changes': [['sell', '38379.15', '0.00000000']], 'time': '2021-05-20T03:54:55.189872Z'}
{'type': 'l2update', 'product_id': 'BTC-USD', 'changes': [['buy', '38270.03', '0.00000000']], 'time': '2021-05-20T03:54:55.190466Z'}
{'type': 'l2update', 'product_id': 'BTC-USD', 'changes': [['buy', '38239.95', '0.04714832']], 'time': '2021-05-20T03:54:55.200198Z'}
{'type': 'l2update', 'product_id': 'BTC-USD', 'changes': [['buy', '38270.21', '0.01492000']], 'time': '2021-05-20T03:54:55.205393Z'}
{'type': 'l2update', 'product_id': 'BTC-USD', 'changes': [['sell', '38277.81', '0.07460000']], 'time': '2021-05-20T03:54:55.205461Z'}
{'type': 'l2update', 'product_id': 'BTC-USD', 'changes': [['sell', '38367.54', '0.01000000']], 'time': '2021-05-20T03:54:55.205536Z'}
{'type': 'l2update', 'product_id': 'BTC-USD', 'changes': [['buy', '38239.10', '0.00000000']], 'time': '2021-05-20T03:54:55.205628Z'}
{'type': 'l2update', 'product_id': 'BTC-USD', 'changes': [['sell', '38278.03', '0.01492000']], 'time': '2021-05-20T03:54:55.205645Z'}
{'type': 'l2update', 'product_id': 'BTC-USD', 'changes': [['sell', '38278.48', '0.00000000']], 'time': '2021-05-20T03:54:55.208535Z'}
{'type': 'l2update', 'product_id': 'BTC-USD', 'changes': [['sell', '38306.47', '0.00000000']], 'time': '2021-05-20T03:54:55.209329Z'}
{'type': 'l2update', 'product_id': 'BTC-USD', 'changes': [['sell', '38293.73', '0.00000000']], 'time': '2021-05-20T03:54:55.211615Z'}
{'type': 'l2update', 'product_id': 'BTC-USD', 'changes': [['buy', '38270.21', '0.00000000']], 'time': '2021-05-20T03:54:55.212317Z'}
{'type': 'l2update', 'product_id': 'BTC-USD', 'changes': [['sell', '38278.03', '0.00000000']], 'time': '2021-05-20T03:54:55.212376Z'}
{'type': 'l2update', 'product_id': 'BTC-USD', 'changes': [['sell', '43100.00', '1.09530000']], 'time': '2021-05-20T03:54:55.214853Z'}
{'type': 'l2update', 'product_id': 'BTC-USD', 'changes': [['sell', '38277.81', '0.00000000']], 'time': '2021-05-20T03:54:55.217218Z'}
{'type': 'l2update', 'product_id': 'BTC-USD', 'changes': [['sell', '38395.80', '0.00000000']], 'time': '2021-05-20T03:54:55.217822Z'}
{'type': 'l2update', 'product_id': 'BTC-USD', 'changes': [['sell', '38307.69', '0.48030000']], 'time': '2021-05-20T03:54:55.219830Z'}
{'type': 'l2update', 'product_id': 'BTC-USD', 'changes': [['sell', '38289.74', '0.04201003']], 'time': '2021-05-20T03:54:55.236066Z'}
{'type': 'l2update', 'product_id': 'BTC-USD', 'changes': [['sell', '38278.78', '0.47546355']], 'time': '2021-05-20T03:54:55.236189Z'}
{'type': 'l2update', 'product_id': 'BTC-USD', 'changes': [['sell', '38421.79', '0.01173029']], 'time': '2021-05-20T03:54:55.243426Z'}
{'type': 'l2update', 'product_id': 'BTC-USD', 'changes': [['sell', '38278.34', '0.07460000']], 'time': '2021-05-20T03:54:55.243668Z'}
{'type': 'l2update', 'product_id': 'BTC-USD', 'changes': [['buy', '38270.33', '0.01492000']], 'time': '2021-05-20T03:54:55.243750Z'}
{'type': 'l2update', 'product_id': 'BTC-USD', 'changes': [['sell', '51006.44', '0.00394100']], 'time': '2021-05-20T03:54:55.243778Z'}
{'type': 'l2update', 'product_id': 'BTC-USD', 'changes': [['buy', '38250.00', '0.52100000']], 'time': '2021-05-20T03:54:55.244018Z'}
{'type': 'l2update', 'product_id': 'BTC-USD', 'changes': [['sell', '38278.24', '0.01492000']], 'time': '2021-05-20T03:54:55.246710Z'}
{'type': 'l2update', 'product_id': 'BTC-USD', 'changes': [['sell', '43100.00', '2.73200000']], 'time': '2021-05-20T03:54:55.247149Z'}
{'type': 'l2update', 'product_id': 'BTC-USD', 'changes': [['buy', '38200.84', '0.07800000']], 'time': '2021-05-20T03:54:55.249447Z'}
{'type': 'l2update', 'product_id': 'BTC-USD', 'changes': [['buy', '38209.47', '0.07700000']], 'time': '2021-05-20T03:54:55.253362Z'}
{'type': 'l2update', 'product_id': 'BTC-USD', 'changes': [['sell', '38307.69', '0.00000000']], 'time': '2021-05-20T03:54:55.262311Z'}
{'type': 'l2update', 'product_id': 'BTC-USD', 'changes': [['buy', '38263.79', '0.00000000']], 'time': '2021-05-20T03:54:55.265388Z'}
{'type': 'l2update', 'product_id': 'BTC-USD', 'changes': [['sell', '38278.24', '0.00000000']], 'time': '2021-05-20T03:54:55.268004Z'}
{'type': 'l2update', 'product_id': 'BTC-USD', 'changes': [['sell', '38278.34', '0.00000000']], 'time': '2021-05-20T03:54:55.268611Z'}
{'type': 'l2update', 'product_id': 'BTC-USD', 'changes': [['buy', '37500.01', '0.13400000']], 'time': '2021-05-20T03:54:55.291232Z'}
{'type': 'l2update', 'product_id': 'BTC-USD', 'changes': [['buy', '37500.01', '0.18870000']], 'time': '2021-05-20T03:54:55.296968Z'}
{'type': 'l2update', 'product_id': 'BTC-USD', 'changes': [['buy', '38269.66', '0.00000000']], 'time': '2021-05-20T03:54:55.332617Z'}
{'type': 'l2update', 'product_id': 'BTC-USD', 'changes': [['sell', '38278.54', '0.01492000']], 'time': '2021-05-20T03:54:55.367106Z'}
{'type': 'l2update', 'product_id': 'BTC-USD', 'changes': [['sell', '38278.48', '0.07460000']], 'time': '2021-05-20T03:54:55.369322Z'}
{'type': 'l2update', 'product_id': 'BTC-USD', 'changes': [['sell', '38302.11', '0.05000000']], 'time': '2021-05-20T03:54:55.369475Z'}
{'type': 'l2update', 'product_id': 'BTC-USD', 'changes': [['sell', '38278.48', '0.00000000']], 'time': '2021-05-20T03:54:55.384016Z'}
{'type': 'l2update', 'product_id': 'BTC-USD', 'changes': [['buy', '38270.33', '0.00598030']], 'time': '2021-05-20T03:54:55.384201Z'}
{'type': 'l2update', 'product_id': 'BTC-USD', 'changes': [['buy', '38262.77', '0.52200000']], 'time': '2021-05-20T03:54:55.384556Z'}
{'type': 'l2update', 'product_id': 'BTC-USD', 'changes': [['sell', '38278.54', '0.00000000']], 'time': '2021-05-20T03:54:55.385356Z'}
{'type': 'l2update', 'product_id': 'BTC-USD', 'changes': [['sell', '38307.96', '0.48300000']], 'time': '2021-05-20T03:54:55.391885Z'}
{'type': 'l2update', 'product_id': 'BTC-USD', 'changes': [['sell', '38278.78', '0.00000000']], 'time': '2021-05-20T03:54:55.393858Z'}
{'type': 'l2update', 'product_id': 'BTC-USD', 'changes': [['buy', '38269.66', '0.00176519']], 'time': '2021-05-20T03:54:55.398872Z'}
{'type': 'l2update', 'product_id': 'BTC-USD', 'changes': [['sell', '38309.17', '0.15200000']], 'time': '2021-05-20T03:54:55.399001Z'}
{'type': 'l2update', 'product_id': 'BTC-USD', 'changes': [['sell', '38278.26', '0.07460000']], 'time': '2021-05-20T03:54:55.417513Z'}
{'type': 'l2update', 'product_id': 'BTC-USD', 'changes': [['sell', '38281.35', '0.00000000']], 'time': '2021-05-20T03:54:55.418989Z'}
{'type': 'l2update', 'product_id': 'BTC-USD', 'changes': [['sell', '51022.67', '0.00253500']], 'time': '2021-05-20T03:54:55.425043Z'}
{'type': 'l2update', 'product_id': 'BTC-USD', 'changes': [['sell', '38278.48', '0.01492000']], 'time': '2021-05-20T03:54:55.425907Z'}
{'type': 'l2update', 'product_id': 'BTC-USD', 'changes': [['sell', '38317.95', '0.10000000']], 'time': '2021-05-20T03:54:55.442474Z'}
{'type': 'l2update', 'product_id': 'BTC-USD', 'changes': [['sell', '38446.25', '0.01000000']], 'time': '2021-05-20T03:54:55.444580Z'}
{'type': 'l2update', 'product_id': 'BTC-USD', 'changes': [['sell', '38278.78', '0.47546355']], 'time': '2021-05-20T03:54:55.450670Z'}
{'type': 'l2update', 'product_id': 'BTC-USD', 'changes': [['sell', '38278.26', '0.00000000']], 'time': '2021-05-20T03:54:55.459503Z'}
{'type': 'l2update', 'product_id': 'BTC-USD', 'changes': [['sell', '38284.08', '2.14100000']], 'time': '2021-05-20T03:54:55.473941Z'}
{'type': 'l2update', 'product_id': 'BTC-USD', 'changes': [['sell', '38278.48', '0.00000000']], 'time': '2021-05-20T03:54:55.474066Z'}
{'type': 'l2update', 'product_id': 'BTC-USD', 'changes': [['buy', '38218.55', '0.00000000']], 'time': '2021-05-20T03:54:55.474354Z'}
{'type': 'l2update', 'product_id': 'BTC-USD', 'changes': [['buy', '38248.48', '0.00000000']], 'time': '2021-05-20T03:54:55.478574Z'}
{'type': 'l2update', 'product_id': 'BTC-USD', 'changes': [['buy', '38248.65', '0.00000000']], 'time': '2021-05-20T03:54:55.496981Z'}
{'type': 'l2update', 'product_id': 'BTC-USD', 'changes': [['buy', '38270.33', '0.01492000']], 'time': '2021-05-20T03:54:55.511328Z'}
{'type': 'l2update', 'product_id': 'BTC-USD', 'changes': [['sell', '38280.08', '0.00969407']], 'time': '2021-05-20T03:54:55.512571Z'}
{'type': 'l2update', 'product_id': 'BTC-USD', 'changes': [['sell', '38410.29', '0.00000000']], 'time': '2021-05-20T03:54:55.512768Z'}
{'type': 'l2update', 'product_id': 'BTC-USD', 'changes': [['sell', '38369.94', '0.00000000']], 'time': '2021-05-20T03:54:55.513517Z'}
{'type': 'l2update', 'product_id': 'BTC-USD', 'changes': [['buy', '38276.04', '0.00967521']], 'time': '2021-05-20T03:54:55.521131Z'}
{'type': 'l2update', 'product_id': 'BTC-USD', 'changes': [['sell', '38307.96', '0.00000000']], 'time': '2021-05-20T03:54:55.527288Z'}
{'type': 'l2update', 'product_id': 'BTC-USD', 'changes': [['sell', '38278.23', '0.07460000']], 'time': '2021-05-20T03:54:55.529241Z'}
{'type': 'l2update', 'product_id': 'BTC-USD', 'changes': [['buy', '38220.55', '0.10000000']], 'time': '2021-05-20T03:54:55.533218Z'}
{'type': 'l2update', 'product_id': 'BTC-USD', 'changes': [['sell', '38409.27', '0.00000000']], 'time': '2021-05-20T03:54:55.539544Z'}
{'type': 'l2update', 'product_id': 'BTC-USD', 'changes': [['buy', '38205.27', '0.00000000']], 'time': '2021-05-20T03:54:55.554865Z'}
{'type': 'l2update', 'product_id': 'BTC-USD', 'changes': [['sell', '38278.17', '0.01492000']], 'time': '2021-05-20T03:54:55.558066Z'}
{'type': 'l2update', 'product_id': 'BTC-USD', 'changes': [['sell', '38381.58', '0.03625153']], 'time': '2021-05-20T03:54:55.564136Z'}
{'type': 'l2update', 'product_id': 'BTC-USD', 'changes': [['buy', '38269.70', '0.05000000']], 'time': '2021-05-20T03:54:55.564470Z'}
{'type': 'l2update', 'product_id': 'BTC-USD', 'changes': [['buy', '38258.94', '0.00000000']], 'time': '2021-05-20T03:54:55.564875Z'}
{'type': 'l2update', 'product_id': 'BTC-USD', 'changes': [['sell', '38284.08', '1.09500000']], 'time': '2021-05-20T03:54:55.569656Z'}
{'type': 'l2update', 'product_id': 'BTC-USD', 'changes': [['buy', '38199.36', '0.00000000']], 'time': '2021-05-20T03:54:55.570645Z'}
{'type': 'l2update', 'product_id': 'BTC-USD', 'changes': [['buy', '38267.64', '0.04883826']], 'time': '2021-05-20T03:54:55.571468Z'}
{'type': 'l2update', 'product_id': 'BTC-USD', 'changes': [['sell', '39607.33', '0.00000000']], 'time': '2021-05-20T03:54:55.573110Z'}
{'type': 'l2update', 'product_id': 'BTC-USD', 'changes': [['sell', '38278.23', '0.00000000']], 'time': '2021-05-20T03:54:55.575666Z'}
{'type': 'l2update', 'product_id': 'BTC-USD', 'changes': [['sell', '38278.23', '0.20000000']], 'time': '2021-05-20T03:54:55.584225Z'}
{'type': 'l2update', 'product_id': 'BTC-USD', 'changes': [['sell', '38394.27', '0.01000000']], 'time': '2021-05-20T03:54:55.587665Z'}
{'type': 'l2update', 'product_id': 'BTC-USD', 'changes': [['buy', '38244.31', '0.00000000']], 'time': '2021-05-20T03:54:55.594424Z'}
{'type': 'l2update', 'product_id': 'BTC-USD', 'changes': [['sell', '38280.08', '0.00000000']], 'time': '2021-05-20T03:54:55.598663Z'}
{'type': 'l2update', 'product_id': 'BTC-USD', 'changes': [['buy', '38260.29', '0.00000000']], 'time': '2021-05-20T03:54:55.599946Z'}
{'type': 'l2update', 'product_id': 'BTC-USD', 'changes': [['sell', '38278.17', '0.00000000']], 'time': '2021-05-20T03:54:55.605875Z'}
{'type': 'l2update', 'product_id': 'BTC-USD', 'changes': [['buy', '38248.89', '0.48460000']], 'time': '2021-05-20T03:54:55.611719Z'}
{'type': 'l2update', 'product_id': 'BTC-USD', 'changes': [['sell', '51037.26', '0.00253500']], 'time': '2021-05-20T03:54:55.623550Z'}
{'type': 'l2update', 'product_id': 'BTC-USD', 'changes': [['sell', '38287.79', '0.99700000']], 'time': '2021-05-20T03:54:55.627983Z'}
{'type': 'l2update', 'product_id': 'BTC-USD', 'changes': [['buy', '38263.78', '0.00000000']], 'time': '2021-05-20T03:54:55.628897Z'}
{'type': 'l2update', 'product_id': 'BTC-USD', 'changes': [['buy', '38260.30', '0.58716278']], 'time': '2021-05-20T03:54:55.630677Z'}
{'type': 'l2update', 'product_id': 'BTC-USD', 'changes': [['sell', '38278.23', '0.30000000']], 'time': '2021-05-20T03:54:55.643151Z'}
{'type': 'l2update', 'product_id': 'BTC-USD', 'changes': [['buy', '38239.09', '0.12000000']], 'time': '2021-05-20T03:54:55.643280Z'}
{'type': 'l2update', 'product_id': 'BTC-USD', 'changes': [['buy', '38269.67', '0.00000000']], 'time': '2021-05-20T03:54:55.644289Z'}
{'type': 'l2update', 'product_id': 'BTC-USD', 'changes': [['buy', '37501.01', '0.00590000']], 'time': '2021-05-20T03:54:55.657409Z'}
{'type': 'l2update', 'product_id': 'BTC-USD', 'changes': [['sell', '38281.40', '0.00000000']], 'time': '2021-05-20T03:54:55.658732Z'}
{'type': 'l2update', 'product_id': 'BTC-USD', 'changes': [['sell', '38278.23', '0.29312795']], 'time': '2021-05-20T03:54:55.658991Z'}
{'type': 'l2update', 'product_id': 'BTC-USD', 'changes': [['buy', '38272.32', '0.05037069']], 'time': '2021-05-20T03:54:55.662677Z'}
{'type': 'l2update', 'product_id': 'BTC-USD', 'changes': [['sell', '38307.01', '0.43890000']], 'time': '2021-05-20T03:54:55.662780Z'}
{'type': 'l2update', 'product_id': 'BTC-USD', 'changes': [['buy', '38249.71', '0.00000000']], 'time': '2021-05-20T03:54:55.692170Z'}
{'type': 'l2update', 'product_id': 'BTC-USD', 'changes': [['buy', '38248.90', '0.00000000']], 'time': '2021-05-20T03:54:55.692170Z'}
{'type': 'l2update', 'product_id': 'BTC-USD', 'changes': [['buy', '38247.82', '0.00000000']], 'time': '2021-05-20T03:54:55.692170Z'}
{'type': 'l2update', 'product_id': 'BTC-USD', 'changes': [['sell', '38278.79', '0.00000000']], 'time': '2021-05-20T03:54:55.702920Z'}
{'type': 'l2update', 'product_id': 'BTC-USD', 'changes': [['sell', '38278.78', '0.00000000']], 'time': '2021-05-20T03:54:55.703205Z'}
{'type': 'l2update', 'product_id': 'BTC-USD', 'changes': [['buy', '38239.09', '0.09000000']], 'time': '2021-05-20T03:54:55.703517Z'}
{'type': 'l2update', 'product_id': 'BTC-USD', 'changes': [['sell', '38278.23', '0.10000000']], 'time': '2021-05-20T03:54:55.703933Z'}
{'type': 'l2update', 'product_id': 'BTC-USD', 'changes': [['buy', '38276.04', '0.00000000']], 'time': '2021-05-20T03:54:55.705137Z'}
{'type': 'l2update', 'product_id': 'BTC-USD', 'changes': [['buy', '38248.89', '0.00000000']], 'time': '2021-05-20T03:54:55.705336Z'}
{'type': 'l2update', 'product_id': 'BTC-USD', 'changes': [['sell', '38305.40', '0.00000000']], 'time': '2021-05-20T03:54:55.706263Z'}
{'type': 'l2update', 'product_id': 'BTC-USD', 'changes': [['buy', '38278.22', '0.02590000']], 'time': '2021-05-20T03:54:55.712273Z'}
{'type': 'l2update', 'product_id': 'BTC-USD', 'changes': [['buy', '38270.33', '0.00893970']], 'time': '2021-05-20T03:54:55.712792Z'}
{'type': 'l2update', 'product_id': 'BTC-USD', 'changes': [['buy', '38270.33', '0.00000000']], 'time': '2021-05-20T03:54:55.713016Z'}
{'type': 'l2update', 'product_id': 'BTC-USD', 'changes': [['buy', '38269.66', '0.00000000']], 'time': '2021-05-20T03:54:55.715040Z'}
{'type': 'l2update', 'product_id': 'BTC-USD', 'changes': [['buy', '38242.50', '0.04220602']], 'time': '2021-05-20T03:54:55.717012Z'}
{'type': 'l2update', 'product_id': 'BTC-USD', 'changes': [['buy', '38239.09', '0.05000000']], 'time': '2021-05-20T03:54:55.718230Z'}
{'type': 'l2update', 'product_id': 'BTC-USD', 'changes': [['sell', '38307.01', '0.00000000']], 'time': '2021-05-20T03:54:55.718405Z'}
{'type': 'l2update', 'product_id': 'BTC-USD', 'changes': [['buy', '38238.29', '0.00000000']], 'time': '2021-05-20T03:54:55.718559Z'}
{'type': 'l2update', 'product_id': 'BTC-USD', 'changes': [['buy', '38260.31', '0.11570201']], 'time': '2021-05-20T03:54:55.723126Z'}
{'type': 'l2update', 'product_id': 'BTC-USD', 'changes': [['buy', '38253.45', '0.02400000']], 'time': '2021-05-20T03:54:55.723242Z'}
{'type': 'l2update', 'product_id': 'BTC-USD', 'changes': [['buy', '38252.64', '0.02400000']], 'time': '2021-05-20T03:54:55.723242Z'}
{'type': 'l2update', 'product_id': 'BTC-USD', 'changes': [['buy', '38251.83', '0.02400000']], 'time': '2021-05-20T03:54:55.723242Z'}
{'type': 'l2update', 'product_id': 'BTC-USD', 'changes': [['buy', '38267.64', '0.00000000']], 'time': '2021-05-20T03:54:55.723743Z'}
{'type': 'l2update', 'product_id': 'BTC-USD', 'changes': [['sell', '38288.65', '0.04871924']], 'time': '2021-05-20T03:54:55.727447Z'}
{'type': 'l2update', 'product_id': 'BTC-USD', 'changes': [['sell', '39607.33', '0.24200000']], 'time': '2021-05-20T03:54:55.727594Z'}
{'type': 'l2update', 'product_id': 'BTC-USD', 'changes': [['buy', '38239.09', '0.00000000']], 'time': '2021-05-20T03:54:55.731783Z'}
{'type': 'l2update', 'product_id': 'BTC-USD', 'changes': [['sell', '38303.40', '0.00000000']], 'time': '2021-05-20T03:54:55.734213Z'}
{'type': 'l2update', 'product_id': 'BTC-USD', 'changes': [['sell', '38278.80', '0.50000000']], 'time': '2021-05-20T03:54:55.735634Z'}
{'type': 'l2update', 'product_id': 'BTC-USD', 'changes': [['sell', '38355.90', '0.00000000']], 'time': '2021-05-20T03:54:55.737056Z'}
{'type': 'l2update', 'product_id': 'BTC-USD', 'changes': [['buy', '38239.95', '0.00000000']], 'time': '2021-05-20T03:54:55.737161Z'}
{'type': 'l2update', 'product_id': 'BTC-USD', 'changes': [['buy', '38252.64', '0.00000000']], 'time': '2021-05-20T03:54:55.737945Z'}
{'type': 'l2update', 'product_id': 'BTC-USD', 'changes': [['buy', '38251.83', '0.00000000']], 'time': '2021-05-20T03:54:55.737945Z'}
{'type': 'l2update', 'product_id': 'BTC-USD', 'changes': [['buy', '38278.22', '0.27590000']], 'time': '2021-05-20T03:54:55.738047Z'}
{'type': 'l2update', 'product_id': 'BTC-USD', 'changes': [['sell', '38381.58', '0.00000000']], 'time': '2021-05-20T03:54:55.738188Z'}
{'type': 'l2update', 'product_id': 'BTC-USD', 'changes': [['sell', '38283.09', '2.48969908']], 'time': '2021-05-20T03:54:55.738238Z'}
{'type': 'l2update', 'product_id': 'BTC-USD', 'changes': [['sell', '38428.86', '0.00000000']], 'time': '2021-05-20T03:54:55.738947Z'}
{'type': 'l2update', 'product_id': 'BTC-USD', 'changes': [['buy', '38266.00', '0.05522417']], 'time': '2021-05-20T03:54:55.743227Z'}
{'type': 'l2update', 'product_id': 'BTC-USD', 'changes': [['buy', '38113.22', '0.05093916']], 'time': '2021-05-20T03:54:55.743741Z'}
{'type': 'l2update', 'product_id': 'BTC-USD', 'changes': [['buy', '38276.33', '0.04872299']], 'time': '2021-05-20T03:54:55.743784Z'}
{'type': 'l2update', 'product_id': 'BTC-USD', 'changes': [['sell', '38284.08', '0.54700000']], 'time': '2021-05-20T03:54:55.754898Z'}
{'type': 'l2update', 'product_id': 'BTC-USD', 'changes': [['buy', '38154.63', '0.00000000']], 'time': '2021-05-20T03:54:55.755516Z'}
{'type': 'l2update', 'product_id': 'BTC-USD', 'changes': [['buy', '38251.69', '0.01000000']], 'time': '2021-05-20T03:54:55.756087Z'}
{'type': 'l2update', 'product_id': 'BTC-USD', 'changes': [['sell', '38283.09', '2.96516263']], 'time': '2021-05-20T03:54:55.756097Z'}
{'type': 'l2update', 'product_id': 'BTC-USD', 'changes': [['buy', '38266.04', '0.52100000']], 'time': '2021-05-20T03:54:55.756194Z'}
{'type': 'l2update', 'product_id': 'BTC-USD', 'changes': [['sell', '38365.92', '0.13040000']], 'time': '2021-05-20T03:54:55.756298Z'}
{'type': 'l2update', 'product_id': 'BTC-USD', 'changes': [['buy', '38278.22', '0.25000000']], 'time': '2021-05-20T03:54:55.756425Z'}
{'type': 'l2update', 'product_id': 'BTC-USD', 'changes': [['buy', '38278.22', '0.00000000']], 'time': '2021-05-20T03:54:55.756496Z'}
{'type': 'l2update', 'product_id': 'BTC-USD', 'changes': [['sell', '38283.14', '0.00000000']], 'time': '2021-05-20T03:54:55.756800Z'}
{'type': 'l2update', 'product_id': 'BTC-USD', 'changes': [['buy', '38269.68', '0.00000000']], 'time': '2021-05-20T03:54:55.756922Z'}
{'type': 'l2update', 'product_id': 'BTC-USD', 'changes': [['sell', '38374.38', '0.01000000']], 'time': '2021-05-20T03:54:55.758862Z'}
{'type': 'l2update', 'product_id': 'BTC-USD', 'changes': [['sell', '38284.08', '0.00000000']], 'time': '2021-05-20T03:54:55.759301Z'}
{'type': 'l2update', 'product_id': 'BTC-USD', 'changes': [['sell', '38284.13', '0.00000000']], 'time': '2021-05-20T03:54:55.760184Z'}
{'type': 'l2update', 'product_id': 'BTC-USD', 'changes': [['sell', '38302.11', '0.00000000']], 'time': '2021-05-20T03:54:55.760900Z'}
{'type': 'l2update', 'product_id': 'BTC-USD', 'changes': [['sell', '38365.91', '0.03409489']], 'time': '2021-05-20T03:54:55.764221Z'}
{'type': 'l2update', 'product_id': 'BTC-USD', 'changes': [['sell', '38396.34', '0.13022077']], 'time': '2021-05-20T03:54:55.764423Z'}
{'type': 'l2update', 'product_id': 'BTC-USD', 'changes': [['buy', '38244.89', '0.04220602']], 'time': '2021-05-20T03:54:55.764881Z'}
{'type': 'l2update', 'product_id': 'BTC-USD', 'changes': [['sell', '38280.18', '0.00000000']], 'time': '2021-05-20T03:54:55.769139Z'}
{'type': 'l2update', 'product_id': 'BTC-USD', 'changes': [['sell', '38317.95', '0.00000000']], 'time': '2021-05-20T03:54:55.769169Z'}
{'type': 'l2update', 'product_id': 'BTC-USD', 'changes': [['buy', '38167.19', '0.03577500']], 'time': '2021-05-20T03:54:55.769757Z'}
{'type': 'l2update', 'product_id': 'BTC-USD', 'changes': [['buy', '38250.26', '0.02000000']], 'time': '2021-05-20T03:54:55.774712Z'}
{'type': 'l2update', 'product_id': 'BTC-USD', 'changes': [['sell', '38287.79', '1.54400000']], 'time': '2021-05-20T03:54:55.777226Z'}
{'type': 'l2update', 'product_id': 'BTC-USD', 'changes': [['buy', '38278.22', '0.01492000']], 'time': '2021-05-20T03:54:55.777466Z'}
{'type': 'l2update', 'product_id': 'BTC-USD', 'changes': [['buy', '38272.32', '0.00000000']], 'time': '2021-05-20T03:54:55.777639Z'}
{'type': 'l2update', 'product_id': 'BTC-USD', 'changes': [['sell', '38287.93', '0.56500000']], 'time': '2021-05-20T03:54:55.781137Z'}
{'type': 'l2update', 'product_id': 'BTC-USD', 'changes': [['buy', '38244.88', '0.00000000']], 'time': '2021-05-20T03:54:55.781207Z'}
{'type': 'l2update', 'product_id': 'BTC-USD', 'changes': [['buy', '37501.01', '0.00730000']], 'time': '2021-05-20T03:54:55.782878Z'}
{'type': 'l2update', 'product_id': 'BTC-USD', 'changes': [['buy', '38242.50', '0.00000000']], 'time': '2021-05-20T03:54:55.782980Z'}
{'type': 'l2update', 'product_id': 'BTC-USD', 'changes': [['buy', '38107.33', '0.00000000']], 'time': '2021-05-20T03:54:55.783383Z'}
{'type': 'l2update', 'product_id': 'BTC-USD', 'changes': [['buy', '38276.33', '0.00000000']], 'time': '2021-05-20T03:54:55.785900Z'}
{'type': 'l2update', 'product_id': 'BTC-USD', 'changes': [['buy', '38269.69', '0.10176519']], 'time': '2021-05-20T03:54:55.787914Z'}
{'type': 'l2update', 'product_id': 'BTC-USD', 'changes': [['buy', '38216.57', '1.54120000']], 'time': '2021-05-20T03:54:55.788178Z'}
{'type': 'l2update', 'product_id': 'BTC-USD', 'changes': [['sell', '38320.20', '0.04940571']], 'time': '2021-05-20T03:54:55.789143Z'}
{'type': 'l2update', 'product_id': 'BTC-USD', 'changes': [['buy', '38269.75', '0.52200000']], 'time': '2021-05-20T03:54:55.789444Z'}
{'type': 'l2update', 'product_id': 'BTC-USD', 'changes': [['buy', '38122.44', '0.05115795']], 'time': '2021-05-20T03:54:55.789796Z'}
{'type': 'l2update', 'product_id': 'BTC-USD', 'changes': [['sell', '38287.79', '0.54700000']], 'time': '2021-05-20T03:54:55.789836Z'}
{'type': 'l2update', 'product_id': 'BTC-USD', 'changes': [['sell', '38278.80', '0.00000000']], 'time': '2021-05-20T03:54:55.790740Z'}
{'type': 'l2update', 'product_id': 'BTC-USD', 'changes': [['buy', '38235.31', '0.00000000']], 'time': '2021-05-20T03:54:55.791136Z'}
{'type': 'l2update', 'product_id': 'BTC-USD', 'changes': [['buy', '38249.09', '0.03000000']], 'time': '2021-05-20T03:54:55.793940Z'}
{'type': 'l2update', 'product_id': 'BTC-USD', 'changes': [['buy', '38006.35', '0.00000000']], 'time': '2021-05-20T03:54:55.797363Z'}
{'type': 'l2update', 'product_id': 'BTC-USD', 'changes': [['sell', '38287.93', '0.00000000']], 'time': '2021-05-20T03:54:55.800729Z'}
{'type': 'l2update', 'product_id': 'BTC-USD', 'changes': [['buy', '38260.31', '0.00000000']], 'time': '2021-05-20T03:54:55.803960Z'}
{'type': 'l2update', 'product_id': 'BTC-USD', 'changes': [['sell', '38370.15', '0.00000000']], 'time': '2021-05-20T03:54:55.804005Z'}
{'type': 'l2update', 'product_id': 'BTC-USD', 'changes': [['buy', '38255.70', '0.02400000']], 'time': '2021-05-20T03:54:55.805383Z'}
{'type': 'l2update', 'product_id': 'BTC-USD', 'changes': [['buy', '38254.89', '0.02400000']], 'time': '2021-05-20T03:54:55.805383Z'}
{'type': 'l2update', 'product_id': 'BTC-USD', 'changes': [['sell', '38283.09', '0.47546355']], 'time': '2021-05-20T03:54:55.805414Z'}
{'type': 'l2update', 'product_id': 'BTC-USD', 'changes': [['sell', '38298.77', '0.01000000']], 'time': '2021-05-20T03:54:55.805747Z'}
{'type': 'l2update', 'product_id': 'BTC-USD', 'changes': [['sell', '38396.34', '0.00000000']], 'time': '2021-05-20T03:54:55.808937Z'}
{'type': 'l2update', 'product_id': 'BTC-USD', 'changes': [['buy', '38244.89', '0.00000000']], 'time': '2021-05-20T03:54:55.809181Z'}
{'type': 'l2update', 'product_id': 'BTC-USD', 'changes': [['sell', '38289.74', '0.00000000']], 'time': '2021-05-20T03:54:55.809891Z'}
{'type': 'l2update', 'product_id': 'BTC-USD', 'changes': [['sell', '38291.50', '0.52265672']], 'time': '2021-05-20T03:54:55.810509Z'}
{'type': 'l2update', 'product_id': 'BTC-USD', 'changes': [['buy', '38278.22', '0.00000000']], 'time': '2021-05-20T03:54:55.810935Z'}
{'type': 'l2update', 'product_id': 'BTC-USD', 'changes': [['buy', '38249.85', '0.00000000']], 'time': '2021-05-20T03:54:55.811350Z'}
{'type': 'l2update', 'product_id': 'BTC-USD', 'changes': [['sell', '38283.09', '0.00000000']], 'time': '2021-05-20T03:54:55.813366Z'}
{'type': 'l2update', 'product_id': 'BTC-USD', 'changes': [['sell', '38324.18', '0.07600000']], 'time': '2021-05-20T03:54:55.815643Z'}
{'type': 'l2update', 'product_id': 'BTC-USD', 'changes': [['buy', '38255.70', '0.00000000']], 'time': '2021-05-20T03:54:55.816583Z'}
{'type': 'l2update', 'product_id': 'BTC-USD', 'changes': [['sell', '38315.89', '0.04820440']], 'time': '2021-05-20T03:54:55.816660Z'}
{'type': 'l2update', 'product_id': 'BTC-USD', 'changes': [['sell', '38283.08', '0.50000000']], 'time': '2021-05-20T03:54:55.816938Z'}
{'type': 'l2update', 'product_id': 'BTC-USD', 'changes': [['buy', '38242.49', '0.00000000']], 'time': '2021-05-20T03:54:55.817781Z'}
{'type': 'l2update', 'product_id': 'BTC-USD', 'changes': [['sell', '38297.11', '1.28600000']], 'time': '2021-05-20T03:54:55.820694Z'}
{'type': 'l2update', 'product_id': 'BTC-USD', 'changes': [['sell', '38287.79', '0.00000000']], 'time': '2021-05-20T03:54:55.821287Z'}
{'type': 'l2update', 'product_id': 'BTC-USD', 'changes': [['buy', '38019.23', '0.05398650']], 'time': '2021-05-20T03:54:55.825623Z'}
{'type': 'l2update', 'product_id': 'BTC-USD', 'changes': [['buy', '38249.09', '0.07000000']], 'time': '2021-05-20T03:54:55.825984Z'}
{'type': 'l2update', 'product_id': 'BTC-USD', 'changes': [['buy', '38254.89', '0.00000000']], 'time': '2021-05-20T03:54:55.826871Z'}
{'type': 'l2update', 'product_id': 'BTC-USD', 'changes': [['sell', '38441.80', '0.00000000']], 'time': '2021-05-20T03:54:55.829176Z'}
{'type': 'l2update', 'product_id': 'BTC-USD', 'changes': [['buy', '38260.28', '0.00000000']], 'time': '2021-05-20T03:54:55.829322Z'}
{'type': 'l2update', 'product_id': 'BTC-USD', 'changes': [['buy', '38122.44', '0.00000000']], 'time': '2021-05-20T03:54:55.829994Z'}
{'type': 'l2update', 'product_id': 'BTC-USD', 'changes': [['sell', '38283.08', '0.00000000']], 'time': '2021-05-20T03:54:55.830560Z'}
{'type': 'l2update', 'product_id': 'BTC-USD', 'changes': [['buy', '38244.41', '0.44900000']], 'time': '2021-05-20T03:54:55.830668Z'}
{'type': 'l2update', 'product_id': 'BTC-USD', 'changes': [['buy', '38262.44', '0.52265672']], 'time': '2021-05-20T03:54:55.830860Z'}
{'type': 'l2update', 'product_id': 'BTC-USD', 'changes': [['buy', '38270.08', '0.07460000']], 'time': '2021-05-20T03:54:55.830874Z'}
{'type': 'l2update', 'product_id': 'BTC-USD', 'changes': [['sell', '38287.78', '2.48969908']], 'time': '2021-05-20T03:54:55.830890Z'}
{'type': 'l2update', 'product_id': 'BTC-USD', 'changes': [['sell', '38298.34', '0.00000000']], 'time': '2021-05-20T03:54:55.835629Z'}
{'type': 'l2update', 'product_id': 'BTC-USD', 'changes': [['sell', '38291.76', '0.54800000']], 'time': '2021-05-20T03:54:55.840799Z'}
{'type': 'l2update', 'product_id': 'BTC-USD', 'changes': [['buy', '38270.12', '0.01492000']], 'time': '2021-05-20T03:54:55.841085Z'}
{'type': 'l2update', 'product_id': 'BTC-USD', 'changes': [['buy', '38270.12', '0.01444030']], 'time': '2021-05-20T03:54:55.841169Z'}
{'type': 'l2update', 'product_id': 'BTC-USD', 'changes': [['sell', '39607.33', '0.00000000']], 'time': '2021-05-20T03:54:55.844948Z'}
{'type': 'l2update', 'product_id': 'BTC-USD', 'changes': [['sell', '38287.78', '2.96516263']], 'time': '2021-05-20T03:54:55.846849Z'}
{'type': 'l2update', 'product_id': 'BTC-USD', 'changes': [['buy', '38249.09', '0.12000000']], 'time': '2021-05-20T03:54:55.846946Z'}
{'type': 'l2update', 'product_id': 'BTC-USD', 'changes': [['buy', '38269.76', '0.05000000']], 'time': '2021-05-20T03:54:55.847038Z'}
{'type': 'l2update', 'product_id': 'BTC-USD', 'changes': [['sell', '38428.86', '0.13011056']], 'time': '2021-05-20T03:54:55.847449Z'}
{'type': 'l2update', 'product_id': 'BTC-USD', 'changes': [['buy', '38270.12', '0.00000000']], 'time': '2021-05-20T03:54:55.848837Z'}
{'type': 'l2update', 'product_id': 'BTC-USD', 'changes': [['buy', '38270.08', '0.00000000']], 'time': '2021-05-20T03:54:55.849767Z'}
{'type': 'l2update', 'product_id': 'BTC-USD', 'changes': [['sell', '38427.35', '0.01000000']], 'time': '2021-05-20T03:54:55.850559Z'}
{'type': 'l2update', 'product_id': 'BTC-USD', 'changes': [['sell', '38308.77', '0.49340000']], 'time': '2021-05-20T03:54:55.850622Z'}
{'type': 'l2update', 'product_id': 'BTC-USD', 'changes': [['sell', '38287.83', '0.50000000']], 'time': '2021-05-20T03:54:55.850692Z'}
{'type': 'l2update', 'product_id': 'BTC-USD', 'changes': [['sell', '38297.10', '0.05000000']], 'time': '2021-05-20T03:54:55.851273Z'}
{'type': 'l2update', 'product_id': 'BTC-USD', 'changes': [['buy', '38269.76', '0.16570201']], 'time': '2021-05-20T03:54:55.851696Z'}
{'type': 'l2update', 'product_id': 'BTC-USD', 'changes': [['sell', '38349.26', '0.00000000']], 'time': '2021-05-20T03:54:55.855886Z'}
{'type': 'l2update', 'product_id': 'BTC-USD', 'changes': [['buy', '38244.41', '0.00000000']], 'time': '2021-05-20T03:54:55.857269Z'}
{'type': 'l2update', 'product_id': 'BTC-USD', 'changes': [['sell', '51038.45', '0.00250300']], 'time': '2021-05-20T03:54:55.859930Z'}
{'type': 'l2update', 'product_id': 'BTC-USD', 'changes': [['buy', '38253.25', '0.02400000']], 'time': '2021-05-20T03:54:55.860104Z'}
{'type': 'l2update', 'product_id': 'BTC-USD', 'changes': [['buy', '38252.44', '0.02400000']], 'time': '2021-05-20T03:54:55.860104Z'}
{'type': 'l2update', 'product_id': 'BTC-USD', 'changes': [['sell', '38320.20', '0.00000000']], 'time': '2021-05-20T03:54:55.860459Z'}
{'type': 'l2update', 'product_id': 'BTC-USD', 'changes': [['sell', '38306.96', '0.04000000']], 'time': '2021-05-20T03:54:55.860718Z'}
{'type': 'l2update', 'product_id': 'BTC-USD', 'changes': [['buy', '38270.36', '0.07460000']], 'time': '2021-05-20T03:54:55.860823Z'}
{'type': 'l2update', 'product_id': 'BTC-USD', 'changes': [['sell', '38297.99', '0.04201003']], 'time': '2021-05-20T03:54:55.861107Z'}
{'type': 'l2update', 'product_id': 'BTC-USD', 'changes': [['buy', '38242.51', '0.04220602']], 'time': '2021-05-20T03:54:55.862236Z'}
{'type': 'l2update', 'product_id': 'BTC-USD', 'changes': [['buy', '38270.43', '0.01492000']], 'time': '2021-05-20T03:54:55.865014Z'}
{'type': 'l2update', 'product_id': 'BTC-USD', 'changes': [['buy', '38269.76', '0.26570201']], 'time': '2021-05-20T03:54:55.865155Z'}
{'type': 'l2update', 'product_id': 'BTC-USD', 'changes': [['buy', '38270.43', '0.00000000']], 'time': '2021-05-20T03:54:55.873928Z'}
{'type': 'l2update', 'product_id': 'BTC-USD', 'changes': [['buy', '38270.36', '0.00000000']], 'time': '2021-05-20T03:54:55.874465Z'}
{'type': 'l2update', 'product_id': 'BTC-USD', 'changes': [['buy', '38269.70', '0.00000000']], 'time': '2021-05-20T03:54:55.875093Z'}
{'type': 'l2update', 'product_id': 'BTC-USD', 'changes': [['buy', '38250.96', '0.04220602']], 'time': '2021-05-20T03:54:55.885592Z'}
{'type': 'l2update', 'product_id': 'BTC-USD', 'changes': [['sell', '38297.99', '0.00000000']], 'time': '2021-05-20T03:54:55.886734Z'}
{'type': 'l2update', 'product_id': 'BTC-USD', 'changes': [['buy', '38270.19', '0.01492000']], 'time': '2021-05-20T03:54:55.889359Z'}
{'type': 'l2update', 'product_id': 'BTC-USD', 'changes': [['buy', '38270.20', '0.07460000']], 'time': '2021-05-20T03:54:55.889879Z'}
{'type': 'l2update', 'product_id': 'BTC-USD', 'changes': [['buy', '38270.20', '0.00000000']], 'time': '2021-05-20T03:54:55.897112Z'}
{'type': 'l2update', 'product_id': 'BTC-USD', 'changes': [['sell', '38410.66', '0.00000000']], 'time': '2021-05-20T03:54:55.898786Z'}
{'type': 'l2update', 'product_id': 'BTC-USD', 'changes': [['buy', '38270.19', '0.00000000']], 'time': '2021-05-20T03:54:55.899880Z'}
{'type': 'l2update', 'product_id': 'BTC-USD', 'changes': [['sell', '38287.78', '2.48969908']], 'time': '2021-05-20T03:54:55.904564Z'}
{'type': 'l2update', 'product_id': 'BTC-USD', 'changes': [['sell', '38428.86', '0.00000000']], 'time': '2021-05-20T03:54:55.907621Z'}
{'type': 'l2update', 'product_id': 'BTC-USD', 'changes': [['buy', '38250.01', '0.05001321']], 'time': '2021-05-20T03:54:55.908523Z'}
{'type': 'l2update', 'product_id': 'BTC-USD', 'changes': [['sell', '38290.68', '0.05531830']], 'time': '2021-05-20T03:54:55.908523Z'}
{'type': 'l2update', 'product_id': 'BTC-USD', 'changes': [['sell', '38423.77', '0.02026400']], 'time': '2021-05-20T03:54:55.909430Z'}
{'type': 'l2update', 'product_id': 'BTC-USD', 'changes': [['buy', '38242.51', '0.00000000']], 'time': '2021-05-20T03:54:55.915364Z'}
{'type': 'l2update', 'product_id': 'BTC-USD', 'changes': [['buy', '38270.36', '0.07460000']], 'time': '2021-05-20T03:54:55.915885Z'}
{'type': 'l2update', 'product_id': 'BTC-USD', 'changes': [['buy', '38270.30', '0.01492000']], 'time': '2021-05-20T03:54:55.915992Z'}
{'type': 'l2update', 'product_id': 'BTC-USD', 'changes': [['buy', '38269.76', '0.15000000']], 'time': '2021-05-20T03:54:55.918961Z'}
{'type': 'l2update', 'product_id': 'BTC-USD', 'changes': [['sell', '38454.88', '0.02166780']], 'time': '2021-05-20T03:54:55.920777Z'}
{'type': 'l2update', 'product_id': 'BTC-USD', 'changes': [['sell', '38278.23', '0.09799725']], 'time': '2021-05-20T03:54:55.922160Z'}
{'type': 'l2update', 'product_id': 'BTC-USD', 'changes': [['buy', '38173.93', '0.00000000']], 'time': '2021-05-20T03:54:55.922701Z'}
{'type': 'l2update', 'product_id': 'BTC-USD', 'changes': [['sell', '38365.91', '0.00000000']], 'time': '2021-05-20T03:54:55.923153Z'}
{'type': 'l2update', 'product_id': 'BTC-USD', 'changes': [['buy', '38270.30', '0.00000000']], 'time': '2021-05-20T03:54:55.924413Z'}
{'type': 'l2update', 'product_id': 'BTC-USD', 'changes': [['buy', '38270.36', '0.00000000']], 'time': '2021-05-20T03:54:55.925383Z'}
{'type': 'l2update', 'product_id': 'BTC-USD', 'changes': [['buy', '38212.36', '0.12271041']], 'time': '2021-05-20T03:54:55.926082Z'}
{'type': 'l2update', 'product_id': 'BTC-USD', 'changes': [['sell', '38301.19', '0.04201003']], 'time': '2021-05-20T03:54:55.926419Z'}
{'type': 'l2update', 'product_id': 'BTC-USD', 'changes': [['sell', '38454.88', '0.00000000']], 'time': '2021-05-20T03:54:55.930684Z'}
{'type': 'l2update', 'product_id': 'BTC-USD', 'changes': [['sell', '38287.77', '0.47546355']], 'time': '2021-05-20T03:54:55.936279Z'}
{'type': 'l2update', 'product_id': 'BTC-USD', 'changes': [['buy', '38270.07', '0.01492000']], 'time': '2021-05-20T03:54:55.944090Z'}
{'type': 'l2update', 'product_id': 'BTC-USD', 'changes': [['sell', '38428.86', '0.06523440']], 'time': '2021-05-20T03:54:55.944733Z'}
{'type': 'l2update', 'product_id': 'BTC-USD', 'changes': [['buy', '38270.09', '0.07460000']], 'time': '2021-05-20T03:54:55.944820Z'}
{'type': 'l2update', 'product_id': 'BTC-USD', 'changes': [['buy', '38250.96', '0.00000000']], 'time': '2021-05-20T03:54:55.945285Z'}
{'type': 'l2update', 'product_id': 'BTC-USD', 'changes': [['buy', '38270.09', '0.00000000']], 'time': '2021-05-20T03:54:55.950934Z'}
{'type': 'l2update', 'product_id': 'BTC-USD', 'changes': [['buy', '38270.07', '0.00000000']], 'time': '2021-05-20T03:54:55.951727Z'}
{'type': 'l2update', 'product_id': 'BTC-USD', 'changes': [['sell', '38377.73', '0.05953365']], 'time': '2021-05-20T03:54:55.952369Z'}
{'type': 'l2update', 'product_id': 'BTC-USD', 'changes': [['buy', '38269.69', '0.00176519']], 'time': '2021-05-20T03:54:55.952524Z'}
{'type': 'l2update', 'product_id': 'BTC-USD', 'changes': [['sell', '38287.83', '0.00000000']], 'time': '2021-05-20T03:54:55.954238Z'}
{'type': 'l2update', 'product_id': 'BTC-USD', 'changes': [['buy', '38252.76', '0.40980000']], 'time': '2021-05-20T03:54:55.954905Z'}
{'type': 'l2update', 'product_id': 'BTC-USD', 'changes': [['buy', '38262.77', '0.00000000']], 'time': '2021-05-20T03:54:55.958679Z'}
{'type': 'l2update', 'product_id': 'BTC-USD', 'changes': [['buy', '38269.75', '0.00000000']], 'time': '2021-05-20T03:54:55.959379Z'}
{'type': 'l2update', 'product_id': 'BTC-USD', 'changes': [['buy', '38266.04', '0.00000000']], 'time': '2021-05-20T03:54:55.962421Z'}
{'type': 'l2update', 'product_id': 'BTC-USD', 'changes': [['buy', '38239.95', '0.04220602']], 'time': '2021-05-20T03:54:55.962842Z'}
{'type': 'l2update', 'product_id': 'BTC-USD', 'changes': [['buy', '38270.44', '0.07460000']], 'time': '2021-05-20T03:54:55.962882Z'}
{'type': 'l2update', 'product_id': 'BTC-USD', 'changes': [['sell', '38380.63', '0.00000000']], 'time': '2021-05-20T03:54:55.966239Z'}
{'type': 'l2update', 'product_id': 'BTC-USD', 'changes': [['buy', '38270.10', '0.01492000']], 'time': '2021-05-20T03:54:55.967324Z'}
{'type': 'l2update', 'product_id': 'BTC-USD', 'changes': [['sell', '38283.09', '0.50000000']], 'time': '2021-05-20T03:54:55.971754Z'}
{'type': 'l2update', 'product_id': 'BTC-USD', 'changes': [['buy', '38270.10', '0.00000000']], 'time': '2021-05-20T03:54:55.973201Z'}
{'type': 'l2update', 'product_id': 'BTC-USD', 'changes': [['sell', '38287.72', '0.54800000']], 'time': '2021-05-20T03:54:55.974971Z'}
{'type': 'l2update', 'product_id': 'BTC-USD', 'changes': [['buy', '38266.05', '0.11570201']], 'time': '2021-05-20T03:54:55.975253Z'}
{'type': 'l2update', 'product_id': 'BTC-USD', 'changes': [['sell', '38403.97', '0.01000000']], 'time': '2021-05-20T03:54:55.980896Z'}
{'type': 'l2update', 'product_id': 'BTC-USD', 'changes': [['buy', '38235.31', '1.20000000']], 'time': '2021-05-20T03:54:55.988043Z'}
{'type': 'l2update', 'product_id': 'BTC-USD', 'changes': [['sell', '38370.15', '1.20000000']], 'time': '2021-05-20T03:54:55.999598Z'}
{'type': 'l2update', 'product_id': 'BTC-USD', 'changes': [['sell', '38356.00', '0.00000000']], 'time': '2021-05-20T03:54:56.005364Z'}
{'type': 'l2update', 'product_id': 'BTC-USD', 'changes': [['sell', '51053.04', '0.00250300']], 'time': '2021-05-20T03:54:56.019875Z'}
{'type': 'l2update', 'product_id': 'BTC-USD', 'changes': [['buy', '38278.22', '0.01492000']], 'time': '2021-05-20T03:54:56.024406Z'}
{'type': 'l2update', 'product_id': 'BTC-USD', 'changes': [['sell', '38290.68', '0.00000000']], 'time': '2021-05-20T03:54:56.025933Z'}
{'type': 'l2update', 'product_id': 'BTC-USD', 'changes': [['sell', '38287.77', '0.00000000']], 'time': '2021-05-20T03:54:56.027317Z'}
{'type': 'l2update', 'product_id': 'BTC-USD', 'changes': [['sell', '38374.14', '0.01302960']], 'time': '2021-05-20T03:54:56.028618Z'}
{'type': 'l2update', 'product_id': 'BTC-USD', 'changes': [['buy', '38269.69', '0.00000000']], 'time': '2021-05-20T03:54:56.029012Z'}
{'type': 'l2update', 'product_id': 'BTC-USD', 'changes': [['buy', '38270.44', '0.00000000']], 'time': '2021-05-20T03:54:56.030569Z'}
{'type': 'l2update', 'product_id': 'BTC-USD', 'changes': [['buy', '38266.05', '0.00000000']], 'time': '2021-05-20T03:54:56.031584Z'}
{'type': 'l2update', 'product_id': 'BTC-USD', 'changes': [['sell', '38297.10', '0.00000000']], 'time': '2021-05-20T03:54:56.032588Z'}
{'type': 'l2update', 'product_id': 'BTC-USD', 'changes': [['sell', '38308.77', '0.00000000']], 'time': '2021-05-20T03:54:56.037972Z'}
{'type': 'l2update', 'product_id': 'BTC-USD', 'changes': [['buy', '38266.10', '0.52100000']], 'time': '2021-05-20T03:54:56.041757Z'}
{'type': 'l2update', 'product_id': 'BTC-USD', 'changes': [['sell', '38303.18', '0.05000000']], 'time': '2021-05-20T03:54:56.042169Z'}
{'type': 'l2update', 'product_id': 'BTC-USD', 'changes': [['sell', '38283.08', '0.47546355']], 'time': '2021-05-20T03:54:56.047492Z'}
{'type': 'l2update', 'product_id': 'BTC-USD', 'changes': [['buy', '38278.22', '0.00000000']], 'time': '2021-05-20T03:54:56.047936Z'}
{'type': 'l2update', 'product_id': 'BTC-USD', 'changes': [['buy', '38260.30', '0.00000000']], 'time': '2021-05-20T03:54:56.048441Z'}
{'type': 'l2update', 'product_id': 'BTC-USD', 'changes': [['sell', '38307.40', '0.46600000']], 'time': '2021-05-20T03:54:56.051754Z'}
{'type': 'l2update', 'product_id': 'BTC-USD', 'changes': [['sell', '38297.32', '0.05578842']], 'time': '2021-05-20T03:54:56.051875Z'}
{'type': 'l2update', 'product_id': 'BTC-USD', 'changes': [['sell', '38303.18', '0.00000000']], 'time': '2021-05-20T03:54:56.056186Z'}
{'type': 'l2update', 'product_id': 'BTC-USD', 'changes': [['buy', '38262.73', '0.11570201']], 'time': '2021-05-20T03:54:56.058310Z'}
{'type': 'l2update', 'product_id': 'BTC-USD', 'changes': [['buy', '38270.15', '0.04672727']], 'time': '2021-05-20T03:54:56.064920Z'}
{'type': 'l2update', 'product_id': 'BTC-USD', 'changes': [['buy', '38270.07', '0.01492000']], 'time': '2021-05-20T03:54:56.065084Z'}
{'type': 'l2update', 'product_id': 'BTC-USD', 'changes': [['buy', '38262.73', '0.70286479']], 'time': '2021-05-20T03:54:56.067018Z'}
{'type': 'l2update', 'product_id': 'BTC-USD', 'changes': [['sell', '38297.10', '0.05000000']], 'time': '2021-05-20T03:54:56.067221Z'}
{'type': 'l2update', 'product_id': 'BTC-USD', 'changes': [['buy', '38270.15', '0.07153450']], 'time': '2021-05-20T03:54:56.070715Z'}
{'type': 'l2update', 'product_id': 'BTC-USD', 'changes': [['buy', '38270.07', '0.00000000']], 'time': '2021-05-20T03:54:56.072775Z'}
{'type': 'l2update', 'product_id': 'BTC-USD', 'changes': [['sell', '38338.48', '0.00000000']], 'time': '2021-05-20T03:54:56.074688Z'}
{'type': 'l2update', 'product_id': 'BTC-USD', 'changes': [['sell', '38426.73', '0.00000000']], 'time': '2021-05-20T03:54:56.077633Z'}
{'type': 'l2update', 'product_id': 'BTC-USD', 'changes': [['buy', '38217.92', '0.00000000']], 'time': '2021-05-20T03:54:56.079130Z'}
{'type': 'l2update', 'product_id': 'BTC-USD', 'changes': [['buy', '38272.32', '0.00176519']], 'time': '2021-05-20T03:54:56.079142Z'}
{'type': 'l2update', 'product_id': 'BTC-USD', 'changes': [['buy', '38252.76', '0.00000000']], 'time': '2021-05-20T03:54:56.079656Z'}
{'type': 'l2update', 'product_id': 'BTC-USD', 'changes': [['sell', '38307.40', '0.00000000']], 'time': '2021-05-20T03:54:56.083717Z'}
{'type': 'l2update', 'product_id': 'BTC-USD', 'changes': [['sell', '38451.32', '0.01000000']], 'time': '2021-05-20T03:54:56.091413Z'}
{'type': 'l2update', 'product_id': 'BTC-USD', 'changes': [['buy', '38214.62', '1.28345538']], 'time': '2021-05-20T03:54:56.096269Z'}
{'type': 'l2update', 'product_id': 'BTC-USD', 'changes': [['buy', '38255.49', '0.46080000']], 'time': '2021-05-20T03:54:56.096623Z'}
{'type': 'l2update', 'product_id': 'BTC-USD', 'changes': [['buy', '38255.49', '0.00000000']], 'time': '2021-05-20T03:54:56.102615Z'}
{'type': 'l2update', 'product_id': 'BTC-USD', 'changes': [['sell', '38301.19', '0.00000000']], 'time': '2021-05-20T03:54:56.107426Z'}
{'type': 'l2update', 'product_id': 'BTC-USD', 'changes': [['buy', '38250.01', '0.00000000']], 'time': '2021-05-20T03:54:56.125739Z'}
{'type': 'l2update', 'product_id': 'BTC-USD', 'changes': [['sell', '38297.32', '0.00000000']], 'time': '2021-05-20T03:54:56.125739Z'}
{'type': 'l2update', 'product_id': 'BTC-USD', 'changes': [['sell', '38298.40', '0.04201003']], 'time': '2021-05-20T03:54:56.127695Z'}
{'type': 'l2update', 'product_id': 'BTC-USD', 'changes': [['buy', '38262.73', '0.58716278']], 'time': '2021-05-20T03:54:56.130976Z'}
{'type': 'l2update', 'product_id': 'BTC-USD', 'changes': [['sell', '38325.44', '0.01000000']], 'time': '2021-05-20T03:54:56.131838Z'}
{'type': 'l2update', 'product_id': 'BTC-USD', 'changes': [['buy', '38243.12', '0.01000000']], 'time': '2021-05-20T03:54:56.144513Z'}
{'type': 'l2update', 'product_id': 'BTC-USD', 'changes': [['buy', '38266.11', '0.11570201']], 'time': '2021-05-20T03:54:56.153083Z'}
{'type': 'l2update', 'product_id': 'BTC-USD', 'changes': [['buy', '25100.00', '14.20864922']], 'time': '2021-05-20T03:54:56.156833Z'}
{'type': 'l2update', 'product_id': 'BTC-USD', 'changes': [['buy', '38253.32', '0.04134247']], 'time': '2021-05-20T03:54:56.156944Z'}
{'type': 'l2update', 'product_id': 'BTC-USD', 'changes': [['sell', '38296.74', '0.04314452']], 'time': '2021-05-20T03:54:56.156944Z'}
{'type': 'l2update', 'product_id': 'BTC-USD', 'changes': [['buy', '38270.38', '0.01492000']], 'time': '2021-05-20T03:54:56.160637Z'}
{'type': 'l2update', 'product_id': 'BTC-USD', 'changes': [['sell', '38298.40', '0.00000000']], 'time': '2021-05-20T03:54:56.164716Z'}
{'type': 'l2update', 'product_id': 'BTC-USD', 'changes': [['sell', '38311.80', '0.43190000']], 'time': '2021-05-20T03:54:56.173616Z'}
{'type': 'l2update', 'product_id': 'BTC-USD', 'changes': [['sell', '52377.00', '0.00202500']], 'time': '2021-05-20T03:54:56.203429Z'}
{'type': 'l2update', 'product_id': 'BTC-USD', 'changes': [['sell', '43100.00', '1.09530000']], 'time': '2021-05-20T03:54:56.215729Z'}
{'type': 'l2update', 'product_id': 'BTC-USD', 'changes': [['sell', '38325.44', '0.00000000']], 'time': '2021-05-20T03:54:56.239626Z'}
{'type': 'l2update', 'product_id': 'BTC-USD', 'changes': [['sell', '38287.78', '0.00000000']], 'time': '2021-05-20T03:54:56.259834Z'}
{'type': 'l2update', 'product_id': 'BTC-USD', 'changes': [['sell', '38278.23', '0.07239249']], 'time': '2021-05-20T03:54:56.335573Z'}
{'type': 'l2update', 'product_id': 'BTC-USD', 'changes': [['buy', '38272.32', '0.00000000']], 'time': '2021-05-20T03:54:56.382283Z'}
{'type': 'l2update', 'product_id': 'BTC-USD', 'changes': [['buy', '38253.45', '0.00000000']], 'time': '2021-05-20T03:54:56.412000Z'}
{'type': 'l2update', 'product_id': 'BTC-USD', 'changes': [['buy', '38253.25', '0.00000000']], 'time': '2021-05-20T03:54:56.412000Z'}
{'type': 'l2update', 'product_id': 'BTC-USD', 'changes': [['buy', '38252.44', '0.00000000']], 'time': '2021-05-20T03:54:56.412000Z'}
{'type': 'l2update', 'product_id': 'BTC-USD', 'changes': [['buy', '38270.15', '0.04672727']], 'time': '2021-05-20T03:54:56.419691Z'}
{'type': 'l2update', 'product_id': 'BTC-USD', 'changes': [['buy', '38270.15', '0.00000000']], 'time': '2021-05-20T03:54:56.419787Z'}
{'type': 'l2update', 'product_id': 'BTC-USD', 'changes': [['buy', '38266.11', '0.00000000']], 'time': '2021-05-20T03:54:56.422860Z'}
{'type': 'l2update', 'product_id': 'BTC-USD', 'changes': [['buy', '38270.38', '0.00000000']], 'time': '2021-05-20T03:54:56.423329Z'}
{'type': 'l2update', 'product_id': 'BTC-USD', 'changes': [['buy', '38220.55', '0.00000000']], 'time': '2021-05-20T03:54:56.423726Z'}
{'type': 'l2update', 'product_id': 'BTC-USD', 'changes': [['buy', '38256.56', '0.44820000']], 'time': '2021-05-20T03:54:56.435660Z'}
{'type': 'l2update', 'product_id': 'BTC-USD', 'changes': [['buy', '38243.12', '0.00000000']], 'time': '2021-05-20T03:54:56.440768Z'}
{'type': 'l2update', 'product_id': 'BTC-USD', 'changes': [['sell', '43100.00', '3.94610000']], 'time': '2021-05-20T03:54:56.452362Z'}
{'type': 'l2update', 'product_id': 'BTC-USD', 'changes': [['sell', '38283.07', '2.48969908']], 'time': '2021-05-20T03:54:56.460016Z'}
{'type': 'l2update', 'product_id': 'BTC-USD', 'changes': [['buy', '38266.10', '0.00000000']], 'time': '2021-05-20T03:54:56.462920Z'}
{'type': 'l2update', 'product_id': 'BTC-USD', 'changes': [['buy', '38272.32', '0.00176519']], 'time': '2021-05-20T03:54:56.482497Z'}
{'type': 'l2update', 'product_id': 'BTC-USD', 'changes': [['sell', '38303.46', '0.00000000']], 'time': '2021-05-20T03:54:56.505722Z'}
{'type': 'l2update', 'product_id': 'BTC-USD', 'changes': [['sell', '38287.79', '1.06400000']], 'time': '2021-05-20T03:54:56.531579Z'}
{'type': 'l2update', 'product_id': 'BTC-USD', 'changes': [['buy', '38225.55', '0.10000000']], 'time': '2021-05-20T03:54:56.532008Z'}
{'type': 'l2update', 'product_id': 'BTC-USD', 'changes': [['buy', '38270.14', '0.01492000']], 'time': '2021-05-20T03:54:56.532608Z'}
{'type': 'l2update', 'product_id': 'BTC-USD', 'changes': [['buy', '38256.56', '0.00000000']], 'time': '2021-05-20T03:54:56.542241Z'}
{'type': 'l2update', 'product_id': 'BTC-USD', 'changes': [['buy', '38262.73', '0.00000000']], 'time': '2021-05-20T03:54:56.543473Z'}
{'type': 'l2update', 'product_id': 'BTC-USD', 'changes': [['sell', '38304.35', '0.00000000']], 'time': '2021-05-20T03:54:56.545016Z'}
{'type': 'l2update', 'product_id': 'BTC-USD', 'changes': [['sell', '38283.03', '0.54700000']], 'time': '2021-05-20T03:54:56.552377Z'}
{'type': 'l2update', 'product_id': 'BTC-USD', 'changes': [['buy', '38262.78', '0.52100000']], 'time': '2021-05-20T03:54:56.552495Z'}
{'type': 'l2update', 'product_id': 'BTC-USD', 'changes': [['buy', '38113.22', '0.00000000']], 'time': '2021-05-20T03:54:56.562055Z'}
{'type': 'l2update', 'product_id': 'BTC-USD', 'changes': [['buy', '38267.67', '0.10000000']], 'time': '2021-05-20T03:54:56.587823Z'}
{'type': 'l2update', 'product_id': 'BTC-USD', 'changes': [['sell', '38278.23', '0.07114683']], 'time': '2021-05-20T03:54:56.590459Z'}
{'type': 'l2update', 'product_id': 'BTC-USD', 'changes': [['buy', '38272.32', '0.00000000']], 'time': '2021-05-20T03:54:56.592292Z'}
{'type': 'l2update', 'product_id': 'BTC-USD', 'changes': [['buy', '38270.14', '0.00881097']], 'time': '2021-05-20T03:54:56.592292Z'}
{'type': 'l2update', 'product_id': 'BTC-USD', 'changes': [['sell', '38301.09', '0.04201003']], 'time': '2021-05-20T03:54:56.597831Z'}
{'type': 'l2update', 'product_id': 'BTC-USD', 'changes': [['sell', '52380.74', '0.00184400']], 'time': '2021-05-20T03:54:56.597841Z'}
{'type': 'l2update', 'product_id': 'BTC-USD', 'changes': [['buy', '38270.21', '0.00143159']], 'time': '2021-05-20T03:54:56.625635Z'}
{'type': 'l2update', 'product_id': 'BTC-USD', 'changes': [['buy', '38270.21', '0.07460000']], 'time': '2021-05-20T03:54:56.627630Z'}
{'type': 'l2update', 'product_id': 'BTC-USD', 'changes': [['buy', '37500.02', '0.00000000']], 'time': '2021-05-20T03:54:56.640416Z'}
{'type': 'l2update', 'product_id': 'BTC-USD', 'changes': [['buy', '37500.01', '0.12840000']], 'time': '2021-05-20T03:54:56.640416Z'}
{'type': 'l2update', 'product_id': 'BTC-USD', 'changes': [['buy', '37500.01', '0.18840000']], 'time': '2021-05-20T03:54:56.643926Z'}
{'type': 'l2update', 'product_id': 'BTC-USD', 'changes': [['sell', '38283.09', '0.00000000']], 'time': '2021-05-20T03:54:56.681288Z'}
{'type': 'l2update', 'product_id': 'BTC-USD', 'changes': [['sell', '38278.23', '0.05162355']], 'time': '2021-05-20T03:54:56.685481Z'}
{'type': 'l2update', 'product_id': 'BTC-USD', 'changes': [['sell', '38311.80', '0.00000000']], 'time': '2021-05-20T03:54:56.767331Z'}
{'type': 'l2update', 'product_id': 'BTC-USD', 'changes': [['sell', '38278.23', '0.05037550']], 'time': '2021-05-20T03:54:56.775388Z'}
{'type': 'l2update', 'product_id': 'BTC-USD', 'changes': [['buy', '38260.24', '0.58716278']], 'time': '2021-05-20T03:54:56.775398Z'}
{'type': 'l2update', 'product_id': 'BTC-USD', 'changes': [['buy', '38266.12', '0.11570201']], 'time': '2021-05-20T03:54:56.778921Z'}
{'type': 'l2update', 'product_id': 'BTC-USD', 'changes': [['buy', '38269.67', '0.00428000']], 'time': '2021-05-20T03:54:56.840758Z'}
{'type': 'l2update', 'product_id': 'BTC-USD', 'changes': [['buy', '38270.21', '0.00143159']], 'time': '2021-05-20T03:54:56.920003Z'}
{'type': 'l2update', 'product_id': 'BTC-USD', 'changes': [['sell', '38306.96', '0.00000000']], 'time': '2021-05-20T03:54:56.923545Z'}
{'type': 'l2update', 'product_id': 'BTC-USD', 'changes': [['buy', '38270.21', '0.00000000']], 'time': '2021-05-20T03:54:56.924487Z'}
{'type': 'l2update', 'product_id': 'BTC-USD', 'changes': [['sell', '38327.31', '0.00000000']], 'time': '2021-05-20T03:54:56.925596Z'}
{'type': 'l2update', 'product_id': 'BTC-USD', 'changes': [['buy', '38270.14', '0.00000000']], 'time': '2021-05-20T03:54:56.927672Z'}
{'type': 'l2update', 'product_id': 'BTC-USD', 'changes': [['buy', '38210.73', '0.00000000']], 'time': '2021-05-20T03:54:56.928463Z'}
{'type': 'l2update', 'product_id': 'BTC-USD', 'changes': [['sell', '38393.62', '0.00000000']], 'time': '2021-05-20T03:54:56.928463Z'}
{'type': 'l2update', 'product_id': 'BTC-USD', 'changes': [['sell', '39607.33', '0.24200000']], 'time': '2021-05-20T03:54:56.934988Z'}
{'type': 'l2update', 'product_id': 'BTC-USD', 'changes': [['sell', '38278.22', '0.50000000']], 'time': '2021-05-20T03:54:56.935224Z'}
{'type': 'l2update', 'product_id': 'BTC-USD', 'changes': [['sell', '38305.35', '0.04879890']], 'time': '2021-05-20T03:54:56.936105Z'}
{'type': 'l2update', 'product_id': 'BTC-USD', 'changes': [['buy', '38270.46', '0.00610903']], 'time': '2021-05-20T03:54:56.939923Z'}
{'type': 'l2update', 'product_id': 'BTC-USD', 'changes': [['buy', '38209.47', '0.00000000']], 'time': '2021-05-20T03:54:56.941117Z'}
{'type': 'l2update', 'product_id': 'BTC-USD', 'changes': [['buy', '38225.55', '0.00000000']], 'time': '2021-05-20T03:54:56.941767Z'}
{'type': 'l2update', 'product_id': 'BTC-USD', 'changes': [['sell', '38283.08', '0.00000000']], 'time': '2021-05-20T03:54:56.942780Z'}
{'type': 'l2update', 'product_id': 'BTC-USD', 'changes': [['sell', '38421.79', '0.00000000']], 'time': '2021-05-20T03:54:56.943061Z'}
{'type': 'l2update', 'product_id': 'BTC-USD', 'changes': [['buy', '38273.64', '0.00973279']], 'time': '2021-05-20T03:54:56.948315Z'}
{'type': 'l2update', 'product_id': 'BTC-USD', 'changes': [['sell', '38279.57', '0.00868102']], 'time': '2021-05-20T03:54:56.948315Z'}
{'type': 'l2update', 'product_id': 'BTC-USD', 'changes': [['buy', '38271.88', '0.04860278']], 'time': '2021-05-20T03:54:56.948925Z'}
{'type': 'l2update', 'product_id': 'BTC-USD', 'changes': [['buy', '38272.32', '0.00176519']], 'time': '2021-05-20T03:54:56.991217Z'}
{'type': 'l2update', 'product_id': 'BTC-USD', 'changes': [['sell', '38301.09', '0.00000000']], 'time': '2021-05-20T03:54:56.995609Z'}
{'type': 'l2update', 'product_id': 'BTC-USD', 'changes': [['buy', '37500.01', '0.18610000']], 'time': '2021-05-20T03:54:57.012056Z'}
{'type': 'l2update', 'product_id': 'BTC-USD', 'changes': [['buy', '38270.27', '0.07316841']], 'time': '2021-05-20T03:54:57.016739Z'}
{'type': 'l2update', 'product_id': 'BTC-USD', 'changes': [['buy', '38201.33', '0.03521768']], 'time': '2021-05-20T03:54:57.016815Z'}
{'type': 'l2update', 'product_id': 'BTC-USD', 'changes': [['buy', '38206.63', '0.02663544']], 'time': '2021-05-20T03:54:57.016815Z'}
{'type': 'l2update', 'product_id': 'BTC-USD', 'changes': [['sell', '38278.23', '0.00000000']], 'time': '2021-05-20T03:54:57.019503Z'}
{'type': 'l2update', 'product_id': 'BTC-USD', 'changes': [['sell', '38296.87', '0.02000000']], 'time': '2021-05-20T03:54:57.020390Z'}
{'type': 'l2update', 'product_id': 'BTC-USD', 'changes': [['buy', '38270.17', '0.00881097']], 'time': '2021-05-20T03:54:57.024595Z'}
{'type': 'l2update', 'product_id': 'BTC-USD', 'changes': [['buy', '38249.70', '0.17700000']], 'time': '2021-05-20T03:54:57.036200Z'}
{'type': 'l2update', 'product_id': 'BTC-USD', 'changes': [['buy', '38269.76', '0.05000000']], 'time': '2021-05-20T03:54:57.037100Z'}
{'type': 'l2update', 'product_id': 'BTC-USD', 'changes': [['buy', '38270.46', '0.00000000']], 'time': '2021-05-20T03:54:57.038034Z'}
{'type': 'l2update', 'product_id': 'BTC-USD', 'changes': [['sell', '38451.32', '0.00000000']], 'time': '2021-05-20T03:54:57.038070Z'}
{'type': 'l2update', 'product_id': 'BTC-USD', 'changes': [['buy', '38200.84', '0.00000000']], 'time': '2021-05-20T03:54:57.038388Z'}
{'type': 'l2update', 'product_id': 'BTC-USD', 'changes': [['buy', '38253.32', '0.00000000']], 'time': '2021-05-20T03:54:57.039098Z'}
{'type': 'l2update', 'product_id': 'BTC-USD', 'changes': [['sell', '38296.74', '0.00000000']], 'time': '2021-05-20T03:54:57.039098Z'}
{'type': 'l2update', 'product_id': 'BTC-USD', 'changes': [['buy', '38220.55', '0.10000000']], 'time': '2021-05-20T03:54:57.045249Z'}
{'type': 'l2update', 'product_id': 'BTC-USD', 'changes': [['sell', '38405.60', '0.01000000']], 'time': '2021-05-20T03:54:57.045290Z'}
{'type': 'l2update', 'product_id': 'BTC-USD', 'changes': [['buy', '37500.01', '0.19590000']], 'time': '2021-05-20T03:54:57.045331Z'}
{'type': 'l2update', 'product_id': 'BTC-USD', 'changes': [['buy', '38260.24', '0.00000000']], 'time': '2021-05-20T03:54:57.045930Z'}
{'type': 'l2update', 'product_id': 'BTC-USD', 'changes': [['buy', '38107.27', '0.05185368']], 'time': '2021-05-20T03:54:57.049589Z'}
{'type': 'l2update', 'product_id': 'BTC-USD', 'changes': [['buy', '37583.06', '0.04190000']], 'time': '2021-05-20T03:54:57.049661Z'}
{'type': 'l2update', 'product_id': 'BTC-USD', 'changes': [['buy', '36981.10', '0.05920000']], 'time': '2021-05-20T03:54:57.049661Z'}
{'type': 'l2update', 'product_id': 'BTC-USD', 'changes': [['sell', '38297.75', '0.04201003']], 'time': '2021-05-20T03:54:57.062707Z'}
{'type': 'l2update', 'product_id': 'BTC-USD', 'changes': [['sell', '52384.49', '0.00184400']], 'time': '2021-05-20T03:54:57.082457Z'}
{'type': 'l2update', 'product_id': 'BTC-USD', 'changes': [['buy', '38266.00', '0.00000000']], 'time': '2021-05-20T03:54:57.090993Z'}
{'type': 'l2update', 'product_id': 'BTC-USD', 'changes': [['buy', '37802.72', '0.00000000']], 'time': '2021-05-20T03:54:57.124254Z'}
{'type': 'l2update', 'product_id': 'BTC-USD', 'changes': [['buy', '38270.27', '0.00000000']], 'time': '2021-05-20T03:54:57.127341Z'}
{'type': 'l2update', 'product_id': 'BTC-USD', 'changes': [['buy', '38270.17', '0.00000000']], 'time': '2021-05-20T03:54:57.130725Z'}
{'type': 'l2update', 'product_id': 'BTC-USD', 'changes': [['buy', '38256.61', '0.40350000']], 'time': '2021-05-20T03:54:57.137712Z'}
{'type': 'l2update', 'product_id': 'BTC-USD', 'changes': [['buy', '38172.83', '0.00000000']], 'time': '2021-05-20T03:54:57.148351Z'}
{'type': 'l2update', 'product_id': 'BTC-USD', 'changes': [['buy', '38178.50', '0.00000000']], 'time': '2021-05-20T03:54:57.148351Z'}
{'type': 'l2update', 'product_id': 'BTC-USD', 'changes': [['sell', '38287.79', '0.00000000']], 'time': '2021-05-20T03:54:57.150105Z'}
{'type': 'l2update', 'product_id': 'BTC-USD', 'changes': [['buy', '38266.12', '0.00000000']], 'time': '2021-05-20T03:54:57.150678Z'}
{'type': 'l2update', 'product_id': 'BTC-USD', 'changes': [['sell', '38315.89', '0.00000000']], 'time': '2021-05-20T03:54:57.152958Z'}
{'type': 'l2update', 'product_id': 'BTC-USD', 'changes': [['sell', '38304.22', '0.05000000']], 'time': '2021-05-20T03:54:57.155372Z'}
{'type': 'l2update', 'product_id': 'BTC-USD', 'changes': [['buy', '38266.00', '0.10000000']], 'time': '2021-05-20T03:54:57.155599Z'}
{'type': 'l2update', 'product_id': 'BTC-USD', 'changes': [['sell', '38303.32', '0.03000000']], 'time': '2021-05-20T03:54:57.156135Z'}
{'type': 'l2update', 'product_id': 'BTC-USD', 'changes': [['sell', '38397.50', '0.01000000']], 'time': '2021-05-20T03:54:57.161702Z'}
{'type': 'l2update', 'product_id': 'BTC-USD', 'changes': [['buy', '38262.79', '0.58716278']], 'time': '2021-05-20T03:54:57.162085Z'}
{'type': 'l2update', 'product_id': 'BTC-USD', 'changes': [['buy', '38266.17', '0.52100000']], 'time': '2021-05-20T03:54:57.162102Z'}
{'type': 'l2update', 'product_id': 'BTC-USD', 'changes': [['sell', '38503.30', '0.00000000']], 'time': '2021-05-20T03:54:57.185370Z'}
{'type': 'l2update', 'product_id': 'BTC-USD', 'changes': [['sell', '38283.03', '0.00000000']], 'time': '2021-05-20T03:54:57.185714Z'}
{'type': 'l2update', 'product_id': 'BTC-USD', 'changes': [['buy', '38235.31', '0.00000000']], 'time': '2021-05-20T03:54:57.185948Z'}
{'type': 'l2update', 'product_id': 'BTC-USD', 'changes': [['sell', '38305.00', '0.04000000']], 'time': '2021-05-20T03:54:57.191426Z'}
{'type': 'l2update', 'product_id': 'BTC-USD', 'changes': [['sell', '38278.22', '0.49951881']], 'time': '2021-05-20T03:54:57.191788Z'}
{'type': 'l2update', 'product_id': 'BTC-USD', 'changes': [['sell', '38307.83', '0.41060000']], 'time': '2021-05-20T03:54:57.192528Z'}
{'type': 'l2update', 'product_id': 'BTC-USD', 'changes': [['buy', '38267.68', '0.10000000']], 'time': '2021-05-20T03:54:57.192943Z'}
{'type': 'l2update', 'product_id': 'BTC-USD', 'changes': [['buy', '38270.28', '0.05000000']], 'time': '2021-05-20T03:54:57.205403Z'}
{'type': 'l2update', 'product_id': 'BTC-USD', 'changes': [['sell', '38429.78', '0.00780644']], 'time': '2021-05-20T03:54:57.205666Z'}
{'type': 'l2update', 'product_id': 'BTC-USD', 'changes': [['sell', '38291.45', '1.00000000']], 'time': '2021-05-20T03:54:57.205759Z'}
{'type': 'l2update', 'product_id': 'BTC-USD', 'changes': [['sell', '38370.15', '0.00000000']], 'time': '2021-05-20T03:54:57.209026Z'}
{'type': 'l2update', 'product_id': 'BTC-USD', 'changes': [['sell', '38296.87', '0.00000000']], 'time': '2021-05-20T03:54:57.212781Z'}
{'type': 'l2update', 'product_id': 'BTC-USD', 'changes': [['sell', '38287.79', '0.54700000']], 'time': '2021-05-20T03:54:57.213277Z'}
{'type': 'l2update', 'product_id': 'BTC-USD', 'changes': [['sell', '43100.00', '1.09530000']], 'time': '2021-05-20T03:54:57.214800Z'}
{'type': 'l2update', 'product_id': 'BTC-USD', 'changes': [['sell', '38278.22', '0.00000000']], 'time': '2021-05-20T03:54:57.215981Z'}
{'type': 'l2update', 'product_id': 'BTC-USD', 'changes': [['sell', '38307.83', '0.00000000']], 'time': '2021-05-20T03:54:57.217199Z'}
{'type': 'l2update', 'product_id': 'BTC-USD', 'changes': [['sell', '38278.21', '0.47546355']], 'time': '2021-05-20T03:54:57.220241Z'}
{'type': 'l2update', 'product_id': 'BTC-USD', 'changes': [['sell', '38320.05', '0.10000000']], 'time': '2021-05-20T03:54:57.221499Z'}
{'type': 'l2update', 'product_id': 'BTC-USD', 'changes': [['sell', '38297.75', '0.00000000']], 'time': '2021-05-20T03:54:57.224594Z'}
{'type': 'l2update', 'product_id': 'BTC-USD', 'changes': [['buy', '38167.19', '0.00000000']], 'time': '2021-05-20T03:54:57.233310Z'}
{'type': 'l2update', 'product_id': 'BTC-USD', 'changes': [['sell', '38510.95', '0.00649166']], 'time': '2021-05-20T03:54:57.233556Z'}
{'type': 'l2update', 'product_id': 'BTC-USD', 'changes': [['buy', '38256.61', '0.00000000']], 'time': '2021-05-20T03:54:57.238094Z'}
{'type': 'l2update', 'product_id': 'BTC-USD', 'changes': [['sell', '43100.00', '3.44980000']], 'time': '2021-05-20T03:54:57.241272Z'}
{'type': 'l2update', 'product_id': 'BTC-USD', 'changes': [['sell', '38278.21', '0.47405971']], 'time': '2021-05-20T03:54:57.246864Z'}
{'type': 'l2update', 'product_id': 'BTC-USD', 'changes': [['buy', '38269.77', '0.10000000']], 'time': '2021-05-20T03:54:57.252669Z'}
{'type': 'l2update', 'product_id': 'BTC-USD', 'changes': [['sell', '38282.47', '0.01492000']], 'time': '2021-05-20T03:54:57.257858Z'}
{'type': 'l2update', 'product_id': 'BTC-USD', 'changes': [['sell', '38282.48', '0.07460000']], 'time': '2021-05-20T03:54:57.257958Z'}
{'type': 'l2update', 'product_id': 'BTC-USD', 'changes': [['buy', '38179.74', '0.03577500']], 'time': '2021-05-20T03:54:57.264773Z'}
{'type': 'l2update', 'product_id': 'BTC-USD', 'changes': [['sell', '38283.06', '0.50000000']], 'time': '2021-05-20T03:54:57.264955Z'}
{'type': 'l2update', 'product_id': 'BTC-USD', 'changes': [['sell', '38396.20', '0.00000000']], 'time': '2021-05-20T03:54:57.270512Z'}
{'type': 'l2update', 'product_id': 'BTC-USD', 'changes': [['sell', '38383.56', '0.06770000']], 'time': '2021-05-20T03:54:57.272647Z'}
{'type': 'l2update', 'product_id': 'BTC-USD', 'changes': [['buy', '38227.39', '0.06600000']], 'time': '2021-05-20T03:54:57.272647Z'}
{'type': 'l2update', 'product_id': 'BTC-USD', 'changes': [['sell', '38309.17', '0.00000000']], 'time': '2021-05-20T03:54:57.273275Z'}
{'type': 'l2update', 'product_id': 'BTC-USD', 'changes': [['buy', '38250.95', '0.00000000']], 'time': '2021-05-20T03:54:57.275894Z'}
{'type': 'l2update', 'product_id': 'BTC-USD', 'changes': [['sell', '38282.47', '0.00000000']], 'time': '2021-05-20T03:54:57.276233Z'}
{'type': 'l2update', 'product_id': 'BTC-USD', 'changes': [['sell', '38302.58', '0.04201003']], 'time': '2021-05-20T03:54:57.276512Z'}
{'type': 'l2update', 'product_id': 'BTC-USD', 'changes': [['sell', '38282.48', '0.00000000']], 'time': '2021-05-20T03:54:57.276797Z'}
{'type': 'l2update', 'product_id': 'BTC-USD', 'changes': [['sell', '38403.97', '0.00000000']], 'time': '2021-05-20T03:54:57.282640Z'}
{'type': 'l2update', 'product_id': 'BTC-USD', 'changes': [['buy', '38191.61', '0.00000000']], 'time': '2021-05-20T03:54:57.291648Z'}
{'type': 'l2update', 'product_id': 'BTC-USD', 'changes': [['sell', '38433.14', '0.01279710']], 'time': '2021-05-20T03:54:57.294933Z'}
{'type': 'l2update', 'product_id': 'BTC-USD', 'changes': [['buy', '38251.04', '0.03955899']], 'time': '2021-05-20T03:54:57.304787Z'}
{'type': 'l2update', 'product_id': 'BTC-USD', 'changes': [['sell', '38297.29', '0.04288489']], 'time': '2021-05-20T03:54:57.304787Z'}
{'type': 'l2update', 'product_id': 'BTC-USD', 'changes': [['buy', '31800.00', '4.57005073']], 'time': '2021-05-20T03:54:57.305326Z'}
{'type': 'l2update', 'product_id': 'BTC-USD', 'changes': [['sell', '52388.23', '0.00184400']], 'time': '2021-05-20T03:54:57.310789Z'}
{'type': 'l2update', 'product_id': 'BTC-USD', 'changes': [['buy', '38267.68', '0.15080417']], 'time': '2021-05-20T03:54:57.313718Z'}
{'type': 'l2update', 'product_id': 'BTC-USD', 'changes': [['sell', '38278.21', '0.00000000']], 'time': '2021-05-20T03:54:57.319001Z'}
{'type': 'l2update', 'product_id': 'BTC-USD', 'changes': [['buy', '37776.08', '0.00067409']], 'time': '2021-05-20T03:54:57.320674Z'}
{'type': 'l2update', 'product_id': 'BTC-USD', 'changes': [['sell', '38382.52', '0.01000000']], 'time': '2021-05-20T03:54:57.321824Z'}
{'type': 'l2update', 'product_id': 'BTC-USD', 'changes': [['sell', '38428.86', '0.00000000']], 'time': '2021-05-20T03:54:57.329082Z'}
{'type': 'l2update', 'product_id': 'BTC-USD', 'changes': [['sell', '38306.88', '0.49300000']], 'time': '2021-05-20T03:54:57.329309Z'}
{'type': 'l2update', 'product_id': 'BTC-USD', 'changes': [['sell', '38405.60', '0.00000000']], 'time': '2021-05-20T03:54:57.335159Z'}
{'type': 'l2update', 'product_id': 'BTC-USD', 'changes': [['sell', '38283.06', '0.00000000']], 'time': '2021-05-20T03:54:57.340331Z'}
{'type': 'l2update', 'product_id': 'BTC-USD', 'changes': [['sell', '38282.67', '0.01492000']], 'time': '2021-05-20T03:54:57.345258Z'}
{'type': 'l2update', 'product_id': 'BTC-USD', 'changes': [['sell', '38282.59', '0.07460000']], 'time': '2021-05-20T03:54:57.345789Z'}
{'type': 'l2update', 'product_id': 'BTC-USD', 'changes': [['buy', '38245.13', '0.78403419']], 'time': '2021-05-20T03:54:57.354958Z'}
{'type': 'l2update', 'product_id': 'BTC-USD', 'changes': [['sell', '38283.05', '0.47405971']], 'time': '2021-05-20T03:54:57.355813Z'}
{'type': 'l2update', 'product_id': 'BTC-USD', 'changes': [['sell', '38279.57', '0.00616015']], 'time': '2021-05-20T03:54:57.358964Z'}
{'type': 'l2update', 'product_id': 'BTC-USD', 'changes': [['buy', '38253.83', '0.43880000']], 'time': '2021-05-20T03:54:57.360354Z'}
{'type': 'l2update', 'product_id': 'BTC-USD', 'changes': [['sell', '38454.88', '0.13002253']], 'time': '2021-05-20T03:54:57.360388Z'}
{'type': 'l2update', 'product_id': 'BTC-USD', 'changes': [['sell', '38374.14', '0.00000000']], 'time': '2021-05-20T03:54:57.365146Z'}
{'type': 'l2update', 'product_id': 'BTC-USD', 'changes': [['buy', '38220.78', '0.20400000']], 'time': '2021-05-20T03:54:57.365702Z'}
{'type': 'l2update', 'product_id': 'BTC-USD', 'changes': [['sell', '38279.56', '0.50000000']], 'time': '2021-05-20T03:54:57.369058Z'}
{'type': 'l2update', 'product_id': 'BTC-USD', 'changes': [['sell', '38282.67', '0.00000000']], 'time': '2021-05-20T03:54:57.375580Z'}
{'type': 'l2update', 'product_id': 'BTC-USD', 'changes': [['buy', '38265.99', '0.00000000']], 'time': '2021-05-20T03:54:57.379486Z'}
{'type': 'l2update', 'product_id': 'BTC-USD', 'changes': [['buy', '38239.95', '0.00000000']], 'time': '2021-05-20T03:54:57.380996Z'}
{'type': 'l2update', 'product_id': 'BTC-USD', 'changes': [['sell', '38282.59', '0.00000000']], 'time': '2021-05-20T03:54:57.384479Z'}
{'type': 'l2update', 'product_id': 'BTC-USD', 'changes': [['sell', '38382.52', '0.00000000']], 'time': '2021-05-20T03:54:57.384588Z'}
{'type': 'l2update', 'product_id': 'BTC-USD', 'changes': [['sell', '38302.58', '0.00000000']], 'time': '2021-05-20T03:54:57.385901Z'}
{'type': 'l2update', 'product_id': 'BTC-USD', 'changes': [['sell', '38287.79', '1.56600000']], 'time': '2021-05-20T03:54:57.385925Z'}
{'type': 'l2update', 'product_id': 'BTC-USD', 'changes': [['sell', '38401.66', '0.01302027']], 'time': '2021-05-20T03:54:57.386306Z'}
{'type': 'l2update', 'product_id': 'BTC-USD', 'changes': [['sell', '38279.56', '0.49224210']], 'time': '2021-05-20T03:54:57.391691Z'}
{'type': 'l2update', 'product_id': 'BTC-USD', 'changes': [['sell', '38375.41', '0.01000000']], 'time': '2021-05-20T03:54:57.391713Z'}
{'type': 'l2update', 'product_id': 'BTC-USD', 'changes': [['buy', '38235.31', '1.20000000']], 'time': '2021-05-20T03:54:57.392680Z'}
{'type': 'l2update', 'product_id': 'BTC-USD', 'changes': [['sell', '38279.57', '0.00000000']], 'time': '2021-05-20T03:54:57.402079Z'}
{'type': 'l2update', 'product_id': 'BTC-USD', 'changes': [['sell', '38383.56', '0.00170000']], 'time': '2021-05-20T03:54:57.402893Z'}
{'type': 'l2update', 'product_id': 'BTC-USD', 'changes': [['sell', '38297.11', '0.00000000']], 'time': '2021-05-20T03:54:57.404981Z'}
{'type': 'l2update', 'product_id': 'BTC-USD', 'changes': [['sell', '38279.56', '0.00000000']], 'time': '2021-05-20T03:54:57.406913Z'}
{'type': 'l2update', 'product_id': 'BTC-USD', 'changes': [['buy', '38262.80', '0.11710585']], 'time': '2021-05-20T03:54:57.410362Z'}
{'type': 'l2update', 'product_id': 'BTC-USD', 'changes': [['sell', '38368.46', '0.01000000']], 'time': '2021-05-20T03:54:57.410597Z'}
{'type': 'l2update', 'product_id': 'BTC-USD', 'changes': [['buy', '38267.72', '0.84800000']], 'time': '2021-05-20T03:54:57.416890Z'}
{'type': 'l2update', 'product_id': 'BTC-USD', 'changes': [['sell', '38370.15', '1.20000000']], 'time': '2021-05-20T03:54:57.417067Z'}
{'type': 'l2update', 'product_id': 'BTC-USD', 'changes': [['sell', '38279.56', '0.50000000']], 'time': '2021-05-20T03:54:57.429116Z'}
{'type': 'l2update', 'product_id': 'BTC-USD', 'changes': [['buy', '38272.96', '0.01492000']], 'time': '2021-05-20T03:54:57.429365Z'}
{'type': 'l2update', 'product_id': 'BTC-USD', 'changes': [['sell', '38282.59', '0.07460000']], 'time': '2021-05-20T03:54:57.429572Z'}
{'type': 'l2update', 'product_id': 'BTC-USD', 'changes': [['sell', '38429.78', '0.00000000']], 'time': '2021-05-20T03:54:57.434724Z'}
{'type': 'l2update', 'product_id': 'BTC-USD', 'changes': [['buy', '38126.96', '0.16150000']], 'time': '2021-05-20T03:54:57.437098Z'}
{'type': 'l2update', 'product_id': 'BTC-USD', 'changes': [['sell', '38282.59', '0.00000000']], 'time': '2021-05-20T03:54:57.439113Z'}
{'type': 'l2update', 'product_id': 'BTC-USD', 'changes': [['sell', '38279.56', '0.00000000']], 'time': '2021-05-20T03:54:57.440288Z'}
{'type': 'l2update', 'product_id': 'BTC-USD', 'changes': [['sell', '38368.68', '0.06600000']], 'time': '2021-05-20T03:54:57.449587Z'}
{'type': 'l2update', 'product_id': 'BTC-USD', 'changes': [['sell', '38297.04', '0.04201003']], 'time': '2021-05-20T03:54:57.451293Z'}
{'type': 'l2update', 'product_id': 'BTC-USD', 'changes': [['sell', '38282.43', '0.01492000']], 'time': '2021-05-20T03:54:57.451309Z'}
{'type': 'l2update', 'product_id': 'BTC-USD', 'changes': [['sell', '38374.38', '0.00000000']], 'time': '2021-05-20T03:54:57.451979Z'}
{'type': 'l2update', 'product_id': 'BTC-USD', 'changes': [['buy', '38245.14', '0.03218864']], 'time': '2021-05-20T03:54:57.458053Z'}
{'type': 'l2update', 'product_id': 'BTC-USD', 'changes': [['buy', '38183.04', '0.00000000']], 'time': '2021-05-20T03:54:57.458139Z'}
{'type': 'l2update', 'product_id': 'BTC-USD', 'changes': [['sell', '38282.71', '0.07460000']], 'time': '2021-05-20T03:54:57.461246Z'}
{'type': 'l2update', 'product_id': 'BTC-USD', 'changes': [['sell', '38283.04', '0.50000000']], 'time': '2021-05-20T03:54:57.461356Z'}
{'type': 'l2update', 'product_id': 'BTC-USD', 'changes': [['sell', '38282.43', '0.00000000']], 'time': '2021-05-20T03:54:57.461941Z'}
{'type': 'l2update', 'product_id': 'BTC-USD', 'changes': [['buy', '38272.96', '0.00000000']], 'time': '2021-05-20T03:54:57.461949Z'}
{'type': 'l2update', 'product_id': 'BTC-USD', 'changes': [['sell', '38464.19', '0.00000000']], 'time': '2021-05-20T03:54:57.463980Z'}
{'type': 'l2update', 'product_id': 'BTC-USD', 'changes': [['sell', '38305.35', '0.00000000']], 'time': '2021-05-20T03:54:57.464487Z'}
{'type': 'l2update', 'product_id': 'BTC-USD', 'changes': [['sell', '38411.38', '0.01000000']], 'time': '2021-05-20T03:54:57.469484Z'}
{'type': 'l2update', 'product_id': 'BTC-USD', 'changes': [['sell', '38282.71', '0.00000000']], 'time': '2021-05-20T03:54:57.470838Z'}
{'type': 'l2update', 'product_id': 'BTC-USD', 'changes': [['buy', '38262.80', '0.00000000']], 'time': '2021-05-20T03:54:57.471721Z'}
{'type': 'l2update', 'product_id': 'BTC-USD', 'changes': [['sell', '38283.05', '0.00000000']], 'time': '2021-05-20T03:54:57.472000Z'}
{'type': 'l2update', 'product_id': 'BTC-USD', 'changes': [['buy', '38111.79', '0.05090359']], 'time': '2021-05-20T03:54:57.473533Z'}
{'type': 'l2update', 'product_id': 'BTC-USD', 'changes': [['buy', '38151.67', '0.01000000']], 'time': '2021-05-20T03:54:57.475882Z'}
{'type': 'l2update', 'product_id': 'BTC-USD', 'changes': [['sell', '38297.29', '0.00000000']], 'time': '2021-05-20T03:54:57.476484Z'}
{'type': 'l2update', 'product_id': 'BTC-USD', 'changes': [['sell', '38303.82', '0.02000000']], 'time': '2021-05-20T03:54:57.480251Z'}
{'type': 'l2update', 'product_id': 'BTC-USD', 'changes': [['sell', '38475.81', '0.01000000']], 'time': '2021-05-20T03:54:57.480312Z'}
{'type': 'l2update', 'product_id': 'BTC-USD', 'changes': [['buy', '38267.68', '0.10000000']], 'time': '2021-05-20T03:54:57.483571Z'}
{'type': 'l2update', 'product_id': 'BTC-USD', 'changes': [['buy', '38272.56', '0.01492000']], 'time': '2021-05-20T03:54:57.484162Z'}
{'type': 'l2update', 'product_id': 'BTC-USD', 'changes': [['sell', '38282.43', '0.01492000']], 'time': '2021-05-20T03:54:57.484756Z'}
{'type': 'l2update', 'product_id': 'BTC-USD', 'changes': [['buy', '38179.74', '0.00000000']], 'time': '2021-05-20T03:54:57.486024Z'}
{'type': 'l2update', 'product_id': 'BTC-USD', 'changes': [['sell', '38282.42', '0.07460000']], 'time': '2021-05-20T03:54:57.487793Z'}
{'type': 'l2update', 'product_id': 'BTC-USD', 'changes': [['sell', '52391.98', '0.00184400']], 'time': '2021-05-20T03:54:57.488265Z'}
{'type': 'l2update', 'product_id': 'BTC-USD', 'changes': [['buy', '38251.69', '0.00000000']], 'time': '2021-05-20T03:54:57.489380Z'}
{'type': 'l2update', 'product_id': 'BTC-USD', 'changes': [['sell', '38309.12', '0.04872178']], 'time': '2021-05-20T03:54:57.491804Z'}
{'type': 'l2update', 'product_id': 'BTC-USD', 'changes': [['buy', '38272.32', '0.00000000']], 'time': '2021-05-20T03:54:57.493469Z'}
{'type': 'l2update', 'product_id': 'BTC-USD', 'changes': [['buy', '38273.64', '0.00000000']], 'time': '2021-05-20T03:54:57.497464Z'}
{'type': 'l2update', 'product_id': 'BTC-USD', 'changes': [['sell', '38282.43', '0.00000000']], 'time': '2021-05-20T03:54:57.497507Z'}
{'type': 'l2update', 'product_id': 'BTC-USD', 'changes': [['buy', '38250.26', '0.00000000']], 'time': '2021-05-20T03:54:57.498542Z'}
{'type': 'l2update', 'product_id': 'BTC-USD', 'changes': [['sell', '38283.03', '0.47405971']], 'time': '2021-05-20T03:54:57.501088Z'}
{'type': 'l2update', 'product_id': 'BTC-USD', 'changes': [['buy', '38107.27', '0.00000000']], 'time': '2021-05-20T03:54:57.501635Z'}
{'type': 'l2update', 'product_id': 'BTC-USD', 'changes': [['sell', '38394.27', '0.00000000']], 'time': '2021-05-20T03:54:57.502105Z'}
{'type': 'l2update', 'product_id': 'BTC-USD', 'changes': [['buy', '38249.09', '0.09000000']], 'time': '2021-05-20T03:54:57.505481Z'}
{'type': 'l2update', 'product_id': 'BTC-USD', 'changes': [['buy', '38192.93', '0.01000000']], 'time': '2021-05-20T03:54:57.506385Z'}
{'type': 'l2update', 'product_id': 'BTC-USD', 'changes': [['buy', '38249.09', '0.05000000']], 'time': '2021-05-20T03:54:57.510069Z'}
{'type': 'l2update', 'product_id': 'BTC-USD', 'changes': [['sell', '38368.46', '0.00000000']], 'time': '2021-05-20T03:54:57.511064Z'}
{'type': 'l2update', 'product_id': 'BTC-USD', 'changes': [['buy', '38151.67', '0.00000000']], 'time': '2021-05-20T03:54:57.513544Z'}
{'type': 'l2update', 'product_id': 'BTC-USD', 'changes': [['buy', '38249.09', '0.00000000']], 'time': '2021-05-20T03:54:57.513788Z'}
{'type': 'l2update', 'product_id': 'BTC-USD', 'changes': [['buy', '38267.73', '0.11710585']], 'time': '2021-05-20T03:54:57.516222Z'}
{'type': 'l2update', 'product_id': 'BTC-USD', 'changes': [['sell', '38409.09', '0.03291735']], 'time': '2021-05-20T03:54:57.516605Z'}
{'type': 'l2update', 'product_id': 'BTC-USD', 'changes': [['sell', '38282.04', '0.01492000']], 'time': '2021-05-20T03:54:57.516645Z'}
{'type': 'l2update', 'product_id': 'BTC-USD', 'changes': [['buy', '37566.35', '0.00000000']], 'time': '2021-05-20T03:54:57.522730Z'}
{'type': 'l2update', 'product_id': 'BTC-USD', 'changes': [['buy', '36949.00', '0.00000000']], 'time': '2021-05-20T03:54:57.522730Z'}
{'type': 'l2update', 'product_id': 'BTC-USD', 'changes': [['sell', '38295.35', '0.05967560']], 'time': '2021-05-20T03:54:57.524714Z'}
{'type': 'l2update', 'product_id': 'BTC-USD', 'changes': [['sell', '38282.42', '0.00000000']], 'time': '2021-05-20T03:54:57.526304Z'}
{'type': 'l2update', 'product_id': 'BTC-USD', 'changes': [['buy', '38267.91', '0.01000000']], 'time': '2021-05-20T03:54:57.534912Z'}
{'type': 'l2update', 'product_id': 'BTC-USD', 'changes': [['sell', '38438.56', '0.00780466']], 'time': '2021-05-20T03:54:57.534973Z'}
{'type': 'l2update', 'product_id': 'BTC-USD', 'changes': [['sell', '38392.41', '0.01000000']], 'time': '2021-05-20T03:54:57.535050Z'}
{'type': 'l2update', 'product_id': 'BTC-USD', 'changes': [['buy', '38251.65', '0.39490431']], 'time': '2021-05-20T03:54:57.543570Z'}
{'type': 'l2update', 'product_id': 'BTC-USD', 'changes': [['sell', '38295.29', '0.00176519']], 'time': '2021-05-20T03:54:57.554121Z'}
{'type': 'l2update', 'product_id': 'BTC-USD', 'changes': [['buy', '38267.90', '0.02000000']], 'time': '2021-05-20T03:54:57.554799Z'}
{'type': 'l2update', 'product_id': 'BTC-USD', 'changes': [['buy', '38267.73', '0.00000000']], 'time': '2021-05-20T03:54:57.562630Z'}
{'type': 'l2update', 'product_id': 'BTC-USD', 'changes': [['sell', '38281.72', '0.07460000']], 'time': '2021-05-20T03:54:57.564254Z'}
{'type': 'l2update', 'product_id': 'BTC-USD', 'changes': [['sell', '38392.41', '0.00000000']], 'time': '2021-05-20T03:54:57.566145Z'}
{'type': 'l2update', 'product_id': 'BTC-USD', 'changes': [['buy', '38267.90', '0.05000000']], 'time': '2021-05-20T03:54:57.569054Z'}
{'type': 'l2update', 'product_id': 'BTC-USD', 'changes': [['sell', '38282.04', '0.00000000']], 'time': '2021-05-20T03:54:57.572691Z'}
{'type': 'l2update', 'product_id': 'BTC-USD', 'changes': [['sell', '38306.88', '0.00000000']], 'time': '2021-05-20T03:54:57.573547Z'}
{'type': 'l2update', 'product_id': 'BTC-USD', 'changes': [['buy', '38111.79', '0.00000000']], 'time': '2021-05-20T03:54:57.575367Z'}
{'type': 'l2update', 'product_id': 'BTC-USD', 'changes': [['sell', '38286.75', '0.00600000']], 'time': '2021-05-20T03:54:57.579898Z'}
{'type': 'l2update', 'product_id': 'BTC-USD', 'changes': [['sell', '38370.35', '0.01000000']], 'time': '2021-05-20T03:54:57.579921Z'}
{'type': 'l2update', 'product_id': 'BTC-USD', 'changes': [['buy', '38245.14', '0.00000000']], 'time': '2021-05-20T03:54:57.584457Z'}
{'type': 'l2update', 'product_id': 'BTC-USD', 'changes': [['sell', '38281.72', '0.00000000']], 'time': '2021-05-20T03:54:57.585099Z'}
{'type': 'l2update', 'product_id': 'BTC-USD', 'changes': [['buy', '38267.90', '0.09000000']], 'time': '2021-05-20T03:54:57.585869Z'}
{'type': 'l2update', 'product_id': 'BTC-USD', 'changes': [['buy', '38220.55', '0.00000000']], 'time': '2021-05-20T03:54:57.586699Z'}
{'type': 'l2update', 'product_id': 'BTC-USD', 'changes': [['sell', '38297.04', '0.00000000']], 'time': '2021-05-20T03:54:57.589236Z'}
{'type': 'l2update', 'product_id': 'BTC-USD', 'changes': [['buy', '38267.72', '0.00000000']], 'time': '2021-05-20T03:54:57.590464Z'}
{'type': 'l2update', 'product_id': 'BTC-USD', 'changes': [['sell', '38308.09', '0.41430000']], 'time': '2021-05-20T03:54:57.591984Z'}
{'type': 'l2update', 'product_id': 'BTC-USD', 'changes': [['buy', '38266.17', '0.00000000']], 'time': '2021-05-20T03:54:57.592511Z'}
{'type': 'l2update', 'product_id': 'BTC-USD', 'changes': [['sell', '38281.49', '0.01492000']], 'time': '2021-05-20T03:54:57.596519Z'}
{'type': 'l2update', 'product_id': 'BTC-USD', 'changes': [['sell', '38282.35', '0.07460000']], 'time': '2021-05-20T03:54:57.596606Z'}
{'type': 'l2update', 'product_id': 'BTC-USD', 'changes': [['buy', '38267.90', '0.14000000']], 'time': '2021-05-20T03:54:57.596809Z'}
{'type': 'l2update', 'product_id': 'BTC-USD', 'changes': [['sell', '38281.49', '0.00000000']], 'time': '2021-05-20T03:54:57.603563Z'}
{'type': 'l2update', 'product_id': 'BTC-USD', 'changes': [['sell', '38282.35', '0.00000000']], 'time': '2021-05-20T03:54:57.604235Z'}
{'type': 'l2update', 'product_id': 'BTC-USD', 'changes': [['buy', '38239.95', '0.03266022']], 'time': '2021-05-20T03:54:57.604819Z'}
{'type': 'l2update', 'product_id': 'BTC-USD', 'changes': [['buy', '38266.05', '0.84800000']], 'time': '2021-05-20T03:54:57.604937Z'}
{'type': 'l2update', 'product_id': 'BTC-USD', 'changes': [['buy', '38224.55', '0.10000000']], 'time': '2021-05-20T03:54:57.605099Z'}
{'type': 'l2update', 'product_id': 'BTC-USD', 'changes': [['buy', '38262.80', '0.11710585']], 'time': '2021-05-20T03:54:57.609234Z'}
{'type': 'l2update', 'product_id': 'BTC-USD', 'changes': [['buy', '38262.84', '0.52100000']], 'time': '2021-05-20T03:54:57.609516Z'}
{'type': 'l2update', 'product_id': 'BTC-USD', 'changes': [['sell', '38281.70', '0.01492000']], 'time': '2021-05-20T03:54:57.616841Z'}
{'type': 'l2update', 'product_id': 'BTC-USD', 'changes': [['sell', '38292.92', '0.04201003']], 'time': '2021-05-20T03:54:57.616992Z'}
{'type': 'l2update', 'product_id': 'BTC-USD', 'changes': [['sell', '38282.67', '0.07460000']], 'time': '2021-05-20T03:54:57.617037Z'}
{'type': 'l2update', 'product_id': 'BTC-USD', 'changes': [['buy', '38239.95', '0.00000000']], 'time': '2021-05-20T03:54:57.620571Z'}
{'type': 'l2update', 'product_id': 'BTC-USD', 'changes': [['sell', '38281.70', '0.00000000']], 'time': '2021-05-20T03:54:57.622957Z'}
{'type': 'l2update', 'product_id': 'BTC-USD', 'changes': [['sell', '38282.67', '0.00000000']], 'time': '2021-05-20T03:54:57.623918Z'}
{'type': 'l2update', 'product_id': 'BTC-USD', 'changes': [['sell', '38283.03', '0.00000000']], 'time': '2021-05-20T03:54:57.625470Z'}
{'type': 'l2update', 'product_id': 'BTC-USD', 'changes': [['buy', '38245.13', '0.81669441']], 'time': '2021-05-20T03:54:57.625969Z'}
{'type': 'l2update', 'product_id': 'BTC-USD', 'changes': [['sell', '38329.38', '0.50000000']], 'time': '2021-05-20T03:54:57.630112Z'}
{'type': 'l2update', 'product_id': 'BTC-USD', 'changes': [['sell', '38295.35', '0.00000000']], 'time': '2021-05-20T03:54:57.630607Z'}
{'type': 'l2update', 'product_id': 'BTC-USD', 'changes': [['sell', '38282.53', '0.07460000']], 'time': '2021-05-20T03:54:57.634136Z'}
{'type': 'l2update', 'product_id': 'BTC-USD', 'changes': [['buy', '38245.13', '0.78403419']], 'time': '2021-05-20T03:54:57.635283Z'}
{'type': 'l2update', 'product_id': 'BTC-USD', 'changes': [['sell', '38282.38', '0.01492000']], 'time': '2021-05-20T03:54:57.641743Z'}
{'type': 'l2update', 'product_id': 'BTC-USD', 'changes': [['buy', '38239.95', '0.03266022']], 'time': '2021-05-20T03:54:57.643239Z'}
{'type': 'l2update', 'product_id': 'BTC-USD', 'changes': [['buy', '38266.00', '0.00000000']], 'time': '2021-05-20T03:54:57.643461Z'}
{'type': 'l2update', 'product_id': 'BTC-USD', 'changes': [['buy', '38267.68', '0.00000000']], 'time': '2021-05-20T03:54:57.643612Z'}
{'type': 'l2update', 'product_id': 'BTC-USD', 'changes': [['buy', '38214.51', '0.00000000']], 'time': '2021-05-20T03:54:57.644271Z'}
{'type': 'l2update', 'product_id': 'BTC-USD', 'changes': [['sell', '38282.53', '0.00000000']], 'time': '2021-05-20T03:54:57.647421Z'}
{'type': 'l2update', 'product_id': 'BTC-USD', 'changes': [['buy', '38269.76', '0.00000000']], 'time': '2021-05-20T03:54:57.648122Z'}
{'type': 'l2update', 'product_id': 'BTC-USD', 'changes': [['sell', '38283.03', '0.47405971']], 'time': '2021-05-20T03:54:57.648936Z'}
{'type': 'l2update', 'product_id': 'BTC-USD', 'changes': [['sell', '52399.47', '0.00184400']], 'time': '2021-05-20T03:54:57.657425Z'}
{'type': 'l2update', 'product_id': 'BTC-USD', 'changes': [['sell', '38292.86', '0.06151505']], 'time': '2021-05-20T03:54:57.659023Z'}
{'type': 'l2update', 'product_id': 'BTC-USD', 'changes': [['sell', '38281.97', '0.07460000']], 'time': '2021-05-20T03:54:57.659245Z'}
{'type': 'l2update', 'product_id': 'BTC-USD', 'changes': [['buy', '38262.45', '0.05096058']], 'time': '2021-05-20T03:54:57.664387Z'}
{'type': 'l2update', 'product_id': 'BTC-USD', 'changes': [['buy', '38262.80', '0.00000000']], 'time': '2021-05-20T03:54:57.666780Z'}
{'type': 'l2update', 'product_id': 'BTC-USD', 'changes': [['sell', '38282.38', '0.00000000']], 'time': '2021-05-20T03:54:57.667161Z'}
{'type': 'l2update', 'product_id': 'BTC-USD', 'changes': [['buy', '38255.06', '0.00000000']], 'time': '2021-05-20T03:54:57.668398Z'}
{'type': 'l2update', 'product_id': 'BTC-USD', 'changes': [['buy', '38233.40', '0.00000000']], 'time': '2021-05-20T03:54:57.674504Z'}
{'type': 'l2update', 'product_id': 'BTC-USD', 'changes': [['sell', '38281.97', '0.00000000']], 'time': '2021-05-20T03:54:57.680649Z'}
{'type': 'l2update', 'product_id': 'BTC-USD', 'changes': [['sell', '38281.51', '0.01492000']], 'time': '2021-05-20T03:54:57.692258Z'}
{'type': 'l2update', 'product_id': 'BTC-USD', 'changes': [['buy', '38262.85', '0.11710585']], 'time': '2021-05-20T03:54:57.692289Z'}
{'type': 'l2update', 'product_id': 'BTC-USD', 'changes': [['sell', '38282.49', '0.07460000']], 'time': '2021-05-20T03:54:57.696169Z'}
{'type': 'l2update', 'product_id': 'BTC-USD', 'changes': [['sell', '38281.51', '0.00000000']], 'time': '2021-05-20T03:54:57.697188Z'}
{'type': 'l2update', 'product_id': 'BTC-USD', 'changes': [['sell', '38370.35', '0.00000000']], 'time': '2021-05-20T03:54:57.700056Z'}
{'type': 'l2update', 'product_id': 'BTC-USD', 'changes': [['sell', '38283.07', '0.00000000']], 'time': '2021-05-20T03:54:57.700737Z'}
{'type': 'l2update', 'product_id': 'BTC-USD', 'changes': [['sell', '38282.49', '0.00000000']], 'time': '2021-05-20T03:54:57.702438Z'}
{'type': 'l2update', 'product_id': 'BTC-USD', 'changes': [['sell', '38281.91', '0.01492000']], 'time': '2021-05-20T03:54:57.713235Z'}
{'type': 'l2update', 'product_id': 'BTC-USD', 'changes': [['sell', '38391.78', '0.03575250']], 'time': '2021-05-20T03:54:57.713292Z'}
{'type': 'l2update', 'product_id': 'BTC-USD', 'changes': [['sell', '38282.52', '0.07460000']], 'time': '2021-05-20T03:54:57.718520Z'}
{'type': 'l2update', 'product_id': 'BTC-USD', 'changes': [['sell', '38292.86', '0.00000000']], 'time': '2021-05-20T03:54:57.719647Z'}
{'type': 'l2update', 'product_id': 'BTC-USD', 'changes': [['sell', '38281.91', '0.00000000']], 'time': '2021-05-20T03:54:57.720643Z'}
{'type': 'l2update', 'product_id': 'BTC-USD', 'changes': [['sell', '38282.52', '0.00000000']], 'time': '2021-05-20T03:54:57.723309Z'}
{'type': 'l2update', 'product_id': 'BTC-USD', 'changes': [['sell', '38283.02', '2.48969908']], 'time': '2021-05-20T03:54:57.723399Z'}
{'type': 'l2update', 'product_id': 'BTC-USD', 'changes': [['sell', '38283.03', '0.00000000']], 'time': '2021-05-20T03:54:57.730194Z'}
{'type': 'l2update', 'product_id': 'BTC-USD', 'changes': [['sell', '38282.74', '0.07460000']], 'time': '2021-05-20T03:54:57.735319Z'}
{'type': 'l2update', 'product_id': 'BTC-USD', 'changes': [['sell', '38291.71', '0.05466616']], 'time': '2021-05-20T03:54:57.735427Z'}
{'type': 'l2update', 'product_id': 'BTC-USD', 'changes': [['sell', '38282.22', '0.01492000']], 'time': '2021-05-20T03:54:57.735665Z'}
{'type': 'l2update', 'product_id': 'BTC-USD', 'changes': [['sell', '38282.74', '0.00000000']], 'time': '2021-05-20T03:54:57.742732Z'}
{'type': 'l2update', 'product_id': 'BTC-USD', 'changes': [['sell', '38282.73', '0.47405971']], 'time': '2021-05-20T03:54:57.751132Z'}
{'type': 'l2update', 'product_id': 'BTC-USD', 'changes': [['sell', '38308.09', '0.00000000']], 'time': '2021-05-20T03:54:57.756833Z'}
{'type': 'l2update', 'product_id': 'BTC-USD', 'changes': [['buy', '38251.04', '0.00000000']], 'time': '2021-05-20T03:54:57.759190Z'}
{'type': 'l2update', 'product_id': 'BTC-USD', 'changes': [['sell', '38281.67', '0.07460000']], 'time': '2021-05-20T03:54:57.762967Z'}
{'type': 'l2update', 'product_id': 'BTC-USD', 'changes': [['sell', '38306.94', '0.40030000']], 'time': '2021-05-20T03:54:57.767139Z'}
{'type': 'l2update', 'product_id': 'BTC-USD', 'changes': [['sell', '38282.22', '0.00000000']], 'time': '2021-05-20T03:54:57.770331Z'}
{'type': 'l2update', 'product_id': 'BTC-USD', 'changes': [['buy', '38107.96', '0.04839178']], 'time': '2021-05-20T03:54:57.779444Z'}
{'type': 'l2update', 'product_id': 'BTC-USD', 'changes': [['sell', '38281.67', '0.00000000']], 'time': '2021-05-20T03:54:57.790305Z'}
{'type': 'l2update', 'product_id': 'BTC-USD', 'changes': [['sell', '38282.73', '0.47369029']], 'time': '2021-05-20T03:54:57.790305Z'}
{'type': 'l2update', 'product_id': 'BTC-USD', 'changes': [['buy', '38250.03', '0.05234864']], 'time': '2021-05-20T03:54:57.795127Z'}
{'type': 'l2update', 'product_id': 'BTC-USD', 'changes': [['sell', '38281.36', '0.01492000']], 'time': '2021-05-20T03:54:57.795416Z'}
{'type': 'l2update', 'product_id': 'BTC-USD', 'changes': [['sell', '38282.73', '0.00000000']], 'time': '2021-05-20T03:54:57.798947Z'}
{'type': 'l2update', 'product_id': 'BTC-USD', 'changes': [['sell', '38281.36', '0.00000000']], 'time': '2021-05-20T03:54:57.802388Z'}
{'type': 'l2update', 'product_id': 'BTC-USD', 'changes': [['sell', '38304.22', '0.00000000']], 'time': '2021-05-20T03:54:57.803544Z'}
{'type': 'l2update', 'product_id': 'BTC-USD', 'changes': [['sell', '38320.05', '0.00000000']], 'time': '2021-05-20T03:54:57.805128Z'}
{'type': 'l2update', 'product_id': 'BTC-USD', 'changes': [['buy', '38273.09', '0.07460000']], 'time': '2021-05-20T03:54:57.807390Z'}
{'type': 'l2update', 'product_id': 'BTC-USD', 'changes': [['sell', '38281.05', '0.07460000']], 'time': '2021-05-20T03:54:57.811672Z'}
{'type': 'l2update', 'product_id': 'BTC-USD', 'changes': [['sell', '38282.70', '0.01492000']], 'time': '2021-05-20T03:54:57.814862Z'}
{'type': 'l2update', 'product_id': 'BTC-USD', 'changes': [['buy', '38272.56', '0.00000000']], 'time': '2021-05-20T03:54:57.815387Z'}
{'type': 'l2update', 'product_id': 'BTC-USD', 'changes': [['sell', '38281.05', '0.00000000']], 'time': '2021-05-20T03:54:57.815988Z'}
{'type': 'l2update', 'product_id': 'BTC-USD', 'changes': [['sell', '38454.88', '0.00000000']], 'time': '2021-05-20T03:54:57.818147Z'}
{'type': 'l2update', 'product_id': 'BTC-USD', 'changes': [['buy', '38262.85', '0.00000000']], 'time': '2021-05-20T03:54:57.818688Z'}
{'type': 'l2update', 'product_id': 'BTC-USD', 'changes': [['sell', '52410.70', '0.00184400']], 'time': '2021-05-20T03:54:57.819147Z'}
{'type': 'l2update', 'product_id': 'BTC-USD', 'changes': [['sell', '38282.70', '0.00000000']], 'time': '2021-05-20T03:54:57.819949Z'}
{'type': 'l2update', 'product_id': 'BTC-USD', 'changes': [['buy', '38273.09', '0.00000000']], 'time': '2021-05-20T03:54:57.820961Z'}
{'type': 'l2update', 'product_id': 'BTC-USD', 'changes': [['sell', '38283.01', '0.47369029']], 'time': '2021-05-20T03:54:57.823888Z'}
{'type': 'l2update', 'product_id': 'BTC-USD', 'changes': [['sell', '39607.33', '0.00000000']], 'time': '2021-05-20T03:54:57.826381Z'}
{'type': 'l2update', 'product_id': 'BTC-USD', 'changes': [['sell', '38282.07', '0.07460000']], 'time': '2021-05-20T03:54:57.829553Z'}
{'type': 'l2update', 'product_id': 'BTC-USD', 'changes': [['buy', '38272.36', '0.07460000']], 'time': '2021-05-20T03:54:57.830650Z'}
{'type': 'l2update', 'product_id': 'BTC-USD', 'changes': [['sell', '38441.87', '0.13006653']], 'time': '2021-05-20T03:54:57.830773Z'}
{'type': 'l2update', 'product_id': 'BTC-USD', 'changes': [['buy', '38269.82', '0.84900000']], 'time': '2021-05-20T03:54:57.830879Z'}
{'type': 'l2update', 'product_id': 'BTC-USD', 'changes': [['buy', '38273.43', '0.01492000']], 'time': '2021-05-20T03:54:57.830919Z'}
{'type': 'l2update', 'product_id': 'BTC-USD', 'changes': [['buy', '38272.00', '0.15000000']], 'time': '2021-05-20T03:54:57.835748Z'}
{'type': 'l2update', 'product_id': 'BTC-USD', 'changes': [['buy', '38273.43', '0.00000000']], 'time': '2021-05-20T03:54:57.837762Z'}
{'type': 'l2update', 'product_id': 'BTC-USD', 'changes': [['buy', '38272.36', '0.00000000']], 'time': '2021-05-20T03:54:57.838041Z'}
{'type': 'l2update', 'product_id': 'BTC-USD', 'changes': [['buy', '38269.82', '0.00000000']], 'time': '2021-05-20T03:54:57.839058Z'}
{'type': 'l2update', 'product_id': 'BTC-USD', 'changes': [['buy', '38262.85', '0.11747527']], 'time': '2021-05-20T03:54:57.839723Z'}
{'type': 'l2update', 'product_id': 'BTC-USD', 'changes': [['buy', '38270.28', '0.00000000']], 'time': '2021-05-20T03:54:57.842426Z'}
