{'type': 'l2update', 'product_id': 'BTC-USD', 'changes': [['sell', '38434.16', '0.96255100']], 'time': '2021-05-20T03:56:28.869078Z'}
{'type': 'l2update', 'product_id': 'BTC-USD', 'changes': [['sell', '38346.21', '0.20200000']], 'time': '2021-05-20T03:56:28.869209Z'}
{'type': 'l2update', 'product_id': 'BTC-USD', 'changes': [['sell', '38475.97', '0.01000000']], 'time': '2021-05-20T03:56:28.869343Z'}
{'type': 'l2update', 'product_id': 'BTC-USD', 'changes': [['sell', '38335.91', '2.48969908']], 'time': '2021-05-20T03:56:28.869540Z'}
{'type': 'l2update', 'product_id': 'BTC-USD', 'changes': [['buy', '38201.76', '0.03323891']], 'time': '2021-05-20T03:56:28.869733Z'}
{'type': 'l2update', 'product_id': 'BTC-USD', 'changes': [['sell', '38405.24', '0.02603811']], 'time': '2021-05-20T03:56:28.870481Z'}
{'type': 'l2update', 'product_id': 'BTC-USD', 'changes': [['buy', '38302.82', '0.00000000']], 'time': '2021-05-20T03:56:28.875537Z'}
{'type': 'l2update', 'product_id': 'BTC-USD', 'changes': [['sell', '38354.48', '0.00000000']], 'time': '2021-05-20T03:56:28.875537Z'}
{'type': 'l2update', 'product_id': 'BTC-USD', 'changes': [['sell', '38363.85', '2.60953346']], 'time': '2021-05-20T03:56:28.882360Z'}
{'type': 'l2update', 'product_id': 'BTC-USD', 'changes': [['buy', '38274.14', '0.01000000']], 'time': '2021-05-20T03:56:28.882893Z'}
{'type': 'l2update', 'product_id': 'BTC-USD', 'changes': [['sell', '38472.31', '0.01000000']], 'time': '2021-05-20T03:56:28.887207Z'}
{'type': 'l2update', 'product_id': 'BTC-USD', 'changes': [['sell', '38352.03', '0.22593310']], 'time': '2021-05-20T03:56:28.889292Z'}
{'type': 'l2update', 'product_id': 'BTC-USD', 'changes': [['sell', '38352.03', '0.00000000']], 'time': '2021-05-20T03:56:28.889292Z'}
{'type': 'l2update', 'product_id': 'BTC-USD', 'changes': [['buy', '38309.22', '0.59116555']], 'time': '2021-05-20T03:56:28.898483Z'}
{'type': 'l2update', 'product_id': 'BTC-USD', 'changes': [['sell', '38412.14', '0.03552352']], 'time': '2021-05-20T03:56:28.904577Z'}
{'type': 'l2update', 'product_id': 'BTC-USD', 'changes': [['sell', '38405.25', '0.03736810']], 'time': '2021-05-20T03:56:28.904577Z'}
{'type': 'l2update', 'product_id': 'BTC-USD', 'changes': [['sell', '38396.75', '0.03626966']], 'time': '2021-05-20T03:56:28.904577Z'}
{'type': 'l2update', 'product_id': 'BTC-USD', 'changes': [['sell', '38392.00', '0.03224201']], 'time': '2021-05-20T03:56:28.904577Z'}
{'type': 'l2update', 'product_id': 'BTC-USD', 'changes': [['buy', '38305.41', '0.48930000']], 'time': '2021-05-20T03:56:28.908866Z'}
{'type': 'l2update', 'product_id': 'BTC-USD', 'changes': [['buy', '38261.67', '2.60979856']], 'time': '2021-05-20T03:56:28.909303Z'}
{'type': 'l2update', 'product_id': 'BTC-USD', 'changes': [['buy', '38269.31', '0.00000000']], 'time': '2021-05-20T03:56:28.913391Z'}
{'type': 'l2update', 'product_id': 'BTC-USD', 'changes': [['sell', '38352.02', '0.00000000']], 'time': '2021-05-20T03:56:28.916490Z'}
{'type': 'l2update', 'product_id': 'BTC-USD', 'changes': [['sell', '38450.20', '0.36987569']], 'time': '2021-05-20T03:56:28.923667Z'}
{'type': 'l2update', 'product_id': 'BTC-USD', 'changes': [['sell', '38377.00', '0.42040229']], 'time': '2021-05-20T03:56:28.923667Z'}
{'type': 'l2update', 'product_id': 'BTC-USD', 'changes': [['sell', '38429.70', '0.00000000']], 'time': '2021-05-20T03:56:28.924039Z'}
{'type': 'l2update', 'product_id': 'BTC-USD', 'changes': [['sell', '38354.47', '0.16000000']], 'time': '2021-05-20T03:56:28.927012Z'}
{'type': 'l2update', 'product_id': 'BTC-USD', 'changes': [['sell', '38446.57', '0.03522121']], 'time': '2021-05-20T03:56:28.928287Z'}
{'type': 'l2update', 'product_id': 'BTC-USD', 'changes': [['sell', '38441.68', '0.00000000']], 'time': '2021-05-20T03:56:28.928287Z'}
{'type': 'l2update', 'product_id': 'BTC-USD', 'changes': [['sell', '38434.16', '0.92628134']], 'time': '2021-05-20T03:56:28.928287Z'}
{'type': 'l2update', 'product_id': 'BTC-USD', 'changes': [['sell', '38428.07', '0.00000000']], 'time': '2021-05-20T03:56:28.928287Z'}
{'type': 'l2update', 'product_id': 'BTC-USD', 'changes': [['sell', '38523.41', '0.00000000']], 'time': '2021-05-20T03:56:28.941933Z'}
{'type': 'l2update', 'product_id': 'BTC-USD', 'changes': [['buy', '38234.93', '0.02730744']], 'time': '2021-05-20T03:56:28.943861Z'}
{'type': 'l2update', 'product_id': 'BTC-USD', 'changes': [['sell', '38371.15', '2.60990597']], 'time': '2021-05-20T03:56:28.944011Z'}
{'type': 'l2update', 'product_id': 'BTC-USD', 'changes': [['sell', '38428.45', '0.00000000']], 'time': '2021-05-20T03:56:28.946266Z'}
{'type': 'l2update', 'product_id': 'BTC-USD', 'changes': [['sell', '38352.55', '0.05000000']], 'time': '2021-05-20T03:56:28.949492Z'}
{'type': 'l2update', 'product_id': 'BTC-USD', 'changes': [['buy', '38285.39', '0.00000000']], 'time': '2021-05-20T03:56:28.949713Z'}
{'type': 'l2update', 'product_id': 'BTC-USD', 'changes': [['buy', '38274.14', '0.00000000']], 'time': '2021-05-20T03:56:28.951892Z'}
{'type': 'l2update', 'product_id': 'BTC-USD', 'changes': [['buy', '38328.57', '0.00000000']], 'time': '2021-05-20T03:56:28.958946Z'}
{'type': 'l2update', 'product_id': 'BTC-USD', 'changes': [['sell', '38346.48', '0.00000000']], 'time': '2021-05-20T03:56:28.959474Z'}
{'type': 'l2update', 'product_id': 'BTC-USD', 'changes': [['sell', '38365.32', '0.42610000']], 'time': '2021-05-20T03:56:28.961056Z'}
{'type': 'l2update', 'product_id': 'BTC-USD', 'changes': [['buy', '38252.56', '0.00000000']], 'time': '2021-05-20T03:56:28.963366Z'}
{'type': 'l2update', 'product_id': 'BTC-USD', 'changes': [['sell', '38434.35', '0.00000000']], 'time': '2021-05-20T03:56:28.964289Z'}
{'type': 'l2update', 'product_id': 'BTC-USD', 'changes': [['sell', '38496.71', '0.01280690']], 'time': '2021-05-20T03:56:28.971217Z'}
{'type': 'l2update', 'product_id': 'BTC-USD', 'changes': [['sell', '38401.01', '0.31218496']], 'time': '2021-05-20T03:56:28.981966Z'}
{'type': 'l2update', 'product_id': 'BTC-USD', 'changes': [['sell', '38376.66', '0.02861932']], 'time': '2021-05-20T03:56:28.982130Z'}
{'type': 'l2update', 'product_id': 'BTC-USD', 'changes': [['sell', '38352.55', '0.00000000']], 'time': '2021-05-20T03:56:28.986592Z'}
{'type': 'l2update', 'product_id': 'BTC-USD', 'changes': [['sell', '38422.36', '0.00000000']], 'time': '2021-05-20T03:56:28.986976Z'}
{'type': 'l2update', 'product_id': 'BTC-USD', 'changes': [['sell', '38365.32', '0.00000000']], 'time': '2021-05-20T03:56:28.989325Z'}
{'type': 'l2update', 'product_id': 'BTC-USD', 'changes': [['buy', '38309.19', '0.00000000']], 'time': '2021-05-20T03:56:28.992274Z'}
{'type': 'l2update', 'product_id': 'BTC-USD', 'changes': [['sell', '38482.88', '0.01113581']], 'time': '2021-05-20T03:56:28.993762Z'}
{'type': 'l2update', 'product_id': 'BTC-USD', 'changes': [['buy', '38305.94', '0.06193344']], 'time': '2021-05-20T03:56:28.994892Z'}
{'type': 'l2update', 'product_id': 'BTC-USD', 'changes': [['sell', '38348.78', '0.05000746']], 'time': '2021-05-20T03:56:28.994892Z'}
{'type': 'l2update', 'product_id': 'BTC-USD', 'changes': [['sell', '38422.05', '0.03218500']], 'time': '2021-05-20T03:56:28.996113Z'}
{'type': 'l2update', 'product_id': 'BTC-USD', 'changes': [['sell', '38373.67', '0.05086873']], 'time': '2021-05-20T03:56:28.996766Z'}
{'type': 'l2update', 'product_id': 'BTC-USD', 'changes': [['buy', '38227.92', '0.01000000']], 'time': '2021-05-20T03:56:29.005962Z'}
{'type': 'l2update', 'product_id': 'BTC-USD', 'changes': [['sell', '38434.16', '0.61409638']], 'time': '2021-05-20T03:56:29.006170Z'}
{'type': 'l2update', 'product_id': 'BTC-USD', 'changes': [['sell', '38396.07', '0.00000000']], 'time': '2021-05-20T03:56:29.006196Z'}
{'type': 'l2update', 'product_id': 'BTC-USD', 'changes': [['sell', '38495.07', '0.00000000']], 'time': '2021-05-20T03:56:29.006737Z'}
{'type': 'l2update', 'product_id': 'BTC-USD', 'changes': [['sell', '38333.74', '0.04835734']], 'time': '2021-05-20T03:56:29.011621Z'}
{'type': 'l2update', 'product_id': 'BTC-USD', 'changes': [['sell', '38335.00', '0.00000000']], 'time': '2021-05-20T03:56:29.012593Z'}
{'type': 'l2update', 'product_id': 'BTC-USD', 'changes': [['sell', '38333.74', '0.04711255']], 'time': '2021-05-20T03:56:29.015757Z'}
{'type': 'l2update', 'product_id': 'BTC-USD', 'changes': [['sell', '38495.76', '0.00000000']], 'time': '2021-05-20T03:56:29.017033Z'}
{'type': 'l2update', 'product_id': 'BTC-USD', 'changes': [['sell', '38351.52', '0.05000000']], 'time': '2021-05-20T03:56:29.020305Z'}
{'type': 'l2update', 'product_id': 'BTC-USD', 'changes': [['buy', '38297.32', '0.05150838']], 'time': '2021-05-20T03:56:29.020711Z'}
{'type': 'l2update', 'product_id': 'BTC-USD', 'changes': [['buy', '38250.19', '0.01000000']], 'time': '2021-05-20T03:56:29.020883Z'}
{'type': 'l2update', 'product_id': 'BTC-USD', 'changes': [['sell', '38409.35', '0.01000000']], 'time': '2021-05-20T03:56:29.021373Z'}
{'type': 'l2update', 'product_id': 'BTC-USD', 'changes': [['buy', '38241.97', '0.00000000']], 'time': '2021-05-20T03:56:29.029169Z'}
{'type': 'l2update', 'product_id': 'BTC-USD', 'changes': [['buy', '38130.01', '0.95102270']], 'time': '2021-05-20T03:56:29.034622Z'}
{'type': 'l2update', 'product_id': 'BTC-USD', 'changes': [['sell', '38335.97', '0.00000000']], 'time': '2021-05-20T03:56:29.035594Z'}
{'type': 'l2update', 'product_id': 'BTC-USD', 'changes': [['sell', '38428.93', '0.03198549']], 'time': '2021-05-20T03:56:29.041685Z'}
{'type': 'l2update', 'product_id': 'BTC-USD', 'changes': [['sell', '38412.14', '0.07074473']], 'time': '2021-05-20T03:56:29.041685Z'}
{'type': 'l2update', 'product_id': 'BTC-USD', 'changes': [['sell', '38411.46', '0.39993079']], 'time': '2021-05-20T03:56:29.042762Z'}
{'type': 'l2update', 'product_id': 'BTC-USD', 'changes': [['sell', '38333.69', '0.59200000']], 'time': '2021-05-20T03:56:29.042912Z'}
{'type': 'l2update', 'product_id': 'BTC-USD', 'changes': [['buy', '38250.19', '0.00000000']], 'time': '2021-05-20T03:56:29.052269Z'}
{'type': 'l2update', 'product_id': 'BTC-USD', 'changes': [['sell', '38405.84', '0.68149731']], 'time': '2021-05-20T03:56:29.052970Z'}
{'type': 'l2update', 'product_id': 'BTC-USD', 'changes': [['sell', '38350.70', '0.00000000']], 'time': '2021-05-20T03:56:29.055549Z'}
{'type': 'l2update', 'product_id': 'BTC-USD', 'changes': [['buy', '38288.42', '0.08000000']], 'time': '2021-05-20T03:56:29.064540Z'}
{'type': 'l2update', 'product_id': 'BTC-USD', 'changes': [['sell', '38446.57', '0.00000000']], 'time': '2021-05-20T03:56:29.064800Z'}
{'type': 'l2update', 'product_id': 'BTC-USD', 'changes': [['sell', '38446.91', '0.00000000']], 'time': '2021-05-20T03:56:29.069147Z'}
{'type': 'l2update', 'product_id': 'BTC-USD', 'changes': [['sell', '38452.90', '0.01207004']], 'time': '2021-05-20T03:56:29.074814Z'}
{'type': 'l2update', 'product_id': 'BTC-USD', 'changes': [['sell', '38522.64', '0.01774908']], 'time': '2021-05-20T03:56:29.074834Z'}
{'type': 'l2update', 'product_id': 'BTC-USD', 'changes': [['buy', '38215.50', '0.01000000']], 'time': '2021-05-20T03:56:29.083486Z'}
{'type': 'l2update', 'product_id': 'BTC-USD', 'changes': [['sell', '38347.23', '0.00000000']], 'time': '2021-05-20T03:56:29.086643Z'}
{'type': 'l2update', 'product_id': 'BTC-USD', 'changes': [['buy', '38288.42', '0.05000000']], 'time': '2021-05-20T03:56:29.086688Z'}
{'type': 'l2update', 'product_id': 'BTC-USD', 'changes': [['sell', '38446.57', '0.02796531']], 'time': '2021-05-20T03:56:29.096715Z'}
{'type': 'l2update', 'product_id': 'BTC-USD', 'changes': [['sell', '38375.75', '0.03224201']], 'time': '2021-05-20T03:56:29.096715Z'}
{'type': 'l2update', 'product_id': 'BTC-USD', 'changes': [['sell', '38364.05', '0.44000000']], 'time': '2021-05-20T03:56:29.100590Z'}
{'type': 'l2update', 'product_id': 'BTC-USD', 'changes': [['sell', '38395.28', '0.30558754']], 'time': '2021-05-20T03:56:29.100683Z'}
{'type': 'l2update', 'product_id': 'BTC-USD', 'changes': [['buy', '38288.42', '0.01000000']], 'time': '2021-05-20T03:56:29.105635Z'}
{'type': 'l2update', 'product_id': 'BTC-USD', 'changes': [['sell', '38392.00', '0.00000000']], 'time': '2021-05-20T03:56:29.115253Z'}
{'type': 'l2update', 'product_id': 'BTC-USD', 'changes': [['sell', '38434.16', '0.30850884']], 'time': '2021-05-20T03:56:29.120923Z'}
{'type': 'l2update', 'product_id': 'BTC-USD', 'changes': [['buy', '38287.49', '0.00000000']], 'time': '2021-05-20T03:56:29.124368Z'}
{'type': 'l2update', 'product_id': 'BTC-USD', 'changes': [['sell', '38363.05', '0.27700000']], 'time': '2021-05-20T03:56:29.131408Z'}
{'type': 'l2update', 'product_id': 'BTC-USD', 'changes': [['sell', '38440.77', '0.03166240']], 'time': '2021-05-20T03:56:29.143126Z'}
{'type': 'l2update', 'product_id': 'BTC-USD', 'changes': [['sell', '38421.42', '0.61482416']], 'time': '2021-05-20T03:56:29.143307Z'}
{'type': 'l2update', 'product_id': 'BTC-USD', 'changes': [['sell', '38389.22', '0.50000000']], 'time': '2021-05-20T03:56:29.148870Z'}
{'type': 'l2update', 'product_id': 'BTC-USD', 'changes': [['buy', '38278.56', '0.02000000']], 'time': '2021-05-20T03:56:29.149505Z'}
{'type': 'l2update', 'product_id': 'BTC-USD', 'changes': [['sell', '38622.32', '0.00000000']], 'time': '2021-05-20T03:56:29.151200Z'}
{'type': 'l2update', 'product_id': 'BTC-USD', 'changes': [['sell', '38482.88', '0.00000000']], 'time': '2021-05-20T03:56:29.151459Z'}
{'type': 'l2update', 'product_id': 'BTC-USD', 'changes': [['sell', '38400.41', '0.30850884']], 'time': '2021-05-20T03:56:29.154190Z'}
{'type': 'l2update', 'product_id': 'BTC-USD', 'changes': [['sell', '38496.71', '0.00000000']], 'time': '2021-05-20T03:56:29.165627Z'}
{'type': 'l2update', 'product_id': 'BTC-USD', 'changes': [['sell', '38422.05', '0.00000000']], 'time': '2021-05-20T03:56:29.169949Z'}
{'type': 'l2update', 'product_id': 'BTC-USD', 'changes': [['sell', '38434.16', '0.00000000']], 'time': '2021-05-20T03:56:29.171683Z'}
{'type': 'l2update', 'product_id': 'BTC-USD', 'changes': [['sell', '38348.78', '0.00000000']], 'time': '2021-05-20T03:56:29.176982Z'}
{'type': 'l2update', 'product_id': 'BTC-USD', 'changes': [['sell', '38465.34', '0.01944398']], 'time': '2021-05-20T03:56:29.177535Z'}
{'type': 'l2update', 'product_id': 'BTC-USD', 'changes': [['sell', '38591.58', '0.00647809']], 'time': '2021-05-20T03:56:29.177574Z'}
{'type': 'l2update', 'product_id': 'BTC-USD', 'changes': [['buy', '38278.41', '0.03000000']], 'time': '2021-05-20T03:56:29.177636Z'}
{'type': 'l2update', 'product_id': 'BTC-USD', 'changes': [['sell', '38356.74', '0.05340846']], 'time': '2021-05-20T03:56:29.179858Z'}
{'type': 'l2update', 'product_id': 'BTC-USD', 'changes': [['buy', '38305.41', '0.00000000']], 'time': '2021-05-20T03:56:29.185413Z'}
{'type': 'l2update', 'product_id': 'BTC-USD', 'changes': [['sell', '38440.77', '0.06160580']], 'time': '2021-05-20T03:56:29.188898Z'}
{'type': 'l2update', 'product_id': 'BTC-USD', 'changes': [['sell', '38483.01', '0.01280690']], 'time': '2021-05-20T03:56:29.189192Z'}
{'type': 'l2update', 'product_id': 'BTC-USD', 'changes': [['sell', '38504.57', '0.00000000']], 'time': '2021-05-20T03:56:29.189882Z'}
{'type': 'l2update', 'product_id': 'BTC-USD', 'changes': [['sell', '38356.74', '0.00000000']], 'time': '2021-05-20T03:56:29.194484Z'}
{'type': 'l2update', 'product_id': 'BTC-USD', 'changes': [['sell', '38364.69', '0.42040229']], 'time': '2021-05-20T03:56:29.194883Z'}
{'type': 'l2update', 'product_id': 'BTC-USD', 'changes': [['sell', '38468.76', '0.00000000']], 'time': '2021-05-20T03:56:29.195741Z'}
{'type': 'l2update', 'product_id': 'BTC-USD', 'changes': [['sell', '38591.58', '0.00000000']], 'time': '2021-05-20T03:56:29.199215Z'}
{'type': 'l2update', 'product_id': 'BTC-USD', 'changes': [['buy', '38274.34', '0.04000000']], 'time': '2021-05-20T03:56:29.200078Z'}
{'type': 'l2update', 'product_id': 'BTC-USD', 'changes': [['sell', '38522.64', '0.00000000']], 'time': '2021-05-20T03:56:29.204501Z'}
{'type': 'l2update', 'product_id': 'BTC-USD', 'changes': [['buy', '38303.58', '0.44600000']], 'time': '2021-05-20T03:56:29.206603Z'}
{'type': 'l2update', 'product_id': 'BTC-USD', 'changes': [['buy', '38276.50', '0.00000000']], 'time': '2021-05-20T03:56:29.208228Z'}
{'type': 'l2update', 'product_id': 'BTC-USD', 'changes': [['sell', '38377.00', '0.00000000']], 'time': '2021-05-20T03:56:29.212535Z'}
{'type': 'l2update', 'product_id': 'BTC-USD', 'changes': [['sell', '38456.36', '0.01000000']], 'time': '2021-05-20T03:56:29.218949Z'}
{'type': 'l2update', 'product_id': 'BTC-USD', 'changes': [['sell', '38427.71', '0.11584800']], 'time': '2021-05-20T03:56:29.219482Z'}
{'type': 'l2update', 'product_id': 'BTC-USD', 'changes': [['sell', '38486.12', '0.01299169']], 'time': '2021-05-20T03:56:29.219548Z'}
{'type': 'l2update', 'product_id': 'BTC-USD', 'changes': [['buy', '38303.58', '0.00000000']], 'time': '2021-05-20T03:56:29.220289Z'}
{'type': 'l2update', 'product_id': 'BTC-USD', 'changes': [['buy', '38273.71', '0.05000000']], 'time': '2021-05-20T03:56:29.232531Z'}
{'type': 'l2update', 'product_id': 'BTC-USD', 'changes': [['buy', '38271.51', '0.10000000']], 'time': '2021-05-20T03:56:29.235143Z'}
{'type': 'l2update', 'product_id': 'BTC-USD', 'changes': [['sell', '38499.57', '0.01774908']], 'time': '2021-05-20T03:56:29.235532Z'}
{'type': 'l2update', 'product_id': 'BTC-USD', 'changes': [['sell', '38380.12', '0.31218496']], 'time': '2021-05-20T03:56:29.235601Z'}
{'type': 'l2update', 'product_id': 'BTC-USD', 'changes': [['buy', '38256.01', '1.95510000']], 'time': '2021-05-20T03:56:29.249102Z'}
{'type': 'l2update', 'product_id': 'BTC-USD', 'changes': [['sell', '38346.78', '0.04578753']], 'time': '2021-05-20T03:56:29.251212Z'}
{'type': 'l2update', 'product_id': 'BTC-USD', 'changes': [['sell', '38458.97', '0.00000000']], 'time': '2021-05-20T03:56:29.251415Z'}
{'type': 'l2update', 'product_id': 'BTC-USD', 'changes': [['sell', '38608.87', '0.01000000']], 'time': '2021-05-20T03:56:29.256347Z'}
{'type': 'l2update', 'product_id': 'BTC-USD', 'changes': [['buy', '38193.73', '0.00000000']], 'time': '2021-05-20T03:56:29.257107Z'}
{'type': 'l2update', 'product_id': 'BTC-USD', 'changes': [['sell', '38401.01', '0.00000000']], 'time': '2021-05-20T03:56:29.257149Z'}
{'type': 'l2update', 'product_id': 'BTC-USD', 'changes': [['sell', '38335.91', '0.00000000']], 'time': '2021-05-20T03:56:29.260688Z'}
{'type': 'l2update', 'product_id': 'BTC-USD', 'changes': [['sell', '38446.67', '0.00000000']], 'time': '2021-05-20T03:56:29.264116Z'}
{'type': 'l2update', 'product_id': 'BTC-USD', 'changes': [['buy', '38303.08', '0.00000000']], 'time': '2021-05-20T03:56:29.265219Z'}
{'type': 'l2update', 'product_id': 'BTC-USD', 'changes': [['sell', '38333.69', '0.39200000']], 'time': '2021-05-20T03:56:29.270520Z'}
{'type': 'l2update', 'product_id': 'BTC-USD', 'changes': [['buy', '38237.94', '0.00000000']], 'time': '2021-05-20T03:56:29.274173Z'}
{'type': 'l2update', 'product_id': 'BTC-USD', 'changes': [['sell', '38447.10', '0.01000000']], 'time': '2021-05-20T03:56:29.281869Z'}
{'type': 'l2update', 'product_id': 'BTC-USD', 'changes': [['sell', '38542.51', '0.00000000']], 'time': '2021-05-20T03:56:29.283791Z'}
{'type': 'l2update', 'product_id': 'BTC-USD', 'changes': [['sell', '38389.43', '0.39993079']], 'time': '2021-05-20T03:56:29.289445Z'}
{'type': 'l2update', 'product_id': 'BTC-USD', 'changes': [['sell', '38422.80', '0.01000000']], 'time': '2021-05-20T03:56:29.293486Z'}
{'type': 'l2update', 'product_id': 'BTC-USD', 'changes': [['sell', '38333.68', '2.48969908']], 'time': '2021-05-20T03:56:29.293543Z'}
{'type': 'l2update', 'product_id': 'BTC-USD', 'changes': [['sell', '38477.22', '0.00000000']], 'time': '2021-05-20T03:56:29.296876Z'}
{'type': 'l2update', 'product_id': 'BTC-USD', 'changes': [['buy', '38298.70', '0.03884941']], 'time': '2021-05-20T03:56:29.303287Z'}
{'type': 'l2update', 'product_id': 'BTC-USD', 'changes': [['buy', '38325.14', '0.00000000']], 'time': '2021-05-20T03:56:29.304891Z'}
{'type': 'l2update', 'product_id': 'BTC-USD', 'changes': [['sell', '38365.89', '0.00000000']], 'time': '2021-05-20T03:56:29.309233Z'}
{'type': 'l2update', 'product_id': 'BTC-USD', 'changes': [['sell', '38411.46', '0.00000000']], 'time': '2021-05-20T03:56:29.309906Z'}
{'type': 'l2update', 'product_id': 'BTC-USD', 'changes': [['sell', '38483.01', '0.00000000']], 'time': '2021-05-20T03:56:29.311822Z'}
{'type': 'l2update', 'product_id': 'BTC-USD', 'changes': [['buy', '38309.27', '0.84700000']], 'time': '2021-05-20T03:56:29.312845Z'}
{'type': 'l2update', 'product_id': 'BTC-USD', 'changes': [['sell', '38529.01', '0.02392950']], 'time': '2021-05-20T03:56:29.319931Z'}
{'type': 'l2update', 'product_id': 'BTC-USD', 'changes': [['buy', '38282.51', '0.00000000']], 'time': '2021-05-20T03:56:29.320513Z'}
{'type': 'l2update', 'product_id': 'BTC-USD', 'changes': [['buy', '38218.88', '0.01000000']], 'time': '2021-05-20T03:56:29.320711Z'}
{'type': 'l2update', 'product_id': 'BTC-USD', 'changes': [['sell', '38405.84', '0.00000000']], 'time': '2021-05-20T03:56:29.323451Z'}
{'type': 'l2update', 'product_id': 'BTC-USD', 'changes': [['sell', '38448.96', '0.01000000']], 'time': '2021-05-20T03:56:29.328987Z'}
{'type': 'l2update', 'product_id': 'BTC-USD', 'changes': [['buy', '38309.22', '0.00000000']], 'time': '2021-05-20T03:56:29.329233Z'}
{'type': 'l2update', 'product_id': 'BTC-USD', 'changes': [['buy', '38154.97', '0.00000000']], 'time': '2021-05-20T03:56:29.336017Z'}
{'type': 'l2update', 'product_id': 'BTC-USD', 'changes': [['sell', '38417.51', '0.00000000']], 'time': '2021-05-20T03:56:29.337016Z'}
{'type': 'l2update', 'product_id': 'BTC-USD', 'changes': [['buy', '38300.33', '0.46520000']], 'time': '2021-05-20T03:56:29.339408Z'}
{'type': 'l2update', 'product_id': 'BTC-USD', 'changes': [['sell', '38416.03', '0.36987569']], 'time': '2021-05-20T03:56:29.339672Z'}
{'type': 'l2update', 'product_id': 'BTC-USD', 'changes': [['sell', '38377.00', '0.30558754']], 'time': '2021-05-20T03:56:29.339672Z'}
{'type': 'l2update', 'product_id': 'BTC-USD', 'changes': [['buy', '38305.94', '0.00000000']], 'time': '2021-05-20T03:56:29.341413Z'}
{'type': 'l2update', 'product_id': 'BTC-USD', 'changes': [['sell', '38346.78', '0.00000000']], 'time': '2021-05-20T03:56:29.341413Z'}
{'type': 'l2update', 'product_id': 'BTC-USD', 'changes': [['buy', '38303.19', '0.03884941']], 'time': '2021-05-20T03:56:29.343436Z'}
{'type': 'l2update', 'product_id': 'BTC-USD', 'changes': [['sell', '38464.74', '0.01280690']], 'time': '2021-05-20T03:56:29.343497Z'}
{'type': 'l2update', 'product_id': 'BTC-USD', 'changes': [['sell', '38443.00', '0.00000000']], 'time': '2021-05-20T03:56:29.343550Z'}
{'type': 'l2update', 'product_id': 'BTC-USD', 'changes': [['buy', '38298.70', '0.00000000']], 'time': '2021-05-20T03:56:29.343974Z'}
{'type': 'l2update', 'product_id': 'BTC-USD', 'changes': [['buy', '38327.66', '0.01474526']], 'time': '2021-05-20T03:56:29.348292Z'}
{'type': 'l2update', 'product_id': 'BTC-USD', 'changes': [['buy', '38319.93', '0.05184983']], 'time': '2021-05-20T03:56:29.353649Z'}
{'type': 'l2update', 'product_id': 'BTC-USD', 'changes': [['sell', '38364.05', '0.00000000']], 'time': '2021-05-20T03:56:29.358091Z'}
{'type': 'l2update', 'product_id': 'BTC-USD', 'changes': [['sell', '38450.20', '0.00000000']], 'time': '2021-05-20T03:56:29.359339Z'}
{'type': 'l2update', 'product_id': 'BTC-USD', 'changes': [['sell', '38395.28', '0.00000000']], 'time': '2021-05-20T03:56:29.359339Z'}
{'type': 'l2update', 'product_id': 'BTC-USD', 'changes': [['buy', '38144.27', '0.02621625']], 'time': '2021-05-20T03:56:29.365417Z'}
{'type': 'l2update', 'product_id': 'BTC-USD', 'changes': [['buy', '38309.28', '0.59116555']], 'time': '2021-05-20T03:56:29.366626Z'}
{'type': 'l2update', 'product_id': 'BTC-USD', 'changes': [['sell', '38430.46', '0.01000000']], 'time': '2021-05-20T03:56:29.370602Z'}
{'type': 'l2update', 'product_id': 'BTC-USD', 'changes': [['buy', '38300.61', '0.00000000']], 'time': '2021-05-20T03:56:29.380264Z'}
{'type': 'l2update', 'product_id': 'BTC-USD', 'changes': [['sell', '38451.86', '0.00000000']], 'time': '2021-05-20T03:56:29.383959Z'}
{'type': 'l2update', 'product_id': 'BTC-USD', 'changes': [['sell', '38380.12', '0.00000000']], 'time': '2021-05-20T03:56:29.383959Z'}
{'type': 'l2update', 'product_id': 'BTC-USD', 'changes': [['sell', '38366.89', '0.41830000']], 'time': '2021-05-20T03:56:29.385431Z'}
{'type': 'l2update', 'product_id': 'BTC-USD', 'changes': [['buy', '38309.27', '0.00000000']], 'time': '2021-05-20T03:56:29.385490Z'}
{'type': 'l2update', 'product_id': 'BTC-USD', 'changes': [['sell', '38366.89', '0.00000000']], 'time': '2021-05-20T03:56:29.400910Z'}
{'type': 'l2update', 'product_id': 'BTC-USD', 'changes': [['buy', '38303.19', '0.00000000']], 'time': '2021-05-20T03:56:29.404221Z'}
{'type': 'l2update', 'product_id': 'BTC-USD', 'changes': [['sell', '39430.75', '0.00000000']], 'time': '2021-05-20T03:56:29.411596Z'}
{'type': 'l2update', 'product_id': 'BTC-USD', 'changes': [['sell', '39431.86', '0.06300000']], 'time': '2021-05-20T03:56:29.411596Z'}
{'type': 'l2update', 'product_id': 'BTC-USD', 'changes': [['sell', '38355.87', '0.05000000']], 'time': '2021-05-20T03:56:29.413869Z'}
{'type': 'l2update', 'product_id': 'BTC-USD', 'changes': [['sell', '38333.68', '2.48921909']], 'time': '2021-05-20T03:56:29.414658Z'}
{'type': 'l2update', 'product_id': 'BTC-USD', 'changes': [['buy', '38290.47', '0.03522338']], 'time': '2021-05-20T03:56:29.414732Z'}
{'type': 'l2update', 'product_id': 'BTC-USD', 'changes': [['buy', '38129.89', '0.00000000']], 'time': '2021-05-20T03:56:29.415646Z'}
{'type': 'l2update', 'product_id': 'BTC-USD', 'changes': [['sell', '39499.99', '0.06400000']], 'time': '2021-05-20T03:56:29.425658Z'}
{'type': 'l2update', 'product_id': 'BTC-USD', 'changes': [['sell', '39495.99', '0.00260000']], 'time': '2021-05-20T03:56:29.425658Z'}
{'type': 'l2update', 'product_id': 'BTC-USD', 'changes': [['sell', '38333.68', '0.00000000']], 'time': '2021-05-20T03:56:29.426137Z'}
{'type': 'l2update', 'product_id': 'BTC-USD', 'changes': [['sell', '38466.30', '0.00000000']], 'time': '2021-05-20T03:56:29.426698Z'}
{'type': 'l2update', 'product_id': 'BTC-USD', 'changes': [['sell', '38455.19', '0.00000000']], 'time': '2021-05-20T03:56:29.426698Z'}
{'type': 'l2update', 'product_id': 'BTC-USD', 'changes': [['sell', '38454.56', '0.00000000']], 'time': '2021-05-20T03:56:29.426698Z'}
{'type': 'l2update', 'product_id': 'BTC-USD', 'changes': [['sell', '38453.57', '0.00000000']], 'time': '2021-05-20T03:56:29.426698Z'}
{'type': 'l2update', 'product_id': 'BTC-USD', 'changes': [['sell', '38416.03', '0.00000000']], 'time': '2021-05-20T03:56:29.426698Z'}
{'type': 'l2update', 'product_id': 'BTC-USD', 'changes': [['sell', '38400.41', '0.00000000']], 'time': '2021-05-20T03:56:29.426698Z'}
{'type': 'l2update', 'product_id': 'BTC-USD', 'changes': [['sell', '38389.43', '0.00000000']], 'time': '2021-05-20T03:56:29.426698Z'}
{'type': 'l2update', 'product_id': 'BTC-USD', 'changes': [['sell', '38377.00', '0.00000000']], 'time': '2021-05-20T03:56:29.426698Z'}
{'type': 'l2update', 'product_id': 'BTC-USD', 'changes': [['buy', '38299.18', '0.03522338']], 'time': '2021-05-20T03:56:29.429682Z'}
{'type': 'l2update', 'product_id': 'BTC-USD', 'changes': [['buy', '38309.26', '0.84800000']], 'time': '2021-05-20T03:56:29.429905Z'}
{'type': 'l2update', 'product_id': 'BTC-USD', 'changes': [['buy', '38215.50', '0.00000000']], 'time': '2021-05-20T03:56:29.435672Z'}
{'type': 'l2update', 'product_id': 'BTC-USD', 'changes': [['buy', '38309.21', '0.00000000']], 'time': '2021-05-20T03:56:29.438549Z'}
{'type': 'l2update', 'product_id': 'BTC-USD', 'changes': [['buy', '38300.33', '0.00000000']], 'time': '2021-05-20T03:56:29.439757Z'}
{'type': 'l2update', 'product_id': 'BTC-USD', 'changes': [['buy', '38297.43', '0.03884941']], 'time': '2021-05-20T03:56:29.442495Z'}
{'type': 'l2update', 'product_id': 'BTC-USD', 'changes': [['buy', '38299.18', '0.00000000']], 'time': '2021-05-20T03:56:29.443391Z'}
{'type': 'l2update', 'product_id': 'BTC-USD', 'changes': [['buy', '38290.47', '0.00000000']], 'time': '2021-05-20T03:56:29.451164Z'}
{'type': 'l2update', 'product_id': 'BTC-USD', 'changes': [['buy', '38299.44', '0.06490092']], 'time': '2021-05-20T03:56:29.451996Z'}
{'type': 'l2update', 'product_id': 'BTC-USD', 'changes': [['sell', '38341.23', '0.04123959']], 'time': '2021-05-20T03:56:29.451996Z'}
{'type': 'l2update', 'product_id': 'BTC-USD', 'changes': [['buy', '38231.69', '0.01000000']], 'time': '2021-05-20T03:56:29.456931Z'}
{'type': 'l2update', 'product_id': 'BTC-USD', 'changes': [['sell', '38333.68', '2.48969908']], 'time': '2021-05-20T03:56:29.471829Z'}
{'type': 'l2update', 'product_id': 'BTC-USD', 'changes': [['buy', '38297.85', '0.46550000']], 'time': '2021-05-20T03:56:29.472372Z'}
{'type': 'l2update', 'product_id': 'BTC-USD', 'changes': [['buy', '38297.85', '0.00000000']], 'time': '2021-05-20T03:56:29.484408Z'}
{'type': 'l2update', 'product_id': 'BTC-USD', 'changes': [['buy', '38297.43', '0.00000000']], 'time': '2021-05-20T03:56:29.485447Z'}
{'type': 'l2update', 'product_id': 'BTC-USD', 'changes': [['sell', '38352.56', '0.00000000']], 'time': '2021-05-20T03:56:29.486809Z'}
{'type': 'l2update', 'product_id': 'BTC-USD', 'changes': [['buy', '38301.77', '0.00000000']], 'time': '2021-05-20T03:56:29.487270Z'}
{'type': 'l2update', 'product_id': 'BTC-USD', 'changes': [['buy', '38309.28', '2.58051512']], 'time': '2021-05-20T03:56:29.489356Z'}
{'type': 'l2update', 'product_id': 'BTC-USD', 'changes': [['buy', '38300.01', '0.03522338']], 'time': '2021-05-20T03:56:29.489869Z'}
{'type': 'l2update', 'product_id': 'BTC-USD', 'changes': [['sell', '38364.69', '0.72421218']], 'time': '2021-05-20T03:56:29.490599Z'}
{'type': 'l2update', 'product_id': 'BTC-USD', 'changes': [['buy', '38309.28', '1.98934957']], 'time': '2021-05-20T03:56:29.503903Z'}
{'type': 'l2update', 'product_id': 'BTC-USD', 'changes': [['sell', '38354.48', '0.43990000']], 'time': '2021-05-20T03:56:29.507490Z'}
{'type': 'l2update', 'product_id': 'BTC-USD', 'changes': [['sell', '38371.71', '0.65369058']], 'time': '2021-05-20T03:56:29.507969Z'}
{'type': 'l2update', 'product_id': 'BTC-USD', 'changes': [['sell', '38367.58', '0.37214664']], 'time': '2021-05-20T03:56:29.513689Z'}
{'type': 'l2update', 'product_id': 'BTC-USD', 'changes': [['buy', '38298.97', '0.02400000']], 'time': '2021-05-20T03:56:29.514245Z'}
{'type': 'l2update', 'product_id': 'BTC-USD', 'changes': [['sell', '38354.48', '0.00000000']], 'time': '2021-05-20T03:56:29.519611Z'}
{'type': 'l2update', 'product_id': 'BTC-USD', 'changes': [['buy', '38308.36', '0.03884941']], 'time': '2021-05-20T03:56:29.523526Z'}
{'type': 'l2update', 'product_id': 'BTC-USD', 'changes': [['buy', '38238.70', '0.02400000']], 'time': '2021-05-20T03:56:29.528359Z'}
{'type': 'l2update', 'product_id': 'BTC-USD', 'changes': [['buy', '38218.88', '0.00000000']], 'time': '2021-05-20T03:56:29.532086Z'}
{'type': 'l2update', 'product_id': 'BTC-USD', 'changes': [['buy', '38309.29', '0.59116555']], 'time': '2021-05-20T03:56:29.534993Z'}
{'type': 'l2update', 'product_id': 'BTC-USD', 'changes': [['sell', '38363.05', '0.00000000']], 'time': '2021-05-20T03:56:29.538791Z'}
{'type': 'l2update', 'product_id': 'BTC-USD', 'changes': [['sell', '38371.57', '0.38755687']], 'time': '2021-05-20T03:56:29.540320Z'}
{'type': 'l2update', 'product_id': 'BTC-USD', 'changes': [['buy', '38152.17', '0.00000000']], 'time': '2021-05-20T03:56:29.547795Z'}
{'type': 'l2update', 'product_id': 'BTC-USD', 'changes': [['sell', '38464.74', '0.00000000']], 'time': '2021-05-20T03:56:29.551188Z'}
{'type': 'l2update', 'product_id': 'BTC-USD', 'changes': [['sell', '38373.70', '2.16932808']], 'time': '2021-05-20T03:56:29.551577Z'}
{'type': 'l2update', 'product_id': 'BTC-USD', 'changes': [['buy', '38305.30', '0.03884941']], 'time': '2021-05-20T03:56:29.556379Z'}
{'type': 'l2update', 'product_id': 'BTC-USD', 'changes': [['sell', '38422.89', '0.00000000']], 'time': '2021-05-20T03:56:29.557220Z'}
{'type': 'l2update', 'product_id': 'BTC-USD', 'changes': [['sell', '38361.27', '0.00000000']], 'time': '2021-05-20T03:56:29.560668Z'}
{'type': 'l2update', 'product_id': 'BTC-USD', 'changes': [['sell', '38365.39', '0.10000000']], 'time': '2021-05-20T03:56:29.561460Z'}
{'type': 'l2update', 'product_id': 'BTC-USD', 'changes': [['sell', '38380.12', '0.35155024']], 'time': '2021-05-20T03:56:29.562154Z'}
{'type': 'l2update', 'product_id': 'BTC-USD', 'changes': [['buy', '38308.36', '0.00000000']], 'time': '2021-05-20T03:56:29.562209Z'}
{'type': 'l2update', 'product_id': 'BTC-USD', 'changes': [['buy', '38299.44', '0.00000000']], 'time': '2021-05-20T03:56:29.563222Z'}
{'type': 'l2update', 'product_id': 'BTC-USD', 'changes': [['sell', '38341.23', '0.00000000']], 'time': '2021-05-20T03:56:29.563222Z'}
{'type': 'l2update', 'product_id': 'BTC-USD', 'changes': [['sell', '38354.46', '0.05981455']], 'time': '2021-05-20T03:56:29.566531Z'}
{'type': 'l2update', 'product_id': 'BTC-USD', 'changes': [['sell', '38441.90', '0.01280690']], 'time': '2021-05-20T03:56:29.568740Z'}
{'type': 'l2update', 'product_id': 'BTC-USD', 'changes': [['buy', '38300.01', '0.00000000']], 'time': '2021-05-20T03:56:29.578602Z'}
{'type': 'l2update', 'product_id': 'BTC-USD', 'changes': [['sell', '38408.89', '0.01301782']], 'time': '2021-05-20T03:56:29.581289Z'}
{'type': 'l2update', 'product_id': 'BTC-USD', 'changes': [['buy', '38297.01', '0.46790000']], 'time': '2021-05-20T03:56:29.586285Z'}
{'type': 'l2update', 'product_id': 'BTC-USD', 'changes': [['sell', '38384.68', '0.29480165']], 'time': '2021-05-20T03:56:29.586409Z'}
{'type': 'l2update', 'product_id': 'BTC-USD', 'changes': [['sell', '38333.67', '1.47203756']], 'time': '2021-05-20T03:56:29.596970Z'}
{'type': 'l2update', 'product_id': 'BTC-USD', 'changes': [['buy', '38231.69', '0.00000000']], 'time': '2021-05-20T03:56:29.598334Z'}
{'type': 'l2update', 'product_id': 'BTC-USD', 'changes': [['sell', '38441.90', '0.00000000']], 'time': '2021-05-20T03:56:29.598362Z'}
{'type': 'l2update', 'product_id': 'BTC-USD', 'changes': [['sell', '38394.37', '0.29668765']], 'time': '2021-05-20T03:56:29.606435Z'}
{'type': 'l2update', 'product_id': 'BTC-USD', 'changes': [['buy', '38305.30', '0.00000000']], 'time': '2021-05-20T03:56:29.607152Z'}
{'type': 'l2update', 'product_id': 'BTC-USD', 'changes': [['sell', '38333.67', '0.00000000']], 'time': '2021-05-20T03:56:29.608521Z'}
{'type': 'l2update', 'product_id': 'BTC-USD', 'changes': [['buy', '38327.66', '0.01298051']], 'time': '2021-05-20T03:56:29.617164Z'}
{'type': 'l2update', 'product_id': 'BTC-USD', 'changes': [['sell', '38333.68', '2.48956905']], 'time': '2021-05-20T03:56:29.619537Z'}
{'type': 'l2update', 'product_id': 'BTC-USD', 'changes': [['sell', '38358.43', '0.44970000']], 'time': '2021-05-20T03:56:29.619805Z'}
{'type': 'l2update', 'product_id': 'BTC-USD', 'changes': [['buy', '38220.13', '0.01000000']], 'time': '2021-05-20T03:56:29.620108Z'}
{'type': 'l2update', 'product_id': 'BTC-USD', 'changes': [['buy', '38290.47', '0.05981455']], 'time': '2021-05-20T03:56:29.620748Z'}
{'type': 'l2update', 'product_id': 'BTC-USD', 'changes': [['sell', '38399.50', '0.32679254']], 'time': '2021-05-20T03:56:29.629086Z'}
{'type': 'l2update', 'product_id': 'BTC-USD', 'changes': [['sell', '38333.68', '0.00000000']], 'time': '2021-05-20T03:56:29.636123Z'}
{'type': 'l2update', 'product_id': 'BTC-USD', 'changes': [['buy', '38309.28', '0.00000000']], 'time': '2021-05-20T03:56:29.641681Z'}
{'type': 'l2update', 'product_id': 'BTC-USD', 'changes': [['buy', '38297.02', '0.05981455']], 'time': '2021-05-20T03:56:29.643289Z'}
{'type': 'l2update', 'product_id': 'BTC-USD', 'changes': [['sell', '38410.33', '0.38882017']], 'time': '2021-05-20T03:56:29.647651Z'}
{'type': 'l2update', 'product_id': 'BTC-USD', 'changes': [['buy', '38171.70', '0.01000000']], 'time': '2021-05-20T03:56:29.648218Z'}
{'type': 'l2update', 'product_id': 'BTC-USD', 'changes': [['buy', '38308.16', '0.03884941']], 'time': '2021-05-20T03:56:29.648297Z'}
{'type': 'l2update', 'product_id': 'BTC-USD', 'changes': [['sell', '38459.44', '0.02284261']], 'time': '2021-05-20T03:56:29.652831Z'}
{'type': 'l2update', 'product_id': 'BTC-USD', 'changes': [['buy', '38005.99', '0.01000000']], 'time': '2021-05-20T03:56:29.657321Z'}
{'type': 'l2update', 'product_id': 'BTC-USD', 'changes': [['sell', '38333.68', '2.48969908']], 'time': '2021-05-20T03:56:29.659687Z'}
{'type': 'l2update', 'product_id': 'BTC-USD', 'changes': [['buy', '38327.66', '0.01474526']], 'time': '2021-05-20T03:56:29.659723Z'}
{'type': 'l2update', 'product_id': 'BTC-USD', 'changes': [['buy', '38290.47', '0.00000000']], 'time': '2021-05-20T03:56:29.666181Z'}
{'type': 'l2update', 'product_id': 'BTC-USD', 'changes': [['sell', '38416.03', '0.39174595']], 'time': '2021-05-20T03:56:29.667810Z'}
{'type': 'l2update', 'product_id': 'BTC-USD', 'changes': [['buy', '38151.22', '0.00000000']], 'time': '2021-05-20T03:56:29.669083Z'}
{'type': 'l2update', 'product_id': 'BTC-USD', 'changes': [['sell', '38499.57', '0.00000000']], 'time': '2021-05-20T03:56:29.675499Z'}
{'type': 'l2update', 'product_id': 'BTC-USD', 'changes': [['sell', '38354.46', '0.00000000']], 'time': '2021-05-20T03:56:29.677434Z'}
{'type': 'l2update', 'product_id': 'BTC-USD', 'changes': [['buy', '38297.02', '0.00000000']], 'time': '2021-05-20T03:56:29.677524Z'}
{'type': 'l2update', 'product_id': 'BTC-USD', 'changes': [['buy', '38295.71', '0.05707509']], 'time': '2021-05-20T03:56:29.678473Z'}
{'type': 'l2update', 'product_id': 'BTC-USD', 'changes': [['sell', '38344.15', '0.04698919']], 'time': '2021-05-20T03:56:29.678473Z'}
{'type': 'l2update', 'product_id': 'BTC-USD', 'changes': [['sell', '38345.15', '0.05050542']], 'time': '2021-05-20T03:56:29.678552Z'}
{'type': 'l2update', 'product_id': 'BTC-USD', 'changes': [['buy', '38309.27', '1.98947960']], 'time': '2021-05-20T03:56:29.679071Z'}
{'type': 'l2update', 'product_id': 'BTC-USD', 'changes': [['sell', '38486.12', '0.00000000']], 'time': '2021-05-20T03:56:29.681775Z'}
{'type': 'l2update', 'product_id': 'BTC-USD', 'changes': [['buy', '38300.01', '0.05981455']], 'time': '2021-05-20T03:56:29.686937Z'}
{'type': 'l2update', 'product_id': 'BTC-USD', 'changes': [['sell', '38428.02', '0.33983798']], 'time': '2021-05-20T03:56:29.687054Z'}
{'type': 'l2update', 'product_id': 'BTC-USD', 'changes': [['sell', '38358.42', '0.05981455']], 'time': '2021-05-20T03:56:29.688418Z'}
{'type': 'l2update', 'product_id': 'BTC-USD', 'changes': [['sell', '38459.44', '0.00000000']], 'time': '2021-05-20T03:56:29.689941Z'}
{'type': 'l2update', 'product_id': 'BTC-USD', 'changes': [['sell', '38479.67', '0.01774908']], 'time': '2021-05-20T03:56:29.694922Z'}
{'type': 'l2update', 'product_id': 'BTC-USD', 'changes': [['sell', '38354.46', '0.05981455']], 'time': '2021-05-20T03:56:29.695157Z'}
{'type': 'l2update', 'product_id': 'BTC-USD', 'changes': [['sell', '38371.72', '0.00000000']], 'time': '2021-05-20T03:56:29.695863Z'}
{'type': 'l2update', 'product_id': 'BTC-USD', 'changes': [['sell', '38472.10', '0.01000000']], 'time': '2021-05-20T03:56:29.697054Z'}
{'type': 'l2update', 'product_id': 'BTC-USD', 'changes': [['sell', '38345.15', '0.00000000']], 'time': '2021-05-20T03:56:29.702001Z'}
{'type': 'l2update', 'product_id': 'BTC-USD', 'changes': [['sell', '38434.30', '0.32259773']], 'time': '2021-05-20T03:56:29.703959Z'}
{'type': 'l2update', 'product_id': 'BTC-USD', 'changes': [['buy', '38308.16', '0.00000000']], 'time': '2021-05-20T03:56:29.706733Z'}
{'type': 'l2update', 'product_id': 'BTC-USD', 'changes': [['buy', '38151.58', '0.05098161']], 'time': '2021-05-20T03:56:29.711485Z'}
{'type': 'l2update', 'product_id': 'BTC-USD', 'changes': [['buy', '38300.01', '0.00000000']], 'time': '2021-05-20T03:56:29.712663Z'}
{'type': 'l2update', 'product_id': 'BTC-USD', 'changes': [['buy', '38303.15', '0.03884941']], 'time': '2021-05-20T03:56:29.715920Z'}
{'type': 'l2update', 'product_id': 'BTC-USD', 'changes': [['sell', '38484.92', '0.00000000']], 'time': '2021-05-20T03:56:29.716231Z'}
{'type': 'l2update', 'product_id': 'BTC-USD', 'changes': [['buy', '38166.74', '0.13500000']], 'time': '2021-05-20T03:56:29.724402Z'}
{'type': 'l2update', 'product_id': 'BTC-USD', 'changes': [['sell', '38440.77', '0.44339595']], 'time': '2021-05-20T03:56:29.724499Z'}
{'type': 'l2update', 'product_id': 'BTC-USD', 'changes': [['buy', '38297.02', '0.05981455']], 'time': '2021-05-20T03:56:29.725056Z'}
{'type': 'l2update', 'product_id': 'BTC-USD', 'changes': [['buy', '38274.34', '0.00000000']], 'time': '2021-05-20T03:56:29.726406Z'}
{'type': 'l2update', 'product_id': 'BTC-USD', 'changes': [['sell', '38358.42', '0.00000000']], 'time': '2021-05-20T03:56:29.727434Z'}
{'type': 'l2update', 'product_id': 'BTC-USD', 'changes': [['sell', '38512.14', '0.01000000']], 'time': '2021-05-20T03:56:29.728975Z'}
{'type': 'l2update', 'product_id': 'BTC-USD', 'changes': [['buy', '38253.40', '0.00000000']], 'time': '2021-05-20T03:56:29.735719Z'}
{'type': 'l2update', 'product_id': 'BTC-USD', 'changes': [['buy', '38307.90', '0.03884941']], 'time': '2021-05-20T03:56:29.736341Z'}
{'type': 'l2update', 'product_id': 'BTC-USD', 'changes': [['buy', '38273.71', '0.00000000']], 'time': '2021-05-20T03:56:29.736369Z'}
{'type': 'l2update', 'product_id': 'BTC-USD', 'changes': [['sell', '38329.10', '0.04929164']], 'time': '2021-05-20T03:56:29.740882Z'}
{'type': 'l2update', 'product_id': 'BTC-USD', 'changes': [['buy', '38303.15', '0.00000000']], 'time': '2021-05-20T03:56:29.745134Z'}
{'type': 'l2update', 'product_id': 'BTC-USD', 'changes': [['sell', '38469.67', '0.01000000']], 'time': '2021-05-20T03:56:29.747629Z'}
{'type': 'l2update', 'product_id': 'BTC-USD', 'changes': [['sell', '38344.15', '0.00000000']], 'time': '2021-05-20T03:56:29.751551Z'}
{'type': 'l2update', 'product_id': 'BTC-USD', 'changes': [['sell', '38333.74', '0.00000000']], 'time': '2021-05-20T03:56:29.756336Z'}
{'type': 'l2update', 'product_id': 'BTC-USD', 'changes': [['buy', '38283.92', '0.04000000']], 'time': '2021-05-20T03:56:29.761861Z'}
{'type': 'l2update', 'product_id': 'BTC-USD', 'changes': [['sell', '38608.87', '0.00000000']], 'time': '2021-05-20T03:56:29.763092Z'}
{'type': 'l2update', 'product_id': 'BTC-USD', 'changes': [['sell', '38329.10', '0.24929164']], 'time': '2021-05-20T03:56:29.767529Z'}
{'type': 'l2update', 'product_id': 'BTC-USD', 'changes': [['sell', '38448.96', '0.00000000']], 'time': '2021-05-20T03:56:29.772889Z'}
{'type': 'l2update', 'product_id': 'BTC-USD', 'changes': [['buy', '38279.67', '0.05000000']], 'time': '2021-05-20T03:56:29.775849Z'}
{'type': 'l2update', 'product_id': 'BTC-USD', 'changes': [['sell', '38334.99', '0.51683228']], 'time': '2021-05-20T03:56:29.778261Z'}
{'type': 'l2update', 'product_id': 'BTC-USD', 'changes': [['sell', '38329.05', '0.59300000']], 'time': '2021-05-20T03:56:29.783446Z'}
{'type': 'l2update', 'product_id': 'BTC-USD', 'changes': [['buy', '38234.93', '0.00000000']], 'time': '2021-05-20T03:56:29.784894Z'}
{'type': 'l2update', 'product_id': 'BTC-USD', 'changes': [['sell', '38344.06', '0.00000000']], 'time': '2021-05-20T03:56:29.793721Z'}
{'type': 'l2update', 'product_id': 'BTC-USD', 'changes': [['sell', '38447.10', '0.00000000']], 'time': '2021-05-20T03:56:29.800432Z'}
{'type': 'l2update', 'product_id': 'BTC-USD', 'changes': [['sell', '38329.10', '0.04929164']], 'time': '2021-05-20T03:56:29.801425Z'}
{'type': 'l2update', 'product_id': 'BTC-USD', 'changes': [['sell', '38437.02', '0.01817046']], 'time': '2021-05-20T03:56:29.802394Z'}
{'type': 'l2update', 'product_id': 'BTC-USD', 'changes': [['sell', '38512.14', '0.00000000']], 'time': '2021-05-20T03:56:29.802490Z'}
{'type': 'l2update', 'product_id': 'BTC-USD', 'changes': [['sell', '38651.55', '0.01000000']], 'time': '2021-05-20T03:56:29.802602Z'}
{'type': 'l2update', 'product_id': 'BTC-USD', 'changes': [['sell', '38329.09', '0.50000000']], 'time': '2021-05-20T03:56:29.802732Z'}
{'type': 'l2update', 'product_id': 'BTC-USD', 'changes': [['sell', '38374.42', '0.00000000']], 'time': '2021-05-20T03:56:29.803093Z'}
{'type': 'l2update', 'product_id': 'BTC-USD', 'changes': [['buy', '38220.13', '0.00000000']], 'time': '2021-05-20T03:56:29.809794Z'}
{'type': 'l2update', 'product_id': 'BTC-USD', 'changes': [['buy', '38307.90', '0.00000000']], 'time': '2021-05-20T03:56:29.815380Z'}
{'type': 'l2update', 'product_id': 'BTC-USD', 'changes': [['sell', '38367.66', '0.05000000']], 'time': '2021-05-20T03:56:29.820913Z'}
{'type': 'l2update', 'product_id': 'BTC-USD', 'changes': [['buy', '38214.93', '0.03593250']], 'time': '2021-05-20T03:56:29.821782Z'}
{'type': 'l2update', 'product_id': 'BTC-USD', 'changes': [['sell', '38435.23', '0.01000000']], 'time': '2021-05-20T03:56:29.821922Z'}
{'type': 'l2update', 'product_id': 'BTC-USD', 'changes': [['sell', '38351.52', '0.10981455']], 'time': '2021-05-20T03:56:29.827073Z'}
{'type': 'l2update', 'product_id': 'BTC-USD', 'changes': [['buy', '37974.15', '0.00000000']], 'time': '2021-05-20T03:56:29.832025Z'}
{'type': 'l2update', 'product_id': 'BTC-USD', 'changes': [['sell', '38354.46', '0.00000000']], 'time': '2021-05-20T03:56:29.833514Z'}
{'type': 'l2update', 'product_id': 'BTC-USD', 'changes': [['sell', '38493.84', '0.01000000']], 'time': '2021-05-20T03:56:29.834801Z'}
{'type': 'l2update', 'product_id': 'BTC-USD', 'changes': [['buy', '37504.11', '0.00000000']], 'time': '2021-05-20T03:56:29.835930Z'}
{'type': 'l2update', 'product_id': 'BTC-USD', 'changes': [['buy', '36813.63', '0.00000000']], 'time': '2021-05-20T03:56:29.835930Z'}
{'type': 'l2update', 'product_id': 'BTC-USD', 'changes': [['buy', '38245.87', '0.01000000']], 'time': '2021-05-20T03:56:29.841807Z'}
{'type': 'l2update', 'product_id': 'BTC-USD', 'changes': [['sell', '38358.43', '0.00000000']], 'time': '2021-05-20T03:56:29.842576Z'}
{'type': 'l2update', 'product_id': 'BTC-USD', 'changes': [['buy', '38271.51', '0.00000000']], 'time': '2021-05-20T03:56:29.842610Z'}
{'type': 'l2update', 'product_id': 'BTC-USD', 'changes': [['sell', '38334.99', '0.00000000']], 'time': '2021-05-20T03:56:29.854580Z'}
{'type': 'l2update', 'product_id': 'BTC-USD', 'changes': [['sell', '38357.27', '0.47650000']], 'time': '2021-05-20T03:56:29.857945Z'}
{'type': 'l2update', 'product_id': 'BTC-USD', 'changes': [['buy', '38227.22', '0.11446820']], 'time': '2021-05-20T03:56:29.858107Z'}
{'type': 'l2update', 'product_id': 'BTC-USD', 'changes': [['sell', '38341.23', '0.06371217']], 'time': '2021-05-20T03:56:29.862757Z'}
{'type': 'l2update', 'product_id': 'BTC-USD', 'changes': [['buy', '38302.34', '0.03884941']], 'time': '2021-05-20T03:56:29.863005Z'}
{'type': 'l2update', 'product_id': 'BTC-USD', 'changes': [['buy', '30000.00', '498.01170624']], 'time': '2021-05-20T03:56:29.872582Z'}
{'type': 'l2update', 'product_id': 'BTC-USD', 'changes': [['buy', '38268.51', '0.10000000']], 'time': '2021-05-20T03:56:29.877272Z'}
{'type': 'l2update', 'product_id': 'BTC-USD', 'changes': [['buy', '38302.34', '0.00000000']], 'time': '2021-05-20T03:56:29.905218Z'}
{'type': 'l2update', 'product_id': 'BTC-USD', 'changes': [['sell', '38689.76', '0.00000000']], 'time': '2021-05-20T03:56:29.905630Z'}
{'type': 'l2update', 'product_id': 'BTC-USD', 'changes': [['sell', '38369.67', '0.05000000']], 'time': '2021-05-20T03:56:29.907356Z'}
{'type': 'l2update', 'product_id': 'BTC-USD', 'changes': [['sell', '38327.67', '0.01492000']], 'time': '2021-05-20T03:56:29.908221Z'}
{'type': 'l2update', 'product_id': 'BTC-USD', 'changes': [['sell', '38327.67', '0.08952000']], 'time': '2021-05-20T03:56:29.908248Z'}
{'type': 'l2update', 'product_id': 'BTC-USD', 'changes': [['sell', '38369.67', '0.03000000']], 'time': '2021-05-20T03:56:29.913679Z'}
{'type': 'l2update', 'product_id': 'BTC-USD', 'changes': [['buy', '38308.54', '0.03884941']], 'time': '2021-05-20T03:56:29.917519Z'}
{'type': 'l2update', 'product_id': 'BTC-USD', 'changes': [['sell', '38369.67', '0.00000000']], 'time': '2021-05-20T03:56:29.917602Z'}
{'type': 'l2update', 'product_id': 'BTC-USD', 'changes': [['buy', '38303.84', '0.00000000']], 'time': '2021-05-20T03:56:29.920009Z'}
{'type': 'l2update', 'product_id': 'BTC-USD', 'changes': [['sell', '38327.67', '0.11842000']], 'time': '2021-05-20T03:56:29.922382Z'}
{'type': 'l2update', 'product_id': 'BTC-USD', 'changes': [['sell', '38327.67', '0.76842000']], 'time': '2021-05-20T03:56:29.922661Z'}
{'type': 'l2update', 'product_id': 'BTC-USD', 'changes': [['sell', '38651.55', '0.00000000']], 'time': '2021-05-20T03:56:29.923783Z'}
{'type': 'l2update', 'product_id': 'BTC-USD', 'changes': [['sell', '38369.75', '0.00000000']], 'time': '2021-05-20T03:56:29.928856Z'}
{'type': 'l2update', 'product_id': 'BTC-USD', 'changes': [['sell', '38430.46', '0.00000000']], 'time': '2021-05-20T03:56:29.929414Z'}
{'type': 'l2update', 'product_id': 'BTC-USD', 'changes': [['sell', '38357.51', '0.39490432']], 'time': '2021-05-20T03:56:29.929646Z'}
{'type': 'l2update', 'product_id': 'BTC-USD', 'changes': [['buy', '38299.18', '0.05981455']], 'time': '2021-05-20T03:56:29.929955Z'}
{'type': 'l2update', 'product_id': 'BTC-USD', 'changes': [['buy', '38297.02', '0.00000000']], 'time': '2021-05-20T03:56:29.932309Z'}
{'type': 'l2update', 'product_id': 'BTC-USD', 'changes': [['sell', '38633.30', '0.01000000']], 'time': '2021-05-20T03:56:29.945046Z'}
{'type': 'l2update', 'product_id': 'BTC-USD', 'changes': [['sell', '38362.64', '0.01000000']], 'time': '2021-05-20T03:56:29.945231Z'}
{'type': 'l2update', 'product_id': 'BTC-USD', 'changes': [['sell', '38447.43', '0.35734277']], 'time': '2021-05-20T03:56:29.945742Z'}
{'type': 'l2update', 'product_id': 'BTC-USD', 'changes': [['sell', '38417.57', '0.03256930']], 'time': '2021-05-20T03:56:29.950785Z'}
{'type': 'l2update', 'product_id': 'BTC-USD', 'changes': [['buy', '38308.54', '0.00000000']], 'time': '2021-05-20T03:56:29.951466Z'}
{'type': 'l2update', 'product_id': 'BTC-USD', 'changes': [['buy', '38327.66', '0.01298051']], 'time': '2021-05-20T03:56:29.955014Z'}
{'type': 'l2update', 'product_id': 'BTC-USD', 'changes': [['buy', '38295.71', '0.00000000']], 'time': '2021-05-20T03:56:29.955652Z'}
{'type': 'l2update', 'product_id': 'BTC-USD', 'changes': [['sell', '38341.23', '0.00000000']], 'time': '2021-05-20T03:56:29.955652Z'}
{'type': 'l2update', 'product_id': 'BTC-USD', 'changes': [['buy', '38299.18', '0.00000000']], 'time': '2021-05-20T03:56:29.956966Z'}
{'type': 'l2update', 'product_id': 'BTC-USD', 'changes': [['sell', '38362.64', '0.03000000']], 'time': '2021-05-20T03:56:29.963600Z'}
{'type': 'l2update', 'product_id': 'BTC-USD', 'changes': [['buy', '38297.02', '0.05981455']], 'time': '2021-05-20T03:56:29.970519Z'}
{'type': 'l2update', 'product_id': 'BTC-USD', 'changes': [['sell', '38454.28', '0.30396324']], 'time': '2021-05-20T03:56:29.970638Z'}
{'type': 'l2update', 'product_id': 'BTC-USD', 'changes': [['sell', '38362.64', '0.06000000']], 'time': '2021-05-20T03:56:29.978909Z'}
{'type': 'l2update', 'product_id': 'BTC-USD', 'changes': [['buy', '38305.32', '0.03884941']], 'time': '2021-05-20T03:56:29.979118Z'}
{'type': 'l2update', 'product_id': 'BTC-USD', 'changes': [['sell', '38447.56', '0.00000000']], 'time': '2021-05-20T03:56:29.985886Z'}
{'type': 'l2update', 'product_id': 'BTC-USD', 'changes': [['sell', '38371.68', '0.01000000']], 'time': '2021-05-20T03:56:29.988550Z'}
{'type': 'l2update', 'product_id': 'BTC-USD', 'changes': [['sell', '38362.64', '0.10000000']], 'time': '2021-05-20T03:56:29.994643Z'}
{'type': 'l2update', 'product_id': 'BTC-USD', 'changes': [['sell', '38754.85', '0.00197097']], 'time': '2021-05-20T03:56:29.996141Z'}
{'type': 'l2update', 'product_id': 'BTC-USD', 'changes': [['sell', '38435.96', '0.01502109']], 'time': '2021-05-20T03:56:29.999787Z'}
{'type': 'l2update', 'product_id': 'BTC-USD', 'changes': [['buy', '38289.27', '0.01000000']], 'time': '2021-05-20T03:56:30.003945Z'}
{'type': 'l2update', 'product_id': 'BTC-USD', 'changes': [['sell', '38475.47', '0.00000000']], 'time': '2021-05-20T03:56:30.008996Z'}
{'type': 'l2update', 'product_id': 'BTC-USD', 'changes': [['buy', '38327.66', '0.01474526']], 'time': '2021-05-20T03:56:30.012833Z'}
{'type': 'l2update', 'product_id': 'BTC-USD', 'changes': [['buy', '38299.18', '0.05981455']], 'time': '2021-05-20T03:56:30.018529Z'}
{'type': 'l2update', 'product_id': 'BTC-USD', 'changes': [['buy', '38305.32', '0.00000000']], 'time': '2021-05-20T03:56:30.019573Z'}
{'type': 'l2update', 'product_id': 'BTC-USD', 'changes': [['sell', '38351.52', '0.05000000']], 'time': '2021-05-20T03:56:30.020110Z'}
{'type': 'l2update', 'product_id': 'BTC-USD', 'changes': [['sell', '38472.31', '0.00000000']], 'time': '2021-05-20T03:56:30.020754Z'}
{'type': 'l2update', 'product_id': 'BTC-USD', 'changes': [['sell', '38346.20', '0.05981455']], 'time': '2021-05-20T03:56:30.022825Z'}
{'type': 'l2update', 'product_id': 'BTC-USD', 'changes': [['sell', '38454.36', '0.01000000']], 'time': '2021-05-20T03:56:30.024379Z'}
{'type': 'l2update', 'product_id': 'BTC-USD', 'changes': [['buy', '38297.02', '0.00000000']], 'time': '2021-05-20T03:56:30.025217Z'}
{'type': 'l2update', 'product_id': 'BTC-USD', 'changes': [['buy', '38310.96', '0.03884941']], 'time': '2021-05-20T03:56:30.028961Z'}
{'type': 'l2update', 'product_id': 'BTC-USD', 'changes': [['buy', '38171.70', '0.00000000']], 'time': '2021-05-20T03:56:30.037220Z'}
{'type': 'l2update', 'product_id': 'BTC-USD', 'changes': [['sell', '38409.35', '0.00000000']], 'time': '2021-05-20T03:56:30.039678Z'}
{'type': 'l2update', 'product_id': 'BTC-USD', 'changes': [['buy', '38299.18', '0.00000000']], 'time': '2021-05-20T03:56:30.048577Z'}
{'type': 'l2update', 'product_id': 'BTC-USD', 'changes': [['sell', '38346.20', '0.00000000']], 'time': '2021-05-20T03:56:30.048946Z'}
{'type': 'l2update', 'product_id': 'BTC-USD', 'changes': [['buy', '38183.80', '0.01000000']], 'time': '2021-05-20T03:56:30.050889Z'}
{'type': 'l2update', 'product_id': 'BTC-USD', 'changes': [['buy', '38295.04', '0.04084161']], 'time': '2021-05-20T03:56:30.051202Z'}
{'type': 'l2update', 'product_id': 'BTC-USD', 'changes': [['sell', '38338.69', '0.04187363']], 'time': '2021-05-20T03:56:30.051202Z'}
{'type': 'l2update', 'product_id': 'BTC-USD', 'changes': [['sell', '38396.34', '0.01000000']], 'time': '2021-05-20T03:56:30.055526Z'}
{'type': 'l2update', 'product_id': 'BTC-USD', 'changes': [['sell', '38489.90', '0.01000000']], 'time': '2021-05-20T03:56:30.056128Z'}
{'type': 'l2update', 'product_id': 'BTC-USD', 'changes': [['buy', '38300.61', '0.05981455']], 'time': '2021-05-20T03:56:30.057719Z'}
{'type': 'l2update', 'product_id': 'BTC-USD', 'changes': [['sell', '38351.51', '0.05981455']], 'time': '2021-05-20T03:56:30.058404Z'}
{'type': 'l2update', 'product_id': 'BTC-USD', 'changes': [['sell', '38346.20', '0.05981455']], 'time': '2021-05-20T03:56:30.061755Z'}
{'type': 'l2update', 'product_id': 'BTC-USD', 'changes': [['buy', '38310.96', '0.00000000']], 'time': '2021-05-20T03:56:30.068363Z'}
{'type': 'l2update', 'product_id': 'BTC-USD', 'changes': [['buy', '38327.66', '0.21474526']], 'time': '2021-05-20T03:56:30.070196Z'}
{'type': 'l2update', 'product_id': 'BTC-USD', 'changes': [['sell', '38351.51', '0.00000000']], 'time': '2021-05-20T03:56:30.074859Z'}
{'type': 'l2update', 'product_id': 'BTC-USD', 'changes': [['sell', '38578.88', '0.00000000']], 'time': '2021-05-20T03:56:30.090931Z'}
{'type': 'l2update', 'product_id': 'BTC-USD', 'changes': [['buy', '38298.97', '0.00000000']], 'time': '2021-05-20T03:56:30.092564Z'}
{'type': 'l2update', 'product_id': 'BTC-USD', 'changes': [['buy', '38005.99', '0.00000000']], 'time': '2021-05-20T03:56:30.093879Z'}
{'type': 'l2update', 'product_id': 'BTC-USD', 'changes': [['buy', '38304.21', '0.03884941']], 'time': '2021-05-20T03:56:30.097613Z'}
{'type': 'l2update', 'product_id': 'BTC-USD', 'changes': [['buy', '38302.36', '0.02400000']], 'time': '2021-05-20T03:56:30.104599Z'}
{'type': 'l2update', 'product_id': 'BTC-USD', 'changes': [['buy', '37997.34', '0.00000000']], 'time': '2021-05-20T03:56:30.109312Z'}
{'type': 'l2update', 'product_id': 'BTC-USD', 'changes': [['sell', '38329.05', '0.00000000']], 'time': '2021-05-20T03:56:30.115999Z'}
{'type': 'l2update', 'product_id': 'BTC-USD', 'changes': [['sell', '38654.05', '3.22896294']], 'time': '2021-05-20T03:56:30.122100Z'}
{'type': 'l2update', 'product_id': 'BTC-USD', 'changes': [['buy', '38295.04', '0.00000000']], 'time': '2021-05-20T03:56:30.122847Z'}
{'type': 'l2update', 'product_id': 'BTC-USD', 'changes': [['sell', '38338.69', '0.00000000']], 'time': '2021-05-20T03:56:30.122847Z'}
{'type': 'l2update', 'product_id': 'BTC-USD', 'changes': [['buy', '38008.63', '0.55100000']], 'time': '2021-05-20T03:56:30.124203Z'}
{'type': 'l2update', 'product_id': 'BTC-USD', 'changes': [['sell', '38327.67', '0.75350000']], 'time': '2021-05-20T03:56:30.128822Z'}
{'type': 'l2update', 'product_id': 'BTC-USD', 'changes': [['sell', '38327.67', '0.73861361']], 'time': '2021-05-20T03:56:30.128822Z'}
{'type': 'l2update', 'product_id': 'BTC-USD', 'changes': [['sell', '38333.68', '0.00000000']], 'time': '2021-05-20T03:56:30.130504Z'}
{'type': 'l2update', 'product_id': 'BTC-USD', 'changes': [['sell', '38333.63', '0.59200000']], 'time': '2021-05-20T03:56:30.132666Z'}
{'type': 'l2update', 'product_id': 'BTC-USD', 'changes': [['buy', '38303.87', '0.05981455']], 'time': '2021-05-20T03:56:30.137605Z'}
{'type': 'l2update', 'product_id': 'BTC-USD', 'changes': [['buy', '38300.61', '0.00000000']], 'time': '2021-05-20T03:56:30.141604Z'}
{'type': 'l2update', 'product_id': 'BTC-USD', 'changes': [['sell', '38633.30', '0.00000000']], 'time': '2021-05-20T03:56:30.144093Z'}
{'type': 'l2update', 'product_id': 'BTC-USD', 'changes': [['sell', '38346.20', '0.00000000']], 'time': '2021-05-20T03:56:30.145387Z'}
{'type': 'l2update', 'product_id': 'BTC-USD', 'changes': [['sell', '38329.09', '0.00000000']], 'time': '2021-05-20T03:56:30.149167Z'}
{'type': 'l2update', 'product_id': 'BTC-USD', 'changes': [['buy', '38304.21', '0.00000000']], 'time': '2021-05-20T03:56:30.149715Z'}
{'type': 'l2update', 'product_id': 'BTC-USD', 'changes': [['buy', '38303.87', '0.00000000']], 'time': '2021-05-20T03:56:30.151226Z'}
{'type': 'l2update', 'product_id': 'BTC-USD', 'changes': [['sell', '38334.97', '2.48969908']], 'time': '2021-05-20T03:56:30.153081Z'}
{'type': 'l2update', 'product_id': 'BTC-USD', 'changes': [['sell', '38351.52', '0.10981455']], 'time': '2021-05-20T03:56:30.153156Z'}
{'type': 'l2update', 'product_id': 'BTC-USD', 'changes': [['buy', '38300.96', '0.00000000']], 'time': '2021-05-20T03:56:30.156334Z'}
{'type': 'l2update', 'product_id': 'BTC-USD', 'changes': [['buy', '38300.15', '0.00000000']], 'time': '2021-05-20T03:56:30.156334Z'}
{'type': 'l2update', 'product_id': 'BTC-USD', 'changes': [['buy', '38305.72', '0.05981455']], 'time': '2021-05-20T03:56:30.164022Z'}
{'type': 'l2update', 'product_id': 'BTC-USD', 'changes': [['buy', '38287.47', '0.05446116']], 'time': '2021-05-20T03:56:30.164129Z'}
{'type': 'l2update', 'product_id': 'BTC-USD', 'changes': [['sell', '38620.27', '0.01000000']], 'time': '2021-05-20T03:56:30.168792Z'}
{'type': 'l2update', 'product_id': 'BTC-USD', 'changes': [['sell', '38333.68', '0.50000000']], 'time': '2021-05-20T03:56:30.170494Z'}
{'type': 'l2update', 'product_id': 'BTC-USD', 'changes': [['buy', '38303.42', '0.02400000']], 'time': '2021-05-20T03:56:30.174117Z'}
{'type': 'l2update', 'product_id': 'BTC-USD', 'changes': [['buy', '38301.81', '0.02400000']], 'time': '2021-05-20T03:56:30.174117Z'}
{'type': 'l2update', 'product_id': 'BTC-USD', 'changes': [['sell', '38396.34', '0.00000000']], 'time': '2021-05-20T03:56:30.178610Z'}
{'type': 'l2update', 'product_id': 'BTC-USD', 'changes': [['buy', '38297.01', '0.00000000']], 'time': '2021-05-20T03:56:30.179333Z'}
{'type': 'l2update', 'product_id': 'BTC-USD', 'changes': [['sell', '38405.24', '0.00000000']], 'time': '2021-05-20T03:56:30.179363Z'}
{'type': 'l2update', 'product_id': 'BTC-USD', 'changes': [['buy', '38311.82', '0.03884941']], 'time': '2021-05-20T03:56:30.181448Z'}
{'type': 'l2update', 'product_id': 'BTC-USD', 'changes': [['buy', '38214.93', '0.00000000']], 'time': '2021-05-20T03:56:30.181808Z'}
{'type': 'l2update', 'product_id': 'BTC-USD', 'changes': [['buy', '38217.01', '0.01000000']], 'time': '2021-05-20T03:56:30.183331Z'}
{'type': 'l2update', 'product_id': 'BTC-USD', 'changes': [['sell', '38346.20', '0.05981455']], 'time': '2021-05-20T03:56:30.183454Z'}
{'type': 'l2update', 'product_id': 'BTC-USD', 'changes': [['buy', '38298.93', '0.05175431']], 'time': '2021-05-20T03:56:30.183525Z'}
{'type': 'l2update', 'product_id': 'BTC-USD', 'changes': [['sell', '38348.12', '0.04777752']], 'time': '2021-05-20T03:56:30.183525Z'}
{'type': 'l2update', 'product_id': 'BTC-USD', 'changes': [['sell', '38620.27', '0.00000000']], 'time': '2021-05-20T03:56:30.190346Z'}
{'type': 'l2update', 'product_id': 'BTC-USD', 'changes': [['sell', '38384.03', '0.02605250']], 'time': '2021-05-20T03:56:30.191040Z'}
{'type': 'l2update', 'product_id': 'BTC-USD', 'changes': [['buy', '38298.41', '0.48430000']], 'time': '2021-05-20T03:56:30.191124Z'}
{'type': 'l2update', 'product_id': 'BTC-USD', 'changes': [['buy', '38303.87', '0.05981455']], 'time': '2021-05-20T03:56:30.191142Z'}
{'type': 'l2update', 'product_id': 'BTC-USD', 'changes': [['sell', '38351.52', '0.05000000']], 'time': '2021-05-20T03:56:30.191256Z'}
{'type': 'l2update', 'product_id': 'BTC-USD', 'changes': [['buy', '38305.72', '0.00000000']], 'time': '2021-05-20T03:56:30.191268Z'}
{'type': 'l2update', 'product_id': 'BTC-USD', 'changes': [['sell', '38421.09', '0.12256341']], 'time': '2021-05-20T03:56:30.197973Z'}
{'type': 'l2update', 'product_id': 'BTC-USD', 'changes': [['buy', '38311.82', '0.00000000']], 'time': '2021-05-20T03:56:30.198170Z'}
{'type': 'l2update', 'product_id': 'BTC-USD', 'changes': [['buy', '38303.42', '0.00000000']], 'time': '2021-05-20T03:56:30.198391Z'}
{'type': 'l2update', 'product_id': 'BTC-USD', 'changes': [['buy', '38302.36', '0.00000000']], 'time': '2021-05-20T03:56:30.198391Z'}
{'type': 'l2update', 'product_id': 'BTC-USD', 'changes': [['buy', '38301.81', '0.00000000']], 'time': '2021-05-20T03:56:30.198391Z'}
{'type': 'l2update', 'product_id': 'BTC-USD', 'changes': [['buy', '38227.43', '0.03593250']], 'time': '2021-05-20T03:56:30.201683Z'}
{'type': 'l2update', 'product_id': 'BTC-USD', 'changes': [['buy', '38311.87', '0.84600000']], 'time': '2021-05-20T03:56:30.205409Z'}
{'type': 'l2update', 'product_id': 'BTC-USD', 'changes': [['sell', '38647.29', '0.03150270']], 'time': '2021-05-20T03:56:30.208528Z'}
{'type': 'l2update', 'product_id': 'BTC-USD', 'changes': [['sell', '38327.67', '0.08861361']], 'time': '2021-05-20T03:56:30.211418Z'}
{'type': 'l2update', 'product_id': 'BTC-USD', 'changes': [['buy', '38278.56', '0.00000000']], 'time': '2021-05-20T03:56:30.216161Z'}
{'type': 'l2update', 'product_id': 'BTC-USD', 'changes': [['buy', '38309.29', '0.00000000']], 'time': '2021-05-20T03:56:30.217189Z'}
{'type': 'l2update', 'product_id': 'BTC-USD', 'changes': [['sell', '38327.67', '0.05971361']], 'time': '2021-05-20T03:56:30.218307Z'}
{'type': 'l2update', 'product_id': 'BTC-USD', 'changes': [['buy', '38303.87', '0.00000000']], 'time': '2021-05-20T03:56:30.220671Z'}
{'type': 'l2update', 'product_id': 'BTC-USD', 'changes': [['sell', '38489.90', '0.00000000']], 'time': '2021-05-20T03:56:30.220687Z'}
{'type': 'l2update', 'product_id': 'BTC-USD', 'changes': [['sell', '38346.21', '0.00000000']], 'time': '2021-05-20T03:56:30.220809Z'}
{'type': 'l2update', 'product_id': 'BTC-USD', 'changes': [['buy', '38303.61', '0.02400000']], 'time': '2021-05-20T03:56:30.220831Z'}
{'type': 'l2update', 'product_id': 'BTC-USD', 'changes': [['buy', '38302.81', '0.02400000']], 'time': '2021-05-20T03:56:30.220831Z'}
{'type': 'l2update', 'product_id': 'BTC-USD', 'changes': [['buy', '38302.00', '0.02400000']], 'time': '2021-05-20T03:56:30.220831Z'}
{'type': 'l2update', 'product_id': 'BTC-USD', 'changes': [['buy', '38306.93', '0.03884941']], 'time': '2021-05-20T03:56:30.221128Z'}
{'type': 'l2update', 'product_id': 'BTC-USD', 'changes': [['buy', '38311.87', '1.36600000']], 'time': '2021-05-20T03:56:30.224134Z'}
{'type': 'l2update', 'product_id': 'BTC-USD', 'changes': [['buy', '38305.72', '0.05981455']], 'time': '2021-05-20T03:56:30.228189Z'}
{'type': 'l2update', 'product_id': 'BTC-USD', 'changes': [['sell', '38362.64', '0.07000000']], 'time': '2021-05-20T03:56:30.229433Z'}
{'type': 'l2update', 'product_id': 'BTC-USD', 'changes': [['sell', '38346.20', '0.00000000']], 'time': '2021-05-20T03:56:30.236569Z'}
{'type': 'l2update', 'product_id': 'BTC-USD', 'changes': [['sell', '38362.64', '0.03000000']], 'time': '2021-05-20T03:56:30.238468Z'}
{'type': 'l2update', 'product_id': 'BTC-USD', 'changes': [['sell', '38474.74', '0.01000000']], 'time': '2021-05-20T03:56:30.240157Z'}
{'type': 'l2update', 'product_id': 'BTC-USD', 'changes': [['buy', '38305.72', '0.00000000']], 'time': '2021-05-20T03:56:30.243122Z'}
{'type': 'l2update', 'product_id': 'BTC-USD', 'changes': [['buy', '38327.66', '0.21298051']], 'time': '2021-05-20T03:56:30.243619Z'}
{'type': 'l2update', 'product_id': 'BTC-USD', 'changes': [['buy', '38285.73', '0.02000000']], 'time': '2021-05-20T03:56:30.252665Z'}
{'type': 'l2update', 'product_id': 'BTC-USD', 'changes': [['buy', '38311.88', '0.59116555']], 'time': '2021-05-20T03:56:30.253128Z'}
{'type': 'l2update', 'product_id': 'BTC-USD', 'changes': [['buy', '38306.68', '0.05981455']], 'time': '2021-05-20T03:56:30.253163Z'}
{'type': 'l2update', 'product_id': 'BTC-USD', 'changes': [['sell', '38472.10', '0.00000000']], 'time': '2021-05-20T03:56:30.254310Z'}
{'type': 'l2update', 'product_id': 'BTC-USD', 'changes': [['sell', '38351.52', '0.10981455']], 'time': '2021-05-20T03:56:30.257398Z'}
{'type': 'l2update', 'product_id': 'BTC-USD', 'changes': [['sell', '38605.87', '0.01000000']], 'time': '2021-05-20T03:56:30.257585Z'}
{'type': 'l2update', 'product_id': 'BTC-USD', 'changes': [['buy', '38298.93', '0.00000000']], 'time': '2021-05-20T03:56:30.263680Z'}
{'type': 'l2update', 'product_id': 'BTC-USD', 'changes': [['sell', '38369.29', '0.03000000']], 'time': '2021-05-20T03:56:30.265326Z'}
{'type': 'l2update', 'product_id': 'BTC-USD', 'changes': [['sell', '38500.90', '0.01298671']], 'time': '2021-05-20T03:56:30.269736Z'}
{'type': 'l2update', 'product_id': 'BTC-USD', 'changes': [['sell', '38370.31', '0.04000000']], 'time': '2021-05-20T03:56:30.278765Z'}
{'type': 'l2update', 'product_id': 'BTC-USD', 'changes': [['sell', '38387.25', '0.05447373']], 'time': '2021-05-20T03:56:30.278834Z'}
{'type': 'l2update', 'product_id': 'BTC-USD', 'changes': [['sell', '38529.01', '0.00000000']], 'time': '2021-05-20T03:56:30.291333Z'}
{'type': 'l2update', 'product_id': 'BTC-USD', 'changes': [['buy', '38327.66', '0.21474526']], 'time': '2021-05-20T03:56:30.295424Z'}
{'type': 'l2update', 'product_id': 'BTC-USD', 'changes': [['buy', '38299.70', '0.06030716']], 'time': '2021-05-20T03:56:30.301386Z'}
{'type': 'l2update', 'product_id': 'BTC-USD', 'changes': [['sell', '38512.81', '0.02596539']], 'time': '2021-05-20T03:56:30.305342Z'}
{'type': 'l2update', 'product_id': 'BTC-USD', 'changes': [['buy', '38298.41', '0.00000000']], 'time': '2021-05-20T03:56:30.307404Z'}
{'type': 'l2update', 'product_id': 'BTC-USD', 'changes': [['sell', '38349.50', '0.00000000']], 'time': '2021-05-20T03:56:30.310669Z'}
{'type': 'l2update', 'product_id': 'BTC-USD', 'changes': [['sell', '38329.10', '0.00000000']], 'time': '2021-05-20T03:56:30.321197Z'}
{'type': 'l2update', 'product_id': 'BTC-USD', 'changes': [['buy', '38306.67', '0.00000000']], 'time': '2021-05-20T03:56:30.334460Z'}
{'type': 'l2update', 'product_id': 'BTC-USD', 'changes': [['buy', '37963.29', '0.00000000']], 'time': '2021-05-20T03:56:30.347430Z'}
{'type': 'l2update', 'product_id': 'BTC-USD', 'changes': [['buy', '35064.00', '1.00000000']], 'time': '2021-05-20T03:56:30.371835Z'}
{'type': 'l2update', 'product_id': 'BTC-USD', 'changes': [['buy', '38278.41', '0.00000000']], 'time': '2021-05-20T03:56:30.381065Z'}
{'type': 'l2update', 'product_id': 'BTC-USD', 'changes': [['sell', '38348.12', '0.00000000']], 'time': '2021-05-20T03:56:30.413752Z'}
{'type': 'l2update', 'product_id': 'BTC-USD', 'changes': [['sell', '38363.05', '0.27700000']], 'time': '2021-05-20T03:56:30.414608Z'}
{'type': 'l2update', 'product_id': 'BTC-USD', 'changes': [['buy', '38296.90', '0.43720000']], 'time': '2021-05-20T03:56:30.415180Z'}
{'type': 'l2update', 'product_id': 'BTC-USD', 'changes': [['buy', '38157.32', '0.04847312']], 'time': '2021-05-20T03:56:30.415755Z'}
{'type': 'l2update', 'product_id': 'BTC-USD', 'changes': [['sell', '38500.90', '0.00000000']], 'time': '2021-05-20T03:56:30.423462Z'}
{'type': 'l2update', 'product_id': 'BTC-USD', 'changes': [['buy', '38299.70', '0.00000000']], 'time': '2021-05-20T03:56:30.429374Z'}
{'type': 'l2update', 'product_id': 'BTC-USD', 'changes': [['sell', '38355.34', '0.04997503']], 'time': '2021-05-20T03:56:30.464199Z'}
{'type': 'l2update', 'product_id': 'BTC-USD', 'changes': [['sell', '39114.47', '0.00505876']], 'time': '2021-05-20T03:56:30.465526Z'}
{'type': 'l2update', 'product_id': 'BTC-USD', 'changes': [['buy', '38288.62', '0.03000000']], 'time': '2021-05-20T03:56:30.465862Z'}
{'type': 'l2update', 'product_id': 'BTC-USD', 'changes': [['buy', '38311.89', '0.50000000']], 'time': '2021-05-20T03:56:30.466444Z'}
{'type': 'l2update', 'product_id': 'BTC-USD', 'changes': [['buy', '38268.51', '0.00000000']], 'time': '2021-05-20T03:56:30.469360Z'}
{'type': 'l2update', 'product_id': 'BTC-USD', 'changes': [['sell', '38582.05', '0.01295939']], 'time': '2021-05-20T03:56:30.469886Z'}
{'type': 'l2update', 'product_id': 'BTC-USD', 'changes': [['sell', '38417.57', '0.00000000']], 'time': '2021-05-20T03:56:30.482128Z'}
{'type': 'l2update', 'product_id': 'BTC-USD', 'changes': [['buy', '38311.88', '0.00000000']], 'time': '2021-05-20T03:56:30.484256Z'}
{'type': 'l2update', 'product_id': 'BTC-USD', 'changes': [['buy', '38306.93', '0.00000000']], 'time': '2021-05-20T03:56:30.490596Z'}
{'type': 'l2update', 'product_id': 'BTC-USD', 'changes': [['buy', '38270.51', '0.10000000']], 'time': '2021-05-20T03:56:30.493073Z'}
{'type': 'l2update', 'product_id': 'BTC-USD', 'changes': [['sell', '38371.68', '0.00000000']], 'time': '2021-05-20T03:56:30.496162Z'}
{'type': 'l2update', 'product_id': 'BTC-USD', 'changes': [['sell', '38327.67', '0.05719564']], 'time': '2021-05-20T03:56:30.499345Z'}
{'type': 'l2update', 'product_id': 'BTC-USD', 'changes': [['sell', '41500.00', '5.90849559']], 'time': '2021-05-20T03:56:30.502072Z'}
{'type': 'l2update', 'product_id': 'BTC-USD', 'changes': [['buy', '38238.70', '0.00000000']], 'time': '2021-05-20T03:56:30.509356Z'}
{'type': 'l2update', 'product_id': 'BTC-USD', 'changes': [['sell', '38429.77', '0.01000000']], 'time': '2021-05-20T03:56:30.509954Z'}
{'type': 'l2update', 'product_id': 'BTC-USD', 'changes': [['buy', '38289.27', '0.00000000']], 'time': '2021-05-20T03:56:30.514825Z'}
{'type': 'l2update', 'product_id': 'BTC-USD', 'changes': [['buy', '38311.90', '0.59116555']], 'time': '2021-05-20T03:56:30.523350Z'}
{'type': 'l2update', 'product_id': 'BTC-USD', 'changes': [['sell', '38493.84', '0.00000000']], 'time': '2021-05-20T03:56:30.524784Z'}
{'type': 'l2update', 'product_id': 'BTC-USD', 'changes': [['sell', '38373.70', '0.00000000']], 'time': '2021-05-20T03:56:30.525388Z'}
{'type': 'l2update', 'product_id': 'BTC-USD', 'changes': [['buy', '38151.58', '0.00000000']], 'time': '2021-05-20T03:56:30.525665Z'}
{'type': 'l2update', 'product_id': 'BTC-USD', 'changes': [['sell', '38332.76', '0.05143867']], 'time': '2021-05-20T03:56:30.532044Z'}
{'type': 'l2update', 'product_id': 'BTC-USD', 'changes': [['sell', '38512.81', '0.00000000']], 'time': '2021-05-20T03:56:30.535387Z'}
{'type': 'l2update', 'product_id': 'BTC-USD', 'changes': [['buy', '38313.34', '0.03884941']], 'time': '2021-05-20T03:56:30.536226Z'}
{'type': 'l2update', 'product_id': 'BTC-USD', 'changes': [['sell', '39114.47', '0.00681752']], 'time': '2021-05-20T03:56:30.537516Z'}
{'type': 'l2update', 'product_id': 'BTC-USD', 'changes': [['sell', '38480.11', '0.01000000']], 'time': '2021-05-20T03:56:30.548997Z'}
{'type': 'l2update', 'product_id': 'BTC-USD', 'changes': [['sell', '38499.31', '0.01279950']], 'time': '2021-05-20T03:56:30.553823Z'}
{'type': 'l2update', 'product_id': 'BTC-USD', 'changes': [['buy', '38306.68', '0.00000000']], 'time': '2021-05-20T03:56:30.579566Z'}
{'type': 'l2update', 'product_id': 'BTC-USD', 'changes': [['buy', '38311.87', '0.84600000']], 'time': '2021-05-20T03:56:30.589209Z'}
{'type': 'l2update', 'product_id': 'BTC-USD', 'changes': [['buy', '38144.27', '0.00000000']], 'time': '2021-05-20T03:56:30.598482Z'}
{'type': 'l2update', 'product_id': 'BTC-USD', 'changes': [['buy', '38308.01', '0.05872720']], 'time': '2021-05-20T03:56:30.598693Z'}
{'type': 'l2update', 'product_id': 'BTC-USD', 'changes': [['sell', '38427.71', '0.00000000']], 'time': '2021-05-20T03:56:30.602501Z'}
{'type': 'l2update', 'product_id': 'BTC-USD', 'changes': [['buy', '38309.27', '0.00000000']], 'time': '2021-05-20T03:56:30.606676Z'}
{'type': 'l2update', 'product_id': 'BTC-USD', 'changes': [['buy', '38306.73', '0.52100000']], 'time': '2021-05-20T03:56:30.611291Z'}
{'type': 'l2update', 'product_id': 'BTC-USD', 'changes': [['buy', '38311.87', '0.00000000']], 'time': '2021-05-20T03:56:30.613737Z'}
{'type': 'l2update', 'product_id': 'BTC-USD', 'changes': [['buy', '38122.85', '0.01000000']], 'time': '2021-05-20T03:56:30.615578Z'}
{'type': 'l2update', 'product_id': 'BTC-USD', 'changes': [['buy', '38311.90', '0.00000000']], 'time': '2021-05-20T03:56:30.625967Z'}
{'type': 'l2update', 'product_id': 'BTC-USD', 'changes': [['sell', '38414.17', '0.11584800']], 'time': '2021-05-20T03:56:30.633854Z'}
{'type': 'l2update', 'product_id': 'BTC-USD', 'changes': [['buy', '38301.86', '0.06123979']], 'time': '2021-05-20T03:56:30.634580Z'}
{'type': 'l2update', 'product_id': 'BTC-USD', 'changes': [['sell', '38342.72', '0.05762035']], 'time': '2021-05-20T03:56:30.634580Z'}
{'type': 'l2update', 'product_id': 'BTC-USD', 'changes': [['buy', '38309.32', '0.84700000']], 'time': '2021-05-20T03:56:30.634626Z'}
{'type': 'l2update', 'product_id': 'BTC-USD', 'changes': [['buy', '38311.91', '1.98947960']], 'time': '2021-05-20T03:56:30.634906Z'}
{'type': 'l2update', 'product_id': 'BTC-USD', 'changes': [['buy', '38303.61', '0.00000000']], 'time': '2021-05-20T03:56:30.638825Z'}
{'type': 'l2update', 'product_id': 'BTC-USD', 'changes': [['buy', '38302.81', '0.00000000']], 'time': '2021-05-20T03:56:30.638825Z'}
{'type': 'l2update', 'product_id': 'BTC-USD', 'changes': [['buy', '38308.01', '0.00000000']], 'time': '2021-05-20T03:56:30.642278Z'}
{'type': 'l2update', 'product_id': 'BTC-USD', 'changes': [['buy', '38311.91', '0.00000000']], 'time': '2021-05-20T03:56:30.651707Z'}
{'type': 'l2update', 'product_id': 'BTC-USD', 'changes': [['buy', '38309.27', '0.59116555']], 'time': '2021-05-20T03:56:30.651821Z'}
{'type': 'l2update', 'product_id': 'BTC-USD', 'changes': [['buy', '38306.74', '0.05872720']], 'time': '2021-05-20T03:56:30.653571Z'}
{'type': 'l2update', 'product_id': 'BTC-USD', 'changes': [['buy', '38308.01', '0.05872720']], 'time': '2021-05-20T03:56:30.659947Z'}
{'type': 'l2update', 'product_id': 'BTC-USD', 'changes': [['buy', '38300.79', '0.02400000']], 'time': '2021-05-20T03:56:30.660433Z'}
{'type': 'l2update', 'product_id': 'BTC-USD', 'changes': [['buy', '38299.99', '0.02400000']], 'time': '2021-05-20T03:56:30.660433Z'}
{'type': 'l2update', 'product_id': 'BTC-USD', 'changes': [['buy', '37500.01', '0.00220000']], 'time': '2021-05-20T03:56:30.662529Z'}
{'type': 'l2update', 'product_id': 'BTC-USD', 'changes': [['buy', '37505.01', '0.00000000']], 'time': '2021-05-20T03:56:30.662529Z'}
{'type': 'l2update', 'product_id': 'BTC-USD', 'changes': [['buy', '37500.02', '0.00000000']], 'time': '2021-05-20T03:56:30.662529Z'}
{'type': 'l2update', 'product_id': 'BTC-USD', 'changes': [['buy', '37506.22', '0.00000000']], 'time': '2021-05-20T03:56:30.662529Z'}
{'type': 'l2update', 'product_id': 'BTC-USD', 'changes': [['buy', '37500.01', '0.00010000']], 'time': '2021-05-20T03:56:30.662529Z'}
{'type': 'l2update', 'product_id': 'BTC-USD', 'changes': [['buy', '37500.01', '0.00000000']], 'time': '2021-05-20T03:56:30.662529Z'}
{'type': 'l2update', 'product_id': 'BTC-USD', 'changes': [['buy', '38306.74', '0.00000000']], 'time': '2021-05-20T03:56:30.663214Z'}
{'type': 'l2update', 'product_id': 'BTC-USD', 'changes': [['buy', '38308.01', '0.00000000']], 'time': '2021-05-20T03:56:30.668521Z'}
{'type': 'l2update', 'product_id': 'BTC-USD', 'changes': [['sell', '38372.84', '0.00000000']], 'time': '2021-05-20T03:56:30.674125Z'}
{'type': 'l2update', 'product_id': 'BTC-USD', 'changes': [['buy', '38309.33', '1.98947960']], 'time': '2021-05-20T03:56:30.678653Z'}
{'type': 'l2update', 'product_id': 'BTC-USD', 'changes': [['buy', '38306.74', '0.05872720']], 'time': '2021-05-20T03:56:30.683646Z'}
{'type': 'l2update', 'product_id': 'BTC-USD', 'changes': [['sell', '38334.97', '0.00000000']], 'time': '2021-05-20T03:56:30.684430Z'}
{'type': 'l2update', 'product_id': 'BTC-USD', 'changes': [['buy', '38306.74', '0.00000000']], 'time': '2021-05-20T03:56:30.692833Z'}
{'type': 'l2update', 'product_id': 'BTC-USD', 'changes': [['buy', '38313.39', '0.84700000']], 'time': '2021-05-20T03:56:30.701936Z'}
{'type': 'l2update', 'product_id': 'BTC-USD', 'changes': [['buy', '38238.70', '0.02400000']], 'time': '2021-05-20T03:56:30.702415Z'}
{'type': 'l2update', 'product_id': 'BTC-USD', 'changes': [['sell', '38582.05', '0.00000000']], 'time': '2021-05-20T03:56:30.705675Z'}
{'type': 'l2update', 'product_id': 'BTC-USD', 'changes': [['sell', '38332.75', '2.48969908']], 'time': '2021-05-20T03:56:30.706588Z'}
{'type': 'l2update', 'product_id': 'BTC-USD', 'changes': [['buy', '38308.01', '0.05872720']], 'time': '2021-05-20T03:56:30.710954Z'}
{'type': 'l2update', 'product_id': 'BTC-USD', 'changes': [['sell', '38454.36', '0.00000000']], 'time': '2021-05-20T03:56:30.712385Z'}
{'type': 'l2update', 'product_id': 'BTC-USD', 'changes': [['sell', '38553.56', '0.01000000']], 'time': '2021-05-20T03:56:30.718645Z'}
{'type': 'l2update', 'product_id': 'BTC-USD', 'changes': [['sell', '38373.70', '2.16932808']], 'time': '2021-05-20T03:56:30.718655Z'}
{'type': 'l2update', 'product_id': 'BTC-USD', 'changes': [['buy', '38308.01', '0.00000000']], 'time': '2021-05-20T03:56:30.722367Z'}
{'type': 'l2update', 'product_id': 'BTC-USD', 'changes': [['sell', '38442.62', '0.01000000']], 'time': '2021-05-20T03:56:30.729571Z'}
{'type': 'l2update', 'product_id': 'BTC-USD', 'changes': [['buy', '38306.74', '0.05872720']], 'time': '2021-05-20T03:56:30.729712Z'}
{'type': 'l2update', 'product_id': 'BTC-USD', 'changes': [['sell', '38357.27', '0.00000000']], 'time': '2021-05-20T03:56:30.747569Z'}
{'type': 'l2update', 'product_id': 'BTC-USD', 'changes': [['sell', '38363.05', '0.00000000']], 'time': '2021-05-20T03:56:30.750701Z'}
{'type': 'l2update', 'product_id': 'BTC-USD', 'changes': [['buy', '38309.27', '0.00000000']], 'time': '2021-05-20T03:56:30.751713Z'}
{'type': 'l2update', 'product_id': 'BTC-USD', 'changes': [['buy', '38279.67', '0.00000000']], 'time': '2021-05-20T03:56:30.759722Z'}
{'type': 'l2update', 'product_id': 'BTC-USD', 'changes': [['buy', '38227.43', '0.00000000']], 'time': '2021-05-20T03:56:30.760307Z'}
{'type': 'l2update', 'product_id': 'BTC-USD', 'changes': [['sell', '38358.56', '0.46990000']], 'time': '2021-05-20T03:56:30.762243Z'}
{'type': 'l2update', 'product_id': 'BTC-USD', 'changes': [['buy', '38311.94', '0.52000000']], 'time': '2021-05-20T03:56:30.762727Z'}
{'type': 'l2update', 'product_id': 'BTC-USD', 'changes': [['buy', '38301.86', '0.00000000']], 'time': '2021-05-20T03:56:30.764029Z'}
{'type': 'l2update', 'product_id': 'BTC-USD', 'changes': [['sell', '38342.72', '0.00000000']], 'time': '2021-05-20T03:56:30.764029Z'}
{'type': 'l2update', 'product_id': 'BTC-USD', 'changes': [['buy', '38296.90', '0.00000000']], 'time': '2021-05-20T03:56:30.767474Z'}
{'type': 'l2update', 'product_id': 'BTC-USD', 'changes': [['sell', '38332.75', '0.00000000']], 'time': '2021-05-20T03:56:30.773519Z'}
{'type': 'l2update', 'product_id': 'BTC-USD', 'changes': [['buy', '38313.40', '0.59116555']], 'time': '2021-05-20T03:56:30.773792Z'}
{'type': 'l2update', 'product_id': 'BTC-USD', 'changes': [['buy', '37929.54', '0.35840000']], 'time': '2021-05-20T03:56:30.773805Z'}
{'type': 'l2update', 'product_id': 'BTC-USD', 'changes': [['buy', '38239.31', '0.02730744']], 'time': '2021-05-20T03:56:30.773945Z'}
{'type': 'l2update', 'product_id': 'BTC-USD', 'changes': [['buy', '38306.74', '0.00000000']], 'time': '2021-05-20T03:56:30.775298Z'}
{'type': 'l2update', 'product_id': 'BTC-USD', 'changes': [['sell', '38442.62', '0.00000000']], 'time': '2021-05-20T03:56:30.776910Z'}
{'type': 'l2update', 'product_id': 'BTC-USD', 'changes': [['buy', '38288.47', '0.05000000']], 'time': '2021-05-20T03:56:30.778108Z'}
{'type': 'l2update', 'product_id': 'BTC-USD', 'changes': [['buy', '38308.01', '0.05872720']], 'time': '2021-05-20T03:56:30.778308Z'}
{'type': 'l2update', 'product_id': 'BTC-USD', 'changes': [['sell', '38327.67', '0.04698000']], 'time': '2021-05-20T03:56:30.778434Z'}
{'type': 'l2update', 'product_id': 'BTC-USD', 'changes': [['buy', '38299.37', '0.48810000']], 'time': '2021-05-20T03:56:30.783430Z'}
{'type': 'l2update', 'product_id': 'BTC-USD', 'changes': [['sell', '38333.69', '0.00000000']], 'time': '2021-05-20T03:56:30.783642Z'}
{'type': 'l2update', 'product_id': 'BTC-USD', 'changes': [['buy', '38327.66', '0.21298051']], 'time': '2021-05-20T03:56:30.786774Z'}
{'type': 'l2update', 'product_id': 'BTC-USD', 'changes': [['buy', '38308.01', '0.00000000']], 'time': '2021-05-20T03:56:30.787636Z'}
{'type': 'l2update', 'product_id': 'BTC-USD', 'changes': [['sell', '38334.98', '0.00000000']], 'time': '2021-05-20T03:56:30.788033Z'}
{'type': 'l2update', 'product_id': 'BTC-USD', 'changes': [['buy', '38299.37', '0.00000000']], 'time': '2021-05-20T03:56:30.788262Z'}
{'type': 'l2update', 'product_id': 'BTC-USD', 'changes': [['sell', '38363.71', '0.00000000']], 'time': '2021-05-20T03:56:30.795340Z'}
{'type': 'l2update', 'product_id': 'BTC-USD', 'changes': [['sell', '38333.63', '0.00000000']], 'time': '2021-05-20T03:56:30.795452Z'}
{'type': 'l2update', 'product_id': 'BTC-USD', 'changes': [['buy', '38309.34', '0.05872720']], 'time': '2021-05-20T03:56:30.798678Z'}
{'type': 'l2update', 'product_id': 'BTC-USD', 'changes': [['buy', '38238.70', '0.00000000']], 'time': '2021-05-20T03:56:30.800722Z'}
{'type': 'l2update', 'product_id': 'BTC-USD', 'changes': [['sell', '38362.64', '0.02000000']], 'time': '2021-05-20T03:56:30.801728Z'}
{'type': 'l2update', 'product_id': 'BTC-USD', 'changes': [['sell', '38333.68', '0.00000000']], 'time': '2021-05-20T03:56:30.803526Z'}
{'type': 'l2update', 'product_id': 'BTC-USD', 'changes': [['sell', '38343.10', '2.48969908']], 'time': '2021-05-20T03:56:30.803567Z'}
{'type': 'l2update', 'product_id': 'BTC-USD', 'changes': [['sell', '38349.82', '0.00000000']], 'time': '2021-05-20T03:56:30.805663Z'}
{'type': 'l2update', 'product_id': 'BTC-USD', 'changes': [['buy', '38008.63', '0.00000000']], 'time': '2021-05-20T03:56:30.805979Z'}
{'type': 'l2update', 'product_id': 'BTC-USD', 'changes': [['sell', '38358.56', '0.00000000']], 'time': '2021-05-20T03:56:30.807582Z'}
{'type': 'l2update', 'product_id': 'BTC-USD', 'changes': [['sell', '38362.64', '0.00000000']], 'time': '2021-05-20T03:56:30.808754Z'}
{'type': 'l2update', 'product_id': 'BTC-USD', 'changes': [['sell', '38373.70', '0.00000000']], 'time': '2021-05-20T03:56:30.808826Z'}
{'type': 'l2update', 'product_id': 'BTC-USD', 'changes': [['sell', '38457.60', '0.01000000']], 'time': '2021-05-20T03:56:30.811399Z'}
{'type': 'l2update', 'product_id': 'BTC-USD', 'changes': [['buy', '38319.98', '0.84600000']], 'time': '2021-05-20T03:56:30.818924Z'}
{'type': 'l2update', 'product_id': 'BTC-USD', 'changes': [['buy', '38019.85', '0.44800000']], 'time': '2021-05-20T03:56:30.819239Z'}
{'type': 'l2update', 'product_id': 'BTC-USD', 'changes': [['sell', '38342.67', '0.59300000']], 'time': '2021-05-20T03:56:30.819705Z'}
{'type': 'l2update', 'product_id': 'BTC-USD', 'changes': [['sell', '38332.76', '0.00000000']], 'time': '2021-05-20T03:56:30.821584Z'}
{'type': 'l2update', 'product_id': 'BTC-USD', 'changes': [['sell', '38369.65', '0.01000000']], 'time': '2021-05-20T03:56:30.823590Z'}
{'type': 'l2update', 'product_id': 'BTC-USD', 'changes': [['sell', '38343.10', '2.98969908']], 'time': '2021-05-20T03:56:30.823990Z'}
{'type': 'l2update', 'product_id': 'BTC-USD', 'changes': [['sell', '38465.34', '0.00000000']], 'time': '2021-05-20T03:56:30.826669Z'}
{'type': 'l2update', 'product_id': 'BTC-USD', 'changes': [['sell', '38327.67', '0.04360499']], 'time': '2021-05-20T03:56:30.830176Z'}
{'type': 'l2update', 'product_id': 'BTC-USD', 'changes': [['buy', '38325.22', '0.04888044']], 'time': '2021-05-20T03:56:30.830313Z'}
{'type': 'l2update', 'product_id': 'BTC-USD', 'changes': [['sell', '38327.67', '0.00000000']], 'time': '2021-05-20T03:56:30.837678Z'}
{'type': 'l2update', 'product_id': 'BTC-USD', 'changes': [['sell', '38351.52', '0.05000000']], 'time': '2021-05-20T03:56:30.838382Z'}
{'type': 'l2update', 'product_id': 'BTC-USD', 'changes': [['sell', '38371.71', '0.00000000']], 'time': '2021-05-20T03:56:30.839475Z'}
{'type': 'l2update', 'product_id': 'BTC-USD', 'changes': [['sell', '38369.65', '0.03000000']], 'time': '2021-05-20T03:56:30.842160Z'}
{'type': 'l2update', 'product_id': 'BTC-USD', 'changes': [['sell', '38482.80', '0.01000000']], 'time': '2021-05-20T03:56:30.847001Z'}
{'type': 'l2update', 'product_id': 'BTC-USD', 'changes': [['buy', '38319.93', '0.00000000']], 'time': '2021-05-20T03:56:30.847448Z'}
{'type': 'l2update', 'product_id': 'BTC-USD', 'changes': [['sell', '38373.67', '0.00000000']], 'time': '2021-05-20T03:56:30.848879Z'}
{'type': 'l2update', 'product_id': 'BTC-USD', 'changes': [['buy', '38309.26', '0.00000000']], 'time': '2021-05-20T03:56:30.851146Z'}
{'type': 'l2update', 'product_id': 'BTC-USD', 'changes': [['sell', '38335.92', '0.00000000']], 'time': '2021-05-20T03:56:30.851604Z'}
{'type': 'l2update', 'product_id': 'BTC-USD', 'changes': [['sell', '38385.68', '0.02723275']], 'time': '2021-05-20T03:56:30.852159Z'}
{'type': 'l2update', 'product_id': 'BTC-USD', 'changes': [['sell', '38335.59', '0.02762000']], 'time': '2021-05-20T03:56:30.857451Z'}
{'type': 'l2update', 'product_id': 'BTC-USD', 'changes': [['sell', '38336.71', '0.05105263']], 'time': '2021-05-20T03:56:30.857648Z'}
{'type': 'l2update', 'product_id': 'BTC-USD', 'changes': [['buy', '38327.66', '0.21474526']], 'time': '2021-05-20T03:56:30.857699Z'}
{'type': 'l2update', 'product_id': 'BTC-USD', 'changes': [['sell', '38354.46', '0.05872720']], 'time': '2021-05-20T03:56:30.857726Z'}
{'type': 'l2update', 'product_id': 'BTC-USD', 'changes': [['buy', '38311.89', '0.00000000']], 'time': '2021-05-20T03:56:30.858352Z'}
{'type': 'l2update', 'product_id': 'BTC-USD', 'changes': [['sell', '38475.97', '0.00000000']], 'time': '2021-05-20T03:56:30.858487Z'}
{'type': 'l2update', 'product_id': 'BTC-USD', 'changes': [['buy', '38319.98', '0.00000000']], 'time': '2021-05-20T03:56:30.861173Z'}
{'type': 'l2update', 'product_id': 'BTC-USD', 'changes': [['buy', '38328.20', '0.01492000']], 'time': '2021-05-20T03:56:30.862840Z'}
{'type': 'l2update', 'product_id': 'BTC-USD', 'changes': [['buy', '38183.80', '0.00000000']], 'time': '2021-05-20T03:56:30.864432Z'}
{'type': 'l2update', 'product_id': 'BTC-USD', 'changes': [['sell', '38435.23', '0.00000000']], 'time': '2021-05-20T03:56:30.864834Z'}
{'type': 'l2update', 'product_id': 'BTC-USD', 'changes': [['sell', '38342.37', '0.04698000']], 'time': '2021-05-20T03:56:30.870843Z'}
{'type': 'l2update', 'product_id': 'BTC-USD', 'changes': [['sell', '38343.05', '0.59300000']], 'time': '2021-05-20T03:56:30.871315Z'}
{'type': 'l2update', 'product_id': 'BTC-USD', 'changes': [['buy', '38328.20', '0.00000000']], 'time': '2021-05-20T03:56:30.873313Z'}
{'type': 'l2update', 'product_id': 'BTC-USD', 'changes': [['buy', '38327.66', '0.01474526']], 'time': '2021-05-20T03:56:30.875971Z'}
{'type': 'l2update', 'product_id': 'BTC-USD', 'changes': [['buy', '38319.65', '0.19300000']], 'time': '2021-05-20T03:56:30.879602Z'}
{'type': 'l2update', 'product_id': 'BTC-USD', 'changes': [['sell', '38526.78', '0.01000000']], 'time': '2021-05-20T03:56:30.879838Z'}
{'type': 'l2update', 'product_id': 'BTC-USD', 'changes': [['sell', '38383.32', '0.05063418']], 'time': '2021-05-20T03:56:30.879899Z'}
{'type': 'l2update', 'product_id': 'BTC-USD', 'changes': [['sell', '38387.24', '0.63415759']], 'time': '2021-05-20T03:56:30.880366Z'}
{'type': 'l2update', 'product_id': 'BTC-USD', 'changes': [['buy', '38291.17', '0.47770000']], 'time': '2021-05-20T03:56:30.880705Z'}
{'type': 'l2update', 'product_id': 'BTC-USD', 'changes': [['buy', '38328.17', '0.07460000']], 'time': '2021-05-20T03:56:30.880916Z'}
{'type': 'l2update', 'product_id': 'BTC-USD', 'changes': [['sell', '38335.59', '0.00000000']], 'time': '2021-05-20T03:56:30.881345Z'}
{'type': 'l2update', 'product_id': 'BTC-USD', 'changes': [['sell', '38342.37', '0.00000000']], 'time': '2021-05-20T03:56:30.881422Z'}
{'type': 'l2update', 'product_id': 'BTC-USD', 'changes': [['buy', '38279.73', '0.00000000']], 'time': '2021-05-20T03:56:30.881442Z'}
{'type': 'l2update', 'product_id': 'BTC-USD', 'changes': [['sell', '38457.60', '0.00000000']], 'time': '2021-05-20T03:56:30.884104Z'}
{'type': 'l2update', 'product_id': 'BTC-USD', 'changes': [['sell', '38351.51', '0.05872720']], 'time': '2021-05-20T03:56:30.886430Z'}
{'type': 'l2update', 'product_id': 'BTC-USD', 'changes': [['sell', '38342.09', '0.01492000']], 'time': '2021-05-20T03:56:30.886594Z'}
{'type': 'l2update', 'product_id': 'BTC-USD', 'changes': [['sell', '38332.52', '0.52195716']], 'time': '2021-05-20T03:56:30.886761Z'}
{'type': 'l2update', 'product_id': 'BTC-USD', 'changes': [['buy', '38195.90', '0.01000000']], 'time': '2021-05-20T03:56:30.886924Z'}
{'type': 'l2update', 'product_id': 'BTC-USD', 'changes': [['buy', '38319.99', '0.50000000']], 'time': '2021-05-20T03:56:30.887021Z'}
{'type': 'l2update', 'product_id': 'BTC-USD', 'changes': [['buy', '38328.17', '0.00000000']], 'time': '2021-05-20T03:56:30.890806Z'}
{'type': 'l2update', 'product_id': 'BTC-USD', 'changes': [['sell', '38342.09', '0.00000000']], 'time': '2021-05-20T03:56:30.897139Z'}
{'type': 'l2update', 'product_id': 'BTC-USD', 'changes': [['buy', '38328.43', '0.01492000']], 'time': '2021-05-20T03:56:30.898585Z'}
{'type': 'l2update', 'product_id': 'BTC-USD', 'changes': [['buy', '38313.34', '0.00000000']], 'time': '2021-05-20T03:56:30.898943Z'}
{'type': 'l2update', 'product_id': 'BTC-USD', 'changes': [['sell', '38367.66', '0.00000000']], 'time': '2021-05-20T03:56:30.899786Z'}
{'type': 'l2update', 'product_id': 'BTC-USD', 'changes': [['buy', '38319.99', '0.00000000']], 'time': '2021-05-20T03:56:30.901513Z'}
{'type': 'l2update', 'product_id': 'BTC-USD', 'changes': [['buy', '38227.92', '0.00000000']], 'time': '2021-05-20T03:56:30.901872Z'}
{'type': 'l2update', 'product_id': 'BTC-USD', 'changes': [['sell', '38365.30', '0.45510000']], 'time': '2021-05-20T03:56:30.902817Z'}
{'type': 'l2update', 'product_id': 'BTC-USD', 'changes': [['sell', '38372.37', '0.00000000']], 'time': '2021-05-20T03:56:30.902999Z'}
{'type': 'l2update', 'product_id': 'BTC-USD', 'changes': [['buy', '38321.04', '0.00300000']], 'time': '2021-05-20T03:56:30.903408Z'}
{'type': 'l2update', 'product_id': 'BTC-USD', 'changes': [['sell', '38357.51', '0.00000000']], 'time': '2021-05-20T03:56:30.903820Z'}
{'type': 'l2update', 'product_id': 'BTC-USD', 'changes': [['sell', '38355.87', '0.00000000']], 'time': '2021-05-20T03:56:30.908890Z'}
{'type': 'l2update', 'product_id': 'BTC-USD', 'changes': [['sell', '38414.17', '0.00000000']], 'time': '2021-05-20T03:56:30.910092Z'}
{'type': 'l2update', 'product_id': 'BTC-USD', 'changes': [['buy', '38332.51', '0.03159764']], 'time': '2021-05-20T03:56:30.910218Z'}
{'type': 'l2update', 'product_id': 'BTC-USD', 'changes': [['sell', '38466.72', '0.01375673']], 'time': '2021-05-20T03:56:30.910318Z'}
{'type': 'l2update', 'product_id': 'BTC-USD', 'changes': [['buy', '38295.98', '0.52198045']], 'time': '2021-05-20T03:56:30.910710Z'}
{'type': 'l2update', 'product_id': 'BTC-USD', 'changes': [['buy', '38290.47', '0.48664813']], 'time': '2021-05-20T03:56:30.910921Z'}
{'type': 'l2update', 'product_id': 'BTC-USD', 'changes': [['buy', '38328.43', '0.00000000']], 'time': '2021-05-20T03:56:30.912233Z'}
{'type': 'l2update', 'product_id': 'BTC-USD', 'changes': [['buy', '38164.27', '0.04839822']], 'time': '2021-05-20T03:56:30.915081Z'}
{'type': 'l2update', 'product_id': 'BTC-USD', 'changes': [['sell', '38435.96', '0.00000000']], 'time': '2021-05-20T03:56:30.916083Z'}
{'type': 'l2update', 'product_id': 'BTC-USD', 'changes': [['sell', '38342.67', '0.00000000']], 'time': '2021-05-20T03:56:30.917114Z'}
{'type': 'l2update', 'product_id': 'BTC-USD', 'changes': [['buy', '38313.39', '0.00000000']], 'time': '2021-05-20T03:56:30.919878Z'}
{'type': 'l2update', 'product_id': 'BTC-USD', 'changes': [['buy', '38309.32', '0.00000000']], 'time': '2021-05-20T03:56:30.919898Z'}
{'type': 'l2update', 'product_id': 'BTC-USD', 'changes': [['sell', '38355.34', '0.00000000']], 'time': '2021-05-20T03:56:30.920100Z'}
{'type': 'l2update', 'product_id': 'BTC-USD', 'changes': [['sell', '38365.39', '0.00000000']], 'time': '2021-05-20T03:56:30.920527Z'}
{'type': 'l2update', 'product_id': 'BTC-USD', 'changes': [['buy', '38332.51', '0.07460000']], 'time': '2021-05-20T03:56:30.927099Z'}
{'type': 'l2update', 'product_id': 'BTC-USD', 'changes': [['buy', '38306.16', '0.39490431']], 'time': '2021-05-20T03:56:30.927316Z'}
{'type': 'l2update', 'product_id': 'BTC-USD', 'changes': [['buy', '38313.41', '0.50000000']], 'time': '2021-05-20T03:56:30.927351Z'}
{'type': 'l2update', 'product_id': 'BTC-USD', 'changes': [['sell', '38374.28', '0.05000000']], 'time': '2021-05-20T03:56:30.927587Z'}
{'type': 'l2update', 'product_id': 'BTC-USD', 'changes': [['sell', '38442.62', '0.01000000']], 'time': '2021-05-20T03:56:30.927788Z'}
{'type': 'l2update', 'product_id': 'BTC-USD', 'changes': [['buy', '38227.22', '0.00000000']], 'time': '2021-05-20T03:56:30.927893Z'}
{'type': 'l2update', 'product_id': 'BTC-USD', 'changes': [['buy', '38191.82', '0.01000000']], 'time': '2021-05-20T03:56:30.928476Z'}
{'type': 'l2update', 'product_id': 'BTC-USD', 'changes': [['sell', '38343.05', '0.00000000']], 'time': '2021-05-20T03:56:30.932984Z'}
{'type': 'l2update', 'product_id': 'BTC-USD', 'changes': [['sell', '38365.84', '0.00000000']], 'time': '2021-05-20T03:56:30.935160Z'}
{'type': 'l2update', 'product_id': 'BTC-USD', 'changes': [['sell', '38336.71', '0.00000000']], 'time': '2021-05-20T03:56:30.935783Z'}
{'type': 'l2update', 'product_id': 'BTC-USD', 'changes': [['sell', '38365.30', '0.00000000']], 'time': '2021-05-20T03:56:30.936103Z'}
{'type': 'l2update', 'product_id': 'BTC-USD', 'changes': [['buy', '38332.51', '0.17460000']], 'time': '2021-05-20T03:56:30.936887Z'}
{'type': 'l2update', 'product_id': 'BTC-USD', 'changes': [['sell', '38362.93', '0.05000000']], 'time': '2021-05-20T03:56:30.937449Z'}
{'type': 'l2update', 'product_id': 'BTC-USD', 'changes': [['sell', '38431.14', '0.18188453']], 'time': '2021-05-20T03:56:30.937824Z'}
{'type': 'l2update', 'product_id': 'BTC-USD', 'changes': [['buy', '38310.25', '0.03884941']], 'time': '2021-05-20T03:56:30.938588Z'}
{'type': 'l2update', 'product_id': 'BTC-USD', 'changes': [['sell', '38335.17', '0.52198118']], 'time': '2021-05-20T03:56:30.938787Z'}
{'type': 'l2update', 'product_id': 'BTC-USD', 'changes': [['buy', '38332.51', '0.23460000']], 'time': '2021-05-20T03:56:30.938980Z'}
{'type': 'l2update', 'product_id': 'BTC-USD', 'changes': [['buy', '38332.51', '0.26350000']], 'time': '2021-05-20T03:56:30.939064Z'}
{'type': 'l2update', 'product_id': 'BTC-USD', 'changes': [['buy', '38313.40', '0.00000000']], 'time': '2021-05-20T03:56:30.939581Z'}
{'type': 'l2update', 'product_id': 'BTC-USD', 'changes': [['sell', '38369.65', '0.02000000']], 'time': '2021-05-20T03:56:30.941204Z'}
{'type': 'l2update', 'product_id': 'BTC-USD', 'changes': [['sell', '38343.10', '2.48969908']], 'time': '2021-05-20T03:56:30.941597Z'}
{'type': 'l2update', 'product_id': 'BTC-USD', 'changes': [['sell', '38374.51', '0.10000000']], 'time': '2021-05-20T03:56:30.942475Z'}
{'type': 'l2update', 'product_id': 'BTC-USD', 'changes': [['sell', '38332.52', '0.00000000']], 'time': '2021-05-20T03:56:30.942517Z'}
{'type': 'l2update', 'product_id': 'BTC-USD', 'changes': [['buy', '38319.70', '0.52000000']], 'time': '2021-05-20T03:56:30.942994Z'}
{'type': 'l2update', 'product_id': 'BTC-USD', 'changes': [['sell', '38343.10', '0.00000000']], 'time': '2021-05-20T03:56:30.944146Z'}
{'type': 'l2update', 'product_id': 'BTC-USD', 'changes': [['sell', '38351.51', '0.00000000']], 'time': '2021-05-20T03:56:30.948318Z'}
{'type': 'l2update', 'product_id': 'BTC-USD', 'changes': [['buy', '38291.17', '0.00000000']], 'time': '2021-05-20T03:56:30.948937Z'}
{'type': 'l2update', 'product_id': 'BTC-USD', 'changes': [['buy', '38332.52', '0.00573000']], 'time': '2021-05-20T03:56:30.950653Z'}
{'type': 'l2update', 'product_id': 'BTC-USD', 'changes': [['buy', '38240.18', '0.01155000']], 'time': '2021-05-20T03:56:30.955740Z'}
{'type': 'l2update', 'product_id': 'BTC-USD', 'changes': [['buy', '38271.89', '0.07818392']], 'time': '2021-05-20T03:56:30.956120Z'}
{'type': 'l2update', 'product_id': 'BTC-USD', 'changes': [['sell', '38454.95', '0.05696597']], 'time': '2021-05-20T03:56:30.956230Z'}
{'type': 'l2update', 'product_id': 'BTC-USD', 'changes': [['buy', '38332.52', '0.00222188']], 'time': '2021-05-20T03:56:30.956643Z'}
{'type': 'l2update', 'product_id': 'BTC-USD', 'changes': [['sell', '38362.93', '0.00000000']], 'time': '2021-05-20T03:56:30.956926Z'}
{'type': 'l2update', 'product_id': 'BTC-USD', 'changes': [['sell', '38369.65', '0.00000000']], 'time': '2021-05-20T03:56:30.957474Z'}
{'type': 'l2update', 'product_id': 'BTC-USD', 'changes': [['buy', '38190.00', '0.00000000']], 'time': '2021-05-20T03:56:30.959110Z'}
{'type': 'l2update', 'product_id': 'BTC-USD', 'changes': [['buy', '38332.51', '0.46350000']], 'time': '2021-05-20T03:56:30.960305Z'}
{'type': 'l2update', 'product_id': 'BTC-USD', 'changes': [['buy', '38332.51', '0.42049764']], 'time': '2021-05-20T03:56:30.960572Z'}
{'type': 'l2update', 'product_id': 'BTC-USD', 'changes': [['buy', '38332.51', '0.38890000']], 'time': '2021-05-20T03:56:30.960950Z'}
{'type': 'l2update', 'product_id': 'BTC-USD', 'changes': [['sell', '38374.51', '0.00000000']], 'time': '2021-05-20T03:56:30.961468Z'}
{'type': 'l2update', 'product_id': 'BTC-USD', 'changes': [['sell', '38337.77', '0.78299823']], 'time': '2021-05-20T03:56:30.965857Z'}
{'type': 'l2update', 'product_id': 'BTC-USD', 'changes': [['sell', '38431.14', '0.00000000']], 'time': '2021-05-20T03:56:30.966420Z'}
{'type': 'l2update', 'product_id': 'BTC-USD', 'changes': [['buy', '38335.16', '0.02890000']], 'time': '2021-05-20T03:56:30.970339Z'}
{'type': 'l2update', 'product_id': 'BTC-USD', 'changes': [['buy', '38332.51', '0.53890000']], 'time': '2021-05-20T03:56:30.970514Z'}
{'type': 'l2update', 'product_id': 'BTC-USD', 'changes': [['buy', '38335.16', '0.04382000']], 'time': '2021-05-20T03:56:30.971240Z'}
{'type': 'l2update', 'product_id': 'BTC-USD', 'changes': [['buy', '38332.51', '0.47890000']], 'time': '2021-05-20T03:56:30.971718Z'}
{'type': 'l2update', 'product_id': 'BTC-USD', 'changes': [['sell', '38442.62', '0.00000000']], 'time': '2021-05-20T03:56:30.973741Z'}
{'type': 'l2update', 'product_id': 'BTC-USD', 'changes': [['buy', '38313.42', '0.59116555']], 'time': '2021-05-20T03:56:30.976085Z'}
{'type': 'l2update', 'product_id': 'BTC-USD', 'changes': [['buy', '38285.88', '1.20000000']], 'time': '2021-05-20T03:56:30.976249Z'}
{'type': 'l2update', 'product_id': 'BTC-USD', 'changes': [['sell', '38384.04', '0.00000000']], 'time': '2021-05-20T03:56:30.976301Z'}
{'type': 'l2update', 'product_id': 'BTC-USD', 'changes': [['sell', '38343.09', '0.50000000']], 'time': '2021-05-20T03:56:30.976662Z'}
{'type': 'l2update', 'product_id': 'BTC-USD', 'changes': [['buy', '38229.08', '0.00000000']], 'time': '2021-05-20T03:56:30.977746Z'}
{'type': 'l2update', 'product_id': 'BTC-USD', 'changes': [['sell', '38654.97', '0.36150000']], 'time': '2021-05-20T03:56:30.978264Z'}
{'type': 'l2update', 'product_id': 'BTC-USD', 'changes': [['buy', '38247.27', '0.00000000']], 'time': '2021-05-20T03:56:30.979698Z'}
{'type': 'l2update', 'product_id': 'BTC-USD', 'changes': [['sell', '38369.29', '0.00000000']], 'time': '2021-05-20T03:56:30.981159Z'}
{'type': 'l2update', 'product_id': 'BTC-USD', 'changes': [['buy', '38332.51', '0.48463000']], 'time': '2021-05-20T03:56:30.984513Z'}
{'type': 'l2update', 'product_id': 'BTC-USD', 'changes': [['buy', '38334.43', '0.06000000']], 'time': '2021-05-20T03:56:30.984624Z'}
{'type': 'l2update', 'product_id': 'BTC-USD', 'changes': [['sell', '38335.17', '0.00000000']], 'time': '2021-05-20T03:56:30.985343Z'}
{'type': 'l2update', 'product_id': 'BTC-USD', 'changes': [['sell', '38480.11', '0.00000000']], 'time': '2021-05-20T03:56:30.992238Z'}
{'type': 'l2update', 'product_id': 'BTC-USD', 'changes': [['buy', '38332.51', '0.45573000']], 'time': '2021-05-20T03:56:30.994118Z'}
{'type': 'l2update', 'product_id': 'BTC-USD', 'changes': [['buy', '38192.12', '0.41738576']], 'time': '2021-05-20T03:56:30.995572Z'}
{'type': 'l2update', 'product_id': 'BTC-USD', 'changes': [['buy', '38244.35', '0.43292396']], 'time': '2021-05-20T03:56:30.995572Z'}
{'type': 'l2update', 'product_id': 'BTC-USD', 'changes': [['buy', '38250.03', '0.12890961']], 'time': '2021-05-20T03:56:30.995572Z'}
{'type': 'l2update', 'product_id': 'BTC-USD', 'changes': [['buy', '38313.41', '0.00000000']], 'time': '2021-05-20T03:56:31.001247Z'}
{'type': 'l2update', 'product_id': 'BTC-USD', 'changes': [['sell', '38605.87', '0.00000000']], 'time': '2021-05-20T03:56:31.001748Z'}
{'type': 'l2update', 'product_id': 'BTC-USD', 'changes': [['sell', '38346.83', '1.30495293']], 'time': '2021-05-20T03:56:31.002744Z'}
{'type': 'l2update', 'product_id': 'BTC-USD', 'changes': [['sell', '38436.90', '0.34824054']], 'time': '2021-05-20T03:56:31.002780Z'}
{'type': 'l2update', 'product_id': 'BTC-USD', 'changes': [['buy', '38332.51', '0.55573000']], 'time': '2021-05-20T03:56:31.003127Z'}
{'type': 'l2update', 'product_id': 'BTC-USD', 'changes': [['sell', '38365.33', '0.00000000']], 'time': '2021-05-20T03:56:31.004080Z'}
{'type': 'l2update', 'product_id': 'BTC-USD', 'changes': [['sell', '38370.31', '0.00000000']], 'time': '2021-05-20T03:56:31.004394Z'}
{'type': 'l2update', 'product_id': 'BTC-USD', 'changes': [['buy', '38334.43', '0.00000000']], 'time': '2021-05-20T03:56:31.007168Z'}
{'type': 'l2update', 'product_id': 'BTC-USD', 'changes': [['sell', '38437.02', '0.00000000']], 'time': '2021-05-20T03:56:31.008210Z'}
{'type': 'l2update', 'product_id': 'BTC-USD', 'changes': [['buy', '38311.94', '0.00000000']], 'time': '2021-05-20T03:56:31.008953Z'}
{'type': 'l2update', 'product_id': 'BTC-USD', 'changes': [['buy', '38319.70', '0.00000000']], 'time': '2021-05-20T03:56:31.009126Z'}
{'type': 'l2update', 'product_id': 'BTC-USD', 'changes': [['buy', '38335.16', '0.02890000']], 'time': '2021-05-20T03:56:31.012661Z'}
{'type': 'l2update', 'product_id': 'BTC-USD', 'changes': [['sell', '38337.77', '0.57698651']], 'time': '2021-05-20T03:56:31.014305Z'}
{'type': 'l2update', 'product_id': 'BTC-USD', 'changes': [['buy', '38335.16', '0.03463000']], 'time': '2021-05-20T03:56:31.014700Z'}
{'type': 'l2update', 'product_id': 'BTC-USD', 'changes': [['sell', '38457.60', '0.01000000']], 'time': '2021-05-20T03:56:31.015580Z'}
{'type': 'l2update', 'product_id': 'BTC-USD', 'changes': [['buy', '38184.16', '0.12390000']], 'time': '2021-05-20T03:56:31.015625Z'}
{'type': 'l2update', 'product_id': 'BTC-USD', 'changes': [['sell', '38426.90', '1.20000000']], 'time': '2021-05-20T03:56:31.015675Z'}
{'type': 'l2update', 'product_id': 'BTC-USD', 'changes': [['buy', '38306.73', '0.00000000']], 'time': '2021-05-20T03:56:31.016144Z'}
{'type': 'l2update', 'product_id': 'BTC-USD', 'changes': [['sell', '38452.90', '0.00000000']], 'time': '2021-05-20T03:56:31.017198Z'}
{'type': 'l2update', 'product_id': 'BTC-USD', 'changes': [['sell', '38456.36', '0.00000000']], 'time': '2021-05-20T03:56:31.018848Z'}
{'type': 'l2update', 'product_id': 'BTC-USD', 'changes': [['buy', '38335.16', '0.09463000']], 'time': '2021-05-20T03:56:31.020418Z'}
{'type': 'l2update', 'product_id': 'BTC-USD', 'changes': [['buy', '38337.76', '0.07460000']], 'time': '2021-05-20T03:56:31.020481Z'}
{'type': 'l2update', 'product_id': 'BTC-USD', 'changes': [['buy', '38211.84', '0.39452502']], 'time': '2021-05-20T03:56:31.022096Z'}
{'type': 'l2update', 'product_id': 'BTC-USD', 'changes': [['buy', '38220.42', '0.00000000']], 'time': '2021-05-20T03:56:31.022096Z'}
{'type': 'l2update', 'product_id': 'BTC-USD', 'changes': [['sell', '38343.09', '0.00000000']], 'time': '2021-05-20T03:56:31.024046Z'}
{'type': 'l2update', 'product_id': 'BTC-USD', 'changes': [['sell', '38337.77', '0.57436846']], 'time': '2021-05-20T03:56:31.027222Z'}
{'type': 'l2update', 'product_id': 'BTC-USD', 'changes': [['buy', '38290.20', '0.00000000']], 'time': '2021-05-20T03:56:31.030006Z'}
{'type': 'l2update', 'product_id': 'BTC-USD', 'changes': [['sell', '38593.39', '0.01000000']], 'time': '2021-05-20T03:56:31.030864Z'}
{'type': 'l2update', 'product_id': 'BTC-USD', 'changes': [['sell', '38445.88', '0.00000000']], 'time': '2021-05-20T03:56:31.036932Z'}
{'type': 'l2update', 'product_id': 'BTC-USD', 'changes': [['buy', '38335.16', '0.19463000']], 'time': '2021-05-20T03:56:31.037310Z'}
{'type': 'l2update', 'product_id': 'BTC-USD', 'changes': [['buy', '38332.52', '0.00000000']], 'time': '2021-05-20T03:56:31.038352Z'}
{'type': 'l2update', 'product_id': 'BTC-USD', 'changes': [['sell', '38387.25', '0.00000000']], 'time': '2021-05-20T03:56:31.040535Z'}
{'type': 'l2update', 'product_id': 'BTC-USD', 'changes': [['sell', '38402.09', '0.00000000']], 'time': '2021-05-20T03:56:31.040973Z'}
{'type': 'l2update', 'product_id': 'BTC-USD', 'changes': [['sell', '38465.91', '0.01147859']], 'time': '2021-05-20T03:56:31.041644Z'}
{'type': 'l2update', 'product_id': 'BTC-USD', 'changes': [['sell', '38377.88', '0.01000000']], 'time': '2021-05-20T03:56:31.041740Z'}
{'type': 'l2update', 'product_id': 'BTC-USD', 'changes': [['sell', '38403.93', '0.00000000']], 'time': '2021-05-20T03:56:31.043893Z'}
{'type': 'l2update', 'product_id': 'BTC-USD', 'changes': [['sell', '38422.80', '0.00000000']], 'time': '2021-05-20T03:56:31.044097Z'}
{'type': 'l2update', 'product_id': 'BTC-USD', 'changes': [['buy', '38308.00', '0.00000000']], 'time': '2021-05-20T03:56:31.044630Z'}
{'type': 'l2update', 'product_id': 'BTC-USD', 'changes': [['sell', '38351.51', '2.48969908']], 'time': '2021-05-20T03:56:31.049159Z'}
{'type': 'l2update', 'product_id': 'BTC-USD', 'changes': [['buy', '38337.76', '0.08952000']], 'time': '2021-05-20T03:56:31.049954Z'}
{'type': 'l2update', 'product_id': 'BTC-USD', 'changes': [['buy', '38335.16', '0.16573000']], 'time': '2021-05-20T03:56:31.050672Z'}
{'type': 'l2update', 'product_id': 'BTC-USD', 'changes': [['sell', '38351.52', '0.00000000']], 'time': '2021-05-20T03:56:31.052475Z'}
{'type': 'l2update', 'product_id': 'BTC-USD', 'changes': [['buy', '38335.16', '0.10573000']], 'time': '2021-05-20T03:56:31.052536Z'}
{'type': 'l2update', 'product_id': 'BTC-USD', 'changes': [['buy', '38295.98', '0.00000000']], 'time': '2021-05-20T03:56:31.055641Z'}
{'type': 'l2update', 'product_id': 'BTC-USD', 'changes': [['sell', '38367.58', '0.00000000']], 'time': '2021-05-20T03:56:31.055827Z'}
{'type': 'l2update', 'product_id': 'BTC-USD', 'changes': [['sell', '38468.76', '0.01007576']], 'time': '2021-05-20T03:56:31.056230Z'}
{'type': 'l2update', 'product_id': 'BTC-USD', 'changes': [['buy', '38321.05', '0.50000000']], 'time': '2021-05-20T03:56:31.063571Z'}
{'type': 'l2update', 'product_id': 'BTC-USD', 'changes': [['sell', '38454.95', '0.00000000']], 'time': '2021-05-20T03:56:31.065775Z'}
{'type': 'l2update', 'product_id': 'BTC-USD', 'changes': [['sell', '38515.30', '0.03061800']], 'time': '2021-05-20T03:56:31.067289Z'}
{'type': 'l2update', 'product_id': 'BTC-USD', 'changes': [['sell', '38375.75', '0.00000000']], 'time': '2021-05-20T03:56:31.069640Z'}
{'type': 'l2update', 'product_id': 'BTC-USD', 'changes': [['sell', '38370.42', '0.00000000']], 'time': '2021-05-20T03:56:31.069640Z'}
{'type': 'l2update', 'product_id': 'BTC-USD', 'changes': [['buy', '38233.82', '0.00000000']], 'time': '2021-05-20T03:56:31.069640Z'}
{'type': 'l2update', 'product_id': 'BTC-USD', 'changes': [['buy', '38240.64', '0.02943712']], 'time': '2021-05-20T03:56:31.069640Z'}
{'type': 'l2update', 'product_id': 'BTC-USD', 'changes': [['buy', '38240.64', '0.00000000']], 'time': '2021-05-20T03:56:31.069640Z'}
{'type': 'l2update', 'product_id': 'BTC-USD', 'changes': [['buy', '38271.89', '0.04586018']], 'time': '2021-05-20T03:56:31.069640Z'}
{'type': 'l2update', 'product_id': 'BTC-USD', 'changes': [['buy', '38327.71', '0.84600000']], 'time': '2021-05-20T03:56:31.071126Z'}
{'type': 'l2update', 'product_id': 'BTC-USD', 'changes': [['sell', '38359.72', '0.00000000']], 'time': '2021-05-20T03:56:31.078433Z'}
{'type': 'l2update', 'product_id': 'BTC-USD', 'changes': [['sell', '38384.03', '0.00000000']], 'time': '2021-05-20T03:56:31.080501Z'}
{'type': 'l2update', 'product_id': 'BTC-USD', 'changes': [['buy', '38335.16', '0.30573000']], 'time': '2021-05-20T03:56:31.081719Z'}
{'type': 'l2update', 'product_id': 'BTC-USD', 'changes': [['sell', '38459.35', '0.01300074']], 'time': '2021-05-20T03:56:31.082044Z'}
{'type': 'l2update', 'product_id': 'BTC-USD', 'changes': [['buy', '38335.16', '0.45673000']], 'time': '2021-05-20T03:56:31.082385Z'}
{'type': 'l2update', 'product_id': 'BTC-USD', 'changes': [['buy', '38290.47', '0.00000000']], 'time': '2021-05-20T03:56:31.083294Z'}
{'type': 'l2update', 'product_id': 'BTC-USD', 'changes': [['buy', '38335.17', '0.00573000']], 'time': '2021-05-20T03:56:31.085023Z'}
{'type': 'l2update', 'product_id': 'BTC-USD', 'changes': [['buy', '38288.42', '0.00000000']], 'time': '2021-05-20T03:56:31.088897Z'}
{'type': 'l2update', 'product_id': 'BTC-USD', 'changes': [['buy', '38310.25', '0.00000000']], 'time': '2021-05-20T03:56:31.097984Z'}
{'type': 'l2update', 'product_id': 'BTC-USD', 'changes': [['buy', '38191.82', '0.00000000']], 'time': '2021-05-20T03:56:31.104866Z'}
{'type': 'l2update', 'product_id': 'BTC-USD', 'changes': [['buy', '38313.42', '0.00000000']], 'time': '2021-05-20T03:56:31.107917Z'}
{'type': 'l2update', 'product_id': 'BTC-USD', 'changes': [['buy', '38309.33', '0.00000000']], 'time': '2021-05-20T03:56:31.111366Z'}
{'type': 'l2update', 'product_id': 'BTC-USD', 'changes': [['buy', '38337.08', '0.06000000']], 'time': '2021-05-20T03:56:31.112464Z'}
{'type': 'l2update', 'product_id': 'BTC-USD', 'changes': [['buy', '38290.46', '0.00000000']], 'time': '2021-05-20T03:56:31.120370Z'}
{'type': 'l2update', 'product_id': 'BTC-USD', 'changes': [['buy', '38332.51', '0.55833898']], 'time': '2021-05-20T03:56:31.120838Z'}
{'type': 'l2update', 'product_id': 'BTC-USD', 'changes': [['sell', '38363.84', '0.05000000']], 'time': '2021-05-20T03:56:31.125236Z'}
{'type': 'l2update', 'product_id': 'BTC-USD', 'changes': [['sell', '38371.57', '0.00000000']], 'time': '2021-05-20T03:56:31.126869Z'}
{'type': 'l2update', 'product_id': 'BTC-USD', 'changes': [['sell', '38364.69', '0.30380989']], 'time': '2021-05-20T03:56:31.126869Z'}
{'type': 'l2update', 'product_id': 'BTC-USD', 'changes': [['sell', '38364.69', '0.00000000']], 'time': '2021-05-20T03:56:31.126869Z'}
{'type': 'l2update', 'product_id': 'BTC-USD', 'changes': [['sell', '38363.20', '0.00000000']], 'time': '2021-05-20T03:56:31.126869Z'}
{'type': 'l2update', 'product_id': 'BTC-USD', 'changes': [['sell', '38360.17', '0.00000000']], 'time': '2021-05-20T03:56:31.126869Z'}
{'type': 'l2update', 'product_id': 'BTC-USD', 'changes': [['sell', '38474.73', '0.01299554']], 'time': '2021-05-20T03:56:31.133123Z'}
{'type': 'l2update', 'product_id': 'BTC-USD', 'changes': [['buy', '38256.01', '0.00000000']], 'time': '2021-05-20T03:56:31.139074Z'}
{'type': 'l2update', 'product_id': 'BTC-USD', 'changes': [['sell', '38351.51', '2.98969908']], 'time': '2021-05-20T03:56:31.144768Z'}
{'type': 'l2update', 'product_id': 'BTC-USD', 'changes': [['sell', '38337.77', '0.56072634']], 'time': '2021-05-20T03:56:31.156423Z'}
{'type': 'l2update', 'product_id': 'BTC-USD', 'changes': [['sell', '38391.95', '0.01000000']], 'time': '2021-05-20T03:56:31.166826Z'}
{'type': 'l2update', 'product_id': 'BTC-USD', 'changes': [['sell', '38473.43', '0.03060692']], 'time': '2021-05-20T03:56:31.173282Z'}
{'type': 'l2update', 'product_id': 'BTC-USD', 'changes': [['buy', '38291.32', '0.01299913']], 'time': '2021-05-20T03:56:31.173282Z'}
{'type': 'l2update', 'product_id': 'BTC-USD', 'changes': [['buy', '38302.69', '0.01314442']], 'time': '2021-05-20T03:56:31.173282Z'}
{'type': 'l2update', 'product_id': 'BTC-USD', 'changes': [['buy', '38332.51', '0.55260898']], 'time': '2021-05-20T03:56:31.182876Z'}
{'type': 'l2update', 'product_id': 'BTC-USD', 'changes': [['buy', '38126.05', '0.00000000']], 'time': '2021-05-20T03:56:31.182952Z'}
{'type': 'l2update', 'product_id': 'BTC-USD', 'changes': [['buy', '38335.16', '0.55673000']], 'time': '2021-05-20T03:56:31.186854Z'}
{'type': 'l2update', 'product_id': 'BTC-USD', 'changes': [['buy', '38288.62', '0.00000000']], 'time': '2021-05-20T03:56:31.198748Z'}
{'type': 'l2update', 'product_id': 'BTC-USD', 'changes': [['buy', '38290.21', '0.00000000']], 'time': '2021-05-20T03:56:31.207402Z'}
{'type': 'l2update', 'product_id': 'BTC-USD', 'changes': [['sell', '38351.51', '0.50000000']], 'time': '2021-05-20T03:56:31.210274Z'}
{'type': 'l2update', 'product_id': 'BTC-USD', 'changes': [['buy', '38166.74', '0.00000000']], 'time': '2021-05-20T03:56:31.221686Z'}
{'type': 'l2update', 'product_id': 'BTC-USD', 'changes': [['sell', '38435.16', '0.01182855']], 'time': '2021-05-20T03:56:31.223263Z'}
{'type': 'l2update', 'product_id': 'BTC-USD', 'changes': [['sell', '38337.77', '0.51980869']], 'time': '2021-05-20T03:56:31.225210Z'}
{'type': 'l2update', 'product_id': 'BTC-USD', 'changes': [['buy', '38327.66', '0.01298051']], 'time': '2021-05-20T03:56:31.225358Z'}
{'type': 'l2update', 'product_id': 'BTC-USD', 'changes': [['buy', '38261.67', '0.00000000']], 'time': '2021-05-20T03:56:31.228339Z'}
{'type': 'l2update', 'product_id': 'BTC-USD', 'changes': [['sell', '38474.74', '0.00000000']], 'time': '2021-05-20T03:56:31.229869Z'}
{'type': 'l2update', 'product_id': 'BTC-USD', 'changes': [['buy', '38285.88', '0.00000000']], 'time': '2021-05-20T03:56:31.230225Z'}
{'type': 'l2update', 'product_id': 'BTC-USD', 'changes': [['sell', '38498.93', '0.33893695']], 'time': '2021-05-20T03:56:31.233667Z'}
{'type': 'l2update', 'product_id': 'BTC-USD', 'changes': [['buy', '38241.11', '0.41403988']], 'time': '2021-05-20T03:56:31.233667Z'}
{'type': 'l2update', 'product_id': 'BTC-USD', 'changes': [['buy', '38250.03', '0.52343463']], 'time': '2021-05-20T03:56:31.233667Z'}
{'type': 'l2update', 'product_id': 'BTC-USD', 'changes': [['buy', '38278.24', '0.43292396']], 'time': '2021-05-20T03:56:31.233667Z'}
{'type': 'l2update', 'product_id': 'BTC-USD', 'changes': [['sell', '43100.00', '3.23860000']], 'time': '2021-05-20T03:56:31.241340Z'}
{'type': 'l2update', 'product_id': 'BTC-USD', 'changes': [['buy', '38302.00', '0.00000000']], 'time': '2021-05-20T03:56:31.258854Z'}
{'type': 'l2update', 'product_id': 'BTC-USD', 'changes': [['buy', '38300.79', '0.00000000']], 'time': '2021-05-20T03:56:31.258854Z'}
{'type': 'l2update', 'product_id': 'BTC-USD', 'changes': [['buy', '38299.99', '0.00000000']], 'time': '2021-05-20T03:56:31.258854Z'}
{'type': 'l2update', 'product_id': 'BTC-USD', 'changes': [['sell', '38439.45', '0.05699999']], 'time': '2021-05-20T03:56:31.264732Z'}
{'type': 'l2update', 'product_id': 'BTC-USD', 'changes': [['sell', '38482.80', '0.00000000']], 'time': '2021-05-20T03:56:31.271033Z'}
{'type': 'l2update', 'product_id': 'BTC-USD', 'changes': [['buy', '38309.49', '0.01000000']], 'time': '2021-05-20T03:56:31.274413Z'}
{'type': 'l2update', 'product_id': 'BTC-USD', 'changes': [['sell', '38412.14', '0.03522121']], 'time': '2021-05-20T03:56:31.276213Z'}
{'type': 'l2update', 'product_id': 'BTC-USD', 'changes': [['sell', '38396.75', '0.00000000']], 'time': '2021-05-20T03:56:31.276213Z'}
{'type': 'l2update', 'product_id': 'BTC-USD', 'changes': [['sell', '38376.66', '0.00000000']], 'time': '2021-05-20T03:56:31.276213Z'}
{'type': 'l2update', 'product_id': 'BTC-USD', 'changes': [['buy', '38271.89', '0.03286105']], 'time': '2021-05-20T03:56:31.276213Z'}
{'type': 'l2update', 'product_id': 'BTC-USD', 'changes': [['buy', '38271.89', '0.00000000']], 'time': '2021-05-20T03:56:31.276213Z'}
{'type': 'l2update', 'product_id': 'BTC-USD', 'changes': [['buy', '38313.43', '0.02610051']], 'time': '2021-05-20T03:56:31.281429Z'}
{'type': 'l2update', 'product_id': 'BTC-USD', 'changes': [['buy', '38332.51', '0.45260898']], 'time': '2021-05-20T03:56:31.291102Z'}
{'type': 'l2update', 'product_id': 'BTC-USD', 'changes': [['buy', '38337.76', '0.09525000']], 'time': '2021-05-20T03:56:31.293322Z'}
{'type': 'l2update', 'product_id': 'BTC-USD', 'changes': [['buy', '38288.47', '0.00000000']], 'time': '2021-05-20T03:56:31.298325Z'}
{'type': 'l2update', 'product_id': 'BTC-USD', 'changes': [['sell', '38408.89', '0.00000000']], 'time': '2021-05-20T03:56:31.301970Z'}
{'type': 'l2update', 'product_id': 'BTC-USD', 'changes': [['sell', '38421.09', '0.00000000']], 'time': '2021-05-20T03:56:31.315949Z'}
{'type': 'l2update', 'product_id': 'BTC-USD', 'changes': [['sell', '38688.46', '0.00000000']], 'time': '2021-05-20T03:56:31.318135Z'}
{'type': 'l2update', 'product_id': 'BTC-USD', 'changes': [['sell', '38337.77', '0.51845869']], 'time': '2021-05-20T03:56:31.325303Z'}
{'type': 'l2update', 'product_id': 'BTC-USD', 'changes': [['buy', '38327.67', '1.98947960']], 'time': '2021-05-20T03:56:31.325979Z'}
{'type': 'l2update', 'product_id': 'BTC-USD', 'changes': [['buy', '38205.40', '0.01000000']], 'time': '2021-05-20T03:56:31.328901Z'}
{'type': 'l2update', 'product_id': 'BTC-USD', 'changes': [['buy', '38270.51', '0.00000000']], 'time': '2021-05-20T03:56:31.334701Z'}
{'type': 'l2update', 'product_id': 'BTC-USD', 'changes': [['sell', '38363.79', '0.59200000']], 'time': '2021-05-20T03:56:31.341683Z'}
{'type': 'l2update', 'product_id': 'BTC-USD', 'changes': [['sell', '38426.90', '0.00000000']], 'time': '2021-05-20T03:56:31.342212Z'}
{'type': 'l2update', 'product_id': 'BTC-USD', 'changes': [['sell', '38385.68', '0.00000000']], 'time': '2021-05-20T03:56:31.350369Z'}
{'type': 'l2update', 'product_id': 'BTC-USD', 'changes': [['buy', '38278.24', '0.56183357']], 'time': '2021-05-20T03:56:31.355342Z'}
{'type': 'l2update', 'product_id': 'BTC-USD', 'changes': [['buy', '38327.66', '0.01474542']], 'time': '2021-05-20T03:56:31.367746Z'}
{'type': 'l2update', 'product_id': 'BTC-USD', 'changes': [['sell', '38351.51', '0.00000000']], 'time': '2021-05-20T03:56:31.375584Z'}
{'type': 'l2update', 'product_id': 'BTC-USD', 'changes': [['sell', '38337.77', '0.51346986']], 'time': '2021-05-20T03:56:31.381399Z'}
{'type': 'l2update', 'product_id': 'BTC-USD', 'changes': [['buy', '38337.49', '0.04999215']], 'time': '2021-05-20T03:56:31.396415Z'}
{'type': 'l2update', 'product_id': 'BTC-USD', 'changes': [['sell', '38501.08', '0.01000000']], 'time': '2021-05-20T03:56:31.397980Z'}
{'type': 'l2update', 'product_id': 'BTC-USD', 'changes': [['sell', '38491.12', '0.03673172']], 'time': '2021-05-20T03:56:31.400150Z'}
{'type': 'l2update', 'product_id': 'BTC-USD', 'changes': [['buy', '38240.64', '0.03323891']], 'time': '2021-05-20T03:56:31.400150Z'}
{'type': 'l2update', 'product_id': 'BTC-USD', 'changes': [['sell', '38405.84', '0.02603771']], 'time': '2021-05-20T03:56:31.404452Z'}
{'type': 'l2update', 'product_id': 'BTC-USD', 'changes': [['buy', '38335.16', '0.55100000']], 'time': '2021-05-20T03:56:31.411123Z'}
{'type': 'l2update', 'product_id': 'BTC-USD', 'changes': [['sell', '38389.22', '0.00000000']], 'time': '2021-05-20T03:56:31.413734Z'}
{'type': 'l2update', 'product_id': 'BTC-USD', 'changes': [['buy', '38240.18', '0.00000000']], 'time': '2021-05-20T03:56:31.417672Z'}
{'type': 'l2update', 'product_id': 'BTC-USD', 'changes': [['sell', '38379.02', '0.02000000']], 'time': '2021-05-20T03:56:31.426540Z'}
{'type': 'l2update', 'product_id': 'BTC-USD', 'changes': [['sell', '38337.77', '0.51140799']], 'time': '2021-05-20T03:56:31.426785Z'}
{'type': 'l2update', 'product_id': 'BTC-USD', 'changes': [['buy', '38309.00', '0.02400000']], 'time': '2021-05-20T03:56:31.429491Z'}
{'type': 'l2update', 'product_id': 'BTC-USD', 'changes': [['buy', '38308.19', '0.02400000']], 'time': '2021-05-20T03:56:31.429491Z'}
{'type': 'l2update', 'product_id': 'BTC-USD', 'changes': [['buy', '38307.39', '0.02400000']], 'time': '2021-05-20T03:56:31.429491Z'}
{'type': 'l2update', 'product_id': 'BTC-USD', 'changes': [['sell', '38364.64', '1.13900000']], 'time': '2021-05-20T03:56:31.437230Z'}
{'type': 'l2update', 'product_id': 'BTC-USD', 'changes': [['sell', '38363.83', '2.48969908']], 'time': '2021-05-20T03:56:31.453933Z'}
{'type': 'l2update', 'product_id': 'BTC-USD', 'changes': [['sell', '38337.77', '0.00000000']], 'time': '2021-05-20T03:56:31.457728Z'}
{'type': 'l2update', 'product_id': 'BTC-USD', 'changes': [['buy', '38292.49', '0.10000000']], 'time': '2021-05-20T03:56:31.459346Z'}
{'type': 'l2update', 'product_id': 'BTC-USD', 'changes': [['sell', '38399.50', '0.00000000']], 'time': '2021-05-20T03:56:31.477008Z'}
{'type': 'l2update', 'product_id': 'BTC-USD', 'changes': [['sell', '38394.37', '0.00000000']], 'time': '2021-05-20T03:56:31.477008Z'}
{'type': 'l2update', 'product_id': 'BTC-USD', 'changes': [['sell', '38384.68', '0.00000000']], 'time': '2021-05-20T03:56:31.477008Z'}
{'type': 'l2update', 'product_id': 'BTC-USD', 'changes': [['sell', '38380.12', '0.00000000']], 'time': '2021-05-20T03:56:31.477008Z'}
{'type': 'l2update', 'product_id': 'BTC-USD', 'changes': [['buy', '38204.27', '0.42039654']], 'time': '2021-05-20T03:56:31.477008Z'}
{'type': 'l2update', 'product_id': 'BTC-USD', 'changes': [['buy', '38211.84', '0.00000000']], 'time': '2021-05-20T03:56:31.477008Z'}
{'type': 'l2update', 'product_id': 'BTC-USD', 'changes': [['buy', '38244.35', '0.00000000']], 'time': '2021-05-20T03:56:31.477008Z'}
{'type': 'l2update', 'product_id': 'BTC-USD', 'changes': [['buy', '38250.03', '0.39452502']], 'time': '2021-05-20T03:56:31.477008Z'}
{'type': 'l2update', 'product_id': 'BTC-USD', 'changes': [['buy', '32130.00', '0.06406635']], 'time': '2021-05-20T03:56:31.486988Z'}
{'type': 'l2update', 'product_id': 'BTC-USD', 'changes': [['sell', '39449.99', '0.00000000']], 'time': '2021-05-20T03:56:31.490392Z'}
{'type': 'l2update', 'product_id': 'BTC-USD', 'changes': [['sell', '38363.84', '0.00000000']], 'time': '2021-05-20T03:56:31.494707Z'}
{'type': 'l2update', 'product_id': 'BTC-USD', 'changes': [['sell', '39499.99', '0.11060000']], 'time': '2021-05-20T03:56:31.498206Z'}
{'type': 'l2update', 'product_id': 'BTC-USD', 'changes': [['buy', '38266.17', '1.97260000']], 'time': '2021-05-20T03:56:31.501455Z'}
{'type': 'l2update', 'product_id': 'BTC-USD', 'changes': [['sell', '38343.11', '1.26512591']], 'time': '2021-05-20T03:56:31.507178Z'}
{'type': 'l2update', 'product_id': 'BTC-USD', 'changes': [['sell', '38510.65', '0.01665731']], 'time': '2021-05-20T03:56:31.522742Z'}
{'type': 'l2update', 'product_id': 'BTC-USD', 'changes': [['sell', '39114.47', '0.00505876']], 'time': '2021-05-20T03:56:31.524600Z'}
{'type': 'l2update', 'product_id': 'BTC-USD', 'changes': [['sell', '38412.14', '0.00000000']], 'time': '2021-05-20T03:56:31.528634Z'}
{'type': 'l2update', 'product_id': 'BTC-USD', 'changes': [['sell', '38405.25', '0.00000000']], 'time': '2021-05-20T03:56:31.528634Z'}
{'type': 'l2update', 'product_id': 'BTC-USD', 'changes': [['buy', '38201.76', '0.00000000']], 'time': '2021-05-20T03:56:31.528634Z'}
{'type': 'l2update', 'product_id': 'BTC-USD', 'changes': [['sell', '38363.83', '2.98969908']], 'time': '2021-05-20T03:56:31.535391Z'}
{'type': 'l2update', 'product_id': 'BTC-USD', 'changes': [['sell', '38512.10', '0.00722767']], 'time': '2021-05-20T03:56:31.535432Z'}
{'type': 'l2update', 'product_id': 'BTC-USD', 'changes': [['buy', '38337.77', '0.00573000']], 'time': '2021-05-20T03:56:31.538523Z'}
{'type': 'l2update', 'product_id': 'BTC-USD', 'changes': [['buy', '38332.51', '0.25260898']], 'time': '2021-05-20T03:56:31.540635Z'}
{'type': 'l2update', 'product_id': 'BTC-USD', 'changes': [['sell', '38374.28', '0.00000000']], 'time': '2021-05-20T03:56:31.543449Z'}
{'type': 'l2update', 'product_id': 'BTC-USD', 'changes': [['sell', '38463.96', '0.01299918']], 'time': '2021-05-20T03:56:31.554809Z'}
{'type': 'l2update', 'product_id': 'BTC-USD', 'changes': [['buy', '38327.67', '0.00000000']], 'time': '2021-05-20T03:56:31.559991Z'}
{'type': 'l2update', 'product_id': 'BTC-USD', 'changes': [['buy', '38300.60', '0.00000000']], 'time': '2021-05-20T03:56:31.569898Z'}
{'type': 'l2update', 'product_id': 'BTC-USD', 'changes': [['buy', '38253.15', '0.01155000']], 'time': '2021-05-20T03:56:31.579634Z'}
{'type': 'l2update', 'product_id': 'BTC-USD', 'changes': [['sell', '38348.42', '0.04882942']], 'time': '2021-05-20T03:56:31.579767Z'}
{'type': 'l2update', 'product_id': 'BTC-USD', 'changes': [['sell', '38498.93', '0.68660533']], 'time': '2021-05-20T03:56:31.589233Z'}
{'type': 'l2update', 'product_id': 'BTC-USD', 'changes': [['sell', '38363.78', '0.05000000']], 'time': '2021-05-20T03:56:31.602349Z'}
{'type': 'l2update', 'product_id': 'BTC-USD', 'changes': [['buy', '38337.76', '0.08033000']], 'time': '2021-05-20T03:56:31.609586Z'}
{'type': 'l2update', 'product_id': 'BTC-USD', 'changes': [['buy', '38337.76', '0.00573000']], 'time': '2021-05-20T03:56:31.609773Z'}
{'type': 'l2update', 'product_id': 'BTC-USD', 'changes': [['sell', '38502.78', '0.00000000']], 'time': '2021-05-20T03:56:31.610583Z'}
{'type': 'l2update', 'product_id': 'BTC-USD', 'changes': [['sell', '38526.78', '0.00000000']], 'time': '2021-05-20T03:56:31.611426Z'}
{'type': 'l2update', 'product_id': 'BTC-USD', 'changes': [['buy', '38306.16', '0.00000000']], 'time': '2021-05-20T03:56:31.627921Z'}
{'type': 'l2update', 'product_id': 'BTC-USD', 'changes': [['buy', '38306.17', '0.46284379']], 'time': '2021-05-20T03:56:31.630456Z'}
{'type': 'l2update', 'product_id': 'BTC-USD', 'changes': [['buy', '38242.72', '0.50000000']], 'time': '2021-05-20T03:56:31.630494Z'}
{'type': 'l2update', 'product_id': 'BTC-USD', 'changes': [['sell', '38346.82', '1.48016088']], 'time': '2021-05-20T03:56:31.654545Z'}
{'type': 'l2update', 'product_id': 'BTC-USD', 'changes': [['sell', '38499.31', '0.00000000']], 'time': '2021-05-20T03:56:31.669006Z'}
{'type': 'l2update', 'product_id': 'BTC-USD', 'changes': [['sell', '38421.42', '0.00000000']], 'time': '2021-05-20T03:56:31.678758Z'}
{'type': 'l2update', 'product_id': 'BTC-USD', 'changes': [['buy', '38335.17', '0.00000000']], 'time': '2021-05-20T03:56:31.679996Z'}
{'type': 'l2update', 'product_id': 'BTC-USD', 'changes': [['sell', '38363.83', '2.48969908']], 'time': '2021-05-20T03:56:31.680115Z'}
{'type': 'l2update', 'product_id': 'BTC-USD', 'changes': [['sell', '38383.32', '0.00000000']], 'time': '2021-05-20T03:56:31.680868Z'}
{'type': 'l2update', 'product_id': 'BTC-USD', 'changes': [['sell', '38391.95', '0.00000000']], 'time': '2021-05-20T03:56:31.682586Z'}
{'type': 'l2update', 'product_id': 'BTC-USD', 'changes': [['sell', '38378.14', '0.03000000']], 'time': '2021-05-20T03:56:31.688876Z'}
{'type': 'l2update', 'product_id': 'BTC-USD', 'changes': [['buy', '38177.33', '0.05051738']], 'time': '2021-05-20T03:56:31.689378Z'}
{'type': 'l2update', 'product_id': 'BTC-USD', 'changes': [['buy', '38319.99', '0.04980808']], 'time': '2021-05-20T03:56:31.690200Z'}
{'type': 'l2update', 'product_id': 'BTC-USD', 'changes': [['sell', '38361.00', '0.04242969']], 'time': '2021-05-20T03:56:31.690200Z'}
{'type': 'l2update', 'product_id': 'BTC-USD', 'changes': [['buy', '38337.76', '0.20573000']], 'time': '2021-05-20T03:56:31.690281Z'}
{'type': 'l2update', 'product_id': 'BTC-USD', 'changes': [['sell', '38491.12', '0.06903776']], 'time': '2021-05-20T03:56:31.692395Z'}
{'type': 'l2update', 'product_id': 'BTC-USD', 'changes': [['buy', '38249.58', '0.02616620']], 'time': '2021-05-20T03:56:31.692395Z'}
{'type': 'l2update', 'product_id': 'BTC-USD', 'changes': [['sell', '38466.72', '0.00000000']], 'time': '2021-05-20T03:56:31.702789Z'}
{'type': 'l2update', 'product_id': 'BTC-USD', 'changes': [['sell', '38434.30', '0.00000000']], 'time': '2021-05-20T03:56:31.705457Z'}
{'type': 'l2update', 'product_id': 'BTC-USD', 'changes': [['sell', '38428.02', '0.00000000']], 'time': '2021-05-20T03:56:31.705457Z'}
{'type': 'l2update', 'product_id': 'BTC-USD', 'changes': [['sell', '38416.03', '0.00000000']], 'time': '2021-05-20T03:56:31.705457Z'}
{'type': 'l2update', 'product_id': 'BTC-USD', 'changes': [['sell', '38410.33', '0.00000000']], 'time': '2021-05-20T03:56:31.705457Z'}
{'type': 'l2update', 'product_id': 'BTC-USD', 'changes': [['buy', '38325.22', '0.00000000']], 'time': '2021-05-20T03:56:31.706207Z'}
{'type': 'l2update', 'product_id': 'BTC-USD', 'changes': [['sell', '39114.47', '0.00330000']], 'time': '2021-05-20T03:56:31.709194Z'}
{'type': 'l2update', 'product_id': 'BTC-USD', 'changes': [['sell', '38351.48', '0.59300000']], 'time': '2021-05-20T03:56:31.710296Z'}
{'type': 'l2update', 'product_id': 'BTC-USD', 'changes': [['buy', '38313.44', '1.98947960']], 'time': '2021-05-20T03:56:31.712175Z'}
{'type': 'l2update', 'product_id': 'BTC-USD', 'changes': [['buy', '38299.21', '1.20000000']], 'time': '2021-05-20T03:56:31.716739Z'}
{'type': 'l2update', 'product_id': 'BTC-USD', 'changes': [['sell', '38517.98', '0.01298095']], 'time': '2021-05-20T03:56:31.720435Z'}
{'type': 'l2update', 'product_id': 'BTC-USD', 'changes': [['buy', '38337.76', '0.24457941']], 'time': '2021-05-20T03:56:31.720653Z'}
{'type': 'l2update', 'product_id': 'BTC-USD', 'changes': [['sell', '38343.10', '1.20605701']], 'time': '2021-05-20T03:56:31.720794Z'}
{'type': 'l2update', 'product_id': 'BTC-USD', 'changes': [['sell', '38430.61', '0.11800000']], 'time': '2021-05-20T03:56:31.723750Z'}
{'type': 'l2update', 'product_id': 'BTC-USD', 'changes': [['buy', '38309.00', '0.00000000']], 'time': '2021-05-20T03:56:31.726754Z'}
{'type': 'l2update', 'product_id': 'BTC-USD', 'changes': [['sell', '38418.83', '0.01000000']], 'time': '2021-05-20T03:56:31.736242Z'}
{'type': 'l2update', 'product_id': 'BTC-USD', 'changes': [['buy', '38157.32', '0.00000000']], 'time': '2021-05-20T03:56:31.779322Z'}
{'type': 'l2update', 'product_id': 'BTC-USD', 'changes': [['buy', '38337.76', '0.23884941']], 'time': '2021-05-20T03:56:31.779856Z'}
{'type': 'l2update', 'product_id': 'BTC-USD', 'changes': [['buy', '38309.49', '0.00000000']], 'time': '2021-05-20T03:56:31.779968Z'}
{'type': 'l2update', 'product_id': 'BTC-USD', 'changes': [['buy', '38321.05', '0.00000000']], 'time': '2021-05-20T03:56:31.780086Z'}
{'type': 'l2update', 'product_id': 'BTC-USD', 'changes': [['sell', '38512.81', '0.01000000']], 'time': '2021-05-20T03:56:31.786814Z'}
{'type': 'l2update', 'product_id': 'BTC-USD', 'changes': [['sell', '38347.96', '0.00600000']], 'time': '2021-05-20T03:56:31.794548Z'}
{'type': 'l2update', 'product_id': 'BTC-USD', 'changes': [['buy', '38266.17', '0.00000000']], 'time': '2021-05-20T03:56:31.810080Z'}
{'type': 'l2update', 'product_id': 'BTC-USD', 'changes': [['sell', '38337.78', '0.00421942']], 'time': '2021-05-20T03:56:31.826166Z'}
{'type': 'l2update', 'product_id': 'BTC-USD', 'changes': [['buy', '38242.72', '0.00000000']], 'time': '2021-05-20T03:56:31.830540Z'}
{'type': 'l2update', 'product_id': 'BTC-USD', 'changes': [['buy', '38332.51', '0.10260898']], 'time': '2021-05-20T03:56:31.836760Z'}
{'type': 'l2update', 'product_id': 'BTC-USD', 'changes': [['sell', '38337.78', '0.00373929']], 'time': '2021-05-20T03:56:31.868623Z'}
{'type': 'l2update', 'product_id': 'BTC-USD', 'changes': [['sell', '38337.78', '0.00000000']], 'time': '2021-05-20T03:56:31.938244Z'}
{'type': 'l2update', 'product_id': 'BTC-USD', 'changes': [['sell', '38351.53', '0.00000000']], 'time': '2021-05-20T03:56:31.939006Z'}
{'type': 'l2update', 'product_id': 'BTC-USD', 'changes': [['sell', '38454.28', '0.00000000']], 'time': '2021-05-20T03:56:31.951377Z'}
{'type': 'l2update', 'product_id': 'BTC-USD', 'changes': [['sell', '38447.43', '0.00000000']], 'time': '2021-05-20T03:56:31.951377Z'}
{'type': 'l2update', 'product_id': 'BTC-USD', 'changes': [['sell', '38440.77', '0.06160580']], 'time': '2021-05-20T03:56:31.951377Z'}
{'type': 'l2update', 'product_id': 'BTC-USD', 'changes': [['sell', '38363.83', '0.00000000']], 'time': '2021-05-20T03:56:31.951480Z'}
{'type': 'l2update', 'product_id': 'BTC-USD', 'changes': [['buy', '38327.71', '0.00000000']], 'time': '2021-05-20T03:56:31.951518Z'}
{'type': 'l2update', 'product_id': 'BTC-USD', 'changes': [['buy', '38335.16', '0.45100000']], 'time': '2021-05-20T03:56:31.951702Z'}
{'type': 'l2update', 'product_id': 'BTC-USD', 'changes': [['buy', '38308.19', '0.00000000']], 'time': '2021-05-20T03:56:31.952650Z'}
{'type': 'l2update', 'product_id': 'BTC-USD', 'changes': [['buy', '38307.39', '0.00000000']], 'time': '2021-05-20T03:56:31.952650Z'}
{'type': 'l2update', 'product_id': 'BTC-USD', 'changes': [['buy', '38337.77', '0.00000000']], 'time': '2021-05-20T03:56:31.953078Z'}
{'type': 'l2update', 'product_id': 'BTC-USD', 'changes': [['buy', '38308.04', '0.39490431']], 'time': '2021-05-20T03:56:31.953781Z'}
{'type': 'l2update', 'product_id': 'BTC-USD', 'changes': [['sell', '38376.44', '0.01000000']], 'time': '2021-05-20T03:56:31.954579Z'}
{'type': 'l2update', 'product_id': 'BTC-USD', 'changes': [['sell', '38518.44', '0.29903963']], 'time': '2021-05-20T03:56:31.954711Z'}
{'type': 'l2update', 'product_id': 'BTC-USD', 'changes': [['sell', '38378.14', '0.07000000']], 'time': '2021-05-20T03:56:31.954921Z'}
{'type': 'l2update', 'product_id': 'BTC-USD', 'changes': [['buy', '38285.10', '1.28140262']], 'time': '2021-05-20T03:56:31.955033Z'}
{'type': 'l2update', 'product_id': 'BTC-USD', 'changes': [['buy', '38327.72', '0.52100000']], 'time': '2021-05-20T03:56:31.955298Z'}
{'type': 'l2update', 'product_id': 'BTC-USD', 'changes': [['buy', '38337.77', '0.02890000']], 'time': '2021-05-20T03:56:31.955530Z'}
{'type': 'l2update', 'product_id': 'BTC-USD', 'changes': [['sell', '38337.78', '1.52127646']], 'time': '2021-05-20T03:56:31.955548Z'}
{'type': 'l2update', 'product_id': 'BTC-USD', 'changes': [['sell', '38434.27', '1.20000000']], 'time': '2021-05-20T03:56:31.955740Z'}
{'type': 'l2update', 'product_id': 'BTC-USD', 'changes': [['sell', '38343.10', '1.70605701']], 'time': '2021-05-20T03:56:31.956229Z'}
{'type': 'l2update', 'product_id': 'BTC-USD', 'changes': [['buy', '38249.58', '0.06005770']], 'time': '2021-05-20T03:56:31.956297Z'}
{'type': 'l2update', 'product_id': 'BTC-USD', 'changes': [['buy', '38260.75', '0.03570076']], 'time': '2021-05-20T03:56:31.956297Z'}
{'type': 'l2update', 'product_id': 'BTC-USD', 'changes': [['buy', '38266.05', '0.03610677']], 'time': '2021-05-20T03:56:31.956297Z'}
{'type': 'l2update', 'product_id': 'BTC-USD', 'changes': [['sell', '38337.78', '1.51449853']], 'time': '2021-05-20T03:56:31.956297Z'}
{'type': 'l2update', 'product_id': 'BTC-USD', 'changes': [['sell', '38337.78', '1.50833670']], 'time': '2021-05-20T03:56:31.956297Z'}
{'type': 'l2update', 'product_id': 'BTC-USD', 'changes': [['buy', '38292.49', '0.00000000']], 'time': '2021-05-20T03:56:32.001974Z'}
{'type': 'l2update', 'product_id': 'BTC-USD', 'changes': [['buy', '38313.44', '0.00000000']], 'time': '2021-05-20T03:56:32.038803Z'}
{'type': 'l2update', 'product_id': 'BTC-USD', 'changes': [['sell', '38343.11', '0.00000000']], 'time': '2021-05-20T03:56:32.039411Z'}
{'type': 'l2update', 'product_id': 'BTC-USD', 'changes': [['buy', '38245.87', '0.00000000']], 'time': '2021-05-20T03:56:32.039975Z'}
{'type': 'l2update', 'product_id': 'BTC-USD', 'changes': [['buy', '38122.85', '0.00000000']], 'time': '2021-05-20T03:56:32.041036Z'}
{'type': 'l2update', 'product_id': 'BTC-USD', 'changes': [['sell', '38405.88', '0.61482417']], 'time': '2021-05-20T03:56:32.047388Z'}
{'type': 'l2update', 'product_id': 'BTC-USD', 'changes': [['sell', '38425.84', '0.01000000']], 'time': '2021-05-20T03:56:32.047619Z'}
{'type': 'l2update', 'product_id': 'BTC-USD', 'changes': [['sell', '38337.78', '1.51406670']], 'time': '2021-05-20T03:56:32.048070Z'}
{'type': 'l2update', 'product_id': 'BTC-USD', 'changes': [['sell', '38553.56', '0.00000000']], 'time': '2021-05-20T03:56:32.049356Z'}
{'type': 'l2update', 'product_id': 'BTC-USD', 'changes': [['buy', '38337.76', '0.33884941']], 'time': '2021-05-20T03:56:32.051626Z'}
{'type': 'l2update', 'product_id': 'BTC-USD', 'changes': [['buy', '38285.73', '0.00000000']], 'time': '2021-05-20T03:56:32.058016Z'}
{'type': 'l2update', 'product_id': 'BTC-USD', 'changes': [['buy', '38299.21', '0.00000000']], 'time': '2021-05-20T03:56:32.058116Z'}
{'type': 'l2update', 'product_id': 'BTC-USD', 'changes': [['buy', '38231.40', '0.31002012']], 'time': '2021-05-20T03:56:32.058168Z'}
{'type': 'l2update', 'product_id': 'BTC-USD', 'changes': [['sell', '38343.10', '0.50000000']], 'time': '2021-05-20T03:56:32.058679Z'}
{'type': 'l2update', 'product_id': 'BTC-USD', 'changes': [['buy', '38337.49', '0.00000000']], 'time': '2021-05-20T03:56:32.058722Z'}
{'type': 'l2update', 'product_id': 'BTC-USD', 'changes': [['buy', '38337.77', '0.00000000']], 'time': '2021-05-20T03:56:32.059202Z'}
{'type': 'l2update', 'product_id': 'BTC-USD', 'changes': [['sell', '38440.77', '0.02994340']], 'time': '2021-05-20T03:56:32.059425Z'}
{'type': 'l2update', 'product_id': 'BTC-USD', 'changes': [['sell', '38440.77', '0.00000000']], 'time': '2021-05-20T03:56:32.059425Z'}
{'type': 'l2update', 'product_id': 'BTC-USD', 'changes': [['sell', '38428.93', '0.00000000']], 'time': '2021-05-20T03:56:32.059425Z'}
{'type': 'l2update', 'product_id': 'BTC-USD', 'changes': [['buy', '38209.35', '0.00000000']], 'time': '2021-05-20T03:56:32.059425Z'}
{'type': 'l2update', 'product_id': 'BTC-USD', 'changes': [['buy', '38216.08', '0.00000000']], 'time': '2021-05-20T03:56:32.059425Z'}
{'type': 'l2update', 'product_id': 'BTC-USD', 'changes': [['buy', '38225.74', '0.00000000']], 'time': '2021-05-20T03:56:32.059425Z'}
{'type': 'l2update', 'product_id': 'BTC-USD', 'changes': [['buy', '38226.82', '0.00000000']], 'time': '2021-05-20T03:56:32.059425Z'}
{'type': 'l2update', 'product_id': 'BTC-USD', 'changes': [['buy', '38337.76', '0.30000000']], 'time': '2021-05-20T03:56:32.060320Z'}
{'type': 'l2update', 'product_id': 'BTC-USD', 'changes': [['buy', '38313.44', '0.50000000']], 'time': '2021-05-20T03:56:32.066310Z'}
{'type': 'l2update', 'product_id': 'BTC-USD', 'changes': [['buy', '38271.51', '0.10000000']], 'time': '2021-05-20T03:56:32.066981Z'}
{'type': 'l2update', 'product_id': 'BTC-USD', 'changes': [['buy', '35000.00', '209.99902780']], 'time': '2021-05-20T03:56:32.079759Z'}
{'type': 'l2update', 'product_id': 'BTC-USD', 'changes': [['sell', '38337.78', '1.46332988']], 'time': '2021-05-20T03:56:32.087564Z'}
{'type': 'l2update', 'product_id': 'BTC-USD', 'changes': [['buy', '38337.77', '0.15000000']], 'time': '2021-05-20T03:56:32.090817Z'}
{'type': 'l2update', 'product_id': 'BTC-USD', 'changes': [['sell', '38376.44', '0.00000000']], 'time': '2021-05-20T03:56:32.098999Z'}
{'type': 'l2update', 'product_id': 'BTC-USD', 'changes': [['buy', '38303.86', '0.00000000']], 'time': '2021-05-20T03:56:32.130839Z'}
{'type': 'l2update', 'product_id': 'BTC-USD', 'changes': [['sell', '38374.97', '0.50000000']], 'time': '2021-05-20T03:56:32.134405Z'}
{'type': 'l2update', 'product_id': 'BTC-USD', 'changes': [['buy', '38321.06', '0.59116555']], 'time': '2021-05-20T03:56:32.135654Z'}
{'type': 'l2update', 'product_id': 'BTC-USD', 'changes': [['sell', '38346.81', '2.48969908']], 'time': '2021-05-20T03:56:32.139990Z'}
{'type': 'l2update', 'product_id': 'BTC-USD', 'changes': [['buy', '38251.31', '1.93290000']], 'time': '2021-05-20T03:56:32.156946Z'}
{'type': 'l2update', 'product_id': 'BTC-USD', 'changes': [['sell', '38337.78', '1.46133242']], 'time': '2021-05-20T03:56:32.156967Z'}
{'type': 'l2update', 'product_id': 'BTC-USD', 'changes': [['buy', '38327.66', '0.01298051']], 'time': '2021-05-20T03:56:32.185486Z'}
{'type': 'l2update', 'product_id': 'BTC-USD', 'changes': [['sell', '38337.78', '1.45881546']], 'time': '2021-05-20T03:56:32.216486Z'}
{'type': 'l2update', 'product_id': 'BTC-USD', 'changes': [['sell', '38512.10', '0.00000000']], 'time': '2021-05-20T03:56:32.300919Z'}
{'type': 'l2update', 'product_id': 'BTC-USD', 'changes': [['buy', '38164.27', '0.00000000']], 'time': '2021-05-20T03:56:32.303072Z'}
{'type': 'l2update', 'product_id': 'BTC-USD', 'changes': [['sell', '38647.29', '0.00000000']], 'time': '2021-05-20T03:56:32.303232Z'}
{'type': 'l2update', 'product_id': 'BTC-USD', 'changes': [['buy', '38332.51', '0.00260898']], 'time': '2021-05-20T03:56:32.303266Z'}
{'type': 'l2update', 'product_id': 'BTC-USD', 'changes': [['sell', '38434.27', '0.00000000']], 'time': '2021-05-20T03:56:32.303549Z'}
{'type': 'l2update', 'product_id': 'BTC-USD', 'changes': [['buy', '38019.85', '0.00000000']], 'time': '2021-05-20T03:56:32.303787Z'}
{'type': 'l2update', 'product_id': 'BTC-USD', 'changes': [['buy', '38283.92', '0.00000000']], 'time': '2021-05-20T03:56:32.303918Z'}
{'type': 'l2update', 'product_id': 'BTC-USD', 'changes': [['sell', '38418.83', '0.00000000']], 'time': '2021-05-20T03:56:32.304098Z'}
{'type': 'l2update', 'product_id': 'BTC-USD', 'changes': [['sell', '38337.78', '0.00573000']], 'time': '2021-05-20T03:56:32.304128Z'}
{'type': 'l2update', 'product_id': 'BTC-USD', 'changes': [['sell', '43100.00', '1.09530000']], 'time': '2021-05-20T03:56:32.306469Z'}
{'type': 'l2update', 'product_id': 'BTC-USD', 'changes': [['buy', '38177.33', '0.00000000']], 'time': '2021-05-20T03:56:32.307503Z'}
{'type': 'l2update', 'product_id': 'BTC-USD', 'changes': [['sell', '38352.01', '0.05010117']], 'time': '2021-05-20T03:56:32.311922Z'}
{'type': 'l2update', 'product_id': 'BTC-USD', 'changes': [['sell', '38535.06', '0.01297519']], 'time': '2021-05-20T03:56:32.312517Z'}
{'type': 'l2update', 'product_id': 'BTC-USD', 'changes': [['buy', '38337.77', '0.17890000']], 'time': '2021-05-20T03:56:32.312552Z'}
{'type': 'l2update', 'product_id': 'BTC-USD', 'changes': [['buy', '38144.27', '0.02621625']], 'time': '2021-05-20T03:56:32.312949Z'}
{'type': 'l2update', 'product_id': 'BTC-USD', 'changes': [['buy', '38231.40', '0.70657983']], 'time': '2021-05-20T03:56:32.318258Z'}
{'type': 'l2update', 'product_id': 'BTC-USD', 'changes': [['buy', '38306.17', '1.15118334']], 'time': '2021-05-20T03:56:32.318624Z'}
{'type': 'l2update', 'product_id': 'BTC-USD', 'changes': [['buy', '38337.77', '0.02890000']], 'time': '2021-05-20T03:56:32.319319Z'}
{'type': 'l2update', 'product_id': 'BTC-USD', 'changes': [['sell', '38463.96', '0.00000000']], 'time': '2021-05-20T03:56:32.319351Z'}
{'type': 'l2update', 'product_id': 'BTC-USD', 'changes': [['buy', '38262.93', '0.00000000']], 'time': '2021-05-20T03:56:32.319370Z'}
{'type': 'l2update', 'product_id': 'BTC-USD', 'changes': [['buy', '38293.04', '0.01000000']], 'time': '2021-05-20T03:56:32.325634Z'}
{'type': 'l2update', 'product_id': 'BTC-USD', 'changes': [['buy', '38309.50', '1.98947960']], 'time': '2021-05-20T03:56:32.325686Z'}
{'type': 'l2update', 'product_id': 'BTC-USD', 'changes': [['buy', '38335.17', '0.10000000']], 'time': '2021-05-20T03:56:32.325698Z'}
{'type': 'l2update', 'product_id': 'BTC-USD', 'changes': [['sell', '38337.78', '0.00000000']], 'time': '2021-05-20T03:56:32.329264Z'}
{'type': 'l2update', 'product_id': 'BTC-USD', 'changes': [['buy', '38337.78', '0.00056727']], 'time': '2021-05-20T03:56:32.329264Z'}
{'type': 'l2update', 'product_id': 'BTC-USD', 'changes': [['buy', '38338.96', '0.00630840']], 'time': '2021-05-20T03:56:32.329264Z'}
{'type': 'l2update', 'product_id': 'BTC-USD', 'changes': [['sell', '38374.97', '0.00000000']], 'time': '2021-05-20T03:56:32.333151Z'}
{'type': 'l2update', 'product_id': 'BTC-USD', 'changes': [['buy', '38337.76', '0.30176491']], 'time': '2021-05-20T03:56:32.356154Z'}
{'type': 'l2update', 'product_id': 'BTC-USD', 'changes': [['buy', '38335.22', '0.03884941']], 'time': '2021-05-20T03:56:32.380597Z'}
{'type': 'l2update', 'product_id': 'BTC-USD', 'changes': [['sell', '38354.46', '0.00000000']], 'time': '2021-05-20T03:56:32.419135Z'}
{'type': 'l2update', 'product_id': 'BTC-USD', 'changes': [['sell', '38346.82', '0.00000000']], 'time': '2021-05-20T03:56:32.419150Z'}
{'type': 'l2update', 'product_id': 'BTC-USD', 'changes': [['sell', '38343.10', '0.49875560']], 'time': '2021-05-20T03:56:32.425325Z'}
{'type': 'l2update', 'product_id': 'BTC-USD', 'changes': [['sell', '43100.00', '2.80820000']], 'time': '2021-05-20T03:56:32.430175Z'}
{'type': 'l2update', 'product_id': 'BTC-USD', 'changes': [['sell', '38376.95', '0.05138560']], 'time': '2021-05-20T03:56:32.430606Z'}
{'type': 'l2update', 'product_id': 'BTC-USD', 'changes': [['sell', '38454.48', '0.01000000']], 'time': '2021-05-20T03:56:32.431625Z'}
{'type': 'l2update', 'product_id': 'BTC-USD', 'changes': [['sell', '38660.39', '0.01883430']], 'time': '2021-05-20T03:56:32.431756Z'}
{'type': 'l2update', 'product_id': 'BTC-USD', 'changes': [['buy', '38280.20', '0.01000000']], 'time': '2021-05-20T03:56:32.431796Z'}
{'type': 'l2update', 'product_id': 'BTC-USD', 'changes': [['buy', '38124.67', '0.38900000']], 'time': '2021-05-20T03:56:32.432124Z'}
{'type': 'l2update', 'product_id': 'BTC-USD', 'changes': [['sell', '38435.16', '0.00000000']], 'time': '2021-05-20T03:56:32.460696Z'}
{'type': 'l2update', 'product_id': 'BTC-USD', 'changes': [['sell', '38436.90', '0.00000000']], 'time': '2021-05-20T03:56:32.475274Z'}
{'type': 'l2update', 'product_id': 'BTC-USD', 'changes': [['buy', '38337.77', '0.00000000']], 'time': '2021-05-20T03:56:32.480262Z'}
{'type': 'l2update', 'product_id': 'BTC-USD', 'changes': [['sell', '38535.06', '0.00000000']], 'time': '2021-05-20T03:56:32.480928Z'}
{'type': 'l2update', 'product_id': 'BTC-USD', 'changes': [['sell', '38346.83', '0.00000000']], 'time': '2021-05-20T03:56:32.482131Z'}
{'type': 'l2update', 'product_id': 'BTC-USD', 'changes': [['sell', '38454.08', '0.00000000']], 'time': '2021-05-20T03:56:32.483236Z'}
{'type': 'l2update', 'product_id': 'BTC-USD', 'changes': [['sell', '38446.57', '0.00000000']], 'time': '2021-05-20T03:56:32.483236Z'}
{'type': 'l2update', 'product_id': 'BTC-USD', 'changes': [['sell', '38346.81', '0.00000000']], 'time': '2021-05-20T03:56:32.484796Z'}
{'type': 'l2update', 'product_id': 'BTC-USD', 'changes': [['sell', '38367.78', '0.63678666']], 'time': '2021-05-20T03:56:32.492197Z'}
{'type': 'l2update', 'product_id': 'BTC-USD', 'changes': [['sell', '38339.36', '0.05034474']], 'time': '2021-05-20T03:56:32.492897Z'}
{'type': 'l2update', 'product_id': 'BTC-USD', 'changes': [['buy', '38231.40', '1.12396559']], 'time': '2021-05-20T03:56:32.493238Z'}
{'type': 'l2update', 'product_id': 'BTC-USD', 'changes': [['buy', '38258.97', '0.01000000']], 'time': '2021-05-20T03:56:32.497335Z'}
{'type': 'l2update', 'product_id': 'BTC-USD', 'changes': [['sell', '38339.36', '0.04961874']], 'time': '2021-05-20T03:56:32.505438Z'}
{'type': 'l2update', 'product_id': 'BTC-USD', 'changes': [['sell', '38467.16', '0.00000000']], 'time': '2021-05-20T03:56:32.512478Z'}
{'type': 'l2update', 'product_id': 'BTC-USD', 'changes': [['buy', '38335.22', '0.00000000']], 'time': '2021-05-20T03:56:32.514617Z'}
{'type': 'l2update', 'product_id': 'BTC-USD', 'changes': [['buy', '38293.04', '0.00000000']], 'time': '2021-05-20T03:56:32.521680Z'}
{'type': 'l2update', 'product_id': 'BTC-USD', 'changes': [['sell', '38343.10', '0.00000000']], 'time': '2021-05-20T03:56:32.527680Z'}
{'type': 'l2update', 'product_id': 'BTC-USD', 'changes': [['buy', '38309.34', '0.00000000']], 'time': '2021-05-20T03:56:32.533849Z'}
{'type': 'l2update', 'product_id': 'BTC-USD', 'changes': [['buy', '38335.16', '0.25100000']], 'time': '2021-05-20T03:56:32.534740Z'}
{'type': 'l2update', 'product_id': 'BTC-USD', 'changes': [['buy', '38195.90', '0.00000000']], 'time': '2021-05-20T03:56:32.540319Z'}
{'type': 'l2update', 'product_id': 'BTC-USD', 'changes': [['buy', '38265.06', '0.03000000']], 'time': '2021-05-20T03:56:32.544220Z'}
{'type': 'l2update', 'product_id': 'BTC-USD', 'changes': [['buy', '3500.00', '307.98788917']], 'time': '2021-05-20T03:56:32.545571Z'}
{'type': 'l2update', 'product_id': 'BTC-USD', 'changes': [['buy', '38299.17', '0.00000000']], 'time': '2021-05-20T03:56:32.546706Z'}
{'type': 'l2update', 'product_id': 'BTC-USD', 'changes': [['buy', '38302.69', '0.00000000']], 'time': '2021-05-20T03:56:32.546937Z'}
{'type': 'l2update', 'product_id': 'BTC-USD', 'changes': [['sell', '38457.60', '0.00000000']], 'time': '2021-05-20T03:56:32.547253Z'}
{'type': 'l2update', 'product_id': 'BTC-USD', 'changes': [['buy', '37456.66', '0.04190000']], 'time': '2021-05-20T03:56:32.547486Z'}
{'type': 'l2update', 'product_id': 'BTC-USD', 'changes': [['buy', '36717.90', '0.05920000']], 'time': '2021-05-20T03:56:32.547486Z'}
{'type': 'l2update', 'product_id': 'BTC-USD', 'changes': [['buy', '38309.50', '0.00000000']], 'time': '2021-05-20T03:56:32.547594Z'}
{'type': 'l2update', 'product_id': 'BTC-USD', 'changes': [['sell', '38654.06', '0.00000000']], 'time': '2021-05-20T03:56:32.548627Z'}
{'type': 'l2update', 'product_id': 'BTC-USD', 'changes': [['sell', '38343.06', '0.67500000']], 'time': '2021-05-20T03:56:32.551943Z'}
{'type': 'l2update', 'product_id': 'BTC-USD', 'changes': [['sell', '39090.90', '0.00175897']], 'time': '2021-05-20T03:56:32.552154Z'}
{'type': 'l2update', 'product_id': 'BTC-USD', 'changes': [['sell', '38450.16', '0.03544380']], 'time': '2021-05-20T03:56:32.556869Z'}
{'type': 'l2update', 'product_id': 'BTC-USD', 'changes': [['sell', '38545.04', '0.01297184']], 'time': '2021-05-20T03:56:32.557226Z'}
{'type': 'l2update', 'product_id': 'BTC-USD', 'changes': [['buy', '38191.89', '0.00000000']], 'time': '2021-05-20T03:56:32.567224Z'}
{'type': 'l2update', 'product_id': 'BTC-USD', 'changes': [['buy', '38192.09', '0.00000000']], 'time': '2021-05-20T03:56:32.567224Z'}
{'type': 'l2update', 'product_id': 'BTC-USD', 'changes': [['buy', '38192.12', '0.00000000']], 'time': '2021-05-20T03:56:32.567224Z'}
{'type': 'l2update', 'product_id': 'BTC-USD', 'changes': [['buy', '38319.99', '0.00000000']], 'time': '2021-05-20T03:56:32.568413Z'}
{'type': 'l2update', 'product_id': 'BTC-USD', 'changes': [['sell', '38361.00', '0.00000000']], 'time': '2021-05-20T03:56:32.568413Z'}
{'type': 'l2update', 'product_id': 'BTC-USD', 'changes': [['buy', '38335.16', '0.15100000']], 'time': '2021-05-20T03:56:32.572193Z'}
{'type': 'l2update', 'product_id': 'BTC-USD', 'changes': [['sell', '38347.95', '0.50000000']], 'time': '2021-05-20T03:56:32.578152Z'}
{'type': 'l2update', 'product_id': 'BTC-USD', 'changes': [['buy', '38339.35', '0.02890000']], 'time': '2021-05-20T03:56:32.579724Z'}
{'type': 'l2update', 'product_id': 'BTC-USD', 'changes': [['sell', '38363.85', '0.00000000']], 'time': '2021-05-20T03:56:32.583096Z'}
{'type': 'l2update', 'product_id': 'BTC-USD', 'changes': [['buy', '38248.79', '0.02400000']], 'time': '2021-05-20T03:56:32.583689Z'}
{'type': 'l2update', 'product_id': 'BTC-USD', 'changes': [['sell', '38363.05', '0.27700000']], 'time': '2021-05-20T03:56:32.583805Z'}
{'type': 'l2update', 'product_id': 'BTC-USD', 'changes': [['buy', '38164.28', '0.80355629']], 'time': '2021-05-20T03:56:32.586507Z'}
{'type': 'l2update', 'product_id': 'BTC-USD', 'changes': [['buy', '38208.14', '0.01000000']], 'time': '2021-05-20T03:56:32.587029Z'}
{'type': 'l2update', 'product_id': 'BTC-USD', 'changes': [['buy', '38259.41', '0.05000000']], 'time': '2021-05-20T03:56:32.591316Z'}
{'type': 'l2update', 'product_id': 'BTC-USD', 'changes': [['sell', '38351.47', '2.48969908']], 'time': '2021-05-20T03:56:32.596328Z'}
{'type': 'l2update', 'product_id': 'BTC-USD', 'changes': [['sell', '38339.36', '0.04627030']], 'time': '2021-05-20T03:56:32.596609Z'}
{'type': 'l2update', 'product_id': 'BTC-USD', 'changes': [['sell', '38443.04', '0.01000000']], 'time': '2021-05-20T03:56:32.597011Z'}
{'type': 'l2update', 'product_id': 'BTC-USD', 'changes': [['sell', '38510.65', '0.00000000']], 'time': '2021-05-20T03:56:32.597109Z'}
{'type': 'l2update', 'product_id': 'BTC-USD', 'changes': [['buy', '38144.27', '0.00000000']], 'time': '2021-05-20T03:56:32.597584Z'}
{'type': 'l2update', 'product_id': 'BTC-USD', 'changes': [['sell', '38518.44', '0.00000000']], 'time': '2021-05-20T03:56:32.600625Z'}
{'type': 'l2update', 'product_id': 'BTC-USD', 'changes': [['sell', '38453.45', '0.00000000']], 'time': '2021-05-20T03:56:32.605210Z'}
{'type': 'l2update', 'product_id': 'BTC-USD', 'changes': [['buy', '38329.78', '0.03884941']], 'time': '2021-05-20T03:56:32.608734Z'}
{'type': 'l2update', 'product_id': 'BTC-USD', 'changes': [['sell', '38445.06', '0.01000000']], 'time': '2021-05-20T03:56:32.609075Z'}
{'type': 'l2update', 'product_id': 'BTC-USD', 'changes': [['buy', '38325.27', '0.84700000']], 'time': '2021-05-20T03:56:32.610056Z'}
{'type': 'l2update', 'product_id': 'BTC-USD', 'changes': [['sell', '38450.89', '0.02828068']], 'time': '2021-05-20T03:56:32.610175Z'}
{'type': 'l2update', 'product_id': 'BTC-USD', 'changes': [['sell', '38428.93', '0.03060692']], 'time': '2021-05-20T03:56:32.610175Z'}
{'type': 'l2update', 'product_id': 'BTC-USD', 'changes': [['buy', '38330.75', '0.04965793']], 'time': '2021-05-20T03:56:32.610413Z'}
{'type': 'l2update', 'product_id': 'BTC-USD', 'changes': [['buy', '38313.44', '0.00000000']], 'time': '2021-05-20T03:56:32.610449Z'}
{'type': 'l2update', 'product_id': 'BTC-USD', 'changes': [['sell', '38454.48', '0.00000000']], 'time': '2021-05-20T03:56:32.611630Z'}
{'type': 'l2update', 'product_id': 'BTC-USD', 'changes': [['buy', '38337.76', '0.40176491']], 'time': '2021-05-20T03:56:32.615517Z'}
{'type': 'l2update', 'product_id': 'BTC-USD', 'changes': [['buy', '38272.40', '0.00000000']], 'time': '2021-05-20T03:56:32.620101Z'}
{'type': 'l2update', 'product_id': 'BTC-USD', 'changes': [['sell', '38517.98', '0.00000000']], 'time': '2021-05-20T03:56:32.622089Z'}
{'type': 'l2update', 'product_id': 'BTC-USD', 'changes': [['sell', '38464.40', '0.37775113']], 'time': '2021-05-20T03:56:32.622221Z'}
{'type': 'l2update', 'product_id': 'BTC-USD', 'changes': [['sell', '38363.78', '0.00000000']], 'time': '2021-05-20T03:56:32.623705Z'}
{'type': 'l2update', 'product_id': 'BTC-USD', 'changes': [['sell', '38383.83', '2.16932808']], 'time': '2021-05-20T03:56:32.627200Z'}
{'type': 'l2update', 'product_id': 'BTC-USD', 'changes': [['sell', '38469.67', '0.00000000']], 'time': '2021-05-20T03:56:32.629336Z'}
{'type': 'l2update', 'product_id': 'BTC-USD', 'changes': [['sell', '38379.02', '0.00000000']], 'time': '2021-05-20T03:56:32.630442Z'}
{'type': 'l2update', 'product_id': 'BTC-USD', 'changes': [['buy', '38205.40', '0.00000000']], 'time': '2021-05-20T03:56:32.634740Z'}
{'type': 'l2update', 'product_id': 'BTC-USD', 'changes': [['sell', '38352.01', '0.00000000']], 'time': '2021-05-20T03:56:32.635020Z'}
{'type': 'l2update', 'product_id': 'BTC-USD', 'changes': [['buy', '38232.38', '0.50000000']], 'time': '2021-05-20T03:56:32.636266Z'}
{'type': 'l2update', 'product_id': 'BTC-USD', 'changes': [['sell', '38472.58', '0.03592400']], 'time': '2021-05-20T03:56:32.642889Z'}
{'type': 'l2update', 'product_id': 'BTC-USD', 'changes': [['sell', '38535.15', '0.01000000']], 'time': '2021-05-20T03:56:32.642953Z'}
{'type': 'l2update', 'product_id': 'BTC-USD', 'changes': [['buy', '38157.65', '0.01081700']], 'time': '2021-05-20T03:56:32.643211Z'}
{'type': 'l2update', 'product_id': 'BTC-USD', 'changes': [['buy', '38313.45', '1.98947960']], 'time': '2021-05-20T03:56:32.644605Z'}
{'type': 'l2update', 'product_id': 'BTC-USD', 'changes': [['buy', '38321.06', '0.00000000']], 'time': '2021-05-20T03:56:32.644856Z'}
{'type': 'l2update', 'product_id': 'BTC-USD', 'changes': [['buy', '38327.72', '0.00000000']], 'time': '2021-05-20T03:56:32.644970Z'}
{'type': 'l2update', 'product_id': 'BTC-USD', 'changes': [['sell', '38473.43', '0.00000000']], 'time': '2021-05-20T03:56:32.646461Z'}
{'type': 'l2update', 'product_id': 'BTC-USD', 'changes': [['sell', '38430.09', '0.01000000']], 'time': '2021-05-20T03:56:32.657746Z'}
{'type': 'l2update', 'product_id': 'BTC-USD', 'changes': [['buy', '38313.44', '0.50000000']], 'time': '2021-05-20T03:56:32.660110Z'}
{'type': 'l2update', 'product_id': 'BTC-USD', 'changes': [['buy', '38309.52', '0.43890000']], 'time': '2021-05-20T03:56:32.667866Z'}
{'type': 'l2update', 'product_id': 'BTC-USD', 'changes': [['sell', '38363.04', '0.05000000']], 'time': '2021-05-20T03:56:32.668737Z'}
{'type': 'l2update', 'product_id': 'BTC-USD', 'changes': [['sell', '38506.35', '0.01000000']], 'time': '2021-05-20T03:56:32.668919Z'}
{'type': 'l2update', 'product_id': 'BTC-USD', 'changes': [['sell', '38372.73', '0.05000000']], 'time': '2021-05-20T03:56:32.672819Z'}
{'type': 'l2update', 'product_id': 'BTC-USD', 'changes': [['sell', '38471.45', '0.41637047']], 'time': '2021-05-20T03:56:32.672911Z'}
{'type': 'l2update', 'product_id': 'BTC-USD', 'changes': [['sell', '38485.85', '0.01000000']], 'time': '2021-05-20T03:56:32.672927Z'}
{'type': 'l2update', 'product_id': 'BTC-USD', 'changes': [['buy', '38271.51', '0.00000000']], 'time': '2021-05-20T03:56:32.673345Z'}
{'type': 'l2update', 'product_id': 'BTC-USD', 'changes': [['sell', '38512.81', '0.00000000']], 'time': '2021-05-20T03:56:32.678260Z'}
{'type': 'l2update', 'product_id': 'BTC-USD', 'changes': [['buy', '38339.35', '0.17890000']], 'time': '2021-05-20T03:56:32.682709Z'}
{'type': 'l2update', 'product_id': 'BTC-USD', 'changes': [['buy', '38291.32', '0.00000000']], 'time': '2021-05-20T03:56:32.683011Z'}
{'type': 'l2update', 'product_id': 'BTC-USD', 'changes': [['sell', '38515.30', '0.00000000']], 'time': '2021-05-20T03:56:32.684427Z'}
{'type': 'l2update', 'product_id': 'BTC-USD', 'changes': [['buy', '38337.76', '0.20176491']], 'time': '2021-05-20T03:56:32.684547Z'}
{'type': 'l2update', 'product_id': 'BTC-USD', 'changes': [['buy', '38339.35', '0.15000000']], 'time': '2021-05-20T03:56:32.691361Z'}
{'type': 'l2update', 'product_id': 'BTC-USD', 'changes': [['buy', '38313.49', '0.52000000']], 'time': '2021-05-20T03:56:32.695151Z'}
{'type': 'l2update', 'product_id': 'BTC-USD', 'changes': [['buy', '38161.27', '0.04889235']], 'time': '2021-05-20T03:56:32.696081Z'}
{'type': 'l2update', 'product_id': 'BTC-USD', 'changes': [['buy', '38335.28', '0.04802627']], 'time': '2021-05-20T03:56:32.696334Z'}
{'type': 'l2update', 'product_id': 'BTC-USD', 'changes': [['sell', '38339.36', '0.00000000']], 'time': '2021-05-20T03:56:32.699036Z'}
{'type': 'l2update', 'product_id': 'BTC-USD', 'changes': [['buy', '38277.83', '0.00000000']], 'time': '2021-05-20T03:56:32.704938Z'}
{'type': 'l2update', 'product_id': 'BTC-USD', 'changes': [['buy', '38136.46', '0.05215664']], 'time': '2021-05-20T03:56:32.711801Z'}
{'type': 'l2update', 'product_id': 'BTC-USD', 'changes': [['sell', '38377.88', '0.00000000']], 'time': '2021-05-20T03:56:32.712402Z'}
{'type': 'l2update', 'product_id': 'BTC-USD', 'changes': [['sell', '38369.51', '0.40620000']], 'time': '2021-05-20T03:56:32.713418Z'}
{'type': 'l2update', 'product_id': 'BTC-USD', 'changes': [['buy', '38313.46', '0.59116555']], 'time': '2021-05-20T03:56:32.718980Z'}
{'type': 'l2update', 'product_id': 'BTC-USD', 'changes': [['buy', '38339.35', '0.00000000']], 'time': '2021-05-20T03:56:32.721199Z'}
{'type': 'l2update', 'product_id': 'BTC-USD', 'changes': [['buy', '38278.50', '0.10000000']], 'time': '2021-05-20T03:56:32.725234Z'}
{'type': 'l2update', 'product_id': 'BTC-USD', 'changes': [['sell', '38542.51', '0.02594538']], 'time': '2021-05-20T03:56:32.725971Z'}
{'type': 'l2update', 'product_id': 'BTC-USD', 'changes': [['sell', '38478.69', '0.39716071']], 'time': '2021-05-20T03:56:32.726331Z'}
{'type': 'l2update', 'product_id': 'BTC-USD', 'changes': [['buy', '38224.49', '0.01000000']], 'time': '2021-05-20T03:56:32.726547Z'}
{'type': 'l2update', 'product_id': 'BTC-USD', 'changes': [['sell', '38444.43', '0.03361448']], 'time': '2021-05-20T03:56:32.729670Z'}
{'type': 'l2update', 'product_id': 'BTC-USD', 'changes': [['sell', '38438.15', '0.03673172']], 'time': '2021-05-20T03:56:32.729670Z'}
{'type': 'l2update', 'product_id': 'BTC-USD', 'changes': [['sell', '38403.10', '0.17200000']], 'time': '2021-05-20T03:56:32.730019Z'}
{'type': 'l2update', 'product_id': 'BTC-USD', 'changes': [['sell', '38354.47', '0.00000000']], 'time': '2021-05-20T03:56:32.733179Z'}
{'type': 'l2update', 'product_id': 'BTC-USD', 'changes': [['buy', '38335.16', '0.00000000']], 'time': '2021-05-20T03:56:32.735298Z'}
{'type': 'l2update', 'product_id': 'BTC-USD', 'changes': [['sell', '38445.06', '0.00000000']], 'time': '2021-05-20T03:56:32.738505Z'}
{'type': 'l2update', 'product_id': 'BTC-USD', 'changes': [['sell', '38378.14', '0.04000000']], 'time': '2021-05-20T03:56:32.746886Z'}
{'type': 'l2update', 'product_id': 'BTC-USD', 'changes': [['buy', '38309.52', '0.00000000']], 'time': '2021-05-20T03:56:32.747901Z'}
{'type': 'l2update', 'product_id': 'BTC-USD', 'changes': [['buy', '38317.56', '0.52186104']], 'time': '2021-05-20T03:56:32.752029Z'}
{'type': 'l2update', 'product_id': 'BTC-USD', 'changes': [['buy', '38278.24', '0.12890961']], 'time': '2021-05-20T03:56:32.761324Z'}
{'type': 'l2update', 'product_id': 'BTC-USD', 'changes': [['sell', '38545.04', '0.00000000']], 'time': '2021-05-20T03:56:32.764362Z'}
{'type': 'l2update', 'product_id': 'BTC-USD', 'changes': [['sell', '38491.12', '0.03230604']], 'time': '2021-05-20T03:56:32.764721Z'}
{'type': 'l2update', 'product_id': 'BTC-USD', 'changes': [['buy', '38337.76', '0.10176491']], 'time': '2021-05-20T03:56:32.764760Z'}
{'type': 'l2update', 'product_id': 'BTC-USD', 'changes': [['buy', '38224.49', '0.00000000']], 'time': '2021-05-20T03:56:32.764852Z'}
{'type': 'l2update', 'product_id': 'BTC-USD', 'changes': [['sell', '38535.15', '0.00000000']], 'time': '2021-05-20T03:56:32.766096Z'}
{'type': 'l2update', 'product_id': 'BTC-USD', 'changes': [['buy', '38330.75', '0.00000000']], 'time': '2021-05-20T03:56:32.770383Z'}
{'type': 'l2update', 'product_id': 'BTC-USD', 'changes': [['sell', '38378.14', '0.00000000']], 'time': '2021-05-20T03:56:32.779155Z'}
{'type': 'l2update', 'product_id': 'BTC-USD', 'changes': [['sell', '38479.67', '0.00000000']], 'time': '2021-05-20T03:56:32.785300Z'}
{'type': 'l2update', 'product_id': 'BTC-USD', 'changes': [['buy', '38278.24', '0.00000000']], 'time': '2021-05-20T03:56:32.793378Z'}
{'type': 'l2update', 'product_id': 'BTC-USD', 'changes': [['buy', '38313.46', '0.00000000']], 'time': '2021-05-20T03:56:32.794628Z'}
{'type': 'l2update', 'product_id': 'BTC-USD', 'changes': [['sell', '38347.95', '0.00000000']], 'time': '2021-05-20T03:56:32.797473Z'}
{'type': 'l2update', 'product_id': 'BTC-USD', 'changes': [['sell', '38369.00', '0.00000000']], 'time': '2021-05-20T03:56:32.798665Z'}
{'type': 'l2update', 'product_id': 'BTC-USD', 'changes': [['buy', '38313.44', '0.00000000']], 'time': '2021-05-20T03:56:32.805947Z'}
{'type': 'l2update', 'product_id': 'BTC-USD', 'changes': [['sell', '38439.45', '0.00000000']], 'time': '2021-05-20T03:56:32.818605Z'}
{'type': 'l2update', 'product_id': 'BTC-USD', 'changes': [['sell', '38398.64', '0.05444395']], 'time': '2021-05-20T03:56:32.819215Z'}
{'type': 'l2update', 'product_id': 'BTC-USD', 'changes': [['sell', '38528.58', '0.01413758']], 'time': '2021-05-20T03:56:32.819349Z'}
{'type': 'l2update', 'product_id': 'BTC-USD', 'changes': [['sell', '38526.56', '0.01297806']], 'time': '2021-05-20T03:56:32.819571Z'}
{'type': 'l2update', 'product_id': 'BTC-USD', 'changes': [['buy', '38165.10', '0.04813599']], 'time': '2021-05-20T03:56:32.820806Z'}
{'type': 'l2update', 'product_id': 'BTC-USD', 'changes': [['sell', '38343.06', '0.67250758']], 'time': '2021-05-20T03:56:32.820882Z'}
{'type': 'l2update', 'product_id': 'BTC-USD', 'changes': [['buy', '38273.12', '0.02000000']], 'time': '2021-05-20T03:56:32.821212Z'}
{'type': 'l2update', 'product_id': 'BTC-USD', 'changes': [['sell', '38341.61', '0.52189699']], 'time': '2021-05-20T03:56:32.821300Z'}
{'type': 'l2update', 'product_id': 'BTC-USD', 'changes': [['buy', '38337.77', '0.10000000']], 'time': '2021-05-20T03:56:32.821714Z'}
{'type': 'l2update', 'product_id': 'BTC-USD', 'changes': [['sell', '38641.27', '3.23362444']], 'time': '2021-05-20T03:56:32.822301Z'}
{'type': 'l2update', 'product_id': 'BTC-USD', 'changes': [['sell', '38505.83', '0.00705115']], 'time': '2021-05-20T03:56:32.822353Z'}
{'type': 'l2update', 'product_id': 'BTC-USD', 'changes': [['sell', '38364.74', '0.05000000']], 'time': '2021-05-20T03:56:32.822889Z'}
{'type': 'l2update', 'product_id': 'BTC-USD', 'changes': [['sell', '38497.70', '0.01000000']], 'time': '2021-05-20T03:56:32.822950Z'}
{'type': 'l2update', 'product_id': 'BTC-USD', 'changes': [['sell', '38343.05', '0.50000000']], 'time': '2021-05-20T03:56:32.828084Z'}
{'type': 'l2update', 'product_id': 'BTC-USD', 'changes': [['sell', '38528.03', '0.02905980']], 'time': '2021-05-20T03:56:32.830780Z'}
{'type': 'l2update', 'product_id': 'BTC-USD', 'changes': [['buy', '38238.50', '0.01000000']], 'time': '2021-05-20T03:56:32.830850Z'}
{'type': 'l2update', 'product_id': 'BTC-USD', 'changes': [['sell', '38438.15', '0.06903776']], 'time': '2021-05-20T03:56:32.830930Z'}
{'type': 'l2update', 'product_id': 'BTC-USD', 'changes': [['buy', '38306.12', '0.05293330']], 'time': '2021-05-20T03:56:32.831071Z'}
{'type': 'l2update', 'product_id': 'BTC-USD', 'changes': [['sell', '38349.08', '0.05041485']], 'time': '2021-05-20T03:56:32.831071Z'}
{'type': 'l2update', 'product_id': 'BTC-USD', 'changes': [['sell', '38459.35', '0.00000000']], 'time': '2021-05-20T03:56:32.831290Z'}
{'type': 'l2update', 'product_id': 'BTC-USD', 'changes': [['sell', '38363.05', '0.00000000']], 'time': '2021-05-20T03:56:32.832225Z'}
{'type': 'l2update', 'product_id': 'BTC-USD', 'changes': [['sell', '38450.89', '0.42921168']], 'time': '2021-05-20T03:56:32.836064Z'}
{'type': 'l2update', 'product_id': 'BTC-USD', 'changes': [['sell', '38444.42', '0.33893695']], 'time': '2021-05-20T03:56:32.836064Z'}
{'type': 'l2update', 'product_id': 'BTC-USD', 'changes': [['buy', '38335.17', '0.00000000']], 'time': '2021-05-20T03:56:32.844521Z'}
{'type': 'l2update', 'product_id': 'BTC-USD', 'changes': [['buy', '38161.27', '0.00000000']], 'time': '2021-05-20T03:56:32.845169Z'}
{'type': 'l2update', 'product_id': 'BTC-USD', 'changes': [['sell', '38403.10', '0.00000000']], 'time': '2021-05-20T03:56:32.849223Z'}
{'type': 'l2update', 'product_id': 'BTC-USD', 'changes': [['sell', '38343.06', '0.00000000']], 'time': '2021-05-20T03:56:32.851966Z'}
{'type': 'l2update', 'product_id': 'BTC-USD', 'changes': [['buy', '38314.81', '0.52189699']], 'time': '2021-05-20T03:56:32.853458Z'}
{'type': 'l2update', 'product_id': 'BTC-USD', 'changes': [['sell', '38509.68', '0.29905645']], 'time': '2021-05-20T03:56:32.854060Z'}
{'type': 'l2update', 'product_id': 'BTC-USD', 'changes': [['sell', '38424.25', '0.01000000']], 'time': '2021-05-20T03:56:32.854079Z'}
{'type': 'l2update', 'product_id': 'BTC-USD', 'changes': [['sell', '38419.21', '0.14600000']], 'time': '2021-05-20T03:56:32.854231Z'}
{'type': 'l2update', 'product_id': 'BTC-USD', 'changes': [['buy', '38243.80', '0.04000000']], 'time': '2021-05-20T03:56:32.854433Z'}
{'type': 'l2update', 'product_id': 'BTC-USD', 'changes': [['buy', '38337.77', '0.30000000']], 'time': '2021-05-20T03:56:32.854598Z'}
{'type': 'l2update', 'product_id': 'BTC-USD', 'changes': [['buy', '38325.27', '0.00000000']], 'time': '2021-05-20T03:56:32.854911Z'}
{'type': 'l2update', 'product_id': 'BTC-USD', 'changes': [['sell', '38430.09', '0.00000000']], 'time': '2021-05-20T03:56:32.855588Z'}
{'type': 'l2update', 'product_id': 'BTC-USD', 'changes': [['sell', '38369.51', '0.00000000']], 'time': '2021-05-20T03:56:32.857375Z'}
{'type': 'l2update', 'product_id': 'BTC-USD', 'changes': [['sell', '38491.12', '0.00000000']], 'time': '2021-05-20T03:56:32.861322Z'}
{'type': 'l2update', 'product_id': 'BTC-USD', 'changes': [['sell', '38498.93', '0.34766838']], 'time': '2021-05-20T03:56:32.866817Z'}
{'type': 'l2update', 'product_id': 'BTC-USD', 'changes': [['buy', '38325.28', '0.50000000']], 'time': '2021-05-20T03:56:32.867869Z'}
{'type': 'l2update', 'product_id': 'BTC-USD', 'changes': [['sell', '38414.04', '0.19800000']], 'time': '2021-05-20T03:56:32.872166Z'}
{'type': 'l2update', 'product_id': 'BTC-USD', 'changes': [['sell', '38476.69', '0.01299488']], 'time': '2021-05-20T03:56:32.872198Z'}
{'type': 'l2update', 'product_id': 'BTC-USD', 'changes': [['sell', '38450.16', '0.00000000']], 'time': '2021-05-20T03:56:32.876081Z'}
{'type': 'l2update', 'product_id': 'BTC-USD', 'changes': [['buy', '38337.76', '0.10000000']], 'time': '2021-05-20T03:56:32.879239Z'}
{'type': 'l2update', 'product_id': 'BTC-USD', 'changes': [['sell', '38375.08', '0.01000000']], 'time': '2021-05-20T03:56:32.890740Z'}
{'type': 'l2update', 'product_id': 'BTC-USD', 'changes': [['sell', '38501.08', '0.00000000']], 'time': '2021-05-20T03:56:32.892858Z'}
{'type': 'l2update', 'product_id': 'BTC-USD', 'changes': [['sell', '38344.13', '0.52186368']], 'time': '2021-05-20T03:56:32.897664Z'}
{'type': 'l2update', 'product_id': 'BTC-USD', 'changes': [['buy', '38319.70', '0.52000000']], 'time': '2021-05-20T03:56:32.898455Z'}
{'type': 'l2update', 'product_id': 'BTC-USD', 'changes': [['sell', '38370.83', '0.48190000']], 'time': '2021-05-20T03:56:32.898467Z'}
{'type': 'l2update', 'product_id': 'BTC-USD', 'changes': [['sell', '38339.36', '0.02000000']], 'time': '2021-05-20T03:56:32.898484Z'}
{'type': 'l2update', 'product_id': 'BTC-USD', 'changes': [['sell', '38343.05', '0.00000000']], 'time': '2021-05-20T03:56:32.899976Z'}
{'type': 'l2update', 'product_id': 'BTC-USD', 'changes': [['sell', '38469.29', '0.01901000']], 'time': '2021-05-20T03:56:32.904363Z'}
{'type': 'l2update', 'product_id': 'BTC-USD', 'changes': [['buy', '38313.50', '0.59116555']], 'time': '2021-05-20T03:56:32.904595Z'}
{'type': 'l2update', 'product_id': 'BTC-USD', 'changes': [['sell', '38444.42', '0.36761825']], 'time': '2021-05-20T03:56:32.906185Z'}
{'type': 'l2update', 'product_id': 'BTC-USD', 'changes': [['buy', '38237.66', '0.02868130']], 'time': '2021-05-20T03:56:32.906185Z'}
{'type': 'l2update', 'product_id': 'BTC-USD', 'changes': [['sell', '38351.47', '0.00000000']], 'time': '2021-05-20T03:56:32.911829Z'}
{'type': 'l2update', 'product_id': 'BTC-USD', 'changes': [['sell', '38471.45', '0.75411583']], 'time': '2021-05-20T03:56:32.919986Z'}
{'type': 'l2update', 'product_id': 'BTC-USD', 'changes': [['buy', '38280.20', '0.00000000']], 'time': '2021-05-20T03:56:32.927306Z'}
{'type': 'l2update', 'product_id': 'BTC-USD', 'changes': [['buy', '38338.96', '0.20630840']], 'time': '2021-05-20T03:56:32.927376Z'}
{'type': 'l2update', 'product_id': 'BTC-USD', 'changes': [['buy', '38292.66', '0.01000000']], 'time': '2021-05-20T03:56:32.927600Z'}
{'type': 'l2update', 'product_id': 'BTC-USD', 'changes': [['buy', '38325.28', '0.00000000']], 'time': '2021-05-20T03:56:32.929280Z'}
{'type': 'l2update', 'product_id': 'BTC-USD', 'changes': [['sell', '38347.91', '0.59300000']], 'time': '2021-05-20T03:56:32.932087Z'}
{'type': 'l2update', 'product_id': 'BTC-USD', 'changes': [['buy', '38312.41', '0.52182233']], 'time': '2021-05-20T03:56:32.932192Z'}
{'type': 'l2update', 'product_id': 'BTC-USD', 'changes': [['buy', '38157.65', '0.00000000']], 'time': '2021-05-20T03:56:32.937995Z'}
{'type': 'l2update', 'product_id': 'BTC-USD', 'changes': [['buy', '38339.35', '0.01492000']], 'time': '2021-05-20T03:56:32.945072Z'}
{'type': 'l2update', 'product_id': 'BTC-USD', 'changes': [['buy', '38339.35', '0.04651764']], 'time': '2021-05-20T03:56:32.945629Z'}
{'type': 'l2update', 'product_id': 'BTC-USD', 'changes': [['buy', '38302.99', '0.41640000']], 'time': '2021-05-20T03:56:32.946101Z'}
{'type': 'l2update', 'product_id': 'BTC-USD', 'changes': [['buy', '38175.51', '0.05152079']], 'time': '2021-05-20T03:56:32.947079Z'}
{'type': 'l2update', 'product_id': 'BTC-USD', 'changes': [['buy', '38258.97', '0.00000000']], 'time': '2021-05-20T03:56:32.948722Z'}
{'type': 'l2update', 'product_id': 'BTC-USD', 'changes': [['buy', '38337.76', '0.10176491']], 'time': '2021-05-20T03:56:32.951984Z'}
{'type': 'l2update', 'product_id': 'BTC-USD', 'changes': [['sell', '38381.11', '0.03207306']], 'time': '2021-05-20T03:56:32.952954Z'}
{'type': 'l2update', 'product_id': 'BTC-USD', 'changes': [['buy', '38265.06', '0.00000000']], 'time': '2021-05-20T03:56:32.953870Z'}
{'type': 'l2update', 'product_id': 'BTC-USD', 'changes': [['buy', '38337.76', '0.00176491']], 'time': '2021-05-20T03:56:32.954489Z'}
{'type': 'l2update', 'product_id': 'BTC-USD', 'changes': [['sell', '38593.39', '0.00000000']], 'time': '2021-05-20T03:56:32.954532Z'}
{'type': 'l2update', 'product_id': 'BTC-USD', 'changes': [['sell', '38398.51', '0.04750688']], 'time': '2021-05-20T03:56:32.957322Z'}
{'type': 'l2update', 'product_id': 'BTC-USD', 'changes': [['sell', '38478.69', '0.79539321']], 'time': '2021-05-20T03:56:32.957415Z'}
{'type': 'l2update', 'product_id': 'BTC-USD', 'changes': [['sell', '38416.30', '0.07800000']], 'time': '2021-05-20T03:56:32.958673Z'}
{'type': 'l2update', 'product_id': 'BTC-USD', 'changes': [['sell', '38363.03', '2.48969908']], 'time': '2021-05-20T03:56:32.958913Z'}
{'type': 'l2update', 'product_id': 'BTC-USD', 'changes': [['sell', '38375.08', '0.00000000']], 'time': '2021-05-20T03:56:32.962258Z'}
{'type': 'l2update', 'product_id': 'BTC-USD', 'changes': [['sell', '38450.89', '0.46569742']], 'time': '2021-05-20T03:56:32.964128Z'}
{'type': 'l2update', 'product_id': 'BTC-USD', 'changes': [['buy', '38231.41', '0.03648574']], 'time': '2021-05-20T03:56:32.964128Z'}
{'type': 'l2update', 'product_id': 'BTC-USD', 'changes': [['sell', '38347.95', '0.50000000']], 'time': '2021-05-20T03:56:32.969847Z'}
{'type': 'l2update', 'product_id': 'BTC-USD', 'changes': [['buy', '38327.71', '0.52100000']], 'time': '2021-05-20T03:56:32.969870Z'}
{'type': 'l2update', 'product_id': 'BTC-USD', 'changes': [['sell', '38363.04', '0.10854250']], 'time': '2021-05-20T03:56:32.969929Z'}
{'type': 'l2update', 'product_id': 'BTC-USD', 'changes': [['sell', '38351.91', '0.78279274']], 'time': '2021-05-20T03:56:32.970010Z'}
{'type': 'l2update', 'product_id': 'BTC-USD', 'changes': [['buy', '38302.99', '0.00000000']], 'time': '2021-05-20T03:56:32.972980Z'}
{'type': 'l2update', 'product_id': 'BTC-USD', 'changes': [['buy', '38171.03', '0.02619787']], 'time': '2021-05-20T03:56:32.975216Z'}
{'type': 'l2update', 'product_id': 'BTC-USD', 'changes': [['sell', '38364.74', '0.00000000']], 'time': '2021-05-20T03:56:32.975736Z'}
{'type': 'l2update', 'product_id': 'BTC-USD', 'changes': [['buy', '38339.35', '0.07541764']], 'time': '2021-05-20T03:56:32.980764Z'}
{'type': 'l2update', 'product_id': 'BTC-USD', 'changes': [['sell', '38408.87', '0.07700000']], 'time': '2021-05-20T03:56:32.981690Z'}
{'type': 'l2update', 'product_id': 'BTC-USD', 'changes': [['buy', '38339.31', '0.15000000']], 'time': '2021-05-20T03:56:32.981762Z'}
{'type': 'l2update', 'product_id': 'BTC-USD', 'changes': [['sell', '38509.68', '0.00000000']], 'time': '2021-05-20T03:56:32.982025Z'}
{'type': 'l2update', 'product_id': 'BTC-USD', 'changes': [['sell', '38430.61', '0.00000000']], 'time': '2021-05-20T03:56:32.983269Z'}
{'type': 'l2update', 'product_id': 'BTC-USD', 'changes': [['buy', '38259.41', '0.00000000']], 'time': '2021-05-20T03:56:32.983431Z'}
{'type': 'l2update', 'product_id': 'BTC-USD', 'changes': [['sell', '38444.19', '0.03544931']], 'time': '2021-05-20T03:56:32.992672Z'}
{'type': 'l2update', 'product_id': 'BTC-USD', 'changes': [['buy', '38292.66', '0.00000000']], 'time': '2021-05-20T03:56:32.992898Z'}
{'type': 'l2update', 'product_id': 'BTC-USD', 'changes': [['sell', '38363.04', '0.05854250']], 'time': '2021-05-20T03:56:32.994489Z'}
{'type': 'l2update', 'product_id': 'BTC-USD', 'changes': [['sell', '38438.15', '0.47269226']], 'time': '2021-05-20T03:56:32.996984Z'}
{'type': 'l2update', 'product_id': 'BTC-USD', 'changes': [['sell', '38432.06', '0.13906735']], 'time': '2021-05-20T03:56:32.996984Z'}
{'type': 'l2update', 'product_id': 'BTC-USD', 'changes': [['sell', '38347.91', '0.00000000']], 'time': '2021-05-20T03:56:32.998397Z'}
{'type': 'l2update', 'product_id': 'BTC-USD', 'changes': [['buy', '38319.66', '0.05854250']], 'time': '2021-05-20T03:56:33.001319Z'}
{'type': 'l2update', 'product_id': 'BTC-USD', 'changes': [['sell', '38370.83', '0.00000000']], 'time': '2021-05-20T03:56:33.001420Z'}
{'type': 'l2update', 'product_id': 'BTC-USD', 'changes': [['buy', '38267.68', '0.00000000']], 'time': '2021-05-20T03:56:33.002828Z'}
{'type': 'l2update', 'product_id': 'BTC-USD', 'changes': [['sell', '38457.56', '0.03525793']], 'time': '2021-05-20T03:56:33.005962Z'}
{'type': 'l2update', 'product_id': 'BTC-USD', 'changes': [['buy', '38224.98', '0.03525793']], 'time': '2021-05-20T03:56:33.005962Z'}
{'type': 'l2update', 'product_id': 'BTC-USD', 'changes': [['buy', '38321.05', '0.50000000']], 'time': '2021-05-20T03:56:33.006531Z'}
{'type': 'l2update', 'product_id': 'BTC-USD', 'changes': [['buy', '38299.34', '0.78284548']], 'time': '2021-05-20T03:56:33.006757Z'}
{'type': 'l2update', 'product_id': 'BTC-USD', 'changes': [['buy', '38321.11', '0.84700000']], 'time': '2021-05-20T03:56:33.010253Z'}
{'type': 'l2update', 'product_id': 'BTC-USD', 'changes': [['sell', '38528.03', '0.00000000']], 'time': '2021-05-20T03:56:33.011181Z'}
{'type': 'l2update', 'product_id': 'BTC-USD', 'changes': [['sell', '38372.73', '0.00000000']], 'time': '2021-05-20T03:56:33.012197Z'}
{'type': 'l2update', 'product_id': 'BTC-USD', 'changes': [['sell', '38476.69', '0.00000000']], 'time': '2021-05-20T03:56:33.025339Z'}
{'type': 'l2update', 'product_id': 'BTC-USD', 'changes': [['sell', '38498.93', '0.00000000']], 'time': '2021-05-20T03:56:33.029270Z'}
{'type': 'l2update', 'product_id': 'BTC-USD', 'changes': [['buy', '38339.35', '0.08114764']], 'time': '2021-05-20T03:56:33.032779Z'}
{'type': 'l2update', 'product_id': 'BTC-USD', 'changes': [['sell', '38363.02', '0.05000000']], 'time': '2021-05-20T03:56:33.032842Z'}
{'type': 'l2update', 'product_id': 'BTC-USD', 'changes': [['buy', '38235.04', '0.01000000']], 'time': '2021-05-20T03:56:33.033926Z'}
{'type': 'l2update', 'product_id': 'BTC-USD', 'changes': [['buy', '38329.83', '0.52100000']], 'time': '2021-05-20T03:56:33.037146Z'}
{'type': 'l2update', 'product_id': 'BTC-USD', 'changes': [['sell', '38362.99', '0.59300000']], 'time': '2021-05-20T03:56:33.037171Z'}
{'type': 'l2update', 'product_id': 'BTC-USD', 'changes': [['buy', '38306.12', '0.00000000']], 'time': '2021-05-20T03:56:33.037786Z'}
{'type': 'l2update', 'product_id': 'BTC-USD', 'changes': [['sell', '38349.08', '0.00000000']], 'time': '2021-05-20T03:56:33.037786Z'}
{'type': 'l2update', 'product_id': 'BTC-USD', 'changes': [['sell', '38347.95', '0.00000000']], 'time': '2021-05-20T03:56:33.038054Z'}
{'type': 'l2update', 'product_id': 'BTC-USD', 'changes': [['buy', '38313.50', '0.00000000']], 'time': '2021-05-20T03:56:33.040211Z'}
{'type': 'l2update', 'product_id': 'BTC-USD', 'changes': [['buy', '38291.33', '0.02611557']], 'time': '2021-05-20T03:56:33.041644Z'}
{'type': 'l2update', 'product_id': 'BTC-USD', 'changes': [['buy', '38290.20', '0.09517153']], 'time': '2021-05-20T03:56:33.041657Z'}
{'type': 'l2update', 'product_id': 'BTC-USD', 'changes': [['buy', '38337.77', '0.20000000']], 'time': '2021-05-20T03:56:33.042957Z'}
{'type': 'l2update', 'product_id': 'BTC-USD', 'changes': [['buy', '38218.36', '0.03104989']], 'time': '2021-05-20T03:56:33.045269Z'}
{'type': 'l2update', 'product_id': 'BTC-USD', 'changes': [['sell', '38356.94', '1.30462336']], 'time': '2021-05-20T03:56:33.045433Z'}
{'type': 'l2update', 'product_id': 'BTC-USD', 'changes': [['sell', '38474.73', '0.00000000']], 'time': '2021-05-20T03:56:33.049294Z'}
{'type': 'l2update', 'product_id': 'BTC-USD', 'changes': [['sell', '38343.06', '0.01000000']], 'time': '2021-05-20T03:56:33.050086Z'}
{'type': 'l2update', 'product_id': 'BTC-USD', 'changes': [['sell', '38495.38', '0.01000000']], 'time': '2021-05-20T03:56:33.050526Z'}
{'type': 'l2update', 'product_id': 'BTC-USD', 'changes': [['sell', '38465.91', '0.00000000']], 'time': '2021-05-20T03:56:33.052984Z'}
{'type': 'l2update', 'product_id': 'BTC-USD', 'changes': [['sell', '38485.74', '0.01000000']], 'time': '2021-05-20T03:56:33.054149Z'}
{'type': 'l2update', 'product_id': 'BTC-USD', 'changes': [['sell', '38379.45', '0.01000000']], 'time': '2021-05-20T03:56:33.054464Z'}
{'type': 'l2update', 'product_id': 'BTC-USD', 'changes': [['sell', '38363.02', '0.00000000']], 'time': '2021-05-20T03:56:33.068495Z'}
{'type': 'l2update', 'product_id': 'BTC-USD', 'changes': [['buy', '38321.05', '0.00000000']], 'time': '2021-05-20T03:56:33.068650Z'}
{'type': 'l2update', 'product_id': 'BTC-USD', 'changes': [['sell', '38457.56', '0.45925272']], 'time': '2021-05-20T03:56:33.069954Z'}
{'type': 'l2update', 'product_id': 'BTC-USD', 'changes': [['buy', '38329.83', '0.00000000']], 'time': '2021-05-20T03:56:33.071292Z'}
{'type': 'l2update', 'product_id': 'BTC-USD', 'changes': [['buy', '38337.77', '0.00000000']], 'time': '2021-05-20T03:56:33.073243Z'}
{'type': 'l2update', 'product_id': 'BTC-USD', 'changes': [['buy', '38319.71', '0.05854250']], 'time': '2021-05-20T03:56:33.073866Z'}
{'type': 'l2update', 'product_id': 'BTC-USD', 'changes': [['buy', '38337.78', '0.00000000']], 'time': '2021-05-20T03:56:33.074342Z'}
{'type': 'l2update', 'product_id': 'BTC-USD', 'changes': [['buy', '38338.96', '0.20000000']], 'time': '2021-05-20T03:56:33.074342Z'}
{'type': 'l2update', 'product_id': 'BTC-USD', 'changes': [['sell', '38383.82', '0.09543604']], 'time': '2021-05-20T03:56:33.079990Z'}
{'type': 'l2update', 'product_id': 'BTC-USD', 'changes': [['buy', '38292.80', '1.30455672']], 'time': '2021-05-20T03:56:33.080204Z'}
{'type': 'l2update', 'product_id': 'BTC-USD', 'changes': [['buy', '38239.31', '0.00000000']], 'time': '2021-05-20T03:56:33.081622Z'}
{'type': 'l2update', 'product_id': 'BTC-USD', 'changes': [['sell', '38375.62', '0.10000000']], 'time': '2021-05-20T03:56:33.086650Z'}
{'type': 'l2update', 'product_id': 'BTC-USD', 'changes': [['sell', '38454.32', '0.01176682']], 'time': '2021-05-20T03:56:33.086822Z'}
{'type': 'l2update', 'product_id': 'BTC-USD', 'changes': [['sell', '38343.06', '0.04000000']], 'time': '2021-05-20T03:56:33.086836Z'}
{'type': 'l2update', 'product_id': 'BTC-USD', 'changes': [['buy', '38297.02', '0.01000000']], 'time': '2021-05-20T03:56:33.094074Z'}
{'type': 'l2update', 'product_id': 'BTC-USD', 'changes': [['buy', '38321.79', '0.49030000']], 'time': '2021-05-20T03:56:33.094685Z'}
{'type': 'l2update', 'product_id': 'BTC-USD', 'changes': [['buy', '38329.83', '0.84700000']], 'time': '2021-05-20T03:56:33.097690Z'}
{'type': 'l2update', 'product_id': 'BTC-USD', 'changes': [['sell', '38362.98', '0.05000000']], 'time': '2021-05-20T03:56:33.102129Z'}
{'type': 'l2update', 'product_id': 'BTC-USD', 'changes': [['sell', '38460.19', '0.01300045']], 'time': '2021-05-20T03:56:33.108866Z'}
{'type': 'l2update', 'product_id': 'BTC-USD', 'changes': [['sell', '38363.03', '2.98969908']], 'time': '2021-05-20T03:56:33.109474Z'}
{'type': 'l2update', 'product_id': 'BTC-USD', 'changes': [['sell', '38471.45', '1.15878584']], 'time': '2021-05-20T03:56:33.115047Z'}
{'type': 'l2update', 'product_id': 'BTC-USD', 'changes': [['sell', '38376.30', '2.60920996']], 'time': '2021-05-20T03:56:33.115548Z'}
{'type': 'l2update', 'product_id': 'BTC-USD', 'changes': [['sell', '38450.89', '0.49963282']], 'time': '2021-05-20T03:56:33.115578Z'}
{'type': 'l2update', 'product_id': 'BTC-USD', 'changes': [['buy', '38339.32', '0.05000000']], 'time': '2021-05-20T03:56:33.116498Z'}
{'type': 'l2update', 'product_id': 'BTC-USD', 'changes': [['sell', '38485.85', '0.00000000']], 'time': '2021-05-20T03:56:33.119133Z'}
{'type': 'l2update', 'product_id': 'BTC-USD', 'changes': [['buy', '38313.45', '0.00000000']], 'time': '2021-05-20T03:56:33.119427Z'}
{'type': 'l2update', 'product_id': 'BTC-USD', 'changes': [['sell', '38503.59', '0.01000000']], 'time': '2021-05-20T03:56:33.124118Z'}
{'type': 'l2update', 'product_id': 'BTC-USD', 'changes': [['sell', '38429.77', '0.00000000']], 'time': '2021-05-20T03:56:33.124369Z'}
{'type': 'l2update', 'product_id': 'BTC-USD', 'changes': [['buy', '38329.78', '0.00000000']], 'time': '2021-05-20T03:56:33.127497Z'}
{'type': 'l2update', 'product_id': 'BTC-USD', 'changes': [['sell', '38514.00', '0.29904466']], 'time': '2021-05-20T03:56:33.131075Z'}
{'type': 'l2update', 'product_id': 'BTC-USD', 'changes': [['sell', '38343.06', '0.08000000']], 'time': '2021-05-20T03:56:33.131126Z'}
{'type': 'l2update', 'product_id': 'BTC-USD', 'changes': [['sell', '38383.90', '0.50000000']], 'time': '2021-05-20T03:56:33.132181Z'}
{'type': 'l2update', 'product_id': 'BTC-USD', 'changes': [['sell', '38374.26', '0.49140000']], 'time': '2021-05-20T03:56:33.132209Z'}
{'type': 'l2update', 'product_id': 'BTC-USD', 'changes': [['buy', '38321.12', '0.59116555']], 'time': '2021-05-20T03:56:33.137463Z'}
{'type': 'l2update', 'product_id': 'BTC-USD', 'changes': [['buy', '38339.35', '0.17954764']], 'time': '2021-05-20T03:56:33.142759Z'}
{'type': 'l2update', 'product_id': 'BTC-USD', 'changes': [['buy', '38327.72', '0.50000000']], 'time': '2021-05-20T03:56:33.148249Z'}
{'type': 'l2update', 'product_id': 'BTC-USD', 'changes': [['buy', '38329.83', '0.00000000']], 'time': '2021-05-20T03:56:33.151280Z'}
{'type': 'l2update', 'product_id': 'BTC-USD', 'changes': [['sell', '38457.56', '0.84662942']], 'time': '2021-05-20T03:56:33.155194Z'}
{'type': 'l2update', 'product_id': 'BTC-USD', 'changes': [['sell', '38457.56', '0.88470436']], 'time': '2021-05-20T03:56:33.155215Z'}
{'type': 'l2update', 'product_id': 'BTC-USD', 'changes': [['sell', '38380.75', '0.10000000']], 'time': '2021-05-20T03:56:33.155266Z'}
{'type': 'l2update', 'product_id': 'BTC-USD', 'changes': [['buy', '38292.22', '2.60864703']], 'time': '2021-05-20T03:56:33.155605Z'}
{'type': 'l2update', 'product_id': 'BTC-USD', 'changes': [['buy', '38256.81', '0.01133744']], 'time': '2021-05-20T03:56:33.156919Z'}
{'type': 'l2update', 'product_id': 'BTC-USD', 'changes': [['sell', '38446.55', '0.01000000']], 'time': '2021-05-20T03:56:33.157034Z'}
{'type': 'l2update', 'product_id': 'BTC-USD', 'changes': [['buy', '38124.67', '0.00000000']], 'time': '2021-05-20T03:56:33.158117Z'}
{'type': 'l2update', 'product_id': 'BTC-USD', 'changes': [['sell', '38514.00', '0.00000000']], 'time': '2021-05-20T03:56:33.158214Z'}
{'type': 'l2update', 'product_id': 'BTC-USD', 'changes': [['buy', '38273.12', '0.00000000']], 'time': '2021-05-20T03:56:33.158306Z'}
{'type': 'l2update', 'product_id': 'BTC-USD', 'changes': [['buy', '38251.31', '0.00000000']], 'time': '2021-05-20T03:56:33.162403Z'}
{'type': 'l2update', 'product_id': 'BTC-USD', 'changes': [['buy', '38321.12', '2.58064515']], 'time': '2021-05-20T03:56:33.169235Z'}
{'type': 'l2update', 'product_id': 'BTC-USD', 'changes': [['buy', '38312.34', '0.05630363']], 'time': '2021-05-20T03:56:33.169508Z'}
{'type': 'l2update', 'product_id': 'BTC-USD', 'changes': [['sell', '38360.60', '0.06303449']], 'time': '2021-05-20T03:56:33.169508Z'}
{'type': 'l2update', 'product_id': 'BTC-USD', 'changes': [['buy', '38339.35', '0.23954764']], 'time': '2021-05-20T03:56:33.176819Z'}
{'type': 'l2update', 'product_id': 'BTC-USD', 'changes': [['sell', '38660.39', '0.00000000']], 'time': '2021-05-20T03:56:33.177846Z'}
{'type': 'l2update', 'product_id': 'BTC-USD', 'changes': [['sell', '38363.03', '2.48969908']], 'time': '2021-05-20T03:56:33.178293Z'}
{'type': 'l2update', 'product_id': 'BTC-USD', 'changes': [['buy', '38339.35', '0.43954764']], 'time': '2021-05-20T03:56:33.185973Z'}
{'type': 'l2update', 'product_id': 'BTC-USD', 'changes': [['sell', '38363.02', '0.05854250']], 'time': '2021-05-20T03:56:33.186227Z'}
{'type': 'l2update', 'product_id': 'BTC-USD', 'changes': [['sell', '38503.59', '0.00000000']], 'time': '2021-05-20T03:56:33.186407Z'}
{'type': 'l2update', 'product_id': 'BTC-USD', 'changes': [['sell', '38505.83', '0.00000000']], 'time': '2021-05-20T03:56:33.187953Z'}
{'type': 'l2update', 'product_id': 'BTC-USD', 'changes': [['buy', '38219.93', '0.03004673']], 'time': '2021-05-20T03:56:33.191555Z'}
{'type': 'l2update', 'product_id': 'BTC-USD', 'changes': [['buy', '38337.76', '0.00000000']], 'time': '2021-05-20T03:56:33.192074Z'}
{'type': 'l2update', 'product_id': 'BTC-USD', 'changes': [['sell', '38385.49', '2.60884370']], 'time': '2021-05-20T03:56:33.192373Z'}
{'type': 'l2update', 'product_id': 'BTC-USD', 'changes': [['sell', '38464.40', '0.69707579']], 'time': '2021-05-20T03:56:33.192443Z'}
{'type': 'l2update', 'product_id': 'BTC-USD', 'changes': [['sell', '38363.04', '0.00000000']], 'time': '2021-05-20T03:56:33.193618Z'}
{'type': 'l2update', 'product_id': 'BTC-USD', 'changes': [['buy', '38245.41', '0.01000000']], 'time': '2021-05-20T03:56:33.197169Z'}
{'type': 'l2update', 'product_id': 'BTC-USD', 'changes': [['buy', '38337.08', '0.00000000']], 'time': '2021-05-20T03:56:33.203635Z'}
{'type': 'l2update', 'product_id': 'BTC-USD', 'changes': [['buy', '38136.71', '0.45900000']], 'time': '2021-05-20T03:56:33.204038Z'}
{'type': 'l2update', 'product_id': 'BTC-USD', 'changes': [['buy', '38319.66', '0.00000000']], 'time': '2021-05-20T03:56:33.204213Z'}
{'type': 'l2update', 'product_id': 'BTC-USD', 'changes': [['buy', '38338.96', '0.00000000']], 'time': '2021-05-20T03:56:33.209392Z'}
{'type': 'l2update', 'product_id': 'BTC-USD', 'changes': [['sell', '38347.91', '0.59200000']], 'time': '2021-05-20T03:56:33.213066Z'}
{'type': 'l2update', 'product_id': 'BTC-USD', 'changes': [['sell', '38680.03', '0.12926569']], 'time': '2021-05-20T03:56:33.213493Z'}
{'type': 'l2update', 'product_id': 'BTC-USD', 'changes': [['buy', '38321.12', '1.98947960']], 'time': '2021-05-20T03:56:33.214543Z'}
{'type': 'l2update', 'product_id': 'BTC-USD', 'changes': [['sell', '43100.00', '1.09530000']], 'time': '2021-05-20T03:56:33.215533Z'}
{'type': 'l2update', 'product_id': 'BTC-USD', 'changes': [['buy', '38327.71', '0.00000000']], 'time': '2021-05-20T03:56:33.216169Z'}
{'type': 'l2update', 'product_id': 'BTC-USD', 'changes': [['sell', '38351.47', '0.50000000']], 'time': '2021-05-20T03:56:33.221396Z'}
{'type': 'l2update', 'product_id': 'BTC-USD', 'changes': [['sell', '38459.63', '0.01000000']], 'time': '2021-05-20T03:56:33.221512Z'}
{'type': 'l2update', 'product_id': 'BTC-USD', 'changes': [['sell', '39431.86', '0.00000000']], 'time': '2021-05-20T03:56:33.222139Z'}
{'type': 'l2update', 'product_id': 'BTC-USD', 'changes': [['buy', '38274.16', '2.60911162']], 'time': '2021-05-20T03:56:33.225759Z'}
{'type': 'l2update', 'product_id': 'BTC-USD', 'changes': [['sell', '38422.03', '0.02828068']], 'time': '2021-05-20T03:56:33.225907Z'}
{'type': 'l2update', 'product_id': 'BTC-USD', 'changes': [['sell', '38379.27', '0.01224277']], 'time': '2021-05-20T03:56:33.225907Z'}
{'type': 'l2update', 'product_id': 'BTC-USD', 'changes': [['buy', '38339.35', '0.48954764']], 'time': '2021-05-20T03:56:33.226603Z'}
{'type': 'l2update', 'product_id': 'BTC-USD', 'changes': [['sell', '38469.29', '0.02901000']], 'time': '2021-05-20T03:56:33.226630Z'}
{'type': 'l2update', 'product_id': 'BTC-USD', 'changes': [['sell', '38387.24', '0.00000000']], 'time': '2021-05-20T03:56:33.229168Z'}
{'type': 'l2update', 'product_id': 'BTC-USD', 'changes': [['sell', '38471.45', '1.53110357']], 'time': '2021-05-20T03:56:33.230889Z'}
{'type': 'l2update', 'product_id': 'BTC-USD', 'changes': [['sell', '39499.99', '0.16960000']], 'time': '2021-05-20T03:56:33.231431Z'}
{'type': 'l2update', 'product_id': 'BTC-USD', 'changes': [['buy', '38245.30', '0.03000000']], 'time': '2021-05-20T03:56:33.234262Z'}
{'type': 'l2update', 'product_id': 'BTC-USD', 'changes': [['sell', '38497.70', '0.00000000']], 'time': '2021-05-20T03:56:33.236969Z'}
{'type': 'l2update', 'product_id': 'BTC-USD', 'changes': [['sell', '38691.17', '3.22896658']], 'time': '2021-05-20T03:56:33.238582Z'}
{'type': 'l2update', 'product_id': 'BTC-USD', 'changes': [['sell', '38347.96', '0.00000000']], 'time': '2021-05-20T03:56:33.246721Z'}
{'type': 'l2update', 'product_id': 'BTC-USD', 'changes': [['buy', '38338.96', '0.00176491']], 'time': '2021-05-20T03:56:33.251722Z'}
{'type': 'l2update', 'product_id': 'BTC-USD', 'changes': [['sell', '43100.00', '1.99660000']], 'time': '2021-05-20T03:56:33.252523Z'}
{'type': 'l2update', 'product_id': 'BTC-USD', 'changes': [['sell', '38450.89', '0.47135214']], 'time': '2021-05-20T03:56:33.253165Z'}
{'type': 'l2update', 'product_id': 'BTC-USD', 'changes': [['sell', '38428.93', '0.00000000']], 'time': '2021-05-20T03:56:33.253165Z'}
{'type': 'l2update', 'product_id': 'BTC-USD', 'changes': [['sell', '38363.79', '0.00000000']], 'time': '2021-05-20T03:56:33.254492Z'}
{'type': 'l2update', 'product_id': 'BTC-USD', 'changes': [['sell', '38424.25', '0.00000000']], 'time': '2021-05-20T03:56:33.258431Z'}
{'type': 'l2update', 'product_id': 'BTC-USD', 'changes': [['sell', '38351.47', '0.00000000']], 'time': '2021-05-20T03:56:33.258547Z'}
{'type': 'l2update', 'product_id': 'BTC-USD', 'changes': [['buy', '38217.01', '0.00000000']], 'time': '2021-05-20T03:56:33.264725Z'}
{'type': 'l2update', 'product_id': 'BTC-USD', 'changes': [['buy', '38339.32', '0.00000000']], 'time': '2021-05-20T03:56:33.270255Z'}
{'type': 'l2update', 'product_id': 'BTC-USD', 'changes': [['buy', '38130.01', '0.00000000']], 'time': '2021-05-20T03:56:33.271330Z'}
{'type': 'l2update', 'product_id': 'BTC-USD', 'changes': [['sell', '38406.06', '0.15110045']], 'time': '2021-05-20T03:56:33.271411Z'}
{'type': 'l2update', 'product_id': 'BTC-USD', 'changes': [['buy', '38245.30', '0.08000000']], 'time': '2021-05-20T03:56:33.275067Z'}
{'type': 'l2update', 'product_id': 'BTC-USD', 'changes': [['buy', '38321.80', '0.59116555']], 'time': '2021-05-20T03:56:33.275247Z'}
{'type': 'l2update', 'product_id': 'BTC-USD', 'changes': [['sell', '38360.60', '0.00000000']], 'time': '2021-05-20T03:56:33.279398Z'}
{'type': 'l2update', 'product_id': 'BTC-USD', 'changes': [['buy', '38312.41', '0.00000000']], 'time': '2021-05-20T03:56:33.285435Z'}
{'type': 'l2update', 'product_id': 'BTC-USD', 'changes': [['buy', '38339.32', '0.10000000']], 'time': '2021-05-20T03:56:33.296582Z'}
{'type': 'l2update', 'product_id': 'BTC-USD', 'changes': [['buy', '38286.98', '0.03610677']], 'time': '2021-05-20T03:56:33.296605Z'}
{'type': 'l2update', 'product_id': 'BTC-USD', 'changes': [['sell', '38347.95', '0.50000000']], 'time': '2021-05-20T03:56:33.300232Z'}
{'type': 'l2update', 'product_id': 'BTC-USD', 'changes': [['sell', '38464.40', '0.31932466']], 'time': '2021-05-20T03:56:33.301279Z'}
{'type': 'l2update', 'product_id': 'BTC-USD', 'changes': [['buy', '38248.79', '0.00000000']], 'time': '2021-05-20T03:56:33.303917Z'}
{'type': 'l2update', 'product_id': 'BTC-USD', 'changes': [['sell', '38345.35', '0.05000000']], 'time': '2021-05-20T03:56:33.313745Z'}
{'type': 'l2update', 'product_id': 'BTC-USD', 'changes': [['buy', '38229.39', '0.01000000']], 'time': '2021-05-20T03:56:33.314085Z'}
{'type': 'l2update', 'product_id': 'BTC-USD', 'changes': [['buy', '38035.81', '0.95090666']], 'time': '2021-05-20T03:56:33.314304Z'}
{'type': 'l2update', 'product_id': 'BTC-USD', 'changes': [['sell', '38480.11', '0.01000000']], 'time': '2021-05-20T03:56:33.315565Z'}
{'type': 'l2update', 'product_id': 'BTC-USD', 'changes': [['sell', '38469.29', '0.01000000']], 'time': '2021-05-20T03:56:33.316510Z'}
{'type': 'l2update', 'product_id': 'BTC-USD', 'changes': [['sell', '38443.04', '0.00000000']], 'time': '2021-05-20T03:56:33.317720Z'}
{'type': 'l2update', 'product_id': 'BTC-USD', 'changes': [['buy', '38319.71', '0.00000000']], 'time': '2021-05-20T03:56:33.324055Z'}
{'type': 'l2update', 'product_id': 'BTC-USD', 'changes': [['buy', '38266.05', '0.00000000']], 'time': '2021-05-20T03:56:33.325408Z'}
{'type': 'l2update', 'product_id': 'BTC-USD', 'changes': [['sell', '38383.83', '0.00000000']], 'time': '2021-05-20T03:56:33.330817Z'}
{'type': 'l2update', 'product_id': 'BTC-USD', 'changes': [['sell', '38408.66', '0.01000000']], 'time': '2021-05-20T03:56:33.332082Z'}
{'type': 'l2update', 'product_id': 'BTC-USD', 'changes': [['sell', '38341.61', '0.00000000']], 'time': '2021-05-20T03:56:33.333218Z'}
{'type': 'l2update', 'product_id': 'BTC-USD', 'changes': [['buy', '38319.65', '0.21700000']], 'time': '2021-05-20T03:56:33.340269Z'}
{'type': 'l2update', 'product_id': 'BTC-USD', 'changes': [['buy', '38318.85', '0.02400000']], 'time': '2021-05-20T03:56:33.340269Z'}
{'type': 'l2update', 'product_id': 'BTC-USD', 'changes': [['buy', '38318.04', '0.02400000']], 'time': '2021-05-20T03:56:33.340269Z'}
{'type': 'l2update', 'product_id': 'BTC-USD', 'changes': [['buy', '38204.27', '0.71276307']], 'time': '2021-05-20T03:56:33.340554Z'}
{'type': 'l2update', 'product_id': 'BTC-USD', 'changes': [['buy', '38321.85', '0.52100000']], 'time': '2021-05-20T03:56:33.344604Z'}
{'type': 'l2update', 'product_id': 'BTC-USD', 'changes': [['sell', '38347.95', '0.00000000']], 'time': '2021-05-20T03:56:33.347514Z'}
{'type': 'l2update', 'product_id': 'BTC-USD', 'changes': [['buy', '38246.10', '0.02000000']], 'time': '2021-05-20T03:56:33.350930Z'}
{'type': 'l2update', 'product_id': 'BTC-USD', 'changes': [['buy', '38336.27', '0.21900000']], 'time': '2021-05-20T03:56:33.351385Z'}
{'type': 'l2update', 'product_id': 'BTC-USD', 'changes': [['sell', '38415.76', '0.01000000']], 'time': '2021-05-20T03:56:33.358832Z'}
{'type': 'l2update', 'product_id': 'BTC-USD', 'changes': [['sell', '38459.63', '0.00000000']], 'time': '2021-05-20T03:56:33.360543Z'}
{'type': 'l2update', 'product_id': 'BTC-USD', 'changes': [['buy', '38314.81', '0.00000000']], 'time': '2021-05-20T03:56:33.361660Z'}
{'type': 'l2update', 'product_id': 'BTC-USD', 'changes': [['sell', '38425.84', '0.00000000']], 'time': '2021-05-20T03:56:33.368651Z'}
{'type': 'l2update', 'product_id': 'BTC-USD', 'changes': [['sell', '38410.80', '0.03361448']], 'time': '2021-05-20T03:56:33.369489Z'}
{'type': 'l2update', 'product_id': 'BTC-USD', 'changes': [['sell', '38395.98', '0.03673172']], 'time': '2021-05-20T03:56:33.369489Z'}
{'type': 'l2update', 'product_id': 'BTC-USD', 'changes': [['sell', '38454.32', '0.00000000']], 'time': '2021-05-20T03:56:33.370382Z'}
{'type': 'l2update', 'product_id': 'BTC-USD', 'changes': [['buy', '38245.41', '0.00000000']], 'time': '2021-05-20T03:56:33.378771Z'}
{'type': 'l2update', 'product_id': 'BTC-USD', 'changes': [['sell', '38387.05', '0.40093100']], 'time': '2021-05-20T03:56:33.379796Z'}
{'type': 'l2update', 'product_id': 'BTC-USD', 'changes': [['buy', '38318.04', '0.00000000']], 'time': '2021-05-20T03:56:33.383935Z'}
{'type': 'l2update', 'product_id': 'BTC-USD', 'changes': [['buy', '38299.34', '0.00000000']], 'time': '2021-05-20T03:56:33.386825Z'}
{'type': 'l2update', 'product_id': 'BTC-USD', 'changes': [['sell', '38347.90', '0.50000000']], 'time': '2021-05-20T03:56:33.389515Z'}
{'type': 'l2update', 'product_id': 'BTC-USD', 'changes': [['buy', '38175.51', '0.00000000']], 'time': '2021-05-20T03:56:33.393562Z'}
{'type': 'l2update', 'product_id': 'BTC-USD', 'changes': [['sell', '38444.43', '0.00000000']], 'time': '2021-05-20T03:56:33.393605Z'}
{'type': 'l2update', 'product_id': 'BTC-USD', 'changes': [['sell', '38438.15', '0.43596054']], 'time': '2021-05-20T03:56:33.393605Z'}
{'type': 'l2update', 'product_id': 'BTC-USD', 'changes': [['buy', '38263.27', '2.00150000']], 'time': '2021-05-20T03:56:33.395439Z'}
{'type': 'l2update', 'product_id': 'BTC-USD', 'changes': [['buy', '38321.80', '0.00000000']], 'time': '2021-05-20T03:56:33.398925Z'}
{'type': 'l2update', 'product_id': 'BTC-USD', 'changes': [['buy', '38246.10', '0.00000000']], 'time': '2021-05-20T03:56:33.402594Z'}
