{'type': 'l2update', 'product_id': 'BTC-USD', 'changes': [['sell', '38387.17', '0.06174417']], 'time': '2021-05-20T03:54:48.702500Z'}
{'type': 'l2update', 'product_id': 'BTC-USD', 'changes': [['buy', '38217.08', '0.04604781']], 'time': '2021-05-20T03:54:48.702500Z'}
{'type': 'l2update', 'product_id': 'BTC-USD', 'changes': [['sell', '38274.57', '0.36249352']], 'time': '2021-05-20T03:54:48.702625Z'}
{'type': 'l2update', 'product_id': 'BTC-USD', 'changes': [['sell', '38402.84', '0.13019871']], 'time': '2021-05-20T03:54:48.702816Z'}
{'type': 'l2update', 'product_id': 'BTC-USD', 'changes': [['sell', '38289.46', '1.30723775']], 'time': '2021-05-20T03:54:48.702971Z'}
{'type': 'l2update', 'product_id': 'BTC-USD', 'changes': [['buy', '38167.55', '0.00000000']], 'time': '2021-05-20T03:54:48.708213Z'}
{'type': 'l2update', 'product_id': 'BTC-USD', 'changes': [['sell', '38277.40', '1.08700000']], 'time': '2021-05-20T03:54:48.708428Z'}
{'type': 'l2update', 'product_id': 'BTC-USD', 'changes': [['sell', '38327.36', '0.30812792']], 'time': '2021-05-20T03:54:48.708636Z'}
{'type': 'l2update', 'product_id': 'BTC-USD', 'changes': [['sell', '38317.69', '0.75620467']], 'time': '2021-05-20T03:54:48.708636Z'}
{'type': 'l2update', 'product_id': 'BTC-USD', 'changes': [['sell', '38313.14', '0.37050181']], 'time': '2021-05-20T03:54:48.708636Z'}
{'type': 'l2update', 'product_id': 'BTC-USD', 'changes': [['sell', '38538.46', '0.00000000']], 'time': '2021-05-20T03:54:48.709778Z'}
{'type': 'l2update', 'product_id': 'BTC-USD', 'changes': [['sell', '38282.34', '0.00000000']], 'time': '2021-05-20T03:54:48.710736Z'}
{'type': 'l2update', 'product_id': 'BTC-USD', 'changes': [['buy', '38224.26', '1.30715026']], 'time': '2021-05-20T03:54:48.713719Z'}
{'type': 'l2update', 'product_id': 'BTC-USD', 'changes': [['sell', '49361.56', '0.00544700']], 'time': '2021-05-20T03:54:48.717619Z'}
{'type': 'l2update', 'product_id': 'BTC-USD', 'changes': [['sell', '38282.38', '0.00000000']], 'time': '2021-05-20T03:54:48.718097Z'}
{'type': 'l2update', 'product_id': 'BTC-USD', 'changes': [['buy', '38155.18', '0.01000000']], 'time': '2021-05-20T03:54:48.718419Z'}
{'type': 'l2update', 'product_id': 'BTC-USD', 'changes': [['sell', '38283.94', '0.00000000']], 'time': '2021-05-20T03:54:48.723533Z'}
{'type': 'l2update', 'product_id': 'BTC-USD', 'changes': [['sell', '38313.14', '0.66337657']], 'time': '2021-05-20T03:54:48.724915Z'}
{'type': 'l2update', 'product_id': 'BTC-USD', 'changes': [['sell', '38523.47', '0.01297910']], 'time': '2021-05-20T03:54:48.725967Z'}
{'type': 'l2update', 'product_id': 'BTC-USD', 'changes': [['buy', '38208.57', '0.02996595']], 'time': '2021-05-20T03:54:48.726145Z'}
{'type': 'l2update', 'product_id': 'BTC-USD', 'changes': [['sell', '38296.24', '2.61450909']], 'time': '2021-05-20T03:54:48.726269Z'}
{'type': 'l2update', 'product_id': 'BTC-USD', 'changes': [['sell', '38285.09', '0.00000000']], 'time': '2021-05-20T03:54:48.727119Z'}
{'type': 'l2update', 'product_id': 'BTC-USD', 'changes': [['sell', '38272.05', '0.00000000']], 'time': '2021-05-20T03:54:48.728475Z'}
{'type': 'l2update', 'product_id': 'BTC-USD', 'changes': [['sell', '38401.42', '0.34367376']], 'time': '2021-05-20T03:54:48.730437Z'}
{'type': 'l2update', 'product_id': 'BTC-USD', 'changes': [['sell', '38401.42', '0.00000000']], 'time': '2021-05-20T03:54:48.730437Z'}
{'type': 'l2update', 'product_id': 'BTC-USD', 'changes': [['sell', '38394.20', '0.00000000']], 'time': '2021-05-20T03:54:48.730437Z'}
{'type': 'l2update', 'product_id': 'BTC-USD', 'changes': [['sell', '38285.42', '0.00000000']], 'time': '2021-05-20T03:54:48.733245Z'}
{'type': 'l2update', 'product_id': 'BTC-USD', 'changes': [['sell', '38306.00', '2.61434071']], 'time': '2021-05-20T03:54:48.742033Z'}
{'type': 'l2update', 'product_id': 'BTC-USD', 'changes': [['sell', '38360.95', '0.40127381']], 'time': '2021-05-20T03:54:48.743268Z'}
{'type': 'l2update', 'product_id': 'BTC-USD', 'changes': [['buy', '38199.30', '0.03041148']], 'time': '2021-05-20T03:54:48.747767Z'}
{'type': 'l2update', 'product_id': 'BTC-USD', 'changes': [['sell', '38289.62', '0.01000000']], 'time': '2021-05-20T03:54:48.747780Z'}
{'type': 'l2update', 'product_id': 'BTC-USD', 'changes': [['sell', '38266.65', '0.50000000']], 'time': '2021-05-20T03:54:48.747825Z'}
{'type': 'l2update', 'product_id': 'BTC-USD', 'changes': [['sell', '38306.16', '2.61381188']], 'time': '2021-05-20T03:54:48.755947Z'}
{'type': 'l2update', 'product_id': 'BTC-USD', 'changes': [['sell', '38367.22', '0.38124158']], 'time': '2021-05-20T03:54:48.756146Z'}
{'type': 'l2update', 'product_id': 'BTC-USD', 'changes': [['buy', '38231.77', '0.43710000']], 'time': '2021-05-20T03:54:48.758978Z'}
{'type': 'l2update', 'product_id': 'BTC-USD', 'changes': [['buy', '38220.83', '0.00000000']], 'time': '2021-05-20T03:54:48.758997Z'}
{'type': 'l2update', 'product_id': 'BTC-USD', 'changes': [['buy', '38220.03', '0.00000000']], 'time': '2021-05-20T03:54:48.758997Z'}
{'type': 'l2update', 'product_id': 'BTC-USD', 'changes': [['sell', '38291.15', '0.02000000']], 'time': '2021-05-20T03:54:48.759038Z'}
{'type': 'l2update', 'product_id': 'BTC-USD', 'changes': [['sell', '38266.66', '0.00000000']], 'time': '2021-05-20T03:54:48.764431Z'}
{'type': 'l2update', 'product_id': 'BTC-USD', 'changes': [['buy', '38221.64', '0.00000000']], 'time': '2021-05-20T03:54:48.766157Z'}
{'type': 'l2update', 'product_id': 'BTC-USD', 'changes': [['buy', '38227.34', '0.00000000']], 'time': '2021-05-20T03:54:48.767925Z'}
{'type': 'l2update', 'product_id': 'BTC-USD', 'changes': [['sell', '38303.96', '0.40210000']], 'time': '2021-05-20T03:54:48.771705Z'}
{'type': 'l2update', 'product_id': 'BTC-USD', 'changes': [['sell', '38292.13', '0.03000000']], 'time': '2021-05-20T03:54:48.771894Z'}
{'type': 'l2update', 'product_id': 'BTC-USD', 'changes': [['sell', '38306.16', '0.00000000']], 'time': '2021-05-20T03:54:48.772194Z'}
{'type': 'l2update', 'product_id': 'BTC-USD', 'changes': [['buy', '38194.38', '0.03553200']], 'time': '2021-05-20T03:54:48.776862Z'}
{'type': 'l2update', 'product_id': 'BTC-USD', 'changes': [['sell', '38266.65', '0.00000000']], 'time': '2021-05-20T03:54:48.777639Z'}
{'type': 'l2update', 'product_id': 'BTC-USD', 'changes': [['sell', '38402.84', '0.00000000']], 'time': '2021-05-20T03:54:48.779267Z'}
{'type': 'l2update', 'product_id': 'BTC-USD', 'changes': [['sell', '38348.98', '0.37887152']], 'time': '2021-05-20T03:54:48.780929Z'}
{'type': 'l2update', 'product_id': 'BTC-USD', 'changes': [['sell', '38332.48', '0.40559911']], 'time': '2021-05-20T03:54:48.780929Z'}
{'type': 'l2update', 'product_id': 'BTC-USD', 'changes': [['buy', '38228.20', '0.02400000']], 'time': '2021-05-20T03:54:48.781054Z'}
{'type': 'l2update', 'product_id': 'BTC-USD', 'changes': [['buy', '38227.39', '0.02400000']], 'time': '2021-05-20T03:54:48.781054Z'}
{'type': 'l2update', 'product_id': 'BTC-USD', 'changes': [['buy', '38226.58', '0.02400000']], 'time': '2021-05-20T03:54:48.781054Z'}
{'type': 'l2update', 'product_id': 'BTC-USD', 'changes': [['sell', '38292.77', '0.04000000']], 'time': '2021-05-20T03:54:48.782648Z'}
{'type': 'l2update', 'product_id': 'BTC-USD', 'changes': [['buy', '38231.77', '0.00000000']], 'time': '2021-05-20T03:54:48.786509Z'}
{'type': 'l2update', 'product_id': 'BTC-USD', 'changes': [['buy', '38228.20', '0.00000000']], 'time': '2021-05-20T03:54:48.787604Z'}
{'type': 'l2update', 'product_id': 'BTC-USD', 'changes': [['buy', '38227.39', '0.00000000']], 'time': '2021-05-20T03:54:48.787604Z'}
{'type': 'l2update', 'product_id': 'BTC-USD', 'changes': [['buy', '38226.58', '0.00000000']], 'time': '2021-05-20T03:54:48.787604Z'}
{'type': 'l2update', 'product_id': 'BTC-USD', 'changes': [['sell', '38360.95', '0.02653759']], 'time': '2021-05-20T03:54:48.788321Z'}
{'type': 'l2update', 'product_id': 'BTC-USD', 'changes': [['sell', '38389.83', '0.13024283']], 'time': '2021-05-20T03:54:48.790065Z'}
{'type': 'l2update', 'product_id': 'BTC-USD', 'changes': [['buy', '30888.00', '2.91874110']], 'time': '2021-05-20T03:54:48.790097Z'}
{'type': 'l2update', 'product_id': 'BTC-USD', 'changes': [['sell', '38270.23', '0.50000000']], 'time': '2021-05-20T03:54:48.794938Z'}
{'type': 'l2update', 'product_id': 'BTC-USD', 'changes': [['sell', '38293.72', '0.05000000']], 'time': '2021-05-20T03:54:48.795146Z'}
{'type': 'l2update', 'product_id': 'BTC-USD', 'changes': [['sell', '38269.81', '0.07460000']], 'time': '2021-05-20T03:54:48.798233Z'}
{'type': 'l2update', 'product_id': 'BTC-USD', 'changes': [['sell', '38367.22', '0.69010299']], 'time': '2021-05-20T03:54:48.803170Z'}
{'type': 'l2update', 'product_id': 'BTC-USD', 'changes': [['buy', '38250.85', '0.52100000']], 'time': '2021-05-20T03:54:48.806986Z'}
{'type': 'l2update', 'product_id': 'BTC-USD', 'changes': [['sell', '38347.54', '0.00000000']], 'time': '2021-05-20T03:54:48.808675Z'}
{'type': 'l2update', 'product_id': 'BTC-USD', 'changes': [['sell', '38269.35', '0.01492000']], 'time': '2021-05-20T03:54:48.814385Z'}
{'type': 'l2update', 'product_id': 'BTC-USD', 'changes': [['buy', '38250.80', '0.00000000']], 'time': '2021-05-20T03:54:48.818011Z'}
{'type': 'l2update', 'product_id': 'BTC-USD', 'changes': [['buy', '38203.57', '0.00000000']], 'time': '2021-05-20T03:54:48.820086Z'}
{'type': 'l2update', 'product_id': 'BTC-USD', 'changes': [['sell', '38269.81', '0.00000000']], 'time': '2021-05-20T03:54:48.829746Z'}
{'type': 'l2update', 'product_id': 'BTC-USD', 'changes': [['sell', '38360.95', '0.33236930']], 'time': '2021-05-20T03:54:48.829832Z'}
{'type': 'l2update', 'product_id': 'BTC-USD', 'changes': [['sell', '38260.84', '0.00448213']], 'time': '2021-05-20T03:54:48.833634Z'}
{'type': 'l2update', 'product_id': 'BTC-USD', 'changes': [['buy', '38212.56', '0.10000000']], 'time': '2021-05-20T03:54:48.833676Z'}
{'type': 'l2update', 'product_id': 'BTC-USD', 'changes': [['sell', '38303.96', '0.00000000']], 'time': '2021-05-20T03:54:48.834475Z'}
{'type': 'l2update', 'product_id': 'BTC-USD', 'changes': [['buy', '38250.86', '0.22867204']], 'time': '2021-05-20T03:54:48.837227Z'}
{'type': 'l2update', 'product_id': 'BTC-USD', 'changes': [['sell', '38277.45', '0.00000000']], 'time': '2021-05-20T03:54:48.839532Z'}
{'type': 'l2update', 'product_id': 'BTC-USD', 'changes': [['sell', '38429.45', '0.01301085']], 'time': '2021-05-20T03:54:48.845490Z'}
{'type': 'l2update', 'product_id': 'BTC-USD', 'changes': [['sell', '38268.67', '0.07460000']], 'time': '2021-05-20T03:54:48.845516Z'}
{'type': 'l2update', 'product_id': 'BTC-USD', 'changes': [['buy', '38236.10', '0.02400000']], 'time': '2021-05-20T03:54:48.845623Z'}
{'type': 'l2update', 'product_id': 'BTC-USD', 'changes': [['buy', '38235.29', '0.02400000']], 'time': '2021-05-20T03:54:48.845623Z'}
{'type': 'l2update', 'product_id': 'BTC-USD', 'changes': [['buy', '38234.49', '0.02400000']], 'time': '2021-05-20T03:54:48.845623Z'}
{'type': 'l2update', 'product_id': 'BTC-USD', 'changes': [['buy', '38235.29', '0.00000000']], 'time': '2021-05-20T03:54:48.855319Z'}
{'type': 'l2update', 'product_id': 'BTC-USD', 'changes': [['buy', '38234.49', '0.00000000']], 'time': '2021-05-20T03:54:48.855319Z'}
{'type': 'l2update', 'product_id': 'BTC-USD', 'changes': [['sell', '38373.68', '0.45451169']], 'time': '2021-05-20T03:54:48.857192Z'}
{'type': 'l2update', 'product_id': 'BTC-USD', 'changes': [['sell', '38269.34', '2.48969908']], 'time': '2021-05-20T03:54:48.857603Z'}
{'type': 'l2update', 'product_id': 'BTC-USD', 'changes': [['sell', '38269.35', '0.00000000']], 'time': '2021-05-20T03:54:48.863904Z'}
{'type': 'l2update', 'product_id': 'BTC-USD', 'changes': [['sell', '38274.57', '0.00000000']], 'time': '2021-05-20T03:54:48.864956Z'}
{'type': 'l2update', 'product_id': 'BTC-USD', 'changes': [['buy', '38238.06', '0.02400000']], 'time': '2021-05-20T03:54:48.870331Z'}
{'type': 'l2update', 'product_id': 'BTC-USD', 'changes': [['buy', '38237.25', '0.02400000']], 'time': '2021-05-20T03:54:48.870331Z'}
{'type': 'l2update', 'product_id': 'BTC-USD', 'changes': [['buy', '38235.96', '0.39490431']], 'time': '2021-05-20T03:54:48.873769Z'}
{'type': 'l2update', 'product_id': 'BTC-USD', 'changes': [['sell', '38269.34', '0.00000000']], 'time': '2021-05-20T03:54:48.874029Z'}
{'type': 'l2update', 'product_id': 'BTC-USD', 'changes': [['buy', '38238.06', '0.00000000']], 'time': '2021-05-20T03:54:48.876831Z'}
{'type': 'l2update', 'product_id': 'BTC-USD', 'changes': [['buy', '38237.25', '0.00000000']], 'time': '2021-05-20T03:54:48.876831Z'}
{'type': 'l2update', 'product_id': 'BTC-USD', 'changes': [['buy', '38236.10', '0.00000000']], 'time': '2021-05-20T03:54:48.876831Z'}
{'type': 'l2update', 'product_id': 'BTC-USD', 'changes': [['buy', '38234.45', '0.49610000']], 'time': '2021-05-20T03:54:48.878447Z'}
{'type': 'l2update', 'product_id': 'BTC-USD', 'changes': [['sell', '49365.08', '0.00544700']], 'time': '2021-05-20T03:54:48.882991Z'}
{'type': 'l2update', 'product_id': 'BTC-USD', 'changes': [['sell', '38380.33', '0.38290609']], 'time': '2021-05-20T03:54:48.883015Z'}
{'type': 'l2update', 'product_id': 'BTC-USD', 'changes': [['sell', '38268.67', '0.00000000']], 'time': '2021-05-20T03:54:48.886512Z'}
{'type': 'l2update', 'product_id': 'BTC-USD', 'changes': [['sell', '38269.33', '0.36249352']], 'time': '2021-05-20T03:54:48.887334Z'}
{'type': 'l2update', 'product_id': 'BTC-USD', 'changes': [['sell', '38274.57', '2.48969908']], 'time': '2021-05-20T03:54:48.891208Z'}
{'type': 'l2update', 'product_id': 'BTC-USD', 'changes': [['sell', '38277.46', '0.00000000']], 'time': '2021-05-20T03:54:48.892870Z'}
{'type': 'l2update', 'product_id': 'BTC-USD', 'changes': [['buy', '38232.11', '0.00000000']], 'time': '2021-05-20T03:54:48.893871Z'}
{'type': 'l2update', 'product_id': 'BTC-USD', 'changes': [['sell', '38276.55', '0.00000000']], 'time': '2021-05-20T03:54:48.893871Z'}
{'type': 'l2update', 'product_id': 'BTC-USD', 'changes': [['sell', '38268.85', '0.07460000']], 'time': '2021-05-20T03:54:48.903371Z'}
{'type': 'l2update', 'product_id': 'BTC-USD', 'changes': [['buy', '38178.50', '0.02663544']], 'time': '2021-05-20T03:54:48.903423Z'}
{'type': 'l2update', 'product_id': 'BTC-USD', 'changes': [['sell', '38429.45', '0.00000000']], 'time': '2021-05-20T03:54:48.908929Z'}
{'type': 'l2update', 'product_id': 'BTC-USD', 'changes': [['sell', '38415.07', '0.01000000']], 'time': '2021-05-20T03:54:48.919232Z'}
{'type': 'l2update', 'product_id': 'BTC-USD', 'changes': [['buy', '38257.53', '0.00000000']], 'time': '2021-05-20T03:54:48.920353Z'}
{'type': 'l2update', 'product_id': 'BTC-USD', 'changes': [['buy', '38235.63', '0.04111140']], 'time': '2021-05-20T03:54:48.923684Z'}
{'type': 'l2update', 'product_id': 'BTC-USD', 'changes': [['sell', '38278.75', '0.04980088']], 'time': '2021-05-20T03:54:48.923684Z'}
{'type': 'l2update', 'product_id': 'BTC-USD', 'changes': [['sell', '38289.40', '0.40470000']], 'time': '2021-05-20T03:54:48.927738Z'}
{'type': 'l2update', 'product_id': 'BTC-USD', 'changes': [['buy', '38235.03', '0.02400000']], 'time': '2021-05-20T03:54:48.932179Z'}
{'type': 'l2update', 'product_id': 'BTC-USD', 'changes': [['buy', '38234.22', '0.02400000']], 'time': '2021-05-20T03:54:48.932179Z'}
{'type': 'l2update', 'product_id': 'BTC-USD', 'changes': [['buy', '38233.42', '0.02400000']], 'time': '2021-05-20T03:54:48.932179Z'}
{'type': 'l2update', 'product_id': 'BTC-USD', 'changes': [['sell', '38274.52', '0.58500000']], 'time': '2021-05-20T03:54:48.936943Z'}
{'type': 'l2update', 'product_id': 'BTC-USD', 'changes': [['sell', '38381.10', '0.00000000']], 'time': '2021-05-20T03:54:48.939206Z'}
{'type': 'l2update', 'product_id': 'BTC-USD', 'changes': [['buy', '38260.83', '0.60580420']], 'time': '2021-05-20T03:54:48.941456Z'}
{'type': 'l2update', 'product_id': 'BTC-USD', 'changes': [['sell', '38269.33', '0.00000000']], 'time': '2021-05-20T03:54:48.943092Z'}
{'type': 'l2update', 'product_id': 'BTC-USD', 'changes': [['sell', '38316.93', '0.02609812']], 'time': '2021-05-20T03:54:48.944865Z'}
{'type': 'l2update', 'product_id': 'BTC-USD', 'changes': [['buy', '38260.83', '0.63580420']], 'time': '2021-05-20T03:54:48.945080Z'}
{'type': 'l2update', 'product_id': 'BTC-USD', 'changes': [['sell', '38394.55', '0.01568547']], 'time': '2021-05-20T03:54:48.950474Z'}
{'type': 'l2update', 'product_id': 'BTC-USD', 'changes': [['sell', '38268.85', '0.00000000']], 'time': '2021-05-20T03:54:48.951420Z'}
{'type': 'l2update', 'product_id': 'BTC-USD', 'changes': [['sell', '38270.70', '0.05464385']], 'time': '2021-05-20T03:54:48.953615Z'}
{'type': 'l2update', 'product_id': 'BTC-USD', 'changes': [['sell', '38289.40', '0.00000000']], 'time': '2021-05-20T03:54:48.957420Z'}
{'type': 'l2update', 'product_id': 'BTC-USD', 'changes': [['buy', '38235.63', '0.00000000']], 'time': '2021-05-20T03:54:48.960187Z'}
{'type': 'l2update', 'product_id': 'BTC-USD', 'changes': [['sell', '38278.75', '0.00000000']], 'time': '2021-05-20T03:54:48.960187Z'}
{'type': 'l2update', 'product_id': 'BTC-USD', 'changes': [['sell', '38277.40', '0.00000000']], 'time': '2021-05-20T03:54:48.960245Z'}
{'type': 'l2update', 'product_id': 'BTC-USD', 'changes': [['buy', '38234.45', '0.00000000']], 'time': '2021-05-20T03:54:48.961281Z'}
{'type': 'l2update', 'product_id': 'BTC-USD', 'changes': [['sell', '38274.52', '0.00000000']], 'time': '2021-05-20T03:54:48.965058Z'}
{'type': 'l2update', 'product_id': 'BTC-USD', 'changes': [['buy', '38240.26', '0.00000000']], 'time': '2021-05-20T03:54:48.967453Z'}
{'type': 'l2update', 'product_id': 'BTC-USD', 'changes': [['sell', '38274.51', '0.36249352']], 'time': '2021-05-20T03:54:48.967981Z'}
{'type': 'l2update', 'product_id': 'BTC-USD', 'changes': [['sell', '38269.65', '0.07460000']], 'time': '2021-05-20T03:54:48.968424Z'}
{'type': 'l2update', 'product_id': 'BTC-USD', 'changes': [['buy', '38142.70', '0.00000000']], 'time': '2021-05-20T03:54:48.975125Z'}
{'type': 'l2update', 'product_id': 'BTC-USD', 'changes': [['sell', '38345.20', '0.17760000']], 'time': '2021-05-20T03:54:48.990349Z'}
{'type': 'l2update', 'product_id': 'BTC-USD', 'changes': [['buy', '38260.83', '0.63756949']], 'time': '2021-05-20T03:54:48.992330Z'}
{'type': 'l2update', 'product_id': 'BTC-USD', 'changes': [['buy', '38154.63', '0.01000000']], 'time': '2021-05-20T03:54:48.992574Z'}
{'type': 'l2update', 'product_id': 'BTC-USD', 'changes': [['sell', '38269.28', '0.00730463']], 'time': '2021-05-20T03:54:48.992601Z'}
{'type': 'l2update', 'product_id': 'BTC-USD', 'changes': [['buy', '38250.79', '0.00000000']], 'time': '2021-05-20T03:54:48.994895Z'}
{'type': 'l2update', 'product_id': 'BTC-USD', 'changes': [['sell', '38387.17', '0.48754318']], 'time': '2021-05-20T03:54:48.996555Z'}
{'type': 'l2update', 'product_id': 'BTC-USD', 'changes': [['buy', '38240.28', '0.06508382']], 'time': '2021-05-20T03:54:48.996580Z'}
{'type': 'l2update', 'product_id': 'BTC-USD', 'changes': [['sell', '38280.84', '0.06411732']], 'time': '2021-05-20T03:54:48.996580Z'}
{'type': 'l2update', 'product_id': 'BTC-USD', 'changes': [['sell', '38289.01', '0.00000000']], 'time': '2021-05-20T03:54:49.003808Z'}
{'type': 'l2update', 'product_id': 'BTC-USD', 'changes': [['buy', '38176.55', '0.00000000']], 'time': '2021-05-20T03:54:49.006252Z'}
{'type': 'l2update', 'product_id': 'BTC-USD', 'changes': [['sell', '38269.65', '0.00000000']], 'time': '2021-05-20T03:54:49.006848Z'}
{'type': 'l2update', 'product_id': 'BTC-USD', 'changes': [['sell', '38269.28', '0.00000000']], 'time': '2021-05-20T03:54:49.008676Z'}
{'type': 'l2update', 'product_id': 'BTC-USD', 'changes': [['buy', '38253.23', '0.58716278']], 'time': '2021-05-20T03:54:49.009516Z'}
{'type': 'l2update', 'product_id': 'BTC-USD', 'changes': [['sell', '38293.06', '0.05000000']], 'time': '2021-05-20T03:54:49.010008Z'}
{'type': 'l2update', 'product_id': 'BTC-USD', 'changes': [['sell', '38324.88', '0.17400000']], 'time': '2021-05-20T03:54:49.010032Z'}
{'type': 'l2update', 'product_id': 'BTC-USD', 'changes': [['sell', '38401.42', '0.32702610']], 'time': '2021-05-20T03:54:49.022650Z'}
{'type': 'l2update', 'product_id': 'BTC-USD', 'changes': [['sell', '38438.08', '0.00000000']], 'time': '2021-05-20T03:54:49.027368Z'}
{'type': 'l2update', 'product_id': 'BTC-USD', 'changes': [['sell', '38429.36', '0.00000000']], 'time': '2021-05-20T03:54:49.029381Z'}
{'type': 'l2update', 'product_id': 'BTC-USD', 'changes': [['sell', '38345.98', '0.00000000']], 'time': '2021-05-20T03:54:49.029782Z'}
{'type': 'l2update', 'product_id': 'BTC-USD', 'changes': [['buy', '38178.50', '0.05387864']], 'time': '2021-05-20T03:54:49.031138Z'}
{'type': 'l2update', 'product_id': 'BTC-USD', 'changes': [['sell', '38351.55', '0.05455871']], 'time': '2021-05-20T03:54:49.037180Z'}
{'type': 'l2update', 'product_id': 'BTC-USD', 'changes': [['sell', '38453.15', '0.01000000']], 'time': '2021-05-20T03:54:49.041621Z'}
{'type': 'l2update', 'product_id': 'BTC-USD', 'changes': [['sell', '38351.56', '0.00000000']], 'time': '2021-05-20T03:54:49.047803Z'}
{'type': 'l2update', 'product_id': 'BTC-USD', 'changes': [['sell', '38299.93', '0.42180000']], 'time': '2021-05-20T03:54:49.048106Z'}
{'type': 'l2update', 'product_id': 'BTC-USD', 'changes': [['sell', '38269.88', '0.07460000']], 'time': '2021-05-20T03:54:49.048155Z'}
{'type': 'l2update', 'product_id': 'BTC-USD', 'changes': [['sell', '49368.61', '0.00544700']], 'time': '2021-05-20T03:54:49.048195Z'}
{'type': 'l2update', 'product_id': 'BTC-USD', 'changes': [['sell', '38292.42', '0.04989888']], 'time': '2021-05-20T03:54:49.048487Z'}
{'type': 'l2update', 'product_id': 'BTC-USD', 'changes': [['sell', '38366.86', '0.01000000']], 'time': '2021-05-20T03:54:49.060835Z'}
{'type': 'l2update', 'product_id': 'BTC-USD', 'changes': [['buy', '38241.40', '0.40090000']], 'time': '2021-05-20T03:54:49.060963Z'}
{'type': 'l2update', 'product_id': 'BTC-USD', 'changes': [['sell', '38402.36', '0.01000000']], 'time': '2021-05-20T03:54:49.061075Z'}
{'type': 'l2update', 'product_id': 'BTC-USD', 'changes': [['sell', '38366.76', '0.00000000']], 'time': '2021-05-20T03:54:49.076454Z'}
{'type': 'l2update', 'product_id': 'BTC-USD', 'changes': [['sell', '38284.66', '0.12912501']], 'time': '2021-05-20T03:54:49.081285Z'}
{'type': 'l2update', 'product_id': 'BTC-USD', 'changes': [['sell', '38270.70', '0.00000000']], 'time': '2021-05-20T03:54:49.090600Z'}
{'type': 'l2update', 'product_id': 'BTC-USD', 'changes': [['sell', '38391.42', '0.01791638']], 'time': '2021-05-20T03:54:49.097229Z'}
{'type': 'l2update', 'product_id': 'BTC-USD', 'changes': [['buy', '37500.01', '0.07230000']], 'time': '2021-05-20T03:54:49.098559Z'}
{'type': 'l2update', 'product_id': 'BTC-USD', 'changes': [['sell', '39499.99', '0.00000000']], 'time': '2021-05-20T03:54:49.098559Z'}
{'type': 'l2update', 'product_id': 'BTC-USD', 'changes': [['buy', '38159.08', '0.00000000']], 'time': '2021-05-20T03:54:49.100921Z'}
{'type': 'l2update', 'product_id': 'BTC-USD', 'changes': [['buy', '38253.28', '0.84800000']], 'time': '2021-05-20T03:54:49.105287Z'}
{'type': 'l2update', 'product_id': 'BTC-USD', 'changes': [['buy', '37469.35', '0.11560000']], 'time': '2021-05-20T03:54:49.105392Z'}
{'type': 'l2update', 'product_id': 'BTC-USD', 'changes': [['sell', '39443.99', '0.04620000']], 'time': '2021-05-20T03:54:49.105392Z'}
{'type': 'l2update', 'product_id': 'BTC-USD', 'changes': [['buy', '38250.86', '0.00000000']], 'time': '2021-05-20T03:54:49.113094Z'}
{'type': 'l2update', 'product_id': 'BTC-USD', 'changes': [['sell', '38269.61', '0.01492000']], 'time': '2021-05-20T03:54:49.114053Z'}
{'type': 'l2update', 'product_id': 'BTC-USD', 'changes': [['buy', '38172.83', '0.03521768']], 'time': '2021-05-20T03:54:49.114165Z'}
{'type': 'l2update', 'product_id': 'BTC-USD', 'changes': [['sell', '38282.38', '0.05464385']], 'time': '2021-05-20T03:54:49.117410Z'}
{'type': 'l2update', 'product_id': 'BTC-USD', 'changes': [['sell', '38270.24', '0.00000000']], 'time': '2021-05-20T03:54:49.125279Z'}
{'type': 'l2update', 'product_id': 'BTC-USD', 'changes': [['sell', '38305.58', '0.01000000']], 'time': '2021-05-20T03:54:49.133392Z'}
{'type': 'l2update', 'product_id': 'BTC-USD', 'changes': [['buy', '38253.29', '0.22867204']], 'time': '2021-05-20T03:54:49.133586Z'}
{'type': 'l2update', 'product_id': 'BTC-USD', 'changes': [['buy', '37911.84', '5.00000000']], 'time': '2021-05-20T03:54:49.133789Z'}
{'type': 'l2update', 'product_id': 'BTC-USD', 'changes': [['buy', '38195.17', '0.32000000']], 'time': '2021-05-20T03:54:49.133789Z'}
{'type': 'l2update', 'product_id': 'BTC-USD', 'changes': [['buy', '38100.73', '0.80000000']], 'time': '2021-05-20T03:54:49.133789Z'}
{'type': 'l2update', 'product_id': 'BTC-USD', 'changes': [['sell', '38357.65', '0.00000000']], 'time': '2021-05-20T03:54:49.136239Z'}
{'type': 'l2update', 'product_id': 'BTC-USD', 'changes': [['sell', '38260.84', '0.00307810']], 'time': '2021-05-20T03:54:49.137368Z'}
{'type': 'l2update', 'product_id': 'BTC-USD', 'changes': [['sell', '38269.88', '0.00000000']], 'time': '2021-05-20T03:54:49.141082Z'}
{'type': 'l2update', 'product_id': 'BTC-USD', 'changes': [['sell', '38391.42', '0.00000000']], 'time': '2021-05-20T03:54:49.142192Z'}
{'type': 'l2update', 'product_id': 'BTC-USD', 'changes': [['buy', '38223.31', '0.01000000']], 'time': '2021-05-20T03:54:49.146785Z'}
{'type': 'l2update', 'product_id': 'BTC-USD', 'changes': [['sell', '38297.37', '0.00000000']], 'time': '2021-05-20T03:54:49.150370Z'}
{'type': 'l2update', 'product_id': 'BTC-USD', 'changes': [['buy', '38260.83', '1.28756949']], 'time': '2021-05-20T03:54:49.153972Z'}
{'type': 'l2update', 'product_id': 'BTC-USD', 'changes': [['buy', '38166.97', '0.03761271']], 'time': '2021-05-20T03:54:49.154366Z'}
{'type': 'l2update', 'product_id': 'BTC-USD', 'changes': [['sell', '38305.58', '0.00000000']], 'time': '2021-05-20T03:54:49.154571Z'}
{'type': 'l2update', 'product_id': 'BTC-USD', 'changes': [['sell', '38300.74', '0.04913547']], 'time': '2021-05-20T03:54:49.158686Z'}
{'type': 'l2update', 'product_id': 'BTC-USD', 'changes': [['buy', '38258.37', '0.05028608']], 'time': '2021-05-20T03:54:49.159003Z'}
{'type': 'l2update', 'product_id': 'BTC-USD', 'changes': [['buy', '38233.39', '0.00000000']], 'time': '2021-05-20T03:54:49.159516Z'}
{'type': 'l2update', 'product_id': 'BTC-USD', 'changes': [['sell', '38269.03', '0.07460000']], 'time': '2021-05-20T03:54:49.162861Z'}
{'type': 'l2update', 'product_id': 'BTC-USD', 'changes': [['sell', '38453.15', '0.00000000']], 'time': '2021-05-20T03:54:49.163247Z'}
{'type': 'l2update', 'product_id': 'BTC-USD', 'changes': [['buy', '38223.31', '0.00000000']], 'time': '2021-05-20T03:54:49.163544Z'}
{'type': 'l2update', 'product_id': 'BTC-USD', 'changes': [['sell', '38274.51', '0.00000000']], 'time': '2021-05-20T03:54:49.165857Z'}
{'type': 'l2update', 'product_id': 'BTC-USD', 'changes': [['sell', '38275.85', '0.05053276']], 'time': '2021-05-20T03:54:49.166320Z'}
{'type': 'l2update', 'product_id': 'BTC-USD', 'changes': [['sell', '38376.42', '0.01792338']], 'time': '2021-05-20T03:54:49.166352Z'}
{'type': 'l2update', 'product_id': 'BTC-USD', 'changes': [['sell', '38303.04', '0.10000000']], 'time': '2021-05-20T03:54:49.169743Z'}
{'type': 'l2update', 'product_id': 'BTC-USD', 'changes': [['sell', '38260.84', '0.00007810']], 'time': '2021-05-20T03:54:49.169982Z'}
{'type': 'l2update', 'product_id': 'BTC-USD', 'changes': [['buy', '38220.02', '0.02000000']], 'time': '2021-05-20T03:54:49.170005Z'}
{'type': 'l2update', 'product_id': 'BTC-USD', 'changes': [['sell', '38269.03', '0.00000000']], 'time': '2021-05-20T03:54:49.170419Z'}
{'type': 'l2update', 'product_id': 'BTC-USD', 'changes': [['sell', '38269.61', '0.00000000']], 'time': '2021-05-20T03:54:49.174146Z'}
{'type': 'l2update', 'product_id': 'BTC-USD', 'changes': [['buy', '38244.43', '0.53200000']], 'time': '2021-05-20T03:54:49.174693Z'}
{'type': 'l2update', 'product_id': 'BTC-USD', 'changes': [['buy', '38160.92', '0.03545956']], 'time': '2021-05-20T03:54:49.179834Z'}
{'type': 'l2update', 'product_id': 'BTC-USD', 'changes': [['sell', '38439.96', '0.01000000']], 'time': '2021-05-20T03:54:49.180151Z'}
{'type': 'l2update', 'product_id': 'BTC-USD', 'changes': [['sell', '38270.23', '0.00000000']], 'time': '2021-05-20T03:54:49.181719Z'}
{'type': 'l2update', 'product_id': 'BTC-USD', 'changes': [['buy', '38248.03', '0.00000000']], 'time': '2021-05-20T03:54:49.181931Z'}
{'type': 'l2update', 'product_id': 'BTC-USD', 'changes': [['sell', '38345.20', '0.00000000']], 'time': '2021-05-20T03:54:49.187168Z'}
{'type': 'l2update', 'product_id': 'BTC-USD', 'changes': [['sell', '38299.93', '0.00000000']], 'time': '2021-05-20T03:54:49.187550Z'}
{'type': 'l2update', 'product_id': 'BTC-USD', 'changes': [['sell', '38274.56', '0.36249352']], 'time': '2021-05-20T03:54:49.189661Z'}
{'type': 'l2update', 'product_id': 'BTC-USD', 'changes': [['sell', '38269.65', '0.03615163']], 'time': '2021-05-20T03:54:49.189959Z'}
{'type': 'l2update', 'product_id': 'BTC-USD', 'changes': [['sell', '38269.89', '0.02595651']], 'time': '2021-05-20T03:54:49.195999Z'}
{'type': 'l2update', 'product_id': 'BTC-USD', 'changes': [['buy', '38237.08', '0.00000000']], 'time': '2021-05-20T03:54:49.196190Z'}
{'type': 'l2update', 'product_id': 'BTC-USD', 'changes': [['sell', '38269.65', '0.00000000']], 'time': '2021-05-20T03:54:49.197096Z'}
{'type': 'l2update', 'product_id': 'BTC-USD', 'changes': [['sell', '38298.10', '0.40510000']], 'time': '2021-05-20T03:54:49.200646Z'}
{'type': 'l2update', 'product_id': 'BTC-USD', 'changes': [['sell', '38274.56', '0.86249352']], 'time': '2021-05-20T03:54:49.200939Z'}
{'type': 'l2update', 'product_id': 'BTC-USD', 'changes': [['sell', '38269.89', '0.00000000']], 'time': '2021-05-20T03:54:49.204063Z'}
{'type': 'l2update', 'product_id': 'BTC-USD', 'changes': [['buy', '38170.09', '0.65492649']], 'time': '2021-05-20T03:54:49.204679Z'}
{'type': 'l2update', 'product_id': 'BTC-USD', 'changes': [['buy', '38260.28', '0.84900000']], 'time': '2021-05-20T03:54:49.207992Z'}
{'type': 'l2update', 'product_id': 'BTC-USD', 'changes': [['sell', '49375.67', '0.00544700']], 'time': '2021-05-20T03:54:49.210298Z'}
{'type': 'l2update', 'product_id': 'BTC-USD', 'changes': [['sell', '38277.39', '0.00000000']], 'time': '2021-05-20T03:54:49.210731Z'}
{'type': 'l2update', 'product_id': 'BTC-USD', 'changes': [['sell', '38274.33', '0.01249186']], 'time': '2021-05-20T03:54:49.212278Z'}
{'type': 'l2update', 'product_id': 'BTC-USD', 'changes': [['buy', '38148.27', '0.02749752']], 'time': '2021-05-20T03:54:49.230074Z'}
{'type': 'l2update', 'product_id': 'BTC-USD', 'changes': [['sell', '38439.96', '0.00000000']], 'time': '2021-05-20T03:54:49.233799Z'}
{'type': 'l2update', 'product_id': 'BTC-USD', 'changes': [['sell', '38351.62', '0.00000000']], 'time': '2021-05-20T03:54:49.234428Z'}
{'type': 'l2update', 'product_id': 'BTC-USD', 'changes': [['buy', '38199.45', '1.61030000']], 'time': '2021-05-20T03:54:49.243632Z'}
{'type': 'l2update', 'product_id': 'BTC-USD', 'changes': [['sell', '38456.92', '0.01000000']], 'time': '2021-05-20T03:54:49.244655Z'}
{'type': 'l2update', 'product_id': 'BTC-USD', 'changes': [['sell', '38414.06', '0.03573000']], 'time': '2021-05-20T03:54:49.244899Z'}
{'type': 'l2update', 'product_id': 'BTC-USD', 'changes': [['sell', '38273.99', '0.01492000']], 'time': '2021-05-20T03:54:49.248815Z'}
{'type': 'l2update', 'product_id': 'BTC-USD', 'changes': [['sell', '38351.55', '0.00000000']], 'time': '2021-05-20T03:54:49.251371Z'}
{'type': 'l2update', 'product_id': 'BTC-USD', 'changes': [['sell', '38274.56', '0.50000000']], 'time': '2021-05-20T03:54:49.257342Z'}
{'type': 'l2update', 'product_id': 'BTC-USD', 'changes': [['sell', '38349.99', '0.02727879']], 'time': '2021-05-20T03:54:49.258776Z'}
{'type': 'l2update', 'product_id': 'BTC-USD', 'changes': [['buy', '38239.30', '0.00000000']], 'time': '2021-05-20T03:54:49.260255Z'}
{'type': 'l2update', 'product_id': 'BTC-USD', 'changes': [['buy', '38114.98', '0.80355629']], 'time': '2021-05-20T03:54:49.262644Z'}
{'type': 'l2update', 'product_id': 'BTC-USD', 'changes': [['sell', '38456.92', '0.00000000']], 'time': '2021-05-20T03:54:49.265489Z'}
{'type': 'l2update', 'product_id': 'BTC-USD', 'changes': [['buy', '38141.66', '0.02805188']], 'time': '2021-05-20T03:54:49.266264Z'}
{'type': 'l2update', 'product_id': 'BTC-USD', 'changes': [['sell', '38274.33', '0.00000000']], 'time': '2021-05-20T03:54:49.275345Z'}
{'type': 'l2update', 'product_id': 'BTC-USD', 'changes': [['sell', '38274.55', '0.36249352']], 'time': '2021-05-20T03:54:49.277447Z'}
{'type': 'l2update', 'product_id': 'BTC-USD', 'changes': [['sell', '38439.96', '0.01000000']], 'time': '2021-05-20T03:54:49.277510Z'}
{'type': 'l2update', 'product_id': 'BTC-USD', 'changes': [['sell', '38420.65', '0.00000000']], 'time': '2021-05-20T03:54:49.284438Z'}
{'type': 'l2update', 'product_id': 'BTC-USD', 'changes': [['sell', '38273.38', '0.06210814']], 'time': '2021-05-20T03:54:49.289717Z'}
{'type': 'l2update', 'product_id': 'BTC-USD', 'changes': [['sell', '38523.47', '0.00000000']], 'time': '2021-05-20T03:54:49.294680Z'}
{'type': 'l2update', 'product_id': 'BTC-USD', 'changes': [['sell', '38282.38', '0.00000000']], 'time': '2021-05-20T03:54:49.295633Z'}
{'type': 'l2update', 'product_id': 'BTC-USD', 'changes': [['sell', '38392.87', '0.01000000']], 'time': '2021-05-20T03:54:49.296603Z'}
{'type': 'l2update', 'product_id': 'BTC-USD', 'changes': [['sell', '38270.56', '0.01115706']], 'time': '2021-05-20T03:54:49.302001Z'}
{'type': 'l2update', 'product_id': 'BTC-USD', 'changes': [['sell', '38273.99', '0.00000000']], 'time': '2021-05-20T03:54:49.308110Z'}
{'type': 'l2update', 'product_id': 'BTC-USD', 'changes': [['buy', '38260.83', '1.29890850']], 'time': '2021-05-20T03:54:49.310392Z'}
{'type': 'l2update', 'product_id': 'BTC-USD', 'changes': [['sell', '38508.47', '0.01298415']], 'time': '2021-05-20T03:54:49.310628Z'}
{'type': 'l2update', 'product_id': 'BTC-USD', 'changes': [['sell', '38376.42', '0.00000000']], 'time': '2021-05-20T03:54:49.317286Z'}
{'type': 'l2update', 'product_id': 'BTC-USD', 'changes': [['sell', '38280.00', '0.05464385']], 'time': '2021-05-20T03:54:49.330724Z'}
{'type': 'l2update', 'product_id': 'BTC-USD', 'changes': [['buy', '38260.83', '1.29883430']], 'time': '2021-05-20T03:54:49.335608Z'}
{'type': 'l2update', 'product_id': 'BTC-USD', 'changes': [['buy', '38260.83', '1.28883430']], 'time': '2021-05-20T03:54:49.335608Z'}
{'type': 'l2update', 'product_id': 'BTC-USD', 'changes': [['buy', '38260.83', '1.28624830']], 'time': '2021-05-20T03:54:49.335608Z'}
{'type': 'l2update', 'product_id': 'BTC-USD', 'changes': [['sell', '38273.38', '0.00000000']], 'time': '2021-05-20T03:54:49.340526Z'}
{'type': 'l2update', 'product_id': 'BTC-USD', 'changes': [['sell', '38391.42', '0.01791638']], 'time': '2021-05-20T03:54:49.344989Z'}
{'type': 'l2update', 'product_id': 'BTC-USD', 'changes': [['sell', '38269.95', '0.01249186']], 'time': '2021-05-20T03:54:49.348591Z'}
{'type': 'l2update', 'product_id': 'BTC-USD', 'changes': [['sell', '38270.15', '0.01492000']], 'time': '2021-05-20T03:54:49.351019Z'}
{'type': 'l2update', 'product_id': 'BTC-USD', 'changes': [['sell', '38317.43', '0.04913768']], 'time': '2021-05-20T03:54:49.357656Z'}
{'type': 'l2update', 'product_id': 'BTC-USD', 'changes': [['buy', '38094.91', '0.04965290']], 'time': '2021-05-20T03:54:49.357852Z'}
{'type': 'l2update', 'product_id': 'BTC-USD', 'changes': [['sell', '38280.79', '1.06400000']], 'time': '2021-05-20T03:54:49.362507Z'}
{'type': 'l2update', 'product_id': 'BTC-USD', 'changes': [['sell', '38395.23', '0.00000000']], 'time': '2021-05-20T03:54:49.367871Z'}
{'type': 'l2update', 'product_id': 'BTC-USD', 'changes': [['sell', '38270.15', '0.00000000']], 'time': '2021-05-20T03:54:49.375928Z'}
{'type': 'l2update', 'product_id': 'BTC-USD', 'changes': [['buy', '38260.83', '1.29624830']], 'time': '2021-05-20T03:54:49.377241Z'}
{'type': 'l2update', 'product_id': 'BTC-USD', 'changes': [['sell', '49386.26', '0.00544700']], 'time': '2021-05-20T03:54:49.377844Z'}
{'type': 'l2update', 'product_id': 'BTC-USD', 'changes': [['sell', '38379.98', '0.01302762']], 'time': '2021-05-20T03:54:49.381571Z'}
{'type': 'l2update', 'product_id': 'BTC-USD', 'changes': [['buy', '38253.29', '0.00000000']], 'time': '2021-05-20T03:54:49.381710Z'}
{'type': 'l2update', 'product_id': 'BTC-USD', 'changes': [['buy', '38253.29', '0.22867204']], 'time': '2021-05-20T03:54:49.406568Z'}
{'type': 'l2update', 'product_id': 'BTC-USD', 'changes': [['sell', '38269.64', '0.01492000']], 'time': '2021-05-20T03:54:49.412133Z'}
{'type': 'l2update', 'product_id': 'BTC-USD', 'changes': [['sell', '38391.42', '0.00000000']], 'time': '2021-05-20T03:54:49.413195Z'}
{'type': 'l2update', 'product_id': 'BTC-USD', 'changes': [['sell', '38269.64', '0.00000000']], 'time': '2021-05-20T03:54:49.417301Z'}
{'type': 'l2update', 'product_id': 'BTC-USD', 'changes': [['sell', '38376.42', '0.01792338']], 'time': '2021-05-20T03:54:49.435429Z'}
{'type': 'l2update', 'product_id': 'BTC-USD', 'changes': [['sell', '38414.06', '0.00000000']], 'time': '2021-05-20T03:54:49.435643Z'}
{'type': 'l2update', 'product_id': 'BTC-USD', 'changes': [['buy', '38199.45', '0.00000000']], 'time': '2021-05-20T03:54:49.437880Z'}
{'type': 'l2update', 'product_id': 'BTC-USD', 'changes': [['buy', '37323.95', '0.00000000']], 'time': '2021-05-20T03:54:49.446702Z'}
{'type': 'l2update', 'product_id': 'BTC-USD', 'changes': [['buy', '36464.74', '0.00000000']], 'time': '2021-05-20T03:54:49.446702Z'}
{'type': 'l2update', 'product_id': 'BTC-USD', 'changes': [['sell', '38375.59', '0.01000000']], 'time': '2021-05-20T03:54:49.448910Z'}
{'type': 'l2update', 'product_id': 'BTC-USD', 'changes': [['buy', '38154.63', '0.00000000']], 'time': '2021-05-20T03:54:49.453807Z'}
{'type': 'l2update', 'product_id': 'BTC-USD', 'changes': [['sell', '38270.56', '0.00000000']], 'time': '2021-05-20T03:54:49.462469Z'}
{'type': 'l2update', 'product_id': 'BTC-USD', 'changes': [['buy', '38167.19', '0.03577500']], 'time': '2021-05-20T03:54:49.465911Z'}
{'type': 'l2update', 'product_id': 'BTC-USD', 'changes': [['buy', '38235.03', '0.00000000']], 'time': '2021-05-20T03:54:49.472754Z'}
{'type': 'l2update', 'product_id': 'BTC-USD', 'changes': [['buy', '38234.22', '0.00000000']], 'time': '2021-05-20T03:54:49.472754Z'}
{'type': 'l2update', 'product_id': 'BTC-USD', 'changes': [['buy', '38233.42', '0.00000000']], 'time': '2021-05-20T03:54:49.472754Z'}
{'type': 'l2update', 'product_id': 'BTC-USD', 'changes': [['sell', '38279.82', '0.55100000']], 'time': '2021-05-20T03:54:49.474060Z'}
{'type': 'l2update', 'product_id': 'BTC-USD', 'changes': [['sell', '38269.95', '0.00000000']], 'time': '2021-05-20T03:54:49.475130Z'}
{'type': 'l2update', 'product_id': 'BTC-USD', 'changes': [['sell', '38376.42', '0.00000000']], 'time': '2021-05-20T03:54:49.480748Z'}
{'type': 'l2update', 'product_id': 'BTC-USD', 'changes': [['sell', '38274.27', '0.06210814']], 'time': '2021-05-20T03:54:49.482307Z'}
{'type': 'l2update', 'product_id': 'BTC-USD', 'changes': [['buy', '38260.28', '0.00000000']], 'time': '2021-05-20T03:54:49.484380Z'}
{'type': 'l2update', 'product_id': 'BTC-USD', 'changes': [['sell', '38310.36', '0.01000000']], 'time': '2021-05-20T03:54:49.486321Z'}
{'type': 'l2update', 'product_id': 'BTC-USD', 'changes': [['buy', '38240.18', '0.02400000']], 'time': '2021-05-20T03:54:49.490036Z'}
{'type': 'l2update', 'product_id': 'BTC-USD', 'changes': [['buy', '38239.37', '0.02400000']], 'time': '2021-05-20T03:54:49.490036Z'}
{'type': 'l2update', 'product_id': 'BTC-USD', 'changes': [['buy', '38238.57', '0.02400000']], 'time': '2021-05-20T03:54:49.490036Z'}
{'type': 'l2update', 'product_id': 'BTC-USD', 'changes': [['buy', '38260.83', '0.64624830']], 'time': '2021-05-20T03:54:49.493413Z'}
{'type': 'l2update', 'product_id': 'BTC-USD', 'changes': [['sell', '38274.27', '0.07460000']], 'time': '2021-05-20T03:54:49.493610Z'}
{'type': 'l2update', 'product_id': 'BTC-USD', 'changes': [['buy', '38212.56', '0.00000000']], 'time': '2021-05-20T03:54:49.496162Z'}
{'type': 'l2update', 'product_id': 'BTC-USD', 'changes': [['buy', '38240.18', '0.00000000']], 'time': '2021-05-20T03:54:49.497277Z'}
{'type': 'l2update', 'product_id': 'BTC-USD', 'changes': [['sell', '38364.60', '0.12274819']], 'time': '2021-05-20T03:54:49.498547Z'}
{'type': 'l2update', 'product_id': 'BTC-USD', 'changes': [['buy', '38228.09', '0.01000000']], 'time': '2021-05-20T03:54:49.503021Z'}
{'type': 'l2update', 'product_id': 'BTC-USD', 'changes': [['sell', '38355.56', '0.05455475']], 'time': '2021-05-20T03:54:49.503300Z'}
{'type': 'l2update', 'product_id': 'BTC-USD', 'changes': [['buy', '38240.28', '0.00000000']], 'time': '2021-05-20T03:54:49.504455Z'}
{'type': 'l2update', 'product_id': 'BTC-USD', 'changes': [['sell', '38280.84', '0.00000000']], 'time': '2021-05-20T03:54:49.504455Z'}
{'type': 'l2update', 'product_id': 'BTC-USD', 'changes': [['buy', '38216.56', '0.10000000']], 'time': '2021-05-20T03:54:49.506785Z'}
{'type': 'l2update', 'product_id': 'BTC-USD', 'changes': [['sell', '38273.63', '0.01492000']], 'time': '2021-05-20T03:54:49.506838Z'}
{'type': 'l2update', 'product_id': 'BTC-USD', 'changes': [['sell', '38391.42', '0.01791638']], 'time': '2021-05-20T03:54:49.506997Z'}
{'type': 'l2update', 'product_id': 'BTC-USD', 'changes': [['buy', '38253.29', '0.00000000']], 'time': '2021-05-20T03:54:49.510896Z'}
{'type': 'l2update', 'product_id': 'BTC-USD', 'changes': [['sell', '38274.55', '0.00000000']], 'time': '2021-05-20T03:54:49.515267Z'}
{'type': 'l2update', 'product_id': 'BTC-USD', 'changes': [['sell', '38298.10', '0.00000000']], 'time': '2021-05-20T03:54:49.519862Z'}
{'type': 'l2update', 'product_id': 'BTC-USD', 'changes': [['sell', '38274.27', '0.01249186']], 'time': '2021-05-20T03:54:49.521897Z'}
{'type': 'l2update', 'product_id': 'BTC-USD', 'changes': [['buy', '38260.83', '0.64448301']], 'time': '2021-05-20T03:54:49.523323Z'}
{'type': 'l2update', 'product_id': 'BTC-USD', 'changes': [['sell', '38274.27', '0.00000000']], 'time': '2021-05-20T03:54:49.526621Z'}
{'type': 'l2update', 'product_id': 'BTC-USD', 'changes': [['sell', '38415.07', '0.00000000']], 'time': '2021-05-20T03:54:49.527570Z'}
{'type': 'l2update', 'product_id': 'BTC-USD', 'changes': [['sell', '38296.45', '0.41750000']], 'time': '2021-05-20T03:54:49.530992Z'}
{'type': 'l2update', 'product_id': 'BTC-USD', 'changes': [['buy', '38240.83', '0.04619989']], 'time': '2021-05-20T03:54:49.535065Z'}
{'type': 'l2update', 'product_id': 'BTC-USD', 'changes': [['sell', '38281.39', '0.03990002']], 'time': '2021-05-20T03:54:49.535065Z'}
{'type': 'l2update', 'product_id': 'BTC-USD', 'changes': [['sell', '38274.55', '0.36249352']], 'time': '2021-05-20T03:54:49.535127Z'}
{'type': 'l2update', 'product_id': 'BTC-USD', 'changes': [['buy', '38253.29', '0.22867204']], 'time': '2021-05-20T03:54:49.535190Z'}
{'type': 'l2update', 'product_id': 'BTC-USD', 'changes': [['sell', '38273.40', '0.07460000']], 'time': '2021-05-20T03:54:49.539555Z'}
{'type': 'l2update', 'product_id': 'BTC-USD', 'changes': [['buy', '38237.57', '0.02400000']], 'time': '2021-05-20T03:54:49.551790Z'}
{'type': 'l2update', 'product_id': 'BTC-USD', 'changes': [['sell', '38403.13', '0.01000000']], 'time': '2021-05-20T03:54:49.551899Z'}
{'type': 'l2update', 'product_id': 'BTC-USD', 'changes': [['buy', '38239.37', '0.00000000']], 'time': '2021-05-20T03:54:49.556059Z'}
{'type': 'l2update', 'product_id': 'BTC-USD', 'changes': [['sell', '38284.66', '0.00000000']], 'time': '2021-05-20T03:54:49.558337Z'}
{'type': 'l2update', 'product_id': 'BTC-USD', 'changes': [['buy', '38236.33', '0.02400000']], 'time': '2021-05-20T03:54:49.568473Z'}
{'type': 'l2update', 'product_id': 'BTC-USD', 'changes': [['buy', '38260.83', '0.64624830']], 'time': '2021-05-20T03:54:49.568531Z'}
{'type': 'l2update', 'product_id': 'BTC-USD', 'changes': [['sell', '38260.84', '0.00000000']], 'time': '2021-05-20T03:54:49.573089Z'}
{'type': 'l2update', 'product_id': 'BTC-USD', 'changes': [['sell', '38273.40', '0.04907184']], 'time': '2021-05-20T03:54:49.573089Z'}
{'type': 'l2update', 'product_id': 'BTC-USD', 'changes': [['sell', '49400.37', '0.00544700']], 'time': '2021-05-20T03:54:49.573121Z'}
{'type': 'l2update', 'product_id': 'BTC-USD', 'changes': [['sell', '38565.49', '3.23362444']], 'time': '2021-05-20T03:54:49.576962Z'}
{'type': 'l2update', 'product_id': 'BTC-USD', 'changes': [['sell', '38273.63', '0.00000000']], 'time': '2021-05-20T03:54:49.577531Z'}
{'type': 'l2update', 'product_id': 'BTC-USD', 'changes': [['buy', '38260.83', '0.64051830']], 'time': '2021-05-20T03:54:49.580450Z'}
{'type': 'l2update', 'product_id': 'BTC-USD', 'changes': [['buy', '38261.09', '0.01492000']], 'time': '2021-05-20T03:54:49.584722Z'}
{'type': 'l2update', 'product_id': 'BTC-USD', 'changes': [['buy', '38261.47', '0.07460000']], 'time': '2021-05-20T03:54:49.584992Z'}
{'type': 'l2update', 'product_id': 'BTC-USD', 'changes': [['buy', '38260.84', '0.65000000']], 'time': '2021-05-20T03:54:49.585012Z'}
{'type': 'l2update', 'product_id': 'BTC-USD', 'changes': [['sell', '38296.45', '0.00000000']], 'time': '2021-05-20T03:54:49.585145Z'}
{'type': 'l2update', 'product_id': 'BTC-USD', 'changes': [['sell', '38275.85', '0.00000000']], 'time': '2021-05-20T03:54:49.586036Z'}
{'type': 'l2update', 'product_id': 'BTC-USD', 'changes': [['sell', '38273.40', '0.00000000']], 'time': '2021-05-20T03:54:49.587115Z'}
{'type': 'l2update', 'product_id': 'BTC-USD', 'changes': [['buy', '38257.68', '0.19600000']], 'time': '2021-05-20T03:54:49.588569Z'}
{'type': 'l2update', 'product_id': 'BTC-USD', 'changes': [['buy', '38260.83', '0.54051830']], 'time': '2021-05-20T03:54:49.590626Z'}
{'type': 'l2update', 'product_id': 'BTC-USD', 'changes': [['buy', '38253.29', '0.00000000']], 'time': '2021-05-20T03:54:49.592536Z'}
{'type': 'l2update', 'product_id': 'BTC-USD', 'changes': [['buy', '38261.09', '0.00000000']], 'time': '2021-05-20T03:54:49.593137Z'}
{'type': 'l2update', 'product_id': 'BTC-USD', 'changes': [['buy', '38262.94', '0.05120144']], 'time': '2021-05-20T03:54:49.593169Z'}
{'type': 'l2update', 'product_id': 'BTC-USD', 'changes': [['sell', '38565.48', '3.22888487']], 'time': '2021-05-20T03:54:49.593820Z'}
{'type': 'l2update', 'product_id': 'BTC-USD', 'changes': [['buy', '38260.83', '0.34051830']], 'time': '2021-05-20T03:54:49.597417Z'}
{'type': 'l2update', 'product_id': 'BTC-USD', 'changes': [['sell', '38565.50', '0.00000000']], 'time': '2021-05-20T03:54:49.599534Z'}
{'type': 'l2update', 'product_id': 'BTC-USD', 'changes': [['sell', '38274.29', '0.04907184']], 'time': '2021-05-20T03:54:49.601567Z'}
{'type': 'l2update', 'product_id': 'BTC-USD', 'changes': [['buy', '38253.34', '0.52100000']], 'time': '2021-05-20T03:54:49.601673Z'}
{'type': 'l2update', 'product_id': 'BTC-USD', 'changes': [['sell', '38384.37', '0.00000000']], 'time': '2021-05-20T03:54:49.603727Z'}
{'type': 'l2update', 'product_id': 'BTC-USD', 'changes': [['buy', '38258.37', '0.00000000']], 'time': '2021-05-20T03:54:49.605719Z'}
{'type': 'l2update', 'product_id': 'BTC-USD', 'changes': [['sell', '38279.80', '0.04926715']], 'time': '2021-05-20T03:54:49.607483Z'}
{'type': 'l2update', 'product_id': 'BTC-USD', 'changes': [['sell', '38274.29', '0.07460000']], 'time': '2021-05-20T03:54:49.607755Z'}
{'type': 'l2update', 'product_id': 'BTC-USD', 'changes': [['buy', '38263.59', '0.01492000']], 'time': '2021-05-20T03:54:49.609783Z'}
{'type': 'l2update', 'product_id': 'BTC-USD', 'changes': [['sell', '38273.98', '0.01492000']], 'time': '2021-05-20T03:54:49.613245Z'}
{'type': 'l2update', 'product_id': 'BTC-USD', 'changes': [['buy', '38261.47', '0.00000000']], 'time': '2021-05-20T03:54:49.613500Z'}
{'type': 'l2update', 'product_id': 'BTC-USD', 'changes': [['sell', '38274.55', '0.00000000']], 'time': '2021-05-20T03:54:49.615257Z'}
{'type': 'l2update', 'product_id': 'BTC-USD', 'changes': [['sell', '38284.67', '0.00000000']], 'time': '2021-05-20T03:54:49.615839Z'}
{'type': 'l2update', 'product_id': 'BTC-USD', 'changes': [['sell', '38274.29', '0.04907184']], 'time': '2021-05-20T03:54:49.620915Z'}
{'type': 'l2update', 'product_id': 'BTC-USD', 'changes': [['sell', '38274.29', '0.00000000']], 'time': '2021-05-20T03:54:49.621988Z'}
{'type': 'l2update', 'product_id': 'BTC-USD', 'changes': [['buy', '38240.83', '0.00000000']], 'time': '2021-05-20T03:54:49.627225Z'}
{'type': 'l2update', 'product_id': 'BTC-USD', 'changes': [['sell', '38281.39', '0.00000000']], 'time': '2021-05-20T03:54:49.627225Z'}
{'type': 'l2update', 'product_id': 'BTC-USD', 'changes': [['sell', '38508.47', '0.00000000']], 'time': '2021-05-20T03:54:49.629934Z'}
{'type': 'l2update', 'product_id': 'BTC-USD', 'changes': [['sell', '38289.45', '0.05000000']], 'time': '2021-05-20T03:54:49.631939Z'}
{'type': 'l2update', 'product_id': 'BTC-USD', 'changes': [['sell', '38430.84', '0.01000000']], 'time': '2021-05-20T03:54:49.632180Z'}
{'type': 'l2update', 'product_id': 'BTC-USD', 'changes': [['sell', '38278.02', '0.00600000']], 'time': '2021-05-20T03:54:49.634265Z'}
{'type': 'l2update', 'product_id': 'BTC-USD', 'changes': [['sell', '38274.55', '0.36249352']], 'time': '2021-05-20T03:54:49.638799Z'}
{'type': 'l2update', 'product_id': 'BTC-USD', 'changes': [['sell', '38430.84', '0.00000000']], 'time': '2021-05-20T03:54:49.641184Z'}
{'type': 'l2update', 'product_id': 'BTC-USD', 'changes': [['sell', '38493.48', '0.01298921']], 'time': '2021-05-20T03:54:49.641803Z'}
{'type': 'l2update', 'product_id': 'BTC-USD', 'changes': [['buy', '38264.04', '0.07460000']], 'time': '2021-05-20T03:54:49.645628Z'}
{'type': 'l2update', 'product_id': 'BTC-USD', 'changes': [['buy', '38206.58', '1.54700000']], 'time': '2021-05-20T03:54:49.645669Z'}
{'type': 'l2update', 'product_id': 'BTC-USD', 'changes': [['buy', '38263.59', '0.00000000']], 'time': '2021-05-20T03:54:49.652766Z'}
{'type': 'l2update', 'product_id': 'BTC-USD', 'changes': [['sell', '38418.72', '0.01000000']], 'time': '2021-05-20T03:54:49.653485Z'}
{'type': 'l2update', 'product_id': 'BTC-USD', 'changes': [['buy', '38240.28', '0.05265034']], 'time': '2021-05-20T03:54:49.653505Z'}
{'type': 'l2update', 'product_id': 'BTC-USD', 'changes': [['sell', '38280.84', '0.04803467']], 'time': '2021-05-20T03:54:49.653505Z'}
{'type': 'l2update', 'product_id': 'BTC-USD', 'changes': [['sell', '38273.64', '0.07460000']], 'time': '2021-05-20T03:54:49.657495Z'}
{'type': 'l2update', 'product_id': 'BTC-USD', 'changes': [['sell', '38273.98', '0.00000000']], 'time': '2021-05-20T03:54:49.665829Z'}
{'type': 'l2update', 'product_id': 'BTC-USD', 'changes': [['buy', '38264.70', '0.01492000']], 'time': '2021-05-20T03:54:49.673583Z'}
{'type': 'l2update', 'product_id': 'BTC-USD', 'changes': [['sell', '38297.82', '0.49220000']], 'time': '2021-05-20T03:54:49.673822Z'}
{'type': 'l2update', 'product_id': 'BTC-USD', 'changes': [['buy', '38241.40', '0.00000000']], 'time': '2021-05-20T03:54:49.678847Z'}
{'type': 'l2update', 'product_id': 'BTC-USD', 'changes': [['buy', '38264.04', '0.00000000']], 'time': '2021-05-20T03:54:49.679000Z'}
{'type': 'l2update', 'product_id': 'BTC-USD', 'changes': [['sell', '38273.32', '0.01492000']], 'time': '2021-05-20T03:54:49.682241Z'}
{'type': 'l2update', 'product_id': 'BTC-USD', 'changes': [['buy', '38264.70', '0.00000000']], 'time': '2021-05-20T03:54:49.688669Z'}
{'type': 'l2update', 'product_id': 'BTC-USD', 'changes': [['buy', '38240.02', '0.49310000']], 'time': '2021-05-20T03:54:49.691586Z'}
{'type': 'l2update', 'product_id': 'BTC-USD', 'changes': [['buy', '38265.29', '0.07460000']], 'time': '2021-05-20T03:54:49.695027Z'}
{'type': 'l2update', 'product_id': 'BTC-USD', 'changes': [['sell', '38375.59', '0.00000000']], 'time': '2021-05-20T03:54:49.699332Z'}
{'type': 'l2update', 'product_id': 'BTC-USD', 'changes': [['buy', '38265.29', '0.00000000']], 'time': '2021-05-20T03:54:49.699889Z'}
{'type': 'l2update', 'product_id': 'BTC-USD', 'changes': [['sell', '38273.64', '0.00000000']], 'time': '2021-05-20T03:54:49.701280Z'}
{'type': 'l2update', 'product_id': 'BTC-USD', 'changes': [['buy', '38263.50', '0.01492000']], 'time': '2021-05-20T03:54:49.702803Z'}
{'type': 'l2update', 'product_id': 'BTC-USD', 'changes': [['buy', '38170.09', '0.00000000']], 'time': '2021-05-20T03:54:49.703022Z'}
{'type': 'l2update', 'product_id': 'BTC-USD', 'changes': [['buy', '38260.83', '0.19051830']], 'time': '2021-05-20T03:54:49.703209Z'}
{'type': 'l2update', 'product_id': 'BTC-USD', 'changes': [['buy', '38263.50', '0.00000000']], 'time': '2021-05-20T03:54:49.707836Z'}
{'type': 'l2update', 'product_id': 'BTC-USD', 'changes': [['sell', '38273.32', '0.00000000']], 'time': '2021-05-20T03:54:49.709495Z'}
{'type': 'l2update', 'product_id': 'BTC-USD', 'changes': [['sell', '38405.23', '0.02733011']], 'time': '2021-05-20T03:54:49.711402Z'}
{'type': 'l2update', 'product_id': 'BTC-USD', 'changes': [['sell', '38364.60', '0.00000000']], 'time': '2021-05-20T03:54:49.713634Z'}
{'type': 'l2update', 'product_id': 'BTC-USD', 'changes': [['sell', '38439.96', '0.00000000']], 'time': '2021-05-20T03:54:49.713763Z'}
{'type': 'l2update', 'product_id': 'BTC-USD', 'changes': [['sell', '38272.67', '0.07460000']], 'time': '2021-05-20T03:54:49.714456Z'}
{'type': 'l2update', 'product_id': 'BTC-USD', 'changes': [['sell', '38289.45', '0.17905773']], 'time': '2021-05-20T03:54:49.714618Z'}
{'type': 'l2update', 'product_id': 'BTC-USD', 'changes': [['buy', '38263.40', '0.07460000']], 'time': '2021-05-20T03:54:49.714660Z'}
{'type': 'l2update', 'product_id': 'BTC-USD', 'changes': [['buy', '38257.68', '0.00000000']], 'time': '2021-05-20T03:54:49.716688Z'}
{'type': 'l2update', 'product_id': 'BTC-USD', 'changes': [['buy', '38253.35', '0.22867204']], 'time': '2021-05-20T03:54:49.718824Z'}
{'type': 'l2update', 'product_id': 'BTC-USD', 'changes': [['sell', '38272.67', '0.00000000']], 'time': '2021-05-20T03:54:49.719610Z'}
{'type': 'l2update', 'product_id': 'BTC-USD', 'changes': [['buy', '38263.40', '0.00000000']], 'time': '2021-05-20T03:54:49.719976Z'}
{'type': 'l2update', 'product_id': 'BTC-USD', 'changes': [['buy', '38240.42', '0.17400000']], 'time': '2021-05-20T03:54:49.722539Z'}
{'type': 'l2update', 'product_id': 'BTC-USD', 'changes': [['buy', '38263.22', '0.01492000']], 'time': '2021-05-20T03:54:49.722883Z'}
{'type': 'l2update', 'product_id': 'BTC-USD', 'changes': [['sell', '38419.85', '0.01000000']], 'time': '2021-05-20T03:54:49.726382Z'}
{'type': 'l2update', 'product_id': 'BTC-USD', 'changes': [['sell', '38272.19', '0.01492000']], 'time': '2021-05-20T03:54:49.726425Z'}
{'type': 'l2update', 'product_id': 'BTC-USD', 'changes': [['buy', '38263.22', '0.00000000']], 'time': '2021-05-20T03:54:49.730767Z'}
{'type': 'l2update', 'product_id': 'BTC-USD', 'changes': [['sell', '38273.87', '0.07460000']], 'time': '2021-05-20T03:54:49.730925Z'}
{'type': 'l2update', 'product_id': 'BTC-USD', 'changes': [['sell', '38272.19', '0.00000000']], 'time': '2021-05-20T03:54:49.731990Z'}
{'type': 'l2update', 'product_id': 'BTC-USD', 'changes': [['sell', '38273.87', '0.00000000']], 'time': '2021-05-20T03:54:49.736647Z'}
{'type': 'l2update', 'product_id': 'BTC-USD', 'changes': [['sell', '50776.85', '0.00486600']], 'time': '2021-05-20T03:54:49.738426Z'}
{'type': 'l2update', 'product_id': 'BTC-USD', 'changes': [['buy', '37500.01', '0.06200000']], 'time': '2021-05-20T03:54:49.740618Z'}
{'type': 'l2update', 'product_id': 'BTC-USD', 'changes': [['sell', '39236.99', '0.06130000']], 'time': '2021-05-20T03:54:49.740618Z'}
{'type': 'l2update', 'product_id': 'BTC-USD', 'changes': [['buy', '38263.17', '0.07460000']], 'time': '2021-05-20T03:54:49.742120Z'}
{'type': 'l2update', 'product_id': 'BTC-USD', 'changes': [['buy', '38263.42', '0.01492000']], 'time': '2021-05-20T03:54:49.746135Z'}
{'type': 'l2update', 'product_id': 'BTC-USD', 'changes': [['sell', '39495.99', '0.02510000']], 'time': '2021-05-20T03:54:49.746234Z'}
{'type': 'l2update', 'product_id': 'BTC-USD', 'changes': [['buy', '37500.01', '0.07230000']], 'time': '2021-05-20T03:54:49.746234Z'}
{'type': 'l2update', 'product_id': 'BTC-USD', 'changes': [['sell', '38273.42', '0.01492000']], 'time': '2021-05-20T03:54:49.746265Z'}
{'type': 'l2update', 'product_id': 'BTC-USD', 'changes': [['sell', '38274.25', '0.07460000']], 'time': '2021-05-20T03:54:49.746335Z'}
{'type': 'l2update', 'product_id': 'BTC-USD', 'changes': [['buy', '38263.17', '0.00000000']], 'time': '2021-05-20T03:54:49.747091Z'}
{'type': 'l2update', 'product_id': 'BTC-USD', 'changes': [['sell', '38273.42', '0.00000000']], 'time': '2021-05-20T03:54:49.752271Z'}
{'type': 'l2update', 'product_id': 'BTC-USD', 'changes': [['sell', '38274.25', '0.00000000']], 'time': '2021-05-20T03:54:49.752707Z'}
{'type': 'l2update', 'product_id': 'BTC-USD', 'changes': [['sell', '38280.00', '0.00000000']], 'time': '2021-05-20T03:54:49.753545Z'}
{'type': 'l2update', 'product_id': 'BTC-USD', 'changes': [['sell', '38274.55', '0.00000000']], 'time': '2021-05-20T03:54:49.754651Z'}
{'type': 'l2update', 'product_id': 'BTC-USD', 'changes': [['buy', '38263.99', '0.07460000']], 'time': '2021-05-20T03:54:49.762726Z'}
{'type': 'l2update', 'product_id': 'BTC-USD', 'changes': [['sell', '38274.23', '0.07460000']], 'time': '2021-05-20T03:54:49.767506Z'}
{'type': 'l2update', 'product_id': 'BTC-USD', 'changes': [['sell', '38273.94', '0.01492000']], 'time': '2021-05-20T03:54:49.768272Z'}
{'type': 'l2update', 'product_id': 'BTC-USD', 'changes': [['buy', '38263.42', '0.00000000']], 'time': '2021-05-20T03:54:49.769128Z'}
{'type': 'l2update', 'product_id': 'BTC-USD', 'changes': [['sell', '38274.23', '0.00000000']], 'time': '2021-05-20T03:54:49.774159Z'}
{'type': 'l2update', 'product_id': 'BTC-USD', 'changes': [['sell', '38274.55', '0.36249352']], 'time': '2021-05-20T03:54:49.774492Z'}
{'type': 'l2update', 'product_id': 'BTC-USD', 'changes': [['sell', '38274.11', '0.05464385']], 'time': '2021-05-20T03:54:49.774502Z'}
{'type': 'l2update', 'product_id': 'BTC-USD', 'changes': [['buy', '38263.99', '0.00000000']], 'time': '2021-05-20T03:54:49.785752Z'}
{'type': 'l2update', 'product_id': 'BTC-USD', 'changes': [['buy', '38264.61', '0.01492000']], 'time': '2021-05-20T03:54:49.790096Z'}
{'type': 'l2update', 'product_id': 'BTC-USD', 'changes': [['sell', '38273.36', '0.07460000']], 'time': '2021-05-20T03:54:49.793785Z'}
{'type': 'l2update', 'product_id': 'BTC-USD', 'changes': [['sell', '38419.85', '0.00000000']], 'time': '2021-05-20T03:54:49.793950Z'}
{'type': 'l2update', 'product_id': 'BTC-USD', 'changes': [['sell', '39000.00', '7.21185852']], 'time': '2021-05-20T03:54:49.794694Z'}
{'type': 'l2update', 'product_id': 'BTC-USD', 'changes': [['buy', '38264.61', '0.00000000']], 'time': '2021-05-20T03:54:49.794776Z'}
{'type': 'l2update', 'product_id': 'BTC-USD', 'changes': [['sell', '38280.84', '0.00000000']], 'time': '2021-05-20T03:54:49.795900Z'}
{'type': 'l2update', 'product_id': 'BTC-USD', 'changes': [['buy', '38253.28', '0.00000000']], 'time': '2021-05-20T03:54:49.795933Z'}
{'type': 'l2update', 'product_id': 'BTC-USD', 'changes': [['buy', '38250.05', '0.00000000']], 'time': '2021-05-20T03:54:49.796547Z'}
{'type': 'l2update', 'product_id': 'BTC-USD', 'changes': [['buy', '38263.54', '0.07460000']], 'time': '2021-05-20T03:54:49.797511Z'}
{'type': 'l2update', 'product_id': 'BTC-USD', 'changes': [['sell', '38273.94', '0.00000000']], 'time': '2021-05-20T03:54:49.799753Z'}
{'type': 'l2update', 'product_id': 'BTC-USD', 'changes': [['sell', '38433.12', '0.00000000']], 'time': '2021-05-20T03:54:49.800689Z'}
{'type': 'l2update', 'product_id': 'BTC-USD', 'changes': [['sell', '38394.77', '0.00000000']], 'time': '2021-05-20T03:54:49.800689Z'}
{'type': 'l2update', 'product_id': 'BTC-USD', 'changes': [['buy', '38156.50', '0.00000000']], 'time': '2021-05-20T03:54:49.800689Z'}
{'type': 'l2update', 'product_id': 'BTC-USD', 'changes': [['buy', '38194.75', '0.00000000']], 'time': '2021-05-20T03:54:49.800689Z'}
{'type': 'l2update', 'product_id': 'BTC-USD', 'changes': [['buy', '38213.88', '0.00000000']], 'time': '2021-05-20T03:54:49.800689Z'}
{'type': 'l2update', 'product_id': 'BTC-USD', 'changes': [['buy', '38263.54', '0.00000000']], 'time': '2021-05-20T03:54:49.802332Z'}
{'type': 'l2update', 'product_id': 'BTC-USD', 'changes': [['buy', '38263.29', '0.01492000']], 'time': '2021-05-20T03:54:49.805326Z'}
{'type': 'l2update', 'product_id': 'BTC-USD', 'changes': [['sell', '38433.04', '0.01000000']], 'time': '2021-05-20T03:54:49.805357Z'}
{'type': 'l2update', 'product_id': 'BTC-USD', 'changes': [['buy', '38253.40', '0.84800000']], 'time': '2021-05-20T03:54:49.805766Z'}
{'type': 'l2update', 'product_id': 'BTC-USD', 'changes': [['buy', '38238.57', '0.00000000']], 'time': '2021-05-20T03:54:49.808872Z'}
{'type': 'l2update', 'product_id': 'BTC-USD', 'changes': [['buy', '38237.57', '0.00000000']], 'time': '2021-05-20T03:54:49.808872Z'}
{'type': 'l2update', 'product_id': 'BTC-USD', 'changes': [['buy', '38263.29', '0.00000000']], 'time': '2021-05-20T03:54:49.809814Z'}
{'type': 'l2update', 'product_id': 'BTC-USD', 'changes': [['buy', '38253.35', '0.00000000']], 'time': '2021-05-20T03:54:49.812497Z'}
{'type': 'l2update', 'product_id': 'BTC-USD', 'changes': [['buy', '38263.58', '0.07460000']], 'time': '2021-05-20T03:54:49.813315Z'}
{'type': 'l2update', 'product_id': 'BTC-USD', 'changes': [['sell', '38280.79', '0.00000000']], 'time': '2021-05-20T03:54:49.816295Z'}
{'type': 'l2update', 'product_id': 'BTC-USD', 'changes': [['sell', '38287.39', '0.05974589']], 'time': '2021-05-20T03:54:49.817292Z'}
{'type': 'l2update', 'product_id': 'BTC-USD', 'changes': [['buy', '38263.43', '0.01492000']], 'time': '2021-05-20T03:54:49.821145Z'}
{'type': 'l2update', 'product_id': 'BTC-USD', 'changes': [['buy', '38235.90', '0.02400000']], 'time': '2021-05-20T03:54:49.821219Z'}
{'type': 'l2update', 'product_id': 'BTC-USD', 'changes': [['buy', '38235.10', '0.02400000']], 'time': '2021-05-20T03:54:49.821219Z'}
{'type': 'l2update', 'product_id': 'BTC-USD', 'changes': [['buy', '38260.83', '0.18875301']], 'time': '2021-05-20T03:54:49.822196Z'}
{'type': 'l2update', 'product_id': 'BTC-USD', 'changes': [['buy', '38253.40', '0.00000000']], 'time': '2021-05-20T03:54:49.824133Z'}
{'type': 'l2update', 'product_id': 'BTC-USD', 'changes': [['buy', '38250.85', '0.00000000']], 'time': '2021-05-20T03:54:49.825814Z'}
{'type': 'l2update', 'product_id': 'BTC-USD', 'changes': [['buy', '38263.43', '0.00000000']], 'time': '2021-05-20T03:54:49.826752Z'}
{'type': 'l2update', 'product_id': 'BTC-USD', 'changes': [['buy', '38253.34', '0.00000000']], 'time': '2021-05-20T03:54:49.827912Z'}
{'type': 'l2update', 'product_id': 'BTC-USD', 'changes': [['buy', '38237.04', '0.00000000']], 'time': '2021-05-20T03:54:49.829150Z'}
{'type': 'l2update', 'product_id': 'BTC-USD', 'changes': [['buy', '38236.33', '0.00000000']], 'time': '2021-05-20T03:54:49.834207Z'}
{'type': 'l2update', 'product_id': 'BTC-USD', 'changes': [['buy', '38235.90', '0.00000000']], 'time': '2021-05-20T03:54:49.834207Z'}
{'type': 'l2update', 'product_id': 'BTC-USD', 'changes': [['sell', '38279.82', '0.00000000']], 'time': '2021-05-20T03:54:49.834904Z'}
{'type': 'l2update', 'product_id': 'BTC-USD', 'changes': [['buy', '38253.35', '0.22867204']], 'time': '2021-05-20T03:54:49.835963Z'}
{'type': 'l2update', 'product_id': 'BTC-USD', 'changes': [['sell', '38441.08', '0.66500000']], 'time': '2021-05-20T03:54:49.839885Z'}
{'type': 'l2update', 'product_id': 'BTC-USD', 'changes': [['buy', '38153.36', '0.66500000']], 'time': '2021-05-20T03:54:49.839885Z'}
{'type': 'l2update', 'product_id': 'BTC-USD', 'changes': [['buy', '38191.61', '0.20400000']], 'time': '2021-05-20T03:54:49.839885Z'}
{'type': 'l2update', 'product_id': 'BTC-USD', 'changes': [['buy', '38210.73', '0.06600000']], 'time': '2021-05-20T03:54:49.839885Z'}
{'type': 'l2update', 'product_id': 'BTC-USD', 'changes': [['sell', '38402.73', '0.20400000']], 'time': '2021-05-20T03:54:49.839885Z'}
{'type': 'l2update', 'product_id': 'BTC-USD', 'changes': [['buy', '38263.96', '0.01492000']], 'time': '2021-05-20T03:54:49.844438Z'}
{'type': 'l2update', 'product_id': 'BTC-USD', 'changes': [['buy', '38263.58', '0.00000000']], 'time': '2021-05-20T03:54:49.850167Z'}
{'type': 'l2update', 'product_id': 'BTC-USD', 'changes': [['buy', '38240.02', '0.00000000']], 'time': '2021-05-20T03:54:49.852429Z'}
{'type': 'l2update', 'product_id': 'BTC-USD', 'changes': [['buy', '38234.14', '0.02400000']], 'time': '2021-05-20T03:54:49.852978Z'}
{'type': 'l2update', 'product_id': 'BTC-USD', 'changes': [['buy', '38233.33', '0.02400000']], 'time': '2021-05-20T03:54:49.852978Z'}
{'type': 'l2update', 'product_id': 'BTC-USD', 'changes': [['sell', '38297.82', '0.00000000']], 'time': '2021-05-20T03:54:49.856109Z'}
{'type': 'l2update', 'product_id': 'BTC-USD', 'changes': [['buy', '38260.83', '0.19051830']], 'time': '2021-05-20T03:54:49.859763Z'}
{'type': 'l2update', 'product_id': 'BTC-USD', 'changes': [['sell', '38287.39', '0.00000000']], 'time': '2021-05-20T03:54:49.859816Z'}
{'type': 'l2update', 'product_id': 'BTC-USD', 'changes': [['buy', '38264.27', '0.07460000']], 'time': '2021-05-20T03:54:49.863285Z'}
{'type': 'l2update', 'product_id': 'BTC-USD', 'changes': [['sell', '38274.11', '0.00000000']], 'time': '2021-05-20T03:54:49.864800Z'}
{'type': 'l2update', 'product_id': 'BTC-USD', 'changes': [['buy', '38263.96', '0.00000000']], 'time': '2021-05-20T03:54:49.869737Z'}
{'type': 'l2update', 'product_id': 'BTC-USD', 'changes': [['sell', '38273.11', '0.01492000']], 'time': '2021-05-20T03:54:49.875554Z'}
{'type': 'l2update', 'product_id': 'BTC-USD', 'changes': [['sell', '38274.50', '1.07100000']], 'time': '2021-05-20T03:54:49.875581Z'}
{'type': 'l2update', 'product_id': 'BTC-USD', 'changes': [['buy', '38264.27', '0.00000000']], 'time': '2021-05-20T03:54:49.876027Z'}
{'type': 'l2update', 'product_id': 'BTC-USD', 'changes': [['sell', '38273.36', '0.00000000']], 'time': '2021-05-20T03:54:49.881993Z'}
{'type': 'l2update', 'product_id': 'BTC-USD', 'changes': [['sell', '38274.55', '0.00000000']], 'time': '2021-05-20T03:54:49.882491Z'}
{'type': 'l2update', 'product_id': 'BTC-USD', 'changes': [['buy', '38235.10', '0.00000000']], 'time': '2021-05-20T03:54:49.882668Z'}
{'type': 'l2update', 'product_id': 'BTC-USD', 'changes': [['sell', '38285.64', '0.06294597']], 'time': '2021-05-20T03:54:49.887207Z'}
{'type': 'l2update', 'product_id': 'BTC-USD', 'changes': [['buy', '38263.63', '0.07460000']], 'time': '2021-05-20T03:54:49.887395Z'}
{'type': 'l2update', 'product_id': 'BTC-USD', 'changes': [['buy', '38263.29', '0.01492000']], 'time': '2021-05-20T03:54:49.891426Z'}
{'type': 'l2update', 'product_id': 'BTC-USD', 'changes': [['sell', '38273.11', '0.00000000']], 'time': '2021-05-20T03:54:49.894124Z'}
{'type': 'l2update', 'product_id': 'BTC-USD', 'changes': [['sell', '38273.93', '0.05464385']], 'time': '2021-05-20T03:54:49.894620Z'}
{'type': 'l2update', 'product_id': 'BTC-USD', 'changes': [['buy', '38253.35', '0.00000000']], 'time': '2021-05-20T03:54:49.894663Z'}
{'type': 'l2update', 'product_id': 'BTC-USD', 'changes': [['buy', '38232.01', '0.02400000']], 'time': '2021-05-20T03:54:49.894689Z'}
{'type': 'l2update', 'product_id': 'BTC-USD', 'changes': [['buy', '38263.29', '0.00000000']], 'time': '2021-05-20T03:54:49.896680Z'}
{'type': 'l2update', 'product_id': 'BTC-USD', 'changes': [['sell', '38272.71', '0.07460000']], 'time': '2021-05-20T03:54:49.898895Z'}
{'type': 'l2update', 'product_id': 'BTC-USD', 'changes': [['sell', '38272.71', '0.00000000']], 'time': '2021-05-20T03:54:49.903673Z'}
{'type': 'l2update', 'product_id': 'BTC-USD', 'changes': [['sell', '38274.49', '0.36249352']], 'time': '2021-05-20T03:54:49.904685Z'}
{'type': 'l2update', 'product_id': 'BTC-USD', 'changes': [['sell', '38273.85', '0.01492000']], 'time': '2021-05-20T03:54:49.913087Z'}
{'type': 'l2update', 'product_id': 'BTC-USD', 'changes': [['buy', '38245.90', '0.22867204']], 'time': '2021-05-20T03:54:49.916579Z'}
{'type': 'l2update', 'product_id': 'BTC-USD', 'changes': [['sell', '38273.29', '0.07460000']], 'time': '2021-05-20T03:54:49.917046Z'}
{'type': 'l2update', 'product_id': 'BTC-USD', 'changes': [['buy', '31348.00', '0.00700000']], 'time': '2021-05-20T03:54:49.917481Z'}
{'type': 'l2update', 'product_id': 'BTC-USD', 'changes': [['sell', '38273.85', '0.00000000']], 'time': '2021-05-20T03:54:49.917863Z'}
{'type': 'l2update', 'product_id': 'BTC-USD', 'changes': [['buy', '38264.09', '0.01492000']], 'time': '2021-05-20T03:54:49.925155Z'}
{'type': 'l2update', 'product_id': 'BTC-USD', 'changes': [['buy', '38263.63', '0.00000000']], 'time': '2021-05-20T03:54:49.931279Z'}
{'type': 'l2update', 'product_id': 'BTC-USD', 'changes': [['sell', '50780.49', '0.00420900']], 'time': '2021-05-20T03:54:49.933591Z'}
{'type': 'l2update', 'product_id': 'BTC-USD', 'changes': [['sell', '38272.60', '0.01492000']], 'time': '2021-05-20T03:54:49.934285Z'}
{'type': 'l2update', 'product_id': 'BTC-USD', 'changes': [['sell', '38379.98', '0.00000000']], 'time': '2021-05-20T03:54:49.936584Z'}
{'type': 'l2update', 'product_id': 'BTC-USD', 'changes': [['sell', '38273.29', '0.00000000']], 'time': '2021-05-20T03:54:49.940814Z'}
{'type': 'l2update', 'product_id': 'BTC-USD', 'changes': [['sell', '38365.56', '0.12274586']], 'time': '2021-05-20T03:54:49.941209Z'}
{'type': 'l2update', 'product_id': 'BTC-USD', 'changes': [['buy', '38240.06', '0.43240000']], 'time': '2021-05-20T03:54:49.941342Z'}
{'type': 'l2update', 'product_id': 'BTC-USD', 'changes': [['sell', '38277.50', '0.52284398']], 'time': '2021-05-20T03:54:49.945773Z'}
{'type': 'l2update', 'product_id': 'BTC-USD', 'changes': [['sell', '38406.52', '0.01000000']], 'time': '2021-05-20T03:54:49.950003Z'}
{'type': 'l2update', 'product_id': 'BTC-USD', 'changes': [['buy', '38264.39', '0.07460000']], 'time': '2021-05-20T03:54:49.950116Z'}
{'type': 'l2update', 'product_id': 'BTC-USD', 'changes': [['sell', '38403.13', '0.00000000']], 'time': '2021-05-20T03:54:49.951744Z'}
{'type': 'l2update', 'product_id': 'BTC-USD', 'changes': [['sell', '38299.25', '0.45930000']], 'time': '2021-05-20T03:54:49.953483Z'}
{'type': 'l2update', 'product_id': 'BTC-USD', 'changes': [['sell', '38272.60', '0.00000000']], 'time': '2021-05-20T03:54:49.954002Z'}
{'type': 'l2update', 'product_id': 'BTC-USD', 'changes': [['buy', '38264.09', '0.00000000']], 'time': '2021-05-20T03:54:49.956570Z'}
{'type': 'l2update', 'product_id': 'BTC-USD', 'changes': [['buy', '38272.55', '0.15000000']], 'time': '2021-05-20T03:54:49.957078Z'}
{'type': 'l2update', 'product_id': 'BTC-USD', 'changes': [['buy', '38249.69', '0.52282717']], 'time': '2021-05-20T03:54:49.957235Z'}
{'type': 'l2update', 'product_id': 'BTC-USD', 'changes': [['buy', '38200.01', '0.00000000']], 'time': '2021-05-20T03:54:49.965497Z'}
{'type': 'l2update', 'product_id': 'BTC-USD', 'changes': [['sell', '38290.44', '0.00000000']], 'time': '2021-05-20T03:54:49.966539Z'}
{'type': 'l2update', 'product_id': 'BTC-USD', 'changes': [['sell', '38281.35', '0.52279655']], 'time': '2021-05-20T03:54:49.967869Z'}
{'type': 'l2update', 'product_id': 'BTC-USD', 'changes': [['sell', '38272.56', '0.10000000']], 'time': '2021-05-20T03:54:49.968032Z'}
{'type': 'l2update', 'product_id': 'BTC-USD', 'changes': [['sell', '38273.63', '0.01492000']], 'time': '2021-05-20T03:54:49.968327Z'}
{'type': 'l2update', 'product_id': 'BTC-USD', 'changes': [['buy', '38260.83', '0.18051830']], 'time': '2021-05-20T03:54:49.968603Z'}
{'type': 'l2update', 'product_id': 'BTC-USD', 'changes': [['sell', '38289.45', '0.12905773']], 'time': '2021-05-20T03:54:49.969167Z'}
{'type': 'l2update', 'product_id': 'BTC-USD', 'changes': [['buy', '38264.39', '0.00000000']], 'time': '2021-05-20T03:54:49.970160Z'}
{'type': 'l2update', 'product_id': 'BTC-USD', 'changes': [['buy', '38260.83', '0.16310430']], 'time': '2021-05-20T03:54:49.974319Z'}
{'type': 'l2update', 'product_id': 'BTC-USD', 'changes': [['sell', '38273.63', '0.00000000']], 'time': '2021-05-20T03:54:49.974592Z'}
{'type': 'l2update', 'product_id': 'BTC-USD', 'changes': [['buy', '38185.21', '0.65954123']], 'time': '2021-05-20T03:54:49.978054Z'}
{'type': 'l2update', 'product_id': 'BTC-USD', 'changes': [['buy', '38260.83', '0.13310430']], 'time': '2021-05-20T03:54:49.979756Z'}
{'type': 'l2update', 'product_id': 'BTC-USD', 'changes': [['buy', '38233.04', '0.78426597']], 'time': '2021-05-20T03:54:49.982436Z'}
{'type': 'l2update', 'product_id': 'BTC-USD', 'changes': [['sell', '38273.93', '0.25464385']], 'time': '2021-05-20T03:54:49.982542Z'}
{'type': 'l2update', 'product_id': 'BTC-USD', 'changes': [['sell', '38295.81', '0.05000000']], 'time': '2021-05-20T03:54:49.982553Z'}
{'type': 'l2update', 'product_id': 'BTC-USD', 'changes': [['sell', '38406.52', '0.00000000']], 'time': '2021-05-20T03:54:49.982756Z'}
{'type': 'l2update', 'product_id': 'BTC-USD', 'changes': [['buy', '38260.83', '0.09310430']], 'time': '2021-05-20T03:54:49.983644Z'}
{'type': 'l2update', 'product_id': 'BTC-USD', 'changes': [['sell', '38349.44', '0.16090000']], 'time': '2021-05-20T03:54:49.986452Z'}
{'type': 'l2update', 'product_id': 'BTC-USD', 'changes': [['buy', '38260.83', '0.04310430']], 'time': '2021-05-20T03:54:49.989806Z'}
{'type': 'l2update', 'product_id': 'BTC-USD', 'changes': [['sell', '38383.70', '0.01000000']], 'time': '2021-05-20T03:54:49.990683Z'}
{'type': 'l2update', 'product_id': 'BTC-USD', 'changes': [['sell', '38274.49', '0.00000000']], 'time': '2021-05-20T03:54:49.990792Z'}
{'type': 'l2update', 'product_id': 'BTC-USD', 'changes': [['buy', '38245.90', '0.00000000']], 'time': '2021-05-20T03:54:49.995482Z'}
{'type': 'l2update', 'product_id': 'BTC-USD', 'changes': [['sell', '38315.67', '2.61421988']], 'time': '2021-05-20T03:54:49.996945Z'}
{'type': 'l2update', 'product_id': 'BTC-USD', 'changes': [['sell', '38404.26', '0.01301939']], 'time': '2021-05-20T03:54:49.997037Z'}
{'type': 'l2update', 'product_id': 'BTC-USD', 'changes': [['buy', '38217.28', '0.00000000']], 'time': '2021-05-20T03:54:49.999818Z'}
{'type': 'l2update', 'product_id': 'BTC-USD', 'changes': [['buy', '38272.55', '0.16000000']], 'time': '2021-05-20T03:54:50.001125Z'}
{'type': 'l2update', 'product_id': 'BTC-USD', 'changes': [['sell', '38433.04', '0.00000000']], 'time': '2021-05-20T03:54:50.004918Z'}
{'type': 'l2update', 'product_id': 'BTC-USD', 'changes': [['sell', '38273.92', '0.36249352']], 'time': '2021-05-20T03:54:50.012097Z'}
{'type': 'l2update', 'product_id': 'BTC-USD', 'changes': [['buy', '38272.55', '0.18000000']], 'time': '2021-05-20T03:54:50.012388Z'}
{'type': 'l2update', 'product_id': 'BTC-USD', 'changes': [['buy', '38250.01', '0.22867204']], 'time': '2021-05-20T03:54:50.015471Z'}
{'type': 'l2update', 'product_id': 'BTC-USD', 'changes': [['sell', '38273.93', '0.05464385']], 'time': '2021-05-20T03:54:50.016887Z'}
{'type': 'l2update', 'product_id': 'BTC-USD', 'changes': [['sell', '38405.23', '0.00000000']], 'time': '2021-05-20T03:54:50.018739Z'}
{'type': 'l2update', 'product_id': 'BTC-USD', 'changes': [['buy', '38253.28', '0.84700000']], 'time': '2021-05-20T03:54:50.019810Z'}
{'type': 'l2update', 'product_id': 'BTC-USD', 'changes': [['buy', '38272.55', '0.21000000']], 'time': '2021-05-20T03:54:50.023413Z'}
{'type': 'l2update', 'product_id': 'BTC-USD', 'changes': [['sell', '38419.85', '0.01000000']], 'time': '2021-05-20T03:54:50.027520Z'}
{'type': 'l2update', 'product_id': 'BTC-USD', 'changes': [['sell', '38392.62', '0.02733011']], 'time': '2021-05-20T03:54:50.031071Z'}
{'type': 'l2update', 'product_id': 'BTC-USD', 'changes': [['buy', '38272.55', '0.25000000']], 'time': '2021-05-20T03:54:50.035055Z'}
{'type': 'l2update', 'product_id': 'BTC-USD', 'changes': [['buy', '38272.55', '0.30000000']], 'time': '2021-05-20T03:54:50.047096Z'}
{'type': 'l2update', 'product_id': 'BTC-USD', 'changes': [['sell', '38273.92', '0.00000000']], 'time': '2021-05-20T03:54:50.061509Z'}
{'type': 'l2update', 'product_id': 'BTC-USD', 'changes': [['buy', '38260.83', '0.04133901']], 'time': '2021-05-20T03:54:50.071369Z'}
{'type': 'l2update', 'product_id': 'BTC-USD', 'changes': [['buy', '38250.01', '0.00000000']], 'time': '2021-05-20T03:54:50.089576Z'}
{'type': 'l2update', 'product_id': 'BTC-USD', 'changes': [['sell', '38274.49', '0.36249352']], 'time': '2021-05-20T03:54:50.104946Z'}
{'type': 'l2update', 'product_id': 'BTC-USD', 'changes': [['sell', '50780.64', '0.00296600']], 'time': '2021-05-20T03:54:50.112941Z'}
{'type': 'l2update', 'product_id': 'BTC-USD', 'changes': [['buy', '38253.29', '0.22867204']], 'time': '2021-05-20T03:54:50.121917Z'}
{'type': 'l2update', 'product_id': 'BTC-USD', 'changes': [['buy', '38262.94', '0.05296673']], 'time': '2021-05-20T03:54:50.126236Z'}
{'type': 'l2update', 'product_id': 'BTC-USD', 'changes': [['sell', '39607.33', '0.24200000']], 'time': '2021-05-20T03:54:50.143303Z'}
{'type': 'l2update', 'product_id': 'BTC-USD', 'changes': [['buy', '38242.91', '0.00000000']], 'time': '2021-05-20T03:54:50.156473Z'}
{'type': 'l2update', 'product_id': 'BTC-USD', 'changes': [['buy', '38216.56', '0.00000000']], 'time': '2021-05-20T03:54:50.175929Z'}
{'type': 'l2update', 'product_id': 'BTC-USD', 'changes': [['sell', '38274.57', '0.00000000']], 'time': '2021-05-20T03:54:50.181312Z'}
{'type': 'l2update', 'product_id': 'BTC-USD', 'changes': [['sell', '38272.56', '0.30000000']], 'time': '2021-05-20T03:54:50.185386Z'}
{'type': 'l2update', 'product_id': 'BTC-USD', 'changes': [['buy', '38272.55', '0.15000000']], 'time': '2021-05-20T03:54:50.189468Z'}
{'type': 'l2update', 'product_id': 'BTC-USD', 'changes': [['buy', '38240.06', '0.00000000']], 'time': '2021-05-20T03:54:50.201865Z'}
{'type': 'l2update', 'product_id': 'BTC-USD', 'changes': [['sell', '38285.64', '0.00000000']], 'time': '2021-05-20T03:54:50.209026Z'}
{'type': 'l2update', 'product_id': 'BTC-USD', 'changes': [['buy', '38250.01', '0.06399492']], 'time': '2021-05-20T03:54:50.223467Z'}
{'type': 'l2update', 'product_id': 'BTC-USD', 'changes': [['buy', '38240.42', '0.00000000']], 'time': '2021-05-20T03:54:50.227819Z'}
{'type': 'l2update', 'product_id': 'BTC-USD', 'changes': [['buy', '38196.44', '0.00000000']], 'time': '2021-05-20T03:54:50.234240Z'}
{'type': 'l2update', 'product_id': 'BTC-USD', 'changes': [['buy', '38272.55', '0.14000000']], 'time': '2021-05-20T03:54:50.236708Z'}
{'type': 'l2update', 'product_id': 'BTC-USD', 'changes': [['buy', '38272.55', '0.12000000']], 'time': '2021-05-20T03:54:50.236708Z'}
{'type': 'l2update', 'product_id': 'BTC-USD', 'changes': [['buy', '38272.55', '0.09877000']], 'time': '2021-05-20T03:54:50.236708Z'}
{'type': 'l2update', 'product_id': 'BTC-USD', 'changes': [['sell', '38303.78', '0.18600000']], 'time': '2021-05-20T03:54:50.237806Z'}
{'type': 'l2update', 'product_id': 'BTC-USD', 'changes': [['sell', '43100.00', '2.14740000']], 'time': '2021-05-20T03:54:50.238499Z'}
{'type': 'l2update', 'product_id': 'BTC-USD', 'changes': [['buy', '38210.56', '0.10000000']], 'time': '2021-05-20T03:54:50.238973Z'}
{'type': 'l2update', 'product_id': 'BTC-USD', 'changes': [['buy', '38219.06', '0.05454008']], 'time': '2021-05-20T03:54:50.240406Z'}
{'type': 'l2update', 'product_id': 'BTC-USD', 'changes': [['sell', '38272.56', '2.78969908']], 'time': '2021-05-20T03:54:50.244600Z'}
{'type': 'l2update', 'product_id': 'BTC-USD', 'changes': [['sell', '39236.98', '0.00000000']], 'time': '2021-05-20T03:54:50.251459Z'}
{'type': 'l2update', 'product_id': 'BTC-USD', 'changes': [['sell', '39236.99', '0.00000000']], 'time': '2021-05-20T03:54:50.251459Z'}
{'type': 'l2update', 'product_id': 'BTC-USD', 'changes': [['buy', '38231.66', '0.49840000']], 'time': '2021-05-20T03:54:50.253122Z'}
{'type': 'l2update', 'product_id': 'BTC-USD', 'changes': [['sell', '38590.87', '0.34280000']], 'time': '2021-05-20T03:54:50.262237Z'}
{'type': 'l2update', 'product_id': 'BTC-USD', 'changes': [['sell', '38316.94', '0.00000000']], 'time': '2021-05-20T03:54:50.263721Z'}
{'type': 'l2update', 'product_id': 'BTC-USD', 'changes': [['sell', '38291.80', '0.06399492']], 'time': '2021-05-20T03:54:50.270110Z'}
{'type': 'l2update', 'product_id': 'BTC-USD', 'changes': [['sell', '38273.88', '0.57500000']], 'time': '2021-05-20T03:54:50.283470Z'}
{'type': 'l2update', 'product_id': 'BTC-USD', 'changes': [['sell', '38290.44', '0.06399492']], 'time': '2021-05-20T03:54:50.283879Z'}
{'type': 'l2update', 'product_id': 'BTC-USD', 'changes': [['buy', '38260.83', '0.01133901']], 'time': '2021-05-20T03:54:50.286798Z'}
{'type': 'l2update', 'product_id': 'BTC-USD', 'changes': [['sell', '38272.56', '3.43969908']], 'time': '2021-05-20T03:54:50.288296Z'}
{'type': 'l2update', 'product_id': 'BTC-USD', 'changes': [['sell', '50784.27', '0.00296600']], 'time': '2021-05-20T03:54:50.291660Z'}
{'type': 'l2update', 'product_id': 'BTC-USD', 'changes': [['sell', '38418.72', '0.00000000']], 'time': '2021-05-20T03:54:50.298100Z'}
{'type': 'l2update', 'product_id': 'BTC-USD', 'changes': [['buy', '38231.66', '0.00000000']], 'time': '2021-05-20T03:54:50.299492Z'}
{'type': 'l2update', 'product_id': 'BTC-USD', 'changes': [['buy', '38272.55', '0.09000000']], 'time': '2021-05-20T03:54:50.306010Z'}
{'type': 'l2update', 'product_id': 'BTC-USD', 'changes': [['sell', '39249.99', '0.06120000']], 'time': '2021-05-20T03:54:50.308816Z'}
{'type': 'l2update', 'product_id': 'BTC-USD', 'changes': [['sell', '39248.48', '0.04200000']], 'time': '2021-05-20T03:54:50.308816Z'}
{'type': 'l2update', 'product_id': 'BTC-USD', 'changes': [['sell', '38419.85', '0.00000000']], 'time': '2021-05-20T03:54:50.313482Z'}
{'type': 'l2update', 'product_id': 'BTC-USD', 'changes': [['sell', '38272.56', '0.95000000']], 'time': '2021-05-20T03:54:50.313661Z'}
{'type': 'l2update', 'product_id': 'BTC-USD', 'changes': [['buy', '38260.84', '0.00000000']], 'time': '2021-05-20T03:54:50.343117Z'}
{'type': 'l2update', 'product_id': 'BTC-USD', 'changes': [['sell', '38274.49', '0.00000000']], 'time': '2021-05-20T03:54:50.343871Z'}
{'type': 'l2update', 'product_id': 'BTC-USD', 'changes': [['sell', '38299.25', '0.00000000']], 'time': '2021-05-20T03:54:50.353648Z'}
{'type': 'l2update', 'product_id': 'BTC-USD', 'changes': [['buy', '38272.55', '0.05000000']], 'time': '2021-05-20T03:54:50.355247Z'}
{'type': 'l2update', 'product_id': 'BTC-USD', 'changes': [['buy', '38253.28', '0.00000000']], 'time': '2021-05-20T03:54:50.358128Z'}
{'type': 'l2update', 'product_id': 'BTC-USD', 'changes': [['buy', '38253.23', '0.00000000']], 'time': '2021-05-20T03:54:50.360164Z'}
{'type': 'l2update', 'product_id': 'BTC-USD', 'changes': [['buy', '38272.55', '0.00000000']], 'time': '2021-05-20T03:54:50.366880Z'}
{'type': 'l2update', 'product_id': 'BTC-USD', 'changes': [['sell', '38272.55', '0.04870000']], 'time': '2021-05-20T03:54:50.366880Z'}
{'type': 'l2update', 'product_id': 'BTC-USD', 'changes': [['buy', '38234.14', '0.00000000']], 'time': '2021-05-20T03:54:50.381413Z'}
{'type': 'l2update', 'product_id': 'BTC-USD', 'changes': [['sell', '38272.56', '0.85000000']], 'time': '2021-05-20T03:54:50.386583Z'}
{'type': 'l2update', 'product_id': 'BTC-USD', 'changes': [['buy', '38262.94', '0.05120144']], 'time': '2021-05-20T03:54:50.386680Z'}
{'type': 'l2update', 'product_id': 'BTC-USD', 'changes': [['buy', '38233.33', '0.00000000']], 'time': '2021-05-20T03:54:50.390896Z'}
{'type': 'l2update', 'product_id': 'BTC-USD', 'changes': [['sell', '38295.81', '0.00000000']], 'time': '2021-05-20T03:54:50.401495Z'}
{'type': 'l2update', 'product_id': 'BTC-USD', 'changes': [['sell', '38281.35', '0.00000000']], 'time': '2021-05-20T03:54:50.416307Z'}
{'type': 'l2update', 'product_id': 'BTC-USD', 'changes': [['buy', '38210.12', '1.28375874']], 'time': '2021-05-20T03:54:50.443251Z'}
{'type': 'l2update', 'product_id': 'BTC-USD', 'changes': [['buy', '38262.94', '0.05018116']], 'time': '2021-05-20T03:54:50.443412Z'}
{'type': 'l2update', 'product_id': 'BTC-USD', 'changes': [['sell', '38273.87', '0.36249352']], 'time': '2021-05-20T03:54:50.448913Z'}
{'type': 'l2update', 'product_id': 'BTC-USD', 'changes': [['buy', '38261.26', '0.01000000']], 'time': '2021-05-20T03:54:50.449045Z'}
{'type': 'l2update', 'product_id': 'BTC-USD', 'changes': [['buy', '38209.50', '0.11729604']], 'time': '2021-05-20T03:54:50.449960Z'}
{'type': 'l2update', 'product_id': 'BTC-USD', 'changes': [['sell', '38289.45', '0.17905773']], 'time': '2021-05-20T03:54:50.449982Z'}
{'type': 'l2update', 'product_id': 'BTC-USD', 'changes': [['buy', '38263.46', '0.01492000']], 'time': '2021-05-20T03:54:50.450487Z'}
{'type': 'l2update', 'product_id': 'BTC-USD', 'changes': [['buy', '38263.41', '0.07460000']], 'time': '2021-05-20T03:54:50.450876Z'}
{'type': 'l2update', 'product_id': 'BTC-USD', 'changes': [['buy', '38253.34', '0.84900000']], 'time': '2021-05-20T03:54:50.452716Z'}
{'type': 'l2update', 'product_id': 'BTC-USD', 'changes': [['sell', '38297.66', '0.48890000']], 'time': '2021-05-20T03:54:50.453490Z'}
{'type': 'l2update', 'product_id': 'BTC-USD', 'changes': [['sell', '38433.04', '0.01000000']], 'time': '2021-05-20T03:54:50.453814Z'}
{'type': 'l2update', 'product_id': 'BTC-USD', 'changes': [['sell', '38286.63', '0.04390419']], 'time': '2021-05-20T03:54:50.456322Z'}
{'type': 'l2update', 'product_id': 'BTC-USD', 'changes': [['buy', '38269.50', '0.15000000']], 'time': '2021-05-20T03:54:50.457154Z'}
{'type': 'l2update', 'product_id': 'BTC-USD', 'changes': [['sell', '38272.30', '0.01492000']], 'time': '2021-05-20T03:54:50.457386Z'}
{'type': 'l2update', 'product_id': 'BTC-USD', 'changes': [['sell', '38273.92', '2.48969908']], 'time': '2021-05-20T03:54:50.458175Z'}
{'type': 'l2update', 'product_id': 'BTC-USD', 'changes': [['sell', '38272.26', '0.07460000']], 'time': '2021-05-20T03:54:50.458212Z'}
{'type': 'l2update', 'product_id': 'BTC-USD', 'changes': [['buy', '38230.78', '0.02400000']], 'time': '2021-05-20T03:54:50.460481Z'}
{'type': 'l2update', 'product_id': 'BTC-USD', 'changes': [['buy', '38229.97', '0.02400000']], 'time': '2021-05-20T03:54:50.460481Z'}
{'type': 'l2update', 'product_id': 'BTC-USD', 'changes': [['sell', '38372.26', '0.01000000']], 'time': '2021-05-20T03:54:50.485725Z'}
{'type': 'l2update', 'product_id': 'BTC-USD', 'changes': [['buy', '38263.41', '0.00000000']], 'time': '2021-05-20T03:54:50.485950Z'}
{'type': 'l2update', 'product_id': 'BTC-USD', 'changes': [['sell', '38297.66', '0.00000000']], 'time': '2021-05-20T03:54:50.487290Z'}
{'type': 'l2update', 'product_id': 'BTC-USD', 'changes': [['buy', '38260.59', '0.02000000']], 'time': '2021-05-20T03:54:50.487481Z'}
{'type': 'l2update', 'product_id': 'BTC-USD', 'changes': [['sell', '38493.48', '0.00000000']], 'time': '2021-05-20T03:54:50.488695Z'}
{'type': 'l2update', 'product_id': 'BTC-USD', 'changes': [['buy', '38263.46', '0.00000000']], 'time': '2021-05-20T03:54:50.492863Z'}
{'type': 'l2update', 'product_id': 'BTC-USD', 'changes': [['sell', '38272.30', '0.00000000']], 'time': '2021-05-20T03:54:50.493209Z'}
{'type': 'l2update', 'product_id': 'BTC-USD', 'changes': [['sell', '50787.74', '0.00420900']], 'time': '2021-05-20T03:54:50.496251Z'}
{'type': 'l2update', 'product_id': 'BTC-USD', 'changes': [['sell', '38366.75', '0.00000000']], 'time': '2021-05-20T03:54:50.496441Z'}
{'type': 'l2update', 'product_id': 'BTC-USD', 'changes': [['sell', '38272.55', '0.14870000']], 'time': '2021-05-20T03:54:50.499926Z'}
{'type': 'l2update', 'product_id': 'BTC-USD', 'changes': [['buy', '38250.79', '0.58716278']], 'time': '2021-05-20T03:54:50.499948Z'}
{'type': 'l2update', 'product_id': 'BTC-USD', 'changes': [['buy', '38253.29', '0.00000000']], 'time': '2021-05-20T03:54:50.501395Z'}
{'type': 'l2update', 'product_id': 'BTC-USD', 'changes': [['sell', '38272.26', '0.00000000']], 'time': '2021-05-20T03:54:50.510121Z'}
{'type': 'l2update', 'product_id': 'BTC-USD', 'changes': [['buy', '38257.35', '0.03000000']], 'time': '2021-05-20T03:54:50.517595Z'}
{'type': 'l2update', 'product_id': 'BTC-USD', 'changes': [['buy', '38228.75', '0.42760000']], 'time': '2021-05-20T03:54:50.517861Z'}
{'type': 'l2update', 'product_id': 'BTC-USD', 'changes': [['buy', '38253.34', '0.00000000']], 'time': '2021-05-20T03:54:50.522950Z'}
{'type': 'l2update', 'product_id': 'BTC-USD', 'changes': [['sell', '38330.66', '0.61482417']], 'time': '2021-05-20T03:54:50.524824Z'}
{'type': 'l2update', 'product_id': 'BTC-USD', 'changes': [['sell', '38395.33', '0.01000000']], 'time': '2021-05-20T03:54:50.525240Z'}
{'type': 'l2update', 'product_id': 'BTC-USD', 'changes': [['sell', '38291.80', '0.00000000']], 'time': '2021-05-20T03:54:50.527137Z'}
{'type': 'l2update', 'product_id': 'BTC-USD', 'changes': [['sell', '38272.55', '0.34870000']], 'time': '2021-05-20T03:54:50.530016Z'}
{'type': 'l2update', 'product_id': 'BTC-USD', 'changes': [['buy', '38250.01', '0.00000000']], 'time': '2021-05-20T03:54:50.534823Z'}
{'type': 'l2update', 'product_id': 'BTC-USD', 'changes': [['buy', '38228.75', '0.00000000']], 'time': '2021-05-20T03:54:50.536163Z'}
{'type': 'l2update', 'product_id': 'BTC-USD', 'changes': [['sell', '38290.44', '0.00000000']], 'time': '2021-05-20T03:54:50.539918Z'}
{'type': 'l2update', 'product_id': 'BTC-USD', 'changes': [['sell', '38553.46', '0.01296900']], 'time': '2021-05-20T03:54:50.540510Z'}
{'type': 'l2update', 'product_id': 'BTC-USD', 'changes': [['buy', '38248.76', '0.04000000']], 'time': '2021-05-20T03:54:50.544184Z'}
{'type': 'l2update', 'product_id': 'BTC-USD', 'changes': [['buy', '38250.84', '0.84900000']], 'time': '2021-05-20T03:54:50.548621Z'}
{'type': 'l2update', 'product_id': 'BTC-USD', 'changes': [['sell', '38273.87', '0.00000000']], 'time': '2021-05-20T03:54:50.552128Z'}
{'type': 'l2update', 'product_id': 'BTC-USD', 'changes': [['buy', '38245.90', '0.06399492']], 'time': '2021-05-20T03:54:50.554021Z'}
{'type': 'l2update', 'product_id': 'BTC-USD', 'changes': [['buy', '38253.35', '0.22867204']], 'time': '2021-05-20T03:54:50.555114Z'}
{'type': 'l2update', 'product_id': 'BTC-USD', 'changes': [['sell', '38407.74', '0.00000000']], 'time': '2021-05-20T03:54:50.556210Z'}
{'type': 'l2update', 'product_id': 'BTC-USD', 'changes': [['buy', '38249.69', '0.00000000']], 'time': '2021-05-20T03:54:50.556531Z'}
{'type': 'l2update', 'product_id': 'BTC-USD', 'changes': [['buy', '38232.01', '0.00000000']], 'time': '2021-05-20T03:54:50.558867Z'}
{'type': 'l2update', 'product_id': 'BTC-USD', 'changes': [['sell', '38270.14', '0.01055986']], 'time': '2021-05-20T03:54:50.559596Z'}
{'type': 'l2update', 'product_id': 'BTC-USD', 'changes': [['buy', '38244.49', '0.05000000']], 'time': '2021-05-20T03:54:50.564401Z'}
{'type': 'l2update', 'product_id': 'BTC-USD', 'changes': [['sell', '38272.56', '0.20000000']], 'time': '2021-05-20T03:54:50.567557Z'}
{'type': 'l2update', 'product_id': 'BTC-USD', 'changes': [['sell', '38272.55', '0.30000000']], 'time': '2021-05-20T03:54:50.567912Z'}
{'type': 'l2update', 'product_id': 'BTC-USD', 'changes': [['buy', '38266.89', '0.01005357']], 'time': '2021-05-20T03:54:50.570399Z'}
{'type': 'l2update', 'product_id': 'BTC-USD', 'changes': [['buy', '38229.06', '0.02400000']], 'time': '2021-05-20T03:54:50.581485Z'}
{'type': 'l2update', 'product_id': 'BTC-USD', 'changes': [['sell', '38272.54', '0.36249352']], 'time': '2021-05-20T03:54:50.581687Z'}
{'type': 'l2update', 'product_id': 'BTC-USD', 'changes': [['buy', '38269.50', '0.00000000']], 'time': '2021-05-20T03:54:50.587410Z'}
{'type': 'l2update', 'product_id': 'BTC-USD', 'changes': [['sell', '38297.26', '0.40240000']], 'time': '2021-05-20T03:54:50.600144Z'}
{'type': 'l2update', 'product_id': 'BTC-USD', 'changes': [['sell', '38270.14', '0.21055986']], 'time': '2021-05-20T03:54:50.606435Z'}
{'type': 'l2update', 'product_id': 'BTC-USD', 'changes': [['sell', '38289.45', '0.12905773']], 'time': '2021-05-20T03:54:50.612181Z'}
{'type': 'l2update', 'product_id': 'BTC-USD', 'changes': [['buy', '38167.19', '0.00000000']], 'time': '2021-05-20T03:54:50.615054Z'}
{'type': 'l2update', 'product_id': 'BTC-USD', 'changes': [['buy', '38245.90', '0.00000000']], 'time': '2021-05-20T03:54:50.617657Z'}
{'type': 'l2update', 'product_id': 'BTC-USD', 'changes': [['sell', '38270.14', '0.31055986']], 'time': '2021-05-20T03:54:50.619685Z'}
{'type': 'l2update', 'product_id': 'BTC-USD', 'changes': [['buy', '38253.35', '0.00000000']], 'time': '2021-05-20T03:54:50.621210Z'}
{'type': 'l2update', 'product_id': 'BTC-USD', 'changes': [['buy', '38250.80', '0.06261042']], 'time': '2021-05-20T03:54:50.624726Z'}
{'type': 'l2update', 'product_id': 'BTC-USD', 'changes': [['sell', '38290.44', '0.05000000']], 'time': '2021-05-20T03:54:50.624955Z'}
{'type': 'l2update', 'product_id': 'BTC-USD', 'changes': [['sell', '38270.14', '0.30000000']], 'time': '2021-05-20T03:54:50.632587Z'}
{'type': 'l2update', 'product_id': 'BTC-USD', 'changes': [['buy', '38147.72', '0.01000000']], 'time': '2021-05-20T03:54:50.633250Z'}
{'type': 'l2update', 'product_id': 'BTC-USD', 'changes': [['sell', '38289.44', '0.06261042']], 'time': '2021-05-20T03:54:50.633285Z'}
{'type': 'l2update', 'product_id': 'BTC-USD', 'changes': [['sell', '38272.54', '0.00000000']], 'time': '2021-05-20T03:54:50.635103Z'}
{'type': 'l2update', 'product_id': 'BTC-USD', 'changes': [['buy', '38260.83', '0.00000000']], 'time': '2021-05-20T03:54:50.635294Z'}
{'type': 'l2update', 'product_id': 'BTC-USD', 'changes': [['buy', '38237.84', '0.40780000']], 'time': '2021-05-20T03:54:50.636686Z'}
{'type': 'l2update', 'product_id': 'BTC-USD', 'changes': [['buy', '38230.00', '0.00284284']], 'time': '2021-05-20T03:54:50.643304Z'}
{'type': 'l2update', 'product_id': 'BTC-USD', 'changes': [['buy', '38250.85', '0.22867204']], 'time': '2021-05-20T03:54:50.643548Z'}
{'type': 'l2update', 'product_id': 'BTC-USD', 'changes': [['sell', '38408.87', '0.00000000']], 'time': '2021-05-20T03:54:50.653996Z'}
{'type': 'l2update', 'product_id': 'BTC-USD', 'changes': [['buy', '38266.89', '0.00000000']], 'time': '2021-05-20T03:54:50.654647Z'}
{'type': 'l2update', 'product_id': 'BTC-USD', 'changes': [['sell', '38270.13', '0.36249352']], 'time': '2021-05-20T03:54:50.655308Z'}
{'type': 'l2update', 'product_id': 'BTC-USD', 'changes': [['buy', '38245.90', '0.06261042']], 'time': '2021-05-20T03:54:50.661975Z'}
{'type': 'l2update', 'product_id': 'BTC-USD', 'changes': [['sell', '38290.44', '0.00000000']], 'time': '2021-05-20T03:54:50.662045Z'}
{'type': 'l2update', 'product_id': 'BTC-USD', 'changes': [['sell', '38394.01', '0.00000000']], 'time': '2021-05-20T03:54:50.663086Z'}
{'type': 'l2update', 'product_id': 'BTC-USD', 'changes': [['sell', '38272.50', '1.08100000']], 'time': '2021-05-20T03:54:50.668107Z'}
{'type': 'l2update', 'product_id': 'BTC-USD', 'changes': [['buy', '38250.80', '0.00000000']], 'time': '2021-05-20T03:54:50.670667Z'}
{'type': 'l2update', 'product_id': 'BTC-USD', 'changes': [['sell', '38284.67', '0.06261042']], 'time': '2021-05-20T03:54:50.671032Z'}
{'type': 'l2update', 'product_id': 'BTC-USD', 'changes': [['sell', '38625.79', '0.00000000']], 'time': '2021-05-20T03:54:50.672791Z'}
{'type': 'l2update', 'product_id': 'BTC-USD', 'changes': [['sell', '38289.44', '0.00000000']], 'time': '2021-05-20T03:54:50.674237Z'}
{'type': 'l2update', 'product_id': 'BTC-USD', 'changes': [['sell', '38289.45', '0.17905773']], 'time': '2021-05-20T03:54:50.677603Z'}
{'type': 'l2update', 'product_id': 'BTC-USD', 'changes': [['buy', '38240.28', '0.00000000']], 'time': '2021-05-20T03:54:50.678722Z'}
{'type': 'l2update', 'product_id': 'BTC-USD', 'changes': [['sell', '38286.63', '0.00000000']], 'time': '2021-05-20T03:54:50.678722Z'}
{'type': 'l2update', 'product_id': 'BTC-USD', 'changes': [['sell', '38273.92', '0.00000000']], 'time': '2021-05-20T03:54:50.681869Z'}
{'type': 'l2update', 'product_id': 'BTC-USD', 'changes': [['sell', '38274.56', '0.00000000']], 'time': '2021-05-20T03:54:50.682537Z'}
{'type': 'l2update', 'product_id': 'BTC-USD', 'changes': [['buy', '38147.72', '0.00000000']], 'time': '2021-05-20T03:54:50.691635Z'}
{'type': 'l2update', 'product_id': 'BTC-USD', 'changes': [['buy', '37903.38', '0.00000000']], 'time': '2021-05-20T03:54:50.693812Z'}
{'type': 'l2update', 'product_id': 'BTC-USD', 'changes': [['sell', '50787.90', '0.00296600']], 'time': '2021-05-20T03:54:50.694437Z'}
{'type': 'l2update', 'product_id': 'BTC-USD', 'changes': [['sell', '38270.12', '0.50000000']], 'time': '2021-05-20T03:54:50.694472Z'}
{'type': 'l2update', 'product_id': 'BTC-USD', 'changes': [['sell', '38433.04', '0.00000000']], 'time': '2021-05-20T03:54:50.700306Z'}
{'type': 'l2update', 'product_id': 'BTC-USD', 'changes': [['buy', '38127.00', '0.01000000']], 'time': '2021-05-20T03:54:50.702511Z'}
{'type': 'l2update', 'product_id': 'BTC-USD', 'changes': [['sell', '38270.12', '2.98969908']], 'time': '2021-05-20T03:54:50.702572Z'}
{'type': 'l2update', 'product_id': 'BTC-USD', 'changes': [['sell', '38270.13', '0.00000000']], 'time': '2021-05-20T03:54:50.705010Z'}
{'type': 'l2update', 'product_id': 'BTC-USD', 'changes': [['sell', '38372.26', '0.00000000']], 'time': '2021-05-20T03:54:50.708051Z'}
{'type': 'l2update', 'product_id': 'BTC-USD', 'changes': [['sell', '38392.62', '0.00000000']], 'time': '2021-05-20T03:54:50.708685Z'}
{'type': 'l2update', 'product_id': 'BTC-USD', 'changes': [['buy', '38236.56', '0.05064818']], 'time': '2021-05-20T03:54:50.709066Z'}
{'type': 'l2update', 'product_id': 'BTC-USD', 'changes': [['sell', '38280.84', '0.04919454']], 'time': '2021-05-20T03:54:50.709066Z'}
{'type': 'l2update', 'product_id': 'BTC-USD', 'changes': [['buy', '38245.90', '0.00000000']], 'time': '2021-05-20T03:54:50.709893Z'}
{'type': 'l2update', 'product_id': 'BTC-USD', 'changes': [['sell', '38420.47', '0.01000000']], 'time': '2021-05-20T03:54:50.717706Z'}
{'type': 'l2update', 'product_id': 'BTC-USD', 'changes': [['buy', '38244.44', '0.06261042']], 'time': '2021-05-20T03:54:50.718626Z'}
{'type': 'l2update', 'product_id': 'BTC-USD', 'changes': [['sell', '38384.37', '0.01000000']], 'time': '2021-05-20T03:54:50.718751Z'}
{'type': 'l2update', 'product_id': 'BTC-USD', 'changes': [['sell', '38377.48', '0.01811971']], 'time': '2021-05-20T03:54:50.722896Z'}
{'type': 'l2update', 'product_id': 'BTC-USD', 'changes': [['sell', '38270.11', '0.36249352']], 'time': '2021-05-20T03:54:50.726425Z'}
{'type': 'l2update', 'product_id': 'BTC-USD', 'changes': [['sell', '38359.42', '0.00000000']], 'time': '2021-05-20T03:54:50.737092Z'}
{'type': 'l2update', 'product_id': 'BTC-USD', 'changes': [['sell', '38297.26', '0.00000000']], 'time': '2021-05-20T03:54:50.742647Z'}
{'type': 'l2update', 'product_id': 'BTC-USD', 'changes': [['buy', '37967.71', '0.00000000']], 'time': '2021-05-20T03:54:50.742804Z'}
{'type': 'l2update', 'product_id': 'BTC-USD', 'changes': [['buy', '37870.66', '0.34380000']], 'time': '2021-05-20T03:54:50.746280Z'}
{'type': 'l2update', 'product_id': 'BTC-USD', 'changes': [['sell', '38280.84', '0.00000000']], 'time': '2021-05-20T03:54:50.746675Z'}
{'type': 'l2update', 'product_id': 'BTC-USD', 'changes': [['buy', '38244.44', '0.00000000']], 'time': '2021-05-20T03:54:50.750749Z'}
{'type': 'l2update', 'product_id': 'BTC-USD', 'changes': [['buy', '37980.59', '0.13164617']], 'time': '2021-05-20T03:54:50.755757Z'}
{'type': 'l2update', 'product_id': 'BTC-USD', 'changes': [['sell', '38295.66', '0.40040000']], 'time': '2021-05-20T03:54:50.755794Z'}
{'type': 'l2update', 'product_id': 'BTC-USD', 'changes': [['buy', '38237.85', '0.06261042']], 'time': '2021-05-20T03:54:50.760577Z'}
{'type': 'l2update', 'product_id': 'BTC-USD', 'changes': [['buy', '37500.01', '0.06800000']], 'time': '2021-05-20T03:54:50.766983Z'}
{'type': 'l2update', 'product_id': 'BTC-USD', 'changes': [['buy', '37500.01', '0.01030000']], 'time': '2021-05-20T03:54:50.766983Z'}
{'type': 'l2update', 'product_id': 'BTC-USD', 'changes': [['buy', '37500.01', '0.07230000']], 'time': '2021-05-20T03:54:50.772706Z'}
{'type': 'l2update', 'product_id': 'BTC-USD', 'changes': [['buy', '38185.61', '0.07700000']], 'time': '2021-05-20T03:54:50.776064Z'}
{'type': 'l2update', 'product_id': 'BTC-USD', 'changes': [['sell', '38277.11', '0.04592550']], 'time': '2021-05-20T03:54:50.784973Z'}
{'type': 'l2update', 'product_id': 'BTC-USD', 'changes': [['buy', '38245.94', '0.52100000']], 'time': '2021-05-20T03:54:50.800684Z'}
{'type': 'l2update', 'product_id': 'BTC-USD', 'changes': [['buy', '38236.56', '0.00000000']], 'time': '2021-05-20T03:54:50.816640Z'}
{'type': 'l2update', 'product_id': 'BTC-USD', 'changes': [['buy', '37980.59', '0.00000000']], 'time': '2021-05-20T03:54:50.824126Z'}
{'type': 'l2update', 'product_id': 'BTC-USD', 'changes': [['buy', '38163.70', '0.07800000']], 'time': '2021-05-20T03:54:50.829769Z'}
{'type': 'l2update', 'product_id': 'BTC-USD', 'changes': [['buy', '38261.26', '0.00000000']], 'time': '2021-05-20T03:54:50.834822Z'}
{'type': 'l2update', 'product_id': 'BTC-USD', 'changes': [['buy', '38260.59', '0.00000000']], 'time': '2021-05-20T03:54:50.839170Z'}
{'type': 'l2update', 'product_id': 'BTC-USD', 'changes': [['buy', '38234.50', '0.05703707']], 'time': '2021-05-20T03:54:50.840662Z'}
{'type': 'l2update', 'product_id': 'BTC-USD', 'changes': [['buy', '37993.47', '0.01162500']], 'time': '2021-05-20T03:54:50.840756Z'}
{'type': 'l2update', 'product_id': 'BTC-USD', 'changes': [['buy', '38257.35', '0.00000000']], 'time': '2021-05-20T03:54:50.842863Z'}
{'type': 'l2update', 'product_id': 'BTC-USD', 'changes': [['buy', '38266.49', '0.15000000']], 'time': '2021-05-20T03:54:50.844782Z'}
{'type': 'l2update', 'product_id': 'BTC-USD', 'changes': [['buy', '38248.76', '0.00000000']], 'time': '2021-05-20T03:54:50.846558Z'}
{'type': 'l2update', 'product_id': 'BTC-USD', 'changes': [['sell', '38420.47', '0.00000000']], 'time': '2021-05-20T03:54:50.848011Z'}
{'type': 'l2update', 'product_id': 'BTC-USD', 'changes': [['buy', '38244.49', '0.00000000']], 'time': '2021-05-20T03:54:50.850511Z'}
{'type': 'l2update', 'product_id': 'BTC-USD', 'changes': [['sell', '38277.11', '0.05847338']], 'time': '2021-05-20T03:54:50.852353Z'}
{'type': 'l2update', 'product_id': 'BTC-USD', 'changes': [['buy', '38257.36', '0.05000000']], 'time': '2021-05-20T03:54:50.852387Z'}
{'type': 'l2update', 'product_id': 'BTC-USD', 'changes': [['sell', '38284.67', '0.00000000']], 'time': '2021-05-20T03:54:50.852884Z'}
{'type': 'l2update', 'product_id': 'BTC-USD', 'changes': [['buy', '38262.94', '0.00000000']], 'time': '2021-05-20T03:54:50.853643Z'}
{'type': 'l2update', 'product_id': 'BTC-USD', 'changes': [['buy', '38234.16', '0.16200000']], 'time': '2021-05-20T03:54:50.856708Z'}
{'type': 'l2update', 'product_id': 'BTC-USD', 'changes': [['sell', '38431.77', '0.01000000']], 'time': '2021-05-20T03:54:50.859971Z'}
{'type': 'l2update', 'product_id': 'BTC-USD', 'changes': [['buy', '38238.09', '0.01000000']], 'time': '2021-05-20T03:54:50.860058Z'}
{'type': 'l2update', 'product_id': 'BTC-USD', 'changes': [['sell', '38289.44', '0.06261042']], 'time': '2021-05-20T03:54:50.860239Z'}
{'type': 'l2update', 'product_id': 'BTC-USD', 'changes': [['buy', '38237.85', '0.00000000']], 'time': '2021-05-20T03:54:50.861164Z'}
{'type': 'l2update', 'product_id': 'BTC-USD', 'changes': [['sell', '50791.53', '0.00296600']], 'time': '2021-05-20T03:54:50.864195Z'}
{'type': 'l2update', 'product_id': 'BTC-USD', 'changes': [['buy', '38244.44', '0.06261042']], 'time': '2021-05-20T03:54:50.867778Z'}
{'type': 'l2update', 'product_id': 'BTC-USD', 'changes': [['buy', '38238.09', '0.03000000']], 'time': '2021-05-20T03:54:50.871424Z'}
{'type': 'l2update', 'product_id': 'BTC-USD', 'changes': [['buy', '38244.44', '0.00000000']], 'time': '2021-05-20T03:54:50.874011Z'}
{'type': 'l2update', 'product_id': 'BTC-USD', 'changes': [['buy', '38237.85', '0.06261042']], 'time': '2021-05-20T03:54:50.882817Z'}
{'type': 'l2update', 'product_id': 'BTC-USD', 'changes': [['buy', '38238.09', '0.06000000']], 'time': '2021-05-20T03:54:50.883126Z'}
{'type': 'l2update', 'product_id': 'BTC-USD', 'changes': [['buy', '38210.56', '0.00000000']], 'time': '2021-05-20T03:54:50.893663Z'}
{'type': 'l2update', 'product_id': 'BTC-USD', 'changes': [['buy', '38238.09', '0.10000000']], 'time': '2021-05-20T03:54:50.895052Z'}
{'type': 'l2update', 'product_id': 'BTC-USD', 'changes': [['buy', '38238.09', '0.15000000']], 'time': '2021-05-20T03:54:50.907867Z'}
{'type': 'l2update', 'product_id': 'BTC-USD', 'changes': [['buy', '38238.10', '0.06261042']], 'time': '2021-05-20T03:54:50.923534Z'}
{'type': 'l2update', 'product_id': 'BTC-USD', 'changes': [['buy', '38237.85', '0.00000000']], 'time': '2021-05-20T03:54:50.927593Z'}
{'type': 'l2update', 'product_id': 'BTC-USD', 'changes': [['buy', '38250.05', '0.52200000']], 'time': '2021-05-20T03:54:50.943627Z'}
{'type': 'l2update', 'product_id': 'BTC-USD', 'changes': [['buy', '38207.56', '0.10000000']], 'time': '2021-05-20T03:54:50.947588Z'}
{'type': 'l2update', 'product_id': 'BTC-USD', 'changes': [['sell', '38404.26', '0.00000000']], 'time': '2021-05-20T03:54:50.953809Z'}
{'type': 'l2update', 'product_id': 'BTC-USD', 'changes': [['sell', '38415.88', '0.01000000']], 'time': '2021-05-20T03:54:50.966162Z'}
{'type': 'l2update', 'product_id': 'BTC-USD', 'changes': [['sell', '38389.83', '0.00000000']], 'time': '2021-05-20T03:54:50.970396Z'}
{'type': 'l2update', 'product_id': 'BTC-USD', 'changes': [['sell', '38314.08', '0.05454587']], 'time': '2021-05-20T03:54:50.970429Z'}
{'type': 'l2update', 'product_id': 'BTC-USD', 'changes': [['buy', '38234.50', '0.00000000']], 'time': '2021-05-20T03:54:50.983881Z'}
{'type': 'l2update', 'product_id': 'BTC-USD', 'changes': [['sell', '38277.11', '0.04592550']], 'time': '2021-05-20T03:54:50.983881Z'}
{'type': 'l2update', 'product_id': 'BTC-USD', 'changes': [['sell', '38277.11', '0.00000000']], 'time': '2021-05-20T03:54:50.983881Z'}
{'type': 'l2update', 'product_id': 'BTC-USD', 'changes': [['sell', '38409.35', '0.04476780']], 'time': '2021-05-20T03:54:50.985022Z'}
{'type': 'l2update', 'product_id': 'BTC-USD', 'changes': [['sell', '38270.11', '0.35609234']], 'time': '2021-05-20T03:54:50.993292Z'}
{'type': 'l2update', 'product_id': 'BTC-USD', 'changes': [['buy', '38236.56', '0.06089717']], 'time': '2021-05-20T03:54:51.005282Z'}
{'type': 'l2update', 'product_id': 'BTC-USD', 'changes': [['sell', '38280.83', '0.04268362']], 'time': '2021-05-20T03:54:51.005282Z'}
{'type': 'l2update', 'product_id': 'BTC-USD', 'changes': [['buy', '38260.20', '0.05106389']], 'time': '2021-05-20T03:54:51.008983Z'}
{'type': 'l2update', 'product_id': 'BTC-USD', 'changes': [['sell', '38289.44', '0.00000000']], 'time': '2021-05-20T03:54:51.012603Z'}
{'type': 'l2update', 'product_id': 'BTC-USD', 'changes': [['buy', '38238.10', '0.00000000']], 'time': '2021-05-20T03:54:51.015882Z'}
{'type': 'l2update', 'product_id': 'BTC-USD', 'changes': [['buy', '38244.44', '0.06261042']], 'time': '2021-05-20T03:54:51.020632Z'}
{'type': 'l2update', 'product_id': 'BTC-USD', 'changes': [['sell', '38284.68', '1.36999667']], 'time': '2021-05-20T03:54:51.020940Z'}
{'type': 'l2update', 'product_id': 'BTC-USD', 'changes': [['buy', '38185.61', '0.00000000']], 'time': '2021-05-20T03:54:51.023845Z'}
{'type': 'l2update', 'product_id': 'BTC-USD', 'changes': [['sell', '38284.68', '1.30738625']], 'time': '2021-05-20T03:54:51.027419Z'}
{'type': 'l2update', 'product_id': 'BTC-USD', 'changes': [['sell', '50795.15', '0.00296600']], 'time': '2021-05-20T03:54:51.028465Z'}
{'type': 'l2update', 'product_id': 'BTC-USD', 'changes': [['sell', '38289.44', '0.06261042']], 'time': '2021-05-20T03:54:51.032531Z'}
{'type': 'l2update', 'product_id': 'BTC-USD', 'changes': [['sell', '38272.50', '0.00000000']], 'time': '2021-05-20T03:54:51.045424Z'}
{'type': 'l2update', 'product_id': 'BTC-USD', 'changes': [['sell', '39607.33', '0.00000000']], 'time': '2021-05-20T03:54:51.045831Z'}
{'type': 'l2update', 'product_id': 'BTC-USD', 'changes': [['sell', '38274.50', '0.00000000']], 'time': '2021-05-20T03:54:51.046070Z'}
{'type': 'l2update', 'product_id': 'BTC-USD', 'changes': [['buy', '38262.94', '0.00176529']], 'time': '2021-05-20T03:54:51.052641Z'}
{'type': 'l2update', 'product_id': 'BTC-USD', 'changes': [['buy', '38244.44', '0.00000000']], 'time': '2021-05-20T03:54:51.059549Z'}
{'type': 'l2update', 'product_id': 'BTC-USD', 'changes': [['sell', '38448.01', '0.01000000']], 'time': '2021-05-20T03:54:51.062092Z'}
{'type': 'l2update', 'product_id': 'BTC-USD', 'changes': [['buy', '38245.95', '0.06261042']], 'time': '2021-05-20T03:54:51.066548Z'}
{'type': 'l2update', 'product_id': 'BTC-USD', 'changes': [['sell', '38270.11', '0.35089233']], 'time': '2021-05-20T03:54:51.087385Z'}
{'type': 'l2update', 'product_id': 'BTC-USD', 'changes': [['sell', '38270.11', '0.33808528']], 'time': '2021-05-20T03:54:51.095244Z'}
{'type': 'l2update', 'product_id': 'BTC-USD', 'changes': [['sell', '38277.97', '1.04600000']], 'time': '2021-05-20T03:54:51.111996Z'}
{'type': 'l2update', 'product_id': 'BTC-USD', 'changes': [['buy', '38155.18', '0.00000000']], 'time': '2021-05-20T03:54:51.121371Z'}
{'type': 'l2update', 'product_id': 'BTC-USD', 'changes': [['buy', '38237.84', '0.00000000']], 'time': '2021-05-20T03:54:51.137013Z'}
{'type': 'l2update', 'product_id': 'BTC-USD', 'changes': [['sell', '38295.66', '0.00000000']], 'time': '2021-05-20T03:54:51.140514Z'}
{'type': 'l2update', 'product_id': 'BTC-USD', 'changes': [['buy', '38173.93', '0.01000000']], 'time': '2021-05-20T03:54:51.141878Z'}
{'type': 'l2update', 'product_id': 'BTC-USD', 'changes': [['sell', '38273.88', '0.00000000']], 'time': '2021-05-20T03:54:51.156328Z'}
{'type': 'l2update', 'product_id': 'BTC-USD', 'changes': [['buy', '38266.49', '0.35000000']], 'time': '2021-05-20T03:54:51.156883Z'}
{'type': 'l2update', 'product_id': 'BTC-USD', 'changes': [['buy', '38266.50', '0.05000000']], 'time': '2021-05-20T03:54:51.157049Z'}
{'type': 'l2update', 'product_id': 'BTC-USD', 'changes': [['buy', '38236.56', '0.00000000']], 'time': '2021-05-20T03:54:51.163665Z'}
{'type': 'l2update', 'product_id': 'BTC-USD', 'changes': [['sell', '38280.83', '0.00000000']], 'time': '2021-05-20T03:54:51.163665Z'}
{'type': 'l2update', 'product_id': 'BTC-USD', 'changes': [['sell', '38277.97', '0.00000000']], 'time': '2021-05-20T03:54:51.164624Z'}
{'type': 'l2update', 'product_id': 'BTC-USD', 'changes': [['buy', '38266.50', '0.15000000']], 'time': '2021-05-20T03:54:51.171450Z'}
{'type': 'l2update', 'product_id': 'BTC-USD', 'changes': [['sell', '38293.06', '0.00000000']], 'time': '2021-05-20T03:54:51.173502Z'}
{'type': 'l2update', 'product_id': 'BTC-USD', 'changes': [['sell', '38270.12', '0.50000000']], 'time': '2021-05-20T03:54:51.173833Z'}
{'type': 'l2update', 'product_id': 'BTC-USD', 'changes': [['buy', '38048.39', '0.00000000']], 'time': '2021-05-20T03:54:51.179636Z'}
{'type': 'l2update', 'product_id': 'BTC-USD', 'changes': [['sell', '38292.42', '0.00000000']], 'time': '2021-05-20T03:54:51.179823Z'}
{'type': 'l2update', 'product_id': 'BTC-USD', 'changes': [['buy', '38265.25', '0.04966139']], 'time': '2021-05-20T03:54:51.181948Z'}
{'type': 'l2update', 'product_id': 'BTC-USD', 'changes': [['buy', '38102.33', '0.05063748']], 'time': '2021-05-20T03:54:51.183619Z'}
{'type': 'l2update', 'product_id': 'BTC-USD', 'changes': [['sell', '50798.63', '0.00242000']], 'time': '2021-05-20T03:54:51.194585Z'}
{'type': 'l2update', 'product_id': 'BTC-USD', 'changes': [['sell', '38272.54', '2.48969908']], 'time': '2021-05-20T03:54:51.195528Z'}
{'type': 'l2update', 'product_id': 'BTC-USD', 'changes': [['sell', '38284.63', '1.26500000']], 'time': '2021-05-20T03:54:51.199817Z'}
{'type': 'l2update', 'product_id': 'BTC-USD', 'changes': [['sell', '38303.04', '0.00000000']], 'time': '2021-05-20T03:54:51.201570Z'}
{'type': 'l2update', 'product_id': 'BTC-USD', 'changes': [['sell', '38395.33', '0.00000000']], 'time': '2021-05-20T03:54:51.205459Z'}
{'type': 'l2update', 'product_id': 'BTC-USD', 'changes': [['buy', '38257.36', '0.00000000']], 'time': '2021-05-20T03:54:51.206315Z'}
{'type': 'l2update', 'product_id': 'BTC-USD', 'changes': [['sell', '38272.54', '0.00000000']], 'time': '2021-05-20T03:54:51.207183Z'}
{'type': 'l2update', 'product_id': 'BTC-USD', 'changes': [['sell', '38271.28', '0.52282378']], 'time': '2021-05-20T03:54:51.209513Z'}
{'type': 'l2update', 'product_id': 'BTC-USD', 'changes': [['sell', '43100.00', '1.09530000']], 'time': '2021-05-20T03:54:51.214870Z'}
{'type': 'l2update', 'product_id': 'BTC-USD', 'changes': [['buy', '38240.20', '0.04020379']], 'time': '2021-05-20T03:54:51.221742Z'}
{'type': 'l2update', 'product_id': 'BTC-USD', 'changes': [['sell', '38285.50', '0.04926426']], 'time': '2021-05-20T03:54:51.221742Z'}
{'type': 'l2update', 'product_id': 'BTC-USD', 'changes': [['sell', '38409.27', '0.01000000']], 'time': '2021-05-20T03:54:51.222036Z'}
{'type': 'l2update', 'product_id': 'BTC-USD', 'changes': [['buy', '38252.35', '0.52279039']], 'time': '2021-05-20T03:54:51.224084Z'}
{'type': 'l2update', 'product_id': 'BTC-USD', 'changes': [['buy', '38237.84', '0.49600000']], 'time': '2021-05-20T03:54:51.228300Z'}
{'type': 'l2update', 'product_id': 'BTC-USD', 'changes': [['sell', '38273.92', '2.48969908']], 'time': '2021-05-20T03:54:51.228467Z'}
{'type': 'l2update', 'product_id': 'BTC-USD', 'changes': [['buy', '37993.47', '0.00000000']], 'time': '2021-05-20T03:54:51.232723Z'}
{'type': 'l2update', 'product_id': 'BTC-USD', 'changes': [['buy', '38250.85', '0.00000000']], 'time': '2021-05-20T03:54:51.238108Z'}
{'type': 'l2update', 'product_id': 'BTC-USD', 'changes': [['sell', '38272.56', '0.00000000']], 'time': '2021-05-20T03:54:51.238532Z'}
{'type': 'l2update', 'product_id': 'BTC-USD', 'changes': [['sell', '43100.00', '5.59170000']], 'time': '2021-05-20T03:54:51.240635Z'}
{'type': 'l2update', 'product_id': 'BTC-USD', 'changes': [['buy', '38248.81', '0.52283996']], 'time': '2021-05-20T03:54:51.240771Z'}
{'type': 'l2update', 'product_id': 'BTC-USD', 'changes': [['sell', '38297.98', '0.45000000']], 'time': '2021-05-20T03:54:51.240797Z'}
{'type': 'l2update', 'product_id': 'BTC-USD', 'changes': [['buy', '38006.35', '0.01162500']], 'time': '2021-05-20T03:54:51.244821Z'}
{'type': 'l2update', 'product_id': 'BTC-USD', 'changes': [['sell', '38272.55', '0.20000000']], 'time': '2021-05-20T03:54:51.248120Z'}
{'type': 'l2update', 'product_id': 'BTC-USD', 'changes': [['sell', '38272.55', '0.00000000']], 'time': '2021-05-20T03:54:51.252527Z'}
{'type': 'l2update', 'product_id': 'BTC-USD', 'changes': [['buy', '38127.00', '0.00000000']], 'time': '2021-05-20T03:54:51.253117Z'}
{'type': 'l2update', 'product_id': 'BTC-USD', 'changes': [['buy', '38094.91', '0.00000000']], 'time': '2021-05-20T03:54:51.253971Z'}
{'type': 'l2update', 'product_id': 'BTC-USD', 'changes': [['sell', '38270.14', '0.10000000']], 'time': '2021-05-20T03:54:51.256478Z'}
{'type': 'l2update', 'product_id': 'BTC-USD', 'changes': [['buy', '38108.74', '0.04997308']], 'time': '2021-05-20T03:54:51.261357Z'}
{'type': 'l2update', 'product_id': 'BTC-USD', 'changes': [['buy', '38252.36', '0.25308028']], 'time': '2021-05-20T03:54:51.261807Z'}
{'type': 'l2update', 'product_id': 'BTC-USD', 'changes': [['sell', '38306.43', '0.05029145']], 'time': '2021-05-20T03:54:51.261895Z'}
{'type': 'l2update', 'product_id': 'BTC-USD', 'changes': [['sell', '38270.14', '0.00000000']], 'time': '2021-05-20T03:54:51.261930Z'}
{'type': 'l2update', 'product_id': 'BTC-USD', 'changes': [['buy', '38138.93', '0.26219922']], 'time': '2021-05-20T03:54:51.265164Z'}
{'type': 'l2update', 'product_id': 'BTC-USD', 'changes': [['buy', '38248.82', '0.06261042']], 'time': '2021-05-20T03:54:51.265275Z'}
{'type': 'l2update', 'product_id': 'BTC-USD', 'changes': [['buy', '38240.20', '0.00000000']], 'time': '2021-05-20T03:54:51.266299Z'}
{'type': 'l2update', 'product_id': 'BTC-USD', 'changes': [['sell', '38285.50', '0.00000000']], 'time': '2021-05-20T03:54:51.266299Z'}
{'type': 'l2update', 'product_id': 'BTC-USD', 'changes': [['buy', '38270.10', '0.01492000']], 'time': '2021-05-20T03:54:51.269224Z'}
{'type': 'l2update', 'product_id': 'BTC-USD', 'changes': [['sell', '38270.11', '0.00000000']], 'time': '2021-05-20T03:54:51.270302Z'}
{'type': 'l2update', 'product_id': 'BTC-USD', 'changes': [['buy', '38245.95', '0.00000000']], 'time': '2021-05-20T03:54:51.270582Z'}
{'type': 'l2update', 'product_id': 'BTC-USD', 'changes': [['buy', '38266.49', '0.15000000']], 'time': '2021-05-20T03:54:51.272586Z'}
{'type': 'l2update', 'product_id': 'BTC-USD', 'changes': [['buy', '38270.10', '0.08952000']], 'time': '2021-05-20T03:54:51.273758Z'}
{'type': 'l2update', 'product_id': 'BTC-USD', 'changes': [['buy', '38270.10', '0.07460000']], 'time': '2021-05-20T03:54:51.277105Z'}
{'type': 'l2update', 'product_id': 'BTC-USD', 'changes': [['sell', '38279.80', '0.00000000']], 'time': '2021-05-20T03:54:51.279028Z'}
{'type': 'l2update', 'product_id': 'BTC-USD', 'changes': [['buy', '38248.82', '0.00000000']], 'time': '2021-05-20T03:54:51.279054Z'}
{'type': 'l2update', 'product_id': 'BTC-USD', 'changes': [['buy', '38270.10', '0.00000000']], 'time': '2021-05-20T03:54:51.279138Z'}
{'type': 'l2update', 'product_id': 'BTC-USD', 'changes': [['buy', '38260.20', '0.00000000']], 'time': '2021-05-20T03:54:51.280685Z'}
{'type': 'l2update', 'product_id': 'BTC-USD', 'changes': [['buy', '38102.33', '0.00000000']], 'time': '2021-05-20T03:54:51.281009Z'}
{'type': 'l2update', 'product_id': 'BTC-USD', 'changes': [['sell', '38317.43', '0.00000000']], 'time': '2021-05-20T03:54:51.282025Z'}
{'type': 'l2update', 'product_id': 'BTC-USD', 'changes': [['buy', '38270.11', '0.02590000']], 'time': '2021-05-20T03:54:51.282158Z'}
{'type': 'l2update', 'product_id': 'BTC-USD', 'changes': [['buy', '38238.34', '0.04034673']], 'time': '2021-05-20T03:54:51.282274Z'}
{'type': 'l2update', 'product_id': 'BTC-USD', 'changes': [['sell', '38284.86', '0.05864535']], 'time': '2021-05-20T03:54:51.282274Z'}
{'type': 'l2update', 'product_id': 'BTC-USD', 'changes': [['buy', '38262.94', '0.00000000']], 'time': '2021-05-20T03:54:51.285744Z'}
{'type': 'l2update', 'product_id': 'BTC-USD', 'changes': [['sell', '38289.44', '0.00000000']], 'time': '2021-05-20T03:54:51.286136Z'}
{'type': 'l2update', 'product_id': 'BTC-USD', 'changes': [['buy', '38270.11', '0.00000000']], 'time': '2021-05-20T03:54:51.287190Z'}
{'type': 'l2update', 'product_id': 'BTC-USD', 'changes': [['buy', '38266.50', '0.35000000']], 'time': '2021-05-20T03:54:51.289242Z'}
{'type': 'l2update', 'product_id': 'BTC-USD', 'changes': [['buy', '38250.85', '0.06261042']], 'time': '2021-05-20T03:54:51.289391Z'}
{'type': 'l2update', 'product_id': 'BTC-USD', 'changes': [['sell', '38291.80', '0.06261042']], 'time': '2021-05-20T03:54:51.289415Z'}
{'type': 'l2update', 'product_id': 'BTC-USD', 'changes': [['buy', '38266.50', '0.25000000']], 'time': '2021-05-20T03:54:51.293528Z'}
{'type': 'l2update', 'product_id': 'BTC-USD', 'changes': [['sell', '38270.11', '0.33808528']], 'time': '2021-05-20T03:54:51.293754Z'}
{'type': 'l2update', 'product_id': 'BTC-USD', 'changes': [['sell', '38310.36', '0.00000000']], 'time': '2021-05-20T03:54:51.294229Z'}
{'type': 'l2update', 'product_id': 'BTC-USD', 'changes': [['sell', '38284.43', '0.04803129']], 'time': '2021-05-20T03:54:51.298050Z'}
{'type': 'l2update', 'product_id': 'BTC-USD', 'changes': [['sell', '38273.92', '0.00000000']], 'time': '2021-05-20T03:54:51.299182Z'}
{'type': 'l2update', 'product_id': 'BTC-USD', 'changes': [['buy', '38228.09', '0.00000000']], 'time': '2021-05-20T03:54:51.300090Z'}
{'type': 'l2update', 'product_id': 'BTC-USD', 'changes': [['sell', '38290.44', '0.06261042']], 'time': '2021-05-20T03:54:51.305769Z'}
{'type': 'l2update', 'product_id': 'BTC-USD', 'changes': [['buy', '38248.82', '0.06261042']], 'time': '2021-05-20T03:54:51.305898Z'}
{'type': 'l2update', 'product_id': 'BTC-USD', 'changes': [['sell', '38291.80', '0.00000000']], 'time': '2021-05-20T03:54:51.310543Z'}
{'type': 'l2update', 'product_id': 'BTC-USD', 'changes': [['buy', '38250.85', '0.00000000']], 'time': '2021-05-20T03:54:51.310832Z'}
{'type': 'l2update', 'product_id': 'BTC-USD', 'changes': [['buy', '38229.06', '0.00000000']], 'time': '2021-05-20T03:54:51.313516Z'}
{'type': 'l2update', 'product_id': 'BTC-USD', 'changes': [['sell', '38277.49', '2.48969908']], 'time': '2021-05-20T03:54:51.318825Z'}
{'type': 'l2update', 'product_id': 'BTC-USD', 'changes': [['buy', '38230.78', '0.00000000']], 'time': '2021-05-20T03:54:51.318840Z'}
{'type': 'l2update', 'product_id': 'BTC-USD', 'changes': [['buy', '38229.97', '0.00000000']], 'time': '2021-05-20T03:54:51.318840Z'}
{'type': 'l2update', 'product_id': 'BTC-USD', 'changes': [['sell', '38289.44', '0.06261042']], 'time': '2021-05-20T03:54:51.325942Z'}
{'type': 'l2update', 'product_id': 'BTC-USD', 'changes': [['sell', '38290.44', '0.00000000']], 'time': '2021-05-20T03:54:51.327565Z'}
{'type': 'l2update', 'product_id': 'BTC-USD', 'changes': [['buy', '38266.48', '0.00176529']], 'time': '2021-05-20T03:54:51.330123Z'}
{'type': 'l2update', 'product_id': 'BTC-USD', 'changes': [['buy', '38270.10', '0.01492000']], 'time': '2021-05-20T03:54:51.330268Z'}
{'type': 'l2update', 'product_id': 'BTC-USD', 'changes': [['buy', '38236.01', '0.02400000']], 'time': '2021-05-20T03:54:51.334133Z'}
{'type': 'l2update', 'product_id': 'BTC-USD', 'changes': [['buy', '38235.21', '0.02400000']], 'time': '2021-05-20T03:54:51.334133Z'}
{'type': 'l2update', 'product_id': 'BTC-USD', 'changes': [['buy', '38234.40', '0.02400000']], 'time': '2021-05-20T03:54:51.334133Z'}
{'type': 'l2update', 'product_id': 'BTC-USD', 'changes': [['buy', '38238.34', '0.00000000']], 'time': '2021-05-20T03:54:51.334227Z'}
{'type': 'l2update', 'product_id': 'BTC-USD', 'changes': [['sell', '38284.86', '0.00000000']], 'time': '2021-05-20T03:54:51.334227Z'}
{'type': 'l2update', 'product_id': 'BTC-USD', 'changes': [['buy', '38266.50', '0.05000000']], 'time': '2021-05-20T03:54:51.337334Z'}
{'type': 'l2update', 'product_id': 'BTC-USD', 'changes': [['buy', '38234.40', '0.00000000']], 'time': '2021-05-20T03:54:51.340166Z'}
{'type': 'l2update', 'product_id': 'BTC-USD', 'changes': [['sell', '38303.78', '0.00000000']], 'time': '2021-05-20T03:54:51.342190Z'}
{'type': 'l2update', 'product_id': 'BTC-USD', 'changes': [['buy', '38235.21', '0.00000000']], 'time': '2021-05-20T03:54:51.343562Z'}
{'type': 'l2update', 'product_id': 'BTC-USD', 'changes': [['buy', '38252.41', '0.52100000']], 'time': '2021-05-20T03:54:51.346836Z'}
{'type': 'l2update', 'product_id': 'BTC-USD', 'changes': [['buy', '38248.82', '0.00000000']], 'time': '2021-05-20T03:54:51.347979Z'}
{'type': 'l2update', 'product_id': 'BTC-USD', 'changes': [['sell', '38271.28', '0.00000000']], 'time': '2021-05-20T03:54:51.350134Z'}
{'type': 'l2update', 'product_id': 'BTC-USD', 'changes': [['buy', '38250.06', '0.06261042']], 'time': '2021-05-20T03:54:51.350510Z'}
{'type': 'l2update', 'product_id': 'BTC-USD', 'changes': [['sell', '50798.63', '0.00420900']], 'time': '2021-05-20T03:54:51.350817Z'}
{'type': 'l2update', 'product_id': 'BTC-USD', 'changes': [['buy', '38252.36', '0.00000000']], 'time': '2021-05-20T03:54:51.354634Z'}
{'type': 'l2update', 'product_id': 'BTC-USD', 'changes': [['buy', '38233.04', '0.00000000']], 'time': '2021-05-20T03:54:51.355003Z'}
{'type': 'l2update', 'product_id': 'BTC-USD', 'changes': [['buy', '38250.06', '0.00000000']], 'time': '2021-05-20T03:54:51.356647Z'}
{'type': 'l2update', 'product_id': 'BTC-USD', 'changes': [['sell', '38284.68', '0.00000000']], 'time': '2021-05-20T03:54:51.358202Z'}
{'type': 'l2update', 'product_id': 'BTC-USD', 'changes': [['buy', '38250.85', '0.06261042']], 'time': '2021-05-20T03:54:51.361987Z'}
{'type': 'l2update', 'product_id': 'BTC-USD', 'changes': [['buy', '38238.00', '0.02400000']], 'time': '2021-05-20T03:54:51.362025Z'}
{'type': 'l2update', 'product_id': 'BTC-USD', 'changes': [['buy', '38237.19', '0.02400000']], 'time': '2021-05-20T03:54:51.362025Z'}
{'type': 'l2update', 'product_id': 'BTC-USD', 'changes': [['sell', '38296.24', '0.00000000']], 'time': '2021-05-20T03:54:51.362908Z'}
{'type': 'l2update', 'product_id': 'BTC-USD', 'changes': [['sell', '38270.12', '0.00000000']], 'time': '2021-05-20T03:54:51.364516Z'}
{'type': 'l2update', 'product_id': 'BTC-USD', 'changes': [['sell', '38270.11', '0.00000000']], 'time': '2021-05-20T03:54:51.366666Z'}
{'type': 'l2update', 'product_id': 'BTC-USD', 'changes': [['buy', '38245.89', '0.00000000']], 'time': '2021-05-20T03:54:51.367131Z'}
{'type': 'l2update', 'product_id': 'BTC-USD', 'changes': [['buy', '38238.09', '0.14000000']], 'time': '2021-05-20T03:54:51.368466Z'}
{'type': 'l2update', 'product_id': 'BTC-USD', 'changes': [['buy', '38206.46', '0.00000000']], 'time': '2021-05-20T03:54:51.369421Z'}
{'type': 'l2update', 'product_id': 'BTC-USD', 'changes': [['buy', '38252.42', '0.06261042']], 'time': '2021-05-20T03:54:51.370292Z'}
{'type': 'l2update', 'product_id': 'BTC-USD', 'changes': [['buy', '38236.01', '0.00000000']], 'time': '2021-05-20T03:54:51.372136Z'}
{'type': 'l2update', 'product_id': 'BTC-USD', 'changes': [['buy', '38250.85', '0.00000000']], 'time': '2021-05-20T03:54:51.372159Z'}
{'type': 'l2update', 'product_id': 'BTC-USD', 'changes': [['buy', '38238.09', '0.12000000']], 'time': '2021-05-20T03:54:51.372195Z'}
{'type': 'l2update', 'product_id': 'BTC-USD', 'changes': [['buy', '38270.10', '0.00000000']], 'time': '2021-05-20T03:54:51.373315Z'}
{'type': 'l2update', 'product_id': 'BTC-USD', 'changes': [['buy', '38252.42', '0.31569070']], 'time': '2021-05-20T03:54:51.375029Z'}
{'type': 'l2update', 'product_id': 'BTC-USD', 'changes': [['buy', '38209.50', '0.02617150']], 'time': '2021-05-20T03:54:51.375358Z'}
{'type': 'l2update', 'product_id': 'BTC-USD', 'changes': [['buy', '38238.09', '0.09000000']], 'time': '2021-05-20T03:54:51.376260Z'}
{'type': 'l2update', 'product_id': 'BTC-USD', 'changes': [['sell', '38273.93', '0.15464385']], 'time': '2021-05-20T03:54:51.377895Z'}
{'type': 'l2update', 'product_id': 'BTC-USD', 'changes': [['buy', '38224.26', '0.00000000']], 'time': '2021-05-20T03:54:51.377937Z'}
{'type': 'l2update', 'product_id': 'BTC-USD', 'changes': [['sell', '38289.44', '0.00000000']], 'time': '2021-05-20T03:54:51.378586Z'}
{'type': 'l2update', 'product_id': 'BTC-USD', 'changes': [['sell', '38291.80', '0.06261042']], 'time': '2021-05-20T03:54:51.378707Z'}
{'type': 'l2update', 'product_id': 'BTC-USD', 'changes': [['sell', '38273.92', '0.50000000']], 'time': '2021-05-20T03:54:51.378798Z'}
{'type': 'l2update', 'product_id': 'BTC-USD', 'changes': [['buy', '38158.24', '0.00000000']], 'time': '2021-05-20T03:54:51.378943Z'}
{'type': 'l2update', 'product_id': 'BTC-USD', 'changes': [['sell', '38300.74', '0.00000000']], 'time': '2021-05-20T03:54:51.380596Z'}
{'type': 'l2update', 'product_id': 'BTC-USD', 'changes': [['buy', '38252.42', '0.25308028']], 'time': '2021-05-20T03:54:51.381738Z'}
{'type': 'l2update', 'product_id': 'BTC-USD', 'changes': [['sell', '38291.80', '0.00000000']], 'time': '2021-05-20T03:54:51.384178Z'}
{'type': 'l2update', 'product_id': 'BTC-USD', 'changes': [['buy', '38239.45', '0.02400000']], 'time': '2021-05-20T03:54:51.386849Z'}
{'type': 'l2update', 'product_id': 'BTC-USD', 'changes': [['buy', '38269.66', '0.04829385']], 'time': '2021-05-20T03:54:51.387085Z'}
{'type': 'l2update', 'product_id': 'BTC-USD', 'changes': [['buy', '38244.89', '0.01000000']], 'time': '2021-05-20T03:54:51.387433Z'}
{'type': 'l2update', 'product_id': 'BTC-USD', 'changes': [['sell', '38274.57', '0.33808528']], 'time': '2021-05-20T03:54:51.387606Z'}
{'type': 'l2update', 'product_id': 'BTC-USD', 'changes': [['sell', '38290.44', '0.06261042']], 'time': '2021-05-20T03:54:51.390864Z'}
{'type': 'l2update', 'product_id': 'BTC-USD', 'changes': [['sell', '38273.93', '0.35464385']], 'time': '2021-05-20T03:54:51.390912Z'}
{'type': 'l2update', 'product_id': 'BTC-USD', 'changes': [['buy', '38252.43', '0.06261042']], 'time': '2021-05-20T03:54:51.390924Z'}
{'type': 'l2update', 'product_id': 'BTC-USD', 'changes': [['buy', '38239.45', '0.00000000']], 'time': '2021-05-20T03:54:51.392772Z'}
{'type': 'l2update', 'product_id': 'BTC-USD', 'changes': [['sell', '38290.44', '0.00000000']], 'time': '2021-05-20T03:54:51.395665Z'}
{'type': 'l2update', 'product_id': 'BTC-USD', 'changes': [['buy', '38265.25', '0.00000000']], 'time': '2021-05-20T03:54:51.398776Z'}
{'type': 'l2update', 'product_id': 'BTC-USD', 'changes': [['buy', '38244.89', '0.03000000']], 'time': '2021-05-20T03:54:51.399588Z'}
{'type': 'l2update', 'product_id': 'BTC-USD', 'changes': [['sell', '38291.80', '0.06261042']], 'time': '2021-05-20T03:54:51.406865Z'}
{'type': 'l2update', 'product_id': 'BTC-USD', 'changes': [['sell', '38274.58', '0.00000000']], 'time': '2021-05-20T03:54:51.407142Z'}
{'type': 'l2update', 'product_id': 'BTC-USD', 'changes': [['buy', '38244.89', '0.06000000']], 'time': '2021-05-20T03:54:51.412129Z'}
{'type': 'l2update', 'product_id': 'BTC-USD', 'changes': [['sell', '38290.44', '0.06261042']], 'time': '2021-05-20T03:54:51.412369Z'}
{'type': 'l2update', 'product_id': 'BTC-USD', 'changes': [['sell', '38314.05', '0.01000000']], 'time': '2021-05-20T03:54:51.412387Z'}
{'type': 'l2update', 'product_id': 'BTC-USD', 'changes': [['buy', '38209.49', '0.02728571']], 'time': '2021-05-20T03:54:51.413008Z'}
{'type': 'l2update', 'product_id': 'BTC-USD', 'changes': [['sell', '38291.80', '0.00000000']], 'time': '2021-05-20T03:54:51.414145Z'}
{'type': 'l2update', 'product_id': 'BTC-USD', 'changes': [['sell', '38290.44', '0.00000000']], 'time': '2021-05-20T03:54:51.418917Z'}
{'type': 'l2update', 'product_id': 'BTC-USD', 'changes': [['buy', '38225.61', '0.00000000']], 'time': '2021-05-20T03:54:51.420679Z'}
{'type': 'l2update', 'product_id': 'BTC-USD', 'changes': [['buy', '38231.76', '0.01000000']], 'time': '2021-05-20T03:54:51.425045Z'}
{'type': 'l2update', 'product_id': 'BTC-USD', 'changes': [['sell', '38360.41', '0.00000000']], 'time': '2021-05-20T03:54:51.425653Z'}
{'type': 'l2update', 'product_id': 'BTC-USD', 'changes': [['buy', '38237.84', '0.00000000']], 'time': '2021-05-20T03:54:51.427332Z'}
{'type': 'l2update', 'product_id': 'BTC-USD', 'changes': [['sell', '38273.93', '0.15464385']], 'time': '2021-05-20T03:54:51.428302Z'}
{'type': 'l2update', 'product_id': 'BTC-USD', 'changes': [['sell', '38291.79', '0.06261042']], 'time': '2021-05-20T03:54:51.428864Z'}
{'type': 'l2update', 'product_id': 'BTC-USD', 'changes': [['sell', '38273.93', '0.05464385']], 'time': '2021-05-20T03:54:51.432184Z'}
{'type': 'l2update', 'product_id': 'BTC-USD', 'changes': [['buy', '38252.42', '0.00000000']], 'time': '2021-05-20T03:54:51.434385Z'}
{'type': 'l2update', 'product_id': 'BTC-USD', 'changes': [['buy', '38187.50', '0.00000000']], 'time': '2021-05-20T03:54:51.437051Z'}
{'type': 'l2update', 'product_id': 'BTC-USD', 'changes': [['buy', '38239.93', '0.45920000']], 'time': '2021-05-20T03:54:51.437859Z'}
{'type': 'l2update', 'product_id': 'BTC-USD', 'changes': [['sell', '38274.57', '0.00000000']], 'time': '2021-05-20T03:54:51.438426Z'}
{'type': 'l2update', 'product_id': 'BTC-USD', 'changes': [['sell', '38273.93', '0.00000000']], 'time': '2021-05-20T03:54:51.445403Z'}
{'type': 'l2update', 'product_id': 'BTC-USD', 'changes': [['buy', '38214.52', '0.02616806']], 'time': '2021-05-20T03:54:51.446340Z'}
{'type': 'l2update', 'product_id': 'BTC-USD', 'changes': [['buy', '38236.51', '0.02400000']], 'time': '2021-05-20T03:54:51.446380Z'}
{'type': 'l2update', 'product_id': 'BTC-USD', 'changes': [['buy', '38252.44', '0.25308028']], 'time': '2021-05-20T03:54:51.454984Z'}
{'type': 'l2update', 'product_id': 'BTC-USD', 'changes': [['sell', '38273.92', '0.00000000']], 'time': '2021-05-20T03:54:51.460001Z'}
{'type': 'l2update', 'product_id': 'BTC-USD', 'changes': [['sell', '38277.48', '0.33808528']], 'time': '2021-05-20T03:54:51.462675Z'}
{'type': 'l2update', 'product_id': 'BTC-USD', 'changes': [['sell', '38279.87', '0.07140000']], 'time': '2021-05-20T03:54:51.465584Z'}
{'type': 'l2update', 'product_id': 'BTC-USD', 'changes': [['sell', '38279.87', '0.07090000']], 'time': '2021-05-20T03:54:51.465604Z'}
{'type': 'l2update', 'product_id': 'BTC-USD', 'changes': [['sell', '38279.87', '0.00000000']], 'time': '2021-05-20T03:54:51.465912Z'}
{'type': 'l2update', 'product_id': 'BTC-USD', 'changes': [['sell', '38291.79', '0.00000000']], 'time': '2021-05-20T03:54:51.466676Z'}
{'type': 'l2update', 'product_id': 'BTC-USD', 'changes': [['sell', '38377.48', '0.00000000']], 'time': '2021-05-20T03:54:51.468392Z'}
{'type': 'l2update', 'product_id': 'BTC-USD', 'changes': [['buy', '38199.18', '0.00000000']], 'time': '2021-05-20T03:54:51.469022Z'}
{'type': 'l2update', 'product_id': 'BTC-USD', 'changes': [['sell', '38279.88', '0.00000000']], 'time': '2021-05-20T03:54:51.470253Z'}
{'type': 'l2update', 'product_id': 'BTC-USD', 'changes': [['buy', '38260.28', '0.84700000']], 'time': '2021-05-20T03:54:51.474574Z'}
{'type': 'l2update', 'product_id': 'BTC-USD', 'changes': [['buy', '38239.94', '0.09287703']], 'time': '2021-05-20T03:54:51.474658Z'}
{'type': 'l2update', 'product_id': 'BTC-USD', 'changes': [['sell', '38277.48', '0.83808528']], 'time': '2021-05-20T03:54:51.475009Z'}
{'type': 'l2update', 'product_id': 'BTC-USD', 'changes': [['sell', '38360.45', '0.01000000']], 'time': '2021-05-20T03:54:51.478607Z'}
{'type': 'l2update', 'product_id': 'BTC-USD', 'changes': [['sell', '38276.58', '0.05464385']], 'time': '2021-05-20T03:54:51.478656Z'}
{'type': 'l2update', 'product_id': 'BTC-USD', 'changes': [['sell', '38295.81', '0.06261042']], 'time': '2021-05-20T03:54:51.478931Z'}
{'type': 'l2update', 'product_id': 'BTC-USD', 'changes': [['buy', '38252.45', '0.06261042']], 'time': '2021-05-20T03:54:51.484924Z'}
{'type': 'l2update', 'product_id': 'BTC-USD', 'changes': [['buy', '38239.93', '0.00000000']], 'time': '2021-05-20T03:54:51.488665Z'}
{'type': 'l2update', 'product_id': 'BTC-USD', 'changes': [['buy', '38252.43', '0.00000000']], 'time': '2021-05-20T03:54:51.489723Z'}
{'type': 'l2update', 'product_id': 'BTC-USD', 'changes': [['sell', '38276.58', '0.04183972']], 'time': '2021-05-20T03:54:51.509568Z'}
{'type': 'l2update', 'product_id': 'BTC-USD', 'changes': [['sell', '38291.15', '0.00000000']], 'time': '2021-05-20T03:54:51.511942Z'}
{'type': 'l2update', 'product_id': 'BTC-USD', 'changes': [['sell', '50802.42', '0.00296600']], 'time': '2021-05-20T03:54:51.514160Z'}
{'type': 'l2update', 'product_id': 'BTC-USD', 'changes': [['sell', '38292.13', '0.00000000']], 'time': '2021-05-20T03:54:51.516180Z'}
{'type': 'l2update', 'product_id': 'BTC-USD', 'changes': [['sell', '38277.48', '0.50000000']], 'time': '2021-05-20T03:54:51.516883Z'}
{'type': 'l2update', 'product_id': 'BTC-USD', 'changes': [['buy', '37348.47', '0.04190000']], 'time': '2021-05-20T03:54:51.517897Z'}
{'type': 'l2update', 'product_id': 'BTC-USD', 'changes': [['buy', '36512.35', '0.05920000']], 'time': '2021-05-20T03:54:51.517897Z'}
{'type': 'l2update', 'product_id': 'BTC-USD', 'changes': [['buy', '38252.44', '0.00000000']], 'time': '2021-05-20T03:54:51.519676Z'}
{'type': 'l2update', 'product_id': 'BTC-USD', 'changes': [['sell', '38277.49', '0.00000000']], 'time': '2021-05-20T03:54:51.520132Z'}
{'type': 'l2update', 'product_id': 'BTC-USD', 'changes': [['sell', '38292.77', '0.00000000']], 'time': '2021-05-20T03:54:51.520149Z'}
{'type': 'l2update', 'product_id': 'BTC-USD', 'changes': [['sell', '38284.43', '0.00000000']], 'time': '2021-05-20T03:54:51.526405Z'}
{'type': 'l2update', 'product_id': 'BTC-USD', 'changes': [['sell', '38297.17', '0.02000000']], 'time': '2021-05-20T03:54:51.529854Z'}
{'type': 'l2update', 'product_id': 'BTC-USD', 'changes': [['sell', '38278.02', '0.00000000']], 'time': '2021-05-20T03:54:51.532232Z'}
{'type': 'l2update', 'product_id': 'BTC-USD', 'changes': [['sell', '38277.47', '0.33808528']], 'time': '2021-05-20T03:54:51.537568Z'}
{'type': 'l2update', 'product_id': 'BTC-USD', 'changes': [['sell', '38298.33', '0.03000000']], 'time': '2021-05-20T03:54:51.541928Z'}
{'type': 'l2update', 'product_id': 'BTC-USD', 'changes': [['sell', '38284.62', '2.48969908']], 'time': '2021-05-20T03:54:51.541960Z'}
{'type': 'l2update', 'product_id': 'BTC-USD', 'changes': [['sell', '38365.56', '0.00000000']], 'time': '2021-05-20T03:54:51.543555Z'}
{'type': 'l2update', 'product_id': 'BTC-USD', 'changes': [['buy', '38252.46', '0.25308028']], 'time': '2021-05-20T03:54:51.546654Z'}
{'type': 'l2update', 'product_id': 'BTC-USD', 'changes': [['buy', '38250.79', '0.00000000']], 'time': '2021-05-20T03:54:51.554537Z'}
{'type': 'l2update', 'product_id': 'BTC-USD', 'changes': [['sell', '38298.85', '0.04000000']], 'time': '2021-05-20T03:54:51.555310Z'}
{'type': 'l2update', 'product_id': 'BTC-USD', 'changes': [['sell', '38297.98', '0.00000000']], 'time': '2021-05-20T03:54:51.556039Z'}
{'type': 'l2update', 'product_id': 'BTC-USD', 'changes': [['sell', '38383.70', '0.00000000']], 'time': '2021-05-20T03:54:51.558784Z'}
{'type': 'l2update', 'product_id': 'BTC-USD', 'changes': [['sell', '38293.72', '0.00000000']], 'time': '2021-05-20T03:54:51.559191Z'}
{'type': 'l2update', 'product_id': 'BTC-USD', 'changes': [['sell', '38306.43', '0.00000000']], 'time': '2021-05-20T03:54:51.562722Z'}
{'type': 'l2update', 'product_id': 'BTC-USD', 'changes': [['sell', '38289.62', '0.00000000']], 'time': '2021-05-20T03:54:51.567159Z'}
{'type': 'l2update', 'product_id': 'BTC-USD', 'changes': [['buy', '38252.47', '0.05816453']], 'time': '2021-05-20T03:54:51.571901Z'}
{'type': 'l2update', 'product_id': 'BTC-USD', 'changes': [['sell', '38284.63', '0.00000000']], 'time': '2021-05-20T03:54:51.572971Z'}
{'type': 'l2update', 'product_id': 'BTC-USD', 'changes': [['sell', '38448.01', '0.00000000']], 'time': '2021-05-20T03:54:51.574817Z'}
{'type': 'l2update', 'product_id': 'BTC-USD', 'changes': [['sell', '38410.62', '0.01000000']], 'time': '2021-05-20T03:54:51.575654Z'}
{'type': 'l2update', 'product_id': 'BTC-USD', 'changes': [['buy', '38260.29', '0.58716278']], 'time': '2021-05-20T03:54:51.575785Z'}
{'type': 'l2update', 'product_id': 'BTC-USD', 'changes': [['sell', '38300.04', '0.43260000']], 'time': '2021-05-20T03:54:51.575928Z'}
{'type': 'l2update', 'product_id': 'BTC-USD', 'changes': [['sell', '38302.25', '0.05000000']], 'time': '2021-05-20T03:54:51.578566Z'}
{'type': 'l2update', 'product_id': 'BTC-USD', 'changes': [['buy', '38252.45', '0.00000000']], 'time': '2021-05-20T03:54:51.578734Z'}
{'type': 'l2update', 'product_id': 'BTC-USD', 'changes': [['buy', '38266.48', '0.00000000']], 'time': '2021-05-20T03:54:51.579586Z'}
{'type': 'l2update', 'product_id': 'BTC-USD', 'changes': [['sell', '38300.04', '0.00000000']], 'time': '2021-05-20T03:54:51.581810Z'}
{'type': 'l2update', 'product_id': 'BTC-USD', 'changes': [['buy', '38235.78', '2.37600000']], 'time': '2021-05-20T03:54:51.583164Z'}
{'type': 'l2update', 'product_id': 'BTC-USD', 'changes': [['sell', '38277.48', '0.00000000']], 'time': '2021-05-20T03:54:51.590067Z'}
{'type': 'l2update', 'product_id': 'BTC-USD', 'changes': [['sell', '38298.76', '0.01000000']], 'time': '2021-05-20T03:54:51.590637Z'}
{'type': 'l2update', 'product_id': 'BTC-USD', 'changes': [['sell', '38388.20', '0.00000000']], 'time': '2021-05-20T03:54:51.590730Z'}
{'type': 'l2update', 'product_id': 'BTC-USD', 'changes': [['sell', '38284.62', '0.00000000']], 'time': '2021-05-20T03:54:51.593901Z'}
{'type': 'l2update', 'product_id': 'BTC-USD', 'changes': [['sell', '38415.88', '0.00000000']], 'time': '2021-05-20T03:54:51.595362Z'}
{'type': 'l2update', 'product_id': 'BTC-USD', 'changes': [['sell', '38370.58', '0.02400000']], 'time': '2021-05-20T03:54:51.595559Z'}
{'type': 'l2update', 'product_id': 'BTC-USD', 'changes': [['sell', '38295.81', '0.00000000']], 'time': '2021-05-20T03:54:51.597332Z'}
{'type': 'l2update', 'product_id': 'BTC-USD', 'changes': [['sell', '38277.47', '0.00000000']], 'time': '2021-05-20T03:54:51.598827Z'}
{'type': 'l2update', 'product_id': 'BTC-USD', 'changes': [['sell', '38276.58', '0.00000000']], 'time': '2021-05-20T03:54:51.602539Z'}
{'type': 'l2update', 'product_id': 'BTC-USD', 'changes': [['sell', '38426.73', '0.00780706']], 'time': '2021-05-20T03:54:51.603796Z'}
{'type': 'l2update', 'product_id': 'BTC-USD', 'changes': [['buy', '38260.34', '0.52100000']], 'time': '2021-05-20T03:54:51.603811Z'}
{'type': 'l2update', 'product_id': 'BTC-USD', 'changes': [['sell', '38304.73', '0.05816453']], 'time': '2021-05-20T03:54:51.603866Z'}
{'type': 'l2update', 'product_id': 'BTC-USD', 'changes': [['sell', '38284.61', '0.50000000']], 'time': '2021-05-20T03:54:51.603913Z'}
{'type': 'l2update', 'product_id': 'BTC-USD', 'changes': [['buy', '38252.46', '0.00000000']], 'time': '2021-05-20T03:54:51.603956Z'}
{'type': 'l2update', 'product_id': 'BTC-USD', 'changes': [['buy', '38207.56', '0.00000000']], 'time': '2021-05-20T03:54:51.605985Z'}
{'type': 'l2update', 'product_id': 'BTC-USD', 'changes': [['sell', '38387.11', '0.01000000']], 'time': '2021-05-20T03:54:51.608133Z'}
{'type': 'l2update', 'product_id': 'BTC-USD', 'changes': [['sell', '38295.82', '0.00000000']], 'time': '2021-05-20T03:54:51.608315Z'}
{'type': 'l2update', 'product_id': 'BTC-USD', 'changes': [['sell', '38423.70', '0.01000000']], 'time': '2021-05-20T03:54:51.608466Z'}
{'type': 'l2update', 'product_id': 'BTC-USD', 'changes': [['sell', '38284.61', '0.00000000']], 'time': '2021-05-20T03:54:51.611884Z'}
{'type': 'l2update', 'product_id': 'BTC-USD', 'changes': [['buy', '38218.55', '0.10000000']], 'time': '2021-05-20T03:54:51.616685Z'}
{'type': 'l2update', 'product_id': 'BTC-USD', 'changes': [['buy', '38256.14', '0.20600000']], 'time': '2021-05-20T03:54:51.616743Z'}
{'type': 'l2update', 'product_id': 'BTC-USD', 'changes': [['buy', '38239.84', '0.40650000']], 'time': '2021-05-20T03:54:51.616797Z'}
{'type': 'l2update', 'product_id': 'BTC-USD', 'changes': [['sell', '38289.44', '2.48969908']], 'time': '2021-05-20T03:54:51.620050Z'}
{'type': 'l2update', 'product_id': 'BTC-USD', 'changes': [['sell', '38289.44', '2.82778436']], 'time': '2021-05-20T03:54:51.620528Z'}
{'type': 'l2update', 'product_id': 'BTC-USD', 'changes': [['sell', '38289.45', '0.12905773']], 'time': '2021-05-20T03:54:51.620884Z'}
{'type': 'l2update', 'product_id': 'BTC-USD', 'changes': [['buy', '38239.84', '0.00000000']], 'time': '2021-05-20T03:54:51.624159Z'}
{'type': 'l2update', 'product_id': 'BTC-USD', 'changes': [['buy', '38260.35', '0.25308028']], 'time': '2021-05-20T03:54:51.624517Z'}
{'type': 'l2update', 'product_id': 'BTC-USD', 'changes': [['sell', '38289.44', '3.32778436']], 'time': '2021-05-20T03:54:51.628294Z'}
{'type': 'l2update', 'product_id': 'BTC-USD', 'changes': [['sell', '38283.28', '0.04183972']], 'time': '2021-05-20T03:54:51.628348Z'}
{'type': 'l2update', 'product_id': 'BTC-USD', 'changes': [['sell', '38304.73', '0.10816453']], 'time': '2021-05-20T03:54:51.633524Z'}
{'type': 'l2update', 'product_id': 'BTC-USD', 'changes': [['sell', '38289.45', '0.00000000']], 'time': '2021-05-20T03:54:51.636426Z'}
{'type': 'l2update', 'product_id': 'BTC-USD', 'changes': [['buy', '38235.96', '0.00000000']], 'time': '2021-05-20T03:54:51.646491Z'}
{'type': 'l2update', 'product_id': 'BTC-USD', 'changes': [['buy', '38266.50', '0.05176529']], 'time': '2021-05-20T03:54:51.648024Z'}
{'type': 'l2update', 'product_id': 'BTC-USD', 'changes': [['buy', '38235.78', '0.00000000']], 'time': '2021-05-20T03:54:51.651105Z'}
{'type': 'l2update', 'product_id': 'BTC-USD', 'changes': [['sell', '38277.50', '0.00000000']], 'time': '2021-05-20T03:54:51.654139Z'}
{'type': 'l2update', 'product_id': 'BTC-USD', 'changes': [['sell', '38355.56', '0.00000000']], 'time': '2021-05-20T03:54:51.654363Z'}
{'type': 'l2update', 'product_id': 'BTC-USD', 'changes': [['sell', '38349.99', '0.00000000']], 'time': '2021-05-20T03:54:51.655777Z'}
{'type': 'l2update', 'product_id': 'BTC-USD', 'changes': [['sell', '38370.58', '0.00000000']], 'time': '2021-05-20T03:54:51.656562Z'}
{'type': 'l2update', 'product_id': 'BTC-USD', 'changes': [['buy', '38248.81', '0.00000000']], 'time': '2021-05-20T03:54:51.659094Z'}
{'type': 'l2update', 'product_id': 'BTC-USD', 'changes': [['sell', '38314.05', '0.00000000']], 'time': '2021-05-20T03:54:51.663247Z'}
{'type': 'l2update', 'product_id': 'BTC-USD', 'changes': [['sell', '38289.46', '0.00000000']], 'time': '2021-05-20T03:54:51.665296Z'}
{'type': 'l2update', 'product_id': 'BTC-USD', 'changes': [['buy', '38245.94', '0.00000000']], 'time': '2021-05-20T03:54:51.666541Z'}
{'type': 'l2update', 'product_id': 'BTC-USD', 'changes': [['buy', '38231.76', '0.00000000']], 'time': '2021-05-20T03:54:51.669727Z'}
{'type': 'l2update', 'product_id': 'BTC-USD', 'changes': [['buy', '38214.53', '0.48621702']], 'time': '2021-05-20T03:54:51.670180Z'}
{'type': 'l2update', 'product_id': 'BTC-USD', 'changes': [['buy', '38270.08', '0.07460000']], 'time': '2021-05-20T03:54:51.670198Z'}
{'type': 'l2update', 'product_id': 'BTC-USD', 'changes': [['buy', '38269.92', '0.01492000']], 'time': '2021-05-20T03:54:51.670470Z'}
{'type': 'l2update', 'product_id': 'BTC-USD', 'changes': [['sell', '38289.44', '2.98969908']], 'time': '2021-05-20T03:54:51.672338Z'}
{'type': 'l2update', 'product_id': 'BTC-USD', 'changes': [['sell', '38299.43', '0.40070000']], 'time': '2021-05-20T03:54:51.674557Z'}
{'type': 'l2update', 'product_id': 'BTC-USD', 'changes': [['sell', '38410.28', '0.31295219']], 'time': '2021-05-20T03:54:51.675000Z'}
{'type': 'l2update', 'product_id': 'BTC-USD', 'changes': [['sell', '50806.75', '0.00431300']], 'time': '2021-05-20T03:54:51.678398Z'}
{'type': 'l2update', 'product_id': 'BTC-USD', 'changes': [['buy', '38269.92', '0.00000000']], 'time': '2021-05-20T03:54:51.678874Z'}
{'type': 'l2update', 'product_id': 'BTC-USD', 'changes': [['sell', '38304.73', '0.05816453']], 'time': '2021-05-20T03:54:51.685079Z'}
{'type': 'l2update', 'product_id': 'BTC-USD', 'changes': [['sell', '38284.69', '0.00936345']], 'time': '2021-05-20T03:54:51.693850Z'}
{'type': 'l2update', 'product_id': 'BTC-USD', 'changes': [['sell', '38299.42', '0.05000000']], 'time': '2021-05-20T03:54:51.694188Z'}
{'type': 'l2update', 'product_id': 'BTC-USD', 'changes': [['sell', '38334.58', '0.07700000']], 'time': '2021-05-20T03:54:51.697584Z'}
{'type': 'l2update', 'product_id': 'BTC-USD', 'changes': [['sell', '38289.43', '0.33808528']], 'time': '2021-05-20T03:54:51.697603Z'}
{'type': 'l2update', 'product_id': 'BTC-USD', 'changes': [['buy', '38278.46', '0.01112510']], 'time': '2021-05-20T03:54:51.701603Z'}
{'type': 'l2update', 'product_id': 'BTC-USD', 'changes': [['buy', '38270.43', '0.01492000']], 'time': '2021-05-20T03:54:51.706160Z'}
{'type': 'l2update', 'product_id': 'BTC-USD', 'changes': [['buy', '38270.08', '0.00000000']], 'time': '2021-05-20T03:54:51.707674Z'}
{'type': 'l2update', 'product_id': 'BTC-USD', 'changes': [['buy', '38252.47', '0.00000000']], 'time': '2021-05-20T03:54:51.708559Z'}
{'type': 'l2update', 'product_id': 'BTC-USD', 'changes': [['buy', '38270.43', '0.00000000']], 'time': '2021-05-20T03:54:51.711404Z'}
{'type': 'l2update', 'product_id': 'BTC-USD', 'changes': [['buy', '38269.67', '0.05000000']], 'time': '2021-05-20T03:54:51.712853Z'}
{'type': 'l2update', 'product_id': 'BTC-USD', 'changes': [['buy', '38245.39', '0.45160000']], 'time': '2021-05-20T03:54:51.717255Z'}
{'type': 'l2update', 'product_id': 'BTC-USD', 'changes': [['buy', '38248.84', '0.39490431']], 'time': '2021-05-20T03:54:51.717353Z'}
{'type': 'l2update', 'product_id': 'BTC-USD', 'changes': [['buy', '38256.15', '0.05816453']], 'time': '2021-05-20T03:54:51.717448Z'}
{'type': 'l2update', 'product_id': 'BTC-USD', 'changes': [['sell', '38289.44', '2.48969908']], 'time': '2021-05-20T03:54:51.734433Z'}
{'type': 'l2update', 'product_id': 'BTC-USD', 'changes': [['sell', '38289.38', '1.16900000']], 'time': '2021-05-20T03:54:51.735604Z'}
{'type': 'l2update', 'product_id': 'BTC-USD', 'changes': [['buy', '38278.46', '0.00000000']], 'time': '2021-05-20T03:54:51.736230Z'}
{'type': 'l2update', 'product_id': 'BTC-USD', 'changes': [['sell', '38279.89', '0.22000000']], 'time': '2021-05-20T03:54:51.742963Z'}
{'type': 'l2update', 'product_id': 'BTC-USD', 'changes': [['sell', '38283.27', '0.50000000']], 'time': '2021-05-20T03:54:51.747253Z'}
{'type': 'l2update', 'product_id': 'BTC-USD', 'changes': [['buy', '38269.67', '0.00000000']], 'time': '2021-05-20T03:54:51.748023Z'}
{'type': 'l2update', 'product_id': 'BTC-USD', 'changes': [['buy', '38270.30', '0.07460000']], 'time': '2021-05-20T03:54:51.750423Z'}
{'type': 'l2update', 'product_id': 'BTC-USD', 'changes': [['buy', '38269.96', '0.01492000']], 'time': '2021-05-20T03:54:51.750509Z'}
{'type': 'l2update', 'product_id': 'BTC-USD', 'changes': [['buy', '38269.96', '0.00000000']], 'time': '2021-05-20T03:54:51.757626Z'}
{'type': 'l2update', 'product_id': 'BTC-USD', 'changes': [['buy', '38249.91', '0.04033788']], 'time': '2021-05-20T03:54:51.758358Z'}
{'type': 'l2update', 'product_id': 'BTC-USD', 'changes': [['sell', '38290.58', '0.04644831']], 'time': '2021-05-20T03:54:51.758358Z'}
{'type': 'l2update', 'product_id': 'BTC-USD', 'changes': [['buy', '38252.42', '0.05816453']], 'time': '2021-05-20T03:54:51.758453Z'}
{'type': 'l2update', 'product_id': 'BTC-USD', 'changes': [['buy', '38138.93', '0.00000000']], 'time': '2021-05-20T03:54:51.760661Z'}
{'type': 'l2update', 'product_id': 'BTC-USD', 'changes': [['buy', '38185.21', '0.00000000']], 'time': '2021-05-20T03:54:51.761955Z'}
{'type': 'l2update', 'product_id': 'BTC-USD', 'changes': [['buy', '38238.09', '0.05000000']], 'time': '2021-05-20T03:54:51.762275Z'}
{'type': 'l2update', 'product_id': 'BTC-USD', 'changes': [['buy', '38238.09', '0.00000000']], 'time': '2021-05-20T03:54:51.767102Z'}
{'type': 'l2update', 'product_id': 'BTC-USD', 'changes': [['buy', '38252.42', '0.00000000']], 'time': '2021-05-20T03:54:51.768319Z'}
{'type': 'l2update', 'product_id': 'BTC-USD', 'changes': [['buy', '38256.15', '0.00000000']], 'time': '2021-05-20T03:54:51.768432Z'}
{'type': 'l2update', 'product_id': 'BTC-USD', 'changes': [['sell', '38289.43', '0.00000000']], 'time': '2021-05-20T03:54:51.771855Z'}
{'type': 'l2update', 'product_id': 'BTC-USD', 'changes': [['sell', '38384.37', '0.00000000']], 'time': '2021-05-20T03:54:51.773531Z'}
{'type': 'l2update', 'product_id': 'BTC-USD', 'changes': [['buy', '38150.86', '0.03577500']], 'time': '2021-05-20T03:54:51.774174Z'}
{'type': 'l2update', 'product_id': 'BTC-USD', 'changes': [['sell', '38370.18', '0.12272820']], 'time': '2021-05-20T03:54:51.774377Z'}
{'type': 'l2update', 'product_id': 'BTC-USD', 'changes': [['buy', '38270.93', '0.01492000']], 'time': '2021-05-20T03:54:51.774529Z'}
{'type': 'l2update', 'product_id': 'BTC-USD', 'changes': [['buy', '38270.30', '0.00000000']], 'time': '2021-05-20T03:54:51.781379Z'}
{'type': 'l2update', 'product_id': 'BTC-USD', 'changes': [['buy', '38250.85', '0.05816453']], 'time': '2021-05-20T03:54:51.784608Z'}
{'type': 'l2update', 'product_id': 'BTC-USD', 'changes': [['buy', '38244.89', '0.10000000']], 'time': '2021-05-20T03:54:51.784635Z'}
{'type': 'l2update', 'product_id': 'BTC-USD', 'changes': [['sell', '38396.49', '0.01302202']], 'time': '2021-05-20T03:54:51.786325Z'}
{'type': 'l2update', 'product_id': 'BTC-USD', 'changes': [['buy', '38250.85', '0.00000000']], 'time': '2021-05-20T03:54:51.791170Z'}
{'type': 'l2update', 'product_id': 'BTC-USD', 'changes': [['sell', '38319.03', '0.01000000']], 'time': '2021-05-20T03:54:51.792163Z'}
{'type': 'l2update', 'product_id': 'BTC-USD', 'changes': [['sell', '38283.28', '0.00000000']], 'time': '2021-05-20T03:54:51.792544Z'}
{'type': 'l2update', 'product_id': 'BTC-USD', 'changes': [['sell', '38283.26', '0.33808528']], 'time': '2021-05-20T03:54:51.794607Z'}
{'type': 'l2update', 'product_id': 'BTC-USD', 'changes': [['buy', '38269.67', '0.05000000']], 'time': '2021-05-20T03:54:51.794860Z'}
{'type': 'l2update', 'product_id': 'BTC-USD', 'changes': [['buy', '38252.42', '0.05816453']], 'time': '2021-05-20T03:54:51.798686Z'}
{'type': 'l2update', 'product_id': 'BTC-USD', 'changes': [['buy', '38244.89', '0.15000000']], 'time': '2021-05-20T03:54:51.798833Z'}
{'type': 'l2update', 'product_id': 'BTC-USD', 'changes': [['buy', '38270.93', '0.00000000']], 'time': '2021-05-20T03:54:51.802676Z'}
{'type': 'l2update', 'product_id': 'BTC-USD', 'changes': [['buy', '38236.73', '0.01000000']], 'time': '2021-05-20T03:54:51.804038Z'}
{'type': 'l2update', 'product_id': 'BTC-USD', 'changes': [['buy', '38271.57', '0.07460000']], 'time': '2021-05-20T03:54:51.804072Z'}
{'type': 'l2update', 'product_id': 'BTC-USD', 'changes': [['buy', '38271.57', '0.00000000']], 'time': '2021-05-20T03:54:51.804339Z'}
{'type': 'l2update', 'product_id': 'BTC-USD', 'changes': [['buy', '38269.67', '0.01627557']], 'time': '2021-05-20T03:54:51.804339Z'}
{'type': 'l2update', 'product_id': 'BTC-USD', 'changes': [['buy', '38252.42', '0.00000000']], 'time': '2021-05-20T03:54:51.805596Z'}
{'type': 'l2update', 'product_id': 'BTC-USD', 'changes': [['sell', '38297.16', '0.13047002']], 'time': '2021-05-20T03:54:51.810245Z'}
{'type': 'l2update', 'product_id': 'BTC-USD', 'changes': [['buy', '38250.85', '0.05816453']], 'time': '2021-05-20T03:54:51.816743Z'}
{'type': 'l2update', 'product_id': 'BTC-USD', 'changes': [['sell', '38304.73', '0.00000000']], 'time': '2021-05-20T03:54:51.820948Z'}
{'type': 'l2update', 'product_id': 'BTC-USD', 'changes': [['sell', '38279.39', '0.06642072']], 'time': '2021-05-20T03:54:51.822678Z'}
{'type': 'l2update', 'product_id': 'BTC-USD', 'changes': [['buy', '38270.11', '0.01492000']], 'time': '2021-05-20T03:54:51.822710Z'}
{'type': 'l2update', 'product_id': 'BTC-USD', 'changes': [['buy', '38250.85', '0.00000000']], 'time': '2021-05-20T03:54:51.826108Z'}
{'type': 'l2update', 'product_id': 'BTC-USD', 'changes': [['sell', '38302.24', '0.05816453']], 'time': '2021-05-20T03:54:51.827073Z'}
{'type': 'l2update', 'product_id': 'BTC-USD', 'changes': [['sell', '38286.66', '0.03761656']], 'time': '2021-05-20T03:54:51.827267Z'}
{'type': 'l2update', 'product_id': 'BTC-USD', 'changes': [['buy', '38270.11', '0.00000000']], 'time': '2021-05-20T03:54:51.830217Z'}
{'type': 'l2update', 'product_id': 'BTC-USD', 'changes': [['sell', '38279.89', '0.02000000']], 'time': '2021-05-20T03:54:51.832022Z'}
{'type': 'l2update', 'product_id': 'BTC-USD', 'changes': [['sell', '38299.43', '0.00000000']], 'time': '2021-05-20T03:54:51.839012Z'}
{'type': 'l2update', 'product_id': 'BTC-USD', 'changes': [['buy', '38245.39', '2.82760000']], 'time': '2021-05-20T03:54:51.839329Z'}
{'type': 'l2update', 'product_id': 'BTC-USD', 'changes': [['buy', '38248.85', '0.05816453']], 'time': '2021-05-20T03:54:51.839498Z'}
{'type': 'l2update', 'product_id': 'BTC-USD', 'changes': [['buy', '38270.22', '0.02205312']], 'time': '2021-05-20T03:54:51.839576Z'}
{'type': 'l2update', 'product_id': 'BTC-USD', 'changes': [['sell', '50813.15', '0.00420900']], 'time': '2021-05-20T03:54:51.843826Z'}
{'type': 'l2update', 'product_id': 'BTC-USD', 'changes': [['buy', '38248.85', '0.00000000']], 'time': '2021-05-20T03:54:51.846492Z'}
{'type': 'l2update', 'product_id': 'BTC-USD', 'changes': [['sell', '38283.26', '0.00000000']], 'time': '2021-05-20T03:54:51.848092Z'}
{'type': 'l2update', 'product_id': 'BTC-USD', 'changes': [['sell', '38302.24', '0.00000000']], 'time': '2021-05-20T03:54:51.849037Z'}
{'type': 'l2update', 'product_id': 'BTC-USD', 'changes': [['buy', '38269.97', '0.01492000']], 'time': '2021-05-20T03:54:51.849215Z'}
{'type': 'l2update', 'product_id': 'BTC-USD', 'changes': [['buy', '38269.97', '0.00000000']], 'time': '2021-05-20T03:54:51.854955Z'}
{'type': 'l2update', 'product_id': 'BTC-USD', 'changes': [['buy', '38245.40', '0.05816453']], 'time': '2021-05-20T03:54:51.856209Z'}
{'type': 'l2update', 'product_id': 'BTC-USD', 'changes': [['sell', '38380.22', '0.02400000']], 'time': '2021-05-20T03:54:51.856363Z'}
{'type': 'l2update', 'product_id': 'BTC-USD', 'changes': [['sell', '38301.30', '0.42250000']], 'time': '2021-05-20T03:54:51.856460Z'}
{'type': 'l2update', 'product_id': 'BTC-USD', 'changes': [['sell', '38304.73', '0.05816453']], 'time': '2021-05-20T03:54:51.857163Z'}
{'type': 'l2update', 'product_id': 'BTC-USD', 'changes': [['buy', '37475.72', '0.00000000']], 'time': '2021-05-20T03:54:51.861739Z'}
{'type': 'l2update', 'product_id': 'BTC-USD', 'changes': [['buy', '37471.32', '0.00000000']], 'time': '2021-05-20T03:54:51.861739Z'}
{'type': 'l2update', 'product_id': 'BTC-USD', 'changes': [['buy', '37469.35', '0.06130000']], 'time': '2021-05-20T03:54:51.861739Z'}
{'type': 'l2update', 'product_id': 'BTC-USD', 'changes': [['sell', '38304.61', '0.00000000']], 'time': '2021-05-20T03:54:51.864800Z'}
{'type': 'l2update', 'product_id': 'BTC-USD', 'changes': [['buy', '38248.86', '0.05816453']], 'time': '2021-05-20T03:54:51.864812Z'}
{'type': 'l2update', 'product_id': 'BTC-USD', 'changes': [['buy', '38245.39', '2.37600000']], 'time': '2021-05-20T03:54:51.865003Z'}
{'type': 'l2update', 'product_id': 'BTC-USD', 'changes': [['buy', '38260.28', '0.00000000']], 'time': '2021-05-20T03:54:51.865243Z'}
{'type': 'l2update', 'product_id': 'BTC-USD', 'changes': [['buy', '38245.40', '0.00000000']], 'time': '2021-05-20T03:54:51.866654Z'}
{'type': 'l2update', 'product_id': 'BTC-USD', 'changes': [['sell', '38299.42', '0.00000000']], 'time': '2021-05-20T03:54:51.867526Z'}
{'type': 'l2update', 'product_id': 'BTC-USD', 'changes': [['buy', '38266.55', '0.84900000']], 'time': '2021-05-20T03:54:51.870938Z'}
{'type': 'l2update', 'product_id': 'BTC-USD', 'changes': [['buy', '38250.84', '0.00000000']], 'time': '2021-05-20T03:54:51.875434Z'}
{'type': 'l2update', 'product_id': 'BTC-USD', 'changes': [['buy', '38266.50', '0.05000000']], 'time': '2021-05-20T03:54:51.878532Z'}
{'type': 'l2update', 'product_id': 'BTC-USD', 'changes': [['buy', '37500.01', '0.13260000']], 'time': '2021-05-20T03:54:51.884436Z'}
{'type': 'l2update', 'product_id': 'BTC-USD', 'changes': [['buy', '37500.02', '0.00720000']], 'time': '2021-05-20T03:54:51.884436Z'}
{'type': 'l2update', 'product_id': 'BTC-USD', 'changes': [['sell', '38289.37', '0.33808528']], 'time': '2021-05-20T03:54:51.884451Z'}
{'type': 'l2update', 'product_id': 'BTC-USD', 'changes': [['buy', '38270.72', '0.01492000']], 'time': '2021-05-20T03:54:51.888799Z'}
{'type': 'l2update', 'product_id': 'BTC-USD', 'changes': [['sell', '38301.29', '0.05000000']], 'time': '2021-05-20T03:54:51.889060Z'}
{'type': 'l2update', 'product_id': 'BTC-USD', 'changes': [['sell', '38371.13', '0.05454416']], 'time': '2021-05-20T03:54:51.889232Z'}
{'type': 'l2update', 'product_id': 'BTC-USD', 'changes': [['buy', '38243.98', '0.48640000']], 'time': '2021-05-20T03:54:51.890690Z'}
{'type': 'l2update', 'product_id': 'BTC-USD', 'changes': [['buy', '38270.22', '0.00000000']], 'time': '2021-05-20T03:54:51.897166Z'}
{'type': 'l2update', 'product_id': 'BTC-USD', 'changes': [['buy', '38243.98', '0.00000000']], 'time': '2021-05-20T03:54:51.900599Z'}
{'type': 'l2update', 'product_id': 'BTC-USD', 'changes': [['buy', '38270.99', '0.05254688']], 'time': '2021-05-20T03:54:51.904404Z'}
{'type': 'l2update', 'product_id': 'BTC-USD', 'changes': [['sell', '38324.88', '0.00000000']], 'time': '2021-05-20T03:54:51.906309Z'}
{'type': 'l2update', 'product_id': 'BTC-USD', 'changes': [['sell', '38301.30', '0.00000000']], 'time': '2021-05-20T03:54:51.909231Z'}
{'type': 'l2update', 'product_id': 'BTC-USD', 'changes': [['sell', '38304.73', '0.00000000']], 'time': '2021-05-20T03:54:51.911673Z'}
{'type': 'l2update', 'product_id': 'BTC-USD', 'changes': [['sell', '38360.82', '0.02727208']], 'time': '2021-05-20T03:54:51.913437Z'}
{'type': 'l2update', 'product_id': 'BTC-USD', 'changes': [['sell', '38402.36', '0.00000000']], 'time': '2021-05-20T03:54:51.914047Z'}
{'type': 'l2update', 'product_id': 'BTC-USD', 'changes': [['sell', '38361.39', '0.00000000']], 'time': '2021-05-20T03:54:51.914331Z'}
{'type': 'l2update', 'product_id': 'BTC-USD', 'changes': [['buy', '38270.72', '0.00000000']], 'time': '2021-05-20T03:54:51.914562Z'}
{'type': 'l2update', 'product_id': 'BTC-USD', 'changes': [['buy', '38269.66', '0.05005909']], 'time': '2021-05-20T03:54:51.919350Z'}
{'type': 'l2update', 'product_id': 'BTC-USD', 'changes': [['buy', '38270.99', '0.00000000']], 'time': '2021-05-20T03:54:51.924167Z'}
{'type': 'l2update', 'product_id': 'BTC-USD', 'changes': [['sell', '38310.49', '0.05816453']], 'time': '2021-05-20T03:54:51.928106Z'}
{'type': 'l2update', 'product_id': 'BTC-USD', 'changes': [['sell', '38396.59', '0.02886117']], 'time': '2021-05-20T03:54:51.936258Z'}
{'type': 'l2update', 'product_id': 'BTC-USD', 'changes': [['buy', '38271.51', '0.01492000']], 'time': '2021-05-20T03:54:51.937029Z'}
{'type': 'l2update', 'product_id': 'BTC-USD', 'changes': [['buy', '38270.27', '0.02205312']], 'time': '2021-05-20T03:54:51.937351Z'}
{'type': 'l2update', 'product_id': 'BTC-USD', 'changes': [['sell', '38387.44', '0.03439855']], 'time': '2021-05-20T03:54:51.937391Z'}
{'type': 'l2update', 'product_id': 'BTC-USD', 'changes': [['sell', '38520.00', '0.00000000']], 'time': '2021-05-20T03:54:51.939582Z'}
{'type': 'l2update', 'product_id': 'BTC-USD', 'changes': [['sell', '38298.85', '0.00000000']], 'time': '2021-05-20T03:54:51.942584Z'}
{'type': 'l2update', 'product_id': 'BTC-USD', 'changes': [['buy', '38248.86', '0.00000000']], 'time': '2021-05-20T03:54:51.944105Z'}
{'type': 'l2update', 'product_id': 'BTC-USD', 'changes': [['buy', '38271.51', '0.00000000']], 'time': '2021-05-20T03:54:51.945922Z'}
{'type': 'l2update', 'product_id': 'BTC-USD', 'changes': [['buy', '38270.27', '0.00000000']], 'time': '2021-05-20T03:54:51.947245Z'}
{'type': 'l2update', 'product_id': 'BTC-USD', 'changes': [['buy', '38174.35', '0.00000000']], 'time': '2021-05-20T03:54:51.947399Z'}
{'type': 'l2update', 'product_id': 'BTC-USD', 'changes': [['sell', '38279.39', '0.00000000']], 'time': '2021-05-20T03:54:51.948393Z'}
{'type': 'l2update', 'product_id': 'BTC-USD', 'changes': [['sell', '38341.16', '0.00000000']], 'time': '2021-05-20T03:54:51.952300Z'}
{'type': 'l2update', 'product_id': 'BTC-USD', 'changes': [['buy', '38245.40', '0.05816453']], 'time': '2021-05-20T03:54:51.954568Z'}
{'type': 'l2update', 'product_id': 'BTC-USD', 'changes': [['buy', '38266.50', '0.00000000']], 'time': '2021-05-20T03:54:51.955942Z'}
{'type': 'l2update', 'product_id': 'BTC-USD', 'changes': [['buy', '38249.91', '0.00000000']], 'time': '2021-05-20T03:54:51.956912Z'}
{'type': 'l2update', 'product_id': 'BTC-USD', 'changes': [['sell', '38394.55', '0.00000000']], 'time': '2021-05-20T03:54:51.959403Z'}
{'type': 'l2update', 'product_id': 'BTC-USD', 'changes': [['sell', '38387.44', '0.00000000']], 'time': '2021-05-20T03:54:51.959501Z'}
{'type': 'l2update', 'product_id': 'BTC-USD', 'changes': [['sell', '38304.87', '0.04000000']], 'time': '2021-05-20T03:54:51.960257Z'}
{'type': 'l2update', 'product_id': 'BTC-USD', 'changes': [['buy', '38271.51', '0.21900000']], 'time': '2021-05-20T03:54:51.960703Z'}
{'type': 'l2update', 'product_id': 'BTC-USD', 'changes': [['buy', '38270.31', '0.05254688']], 'time': '2021-05-20T03:54:51.965283Z'}
{'type': 'l2update', 'product_id': 'BTC-USD', 'changes': [['buy', '38270.56', '0.01492000']], 'time': '2021-05-20T03:54:51.965321Z'}
{'type': 'l2update', 'product_id': 'BTC-USD', 'changes': [['buy', '38187.76', '0.01000000']], 'time': '2021-05-20T03:54:51.965602Z'}
{'type': 'l2update', 'product_id': 'BTC-USD', 'changes': [['buy', '38270.31', '0.07460000']], 'time': '2021-05-20T03:54:51.970519Z'}
{'type': 'l2update', 'product_id': 'BTC-USD', 'changes': [['sell', '38485.64', '0.02359850']], 'time': '2021-05-20T03:54:51.970824Z'}
{'type': 'l2update', 'product_id': 'BTC-USD', 'changes': [['sell', '38404.40', '0.03537175']], 'time': '2021-05-20T03:54:51.970843Z'}
{'type': 'l2update', 'product_id': 'BTC-USD', 'changes': [['buy', '38270.31', '0.02205312']], 'time': '2021-05-20T03:54:51.972343Z'}
{'type': 'l2update', 'product_id': 'BTC-USD', 'changes': [['buy', '38270.56', '0.00000000']], 'time': '2021-05-20T03:54:51.972678Z'}
{'type': 'l2update', 'product_id': 'BTC-USD', 'changes': [['sell', '38423.70', '0.00000000']], 'time': '2021-05-20T03:54:51.972794Z'}
{'type': 'l2update', 'product_id': 'BTC-USD', 'changes': [['buy', '38270.31', '0.00000000']], 'time': '2021-05-20T03:54:51.977905Z'}
{'type': 'l2update', 'product_id': 'BTC-USD', 'changes': [['sell', '38279.57', '0.00583685']], 'time': '2021-05-20T03:54:51.982470Z'}
{'type': 'l2update', 'product_id': 'BTC-USD', 'changes': [['sell', '38414.65', '0.02024699']], 'time': '2021-05-20T03:54:51.983163Z'}
{'type': 'l2update', 'product_id': 'BTC-USD', 'changes': [['buy', '38164.41', '0.71084614']], 'time': '2021-05-20T03:54:51.987891Z'}
{'type': 'l2update', 'product_id': 'BTC-USD', 'changes': [['buy', '37500.01', '0.13490000']], 'time': '2021-05-20T03:54:51.988537Z'}
{'type': 'l2update', 'product_id': 'BTC-USD', 'changes': [['sell', '38279.57', '0.00000000']], 'time': '2021-05-20T03:54:51.989534Z'}
{'type': 'l2update', 'product_id': 'BTC-USD', 'changes': [['buy', '38124.76', '0.32361428']], 'time': '2021-05-20T03:54:51.995003Z'}
{'type': 'l2update', 'product_id': 'BTC-USD', 'changes': [['buy', '38250.78', '0.00000000']], 'time': '2021-05-20T03:54:51.995135Z'}
{'type': 'l2update', 'product_id': 'BTC-USD', 'changes': [['buy', '38248.87', '0.05816453']], 'time': '2021-05-20T03:54:51.995143Z'}
{'type': 'l2update', 'product_id': 'BTC-USD', 'changes': [['sell', '38395.80', '0.01267208']], 'time': '2021-05-20T03:54:51.995545Z'}
{'type': 'l2update', 'product_id': 'BTC-USD', 'changes': [['sell', '38372.42', '0.01401619']], 'time': '2021-05-20T03:54:51.995564Z'}
{'type': 'l2update', 'product_id': 'BTC-USD', 'changes': [['sell', '38370.18', '0.00000000']], 'time': '2021-05-20T03:54:51.998054Z'}
{'type': 'l2update', 'product_id': 'BTC-USD', 'changes': [['buy', '38238.00', '0.00000000']], 'time': '2021-05-20T03:54:51.999955Z'}
{'type': 'l2update', 'product_id': 'BTC-USD', 'changes': [['buy', '38237.19', '0.00000000']], 'time': '2021-05-20T03:54:51.999955Z'}
{'type': 'l2update', 'product_id': 'BTC-USD', 'changes': [['buy', '38236.51', '0.00000000']], 'time': '2021-05-20T03:54:51.999955Z'}
{'type': 'l2update', 'product_id': 'BTC-USD', 'changes': [['buy', '38245.40', '0.00000000']], 'time': '2021-05-20T03:54:52.001384Z'}
{'type': 'l2update', 'product_id': 'BTC-USD', 'changes': [['buy', '38198.19', '0.67933298']], 'time': '2021-05-20T03:54:52.002582Z'}
{'type': 'l2update', 'product_id': 'BTC-USD', 'changes': [['buy', '38248.23', '0.06524458']], 'time': '2021-05-20T03:54:52.005073Z'}
{'type': 'l2update', 'product_id': 'BTC-USD', 'changes': [['buy', '38271.93', '0.01492000']], 'time': '2021-05-20T03:54:52.005136Z'}
{'type': 'l2update', 'product_id': 'BTC-USD', 'changes': [['buy', '38271.87', '0.02205312']], 'time': '2021-05-20T03:54:52.005404Z'}
{'type': 'l2update', 'product_id': 'BTC-USD', 'changes': [['sell', '38286.61', '0.55800000']], 'time': '2021-05-20T03:54:52.009786Z'}
{'type': 'l2update', 'product_id': 'BTC-USD', 'changes': [['buy', '38232.08', '0.01175624']], 'time': '2021-05-20T03:54:52.009900Z'}
{'type': 'l2update', 'product_id': 'BTC-USD', 'changes': [['sell', '50813.31', '0.00296600']], 'time': '2021-05-20T03:54:52.014094Z'}
{'type': 'l2update', 'product_id': 'BTC-USD', 'changes': [['sell', '38290.58', '0.00000000']], 'time': '2021-05-20T03:54:52.015535Z'}
{'type': 'l2update', 'product_id': 'BTC-USD', 'changes': [['buy', '38271.87', '0.00000000']], 'time': '2021-05-20T03:54:52.015749Z'}
{'type': 'l2update', 'product_id': 'BTC-USD', 'changes': [['sell', '38485.64', '0.00000000']], 'time': '2021-05-20T03:54:52.015842Z'}
{'type': 'l2update', 'product_id': 'BTC-USD', 'changes': [['sell', '38279.26', '0.07460000']], 'time': '2021-05-20T03:54:52.016456Z'}
{'type': 'l2update', 'product_id': 'BTC-USD', 'changes': [['buy', '38247.82', '0.02400000']], 'time': '2021-05-20T03:54:52.021619Z'}
{'type': 'l2update', 'product_id': 'BTC-USD', 'changes': [['buy', '38247.01', '0.02400000']], 'time': '2021-05-20T03:54:52.021619Z'}
{'type': 'l2update', 'product_id': 'BTC-USD', 'changes': [['buy', '38246.21', '0.02400000']], 'time': '2021-05-20T03:54:52.021619Z'}
{'type': 'l2update', 'product_id': 'BTC-USD', 'changes': [['buy', '38208.57', '0.05720915']], 'time': '2021-05-20T03:54:52.025760Z'}
{'type': 'l2update', 'product_id': 'BTC-USD', 'changes': [['buy', '38217.82', '0.03553200']], 'time': '2021-05-20T03:54:52.025760Z'}
{'type': 'l2update', 'product_id': 'BTC-USD', 'changes': [['buy', '38222.55', '0.03041148']], 'time': '2021-05-20T03:54:52.025760Z'}
{'type': 'l2update', 'product_id': 'BTC-USD', 'changes': [['buy', '38231.44', '0.02996595']], 'time': '2021-05-20T03:54:52.025760Z'}
{'type': 'l2update', 'product_id': 'BTC-USD', 'changes': [['buy', '38235.60', '0.01424831']], 'time': '2021-05-20T03:54:52.025760Z'}
{'type': 'l2update', 'product_id': 'BTC-USD', 'changes': [['sell', '38279.26', '0.00000000']], 'time': '2021-05-20T03:54:52.027019Z'}
{'type': 'l2update', 'product_id': 'BTC-USD', 'changes': [['buy', '38271.93', '0.00000000']], 'time': '2021-05-20T03:54:52.029568Z'}
{'type': 'l2update', 'product_id': 'BTC-USD', 'changes': [['buy', '38246.21', '0.00000000']], 'time': '2021-05-20T03:54:52.032735Z'}
{'type': 'l2update', 'product_id': 'BTC-USD', 'changes': [['buy', '38272.18', '0.02205312']], 'time': '2021-05-20T03:54:52.035478Z'}
{'type': 'l2update', 'product_id': 'BTC-USD', 'changes': [['buy', '38178.50', '0.02663544']], 'time': '2021-05-20T03:54:52.036664Z'}
{'type': 'l2update', 'product_id': 'BTC-USD', 'changes': [['buy', '38194.38', '0.00000000']], 'time': '2021-05-20T03:54:52.036664Z'}
{'type': 'l2update', 'product_id': 'BTC-USD', 'changes': [['buy', '38199.30', '0.00000000']], 'time': '2021-05-20T03:54:52.036664Z'}
{'type': 'l2update', 'product_id': 'BTC-USD', 'changes': [['buy', '38208.57', '0.02724320']], 'time': '2021-05-20T03:54:52.036664Z'}
{'type': 'l2update', 'product_id': 'BTC-USD', 'changes': [['buy', '38217.08', '0.01042704']], 'time': '2021-05-20T03:54:52.036664Z'}
{'type': 'l2update', 'product_id': 'BTC-USD', 'changes': [['buy', '38248.87', '0.00000000']], 'time': '2021-05-20T03:54:52.037208Z'}
{'type': 'l2update', 'product_id': 'BTC-USD', 'changes': [['buy', '38266.55', '0.00000000']], 'time': '2021-05-20T03:54:52.037744Z'}
{'type': 'l2update', 'product_id': 'BTC-USD', 'changes': [['buy', '38252.35', '0.00000000']], 'time': '2021-05-20T03:54:52.042046Z'}
{'type': 'l2update', 'product_id': 'BTC-USD', 'changes': [['buy', '38272.18', '0.00000000']], 'time': '2021-05-20T03:54:52.043985Z'}
{'type': 'l2update', 'product_id': 'BTC-USD', 'changes': [['sell', '38313.14', '0.63654852']], 'time': '2021-05-20T03:54:52.044942Z'}
{'type': 'l2update', 'product_id': 'BTC-USD', 'changes': [['sell', '38289.38', '0.00000000']], 'time': '2021-05-20T03:54:52.047625Z'}
{'type': 'l2update', 'product_id': 'BTC-USD', 'changes': [['sell', '38289.37', '0.00000000']], 'time': '2021-05-20T03:54:52.048015Z'}
{'type': 'l2update', 'product_id': 'BTC-USD', 'changes': [['sell', '38286.61', '0.00000000']], 'time': '2021-05-20T03:54:52.049962Z'}
{'type': 'l2update', 'product_id': 'BTC-USD', 'changes': [['buy', '38272.10', '0.01492000']], 'time': '2021-05-20T03:54:52.051062Z'}
{'type': 'l2update', 'product_id': 'BTC-USD', 'changes': [['buy', '38248.85', '0.05816453']], 'time': '2021-05-20T03:54:52.051316Z'}
{'type': 'l2update', 'product_id': 'BTC-USD', 'changes': [['sell', '38290.58', '0.04644831']], 'time': '2021-05-20T03:54:52.051358Z'}
{'type': 'l2update', 'product_id': 'BTC-USD', 'changes': [['buy', '38150.24', '0.67953245']], 'time': '2021-05-20T03:54:52.056571Z'}
{'type': 'l2update', 'product_id': 'BTC-USD', 'changes': [['buy', '38157.42', '0.63118134']], 'time': '2021-05-20T03:54:52.056571Z'}
{'type': 'l2update', 'product_id': 'BTC-USD', 'changes': [['buy', '38164.41', '1.03446042']], 'time': '2021-05-20T03:54:52.056571Z'}
{'type': 'l2update', 'product_id': 'BTC-USD', 'changes': [['buy', '38197.51', '0.15240136']], 'time': '2021-05-20T03:54:52.056571Z'}
{'type': 'l2update', 'product_id': 'BTC-USD', 'changes': [['sell', '38289.44', '0.00000000']], 'time': '2021-05-20T03:54:52.056918Z'}
{'type': 'l2update', 'product_id': 'BTC-USD', 'changes': [['buy', '38249.28', '0.02400000']], 'time': '2021-05-20T03:54:52.057521Z'}
{'type': 'l2update', 'product_id': 'BTC-USD', 'changes': [['buy', '38272.10', '0.00000000']], 'time': '2021-05-20T03:54:52.057687Z'}
{'type': 'l2update', 'product_id': 'BTC-USD', 'changes': [['buy', '38271.75', '0.02205312']], 'time': '2021-05-20T03:54:52.062880Z'}
{'type': 'l2update', 'product_id': 'BTC-USD', 'changes': [['buy', '38114.97', '0.00000000']], 'time': '2021-05-20T03:54:52.063933Z'}
{'type': 'l2update', 'product_id': 'BTC-USD', 'changes': [['buy', '38124.76', '0.00000000']], 'time': '2021-05-20T03:54:52.063933Z'}
{'type': 'l2update', 'product_id': 'BTC-USD', 'changes': [['buy', '38164.41', '0.65345701']], 'time': '2021-05-20T03:54:52.063933Z'}
{'type': 'l2update', 'product_id': 'BTC-USD', 'changes': [['buy', '38249.28', '0.00000000']], 'time': '2021-05-20T03:54:52.065181Z'}
{'type': 'l2update', 'product_id': 'BTC-USD', 'changes': [['buy', '38247.82', '0.00000000']], 'time': '2021-05-20T03:54:52.065181Z'}
{'type': 'l2update', 'product_id': 'BTC-USD', 'changes': [['buy', '38271.75', '0.00000000']], 'time': '2021-05-20T03:54:52.069782Z'}
{'type': 'l2update', 'product_id': 'BTC-USD', 'changes': [['buy', '38266.49', '0.00000000']], 'time': '2021-05-20T03:54:52.071552Z'}
{'type': 'l2update', 'product_id': 'BTC-USD', 'changes': [['sell', '38317.69', '0.72252896']], 'time': '2021-05-20T03:54:52.072582Z'}
{'type': 'l2update', 'product_id': 'BTC-USD', 'changes': [['buy', '38248.85', '0.00000000']], 'time': '2021-05-20T03:54:52.072595Z'}
{'type': 'l2update', 'product_id': 'BTC-USD', 'changes': [['buy', '38247.01', '0.00000000']], 'time': '2021-05-20T03:54:52.073182Z'}
{'type': 'l2update', 'product_id': 'BTC-USD', 'changes': [['buy', '38271.77', '0.01492000']], 'time': '2021-05-20T03:54:52.074895Z'}
{'type': 'l2update', 'product_id': 'BTC-USD', 'changes': [['sell', '38289.43', '0.33808528']], 'time': '2021-05-20T03:54:52.074930Z'}
{'type': 'l2update', 'product_id': 'BTC-USD', 'changes': [['sell', '38283.27', '0.00000000']], 'time': '2021-05-20T03:54:52.075451Z'}
{'type': 'l2update', 'product_id': 'BTC-USD', 'changes': [['sell', '38366.86', '0.00000000']], 'time': '2021-05-20T03:54:52.076142Z'}
{'type': 'l2update', 'product_id': 'BTC-USD', 'changes': [['sell', '38471.76', '0.02359850']], 'time': '2021-05-20T03:54:52.080276Z'}
{'type': 'l2update', 'product_id': 'BTC-USD', 'changes': [['sell', '38283.26', '2.48969908']], 'time': '2021-05-20T03:54:52.080362Z'}
{'type': 'l2update', 'product_id': 'BTC-USD', 'changes': [['buy', '38272.17', '0.05254688']], 'time': '2021-05-20T03:54:52.081522Z'}
{'type': 'l2update', 'product_id': 'BTC-USD', 'changes': [['buy', '38271.77', '0.00000000']], 'time': '2021-05-20T03:54:52.082235Z'}
{'type': 'l2update', 'product_id': 'BTC-USD', 'changes': [['sell', '38283.26', '0.00000000']], 'time': '2021-05-20T03:54:52.091060Z'}
{'type': 'l2update', 'product_id': 'BTC-USD', 'changes': [['sell', '38286.65', '0.50000000']], 'time': '2021-05-20T03:54:52.093144Z'}
{'type': 'l2update', 'product_id': 'BTC-USD', 'changes': [['sell', '38379.15', '0.01000000']], 'time': '2021-05-20T03:54:52.093254Z'}
{'type': 'l2update', 'product_id': 'BTC-USD', 'changes': [['buy', '38272.17', '0.07460000']], 'time': '2021-05-20T03:54:52.098375Z'}
{'type': 'l2update', 'product_id': 'BTC-USD', 'changes': [['buy', '38245.40', '0.05816453']], 'time': '2021-05-20T03:54:52.098800Z'}
{'type': 'l2update', 'product_id': 'BTC-USD', 'changes': [['buy', '38245.73', '0.02400000']], 'time': '2021-05-20T03:54:52.102542Z'}
{'type': 'l2update', 'product_id': 'BTC-USD', 'changes': [['buy', '38244.93', '0.02400000']], 'time': '2021-05-20T03:54:52.102542Z'}
{'type': 'l2update', 'product_id': 'BTC-USD', 'changes': [['buy', '38244.12', '0.02400000']], 'time': '2021-05-20T03:54:52.102542Z'}
{'type': 'l2update', 'product_id': 'BTC-USD', 'changes': [['buy', '38272.17', '0.02205312']], 'time': '2021-05-20T03:54:52.103638Z'}
{'type': 'l2update', 'product_id': 'BTC-USD', 'changes': [['buy', '38245.39', '0.00000000']], 'time': '2021-05-20T03:54:52.105126Z'}
{'type': 'l2update', 'product_id': 'BTC-USD', 'changes': [['buy', '38272.17', '0.00000000']], 'time': '2021-05-20T03:54:52.109815Z'}
{'type': 'l2update', 'product_id': 'BTC-USD', 'changes': [['sell', '38284.68', '2.48969908']], 'time': '2021-05-20T03:54:52.114051Z'}
{'type': 'l2update', 'product_id': 'BTC-USD', 'changes': [['sell', '38380.22', '0.00000000']], 'time': '2021-05-20T03:54:52.114191Z'}
{'type': 'l2update', 'product_id': 'BTC-USD', 'changes': [['buy', '38187.76', '0.00000000']], 'time': '2021-05-20T03:54:52.121412Z'}
{'type': 'l2update', 'product_id': 'BTC-USD', 'changes': [['buy', '38271.99', '0.02205312']], 'time': '2021-05-20T03:54:52.126301Z'}
{'type': 'l2update', 'product_id': 'BTC-USD', 'changes': [['buy', '38248.23', '0.00000000']], 'time': '2021-05-20T03:54:52.127219Z'}
{'type': 'l2update', 'product_id': 'BTC-USD', 'changes': [['buy', '38271.82', '0.01492000']], 'time': '2021-05-20T03:54:52.130175Z'}
{'type': 'l2update', 'product_id': 'BTC-USD', 'changes': [['buy', '38170.92', '0.50000000']], 'time': '2021-05-20T03:54:52.130396Z'}
{'type': 'l2update', 'product_id': 'BTC-USD', 'changes': [['buy', '38250.05', '0.00000000']], 'time': '2021-05-20T03:54:52.132677Z'}
{'type': 'l2update', 'product_id': 'BTC-USD', 'changes': [['sell', '38341.10', '0.22300000']], 'time': '2021-05-20T03:54:52.135799Z'}
{'type': 'l2update', 'product_id': 'BTC-USD', 'changes': [['buy', '38271.82', '0.00000000']], 'time': '2021-05-20T03:54:52.138078Z'}
{'type': 'l2update', 'product_id': 'BTC-USD', 'changes': [['sell', '38289.43', '0.00000000']], 'time': '2021-05-20T03:54:52.138482Z'}
{'type': 'l2update', 'product_id': 'BTC-USD', 'changes': [['buy', '38260.34', '0.00000000']], 'time': '2021-05-20T03:54:52.138612Z'}
{'type': 'l2update', 'product_id': 'BTC-USD', 'changes': [['buy', '38252.41', '0.00000000']], 'time': '2021-05-20T03:54:52.138883Z'}
{'type': 'l2update', 'product_id': 'BTC-USD', 'changes': [['buy', '38271.99', '0.00000000']], 'time': '2021-05-20T03:54:52.138940Z'}
{'type': 'l2update', 'product_id': 'BTC-USD', 'changes': [['buy', '38260.40', '0.84800000']], 'time': '2021-05-20T03:54:52.139610Z'}
{'type': 'l2update', 'product_id': 'BTC-USD', 'changes': [['buy', '38269.66', '0.04829385']], 'time': '2021-05-20T03:54:52.141916Z'}
{'type': 'l2update', 'product_id': 'BTC-USD', 'changes': [['buy', '38203.87', '0.02617535']], 'time': '2021-05-20T03:54:52.144666Z'}
{'type': 'l2update', 'product_id': 'BTC-USD', 'changes': [['sell', '38398.55', '0.03022253']], 'time': '2021-05-20T03:54:52.148991Z'}
{'type': 'l2update', 'product_id': 'BTC-USD', 'changes': [['buy', '38260.35', '0.00000000']], 'time': '2021-05-20T03:54:52.149959Z'}
{'type': 'l2update', 'product_id': 'BTC-USD', 'changes': [['buy', '38245.73', '0.00000000']], 'time': '2021-05-20T03:54:52.150961Z'}
{'type': 'l2update', 'product_id': 'BTC-USD', 'changes': [['buy', '38244.93', '0.00000000']], 'time': '2021-05-20T03:54:52.150961Z'}
{'type': 'l2update', 'product_id': 'BTC-USD', 'changes': [['buy', '38244.12', '0.00000000']], 'time': '2021-05-20T03:54:52.150961Z'}
{'type': 'l2update', 'product_id': 'BTC-USD', 'changes': [['sell', '38290.58', '0.00000000']], 'time': '2021-05-20T03:54:52.152395Z'}
{'type': 'l2update', 'product_id': 'BTC-USD', 'changes': [['sell', '38314.08', '0.00000000']], 'time': '2021-05-20T03:54:52.157015Z'}
{'type': 'l2update', 'product_id': 'BTC-USD', 'changes': [['buy', '38271.82', '0.02205312']], 'time': '2021-05-20T03:54:52.157844Z'}
{'type': 'l2update', 'product_id': 'BTC-USD', 'changes': [['buy', '38271.82', '0.03697312']], 'time': '2021-05-20T03:54:52.157921Z'}
{'type': 'l2update', 'product_id': 'BTC-USD', 'changes': [['sell', '38284.67', '0.33808528']], 'time': '2021-05-20T03:54:52.162629Z'}
{'type': 'l2update', 'product_id': 'BTC-USD', 'changes': [['buy', '38271.82', '0.02205312']], 'time': '2021-05-20T03:54:52.166253Z'}
{'type': 'l2update', 'product_id': 'BTC-USD', 'changes': [['sell', '38279.51', '0.07460000']], 'time': '2021-05-20T03:54:52.170947Z'}
{'type': 'l2update', 'product_id': 'BTC-USD', 'changes': [['buy', '38260.41', '0.25308028']], 'time': '2021-05-20T03:54:52.177229Z'}
{'type': 'l2update', 'product_id': 'BTC-USD', 'changes': [['buy', '38239.62', '0.02400000']], 'time': '2021-05-20T03:54:52.177443Z'}
{'type': 'l2update', 'product_id': 'BTC-USD', 'changes': [['buy', '38238.82', '0.02400000']], 'time': '2021-05-20T03:54:52.177443Z'}
{'type': 'l2update', 'product_id': 'BTC-USD', 'changes': [['buy', '38238.01', '0.02400000']], 'time': '2021-05-20T03:54:52.177443Z'}
{'type': 'l2update', 'product_id': 'BTC-USD', 'changes': [['sell', '38279.51', '0.00000000']], 'time': '2021-05-20T03:54:52.178010Z'}
{'type': 'l2update', 'product_id': 'BTC-USD', 'changes': [['buy', '38271.82', '0.00000000']], 'time': '2021-05-20T03:54:52.179032Z'}
{'type': 'l2update', 'product_id': 'BTC-USD', 'changes': [['sell', '38307.25', '0.04976510']], 'time': '2021-05-20T03:54:52.193932Z'}
{'type': 'l2update', 'product_id': 'BTC-USD', 'changes': [['sell', '50817.64', '0.00431300']], 'time': '2021-05-20T03:54:52.193953Z'}
{'type': 'l2update', 'product_id': 'BTC-USD', 'changes': [['sell', '38290.22', '0.04827174']], 'time': '2021-05-20T03:54:52.194162Z'}
{'type': 'l2update', 'product_id': 'BTC-USD', 'changes': [['buy', '38272.17', '0.02205312']], 'time': '2021-05-20T03:54:52.197326Z'}
{'type': 'l2update', 'product_id': 'BTC-USD', 'changes': [['buy', '38272.17', '0.03697312']], 'time': '2021-05-20T03:54:52.197363Z'}
{'type': 'l2update', 'product_id': 'BTC-USD', 'changes': [['buy', '38247.59', '0.04381170']], 'time': '2021-05-20T03:54:52.197427Z'}
{'type': 'l2update', 'product_id': 'BTC-USD', 'changes': [['sell', '38288.25', '0.04973589']], 'time': '2021-05-20T03:54:52.197427Z'}
{'type': 'l2update', 'product_id': 'BTC-USD', 'changes': [['sell', '38286.66', '0.00000000']], 'time': '2021-05-20T03:54:52.198430Z'}
{'type': 'l2update', 'product_id': 'BTC-USD', 'changes': [['buy', '38084.77', '0.04897413']], 'time': '2021-05-20T03:54:52.201726Z'}
{'type': 'l2update', 'product_id': 'BTC-USD', 'changes': [['buy', '38272.17', '0.02205312']], 'time': '2021-05-20T03:54:52.205472Z'}
{'type': 'l2update', 'product_id': 'BTC-USD', 'changes': [['sell', '38304.87', '0.00000000']], 'time': '2021-05-20T03:54:52.206295Z'}
{'type': 'l2update', 'product_id': 'BTC-USD', 'changes': [['buy', '38239.95', '0.05816453']], 'time': '2021-05-20T03:54:52.212499Z'}
{'type': 'l2update', 'product_id': 'BTC-USD', 'changes': [['sell', '38360.45', '0.00000000']], 'time': '2021-05-20T03:54:52.215610Z'}
{'type': 'l2update', 'product_id': 'BTC-USD', 'changes': [['sell', '43100.00', '1.09530000']], 'time': '2021-05-20T03:54:52.215984Z'}
{'type': 'l2update', 'product_id': 'BTC-USD', 'changes': [['sell', '38291.53', '0.03761656']], 'time': '2021-05-20T03:54:52.221982Z'}
{'type': 'l2update', 'product_id': 'BTC-USD', 'changes': [['buy', '38239.95', '0.00000000']], 'time': '2021-05-20T03:54:52.224288Z'}
{'type': 'l2update', 'product_id': 'BTC-USD', 'changes': [['sell', '43100.00', '2.12030000']], 'time': '2021-05-20T03:54:52.231913Z'}
{'type': 'l2update', 'product_id': 'BTC-USD', 'changes': [['buy', '38245.40', '0.00000000']], 'time': '2021-05-20T03:54:52.239250Z'}
{'type': 'l2update', 'product_id': 'BTC-USD', 'changes': [['sell', '38389.46', '0.02733011']], 'time': '2021-05-20T03:54:52.250165Z'}
{'type': 'l2update', 'product_id': 'BTC-USD', 'changes': [['sell', '38373.43', '0.12272224']], 'time': '2021-05-20T03:54:52.254792Z'}
{'type': 'l2update', 'product_id': 'BTC-USD', 'changes': [['buy', '38166.54', '0.00000000']], 'time': '2021-05-20T03:54:52.287796Z'}
{'type': 'l2update', 'product_id': 'BTC-USD', 'changes': [['buy', '38245.39', '2.37600000']], 'time': '2021-05-20T03:54:52.294280Z'}
{'type': 'l2update', 'product_id': 'BTC-USD', 'changes': [['sell', '38286.60', '1.08700000']], 'time': '2021-05-20T03:54:52.302444Z'}
{'type': 'l2update', 'product_id': 'BTC-USD', 'changes': [['buy', '38183.99', '0.01000000']], 'time': '2021-05-20T03:54:52.302463Z'}
{'type': 'l2update', 'product_id': 'BTC-USD', 'changes': [['sell', '38380.22', '0.02400000']], 'time': '2021-05-20T03:54:52.305958Z'}
{'type': 'l2update', 'product_id': 'BTC-USD', 'changes': [['buy', '38279.84', '0.15000000']], 'time': '2021-05-20T03:54:52.327258Z'}
{'type': 'l2update', 'product_id': 'BTC-USD', 'changes': [['buy', '38183.99', '0.00000000']], 'time': '2021-05-20T03:54:52.328490Z'}
{'type': 'l2update', 'product_id': 'BTC-USD', 'changes': [['buy', '38272.17', '0.00000000']], 'time': '2021-05-20T03:54:52.333211Z'}
{'type': 'l2update', 'product_id': 'BTC-USD', 'changes': [['sell', '38372.42', '0.00000000']], 'time': '2021-05-20T03:54:52.334667Z'}
{'type': 'l2update', 'product_id': 'BTC-USD', 'changes': [['sell', '38471.76', '0.00000000']], 'time': '2021-05-20T03:54:52.335928Z'}
{'type': 'l2update', 'product_id': 'BTC-USD', 'changes': [['sell', '38304.74', '0.00000000']], 'time': '2021-05-20T03:54:52.336684Z'}
{'type': 'l2update', 'product_id': 'BTC-USD', 'changes': [['sell', '38279.89', '0.01875240']], 'time': '2021-05-20T03:54:52.342674Z'}
{'type': 'l2update', 'product_id': 'BTC-USD', 'changes': [['sell', '38314.95', '0.05208542']], 'time': '2021-05-20T03:54:52.342752Z'}
{'type': 'l2update', 'product_id': 'BTC-USD', 'changes': [['sell', '38279.85', '0.10000000']], 'time': '2021-05-20T03:54:52.342764Z'}
{'type': 'l2update', 'product_id': 'BTC-USD', 'changes': [['buy', '38201.10', '0.01000000']], 'time': '2021-05-20T03:54:52.342812Z'}
{'type': 'l2update', 'product_id': 'BTC-USD', 'changes': [['buy', '37272.48', '0.00000000']], 'time': '2021-05-20T03:54:52.344702Z'}
{'type': 'l2update', 'product_id': 'BTC-USD', 'changes': [['buy', '36361.80', '0.00000000']], 'time': '2021-05-20T03:54:52.344702Z'}
{'type': 'l2update', 'product_id': 'BTC-USD', 'changes': [['sell', '38301.29', '0.00000000']], 'time': '2021-05-20T03:54:52.344735Z'}
{'type': 'l2update', 'product_id': 'BTC-USD', 'changes': [['sell', '38387.13', '0.52100800']], 'time': '2021-05-20T03:54:52.346774Z'}
{'type': 'l2update', 'product_id': 'BTC-USD', 'changes': [['sell', '38332.34', '0.05198494']], 'time': '2021-05-20T03:54:52.346809Z'}
{'type': 'l2update', 'product_id': 'BTC-USD', 'changes': [['sell', '38304.74', '0.05000000']], 'time': '2021-05-20T03:54:52.355510Z'}
{'type': 'l2update', 'product_id': 'BTC-USD', 'changes': [['sell', '38279.89', '0.21875240']], 'time': '2021-05-20T03:54:52.355577Z'}
{'type': 'l2update', 'product_id': 'BTC-USD', 'changes': [['buy', '38218.55', '0.00000000']], 'time': '2021-05-20T03:54:52.357476Z'}
{'type': 'l2update', 'product_id': 'BTC-USD', 'changes': [['sell', '38454.00', '0.01000000']], 'time': '2021-05-20T03:54:52.361104Z'}
{'type': 'l2update', 'product_id': 'BTC-USD', 'changes': [['sell', '50826.30', '0.00200000']], 'time': '2021-05-20T03:54:52.366292Z'}
{'type': 'l2update', 'product_id': 'BTC-USD', 'changes': [['sell', '38330.65', '0.64583722']], 'time': '2021-05-20T03:54:52.373486Z'}
{'type': 'l2update', 'product_id': 'BTC-USD', 'changes': [['buy', '38222.55', '0.13041148']], 'time': '2021-05-20T03:54:52.373824Z'}
{'type': 'l2update', 'product_id': 'BTC-USD', 'changes': [['buy', '38201.10', '0.00000000']], 'time': '2021-05-20T03:54:52.377791Z'}
{'type': 'l2update', 'product_id': 'BTC-USD', 'changes': [['sell', '38454.00', '0.00000000']], 'time': '2021-05-20T03:54:52.379890Z'}
{'type': 'l2update', 'product_id': 'BTC-USD', 'changes': [['buy', '38150.86', '0.00000000']], 'time': '2021-05-20T03:54:52.382884Z'}
{'type': 'l2update', 'product_id': 'BTC-USD', 'changes': [['buy', '38184.94', '0.01000000']], 'time': '2021-05-20T03:54:52.392518Z'}
{'type': 'l2update', 'product_id': 'BTC-USD', 'changes': [['sell', '38436.26', '0.02318690']], 'time': '2021-05-20T03:54:52.392681Z'}
{'type': 'l2update', 'product_id': 'BTC-USD', 'changes': [['sell', '38279.89', '0.01875240']], 'time': '2021-05-20T03:54:52.396405Z'}
{'type': 'l2update', 'product_id': 'BTC-USD', 'changes': [['buy', '38163.42', '0.03577500']], 'time': '2021-05-20T03:54:52.398267Z'}
{'type': 'l2update', 'product_id': 'BTC-USD', 'changes': [['sell', '38366.08', '0.20340000']], 'time': '2021-05-20T03:54:52.399153Z'}
{'type': 'l2update', 'product_id': 'BTC-USD', 'changes': [['buy', '38260.46', '0.52100000']], 'time': '2021-05-20T03:54:52.412239Z'}
{'type': 'l2update', 'product_id': 'BTC-USD', 'changes': [['sell', '38360.95', '0.30583171']], 'time': '2021-05-20T03:54:52.417074Z'}
{'type': 'l2update', 'product_id': 'BTC-USD', 'changes': [['sell', '38354.87', '0.00000000']], 'time': '2021-05-20T03:54:52.417074Z'}
{'type': 'l2update', 'product_id': 'BTC-USD', 'changes': [['sell', '38348.98', '0.34440992']], 'time': '2021-05-20T03:54:52.417074Z'}
{'type': 'l2update', 'product_id': 'BTC-USD', 'changes': [['sell', '38337.79', '0.00000000']], 'time': '2021-05-20T03:54:52.417074Z'}
{'type': 'l2update', 'product_id': 'BTC-USD', 'changes': [['sell', '38332.48', '0.37473622']], 'time': '2021-05-20T03:54:52.417074Z'}
{'type': 'l2update', 'product_id': 'BTC-USD', 'changes': [['buy', '38260.41', '0.00000000']], 'time': '2021-05-20T03:54:52.419284Z'}
{'type': 'l2update', 'product_id': 'BTC-USD', 'changes': [['buy', '38260.47', '0.25308028']], 'time': '2021-05-20T03:54:52.441227Z'}
{'type': 'l2update', 'product_id': 'BTC-USD', 'changes': [['sell', '38322.95', '0.05453159']], 'time': '2021-05-20T03:54:52.441364Z'}
{'type': 'l2update', 'product_id': 'BTC-USD', 'changes': [['sell', '38279.85', '0.30000000']], 'time': '2021-05-20T03:54:52.455224Z'}
{'type': 'l2update', 'product_id': 'BTC-USD', 'changes': [['sell', '38389.46', '0.00000000']], 'time': '2021-05-20T03:54:52.457193Z'}
{'type': 'l2update', 'product_id': 'BTC-USD', 'changes': [['buy', '38251.94', '0.40880000']], 'time': '2021-05-20T03:54:52.459770Z'}
{'type': 'l2update', 'product_id': 'BTC-USD', 'changes': [['sell', '38414.70', '0.02733011']], 'time': '2021-05-20T03:54:52.469366Z'}
{'type': 'l2update', 'product_id': 'BTC-USD', 'changes': [['sell', '38297.76', '0.04000000']], 'time': '2021-05-20T03:54:52.469429Z'}
{'type': 'l2update', 'product_id': 'BTC-USD', 'changes': [['sell', '38299.98', '0.49380000']], 'time': '2021-05-20T03:54:52.473751Z'}
{'type': 'l2update', 'product_id': 'BTC-USD', 'changes': [['buy', '38244.89', '0.11000000']], 'time': '2021-05-20T03:54:52.475718Z'}
{'type': 'l2update', 'product_id': 'BTC-USD', 'changes': [['buy', '38244.89', '0.06000000']], 'time': '2021-05-20T03:54:52.483188Z'}
{'type': 'l2update', 'product_id': 'BTC-USD', 'changes': [['buy', '38272.16', '0.00176524']], 'time': '2021-05-20T03:54:52.488477Z'}
{'type': 'l2update', 'product_id': 'BTC-USD', 'changes': [['sell', '38319.67', '0.01552271']], 'time': '2021-05-20T03:54:52.488742Z'}
{'type': 'l2update', 'product_id': 'BTC-USD', 'changes': [['sell', '38404.40', '0.00000000']], 'time': '2021-05-20T03:54:52.494362Z'}
{'type': 'l2update', 'product_id': 'BTC-USD', 'changes': [['sell', '38398.55', '0.00000000']], 'time': '2021-05-20T03:54:52.494362Z'}
{'type': 'l2update', 'product_id': 'BTC-USD', 'changes': [['sell', '38396.59', '0.00000000']], 'time': '2021-05-20T03:54:52.494362Z'}
{'type': 'l2update', 'product_id': 'BTC-USD', 'changes': [['sell', '38387.17', '0.46141978']], 'time': '2021-05-20T03:54:52.494362Z'}
{'type': 'l2update', 'product_id': 'BTC-USD', 'changes': [['sell', '38387.17', '0.42579901']], 'time': '2021-05-20T03:54:52.494362Z'}
{'type': 'l2update', 'product_id': 'BTC-USD', 'changes': [['sell', '38373.68', '0.42187037']], 'time': '2021-05-20T03:54:52.494362Z'}
{'type': 'l2update', 'product_id': 'BTC-USD', 'changes': [['sell', '38367.22', '0.65129622']], 'time': '2021-05-20T03:54:52.494362Z'}
{'type': 'l2update', 'product_id': 'BTC-USD', 'changes': [['buy', '38251.94', '0.00000000']], 'time': '2021-05-20T03:54:52.497053Z'}
{'type': 'l2update', 'product_id': 'BTC-USD', 'changes': [['buy', '38238.19', '0.04000000']], 'time': '2021-05-20T03:54:52.498124Z'}
{'type': 'l2update', 'product_id': 'BTC-USD', 'changes': [['sell', '38299.98', '0.00000000']], 'time': '2021-05-20T03:54:52.500518Z'}
{'type': 'l2update', 'product_id': 'BTC-USD', 'changes': [['sell', '38349.44', '0.00000000']], 'time': '2021-05-20T03:54:52.505707Z'}
{'type': 'l2update', 'product_id': 'BTC-USD', 'changes': [['buy', '38238.19', '0.09000000']], 'time': '2021-05-20T03:54:52.511705Z'}
{'type': 'l2update', 'product_id': 'BTC-USD', 'changes': [['buy', '37500.00', '13.30391442']], 'time': '2021-05-20T03:54:52.523811Z'}
{'type': 'l2update', 'product_id': 'BTC-USD', 'changes': [['sell', '38319.67', '0.04748503']], 'time': '2021-05-20T03:54:52.528037Z'}
{'type': 'l2update', 'product_id': 'BTC-USD', 'changes': [['sell', '38279.85', '0.29609914']], 'time': '2021-05-20T03:54:52.531667Z'}
{'type': 'l2update', 'product_id': 'BTC-USD', 'changes': [['sell', '50827.83', '0.00296600']], 'time': '2021-05-20T03:54:52.531735Z'}
{'type': 'l2update', 'product_id': 'BTC-USD', 'changes': [['buy', '38269.72', '0.84900000']], 'time': '2021-05-20T03:54:52.536910Z'}
{'type': 'l2update', 'product_id': 'BTC-USD', 'changes': [['buy', '38260.47', '0.00000000']], 'time': '2021-05-20T03:54:52.545469Z'}
{'type': 'l2update', 'product_id': 'BTC-USD', 'changes': [['buy', '38036.24', '0.95239448']], 'time': '2021-05-20T03:54:52.547003Z'}
{'type': 'l2update', 'product_id': 'BTC-USD', 'changes': [['buy', '38002.43', '0.00000000']], 'time': '2021-05-20T03:54:52.554103Z'}
{'type': 'l2update', 'product_id': 'BTC-USD', 'changes': [['sell', '38327.82', '0.02950017']], 'time': '2021-05-20T03:54:52.554994Z'}
{'type': 'l2update', 'product_id': 'BTC-USD', 'changes': [['buy', '38203.87', '0.00000000']], 'time': '2021-05-20T03:54:52.558213Z'}
{'type': 'l2update', 'product_id': 'BTC-USD', 'changes': [['sell', '38279.85', '0.29556570']], 'time': '2021-05-20T03:54:52.562776Z'}
{'type': 'l2update', 'product_id': 'BTC-USD', 'changes': [['sell', '38461.51', '0.00000000']], 'time': '2021-05-20T03:54:52.563755Z'}
{'type': 'l2update', 'product_id': 'BTC-USD', 'changes': [['buy', '38217.28', '0.01000000']], 'time': '2021-05-20T03:54:52.575620Z'}
{'type': 'l2update', 'product_id': 'BTC-USD', 'changes': [['buy', '38244.89', '0.05000000']], 'time': '2021-05-20T03:54:52.580891Z'}
{'type': 'l2update', 'product_id': 'BTC-USD', 'changes': [['sell', '38332.18', '0.03050067']], 'time': '2021-05-20T03:54:52.583459Z'}
{'type': 'l2update', 'product_id': 'BTC-USD', 'changes': [['buy', '38244.89', '0.03000000']], 'time': '2021-05-20T03:54:52.585407Z'}
{'type': 'l2update', 'product_id': 'BTC-USD', 'changes': [['sell', '38477.70', '0.02598907']], 'time': '2021-05-20T03:54:52.588036Z'}
{'type': 'l2update', 'product_id': 'BTC-USD', 'changes': [['buy', '38252.14', '0.40570000']], 'time': '2021-05-20T03:54:52.588208Z'}
{'type': 'l2update', 'product_id': 'BTC-USD', 'changes': [['buy', '38244.89', '0.00000000']], 'time': '2021-05-20T03:54:52.589437Z'}
{'type': 'l2update', 'product_id': 'BTC-USD', 'changes': [['buy', '38238.19', '0.05000000']], 'time': '2021-05-20T03:54:52.594206Z'}
{'type': 'l2update', 'product_id': 'BTC-USD', 'changes': [['buy', '38238.19', '0.00000000']], 'time': '2021-05-20T03:54:52.598165Z'}
{'type': 'l2update', 'product_id': 'BTC-USD', 'changes': [['sell', '38299.99', '0.41860000']], 'time': '2021-05-20T03:54:52.599928Z'}
{'type': 'l2update', 'product_id': 'BTC-USD', 'changes': [['buy', '38269.72', '0.00000000']], 'time': '2021-05-20T03:54:52.604389Z'}
{'type': 'l2update', 'product_id': 'BTC-USD', 'changes': [['sell', '38341.47', '0.03632841']], 'time': '2021-05-20T03:54:52.608043Z'}
{'type': 'l2update', 'product_id': 'BTC-USD', 'changes': [['buy', '38260.29', '0.59716278']], 'time': '2021-05-20T03:54:52.608295Z'}
{'type': 'l2update', 'product_id': 'BTC-USD', 'changes': [['buy', '38260.47', '0.25308028']], 'time': '2021-05-20T03:54:52.616473Z'}
{'type': 'l2update', 'product_id': 'BTC-USD', 'changes': [['buy', '38260.29', '0.61716278']], 'time': '2021-05-20T03:54:52.620514Z'}
{'type': 'l2update', 'product_id': 'BTC-USD', 'changes': [['sell', '38291.53', '0.00000000']], 'time': '2021-05-20T03:54:52.621285Z'}
{'type': 'l2update', 'product_id': 'BTC-USD', 'changes': [['sell', '38351.54', '0.02945015']], 'time': '2021-05-20T03:54:52.634744Z'}
{'type': 'l2update', 'product_id': 'BTC-USD', 'changes': [['buy', '38257.15', '0.03000000']], 'time': '2021-05-20T03:54:52.634986Z'}
{'type': 'l2update', 'product_id': 'BTC-USD', 'changes': [['sell', '38279.85', '0.29533126']], 'time': '2021-05-20T03:54:52.635013Z'}
{'type': 'l2update', 'product_id': 'BTC-USD', 'changes': [['buy', '38232.08', '0.00000000']], 'time': '2021-05-20T03:54:52.641766Z'}
{'type': 'l2update', 'product_id': 'BTC-USD', 'changes': [['sell', '38294.13', '0.03710766']], 'time': '2021-05-20T03:54:52.647092Z'}
{'type': 'l2update', 'product_id': 'BTC-USD', 'changes': [['buy', '38254.59', '0.04000000']], 'time': '2021-05-20T03:54:52.647425Z'}
{'type': 'l2update', 'product_id': 'BTC-USD', 'changes': [['buy', '38248.84', '0.43190831']], 'time': '2021-05-20T03:54:52.648410Z'}
{'type': 'l2update', 'product_id': 'BTC-USD', 'changes': [['buy', '38248.65', '0.01195355']], 'time': '2021-05-20T03:54:52.651686Z'}
{'type': 'l2update', 'product_id': 'BTC-USD', 'changes': [['buy', '38254.59', '0.09000000']], 'time': '2021-05-20T03:54:52.662656Z'}
{'type': 'l2update', 'product_id': 'BTC-USD', 'changes': [['sell', '38356.86', '0.02816508']], 'time': '2021-05-20T03:54:52.667295Z'}
{'type': 'l2update', 'product_id': 'BTC-USD', 'changes': [['sell', '38477.70', '0.00000000']], 'time': '2021-05-20T03:54:52.668910Z'}
{'type': 'l2update', 'product_id': 'BTC-USD', 'changes': [['sell', '38279.85', '0.29207659']], 'time': '2021-05-20T03:54:52.673872Z'}
{'type': 'l2update', 'product_id': 'BTC-USD', 'changes': [['sell', '38493.91', '0.01000000']], 'time': '2021-05-20T03:54:52.682105Z'}
{'type': 'l2update', 'product_id': 'BTC-USD', 'changes': [['sell', '38286.60', '1.65500000']], 'time': '2021-05-20T03:54:52.694205Z'}
{'type': 'l2update', 'product_id': 'BTC-USD', 'changes': [['sell', '50832.17', '0.00531300']], 'time': '2021-05-20T03:54:52.694232Z'}
{'type': 'l2update', 'product_id': 'BTC-USD', 'changes': [['sell', '38362.37', '0.03475007']], 'time': '2021-05-20T03:54:52.696018Z'}
{'type': 'l2update', 'product_id': 'BTC-USD', 'changes': [['sell', '38279.85', '0.29042693']], 'time': '2021-05-20T03:54:52.711345Z'}
{'type': 'l2update', 'product_id': 'BTC-USD', 'changes': [['sell', '38368.07', '0.03420746']], 'time': '2021-05-20T03:54:52.715961Z'}
{'type': 'l2update', 'product_id': 'BTC-USD', 'changes': [['buy', '38272.16', '0.00000000']], 'time': '2021-05-20T03:54:52.717988Z'}
{'type': 'l2update', 'product_id': 'BTC-USD', 'changes': [['buy', '38210.12', '0.00000000']], 'time': '2021-05-20T03:54:52.729886Z'}
{'type': 'l2update', 'product_id': 'BTC-USD', 'changes': [['sell', '38330.66', '0.00000000']], 'time': '2021-05-20T03:54:52.730358Z'}
{'type': 'l2update', 'product_id': 'BTC-USD', 'changes': [['buy', '38252.14', '0.00000000']], 'time': '2021-05-20T03:54:52.736078Z'}
{'type': 'l2update', 'product_id': 'BTC-USD', 'changes': [['sell', '38286.60', '0.56800000']], 'time': '2021-05-20T03:54:52.738378Z'}
{'type': 'l2update', 'product_id': 'BTC-USD', 'changes': [['buy', '38217.92', '1.28355376']], 'time': '2021-05-20T03:54:52.743481Z'}
{'type': 'l2update', 'product_id': 'BTC-USD', 'changes': [['buy', '38253.94', '0.42700000']], 'time': '2021-05-20T03:54:52.747308Z'}
{'type': 'l2update', 'product_id': 'BTC-USD', 'changes': [['sell', '38380.04', '0.02847920']], 'time': '2021-05-20T03:54:52.747457Z'}
{'type': 'l2update', 'product_id': 'BTC-USD', 'changes': [['sell', '38338.48', '0.61482417']], 'time': '2021-05-20T03:54:52.748386Z'}
{'type': 'l2update', 'product_id': 'BTC-USD', 'changes': [['buy', '38275.84', '0.01007667']], 'time': '2021-05-20T03:54:52.755891Z'}
{'type': 'l2update', 'product_id': 'BTC-USD', 'changes': [['buy', '38248.84', '0.39490431']], 'time': '2021-05-20T03:54:52.760623Z'}
{'type': 'l2update', 'product_id': 'BTC-USD', 'changes': [['buy', '38239.62', '0.00000000']], 'time': '2021-05-20T03:54:52.764999Z'}
{'type': 'l2update', 'product_id': 'BTC-USD', 'changes': [['buy', '38238.82', '0.00000000']], 'time': '2021-05-20T03:54:52.764999Z'}
{'type': 'l2update', 'product_id': 'BTC-USD', 'changes': [['buy', '38238.01', '0.00000000']], 'time': '2021-05-20T03:54:52.764999Z'}
{'type': 'l2update', 'product_id': 'BTC-USD', 'changes': [['sell', '38386.31', '0.02693701']], 'time': '2021-05-20T03:54:52.773125Z'}
{'type': 'l2update', 'product_id': 'BTC-USD', 'changes': [['buy', '38245.66', '0.02400000']], 'time': '2021-05-20T03:54:52.781326Z'}
{'type': 'l2update', 'product_id': 'BTC-USD', 'changes': [['buy', '38244.86', '0.02400000']], 'time': '2021-05-20T03:54:52.781326Z'}
