{'type': 'l2update', 'product_id': 'BTC-USD', 'changes': [['sell', '38282.34', '0.01492000']], 'time': '2021-05-20T03:54:57.843849Z'}
{'type': 'l2update', 'product_id': 'BTC-USD', 'changes': [['buy', '38269.78', '0.05000000']], 'time': '2021-05-20T03:54:57.847683Z'}
{'type': 'l2update', 'product_id': 'BTC-USD', 'changes': [['sell', '38282.34', '0.00000000']], 'time': '2021-05-20T03:54:57.848910Z'}
{'type': 'l2update', 'product_id': 'BTC-USD', 'changes': [['buy', '38272.47', '0.07460000']], 'time': '2021-05-20T03:54:57.851931Z'}
{'type': 'l2update', 'product_id': 'BTC-USD', 'changes': [['buy', '38267.96', '0.84700000']], 'time': '2021-05-20T03:54:57.851959Z'}
{'type': 'l2update', 'product_id': 'BTC-USD', 'changes': [['buy', '38272.93', '0.01492000']], 'time': '2021-05-20T03:54:57.856387Z'}
{'type': 'l2update', 'product_id': 'BTC-USD', 'changes': [['buy', '38272.47', '0.00000000']], 'time': '2021-05-20T03:54:57.861513Z'}
{'type': 'l2update', 'product_id': 'BTC-USD', 'changes': [['sell', '38281.45', '0.01492000']], 'time': '2021-05-20T03:54:57.864964Z'}
{'type': 'l2update', 'product_id': 'BTC-USD', 'changes': [['sell', '38291.71', '0.00000000']], 'time': '2021-05-20T03:54:57.865291Z'}
{'type': 'l2update', 'product_id': 'BTC-USD', 'changes': [['sell', '38281.45', '0.00000000']], 'time': '2021-05-20T03:54:57.869328Z'}
{'type': 'l2update', 'product_id': 'BTC-USD', 'changes': [['sell', '38282.07', '0.00000000']], 'time': '2021-05-20T03:54:57.870244Z'}
{'type': 'l2update', 'product_id': 'BTC-USD', 'changes': [['buy', '38273.45', '0.07460000']], 'time': '2021-05-20T03:54:57.876673Z'}
{'type': 'l2update', 'product_id': 'BTC-USD', 'changes': [['sell', '38282.40', '0.07460000']], 'time': '2021-05-20T03:54:57.882172Z'}
{'type': 'l2update', 'product_id': 'BTC-USD', 'changes': [['buy', '38272.93', '0.00000000']], 'time': '2021-05-20T03:54:57.884433Z'}
{'type': 'l2update', 'product_id': 'BTC-USD', 'changes': [['buy', '37485.34', '0.00000000']], 'time': '2021-05-20T03:54:57.890015Z'}
{'type': 'l2update', 'product_id': 'BTC-USD', 'changes': [['buy', '37500.01', '0.13480000']], 'time': '2021-05-20T03:54:57.890015Z'}
{'type': 'l2update', 'product_id': 'BTC-USD', 'changes': [['buy', '38273.45', '0.00000000']], 'time': '2021-05-20T03:54:57.890695Z'}
{'type': 'l2update', 'product_id': 'BTC-USD', 'changes': [['buy', '38192.93', '0.00000000']], 'time': '2021-05-20T03:54:57.895446Z'}
{'type': 'l2update', 'product_id': 'BTC-USD', 'changes': [['buy', '37500.01', '0.19600000']], 'time': '2021-05-20T03:54:57.897986Z'}
{'type': 'l2update', 'product_id': 'BTC-USD', 'changes': [['buy', '38273.77', '0.01492000']], 'time': '2021-05-20T03:54:57.898127Z'}
{'type': 'l2update', 'product_id': 'BTC-USD', 'changes': [['buy', '38262.85', '0.00000000']], 'time': '2021-05-20T03:54:57.898364Z'}
{'type': 'l2update', 'product_id': 'BTC-USD', 'changes': [['sell', '38295.35', '0.06280728']], 'time': '2021-05-20T03:54:57.901126Z'}
{'type': 'l2update', 'product_id': 'BTC-USD', 'changes': [['buy', '38273.77', '0.00000000']], 'time': '2021-05-20T03:54:57.903448Z'}
{'type': 'l2update', 'product_id': 'BTC-USD', 'changes': [['sell', '38281.82', '0.00726086']], 'time': '2021-05-20T03:54:57.905449Z'}
{'type': 'l2update', 'product_id': 'BTC-USD', 'changes': [['buy', '38272.57', '0.07460000']], 'time': '2021-05-20T03:54:57.905646Z'}
{'type': 'l2update', 'product_id': 'BTC-USD', 'changes': [['buy', '38272.57', '0.00000000']], 'time': '2021-05-20T03:54:57.910413Z'}
{'type': 'l2update', 'product_id': 'BTC-USD', 'changes': [['buy', '38170.95', '0.01551080']], 'time': '2021-05-20T03:54:57.911498Z'}
{'type': 'l2update', 'product_id': 'BTC-USD', 'changes': [['sell', '39607.33', '0.24200000']], 'time': '2021-05-20T03:54:57.911716Z'}
{'type': 'l2update', 'product_id': 'BTC-USD', 'changes': [['sell', '38475.81', '0.00000000']], 'time': '2021-05-20T03:54:57.913574Z'}
{'type': 'l2update', 'product_id': 'BTC-USD', 'changes': [['buy', '38271.89', '0.10000000']], 'time': '2021-05-20T03:54:57.914460Z'}
{'type': 'l2update', 'product_id': 'BTC-USD', 'changes': [['buy', '38267.97', '0.11747527']], 'time': '2021-05-20T03:54:57.918796Z'}
{'type': 'l2update', 'product_id': 'BTC-USD', 'changes': [['buy', '38272.38', '0.01492000']], 'time': '2021-05-20T03:54:57.918961Z'}
{'type': 'l2update', 'product_id': 'BTC-USD', 'changes': [['sell', '38281.82', '0.01492000']], 'time': '2021-05-20T03:54:57.919079Z'}
{'type': 'l2update', 'product_id': 'BTC-USD', 'changes': [['buy', '38272.26', '0.07460000']], 'time': '2021-05-20T03:54:57.921134Z'}
{'type': 'l2update', 'product_id': 'BTC-USD', 'changes': [['buy', '38272.38', '0.00000000']], 'time': '2021-05-20T03:54:57.924340Z'}
{'type': 'l2update', 'product_id': 'BTC-USD', 'changes': [['sell', '38464.19', '0.01000000']], 'time': '2021-05-20T03:54:57.925240Z'}
{'type': 'l2update', 'product_id': 'BTC-USD', 'changes': [['buy', '38245.13', '0.00000000']], 'time': '2021-05-20T03:54:57.926074Z'}
{'type': 'l2update', 'product_id': 'BTC-USD', 'changes': [['buy', '38272.26', '0.00000000']], 'time': '2021-05-20T03:54:57.926334Z'}
{'type': 'l2update', 'product_id': 'BTC-USD', 'changes': [['sell', '38282.40', '0.00000000']], 'time': '2021-05-20T03:54:57.929141Z'}
{'type': 'l2update', 'product_id': 'BTC-USD', 'changes': [['buy', '38224.38', '0.00000000']], 'time': '2021-05-20T03:54:57.931673Z'}
{'type': 'l2update', 'product_id': 'BTC-USD', 'changes': [['sell', '38292.92', '0.00000000']], 'time': '2021-05-20T03:54:57.933637Z'}
{'type': 'l2update', 'product_id': 'BTC-USD', 'changes': [['buy', '38272.80', '0.01492000']], 'time': '2021-05-20T03:54:57.937022Z'}
{'type': 'l2update', 'product_id': 'BTC-USD', 'changes': [['buy', '38250.03', '0.00000000']], 'time': '2021-05-20T03:54:57.940521Z'}
{'type': 'l2update', 'product_id': 'BTC-USD', 'changes': [['sell', '38295.35', '0.00000000']], 'time': '2021-05-20T03:54:57.940521Z'}
{'type': 'l2update', 'product_id': 'BTC-USD', 'changes': [['buy', '38272.65', '0.07460000']], 'time': '2021-05-20T03:54:57.941318Z'}
{'type': 'l2update', 'product_id': 'BTC-USD', 'changes': [['sell', '38281.82', '0.00765914']], 'time': '2021-05-20T03:54:57.943654Z'}
{'type': 'l2update', 'product_id': 'BTC-USD', 'changes': [['sell', '38281.82', '0.00000000']], 'time': '2021-05-20T03:54:57.944178Z'}
{'type': 'l2update', 'product_id': 'BTC-USD', 'changes': [['buy', '38272.65', '0.00000000']], 'time': '2021-05-20T03:54:57.945668Z'}
{'type': 'l2update', 'product_id': 'BTC-USD', 'changes': [['buy', '38111.89', '0.04915621']], 'time': '2021-05-20T03:54:57.953498Z'}
{'type': 'l2update', 'product_id': 'BTC-USD', 'changes': [['sell', '38282.53', '0.07460000']], 'time': '2021-05-20T03:54:57.958223Z'}
{'type': 'l2update', 'product_id': 'BTC-USD', 'changes': [['sell', '38282.78', '0.01492000']], 'time': '2021-05-20T03:54:57.958523Z'}
{'type': 'l2update', 'product_id': 'BTC-USD', 'changes': [['sell', '38282.78', '0.00000000']], 'time': '2021-05-20T03:54:57.964392Z'}
{'type': 'l2update', 'product_id': 'BTC-USD', 'changes': [['sell', '38295.66', '0.04201003']], 'time': '2021-05-20T03:54:57.965535Z'}
{'type': 'l2update', 'product_id': 'BTC-USD', 'changes': [['buy', '38273.18', '0.07460000']], 'time': '2021-05-20T03:54:57.965584Z'}
{'type': 'l2update', 'product_id': 'BTC-USD', 'changes': [['buy', '38251.04', '0.06397087']], 'time': '2021-05-20T03:54:57.972223Z'}
{'type': 'l2update', 'product_id': 'BTC-USD', 'changes': [['sell', '38295.02', '0.04559533']], 'time': '2021-05-20T03:54:57.972223Z'}
{'type': 'l2update', 'product_id': 'BTC-USD', 'changes': [['buy', '38107.96', '0.00000000']], 'time': '2021-05-20T03:54:57.972825Z'}
{'type': 'l2update', 'product_id': 'BTC-USD', 'changes': [['buy', '38272.80', '0.00000000']], 'time': '2021-05-20T03:54:57.973768Z'}
{'type': 'l2update', 'product_id': 'BTC-USD', 'changes': [['buy', '38267.97', '0.00000000']], 'time': '2021-05-20T03:54:57.974894Z'}
{'type': 'l2update', 'product_id': 'BTC-USD', 'changes': [['buy', '38269.77', '0.00000000']], 'time': '2021-05-20T03:54:57.976557Z'}
{'type': 'l2update', 'product_id': 'BTC-USD', 'changes': [['sell', '52425.68', '0.00184400']], 'time': '2021-05-20T03:54:57.981069Z'}
{'type': 'l2update', 'product_id': 'BTC-USD', 'changes': [['buy', '38272.01', '0.10000000']], 'time': '2021-05-20T03:54:57.989049Z'}
{'type': 'l2update', 'product_id': 'BTC-USD', 'changes': [['buy', '38272.01', '0.15000000']], 'time': '2021-05-20T03:54:57.989201Z'}
{'type': 'l2update', 'product_id': 'BTC-USD', 'changes': [['sell', '38282.30', '0.01492000']], 'time': '2021-05-20T03:54:57.989421Z'}
{'type': 'l2update', 'product_id': 'BTC-USD', 'changes': [['buy', '38267.97', '0.11747527']], 'time': '2021-05-20T03:54:57.992754Z'}
{'type': 'l2update', 'product_id': 'BTC-USD', 'changes': [['sell', '38282.53', '0.00000000']], 'time': '2021-05-20T03:54:57.995590Z'}
{'type': 'l2update', 'product_id': 'BTC-USD', 'changes': [['buy', '38273.18', '0.00000000']], 'time': '2021-05-20T03:54:57.995724Z'}
{'type': 'l2update', 'product_id': 'BTC-USD', 'changes': [['buy', '38258.16', '0.02400000']], 'time': '2021-05-20T03:54:57.996450Z'}
{'type': 'l2update', 'product_id': 'BTC-USD', 'changes': [['buy', '38257.36', '0.02400000']], 'time': '2021-05-20T03:54:57.996450Z'}
{'type': 'l2update', 'product_id': 'BTC-USD', 'changes': [['buy', '38256.56', '0.02400000']], 'time': '2021-05-20T03:54:57.996450Z'}
{'type': 'l2update', 'product_id': 'BTC-USD', 'changes': [['buy', '38273.81', '0.01492000']], 'time': '2021-05-20T03:54:58.000479Z'}
{'type': 'l2update', 'product_id': 'BTC-USD', 'changes': [['buy', '38273.81', '0.00000000']], 'time': '2021-05-20T03:54:58.005772Z'}
{'type': 'l2update', 'product_id': 'BTC-USD', 'changes': [['buy', '38272.43', '0.07460000']], 'time': '2021-05-20T03:54:58.008008Z'}
{'type': 'l2update', 'product_id': 'BTC-USD', 'changes': [['sell', '38281.77', '0.04930030']], 'time': '2021-05-20T03:54:58.008019Z'}
{'type': 'l2update', 'product_id': 'BTC-USD', 'changes': [['buy', '38267.91', '0.00000000']], 'time': '2021-05-20T03:54:58.008102Z'}
{'type': 'l2update', 'product_id': 'BTC-USD', 'changes': [['buy', '38269.78', '0.00000000']], 'time': '2021-05-20T03:54:58.008542Z'}
{'type': 'l2update', 'product_id': 'BTC-USD', 'changes': [['sell', '38281.77', '0.07460000']], 'time': '2021-05-20T03:54:58.011632Z'}
{'type': 'l2update', 'product_id': 'BTC-USD', 'changes': [['buy', '38271.89', '0.00000000']], 'time': '2021-05-20T03:54:58.012905Z'}
{'type': 'l2update', 'product_id': 'BTC-USD', 'changes': [['buy', '38272.43', '0.00000000']], 'time': '2021-05-20T03:54:58.013836Z'}
{'type': 'l2update', 'product_id': 'BTC-USD', 'changes': [['sell', '38281.77', '0.02529970']], 'time': '2021-05-20T03:54:58.014088Z'}
{'type': 'l2update', 'product_id': 'BTC-USD', 'changes': [['buy', '38267.90', '0.12000000']], 'time': '2021-05-20T03:54:58.014400Z'}
{'type': 'l2update', 'product_id': 'BTC-USD', 'changes': [['sell', '38441.87', '0.00000000']], 'time': '2021-05-20T03:54:58.014665Z'}
{'type': 'l2update', 'product_id': 'BTC-USD', 'changes': [['sell', '38281.77', '0.00000000']], 'time': '2021-05-20T03:54:58.016497Z'}
{'type': 'l2update', 'product_id': 'BTC-USD', 'changes': [['buy', '38267.90', '0.09000000']], 'time': '2021-05-20T03:54:58.017815Z'}
{'type': 'l2update', 'product_id': 'BTC-USD', 'changes': [['buy', '38272.36', '0.01492000']], 'time': '2021-05-20T03:54:58.018922Z'}
{'type': 'l2update', 'product_id': 'BTC-USD', 'changes': [['buy', '38266.05', '0.00000000']], 'time': '2021-05-20T03:54:58.019486Z'}
{'type': 'l2update', 'product_id': 'BTC-USD', 'changes': [['buy', '38267.90', '0.05000000']], 'time': '2021-05-20T03:54:58.021374Z'}
{'type': 'l2update', 'product_id': 'BTC-USD', 'changes': [['sell', '38282.30', '0.00000000']], 'time': '2021-05-20T03:54:58.023268Z'}
{'type': 'l2update', 'product_id': 'BTC-USD', 'changes': [['buy', '38267.96', '0.00000000']], 'time': '2021-05-20T03:54:58.023787Z'}
{'type': 'l2update', 'product_id': 'BTC-USD', 'changes': [['buy', '38272.36', '0.00000000']], 'time': '2021-05-20T03:54:58.023795Z'}
{'type': 'l2update', 'product_id': 'BTC-USD', 'changes': [['buy', '38267.90', '0.00000000']], 'time': '2021-05-20T03:54:58.025120Z'}
{'type': 'l2update', 'product_id': 'BTC-USD', 'changes': [['buy', '38272.59', '0.07460000']], 'time': '2021-05-20T03:54:58.026692Z'}
{'type': 'l2update', 'product_id': 'BTC-USD', 'changes': [['sell', '38281.71', '0.04930030']], 'time': '2021-05-20T03:54:58.026752Z'}
{'type': 'l2update', 'product_id': 'BTC-USD', 'changes': [['sell', '38428.86', '0.13011056']], 'time': '2021-05-20T03:54:58.026817Z'}
{'type': 'l2update', 'product_id': 'BTC-USD', 'changes': [['buy', '38258.16', '0.00000000']], 'time': '2021-05-20T03:54:58.027132Z'}
{'type': 'l2update', 'product_id': 'BTC-USD', 'changes': [['buy', '38257.36', '0.00000000']], 'time': '2021-05-20T03:54:58.027132Z'}
{'type': 'l2update', 'product_id': 'BTC-USD', 'changes': [['buy', '38256.56', '0.00000000']], 'time': '2021-05-20T03:54:58.027132Z'}
{'type': 'l2update', 'product_id': 'BTC-USD', 'changes': [['sell', '38281.71', '0.00000000']], 'time': '2021-05-20T03:54:58.031519Z'}
{'type': 'l2update', 'product_id': 'BTC-USD', 'changes': [['buy', '38262.84', '0.00000000']], 'time': '2021-05-20T03:54:58.032937Z'}
{'type': 'l2update', 'product_id': 'BTC-USD', 'changes': [['sell', '38282.33', '0.01492000']], 'time': '2021-05-20T03:54:58.035525Z'}
{'type': 'l2update', 'product_id': 'BTC-USD', 'changes': [['buy', '38268.02', '0.84700000']], 'time': '2021-05-20T03:54:58.035637Z'}
{'type': 'l2update', 'product_id': 'BTC-USD', 'changes': [['buy', '38272.01', '0.16000000']], 'time': '2021-05-20T03:54:58.035673Z'}
{'type': 'l2update', 'product_id': 'BTC-USD', 'changes': [['sell', '38281.71', '0.02529970']], 'time': '2021-05-20T03:54:58.035690Z'}
{'type': 'l2update', 'product_id': 'BTC-USD', 'changes': [['buy', '38273.19', '0.01492000']], 'time': '2021-05-20T03:54:58.039245Z'}
{'type': 'l2update', 'product_id': 'BTC-USD', 'changes': [['sell', '38282.33', '0.00000000']], 'time': '2021-05-20T03:54:58.041073Z'}
{'type': 'l2update', 'product_id': 'BTC-USD', 'changes': [['buy', '38262.78', '0.00000000']], 'time': '2021-05-20T03:54:58.042024Z'}
{'type': 'l2update', 'product_id': 'BTC-USD', 'changes': [['sell', '38282.41', '0.04930030']], 'time': '2021-05-20T03:54:58.043377Z'}
{'type': 'l2update', 'product_id': 'BTC-USD', 'changes': [['buy', '38253.45', '0.02400000']], 'time': '2021-05-20T03:54:58.043487Z'}
{'type': 'l2update', 'product_id': 'BTC-USD', 'changes': [['buy', '38252.64', '0.02400000']], 'time': '2021-05-20T03:54:58.043487Z'}
{'type': 'l2update', 'product_id': 'BTC-USD', 'changes': [['buy', '38251.83', '0.02400000']], 'time': '2021-05-20T03:54:58.043487Z'}
{'type': 'l2update', 'product_id': 'BTC-USD', 'changes': [['buy', '38272.59', '0.00000000']], 'time': '2021-05-20T03:54:58.044711Z'}
{'type': 'l2update', 'product_id': 'BTC-USD', 'changes': [['sell', '38295.02', '0.00000000']], 'time': '2021-05-20T03:54:58.045091Z'}
{'type': 'l2update', 'product_id': 'BTC-USD', 'changes': [['buy', '38272.43', '0.02000000']], 'time': '2021-05-20T03:54:58.046504Z'}
{'type': 'l2update', 'product_id': 'BTC-USD', 'changes': [['sell', '38281.71', '0.00000000']], 'time': '2021-05-20T03:54:58.047246Z'}
{'type': 'l2update', 'product_id': 'BTC-USD', 'changes': [['buy', '38267.97', '0.00000000']], 'time': '2021-05-20T03:54:58.047265Z'}
{'type': 'l2update', 'product_id': 'BTC-USD', 'changes': [['sell', '38282.41', '0.00000000']], 'time': '2021-05-20T03:54:58.050957Z'}
{'type': 'l2update', 'product_id': 'BTC-USD', 'changes': [['buy', '38272.43', '0.05000000']], 'time': '2021-05-20T03:54:58.054835Z'}
{'type': 'l2update', 'product_id': 'BTC-USD', 'changes': [['buy', '38273.81', '0.07460000']], 'time': '2021-05-20T03:54:58.059216Z'}
{'type': 'l2update', 'product_id': 'BTC-USD', 'changes': [['sell', '38281.77', '0.01492000']], 'time': '2021-05-20T03:54:58.059268Z'}
{'type': 'l2update', 'product_id': 'BTC-USD', 'changes': [['sell', '38282.50', '0.02529970']], 'time': '2021-05-20T03:54:58.059632Z'}
{'type': 'l2update', 'product_id': 'BTC-USD', 'changes': [['sell', '38306.94', '0.00000000']], 'time': '2021-05-20T03:54:58.059776Z'}
{'type': 'l2update', 'product_id': 'BTC-USD', 'changes': [['sell', '38282.50', '0.00000000']], 'time': '2021-05-20T03:54:58.065490Z'}
{'type': 'l2update', 'product_id': 'BTC-USD', 'changes': [['buy', '38273.19', '0.00000000']], 'time': '2021-05-20T03:54:58.066148Z'}
{'type': 'l2update', 'product_id': 'BTC-USD', 'changes': [['buy', '38272.01', '0.20000000']], 'time': '2021-05-20T03:54:58.067499Z'}
{'type': 'l2update', 'product_id': 'BTC-USD', 'changes': [['sell', '38281.77', '0.00000000']], 'time': '2021-05-20T03:54:58.069791Z'}
{'type': 'l2update', 'product_id': 'BTC-USD', 'changes': [['sell', '38308.10', '0.47120000']], 'time': '2021-05-20T03:54:58.070486Z'}
{'type': 'l2update', 'product_id': 'BTC-USD', 'changes': [['sell', '38282.50', '0.04930030']], 'time': '2021-05-20T03:54:58.070718Z'}
{'type': 'l2update', 'product_id': 'BTC-USD', 'changes': [['buy', '38253.83', '0.00000000']], 'time': '2021-05-20T03:54:58.074508Z'}
{'type': 'l2update', 'product_id': 'BTC-USD', 'changes': [['buy', '38273.81', '0.00000000']], 'time': '2021-05-20T03:54:58.075457Z'}
{'type': 'l2update', 'product_id': 'BTC-USD', 'changes': [['sell', '38291.71', '0.06104588']], 'time': '2021-05-20T03:54:58.076000Z'}
{'type': 'l2update', 'product_id': 'BTC-USD', 'changes': [['sell', '38282.50', '0.00000000']], 'time': '2021-05-20T03:54:58.076490Z'}
{'type': 'l2update', 'product_id': 'BTC-USD', 'changes': [['buy', '38272.01', '0.25000000']], 'time': '2021-05-20T03:54:58.079439Z'}
{'type': 'l2update', 'product_id': 'BTC-USD', 'changes': [['buy', '38272.44', '0.05000000']], 'time': '2021-05-20T03:54:58.079747Z'}
{'type': 'l2update', 'product_id': 'BTC-USD', 'changes': [['sell', '38282.65', '0.01492000']], 'time': '2021-05-20T03:54:58.082823Z'}
{'type': 'l2update', 'product_id': 'BTC-USD', 'changes': [['buy', '38274.16', '0.01492000']], 'time': '2021-05-20T03:54:58.082924Z'}
{'type': 'l2update', 'product_id': 'BTC-USD', 'changes': [['sell', '38282.57', '0.02529970']], 'time': '2021-05-20T03:54:58.083092Z'}
{'type': 'l2update', 'product_id': 'BTC-USD', 'changes': [['buy', '38255.93', '0.43630000']], 'time': '2021-05-20T03:54:58.086451Z'}
{'type': 'l2update', 'product_id': 'BTC-USD', 'changes': [['buy', '38272.99', '0.07460000']], 'time': '2021-05-20T03:54:58.086512Z'}
{'type': 'l2update', 'product_id': 'BTC-USD', 'changes': [['sell', '38282.65', '0.00000000']], 'time': '2021-05-20T03:54:58.087870Z'}
{'type': 'l2update', 'product_id': 'BTC-USD', 'changes': [['buy', '38253.45', '0.00000000']], 'time': '2021-05-20T03:54:58.089053Z'}
{'type': 'l2update', 'product_id': 'BTC-USD', 'changes': [['buy', '38274.16', '0.00000000']], 'time': '2021-05-20T03:54:58.092168Z'}
{'type': 'l2update', 'product_id': 'BTC-USD', 'changes': [['buy', '38272.99', '0.00000000']], 'time': '2021-05-20T03:54:58.092395Z'}
{'type': 'l2update', 'product_id': 'BTC-USD', 'changes': [['buy', '38268.02', '0.00000000']], 'time': '2021-05-20T03:54:58.093180Z'}
{'type': 'l2update', 'product_id': 'BTC-USD', 'changes': [['sell', '38282.57', '0.07460000']], 'time': '2021-05-20T03:54:58.097443Z'}
{'type': 'l2update', 'product_id': 'BTC-USD', 'changes': [['sell', '38469.76', '0.00000000']], 'time': '2021-05-20T03:54:58.101918Z'}
{'type': 'l2update', 'product_id': 'BTC-USD', 'changes': [['buy', '38250.76', '0.02400000']], 'time': '2021-05-20T03:54:58.104305Z'}
{'type': 'l2update', 'product_id': 'BTC-USD', 'changes': [['buy', '38262.80', '0.11747527']], 'time': '2021-05-20T03:54:58.105178Z'}
{'type': 'l2update', 'product_id': 'BTC-USD', 'changes': [['sell', '38281.98', '0.01492000']], 'time': '2021-05-20T03:54:58.105544Z'}
{'type': 'l2update', 'product_id': 'BTC-USD', 'changes': [['sell', '38283.01', '0.00000000']], 'time': '2021-05-20T03:54:58.107213Z'}
{'type': 'l2update', 'product_id': 'BTC-USD', 'changes': [['buy', '38272.81', '0.07460000']], 'time': '2021-05-20T03:54:58.108631Z'}
{'type': 'l2update', 'product_id': 'BTC-USD', 'changes': [['buy', '38273.45', '0.01492000']], 'time': '2021-05-20T03:54:58.108855Z'}
{'type': 'l2update', 'product_id': 'BTC-USD', 'changes': [['buy', '38252.64', '0.00000000']], 'time': '2021-05-20T03:54:58.110489Z'}
{'type': 'l2update', 'product_id': 'BTC-USD', 'changes': [['buy', '38170.95', '0.00000000']], 'time': '2021-05-20T03:54:58.111923Z'}
{'type': 'l2update', 'product_id': 'BTC-USD', 'changes': [['sell', '38282.57', '0.04930030']], 'time': '2021-05-20T03:54:58.112187Z'}
{'type': 'l2update', 'product_id': 'BTC-USD', 'changes': [['buy', '38273.45', '0.00000000']], 'time': '2021-05-20T03:54:58.114908Z'}
{'type': 'l2update', 'product_id': 'BTC-USD', 'changes': [['buy', '38272.81', '0.00000000']], 'time': '2021-05-20T03:54:58.115040Z'}
{'type': 'l2update', 'product_id': 'BTC-USD', 'changes': [['sell', '38282.57', '0.00000000']], 'time': '2021-05-20T03:54:58.115242Z'}
{'type': 'l2update', 'product_id': 'BTC-USD', 'changes': [['buy', '38249.72', '0.02400000']], 'time': '2021-05-20T03:54:58.120492Z'}
{'type': 'l2update', 'product_id': 'BTC-USD', 'changes': [['buy', '38182.88', '0.01000000']], 'time': '2021-05-20T03:54:58.120627Z'}
{'type': 'l2update', 'product_id': 'BTC-USD', 'changes': [['sell', '38492.51', '0.01000000']], 'time': '2021-05-20T03:54:58.125645Z'}
{'type': 'l2update', 'product_id': 'BTC-USD', 'changes': [['sell', '38281.74', '0.07460000']], 'time': '2021-05-20T03:54:58.125753Z'}
{'type': 'l2update', 'product_id': 'BTC-USD', 'changes': [['sell', '38282.56', '0.47369029']], 'time': '2021-05-20T03:54:58.125843Z'}
{'type': 'l2update', 'product_id': 'BTC-USD', 'changes': [['buy', '38272.80', '0.07460000']], 'time': '2021-05-20T03:54:58.128705Z'}
{'type': 'l2update', 'product_id': 'BTC-USD', 'changes': [['buy', '38272.75', '0.01492000']], 'time': '2021-05-20T03:54:58.128789Z'}
{'type': 'l2update', 'product_id': 'BTC-USD', 'changes': [['buy', '38255.93', '0.00000000']], 'time': '2021-05-20T03:54:58.133065Z'}
{'type': 'l2update', 'product_id': 'BTC-USD', 'changes': [['sell', '38281.98', '0.00000000']], 'time': '2021-05-20T03:54:58.133228Z'}
{'type': 'l2update', 'product_id': 'BTC-USD', 'changes': [['buy', '38272.75', '0.00000000']], 'time': '2021-05-20T03:54:58.136195Z'}
{'type': 'l2update', 'product_id': 'BTC-USD', 'changes': [['sell', '38308.10', '0.00000000']], 'time': '2021-05-20T03:54:58.137389Z'}
{'type': 'l2update', 'product_id': 'BTC-USD', 'changes': [['sell', '38492.51', '0.00000000']], 'time': '2021-05-20T03:54:58.138579Z'}
{'type': 'l2update', 'product_id': 'BTC-USD', 'changes': [['buy', '38272.44', '0.00000000']], 'time': '2021-05-20T03:54:58.140842Z'}
{'type': 'l2update', 'product_id': 'BTC-USD', 'changes': [['buy', '38267.72', '0.84800000']], 'time': '2021-05-20T03:54:58.146072Z'}
{'type': 'l2update', 'product_id': 'BTC-USD', 'changes': [['sell', '38281.13', '0.01492000']], 'time': '2021-05-20T03:54:58.146146Z'}
{'type': 'l2update', 'product_id': 'BTC-USD', 'changes': [['sell', '52752.83', '0.00101300']], 'time': '2021-05-20T03:54:58.150180Z'}
{'type': 'l2update', 'product_id': 'BTC-USD', 'changes': [['sell', '38281.74', '0.00000000']], 'time': '2021-05-20T03:54:58.151918Z'}
{'type': 'l2update', 'product_id': 'BTC-USD', 'changes': [['buy', '38272.01', '0.20000000']], 'time': '2021-05-20T03:54:58.154516Z'}
{'type': 'l2update', 'product_id': 'BTC-USD', 'changes': [['buy', '38273.36', '0.01492000']], 'time': '2021-05-20T03:54:58.158368Z'}
{'type': 'l2update', 'product_id': 'BTC-USD', 'changes': [['sell', '38283.02', '0.00000000']], 'time': '2021-05-20T03:54:58.159892Z'}
{'type': 'l2update', 'product_id': 'BTC-USD', 'changes': [['sell', '38477.17', '0.01000000']], 'time': '2021-05-20T03:54:58.162288Z'}
{'type': 'l2update', 'product_id': 'BTC-USD', 'changes': [['buy', '38272.80', '0.00000000']], 'time': '2021-05-20T03:54:58.163578Z'}
{'type': 'l2update', 'product_id': 'BTC-USD', 'changes': [['buy', '38262.80', '0.00000000']], 'time': '2021-05-20T03:54:58.164198Z'}
{'type': 'l2update', 'product_id': 'BTC-USD', 'changes': [['buy', '38224.55', '0.00000000']], 'time': '2021-05-20T03:54:58.164557Z'}
{'type': 'l2update', 'product_id': 'BTC-USD', 'changes': [['buy', '38273.36', '0.00000000']], 'time': '2021-05-20T03:54:58.164999Z'}
{'type': 'l2update', 'product_id': 'BTC-USD', 'changes': [['sell', '38281.13', '0.00000000']], 'time': '2021-05-20T03:54:58.168804Z'}
{'type': 'l2update', 'product_id': 'BTC-USD', 'changes': [['sell', '38282.56', '0.00000000']], 'time': '2021-05-20T03:54:58.170908Z'}
{'type': 'l2update', 'product_id': 'BTC-USD', 'changes': [['sell', '38281.12', '2.48969908']], 'time': '2021-05-20T03:54:58.175340Z'}
{'type': 'l2update', 'product_id': 'BTC-USD', 'changes': [['buy', '38225.55', '0.10000000']], 'time': '2021-05-20T03:54:58.175373Z'}
{'type': 'l2update', 'product_id': 'BTC-USD', 'changes': [['buy', '38273.05', '0.01492000']], 'time': '2021-05-20T03:54:58.179969Z'}
{'type': 'l2update', 'product_id': 'BTC-USD', 'changes': [['sell', '38282.12', '0.07460000']], 'time': '2021-05-20T03:54:58.180023Z'}
{'type': 'l2update', 'product_id': 'BTC-USD', 'changes': [['buy', '38272.78', '0.07460000']], 'time': '2021-05-20T03:54:58.180145Z'}
{'type': 'l2update', 'product_id': 'BTC-USD', 'changes': [['sell', '38281.89', '0.01492000']], 'time': '2021-05-20T03:54:58.180294Z'}
{'type': 'l2update', 'product_id': 'BTC-USD', 'changes': [['sell', '38281.12', '0.00000000']], 'time': '2021-05-20T03:54:58.181008Z'}
{'type': 'l2update', 'product_id': 'BTC-USD', 'changes': [['sell', '38389.87', '0.00000000']], 'time': '2021-05-20T03:54:58.184361Z'}
{'type': 'l2update', 'product_id': 'BTC-USD', 'changes': [['buy', '38262.80', '0.11747527']], 'time': '2021-05-20T03:54:58.184775Z'}
{'type': 'l2update', 'product_id': 'BTC-USD', 'changes': [['sell', '38282.12', '0.00000000']], 'time': '2021-05-20T03:54:58.184836Z'}
{'type': 'l2update', 'product_id': 'BTC-USD', 'changes': [['buy', '38239.95', '0.00000000']], 'time': '2021-05-20T03:54:58.186153Z'}
{'type': 'l2update', 'product_id': 'BTC-USD', 'changes': [['sell', '38281.89', '0.00000000']], 'time': '2021-05-20T03:54:58.187205Z'}
{'type': 'l2update', 'product_id': 'BTC-USD', 'changes': [['buy', '38272.02', '0.05000000']], 'time': '2021-05-20T03:54:58.188365Z'}
{'type': 'l2update', 'product_id': 'BTC-USD', 'changes': [['buy', '38272.78', '0.00000000']], 'time': '2021-05-20T03:54:58.189000Z'}
{'type': 'l2update', 'product_id': 'BTC-USD', 'changes': [['buy', '38235.32', '0.03266022']], 'time': '2021-05-20T03:54:58.192189Z'}
{'type': 'l2update', 'product_id': 'BTC-USD', 'changes': [['sell', '38281.11', '0.47369029']], 'time': '2021-05-20T03:54:58.192635Z'}
{'type': 'l2update', 'product_id': 'BTC-USD', 'changes': [['sell', '38405.40', '0.01301900']], 'time': '2021-05-20T03:54:58.198153Z'}
{'type': 'l2update', 'product_id': 'BTC-USD', 'changes': [['sell', '38282.79', '0.07460000']], 'time': '2021-05-20T03:54:58.201120Z'}
{'type': 'l2update', 'product_id': 'BTC-USD', 'changes': [['sell', '38283.03', '2.48969908']], 'time': '2021-05-20T03:54:58.201192Z'}
{'type': 'l2update', 'product_id': 'BTC-USD', 'changes': [['sell', '38282.41', '0.01492000']], 'time': '2021-05-20T03:54:58.201594Z'}
{'type': 'l2update', 'product_id': 'BTC-USD', 'changes': [['sell', '38282.79', '0.00000000']], 'time': '2021-05-20T03:54:58.206278Z'}
{'type': 'l2update', 'product_id': 'BTC-USD', 'changes': [['sell', '38282.41', '0.00000000']], 'time': '2021-05-20T03:54:58.208009Z'}
{'type': 'l2update', 'product_id': 'BTC-USD', 'changes': [['sell', '38438.56', '0.00000000']], 'time': '2021-05-20T03:54:58.208910Z'}
{'type': 'l2update', 'product_id': 'BTC-USD', 'changes': [['sell', '43100.00', '1.09530000']], 'time': '2021-05-20T03:54:58.214877Z'}
{'type': 'l2update', 'product_id': 'BTC-USD', 'changes': [['buy', '38255.92', '0.45820000']], 'time': '2021-05-20T03:54:58.224028Z'}
{'type': 'l2update', 'product_id': 'BTC-USD', 'changes': [['buy', '36000.00', '32.33005314']], 'time': '2021-05-20T03:54:58.224281Z'}
{'type': 'l2update', 'product_id': 'BTC-USD', 'changes': [['sell', '43100.00', '1.85260000']], 'time': '2021-05-20T03:54:58.231004Z'}
{'type': 'l2update', 'product_id': 'BTC-USD', 'changes': [['sell', '38417.05', '0.00780903']], 'time': '2021-05-20T03:54:58.231145Z'}
{'type': 'l2update', 'product_id': 'BTC-USD', 'changes': [['sell', '38308.47', '0.49590000']], 'time': '2021-05-20T03:54:58.234713Z'}
{'type': 'l2update', 'product_id': 'BTC-USD', 'changes': [['sell', '38433.14', '0.00000000']], 'time': '2021-05-20T03:54:58.242820Z'}
{'type': 'l2update', 'product_id': 'BTC-USD', 'changes': [['sell', '38280.81', '0.01539089']], 'time': '2021-05-20T03:54:58.251366Z'}
{'type': 'l2update', 'product_id': 'BTC-USD', 'changes': [['sell', '38280.84', '0.01492000']], 'time': '2021-05-20T03:54:58.251380Z'}
{'type': 'l2update', 'product_id': 'BTC-USD', 'changes': [['sell', '38419.29', '0.01279710']], 'time': '2021-05-20T03:54:58.256303Z'}
{'type': 'l2update', 'product_id': 'BTC-USD', 'changes': [['sell', '38280.81', '0.00000000']], 'time': '2021-05-20T03:54:58.257499Z'}
{'type': 'l2update', 'product_id': 'BTC-USD', 'changes': [['buy', '38262.80', '0.00000000']], 'time': '2021-05-20T03:54:58.257635Z'}
{'type': 'l2update', 'product_id': 'BTC-USD', 'changes': [['sell', '38280.84', '0.00000000']], 'time': '2021-05-20T03:54:58.257744Z'}
{'type': 'l2update', 'product_id': 'BTC-USD', 'changes': [['sell', '38281.11', '0.00000000']], 'time': '2021-05-20T03:54:58.258333Z'}
{'type': 'l2update', 'product_id': 'BTC-USD', 'changes': [['sell', '39607.33', '0.00000000']], 'time': '2021-05-20T03:54:58.265727Z'}
{'type': 'l2update', 'product_id': 'BTC-USD', 'changes': [['buy', '38275.66', '0.01141150']], 'time': '2021-05-20T03:54:58.272852Z'}
{'type': 'l2update', 'product_id': 'BTC-USD', 'changes': [['sell', '38282.58', '0.07460000']], 'time': '2021-05-20T03:54:58.273044Z'}
{'type': 'l2update', 'product_id': 'BTC-USD', 'changes': [['buy', '38273.74', '0.07460000']], 'time': '2021-05-20T03:54:58.273066Z'}
{'type': 'l2update', 'product_id': 'BTC-USD', 'changes': [['sell', '38282.44', '0.01492000']], 'time': '2021-05-20T03:54:58.277651Z'}
{'type': 'l2update', 'product_id': 'BTC-USD', 'changes': [['sell', '38309.12', '0.00000000']], 'time': '2021-05-20T03:54:58.279649Z'}
{'type': 'l2update', 'product_id': 'BTC-USD', 'changes': [['sell', '38282.58', '0.00000000']], 'time': '2021-05-20T03:54:58.279864Z'}
{'type': 'l2update', 'product_id': 'BTC-USD', 'changes': [['sell', '38417.05', '0.00000000']], 'time': '2021-05-20T03:54:58.279955Z'}
{'type': 'l2update', 'product_id': 'BTC-USD', 'changes': [['buy', '38273.05', '0.00000000']], 'time': '2021-05-20T03:54:58.280020Z'}
{'type': 'l2update', 'product_id': 'BTC-USD', 'changes': [['sell', '38283.02', '0.47369029']], 'time': '2021-05-20T03:54:58.280323Z'}
{'type': 'l2update', 'product_id': 'BTC-USD', 'changes': [['sell', '38281.64', '0.00906738']], 'time': '2021-05-20T03:54:58.280610Z'}
{'type': 'l2update', 'product_id': 'BTC-USD', 'changes': [['buy', '38262.85', '0.52200000']], 'time': '2021-05-20T03:54:58.280736Z'}
{'type': 'l2update', 'product_id': 'BTC-USD', 'changes': [['buy', '38251.65', '0.00000000']], 'time': '2021-05-20T03:54:58.282608Z'}
{'type': 'l2update', 'product_id': 'BTC-USD', 'changes': [['buy', '38273.74', '0.00000000']], 'time': '2021-05-20T03:54:58.283664Z'}
{'type': 'l2update', 'product_id': 'BTC-USD', 'changes': [['buy', '38262.80', '0.11747527']], 'time': '2021-05-20T03:54:58.283966Z'}
{'type': 'l2update', 'product_id': 'BTC-USD', 'changes': [['sell', '38282.44', '0.00000000']], 'time': '2021-05-20T03:54:58.284157Z'}
{'type': 'l2update', 'product_id': 'BTC-USD', 'changes': [['buy', '38235.32', '0.00000000']], 'time': '2021-05-20T03:54:58.287744Z'}
{'type': 'l2update', 'product_id': 'BTC-USD', 'changes': [['sell', '38419.29', '0.00000000']], 'time': '2021-05-20T03:54:58.287902Z'}
{'type': 'l2update', 'product_id': 'BTC-USD', 'changes': [['sell', '38298.77', '0.00000000']], 'time': '2021-05-20T03:54:58.290634Z'}
{'type': 'l2update', 'product_id': 'BTC-USD', 'changes': [['buy', '38258.93', '0.00000000']], 'time': '2021-05-20T03:54:58.291995Z'}
{'type': 'l2update', 'product_id': 'BTC-USD', 'changes': [['sell', '38451.61', '0.01000000']], 'time': '2021-05-20T03:54:58.292175Z'}
{'type': 'l2update', 'product_id': 'BTC-USD', 'changes': [['sell', '38281.64', '0.00000000']], 'time': '2021-05-20T03:54:58.293718Z'}
{'type': 'l2update', 'product_id': 'BTC-USD', 'changes': [['sell', '38302.25', '0.00000000']], 'time': '2021-05-20T03:54:58.294085Z'}
{'type': 'l2update', 'product_id': 'BTC-USD', 'changes': [['buy', '38238.94', '0.03266022']], 'time': '2021-05-20T03:54:58.296518Z'}
{'type': 'l2update', 'product_id': 'BTC-USD', 'changes': [['sell', '38437.76', '0.01279710']], 'time': '2021-05-20T03:54:58.300922Z'}
{'type': 'l2update', 'product_id': 'BTC-USD', 'changes': [['sell', '38304.67', '0.01000000']], 'time': '2021-05-20T03:54:58.305250Z'}
{'type': 'l2update', 'product_id': 'BTC-USD', 'changes': [['buy', '38272.44', '0.05000000']], 'time': '2021-05-20T03:54:58.305545Z'}
{'type': 'l2update', 'product_id': 'BTC-USD', 'changes': [['buy', '38255.92', '0.00000000']], 'time': '2021-05-20T03:54:58.314915Z'}
{'type': 'l2update', 'product_id': 'BTC-USD', 'changes': [['buy', '38251.04', '0.00000000']], 'time': '2021-05-20T03:54:58.317194Z'}
{'type': 'l2update', 'product_id': 'BTC-USD', 'changes': [['sell', '38291.71', '0.00000000']], 'time': '2021-05-20T03:54:58.317194Z'}
{'type': 'l2update', 'product_id': 'BTC-USD', 'changes': [['sell', '38310.02', '0.05000000']], 'time': '2021-05-20T03:54:58.317589Z'}
{'type': 'l2update', 'product_id': 'BTC-USD', 'changes': [['sell', '38510.95', '0.00000000']], 'time': '2021-05-20T03:54:58.325499Z'}
{'type': 'l2update', 'product_id': 'BTC-USD', 'changes': [['buy', '38257.10', '0.44310000']], 'time': '2021-05-20T03:54:58.327551Z'}
{'type': 'l2update', 'product_id': 'BTC-USD', 'changes': [['buy', '38238.94', '0.00000000']], 'time': '2021-05-20T03:54:58.335615Z'}
{'type': 'l2update', 'product_id': 'BTC-USD', 'changes': [['sell', '38287.79', '0.54700000']], 'time': '2021-05-20T03:54:58.336296Z'}
{'type': 'l2update', 'product_id': 'BTC-USD', 'changes': [['sell', '38287.72', '0.00000000']], 'time': '2021-05-20T03:54:58.338398Z'}
{'type': 'l2update', 'product_id': 'BTC-USD', 'changes': [['sell', '38483.20', '0.00649634']], 'time': '2021-05-20T03:54:58.338867Z'}
{'type': 'l2update', 'product_id': 'BTC-USD', 'changes': [['buy', '37500.01', '0.18570000']], 'time': '2021-05-20T03:54:58.339231Z'}
{'type': 'l2update', 'product_id': 'BTC-USD', 'changes': [['sell', '39249.99', '0.00000000']], 'time': '2021-05-20T03:54:58.339231Z'}
{'type': 'l2update', 'product_id': 'BTC-USD', 'changes': [['sell', '38287.79', '0.00000000']], 'time': '2021-05-20T03:54:58.341534Z'}
{'type': 'l2update', 'product_id': 'BTC-USD', 'changes': [['buy', '38262.80', '0.00000000']], 'time': '2021-05-20T03:54:58.344121Z'}
{'type': 'l2update', 'product_id': 'BTC-USD', 'changes': [['buy', '38239.95', '0.03266022']], 'time': '2021-05-20T03:54:58.344339Z'}
{'type': 'l2update', 'product_id': 'BTC-USD', 'changes': [['buy', '37574.43', '0.08380000']], 'time': '2021-05-20T03:54:58.344406Z'}
{'type': 'l2update', 'product_id': 'BTC-USD', 'changes': [['buy', '36963.84', '0.11850000']], 'time': '2021-05-20T03:54:58.344406Z'}
{'type': 'l2update', 'product_id': 'BTC-USD', 'changes': [['sell', '52756.60', '0.00226800']], 'time': '2021-05-20T03:54:58.344954Z'}
{'type': 'l2update', 'product_id': 'BTC-USD', 'changes': [['sell', '39443.99', '0.04210000']], 'time': '2021-05-20T03:54:58.349739Z'}
{'type': 'l2update', 'product_id': 'BTC-USD', 'changes': [['buy', '37500.01', '0.19600000']], 'time': '2021-05-20T03:54:58.349739Z'}
{'type': 'l2update', 'product_id': 'BTC-USD', 'changes': [['buy', '38250.02', '0.06218791']], 'time': '2021-05-20T03:54:58.349882Z'}
{'type': 'l2update', 'product_id': 'BTC-USD', 'changes': [['sell', '38295.35', '0.04100909']], 'time': '2021-05-20T03:54:58.349882Z'}
{'type': 'l2update', 'product_id': 'BTC-USD', 'changes': [['buy', '36500.00', '23.29482195']], 'time': '2021-05-20T03:54:58.353828Z'}
{'type': 'l2update', 'product_id': 'BTC-USD', 'changes': [['buy', '38019.23', '0.00000000']], 'time': '2021-05-20T03:54:58.359896Z'}
{'type': 'l2update', 'product_id': 'BTC-USD', 'changes': [['sell', '38483.20', '0.00000000']], 'time': '2021-05-20T03:54:58.367628Z'}
{'type': 'l2update', 'product_id': 'BTC-USD', 'changes': [['buy', '38272.44', '0.00000000']], 'time': '2021-05-20T03:54:58.368475Z'}
{'type': 'l2update', 'product_id': 'BTC-USD', 'changes': [['buy', '38272.01', '0.10000000']], 'time': '2021-05-20T03:54:58.370115Z'}
{'type': 'l2update', 'product_id': 'BTC-USD', 'changes': [['buy', '38272.02', '0.00000000']], 'time': '2021-05-20T03:54:58.374463Z'}
{'type': 'l2update', 'product_id': 'BTC-USD', 'changes': [['buy', '38267.72', '0.00000000']], 'time': '2021-05-20T03:54:58.378585Z'}
{'type': 'l2update', 'product_id': 'BTC-USD', 'changes': [['buy', '38006.35', '0.08985350']], 'time': '2021-05-20T03:54:58.382035Z'}
{'type': 'l2update', 'product_id': 'BTC-USD', 'changes': [['sell', '38467.89', '0.00649892']], 'time': '2021-05-20T03:54:58.382203Z'}
{'type': 'l2update', 'product_id': 'BTC-USD', 'changes': [['sell', '38295.35', '0.00000000']], 'time': '2021-05-20T03:54:58.384454Z'}
{'type': 'l2update', 'product_id': 'BTC-USD', 'changes': [['buy', '38235.31', '0.00000000']], 'time': '2021-05-20T03:54:58.384883Z'}
{'type': 'l2update', 'product_id': 'BTC-USD', 'changes': [['buy', '38262.86', '0.11747527']], 'time': '2021-05-20T03:54:58.385640Z'}
{'type': 'l2update', 'product_id': 'BTC-USD', 'changes': [['sell', '38370.15', '0.00000000']], 'time': '2021-05-20T03:54:58.392253Z'}
{'type': 'l2update', 'product_id': 'BTC-USD', 'changes': [['buy', '38182.88', '0.00000000']], 'time': '2021-05-20T03:54:58.395114Z'}
{'type': 'l2update', 'product_id': 'BTC-USD', 'changes': [['buy', '38251.83', '0.00000000']], 'time': '2021-05-20T03:54:58.396144Z'}
{'type': 'l2update', 'product_id': 'BTC-USD', 'changes': [['sell', '38295.66', '0.00000000']], 'time': '2021-05-20T03:54:58.396816Z'}
{'type': 'l2update', 'product_id': 'BTC-USD', 'changes': [['buy', '38209.49', '0.00000000']], 'time': '2021-05-20T03:54:58.400409Z'}
{'type': 'l2update', 'product_id': 'BTC-USD', 'changes': [['buy', '38262.84', '0.84800000']], 'time': '2021-05-20T03:54:58.401175Z'}
{'type': 'l2update', 'product_id': 'BTC-USD', 'changes': [['buy', '38194.81', '0.03577500']], 'time': '2021-05-20T03:54:58.410133Z'}
{'type': 'l2update', 'product_id': 'BTC-USD', 'changes': [['sell', '38290.17', '0.00000000']], 'time': '2021-05-20T03:54:58.410771Z'}
{'type': 'l2update', 'product_id': 'BTC-USD', 'changes': [['buy', '38248.56', '0.02400000']], 'time': '2021-05-20T03:54:58.410905Z'}
{'type': 'l2update', 'product_id': 'BTC-USD', 'changes': [['buy', '38262.84', '0.00000000']], 'time': '2021-05-20T03:54:58.411026Z'}
{'type': 'l2update', 'product_id': 'BTC-USD', 'changes': [['buy', '38207.28', '0.00000000']], 'time': '2021-05-20T03:54:58.415546Z'}
{'type': 'l2update', 'product_id': 'BTC-USD', 'changes': [['sell', '38291.45', '0.00000000']], 'time': '2021-05-20T03:54:58.416912Z'}
{'type': 'l2update', 'product_id': 'BTC-USD', 'changes': [['sell', '38302.51', '0.04201003']], 'time': '2021-05-20T03:54:58.424327Z'}
{'type': 'l2update', 'product_id': 'BTC-USD', 'changes': [['sell', '38298.17', '0.04744397']], 'time': '2021-05-20T03:54:58.430300Z'}
{'type': 'l2update', 'product_id': 'BTC-USD', 'changes': [['buy', '38139.14', '0.01000000']], 'time': '2021-05-20T03:54:58.430521Z'}
{'type': 'l2update', 'product_id': 'BTC-USD', 'changes': [['buy', '38250.02', '0.00000000']], 'time': '2021-05-20T03:54:58.435507Z'}
{'type': 'l2update', 'product_id': 'BTC-USD', 'changes': [['sell', '38451.61', '0.00000000']], 'time': '2021-05-20T03:54:58.437051Z'}
{'type': 'l2update', 'product_id': 'BTC-USD', 'changes': [['buy', '38239.94', '0.14433449']], 'time': '2021-05-20T03:54:58.451361Z'}
{'type': 'l2update', 'product_id': 'BTC-USD', 'changes': [['buy', '38250.03', '0.04618490']], 'time': '2021-05-20T03:54:58.451459Z'}
{'type': 'l2update', 'product_id': 'BTC-USD', 'changes': [['sell', '38463.62', '0.01000000']], 'time': '2021-05-20T03:54:58.451490Z'}
{'type': 'l2update', 'product_id': 'BTC-USD', 'changes': [['sell', '38302.51', '0.00000000']], 'time': '2021-05-20T03:54:58.451546Z'}
{'type': 'l2update', 'product_id': 'BTC-USD', 'changes': [['sell', '38467.89', '0.00000000']], 'time': '2021-05-20T03:54:58.451863Z'}
{'type': 'l2update', 'product_id': 'BTC-USD', 'changes': [['buy', '38111.89', '0.00000000']], 'time': '2021-05-20T03:54:58.458122Z'}
{'type': 'l2update', 'product_id': 'BTC-USD', 'changes': [['buy', '38139.14', '0.00000000']], 'time': '2021-05-20T03:54:58.463677Z'}
{'type': 'l2update', 'product_id': 'BTC-USD', 'changes': [['sell', '38298.17', '0.00000000']], 'time': '2021-05-20T03:54:58.465572Z'}
{'type': 'l2update', 'product_id': 'BTC-USD', 'changes': [['sell', '38409.09', '0.00000000']], 'time': '2021-05-20T03:54:58.470273Z'}
{'type': 'l2update', 'product_id': 'BTC-USD', 'changes': [['sell', '38308.47', '0.00000000']], 'time': '2021-05-20T03:54:58.475009Z'}
{'type': 'l2update', 'product_id': 'BTC-USD', 'changes': [['buy', '38151.33', '0.01000000']], 'time': '2021-05-20T03:54:58.479368Z'}
{'type': 'l2update', 'product_id': 'BTC-USD', 'changes': [['sell', '38297.57', '0.04201003']], 'time': '2021-05-20T03:54:58.479532Z'}
{'type': 'l2update', 'product_id': 'BTC-USD', 'changes': [['sell', '38397.45', '0.01000000']], 'time': '2021-05-20T03:54:58.481866Z'}
{'type': 'l2update', 'product_id': 'BTC-USD', 'changes': [['sell', '38305.96', '0.49200000']], 'time': '2021-05-20T03:54:58.486358Z'}
{'type': 'l2update', 'product_id': 'BTC-USD', 'changes': [['buy', '38214.62', '0.00000000']], 'time': '2021-05-20T03:54:58.490168Z'}
{'type': 'l2update', 'product_id': 'BTC-USD', 'changes': [['sell', '38305.96', '0.00000000']], 'time': '2021-05-20T03:54:58.491442Z'}
{'type': 'l2update', 'product_id': 'BTC-USD', 'changes': [['sell', '38292.94', '0.04201003']], 'time': '2021-05-20T03:54:58.498360Z'}
{'type': 'l2update', 'product_id': 'BTC-USD', 'changes': [['buy', '38218.32', '1.28341683']], 'time': '2021-05-20T03:54:58.508929Z'}
{'type': 'l2update', 'product_id': 'BTC-USD', 'changes': [['sell', '38290.70', '0.04865121']], 'time': '2021-05-20T03:54:58.509207Z'}
{'type': 'l2update', 'product_id': 'BTC-USD', 'changes': [['sell', '38297.57', '0.00000000']], 'time': '2021-05-20T03:54:58.514004Z'}
{'type': 'l2update', 'product_id': 'BTC-USD', 'changes': [['buy', '38151.33', '0.00000000']], 'time': '2021-05-20T03:54:58.523429Z'}
{'type': 'l2update', 'product_id': 'BTC-USD', 'changes': [['buy', '38257.10', '0.00000000']], 'time': '2021-05-20T03:54:58.524811Z'}
{'type': 'l2update', 'product_id': 'BTC-USD', 'changes': [['sell', '38317.68', '0.00000000']], 'time': '2021-05-20T03:54:58.531093Z'}
{'type': 'l2update', 'product_id': 'BTC-USD', 'changes': [['sell', '52760.37', '0.00183600']], 'time': '2021-05-20T03:54:58.535902Z'}
{'type': 'l2update', 'product_id': 'BTC-USD', 'changes': [['buy', '38255.47', '0.41950000']], 'time': '2021-05-20T03:54:58.536056Z'}
{'type': 'l2update', 'product_id': 'BTC-USD', 'changes': [['buy', '38163.69', '0.01000000']], 'time': '2021-05-20T03:54:58.536079Z'}
{'type': 'l2update', 'product_id': 'BTC-USD', 'changes': [['sell', '38341.09', '0.02608168']], 'time': '2021-05-20T03:54:58.540579Z'}
{'type': 'l2update', 'product_id': 'BTC-USD', 'changes': [['sell', '38282.97', '0.54700000']], 'time': '2021-05-20T03:54:58.555901Z'}
{'type': 'l2update', 'product_id': 'BTC-USD', 'changes': [['buy', '38235.31', '1.20000000']], 'time': '2021-05-20T03:54:58.556007Z'}
{'type': 'l2update', 'product_id': 'BTC-USD', 'changes': [['sell', '38283.02', '0.00000000']], 'time': '2021-05-20T03:54:58.563343Z'}
{'type': 'l2update', 'product_id': 'BTC-USD', 'changes': [['sell', '38370.15', '1.20000000']], 'time': '2021-05-20T03:54:58.567040Z'}
{'type': 'l2update', 'product_id': 'BTC-USD', 'changes': [['buy', '38104.69', '0.04925402']], 'time': '2021-05-20T03:54:58.578885Z'}
{'type': 'l2update', 'product_id': 'BTC-USD', 'changes': [['sell', '38302.36', '0.04994390']], 'time': '2021-05-20T03:54:58.579252Z'}
{'type': 'l2update', 'product_id': 'BTC-USD', 'changes': [['sell', '38303.73', '0.47090000']], 'time': '2021-05-20T03:54:58.583608Z'}
{'type': 'l2update', 'product_id': 'BTC-USD', 'changes': [['sell', '38282.96', '0.47369029']], 'time': '2021-05-20T03:54:58.587016Z'}
{'type': 'l2update', 'product_id': 'BTC-USD', 'changes': [['buy', '38235.31', '0.00000000']], 'time': '2021-05-20T03:54:58.598552Z'}
{'type': 'l2update', 'product_id': 'BTC-USD', 'changes': [['sell', '38370.15', '0.00000000']], 'time': '2021-05-20T03:54:58.602337Z'}
{'type': 'l2update', 'product_id': 'BTC-USD', 'changes': [['buy', '38163.69', '0.00000000']], 'time': '2021-05-20T03:54:58.604037Z'}
{'type': 'l2update', 'product_id': 'BTC-USD', 'changes': [['buy', '38255.47', '0.00000000']], 'time': '2021-05-20T03:54:58.605081Z'}
{'type': 'l2update', 'product_id': 'BTC-USD', 'changes': [['buy', '38144.67', '0.01000000']], 'time': '2021-05-20T03:54:58.617134Z'}
{'type': 'l2update', 'product_id': 'BTC-USD', 'changes': [['buy', '38216.43', '0.05453690']], 'time': '2021-05-20T03:54:58.628243Z'}
{'type': 'l2update', 'product_id': 'BTC-USD', 'changes': [['buy', '38219.13', '0.02726845']], 'time': '2021-05-20T03:54:58.632161Z'}
{'type': 'l2update', 'product_id': 'BTC-USD', 'changes': [['buy', '38144.67', '0.00000000']], 'time': '2021-05-20T03:54:58.639784Z'}
{'type': 'l2update', 'product_id': 'BTC-USD', 'changes': [['buy', '38160.84', '0.01000000']], 'time': '2021-05-20T03:54:58.651408Z'}
{'type': 'l2update', 'product_id': 'BTC-USD', 'changes': [['buy', '38160.84', '0.00000000']], 'time': '2021-05-20T03:54:58.664750Z'}
{'type': 'l2update', 'product_id': 'BTC-USD', 'changes': [['buy', '38161.79', '0.01000000']], 'time': '2021-05-20T03:54:58.680191Z'}
{'type': 'l2update', 'product_id': 'BTC-USD', 'changes': [['sell', '38290.70', '0.00000000']], 'time': '2021-05-20T03:54:58.686329Z'}
{'type': 'l2update', 'product_id': 'BTC-USD', 'changes': [['buy', '38262.91', '0.84800000']], 'time': '2021-05-20T03:54:58.688798Z'}
{'type': 'l2update', 'product_id': 'BTC-USD', 'changes': [['sell', '38282.97', '0.00000000']], 'time': '2021-05-20T03:54:58.696084Z'}
{'type': 'l2update', 'product_id': 'BTC-USD', 'changes': [['buy', '38262.86', '0.00000000']], 'time': '2021-05-20T03:54:58.697015Z'}
{'type': 'l2update', 'product_id': 'BTC-USD', 'changes': [['buy', '38254.01', '0.44890000']], 'time': '2021-05-20T03:54:58.697059Z'}
{'type': 'l2update', 'product_id': 'BTC-USD', 'changes': [['sell', '52767.92', '0.00263200']], 'time': '2021-05-20T03:54:58.710490Z'}
{'type': 'l2update', 'product_id': 'BTC-USD', 'changes': [['sell', '38297.52', '0.05916465']], 'time': '2021-05-20T03:54:58.717983Z'}
{'type': 'l2update', 'product_id': 'BTC-USD', 'changes': [['buy', '38262.92', '0.11747527']], 'time': '2021-05-20T03:54:58.718073Z'}
{'type': 'l2update', 'product_id': 'BTC-USD', 'changes': [['buy', '38161.79', '0.00000000']], 'time': '2021-05-20T03:54:58.721089Z'}
{'type': 'l2update', 'product_id': 'BTC-USD', 'changes': [['sell', '38310.02', '0.00000000']], 'time': '2021-05-20T03:54:58.725409Z'}
{'type': 'l2update', 'product_id': 'BTC-USD', 'changes': [['buy', '38272.01', '0.09000000']], 'time': '2021-05-20T03:54:58.728780Z'}
{'type': 'l2update', 'product_id': 'BTC-USD', 'changes': [['buy', '38272.43', '0.03000000']], 'time': '2021-05-20T03:54:58.732027Z'}
{'type': 'l2update', 'product_id': 'BTC-USD', 'changes': [['buy', '38250.03', '0.05973437']], 'time': '2021-05-20T03:54:58.733546Z'}
{'type': 'l2update', 'product_id': 'BTC-USD', 'changes': [['buy', '38272.43', '0.00000000']], 'time': '2021-05-20T03:54:58.735490Z'}
{'type': 'l2update', 'product_id': 'BTC-USD', 'changes': [['sell', '38303.73', '0.00000000']], 'time': '2021-05-20T03:54:58.738501Z'}
{'type': 'l2update', 'product_id': 'BTC-USD', 'changes': [['buy', '38272.01', '0.05000000']], 'time': '2021-05-20T03:54:58.739260Z'}
{'type': 'l2update', 'product_id': 'BTC-USD', 'changes': [['buy', '38272.01', '0.00000000']], 'time': '2021-05-20T03:54:58.743330Z'}
{'type': 'l2update', 'product_id': 'BTC-USD', 'changes': [['sell', '38305.10', '0.49900000']], 'time': '2021-05-20T03:54:58.749954Z'}
{'type': 'l2update', 'product_id': 'BTC-USD', 'changes': [['sell', '38297.52', '0.00000000']], 'time': '2021-05-20T03:54:58.750125Z'}
{'type': 'l2update', 'product_id': 'BTC-USD', 'changes': [['sell', '38302.22', '0.05000000']], 'time': '2021-05-20T03:54:58.754190Z'}
{'type': 'l2update', 'product_id': 'BTC-USD', 'changes': [['sell', '38463.62', '0.00000000']], 'time': '2021-05-20T03:54:58.757464Z'}
{'type': 'l2update', 'product_id': 'BTC-USD', 'changes': [['buy', '38245.49', '2.37600000']], 'time': '2021-05-20T03:54:58.762239Z'}
{'type': 'l2update', 'product_id': 'BTC-USD', 'changes': [['sell', '38302.36', '0.00000000']], 'time': '2021-05-20T03:54:58.762861Z'}
{'type': 'l2update', 'product_id': 'BTC-USD', 'changes': [['buy', '38261.89', '0.01000000']], 'time': '2021-05-20T03:54:58.766082Z'}
{'type': 'l2update', 'product_id': 'BTC-USD', 'changes': [['sell', '38493.20', '0.01000000']], 'time': '2021-05-20T03:54:58.770608Z'}
{'type': 'l2update', 'product_id': 'BTC-USD', 'changes': [['buy', '38261.79', '0.02000000']], 'time': '2021-05-20T03:54:58.774435Z'}
{'type': 'l2update', 'product_id': 'BTC-USD', 'changes': [['sell', '38380.32', '0.02400000']], 'time': '2021-05-20T03:54:58.774468Z'}
{'type': 'l2update', 'product_id': 'BTC-USD', 'changes': [['sell', '38296.80', '0.03976702']], 'time': '2021-05-20T03:54:58.774577Z'}
{'type': 'l2update', 'product_id': 'BTC-USD', 'changes': [['buy', '38261.79', '0.05000000']], 'time': '2021-05-20T03:54:58.786504Z'}
{'type': 'l2update', 'product_id': 'BTC-USD', 'changes': [['buy', '38250.03', '0.04618490']], 'time': '2021-05-20T03:54:58.787695Z'}
{'type': 'l2update', 'product_id': 'BTC-USD', 'changes': [['buy', '38250.03', '0.00000000']], 'time': '2021-05-20T03:54:58.787695Z'}
{'type': 'l2update', 'product_id': 'BTC-USD', 'changes': [['buy', '38261.79', '0.09000000']], 'time': '2021-05-20T03:54:58.795785Z'}
{'type': 'l2update', 'product_id': 'BTC-USD', 'changes': [['buy', '38113.67', '0.05183718']], 'time': '2021-05-20T03:54:58.795976Z'}
{'type': 'l2update', 'product_id': 'BTC-USD', 'changes': [['buy', '38261.79', '0.14000000']], 'time': '2021-05-20T03:54:58.806580Z'}
{'type': 'l2update', 'product_id': 'BTC-USD', 'changes': [['buy', '38267.72', '0.84800000']], 'time': '2021-05-20T03:54:58.842613Z'}
{'type': 'l2update', 'product_id': 'BTC-USD', 'changes': [['sell', '38296.80', '0.00000000']], 'time': '2021-05-20T03:54:58.844608Z'}
{'type': 'l2update', 'product_id': 'BTC-USD', 'changes': [['buy', '38214.53', '0.00000000']], 'time': '2021-05-20T03:54:58.851789Z'}
{'type': 'l2update', 'product_id': 'BTC-USD', 'changes': [['buy', '38198.19', '0.00000000']], 'time': '2021-05-20T03:54:58.852731Z'}
{'type': 'l2update', 'product_id': 'BTC-USD', 'changes': [['sell', '38292.94', '0.00000000']], 'time': '2021-05-20T03:54:58.853920Z'}
{'type': 'l2update', 'product_id': 'BTC-USD', 'changes': [['sell', '38321.26', '0.00000000']], 'time': '2021-05-20T03:54:58.857635Z'}
{'type': 'l2update', 'product_id': 'BTC-USD', 'changes': [['buy', '38104.69', '0.00000000']], 'time': '2021-05-20T03:54:58.858109Z'}
{'type': 'l2update', 'product_id': 'BTC-USD', 'changes': [['sell', '38283.03', '0.00000000']], 'time': '2021-05-20T03:54:58.860808Z'}
{'type': 'l2update', 'product_id': 'BTC-USD', 'changes': [['sell', '38493.20', '0.00000000']], 'time': '2021-05-20T03:54:58.862882Z'}
{'type': 'l2update', 'product_id': 'BTC-USD', 'changes': [['buy', '38276.02', '0.05019989']], 'time': '2021-05-20T03:54:58.866287Z'}
{'type': 'l2update', 'product_id': 'BTC-USD', 'changes': [['sell', '52779.23', '0.00223400']], 'time': '2021-05-20T03:54:58.866566Z'}
{'type': 'l2update', 'product_id': 'BTC-USD', 'changes': [['sell', '38282.96', '0.00000000']], 'time': '2021-05-20T03:54:58.867261Z'}
{'type': 'l2update', 'product_id': 'BTC-USD', 'changes': [['sell', '38283.04', '0.00000000']], 'time': '2021-05-20T03:54:58.875343Z'}
{'type': 'l2update', 'product_id': 'BTC-USD', 'changes': [['sell', '38324.89', '0.00000000']], 'time': '2021-05-20T03:54:58.875636Z'}
{'type': 'l2update', 'product_id': 'BTC-USD', 'changes': [['buy', '38272.00', '0.00000000']], 'time': '2021-05-20T03:54:58.876181Z'}
{'type': 'l2update', 'product_id': 'BTC-USD', 'changes': [['sell', '38298.87', '0.04201003']], 'time': '2021-05-20T03:54:58.879723Z'}
{'type': 'l2update', 'product_id': 'BTC-USD', 'changes': [['buy', '38269.57', '0.18300000']], 'time': '2021-05-20T03:54:58.881614Z'}
{'type': 'l2update', 'product_id': 'BTC-USD', 'changes': [['buy', '38262.92', '0.00000000']], 'time': '2021-05-20T03:54:58.881646Z'}
{'type': 'l2update', 'product_id': 'BTC-USD', 'changes': [['sell', '38286.74', '2.48969908']], 'time': '2021-05-20T03:54:58.881666Z'}
{'type': 'l2update', 'product_id': 'BTC-USD', 'changes': [['sell', '38288.65', '0.00000000']], 'time': '2021-05-20T03:54:58.884724Z'}
{'type': 'l2update', 'product_id': 'BTC-USD', 'changes': [['buy', '38271.88', '0.00000000']], 'time': '2021-05-20T03:54:58.884971Z'}
{'type': 'l2update', 'product_id': 'BTC-USD', 'changes': [['sell', '38501.38', '0.01000000']], 'time': '2021-05-20T03:54:58.887231Z'}
{'type': 'l2update', 'product_id': 'BTC-USD', 'changes': [['sell', '38291.49', '0.47369029']], 'time': '2021-05-20T03:54:58.890506Z'}
{'type': 'l2update', 'product_id': 'BTC-USD', 'changes': [['sell', '38286.74', '2.98969908']], 'time': '2021-05-20T03:54:58.890560Z'}
{'type': 'l2update', 'product_id': 'BTC-USD', 'changes': [['sell', '38480.10', '0.01000000']], 'time': '2021-05-20T03:54:58.890662Z'}
{'type': 'l2update', 'product_id': 'BTC-USD', 'changes': [['sell', '38292.17', '0.04201003']], 'time': '2021-05-20T03:54:58.894080Z'}
{'type': 'l2update', 'product_id': 'BTC-USD', 'changes': [['buy', '38194.81', '0.00000000']], 'time': '2021-05-20T03:54:58.896580Z'}
{'type': 'l2update', 'product_id': 'BTC-USD', 'changes': [['sell', '38298.87', '0.00000000']], 'time': '2021-05-20T03:54:58.901448Z'}
{'type': 'l2update', 'product_id': 'BTC-USD', 'changes': [['buy', '38262.92', '0.11747527']], 'time': '2021-05-20T03:54:58.901884Z'}
{'type': 'l2update', 'product_id': 'BTC-USD', 'changes': [['buy', '38207.37', '0.03577500']], 'time': '2021-05-20T03:54:58.906050Z'}
{'type': 'l2update', 'product_id': 'BTC-USD', 'changes': [['sell', '38294.61', '0.05045313']], 'time': '2021-05-20T03:54:58.909986Z'}
{'type': 'l2update', 'product_id': 'BTC-USD', 'changes': [['sell', '38283.10', '0.52024686']], 'time': '2021-05-20T03:54:58.913829Z'}
{'type': 'l2update', 'product_id': 'BTC-USD', 'changes': [['sell', '38700.00', '0.32784407']], 'time': '2021-05-20T03:54:58.915073Z'}
{'type': 'l2update', 'product_id': 'BTC-USD', 'changes': [['buy', '38267.50', '0.52262168']], 'time': '2021-05-20T03:54:58.929349Z'}
{'type': 'l2update', 'product_id': 'BTC-USD', 'changes': [['sell', '38305.10', '0.00000000']], 'time': '2021-05-20T03:54:58.933273Z'}
{'type': 'l2update', 'product_id': 'BTC-USD', 'changes': [['sell', '38292.17', '0.00000000']], 'time': '2021-05-20T03:54:58.933837Z'}
{'type': 'l2update', 'product_id': 'BTC-USD', 'changes': [['buy', '38265.05', '0.52265328']], 'time': '2021-05-20T03:54:58.940845Z'}
{'type': 'l2update', 'product_id': 'BTC-USD', 'changes': [['buy', '38195.04', '0.32361428']], 'time': '2021-05-20T03:54:58.944496Z'}
{'type': 'l2update', 'product_id': 'BTC-USD', 'changes': [['sell', '38306.38', '0.46890000']], 'time': '2021-05-20T03:54:58.944753Z'}
{'type': 'l2update', 'product_id': 'BTC-USD', 'changes': [['sell', '38291.49', '0.00000000']], 'time': '2021-05-20T03:54:58.946970Z'}
{'type': 'l2update', 'product_id': 'BTC-USD', 'changes': [['buy', '38262.92', '0.00000000']], 'time': '2021-05-20T03:54:58.950148Z'}
{'type': 'l2update', 'product_id': 'BTC-USD', 'changes': [['buy', '38164.41', '0.32984273']], 'time': '2021-05-20T03:54:58.950944Z'}
{'type': 'l2update', 'product_id': 'BTC-USD', 'changes': [['buy', '38251.07', '0.78395634']], 'time': '2021-05-20T03:54:58.952574Z'}
{'type': 'l2update', 'product_id': 'BTC-USD', 'changes': [['sell', '38396.22', '0.00000000']], 'time': '2021-05-20T03:54:58.953316Z'}
{'type': 'l2update', 'product_id': 'BTC-USD', 'changes': [['buy', '38243.44', '1.30659389']], 'time': '2021-05-20T03:54:58.962490Z'}
{'type': 'l2update', 'product_id': 'BTC-USD', 'changes': [['sell', '38286.73', '0.47369029']], 'time': '2021-05-20T03:54:58.965975Z'}
{'type': 'l2update', 'product_id': 'BTC-USD', 'changes': [['buy', '38267.73', '0.11747527']], 'time': '2021-05-20T03:54:58.968980Z'}
{'type': 'l2update', 'product_id': 'BTC-USD', 'changes': [['sell', '38298.47', '0.04201003']], 'time': '2021-05-20T03:54:58.969122Z'}
{'type': 'l2update', 'product_id': 'BTC-USD', 'changes': [['buy', '38234.39', '2.61326636']], 'time': '2021-05-20T03:54:58.973029Z'}
{'type': 'l2update', 'product_id': 'BTC-USD', 'changes': [['sell', '38415.34', '0.01000000']], 'time': '2021-05-20T03:54:58.973225Z'}
{'type': 'l2update', 'product_id': 'BTC-USD', 'changes': [['sell', '38291.45', '1.02200000']], 'time': '2021-05-20T03:54:58.976874Z'}
{'type': 'l2update', 'product_id': 'BTC-USD', 'changes': [['buy', '38233.86', '2.61326636']], 'time': '2021-05-20T03:54:58.985152Z'}
{'type': 'l2update', 'product_id': 'BTC-USD', 'changes': [['sell', '38293.07', '0.04201003']], 'time': '2021-05-20T03:54:58.989085Z'}
{'type': 'l2update', 'product_id': 'BTC-USD', 'changes': [['sell', '38286.74', '2.48969908']], 'time': '2021-05-20T03:54:58.991371Z'}
{'type': 'l2update', 'product_id': 'BTC-USD', 'changes': [['sell', '38298.47', '0.00000000']], 'time': '2021-05-20T03:54:58.996926Z'}
{'type': 'l2update', 'product_id': 'BTC-USD', 'changes': [['buy', '38160.00', '0.19720000']], 'time': '2021-05-20T03:54:59.000786Z'}
{'type': 'l2update', 'product_id': 'BTC-USD', 'changes': [['buy', '38249.72', '0.00000000']], 'time': '2021-05-20T03:54:59.001535Z'}
{'type': 'l2update', 'product_id': 'BTC-USD', 'changes': [['buy', '38248.56', '0.00000000']], 'time': '2021-05-20T03:54:59.001535Z'}
{'type': 'l2update', 'product_id': 'BTC-USD', 'changes': [['sell', '38322.95', '0.00000000']], 'time': '2021-05-20T03:54:59.003186Z'}
{'type': 'l2update', 'product_id': 'BTC-USD', 'changes': [['buy', '38250.76', '0.00000000']], 'time': '2021-05-20T03:54:59.006722Z'}
{'type': 'l2update', 'product_id': 'BTC-USD', 'changes': [['sell', '38283.09', '0.50000000']], 'time': '2021-05-20T03:54:59.007750Z'}
{'type': 'l2update', 'product_id': 'BTC-USD', 'changes': [['sell', '38286.73', '0.00000000']], 'time': '2021-05-20T03:54:59.016059Z'}
{'type': 'l2update', 'product_id': 'BTC-USD', 'changes': [['buy', '38255.89', '0.02400000']], 'time': '2021-05-20T03:54:59.021057Z'}
{'type': 'l2update', 'product_id': 'BTC-USD', 'changes': [['buy', '38255.08', '0.02400000']], 'time': '2021-05-20T03:54:59.021057Z'}
{'type': 'l2update', 'product_id': 'BTC-USD', 'changes': [['buy', '38254.28', '0.02400000']], 'time': '2021-05-20T03:54:59.021057Z'}
{'type': 'l2update', 'product_id': 'BTC-USD', 'changes': [['sell', '38286.74', '0.00000000']], 'time': '2021-05-20T03:54:59.024552Z'}
{'type': 'l2update', 'product_id': 'BTC-USD', 'changes': [['buy', '38255.08', '0.00000000']], 'time': '2021-05-20T03:54:59.027911Z'}
{'type': 'l2update', 'product_id': 'BTC-USD', 'changes': [['buy', '38254.28', '0.00000000']], 'time': '2021-05-20T03:54:59.027911Z'}
{'type': 'l2update', 'product_id': 'BTC-USD', 'changes': [['buy', '38255.89', '0.00000000']], 'time': '2021-05-20T03:54:59.031695Z'}
{'type': 'l2update', 'product_id': 'BTC-USD', 'changes': [['sell', '38283.08', '0.47369029']], 'time': '2021-05-20T03:54:59.035409Z'}
{'type': 'l2update', 'product_id': 'BTC-USD', 'changes': [['sell', '52794.31', '0.00220000']], 'time': '2021-05-20T03:54:59.035561Z'}
{'type': 'l2update', 'product_id': 'BTC-USD', 'changes': [['sell', '38283.09', '0.00000000']], 'time': '2021-05-20T03:54:59.037201Z'}
{'type': 'l2update', 'product_id': 'BTC-USD', 'changes': [['sell', '38287.83', '2.48969908']], 'time': '2021-05-20T03:54:59.042851Z'}
{'type': 'l2update', 'product_id': 'BTC-USD', 'changes': [['sell', '38293.07', '0.00000000']], 'time': '2021-05-20T03:54:59.043307Z'}
{'type': 'l2update', 'product_id': 'BTC-USD', 'changes': [['buy', '38160.84', '0.01000000']], 'time': '2021-05-20T03:54:59.050842Z'}
{'type': 'l2update', 'product_id': 'BTC-USD', 'changes': [['buy', '38264.92', '0.02400000']], 'time': '2021-05-20T03:54:59.050889Z'}
{'type': 'l2update', 'product_id': 'BTC-USD', 'changes': [['buy', '38264.11', '0.02400000']], 'time': '2021-05-20T03:54:59.050889Z'}
{'type': 'l2update', 'product_id': 'BTC-USD', 'changes': [['buy', '38263.31', '0.02400000']], 'time': '2021-05-20T03:54:59.050889Z'}
{'type': 'l2update', 'product_id': 'BTC-USD', 'changes': [['sell', '38286.74', '0.50000000']], 'time': '2021-05-20T03:54:59.050961Z'}
{'type': 'l2update', 'product_id': 'BTC-USD', 'changes': [['buy', '38264.92', '0.00000000']], 'time': '2021-05-20T03:54:59.056917Z'}
{'type': 'l2update', 'product_id': 'BTC-USD', 'changes': [['buy', '38264.11', '0.00000000']], 'time': '2021-05-20T03:54:59.056917Z'}
{'type': 'l2update', 'product_id': 'BTC-USD', 'changes': [['buy', '38263.31', '0.00000000']], 'time': '2021-05-20T03:54:59.056917Z'}
{'type': 'l2update', 'product_id': 'BTC-USD', 'changes': [['sell', '38310.91', '0.04873709']], 'time': '2021-05-20T03:54:59.062683Z'}
{'type': 'l2update', 'product_id': 'BTC-USD', 'changes': [['sell', '38298.84', '0.04201003']], 'time': '2021-05-20T03:54:59.076255Z'}
{'type': 'l2update', 'product_id': 'BTC-USD', 'changes': [['buy', '38265.10', '0.52200000']], 'time': '2021-05-20T03:54:59.080169Z'}
{'type': 'l2update', 'product_id': 'BTC-USD', 'changes': [['sell', '38283.08', '0.00000000']], 'time': '2021-05-20T03:54:59.086068Z'}
{'type': 'l2update', 'product_id': 'BTC-USD', 'changes': [['buy', '38283.08', '0.00200844']], 'time': '2021-05-20T03:54:59.096163Z'}
{'type': 'l2update', 'product_id': 'BTC-USD', 'changes': [['sell', '38286.73', '0.47369029']], 'time': '2021-05-20T03:54:59.103224Z'}
{'type': 'l2update', 'product_id': 'BTC-USD', 'changes': [['sell', '38298.84', '0.00000000']], 'time': '2021-05-20T03:54:59.104588Z'}
{'type': 'l2update', 'product_id': 'BTC-USD', 'changes': [['buy', '38239.95', '0.00000000']], 'time': '2021-05-20T03:54:59.104789Z'}
{'type': 'l2update', 'product_id': 'BTC-USD', 'changes': [['sell', '38297.10', '0.00000000']], 'time': '2021-05-20T03:54:59.106675Z'}
{'type': 'l2update', 'product_id': 'BTC-USD', 'changes': [['buy', '38283.08', '0.00000000']], 'time': '2021-05-20T03:54:59.108566Z'}
{'type': 'l2update', 'product_id': 'BTC-USD', 'changes': [['buy', '38276.02', '0.03966965']], 'time': '2021-05-20T03:54:59.108566Z'}
{'type': 'l2update', 'product_id': 'BTC-USD', 'changes': [['sell', '38520.00', '0.19720000']], 'time': '2021-05-20T03:54:59.108802Z'}
{'type': 'l2update', 'product_id': 'BTC-USD', 'changes': [['sell', '38283.09', '0.10000000']], 'time': '2021-05-20T03:54:59.111693Z'}
{'type': 'l2update', 'product_id': 'BTC-USD', 'changes': [['buy', '38261.94', '0.02400000']], 'time': '2021-05-20T03:54:59.115678Z'}
{'type': 'l2update', 'product_id': 'BTC-USD', 'changes': [['buy', '38261.14', '0.02400000']], 'time': '2021-05-20T03:54:59.115678Z'}
{'type': 'l2update', 'product_id': 'BTC-USD', 'changes': [['buy', '38260.33', '0.02400000']], 'time': '2021-05-20T03:54:59.115678Z'}
{'type': 'l2update', 'product_id': 'BTC-USD', 'changes': [['buy', '38243.45', '0.03308025']], 'time': '2021-05-20T03:54:59.115698Z'}
{'type': 'l2update', 'product_id': 'BTC-USD', 'changes': [['sell', '38480.10', '0.00000000']], 'time': '2021-05-20T03:54:59.116628Z'}
{'type': 'l2update', 'product_id': 'BTC-USD', 'changes': [['sell', '38306.37', '0.05000000']], 'time': '2021-05-20T03:54:59.119382Z'}
{'type': 'l2update', 'product_id': 'BTC-USD', 'changes': [['buy', '38269.57', '0.00000000']], 'time': '2021-05-20T03:54:59.121617Z'}
{'type': 'l2update', 'product_id': 'BTC-USD', 'changes': [['sell', '38306.37', '0.00000000']], 'time': '2021-05-20T03:54:59.123904Z'}
{'type': 'l2update', 'product_id': 'BTC-USD', 'changes': [['sell', '38283.09', '0.30000000']], 'time': '2021-05-20T03:54:59.124967Z'}
{'type': 'l2update', 'product_id': 'BTC-USD', 'changes': [['buy', '37478.95', '0.02090000']], 'time': '2021-05-20T03:54:59.125133Z'}
{'type': 'l2update', 'product_id': 'BTC-USD', 'changes': [['buy', '36775.13', '0.02960000']], 'time': '2021-05-20T03:54:59.125133Z'}
{'type': 'l2update', 'product_id': 'BTC-USD', 'changes': [['buy', '38243.45', '0.00000000']], 'time': '2021-05-20T03:54:59.125316Z'}
{'type': 'l2update', 'product_id': 'BTC-USD', 'changes': [['buy', '38277.08', '0.00839673']], 'time': '2021-05-20T03:54:59.127947Z'}
{'type': 'l2update', 'product_id': 'BTC-USD', 'changes': [['sell', '38286.75', '0.00000000']], 'time': '2021-05-20T03:54:59.130760Z'}
{'type': 'l2update', 'product_id': 'BTC-USD', 'changes': [['buy', '38239.95', '0.03308025']], 'time': '2021-05-20T03:54:59.131368Z'}
{'type': 'l2update', 'product_id': 'BTC-USD', 'changes': [['sell', '38303.18', '0.05000000']], 'time': '2021-05-20T03:54:59.131382Z'}
{'type': 'l2update', 'product_id': 'BTC-USD', 'changes': [['sell', '38293.66', '0.04201003']], 'time': '2021-05-20T03:54:59.131432Z'}
{'type': 'l2update', 'product_id': 'BTC-USD', 'changes': [['buy', '38257.84', '0.00000000']], 'time': '2021-05-20T03:54:59.135822Z'}
{'type': 'l2update', 'product_id': 'BTC-USD', 'changes': [['sell', '39234.16', '0.00000000']], 'time': '2021-05-20T03:54:59.145998Z'}
{'type': 'l2update', 'product_id': 'BTC-USD', 'changes': [['sell', '39235.47', '0.00000000']], 'time': '2021-05-20T03:54:59.145998Z'}
{'type': 'l2update', 'product_id': 'BTC-USD', 'changes': [['sell', '39236.99', '0.00000000']], 'time': '2021-05-20T03:54:59.145998Z'}
{'type': 'l2update', 'product_id': 'BTC-USD', 'changes': [['sell', '38298.89', '0.04201003']], 'time': '2021-05-20T03:54:59.147049Z'}
{'type': 'l2update', 'product_id': 'BTC-USD', 'changes': [['buy', '38262.79', '0.00000000']], 'time': '2021-05-20T03:54:59.151004Z'}
{'type': 'l2update', 'product_id': 'BTC-USD', 'changes': [['sell', '39248.48', '0.06190000']], 'time': '2021-05-20T03:54:59.155384Z'}
{'type': 'l2update', 'product_id': 'BTC-USD', 'changes': [['sell', '39499.99', '0.05080000']], 'time': '2021-05-20T03:54:59.155384Z'}
{'type': 'l2update', 'product_id': 'BTC-USD', 'changes': [['sell', '39249.99', '0.01520000']], 'time': '2021-05-20T03:54:59.155384Z'}
{'type': 'l2update', 'product_id': 'BTC-USD', 'changes': [['sell', '38293.66', '0.00000000']], 'time': '2021-05-20T03:54:59.156460Z'}
{'type': 'l2update', 'product_id': 'BTC-USD', 'changes': [['sell', '38441.36', '0.01000000']], 'time': '2021-05-20T03:54:59.159414Z'}
{'type': 'l2update', 'product_id': 'BTC-USD', 'changes': [['buy', '38269.58', '0.58716278']], 'time': '2021-05-20T03:54:59.163126Z'}
{'type': 'l2update', 'product_id': 'BTC-USD', 'changes': [['buy', '38245.49', '0.00000000']], 'time': '2021-05-20T03:54:59.165937Z'}
{'type': 'l2update', 'product_id': 'BTC-USD', 'changes': [['sell', '38380.32', '0.00000000']], 'time': '2021-05-20T03:54:59.169493Z'}
{'type': 'l2update', 'product_id': 'BTC-USD', 'changes': [['buy', '17951.00', '0.00000000']], 'time': '2021-05-20T03:54:59.176289Z'}
{'type': 'l2update', 'product_id': 'BTC-USD', 'changes': [['sell', '38441.36', '0.00000000']], 'time': '2021-05-20T03:54:59.178503Z'}
{'type': 'l2update', 'product_id': 'BTC-USD', 'changes': [['buy', '37600.37', '0.00000000']], 'time': '2021-05-20T03:54:59.184399Z'}
{'type': 'l2update', 'product_id': 'BTC-USD', 'changes': [['sell', '38283.10', '0.00000000']], 'time': '2021-05-20T03:54:59.184977Z'}
{'type': 'l2update', 'product_id': 'BTC-USD', 'changes': [['sell', '38458.93', '0.01000000']], 'time': '2021-05-20T03:54:59.191090Z'}
{'type': 'l2update', 'product_id': 'BTC-USD', 'changes': [['sell', '38298.89', '0.00000000']], 'time': '2021-05-20T03:54:59.196606Z'}
{'type': 'l2update', 'product_id': 'BTC-USD', 'changes': [['sell', '38302.22', '0.00000000']], 'time': '2021-05-20T03:54:59.203082Z'}
{'type': 'l2update', 'product_id': 'BTC-USD', 'changes': [['sell', '38391.42', '0.00000000']], 'time': '2021-05-20T03:54:59.204580Z'}
{'type': 'l2update', 'product_id': 'BTC-USD', 'changes': [['buy', '38269.58', '0.00000000']], 'time': '2021-05-20T03:54:59.206286Z'}
{'type': 'l2update', 'product_id': 'BTC-USD', 'changes': [['sell', '52796.70', '0.00103400']], 'time': '2021-05-20T03:54:59.209920Z'}
{'type': 'l2update', 'product_id': 'BTC-USD', 'changes': [['sell', '38415.34', '0.00000000']], 'time': '2021-05-20T03:54:59.212218Z'}
{'type': 'l2update', 'product_id': 'BTC-USD', 'changes': [['sell', '38420.82', '0.01791638']], 'time': '2021-05-20T03:54:59.213851Z'}
{'type': 'l2update', 'product_id': 'BTC-USD', 'changes': [['sell', '38324.18', '0.00000000']], 'time': '2021-05-20T03:54:59.215117Z'}
{'type': 'l2update', 'product_id': 'BTC-USD', 'changes': [['sell', '43100.00', '1.09530000']], 'time': '2021-05-20T03:54:59.215159Z'}
{'type': 'l2update', 'product_id': 'BTC-USD', 'changes': [['sell', '38310.91', '0.09873709']], 'time': '2021-05-20T03:54:59.217649Z'}
{'type': 'l2update', 'product_id': 'BTC-USD', 'changes': [['sell', '38286.74', '0.00000000']], 'time': '2021-05-20T03:54:59.217873Z'}
{'type': 'l2update', 'product_id': 'BTC-USD', 'changes': [['buy', '38267.74', '0.58716278']], 'time': '2021-05-20T03:54:59.221758Z'}
{'type': 'l2update', 'product_id': 'BTC-USD', 'changes': [['sell', '38440.40', '0.01000000']], 'time': '2021-05-20T03:54:59.221902Z'}
{'type': 'l2update', 'product_id': 'BTC-USD', 'changes': [['sell', '38287.78', '0.54700000']], 'time': '2021-05-20T03:54:59.221937Z'}
{'type': 'l2update', 'product_id': 'BTC-USD', 'changes': [['sell', '38293.56', '0.04201003']], 'time': '2021-05-20T03:54:59.225370Z'}
{'type': 'l2update', 'product_id': 'BTC-USD', 'changes': [['buy', '38267.73', '0.00000000']], 'time': '2021-05-20T03:54:59.231877Z'}
{'type': 'l2update', 'product_id': 'BTC-USD', 'changes': [['sell', '38286.73', '0.00000000']], 'time': '2021-05-20T03:54:59.232158Z'}
{'type': 'l2update', 'product_id': 'BTC-USD', 'changes': [['sell', '38293.56', '0.00000000']], 'time': '2021-05-20T03:54:59.236897Z'}
{'type': 'l2update', 'product_id': 'BTC-USD', 'changes': [['sell', '38334.39', '0.05452627']], 'time': '2021-05-20T03:54:59.241541Z'}
{'type': 'l2update', 'product_id': 'BTC-USD', 'changes': [['sell', '38283.08', '0.50000000']], 'time': '2021-05-20T03:54:59.241568Z'}
{'type': 'l2update', 'product_id': 'BTC-USD', 'changes': [['sell', '43100.00', '1.15480000']], 'time': '2021-05-20T03:54:59.242485Z'}
{'type': 'l2update', 'product_id': 'BTC-USD', 'changes': [['sell', '38283.09', '0.20000000']], 'time': '2021-05-20T03:54:59.247671Z'}
{'type': 'l2update', 'product_id': 'BTC-USD', 'changes': [['sell', '38287.77', '0.47369029']], 'time': '2021-05-20T03:54:59.251545Z'}
{'type': 'l2update', 'product_id': 'BTC-USD', 'changes': [['sell', '38283.09', '0.00000000']], 'time': '2021-05-20T03:54:59.252833Z'}
{'type': 'l2update', 'product_id': 'BTC-USD', 'changes': [['buy', '38267.75', '0.11747527']], 'time': '2021-05-20T03:54:59.255158Z'}
{'type': 'l2update', 'product_id': 'BTC-USD', 'changes': [['sell', '38298.74', '0.04201003']], 'time': '2021-05-20T03:54:59.258402Z'}
{'type': 'l2update', 'product_id': 'BTC-USD', 'changes': [['buy', '38255.79', '0.04444565']], 'time': '2021-05-20T03:54:59.259540Z'}
{'type': 'l2update', 'product_id': 'BTC-USD', 'changes': [['sell', '38296.63', '0.03968177']], 'time': '2021-05-20T03:54:59.259540Z'}
{'type': 'l2update', 'product_id': 'BTC-USD', 'changes': [['sell', '38493.91', '0.00000000']], 'time': '2021-05-20T03:54:59.264034Z'}
{'type': 'l2update', 'product_id': 'BTC-USD', 'changes': [['sell', '38283.08', '0.00000000']], 'time': '2021-05-20T03:54:59.265739Z'}
{'type': 'l2update', 'product_id': 'BTC-USD', 'changes': [['buy', '38239.95', '0.00000000']], 'time': '2021-05-20T03:54:59.272258Z'}
{'type': 'l2update', 'product_id': 'BTC-USD', 'changes': [['sell', '38458.93', '0.00000000']], 'time': '2021-05-20T03:54:59.274052Z'}
{'type': 'l2update', 'product_id': 'BTC-USD', 'changes': [['sell', '38287.76', '0.50000000']], 'time': '2021-05-20T03:54:59.279237Z'}
{'type': 'l2update', 'product_id': 'BTC-USD', 'changes': [['buy', '38276.28', '0.01492000']], 'time': '2021-05-20T03:54:59.279283Z'}
{'type': 'l2update', 'product_id': 'BTC-USD', 'changes': [['buy', '38243.45', '0.03308025']], 'time': '2021-05-20T03:54:59.279420Z'}
{'type': 'l2update', 'product_id': 'BTC-USD', 'changes': [['sell', '38287.50', '0.01492000']], 'time': '2021-05-20T03:54:59.279463Z'}
{'type': 'l2update', 'product_id': 'BTC-USD', 'changes': [['sell', '38518.21', '0.02596175']], 'time': '2021-05-20T03:54:59.279645Z'}
{'type': 'l2update', 'product_id': 'BTC-USD', 'changes': [['buy', '38276.71', '0.07460000']], 'time': '2021-05-20T03:54:59.279740Z'}
{'type': 'l2update', 'product_id': 'BTC-USD', 'changes': [['buy', '38243.45', '0.70863901']], 'time': '2021-05-20T03:54:59.279767Z'}
{'type': 'l2update', 'product_id': 'BTC-USD', 'changes': [['sell', '38283.22', '0.15000000']], 'time': '2021-05-20T03:54:59.279810Z'}
{'type': 'l2update', 'product_id': 'BTC-USD', 'changes': [['buy', '38251.08', '0.45132483']], 'time': '2021-05-20T03:54:59.282920Z'}
{'type': 'l2update', 'product_id': 'BTC-USD', 'changes': [['buy', '38276.71', '0.00000000']], 'time': '2021-05-20T03:54:59.287163Z'}
{'type': 'l2update', 'product_id': 'BTC-USD', 'changes': [['sell', '38287.50', '0.00000000']], 'time': '2021-05-20T03:54:59.288555Z'}
{'type': 'l2update', 'product_id': 'BTC-USD', 'changes': [['buy', '38276.28', '0.00000000']], 'time': '2021-05-20T03:54:59.288633Z'}
{'type': 'l2update', 'product_id': 'BTC-USD', 'changes': [['buy', '38243.45', '0.67555876']], 'time': '2021-05-20T03:54:59.289680Z'}
{'type': 'l2update', 'product_id': 'BTC-USD', 'changes': [['sell', '38287.22', '0.07460000']], 'time': '2021-05-20T03:54:59.291780Z'}
{'type': 'l2update', 'product_id': 'BTC-USD', 'changes': [['sell', '38306.37', '0.66565600']], 'time': '2021-05-20T03:54:59.291805Z'}
{'type': 'l2update', 'product_id': 'BTC-USD', 'changes': [['sell', '38436.55', '0.00780507']], 'time': '2021-05-20T03:54:59.295502Z'}
{'type': 'l2update', 'product_id': 'BTC-USD', 'changes': [['sell', '38287.22', '0.00000000']], 'time': '2021-05-20T03:54:59.297065Z'}
{'type': 'l2update', 'product_id': 'BTC-USD', 'changes': [['sell', '38298.74', '0.00000000']], 'time': '2021-05-20T03:54:59.300864Z'}
{'type': 'l2update', 'product_id': 'BTC-USD', 'changes': [['buy', '38243.46', '0.03308025']], 'time': '2021-05-20T03:54:59.301201Z'}
{'type': 'l2update', 'product_id': 'BTC-USD', 'changes': [['sell', '38282.90', '0.01005960']], 'time': '2021-05-20T03:54:59.305420Z'}
{'type': 'l2update', 'product_id': 'BTC-USD', 'changes': [['buy', '38243.46', '0.00000000']], 'time': '2021-05-20T03:54:59.306256Z'}
{'type': 'l2update', 'product_id': 'BTC-USD', 'changes': [['sell', '38287.77', '0.00000000']], 'time': '2021-05-20T03:54:59.306985Z'}
{'type': 'l2update', 'product_id': 'BTC-USD', 'changes': [['sell', '38296.63', '0.00000000']], 'time': '2021-05-20T03:54:59.312939Z'}
{'type': 'l2update', 'product_id': 'BTC-USD', 'changes': [['buy', '38239.95', '0.03308025']], 'time': '2021-05-20T03:54:59.313621Z'}
{'type': 'l2update', 'product_id': 'BTC-USD', 'changes': [['sell', '38283.22', '0.00000000']], 'time': '2021-05-20T03:54:59.314218Z'}
{'type': 'l2update', 'product_id': 'BTC-USD', 'changes': [['buy', '38239.95', '0.00000000']], 'time': '2021-05-20T03:54:59.320374Z'}
{'type': 'l2update', 'product_id': 'BTC-USD', 'changes': [['sell', '38302.49', '0.04201003']], 'time': '2021-05-20T03:54:59.321661Z'}
{'type': 'l2update', 'product_id': 'BTC-USD', 'changes': [['buy', '38239.94', '0.05145746']], 'time': '2021-05-20T03:54:59.322849Z'}
{'type': 'l2update', 'product_id': 'BTC-USD', 'changes': [['sell', '38287.75', '0.47369029']], 'time': '2021-05-20T03:54:59.325770Z'}
{'type': 'l2update', 'product_id': 'BTC-USD', 'changes': [['buy', '38243.46', '0.03308025']], 'time': '2021-05-20T03:54:59.326231Z'}
{'type': 'l2update', 'product_id': 'BTC-USD', 'changes': [['buy', '38255.79', '0.06340323']], 'time': '2021-05-20T03:54:59.329826Z'}
{'type': 'l2update', 'product_id': 'BTC-USD', 'changes': [['sell', '38296.46', '0.05433079']], 'time': '2021-05-20T03:54:59.329826Z'}
{'type': 'l2update', 'product_id': 'BTC-USD', 'changes': [['sell', '38436.55', '0.00000000']], 'time': '2021-05-20T03:54:59.331751Z'}
{'type': 'l2update', 'product_id': 'BTC-USD', 'changes': [['sell', '38291.20', '0.00600000']], 'time': '2021-05-20T03:54:59.334275Z'}
{'type': 'l2update', 'product_id': 'BTC-USD', 'changes': [['buy', '38267.80', '0.52200000']], 'time': '2021-05-20T03:54:59.337761Z'}
{'type': 'l2update', 'product_id': 'BTC-USD', 'changes': [['buy', '38241.61', '1.20000000']], 'time': '2021-05-20T03:54:59.337773Z'}
{'type': 'l2update', 'product_id': 'BTC-USD', 'changes': [['sell', '38455.06', '0.01000000']], 'time': '2021-05-20T03:54:59.341562Z'}
{'type': 'l2update', 'product_id': 'BTC-USD', 'changes': [['sell', '38302.49', '0.00000000']], 'time': '2021-05-20T03:54:59.344662Z'}
{'type': 'l2update', 'product_id': 'BTC-USD', 'changes': [['buy', '38267.75', '0.00000000']], 'time': '2021-05-20T03:54:59.344677Z'}
{'type': 'l2update', 'product_id': 'BTC-USD', 'changes': [['sell', '38376.47', '1.20000000']], 'time': '2021-05-20T03:54:59.349847Z'}
{'type': 'l2update', 'product_id': 'BTC-USD', 'changes': [['buy', '38267.81', '0.11747527']], 'time': '2021-05-20T03:54:59.365648Z'}
{'type': 'l2update', 'product_id': 'BTC-USD', 'changes': [['sell', '38420.82', '0.00000000']], 'time': '2021-05-20T03:54:59.372291Z'}
{'type': 'l2update', 'product_id': 'BTC-USD', 'changes': [['sell', '38299.39', '0.04201003']], 'time': '2021-05-20T03:54:59.374112Z'}
{'type': 'l2update', 'product_id': 'BTC-USD', 'changes': [['sell', '38395.73', '0.01791638']], 'time': '2021-05-20T03:54:59.383962Z'}
{'type': 'l2update', 'product_id': 'BTC-USD', 'changes': [['buy', '38255.79', '0.04444565']], 'time': '2021-05-20T03:54:59.389962Z'}
{'type': 'l2update', 'product_id': 'BTC-USD', 'changes': [['buy', '38255.79', '0.00000000']], 'time': '2021-05-20T03:54:59.389962Z'}
{'type': 'l2update', 'product_id': 'BTC-USD', 'changes': [['sell', '52804.25', '0.00200000']], 'time': '2021-05-20T03:54:59.391876Z'}
{'type': 'l2update', 'product_id': 'BTC-USD', 'changes': [['buy', '38250.10', '0.04065120']], 'time': '2021-05-20T03:54:59.414669Z'}
{'type': 'l2update', 'product_id': 'BTC-USD', 'changes': [['sell', '38299.39', '0.00000000']], 'time': '2021-05-20T03:54:59.415768Z'}
{'type': 'l2update', 'product_id': 'BTC-USD', 'changes': [['sell', '38282.90', '0.00000000']], 'time': '2021-05-20T03:54:59.427759Z'}
{'type': 'l2update', 'product_id': 'BTC-USD', 'changes': [['sell', '38301.71', '0.04201003']], 'time': '2021-05-20T03:54:59.438245Z'}
{'type': 'l2update', 'product_id': 'BTC-USD', 'changes': [['buy', '38276.55', '0.07460000']], 'time': '2021-05-20T03:54:59.441447Z'}
{'type': 'l2update', 'product_id': 'BTC-USD', 'changes': [['sell', '38287.36', '0.07460000']], 'time': '2021-05-20T03:54:59.441625Z'}
{'type': 'l2update', 'product_id': 'BTC-USD', 'changes': [['buy', '38276.59', '0.01492000']], 'time': '2021-05-20T03:54:59.441693Z'}
{'type': 'l2update', 'product_id': 'BTC-USD', 'changes': [['sell', '38287.13', '0.01492000']], 'time': '2021-05-20T03:54:59.441704Z'}
{'type': 'l2update', 'product_id': 'BTC-USD', 'changes': [['buy', '37510.50', '0.00125810']], 'time': '2021-05-20T03:54:59.445606Z'}
{'type': 'l2update', 'product_id': 'BTC-USD', 'changes': [['sell', '38287.36', '0.00000000']], 'time': '2021-05-20T03:54:59.447396Z'}
{'type': 'l2update', 'product_id': 'BTC-USD', 'changes': [['buy', '38276.55', '0.00000000']], 'time': '2021-05-20T03:54:59.447449Z'}
{'type': 'l2update', 'product_id': 'BTC-USD', 'changes': [['sell', '38287.75', '0.00000000']], 'time': '2021-05-20T03:54:59.449915Z'}
{'type': 'l2update', 'product_id': 'BTC-USD', 'changes': [['buy', '38251.09', '0.09476353']], 'time': '2021-05-20T03:54:59.458516Z'}
{'type': 'l2update', 'product_id': 'BTC-USD', 'changes': [['sell', '38325.55', '0.22800000']], 'time': '2021-05-20T03:54:59.461768Z'}
{'type': 'l2update', 'product_id': 'BTC-USD', 'changes': [['buy', '37500.01', '0.14130000']], 'time': '2021-05-20T03:54:59.463751Z'}
{'type': 'l2update', 'product_id': 'BTC-USD', 'changes': [['sell', '38287.75', '0.47369029']], 'time': '2021-05-20T03:54:59.469278Z'}
{'type': 'l2update', 'product_id': 'BTC-USD', 'changes': [['buy', '37500.01', '0.19600000']], 'time': '2021-05-20T03:54:59.469542Z'}
{'type': 'l2update', 'product_id': 'BTC-USD', 'changes': [['sell', '38455.06', '0.00000000']], 'time': '2021-05-20T03:54:59.471914Z'}
{'type': 'l2update', 'product_id': 'BTC-USD', 'changes': [['sell', '38395.73', '0.00000000']], 'time': '2021-05-20T03:54:59.473556Z'}
{'type': 'l2update', 'product_id': 'BTC-USD', 'changes': [['buy', '38129.15', '0.00000000']], 'time': '2021-05-20T03:54:59.474058Z'}
{'type': 'l2update', 'product_id': 'BTC-USD', 'changes': [['buy', '38277.28', '0.07460000']], 'time': '2021-05-20T03:54:59.478224Z'}
{'type': 'l2update', 'product_id': 'BTC-USD', 'changes': [['sell', '38286.66', '0.07460000']], 'time': '2021-05-20T03:54:59.478406Z'}
{'type': 'l2update', 'product_id': 'BTC-USD', 'changes': [['buy', '38276.59', '0.00000000']], 'time': '2021-05-20T03:54:59.484379Z'}
{'type': 'l2update', 'product_id': 'BTC-USD', 'changes': [['sell', '38411.42', '0.01791638']], 'time': '2021-05-20T03:54:59.485683Z'}
{'type': 'l2update', 'product_id': 'BTC-USD', 'changes': [['sell', '38287.13', '0.00000000']], 'time': '2021-05-20T03:54:59.485803Z'}
{'type': 'l2update', 'product_id': 'BTC-USD', 'changes': [['buy', '38225.55', '0.00000000']], 'time': '2021-05-20T03:54:59.486486Z'}
{'type': 'l2update', 'product_id': 'BTC-USD', 'changes': [['sell', '38438.28', '0.01000000']], 'time': '2021-05-20T03:54:59.493727Z'}
{'type': 'l2update', 'product_id': 'BTC-USD', 'changes': [['sell', '38427.35', '0.00000000']], 'time': '2021-05-20T03:54:59.496124Z'}
{'type': 'l2update', 'product_id': 'BTC-USD', 'changes': [['buy', '38160.85', '0.80355629']], 'time': '2021-05-20T03:54:59.497602Z'}
{'type': 'l2update', 'product_id': 'BTC-USD', 'changes': [['buy', '38226.55', '0.10000000']], 'time': '2021-05-20T03:54:59.498124Z'}
{'type': 'l2update', 'product_id': 'BTC-USD', 'changes': [['buy', '38277.28', '0.00000000']], 'time': '2021-05-20T03:54:59.502601Z'}
{'type': 'l2update', 'product_id': 'BTC-USD', 'changes': [['sell', '38286.66', '0.00000000']], 'time': '2021-05-20T03:54:59.508017Z'}
{'type': 'l2update', 'product_id': 'BTC-USD', 'changes': [['sell', '38286.28', '0.01492000']], 'time': '2021-05-20T03:54:59.510290Z'}
{'type': 'l2update', 'product_id': 'BTC-USD', 'changes': [['sell', '38412.92', '0.01000000']], 'time': '2021-05-20T03:54:59.510483Z'}
{'type': 'l2update', 'product_id': 'BTC-USD', 'changes': [['buy', '38277.67', '0.01492000']], 'time': '2021-05-20T03:54:59.510677Z'}
{'type': 'l2update', 'product_id': 'BTC-USD', 'changes': [['buy', '38277.67', '0.00000000']], 'time': '2021-05-20T03:54:59.516209Z'}
{'type': 'l2update', 'product_id': 'BTC-USD', 'changes': [['sell', '38286.28', '0.00000000']], 'time': '2021-05-20T03:54:59.516400Z'}
{'type': 'l2update', 'product_id': 'BTC-USD', 'changes': [['sell', '38287.36', '0.07460000']], 'time': '2021-05-20T03:54:59.517872Z'}
{'type': 'l2update', 'product_id': 'BTC-USD', 'changes': [['buy', '38276.64', '0.07460000']], 'time': '2021-05-20T03:54:59.522774Z'}
{'type': 'l2update', 'product_id': 'BTC-USD', 'changes': [['sell', '38287.36', '0.00000000']], 'time': '2021-05-20T03:54:59.522820Z'}
{'type': 'l2update', 'product_id': 'BTC-USD', 'changes': [['sell', '38287.75', '0.00000000']], 'time': '2021-05-20T03:54:59.523997Z'}
{'type': 'l2update', 'product_id': 'BTC-USD', 'changes': [['buy', '38160.84', '0.00000000']], 'time': '2021-05-20T03:54:59.525216Z'}
{'type': 'l2update', 'product_id': 'BTC-USD', 'changes': [['buy', '38276.64', '0.00000000']], 'time': '2021-05-20T03:54:59.527358Z'}
{'type': 'l2update', 'product_id': 'BTC-USD', 'changes': [['sell', '38287.42', '0.01492000']], 'time': '2021-05-20T03:54:59.530689Z'}
{'type': 'l2update', 'product_id': 'BTC-USD', 'changes': [['buy', '38276.38', '0.01492000']], 'time': '2021-05-20T03:54:59.531044Z'}
{'type': 'l2update', 'product_id': 'BTC-USD', 'changes': [['buy', '38254.01', '0.00000000']], 'time': '2021-05-20T03:54:59.532496Z'}
{'type': 'l2update', 'product_id': 'BTC-USD', 'changes': [['sell', '38301.71', '0.00000000']], 'time': '2021-05-20T03:54:59.533226Z'}
{'type': 'l2update', 'product_id': 'BTC-USD', 'changes': [['sell', '38287.42', '0.00000000']], 'time': '2021-05-20T03:54:59.536018Z'}
{'type': 'l2update', 'product_id': 'BTC-USD', 'changes': [['buy', '38276.38', '0.00000000']], 'time': '2021-05-20T03:54:59.537468Z'}
{'type': 'l2update', 'product_id': 'BTC-USD', 'changes': [['sell', '38287.16', '0.07460000']], 'time': '2021-05-20T03:54:59.538409Z'}
{'type': 'l2update', 'product_id': 'BTC-USD', 'changes': [['buy', '38255.40', '0.45320000']], 'time': '2021-05-20T03:54:59.542139Z'}
{'type': 'l2update', 'product_id': 'BTC-USD', 'changes': [['sell', '38287.75', '0.47369029']], 'time': '2021-05-20T03:54:59.542230Z'}
{'type': 'l2update', 'product_id': 'BTC-USD', 'changes': [['buy', '38276.46', '0.07460000']], 'time': '2021-05-20T03:54:59.542279Z'}
{'type': 'l2update', 'product_id': 'BTC-USD', 'changes': [['sell', '38287.38', '0.01492000']], 'time': '2021-05-20T03:54:59.549287Z'}
{'type': 'l2update', 'product_id': 'BTC-USD', 'changes': [['buy', '38276.54', '0.01492000']], 'time': '2021-05-20T03:54:59.549494Z'}
{'type': 'l2update', 'product_id': 'BTC-USD', 'changes': [['sell', '38438.28', '0.00000000']], 'time': '2021-05-20T03:54:59.551014Z'}
{'type': 'l2update', 'product_id': 'BTC-USD', 'changes': [['sell', '38287.38', '0.00000000']], 'time': '2021-05-20T03:54:59.554156Z'}
{'type': 'l2update', 'product_id': 'BTC-USD', 'changes': [['sell', '52815.57', '0.00200000']], 'time': '2021-05-20T03:54:59.561775Z'}
{'type': 'l2update', 'product_id': 'BTC-USD', 'changes': [['buy', '38276.46', '0.00000000']], 'time': '2021-05-20T03:54:59.564388Z'}
{'type': 'l2update', 'product_id': 'BTC-USD', 'changes': [['sell', '38437.76', '0.00000000']], 'time': '2021-05-20T03:54:59.575261Z'}
{'type': 'l2update', 'product_id': 'BTC-USD', 'changes': [['buy', '38276.96', '0.07460000']], 'time': '2021-05-20T03:54:59.581678Z'}
{'type': 'l2update', 'product_id': 'BTC-USD', 'changes': [['sell', '38286.77', '0.01492000']], 'time': '2021-05-20T03:54:59.585947Z'}
{'type': 'l2update', 'product_id': 'BTC-USD', 'changes': [['sell', '38401.66', '0.00000000']], 'time': '2021-05-20T03:54:59.586846Z'}
{'type': 'l2update', 'product_id': 'BTC-USD', 'changes': [['sell', '38287.16', '0.00000000']], 'time': '2021-05-20T03:54:59.591702Z'}
{'type': 'l2update', 'product_id': 'BTC-USD', 'changes': [['buy', '38276.54', '0.00000000']], 'time': '2021-05-20T03:54:59.592487Z'}
{'type': 'l2update', 'product_id': 'BTC-USD', 'changes': [['sell', '38420.05', '0.07333276']], 'time': '2021-05-20T03:54:59.598158Z'}
{'type': 'l2update', 'product_id': 'BTC-USD', 'changes': [['sell', '38388.69', '0.01000000']], 'time': '2021-05-20T03:54:59.601385Z'}
{'type': 'l2update', 'product_id': 'BTC-USD', 'changes': [['buy', '38189.81', '0.01000000']], 'time': '2021-05-20T03:54:59.602474Z'}
{'type': 'l2update', 'product_id': 'BTC-USD', 'changes': [['buy', '38267.82', '0.10000000']], 'time': '2021-05-20T03:54:59.602495Z'}
{'type': 'l2update', 'product_id': 'BTC-USD', 'changes': [['buy', '38276.03', '0.05000000']], 'time': '2021-05-20T03:54:59.606380Z'}
{'type': 'l2update', 'product_id': 'BTC-USD', 'changes': [['buy', '38267.81', '0.00000000']], 'time': '2021-05-20T03:54:59.610523Z'}
{'type': 'l2update', 'product_id': 'BTC-USD', 'changes': [['sell', '38420.05', '0.00000000']], 'time': '2021-05-20T03:54:59.611924Z'}
{'type': 'l2update', 'product_id': 'BTC-USD', 'changes': [['sell', '38286.34', '0.07460000']], 'time': '2021-05-20T03:54:59.613818Z'}
{'type': 'l2update', 'product_id': 'BTC-USD', 'changes': [['buy', '38267.74', '0.00000000']], 'time': '2021-05-20T03:54:59.616813Z'}
{'type': 'l2update', 'product_id': 'BTC-USD', 'changes': [['buy', '38277.61', '0.01492000']], 'time': '2021-05-20T03:54:59.617555Z'}
{'type': 'l2update', 'product_id': 'BTC-USD', 'changes': [['sell', '38286.77', '0.00000000']], 'time': '2021-05-20T03:54:59.620504Z'}
{'type': 'l2update', 'product_id': 'BTC-USD', 'changes': [['buy', '38276.96', '0.00000000']], 'time': '2021-05-20T03:54:59.622154Z'}
{'type': 'l2update', 'product_id': 'BTC-USD', 'changes': [['sell', '38286.34', '0.00000000']], 'time': '2021-05-20T03:54:59.632572Z'}
{'type': 'l2update', 'product_id': 'BTC-USD', 'changes': [['buy', '38267.83', '0.11747527']], 'time': '2021-05-20T03:54:59.633720Z'}
{'type': 'l2update', 'product_id': 'BTC-USD', 'changes': [['buy', '38267.83', '0.70463805']], 'time': '2021-05-20T03:54:59.637444Z'}
{'type': 'l2update', 'product_id': 'BTC-USD', 'changes': [['buy', '38278.02', '0.07460000']], 'time': '2021-05-20T03:54:59.637479Z'}
{'type': 'l2update', 'product_id': 'BTC-USD', 'changes': [['buy', '38277.61', '0.00000000']], 'time': '2021-05-20T03:54:59.638808Z'}
{'type': 'l2update', 'product_id': 'BTC-USD', 'changes': [['buy', '38276.03', '0.00000000']], 'time': '2021-05-20T03:54:59.640173Z'}
{'type': 'l2update', 'product_id': 'BTC-USD', 'changes': [['sell', '38287.17', '0.07460000']], 'time': '2021-05-20T03:54:59.646962Z'}
{'type': 'l2update', 'product_id': 'BTC-USD', 'changes': [['sell', '38287.13', '0.01492000']], 'time': '2021-05-20T03:54:59.647285Z'}
{'type': 'l2update', 'product_id': 'BTC-USD', 'changes': [['sell', '38306.38', '0.00000000']], 'time': '2021-05-20T03:54:59.651177Z'}
{'type': 'l2update', 'product_id': 'BTC-USD', 'changes': [['buy', '38278.02', '0.00000000']], 'time': '2021-05-20T03:54:59.651783Z'}
{'type': 'l2update', 'product_id': 'BTC-USD', 'changes': [['sell', '38453.10', '0.10152616']], 'time': '2021-05-20T03:54:59.653334Z'}
{'type': 'l2update', 'product_id': 'BTC-USD', 'changes': [['buy', '38260.33', '0.00000000']], 'time': '2021-05-20T03:54:59.654838Z'}
{'type': 'l2update', 'product_id': 'BTC-USD', 'changes': [['sell', '38287.17', '0.00000000']], 'time': '2021-05-20T03:54:59.654905Z'}
{'type': 'l2update', 'product_id': 'BTC-USD', 'changes': [['sell', '38305.12', '0.46410000']], 'time': '2021-05-20T03:54:59.661232Z'}
{'type': 'l2update', 'product_id': 'BTC-USD', 'changes': [['buy', '38276.55', '0.07460000']], 'time': '2021-05-20T03:54:59.661539Z'}
{'type': 'l2update', 'product_id': 'BTC-USD', 'changes': [['buy', '38278.62', '0.01492000']], 'time': '2021-05-20T03:54:59.661745Z'}
{'type': 'l2update', 'product_id': 'BTC-USD', 'changes': [['buy', '38267.83', '0.75463805']], 'time': '2021-05-20T03:54:59.666549Z'}
{'type': 'l2update', 'product_id': 'BTC-USD', 'changes': [['buy', '38262.98', '0.02400000']], 'time': '2021-05-20T03:54:59.666566Z'}
{'type': 'l2update', 'product_id': 'BTC-USD', 'changes': [['buy', '38278.62', '0.00000000']], 'time': '2021-05-20T03:54:59.668273Z'}
{'type': 'l2update', 'product_id': 'BTC-USD', 'changes': [['buy', '38250.10', '0.00000000']], 'time': '2021-05-20T03:54:59.668834Z'}
{'type': 'l2update', 'product_id': 'BTC-USD', 'changes': [['buy', '38276.55', '0.00000000']], 'time': '2021-05-20T03:54:59.668855Z'}
{'type': 'l2update', 'product_id': 'BTC-USD', 'changes': [['sell', '38286.89', '0.07460000']], 'time': '2021-05-20T03:54:59.678150Z'}
{'type': 'l2update', 'product_id': 'BTC-USD', 'changes': [['buy', '38276.28', '0.07460000']], 'time': '2021-05-20T03:54:59.682206Z'}
{'type': 'l2update', 'product_id': 'BTC-USD', 'changes': [['buy', '38277.20', '0.01492000']], 'time': '2021-05-20T03:54:59.682418Z'}
{'type': 'l2update', 'product_id': 'BTC-USD', 'changes': [['sell', '38453.10', '0.00000000']], 'time': '2021-05-20T03:54:59.684470Z'}
{'type': 'l2update', 'product_id': 'BTC-USD', 'changes': [['sell', '38287.13', '0.00000000']], 'time': '2021-05-20T03:54:59.686001Z'}
{'type': 'l2update', 'product_id': 'BTC-USD', 'changes': [['buy', '38267.83', '0.63716278']], 'time': '2021-05-20T03:54:59.688286Z'}
{'type': 'l2update', 'product_id': 'BTC-USD', 'changes': [['buy', '38276.28', '0.00000000']], 'time': '2021-05-20T03:54:59.688929Z'}
{'type': 'l2update', 'product_id': 'BTC-USD', 'changes': [['sell', '38291.45', '0.00000000']], 'time': '2021-05-20T03:54:59.695351Z'}
{'type': 'l2update', 'product_id': 'BTC-USD', 'changes': [['sell', '38287.78', '0.00000000']], 'time': '2021-05-20T03:54:59.697596Z'}
{'type': 'l2update', 'product_id': 'BTC-USD', 'changes': [['sell', '38494.63', '0.02453230']], 'time': '2021-05-20T03:54:59.700301Z'}
{'type': 'l2update', 'product_id': 'BTC-USD', 'changes': [['buy', '38252.25', '0.06496179']], 'time': '2021-05-20T03:54:59.700376Z'}
{'type': 'l2update', 'product_id': 'BTC-USD', 'changes': [['sell', '38291.76', '0.00000000']], 'time': '2021-05-20T03:54:59.701435Z'}
{'type': 'l2update', 'product_id': 'BTC-USD', 'changes': [['buy', '38261.14', '0.00000000']], 'time': '2021-05-20T03:54:59.704418Z'}
{'type': 'l2update', 'product_id': 'BTC-USD', 'changes': [['sell', '38291.15', '1.05600000']], 'time': '2021-05-20T03:54:59.705494Z'}
{'type': 'l2update', 'product_id': 'BTC-USD', 'changes': [['buy', '38277.20', '0.00000000']], 'time': '2021-05-20T03:54:59.706414Z'}
{'type': 'l2update', 'product_id': 'BTC-USD', 'changes': [['buy', '38267.84', '0.11747527']], 'time': '2021-05-20T03:54:59.709627Z'}
{'type': 'l2update', 'product_id': 'BTC-USD', 'changes': [['sell', '38286.26', '0.01492000']], 'time': '2021-05-20T03:54:59.712862Z'}
{'type': 'l2update', 'product_id': 'BTC-USD', 'changes': [['buy', '38277.72', '0.07460000']], 'time': '2021-05-20T03:54:59.713982Z'}
{'type': 'l2update', 'product_id': 'BTC-USD', 'changes': [['sell', '38286.89', '0.00000000']], 'time': '2021-05-20T03:54:59.717621Z'}
{'type': 'l2update', 'product_id': 'BTC-USD', 'changes': [['buy', '38276.45', '0.01492000']], 'time': '2021-05-20T03:54:59.718892Z'}
{'type': 'l2update', 'product_id': 'BTC-USD', 'changes': [['buy', '38277.72', '0.00000000']], 'time': '2021-05-20T03:54:59.719136Z'}
{'type': 'l2update', 'product_id': 'BTC-USD', 'changes': [['buy', '38264.26', '0.02400000']], 'time': '2021-05-20T03:54:59.719246Z'}
{'type': 'l2update', 'product_id': 'BTC-USD', 'changes': [['sell', '38291.15', '1.60300000']], 'time': '2021-05-20T03:54:59.721157Z'}
{'type': 'l2update', 'product_id': 'BTC-USD', 'changes': [['sell', '52842.00', '0.00291800']], 'time': '2021-05-20T03:54:59.721864Z'}
{'type': 'l2update', 'product_id': 'BTC-USD', 'changes': [['buy', '38276.45', '0.00000000']], 'time': '2021-05-20T03:54:59.724838Z'}
{'type': 'l2update', 'product_id': 'BTC-USD', 'changes': [['sell', '38286.26', '0.00000000']], 'time': '2021-05-20T03:54:59.730454Z'}
{'type': 'l2update', 'product_id': 'BTC-USD', 'changes': [['buy', '38276.98', '0.07460000']], 'time': '2021-05-20T03:54:59.733989Z'}
{'type': 'l2update', 'product_id': 'BTC-USD', 'changes': [['sell', '38285.60', '0.07460000']], 'time': '2021-05-20T03:54:59.734120Z'}
{'type': 'l2update', 'product_id': 'BTC-USD', 'changes': [['buy', '38255.40', '0.00000000']], 'time': '2021-05-20T03:54:59.737557Z'}
{'type': 'l2update', 'product_id': 'BTC-USD', 'changes': [['buy', '38276.98', '0.00000000']], 'time': '2021-05-20T03:54:59.738939Z'}
{'type': 'l2update', 'product_id': 'BTC-USD', 'changes': [['sell', '38285.60', '0.00000000']], 'time': '2021-05-20T03:54:59.740231Z'}
{'type': 'l2update', 'product_id': 'BTC-USD', 'changes': [['sell', '38305.12', '0.00000000']], 'time': '2021-05-20T03:54:59.741538Z'}
{'type': 'l2update', 'product_id': 'BTC-USD', 'changes': [['sell', '38287.42', '0.01492000']], 'time': '2021-05-20T03:54:59.741915Z'}
{'type': 'l2update', 'product_id': 'BTC-USD', 'changes': [['sell', '38411.42', '0.00000000']], 'time': '2021-05-20T03:54:59.743962Z'}
{'type': 'l2update', 'product_id': 'BTC-USD', 'changes': [['buy', '38276.40', '0.01492000']], 'time': '2021-05-20T03:54:59.745480Z'}
{'type': 'l2update', 'product_id': 'BTC-USD', 'changes': [['buy', '38252.25', '0.00000000']], 'time': '2021-05-20T03:54:59.747384Z'}
{'type': 'l2update', 'product_id': 'BTC-USD', 'changes': [['sell', '38287.42', '0.00000000']], 'time': '2021-05-20T03:54:59.747814Z'}
{'type': 'l2update', 'product_id': 'BTC-USD', 'changes': [['buy', '38276.40', '0.00000000']], 'time': '2021-05-20T03:54:59.750742Z'}
{'type': 'l2update', 'product_id': 'BTC-USD', 'changes': [['sell', '38287.12', '0.07460000']], 'time': '2021-05-20T03:54:59.754275Z'}
{'type': 'l2update', 'product_id': 'BTC-USD', 'changes': [['buy', '38276.55', '0.07460000']], 'time': '2021-05-20T03:54:59.754622Z'}
{'type': 'l2update', 'product_id': 'BTC-USD', 'changes': [['sell', '38399.64', '0.01791638']], 'time': '2021-05-20T03:54:59.754723Z'}
{'type': 'l2update', 'product_id': 'BTC-USD', 'changes': [['sell', '38477.17', '0.00000000']], 'time': '2021-05-20T03:54:59.756706Z'}
{'type': 'l2update', 'product_id': 'BTC-USD', 'changes': [['buy', '38267.84', '0.21747527']], 'time': '2021-05-20T03:54:59.758271Z'}
{'type': 'l2update', 'product_id': 'BTC-USD', 'changes': [['buy', '38264.26', '0.00000000']], 'time': '2021-05-20T03:54:59.759331Z'}
{'type': 'l2update', 'product_id': 'BTC-USD', 'changes': [['buy', '38262.91', '0.00000000']], 'time': '2021-05-20T03:54:59.760283Z'}
{'type': 'l2update', 'product_id': 'BTC-USD', 'changes': [['buy', '38267.72', '0.00000000']], 'time': '2021-05-20T03:54:59.760478Z'}
{'type': 'l2update', 'product_id': 'BTC-USD', 'changes': [['sell', '38287.40', '0.01492000']], 'time': '2021-05-20T03:54:59.762138Z'}
{'type': 'l2update', 'product_id': 'BTC-USD', 'changes': [['buy', '38276.42', '0.01492000']], 'time': '2021-05-20T03:54:59.765615Z'}
{'type': 'l2update', 'product_id': 'BTC-USD', 'changes': [['buy', '38267.84', '0.10000000']], 'time': '2021-05-20T03:54:59.767221Z'}
{'type': 'l2update', 'product_id': 'BTC-USD', 'changes': [['sell', '38287.40', '0.00000000']], 'time': '2021-05-20T03:54:59.767932Z'}
{'type': 'l2update', 'product_id': 'BTC-USD', 'changes': [['sell', '38514.52', '0.01000000']], 'time': '2021-05-20T03:54:59.768707Z'}
{'type': 'l2update', 'product_id': 'BTC-USD', 'changes': [['sell', '38287.75', '0.00000000']], 'time': '2021-05-20T03:54:59.769224Z'}
{'type': 'l2update', 'product_id': 'BTC-USD', 'changes': [['buy', '38255.79', '0.06406622']], 'time': '2021-05-20T03:54:59.772703Z'}
{'type': 'l2update', 'product_id': 'BTC-USD', 'changes': [['buy', '38267.85', '0.05000000']], 'time': '2021-05-20T03:54:59.772730Z'}
{'type': 'l2update', 'product_id': 'BTC-USD', 'changes': [['buy', '38261.60', '0.02400000']], 'time': '2021-05-20T03:54:59.772781Z'}
{'type': 'l2update', 'product_id': 'BTC-USD', 'changes': [['sell', '38287.70', '0.54800000']], 'time': '2021-05-20T03:54:59.772803Z'}
{'type': 'l2update', 'product_id': 'BTC-USD', 'changes': [['buy', '38170.92', '0.00000000']], 'time': '2021-05-20T03:54:59.774248Z'}
{'type': 'l2update', 'product_id': 'BTC-USD', 'changes': [['buy', '38276.42', '0.00000000']], 'time': '2021-05-20T03:54:59.774955Z'}
{'type': 'l2update', 'product_id': 'BTC-USD', 'changes': [['buy', '38262.98', '0.00000000']], 'time': '2021-05-20T03:54:59.778275Z'}
{'type': 'l2update', 'product_id': 'BTC-USD', 'changes': [['buy', '38261.60', '0.00000000']], 'time': '2021-05-20T03:54:59.778275Z'}
{'type': 'l2update', 'product_id': 'BTC-USD', 'changes': [['sell', '38291.15', '0.54700000']], 'time': '2021-05-20T03:54:59.779446Z'}
{'type': 'l2update', 'product_id': 'BTC-USD', 'changes': [['sell', '38286.47', '0.01492000']], 'time': '2021-05-20T03:54:59.779840Z'}
{'type': 'l2update', 'product_id': 'BTC-USD', 'changes': [['sell', '38287.12', '0.00000000']], 'time': '2021-05-20T03:54:59.785248Z'}
{'type': 'l2update', 'product_id': 'BTC-USD', 'changes': [['buy', '38276.98', '0.01492000']], 'time': '2021-05-20T03:54:59.792021Z'}
{'type': 'l2update', 'product_id': 'BTC-USD', 'changes': [['buy', '38267.86', '0.11747527']], 'time': '2021-05-20T03:54:59.792197Z'}
{'type': 'l2update', 'product_id': 'BTC-USD', 'changes': [['sell', '38287.11', '0.47369029']], 'time': '2021-05-20T03:54:59.796567Z'}
{'type': 'l2update', 'product_id': 'BTC-USD', 'changes': [['buy', '38267.83', '0.58716278']], 'time': '2021-05-20T03:54:59.802128Z'}
{'type': 'l2update', 'product_id': 'BTC-USD', 'changes': [['buy', '38267.82', '0.00000000']], 'time': '2021-05-20T03:54:59.807193Z'}
{'type': 'l2update', 'product_id': 'BTC-USD', 'changes': [['buy', '38276.03', '0.05000000']], 'time': '2021-05-20T03:54:59.808293Z'}
{'type': 'l2update', 'product_id': 'BTC-USD', 'changes': [['buy', '38276.55', '0.00000000']], 'time': '2021-05-20T03:54:59.809901Z'}
{'type': 'l2update', 'product_id': 'BTC-USD', 'changes': [['buy', '38267.86', '0.21747527']], 'time': '2021-05-20T03:54:59.812866Z'}
{'type': 'l2update', 'product_id': 'BTC-USD', 'changes': [['sell', '38285.83', '0.07460000']], 'time': '2021-05-20T03:54:59.817063Z'}
{'type': 'l2update', 'product_id': 'BTC-USD', 'changes': [['sell', '38286.47', '0.00000000']], 'time': '2021-05-20T03:54:59.824287Z'}
{'type': 'l2update', 'product_id': 'BTC-USD', 'changes': [['buy', '38260.71', '0.02400000']], 'time': '2021-05-20T03:54:59.832178Z'}
{'type': 'l2update', 'product_id': 'BTC-USD', 'changes': [['buy', '38259.90', '0.02400000']], 'time': '2021-05-20T03:54:59.832178Z'}
{'type': 'l2update', 'product_id': 'BTC-USD', 'changes': [['buy', '38277.57', '0.07460000']], 'time': '2021-05-20T03:54:59.832556Z'}
{'type': 'l2update', 'product_id': 'BTC-USD', 'changes': [['buy', '38267.85', '0.00000000']], 'time': '2021-05-20T03:54:59.832705Z'}
{'type': 'l2update', 'product_id': 'BTC-USD', 'changes': [['buy', '38256.09', '0.43770000']], 'time': '2021-05-20T03:54:59.835878Z'}
{'type': 'l2update', 'product_id': 'BTC-USD', 'changes': [['sell', '38285.83', '0.00000000']], 'time': '2021-05-20T03:54:59.839276Z'}
{'type': 'l2update', 'product_id': 'BTC-USD', 'changes': [['sell', '38321.70', '0.01000000']], 'time': '2021-05-20T03:54:59.840759Z'}
{'type': 'l2update', 'product_id': 'BTC-USD', 'changes': [['buy', '38276.98', '0.00000000']], 'time': '2021-05-20T03:54:59.840876Z'}
{'type': 'l2update', 'product_id': 'BTC-USD', 'changes': [['buy', '38267.86', '0.10000000']], 'time': '2021-05-20T03:54:59.844426Z'}
{'type': 'l2update', 'product_id': 'BTC-USD', 'changes': [['sell', '38305.15', '0.41310000']], 'time': '2021-05-20T03:54:59.844795Z'}
{'type': 'l2update', 'product_id': 'BTC-USD', 'changes': [['sell', '38285.45', '0.01492000']], 'time': '2021-05-20T03:54:59.844859Z'}
{'type': 'l2update', 'product_id': 'BTC-USD', 'changes': [['sell', '38286.68', '0.07460000']], 'time': '2021-05-20T03:54:59.848374Z'}
{'type': 'l2update', 'product_id': 'BTC-USD', 'changes': [['buy', '38267.84', '0.00000000']], 'time': '2021-05-20T03:54:59.849214Z'}
{'type': 'l2update', 'product_id': 'BTC-USD', 'changes': [['sell', '38285.45', '0.00000000']], 'time': '2021-05-20T03:54:59.849965Z'}
{'type': 'l2update', 'product_id': 'BTC-USD', 'changes': [['buy', '38277.57', '0.00000000']], 'time': '2021-05-20T03:54:59.850473Z'}
{'type': 'l2update', 'product_id': 'BTC-USD', 'changes': [['sell', '38287.11', '0.00000000']], 'time': '2021-05-20T03:54:59.851135Z'}
{'type': 'l2update', 'product_id': 'BTC-USD', 'changes': [['sell', '38287.70', '0.00000000']], 'time': '2021-05-20T03:54:59.851380Z'}
{'type': 'l2update', 'product_id': 'BTC-USD', 'changes': [['buy', '38239.39', '0.01000000']], 'time': '2021-05-20T03:54:59.852321Z'}
{'type': 'l2update', 'product_id': 'BTC-USD', 'changes': [['sell', '38286.68', '0.00000000']], 'time': '2021-05-20T03:54:59.853943Z'}
{'type': 'l2update', 'product_id': 'BTC-USD', 'changes': [['buy', '38276.03', '0.15000000']], 'time': '2021-05-20T03:54:59.857063Z'}
{'type': 'l2update', 'product_id': 'BTC-USD', 'changes': [['sell', '38310.91', '0.05000000']], 'time': '2021-05-20T03:54:59.858050Z'}
{'type': 'l2update', 'product_id': 'BTC-USD', 'changes': [['buy', '38278.20', '0.01492000']], 'time': '2021-05-20T03:54:59.864554Z'}
{'type': 'l2update', 'product_id': 'BTC-USD', 'changes': [['sell', '38287.26', '0.07460000']], 'time': '2021-05-20T03:54:59.864696Z'}
{'type': 'l2update', 'product_id': 'BTC-USD', 'changes': [['buy', '38276.33', '0.07460000']], 'time': '2021-05-20T03:54:59.864776Z'}
{'type': 'l2update', 'product_id': 'BTC-USD', 'changes': [['buy', '38267.87', '0.11747527']], 'time': '2021-05-20T03:54:59.864929Z'}
{'type': 'l2update', 'product_id': 'BTC-USD', 'changes': [['buy', '38118.62', '0.05096151']], 'time': '2021-05-20T03:54:59.864941Z'}
{'type': 'l2update', 'product_id': 'BTC-USD', 'changes': [['buy', '38262.85', '0.00000000']], 'time': '2021-05-20T03:54:59.867412Z'}
{'type': 'l2update', 'product_id': 'BTC-USD', 'changes': [['buy', '38265.10', '0.00000000']], 'time': '2021-05-20T03:54:59.868074Z'}
{'type': 'l2update', 'product_id': 'BTC-USD', 'changes': [['buy', '38276.33', '0.00000000']], 'time': '2021-05-20T03:54:59.869806Z'}
{'type': 'l2update', 'product_id': 'BTC-USD', 'changes': [['buy', '38278.20', '0.00000000']], 'time': '2021-05-20T03:54:59.870169Z'}
{'type': 'l2update', 'product_id': 'BTC-USD', 'changes': [['buy', '38267.80', '0.00000000']], 'time': '2021-05-20T03:54:59.871144Z'}
{'type': 'l2update', 'product_id': 'BTC-USD', 'changes': [['sell', '38287.75', '0.47369029']], 'time': '2021-05-20T03:54:59.873085Z'}
{'type': 'l2update', 'product_id': 'BTC-USD', 'changes': [['sell', '38291.15', '0.00000000']], 'time': '2021-05-20T03:54:59.876263Z'}
{'type': 'l2update', 'product_id': 'BTC-USD', 'changes': [['buy', '38113.67', '0.00000000']], 'time': '2021-05-20T03:54:59.877867Z'}
{'type': 'l2update', 'product_id': 'BTC-USD', 'changes': [['buy', '38267.91', '0.84700000']], 'time': '2021-05-20T03:54:59.879060Z'}
{'type': 'l2update', 'product_id': 'BTC-USD', 'changes': [['sell', '38286.29', '0.01492000']], 'time': '2021-05-20T03:54:59.879109Z'}
{'type': 'l2update', 'product_id': 'BTC-USD', 'changes': [['sell', '52997.72', '0.00245500']], 'time': '2021-05-20T03:54:59.879287Z'}
{'type': 'l2update', 'product_id': 'BTC-USD', 'changes': [['sell', '38316.31', '0.05027405']], 'time': '2021-05-20T03:54:59.881644Z'}
{'type': 'l2update', 'product_id': 'BTC-USD', 'changes': [['buy', '38276.72', '0.01492000']], 'time': '2021-05-20T03:54:59.881675Z'}
{'type': 'l2update', 'product_id': 'BTC-USD', 'changes': [['buy', '38276.55', '0.07460000']], 'time': '2021-05-20T03:54:59.881799Z'}
{'type': 'l2update', 'product_id': 'BTC-USD', 'changes': [['sell', '38286.29', '0.00000000']], 'time': '2021-05-20T03:54:59.884511Z'}
{'type': 'l2update', 'product_id': 'BTC-USD', 'changes': [['sell', '38287.26', '0.00000000']], 'time': '2021-05-20T03:54:59.886563Z'}
{'type': 'l2update', 'product_id': 'BTC-USD', 'changes': [['buy', '38276.55', '0.00000000']], 'time': '2021-05-20T03:54:59.889358Z'}
{'type': 'l2update', 'product_id': 'BTC-USD', 'changes': [['sell', '38286.75', '0.01492000']], 'time': '2021-05-20T03:54:59.898457Z'}
{'type': 'l2update', 'product_id': 'BTC-USD', 'changes': [['sell', '38287.47', '0.07460000']], 'time': '2021-05-20T03:54:59.898468Z'}
{'type': 'l2update', 'product_id': 'BTC-USD', 'changes': [['sell', '38446.25', '0.00000000']], 'time': '2021-05-20T03:54:59.901834Z'}
{'type': 'l2update', 'product_id': 'BTC-USD', 'changes': [['buy', '38276.98', '0.07460000']], 'time': '2021-05-20T03:54:59.911528Z'}
{'type': 'l2update', 'product_id': 'BTC-USD', 'changes': [['sell', '38465.75', '0.01000000']], 'time': '2021-05-20T03:54:59.911681Z'}
{'type': 'l2update', 'product_id': 'BTC-USD', 'changes': [['buy', '38118.62', '0.00000000']], 'time': '2021-05-20T03:54:59.914950Z'}
{'type': 'l2update', 'product_id': 'BTC-USD', 'changes': [['sell', '38321.70', '0.00000000']], 'time': '2021-05-20T03:54:59.915850Z'}
{'type': 'l2update', 'product_id': 'BTC-USD', 'changes': [['sell', '38287.47', '0.00000000']], 'time': '2021-05-20T03:54:59.915881Z'}
{'type': 'l2update', 'product_id': 'BTC-USD', 'changes': [['buy', '38267.87', '0.00000000']], 'time': '2021-05-20T03:54:59.917642Z'}
{'type': 'l2update', 'product_id': 'BTC-USD', 'changes': [['sell', '38311.70', '0.05073117']], 'time': '2021-05-20T03:54:59.918541Z'}
{'type': 'l2update', 'product_id': 'BTC-USD', 'changes': [['buy', '38239.39', '0.00000000']], 'time': '2021-05-20T03:54:59.919024Z'}
{'type': 'l2update', 'product_id': 'BTC-USD', 'changes': [['buy', '38267.86', '0.00000000']], 'time': '2021-05-20T03:54:59.920646Z'}
{'type': 'l2update', 'product_id': 'BTC-USD', 'changes': [['sell', '38588.06', '0.00000000']], 'time': '2021-05-20T03:54:59.924185Z'}
{'type': 'l2update', 'product_id': 'BTC-USD', 'changes': [['sell', '38316.31', '0.00000000']], 'time': '2021-05-20T03:54:59.936732Z'}
{'type': 'l2update', 'product_id': 'BTC-USD', 'changes': [['sell', '38399.64', '0.00000000']], 'time': '2021-05-20T03:54:59.938940Z'}
{'type': 'l2update', 'product_id': 'BTC-USD', 'changes': [['buy', '38267.92', '0.11747527']], 'time': '2021-05-20T03:54:59.941185Z'}
{'type': 'l2update', 'product_id': 'BTC-USD', 'changes': [['buy', '38276.72', '0.00000000']], 'time': '2021-05-20T03:54:59.944436Z'}
{'type': 'l2update', 'product_id': 'BTC-USD', 'changes': [['sell', '38286.31', '0.07460000']], 'time': '2021-05-20T03:54:59.948690Z'}
{'type': 'l2update', 'product_id': 'BTC-USD', 'changes': [['sell', '38588.06', '3.23362444']], 'time': '2021-05-20T03:54:59.955969Z'}
{'type': 'l2update', 'product_id': 'BTC-USD', 'changes': [['buy', '38243.46', '0.00000000']], 'time': '2021-05-20T03:54:59.956233Z'}
{'type': 'l2update', 'product_id': 'BTC-USD', 'changes': [['sell', '38384.64', '0.01792338']], 'time': '2021-05-20T03:54:59.960125Z'}
{'type': 'l2update', 'product_id': 'BTC-USD', 'changes': [['buy', '38239.95', '0.03327915']], 'time': '2021-05-20T03:54:59.963743Z'}
{'type': 'l2update', 'product_id': 'BTC-USD', 'changes': [['buy', '38277.31', '0.01492000']], 'time': '2021-05-20T03:54:59.963861Z'}
{'type': 'l2update', 'product_id': 'BTC-USD', 'changes': [['sell', '38286.75', '0.00000000']], 'time': '2021-05-20T03:54:59.968459Z'}
{'type': 'l2update', 'product_id': 'BTC-USD', 'changes': [['buy', '38276.98', '0.00000000']], 'time': '2021-05-20T03:54:59.970178Z'}
{'type': 'l2update', 'product_id': 'BTC-USD', 'changes': [['buy', '38239.95', '0.00000000']], 'time': '2021-05-20T03:54:59.970745Z'}
{'type': 'l2update', 'product_id': 'BTC-USD', 'changes': [['buy', '38261.89', '0.00000000']], 'time': '2021-05-20T03:54:59.974248Z'}
{'type': 'l2update', 'product_id': 'BTC-USD', 'changes': [['buy', '38241.61', '1.23327915']], 'time': '2021-05-20T03:54:59.975416Z'}
{'type': 'l2update', 'product_id': 'BTC-USD', 'changes': [['buy', '38277.31', '0.00000000']], 'time': '2021-05-20T03:54:59.976480Z'}
{'type': 'l2update', 'product_id': 'BTC-USD', 'changes': [['buy', '38261.79', '0.12000000']], 'time': '2021-05-20T03:54:59.977924Z'}
{'type': 'l2update', 'product_id': 'BTC-USD', 'changes': [['buy', '38261.79', '0.09000000']], 'time': '2021-05-20T03:54:59.981513Z'}
{'type': 'l2update', 'product_id': 'BTC-USD', 'changes': [['sell', '38286.31', '0.00000000']], 'time': '2021-05-20T03:54:59.982345Z'}
{'type': 'l2update', 'product_id': 'BTC-USD', 'changes': [['sell', '38285.76', '0.01492000']], 'time': '2021-05-20T03:54:59.983672Z'}
{'type': 'l2update', 'product_id': 'BTC-USD', 'changes': [['buy', '38261.79', '0.05000000']], 'time': '2021-05-20T03:54:59.985188Z'}
{'type': 'l2update', 'product_id': 'BTC-USD', 'changes': [['buy', '38276.65', '0.07460000']], 'time': '2021-05-20T03:54:59.987273Z'}
{'type': 'l2update', 'product_id': 'BTC-USD', 'changes': [['buy', '38261.79', '0.00000000']], 'time': '2021-05-20T03:54:59.989402Z'}
{'type': 'l2update', 'product_id': 'BTC-USD', 'changes': [['sell', '38388.69', '0.00000000']], 'time': '2021-05-20T03:54:59.994386Z'}
{'type': 'l2update', 'product_id': 'BTC-USD', 'changes': [['sell', '38287.48', '0.07460000']], 'time': '2021-05-20T03:54:59.996116Z'}
{'type': 'l2update', 'product_id': 'BTC-USD', 'changes': [['buy', '38276.64', '0.01492000']], 'time': '2021-05-20T03:54:59.996238Z'}
{'type': 'l2update', 'product_id': 'BTC-USD', 'changes': [['buy', '38240.43', '0.01000000']], 'time': '2021-05-20T03:55:00.000097Z'}
{'type': 'l2update', 'product_id': 'BTC-USD', 'changes': [['sell', '38291.15', '0.54800000']], 'time': '2021-05-20T03:55:00.000118Z'}
{'type': 'l2update', 'product_id': 'BTC-USD', 'changes': [['sell', '38287.48', '0.00000000']], 'time': '2021-05-20T03:55:00.000905Z'}
{'type': 'l2update', 'product_id': 'BTC-USD', 'changes': [['sell', '38285.76', '0.00000000']], 'time': '2021-05-20T03:55:00.001643Z'}
{'type': 'l2update', 'product_id': 'BTC-USD', 'changes': [['sell', '38287.75', '0.00000000']], 'time': '2021-05-20T03:55:00.003295Z'}
{'type': 'l2update', 'product_id': 'BTC-USD', 'changes': [['sell', '38375.73', '0.01302906']], 'time': '2021-05-20T03:55:00.003862Z'}
{'type': 'l2update', 'product_id': 'BTC-USD', 'changes': [['buy', '38276.64', '0.00000000']], 'time': '2021-05-20T03:55:00.008722Z'}
{'type': 'l2update', 'product_id': 'BTC-USD', 'changes': [['buy', '38235.48', '0.02000000']], 'time': '2021-05-20T03:55:00.012831Z'}
{'type': 'l2update', 'product_id': 'BTC-USD', 'changes': [['sell', '38287.40', '0.07460000']], 'time': '2021-05-20T03:55:00.014969Z'}
{'type': 'l2update', 'product_id': 'BTC-USD', 'changes': [['sell', '38287.15', '0.01492000']], 'time': '2021-05-20T03:55:00.015152Z'}
{'type': 'l2update', 'product_id': 'BTC-USD', 'changes': [['sell', '38494.63', '0.00000000']], 'time': '2021-05-20T03:55:00.017139Z'}
{'type': 'l2update', 'product_id': 'BTC-USD', 'changes': [['sell', '38287.40', '0.00000000']], 'time': '2021-05-20T03:55:00.021486Z'}
{'type': 'l2update', 'product_id': 'BTC-USD', 'changes': [['sell', '38287.75', '0.47369029']], 'time': '2021-05-20T03:55:00.023550Z'}
{'type': 'l2update', 'product_id': 'BTC-USD', 'changes': [['buy', '38234.21', '0.03000000']], 'time': '2021-05-20T03:55:00.023742Z'}
{'type': 'l2update', 'product_id': 'BTC-USD', 'changes': [['buy', '38189.81', '0.00000000']], 'time': '2021-05-20T03:55:00.026124Z'}
{'type': 'l2update', 'product_id': 'BTC-USD', 'changes': [['buy', '38276.92', '0.01492000']], 'time': '2021-05-20T03:55:00.026926Z'}
{'type': 'l2update', 'product_id': 'BTC-USD', 'changes': [['buy', '38181.25', '0.01000000']], 'time': '2021-05-20T03:55:00.037426Z'}
{'type': 'l2update', 'product_id': 'BTC-USD', 'changes': [['buy', '38232.78', '0.04000000']], 'time': '2021-05-20T03:55:00.037537Z'}
{'type': 'l2update', 'product_id': 'BTC-USD', 'changes': [['sell', '38501.38', '0.00000000']], 'time': '2021-05-20T03:55:00.040831Z'}
{'type': 'l2update', 'product_id': 'BTC-USD', 'changes': [['sell', '38472.30', '0.01000000']], 'time': '2021-05-20T03:55:00.041093Z'}
{'type': 'l2update', 'product_id': 'BTC-USD', 'changes': [['sell', '53012.87', '0.00245500']], 'time': '2021-05-20T03:55:00.041691Z'}
{'type': 'l2update', 'product_id': 'BTC-USD', 'changes': [['buy', '38181.25', '0.00000000']], 'time': '2021-05-20T03:55:00.048727Z'}
{'type': 'l2update', 'product_id': 'BTC-USD', 'changes': [['buy', '38267.83', '0.00000000']], 'time': '2021-05-20T03:55:00.048776Z'}
{'type': 'l2update', 'product_id': 'BTC-USD', 'changes': [['buy', '38232.78', '0.09000000']], 'time': '2021-05-20T03:55:00.048877Z'}
{'type': 'l2update', 'product_id': 'BTC-USD', 'changes': [['buy', '38276.65', '0.00000000']], 'time': '2021-05-20T03:55:00.058193Z'}
{'type': 'l2update', 'product_id': 'BTC-USD', 'changes': [['buy', '38261.94', '0.00000000']], 'time': '2021-05-20T03:55:00.059960Z'}
{'type': 'l2update', 'product_id': 'BTC-USD', 'changes': [['sell', '38494.68', '0.00649440']], 'time': '2021-05-20T03:55:00.060960Z'}
{'type': 'l2update', 'product_id': 'BTC-USD', 'changes': [['sell', '38286.73', '0.07460000']], 'time': '2021-05-20T03:55:00.064911Z'}
{'type': 'l2update', 'product_id': 'BTC-USD', 'changes': [['buy', '38269.68', '0.58716278']], 'time': '2021-05-20T03:55:00.068624Z'}
{'type': 'l2update', 'product_id': 'BTC-USD', 'changes': [['sell', '38287.15', '0.00000000']], 'time': '2021-05-20T03:55:00.072391Z'}
{'type': 'l2update', 'product_id': 'BTC-USD', 'changes': [['buy', '38154.62', '0.01000000']], 'time': '2021-05-20T03:55:00.072426Z'}
{'type': 'l2update', 'product_id': 'BTC-USD', 'changes': [['buy', '38259.44', '0.02400000']], 'time': '2021-05-20T03:55:00.072541Z'}
{'type': 'l2update', 'product_id': 'BTC-USD', 'changes': [['buy', '38267.92', '0.00000000']], 'time': '2021-05-20T03:55:00.075387Z'}
{'type': 'l2update', 'product_id': 'BTC-USD', 'changes': [['buy', '38277.42', '0.07460000']], 'time': '2021-05-20T03:55:00.076235Z'}
{'type': 'l2update', 'product_id': 'BTC-USD', 'changes': [['sell', '38472.30', '0.00000000']], 'time': '2021-05-20T03:55:00.081862Z'}
{'type': 'l2update', 'product_id': 'BTC-USD', 'changes': [['buy', '38276.92', '0.00000000']], 'time': '2021-05-20T03:55:00.083699Z'}
{'type': 'l2update', 'product_id': 'BTC-USD', 'changes': [['buy', '38116.54', '0.05009675']], 'time': '2021-05-20T03:55:00.086023Z'}
{'type': 'l2update', 'product_id': 'BTC-USD', 'changes': [['sell', '38440.40', '0.00000000']], 'time': '2021-05-20T03:55:00.088255Z'}
{'type': 'l2update', 'product_id': 'BTC-USD', 'changes': [['sell', '38286.10', '0.01492000']], 'time': '2021-05-20T03:55:00.091336Z'}
{'type': 'l2update', 'product_id': 'BTC-USD', 'changes': [['buy', '38277.42', '0.00000000']], 'time': '2021-05-20T03:55:00.091360Z'}
{'type': 'l2update', 'product_id': 'BTC-USD', 'changes': [['buy', '38269.69', '0.11747527']], 'time': '2021-05-20T03:55:00.094715Z'}
{'type': 'l2update', 'product_id': 'BTC-USD', 'changes': [['sell', '38286.73', '0.00000000']], 'time': '2021-05-20T03:55:00.097182Z'}
{'type': 'l2update', 'product_id': 'BTC-USD', 'changes': [['buy', '38277.76', '0.01492000']], 'time': '2021-05-20T03:55:00.099532Z'}
{'type': 'l2update', 'product_id': 'BTC-USD', 'changes': [['buy', '38276.55', '0.07460000']], 'time': '2021-05-20T03:55:00.102897Z'}
{'type': 'l2update', 'product_id': 'BTC-USD', 'changes': [['buy', '38277.76', '0.00000000']], 'time': '2021-05-20T03:55:00.104412Z'}
{'type': 'l2update', 'product_id': 'BTC-USD', 'changes': [['sell', '38286.10', '0.00000000']], 'time': '2021-05-20T03:55:00.106425Z'}
{'type': 'l2update', 'product_id': 'BTC-USD', 'changes': [['buy', '38276.55', '0.00000000']], 'time': '2021-05-20T03:55:00.107614Z'}
{'type': 'l2update', 'product_id': 'BTC-USD', 'changes': [['sell', '38436.90', '0.01000000']], 'time': '2021-05-20T03:55:00.111544Z'}
{'type': 'l2update', 'product_id': 'BTC-USD', 'changes': [['sell', '38420.93', '0.01000000']], 'time': '2021-05-20T03:55:00.111585Z'}
{'type': 'l2update', 'product_id': 'BTC-USD', 'changes': [['sell', '38285.54', '0.03951301']], 'time': '2021-05-20T03:55:00.111670Z'}
{'type': 'l2update', 'product_id': 'BTC-USD', 'changes': [['sell', '38285.54', '0.04919626']], 'time': '2021-05-20T03:55:00.116330Z'}
{'type': 'l2update', 'product_id': 'BTC-USD', 'changes': [['buy', '38277.11', '0.01492000']], 'time': '2021-05-20T03:55:00.116462Z'}
{'type': 'l2update', 'product_id': 'BTC-USD', 'changes': [['sell', '38322.51', '0.01000000']], 'time': '2021-05-20T03:55:00.116483Z'}
{'type': 'l2update', 'product_id': 'BTC-USD', 'changes': [['sell', '38285.54', '0.00968325']], 'time': '2021-05-20T03:55:00.117694Z'}
{'type': 'l2update', 'product_id': 'BTC-USD', 'changes': [['sell', '38287.49', '0.01492000']], 'time': '2021-05-20T03:55:00.121097Z'}
{'type': 'l2update', 'product_id': 'BTC-USD', 'changes': [['sell', '38285.54', '0.00000000']], 'time': '2021-05-20T03:55:00.121317Z'}
{'type': 'l2update', 'product_id': 'BTC-USD', 'changes': [['sell', '38285.54', '0.02540374']], 'time': '2021-05-20T03:55:00.124110Z'}
{'type': 'l2update', 'product_id': 'BTC-USD', 'changes': [['buy', '38277.11', '0.00000000']], 'time': '2021-05-20T03:55:00.124231Z'}
{'type': 'l2update', 'product_id': 'BTC-USD', 'changes': [['sell', '38287.49', '0.00000000']], 'time': '2021-05-20T03:55:00.126085Z'}
{'type': 'l2update', 'product_id': 'BTC-USD', 'changes': [['buy', '38240.20', '0.01000000']], 'time': '2021-05-20T03:55:00.128362Z'}
{'type': 'l2update', 'product_id': 'BTC-USD', 'changes': [['buy', '38241.61', '1.20000000']], 'time': '2021-05-20T03:55:00.130313Z'}
{'type': 'l2update', 'product_id': 'BTC-USD', 'changes': [['sell', '38285.54', '0.00000000']], 'time': '2021-05-20T03:55:00.130910Z'}
{'type': 'l2update', 'product_id': 'BTC-USD', 'changes': [['sell', '38286.93', '0.03951301']], 'time': '2021-05-20T03:55:00.132221Z'}
{'type': 'l2update', 'product_id': 'BTC-USD', 'changes': [['buy', '38238.94', '0.03327915']], 'time': '2021-05-20T03:55:00.132298Z'}
{'type': 'l2update', 'product_id': 'BTC-USD', 'changes': [['sell', '38291.15', '1.54800000']], 'time': '2021-05-20T03:55:00.136768Z'}
{'type': 'l2update', 'product_id': 'BTC-USD', 'changes': [['buy', '38276.66', '0.07460000']], 'time': '2021-05-20T03:55:00.137071Z'}
{'type': 'l2update', 'product_id': 'BTC-USD', 'changes': [['sell', '38285.11', '0.01492000']], 'time': '2021-05-20T03:55:00.140466Z'}
{'type': 'l2update', 'product_id': 'BTC-USD', 'changes': [['sell', '38286.93', '0.04919626']], 'time': '2021-05-20T03:55:00.140524Z'}
{'type': 'l2update', 'product_id': 'BTC-USD', 'changes': [['buy', '38276.42', '0.01492000']], 'time': '2021-05-20T03:55:00.140622Z'}
{'type': 'l2update', 'product_id': 'BTC-USD', 'changes': [['buy', '38241.61', '0.00000000']], 'time': '2021-05-20T03:55:00.140757Z'}
{'type': 'l2update', 'product_id': 'BTC-USD', 'changes': [['buy', '38276.66', '0.00000000']], 'time': '2021-05-20T03:55:00.143139Z'}
{'type': 'l2update', 'product_id': 'BTC-USD', 'changes': [['sell', '38286.93', '0.07460000']], 'time': '2021-05-20T03:55:00.144996Z'}
{'type': 'l2update', 'product_id': 'BTC-USD', 'changes': [['sell', '38285.11', '0.00000000']], 'time': '2021-05-20T03:55:00.145059Z'}
{'type': 'l2update', 'product_id': 'BTC-USD', 'changes': [['sell', '38376.47', '0.00000000']], 'time': '2021-05-20T03:55:00.145851Z'}
{'type': 'l2update', 'product_id': 'BTC-USD', 'changes': [['sell', '38286.93', '0.06491675']], 'time': '2021-05-20T03:55:00.145940Z'}
{'type': 'l2update', 'product_id': 'BTC-USD', 'changes': [['sell', '38286.93', '0.02540374']], 'time': '2021-05-20T03:55:00.146233Z'}
{'type': 'l2update', 'product_id': 'BTC-USD', 'changes': [['buy', '37501.01', '0.00140000']], 'time': '2021-05-20T03:55:00.148549Z'}
{'type': 'l2update', 'product_id': 'BTC-USD', 'changes': [['buy', '38276.42', '0.00000000']], 'time': '2021-05-20T03:55:00.149404Z'}
{'type': 'l2update', 'product_id': 'BTC-USD', 'changes': [['sell', '38286.93', '0.00000000']], 'time': '2021-05-20T03:55:00.149500Z'}
{'type': 'l2update', 'product_id': 'BTC-USD', 'changes': [['buy', '38239.95', '0.03327915']], 'time': '2021-05-20T03:55:00.153737Z'}
{'type': 'l2update', 'product_id': 'BTC-USD', 'changes': [['buy', '37500.01', '0.20190000']], 'time': '2021-05-20T03:55:00.154274Z'}
{'type': 'l2update', 'product_id': 'BTC-USD', 'changes': [['sell', '38303.32', '0.00000000']], 'time': '2021-05-20T03:55:00.154569Z'}
{'type': 'l2update', 'product_id': 'BTC-USD', 'changes': [['buy', '38276.74', '0.07460000']], 'time': '2021-05-20T03:55:00.158231Z'}
{'type': 'l2update', 'product_id': 'BTC-USD', 'changes': [['sell', '38286.58', '0.01492000']], 'time': '2021-05-20T03:55:00.158350Z'}
{'type': 'l2update', 'product_id': 'BTC-USD', 'changes': [['sell', '38291.15', '1.00000000']], 'time': '2021-05-20T03:55:00.161137Z'}
{'type': 'l2update', 'product_id': 'BTC-USD', 'changes': [['sell', '38287.40', '0.07460000']], 'time': '2021-05-20T03:55:00.162380Z'}
{'type': 'l2update', 'product_id': 'BTC-USD', 'changes': [['buy', '38276.48', '0.01492000']], 'time': '2021-05-20T03:55:00.162400Z'}
{'type': 'l2update', 'product_id': 'BTC-USD', 'changes': [['sell', '38291.15', '0.00000000']], 'time': '2021-05-20T03:55:00.165010Z'}
{'type': 'l2update', 'product_id': 'BTC-USD', 'changes': [['buy', '38238.94', '0.00000000']], 'time': '2021-05-20T03:55:00.166877Z'}
{'type': 'l2update', 'product_id': 'BTC-USD', 'changes': [['sell', '38286.58', '0.00000000']], 'time': '2021-05-20T03:55:00.167896Z'}
{'type': 'l2update', 'product_id': 'BTC-USD', 'changes': [['sell', '38287.40', '0.00000000']], 'time': '2021-05-20T03:55:00.168160Z'}
{'type': 'l2update', 'product_id': 'BTC-USD', 'changes': [['buy', '38276.48', '0.00000000']], 'time': '2021-05-20T03:55:00.168647Z'}
{'type': 'l2update', 'product_id': 'BTC-USD', 'changes': [['sell', '38287.75', '0.00000000']], 'time': '2021-05-20T03:55:00.169567Z'}
{'type': 'l2update', 'product_id': 'BTC-USD', 'changes': [['buy', '38239.95', '0.00000000']], 'time': '2021-05-20T03:55:00.171130Z'}
{'type': 'l2update', 'product_id': 'BTC-USD', 'changes': [['sell', '38309.59', '0.03000000']], 'time': '2021-05-20T03:55:00.171841Z'}
{'type': 'l2update', 'product_id': 'BTC-USD', 'changes': [['sell', '38311.70', '0.00000000']], 'time': '2021-05-20T03:55:00.172860Z'}
{'type': 'l2update', 'product_id': 'BTC-USD', 'changes': [['buy', '38006.35', '0.00000000']], 'time': '2021-05-20T03:55:00.177295Z'}
{'type': 'l2update', 'product_id': 'BTC-USD', 'changes': [['sell', '38296.46', '0.00000000']], 'time': '2021-05-20T03:55:00.183230Z'}
{'type': 'l2update', 'product_id': 'BTC-USD', 'changes': [['sell', '38287.12', '0.01492000']], 'time': '2021-05-20T03:55:00.183244Z'}
{'type': 'l2update', 'product_id': 'BTC-USD', 'changes': [['sell', '38287.35', '0.07460000']], 'time': '2021-05-20T03:55:00.183427Z'}
{'type': 'l2update', 'product_id': 'BTC-USD', 'changes': [['buy', '38238.95', '0.03327915']], 'time': '2021-05-20T03:55:00.183594Z'}
{'type': 'l2update', 'product_id': 'BTC-USD', 'changes': [['sell', '38287.35', '0.00000000']], 'time': '2021-05-20T03:55:00.189106Z'}
{'type': 'l2update', 'product_id': 'BTC-USD', 'changes': [['sell', '38287.75', '0.47369029']], 'time': '2021-05-20T03:55:00.200350Z'}
{'type': 'l2update', 'product_id': 'BTC-USD', 'changes': [['buy', '38019.23', '0.13151236']], 'time': '2021-05-20T03:55:00.200571Z'}
{'type': 'l2update', 'product_id': 'BTC-USD', 'changes': [['buy', '38277.21', '0.01492000']], 'time': '2021-05-20T03:55:00.200688Z'}
{'type': 'l2update', 'product_id': 'BTC-USD', 'changes': [['buy', '38226.55', '0.00000000']], 'time': '2021-05-20T03:55:00.204069Z'}
{'type': 'l2update', 'product_id': 'BTC-USD', 'changes': [['sell', '53098.74', '0.00173600']], 'time': '2021-05-20T03:55:00.208301Z'}
{'type': 'l2update', 'product_id': 'BTC-USD', 'changes': [['buy', '38276.74', '0.00000000']], 'time': '2021-05-20T03:55:00.208611Z'}
{'type': 'l2update', 'product_id': 'BTC-USD', 'changes': [['sell', '38305.00', '0.00000000']], 'time': '2021-05-20T03:55:00.210038Z'}
{'type': 'l2update', 'product_id': 'BTC-USD', 'changes': [['sell', '43100.00', '1.09530000']], 'time': '2021-05-20T03:55:00.214938Z'}
{'type': 'l2update', 'product_id': 'BTC-USD', 'changes': [['buy', '38227.55', '0.10000000']], 'time': '2021-05-20T03:55:00.215523Z'}
{'type': 'l2update', 'product_id': 'BTC-USD', 'changes': [['sell', '38312.00', '0.04000000']], 'time': '2021-05-20T03:55:00.226495Z'}
{'type': 'l2update', 'product_id': 'BTC-USD', 'changes': [['buy', '38277.88', '0.07460000']], 'time': '2021-05-20T03:55:00.226667Z'}
{'type': 'l2update', 'product_id': 'BTC-USD', 'changes': [['buy', '38277.21', '0.00000000']], 'time': '2021-05-20T03:55:00.232671Z'}
{'type': 'l2update', 'product_id': 'BTC-USD', 'changes': [['buy', '38262.44', '0.00000000']], 'time': '2021-05-20T03:55:00.237164Z'}
{'type': 'l2update', 'product_id': 'BTC-USD', 'changes': [['buy', '38262.72', '0.00000000']], 'time': '2021-05-20T03:55:00.237381Z'}
{'type': 'l2update', 'product_id': 'BTC-USD', 'changes': [['sell', '43100.00', '2.29240000']], 'time': '2021-05-20T03:55:00.237976Z'}
{'type': 'l2update', 'product_id': 'BTC-USD', 'changes': [['buy', '38277.22', '0.26100000']], 'time': '2021-05-20T03:55:00.242336Z'}
{'type': 'l2update', 'product_id': 'BTC-USD', 'changes': [['buy', '38238.95', '0.00000000']], 'time': '2021-05-20T03:55:00.244000Z'}
{'type': 'l2update', 'product_id': 'BTC-USD', 'changes': [['sell', '38436.90', '0.00000000']], 'time': '2021-05-20T03:55:00.244158Z'}
{'type': 'l2update', 'product_id': 'BTC-USD', 'changes': [['sell', '38391.78', '0.00000000']], 'time': '2021-05-20T03:55:00.250517Z'}
{'type': 'l2update', 'product_id': 'BTC-USD', 'changes': [['buy', '38269.69', '0.00000000']], 'time': '2021-05-20T03:55:00.250545Z'}
{'type': 'l2update', 'product_id': 'BTC-USD', 'changes': [['buy', '38239.95', '0.03327915']], 'time': '2021-05-20T03:55:00.255069Z'}
{'type': 'l2update', 'product_id': 'BTC-USD', 'changes': [['sell', '38293.71', '0.52260582']], 'time': '2021-05-20T03:55:00.258812Z'}
{'type': 'l2update', 'product_id': 'BTC-USD', 'changes': [['buy', '38278.51', '0.01492000']], 'time': '2021-05-20T03:55:00.273107Z'}
{'type': 'l2update', 'product_id': 'BTC-USD', 'changes': [['sell', '38423.84', '0.01000000']], 'time': '2021-05-20T03:55:00.273251Z'}
{'type': 'l2update', 'product_id': 'BTC-USD', 'changes': [['buy', '38269.69', '0.11747527']], 'time': '2021-05-20T03:55:00.273309Z'}
{'type': 'l2update', 'product_id': 'BTC-USD', 'changes': [['buy', '38270.16', '0.52259712']], 'time': '2021-05-20T03:55:00.273346Z'}
{'type': 'l2update', 'product_id': 'BTC-USD', 'changes': [['sell', '38403.76', '0.01000000']], 'time': '2021-05-20T03:55:00.277493Z'}
{'type': 'l2update', 'product_id': 'BTC-USD', 'changes': [['sell', '38298.81', '0.06046106']], 'time': '2021-05-20T03:55:00.277672Z'}
{'type': 'l2update', 'product_id': 'BTC-USD', 'changes': [['buy', '38277.88', '0.00000000']], 'time': '2021-05-20T03:55:00.279942Z'}
{'type': 'l2update', 'product_id': 'BTC-USD', 'changes': [['buy', '38251.07', '0.00000000']], 'time': '2021-05-20T03:55:00.282558Z'}
{'type': 'l2update', 'product_id': 'BTC-USD', 'changes': [['sell', '38297.11', '0.99800000']], 'time': '2021-05-20T03:55:00.283391Z'}
{'type': 'l2update', 'product_id': 'BTC-USD', 'changes': [['sell', '38325.55', '0.00000000']], 'time': '2021-05-20T03:55:00.285524Z'}
{'type': 'l2update', 'product_id': 'BTC-USD', 'changes': [['buy', '38219.06', '0.00000000']], 'time': '2021-05-20T03:55:00.290034Z'}
{'type': 'l2update', 'product_id': 'BTC-USD', 'changes': [['buy', '38277.23', '0.05000000']], 'time': '2021-05-20T03:55:00.296500Z'}
{'type': 'l2update', 'product_id': 'BTC-USD', 'changes': [['sell', '38332.48', '0.00000000']], 'time': '2021-05-20T03:55:00.298872Z'}
{'type': 'l2update', 'product_id': 'BTC-USD', 'changes': [['buy', '38232.78', '0.05000000']], 'time': '2021-05-20T03:55:00.300153Z'}
{'type': 'l2update', 'product_id': 'BTC-USD', 'changes': [['buy', '38278.51', '0.00000000']], 'time': '2021-05-20T03:55:00.300214Z'}
{'type': 'l2update', 'product_id': 'BTC-USD', 'changes': [['buy', '38278.93', '0.07460000']], 'time': '2021-05-20T03:55:00.300621Z'}
{'type': 'l2update', 'product_id': 'BTC-USD', 'changes': [['sell', '38403.76', '0.00000000']], 'time': '2021-05-20T03:55:00.301385Z'}
{'type': 'l2update', 'product_id': 'BTC-USD', 'changes': [['sell', '38305.15', '0.00000000']], 'time': '2021-05-20T03:55:00.301412Z'}
{'type': 'l2update', 'product_id': 'BTC-USD', 'changes': [['buy', '38232.78', '0.00000000']], 'time': '2021-05-20T03:55:00.304841Z'}
{'type': 'l2update', 'product_id': 'BTC-USD', 'changes': [['buy', '38277.23', '0.15000000']], 'time': '2021-05-20T03:55:00.305469Z'}
{'type': 'l2update', 'product_id': 'BTC-USD', 'changes': [['buy', '38278.93', '0.00000000']], 'time': '2021-05-20T03:55:00.306711Z'}
{'type': 'l2update', 'product_id': 'BTC-USD', 'changes': [['buy', '38277.22', '0.00000000']], 'time': '2021-05-20T03:55:00.313053Z'}
{'type': 'l2update', 'product_id': 'BTC-USD', 'changes': [['sell', '38287.83', '0.00000000']], 'time': '2021-05-20T03:55:00.315925Z'}
{'type': 'l2update', 'product_id': 'BTC-USD', 'changes': [['sell', '38298.35', '0.00000000']], 'time': '2021-05-20T03:55:00.317818Z'}
{'type': 'l2update', 'product_id': 'BTC-USD', 'changes': [['buy', '38241.61', '1.20000000']], 'time': '2021-05-20T03:55:00.318502Z'}
{'type': 'l2update', 'product_id': 'BTC-USD', 'changes': [['buy', '38269.69', '0.00000000']], 'time': '2021-05-20T03:55:00.319867Z'}
{'type': 'l2update', 'product_id': 'BTC-USD', 'changes': [['buy', '38276.03', '0.10000000']], 'time': '2021-05-20T03:55:00.319887Z'}
{'type': 'l2update', 'product_id': 'BTC-USD', 'changes': [['sell', '38297.11', '0.00000000']], 'time': '2021-05-20T03:55:00.321650Z'}
{'type': 'l2update', 'product_id': 'BTC-USD', 'changes': [['buy', '38265.05', '0.00000000']], 'time': '2021-05-20T03:55:00.323188Z'}
{'type': 'l2update', 'product_id': 'BTC-USD', 'changes': [['sell', '38373.43', '0.00000000']], 'time': '2021-05-20T03:55:00.326964Z'}
{'type': 'l2update', 'product_id': 'BTC-USD', 'changes': [['sell', '38360.82', '0.00000000']], 'time': '2021-05-20T03:55:00.328277Z'}
{'type': 'l2update', 'product_id': 'BTC-USD', 'changes': [['sell', '38287.76', '0.00000000']], 'time': '2021-05-20T03:55:00.334832Z'}
{'type': 'l2update', 'product_id': 'BTC-USD', 'changes': [['sell', '38287.75', '0.00000000']], 'time': '2021-05-20T03:55:00.340631Z'}
{'type': 'l2update', 'product_id': 'BTC-USD', 'changes': [['sell', '38319.67', '0.03196232']], 'time': '2021-05-20T03:55:00.342542Z'}
{'type': 'l2update', 'product_id': 'BTC-USD', 'changes': [['buy', '38166.97', '0.00000000']], 'time': '2021-05-20T03:55:00.342542Z'}
{'type': 'l2update', 'product_id': 'BTC-USD', 'changes': [['sell', '38316.93', '0.00000000']], 'time': '2021-05-20T03:55:00.350586Z'}
{'type': 'l2update', 'product_id': 'BTC-USD', 'changes': [['sell', '38322.51', '0.00000000']], 'time': '2021-05-20T03:55:00.353516Z'}
{'type': 'l2update', 'product_id': 'BTC-USD', 'changes': [['buy', '38240.20', '0.00000000']], 'time': '2021-05-20T03:55:00.356778Z'}
{'type': 'l2update', 'product_id': 'BTC-USD', 'changes': [['sell', '38402.73', '0.00000000']], 'time': '2021-05-20T03:55:00.375617Z'}
{'type': 'l2update', 'product_id': 'BTC-USD', 'changes': [['buy', '38227.39', '0.00000000']], 'time': '2021-05-20T03:55:00.375617Z'}
{'type': 'l2update', 'product_id': 'BTC-USD', 'changes': [['buy', '38268.15', '0.16500000']], 'time': '2021-05-20T03:55:00.376893Z'}
{'type': 'l2update', 'product_id': 'BTC-USD', 'changes': [['sell', '38429.60', '0.01000000']], 'time': '2021-05-20T03:55:00.377022Z'}
{'type': 'l2update', 'product_id': 'BTC-USD', 'changes': [['buy', '38279.36', '0.01492000']], 'time': '2021-05-20T03:55:00.377041Z'}
{'type': 'l2update', 'product_id': 'BTC-USD', 'changes': [['buy', '38238.99', '0.04000000']], 'time': '2021-05-20T03:55:00.377204Z'}
{'type': 'l2update', 'product_id': 'BTC-USD', 'changes': [['sell', '38306.32', '0.49490000']], 'time': '2021-05-20T03:55:00.377249Z'}
{'type': 'l2update', 'product_id': 'BTC-USD', 'changes': [['buy', '38277.52', '0.07460000']], 'time': '2021-05-20T03:55:00.377335Z'}
{'type': 'l2update', 'product_id': 'BTC-USD', 'changes': [['buy', '38277.37', '0.26100000']], 'time': '2021-05-20T03:55:00.380649Z'}
{'type': 'l2update', 'product_id': 'BTC-USD', 'changes': [['buy', '38279.36', '0.00000000']], 'time': '2021-05-20T03:55:00.382306Z'}
{'type': 'l2update', 'product_id': 'BTC-USD', 'changes': [['buy', '38256.09', '0.00000000']], 'time': '2021-05-20T03:55:00.382741Z'}
{'type': 'l2update', 'product_id': 'BTC-USD', 'changes': [['buy', '38277.52', '0.00000000']], 'time': '2021-05-20T03:55:00.383787Z'}
{'type': 'l2update', 'product_id': 'BTC-USD', 'changes': [['buy', '38277.23', '0.05000000']], 'time': '2021-05-20T03:55:00.389680Z'}
{'type': 'l2update', 'product_id': 'BTC-USD', 'changes': [['buy', '38277.37', '0.00000000']], 'time': '2021-05-20T03:55:00.391061Z'}
{'type': 'l2update', 'product_id': 'BTC-USD', 'changes': [['buy', '38193.19', '0.03545956']], 'time': '2021-05-20T03:55:00.394113Z'}
{'type': 'l2update', 'product_id': 'BTC-USD', 'changes': [['sell', '38341.08', '0.02608169']], 'time': '2021-05-20T03:55:00.394167Z'}
{'type': 'l2update', 'product_id': 'BTC-USD', 'changes': [['sell', '38324.94', '0.01000000']], 'time': '2021-05-20T03:55:00.394245Z'}
{'type': 'l2update', 'product_id': 'BTC-USD', 'changes': [['sell', '38300.94', '0.01677941']], 'time': '2021-05-20T03:55:00.394643Z'}
{'type': 'l2update', 'product_id': 'BTC-USD', 'changes': [['sell', '38291.49', '0.47369029']], 'time': '2021-05-20T03:55:00.394743Z'}
{'type': 'l2update', 'product_id': 'BTC-USD', 'changes': [['buy', '38287.07', '0.15000000']], 'time': '2021-05-20T03:55:00.394955Z'}
{'type': 'l2update', 'product_id': 'BTC-USD', 'changes': [['sell', '38291.19', '2.48969908']], 'time': '2021-05-20T03:55:00.394988Z'}
{'type': 'l2update', 'product_id': 'BTC-USD', 'changes': [['sell', '38419.18', '0.29873726']], 'time': '2021-05-20T03:55:00.395158Z'}
{'type': 'l2update', 'product_id': 'BTC-USD', 'changes': [['sell', '38291.19', '2.98969908']], 'time': '2021-05-20T03:55:00.395254Z'}
{'type': 'l2update', 'product_id': 'BTC-USD', 'changes': [['buy', '38183.37', '0.50000000']], 'time': '2021-05-20T03:55:00.395487Z'}
{'type': 'l2update', 'product_id': 'BTC-USD', 'changes': [['sell', '38376.47', '1.20000000']], 'time': '2021-05-20T03:55:00.395632Z'}
{'type': 'l2update', 'product_id': 'BTC-USD', 'changes': [['buy', '38270.17', '0.11747527']], 'time': '2021-05-20T03:55:00.397974Z'}
{'type': 'l2update', 'product_id': 'BTC-USD', 'changes': [['buy', '38277.99', '0.01492000']], 'time': '2021-05-20T03:55:00.398401Z'}
{'type': 'l2update', 'product_id': 'BTC-USD', 'changes': [['buy', '38255.33', '0.39490431']], 'time': '2021-05-20T03:55:00.398626Z'}
{'type': 'l2update', 'product_id': 'BTC-USD', 'changes': [['buy', '38238.99', '0.09000000']], 'time': '2021-05-20T03:55:00.398748Z'}
{'type': 'l2update', 'product_id': 'BTC-USD', 'changes': [['buy', '38278.05', '0.07460000']], 'time': '2021-05-20T03:55:00.398768Z'}
{'type': 'l2update', 'product_id': 'BTC-USD', 'changes': [['sell', '53102.54', '0.00173600']], 'time': '2021-05-20T03:55:00.399193Z'}
{'type': 'l2update', 'product_id': 'BTC-USD', 'changes': [['buy', '38258.59', '0.45680000']], 'time': '2021-05-20T03:55:00.399592Z'}
{'type': 'l2update', 'product_id': 'BTC-USD', 'changes': [['buy', '38160.92', '0.00000000']], 'time': '2021-05-20T03:55:00.400371Z'}
{'type': 'l2update', 'product_id': 'BTC-USD', 'changes': [['sell', '38378.89', '0.20400000']], 'time': '2021-05-20T03:55:00.403797Z'}
{'type': 'l2update', 'product_id': 'BTC-USD', 'changes': [['buy', '38242.38', '0.06600000']], 'time': '2021-05-20T03:55:00.403797Z'}
{'type': 'l2update', 'product_id': 'BTC-USD', 'changes': [['buy', '38239.95', '0.00000000']], 'time': '2021-05-20T03:55:00.404144Z'}
{'type': 'l2update', 'product_id': 'BTC-USD', 'changes': [['buy', '38207.37', '0.00000000']], 'time': '2021-05-20T03:55:00.405736Z'}
{'type': 'l2update', 'product_id': 'BTC-USD', 'changes': [['sell', '38300.39', '1.01800000']], 'time': '2021-05-20T03:55:00.407561Z'}
{'type': 'l2update', 'product_id': 'BTC-USD', 'changes': [['sell', '38287.12', '0.00000000']], 'time': '2021-05-20T03:55:00.407602Z'}
{'type': 'l2update', 'product_id': 'BTC-USD', 'changes': [['sell', '38309.73', '0.01677941']], 'time': '2021-05-20T03:55:00.407793Z'}
{'type': 'l2update', 'product_id': 'BTC-USD', 'changes': [['sell', '38303.18', '0.00000000']], 'time': '2021-05-20T03:55:00.408444Z'}
{'type': 'l2update', 'product_id': 'BTC-USD', 'changes': [['sell', '38317.69', '0.37486228']], 'time': '2021-05-20T03:55:00.410929Z'}
{'type': 'l2update', 'product_id': 'BTC-USD', 'changes': [['buy', '38277.99', '0.00000000']], 'time': '2021-05-20T03:55:00.412990Z'}
{'type': 'l2update', 'product_id': 'BTC-USD', 'changes': [['buy', '38278.05', '0.00000000']], 'time': '2021-05-20T03:55:00.413258Z'}
{'type': 'l2update', 'product_id': 'BTC-USD', 'changes': [['sell', '38303.82', '0.00000000']], 'time': '2021-05-20T03:55:00.413769Z'}
{'type': 'l2update', 'product_id': 'BTC-USD', 'changes': [['buy', '38277.37', '0.26100000']], 'time': '2021-05-20T03:55:00.415131Z'}
{'type': 'l2update', 'product_id': 'BTC-USD', 'changes': [['buy', '38258.59', '0.00000000']], 'time': '2021-05-20T03:55:00.415872Z'}
{'type': 'l2update', 'product_id': 'BTC-USD', 'changes': [['sell', '38291.20', '0.00000000']], 'time': '2021-05-20T03:55:00.419756Z'}
{'type': 'l2update', 'product_id': 'BTC-USD', 'changes': [['sell', '38304.67', '0.00000000']], 'time': '2021-05-20T03:55:00.429180Z'}
{'type': 'l2update', 'product_id': 'BTC-USD', 'changes': [['sell', '38297.16', '0.00000000']], 'time': '2021-05-20T03:55:00.431056Z'}
{'type': 'l2update', 'product_id': 'BTC-USD', 'changes': [['buy', '38287.11', '0.03000000']], 'time': '2021-05-20T03:55:00.431655Z'}
{'type': 'l2update', 'product_id': 'BTC-USD', 'changes': [['buy', '38276.04', '0.10000000']], 'time': '2021-05-20T03:55:00.431922Z'}
{'type': 'l2update', 'product_id': 'BTC-USD', 'changes': [['sell', '38410.66', '0.03607754']], 'time': '2021-05-20T03:55:00.432181Z'}
{'type': 'l2update', 'product_id': 'BTC-USD', 'changes': [['buy', '38241.62', '0.03327915']], 'time': '2021-05-20T03:55:00.432415Z'}
{'type': 'l2update', 'product_id': 'BTC-USD', 'changes': [['sell', '38324.94', '0.00000000']], 'time': '2021-05-20T03:55:00.432982Z'}
{'type': 'l2update', 'product_id': 'BTC-USD', 'changes': [['buy', '38255.79', '0.00000000']], 'time': '2021-05-20T03:55:00.433137Z'}
{'type': 'l2update', 'product_id': 'BTC-USD', 'changes': [['sell', '38298.81', '0.00000000']], 'time': '2021-05-20T03:55:00.433137Z'}
{'type': 'l2update', 'product_id': 'BTC-USD', 'changes': [['buy', '38287.11', '0.13000000']], 'time': '2021-05-20T03:55:00.433181Z'}
{'type': 'l2update', 'product_id': 'BTC-USD', 'changes': [['sell', '38306.32', '0.00000000']], 'time': '2021-05-20T03:55:00.433704Z'}
{'type': 'l2update', 'product_id': 'BTC-USD', 'changes': [['buy', '38287.83', '0.03000000']], 'time': '2021-05-20T03:55:00.436549Z'}
{'type': 'l2update', 'product_id': 'BTC-USD', 'changes': [['sell', '38417.89', '0.29512205']], 'time': '2021-05-20T03:55:00.436867Z'}
{'type': 'l2update', 'product_id': 'BTC-USD', 'changes': [['sell', '38313.13', '0.05000000']], 'time': '2021-05-20T03:55:00.436914Z'}
{'type': 'l2update', 'product_id': 'BTC-USD', 'changes': [['buy', '38282.41', '0.04869142']], 'time': '2021-05-20T03:55:00.436975Z'}
{'type': 'l2update', 'product_id': 'BTC-USD', 'changes': [['sell', '38300.39', '0.00000000']], 'time': '2021-05-20T03:55:00.437286Z'}
{'type': 'l2update', 'product_id': 'BTC-USD', 'changes': [['sell', '38309.73', '0.00000000']], 'time': '2021-05-20T03:55:00.438271Z'}
{'type': 'l2update', 'product_id': 'BTC-USD', 'changes': [['sell', '38294.61', '0.00000000']], 'time': '2021-05-20T03:55:00.440892Z'}
{'type': 'l2update', 'product_id': 'BTC-USD', 'changes': [['sell', '38291.19', '0.50000000']], 'time': '2021-05-20T03:55:00.441611Z'}
{'type': 'l2update', 'product_id': 'BTC-USD', 'changes': [['sell', '38306.37', '0.00000000']], 'time': '2021-05-20T03:55:00.443260Z'}
{'type': 'l2update', 'product_id': 'BTC-USD', 'changes': [['buy', '38287.83', '0.04492000']], 'time': '2021-05-20T03:55:00.445307Z'}
{'type': 'l2update', 'product_id': 'BTC-USD', 'changes': [['buy', '38287.11', '0.10000000']], 'time': '2021-05-20T03:55:00.445747Z'}
{'type': 'l2update', 'product_id': 'BTC-USD', 'changes': [['buy', '38019.23', '0.00000000']], 'time': '2021-05-20T03:55:00.453004Z'}
{'type': 'l2update', 'product_id': 'BTC-USD', 'changes': [['sell', '38313.14', '0.34367376']], 'time': '2021-05-20T03:55:00.454103Z'}
{'type': 'l2update', 'product_id': 'BTC-USD', 'changes': [['buy', '38220.55', '0.03577500']], 'time': '2021-05-20T03:55:00.455489Z'}
{'type': 'l2update', 'product_id': 'BTC-USD', 'changes': [['buy', '38287.83', '0.11952000']], 'time': '2021-05-20T03:55:00.455700Z'}
{'type': 'l2update', 'product_id': 'BTC-USD', 'changes': [['sell', '38312.44', '0.02000000']], 'time': '2021-05-20T03:55:00.455868Z'}
{'type': 'l2update', 'product_id': 'BTC-USD', 'changes': [['sell', '38291.49', '0.00000000']], 'time': '2021-05-20T03:55:00.459664Z'}
{'type': 'l2update', 'product_id': 'BTC-USD', 'changes': [['buy', '38287.83', '0.14542000']], 'time': '2021-05-20T03:55:00.461447Z'}
{'type': 'l2update', 'product_id': 'BTC-USD', 'changes': [['buy', '38247.70', '0.01000000']], 'time': '2021-05-20T03:55:00.461706Z'}
{'type': 'l2update', 'product_id': 'BTC-USD', 'changes': [['buy', '38241.61', '0.00000000']], 'time': '2021-05-20T03:55:00.462142Z'}
{'type': 'l2update', 'product_id': 'BTC-USD', 'changes': [['sell', '38287.84', '0.00000000']], 'time': '2021-05-20T03:55:00.464055Z'}
{'type': 'l2update', 'product_id': 'BTC-USD', 'changes': [['buy', '38277.24', '0.10000000']], 'time': '2021-05-20T03:55:00.467417Z'}
{'type': 'l2update', 'product_id': 'BTC-USD', 'changes': [['sell', '38291.19', '0.00000000']], 'time': '2021-05-20T03:55:00.468539Z'}
{'type': 'l2update', 'product_id': 'BTC-USD', 'changes': [['sell', '38300.94', '0.00000000']], 'time': '2021-05-20T03:55:00.470239Z'}
{'type': 'l2update', 'product_id': 'BTC-USD', 'changes': [['buy', '38217.28', '0.00000000']], 'time': '2021-05-20T03:55:00.471015Z'}
{'type': 'l2update', 'product_id': 'BTC-USD', 'changes': [['buy', '38084.77', '0.00000000']], 'time': '2021-05-20T03:55:00.475227Z'}
{'type': 'l2update', 'product_id': 'BTC-USD', 'changes': [['sell', '38425.45', '0.32087223']], 'time': '2021-05-20T03:55:00.478404Z'}
{'type': 'l2update', 'product_id': 'BTC-USD', 'changes': [['buy', '38032.11', '0.01162500']], 'time': '2021-05-20T03:55:00.478487Z'}
{'type': 'l2update', 'product_id': 'BTC-USD', 'changes': [['buy', '38287.11', '0.00000000']], 'time': '2021-05-20T03:55:00.478985Z'}
{'type': 'l2update', 'product_id': 'BTC-USD', 'changes': [['sell', '38376.47', '0.00000000']], 'time': '2021-05-20T03:55:00.479944Z'}
{'type': 'l2update', 'product_id': 'BTC-USD', 'changes': [['sell', '38300.38', '2.48969908']], 'time': '2021-05-20T03:55:00.482552Z'}
{'type': 'l2update', 'product_id': 'BTC-USD', 'changes': [['buy', '38224.39', '0.00000000']], 'time': '2021-05-20T03:55:00.482671Z'}
{'type': 'l2update', 'product_id': 'BTC-USD', 'changes': [['buy', '38287.83', '0.07082000']], 'time': '2021-05-20T03:55:00.485125Z'}
{'type': 'l2update', 'product_id': 'BTC-USD', 'changes': [['buy', '38276.03', '0.00000000']], 'time': '2021-05-20T03:55:00.485621Z'}
{'type': 'l2update', 'product_id': 'BTC-USD', 'changes': [['buy', '38287.12', '0.05000000']], 'time': '2021-05-20T03:55:00.486079Z'}
{'type': 'l2update', 'product_id': 'BTC-USD', 'changes': [['sell', '38312.44', '0.03000000']], 'time': '2021-05-20T03:55:00.486130Z'}
{'type': 'l2update', 'product_id': 'BTC-USD', 'changes': [['buy', '38287.83', '0.05590000']], 'time': '2021-05-20T03:55:00.487450Z'}
{'type': 'l2update', 'product_id': 'BTC-USD', 'changes': [['buy', '38270.17', '0.00000000']], 'time': '2021-05-20T03:55:00.491543Z'}
{'type': 'l2update', 'product_id': 'BTC-USD', 'changes': [['buy', '38241.62', '0.00000000']], 'time': '2021-05-20T03:55:00.491731Z'}
{'type': 'l2update', 'product_id': 'BTC-USD', 'changes': [['buy', '38181.61', '0.03497472']], 'time': '2021-05-20T03:55:00.492228Z'}
{'type': 'l2update', 'product_id': 'BTC-USD', 'changes': [['buy', '38187.85', '0.02805188']], 'time': '2021-05-20T03:55:00.492228Z'}
{'type': 'l2update', 'product_id': 'BTC-USD', 'changes': [['buy', '38193.90', '0.02749752']], 'time': '2021-05-20T03:55:00.492228Z'}
{'type': 'l2update', 'product_id': 'BTC-USD', 'changes': [['buy', '38201.33', '0.06886513']], 'time': '2021-05-20T03:55:00.492228Z'}
{'type': 'l2update', 'product_id': 'BTC-USD', 'changes': [['buy', '38235.52', '0.03553200']], 'time': '2021-05-20T03:55:00.492228Z'}
{'type': 'l2update', 'product_id': 'BTC-USD', 'changes': [['buy', '38244.04', '0.03041148']], 'time': '2021-05-20T03:55:00.492228Z'}
{'type': 'l2update', 'product_id': 'BTC-USD', 'changes': [['buy', '38248.02', '0.01198638']], 'time': '2021-05-20T03:55:00.492228Z'}
{'type': 'l2update', 'product_id': 'BTC-USD', 'changes': [['sell', '38291.50', '0.51953231']], 'time': '2021-05-20T03:55:00.492392Z'}
{'type': 'l2update', 'product_id': 'BTC-USD', 'changes': [['sell', '38291.18', '0.47369029']], 'time': '2021-05-20T03:55:00.492711Z'}
{'type': 'l2update', 'product_id': 'BTC-USD', 'changes': [['buy', '38287.08', '0.05000000']], 'time': '2021-05-20T03:55:00.492744Z'}
{'type': 'l2update', 'product_id': 'BTC-USD', 'changes': [['sell', '38322.43', '0.00000000']], 'time': '2021-05-20T03:55:00.495510Z'}
{'type': 'l2update', 'product_id': 'BTC-USD', 'changes': [['buy', '38230.70', '0.02362200']], 'time': '2021-05-20T03:55:00.496804Z'}
{'type': 'l2update', 'product_id': 'BTC-USD', 'changes': [['sell', '38303.18', '0.50000000']], 'time': '2021-05-20T03:55:00.497460Z'}
{'type': 'l2update', 'product_id': 'BTC-USD', 'changes': [['buy', '38276.04', '0.00000000']], 'time': '2021-05-20T03:55:00.499618Z'}
{'type': 'l2update', 'product_id': 'BTC-USD', 'changes': [['sell', '38321.27', '0.00000000']], 'time': '2021-05-20T03:55:00.500043Z'}
{'type': 'l2update', 'product_id': 'BTC-USD', 'changes': [['buy', '38243.46', '0.03327915']], 'time': '2021-05-20T03:55:00.502247Z'}
{'type': 'l2update', 'product_id': 'BTC-USD', 'changes': [['buy', '38143.91', '0.16240000']], 'time': '2021-05-20T03:55:00.508139Z'}
{'type': 'l2update', 'product_id': 'BTC-USD', 'changes': [['buy', '38247.70', '0.00000000']], 'time': '2021-05-20T03:55:00.510538Z'}
{'type': 'l2update', 'product_id': 'BTC-USD', 'changes': [['buy', '38216.57', '0.00000000']], 'time': '2021-05-20T03:55:00.510585Z'}
{'type': 'l2update', 'product_id': 'BTC-USD', 'changes': [['sell', '38319.67', '0.00000000']], 'time': '2021-05-20T03:55:00.512342Z'}
{'type': 'l2update', 'product_id': 'BTC-USD', 'changes': [['buy', '38141.66', '0.00000000']], 'time': '2021-05-20T03:55:00.512342Z'}
{'type': 'l2update', 'product_id': 'BTC-USD', 'changes': [['buy', '38148.27', '0.00000000']], 'time': '2021-05-20T03:55:00.512342Z'}
{'type': 'l2update', 'product_id': 'BTC-USD', 'changes': [['buy', '38153.43', '0.00000000']], 'time': '2021-05-20T03:55:00.512342Z'}
{'type': 'l2update', 'product_id': 'BTC-USD', 'changes': [['buy', '38217.82', '0.00000000']], 'time': '2021-05-20T03:55:00.512342Z'}
{'type': 'l2update', 'product_id': 'BTC-USD', 'changes': [['buy', '38222.55', '0.00000000']], 'time': '2021-05-20T03:55:00.512342Z'}
{'type': 'l2update', 'product_id': 'BTC-USD', 'changes': [['buy', '38231.44', '0.00000000']], 'time': '2021-05-20T03:55:00.512342Z'}
{'type': 'l2update', 'product_id': 'BTC-USD', 'changes': [['buy', '38267.91', '0.00000000']], 'time': '2021-05-20T03:55:00.512857Z'}
{'type': 'l2update', 'product_id': 'BTC-USD', 'changes': [['buy', '38255.33', '0.00000000']], 'time': '2021-05-20T03:55:00.514028Z'}
{'type': 'l2update', 'product_id': 'BTC-USD', 'changes': [['sell', '38341.10', '0.00000000']], 'time': '2021-05-20T03:55:00.514260Z'}
{'type': 'l2update', 'product_id': 'BTC-USD', 'changes': [['buy', '38183.37', '0.00000000']], 'time': '2021-05-20T03:55:00.516679Z'}
{'type': 'l2update', 'product_id': 'BTC-USD', 'changes': [['buy', '38267.50', '0.00000000']], 'time': '2021-05-20T03:55:00.518803Z'}
{'type': 'l2update', 'product_id': 'BTC-USD', 'changes': [['sell', '38425.45', '0.73885914']], 'time': '2021-05-20T03:55:00.524236Z'}
{'type': 'l2update', 'product_id': 'BTC-USD', 'changes': [['sell', '38412.92', '0.00000000']], 'time': '2021-05-20T03:55:00.526919Z'}
{'type': 'l2update', 'product_id': 'BTC-USD', 'changes': [['sell', '38304.96', '0.04807065']], 'time': '2021-05-20T03:55:00.528317Z'}
{'type': 'l2update', 'product_id': 'BTC-USD', 'changes': [['buy', '38287.12', '0.06302911']], 'time': '2021-05-20T03:55:00.528648Z'}
{'type': 'l2update', 'product_id': 'BTC-USD', 'changes': [['buy', '38255.53', '0.00000000']], 'time': '2021-05-20T03:55:00.529678Z'}
{'type': 'l2update', 'product_id': 'BTC-USD', 'changes': [['sell', '38327.82', '0.00000000']], 'time': '2021-05-20T03:55:00.533659Z'}
{'type': 'l2update', 'product_id': 'BTC-USD', 'changes': [['buy', '38276.02', '0.00000000']], 'time': '2021-05-20T03:55:00.535299Z'}
{'type': 'l2update', 'product_id': 'BTC-USD', 'changes': [['buy', '38229.26', '0.05452056']], 'time': '2021-05-20T03:55:00.537701Z'}
{'type': 'l2update', 'product_id': 'BTC-USD', 'changes': [['buy', '37501.01', '0.00000000']], 'time': '2021-05-20T03:55:00.540163Z'}
{'type': 'l2update', 'product_id': 'BTC-USD', 'changes': [['buy', '38243.44', '0.00000000']], 'time': '2021-05-20T03:55:00.540336Z'}
{'type': 'l2update', 'product_id': 'BTC-USD', 'changes': [['sell', '38332.83', '0.01000000']], 'time': '2021-05-20T03:55:00.542470Z'}
{'type': 'l2update', 'product_id': 'BTC-USD', 'changes': [['buy', '38259.05', '0.04896707']], 'time': '2021-05-20T03:55:00.542782Z'}
{'type': 'l2update', 'product_id': 'BTC-USD', 'changes': [['sell', '38305.54', '0.06096641']], 'time': '2021-05-20T03:55:00.542782Z'}
{'type': 'l2update', 'product_id': 'BTC-USD', 'changes': [['buy', '38291.17', '0.01492000']], 'time': '2021-05-20T03:55:00.543022Z'}
{'type': 'l2update', 'product_id': 'BTC-USD', 'changes': [['sell', '38313.14', '0.00000000']], 'time': '2021-05-20T03:55:00.544815Z'}
{'type': 'l2update', 'product_id': 'BTC-USD', 'changes': [['sell', '38297.22', '0.00980503']], 'time': '2021-05-20T03:55:00.547812Z'}
{'type': 'l2update', 'product_id': 'BTC-USD', 'changes': [['sell', '38306.10', '0.01677941']], 'time': '2021-05-20T03:55:00.551419Z'}
{'type': 'l2update', 'product_id': 'BTC-USD', 'changes': [['buy', '38277.42', '0.84700000']], 'time': '2021-05-20T03:55:00.551689Z'}
{'type': 'l2update', 'product_id': 'BTC-USD', 'changes': [['buy', '37500.01', '0.20330000']], 'time': '2021-05-20T03:55:00.551707Z'}
{'type': 'l2update', 'product_id': 'BTC-USD', 'changes': [['buy', '38285.35', '0.20500000']], 'time': '2021-05-20T03:55:00.551740Z'}
{'type': 'l2update', 'product_id': 'BTC-USD', 'changes': [['sell', '38384.64', '0.00000000']], 'time': '2021-05-20T03:55:00.553144Z'}
{'type': 'l2update', 'product_id': 'BTC-USD', 'changes': [['sell', '38332.18', '0.00000000']], 'time': '2021-05-20T03:55:00.556710Z'}
{'type': 'l2update', 'product_id': 'BTC-USD', 'changes': [['buy', '38287.08', '0.00000000']], 'time': '2021-05-20T03:55:00.557247Z'}
{'type': 'l2update', 'product_id': 'BTC-USD', 'changes': [['sell', '38291.50', '0.00000000']], 'time': '2021-05-20T03:55:00.561614Z'}
{'type': 'l2update', 'product_id': 'BTC-USD', 'changes': [['sell', '38300.38', '0.00000000']], 'time': '2021-05-20T03:55:00.561981Z'}
{'type': 'l2update', 'product_id': 'BTC-USD', 'changes': [['sell', '38291.18', '0.00000000']], 'time': '2021-05-20T03:55:00.562330Z'}
{'type': 'l2update', 'product_id': 'BTC-USD', 'changes': [['buy', '38290.01', '0.04804807']], 'time': '2021-05-20T03:55:00.565234Z'}
{'type': 'l2update', 'product_id': 'BTC-USD', 'changes': [['buy', '38267.00', '0.43200000']], 'time': '2021-05-20T03:55:00.565601Z'}
{'type': 'l2update', 'product_id': 'BTC-USD', 'changes': [['buy', '38287.12', '0.16302911']], 'time': '2021-05-20T03:55:00.565691Z'}
{'type': 'l2update', 'product_id': 'BTC-USD', 'changes': [['sell', '38426.09', '0.01000000']], 'time': '2021-05-20T03:55:00.566343Z'}
{'type': 'l2update', 'product_id': 'BTC-USD', 'changes': [['sell', '38317.69', '0.00000000']], 'time': '2021-05-20T03:55:00.566732Z'}
{'type': 'l2update', 'product_id': 'BTC-USD', 'changes': [['buy', '38287.83', '0.03000000']], 'time': '2021-05-20T03:55:00.566880Z'}
{'type': 'l2update', 'product_id': 'BTC-USD', 'changes': [['sell', '38313.13', '0.00000000']], 'time': '2021-05-20T03:55:00.567046Z'}
{'type': 'l2update', 'product_id': 'BTC-USD', 'changes': [['sell', '38332.83', '0.00000000']], 'time': '2021-05-20T03:55:00.567659Z'}
{'type': 'l2update', 'product_id': 'BTC-USD', 'changes': [['buy', '38291.17', '0.04082000']], 'time': '2021-05-20T03:55:00.574814Z'}
{'type': 'l2update', 'product_id': 'BTC-USD', 'changes': [['buy', '38291.17', '0.14082000']], 'time': '2021-05-20T03:55:00.575024Z'}
{'type': 'l2update', 'product_id': 'BTC-USD', 'changes': [['buy', '38277.23', '0.00000000']], 'time': '2021-05-20T03:55:00.575043Z'}
{'type': 'l2update', 'product_id': 'BTC-USD', 'changes': [['sell', '53106.33', '0.00173600']], 'time': '2021-05-20T03:55:00.575824Z'}
{'type': 'l2update', 'product_id': 'BTC-USD', 'changes': [['sell', '38303.18', '0.00000000']], 'time': '2021-05-20T03:55:00.582219Z'}
{'type': 'l2update', 'product_id': 'BTC-USD', 'changes': [['sell', '38303.19', '0.00000000']], 'time': '2021-05-20T03:55:00.582557Z'}
{'type': 'l2update', 'product_id': 'BTC-USD', 'changes': [['buy', '38218.14', '0.00000000']], 'time': '2021-05-20T03:55:00.584941Z'}
{'type': 'l2update', 'product_id': 'BTC-USD', 'changes': [['buy', '38291.17', '0.12590000']], 'time': '2021-05-20T03:55:00.585619Z'}
{'type': 'l2update', 'product_id': 'BTC-USD', 'changes': [['sell', '38365.27', '0.02726322']], 'time': '2021-05-20T03:55:00.586901Z'}
{'type': 'l2update', 'product_id': 'BTC-USD', 'changes': [['sell', '38407.47', '0.01000000']], 'time': '2021-05-20T03:55:00.586917Z'}
{'type': 'l2update', 'product_id': 'BTC-USD', 'changes': [['buy', '38287.83', '0.00000000']], 'time': '2021-05-20T03:55:00.588967Z'}
{'type': 'l2update', 'product_id': 'BTC-USD', 'changes': [['sell', '38588.07', '0.00000000']], 'time': '2021-05-20T03:55:00.591782Z'}
{'type': 'l2update', 'product_id': 'BTC-USD', 'changes': [['buy', '37911.84', '0.00000000']], 'time': '2021-05-20T03:55:00.591782Z'}
{'type': 'l2update', 'product_id': 'BTC-USD', 'changes': [['sell', '38325.31', '0.00000000']], 'time': '2021-05-20T03:55:00.591782Z'}
{'type': 'l2update', 'product_id': 'BTC-USD', 'changes': [['buy', '38100.73', '0.00000000']], 'time': '2021-05-20T03:55:00.591782Z'}
{'type': 'l2update', 'product_id': 'BTC-USD', 'changes': [['sell', '38399.19', '0.00000000']], 'time': '2021-05-20T03:55:00.591782Z'}
{'type': 'l2update', 'product_id': 'BTC-USD', 'changes': [['buy', '38215.84', '0.00000000']], 'time': '2021-05-20T03:55:00.591782Z'}
{'type': 'l2update', 'product_id': 'BTC-USD', 'changes': [['sell', '38315.65', '0.05000000']], 'time': '2021-05-20T03:55:00.595542Z'}
{'type': 'l2update', 'product_id': 'BTC-USD', 'changes': [['buy', '38254.00', '0.01000000']], 'time': '2021-05-20T03:55:00.595756Z'}
{'type': 'l2update', 'product_id': 'BTC-USD', 'changes': [['buy', '38191.20', '0.33244095']], 'time': '2021-05-20T03:55:00.595886Z'}
{'type': 'l2update', 'product_id': 'BTC-USD', 'changes': [['buy', '38197.51', '0.48224409']], 'time': '2021-05-20T03:55:00.595886Z'}
{'type': 'l2update', 'product_id': 'BTC-USD', 'changes': [['buy', '38291.80', '0.03000000']], 'time': '2021-05-20T03:55:00.596114Z'}
{'type': 'l2update', 'product_id': 'BTC-USD', 'changes': [['buy', '38291.80', '0.10460000']], 'time': '2021-05-20T03:55:00.596451Z'}
{'type': 'l2update', 'product_id': 'BTC-USD', 'changes': [['sell', '38385.40', '0.12268449']], 'time': '2021-05-20T03:55:00.596898Z'}
{'type': 'l2update', 'product_id': 'BTC-USD', 'changes': [['buy', '38291.80', '0.13050000']], 'time': '2021-05-20T03:55:00.597086Z'}
{'type': 'l2update', 'product_id': 'BTC-USD', 'changes': [['buy', '38287.08', '0.01168149']], 'time': '2021-05-20T03:55:00.597990Z'}
{'type': 'l2update', 'product_id': 'BTC-USD', 'changes': [['sell', '38314.95', '0.00000000']], 'time': '2021-05-20T03:55:00.598701Z'}
{'type': 'l2update', 'product_id': 'BTC-USD', 'changes': [['buy', '38291.80', '0.13623000']], 'time': '2021-05-20T03:55:00.602095Z'}
{'type': 'l2update', 'product_id': 'BTC-USD', 'changes': [['sell', '38315.67', '0.00000000']], 'time': '2021-05-20T03:55:00.605790Z'}
{'type': 'l2update', 'product_id': 'BTC-USD', 'changes': [['buy', '38291.17', '0.32590000']], 'time': '2021-05-20T03:55:00.607649Z'}
{'type': 'l2update', 'product_id': 'BTC-USD', 'changes': [['sell', '38486.54', '0.01000000']], 'time': '2021-05-20T03:55:00.611705Z'}
{'type': 'l2update', 'product_id': 'BTC-USD', 'changes': [['sell', '38303.17', '2.48969908']], 'time': '2021-05-20T03:55:00.611941Z'}
{'type': 'l2update', 'product_id': 'BTC-USD', 'changes': [['sell', '38300.44', '0.00000000']], 'time': '2021-05-20T03:55:00.614811Z'}
{'type': 'l2update', 'product_id': 'BTC-USD', 'changes': [['buy', '38240.71', '0.00000000']], 'time': '2021-05-20T03:55:00.614811Z'}
{'type': 'l2update', 'product_id': 'BTC-USD', 'changes': [['sell', '38310.49', '0.50000000']], 'time': '2021-05-20T03:55:00.618675Z'}
{'type': 'l2update', 'product_id': 'BTC-USD', 'changes': [['buy', '38291.17', '0.30000000']], 'time': '2021-05-20T03:55:00.619557Z'}
{'type': 'l2update', 'product_id': 'BTC-USD', 'changes': [['buy', '38157.42', '0.29874039']], 'time': '2021-05-20T03:55:00.620679Z'}
{'type': 'l2update', 'product_id': 'BTC-USD', 'changes': [['buy', '38164.41', '0.00000000']], 'time': '2021-05-20T03:55:00.620679Z'}
{'type': 'l2update', 'product_id': 'BTC-USD', 'changes': [['buy', '38230.70', '0.00000000']], 'time': '2021-05-20T03:55:00.624893Z'}
{'type': 'l2update', 'product_id': 'BTC-USD', 'changes': [['buy', '38277.08', '0.00000000']], 'time': '2021-05-20T03:55:00.625950Z'}
{'type': 'l2update', 'product_id': 'BTC-USD', 'changes': [['buy', '38291.80', '0.15115000']], 'time': '2021-05-20T03:55:00.629295Z'}
{'type': 'l2update', 'product_id': 'BTC-USD', 'changes': [['buy', '38270.16', '0.00000000']], 'time': '2021-05-20T03:55:00.632124Z'}
{'type': 'l2update', 'product_id': 'BTC-USD', 'changes': [['buy', '38282.41', '0.00000000']], 'time': '2021-05-20T03:55:00.632287Z'}
{'type': 'l2update', 'product_id': 'BTC-USD', 'changes': [['buy', '38181.61', '0.06628827']], 'time': '2021-05-20T03:55:00.633502Z'}
{'type': 'l2update', 'product_id': 'BTC-USD', 'changes': [['buy', '38224.99', '0.03364745']], 'time': '2021-05-20T03:55:00.633502Z'}
{'type': 'l2update', 'product_id': 'BTC-USD', 'changes': [['buy', '38229.91', '0.02663544']], 'time': '2021-05-20T03:55:00.633502Z'}
{'type': 'l2update', 'product_id': 'BTC-USD', 'changes': [['buy', '38235.52', '0.06277520']], 'time': '2021-05-20T03:55:00.633502Z'}
{'type': 'l2update', 'product_id': 'BTC-USD', 'changes': [['buy', '38154.62', '0.00000000']], 'time': '2021-05-20T03:55:00.638986Z'}
{'type': 'l2update', 'product_id': 'BTC-USD', 'changes': [['sell', '38332.34', '0.00000000']], 'time': '2021-05-20T03:55:00.641457Z'}
{'type': 'l2update', 'product_id': 'BTC-USD', 'changes': [['buy', '38291.17', '0.40000000']], 'time': '2021-05-20T03:55:00.642950Z'}
{'type': 'l2update', 'product_id': 'BTC-USD', 'changes': [['sell', '38291.81', '0.00000000']], 'time': '2021-05-20T03:55:00.643816Z'}
{'type': 'l2update', 'product_id': 'BTC-USD', 'changes': [['sell', '38310.49', '0.00000000']], 'time': '2021-05-20T03:55:00.644288Z'}
{'type': 'l2update', 'product_id': 'BTC-USD', 'changes': [['buy', '38275.66', '0.00000000']], 'time': '2021-05-20T03:55:00.644868Z'}
{'type': 'l2update', 'product_id': 'BTC-USD', 'changes': [['buy', '38291.81', '0.00573000']], 'time': '2021-05-20T03:55:00.647729Z'}
{'type': 'l2update', 'product_id': 'BTC-USD', 'changes': [['buy', '38126.96', '0.00000000']], 'time': '2021-05-20T03:55:00.650567Z'}
{'type': 'l2update', 'product_id': 'BTC-USD', 'changes': [['buy', '38238.93', '0.00000000']], 'time': '2021-05-20T03:55:00.652743Z'}
{'type': 'l2update', 'product_id': 'BTC-USD', 'changes': [['sell', '38329.38', '0.00000000']], 'time': '2021-05-20T03:55:00.653271Z'}
{'type': 'l2update', 'product_id': 'BTC-USD', 'changes': [['sell', '38293.71', '0.00000000']], 'time': '2021-05-20T03:55:00.653577Z'}
{'type': 'l2update', 'product_id': 'BTC-USD', 'changes': [['buy', '38201.33', '0.03521768']], 'time': '2021-05-20T03:55:00.654957Z'}
{'type': 'l2update', 'product_id': 'BTC-USD', 'changes': [['buy', '38206.63', '0.00000000']], 'time': '2021-05-20T03:55:00.654957Z'}
{'type': 'l2update', 'product_id': 'BTC-USD', 'changes': [['buy', '38208.57', '0.00000000']], 'time': '2021-05-20T03:55:00.654957Z'}
{'type': 'l2update', 'product_id': 'BTC-USD', 'changes': [['buy', '38254.00', '0.00000000']], 'time': '2021-05-20T03:55:00.655603Z'}
{'type': 'l2update', 'product_id': 'BTC-USD', 'changes': [['buy', '38277.24', '0.00000000']], 'time': '2021-05-20T03:55:00.656518Z'}
{'type': 'l2update', 'product_id': 'BTC-USD', 'changes': [['buy', '38207.34', '0.02400000']], 'time': '2021-05-20T03:55:00.658313Z'}
{'type': 'l2update', 'product_id': 'BTC-USD', 'changes': [['buy', '38277.43', '0.11747527']], 'time': '2021-05-20T03:55:00.658736Z'}
{'type': 'l2update', 'product_id': 'BTC-USD', 'changes': [['sell', '38428.56', '0.42036217']], 'time': '2021-05-20T03:55:00.659788Z'}
{'type': 'l2update', 'product_id': 'BTC-USD', 'changes': [['sell', '38344.75', '0.30886141']], 'time': '2021-05-20T03:55:00.659788Z'}
{'type': 'l2update', 'product_id': 'BTC-USD', 'changes': [['sell', '38357.80', '0.00000000']], 'time': '2021-05-20T03:55:00.661205Z'}
{'type': 'l2update', 'product_id': 'BTC-USD', 'changes': [['sell', '38486.54', '0.00000000']], 'time': '2021-05-20T03:55:00.664697Z'}
{'type': 'l2update', 'product_id': 'BTC-USD', 'changes': [['buy', '38251.10', '0.03327915']], 'time': '2021-05-20T03:55:00.668637Z'}
{'type': 'l2update', 'product_id': 'BTC-USD', 'changes': [['buy', '38244.12', '0.01714920']], 'time': '2021-05-20T03:55:00.668764Z'}
{'type': 'l2update', 'product_id': 'BTC-USD', 'changes': [['buy', '38291.80', '0.07655000']], 'time': '2021-05-20T03:55:00.669926Z'}
{'type': 'l2update', 'product_id': 'BTC-USD', 'changes': [['buy', '38291.80', '0.06163000']], 'time': '2021-05-20T03:55:00.670323Z'}
{'type': 'l2update', 'product_id': 'BTC-USD', 'changes': [['buy', '38291.22', '0.52100000']], 'time': '2021-05-20T03:55:00.673554Z'}
{'type': 'l2update', 'product_id': 'BTC-USD', 'changes': [['buy', '38291.80', '0.05590000']], 'time': '2021-05-20T03:55:00.674417Z'}
{'type': 'l2update', 'product_id': 'BTC-USD', 'changes': [['sell', '38303.17', '0.00000000']], 'time': '2021-05-20T03:55:00.676182Z'}
{'type': 'l2update', 'product_id': 'BTC-USD', 'changes': [['sell', '38407.47', '0.00000000']], 'time': '2021-05-20T03:55:00.677672Z'}
{'type': 'l2update', 'product_id': 'BTC-USD', 'changes': [['buy', '38293.70', '0.02300000']], 'time': '2021-05-20T03:55:00.681669Z'}
{'type': 'l2update', 'product_id': 'BTC-USD', 'changes': [['sell', '38327.35', '0.50000000']], 'time': '2021-05-20T03:55:00.681687Z'}
{'type': 'l2update', 'product_id': 'BTC-USD', 'changes': [['buy', '38173.64', '0.01000000']], 'time': '2021-05-20T03:55:00.682784Z'}
{'type': 'l2update', 'product_id': 'BTC-USD', 'changes': [['buy', '38291.80', '0.15590000']], 'time': '2021-05-20T03:55:00.682842Z'}
{'type': 'l2update', 'product_id': 'BTC-USD', 'changes': [['sell', '38367.22', '0.34243481']], 'time': '2021-05-20T03:55:00.683720Z'}
{'type': 'l2update', 'product_id': 'BTC-USD', 'changes': [['sell', '38327.36', '0.00000000']], 'time': '2021-05-20T03:55:00.683720Z'}
{'type': 'l2update', 'product_id': 'BTC-USD', 'changes': [['sell', '38342.23', '2.16932808']], 'time': '2021-05-20T03:55:00.687155Z'}
{'type': 'l2update', 'product_id': 'BTC-USD', 'changes': [['sell', '38423.84', '0.00000000']], 'time': '2021-05-20T03:55:00.688054Z'}
{'type': 'l2update', 'product_id': 'BTC-USD', 'changes': [['sell', '38341.99', '0.01000000']], 'time': '2021-05-20T03:55:00.688720Z'}
{'type': 'l2update', 'product_id': 'BTC-USD', 'changes': [['sell', '38397.45', '0.00000000']], 'time': '2021-05-20T03:55:00.692727Z'}
{'type': 'l2update', 'product_id': 'BTC-USD', 'changes': [['sell', '38304.96', '0.00000000']], 'time': '2021-05-20T03:55:00.693947Z'}
{'type': 'l2update', 'product_id': 'BTC-USD', 'changes': [['buy', '38243.46', '0.00000000']], 'time': '2021-05-20T03:55:00.694432Z'}
{'type': 'l2update', 'product_id': 'BTC-USD', 'changes': [['buy', '38291.81', '0.00000000']], 'time': '2021-05-20T03:55:00.701545Z'}
{'type': 'l2update', 'product_id': 'BTC-USD', 'changes': [['buy', '38233.86', '0.00000000']], 'time': '2021-05-20T03:55:00.702561Z'}
{'type': 'l2update', 'product_id': 'BTC-USD', 'changes': [['buy', '38269.68', '0.00000000']], 'time': '2021-05-20T03:55:00.703126Z'}
{'type': 'l2update', 'product_id': 'BTC-USD', 'changes': [['buy', '38291.80', '0.13000000']], 'time': '2021-05-20T03:55:00.705984Z'}
{'type': 'l2update', 'product_id': 'BTC-USD', 'changes': [['sell', '38315.65', '0.00000000']], 'time': '2021-05-20T03:55:00.706354Z'}
{'type': 'l2update', 'product_id': 'BTC-USD', 'changes': [['buy', '38262.45', '0.00000000']], 'time': '2021-05-20T03:55:00.707024Z'}
{'type': 'l2update', 'product_id': 'BTC-USD', 'changes': [['buy', '38291.17', '0.30000000']], 'time': '2021-05-20T03:55:00.710702Z'}
{'type': 'l2update', 'product_id': 'BTC-USD', 'changes': [['sell', '38420.90', '0.01791638']], 'time': '2021-05-20T03:55:00.711247Z'}
{'type': 'l2update', 'product_id': 'BTC-USD', 'changes': [['buy', '38207.34', '0.00000000']], 'time': '2021-05-20T03:55:00.712798Z'}
{'type': 'l2update', 'product_id': 'BTC-USD', 'changes': [['buy', '38295.28', '0.07460000']], 'time': '2021-05-20T03:55:00.716411Z'}
{'type': 'l2update', 'product_id': 'BTC-USD', 'changes': [['buy', '38295.28', '0.08952000']], 'time': '2021-05-20T03:55:00.716487Z'}
{'type': 'l2update', 'product_id': 'BTC-USD', 'changes': [['sell', '38327.35', '0.00000000']], 'time': '2021-05-20T03:55:00.719884Z'}
{'type': 'l2update', 'product_id': 'BTC-USD', 'changes': [['buy', '38287.84', '0.05000000']], 'time': '2021-05-20T03:55:00.724839Z'}
{'type': 'l2update', 'product_id': 'BTC-USD', 'changes': [['sell', '38630.38', '5.00000000']], 'time': '2021-05-20T03:55:00.725050Z'}
{'type': 'l2update', 'product_id': 'BTC-USD', 'changes': [['sell', '38295.29', '0.00000000']], 'time': '2021-05-20T03:55:00.725178Z'}
{'type': 'l2update', 'product_id': 'BTC-USD', 'changes': [['sell', '38297.22', '0.00000000']], 'time': '2021-05-20T03:55:00.725178Z'}
{'type': 'l2update', 'product_id': 'BTC-USD', 'changes': [['buy', '38220.19', '0.32361428']], 'time': '2021-05-20T03:55:00.725310Z'}
{'type': 'l2update', 'product_id': 'BTC-USD', 'changes': [['buy', '38225.30', '0.15240136']], 'time': '2021-05-20T03:55:00.725310Z'}
{'type': 'l2update', 'product_id': 'BTC-USD', 'changes': [['sell', '38384.43', '0.11050000']], 'time': '2021-05-20T03:55:00.725492Z'}
{'type': 'l2update', 'product_id': 'BTC-USD', 'changes': [['buy', '38234.39', '0.00000000']], 'time': '2021-05-20T03:55:00.728611Z'}
{'type': 'l2update', 'product_id': 'BTC-USD', 'changes': [['sell', '38451.47', '0.01000000']], 'time': '2021-05-20T03:55:00.732309Z'}
{'type': 'l2update', 'product_id': 'BTC-USD', 'changes': [['sell', '38418.62', '0.01501808']], 'time': '2021-05-20T03:55:00.733048Z'}
{'type': 'l2update', 'product_id': 'BTC-USD', 'changes': [['buy', '38259.05', '0.00000000']], 'time': '2021-05-20T03:55:00.733492Z'}
{'type': 'l2update', 'product_id': 'BTC-USD', 'changes': [['sell', '38423.77', '0.00000000']], 'time': '2021-05-20T03:55:00.734107Z'}
{'type': 'l2update', 'product_id': 'BTC-USD', 'changes': [['sell', '38315.64', '2.48969908']], 'time': '2021-05-20T03:55:00.735962Z'}
{'type': 'l2update', 'product_id': 'BTC-USD', 'changes': [['buy', '38295.28', '0.09525000']], 'time': '2021-05-20T03:55:00.736002Z'}
{'type': 'l2update', 'product_id': 'BTC-USD', 'changes': [['buy', '38231.45', '0.00000000']], 'time': '2021-05-20T03:55:00.737880Z'}
{'type': 'l2update', 'product_id': 'BTC-USD', 'changes': [['sell', '38467.39', '0.00779881']], 'time': '2021-05-20T03:55:00.739057Z'}
{'type': 'l2update', 'product_id': 'BTC-USD', 'changes': [['buy', '38291.17', '0.10000000']], 'time': '2021-05-20T03:55:00.739562Z'}
{'type': 'l2update', 'product_id': 'BTC-USD', 'changes': [['sell', '38342.23', '0.00000000']], 'time': '2021-05-20T03:55:00.742575Z'}
{'type': 'l2update', 'product_id': 'BTC-USD', 'changes': [['sell', '38327.35', '0.05000000']], 'time': '2021-05-20T03:55:00.745085Z'}
{'type': 'l2update', 'product_id': 'BTC-USD', 'changes': [['sell', '38315.65', '0.08112604']], 'time': '2021-05-20T03:55:00.745241Z'}
{'type': 'l2update', 'product_id': 'BTC-USD', 'changes': [['sell', '38421.33', '0.02888113']], 'time': '2021-05-20T03:55:00.745442Z'}
{'type': 'l2update', 'product_id': 'BTC-USD', 'changes': [['buy', '38251.09', '0.00000000']], 'time': '2021-05-20T03:55:00.748208Z'}
{'type': 'l2update', 'product_id': 'BTC-USD', 'changes': [['sell', '38465.75', '0.00000000']], 'time': '2021-05-20T03:55:00.748981Z'}
{'type': 'l2update', 'product_id': 'BTC-USD', 'changes': [['buy', '38195.04', '0.00000000']], 'time': '2021-05-20T03:55:00.754666Z'}
{'type': 'l2update', 'product_id': 'BTC-USD', 'changes': [['buy', '38197.51', '0.32984273']], 'time': '2021-05-20T03:55:00.754666Z'}
{'type': 'l2update', 'product_id': 'BTC-USD', 'changes': [['buy', '38295.28', '0.08033000']], 'time': '2021-05-20T03:55:00.755764Z'}
{'type': 'l2update', 'product_id': 'BTC-USD', 'changes': [['sell', '38315.66', '0.00000000']], 'time': '2021-05-20T03:55:00.757636Z'}
{'type': 'l2update', 'product_id': 'BTC-USD', 'changes': [['sell', '38330.95', '0.50000000']], 'time': '2021-05-20T03:55:00.762031Z'}
{'type': 'l2update', 'product_id': 'BTC-USD', 'changes': [['sell', '38346.74', '0.32000000']], 'time': '2021-05-20T03:55:00.767829Z'}
{'type': 'l2update', 'product_id': 'BTC-USD', 'changes': [['sell', '38441.29', '0.80000000']], 'time': '2021-05-20T03:55:00.767829Z'}
{'type': 'l2update', 'product_id': 'BTC-USD', 'changes': [['buy', '38239.13', '0.32000000']], 'time': '2021-05-20T03:55:00.767829Z'}
{'type': 'l2update', 'product_id': 'BTC-USD', 'changes': [['buy', '37955.49', '5.00000000']], 'time': '2021-05-20T03:55:00.767829Z'}
{'type': 'l2update', 'product_id': 'BTC-USD', 'changes': [['buy', '38144.58', '0.80000000']], 'time': '2021-05-20T03:55:00.767829Z'}
{'type': 'l2update', 'product_id': 'BTC-USD', 'changes': [['buy', '38297.21', '0.02590000']], 'time': '2021-05-20T03:55:00.767928Z'}
{'type': 'l2update', 'product_id': 'BTC-USD', 'changes': [['buy', '38291.17', '0.00000000']], 'time': '2021-05-20T03:55:00.772927Z'}
{'type': 'l2update', 'product_id': 'BTC-USD', 'changes': [['sell', '38520.00', '0.00000000']], 'time': '2021-05-20T03:55:00.773195Z'}
{'type': 'l2update', 'product_id': 'BTC-USD', 'changes': [['sell', '38327.35', '0.00000000']], 'time': '2021-05-20T03:55:00.775509Z'}
{'type': 'l2update', 'product_id': 'BTC-USD', 'changes': [['sell', '38449.74', '0.01000000']], 'time': '2021-05-20T03:55:00.776233Z'}
{'type': 'l2update', 'product_id': 'BTC-USD', 'changes': [['buy', '38295.29', '0.00573000']], 'time': '2021-05-20T03:55:00.776298Z'}
{'type': 'l2update', 'product_id': 'BTC-USD', 'changes': [['buy', '38291.82', '0.58716278']], 'time': '2021-05-20T03:55:00.776484Z'}
{'type': 'l2update', 'product_id': 'BTC-USD', 'changes': [['buy', '38277.43', '0.00000000']], 'time': '2021-05-20T03:55:00.778044Z'}
{'type': 'l2update', 'product_id': 'BTC-USD', 'changes': [['buy', '38243.45', '0.00000000']], 'time': '2021-05-20T03:55:00.781293Z'}
{'type': 'l2update', 'product_id': 'BTC-USD', 'changes': [['sell', '38421.33', '0.05906781']], 'time': '2021-05-20T03:55:00.783489Z'}
{'type': 'l2update', 'product_id': 'BTC-USD', 'changes': [['buy', '38262.79', '0.03041148']], 'time': '2021-05-20T03:55:00.783489Z'}
{'type': 'l2update', 'product_id': 'BTC-USD', 'changes': [['sell', '38509.72', '0.01000000']], 'time': '2021-05-20T03:55:00.787445Z'}
{'type': 'l2update', 'product_id': 'BTC-USD', 'changes': [['sell', '38375.73', '0.00000000']], 'time': '2021-05-20T03:55:00.788651Z'}
{'type': 'l2update', 'product_id': 'BTC-USD', 'changes': [['buy', '38214.52', '0.00000000']], 'time': '2021-05-20T03:55:00.789403Z'}
{'type': 'l2update', 'product_id': 'BTC-USD', 'changes': [['sell', '38312.44', '0.02000000']], 'time': '2021-05-20T03:55:00.789925Z'}
{'type': 'l2update', 'product_id': 'BTC-USD', 'changes': [['buy', '38291.18', '0.05000000']], 'time': '2021-05-20T03:55:00.791056Z'}
{'type': 'l2update', 'product_id': 'BTC-USD', 'changes': [['buy', '38191.82', '0.29874039']], 'time': '2021-05-20T03:55:00.791215Z'}
{'type': 'l2update', 'product_id': 'BTC-USD', 'changes': [['buy', '38225.30', '0.48224409']], 'time': '2021-05-20T03:55:00.791215Z'}
{'type': 'l2update', 'product_id': 'BTC-USD', 'changes': [['buy', '38295.28', '0.00573000']], 'time': '2021-05-20T03:55:00.791682Z'}
{'type': 'l2update', 'product_id': 'BTC-USD', 'changes': [['sell', '38305.54', '0.00000000']], 'time': '2021-05-20T03:55:00.795463Z'}
{'type': 'l2update', 'product_id': 'BTC-USD', 'changes': [['sell', '38341.99', '0.00000000']], 'time': '2021-05-20T03:55:00.802544Z'}
{'type': 'l2update', 'product_id': 'BTC-USD', 'changes': [['sell', '38565.50', '3.22890913']], 'time': '2021-05-20T03:55:00.805765Z'}
{'type': 'l2update', 'product_id': 'BTC-USD', 'changes': [['buy', '38295.28', '0.00000000']], 'time': '2021-05-20T03:55:00.809124Z'}
{'type': 'l2update', 'product_id': 'BTC-USD', 'changes': [['sell', '38315.64', '0.00000000']], 'time': '2021-05-20T03:55:00.809632Z'}
{'type': 'l2update', 'product_id': 'BTC-USD', 'changes': [['sell', '38321.86', '0.02000000']], 'time': '2021-05-20T03:55:00.809945Z'}
{'type': 'l2update', 'product_id': 'BTC-USD', 'changes': [['buy', '38264.01', '0.02000000']], 'time': '2021-05-20T03:55:00.809945Z'}
{'type': 'l2update', 'product_id': 'BTC-USD', 'changes': [['buy', '38297.49', '0.01492000']], 'time': '2021-05-20T03:55:00.809982Z'}
{'type': 'l2update', 'product_id': 'BTC-USD', 'changes': [['sell', '38420.90', '0.00000000']], 'time': '2021-05-20T03:55:00.811204Z'}
{'type': 'l2update', 'product_id': 'BTC-USD', 'changes': [['sell', '38330.95', '0.55000000']], 'time': '2021-05-20T03:55:00.814480Z'}
{'type': 'l2update', 'product_id': 'BTC-USD', 'changes': [['sell', '38312.44', '0.00000000']], 'time': '2021-05-20T03:55:00.823842Z'}
{'type': 'l2update', 'product_id': 'BTC-USD', 'changes': [['buy', '38157.42', '0.00000000']], 'time': '2021-05-20T03:55:00.825410Z'}
{'type': 'l2update', 'product_id': 'BTC-USD', 'changes': [['buy', '38197.51', '0.00000000']], 'time': '2021-05-20T03:55:00.825410Z'}
{'type': 'l2update', 'product_id': 'BTC-USD', 'changes': [['sell', '38306.10', '0.00000000']], 'time': '2021-05-20T03:55:00.831462Z'}
{'type': 'l2update', 'product_id': 'BTC-USD', 'changes': [['sell', '38309.59', '0.00000000']], 'time': '2021-05-20T03:55:00.831462Z'}
{'type': 'l2update', 'product_id': 'BTC-USD', 'changes': [['buy', '38310.34', '0.00260138']], 'time': '2021-05-20T03:55:00.831462Z'}
{'type': 'l2update', 'product_id': 'BTC-USD', 'changes': [['sell', '38310.50', '0.08634591']], 'time': '2021-05-20T03:55:00.836161Z'}
{'type': 'l2update', 'product_id': 'BTC-USD', 'changes': [['sell', '38565.48', '0.00000000']], 'time': '2021-05-20T03:55:00.838985Z'}
{'type': 'l2update', 'product_id': 'BTC-USD', 'changes': [['buy', '38295.29', '0.00000000']], 'time': '2021-05-20T03:55:00.840461Z'}
{'type': 'l2update', 'product_id': 'BTC-USD', 'changes': [['buy', '38230.71', '0.02615698']], 'time': '2021-05-20T03:55:00.840515Z'}
{'type': 'l2update', 'product_id': 'BTC-USD', 'changes': [['buy', '38293.70', '0.12300000']], 'time': '2021-05-20T03:55:00.840638Z'}
{'type': 'l2update', 'product_id': 'BTC-USD', 'changes': [['buy', '38297.57', '0.07460000']], 'time': '2021-05-20T03:55:00.840888Z'}
{'type': 'l2update', 'product_id': 'BTC-USD', 'changes': [['buy', '38297.49', '0.00000000']], 'time': '2021-05-20T03:55:00.841204Z'}
{'type': 'l2update', 'product_id': 'BTC-USD', 'changes': [['buy', '38262.79', '0.04239786']], 'time': '2021-05-20T03:55:00.841893Z'}
{'type': 'l2update', 'product_id': 'BTC-USD', 'changes': [['sell', '38451.47', '0.00000000']], 'time': '2021-05-20T03:55:00.845066Z'}
{'type': 'l2update', 'product_id': 'BTC-USD', 'changes': [['sell', '38330.95', '0.50000000']], 'time': '2021-05-20T03:55:00.845309Z'}
{'type': 'l2update', 'product_id': 'BTC-USD', 'changes': [['sell', '38396.49', '0.00000000']], 'time': '2021-05-20T03:55:00.846659Z'}
{'type': 'l2update', 'product_id': 'BTC-USD', 'changes': [['sell', '38330.90', '0.54600000']], 'time': '2021-05-20T03:55:00.847127Z'}
{'type': 'l2update', 'product_id': 'BTC-USD', 'changes': [['sell', '38330.96', '0.00000000']], 'time': '2021-05-20T03:55:00.848887Z'}
{'type': 'l2update', 'product_id': 'BTC-USD', 'changes': [['buy', '38251.08', '0.00000000']], 'time': '2021-05-20T03:55:00.849105Z'}
{'type': 'l2update', 'product_id': 'BTC-USD', 'changes': [['sell', '38367.54', '0.00000000']], 'time': '2021-05-20T03:55:00.854327Z'}
{'type': 'l2update', 'product_id': 'BTC-USD', 'changes': [['sell', '38365.27', '0.00000000']], 'time': '2021-05-20T03:55:00.854586Z'}
{'type': 'l2update', 'product_id': 'BTC-USD', 'changes': [['sell', '38330.94', '0.45705020']], 'time': '2021-05-20T03:55:00.857772Z'}
{'type': 'l2update', 'product_id': 'BTC-USD', 'changes': [['sell', '38447.61', '0.35752218']], 'time': '2021-05-20T03:55:00.864181Z'}
{'type': 'l2update', 'product_id': 'BTC-USD', 'changes': [['buy', '38182.62', '0.29326436']], 'time': '2021-05-20T03:55:00.864181Z'}
{'type': 'l2update', 'product_id': 'BTC-USD', 'changes': [['buy', '38268.16', '0.63758910']], 'time': '2021-05-20T03:55:00.864240Z'}
{'type': 'l2update', 'product_id': 'BTC-USD', 'changes': [['sell', '38416.09', '0.01000000']], 'time': '2021-05-20T03:55:00.864450Z'}
{'type': 'l2update', 'product_id': 'BTC-USD', 'changes': [['buy', '38297.21', '0.00000000']], 'time': '2021-05-20T03:55:00.864504Z'}
{'type': 'l2update', 'product_id': 'BTC-USD', 'changes': [['sell', '38385.40', '0.00000000']], 'time': '2021-05-20T03:55:00.864933Z'}
{'type': 'l2update', 'product_id': 'BTC-USD', 'changes': [['buy', '38277.42', '0.00000000']], 'time': '2021-05-20T03:55:00.868083Z'}
{'type': 'l2update', 'product_id': 'BTC-USD', 'changes': [['buy', '38287.12', '0.11302911']], 'time': '2021-05-20T03:55:00.868796Z'}
{'type': 'l2update', 'product_id': 'BTC-USD', 'changes': [['sell', '38365.92', '0.00000000']], 'time': '2021-05-20T03:55:00.869135Z'}
{'type': 'l2update', 'product_id': 'BTC-USD', 'changes': [['buy', '38244.04', '0.00000000']], 'time': '2021-05-20T03:55:00.869472Z'}
{'type': 'l2update', 'product_id': 'BTC-USD', 'changes': [['buy', '38248.02', '0.00000000']], 'time': '2021-05-20T03:55:00.869472Z'}
{'type': 'l2update', 'product_id': 'BTC-USD', 'changes': [['sell', '38330.90', '0.00000000']], 'time': '2021-05-20T03:55:00.875753Z'}
{'type': 'l2update', 'product_id': 'BTC-USD', 'changes': [['buy', '38306.09', '0.00573000']], 'time': '2021-05-20T03:55:00.875888Z'}
{'type': 'l2update', 'product_id': 'BTC-USD', 'changes': [['sell', '38519.50', '0.64576370']], 'time': '2021-05-20T03:55:00.876140Z'}
{'type': 'l2update', 'product_id': 'BTC-USD', 'changes': [['sell', '38565.50', '5.81203381']], 'time': '2021-05-20T03:55:00.876140Z'}
{'type': 'l2update', 'product_id': 'BTC-USD', 'changes': [['buy', '38293.70', '0.32300000']], 'time': '2021-05-20T03:55:00.876269Z'}
{'type': 'l2update', 'product_id': 'BTC-USD', 'changes': [['sell', '38349.81', '0.01000000']], 'time': '2021-05-20T03:55:00.876581Z'}
{'type': 'l2update', 'product_id': 'BTC-USD', 'changes': [['sell', '38330.94', '2.94674928']], 'time': '2021-05-20T03:55:00.876653Z'}
{'type': 'l2update', 'product_id': 'BTC-USD', 'changes': [['buy', '38309.58', '0.02590000']], 'time': '2021-05-20T03:55:00.876681Z'}
{'type': 'l2update', 'product_id': 'BTC-USD', 'changes': [['sell', '38310.50', '0.08611158']], 'time': '2021-05-20T03:55:00.877069Z'}
{'type': 'l2update', 'product_id': 'BTC-USD', 'changes': [['buy', '38291.18', '0.15000000']], 'time': '2021-05-20T03:55:00.877126Z'}
{'type': 'l2update', 'product_id': 'BTC-USD', 'changes': [['buy', '38291.22', '0.00000000']], 'time': '2021-05-20T03:55:00.880235Z'}
{'type': 'l2update', 'product_id': 'BTC-USD', 'changes': [['sell', '38312.00', '0.00000000']], 'time': '2021-05-20T03:55:00.882407Z'}
{'type': 'l2update', 'product_id': 'BTC-USD', 'changes': [['buy', '38268.16', '0.72902646']], 'time': '2021-05-20T03:55:00.885069Z'}
{'type': 'l2update', 'product_id': 'BTC-USD', 'changes': [['sell', '38327.34', '0.05000000']], 'time': '2021-05-20T03:55:00.885216Z'}
{'type': 'l2update', 'product_id': 'BTC-USD', 'changes': [['sell', '38344.75', '0.00000000']], 'time': '2021-05-20T03:55:00.890560Z'}
{'type': 'l2update', 'product_id': 'BTC-USD', 'changes': [['buy', '38143.43', '0.00000000']], 'time': '2021-05-20T03:55:00.890560Z'}
{'type': 'l2update', 'product_id': 'BTC-USD', 'changes': [['sell', '38467.39', '0.00000000']], 'time': '2021-05-20T03:55:00.893708Z'}
{'type': 'l2update', 'product_id': 'BTC-USD', 'changes': [['buy', '38298.17', '0.01492000']], 'time': '2021-05-20T03:55:00.894354Z'}
{'type': 'l2update', 'product_id': 'BTC-USD', 'changes': [['buy', '38259.90', '0.00000000']], 'time': '2021-05-20T03:55:00.896002Z'}
{'type': 'l2update', 'product_id': 'BTC-USD', 'changes': [['buy', '38259.44', '0.00000000']], 'time': '2021-05-20T03:55:00.896002Z'}
{'type': 'l2update', 'product_id': 'BTC-USD', 'changes': [['buy', '38268.16', '1.22662508']], 'time': '2021-05-20T03:55:00.901131Z'}
{'type': 'l2update', 'product_id': 'BTC-USD', 'changes': [['buy', '38297.57', '0.00000000']], 'time': '2021-05-20T03:55:00.901240Z'}
{'type': 'l2update', 'product_id': 'BTC-USD', 'changes': [['sell', '38351.77', '0.04876172']], 'time': '2021-05-20T03:55:00.907466Z'}
{'type': 'l2update', 'product_id': 'BTC-USD', 'changes': [['buy', '38290.69', '0.00060000']], 'time': '2021-05-20T03:55:00.908864Z'}
{'type': 'l2update', 'product_id': 'BTC-USD', 'changes': [['buy', '38306.09', '0.00000000']], 'time': '2021-05-20T03:55:00.909034Z'}
{'type': 'l2update', 'product_id': 'BTC-USD', 'changes': [['sell', '38432.57', '0.03112777']], 'time': '2021-05-20T03:55:00.910265Z'}
{'type': 'l2update', 'product_id': 'BTC-USD', 'changes': [['buy', '38251.99', '0.02724320']], 'time': '2021-05-20T03:55:00.910265Z'}
{'type': 'l2update', 'product_id': 'BTC-USD', 'changes': [['buy', '38291.81', '0.10000000']], 'time': '2021-05-20T03:55:00.910426Z'}
{'type': 'l2update', 'product_id': 'BTC-USD', 'changes': [['buy', '38309.58', '0.00000000']], 'time': '2021-05-20T03:55:00.917513Z'}
{'type': 'l2update', 'product_id': 'BTC-USD', 'changes': [['sell', '38411.38', '0.00000000']], 'time': '2021-05-20T03:55:00.918123Z'}
{'type': 'l2update', 'product_id': 'BTC-USD', 'changes': [['sell', '38310.50', '0.01121158']], 'time': '2021-05-20T03:55:00.920538Z'}
{'type': 'l2update', 'product_id': 'BTC-USD', 'changes': [['sell', '38310.91', '0.00000000']], 'time': '2021-05-20T03:55:00.923516Z'}
{'type': 'l2update', 'product_id': 'BTC-USD', 'changes': [['buy', '38156.83', '0.04899773']], 'time': '2021-05-20T03:55:00.925446Z'}
{'type': 'l2update', 'product_id': 'BTC-USD', 'changes': [['sell', '38379.72', '0.05076634']], 'time': '2021-05-20T03:55:00.925585Z'}
{'type': 'l2update', 'product_id': 'BTC-USD', 'changes': [['buy', '38267.45', '0.01000000']], 'time': '2021-05-20T03:55:00.926006Z'}
{'type': 'l2update', 'product_id': 'BTC-USD', 'changes': [['sell', '38341.08', '0.00000000']], 'time': '2021-05-20T03:55:00.934570Z'}
{'type': 'l2update', 'product_id': 'BTC-USD', 'changes': [['sell', '38327.34', '0.00000000']], 'time': '2021-05-20T03:55:00.938429Z'}
{'type': 'l2update', 'product_id': 'BTC-USD', 'changes': [['buy', '38223.70', '1.59180000']], 'time': '2021-05-20T03:55:00.939915Z'}
{'type': 'l2update', 'product_id': 'BTC-USD', 'changes': [['sell', '38327.29', '1.05100000']], 'time': '2021-05-20T03:55:00.951162Z'}
{'type': 'l2update', 'product_id': 'BTC-USD', 'changes': [['sell', '38433.80', '0.03372604']], 'time': '2021-05-20T03:55:00.960728Z'}
{'type': 'l2update', 'product_id': 'BTC-USD', 'changes': [['sell', '38405.85', '0.02206700']], 'time': '2021-05-20T03:55:00.965139Z'}
{'type': 'l2update', 'product_id': 'BTC-USD', 'changes': [['buy', '38269.69', '2.37600000']], 'time': '2021-05-20T03:55:00.965888Z'}
{'type': 'l2update', 'product_id': 'BTC-USD', 'changes': [['buy', '38298.17', '0.00000000']], 'time': '2021-05-20T03:55:00.970399Z'}
{'type': 'l2update', 'product_id': 'BTC-USD', 'changes': [['sell', '38447.61', '0.65561174']], 'time': '2021-05-20T03:55:00.980286Z'}
{'type': 'l2update', 'product_id': 'BTC-USD', 'changes': [['buy', '38189.05', '0.33466169']], 'time': '2021-05-20T03:55:00.980286Z'}
{'type': 'l2update', 'product_id': 'BTC-USD', 'changes': [['buy', '38260.71', '0.00000000']], 'time': '2021-05-20T03:55:00.981420Z'}
{'type': 'l2update', 'product_id': 'BTC-USD', 'changes': [['sell', '38330.95', '0.00000000']], 'time': '2021-05-20T03:55:00.985562Z'}
{'type': 'l2update', 'product_id': 'BTC-USD', 'changes': [['buy', '38291.81', '0.20000000']], 'time': '2021-05-20T03:55:00.989963Z'}
{'type': 'l2update', 'product_id': 'BTC-USD', 'changes': [['buy', '38298.18', '1.09150484']], 'time': '2021-05-20T03:55:01.016324Z'}
{'type': 'l2update', 'product_id': 'BTC-USD', 'changes': [['sell', '38341.47', '0.00000000']], 'time': '2021-05-20T03:55:01.019343Z'}
{'type': 'l2update', 'product_id': 'BTC-USD', 'changes': [['buy', '38235.52', '0.03553200']], 'time': '2021-05-20T03:55:01.019343Z'}
{'type': 'l2update', 'product_id': 'BTC-USD', 'changes': [['buy', '38295.28', '0.10000000']], 'time': '2021-05-20T03:55:01.024316Z'}
{'type': 'l2update', 'product_id': 'BTC-USD', 'changes': [['sell', '38509.72', '0.00000000']], 'time': '2021-05-20T03:55:01.025758Z'}
{'type': 'l2update', 'product_id': 'BTC-USD', 'changes': [['sell', '38565.50', '2.58312468']], 'time': '2021-05-20T03:55:01.026308Z'}
{'type': 'l2update', 'product_id': 'BTC-USD', 'changes': [['sell', '38442.97', '0.01300628']], 'time': '2021-05-20T03:55:01.031879Z'}
{'type': 'l2update', 'product_id': 'BTC-USD', 'changes': [['buy', '38298.71', '0.07460000']], 'time': '2021-05-20T03:55:01.039857Z'}
{'type': 'l2update', 'product_id': 'BTC-USD', 'changes': [['sell', '38386.04', '0.01188954']], 'time': '2021-05-20T03:55:01.044084Z'}
{'type': 'l2update', 'product_id': 'BTC-USD', 'changes': [['sell', '38319.41', '0.01000000']], 'time': '2021-05-20T03:55:01.046394Z'}
{'type': 'l2update', 'product_id': 'BTC-USD', 'changes': [['buy', '38310.49', '0.02590000']], 'time': '2021-05-20T03:55:01.051481Z'}
{'type': 'l2update', 'product_id': 'BTC-USD', 'changes': [['sell', '38330.94', '2.99674928']], 'time': '2021-05-20T03:55:01.067377Z'}
{'type': 'l2update', 'product_id': 'BTC-USD', 'changes': [['buy', '38293.75', '0.84700000']], 'time': '2021-05-20T03:55:01.079891Z'}
{'type': 'l2update', 'product_id': 'BTC-USD', 'changes': [['buy', '38287.84', '0.00000000']], 'time': '2021-05-20T03:55:01.093663Z'}
{'type': 'l2update', 'product_id': 'BTC-USD', 'changes': [['sell', '38404.61', '0.02400000']], 'time': '2021-05-20T03:55:01.095343Z'}
{'type': 'l2update', 'product_id': 'BTC-USD', 'changes': [['sell', '38455.47', '0.01000000']], 'time': '2021-05-20T03:55:01.109130Z'}
{'type': 'l2update', 'product_id': 'BTC-USD', 'changes': [['buy', '38189.05', '0.67953245']], 'time': '2021-05-20T03:55:01.109190Z'}
{'type': 'l2update', 'product_id': 'BTC-USD', 'changes': [['buy', '38294.07', '0.01492000']], 'time': '2021-05-20T03:55:01.116207Z'}
{'type': 'l2update', 'product_id': 'BTC-USD', 'changes': [['buy', '38239.13', '0.00000000']], 'time': '2021-05-20T03:55:01.121615Z'}
{'type': 'l2update', 'product_id': 'BTC-USD', 'changes': [['sell', '38346.74', '0.00000000']], 'time': '2021-05-20T03:55:01.121615Z'}
{'type': 'l2update', 'product_id': 'BTC-USD', 'changes': [['buy', '38291.82', '0.00000000']], 'time': '2021-05-20T03:55:01.124862Z'}
{'type': 'l2update', 'product_id': 'BTC-USD', 'changes': [['sell', '38391.29', '0.01000000']], 'time': '2021-05-20T03:55:01.127120Z'}
{'type': 'l2update', 'product_id': 'BTC-USD', 'changes': [['buy', '38195.66', '0.50000000']], 'time': '2021-05-20T03:55:01.133674Z'}
{'type': 'l2update', 'product_id': 'BTC-USD', 'changes': [['sell', '38330.93', '0.50000000']], 'time': '2021-05-20T03:55:01.133752Z'}
{'type': 'l2update', 'product_id': 'BTC-USD', 'changes': [['buy', '38287.74', '0.02400000']], 'time': '2021-05-20T03:55:01.133917Z'}
{'type': 'l2update', 'product_id': 'BTC-USD', 'changes': [['buy', '38286.93', '0.02400000']], 'time': '2021-05-20T03:55:01.133917Z'}
{'type': 'l2update', 'product_id': 'BTC-USD', 'changes': [['buy', '38286.12', '0.02400000']], 'time': '2021-05-20T03:55:01.133917Z'}
{'type': 'l2update', 'product_id': 'BTC-USD', 'changes': [['buy', '38298.18', '0.00000000']], 'time': '2021-05-20T03:55:01.144308Z'}
{'type': 'l2update', 'product_id': 'BTC-USD', 'changes': [['sell', '38351.54', '0.00000000']], 'time': '2021-05-20T03:55:01.160312Z'}
{'type': 'l2update', 'product_id': 'BTC-USD', 'changes': [['buy', '38227.55', '0.00000000']], 'time': '2021-05-20T03:55:01.163878Z'}
{'type': 'l2update', 'product_id': 'BTC-USD', 'changes': [['buy', '38291.80', '0.03000000']], 'time': '2021-05-20T03:55:01.164178Z'}
{'type': 'l2update', 'product_id': 'BTC-USD', 'changes': [['sell', '38349.81', '0.00000000']], 'time': '2021-05-20T03:55:01.164415Z'}
{'type': 'l2update', 'product_id': 'BTC-USD', 'changes': [['buy', '38032.11', '0.00000000']], 'time': '2021-05-20T03:55:01.169048Z'}
{'type': 'l2update', 'product_id': 'BTC-USD', 'changes': [['buy', '38251.10', '0.00000000']], 'time': '2021-05-20T03:55:01.169849Z'}
{'type': 'l2update', 'product_id': 'BTC-USD', 'changes': [['buy', '38287.12', '0.01302911']], 'time': '2021-05-20T03:55:01.172691Z'}
{'type': 'l2update', 'product_id': 'BTC-USD', 'changes': [['sell', '38497.34', '0.01000000']], 'time': '2021-05-20T03:55:01.174989Z'}
{'type': 'l2update', 'product_id': 'BTC-USD', 'changes': [['buy', '38293.85', '0.26100000']], 'time': '2021-05-20T03:55:01.175061Z'}
{'type': 'l2update', 'product_id': 'BTC-USD', 'changes': [['buy', '38298.71', '0.00000000']], 'time': '2021-05-20T03:55:01.176858Z'}
{'type': 'l2update', 'product_id': 'BTC-USD', 'changes': [['sell', '38319.41', '0.03000000']], 'time': '2021-05-20T03:55:01.187343Z'}
{'type': 'l2update', 'product_id': 'BTC-USD', 'changes': [['buy', '38291.80', '0.00000000']], 'time': '2021-05-20T03:55:01.191375Z'}
{'type': 'l2update', 'product_id': 'BTC-USD', 'changes': [['buy', '38293.70', '0.30000000']], 'time': '2021-05-20T03:55:01.191976Z'}
{'type': 'l2update', 'product_id': 'BTC-USD', 'changes': [['buy', '38277.19', '0.06511432']], 'time': '2021-05-20T03:55:01.194758Z'}
{'type': 'l2update', 'product_id': 'BTC-USD', 'changes': [['sell', '38319.05', '0.05522885']], 'time': '2021-05-20T03:55:01.194758Z'}
{'type': 'l2update', 'product_id': 'BTC-USD', 'changes': [['buy', '38310.49', '0.00000000']], 'time': '2021-05-20T03:55:01.216844Z'}
{'type': 'l2update', 'product_id': 'BTC-USD', 'changes': [['sell', '38330.94', '2.94674928']], 'time': '2021-05-20T03:55:01.217057Z'}
{'type': 'l2update', 'product_id': 'BTC-USD', 'changes': [['sell', '38319.36', '1.11000000']], 'time': '2021-05-20T03:55:01.227454Z'}
{'type': 'l2update', 'product_id': 'BTC-USD', 'changes': [['buy', '38269.69', '0.00000000']], 'time': '2021-05-20T03:55:01.259422Z'}
{'type': 'l2update', 'product_id': 'BTC-USD', 'changes': [['buy', '38293.75', '0.00000000']], 'time': '2021-05-20T03:55:01.260187Z'}
{'type': 'l2update', 'product_id': 'BTC-USD', 'changes': [['buy', '38173.64', '0.00000000']], 'time': '2021-05-20T03:55:01.268632Z'}
{'type': 'l2update', 'product_id': 'BTC-USD', 'changes': [['buy', '38294.07', '0.00000000']], 'time': '2021-05-20T03:55:01.270030Z'}
{'type': 'l2update', 'product_id': 'BTC-USD', 'changes': [['sell', '38348.98', '0.00000000']], 'time': '2021-05-20T03:55:01.270578Z'}
{'type': 'l2update', 'product_id': 'BTC-USD', 'changes': [['buy', '38150.24', '0.34487076']], 'time': '2021-05-20T03:55:01.270578Z'}
{'type': 'l2update', 'product_id': 'BTC-USD', 'changes': [['buy', '38150.24', '0.00000000']], 'time': '2021-05-20T03:55:01.270578Z'}
{'type': 'l2update', 'product_id': 'BTC-USD', 'changes': [['buy', '38244.12', '0.00000000']], 'time': '2021-05-20T03:55:01.270834Z'}
{'type': 'l2update', 'product_id': 'BTC-USD', 'changes': [['buy', '38297.58', '0.05000000']], 'time': '2021-05-20T03:55:01.271141Z'}
{'type': 'l2update', 'product_id': 'BTC-USD', 'changes': [['sell', '38321.86', '0.00000000']], 'time': '2021-05-20T03:55:01.271524Z'}
{'type': 'l2update', 'product_id': 'BTC-USD', 'changes': [['buy', '38264.01', '0.00000000']], 'time': '2021-05-20T03:55:01.271524Z'}
{'type': 'l2update', 'product_id': 'BTC-USD', 'changes': [['sell', '38330.94', '0.45705020']], 'time': '2021-05-20T03:55:01.272127Z'}
{'type': 'l2update', 'product_id': 'BTC-USD', 'changes': [['sell', '43100.00', '1.09530000']], 'time': '2021-05-20T03:55:01.286029Z'}
{'type': 'l2update', 'product_id': 'BTC-USD', 'changes': [['sell', '38356.86', '0.00000000']], 'time': '2021-05-20T03:55:01.300905Z'}
{'type': 'l2update', 'product_id': 'BTC-USD', 'changes': [['buy', '38267.45', '0.00000000']], 'time': '2021-05-20T03:55:01.301437Z'}
{'type': 'l2update', 'product_id': 'BTC-USD', 'changes': [['sell', '38313.77', '1.41803105']], 'time': '2021-05-20T03:55:01.303805Z'}
{'type': 'l2update', 'product_id': 'BTC-USD', 'changes': [['buy', '38296.63', '0.52223980']], 'time': '2021-05-20T03:55:01.304280Z'}
{'type': 'l2update', 'product_id': 'BTC-USD', 'changes': [['buy', '38195.66', '0.00000000']], 'time': '2021-05-20T03:55:01.305344Z'}
{'type': 'l2update', 'product_id': 'BTC-USD', 'changes': [['buy', '38297.21', '0.10000000']], 'time': '2021-05-20T03:55:01.307715Z'}
{'type': 'l2update', 'product_id': 'BTC-USD', 'changes': [['sell', '38310.50', '0.03711158']], 'time': '2021-05-20T03:55:01.307852Z'}
{'type': 'l2update', 'product_id': 'BTC-USD', 'changes': [['buy', '38264.51', '0.10000000']], 'time': '2021-05-20T03:55:01.307913Z'}
{'type': 'l2update', 'product_id': 'BTC-USD', 'changes': [['buy', '38156.83', '0.00000000']], 'time': '2021-05-20T03:55:01.309210Z'}
{'type': 'l2update', 'product_id': 'BTC-USD', 'changes': [['buy', '38269.69', '0.02677928']], 'time': '2021-05-20T03:55:01.311695Z'}
{'type': 'l2update', 'product_id': 'BTC-USD', 'changes': [['buy', '38045.00', '0.05716400']], 'time': '2021-05-20T03:55:01.311722Z'}
{'type': 'l2update', 'product_id': 'BTC-USD', 'changes': [['buy', '38287.07', '0.00000000']], 'time': '2021-05-20T03:55:01.323413Z'}
{'type': 'l2update', 'product_id': 'BTC-USD', 'changes': [['sell', '38343.84', '0.04918281']], 'time': '2021-05-20T03:55:01.332371Z'}
{'type': 'l2update', 'product_id': 'BTC-USD', 'changes': [['sell', '38319.41', '0.06000000']], 'time': '2021-05-20T03:55:01.332594Z'}
{'type': 'l2update', 'product_id': 'BTC-USD', 'changes': [['sell', '38344.74', '0.05000000']], 'time': '2021-05-20T03:55:01.344237Z'}
{'type': 'l2update', 'product_id': 'BTC-USD', 'changes': [['sell', '38334.58', '0.00000000']], 'time': '2021-05-20T03:55:01.348900Z'}
{'type': 'l2update', 'product_id': 'BTC-USD', 'changes': [['buy', '38310.49', '0.00573000']], 'time': '2021-05-20T03:55:01.358651Z'}
{'type': 'l2update', 'product_id': 'BTC-USD', 'changes': [['sell', '38404.61', '0.00000000']], 'time': '2021-05-20T03:55:01.358698Z'}
{'type': 'l2update', 'product_id': 'BTC-USD', 'changes': [['buy', '38143.91', '0.00000000']], 'time': '2021-05-20T03:55:01.359622Z'}
{'type': 'l2update', 'product_id': 'BTC-USD', 'changes': [['buy', '38295.90', '0.07460000']], 'time': '2021-05-20T03:55:01.362168Z'}
{'type': 'l2update', 'product_id': 'BTC-USD', 'changes': [['sell', '38518.21', '0.00000000']], 'time': '2021-05-20T03:55:01.364645Z'}
{'type': 'l2update', 'product_id': 'BTC-USD', 'changes': [['buy', '38252.00', '0.02614242']], 'time': '2021-05-20T03:55:01.369210Z'}
{'type': 'l2update', 'product_id': 'BTC-USD', 'changes': [['buy', '38223.67', '0.29874039']], 'time': '2021-05-20T03:55:01.375084Z'}
{'type': 'l2update', 'product_id': 'BTC-USD', 'changes': [['buy', '38242.97', '0.13193709']], 'time': '2021-05-20T03:55:01.375084Z'}
{'type': 'l2update', 'product_id': 'BTC-USD', 'changes': [['buy', '38277.37', '0.00000000']], 'time': '2021-05-20T03:55:01.376716Z'}
{'type': 'l2update', 'product_id': 'BTC-USD', 'changes': [['sell', '38367.21', '0.06736008']], 'time': '2021-05-20T03:55:01.382500Z'}
{'type': 'l2update', 'product_id': 'BTC-USD', 'changes': [['buy', '38291.82', '0.58716278']], 'time': '2021-05-20T03:55:01.383057Z'}
