{'type': 'l2update', 'product_id': 'BTC-USD', 'changes': [['buy', '38260.28', '0.00000000']], 'time': '2021-05-20T03:56:14.921638Z'}
{'type': 'l2update', 'product_id': 'BTC-USD', 'changes': [['buy', '38304.15', '0.02400000']], 'time': '2021-05-20T03:56:14.921998Z'}
{'type': 'l2update', 'product_id': 'BTC-USD', 'changes': [['buy', '38322.35', '0.00000000']], 'time': '2021-05-20T03:56:14.925980Z'}
{'type': 'l2update', 'product_id': 'BTC-USD', 'changes': [['buy', '38294.58', '0.47880000']], 'time': '2021-05-20T03:56:14.926838Z'}
{'type': 'l2update', 'product_id': 'BTC-USD', 'changes': [['buy', '38322.35', '0.02330058']], 'time': '2021-05-20T03:56:14.926856Z'}
{'type': 'l2update', 'product_id': 'BTC-USD', 'changes': [['sell', '38335.52', '0.00000000']], 'time': '2021-05-20T03:56:14.926929Z'}
{'type': 'l2update', 'product_id': 'BTC-USD', 'changes': [['buy', '38330.07', '0.07172821']], 'time': '2021-05-20T03:56:14.931523Z'}
{'type': 'l2update', 'product_id': 'BTC-USD', 'changes': [['sell', '38387.64', '2.16932808']], 'time': '2021-05-20T03:56:14.931557Z'}
{'type': 'l2update', 'product_id': 'BTC-USD', 'changes': [['sell', '38346.54', '0.05000000']], 'time': '2021-05-20T03:56:14.931677Z'}
{'type': 'l2update', 'product_id': 'BTC-USD', 'changes': [['sell', '38442.70', '0.03810065']], 'time': '2021-05-20T03:56:14.933835Z'}
{'type': 'l2update', 'product_id': 'BTC-USD', 'changes': [['buy', '38323.08', '0.02251804']], 'time': '2021-05-20T03:56:14.933848Z'}
{'type': 'l2update', 'product_id': 'BTC-USD', 'changes': [['sell', '38359.06', '0.46596179']], 'time': '2021-05-20T03:56:14.933930Z'}
{'type': 'l2update', 'product_id': 'BTC-USD', 'changes': [['sell', '38335.15', '0.07460000']], 'time': '2021-05-20T03:56:14.934024Z'}
{'type': 'l2update', 'product_id': 'BTC-USD', 'changes': [['buy', '38322.35', '0.00000000']], 'time': '2021-05-20T03:56:14.934530Z'}
{'type': 'l2update', 'product_id': 'BTC-USD', 'changes': [['sell', '38474.83', '0.01000000']], 'time': '2021-05-20T03:56:14.938562Z'}
{'type': 'l2update', 'product_id': 'BTC-USD', 'changes': [['buy', '38323.08', '0.00000000']], 'time': '2021-05-20T03:56:14.941110Z'}
{'type': 'l2update', 'product_id': 'BTC-USD', 'changes': [['buy', '38322.46', '0.00000000']], 'time': '2021-05-20T03:56:14.941139Z'}
{'type': 'l2update', 'product_id': 'BTC-USD', 'changes': [['sell', '38335.15', '0.00000000']], 'time': '2021-05-20T03:56:14.941828Z'}
{'type': 'l2update', 'product_id': 'BTC-USD', 'changes': [['sell', '38349.60', '0.00000000']], 'time': '2021-05-20T03:56:14.941953Z'}
{'type': 'l2update', 'product_id': 'BTC-USD', 'changes': [['sell', '38439.35', '0.31482376']], 'time': '2021-05-20T03:56:14.943080Z'}
{'type': 'l2update', 'product_id': 'BTC-USD', 'changes': [['sell', '38346.54', '0.00000000']], 'time': '2021-05-20T03:56:14.944274Z'}
{'type': 'l2update', 'product_id': 'BTC-USD', 'changes': [['buy', '37535.54', '0.06948064']], 'time': '2021-05-20T03:56:14.944653Z'}
{'type': 'l2update', 'product_id': 'BTC-USD', 'changes': [['sell', '38420.44', '0.00000000']], 'time': '2021-05-20T03:56:14.945581Z'}
{'type': 'l2update', 'product_id': 'BTC-USD', 'changes': [['sell', '38339.18', '0.01492000']], 'time': '2021-05-20T03:56:14.946543Z'}
{'type': 'l2update', 'product_id': 'BTC-USD', 'changes': [['sell', '38383.26', '0.03790087']], 'time': '2021-05-20T03:56:14.947071Z'}
{'type': 'l2update', 'product_id': 'BTC-USD', 'changes': [['sell', '38378.70', '0.02811794']], 'time': '2021-05-20T03:56:14.947071Z'}
{'type': 'l2update', 'product_id': 'BTC-USD', 'changes': [['sell', '38339.73', '0.00600000']], 'time': '2021-05-20T03:56:14.947100Z'}
{'type': 'l2update', 'product_id': 'BTC-USD', 'changes': [['sell', '38339.40', '0.55400000']], 'time': '2021-05-20T03:56:14.947275Z'}
{'type': 'l2update', 'product_id': 'BTC-USD', 'changes': [['buy', '38294.58', '0.00000000']], 'time': '2021-05-20T03:56:14.947595Z'}
{'type': 'l2update', 'product_id': 'BTC-USD', 'changes': [['buy', '38330.07', '0.00000000']], 'time': '2021-05-20T03:56:14.947614Z'}
{'type': 'l2update', 'product_id': 'BTC-USD', 'changes': [['sell', '38385.38', '0.00000000']], 'time': '2021-05-20T03:56:14.947657Z'}
{'type': 'l2update', 'product_id': 'BTC-USD', 'changes': [['sell', '38673.48', '0.00000000']], 'time': '2021-05-20T03:56:14.950235Z'}
{'type': 'l2update', 'product_id': 'BTC-USD', 'changes': [['sell', '38339.18', '0.00000000']], 'time': '2021-05-20T03:56:14.952018Z'}
{'type': 'l2update', 'product_id': 'BTC-USD', 'changes': [['sell', '38359.07', '0.00000000']], 'time': '2021-05-20T03:56:14.953511Z'}
{'type': 'l2update', 'product_id': 'BTC-USD', 'changes': [['sell', '38452.84', '0.00000000']], 'time': '2021-05-20T03:56:14.953693Z'}
{'type': 'l2update', 'product_id': 'BTC-USD', 'changes': [['buy', '38318.02', '0.00000000']], 'time': '2021-05-20T03:56:14.953809Z'}
{'type': 'l2update', 'product_id': 'BTC-USD', 'changes': [['buy', '38259.63', '0.00000000']], 'time': '2021-05-20T03:56:14.955019Z'}
{'type': 'l2update', 'product_id': 'BTC-USD', 'changes': [['sell', '38396.63', '0.00000000']], 'time': '2021-05-20T03:56:14.955872Z'}
{'type': 'l2update', 'product_id': 'BTC-USD', 'changes': [['sell', '38339.19', '0.07460000']], 'time': '2021-05-20T03:56:14.956704Z'}
{'type': 'l2update', 'product_id': 'BTC-USD', 'changes': [['sell', '38359.05', '0.05000000']], 'time': '2021-05-20T03:56:14.956872Z'}
{'type': 'l2update', 'product_id': 'BTC-USD', 'changes': [['sell', '39126.23', '0.06409902']], 'time': '2021-05-20T03:56:14.956953Z'}
{'type': 'l2update', 'product_id': 'BTC-USD', 'changes': [['sell', '38350.54', '0.00000000']], 'time': '2021-05-20T03:56:14.961431Z'}
{'type': 'l2update', 'product_id': 'BTC-USD', 'changes': [['sell', '38346.54', '0.10525458']], 'time': '2021-05-20T03:56:14.961498Z'}
{'type': 'l2update', 'product_id': 'BTC-USD', 'changes': [['buy', '37931.24', '0.00000000']], 'time': '2021-05-20T03:56:14.961566Z'}
{'type': 'l2update', 'product_id': 'BTC-USD', 'changes': [['sell', '38339.19', '0.00000000']], 'time': '2021-05-20T03:56:14.962496Z'}
{'type': 'l2update', 'product_id': 'BTC-USD', 'changes': [['buy', '38322.12', '0.01492000']], 'time': '2021-05-20T03:56:14.963237Z'}
{'type': 'l2update', 'product_id': 'BTC-USD', 'changes': [['sell', '38399.10', '0.06600000']], 'time': '2021-05-20T03:56:14.963503Z'}
{'type': 'l2update', 'product_id': 'BTC-USD', 'changes': [['buy', '38322.31', '0.02251804']], 'time': '2021-05-20T03:56:14.963840Z'}
{'type': 'l2update', 'product_id': 'BTC-USD', 'changes': [['sell', '38362.53', '0.45880000']], 'time': '2021-05-20T03:56:14.963890Z'}
{'type': 'l2update', 'product_id': 'BTC-USD', 'changes': [['sell', '38660.39', '0.01992060']], 'time': '2021-05-20T03:56:14.963915Z'}
{'type': 'l2update', 'product_id': 'BTC-USD', 'changes': [['sell', '38339.44', '2.48969908']], 'time': '2021-05-20T03:56:14.963945Z'}
{'type': 'l2update', 'product_id': 'BTC-USD', 'changes': [['sell', '38339.40', '0.55376629']], 'time': '2021-05-20T03:56:14.964007Z'}
{'type': 'l2update', 'product_id': 'BTC-USD', 'changes': [['buy', '38317.46', '0.00000000']], 'time': '2021-05-20T03:56:14.964880Z'}
{'type': 'l2update', 'product_id': 'BTC-USD', 'changes': [['sell', '38359.05', '0.00000000']], 'time': '2021-05-20T03:56:14.965824Z'}
{'type': 'l2update', 'product_id': 'BTC-USD', 'changes': [['buy', '38295.49', '0.00000000']], 'time': '2021-05-20T03:56:14.966104Z'}
{'type': 'l2update', 'product_id': 'BTC-USD', 'changes': [['sell', '38362.53', '0.00000000']], 'time': '2021-05-20T03:56:14.969533Z'}
{'type': 'l2update', 'product_id': 'BTC-USD', 'changes': [['sell', '38339.13', '0.01492000']], 'time': '2021-05-20T03:56:14.970948Z'}
{'type': 'l2update', 'product_id': 'BTC-USD', 'changes': [['sell', '38394.30', '0.03234674']], 'time': '2021-05-20T03:56:14.970989Z'}
{'type': 'l2update', 'product_id': 'BTC-USD', 'changes': [['buy', '38322.12', '0.00000000']], 'time': '2021-05-20T03:56:14.971275Z'}
{'type': 'l2update', 'product_id': 'BTC-USD', 'changes': [['buy', '38306.32', '0.00000000']], 'time': '2021-05-20T03:56:14.975804Z'}
{'type': 'l2update', 'product_id': 'BTC-USD', 'changes': [['buy', '38305.51', '0.00000000']], 'time': '2021-05-20T03:56:14.975804Z'}
{'type': 'l2update', 'product_id': 'BTC-USD', 'changes': [['buy', '38304.15', '0.00000000']], 'time': '2021-05-20T03:56:14.975804Z'}
{'type': 'l2update', 'product_id': 'BTC-USD', 'changes': [['buy', '38311.86', '0.59116555']], 'time': '2021-05-20T03:56:14.976001Z'}
{'type': 'l2update', 'product_id': 'BTC-USD', 'changes': [['buy', '38227.22', '0.03956259']], 'time': '2021-05-20T03:56:14.976056Z'}
{'type': 'l2update', 'product_id': 'BTC-USD', 'changes': [['sell', '38338.81', '0.07460000']], 'time': '2021-05-20T03:56:14.976218Z'}
{'type': 'l2update', 'product_id': 'BTC-USD', 'changes': [['buy', '38290.39', '0.03823166']], 'time': '2021-05-20T03:56:14.981803Z'}
{'type': 'l2update', 'product_id': 'BTC-USD', 'changes': [['sell', '38436.71', '0.41313943']], 'time': '2021-05-20T03:56:14.982049Z'}
{'type': 'l2update', 'product_id': 'BTC-USD', 'changes': [['sell', '38369.99', '0.33792367']], 'time': '2021-05-20T03:56:14.982049Z'}
{'type': 'l2update', 'product_id': 'BTC-USD', 'changes': [['sell', '38346.54', '0.15525458']], 'time': '2021-05-20T03:56:14.982266Z'}
{'type': 'l2update', 'product_id': 'BTC-USD', 'changes': [['sell', '38339.13', '0.00000000']], 'time': '2021-05-20T03:56:14.986556Z'}
{'type': 'l2update', 'product_id': 'BTC-USD', 'changes': [['sell', '38423.11', '0.00000000']], 'time': '2021-05-20T03:56:14.992752Z'}
{'type': 'l2update', 'product_id': 'BTC-USD', 'changes': [['sell', '38401.69', '0.00000000']], 'time': '2021-05-20T03:56:14.995674Z'}
{'type': 'l2update', 'product_id': 'BTC-USD', 'changes': [['buy', '38241.81', '0.00000000']], 'time': '2021-05-20T03:56:14.997237Z'}
{'type': 'l2update', 'product_id': 'BTC-USD', 'changes': [['buy', '38315.11', '0.01363843']], 'time': '2021-05-20T03:56:14.997552Z'}
{'type': 'l2update', 'product_id': 'BTC-USD', 'changes': [['buy', '38290.39', '0.00000000']], 'time': '2021-05-20T03:56:14.997711Z'}
{'type': 'l2update', 'product_id': 'BTC-USD', 'changes': [['buy', '38322.54', '0.01492000']], 'time': '2021-05-20T03:56:14.997746Z'}
{'type': 'l2update', 'product_id': 'BTC-USD', 'changes': [['buy', '38301.49', '0.02400000']], 'time': '2021-05-20T03:56:14.998077Z'}
{'type': 'l2update', 'product_id': 'BTC-USD', 'changes': [['buy', '38300.68', '0.02400000']], 'time': '2021-05-20T03:56:14.998077Z'}
{'type': 'l2update', 'product_id': 'BTC-USD', 'changes': [['buy', '38299.87', '0.02400000']], 'time': '2021-05-20T03:56:14.998077Z'}
{'type': 'l2update', 'product_id': 'BTC-USD', 'changes': [['sell', '38369.99', '0.50746294']], 'time': '2021-05-20T03:56:15.002041Z'}
{'type': 'l2update', 'product_id': 'BTC-USD', 'changes': [['sell', '38399.05', '0.03337070']], 'time': '2021-05-20T03:56:15.003016Z'}
{'type': 'l2update', 'product_id': 'BTC-USD', 'changes': [['sell', '38388.60', '0.03810065']], 'time': '2021-05-20T03:56:15.003016Z'}
{'type': 'l2update', 'product_id': 'BTC-USD', 'changes': [['buy', '38322.31', '0.00000000']], 'time': '2021-05-20T03:56:15.005099Z'}
{'type': 'l2update', 'product_id': 'BTC-USD', 'changes': [['sell', '38338.34', '0.01492000']], 'time': '2021-05-20T03:56:15.006533Z'}
{'type': 'l2update', 'product_id': 'BTC-USD', 'changes': [['buy', '38224.93', '0.01000000']], 'time': '2021-05-20T03:56:15.007581Z'}
{'type': 'l2update', 'product_id': 'BTC-USD', 'changes': [['sell', '38407.53', '0.01301828']], 'time': '2021-05-20T03:56:15.007679Z'}
{'type': 'l2update', 'product_id': 'BTC-USD', 'changes': [['sell', '38387.79', '0.00000000']], 'time': '2021-05-20T03:56:15.007749Z'}
{'type': 'l2update', 'product_id': 'BTC-USD', 'changes': [['sell', '38384.14', '0.00000000']], 'time': '2021-05-20T03:56:15.007749Z'}
{'type': 'l2update', 'product_id': 'BTC-USD', 'changes': [['sell', '38442.70', '0.00000000']], 'time': '2021-05-20T03:56:15.011757Z'}
{'type': 'l2update', 'product_id': 'BTC-USD', 'changes': [['buy', '38323.08', '0.02251804']], 'time': '2021-05-20T03:56:15.012264Z'}
{'type': 'l2update', 'product_id': 'BTC-USD', 'changes': [['buy', '38331.46', '0.00176479']], 'time': '2021-05-20T03:56:15.012294Z'}
{'type': 'l2update', 'product_id': 'BTC-USD', 'changes': [['sell', '38338.81', '0.00000000']], 'time': '2021-05-20T03:56:15.014527Z'}
{'type': 'l2update', 'product_id': 'BTC-USD', 'changes': [['sell', '38383.26', '0.00000000']], 'time': '2021-05-20T03:56:15.018611Z'}
{'type': 'l2update', 'product_id': 'BTC-USD', 'changes': [['sell', '38378.70', '0.00000000']], 'time': '2021-05-20T03:56:15.018611Z'}
{'type': 'l2update', 'product_id': 'BTC-USD', 'changes': [['buy', '38322.54', '0.00000000']], 'time': '2021-05-20T03:56:15.020311Z'}
{'type': 'l2update', 'product_id': 'BTC-USD', 'changes': [['sell', '38338.34', '0.00000000']], 'time': '2021-05-20T03:56:15.021224Z'}
{'type': 'l2update', 'product_id': 'BTC-USD', 'changes': [['sell', '38339.40', '0.54076173']], 'time': '2021-05-20T03:56:15.022009Z'}
{'type': 'l2update', 'product_id': 'BTC-USD', 'changes': [['buy', '37535.54', '0.00000000']], 'time': '2021-05-20T03:56:15.026064Z'}
{'type': 'l2update', 'product_id': 'BTC-USD', 'changes': [['sell', '38368.26', '0.00000000']], 'time': '2021-05-20T03:56:15.027507Z'}
{'type': 'l2update', 'product_id': 'BTC-USD', 'changes': [['buy', '38323.08', '0.00000000']], 'time': '2021-05-20T03:56:15.027668Z'}
{'type': 'l2update', 'product_id': 'BTC-USD', 'changes': [['sell', '38370.22', '0.00000000']], 'time': '2021-05-20T03:56:15.027737Z'}
{'type': 'l2update', 'product_id': 'BTC-USD', 'changes': [['sell', '38464.44', '0.00000000']], 'time': '2021-05-20T03:56:15.031440Z'}
{'type': 'l2update', 'product_id': 'BTC-USD', 'changes': [['sell', '38331.47', '0.01680419']], 'time': '2021-05-20T03:56:15.034379Z'}
{'type': 'l2update', 'product_id': 'BTC-USD', 'changes': [['buy', '38323.56', '0.01492000']], 'time': '2021-05-20T03:56:15.035634Z'}
{'type': 'l2update', 'product_id': 'BTC-USD', 'changes': [['buy', '38322.36', '0.05208196']], 'time': '2021-05-20T03:56:15.036858Z'}
{'type': 'l2update', 'product_id': 'BTC-USD', 'changes': [['sell', '38331.47', '0.00000000']], 'time': '2021-05-20T03:56:15.041005Z'}
{'type': 'l2update', 'product_id': 'BTC-USD', 'changes': [['buy', '38323.56', '0.00000000']], 'time': '2021-05-20T03:56:15.042232Z'}
{'type': 'l2update', 'product_id': 'BTC-USD', 'changes': [['buy', '38322.36', '0.00000000']], 'time': '2021-05-20T03:56:15.045452Z'}
{'type': 'l2update', 'product_id': 'BTC-USD', 'changes': [['buy', '38290.63', '0.46040000']], 'time': '2021-05-20T03:56:15.046265Z'}
{'type': 'l2update', 'product_id': 'BTC-USD', 'changes': [['buy', '38322.36', '0.02251804']], 'time': '2021-05-20T03:56:15.051225Z'}
{'type': 'l2update', 'product_id': 'BTC-USD', 'changes': [['sell', '38331.47', '0.02890000']], 'time': '2021-05-20T03:56:15.051665Z'}
{'type': 'l2update', 'product_id': 'BTC-USD', 'changes': [['buy', '38290.39', '0.03823166']], 'time': '2021-05-20T03:56:15.055676Z'}
{'type': 'l2update', 'product_id': 'BTC-USD', 'changes': [['sell', '38439.45', '0.01000000']], 'time': '2021-05-20T03:56:15.056986Z'}
{'type': 'l2update', 'product_id': 'BTC-USD', 'changes': [['buy', '38322.36', '0.00000000']], 'time': '2021-05-20T03:56:15.057328Z'}
{'type': 'l2update', 'product_id': 'BTC-USD', 'changes': [['sell', '38363.97', '0.14577935']], 'time': '2021-05-20T03:56:15.065631Z'}
{'type': 'l2update', 'product_id': 'BTC-USD', 'changes': [['sell', '38362.52', '0.41200000']], 'time': '2021-05-20T03:56:15.065979Z'}
{'type': 'l2update', 'product_id': 'BTC-USD', 'changes': [['buy', '38323.85', '0.07172821']], 'time': '2021-05-20T03:56:15.066205Z'}
{'type': 'l2update', 'product_id': 'BTC-USD', 'changes': [['sell', '38399.05', '0.00000000']], 'time': '2021-05-20T03:56:15.067726Z'}
{'type': 'l2update', 'product_id': 'BTC-USD', 'changes': [['sell', '38394.30', '0.00000000']], 'time': '2021-05-20T03:56:15.067726Z'}
{'type': 'l2update', 'product_id': 'BTC-USD', 'changes': [['sell', '38388.60', '0.00000000']], 'time': '2021-05-20T03:56:15.067726Z'}
{'type': 'l2update', 'product_id': 'BTC-USD', 'changes': [['sell', '38424.85', '0.61482417']], 'time': '2021-05-20T03:56:15.069733Z'}
{'type': 'l2update', 'product_id': 'BTC-USD', 'changes': [['buy', '38322.72', '0.01492000']], 'time': '2021-05-20T03:56:15.069773Z'}
{'type': 'l2update', 'product_id': 'BTC-USD', 'changes': [['buy', '38322.37', '0.05208196']], 'time': '2021-05-20T03:56:15.070122Z'}
{'type': 'l2update', 'product_id': 'BTC-USD', 'changes': [['sell', '38412.91', '0.00000000']], 'time': '2021-05-20T03:56:15.071614Z'}
{'type': 'l2update', 'product_id': 'BTC-USD', 'changes': [['sell', '38402.76', '0.00000000']], 'time': '2021-05-20T03:56:15.071614Z'}
{'type': 'l2update', 'product_id': 'BTC-USD', 'changes': [['sell', '38393.07', '0.00000000']], 'time': '2021-05-20T03:56:15.071614Z'}
{'type': 'l2update', 'product_id': 'BTC-USD', 'changes': [['sell', '38377.41', '0.14944696']], 'time': '2021-05-20T03:56:15.071614Z'}
{'type': 'l2update', 'product_id': 'BTC-USD', 'changes': [['sell', '38375.97', '0.00000000']], 'time': '2021-05-20T03:56:15.071614Z'}
{'type': 'l2update', 'product_id': 'BTC-USD', 'changes': [['buy', '38322.37', '0.05849421']], 'time': '2021-05-20T03:56:15.076516Z'}
{'type': 'l2update', 'product_id': 'BTC-USD', 'changes': [['buy', '38148.17', '0.01000000']], 'time': '2021-05-20T03:56:15.076545Z'}
{'type': 'l2update', 'product_id': 'BTC-USD', 'changes': [['buy', '37524.58', '0.06476100']], 'time': '2021-05-20T03:56:15.076600Z'}
{'type': 'l2update', 'product_id': 'BTC-USD', 'changes': [['buy', '38311.91', '0.84700000']], 'time': '2021-05-20T03:56:15.076674Z'}
{'type': 'l2update', 'product_id': 'BTC-USD', 'changes': [['sell', '38377.41', '0.00000000']], 'time': '2021-05-20T03:56:15.077950Z'}
{'type': 'l2update', 'product_id': 'BTC-USD', 'changes': [['buy', '38310.15', '0.00000000']], 'time': '2021-05-20T03:56:15.080831Z'}
{'type': 'l2update', 'product_id': 'BTC-USD', 'changes': [['sell', '39114.47', '0.00505876']], 'time': '2021-05-20T03:56:15.081421Z'}
{'type': 'l2update', 'product_id': 'BTC-USD', 'changes': [['buy', '38322.37', '0.05208196']], 'time': '2021-05-20T03:56:15.081669Z'}
{'type': 'l2update', 'product_id': 'BTC-USD', 'changes': [['buy', '38322.37', '0.00000000']], 'time': '2021-05-20T03:56:15.082137Z'}
{'type': 'l2update', 'product_id': 'BTC-USD', 'changes': [['sell', '39126.23', '0.00000000']], 'time': '2021-05-20T03:56:15.082376Z'}
{'type': 'l2update', 'product_id': 'BTC-USD', 'changes': [['sell', '38354.82', '0.05000000']], 'time': '2021-05-20T03:56:15.083010Z'}
{'type': 'l2update', 'product_id': 'BTC-USD', 'changes': [['buy', '38290.39', '0.00000000']], 'time': '2021-05-20T03:56:15.083256Z'}
{'type': 'l2update', 'product_id': 'BTC-USD', 'changes': [['buy', '38311.86', '0.00000000']], 'time': '2021-05-20T03:56:15.086333Z'}
{'type': 'l2update', 'product_id': 'BTC-USD', 'changes': [['buy', '38322.37', '0.01610579']], 'time': '2021-05-20T03:56:15.087814Z'}
{'type': 'l2update', 'product_id': 'BTC-USD', 'changes': [['sell', '38376.49', '0.00000000']], 'time': '2021-05-20T03:56:15.089632Z'}
{'type': 'l2update', 'product_id': 'BTC-USD', 'changes': [['buy', '38322.37', '0.00000000']], 'time': '2021-05-20T03:56:15.091959Z'}
{'type': 'l2update', 'product_id': 'BTC-USD', 'changes': [['sell', '38455.17', '0.00000000']], 'time': '2021-05-20T03:56:15.098691Z'}
{'type': 'l2update', 'product_id': 'BTC-USD', 'changes': [['buy', '38322.72', '0.00000000']], 'time': '2021-05-20T03:56:15.099803Z'}
{'type': 'l2update', 'product_id': 'BTC-USD', 'changes': [['sell', '38439.35', '0.00000000']], 'time': '2021-05-20T03:56:15.101434Z'}
{'type': 'l2update', 'product_id': 'BTC-USD', 'changes': [['sell', '38436.71', '0.00000000']], 'time': '2021-05-20T03:56:15.101434Z'}
{'type': 'l2update', 'product_id': 'BTC-USD', 'changes': [['sell', '38430.33', '0.00000000']], 'time': '2021-05-20T03:56:15.101434Z'}
{'type': 'l2update', 'product_id': 'BTC-USD', 'changes': [['sell', '38424.43', '0.00000000']], 'time': '2021-05-20T03:56:15.101434Z'}
{'type': 'l2update', 'product_id': 'BTC-USD', 'changes': [['sell', '38418.72', '0.00000000']], 'time': '2021-05-20T03:56:15.101434Z'}
{'type': 'l2update', 'product_id': 'BTC-USD', 'changes': [['sell', '38360.03', '0.00000000']], 'time': '2021-05-20T03:56:15.102972Z'}
{'type': 'l2update', 'product_id': 'BTC-USD', 'changes': [['sell', '38472.52', '0.00000000']], 'time': '2021-05-20T03:56:15.105689Z'}
{'type': 'l2update', 'product_id': 'BTC-USD', 'changes': [['buy', '38311.92', '0.59116555']], 'time': '2021-05-20T03:56:15.105752Z'}
{'type': 'l2update', 'product_id': 'BTC-USD', 'changes': [['sell', '38584.36', '0.00000000']], 'time': '2021-05-20T03:56:15.107346Z'}
{'type': 'l2update', 'product_id': 'BTC-USD', 'changes': [['buy', '38148.17', '0.00000000']], 'time': '2021-05-20T03:56:15.113284Z'}
{'type': 'l2update', 'product_id': 'BTC-USD', 'changes': [['buy', '38263.33', '0.12252924']], 'time': '2021-05-20T03:56:15.114864Z'}
{'type': 'l2update', 'product_id': 'BTC-USD', 'changes': [['sell', '38443.55', '0.03052289']], 'time': '2021-05-20T03:56:15.120263Z'}
{'type': 'l2update', 'product_id': 'BTC-USD', 'changes': [['buy', '38290.64', '0.03823166']], 'time': '2021-05-20T03:56:15.124594Z'}
{'type': 'l2update', 'product_id': 'BTC-USD', 'changes': [['sell', '38516.81', '0.01000000']], 'time': '2021-05-20T03:56:15.124617Z'}
{'type': 'l2update', 'product_id': 'BTC-USD', 'changes': [['sell', '38560.37', '0.00648334']], 'time': '2021-05-20T03:56:15.130679Z'}
{'type': 'l2update', 'product_id': 'BTC-USD', 'changes': [['sell', '39134.38', '0.00000000']], 'time': '2021-05-20T03:56:15.132087Z'}
{'type': 'l2update', 'product_id': 'BTC-USD', 'changes': [['buy', '38331.46', '0.15176479']], 'time': '2021-05-20T03:56:15.137442Z'}
{'type': 'l2update', 'product_id': 'BTC-USD', 'changes': [['buy', '38165.30', '0.01000000']], 'time': '2021-05-20T03:56:15.145060Z'}
{'type': 'l2update', 'product_id': 'BTC-USD', 'changes': [['sell', '38560.37', '0.00000000']], 'time': '2021-05-20T03:56:15.150423Z'}
{'type': 'l2update', 'product_id': 'BTC-USD', 'changes': [['sell', '38368.30', '0.09669133']], 'time': '2021-05-20T03:56:15.152148Z'}
{'type': 'l2update', 'product_id': 'BTC-USD', 'changes': [['sell', '38481.15', '0.00000000']], 'time': '2021-05-20T03:56:15.152328Z'}
{'type': 'l2update', 'product_id': 'BTC-USD', 'changes': [['buy', '37524.58', '0.00000000']], 'time': '2021-05-20T03:56:15.159146Z'}
{'type': 'l2update', 'product_id': 'BTC-USD', 'changes': [['sell', '38545.97', '0.00648576']], 'time': '2021-05-20T03:56:15.163595Z'}
{'type': 'l2update', 'product_id': 'BTC-USD', 'changes': [['sell', '38374.24', '0.03000000']], 'time': '2021-05-20T03:56:15.164022Z'}
{'type': 'l2update', 'product_id': 'BTC-USD', 'changes': [['buy', '38162.24', '0.00000000']], 'time': '2021-05-20T03:56:15.165962Z'}
{'type': 'l2update', 'product_id': 'BTC-USD', 'changes': [['sell', '39114.47', '0.00330000']], 'time': '2021-05-20T03:56:15.166926Z'}
{'type': 'l2update', 'product_id': 'BTC-USD', 'changes': [['sell', '38374.24', '0.00000000']], 'time': '2021-05-20T03:56:15.168798Z'}
{'type': 'l2update', 'product_id': 'BTC-USD', 'changes': [['sell', '38474.83', '0.00000000']], 'time': '2021-05-20T03:56:15.170408Z'}
{'type': 'l2update', 'product_id': 'BTC-USD', 'changes': [['buy', '38307.61', '0.00000000']], 'time': '2021-05-20T03:56:15.171950Z'}
{'type': 'l2update', 'product_id': 'BTC-USD', 'changes': [['sell', '38468.76', '0.01134432']], 'time': '2021-05-20T03:56:15.172467Z'}
{'type': 'l2update', 'product_id': 'BTC-USD', 'changes': [['sell', '39126.23', '0.06624977']], 'time': '2021-05-20T03:56:15.172667Z'}
{'type': 'l2update', 'product_id': 'BTC-USD', 'changes': [['sell', '38545.97', '0.00000000']], 'time': '2021-05-20T03:56:15.173366Z'}
{'type': 'l2update', 'product_id': 'BTC-USD', 'changes': [['buy', '38331.46', '0.16539424']], 'time': '2021-05-20T03:56:15.175625Z'}
{'type': 'l2update', 'product_id': 'BTC-USD', 'changes': [['buy', '38290.63', '0.00000000']], 'time': '2021-05-20T03:56:15.178596Z'}
{'type': 'l2update', 'product_id': 'BTC-USD', 'changes': [['buy', '38129.11', '0.95109760']], 'time': '2021-05-20T03:56:15.179644Z'}
{'type': 'l2update', 'product_id': 'BTC-USD', 'changes': [['sell', '38462.67', '0.01000000']], 'time': '2021-05-20T03:56:15.179851Z'}
{'type': 'l2update', 'product_id': 'BTC-USD', 'changes': [['buy', '38304.83', '0.00000000']], 'time': '2021-05-20T03:56:15.180597Z'}
{'type': 'l2update', 'product_id': 'BTC-USD', 'changes': [['buy', '38304.56', '0.00000000']], 'time': '2021-05-20T03:56:15.186826Z'}
{'type': 'l2update', 'product_id': 'BTC-USD', 'changes': [['buy', '38303.32', '0.00000000']], 'time': '2021-05-20T03:56:15.190260Z'}
{'type': 'l2update', 'product_id': 'BTC-USD', 'changes': [['buy', '38300.51', '0.00000000']], 'time': '2021-05-20T03:56:15.193909Z'}
{'type': 'l2update', 'product_id': 'BTC-USD', 'changes': [['buy', '38285.80', '0.47160000']], 'time': '2021-05-20T03:56:15.194971Z'}
{'type': 'l2update', 'product_id': 'BTC-USD', 'changes': [['sell', '38374.23', '0.00000000']], 'time': '2021-05-20T03:56:15.197448Z'}
{'type': 'l2update', 'product_id': 'BTC-USD', 'changes': [['buy', '38285.80', '0.00000000']], 'time': '2021-05-20T03:56:15.200862Z'}
{'type': 'l2update', 'product_id': 'BTC-USD', 'changes': [['sell', '38499.07', '0.30081158']], 'time': '2021-05-20T03:56:15.205656Z'}
{'type': 'l2update', 'product_id': 'BTC-USD', 'changes': [['sell', '38366.80', '0.02000000']], 'time': '2021-05-20T03:56:15.209575Z'}
{'type': 'l2update', 'product_id': 'BTC-USD', 'changes': [['sell', '43100.00', '1.09530000']], 'time': '2021-05-20T03:56:15.214725Z'}
{'type': 'l2update', 'product_id': 'BTC-USD', 'changes': [['buy', '38228.28', '0.00000000']], 'time': '2021-05-20T03:56:15.215602Z'}
{'type': 'l2update', 'product_id': 'BTC-USD', 'changes': [['sell', '38461.52', '0.00000000']], 'time': '2021-05-20T03:56:15.220591Z'}
{'type': 'l2update', 'product_id': 'BTC-USD', 'changes': [['sell', '38442.46', '0.00000000']], 'time': '2021-05-20T03:56:15.221593Z'}
{'type': 'l2update', 'product_id': 'BTC-USD', 'changes': [['sell', '38367.75', '0.03000000']], 'time': '2021-05-20T03:56:15.222271Z'}
{'type': 'l2update', 'product_id': 'BTC-USD', 'changes': [['buy', '38293.92', '0.01000000']], 'time': '2021-05-20T03:56:15.234180Z'}
{'type': 'l2update', 'product_id': 'BTC-USD', 'changes': [['buy', '38315.16', '0.52000000']], 'time': '2021-05-20T03:56:15.237067Z'}
{'type': 'l2update', 'product_id': 'BTC-USD', 'changes': [['buy', '38150.83', '0.05012967']], 'time': '2021-05-20T03:56:15.237842Z'}
{'type': 'l2update', 'product_id': 'BTC-USD', 'changes': [['sell', '38499.07', '0.00000000']], 'time': '2021-05-20T03:56:15.238796Z'}
{'type': 'l2update', 'product_id': 'BTC-USD', 'changes': [['sell', '38449.58', '0.01595000']], 'time': '2021-05-20T03:56:15.241249Z'}
{'type': 'l2update', 'product_id': 'BTC-USD', 'changes': [['sell', '43100.00', '1.26070000']], 'time': '2021-05-20T03:56:15.241323Z'}
{'type': 'l2update', 'product_id': 'BTC-USD', 'changes': [['sell', '38331.47', '0.00000000']], 'time': '2021-05-20T03:56:15.243163Z'}
{'type': 'l2update', 'product_id': 'BTC-USD', 'changes': [['buy', '38311.92', '0.00000000']], 'time': '2021-05-20T03:56:15.245463Z'}
{'type': 'l2update', 'product_id': 'BTC-USD', 'changes': [['buy', '38293.92', '0.03000000']], 'time': '2021-05-20T03:56:15.245850Z'}
{'type': 'l2update', 'product_id': 'BTC-USD', 'changes': [['sell', '38354.82', '0.00000000']], 'time': '2021-05-20T03:56:15.249032Z'}
{'type': 'l2update', 'product_id': 'BTC-USD', 'changes': [['sell', '38339.72', '0.00000000']], 'time': '2021-05-20T03:56:15.249589Z'}
{'type': 'l2update', 'product_id': 'BTC-USD', 'changes': [['sell', '38339.40', '0.00000000']], 'time': '2021-05-20T03:56:15.249885Z'}
{'type': 'l2update', 'product_id': 'BTC-USD', 'changes': [['sell', '38361.54', '0.05000000']], 'time': '2021-05-20T03:56:15.257769Z'}
{'type': 'l2update', 'product_id': 'BTC-USD', 'changes': [['buy', '38293.92', '0.06000000']], 'time': '2021-05-20T03:56:15.257966Z'}
{'type': 'l2update', 'product_id': 'BTC-USD', 'changes': [['buy', '38326.80', '0.05178401']], 'time': '2021-05-20T03:56:15.262165Z'}
{'type': 'l2update', 'product_id': 'BTC-USD', 'changes': [['buy', '38221.08', '0.00000000']], 'time': '2021-05-20T03:56:15.263164Z'}
{'type': 'l2update', 'product_id': 'BTC-USD', 'changes': [['buy', '38315.17', '0.59116555']], 'time': '2021-05-20T03:56:15.270286Z'}
{'type': 'l2update', 'product_id': 'BTC-USD', 'changes': [['buy', '38301.88', '0.04818966']], 'time': '2021-05-20T03:56:15.270319Z'}
{'type': 'l2update', 'product_id': 'BTC-USD', 'changes': [['sell', '38338.74', '0.04976059']], 'time': '2021-05-20T03:56:15.270409Z'}
{'type': 'l2update', 'product_id': 'BTC-USD', 'changes': [['sell', '38443.55', '0.00000000']], 'time': '2021-05-20T03:56:15.272453Z'}
{'type': 'l2update', 'product_id': 'BTC-USD', 'changes': [['sell', '38339.21', '0.07460000']], 'time': '2021-05-20T03:56:15.274518Z'}
{'type': 'l2update', 'product_id': 'BTC-USD', 'changes': [['buy', '38310.70', '0.16000000']], 'time': '2021-05-20T03:56:15.274629Z'}
{'type': 'l2update', 'product_id': 'BTC-USD', 'changes': [['buy', '38293.92', '0.10000000']], 'time': '2021-05-20T03:56:15.274745Z'}
{'type': 'l2update', 'product_id': 'BTC-USD', 'changes': [['sell', '38339.73', '0.00000000']], 'time': '2021-05-20T03:56:15.275134Z'}
{'type': 'l2update', 'product_id': 'BTC-USD', 'changes': [['buy', '38312.20', '0.59300000']], 'time': '2021-05-20T03:56:15.279198Z'}
{'type': 'l2update', 'product_id': 'BTC-USD', 'changes': [['sell', '38339.21', '0.00000000']], 'time': '2021-05-20T03:56:15.282641Z'}
{'type': 'l2update', 'product_id': 'BTC-USD', 'changes': [['sell', '38451.89', '0.00000000']], 'time': '2021-05-20T03:56:15.286899Z'}
{'type': 'l2update', 'product_id': 'BTC-USD', 'changes': [['buy', '38220.28', '0.00000000']], 'time': '2021-05-20T03:56:15.287481Z'}
{'type': 'l2update', 'product_id': 'BTC-USD', 'changes': [['sell', '38362.52', '0.00000000']], 'time': '2021-05-20T03:56:15.288337Z'}
{'type': 'l2update', 'product_id': 'BTC-USD', 'changes': [['buy', '38293.92', '0.15000000']], 'time': '2021-05-20T03:56:15.288527Z'}
{'type': 'l2update', 'product_id': 'BTC-USD', 'changes': [['sell', '38339.44', '0.00000000']], 'time': '2021-05-20T03:56:15.294109Z'}
{'type': 'l2update', 'product_id': 'BTC-USD', 'changes': [['sell', '38379.00', '0.10000000']], 'time': '2021-05-20T03:56:15.297319Z'}
{'type': 'l2update', 'product_id': 'BTC-USD', 'changes': [['sell', '38484.10', '0.00000000']], 'time': '2021-05-20T03:56:15.299817Z'}
{'type': 'l2update', 'product_id': 'BTC-USD', 'changes': [['sell', '38339.45', '0.00000000']], 'time': '2021-05-20T03:56:15.302844Z'}
{'type': 'l2update', 'product_id': 'BTC-USD', 'changes': [['sell', '38435.92', '0.01300866']], 'time': '2021-05-20T03:56:15.305063Z'}
{'type': 'l2update', 'product_id': 'BTC-USD', 'changes': [['sell', '38427.09', '0.01403582']], 'time': '2021-05-20T03:56:15.305283Z'}
{'type': 'l2update', 'product_id': 'BTC-USD', 'changes': [['buy', '38303.01', '0.47770000']], 'time': '2021-05-20T03:56:15.305379Z'}
{'type': 'l2update', 'product_id': 'BTC-USD', 'changes': [['sell', '38349.61', '0.00000000']], 'time': '2021-05-20T03:56:15.307248Z'}
{'type': 'l2update', 'product_id': 'BTC-USD', 'changes': [['sell', '38501.72', '0.30080762']], 'time': '2021-05-20T03:56:15.312779Z'}
{'type': 'l2update', 'product_id': 'BTC-USD', 'changes': [['buy', '38304.59', '0.04389316']], 'time': '2021-05-20T03:56:15.313391Z'}
{'type': 'l2update', 'product_id': 'BTC-USD', 'changes': [['sell', '38354.76', '0.05611581']], 'time': '2021-05-20T03:56:15.313391Z'}
{'type': 'l2update', 'product_id': 'BTC-USD', 'changes': [['sell', '38368.21', '0.05000000']], 'time': '2021-05-20T03:56:15.313472Z'}
{'type': 'l2update', 'product_id': 'BTC-USD', 'changes': [['sell', '38374.55', '0.00000000']], 'time': '2021-05-20T03:56:15.313573Z'}
{'type': 'l2update', 'product_id': 'BTC-USD', 'changes': [['sell', '38470.93', '0.01000000']], 'time': '2021-05-20T03:56:15.314107Z'}
{'type': 'l2update', 'product_id': 'BTC-USD', 'changes': [['sell', '38338.74', '0.00000000']], 'time': '2021-05-20T03:56:15.314711Z'}
{'type': 'l2update', 'product_id': 'BTC-USD', 'changes': [['buy', '38290.38', '0.00000000']], 'time': '2021-05-20T03:56:15.319886Z'}
{'type': 'l2update', 'product_id': 'BTC-USD', 'changes': [['sell', '38369.03', '0.00000000']], 'time': '2021-05-20T03:56:15.321001Z'}
{'type': 'l2update', 'product_id': 'BTC-USD', 'changes': [['sell', '38368.46', '0.00000000']], 'time': '2021-05-20T03:56:15.325641Z'}
{'type': 'l2update', 'product_id': 'BTC-USD', 'changes': [['sell', '38501.72', '0.00000000']], 'time': '2021-05-20T03:56:15.326264Z'}
{'type': 'l2update', 'product_id': 'BTC-USD', 'changes': [['sell', '38366.80', '0.00000000']], 'time': '2021-05-20T03:56:15.328771Z'}
{'type': 'l2update', 'product_id': 'BTC-USD', 'changes': [['sell', '38368.31', '0.00000000']], 'time': '2021-05-20T03:56:15.329800Z'}
{'type': 'l2update', 'product_id': 'BTC-USD', 'changes': [['sell', '38346.53', '0.50000000']], 'time': '2021-05-20T03:56:15.330046Z'}
{'type': 'l2update', 'product_id': 'BTC-USD', 'changes': [['buy', '38209.83', '0.03164717']], 'time': '2021-05-20T03:56:15.330412Z'}
{'type': 'l2update', 'product_id': 'BTC-USD', 'changes': [['buy', '38219.47', '0.00000000']], 'time': '2021-05-20T03:56:15.330412Z'}
{'type': 'l2update', 'product_id': 'BTC-USD', 'changes': [['sell', '38367.75', '0.00000000']], 'time': '2021-05-20T03:56:15.331620Z'}
{'type': 'l2update', 'product_id': 'BTC-USD', 'changes': [['sell', '38368.21', '0.00000000']], 'time': '2021-05-20T03:56:15.335839Z'}
{'type': 'l2update', 'product_id': 'BTC-USD', 'changes': [['buy', '38209.83', '0.00000000']], 'time': '2021-05-20T03:56:15.350023Z'}
{'type': 'l2update', 'product_id': 'BTC-USD', 'changes': [['buy', '38252.59', '0.00000000']], 'time': '2021-05-20T03:56:15.351469Z'}
{'type': 'l2update', 'product_id': 'BTC-USD', 'changes': [['sell', '38387.64', '0.00000000']], 'time': '2021-05-20T03:56:15.354138Z'}
{'type': 'l2update', 'product_id': 'BTC-USD', 'changes': [['sell', '38364.41', '0.41440000']], 'time': '2021-05-20T03:56:15.384989Z'}
{'type': 'l2update', 'product_id': 'BTC-USD', 'changes': [['buy', '38331.89', '0.01492000']], 'time': '2021-05-20T03:56:15.385140Z'}
{'type': 'l2update', 'product_id': 'BTC-USD', 'changes': [['sell', '38346.53', '2.98969908']], 'time': '2021-05-20T03:56:15.385444Z'}
{'type': 'l2update', 'product_id': 'BTC-USD', 'changes': [['buy', '38331.84', '0.07460000']], 'time': '2021-05-20T03:56:15.386325Z'}
{'type': 'l2update', 'product_id': 'BTC-USD', 'changes': [['sell', '38361.94', '0.39490432']], 'time': '2021-05-20T03:56:15.386622Z'}
{'type': 'l2update', 'product_id': 'BTC-USD', 'changes': [['sell', '38346.24', '0.07460000']], 'time': '2021-05-20T03:56:15.387087Z'}
{'type': 'l2update', 'product_id': 'BTC-USD', 'changes': [['buy', '38164.65', '0.05148734']], 'time': '2021-05-20T03:56:15.387553Z'}
{'type': 'l2update', 'product_id': 'BTC-USD', 'changes': [['buy', '38303.01', '0.00000000']], 'time': '2021-05-20T03:56:15.389822Z'}
{'type': 'l2update', 'product_id': 'BTC-USD', 'changes': [['buy', '38331.84', '0.00000000']], 'time': '2021-05-20T03:56:15.394001Z'}
{'type': 'l2update', 'product_id': 'BTC-USD', 'changes': [['buy', '38331.46', '0.16362945']], 'time': '2021-05-20T03:56:15.398888Z'}
{'type': 'l2update', 'product_id': 'BTC-USD', 'changes': [['buy', '38311.85', '0.00000000']], 'time': '2021-05-20T03:56:15.401987Z'}
{'type': 'l2update', 'product_id': 'BTC-USD', 'changes': [['buy', '38150.83', '0.00000000']], 'time': '2021-05-20T03:56:15.402876Z'}
{'type': 'l2update', 'product_id': 'BTC-USD', 'changes': [['buy', '38323.85', '0.00000000']], 'time': '2021-05-20T03:56:15.418621Z'}
{'type': 'l2update', 'product_id': 'BTC-USD', 'changes': [['sell', '38364.41', '0.00000000']], 'time': '2021-05-20T03:56:15.422746Z'}
{'type': 'l2update', 'product_id': 'BTC-USD', 'changes': [['sell', '38378.42', '0.04000000']], 'time': '2021-05-20T03:56:15.462429Z'}
{'type': 'l2update', 'product_id': 'BTC-USD', 'changes': [['sell', '38350.96', '0.00600000']], 'time': '2021-05-20T03:56:15.462978Z'}
{'type': 'l2update', 'product_id': 'BTC-USD', 'changes': [['buy', '38235.33', '0.50000000']], 'time': '2021-05-20T03:56:15.463066Z'}
{'type': 'l2update', 'product_id': 'BTC-USD', 'changes': [['sell', '38367.70', '1.99500000']], 'time': '2021-05-20T03:56:15.463300Z'}
{'type': 'l2update', 'product_id': 'BTC-USD', 'changes': [['sell', '38345.65', '0.15000000']], 'time': '2021-05-20T03:56:15.463984Z'}
{'type': 'l2update', 'product_id': 'BTC-USD', 'changes': [['sell', '38346.12', '0.01492000']], 'time': '2021-05-20T03:56:15.465151Z'}
{'type': 'l2update', 'product_id': 'BTC-USD', 'changes': [['buy', '38323.86', '1.06251193']], 'time': '2021-05-20T03:56:15.466685Z'}
{'type': 'l2update', 'product_id': 'BTC-USD', 'changes': [['sell', '38379.98', '0.41807384']], 'time': '2021-05-20T03:56:15.466956Z'}
{'type': 'l2update', 'product_id': 'BTC-USD', 'changes': [['buy', '38332.18', '0.02251804']], 'time': '2021-05-20T03:56:15.468774Z'}
{'type': 'l2update', 'product_id': 'BTC-USD', 'changes': [['buy', '38322.30', '0.00176479']], 'time': '2021-05-20T03:56:15.471501Z'}
{'type': 'l2update', 'product_id': 'BTC-USD', 'changes': [['buy', '38324.71', '0.00300000']], 'time': '2021-05-20T03:56:15.472367Z'}
{'type': 'l2update', 'product_id': 'BTC-USD', 'changes': [['sell', '38372.47', '0.01000000']], 'time': '2021-05-20T03:56:15.475901Z'}
{'type': 'l2update', 'product_id': 'BTC-USD', 'changes': [['buy', '38332.18', '0.05486993']], 'time': '2021-05-20T03:56:15.476106Z'}
{'type': 'l2update', 'product_id': 'BTC-USD', 'changes': [['buy', '38331.51', '0.84700000']], 'time': '2021-05-20T03:56:15.476355Z'}
{'type': 'l2update', 'product_id': 'BTC-USD', 'changes': [['sell', '38467.70', '0.00000000']], 'time': '2021-05-20T03:56:15.479107Z'}
{'type': 'l2update', 'product_id': 'BTC-USD', 'changes': [['buy', '37654.92', '0.05410000']], 'time': '2021-05-20T03:56:15.479850Z'}
{'type': 'l2update', 'product_id': 'BTC-USD', 'changes': [['sell', '38346.12', '0.00000000']], 'time': '2021-05-20T03:56:15.480828Z'}
{'type': 'l2update', 'product_id': 'BTC-USD', 'changes': [['sell', '38374.30', '0.01000000']], 'time': '2021-05-20T03:56:15.482700Z'}
{'type': 'l2update', 'product_id': 'BTC-USD', 'changes': [['buy', '38332.18', '0.07460000']], 'time': '2021-05-20T03:56:15.482716Z'}
{'type': 'l2update', 'product_id': 'BTC-USD', 'changes': [['sell', '38379.98', '0.45173933']], 'time': '2021-05-20T03:56:15.483254Z'}
{'type': 'l2update', 'product_id': 'BTC-USD', 'changes': [['buy', '38258.03', '0.03366549']], 'time': '2021-05-20T03:56:15.483254Z'}
{'type': 'l2update', 'product_id': 'BTC-USD', 'changes': [['buy', '38140.59', '0.04653781']], 'time': '2021-05-20T03:56:15.484989Z'}
{'type': 'l2update', 'product_id': 'BTC-USD', 'changes': [['buy', '37534.02', '0.06411006']], 'time': '2021-05-20T03:56:15.485417Z'}
{'type': 'l2update', 'product_id': 'BTC-USD', 'changes': [['sell', '38550.77', '0.00648495']], 'time': '2021-05-20T03:56:15.486048Z'}
{'type': 'l2update', 'product_id': 'BTC-USD', 'changes': [['buy', '38227.22', '0.00000000']], 'time': '2021-05-20T03:56:15.489190Z'}
{'type': 'l2update', 'product_id': 'BTC-USD', 'changes': [['buy', '38323.86', '0.00000000']], 'time': '2021-05-20T03:56:15.493569Z'}
{'type': 'l2update', 'product_id': 'BTC-USD', 'changes': [['sell', '38384.35', '0.29247068']], 'time': '2021-05-20T03:56:15.495394Z'}
{'type': 'l2update', 'product_id': 'BTC-USD', 'changes': [['buy', '38279.50', '0.00000000']], 'time': '2021-05-20T03:56:15.496072Z'}
{'type': 'l2update', 'product_id': 'BTC-USD', 'changes': [['sell', '38374.64', '0.00000000']], 'time': '2021-05-20T03:56:15.500587Z'}
{'type': 'l2update', 'product_id': 'BTC-USD', 'changes': [['buy', '38331.89', '0.00000000']], 'time': '2021-05-20T03:56:15.505514Z'}
{'type': 'l2update', 'product_id': 'BTC-USD', 'changes': [['sell', '38346.24', '0.00000000']], 'time': '2021-05-20T03:56:15.507394Z'}
{'type': 'l2update', 'product_id': 'BTC-USD', 'changes': [['sell', '38373.64', '0.02000000']], 'time': '2021-05-20T03:56:15.509513Z'}
{'type': 'l2update', 'product_id': 'BTC-USD', 'changes': [['sell', '38447.58', '0.01000000']], 'time': '2021-05-20T03:56:15.509709Z'}
{'type': 'l2update', 'product_id': 'BTC-USD', 'changes': [['sell', '39126.23', '0.00000000']], 'time': '2021-05-20T03:56:15.510174Z'}
{'type': 'l2update', 'product_id': 'BTC-USD', 'changes': [['buy', '38304.59', '0.00000000']], 'time': '2021-05-20T03:56:15.511951Z'}
{'type': 'l2update', 'product_id': 'BTC-USD', 'changes': [['sell', '38354.76', '0.00000000']], 'time': '2021-05-20T03:56:15.511951Z'}
{'type': 'l2update', 'product_id': 'BTC-USD', 'changes': [['sell', '38384.35', '0.33105453']], 'time': '2021-05-20T03:56:15.517881Z'}
{'type': 'l2update', 'product_id': 'BTC-USD', 'changes': [['buy', '38252.16', '0.03858385']], 'time': '2021-05-20T03:56:15.517881Z'}
{'type': 'l2update', 'product_id': 'BTC-USD', 'changes': [['buy', '38291.89', '0.01000000']], 'time': '2021-05-20T03:56:15.518021Z'}
{'type': 'l2update', 'product_id': 'BTC-USD', 'changes': [['buy', '38331.51', '0.00000000']], 'time': '2021-05-20T03:56:15.518355Z'}
{'type': 'l2update', 'product_id': 'BTC-USD', 'changes': [['buy', '38240.18', '0.11379060']], 'time': '2021-05-20T03:56:15.527862Z'}
{'type': 'l2update', 'product_id': 'BTC-USD', 'changes': [['buy', '38255.12', '0.00000000']], 'time': '2021-05-20T03:56:15.529956Z'}
{'type': 'l2update', 'product_id': 'BTC-USD', 'changes': [['buy', '38321.90', '1.06251193']], 'time': '2021-05-20T03:56:15.532223Z'}
{'type': 'l2update', 'product_id': 'BTC-USD', 'changes': [['sell', '38345.20', '0.01492000']], 'time': '2021-05-20T03:56:15.532253Z'}
{'type': 'l2update', 'product_id': 'BTC-USD', 'changes': [['buy', '38278.50', '0.10000000']], 'time': '2021-05-20T03:56:15.533387Z'}
{'type': 'l2update', 'product_id': 'BTC-USD', 'changes': [['buy', '38296.41', '1.20000000']], 'time': '2021-05-20T03:56:15.537197Z'}
{'type': 'l2update', 'product_id': 'BTC-USD', 'changes': [['sell', '38393.95', '0.33444977']], 'time': '2021-05-20T03:56:15.537423Z'}
{'type': 'l2update', 'product_id': 'BTC-USD', 'changes': [['sell', '38346.55', '0.00000000']], 'time': '2021-05-20T03:56:15.539800Z'}
{'type': 'l2update', 'product_id': 'BTC-USD', 'changes': [['sell', '38377.76', '0.03000000']], 'time': '2021-05-20T03:56:15.542146Z'}
{'type': 'l2update', 'product_id': 'BTC-USD', 'changes': [['sell', '38346.54', '0.05000000']], 'time': '2021-05-20T03:56:15.543328Z'}
{'type': 'l2update', 'product_id': 'BTC-USD', 'changes': [['buy', '38284.55', '0.00000000']], 'time': '2021-05-20T03:56:15.548287Z'}
{'type': 'l2update', 'product_id': 'BTC-USD', 'changes': [['sell', '38393.95', '0.36829753']], 'time': '2021-05-20T03:56:15.551395Z'}
{'type': 'l2update', 'product_id': 'BTC-USD', 'changes': [['buy', '38239.26', '0.03384776']], 'time': '2021-05-20T03:56:15.551395Z'}
{'type': 'l2update', 'product_id': 'BTC-USD', 'changes': [['buy', '38326.82', '0.18000000']], 'time': '2021-05-20T03:56:15.551440Z'}
{'type': 'l2update', 'product_id': 'BTC-USD', 'changes': [['buy', '38290.65', '0.02611604']], 'time': '2021-05-20T03:56:15.551711Z'}
{'type': 'l2update', 'product_id': 'BTC-USD', 'changes': [['sell', '38516.81', '0.00000000']], 'time': '2021-05-20T03:56:15.554534Z'}
{'type': 'l2update', 'product_id': 'BTC-USD', 'changes': [['sell', '38458.87', '0.00000000']], 'time': '2021-05-20T03:56:15.555744Z'}
{'type': 'l2update', 'product_id': 'BTC-USD', 'changes': [['sell', '38660.39', '0.00000000']], 'time': '2021-05-20T03:56:15.555831Z'}
{'type': 'l2update', 'product_id': 'BTC-USD', 'changes': [['sell', '38339.18', '0.01028189']], 'time': '2021-05-20T03:56:15.559386Z'}
{'type': 'l2update', 'product_id': 'BTC-USD', 'changes': [['sell', '38344.57', '0.07460000']], 'time': '2021-05-20T03:56:15.560995Z'}
{'type': 'l2update', 'product_id': 'BTC-USD', 'changes': [['buy', '38332.56', '0.01492000']], 'time': '2021-05-20T03:56:15.561017Z'}
{'type': 'l2update', 'product_id': 'BTC-USD', 'changes': [['buy', '38308.37', '0.05153000']], 'time': '2021-05-20T03:56:15.561646Z'}
{'type': 'l2update', 'product_id': 'BTC-USD', 'changes': [['sell', '38351.98', '0.05776111']], 'time': '2021-05-20T03:56:15.561646Z'}
{'type': 'l2update', 'product_id': 'BTC-USD', 'changes': [['sell', '38431.46', '1.20000000']], 'time': '2021-05-20T03:56:15.562061Z'}
{'type': 'l2update', 'product_id': 'BTC-USD', 'changes': [['sell', '38378.51', '0.05000000']], 'time': '2021-05-20T03:56:15.567909Z'}
{'type': 'l2update', 'product_id': 'BTC-USD', 'changes': [['buy', '38332.72', '0.04831179']], 'time': '2021-05-20T03:56:15.568824Z'}
{'type': 'l2update', 'product_id': 'BTC-USD', 'changes': [['sell', '38344.66', '0.05138319']], 'time': '2021-05-20T03:56:15.568873Z'}
{'type': 'l2update', 'product_id': 'BTC-USD', 'changes': [['sell', '38398.89', '0.31014295']], 'time': '2021-05-20T03:56:15.569159Z'}
{'type': 'l2update', 'product_id': 'BTC-USD', 'changes': [['sell', '38374.30', '0.00000000']], 'time': '2021-05-20T03:56:15.571135Z'}
{'type': 'l2update', 'product_id': 'BTC-USD', 'changes': [['buy', '38332.18', '0.04224811']], 'time': '2021-05-20T03:56:15.573430Z'}
{'type': 'l2update', 'product_id': 'BTC-USD', 'changes': [['buy', '38332.18', '0.01973007']], 'time': '2021-05-20T03:56:15.574234Z'}
{'type': 'l2update', 'product_id': 'BTC-USD', 'changes': [['sell', '38345.20', '0.00000000']], 'time': '2021-05-20T03:56:15.574880Z'}
{'type': 'l2update', 'product_id': 'BTC-USD', 'changes': [['sell', '38344.57', '0.00000000']], 'time': '2021-05-20T03:56:15.575226Z'}
{'type': 'l2update', 'product_id': 'BTC-USD', 'changes': [['buy', '38332.56', '0.00000000']], 'time': '2021-05-20T03:56:15.575373Z'}
{'type': 'l2update', 'product_id': 'BTC-USD', 'changes': [['buy', '38331.46', '0.17380063']], 'time': '2021-05-20T03:56:15.578416Z'}
{'type': 'l2update', 'product_id': 'BTC-USD', 'changes': [['sell', '38666.93', '0.01992060']], 'time': '2021-05-20T03:56:15.582381Z'}
{'type': 'l2update', 'product_id': 'BTC-USD', 'changes': [['sell', '38498.46', '0.01000000']], 'time': '2021-05-20T03:56:15.582451Z'}
{'type': 'l2update', 'product_id': 'BTC-USD', 'changes': [['sell', '38404.02', '0.03142865']], 'time': '2021-05-20T03:56:15.582885Z'}
{'type': 'l2update', 'product_id': 'BTC-USD', 'changes': [['buy', '38232.82', '0.36968489']], 'time': '2021-05-20T03:56:15.582885Z'}
{'type': 'l2update', 'product_id': 'BTC-USD', 'changes': [['sell', '38423.72', '0.02602559']], 'time': '2021-05-20T03:56:15.583307Z'}
{'type': 'l2update', 'product_id': 'BTC-USD', 'changes': [['buy', '38315.17', '0.00000000']], 'time': '2021-05-20T03:56:15.583886Z'}
{'type': 'l2update', 'product_id': 'BTC-USD', 'changes': [['buy', '38291.89', '0.00000000']], 'time': '2021-05-20T03:56:15.586025Z'}
{'type': 'l2update', 'product_id': 'BTC-USD', 'changes': [['buy', '38332.18', '0.00000000']], 'time': '2021-05-20T03:56:15.587248Z'}
{'type': 'l2update', 'product_id': 'BTC-USD', 'changes': [['sell', '38468.76', '0.00000000']], 'time': '2021-05-20T03:56:15.587673Z'}
{'type': 'l2update', 'product_id': 'BTC-USD', 'changes': [['buy', '38301.49', '0.00000000']], 'time': '2021-05-20T03:56:15.590634Z'}
{'type': 'l2update', 'product_id': 'BTC-USD', 'changes': [['buy', '38300.68', '0.00000000']], 'time': '2021-05-20T03:56:15.590634Z'}
{'type': 'l2update', 'product_id': 'BTC-USD', 'changes': [['buy', '38299.87', '0.00000000']], 'time': '2021-05-20T03:56:15.590634Z'}
{'type': 'l2update', 'product_id': 'BTC-USD', 'changes': [['sell', '38404.02', '0.38701666']], 'time': '2021-05-20T03:56:15.594047Z'}
{'type': 'l2update', 'product_id': 'BTC-USD', 'changes': [['buy', '38277.96', '0.00000000']], 'time': '2021-05-20T03:56:15.594907Z'}
{'type': 'l2update', 'product_id': 'BTC-USD', 'changes': [['buy', '38320.17', '0.07173003']], 'time': '2021-05-20T03:56:15.600893Z'}
{'type': 'l2update', 'product_id': 'BTC-USD', 'changes': [['sell', '38484.92', '0.01000000']], 'time': '2021-05-20T03:56:15.610348Z'}
{'type': 'l2update', 'product_id': 'BTC-USD', 'changes': [['sell', '38409.34', '0.03546148']], 'time': '2021-05-20T03:56:15.610501Z'}
{'type': 'l2update', 'product_id': 'BTC-USD', 'changes': [['buy', '38225.75', '0.03546148']], 'time': '2021-05-20T03:56:15.610501Z'}
{'type': 'l2update', 'product_id': 'BTC-USD', 'changes': [['sell', '38345.60', '0.55300000']], 'time': '2021-05-20T03:56:15.610702Z'}
{'type': 'l2update', 'product_id': 'BTC-USD', 'changes': [['buy', '38254.93', '0.01000000']], 'time': '2021-05-20T03:56:15.610839Z'}
{'type': 'l2update', 'product_id': 'BTC-USD', 'changes': [['sell', '38415.23', '0.32338471']], 'time': '2021-05-20T03:56:15.620397Z'}
{'type': 'l2update', 'product_id': 'BTC-USD', 'changes': [['sell', '38439.45', '0.00000000']], 'time': '2021-05-20T03:56:15.627819Z'}
{'type': 'l2update', 'product_id': 'BTC-USD', 'changes': [['buy', '38305.57', '0.42760000']], 'time': '2021-05-20T03:56:15.629110Z'}
{'type': 'l2update', 'product_id': 'BTC-USD', 'changes': [['buy', '38338.59', '0.00963584']], 'time': '2021-05-20T03:56:15.629206Z'}
{'type': 'l2update', 'product_id': 'BTC-USD', 'changes': [['sell', '38381.33', '0.50000000']], 'time': '2021-05-20T03:56:15.632041Z'}
{'type': 'l2update', 'product_id': 'BTC-USD', 'changes': [['buy', '38315.17', '0.59116555']], 'time': '2021-05-20T03:56:15.632537Z'}
{'type': 'l2update', 'product_id': 'BTC-USD', 'changes': [['sell', '38415.39', '0.02834435']], 'time': '2021-05-20T03:56:15.632746Z'}
{'type': 'l2update', 'product_id': 'BTC-USD', 'changes': [['buy', '38219.75', '0.02834435']], 'time': '2021-05-20T03:56:15.632746Z'}
{'type': 'l2update', 'product_id': 'BTC-USD', 'changes': [['buy', '38310.64', '0.02400000']], 'time': '2021-05-20T03:56:15.633187Z'}
{'type': 'l2update', 'product_id': 'BTC-USD', 'changes': [['buy', '38309.83', '0.02400000']], 'time': '2021-05-20T03:56:15.633187Z'}
{'type': 'l2update', 'product_id': 'BTC-USD', 'changes': [['buy', '38309.03', '0.02400000']], 'time': '2021-05-20T03:56:15.633187Z'}
{'type': 'l2update', 'product_id': 'BTC-USD', 'changes': [['sell', '38472.60', '0.00000000']], 'time': '2021-05-20T03:56:15.635960Z'}
{'type': 'l2update', 'product_id': 'BTC-USD', 'changes': [['sell', '38583.01', '0.00000000']], 'time': '2021-05-20T03:56:15.636158Z'}
{'type': 'l2update', 'product_id': 'BTC-USD', 'changes': [['buy', '38290.64', '0.00000000']], 'time': '2021-05-20T03:56:15.639759Z'}
{'type': 'l2update', 'product_id': 'BTC-USD', 'changes': [['sell', '38421.10', '0.39914717']], 'time': '2021-05-20T03:56:15.641759Z'}
{'type': 'l2update', 'product_id': 'BTC-USD', 'changes': [['sell', '38450.00', '1.80418201']], 'time': '2021-05-20T03:56:15.642138Z'}
{'type': 'l2update', 'product_id': 'BTC-USD', 'changes': [['sell', '38346.54', '0.00000000']], 'time': '2021-05-20T03:56:15.642503Z'}
{'type': 'l2update', 'product_id': 'BTC-USD', 'changes': [['buy', '38309.03', '0.00000000']], 'time': '2021-05-20T03:56:15.645088Z'}
{'type': 'l2update', 'product_id': 'BTC-USD', 'changes': [['buy', '38326.80', '0.00000000']], 'time': '2021-05-20T03:56:15.646984Z'}
{'type': 'l2update', 'product_id': 'BTC-USD', 'changes': [['sell', '38365.58', '0.41850000']], 'time': '2021-05-20T03:56:15.649023Z'}
{'type': 'l2update', 'product_id': 'BTC-USD', 'changes': [['sell', '38339.18', '0.21028189']], 'time': '2021-05-20T03:56:15.653624Z'}
{'type': 'l2update', 'product_id': 'BTC-USD', 'changes': [['sell', '38339.18', '0.20000000']], 'time': '2021-05-20T03:56:15.653805Z'}
{'type': 'l2update', 'product_id': 'BTC-USD', 'changes': [['sell', '38339.18', '0.08225060']], 'time': '2021-05-20T03:56:15.653805Z'}
{'type': 'l2update', 'product_id': 'BTC-USD', 'changes': [['buy', '38309.83', '0.00000000']], 'time': '2021-05-20T03:56:15.654374Z'}
{'type': 'l2update', 'product_id': 'BTC-USD', 'changes': [['buy', '38305.57', '0.00000000']], 'time': '2021-05-20T03:56:15.656712Z'}
{'type': 'l2update', 'product_id': 'BTC-USD', 'changes': [['buy', '38290.37', '0.00000000']], 'time': '2021-05-20T03:56:15.658837Z'}
{'type': 'l2update', 'product_id': 'BTC-USD', 'changes': [['buy', '38320.17', '0.00000000']], 'time': '2021-05-20T03:56:15.659072Z'}
{'type': 'l2update', 'product_id': 'BTC-USD', 'changes': [['sell', '38361.93', '0.05000000']], 'time': '2021-05-20T03:56:15.660127Z'}
{'type': 'l2update', 'product_id': 'BTC-USD', 'changes': [['sell', '38457.61', '0.01867687']], 'time': '2021-05-20T03:56:15.660414Z'}
{'type': 'l2update', 'product_id': 'BTC-USD', 'changes': [['buy', '38300.02', '0.04313876']], 'time': '2021-05-20T03:56:15.660449Z'}
{'type': 'l2update', 'product_id': 'BTC-USD', 'changes': [['sell', '38365.58', '0.00000000']], 'time': '2021-05-20T03:56:15.663223Z'}
{'type': 'l2update', 'product_id': 'BTC-USD', 'changes': [['buy', '38300.02', '0.13437671']], 'time': '2021-05-20T03:56:15.677232Z'}
{'type': 'l2update', 'product_id': 'BTC-USD', 'changes': [['buy', '38309.36', '0.02400000']], 'time': '2021-05-20T03:56:15.677262Z'}
{'type': 'l2update', 'product_id': 'BTC-USD', 'changes': [['sell', '38421.10', '0.43658928']], 'time': '2021-05-20T03:56:15.677296Z'}
{'type': 'l2update', 'product_id': 'BTC-USD', 'changes': [['sell', '38381.33', '0.00000000']], 'time': '2021-05-20T03:56:15.680373Z'}
{'type': 'l2update', 'product_id': 'BTC-USD', 'changes': [['buy', '38301.89', '0.04313876']], 'time': '2021-05-20T03:56:15.691907Z'}
{'type': 'l2update', 'product_id': 'BTC-USD', 'changes': [['sell', '38426.98', '0.39456207']], 'time': '2021-05-20T03:56:15.691964Z'}
{'type': 'l2update', 'product_id': 'BTC-USD', 'changes': [['sell', '38470.93', '0.00000000']], 'time': '2021-05-20T03:56:15.695843Z'}
{'type': 'l2update', 'product_id': 'BTC-USD', 'changes': [['sell', '38447.58', '0.00000000']], 'time': '2021-05-20T03:56:15.696561Z'}
{'type': 'l2update', 'product_id': 'BTC-USD', 'changes': [['buy', '38310.17', '0.02400000']], 'time': '2021-05-20T03:56:15.696794Z'}
{'type': 'l2update', 'product_id': 'BTC-USD', 'changes': [['sell', '38426.98', '0.42601787']], 'time': '2021-05-20T03:56:15.697642Z'}
{'type': 'l2update', 'product_id': 'BTC-USD', 'changes': [['buy', '37534.02', '0.00000000']], 'time': '2021-05-20T03:56:15.699385Z'}
{'type': 'l2update', 'product_id': 'BTC-USD', 'changes': [['buy', '38300.02', '0.09123795']], 'time': '2021-05-20T03:56:15.700884Z'}
{'type': 'l2update', 'product_id': 'BTC-USD', 'changes': [['buy', '38325.74', '0.07173003']], 'time': '2021-05-20T03:56:15.702398Z'}
{'type': 'l2update', 'product_id': 'BTC-USD', 'changes': [['sell', '39128.76', '0.06823381']], 'time': '2021-05-20T03:56:15.713430Z'}
{'type': 'l2update', 'product_id': 'BTC-USD', 'changes': [['sell', '38508.55', '0.01000000']], 'time': '2021-05-20T03:56:15.713571Z'}
{'type': 'l2update', 'product_id': 'BTC-USD', 'changes': [['sell', '38585.70', '0.02563610']], 'time': '2021-05-20T03:56:15.713755Z'}
{'type': 'l2update', 'product_id': 'BTC-USD', 'changes': [['sell', '38461.35', '0.01000000']], 'time': '2021-05-20T03:56:15.714266Z'}
{'type': 'l2update', 'product_id': 'BTC-USD', 'changes': [['sell', '38354.75', '0.10538026']], 'time': '2021-05-20T03:56:15.725885Z'}
{'type': 'l2update', 'product_id': 'BTC-USD', 'changes': [['sell', '38432.88', '0.03529856']], 'time': '2021-05-20T03:56:15.726779Z'}
{'type': 'l2update', 'product_id': 'BTC-USD', 'changes': [['sell', '38517.10', '0.00000000']], 'time': '2021-05-20T03:56:15.727088Z'}
{'type': 'l2update', 'product_id': 'BTC-USD', 'changes': [['sell', '38585.70', '0.00000000']], 'time': '2021-05-20T03:56:15.740841Z'}
{'type': 'l2update', 'product_id': 'BTC-USD', 'changes': [['buy', '38339.17', '0.01492000']], 'time': '2021-05-20T03:56:15.741214Z'}
{'type': 'l2update', 'product_id': 'BTC-USD', 'changes': [['sell', '38489.39', '0.01000000']], 'time': '2021-05-20T03:56:15.750850Z'}
{'type': 'l2update', 'product_id': 'BTC-USD', 'changes': [['sell', '38432.88', '0.39205365']], 'time': '2021-05-20T03:56:15.751159Z'}
{'type': 'l2update', 'product_id': 'BTC-USD', 'changes': [['sell', '38361.93', '0.00000000']], 'time': '2021-05-20T03:56:15.752161Z'}
{'type': 'l2update', 'product_id': 'BTC-USD', 'changes': [['buy', '38305.58', '0.40990000']], 'time': '2021-05-20T03:56:15.752349Z'}
{'type': 'l2update', 'product_id': 'BTC-USD', 'changes': [['sell', '38438.97', '0.03782586']], 'time': '2021-05-20T03:56:15.752468Z'}
{'type': 'l2update', 'product_id': 'BTC-USD', 'changes': [['buy', '38331.46', '0.16017118']], 'time': '2021-05-20T03:56:15.755853Z'}
{'type': 'l2update', 'product_id': 'BTC-USD', 'changes': [['sell', '38346.53', '0.50000000']], 'time': '2021-05-20T03:56:15.760709Z'}
{'type': 'l2update', 'product_id': 'BTC-USD', 'changes': [['buy', '38326.87', '0.84700000']], 'time': '2021-05-20T03:56:15.762727Z'}
{'type': 'l2update', 'product_id': 'BTC-USD', 'changes': [['buy', '38174.68', '0.01000000']], 'time': '2021-05-20T03:56:15.762871Z'}
{'type': 'l2update', 'product_id': 'BTC-USD', 'changes': [['buy', '38304.02', '0.04313876']], 'time': '2021-05-20T03:56:15.762972Z'}
{'type': 'l2update', 'product_id': 'BTC-USD', 'changes': [['sell', '38508.55', '0.00000000']], 'time': '2021-05-20T03:56:15.763877Z'}
{'type': 'l2update', 'product_id': 'BTC-USD', 'changes': [['sell', '38367.69', '0.05000000']], 'time': '2021-05-20T03:56:15.764644Z'}
{'type': 'l2update', 'product_id': 'BTC-USD', 'changes': [['sell', '38366.36', '0.43730000']], 'time': '2021-05-20T03:56:15.765227Z'}
{'type': 'l2update', 'product_id': 'BTC-USD', 'changes': [['buy', '38321.90', '0.00000000']], 'time': '2021-05-20T03:56:15.765672Z'}
{'type': 'l2update', 'product_id': 'BTC-USD', 'changes': [['buy', '38301.89', '0.00000000']], 'time': '2021-05-20T03:56:15.768967Z'}
{'type': 'l2update', 'product_id': 'BTC-USD', 'changes': [['sell', '38445.25', '0.30287043']], 'time': '2021-05-20T03:56:15.772990Z'}
{'type': 'l2update', 'product_id': 'BTC-USD', 'changes': [['buy', '38304.02', '0.00000000']], 'time': '2021-05-20T03:56:15.779000Z'}
{'type': 'l2update', 'product_id': 'BTC-USD', 'changes': [['buy', '38315.17', '0.00000000']], 'time': '2021-05-20T03:56:15.779017Z'}
{'type': 'l2update', 'product_id': 'BTC-USD', 'changes': [['sell', '49125.69', '0.00000000']], 'time': '2021-05-20T03:56:15.779188Z'}
{'type': 'l2update', 'product_id': 'BTC-USD', 'changes': [['sell', '38367.69', '0.00000000']], 'time': '2021-05-20T03:56:15.779349Z'}
{'type': 'l2update', 'product_id': 'BTC-USD', 'changes': [['sell', '38491.62', '0.01000000']], 'time': '2021-05-20T03:56:15.781973Z'}
{'type': 'l2update', 'product_id': 'BTC-USD', 'changes': [['sell', '49118.88', '0.00000000']], 'time': '2021-05-20T03:56:15.782713Z'}
{'type': 'l2update', 'product_id': 'BTC-USD', 'changes': [['sell', '38451.72', '0.02859715']], 'time': '2021-05-20T03:56:15.784221Z'}
{'type': 'l2update', 'product_id': 'BTC-USD', 'changes': [['sell', '38344.65', '2.48969908']], 'time': '2021-05-20T03:56:15.784950Z'}
{'type': 'l2update', 'product_id': 'BTC-USD', 'changes': [['sell', '38366.36', '0.00000000']], 'time': '2021-05-20T03:56:15.785369Z'}
{'type': 'l2update', 'product_id': 'BTC-USD', 'changes': [['buy', '38326.87', '0.00000000']], 'time': '2021-05-20T03:56:15.785383Z'}
{'type': 'l2update', 'product_id': 'BTC-USD', 'changes': [['sell', '49118.66', '0.00000000']], 'time': '2021-05-20T03:56:15.787657Z'}
{'type': 'l2update', 'product_id': 'BTC-USD', 'changes': [['buy', '38305.59', '0.04313876']], 'time': '2021-05-20T03:56:15.788646Z'}
{'type': 'l2update', 'product_id': 'BTC-USD', 'changes': [['sell', '48952.16', '0.00000000']], 'time': '2021-05-20T03:56:15.793082Z'}
{'type': 'l2update', 'product_id': 'BTC-USD', 'changes': [['sell', '38366.35', '0.05000000']], 'time': '2021-05-20T03:56:15.794645Z'}
{'type': 'l2update', 'product_id': 'BTC-USD', 'changes': [['buy', '38291.89', '0.05444616']], 'time': '2021-05-20T03:56:15.794655Z'}
{'type': 'l2update', 'product_id': 'BTC-USD', 'changes': [['sell', '48938.17', '0.00000000']], 'time': '2021-05-20T03:56:15.796472Z'}
{'type': 'l2update', 'product_id': 'BTC-USD', 'changes': [['buy', '38310.17', '0.00000000']], 'time': '2021-05-20T03:56:15.798282Z'}
{'type': 'l2update', 'product_id': 'BTC-USD', 'changes': [['sell', '38452.30', '0.34706088']], 'time': '2021-05-20T03:56:15.801642Z'}
{'type': 'l2update', 'product_id': 'BTC-USD', 'changes': [['buy', '38315.17', '1.06251193']], 'time': '2021-05-20T03:56:15.801781Z'}
{'type': 'l2update', 'product_id': 'BTC-USD', 'changes': [['sell', '38461.35', '0.00000000']], 'time': '2021-05-20T03:56:15.802221Z'}
{'type': 'l2update', 'product_id': 'BTC-USD', 'changes': [['sell', '48894.45', '0.00000000']], 'time': '2021-05-20T03:56:15.803135Z'}
{'type': 'l2update', 'product_id': 'BTC-USD', 'changes': [['buy', '38310.64', '0.00000000']], 'time': '2021-05-20T03:56:15.805130Z'}
{'type': 'l2update', 'product_id': 'BTC-USD', 'changes': [['buy', '38338.59', '0.00000000']], 'time': '2021-05-20T03:56:15.807631Z'}
{'type': 'l2update', 'product_id': 'BTC-USD', 'changes': [['sell', '48877.58', '0.00000000']], 'time': '2021-05-20T03:56:15.808190Z'}
{'type': 'l2update', 'product_id': 'BTC-USD', 'changes': [['sell', '48487.64', '0.00000000']], 'time': '2021-05-20T03:56:15.812925Z'}
{'type': 'l2update', 'product_id': 'BTC-USD', 'changes': [['buy', '38315.17', '1.65367748']], 'time': '2021-05-20T03:56:15.813280Z'}
{'type': 'l2update', 'product_id': 'BTC-USD', 'changes': [['sell', '38583.01', '0.01000000']], 'time': '2021-05-20T03:56:15.813341Z'}
{'type': 'l2update', 'product_id': 'BTC-USD', 'changes': [['sell', '38351.21', '0.00000000']], 'time': '2021-05-20T03:56:15.816664Z'}
{'type': 'l2update', 'product_id': 'BTC-USD', 'changes': [['sell', '48473.79', '0.00000000']], 'time': '2021-05-20T03:56:15.816874Z'}
{'type': 'l2update', 'product_id': 'BTC-USD', 'changes': [['sell', '38446.35', '0.01000000']], 'time': '2021-05-20T03:56:15.817315Z'}
{'type': 'l2update', 'product_id': 'BTC-USD', 'changes': [['sell', '48463.39', '0.00000000']], 'time': '2021-05-20T03:56:15.820802Z'}
{'type': 'l2update', 'product_id': 'BTC-USD', 'changes': [['buy', '38307.78', '0.02400000']], 'time': '2021-05-20T03:56:15.822514Z'}
{'type': 'l2update', 'product_id': 'BTC-USD', 'changes': [['buy', '38306.97', '0.02400000']], 'time': '2021-05-20T03:56:15.822514Z'}
{'type': 'l2update', 'product_id': 'BTC-USD', 'changes': [['sell', '48456.47', '0.00000000']], 'time': '2021-05-20T03:56:15.824655Z'}
{'type': 'l2update', 'product_id': 'BTC-USD', 'changes': [['sell', '48453.01', '0.00000000']], 'time': '2021-05-20T03:56:15.827835Z'}
{'type': 'l2update', 'product_id': 'BTC-USD', 'changes': [['sell', '38458.96', '0.32838427']], 'time': '2021-05-20T03:56:15.830833Z'}
{'type': 'l2update', 'product_id': 'BTC-USD', 'changes': [['sell', '48449.54', '0.00000000']], 'time': '2021-05-20T03:56:15.833740Z'}
{'type': 'l2update', 'product_id': 'BTC-USD', 'changes': [['sell', '48446.08', '0.00000000']], 'time': '2021-05-20T03:56:15.837393Z'}
{'type': 'l2update', 'product_id': 'BTC-USD', 'changes': [['buy', '38331.46', '0.15000000']], 'time': '2021-05-20T03:56:15.839991Z'}
{'type': 'l2update', 'product_id': 'BTC-USD', 'changes': [['sell', '48442.62', '0.00000000']], 'time': '2021-05-20T03:56:15.840375Z'}
{'type': 'l2update', 'product_id': 'BTC-USD', 'changes': [['buy', '38240.18', '0.00000000']], 'time': '2021-05-20T03:56:15.843381Z'}
{'type': 'l2update', 'product_id': 'BTC-USD', 'changes': [['buy', '38305.59', '0.00000000']], 'time': '2021-05-20T03:56:15.843476Z'}
{'type': 'l2update', 'product_id': 'BTC-USD', 'changes': [['sell', '48411.97', '0.00000000']], 'time': '2021-05-20T03:56:15.843678Z'}
{'type': 'l2update', 'product_id': 'BTC-USD', 'changes': [['sell', '48398.14', '0.00000000']], 'time': '2021-05-20T03:56:15.847132Z'}
{'type': 'l2update', 'product_id': 'BTC-USD', 'changes': [['sell', '38491.62', '0.00000000']], 'time': '2021-05-20T03:56:15.848971Z'}
{'type': 'l2update', 'product_id': 'BTC-USD', 'changes': [['buy', '38308.38', '0.04313876']], 'time': '2021-05-20T03:56:15.851149Z'}
{'type': 'l2update', 'product_id': 'BTC-USD', 'changes': [['sell', '48387.77', '0.00000000']], 'time': '2021-05-20T03:56:15.851226Z'}
{'type': 'l2update', 'product_id': 'BTC-USD', 'changes': [['sell', '38489.39', '0.00000000']], 'time': '2021-05-20T03:56:15.853305Z'}
{'type': 'l2update', 'product_id': 'BTC-USD', 'changes': [['sell', '48380.85', '0.00000000']], 'time': '2021-05-20T03:56:15.856229Z'}
{'type': 'l2update', 'product_id': 'BTC-USD', 'changes': [['buy', '38308.37', '0.00000000']], 'time': '2021-05-20T03:56:15.857921Z'}
{'type': 'l2update', 'product_id': 'BTC-USD', 'changes': [['buy', '38338.93', '0.01362945']], 'time': '2021-05-20T03:56:15.859182Z'}
{'type': 'l2update', 'product_id': 'BTC-USD', 'changes': [['sell', '48377.40', '0.00000000']], 'time': '2021-05-20T03:56:15.859588Z'}
{'type': 'l2update', 'product_id': 'BTC-USD', 'changes': [['sell', '38465.81', '0.38657279']], 'time': '2021-05-20T03:56:15.863697Z'}
{'type': 'l2update', 'product_id': 'BTC-USD', 'changes': [['sell', '38478.45', '0.01000000']], 'time': '2021-05-20T03:56:15.864064Z'}
{'type': 'l2update', 'product_id': 'BTC-USD', 'changes': [['buy', '38308.38', '0.00000000']], 'time': '2021-05-20T03:56:15.865631Z'}
{'type': 'l2update', 'product_id': 'BTC-USD', 'changes': [['buy', '38315.17', '1.06251193']], 'time': '2021-05-20T03:56:15.868019Z'}
{'type': 'l2update', 'product_id': 'BTC-USD', 'changes': [['sell', '38523.98', '0.01000000']], 'time': '2021-05-20T03:56:15.872330Z'}
{'type': 'l2update', 'product_id': 'BTC-USD', 'changes': [['buy', '37999.91', '0.13157923']], 'time': '2021-05-20T03:56:15.876996Z'}
{'type': 'l2update', 'product_id': 'BTC-USD', 'changes': [['sell', '38365.71', '0.47600000']], 'time': '2021-05-20T03:56:15.880967Z'}
{'type': 'l2update', 'product_id': 'BTC-USD', 'changes': [['buy', '38305.59', '0.04313876']], 'time': '2021-05-20T03:56:15.881027Z'}
{'type': 'l2update', 'product_id': 'BTC-USD', 'changes': [['buy', '38308.39', '0.04313876']], 'time': '2021-05-20T03:56:15.888001Z'}
{'type': 'l2update', 'product_id': 'BTC-USD', 'changes': [['buy', '38305.59', '0.00000000']], 'time': '2021-05-20T03:56:15.888108Z'}
{'type': 'l2update', 'product_id': 'BTC-USD', 'changes': [['sell', '38366.35', '0.00000000']], 'time': '2021-05-20T03:56:15.888400Z'}
{'type': 'l2update', 'product_id': 'BTC-USD', 'changes': [['buy', '38315.18', '0.59116555']], 'time': '2021-05-20T03:56:15.891277Z'}
{'type': 'l2update', 'product_id': 'BTC-USD', 'changes': [['buy', '38310.48', '0.03994531']], 'time': '2021-05-20T03:56:15.891307Z'}
{'type': 'l2update', 'product_id': 'BTC-USD', 'changes': [['buy', '38164.96', '0.15050000']], 'time': '2021-05-20T03:56:15.891465Z'}
{'type': 'l2update', 'product_id': 'BTC-USD', 'changes': [['buy', '38308.39', '0.00000000']], 'time': '2021-05-20T03:56:15.896414Z'}
{'type': 'l2update', 'product_id': 'BTC-USD', 'changes': [['buy', '38305.60', '0.04313876']], 'time': '2021-05-20T03:56:15.903541Z'}
{'type': 'l2update', 'product_id': 'BTC-USD', 'changes': [['sell', '38365.70', '0.05000000']], 'time': '2021-05-20T03:56:15.903859Z'}
{'type': 'l2update', 'product_id': 'BTC-USD', 'changes': [['buy', '38224.93', '0.00000000']], 'time': '2021-05-20T03:56:15.906738Z'}
{'type': 'l2update', 'product_id': 'BTC-USD', 'changes': [['buy', '38305.60', '0.00000000']], 'time': '2021-05-20T03:56:15.912245Z'}
{'type': 'l2update', 'product_id': 'BTC-USD', 'changes': [['buy', '38310.71', '0.04313876']], 'time': '2021-05-20T03:56:15.913927Z'}
{'type': 'l2update', 'product_id': 'BTC-USD', 'changes': [['buy', '38236.81', '0.01000000']], 'time': '2021-05-20T03:56:15.921484Z'}
{'type': 'l2update', 'product_id': 'BTC-USD', 'changes': [['buy', '38326.87', '0.84700000']], 'time': '2021-05-20T03:56:15.927969Z'}
{'type': 'l2update', 'product_id': 'BTC-USD', 'changes': [['buy', '38315.18', '0.00000000']], 'time': '2021-05-20T03:56:15.935125Z'}
{'type': 'l2update', 'product_id': 'BTC-USD', 'changes': [['sell', '38457.61', '0.00000000']], 'time': '2021-05-20T03:56:15.941197Z'}
{'type': 'l2update', 'product_id': 'BTC-USD', 'changes': [['sell', '38523.98', '0.00000000']], 'time': '2021-05-20T03:56:15.950412Z'}
{'type': 'l2update', 'product_id': 'BTC-USD', 'changes': [['sell', '38483.69', '0.01895863']], 'time': '2021-05-20T03:56:15.953067Z'}
{'type': 'l2update', 'product_id': 'BTC-USD', 'changes': [['sell', '38377.88', '0.01000000']], 'time': '2021-05-20T03:56:15.958233Z'}
{'type': 'l2update', 'product_id': 'BTC-USD', 'changes': [['sell', '38489.37', '0.01000000']], 'time': '2021-05-20T03:56:15.966467Z'}
{'type': 'l2update', 'product_id': 'BTC-USD', 'changes': [['buy', '38295.46', '0.01000000']], 'time': '2021-05-20T03:56:15.970647Z'}
{'type': 'l2update', 'product_id': 'BTC-USD', 'changes': [['sell', '38339.18', '0.07973364']], 'time': '2021-05-20T03:56:15.970716Z'}
{'type': 'l2update', 'product_id': 'BTC-USD', 'changes': [['buy', '38265.42', '0.07700000']], 'time': '2021-05-20T03:56:15.970744Z'}
{'type': 'l2update', 'product_id': 'BTC-USD', 'changes': [['buy', '38305.58', '0.00000000']], 'time': '2021-05-20T03:56:15.970950Z'}
{'type': 'l2update', 'product_id': 'BTC-USD', 'changes': [['buy', '38310.71', '0.00000000']], 'time': '2021-05-20T03:56:15.981265Z'}
{'type': 'l2update', 'product_id': 'BTC-USD', 'changes': [['buy', '38307.84', '0.43550000']], 'time': '2021-05-20T03:56:15.981829Z'}
{'type': 'l2update', 'product_id': 'BTC-USD', 'changes': [['buy', '38322.30', '0.00000000']], 'time': '2021-05-20T03:56:15.985182Z'}
{'type': 'l2update', 'product_id': 'BTC-USD', 'changes': [['sell', '38365.71', '0.00000000']], 'time': '2021-05-20T03:56:15.985955Z'}
{'type': 'l2update', 'product_id': 'BTC-USD', 'changes': [['buy', '38311.92', '0.04313876']], 'time': '2021-05-20T03:56:15.990751Z'}
{'type': 'l2update', 'product_id': 'BTC-USD', 'changes': [['sell', '38367.01', '0.45780000']], 'time': '2021-05-20T03:56:15.998782Z'}
{'type': 'l2update', 'product_id': 'BTC-USD', 'changes': [['sell', '38362.64', '0.00000000']], 'time': '2021-05-20T03:56:16.003833Z'}
{'type': 'l2update', 'product_id': 'BTC-USD', 'changes': [['sell', '38484.92', '0.00000000']], 'time': '2021-05-20T03:56:16.007342Z'}
{'type': 'l2update', 'product_id': 'BTC-USD', 'changes': [['sell', '38489.37', '0.00000000']], 'time': '2021-05-20T03:56:16.010497Z'}
{'type': 'l2update', 'product_id': 'BTC-USD', 'changes': [['buy', '38168.63', '0.04926652']], 'time': '2021-05-20T03:56:16.012146Z'}
{'type': 'l2update', 'product_id': 'BTC-USD', 'changes': [['sell', '38339.18', '0.07206880']], 'time': '2021-05-20T03:56:16.019134Z'}
{'type': 'l2update', 'product_id': 'BTC-USD', 'changes': [['sell', '38367.01', '0.00000000']], 'time': '2021-05-20T03:56:16.028048Z'}
{'type': 'l2update', 'product_id': 'BTC-USD', 'changes': [['sell', '38339.18', '0.07108222']], 'time': '2021-05-20T03:56:16.029714Z'}
{'type': 'l2update', 'product_id': 'BTC-USD', 'changes': [['sell', '38365.70', '0.00000000']], 'time': '2021-05-20T03:56:16.031021Z'}
{'type': 'l2update', 'product_id': 'BTC-USD', 'changes': [['buy', '38326.87', '0.00000000']], 'time': '2021-05-20T03:56:16.055038Z'}
{'type': 'l2update', 'product_id': 'BTC-USD', 'changes': [['sell', '38471.16', '0.01000000']], 'time': '2021-05-20T03:56:16.055777Z'}
{'type': 'l2update', 'product_id': 'BTC-USD', 'changes': [['sell', '38339.18', '0.00000000']], 'time': '2021-05-20T03:56:16.055806Z'}
{'type': 'l2update', 'product_id': 'BTC-USD', 'changes': [['sell', '38344.65', '2.47880540']], 'time': '2021-05-20T03:56:16.055806Z'}
{'type': 'l2update', 'product_id': 'BTC-USD', 'changes': [['buy', '38164.65', '0.00000000']], 'time': '2021-05-20T03:56:16.065304Z'}
{'type': 'l2update', 'product_id': 'BTC-USD', 'changes': [['sell', '38523.96', '0.01000000']], 'time': '2021-05-20T03:56:16.069353Z'}
{'type': 'l2update', 'product_id': 'BTC-USD', 'changes': [['sell', '38367.00', '0.05000000']], 'time': '2021-05-20T03:56:16.074202Z'}
{'type': 'l2update', 'product_id': 'BTC-USD', 'changes': [['sell', '38365.91', '0.04929360']], 'time': '2021-05-20T03:56:16.074303Z'}
{'type': 'l2update', 'product_id': 'BTC-USD', 'changes': [['sell', '38424.85', '0.00000000']], 'time': '2021-05-20T03:56:16.077605Z'}
{'type': 'l2update', 'product_id': 'BTC-USD', 'changes': [['buy', '38331.46', '0.15176479']], 'time': '2021-05-20T03:56:16.081306Z'}
{'type': 'l2update', 'product_id': 'BTC-USD', 'changes': [['buy', '38339.17', '0.00000000']], 'time': '2021-05-20T03:56:16.082766Z'}
{'type': 'l2update', 'product_id': 'BTC-USD', 'changes': [['sell', '38344.65', '0.00000000']], 'time': '2021-05-20T03:56:16.082790Z'}
{'type': 'l2update', 'product_id': 'BTC-USD', 'changes': [['buy', '38321.94', '0.84600000']], 'time': '2021-05-20T03:56:16.087748Z'}
{'type': 'l2update', 'product_id': 'BTC-USD', 'changes': [['buy', '38315.18', '0.59116555']], 'time': '2021-05-20T03:56:16.088185Z'}
{'type': 'l2update', 'product_id': 'BTC-USD', 'changes': [['sell', '38377.88', '0.00000000']], 'time': '2021-05-20T03:56:16.088903Z'}
{'type': 'l2update', 'product_id': 'BTC-USD', 'changes': [['buy', '38312.21', '0.04313876']], 'time': '2021-05-20T03:56:16.092529Z'}
{'type': 'l2update', 'product_id': 'BTC-USD', 'changes': [['sell', '38344.66', '0.04618554']], 'time': '2021-05-20T03:56:16.096763Z'}
{'type': 'l2update', 'product_id': 'BTC-USD', 'changes': [['sell', '38344.64', '1.15300457']], 'time': '2021-05-20T03:56:16.099810Z'}
{'type': 'l2update', 'product_id': 'BTC-USD', 'changes': [['buy', '38311.92', '0.00000000']], 'time': '2021-05-20T03:56:16.106089Z'}
{'type': 'l2update', 'product_id': 'BTC-USD', 'changes': [['buy', '38315.17', '0.00000000']], 'time': '2021-05-20T03:56:16.115135Z'}
{'type': 'l2update', 'product_id': 'BTC-USD', 'changes': [['buy', '38278.50', '0.00000000']], 'time': '2021-05-20T03:56:16.118988Z'}
{'type': 'l2update', 'product_id': 'BTC-USD', 'changes': [['buy', '38295.46', '0.00000000']], 'time': '2021-05-20T03:56:16.119039Z'}
{'type': 'l2update', 'product_id': 'BTC-USD', 'changes': [['sell', '38434.73', '0.12252119']], 'time': '2021-05-20T03:56:16.121778Z'}
{'type': 'l2update', 'product_id': 'BTC-USD', 'changes': [['sell', '38428.38', '0.02722693']], 'time': '2021-05-20T03:56:16.125942Z'}
{'type': 'l2update', 'product_id': 'BTC-USD', 'changes': [['sell', '38339.18', '0.06294346']], 'time': '2021-05-20T03:56:16.126090Z'}
{'type': 'l2update', 'product_id': 'BTC-USD', 'changes': [['sell', '38431.58', '0.05445386']], 'time': '2021-05-20T03:56:16.130935Z'}
{'type': 'l2update', 'product_id': 'BTC-USD', 'changes': [['sell', '38367.00', '0.00000000']], 'time': '2021-05-20T03:56:16.132579Z'}
{'type': 'l2update', 'product_id': 'BTC-USD', 'changes': [['sell', '38338.94', '0.02890000']], 'time': '2021-05-20T03:56:16.133541Z'}
{'type': 'l2update', 'product_id': 'BTC-USD', 'changes': [['buy', '38321.94', '1.36700000']], 'time': '2021-05-20T03:56:16.137817Z'}
{'type': 'l2update', 'product_id': 'BTC-USD', 'changes': [['buy', '38265.42', '0.00000000']], 'time': '2021-05-20T03:56:16.138274Z'}
{'type': 'l2update', 'product_id': 'BTC-USD', 'changes': [['sell', '38369.00', '0.43000000']], 'time': '2021-05-20T03:56:16.153190Z'}
{'type': 'l2update', 'product_id': 'BTC-USD', 'changes': [['buy', '38304.01', '0.00000000']], 'time': '2021-05-20T03:56:16.154281Z'}
{'type': 'l2update', 'product_id': 'BTC-USD', 'changes': [['buy', '37469.35', '0.14140000']], 'time': '2021-05-20T03:56:16.160386Z'}
{'type': 'l2update', 'product_id': 'BTC-USD', 'changes': [['sell', '39499.99', '0.07410000']], 'time': '2021-05-20T03:56:16.160386Z'}
{'type': 'l2update', 'product_id': 'BTC-USD', 'changes': [['sell', '38344.65', '2.48969908']], 'time': '2021-05-20T03:56:16.161966Z'}
{'type': 'l2update', 'product_id': 'BTC-USD', 'changes': [['buy', '38281.50', '0.10000000']], 'time': '2021-05-20T03:56:16.165684Z'}
{'type': 'l2update', 'product_id': 'BTC-USD', 'changes': [['sell', '38338.94', '0.02841958']], 'time': '2021-05-20T03:56:16.170008Z'}
{'type': 'l2update', 'product_id': 'BTC-USD', 'changes': [['sell', '39499.99', '0.12150000']], 'time': '2021-05-20T03:56:16.170593Z'}
{'type': 'l2update', 'product_id': 'BTC-USD', 'changes': [['buy', '37500.01', '0.00520000']], 'time': '2021-05-20T03:56:16.170593Z'}
{'type': 'l2update', 'product_id': 'BTC-USD', 'changes': [['sell', '38339.18', '0.00000000']], 'time': '2021-05-20T03:56:16.173561Z'}
{'type': 'l2update', 'product_id': 'BTC-USD', 'changes': [['buy', '37537.94', '0.06581330']], 'time': '2021-05-20T03:56:16.187808Z'}
{'type': 'l2update', 'product_id': 'BTC-USD', 'changes': [['sell', '38361.93', '0.05000000']], 'time': '2021-05-20T03:56:16.187920Z'}
{'type': 'l2update', 'product_id': 'BTC-USD', 'changes': [['buy', '38168.63', '0.00000000']], 'time': '2021-05-20T03:56:16.189262Z'}
{'type': 'l2update', 'product_id': 'BTC-USD', 'changes': [['buy', '38312.20', '0.00000000']], 'time': '2021-05-20T03:56:16.192677Z'}
{'type': 'l2update', 'product_id': 'BTC-USD', 'changes': [['sell', '38666.93', '0.00000000']], 'time': '2021-05-20T03:56:16.193669Z'}
{'type': 'l2update', 'product_id': 'BTC-USD', 'changes': [['sell', '38583.01', '0.00000000']], 'time': '2021-05-20T03:56:16.194460Z'}
{'type': 'l2update', 'product_id': 'BTC-USD', 'changes': [['buy', '38296.41', '0.00000000']], 'time': '2021-05-20T03:56:16.205525Z'}
{'type': 'l2update', 'product_id': 'BTC-USD', 'changes': [['buy', '38307.84', '0.00000000']], 'time': '2021-05-20T03:56:16.206804Z'}
{'type': 'l2update', 'product_id': 'BTC-USD', 'changes': [['buy', '38315.18', '0.00000000']], 'time': '2021-05-20T03:56:16.209921Z'}
{'type': 'l2update', 'product_id': 'BTC-USD', 'changes': [['buy', '38312.21', '0.00000000']], 'time': '2021-05-20T03:56:16.214752Z'}
{'type': 'l2update', 'product_id': 'BTC-USD', 'changes': [['sell', '43100.00', '1.09530000']], 'time': '2021-05-20T03:56:16.214913Z'}
{'type': 'l2update', 'product_id': 'BTC-USD', 'changes': [['buy', '38321.94', '0.84600000']], 'time': '2021-05-20T03:56:16.216115Z'}
{'type': 'l2update', 'product_id': 'BTC-USD', 'changes': [['buy', '38315.17', '1.07340561']], 'time': '2021-05-20T03:56:16.218840Z'}
{'type': 'l2update', 'product_id': 'BTC-USD', 'changes': [['sell', '38338.94', '0.00000000']], 'time': '2021-05-20T03:56:16.219482Z'}
{'type': 'l2update', 'product_id': 'BTC-USD', 'changes': [['sell', '38338.94', '0.01165654']], 'time': '2021-05-20T03:56:16.231273Z'}
{'type': 'l2update', 'product_id': 'BTC-USD', 'changes': [['sell', '39128.76', '0.00000000']], 'time': '2021-05-20T03:56:16.234769Z'}
{'type': 'l2update', 'product_id': 'BTC-USD', 'changes': [['buy', '38323.91', '0.50100000']], 'time': '2021-05-20T03:56:16.246419Z'}
{'type': 'l2update', 'product_id': 'BTC-USD', 'changes': [['sell', '38680.03', '0.05546250']], 'time': '2021-05-20T03:56:16.251154Z'}
{'type': 'l2update', 'product_id': 'BTC-USD', 'changes': [['sell', '38431.46', '0.00000000']], 'time': '2021-05-20T03:56:16.255653Z'}
{'type': 'l2update', 'product_id': 'BTC-USD', 'changes': [['sell', '38369.00', '0.00000000']], 'time': '2021-05-20T03:56:16.256140Z'}
{'type': 'l2update', 'product_id': 'BTC-USD', 'changes': [['buy', '38310.48', '0.00000000']], 'time': '2021-05-20T03:56:16.257049Z'}
{'type': 'l2update', 'product_id': 'BTC-USD', 'changes': [['sell', '38351.98', '0.00000000']], 'time': '2021-05-20T03:56:16.257049Z'}
{'type': 'l2update', 'product_id': 'BTC-USD', 'changes': [['sell', '38346.53', '0.00000000']], 'time': '2021-05-20T03:56:16.264743Z'}
{'type': 'l2update', 'product_id': 'BTC-USD', 'changes': [['buy', '38277.63', '1.28140237']], 'time': '2021-05-20T03:56:16.271541Z'}
{'type': 'l2update', 'product_id': 'BTC-USD', 'changes': [['sell', '43100.00', '1.30900000']], 'time': '2021-05-20T03:56:16.272940Z'}
{'type': 'l2update', 'product_id': 'BTC-USD', 'changes': [['buy', '38307.85', '0.04313876']], 'time': '2021-05-20T03:56:16.273153Z'}
{'type': 'l2update', 'product_id': 'BTC-USD', 'changes': [['buy', '38309.36', '0.00000000']], 'time': '2021-05-20T03:56:16.273840Z'}
{'type': 'l2update', 'product_id': 'BTC-USD', 'changes': [['sell', '38404.71', '0.16300000']], 'time': '2021-05-20T03:56:16.285375Z'}
{'type': 'l2update', 'product_id': 'BTC-USD', 'changes': [['buy', '38310.49', '0.04313876']], 'time': '2021-05-20T03:56:16.290148Z'}
{'type': 'l2update', 'product_id': 'BTC-USD', 'changes': [['sell', '38338.94', '0.00000000']], 'time': '2021-05-20T03:56:16.290741Z'}
{'type': 'l2update', 'product_id': 'BTC-USD', 'changes': [['sell', '38338.94', '0.02890000']], 'time': '2021-05-20T03:56:16.298017Z'}
{'type': 'l2update', 'product_id': 'BTC-USD', 'changes': [['sell', '38479.29', '0.01000000']], 'time': '2021-05-20T03:56:16.307138Z'}
{'type': 'l2update', 'product_id': 'BTC-USD', 'changes': [['buy', '38306.45', '0.44990000']], 'time': '2021-05-20T03:56:16.311404Z'}
{'type': 'l2update', 'product_id': 'BTC-USD', 'changes': [['buy', '38323.96', '0.84700000']], 'time': '2021-05-20T03:56:16.314603Z'}
{'type': 'l2update', 'product_id': 'BTC-USD', 'changes': [['buy', '38307.78', '0.00000000']], 'time': '2021-05-20T03:56:16.321367Z'}
{'type': 'l2update', 'product_id': 'BTC-USD', 'changes': [['buy', '38306.97', '0.00000000']], 'time': '2021-05-20T03:56:16.321367Z'}
{'type': 'l2update', 'product_id': 'BTC-USD', 'changes': [['sell', '38361.53', '0.04803792']], 'time': '2021-05-20T03:56:16.327866Z'}
{'type': 'l2update', 'product_id': 'BTC-USD', 'changes': [['sell', '38344.63', '0.50000000']], 'time': '2021-05-20T03:56:16.328714Z'}
{'type': 'l2update', 'product_id': 'BTC-USD', 'changes': [['sell', '38384.92', '0.00000000']], 'time': '2021-05-20T03:56:16.330799Z'}
{'type': 'l2update', 'product_id': 'BTC-USD', 'changes': [['buy', '38311.92', '0.59116555']], 'time': '2021-05-20T03:56:16.337568Z'}
{'type': 'l2update', 'product_id': 'BTC-USD', 'changes': [['sell', '38478.45', '0.00000000']], 'time': '2021-05-20T03:56:16.340805Z'}
{'type': 'l2update', 'product_id': 'BTC-USD', 'changes': [['buy', '38310.49', '0.00000000']], 'time': '2021-05-20T03:56:16.350809Z'}
{'type': 'l2update', 'product_id': 'BTC-USD', 'changes': [['sell', '38471.16', '0.00000000']], 'time': '2021-05-20T03:56:16.358601Z'}
{'type': 'l2update', 'product_id': 'BTC-USD', 'changes': [['buy', '38331.46', '0.15000000']], 'time': '2021-05-20T03:56:16.362054Z'}
{'type': 'l2update', 'product_id': 'BTC-USD', 'changes': [['buy', '38306.45', '0.00000000']], 'time': '2021-05-20T03:56:16.366712Z'}
{'type': 'l2update', 'product_id': 'BTC-USD', 'changes': [['buy', '38331.46', '0.00000000']], 'time': '2021-05-20T03:56:16.376523Z'}
{'type': 'l2update', 'product_id': 'BTC-USD', 'changes': [['sell', '38389.15', '0.50000000']], 'time': '2021-05-20T03:56:16.381847Z'}
{'type': 'l2update', 'product_id': 'BTC-USD', 'changes': [['buy', '38307.85', '0.00000000']], 'time': '2021-05-20T03:56:16.386530Z'}
{'type': 'l2update', 'product_id': 'BTC-USD', 'changes': [['buy', '38304.68', '0.02400000']], 'time': '2021-05-20T03:56:16.390088Z'}
{'type': 'l2update', 'product_id': 'BTC-USD', 'changes': [['buy', '38303.87', '0.02400000']], 'time': '2021-05-20T03:56:16.390088Z'}
{'type': 'l2update', 'product_id': 'BTC-USD', 'changes': [['buy', '38303.07', '0.02400000']], 'time': '2021-05-20T03:56:16.390088Z'}
{'type': 'l2update', 'product_id': 'BTC-USD', 'changes': [['sell', '38338.94', '0.02817345']], 'time': '2021-05-20T03:56:16.400815Z'}
{'type': 'l2update', 'product_id': 'BTC-USD', 'changes': [['sell', '38365.91', '0.00000000']], 'time': '2021-05-20T03:56:16.404363Z'}
{'type': 'l2update', 'product_id': 'BTC-USD', 'changes': [['sell', '38478.45', '0.01000000']], 'time': '2021-05-20T03:56:16.417805Z'}
{'type': 'l2update', 'product_id': 'BTC-USD', 'changes': [['sell', '38365.35', '0.44160000']], 'time': '2021-05-20T03:56:16.421609Z'}
{'type': 'l2update', 'product_id': 'BTC-USD', 'changes': [['sell', '38680.03', '0.00000000']], 'time': '2021-05-20T03:56:16.428964Z'}
{'type': 'l2update', 'product_id': 'BTC-USD', 'changes': [['sell', '38480.34', '0.01000000']], 'time': '2021-05-20T03:56:16.430598Z'}
{'type': 'l2update', 'product_id': 'BTC-USD', 'changes': [['sell', '38483.69', '0.00000000']], 'time': '2021-05-20T03:56:16.450043Z'}
{'type': 'l2update', 'product_id': 'BTC-USD', 'changes': [['sell', '38338.94', '0.00000000']], 'time': '2021-05-20T03:56:16.460375Z'}
{'type': 'l2update', 'product_id': 'BTC-USD', 'changes': [['buy', '38339.16', '0.00176479']], 'time': '2021-05-20T03:56:16.466216Z'}
{'type': 'l2update', 'product_id': 'BTC-USD', 'changes': [['buy', '38252.59', '0.02400000']], 'time': '2021-05-20T03:56:16.469816Z'}
{'type': 'l2update', 'product_id': 'BTC-USD', 'changes': [['buy', '38306.46', '0.04313876']], 'time': '2021-05-20T03:56:16.473874Z'}
{'type': 'l2update', 'product_id': 'BTC-USD', 'changes': [['buy', '38165.67', '0.05113751']], 'time': '2021-05-20T03:56:16.475085Z'}
{'type': 'l2update', 'product_id': 'BTC-USD', 'changes': [['sell', '38365.35', '0.00000000']], 'time': '2021-05-20T03:56:16.481490Z'}
{'type': 'l2update', 'product_id': 'BTC-USD', 'changes': [['buy', '38325.74', '0.00000000']], 'time': '2021-05-20T03:56:16.495442Z'}
{'type': 'l2update', 'product_id': 'BTC-USD', 'changes': [['buy', '38305.92', '0.05829056']], 'time': '2021-05-20T03:56:16.495623Z'}
{'type': 'l2update', 'product_id': 'BTC-USD', 'changes': [['sell', '38347.41', '0.05900887']], 'time': '2021-05-20T03:56:16.495623Z'}
{'type': 'l2update', 'product_id': 'BTC-USD', 'changes': [['buy', '38321.94', '1.36600000']], 'time': '2021-05-20T03:56:16.496519Z'}
{'type': 'l2update', 'product_id': 'BTC-USD', 'changes': [['buy', '38311.92', '0.00000000']], 'time': '2021-05-20T03:56:16.509781Z'}
{'type': 'l2update', 'product_id': 'BTC-USD', 'changes': [['sell', '38466.95', '0.01947840']], 'time': '2021-05-20T03:56:16.515403Z'}
{'type': 'l2update', 'product_id': 'BTC-USD', 'changes': [['buy', '17171.00', '2.00000000']], 'time': '2021-05-20T03:56:16.519273Z'}
{'type': 'l2update', 'product_id': 'BTC-USD', 'changes': [['sell', '38361.93', '0.00000000']], 'time': '2021-05-20T03:56:16.519611Z'}
{'type': 'l2update', 'product_id': 'BTC-USD', 'changes': [['sell', '38387.64', '2.16932808']], 'time': '2021-05-20T03:56:16.524285Z'}
{'type': 'l2update', 'product_id': 'BTC-USD', 'changes': [['buy', '38310.71', '0.04313876']], 'time': '2021-05-20T03:56:16.527060Z'}
{'type': 'l2update', 'product_id': 'BTC-USD', 'changes': [['sell', '38344.62', '1.07437202']], 'time': '2021-05-20T03:56:16.527259Z'}
{'type': 'l2update', 'product_id': 'BTC-USD', 'changes': [['sell', '38478.45', '0.00000000']], 'time': '2021-05-20T03:56:16.529778Z'}
{'type': 'l2update', 'product_id': 'BTC-USD', 'changes': [['buy', '38321.89', '0.00000000']], 'time': '2021-05-20T03:56:16.533742Z'}
{'type': 'l2update', 'product_id': 'BTC-USD', 'changes': [['sell', '38428.86', '0.05582500']], 'time': '2021-05-20T03:56:16.539344Z'}
{'type': 'l2update', 'product_id': 'BTC-USD', 'changes': [['buy', '38338.93', '0.00000000']], 'time': '2021-05-20T03:56:16.541304Z'}
{'type': 'l2update', 'product_id': 'BTC-USD', 'changes': [['buy', '38320.91', '0.52185379']], 'time': '2021-05-20T03:56:16.547671Z'}
{'type': 'l2update', 'product_id': 'BTC-USD', 'changes': [['sell', '38365.34', '0.05000000']], 'time': '2021-05-20T03:56:16.554594Z'}
{'type': 'l2update', 'product_id': 'BTC-USD', 'changes': [['buy', '38310.71', '0.00000000']], 'time': '2021-05-20T03:56:16.557366Z'}
{'type': 'l2update', 'product_id': 'BTC-USD', 'changes': [['buy', '37999.91', '0.00000000']], 'time': '2021-05-20T03:56:16.559669Z'}
{'type': 'l2update', 'product_id': 'BTC-USD', 'changes': [['buy', '38306.46', '0.00000000']], 'time': '2021-05-20T03:56:16.563070Z'}
{'type': 'l2update', 'product_id': 'BTC-USD', 'changes': [['buy', '38301.89', '0.02610837']], 'time': '2021-05-20T03:56:16.564924Z'}
{'type': 'l2update', 'product_id': 'BTC-USD', 'changes': [['sell', '38501.03', '0.01000000']], 'time': '2021-05-20T03:56:16.571317Z'}
{'type': 'l2update', 'product_id': 'BTC-USD', 'changes': [['buy', '38308.71', '0.41120000']], 'time': '2021-05-20T03:56:16.571802Z'}
{'type': 'l2update', 'product_id': 'BTC-USD', 'changes': [['buy', '38332.98', '0.02436689']], 'time': '2021-05-20T03:56:16.572821Z'}
{'type': 'l2update', 'product_id': 'BTC-USD', 'changes': [['buy', '38019.23', '0.02325000']], 'time': '2021-05-20T03:56:16.588466Z'}
{'type': 'l2update', 'product_id': 'BTC-USD', 'changes': [['buy', '38317.88', '0.52188750']], 'time': '2021-05-20T03:56:16.588725Z'}
{'type': 'l2update', 'product_id': 'BTC-USD', 'changes': [['buy', '38308.71', '0.00000000']], 'time': '2021-05-20T03:56:16.588818Z'}
{'type': 'l2update', 'product_id': 'BTC-USD', 'changes': [['buy', '38333.07', '0.01492000']], 'time': '2021-05-20T03:56:16.591626Z'}
{'type': 'l2update', 'product_id': 'BTC-USD', 'changes': [['buy', '38323.97', '0.59116555']], 'time': '2021-05-20T03:56:16.596973Z'}
{'type': 'l2update', 'product_id': 'BTC-USD', 'changes': [['buy', '38236.81', '0.00000000']], 'time': '2021-05-20T03:56:16.599673Z'}
{'type': 'l2update', 'product_id': 'BTC-USD', 'changes': [['buy', '38332.98', '0.03993198']], 'time': '2021-05-20T03:56:16.599905Z'}
{'type': 'l2update', 'product_id': 'BTC-USD', 'changes': [['sell', '38435.92', '0.00000000']], 'time': '2021-05-20T03:56:16.601719Z'}
{'type': 'l2update', 'product_id': 'BTC-USD', 'changes': [['buy', '38314.76', '0.52193209']], 'time': '2021-05-20T03:56:16.612764Z'}
{'type': 'l2update', 'product_id': 'BTC-USD', 'changes': [['buy', '38332.98', '0.01556509']], 'time': '2021-05-20T03:56:16.614550Z'}
{'type': 'l2update', 'product_id': 'BTC-USD', 'changes': [['buy', '38333.76', '0.03466802']], 'time': '2021-05-20T03:56:16.622178Z'}
{'type': 'l2update', 'product_id': 'BTC-USD', 'changes': [['sell', '38367.66', '0.49710000']], 'time': '2021-05-20T03:56:16.622315Z'}
{'type': 'l2update', 'product_id': 'BTC-USD', 'changes': [['buy', '38249.31', '0.02730744']], 'time': '2021-05-20T03:56:16.622486Z'}
{'type': 'l2update', 'product_id': 'BTC-USD', 'changes': [['buy', '38164.96', '0.00000000']], 'time': '2021-05-20T03:56:16.624658Z'}
{'type': 'l2update', 'product_id': 'BTC-USD', 'changes': [['buy', '38332.98', '0.00000000']], 'time': '2021-05-20T03:56:16.626429Z'}
{'type': 'l2update', 'product_id': 'BTC-USD', 'changes': [['sell', '38457.65', '0.01300131']], 'time': '2021-05-20T03:56:16.627020Z'}
{'type': 'l2update', 'product_id': 'BTC-USD', 'changes': [['buy', '38311.92', '0.03100520']], 'time': '2021-05-20T03:56:16.627219Z'}
{'type': 'l2update', 'product_id': 'BTC-USD', 'changes': [['sell', '38367.66', '0.00000000']], 'time': '2021-05-20T03:56:16.632513Z'}
{'type': 'l2update', 'product_id': 'BTC-USD', 'changes': [['sell', '38347.41', '0.00000000']], 'time': '2021-05-20T03:56:16.635065Z'}
{'type': 'l2update', 'product_id': 'BTC-USD', 'changes': [['sell', '38365.34', '0.00000000']], 'time': '2021-05-20T03:56:16.635537Z'}
{'type': 'l2update', 'product_id': 'BTC-USD', 'changes': [['buy', '38344.12', '0.15000000']], 'time': '2021-05-20T03:56:16.636029Z'}
{'type': 'l2update', 'product_id': 'BTC-USD', 'changes': [['buy', '38302.55', '0.78283125']], 'time': '2021-05-20T03:56:16.636424Z'}
{'type': 'l2update', 'product_id': 'BTC-USD', 'changes': [['buy', '38333.76', '0.05903491']], 'time': '2021-05-20T03:56:16.636544Z'}
{'type': 'l2update', 'product_id': 'BTC-USD', 'changes': [['sell', '38377.50', '0.01000000']], 'time': '2021-05-20T03:56:16.640442Z'}
{'type': 'l2update', 'product_id': 'BTC-USD', 'changes': [['buy', '38333.76', '0.02436689']], 'time': '2021-05-20T03:56:16.644696Z'}
{'type': 'l2update', 'product_id': 'BTC-USD', 'changes': [['buy', '38333.76', '0.00000000']], 'time': '2021-05-20T03:56:16.644705Z'}
{'type': 'l2update', 'product_id': 'BTC-USD', 'changes': [['buy', '38333.07', '0.00000000']], 'time': '2021-05-20T03:56:16.645176Z'}
{'type': 'l2update', 'product_id': 'BTC-USD', 'changes': [['sell', '38344.66', '0.00000000']], 'time': '2021-05-20T03:56:16.647604Z'}
{'type': 'l2update', 'product_id': 'BTC-USD', 'changes': [['sell', '38344.62', '0.00000000']], 'time': '2021-05-20T03:56:16.648153Z'}
{'type': 'l2update', 'product_id': 'BTC-USD', 'changes': [['sell', '38359.06', '0.00000000']], 'time': '2021-05-20T03:56:16.648618Z'}
{'type': 'l2update', 'product_id': 'BTC-USD', 'changes': [['sell', '38361.94', '0.00000000']], 'time': '2021-05-20T03:56:16.649407Z'}
{'type': 'l2update', 'product_id': 'BTC-USD', 'changes': [['sell', '38344.13', '0.03760477']], 'time': '2021-05-20T03:56:16.651868Z'}
{'type': 'l2update', 'product_id': 'BTC-USD', 'changes': [['buy', '38328.02', '0.01362945']], 'time': '2021-05-20T03:56:16.652058Z'}
{'type': 'l2update', 'product_id': 'BTC-USD', 'changes': [['sell', '38344.13', '0.04424264']], 'time': '2021-05-20T03:56:16.652184Z'}
{'type': 'l2update', 'product_id': 'BTC-USD', 'changes': [['buy', '38299.14', '1.30459209']], 'time': '2021-05-20T03:56:16.652201Z'}
{'type': 'l2update', 'product_id': 'BTC-USD', 'changes': [['sell', '38367.65', '0.05000000']], 'time': '2021-05-20T03:56:16.652846Z'}
{'type': 'l2update', 'product_id': 'BTC-USD', 'changes': [['sell', '38344.64', '0.00000000']], 'time': '2021-05-20T03:56:16.655303Z'}
{'type': 'l2update', 'product_id': 'BTC-USD', 'changes': [['sell', '38344.13', '0.00663787']], 'time': '2021-05-20T03:56:16.657283Z'}
{'type': 'l2update', 'product_id': 'BTC-USD', 'changes': [['sell', '38344.13', '0.00000000']], 'time': '2021-05-20T03:56:16.659284Z'}
{'type': 'l2update', 'product_id': 'BTC-USD', 'changes': [['buy', '38305.92', '0.00000000']], 'time': '2021-05-20T03:56:16.660759Z'}
{'type': 'l2update', 'product_id': 'BTC-USD', 'changes': [['sell', '38367.65', '0.00000000']], 'time': '2021-05-20T03:56:16.660853Z'}
{'type': 'l2update', 'product_id': 'BTC-USD', 'changes': [['buy', '38314.77', '0.03100520']], 'time': '2021-05-20T03:56:16.661741Z'}
{'type': 'l2update', 'product_id': 'BTC-USD', 'changes': [['buy', '38295.07', '0.01000000']], 'time': '2021-05-20T03:56:16.662031Z'}
{'type': 'l2update', 'product_id': 'BTC-USD', 'changes': [['buy', '38336.71', '0.05189341']], 'time': '2021-05-20T03:56:16.662240Z'}
{'type': 'l2update', 'product_id': 'BTC-USD', 'changes': [['sell', '38344.61', '0.00994930']], 'time': '2021-05-20T03:56:16.662813Z'}
{'type': 'l2update', 'product_id': 'BTC-USD', 'changes': [['buy', '38311.92', '0.00000000']], 'time': '2021-05-20T03:56:16.663815Z'}
{'type': 'l2update', 'product_id': 'BTC-USD', 'changes': [['sell', '38344.13', '1.27090349']], 'time': '2021-05-20T03:56:16.668553Z'}
{'type': 'l2update', 'product_id': 'BTC-USD', 'changes': [['buy', '38290.21', '2.60926893']], 'time': '2021-05-20T03:56:16.669082Z'}
{'type': 'l2update', 'product_id': 'BTC-USD', 'changes': [['sell', '38344.13', '1.29980349']], 'time': '2021-05-20T03:56:16.672353Z'}
{'type': 'l2update', 'product_id': 'BTC-USD', 'changes': [['sell', '38349.61', '0.04864795']], 'time': '2021-05-20T03:56:16.675496Z'}
{'type': 'l2update', 'product_id': 'BTC-USD', 'changes': [['sell', '38367.69', '0.05000000']], 'time': '2021-05-20T03:56:16.675523Z'}
{'type': 'l2update', 'product_id': 'BTC-USD', 'changes': [['buy', '38337.32', '0.00935174']], 'time': '2021-05-20T03:56:16.679453Z'}
{'type': 'l2update', 'product_id': 'BTC-USD', 'changes': [['buy', '38314.77', '0.00000000']], 'time': '2021-05-20T03:56:16.679665Z'}
{'type': 'l2update', 'product_id': 'BTC-USD', 'changes': [['sell', '38344.13', '0.02890000']], 'time': '2021-05-20T03:56:16.680471Z'}
{'type': 'l2update', 'product_id': 'BTC-USD', 'changes': [['buy', '38315.18', '0.03100520']], 'time': '2021-05-20T03:56:16.681850Z'}
{'type': 'l2update', 'product_id': 'BTC-USD', 'changes': [['sell', '38344.13', '0.00000000']], 'time': '2021-05-20T03:56:16.682919Z'}
{'type': 'l2update', 'product_id': 'BTC-USD', 'changes': [['buy', '38332.72', '0.00000000']], 'time': '2021-05-20T03:56:16.684369Z'}
{'type': 'l2update', 'product_id': 'BTC-USD', 'changes': [['buy', '37537.94', '0.00000000']], 'time': '2021-05-20T03:56:16.688820Z'}
{'type': 'l2update', 'product_id': 'BTC-USD', 'changes': [['buy', '38307.39', '0.45510000']], 'time': '2021-05-20T03:56:16.689737Z'}
{'type': 'l2update', 'product_id': 'BTC-USD', 'changes': [['sell', '38449.58', '0.00000000']], 'time': '2021-05-20T03:56:16.691085Z'}
{'type': 'l2update', 'product_id': 'BTC-USD', 'changes': [['sell', '38420.80', '0.18700000']], 'time': '2021-05-20T03:56:16.698472Z'}
{'type': 'l2update', 'product_id': 'BTC-USD', 'changes': [['buy', '38281.50', '0.00000000']], 'time': '2021-05-20T03:56:16.706217Z'}
{'type': 'l2update', 'product_id': 'BTC-USD', 'changes': [['sell', '39137.38', '0.06762031']], 'time': '2021-05-20T03:56:16.707311Z'}
{'type': 'l2update', 'product_id': 'BTC-USD', 'changes': [['sell', '38404.71', '0.00000000']], 'time': '2021-05-20T03:56:16.707894Z'}
{'type': 'l2update', 'product_id': 'BTC-USD', 'changes': [['sell', '38477.85', '0.01595000']], 'time': '2021-05-20T03:56:16.710577Z'}
{'type': 'l2update', 'product_id': 'BTC-USD', 'changes': [['buy', '38309.60', '0.04503195']], 'time': '2021-05-20T03:56:16.710649Z'}
{'type': 'l2update', 'product_id': 'BTC-USD', 'changes': [['sell', '38351.60', '0.05841000']], 'time': '2021-05-20T03:56:16.710649Z'}
{'type': 'l2update', 'product_id': 'BTC-USD', 'changes': [['sell', '38501.03', '0.00000000']], 'time': '2021-05-20T03:56:16.721236Z'}
{'type': 'l2update', 'product_id': 'BTC-USD', 'changes': [['buy', '38280.50', '0.10000000']], 'time': '2021-05-20T03:56:16.723576Z'}
{'type': 'l2update', 'product_id': 'BTC-USD', 'changes': [['sell', '38344.61', '0.20994930']], 'time': '2021-05-20T03:56:16.723820Z'}
{'type': 'l2update', 'product_id': 'BTC-USD', 'changes': [['buy', '38252.59', '0.00000000']], 'time': '2021-05-20T03:56:16.730993Z'}
{'type': 'l2update', 'product_id': 'BTC-USD', 'changes': [['sell', '38368.18', '0.40830000']], 'time': '2021-05-20T03:56:16.731369Z'}
{'type': 'l2update', 'product_id': 'BTC-USD', 'changes': [['sell', '38487.86', '0.01000000']], 'time': '2021-05-20T03:56:16.735427Z'}
{'type': 'l2update', 'product_id': 'BTC-USD', 'changes': [['sell', '38387.64', '0.00000000']], 'time': '2021-05-20T03:56:16.735920Z'}
{'type': 'l2update', 'product_id': 'BTC-USD', 'changes': [['sell', '38344.61', '0.30994930']], 'time': '2021-05-20T03:56:16.739505Z'}
{'type': 'l2update', 'product_id': 'BTC-USD', 'changes': [['sell', '38462.67', '0.00000000']], 'time': '2021-05-20T03:56:16.742864Z'}
{'type': 'l2update', 'product_id': 'BTC-USD', 'changes': [['buy', '38326.83', '0.84700000']], 'time': '2021-05-20T03:56:16.750838Z'}
{'type': 'l2update', 'product_id': 'BTC-USD', 'changes': [['buy', '38307.39', '0.00000000']], 'time': '2021-05-20T03:56:16.758603Z'}
{'type': 'l2update', 'product_id': 'BTC-USD', 'changes': [['buy', '38323.97', '0.00000000']], 'time': '2021-05-20T03:56:16.761040Z'}
{'type': 'l2update', 'product_id': 'BTC-USD', 'changes': [['sell', '38368.18', '0.00000000']], 'time': '2021-05-20T03:56:16.762754Z'}
{'type': 'l2update', 'product_id': 'BTC-USD', 'changes': [['sell', '38492.59', '0.01000000']], 'time': '2021-05-20T03:56:16.770008Z'}
{'type': 'l2update', 'product_id': 'BTC-USD', 'changes': [['buy', '37731.67', '0.04190000']], 'time': '2021-05-20T03:56:16.773805Z'}
{'type': 'l2update', 'product_id': 'BTC-USD', 'changes': [['buy', '37267.92', '0.05920000']], 'time': '2021-05-20T03:56:16.773805Z'}
{'type': 'l2update', 'product_id': 'BTC-USD', 'changes': [['buy', '38339.16', '0.00000000']], 'time': '2021-05-20T03:56:16.780208Z'}
{'type': 'l2update', 'product_id': 'BTC-USD', 'changes': [['buy', '38326.84', '0.59116555']], 'time': '2021-05-20T03:56:16.781458Z'}
{'type': 'l2update', 'product_id': 'BTC-USD', 'changes': [['buy', '38315.18', '0.00000000']], 'time': '2021-05-20T03:56:16.785460Z'}
{'type': 'l2update', 'product_id': 'BTC-USD', 'changes': [['sell', '38361.53', '0.00000000']], 'time': '2021-05-20T03:56:16.792240Z'}
{'type': 'l2update', 'product_id': 'BTC-USD', 'changes': [['sell', '38344.13', '1.50640277']], 'time': '2021-05-20T03:56:16.794411Z'}
{'type': 'l2update', 'product_id': 'BTC-USD', 'changes': [['buy', '38311.92', '0.03100520']], 'time': '2021-05-20T03:56:16.794606Z'}
{'type': 'l2update', 'product_id': 'BTC-USD', 'changes': [['sell', '38344.61', '0.20994930']], 'time': '2021-05-20T03:56:16.800484Z'}
{'type': 'l2update', 'product_id': 'BTC-USD', 'changes': [['sell', '38428.86', '0.00000000']], 'time': '2021-05-20T03:56:16.801407Z'}
{'type': 'l2update', 'product_id': 'BTC-USD', 'changes': [['buy', '38311.92', '0.00000000']], 'time': '2021-05-20T03:56:16.802403Z'}
{'type': 'l2update', 'product_id': 'BTC-USD', 'changes': [['buy', '38311.91', '0.00000000']], 'time': '2021-05-20T03:56:16.802530Z'}
{'type': 'l2update', 'product_id': 'BTC-USD', 'changes': [['buy', '38318.89', '0.07175114']], 'time': '2021-05-20T03:56:16.803445Z'}
{'type': 'l2update', 'product_id': 'BTC-USD', 'changes': [['sell', '38344.61', '0.00994930']], 'time': '2021-05-20T03:56:16.804714Z'}
{'type': 'l2update', 'product_id': 'BTC-USD', 'changes': [['sell', '38487.86', '0.00000000']], 'time': '2021-05-20T03:56:16.805498Z'}
{'type': 'l2update', 'product_id': 'BTC-USD', 'changes': [['sell', '38344.60', '1.36231207']], 'time': '2021-05-20T03:56:16.806850Z'}
{'type': 'l2update', 'product_id': 'BTC-USD', 'changes': [['buy', '38314.77', '0.03100520']], 'time': '2021-05-20T03:56:16.807161Z'}
{'type': 'l2update', 'product_id': 'BTC-USD', 'changes': [['sell', '38474.69', '0.01000000']], 'time': '2021-05-20T03:56:16.814687Z'}
{'type': 'l2update', 'product_id': 'BTC-USD', 'changes': [['buy', '38314.77', '0.00000000']], 'time': '2021-05-20T03:56:16.814896Z'}
{'type': 'l2update', 'product_id': 'BTC-USD', 'changes': [['sell', '38448.37', '0.13004453']], 'time': '2021-05-20T03:56:16.815554Z'}
{'type': 'l2update', 'product_id': 'BTC-USD', 'changes': [['sell', '38344.63', '0.00000000']], 'time': '2021-05-20T03:56:16.818212Z'}
{'type': 'l2update', 'product_id': 'BTC-USD', 'changes': [['buy', '38323.96', '1.36800000']], 'time': '2021-05-20T03:56:16.819571Z'}
{'type': 'l2update', 'product_id': 'BTC-USD', 'changes': [['buy', '38311.85', '0.03100520']], 'time': '2021-05-20T03:56:16.823248Z'}
{'type': 'l2update', 'product_id': 'BTC-USD', 'changes': [['sell', '38344.13', '0.00000000']], 'time': '2021-05-20T03:56:16.824487Z'}
{'type': 'l2update', 'product_id': 'BTC-USD', 'changes': [['sell', '38474.69', '0.00000000']], 'time': '2021-05-20T03:56:16.825902Z'}
{'type': 'l2update', 'product_id': 'BTC-USD', 'changes': [['buy', '38338.93', '0.00176479']], 'time': '2021-05-20T03:56:16.827645Z'}
{'type': 'l2update', 'product_id': 'BTC-USD', 'changes': [['sell', '38354.74', '0.50000000']], 'time': '2021-05-20T03:56:16.831601Z'}
{'type': 'l2update', 'product_id': 'BTC-USD', 'changes': [['sell', '38344.60', '0.00000000']], 'time': '2021-05-20T03:56:16.834382Z'}
{'type': 'l2update', 'product_id': 'BTC-USD', 'changes': [['buy', '38311.85', '0.00000000']], 'time': '2021-05-20T03:56:16.835092Z'}
{'type': 'l2update', 'product_id': 'BTC-USD', 'changes': [['sell', '38487.86', '0.01000000']], 'time': '2021-05-20T03:56:16.840711Z'}
{'type': 'l2update', 'product_id': 'BTC-USD', 'changes': [['buy', '38314.77', '0.03100520']], 'time': '2021-05-20T03:56:16.845655Z'}
{'type': 'l2update', 'product_id': 'BTC-USD', 'changes': [['buy', '38314.76', '0.00000000']], 'time': '2021-05-20T03:56:16.848189Z'}
{'type': 'l2update', 'product_id': 'BTC-USD', 'changes': [['sell', '38344.61', '0.20994930']], 'time': '2021-05-20T03:56:16.848988Z'}
{'type': 'l2update', 'product_id': 'BTC-USD', 'changes': [['buy', '38302.55', '0.00000000']], 'time': '2021-05-20T03:56:16.852511Z'}
{'type': 'l2update', 'product_id': 'BTC-USD', 'changes': [['buy', '38314.77', '0.00000000']], 'time': '2021-05-20T03:56:16.852674Z'}
{'type': 'l2update', 'product_id': 'BTC-USD', 'changes': [['buy', '38315.18', '0.03100520']], 'time': '2021-05-20T03:56:16.854180Z'}
{'type': 'l2update', 'product_id': 'BTC-USD', 'changes': [['buy', '38311.30', '0.45990000']], 'time': '2021-05-20T03:56:16.854300Z'}
{'type': 'l2update', 'product_id': 'BTC-USD', 'changes': [['sell', '38344.61', '0.30994930']], 'time': '2021-05-20T03:56:16.863121Z'}
{'type': 'l2update', 'product_id': 'BTC-USD', 'changes': [['buy', '38337.32', '0.00000000']], 'time': '2021-05-20T03:56:16.887006Z'}
{'type': 'l2update', 'product_id': 'BTC-USD', 'changes': [['sell', '38344.13', '0.10000000']], 'time': '2021-05-20T03:56:16.890935Z'}
{'type': 'l2update', 'product_id': 'BTC-USD', 'changes': [['buy', '38315.18', '0.00000000']], 'time': '2021-05-20T03:56:16.892205Z'}
{'type': 'l2update', 'product_id': 'BTC-USD', 'changes': [['buy', '38303.87', '0.00000000']], 'time': '2021-05-20T03:56:16.894912Z'}
{'type': 'l2update', 'product_id': 'BTC-USD', 'changes': [['buy', '38303.07', '0.00000000']], 'time': '2021-05-20T03:56:16.894912Z'}
{'type': 'l2update', 'product_id': 'BTC-USD', 'changes': [['sell', '38368.98', '0.47620000']], 'time': '2021-05-20T03:56:16.894940Z'}
{'type': 'l2update', 'product_id': 'BTC-USD', 'changes': [['buy', '38296.41', '1.20000000']], 'time': '2021-05-20T03:56:16.898819Z'}
{'type': 'l2update', 'product_id': 'BTC-USD', 'changes': [['buy', '38311.85', '0.03100520']], 'time': '2021-05-20T03:56:16.899379Z'}
{'type': 'l2update', 'product_id': 'BTC-USD', 'changes': [['buy', '38304.68', '0.00000000']], 'time': '2021-05-20T03:56:16.899516Z'}
{'type': 'l2update', 'product_id': 'BTC-USD', 'changes': [['sell', '38368.98', '0.00000000']], 'time': '2021-05-20T03:56:16.902054Z'}
{'type': 'l2update', 'product_id': 'BTC-USD', 'changes': [['sell', '38344.13', '0.75000000']], 'time': '2021-05-20T03:56:16.902601Z'}
{'type': 'l2update', 'product_id': 'BTC-USD', 'changes': [['sell', '38344.13', '0.95000000']], 'time': '2021-05-20T03:56:16.903080Z'}
{'type': 'l2update', 'product_id': 'BTC-USD', 'changes': [['sell', '38344.61', '0.30000000']], 'time': '2021-05-20T03:56:16.903141Z'}
{'type': 'l2update', 'product_id': 'BTC-USD', 'changes': [['buy', '38315.18', '0.03100520']], 'time': '2021-05-20T03:56:16.903162Z'}
{'type': 'l2update', 'product_id': 'BTC-USD', 'changes': [['sell', '38580.00', '1.19720000']], 'time': '2021-05-20T03:56:16.903180Z'}
{'type': 'l2update', 'product_id': 'BTC-USD', 'changes': [['sell', '38431.46', '1.20000000']], 'time': '2021-05-20T03:56:16.906808Z'}
{'type': 'l2update', 'product_id': 'BTC-USD', 'changes': [['buy', '38311.85', '0.00000000']], 'time': '2021-05-20T03:56:16.907329Z'}
{'type': 'l2update', 'product_id': 'BTC-USD', 'changes': [['sell', '38344.61', '0.10000000']], 'time': '2021-05-20T03:56:16.908211Z'}
{'type': 'l2update', 'product_id': 'BTC-USD', 'changes': [['buy', '38315.18', '0.00000000']], 'time': '2021-05-20T03:56:16.909026Z'}
{'type': 'l2update', 'product_id': 'BTC-USD', 'changes': [['sell', '38344.61', '0.00000000']], 'time': '2021-05-20T03:56:16.911512Z'}
{'type': 'l2update', 'product_id': 'BTC-USD', 'changes': [['buy', '38318.89', '0.00000000']], 'time': '2021-05-20T03:56:16.911528Z'}
{'type': 'l2update', 'product_id': 'BTC-USD', 'changes': [['buy', '38310.38', '0.02400000']], 'time': '2021-05-20T03:56:16.914229Z'}
{'type': 'l2update', 'product_id': 'BTC-USD', 'changes': [['buy', '38309.57', '0.02400000']], 'time': '2021-05-20T03:56:16.914229Z'}
{'type': 'l2update', 'product_id': 'BTC-USD', 'changes': [['buy', '38308.76', '0.02400000']], 'time': '2021-05-20T03:56:16.914229Z'}
{'type': 'l2update', 'product_id': 'BTC-USD', 'changes': [['buy', '38309.57', '0.00000000']], 'time': '2021-05-20T03:56:16.920527Z'}
{'type': 'l2update', 'product_id': 'BTC-USD', 'changes': [['buy', '38308.76', '0.00000000']], 'time': '2021-05-20T03:56:16.920527Z'}
{'type': 'l2update', 'product_id': 'BTC-USD', 'changes': [['buy', '38310.38', '0.00000000']], 'time': '2021-05-20T03:56:16.924284Z'}
{'type': 'l2update', 'product_id': 'BTC-USD', 'changes': [['buy', '38311.85', '0.03100520']], 'time': '2021-05-20T03:56:16.924380Z'}
{'type': 'l2update', 'product_id': 'BTC-USD', 'changes': [['buy', '38311.30', '0.00000000']], 'time': '2021-05-20T03:56:16.928555Z'}
{'type': 'l2update', 'product_id': 'BTC-USD', 'changes': [['buy', '38326.83', '0.00000000']], 'time': '2021-05-20T03:56:16.928839Z'}
{'type': 'l2update', 'product_id': 'BTC-USD', 'changes': [['sell', '38351.60', '0.00000000']], 'time': '2021-05-20T03:56:16.932153Z'}
{'type': 'l2update', 'product_id': 'BTC-USD', 'changes': [['buy', '38326.84', '0.00000000']], 'time': '2021-05-20T03:56:16.934230Z'}
{'type': 'l2update', 'product_id': 'BTC-USD', 'changes': [['buy', '38322.16', '0.07175114']], 'time': '2021-05-20T03:56:16.938366Z'}
{'type': 'l2update', 'product_id': 'BTC-USD', 'changes': [['buy', '38324.01', '0.84600000']], 'time': '2021-05-20T03:56:16.944748Z'}
{'type': 'l2update', 'product_id': 'BTC-USD', 'changes': [['sell', '38344.13', '0.95573000']], 'time': '2021-05-20T03:56:16.944905Z'}
{'type': 'l2update', 'product_id': 'BTC-USD', 'changes': [['buy', '38317.21', '0.02400000']], 'time': '2021-05-20T03:56:16.946987Z'}
{'type': 'l2update', 'product_id': 'BTC-USD', 'changes': [['buy', '38316.40', '0.02400000']], 'time': '2021-05-20T03:56:16.946987Z'}
{'type': 'l2update', 'product_id': 'BTC-USD', 'changes': [['buy', '38315.60', '0.02400000']], 'time': '2021-05-20T03:56:16.946987Z'}
{'type': 'l2update', 'product_id': 'BTC-USD', 'changes': [['buy', '38317.21', '0.00000000']], 'time': '2021-05-20T03:56:16.953485Z'}
{'type': 'l2update', 'product_id': 'BTC-USD', 'changes': [['sell', '38351.10', '0.03965010']], 'time': '2021-05-20T03:56:16.955569Z'}
{'type': 'l2update', 'product_id': 'BTC-USD', 'changes': [['buy', '38323.97', '0.59116555']], 'time': '2021-05-20T03:56:16.955595Z'}
{'type': 'l2update', 'product_id': 'BTC-USD', 'changes': [['buy', '38183.00', '0.14020000']], 'time': '2021-05-20T03:56:16.964150Z'}
{'type': 'l2update', 'product_id': 'BTC-USD', 'changes': [['sell', '38344.13', '2.05673268']], 'time': '2021-05-20T03:56:16.984311Z'}
{'type': 'l2update', 'product_id': 'BTC-USD', 'changes': [['sell', '38362.52', '0.40360000']], 'time': '2021-05-20T03:56:16.991435Z'}
{'type': 'l2update', 'product_id': 'BTC-USD', 'changes': [['buy', '38315.17', '0.00000000']], 'time': '2021-05-20T03:56:17.004143Z'}
{'type': 'l2update', 'product_id': 'BTC-USD', 'changes': [['buy', '38314.15', '0.02400000']], 'time': '2021-05-20T03:56:17.007546Z'}
{'type': 'l2update', 'product_id': 'BTC-USD', 'changes': [['buy', '38316.40', '0.00000000']], 'time': '2021-05-20T03:56:17.013394Z'}
{'type': 'l2update', 'product_id': 'BTC-USD', 'changes': [['sell', '38487.86', '0.00000000']], 'time': '2021-05-20T03:56:17.014531Z'}
{'type': 'l2update', 'product_id': 'BTC-USD', 'changes': [['sell', '38344.13', '2.05512380']], 'time': '2021-05-20T03:56:17.014540Z'}
{'type': 'l2update', 'product_id': 'BTC-USD', 'changes': [['buy', '38315.60', '0.00000000']], 'time': '2021-05-20T03:56:17.017096Z'}
{'type': 'l2update', 'product_id': 'BTC-USD', 'changes': [['buy', '38323.97', '0.00000000']], 'time': '2021-05-20T03:56:17.019004Z'}
{'type': 'l2update', 'product_id': 'BTC-USD', 'changes': [['sell', '39499.99', '0.06010000']], 'time': '2021-05-20T03:56:17.021340Z'}
{'type': 'l2update', 'product_id': 'BTC-USD', 'changes': [['buy', '38324.72', '1.07340561']], 'time': '2021-05-20T03:56:17.022641Z'}
{'type': 'l2update', 'product_id': 'BTC-USD', 'changes': [['buy', '38305.98', '0.46530000']], 'time': '2021-05-20T03:56:17.022901Z'}
{'type': 'l2update', 'product_id': 'BTC-USD', 'changes': [['sell', '38497.26', '0.01000000']], 'time': '2021-05-20T03:56:17.026763Z'}
{'type': 'l2update', 'product_id': 'BTC-USD', 'changes': [['buy', '38313.00', '0.02400000']], 'time': '2021-05-20T03:56:17.030501Z'}
{'type': 'l2update', 'product_id': 'BTC-USD', 'changes': [['buy', '38312.19', '0.02400000']], 'time': '2021-05-20T03:56:17.030501Z'}
{'type': 'l2update', 'product_id': 'BTC-USD', 'changes': [['sell', '39499.99', '0.12150000']], 'time': '2021-05-20T03:56:17.030526Z'}
{'type': 'l2update', 'product_id': 'BTC-USD', 'changes': [['buy', '37500.01', '0.00730000']], 'time': '2021-05-20T03:56:17.030526Z'}
{'type': 'l2update', 'product_id': 'BTC-USD', 'changes': [['sell', '38366.88', '0.04958947']], 'time': '2021-05-20T03:56:17.035078Z'}
{'type': 'l2update', 'product_id': 'BTC-USD', 'changes': [['buy', '38324.73', '0.59116555']], 'time': '2021-05-20T03:56:17.042958Z'}
{'type': 'l2update', 'product_id': 'BTC-USD', 'changes': [['buy', '38293.92', '0.14000000']], 'time': '2021-05-20T03:56:17.050138Z'}
{'type': 'l2update', 'product_id': 'BTC-USD', 'changes': [['sell', '38523.96', '0.00000000']], 'time': '2021-05-20T03:56:17.050850Z'}
{'type': 'l2update', 'product_id': 'BTC-USD', 'changes': [['sell', '38344.13', '1.40512380']], 'time': '2021-05-20T03:56:17.051562Z'}
{'type': 'l2update', 'product_id': 'BTC-USD', 'changes': [['sell', '38362.52', '0.00000000']], 'time': '2021-05-20T03:56:17.052637Z'}
{'type': 'l2update', 'product_id': 'BTC-USD', 'changes': [['buy', '38338.93', '0.00000000']], 'time': '2021-05-20T03:56:17.053055Z'}
{'type': 'l2update', 'product_id': 'BTC-USD', 'changes': [['buy', '38293.92', '0.12000000']], 'time': '2021-05-20T03:56:17.053271Z'}
{'type': 'l2update', 'product_id': 'BTC-USD', 'changes': [['buy', '38293.92', '0.09000000']], 'time': '2021-05-20T03:56:17.056498Z'}
{'type': 'l2update', 'product_id': 'BTC-USD', 'changes': [['buy', '38293.92', '0.05000000']], 'time': '2021-05-20T03:56:17.060456Z'}
{'type': 'l2update', 'product_id': 'BTC-USD', 'changes': [['sell', '38489.17', '0.01000000']], 'time': '2021-05-20T03:56:17.063477Z'}
{'type': 'l2update', 'product_id': 'BTC-USD', 'changes': [['buy', '38293.92', '0.00000000']], 'time': '2021-05-20T03:56:17.064579Z'}
{'type': 'l2update', 'product_id': 'BTC-USD', 'changes': [['sell', '38398.39', '0.61482417']], 'time': '2021-05-20T03:56:17.070785Z'}
{'type': 'l2update', 'product_id': 'BTC-USD', 'changes': [['sell', '38344.13', '0.30412112']], 'time': '2021-05-20T03:56:17.072193Z'}
{'type': 'l2update', 'product_id': 'BTC-USD', 'changes': [['buy', '38323.96', '0.84700000']], 'time': '2021-05-20T03:56:17.074650Z'}
{'type': 'l2update', 'product_id': 'BTC-USD', 'changes': [['buy', '38310.33', '0.01000000']], 'time': '2021-05-20T03:56:17.076103Z'}
{'type': 'l2update', 'product_id': 'BTC-USD', 'changes': [['buy', '38324.72', '0.00000000']], 'time': '2021-05-20T03:56:17.078425Z'}
{'type': 'l2update', 'product_id': 'BTC-USD', 'changes': [['buy', '38324.73', '0.00000000']], 'time': '2021-05-20T03:56:17.085077Z'}
{'type': 'l2update', 'product_id': 'BTC-USD', 'changes': [['buy', '38310.33', '0.03000000']], 'time': '2021-05-20T03:56:17.086887Z'}
{'type': 'l2update', 'product_id': 'BTC-USD', 'changes': [['buy', '38320.96', '0.52000000']], 'time': '2021-05-20T03:56:17.088233Z'}
{'type': 'l2update', 'product_id': 'BTC-USD', 'changes': [['sell', '38344.13', '1.47065967']], 'time': '2021-05-20T03:56:17.088397Z'}
{'type': 'l2update', 'product_id': 'BTC-USD', 'changes': [['sell', '38529.35', '0.00000000']], 'time': '2021-05-20T03:56:17.092287Z'}
{'type': 'l2update', 'product_id': 'BTC-USD', 'changes': [['sell', '38344.13', '0.30412112']], 'time': '2021-05-20T03:56:17.094714Z'}
{'type': 'l2update', 'product_id': 'BTC-USD', 'changes': [['buy', '38310.33', '0.06000000']], 'time': '2021-05-20T03:56:17.094963Z'}
{'type': 'l2update', 'product_id': 'BTC-USD', 'changes': [['buy', '38324.01', '0.00000000']], 'time': '2021-05-20T03:56:17.097444Z'}
{'type': 'l2update', 'product_id': 'BTC-USD', 'changes': [['buy', '38101.01', '0.00000000']], 'time': '2021-05-20T03:56:17.099803Z'}
{'type': 'l2update', 'product_id': 'BTC-USD', 'changes': [['buy', '38324.02', '1.07340561']], 'time': '2021-05-20T03:56:17.100643Z'}
{'type': 'l2update', 'product_id': 'BTC-USD', 'changes': [['buy', '38324.02', '1.66457116']], 'time': '2021-05-20T03:56:17.105571Z'}
{'type': 'l2update', 'product_id': 'BTC-USD', 'changes': [['buy', '38310.33', '0.10000000']], 'time': '2021-05-20T03:56:17.107228Z'}
{'type': 'l2update', 'product_id': 'BTC-USD', 'changes': [['buy', '38323.96', '1.69300000']], 'time': '2021-05-20T03:56:17.111190Z'}
{'type': 'l2update', 'product_id': 'BTC-USD', 'changes': [['sell', '38457.65', '0.00000000']], 'time': '2021-05-20T03:56:17.111426Z'}
{'type': 'l2update', 'product_id': 'BTC-USD', 'changes': [['sell', '38497.26', '0.00000000']], 'time': '2021-05-20T03:56:17.116424Z'}
{'type': 'l2update', 'product_id': 'BTC-USD', 'changes': [['buy', '38310.33', '0.15000000']], 'time': '2021-05-20T03:56:17.118925Z'}
{'type': 'l2update', 'product_id': 'BTC-USD', 'changes': [['sell', '38469.43', '0.01299733']], 'time': '2021-05-20T03:56:17.125044Z'}
{'type': 'l2update', 'product_id': 'BTC-USD', 'changes': [['sell', '38484.10', '0.01000000']], 'time': '2021-05-20T03:56:17.126594Z'}
{'type': 'l2update', 'product_id': 'BTC-USD', 'changes': [['buy', '37544.84', '0.00000000']], 'time': '2021-05-20T03:56:17.132688Z'}
{'type': 'l2update', 'product_id': 'BTC-USD', 'changes': [['buy', '36899.32', '0.00000000']], 'time': '2021-05-20T03:56:17.132688Z'}
{'type': 'l2update', 'product_id': 'BTC-USD', 'changes': [['sell', '38484.10', '0.00000000']], 'time': '2021-05-20T03:56:17.138589Z'}
{'type': 'l2update', 'product_id': 'BTC-USD', 'changes': [['sell', '38366.92', '0.49620000']], 'time': '2021-05-20T03:56:17.145547Z'}
{'type': 'l2update', 'product_id': 'BTC-USD', 'changes': [['sell', '38344.13', '0.29134251']], 'time': '2021-05-20T03:56:17.147375Z'}
{'type': 'l2update', 'product_id': 'BTC-USD', 'changes': [['sell', '38497.26', '0.01000000']], 'time': '2021-05-20T03:56:17.151214Z'}
{'type': 'l2update', 'product_id': 'BTC-USD', 'changes': [['buy', '38289.51', '0.00000000']], 'time': '2021-05-20T03:56:17.155303Z'}
{'type': 'l2update', 'product_id': 'BTC-USD', 'changes': [['sell', '38344.13', '0.26518141']], 'time': '2021-05-20T03:56:17.156115Z'}
{'type': 'l2update', 'product_id': 'BTC-USD', 'changes': [['sell', '38383.75', '0.46108380']], 'time': '2021-05-20T03:56:17.156157Z'}
{'type': 'l2update', 'product_id': 'BTC-USD', 'changes': [['buy', '37535.86', '0.06905454']], 'time': '2021-05-20T03:56:17.159646Z'}
{'type': 'l2update', 'product_id': 'BTC-USD', 'changes': [['buy', '38324.02', '1.07340561']], 'time': '2021-05-20T03:56:17.161210Z'}
{'type': 'l2update', 'product_id': 'BTC-USD', 'changes': [['sell', '39137.38', '0.00000000']], 'time': '2021-05-20T03:56:17.166224Z'}
{'type': 'l2update', 'product_id': 'BTC-USD', 'changes': [['sell', '38344.13', '1.78733904']], 'time': '2021-05-20T03:56:17.178989Z'}
{'type': 'l2update', 'product_id': 'BTC-USD', 'changes': [['buy', '38305.98', '0.00000000']], 'time': '2021-05-20T03:56:17.180347Z'}
{'type': 'l2update', 'product_id': 'BTC-USD', 'changes': [['sell', '38480.34', '0.00000000']], 'time': '2021-05-20T03:56:17.182387Z'}
{'type': 'l2update', 'product_id': 'BTC-USD', 'changes': [['buy', '38324.03', '0.59116555']], 'time': '2021-05-20T03:56:17.183248Z'}
{'type': 'l2update', 'product_id': 'BTC-USD', 'changes': [['buy', '38307.85', '0.49770000']], 'time': '2021-05-20T03:56:17.191235Z'}
{'type': 'l2update', 'product_id': 'BTC-USD', 'changes': [['sell', '38354.74', '0.00000000']], 'time': '2021-05-20T03:56:17.192628Z'}
{'type': 'l2update', 'product_id': 'BTC-USD', 'changes': [['sell', '38407.53', '0.00000000']], 'time': '2021-05-20T03:56:17.196239Z'}
{'type': 'l2update', 'product_id': 'BTC-USD', 'changes': [['sell', '38466.57', '0.01000000']], 'time': '2021-05-20T03:56:17.196948Z'}
{'type': 'l2update', 'product_id': 'BTC-USD', 'changes': [['sell', '38344.13', '2.28733904']], 'time': '2021-05-20T03:56:17.207051Z'}
{'type': 'l2update', 'product_id': 'BTC-USD', 'changes': [['sell', '38452.23', '0.01000000']], 'time': '2021-05-20T03:56:17.207084Z'}
{'type': 'l2update', 'product_id': 'BTC-USD', 'changes': [['sell', '43100.00', '1.09530000']], 'time': '2021-05-20T03:56:17.214538Z'}
{'type': 'l2update', 'product_id': 'BTC-USD', 'changes': [['sell', '43100.00', '1.29720000']], 'time': '2021-05-20T03:56:17.227614Z'}
{'type': 'l2update', 'product_id': 'BTC-USD', 'changes': [['sell', '38489.17', '0.00000000']], 'time': '2021-05-20T03:56:17.239591Z'}
{'type': 'l2update', 'product_id': 'BTC-USD', 'changes': [['sell', '38514.82', '0.01000000']], 'time': '2021-05-20T03:56:17.251911Z'}
{'type': 'l2update', 'product_id': 'BTC-USD', 'changes': [['buy', '38326.87', '0.84700000']], 'time': '2021-05-20T03:56:17.292963Z'}
{'type': 'l2update', 'product_id': 'BTC-USD', 'changes': [['sell', '38514.82', '0.00000000']], 'time': '2021-05-20T03:56:17.297362Z'}
{'type': 'l2update', 'product_id': 'BTC-USD', 'changes': [['sell', '38344.13', '1.78733904']], 'time': '2021-05-20T03:56:17.306553Z'}
{'type': 'l2update', 'product_id': 'BTC-USD', 'changes': [['sell', '38489.14', '0.01000000']], 'time': '2021-05-20T03:56:17.308164Z'}
{'type': 'l2update', 'product_id': 'BTC-USD', 'changes': [['buy', '38321.94', '0.52000000']], 'time': '2021-05-20T03:56:17.310336Z'}
{'type': 'l2update', 'product_id': 'BTC-USD', 'changes': [['sell', '38497.26', '0.00000000']], 'time': '2021-05-20T03:56:17.316940Z'}
{'type': 'l2update', 'product_id': 'BTC-USD', 'changes': [['sell', '38354.74', '0.50000000']], 'time': '2021-05-20T03:56:17.319709Z'}
{'type': 'l2update', 'product_id': 'BTC-USD', 'changes': [['sell', '38377.50', '0.00000000']], 'time': '2021-05-20T03:56:17.330867Z'}
{'type': 'l2update', 'product_id': 'BTC-USD', 'changes': [['sell', '38484.10', '0.01000000']], 'time': '2021-05-20T03:56:17.333007Z'}
{'type': 'l2update', 'product_id': 'BTC-USD', 'changes': [['buy', '38295.07', '0.00000000']], 'time': '2021-05-20T03:56:17.337448Z'}
{'type': 'l2update', 'product_id': 'BTC-USD', 'changes': [['sell', '38484.10', '0.00000000']], 'time': '2021-05-20T03:56:17.342599Z'}
{'type': 'l2update', 'product_id': 'BTC-USD', 'changes': [['sell', '38344.13', '0.26518141']], 'time': '2021-05-20T03:56:17.343159Z'}
{'type': 'l2update', 'product_id': 'BTC-USD', 'changes': [['buy', '38324.03', '0.00000000']], 'time': '2021-05-20T03:56:17.350578Z'}
{'type': 'l2update', 'product_id': 'BTC-USD', 'changes': [['sell', '38499.15', '0.01000000']], 'time': '2021-05-20T03:56:17.356022Z'}
{'type': 'l2update', 'product_id': 'BTC-USD', 'changes': [['sell', '38489.14', '0.00000000']], 'time': '2021-05-20T03:56:17.357999Z'}
{'type': 'l2update', 'product_id': 'BTC-USD', 'changes': [['sell', '38514.80', '0.01000000']], 'time': '2021-05-20T03:56:17.367750Z'}
{'type': 'l2update', 'product_id': 'BTC-USD', 'changes': [['buy', '38326.88', '0.59116555']], 'time': '2021-05-20T03:56:17.371554Z'}
{'type': 'l2update', 'product_id': 'BTC-USD', 'changes': [['sell', '38477.81', '0.30055436']], 'time': '2021-05-20T03:56:17.383481Z'}
{'type': 'l2update', 'product_id': 'BTC-USD', 'changes': [['buy', '38180.96', '0.00000000']], 'time': '2021-05-20T03:56:17.386248Z'}
{'type': 'l2update', 'product_id': 'BTC-USD', 'changes': [['sell', '38363.97', '0.00000000']], 'time': '2021-05-20T03:56:17.388059Z'}
{'type': 'l2update', 'product_id': 'BTC-USD', 'changes': [['sell', '38427.09', '0.00000000']], 'time': '2021-05-20T03:56:17.390594Z'}
{'type': 'l2update', 'product_id': 'BTC-USD', 'changes': [['buy', '38010.00', '0.30888104']], 'time': '2021-05-20T03:56:17.399178Z'}
{'type': 'l2update', 'product_id': 'BTC-USD', 'changes': [['sell', '38441.88', '0.15420663']], 'time': '2021-05-20T03:56:17.402642Z'}
{'type': 'l2update', 'product_id': 'BTC-USD', 'changes': [['sell', '48373.94', '0.00000000']], 'time': '2021-05-20T03:56:17.413293Z'}
{'type': 'l2update', 'product_id': 'BTC-USD', 'changes': [['sell', '48370.48', '0.00000000']], 'time': '2021-05-20T03:56:17.415541Z'}
{'type': 'l2update', 'product_id': 'BTC-USD', 'changes': [['sell', '48367.02', '0.00000000']], 'time': '2021-05-20T03:56:17.418386Z'}
{'type': 'l2update', 'product_id': 'BTC-USD', 'changes': [['sell', '48255.15', '0.00000000']], 'time': '2021-05-20T03:56:17.421235Z'}
{'type': 'l2update', 'product_id': 'BTC-USD', 'changes': [['sell', '38514.80', '0.00000000']], 'time': '2021-05-20T03:56:17.421709Z'}
{'type': 'l2update', 'product_id': 'BTC-USD', 'changes': [['sell', '48241.36', '0.00000000']], 'time': '2021-05-20T03:56:17.423732Z'}
{'type': 'l2update', 'product_id': 'BTC-USD', 'changes': [['sell', '48234.97', '0.00000000']], 'time': '2021-05-20T03:56:17.426021Z'}
{'type': 'l2update', 'product_id': 'BTC-USD', 'changes': [['sell', '48231.03', '0.00000000']], 'time': '2021-05-20T03:56:17.428498Z'}
{'type': 'l2update', 'product_id': 'BTC-USD', 'changes': [['sell', '48224.13', '0.00000000']], 'time': '2021-05-20T03:56:17.431159Z'}
{'type': 'l2update', 'product_id': 'BTC-USD', 'changes': [['sell', '38489.13', '0.01000000']], 'time': '2021-05-20T03:56:17.433146Z'}
{'type': 'l2update', 'product_id': 'BTC-USD', 'changes': [['sell', '48220.68', '0.00000000']], 'time': '2021-05-20T03:56:17.433308Z'}
{'type': 'l2update', 'product_id': 'BTC-USD', 'changes': [['sell', '48217.24', '0.00000000']], 'time': '2021-05-20T03:56:17.436957Z'}
{'type': 'l2update', 'product_id': 'BTC-USD', 'changes': [['sell', '48213.79', '0.00000000']], 'time': '2021-05-20T03:56:17.439443Z'}
{'type': 'l2update', 'product_id': 'BTC-USD', 'changes': [['buy', '38307.85', '0.00000000']], 'time': '2021-05-20T03:56:17.440101Z'}
{'type': 'l2update', 'product_id': 'BTC-USD', 'changes': [['sell', '48210.34', '0.00000000']], 'time': '2021-05-20T03:56:17.443244Z'}
{'type': 'l2update', 'product_id': 'BTC-USD', 'changes': [['sell', '48163.77', '0.00000000']], 'time': '2021-05-20T03:56:17.446274Z'}
{'type': 'l2update', 'product_id': 'BTC-USD', 'changes': [['sell', '48150.01', '0.00000000']], 'time': '2021-05-20T03:56:17.449805Z'}
{'type': 'l2update', 'product_id': 'BTC-USD', 'changes': [['buy', '38309.90', '0.46170000']], 'time': '2021-05-20T03:56:17.453417Z'}
{'type': 'l2update', 'product_id': 'BTC-USD', 'changes': [['sell', '48139.69', '0.00000000']], 'time': '2021-05-20T03:56:17.453609Z'}
{'type': 'l2update', 'product_id': 'BTC-USD', 'changes': [['sell', '38371.59', '0.39490432']], 'time': '2021-05-20T03:56:17.454090Z'}
{'type': 'l2update', 'product_id': 'BTC-USD', 'changes': [['sell', '48132.81', '0.00000000']], 'time': '2021-05-20T03:56:17.458467Z'}
{'type': 'l2update', 'product_id': 'BTC-USD', 'changes': [['sell', '48083.31', '0.00000000']], 'time': '2021-05-20T03:56:17.463251Z'}
{'type': 'l2update', 'product_id': 'BTC-USD', 'changes': [['sell', '47867.28', '0.00000000']], 'time': '2021-05-20T03:56:17.467059Z'}
{'type': 'l2update', 'product_id': 'BTC-USD', 'changes': [['sell', '38344.13', '1.60363036']], 'time': '2021-05-20T03:56:17.470544Z'}
{'type': 'l2update', 'product_id': 'BTC-USD', 'changes': [['sell', '47853.62', '0.00000000']], 'time': '2021-05-20T03:56:17.472324Z'}
{'type': 'l2update', 'product_id': 'BTC-USD', 'changes': [['sell', '47843.36', '0.00000000']], 'time': '2021-05-20T03:56:17.477014Z'}
{'type': 'l2update', 'product_id': 'BTC-USD', 'changes': [['sell', '38489.13', '0.00000000']], 'time': '2021-05-20T03:56:17.483450Z'}
{'type': 'l2update', 'product_id': 'BTC-USD', 'changes': [['buy', '38309.60', '0.00000000']], 'time': '2021-05-20T03:56:17.488322Z'}
{'type': 'l2update', 'product_id': 'BTC-USD', 'changes': [['sell', '38351.10', '0.00000000']], 'time': '2021-05-20T03:56:17.488322Z'}
{'type': 'l2update', 'product_id': 'BTC-USD', 'changes': [['buy', '38326.87', '0.00000000']], 'time': '2021-05-20T03:56:17.489273Z'}
{'type': 'l2update', 'product_id': 'BTC-USD', 'changes': [['buy', '38326.88', '0.00000000']], 'time': '2021-05-20T03:56:17.496729Z'}
{'type': 'l2update', 'product_id': 'BTC-USD', 'changes': [['sell', '38514.79', '0.01000000']], 'time': '2021-05-20T03:56:17.497164Z'}
{'type': 'l2update', 'product_id': 'BTC-USD', 'changes': [['sell', '38377.75', '0.01000000']], 'time': '2021-05-20T03:56:17.501078Z'}
{'type': 'l2update', 'product_id': 'BTC-USD', 'changes': [['buy', '38324.02', '0.00000000']], 'time': '2021-05-20T03:56:17.501166Z'}
{'type': 'l2update', 'product_id': 'BTC-USD', 'changes': [['buy', '38171.00', '0.04872157']], 'time': '2021-05-20T03:56:17.504025Z'}
{'type': 'l2update', 'product_id': 'BTC-USD', 'changes': [['buy', '38324.07', '0.84600000']], 'time': '2021-05-20T03:56:17.504081Z'}
{'type': 'l2update', 'product_id': 'BTC-USD', 'changes': [['buy', '38314.15', '0.00000000']], 'time': '2021-05-20T03:56:17.511215Z'}
{'type': 'l2update', 'product_id': 'BTC-USD', 'changes': [['buy', '38303.84', '0.04580925']], 'time': '2021-05-20T03:56:17.512000Z'}
{'type': 'l2update', 'product_id': 'BTC-USD', 'changes': [['sell', '38351.08', '0.05550395']], 'time': '2021-05-20T03:56:17.512000Z'}
{'type': 'l2update', 'product_id': 'BTC-USD', 'changes': [['buy', '38295.33', '0.01000000']], 'time': '2021-05-20T03:56:17.512219Z'}
{'type': 'l2update', 'product_id': 'BTC-USD', 'changes': [['buy', '38323.97', '0.59116555']], 'time': '2021-05-20T03:56:17.517881Z'}
{'type': 'l2update', 'product_id': 'BTC-USD', 'changes': [['buy', '38311.17', '0.02400000']], 'time': '2021-05-20T03:56:17.521862Z'}
{'type': 'l2update', 'product_id': 'BTC-USD', 'changes': [['buy', '38322.17', '1.07340561']], 'time': '2021-05-20T03:56:17.521930Z'}
{'type': 'l2update', 'product_id': 'BTC-USD', 'changes': [['sell', '38499.15', '0.00000000']], 'time': '2021-05-20T03:56:17.524445Z'}
{'type': 'l2update', 'product_id': 'BTC-USD', 'changes': [['sell', '38514.79', '0.00000000']], 'time': '2021-05-20T03:56:17.528093Z'}
{'type': 'l2update', 'product_id': 'BTC-USD', 'changes': [['sell', '38366.92', '0.00000000']], 'time': '2021-05-20T03:56:17.530188Z'}
{'type': 'l2update', 'product_id': 'BTC-USD', 'changes': [['sell', '38366.91', '0.06497884']], 'time': '2021-05-20T03:56:17.534091Z'}
{'type': 'l2update', 'product_id': 'BTC-USD', 'changes': [['sell', '38485.98', '0.01000000']], 'time': '2021-05-20T03:56:17.538035Z'}
{'type': 'l2update', 'product_id': 'BTC-USD', 'changes': [['sell', '38619.76', '0.00000000']], 'time': '2021-05-20T03:56:17.541431Z'}
{'type': 'l2update', 'product_id': 'BTC-USD', 'changes': [['sell', '38362.52', '0.46640000']], 'time': '2021-05-20T03:56:17.541544Z'}
{'type': 'l2update', 'product_id': 'BTC-USD', 'changes': [['sell', '38489.12', '0.01000000']], 'time': '2021-05-20T03:56:17.541655Z'}
{'type': 'l2update', 'product_id': 'BTC-USD', 'changes': [['sell', '38362.52', '0.00000000']], 'time': '2021-05-20T03:56:17.546647Z'}
{'type': 'l2update', 'product_id': 'BTC-USD', 'changes': [['sell', '38485.98', '0.00000000']], 'time': '2021-05-20T03:56:17.548665Z'}
{'type': 'l2update', 'product_id': 'BTC-USD', 'changes': [['sell', '38665.02', '0.01293158']], 'time': '2021-05-20T03:56:17.553072Z'}
{'type': 'l2update', 'product_id': 'BTC-USD', 'changes': [['buy', '38303.84', '0.00000000']], 'time': '2021-05-20T03:56:17.553934Z'}
{'type': 'l2update', 'product_id': 'BTC-USD', 'changes': [['sell', '38351.08', '0.00000000']], 'time': '2021-05-20T03:56:17.553934Z'}
{'type': 'l2update', 'product_id': 'BTC-USD', 'changes': [['buy', '38171.00', '0.00000000']], 'time': '2021-05-20T03:56:17.554441Z'}
{'type': 'l2update', 'product_id': 'BTC-USD', 'changes': [['sell', '38466.95', '0.00000000']], 'time': '2021-05-20T03:56:17.556511Z'}
{'type': 'l2update', 'product_id': 'BTC-USD', 'changes': [['sell', '38362.58', '0.05124923']], 'time': '2021-05-20T03:56:17.558119Z'}
{'type': 'l2update', 'product_id': 'BTC-USD', 'changes': [['buy', '38309.90', '0.00000000']], 'time': '2021-05-20T03:56:17.558674Z'}
{'type': 'l2update', 'product_id': 'BTC-USD', 'changes': [['sell', '38499.15', '0.01000000']], 'time': '2021-05-20T03:56:17.560886Z'}
{'type': 'l2update', 'product_id': 'BTC-USD', 'changes': [['sell', '38481.55', '0.01000000']], 'time': '2021-05-20T03:56:17.564798Z'}
{'type': 'l2update', 'product_id': 'BTC-USD', 'changes': [['buy', '38308.41', '0.40260000']], 'time': '2021-05-20T03:56:17.568685Z'}
{'type': 'l2update', 'product_id': 'BTC-USD', 'changes': [['buy', '38308.41', '0.00000000']], 'time': '2021-05-20T03:56:17.572342Z'}
{'type': 'l2update', 'product_id': 'BTC-USD', 'changes': [['buy', '38323.97', '0.00000000']], 'time': '2021-05-20T03:56:17.574417Z'}
{'type': 'l2update', 'product_id': 'BTC-USD', 'changes': [['sell', '38489.12', '0.00000000']], 'time': '2021-05-20T03:56:17.575366Z'}
{'type': 'l2update', 'product_id': 'BTC-USD', 'changes': [['sell', '38354.74', '0.00000000']], 'time': '2021-05-20T03:56:17.580540Z'}
{'type': 'l2update', 'product_id': 'BTC-USD', 'changes': [['buy', '38306.63', '0.04332483']], 'time': '2021-05-20T03:56:17.580599Z'}
{'type': 'l2update', 'product_id': 'BTC-USD', 'changes': [['sell', '38350.12', '0.05048787']], 'time': '2021-05-20T03:56:17.580599Z'}
{'type': 'l2update', 'product_id': 'BTC-USD', 'changes': [['sell', '38514.78', '0.01000000']], 'time': '2021-05-20T03:56:17.587837Z'}
{'type': 'l2update', 'product_id': 'BTC-USD', 'changes': [['buy', '38320.91', '0.00000000']], 'time': '2021-05-20T03:56:17.591456Z'}
{'type': 'l2update', 'product_id': 'BTC-USD', 'changes': [['sell', '38344.64', '0.50000000']], 'time': '2021-05-20T03:56:17.595351Z'}
{'type': 'l2update', 'product_id': 'BTC-USD', 'changes': [['buy', '38324.08', '0.59116555']], 'time': '2021-05-20T03:56:17.595564Z'}
{'type': 'l2update', 'product_id': 'BTC-USD', 'changes': [['buy', '38324.07', '0.00000000']], 'time': '2021-05-20T03:56:17.601906Z'}
{'type': 'l2update', 'product_id': 'BTC-USD', 'changes': [['buy', '38324.01', '0.84700000']], 'time': '2021-05-20T03:56:17.614463Z'}
{'type': 'l2update', 'product_id': 'BTC-USD', 'changes': [['sell', '38665.02', '0.00000000']], 'time': '2021-05-20T03:56:17.617233Z'}
{'type': 'l2update', 'product_id': 'BTC-USD', 'changes': [['sell', '38469.43', '0.00000000']], 'time': '2021-05-20T03:56:17.617255Z'}
{'type': 'l2update', 'product_id': 'BTC-USD', 'changes': [['buy', '38306.63', '0.00000000']], 'time': '2021-05-20T03:56:17.619909Z'}
{'type': 'l2update', 'product_id': 'BTC-USD', 'changes': [['sell', '38499.15', '0.00000000']], 'time': '2021-05-20T03:56:17.620781Z'}
{'type': 'l2update', 'product_id': 'BTC-USD', 'changes': [['sell', '38649.94', '0.01000000']], 'time': '2021-05-20T03:56:17.626883Z'}
{'type': 'l2update', 'product_id': 'BTC-USD', 'changes': [['sell', '38514.78', '0.00000000']], 'time': '2021-05-20T03:56:17.630570Z'}
{'type': 'l2update', 'product_id': 'BTC-USD', 'changes': [['sell', '38485.98', '0.01000000']], 'time': '2021-05-20T03:56:17.631082Z'}
{'type': 'l2update', 'product_id': 'BTC-USD', 'changes': [['sell', '38455.66', '0.01300198']], 'time': '2021-05-20T03:56:17.638754Z'}
{'type': 'l2update', 'product_id': 'BTC-USD', 'changes': [['sell', '38366.59', '0.42590000']], 'time': '2021-05-20T03:56:17.638806Z'}
{'type': 'l2update', 'product_id': 'BTC-USD', 'changes': [['sell', '38485.98', '0.00000000']], 'time': '2021-05-20T03:56:17.645347Z'}
{'type': 'l2update', 'product_id': 'BTC-USD', 'changes': [['sell', '38489.10', '0.01000000']], 'time': '2021-05-20T03:56:17.645974Z'}
{'type': 'l2update', 'product_id': 'BTC-USD', 'changes': [['sell', '38499.15', '0.01000000']], 'time': '2021-05-20T03:56:17.655636Z'}
{'type': 'l2update', 'product_id': 'BTC-USD', 'changes': [['sell', '38366.58', '0.06497884']], 'time': '2021-05-20T03:56:17.656125Z'}
{'type': 'l2update', 'product_id': 'BTC-USD', 'changes': [['sell', '38399.21', '0.00000000']], 'time': '2021-05-20T03:56:17.658825Z'}
{'type': 'l2update', 'product_id': 'BTC-USD', 'changes': [['buy', '38301.90', '0.46868909']], 'time': '2021-05-20T03:56:17.659957Z'}
{'type': 'l2update', 'product_id': 'BTC-USD', 'changes': [['buy', '38308.40', '0.04086191']], 'time': '2021-05-20T03:56:17.660071Z'}
{'type': 'l2update', 'product_id': 'BTC-USD', 'changes': [['sell', '38366.91', '0.00000000']], 'time': '2021-05-20T03:56:17.660879Z'}
{'type': 'l2update', 'product_id': 'BTC-USD', 'changes': [['sell', '38377.75', '0.00000000']], 'time': '2021-05-20T03:56:17.663538Z'}
{'type': 'l2update', 'product_id': 'BTC-USD', 'changes': [['buy', '38307.91', '0.43540000']], 'time': '2021-05-20T03:56:17.664223Z'}
{'type': 'l2update', 'product_id': 'BTC-USD', 'changes': [['sell', '38378.42', '0.00000000']], 'time': '2021-05-20T03:56:17.664788Z'}
{'type': 'l2update', 'product_id': 'BTC-USD', 'changes': [['buy', '38295.33', '0.00000000']], 'time': '2021-05-20T03:56:17.666994Z'}
{'type': 'l2update', 'product_id': 'BTC-USD', 'changes': [['buy', '37535.86', '0.00000000']], 'time': '2021-05-20T03:56:17.672673Z'}
{'type': 'l2update', 'product_id': 'BTC-USD', 'changes': [['sell', '38372.47', '0.05000000']], 'time': '2021-05-20T03:56:17.676538Z'}
{'type': 'l2update', 'product_id': 'BTC-USD', 'changes': [['sell', '39137.38', '0.06933790']], 'time': '2021-05-20T03:56:17.684338Z'}
{'type': 'l2update', 'product_id': 'BTC-USD', 'changes': [['sell', '38362.58', '0.00000000']], 'time': '2021-05-20T03:56:17.690032Z'}
{'type': 'l2update', 'product_id': 'BTC-USD', 'changes': [['buy', '38344.12', '0.00300000']], 'time': '2021-05-20T03:56:17.701821Z'}
{'type': 'l2update', 'product_id': 'BTC-USD', 'changes': [['sell', '38383.75', '0.00000000']], 'time': '2021-05-20T03:56:17.715531Z'}
{'type': 'l2update', 'product_id': 'BTC-USD', 'changes': [['buy', '38311.85', '0.00000000']], 'time': '2021-05-20T03:56:17.719720Z'}
{'type': 'l2update', 'product_id': 'BTC-USD', 'changes': [['sell', '38489.10', '0.00000000']], 'time': '2021-05-20T03:56:17.721100Z'}
{'type': 'l2update', 'product_id': 'BTC-USD', 'changes': [['sell', '38350.12', '0.00000000']], 'time': '2021-05-20T03:56:17.721201Z'}
{'type': 'l2update', 'product_id': 'BTC-USD', 'changes': [['buy', '38307.91', '0.00000000']], 'time': '2021-05-20T03:56:17.721455Z'}
{'type': 'l2update', 'product_id': 'BTC-USD', 'changes': [['buy', '38307.92', '0.06497884']], 'time': '2021-05-20T03:56:17.721654Z'}
{'type': 'l2update', 'product_id': 'BTC-USD', 'changes': [['sell', '38649.94', '0.00000000']], 'time': '2021-05-20T03:56:17.723950Z'}
{'type': 'l2update', 'product_id': 'BTC-USD', 'changes': [['buy', '38307.92', '0.00000000']], 'time': '2021-05-20T03:56:17.731648Z'}
{'type': 'l2update', 'product_id': 'BTC-USD', 'changes': [['sell', '38514.85', '0.01000000']], 'time': '2021-05-20T03:56:17.732602Z'}
{'type': 'l2update', 'product_id': 'BTC-USD', 'changes': [['buy', '37535.87', '0.06353140']], 'time': '2021-05-20T03:56:17.732747Z'}
{'type': 'l2update', 'product_id': 'BTC-USD', 'changes': [['buy', '38310.34', '0.06497884']], 'time': '2021-05-20T03:56:17.732889Z'}
{'type': 'l2update', 'product_id': 'BTC-USD', 'changes': [['sell', '39137.38', '0.00000000']], 'time': '2021-05-20T03:56:17.740124Z'}
{'type': 'l2update', 'product_id': 'BTC-USD', 'changes': [['buy', '38310.34', '0.00000000']], 'time': '2021-05-20T03:56:17.741548Z'}
{'type': 'l2update', 'product_id': 'BTC-USD', 'changes': [['sell', '38351.59', '0.05261051']], 'time': '2021-05-20T03:56:17.744193Z'}
{'type': 'l2update', 'product_id': 'BTC-USD', 'changes': [['sell', '38591.82', '0.01000000']], 'time': '2021-05-20T03:56:17.744476Z'}
{'type': 'l2update', 'product_id': 'BTC-USD', 'changes': [['buy', '38310.71', '0.06497884']], 'time': '2021-05-20T03:56:17.748152Z'}
{'type': 'l2update', 'product_id': 'BTC-USD', 'changes': [['sell', '38591.82', '0.00000000']], 'time': '2021-05-20T03:56:17.750328Z'}
{'type': 'l2update', 'product_id': 'BTC-USD', 'changes': [['sell', '38518.83', '0.01000000']], 'time': '2021-05-20T03:56:17.761103Z'}
{'type': 'l2update', 'product_id': 'BTC-USD', 'changes': [['sell', '38349.56', '1.15200000']], 'time': '2021-05-20T03:56:17.769171Z'}
{'type': 'l2update', 'product_id': 'BTC-USD', 'changes': [['sell', '38499.15', '0.00000000']], 'time': '2021-05-20T03:56:17.788583Z'}
{'type': 'l2update', 'product_id': 'BTC-USD', 'changes': [['sell', '38485.98', '0.01000000']], 'time': '2021-05-20T03:56:17.799504Z'}
{'type': 'l2update', 'product_id': 'BTC-USD', 'changes': [['sell', '38485.98', '0.00000000']], 'time': '2021-05-20T03:56:17.808227Z'}
{'type': 'l2update', 'product_id': 'BTC-USD', 'changes': [['sell', '38514.85', '0.00000000']], 'time': '2021-05-20T03:56:17.808507Z'}
{'type': 'l2update', 'product_id': 'BTC-USD', 'changes': [['buy', '38309.85', '0.40480000']], 'time': '2021-05-20T03:56:17.811000Z'}
{'type': 'l2update', 'product_id': 'BTC-USD', 'changes': [['buy', '38328.02', '0.00000000']], 'time': '2021-05-20T03:56:17.811484Z'}
{'type': 'l2update', 'product_id': 'BTC-USD', 'changes': [['buy', '38170.39', '0.04860973']], 'time': '2021-05-20T03:56:17.815025Z'}
{'type': 'l2update', 'product_id': 'BTC-USD', 'changes': [['sell', '38344.13', '0.26518141']], 'time': '2021-05-20T03:56:17.816352Z'}
{'type': 'l2update', 'product_id': 'BTC-USD', 'changes': [['sell', '38489.09', '0.01000000']], 'time': '2021-05-20T03:56:17.820202Z'}
{'type': 'l2update', 'product_id': 'BTC-USD', 'changes': [['sell', '38513.03', '0.01000000']], 'time': '2021-05-20T03:56:17.820439Z'}
{'type': 'l2update', 'product_id': 'BTC-USD', 'changes': [['buy', '38265.90', '0.07700000']], 'time': '2021-05-20T03:56:17.824721Z'}
{'type': 'l2update', 'product_id': 'BTC-USD', 'changes': [['buy', '32100.00', '4.94982202']], 'time': '2021-05-20T03:56:17.853850Z'}
{'type': 'l2update', 'product_id': 'BTC-USD', 'changes': [['buy', '38326.87', '0.84700000']], 'time': '2021-05-20T03:56:17.872399Z'}
{'type': 'l2update', 'product_id': 'BTC-USD', 'changes': [['buy', '38324.08', '0.00000000']], 'time': '2021-05-20T03:56:17.878753Z'}
{'type': 'l2update', 'product_id': 'BTC-USD', 'changes': [['buy', '38323.96', '0.84700000']], 'time': '2021-05-20T03:56:17.884928Z'}
{'type': 'l2update', 'product_id': 'BTC-USD', 'changes': [['buy', '38323.03', '0.52182567']], 'time': '2021-05-20T03:56:17.900255Z'}
{'type': 'l2update', 'product_id': 'BTC-USD', 'changes': [['buy', '38326.88', '0.59116555']], 'time': '2021-05-20T03:56:17.900543Z'}
{'type': 'l2update', 'product_id': 'BTC-USD', 'changes': [['sell', '38513.03', '0.00000000']], 'time': '2021-05-20T03:56:17.906739Z'}
{'type': 'l2update', 'product_id': 'BTC-USD', 'changes': [['buy', '38313.58', '0.52184356']], 'time': '2021-05-20T03:56:17.913470Z'}
{'type': 'l2update', 'product_id': 'BTC-USD', 'changes': [['sell', '38528.09', '0.01000000']], 'time': '2021-05-20T03:56:17.918566Z'}
{'type': 'l2update', 'product_id': 'BTC-USD', 'changes': [['buy', '38328.34', '0.01362945']], 'time': '2021-05-20T03:56:17.921171Z'}
{'type': 'l2update', 'product_id': 'BTC-USD', 'changes': [['buy', '38310.71', '0.00000000']], 'time': '2021-05-20T03:56:17.922428Z'}
{'type': 'l2update', 'product_id': 'BTC-USD', 'changes': [['buy', '38307.70', '0.78273851']], 'time': '2021-05-20T03:56:17.926507Z'}
{'type': 'l2update', 'product_id': 'BTC-USD', 'changes': [['buy', '38313.59', '0.06497884']], 'time': '2021-05-20T03:56:17.931510Z'}
{'type': 'l2update', 'product_id': 'BTC-USD', 'changes': [['sell', '38345.65', '0.00000000']], 'time': '2021-05-20T03:56:17.947670Z'}
{'type': 'l2update', 'product_id': 'BTC-USD', 'changes': [['sell', '38385.87', '0.05454844']], 'time': '2021-05-20T03:56:17.950447Z'}
{'type': 'l2update', 'product_id': 'BTC-USD', 'changes': [['sell', '38489.09', '0.00000000']], 'time': '2021-05-20T03:56:17.952194Z'}
{'type': 'l2update', 'product_id': 'BTC-USD', 'changes': [['sell', '38457.12', '0.00000000']], 'time': '2021-05-20T03:56:17.957187Z'}
{'type': 'l2update', 'product_id': 'BTC-USD', 'changes': [['sell', '38523.92', '0.01000000']], 'time': '2021-05-20T03:56:17.964845Z'}
{'type': 'l2update', 'product_id': 'BTC-USD', 'changes': [['sell', '38480.86', '0.01000000']], 'time': '2021-05-20T03:56:17.970720Z'}
{'type': 'l2update', 'product_id': 'BTC-USD', 'changes': [['buy', '37484.81', '0.02090000']], 'time': '2021-05-20T03:56:17.978677Z'}
{'type': 'l2update', 'product_id': 'BTC-USD', 'changes': [['buy', '36776.89', '0.02960000']], 'time': '2021-05-20T03:56:17.978677Z'}
{'type': 'l2update', 'product_id': 'BTC-USD', 'changes': [['sell', '38344.13', '1.49865397']], 'time': '2021-05-20T03:56:17.979198Z'}
{'type': 'l2update', 'product_id': 'BTC-USD', 'changes': [['buy', '38313.59', '0.00000000']], 'time': '2021-05-20T03:56:17.989104Z'}
{'type': 'l2update', 'product_id': 'BTC-USD', 'changes': [['buy', '38174.68', '0.00000000']], 'time': '2021-05-20T03:56:17.994754Z'}
{'type': 'l2update', 'product_id': 'BTC-USD', 'changes': [['buy', '38341.42', '0.00948082']], 'time': '2021-05-20T03:56:17.995705Z'}
{'type': 'l2update', 'product_id': 'BTC-USD', 'changes': [['buy', '38310.71', '0.06497884']], 'time': '2021-05-20T03:56:17.999849Z'}
{'type': 'l2update', 'product_id': 'BTC-USD', 'changes': [['sell', '38347.87', '0.01065798']], 'time': '2021-05-20T03:56:17.999868Z'}
{'type': 'l2update', 'product_id': 'BTC-USD', 'changes': [['buy', '38323.96', '1.36800000']], 'time': '2021-05-20T03:56:18.011357Z'}
{'type': 'l2update', 'product_id': 'BTC-USD', 'changes': [['buy', '38309.85', '0.00000000']], 'time': '2021-05-20T03:56:18.013375Z'}
{'type': 'l2update', 'product_id': 'BTC-USD', 'changes': [['buy', '38311.98', '0.41910000']], 'time': '2021-05-20T03:56:18.023413Z'}
{'type': 'l2update', 'product_id': 'BTC-USD', 'changes': [['buy', '38311.98', '0.00000000']], 'time': '2021-05-20T03:56:18.027080Z'}
{'type': 'l2update', 'product_id': 'BTC-USD', 'changes': [['buy', '38310.71', '0.00000000']], 'time': '2021-05-20T03:56:18.029947Z'}
{'type': 'l2update', 'product_id': 'BTC-USD', 'changes': [['buy', '38280.50', '0.00000000']], 'time': '2021-05-20T03:56:18.038899Z'}
{'type': 'l2update', 'product_id': 'BTC-USD', 'changes': [['buy', '38311.99', '0.06497884']], 'time': '2021-05-20T03:56:18.039832Z'}
{'type': 'l2update', 'product_id': 'BTC-USD', 'changes': [['buy', '38341.42', '0.00000000']], 'time': '2021-05-20T03:56:18.041966Z'}
{'type': 'l2update', 'product_id': 'BTC-USD', 'changes': [['sell', '38498.46', '0.00000000']], 'time': '2021-05-20T03:56:18.047472Z'}
{'type': 'l2update', 'product_id': 'BTC-USD', 'changes': [['buy', '38284.49', '0.10000000']], 'time': '2021-05-20T03:56:18.048587Z'}
{'type': 'l2update', 'product_id': 'BTC-USD', 'changes': [['buy', '38315.16', '0.00000000']], 'time': '2021-05-20T03:56:18.053308Z'}
{'type': 'l2update', 'product_id': 'BTC-USD', 'changes': [['buy', '38322.17', '0.00000000']], 'time': '2021-05-20T03:56:18.062395Z'}
{'type': 'l2update', 'product_id': 'BTC-USD', 'changes': [['sell', '38472.11', '0.01000000']], 'time': '2021-05-20T03:56:18.067548Z'}
{'type': 'l2update', 'product_id': 'BTC-USD', 'changes': [['buy', '37469.36', '0.00000000']], 'time': '2021-05-20T03:56:18.068004Z'}
{'type': 'l2update', 'product_id': 'BTC-USD', 'changes': [['buy', '37469.35', '0.07280000']], 'time': '2021-05-20T03:56:18.068004Z'}
{'type': 'l2update', 'product_id': 'BTC-USD', 'changes': [['sell', '39361.09', '0.00000000']], 'time': '2021-05-20T03:56:18.068004Z'}
{'type': 'l2update', 'product_id': 'BTC-USD', 'changes': [['buy', '38326.89', '1.07340561']], 'time': '2021-05-20T03:56:18.075017Z'}
{'type': 'l2update', 'product_id': 'BTC-USD', 'changes': [['buy', '37500.01', '0.07260000']], 'time': '2021-05-20T03:56:18.075286Z'}
{'type': 'l2update', 'product_id': 'BTC-USD', 'changes': [['sell', '39449.99', '0.05420000']], 'time': '2021-05-20T03:56:18.075286Z'}
{'type': 'l2update', 'product_id': 'BTC-USD', 'changes': [['buy', '37500.02', '0.00360000']], 'time': '2021-05-20T03:56:18.075286Z'}
{'type': 'l2update', 'product_id': 'BTC-USD', 'changes': [['buy', '38326.88', '0.00000000']], 'time': '2021-05-20T03:56:18.080403Z'}
{'type': 'l2update', 'product_id': 'BTC-USD', 'changes': [['sell', '38518.83', '0.00000000']], 'time': '2021-05-20T03:56:18.082677Z'}
{'type': 'l2update', 'product_id': 'BTC-USD', 'changes': [['sell', '38503.79', '0.01000000']], 'time': '2021-05-20T03:56:18.095532Z'}
{'type': 'l2update', 'product_id': 'BTC-USD', 'changes': [['buy', '38326.89', '0.00000000']], 'time': '2021-05-20T03:56:18.099663Z'}
{'type': 'l2update', 'product_id': 'BTC-USD', 'changes': [['sell', '38503.79', '0.00000000']], 'time': '2021-05-20T03:56:18.102643Z'}
{'type': 'l2update', 'product_id': 'BTC-USD', 'changes': [['buy', '38326.90', '0.59116555']], 'time': '2021-05-20T03:56:18.103101Z'}
{'type': 'l2update', 'product_id': 'BTC-USD', 'changes': [['sell', '38472.11', '0.00000000']], 'time': '2021-05-20T03:56:18.104258Z'}
{'type': 'l2update', 'product_id': 'BTC-USD', 'changes': [['buy', '38311.17', '0.00000000']], 'time': '2021-05-20T03:56:18.114256Z'}
{'type': 'l2update', 'product_id': 'BTC-USD', 'changes': [['sell', '38528.09', '0.00000000']], 'time': '2021-05-20T03:56:18.114735Z'}
{'type': 'l2update', 'product_id': 'BTC-USD', 'changes': [['buy', '38312.53', '0.40650000']], 'time': '2021-05-20T03:56:18.115325Z'}
{'type': 'l2update', 'product_id': 'BTC-USD', 'changes': [['sell', '38488.75', '0.01000000']], 'time': '2021-05-20T03:56:18.115438Z'}
{'type': 'l2update', 'product_id': 'BTC-USD', 'changes': [['buy', '30000.00', '497.94508819']], 'time': '2021-05-20T03:56:18.116127Z'}
{'type': 'l2update', 'product_id': 'BTC-USD', 'changes': [['buy', '38324.72', '1.07340561']], 'time': '2021-05-20T03:56:18.119226Z'}
{'type': 'l2update', 'product_id': 'BTC-USD', 'changes': [['sell', '38480.86', '0.00000000']], 'time': '2021-05-20T03:56:18.126092Z'}
{'type': 'l2update', 'product_id': 'BTC-USD', 'changes': [['sell', '38490.49', '0.01000000']], 'time': '2021-05-20T03:56:18.126789Z'}
{'type': 'l2update', 'product_id': 'BTC-USD', 'changes': [['sell', '38514.91', '0.01000000']], 'time': '2021-05-20T03:56:18.127016Z'}
{'type': 'l2update', 'product_id': 'BTC-USD', 'changes': [['buy', '38314.00', '0.02400000']], 'time': '2021-05-20T03:56:18.127092Z'}
{'type': 'l2update', 'product_id': 'BTC-USD', 'changes': [['buy', '38312.19', '0.00000000']], 'time': '2021-05-20T03:56:18.133891Z'}
{'type': 'l2update', 'product_id': 'BTC-USD', 'changes': [['sell', '38494.75', '0.01000000']], 'time': '2021-05-20T03:56:18.137369Z'}
{'type': 'l2update', 'product_id': 'BTC-USD', 'changes': [['buy', '38313.00', '0.00000000']], 'time': '2021-05-20T03:56:18.138323Z'}
{'type': 'l2update', 'product_id': 'BTC-USD', 'changes': [['sell', '38344.13', '0.26518141']], 'time': '2021-05-20T03:56:18.146825Z'}
{'type': 'l2update', 'product_id': 'BTC-USD', 'changes': [['buy', '38316.28', '0.02400000']], 'time': '2021-05-20T03:56:18.154624Z'}
{'type': 'l2update', 'product_id': 'BTC-USD', 'changes': [['buy', '38315.47', '0.02400000']], 'time': '2021-05-20T03:56:18.154624Z'}
{'type': 'l2update', 'product_id': 'BTC-USD', 'changes': [['buy', '38315.47', '0.00000000']], 'time': '2021-05-20T03:56:18.161137Z'}
{'type': 'l2update', 'product_id': 'BTC-USD', 'changes': [['buy', '38314.00', '0.00000000']], 'time': '2021-05-20T03:56:18.161137Z'}
{'type': 'l2update', 'product_id': 'BTC-USD', 'changes': [['buy', '38311.99', '0.00000000']], 'time': '2021-05-20T03:56:18.163886Z'}
{'type': 'l2update', 'product_id': 'BTC-USD', 'changes': [['sell', '38514.91', '0.00000000']], 'time': '2021-05-20T03:56:18.163918Z'}
{'type': 'l2update', 'product_id': 'BTC-USD', 'changes': [['buy', '38313.59', '0.06497884']], 'time': '2021-05-20T03:56:18.174772Z'}
{'type': 'l2update', 'product_id': 'BTC-USD', 'changes': [['sell', '38492.59', '0.00000000']], 'time': '2021-05-20T03:56:18.174938Z'}
{'type': 'l2update', 'product_id': 'BTC-USD', 'changes': [['sell', '38523.92', '0.00000000']], 'time': '2021-05-20T03:56:18.178676Z'}
{'type': 'l2update', 'product_id': 'BTC-USD', 'changes': [['buy', '38310.33', '0.14000000']], 'time': '2021-05-20T03:56:18.179417Z'}
{'type': 'l2update', 'product_id': 'BTC-USD', 'changes': [['sell', '38528.09', '0.01000000']], 'time': '2021-05-20T03:56:18.181557Z'}
{'type': 'l2update', 'product_id': 'BTC-USD', 'changes': [['buy', '38310.33', '0.12000000']], 'time': '2021-05-20T03:56:18.182557Z'}
{'type': 'l2update', 'product_id': 'BTC-USD', 'changes': [['buy', '38322.16', '0.00000000']], 'time': '2021-05-20T03:56:18.182569Z'}
{'type': 'l2update', 'product_id': 'BTC-USD', 'changes': [['sell', '38450.00', '1.78518201']], 'time': '2021-05-20T03:56:18.187375Z'}
{'type': 'l2update', 'product_id': 'BTC-USD', 'changes': [['buy', '38269.00', '0.07700000']], 'time': '2021-05-20T03:56:18.188147Z'}
{'type': 'l2update', 'product_id': 'BTC-USD', 'changes': [['sell', '38344.13', '0.25879211']], 'time': '2021-05-20T03:56:18.188365Z'}
{'type': 'l2update', 'product_id': 'BTC-USD', 'changes': [['sell', '38510.14', '0.01757074']], 'time': '2021-05-20T03:56:18.188503Z'}
{'type': 'l2update', 'product_id': 'BTC-USD', 'changes': [['buy', '38310.33', '0.09000000']], 'time': '2021-05-20T03:56:18.188677Z'}
{'type': 'l2update', 'product_id': 'BTC-USD', 'changes': [['buy', '38310.33', '0.05000000']], 'time': '2021-05-20T03:56:18.194816Z'}
{'type': 'l2update', 'product_id': 'BTC-USD', 'changes': [['buy', '38310.33', '0.00000000']], 'time': '2021-05-20T03:56:18.201626Z'}
{'type': 'l2update', 'product_id': 'BTC-USD', 'changes': [['buy', '38165.67', '0.00000000']], 'time': '2021-05-20T03:56:18.201690Z'}
{'type': 'l2update', 'product_id': 'BTC-USD', 'changes': [['sell', '38455.59', '0.02946550']], 'time': '2021-05-20T03:56:18.203835Z'}
{'type': 'l2update', 'product_id': 'BTC-USD', 'changes': [['sell', '38511.76', '0.01000000']], 'time': '2021-05-20T03:56:18.210437Z'}
{'type': 'l2update', 'product_id': 'BTC-USD', 'changes': [['buy', '38302.43', '0.01000000']], 'time': '2021-05-20T03:56:18.214342Z'}
{'type': 'l2update', 'product_id': 'BTC-USD', 'changes': [['sell', '43100.00', '1.09530000']], 'time': '2021-05-20T03:56:18.215436Z'}
{'type': 'l2update', 'product_id': 'BTC-USD', 'changes': [['buy', '38249.31', '0.00000000']], 'time': '2021-05-20T03:56:18.219229Z'}
{'type': 'l2update', 'product_id': 'BTC-USD', 'changes': [['buy', '38325.94', '0.07091463']], 'time': '2021-05-20T03:56:18.222918Z'}
{'type': 'l2update', 'product_id': 'BTC-USD', 'changes': [['sell', '38455.59', '0.00000000']], 'time': '2021-05-20T03:56:18.224630Z'}
{'type': 'l2update', 'product_id': 'BTC-USD', 'changes': [['buy', '38317.97', '0.02400000']], 'time': '2021-05-20T03:56:18.226693Z'}
{'type': 'l2update', 'product_id': 'BTC-USD', 'changes': [['buy', '38317.17', '0.02400000']], 'time': '2021-05-20T03:56:18.226693Z'}
{'type': 'l2update', 'product_id': 'BTC-USD', 'changes': [['buy', '38301.14', '0.02000000']], 'time': '2021-05-20T03:56:18.226911Z'}
{'type': 'l2update', 'product_id': 'BTC-USD', 'changes': [['sell', '43100.00', '3.85840000']], 'time': '2021-05-20T03:56:18.231496Z'}
{'type': 'l2update', 'product_id': 'BTC-USD', 'changes': [['sell', '38511.76', '0.00000000']], 'time': '2021-05-20T03:56:18.236863Z'}
{'type': 'l2update', 'product_id': 'BTC-USD', 'changes': [['buy', '38261.19', '0.01000000']], 'time': '2021-05-20T03:56:18.240174Z'}
{'type': 'l2update', 'product_id': 'BTC-USD', 'changes': [['buy', '38300.72', '0.03000000']], 'time': '2021-05-20T03:56:18.240261Z'}
{'type': 'l2update', 'product_id': 'BTC-USD', 'changes': [['buy', '37535.87', '0.00000000']], 'time': '2021-05-20T03:56:18.246533Z'}
{'type': 'l2update', 'product_id': 'BTC-USD', 'changes': [['sell', '38435.37', '0.02948100']], 'time': '2021-05-20T03:56:18.247006Z'}
{'type': 'l2update', 'product_id': 'BTC-USD', 'changes': [['buy', '38300.72', '0.07000000']], 'time': '2021-05-20T03:56:18.250637Z'}
{'type': 'l2update', 'product_id': 'BTC-USD', 'changes': [['sell', '38499.86', '0.01000000']], 'time': '2021-05-20T03:56:18.250678Z'}
{'type': 'l2update', 'product_id': 'BTC-USD', 'changes': [['sell', '38528.09', '0.00000000']], 'time': '2021-05-20T03:56:18.258102Z'}
{'type': 'l2update', 'product_id': 'BTC-USD', 'changes': [['sell', '39133.90', '0.06704216']], 'time': '2021-05-20T03:56:18.258844Z'}
{'type': 'l2update', 'product_id': 'BTC-USD', 'changes': [['sell', '38490.49', '0.00000000']], 'time': '2021-05-20T03:56:18.261524Z'}
{'type': 'l2update', 'product_id': 'BTC-USD', 'changes': [['buy', '38152.40', '0.00600000']], 'time': '2021-05-20T03:56:18.262578Z'}
{'type': 'l2update', 'product_id': 'BTC-USD', 'changes': [['buy', '38300.72', '0.12000000']], 'time': '2021-05-20T03:56:18.262643Z'}
{'type': 'l2update', 'product_id': 'BTC-USD', 'changes': [['sell', '38581.34', '0.01970000']], 'time': '2021-05-20T03:56:18.262779Z'}
{'type': 'l2update', 'product_id': 'BTC-USD', 'changes': [['sell', '38514.91', '0.01000000']], 'time': '2021-05-20T03:56:18.271023Z'}
{'type': 'l2update', 'product_id': 'BTC-USD', 'changes': [['sell', '38344.13', '1.76636283']], 'time': '2021-05-20T03:56:18.280982Z'}
{'type': 'l2update', 'product_id': 'BTC-USD', 'changes': [['sell', '38472.11', '0.01000000']], 'time': '2021-05-20T03:56:18.283276Z'}
{'type': 'l2update', 'product_id': 'BTC-USD', 'changes': [['sell', '38514.91', '0.00000000']], 'time': '2021-05-20T03:56:18.286427Z'}
{'type': 'l2update', 'product_id': 'BTC-USD', 'changes': [['buy', '38269.00', '0.00000000']], 'time': '2021-05-20T03:56:18.287485Z'}
{'type': 'l2update', 'product_id': 'BTC-USD', 'changes': [['buy', '38313.59', '0.00000000']], 'time': '2021-05-20T03:56:18.295297Z'}
{'type': 'l2update', 'product_id': 'BTC-USD', 'changes': [['sell', '38528.09', '0.01000000']], 'time': '2021-05-20T03:56:18.300457Z'}
{'type': 'l2update', 'product_id': 'BTC-USD', 'changes': [['buy', '38310.71', '0.06497884']], 'time': '2021-05-20T03:56:18.303798Z'}
{'type': 'l2update', 'product_id': 'BTC-USD', 'changes': [['buy', '38317.97', '0.00000000']], 'time': '2021-05-20T03:56:18.304413Z'}
{'type': 'l2update', 'product_id': 'BTC-USD', 'changes': [['buy', '38317.17', '0.00000000']], 'time': '2021-05-20T03:56:18.304413Z'}
{'type': 'l2update', 'product_id': 'BTC-USD', 'changes': [['buy', '38315.14', '0.02400000']], 'time': '2021-05-20T03:56:18.320407Z'}
{'type': 'l2update', 'product_id': 'BTC-USD', 'changes': [['buy', '38314.33', '0.02400000']], 'time': '2021-05-20T03:56:18.320407Z'}
{'type': 'l2update', 'product_id': 'BTC-USD', 'changes': [['buy', '38312.53', '0.00000000']], 'time': '2021-05-20T03:56:18.360853Z'}
{'type': 'l2update', 'product_id': 'BTC-USD', 'changes': [['sell', '38366.59', '0.00000000']], 'time': '2021-05-20T03:56:18.365317Z'}
{'type': 'l2update', 'product_id': 'BTC-USD', 'changes': [['sell', '38434.47', '0.00000000']], 'time': '2021-05-20T03:56:18.366182Z'}
{'type': 'l2update', 'product_id': 'BTC-USD', 'changes': [['sell', '38344.13', '0.25879211']], 'time': '2021-05-20T03:56:18.371952Z'}
{'type': 'l2update', 'product_id': 'BTC-USD', 'changes': [['buy', '38316.44', '0.43710000']], 'time': '2021-05-20T03:56:18.376504Z'}
{'type': 'l2update', 'product_id': 'BTC-USD', 'changes': [['sell', '38363.55', '0.40070000']], 'time': '2021-05-20T03:56:18.384976Z'}
{'type': 'l2update', 'product_id': 'BTC-USD', 'changes': [['buy', '37500.01', '0.07270000']], 'time': '2021-05-20T03:56:18.388552Z'}
{'type': 'l2update', 'product_id': 'BTC-USD', 'changes': [['buy', '38316.44', '0.00000000']], 'time': '2021-05-20T03:56:18.390374Z'}
{'type': 'l2update', 'product_id': 'BTC-USD', 'changes': [['sell', '38363.55', '0.00000000']], 'time': '2021-05-20T03:56:18.393522Z'}
{'type': 'l2update', 'product_id': 'BTC-USD', 'changes': [['sell', '38472.11', '0.00000000']], 'time': '2021-05-20T03:56:18.408339Z'}
{'type': 'l2update', 'product_id': 'BTC-USD', 'changes': [['sell', '38490.49', '0.01000000']], 'time': '2021-05-20T03:56:18.432063Z'}
{'type': 'l2update', 'product_id': 'BTC-USD', 'changes': [['sell', '38481.55', '0.00000000']], 'time': '2021-05-20T03:56:18.454145Z'}
{'type': 'l2update', 'product_id': 'BTC-USD', 'changes': [['sell', '38501.40', '0.01000000']], 'time': '2021-05-20T03:56:18.465423Z'}
{'type': 'l2update', 'product_id': 'BTC-USD', 'changes': [['buy', '38315.90', '0.43030000']], 'time': '2021-05-20T03:56:18.480404Z'}
{'type': 'l2update', 'product_id': 'BTC-USD', 'changes': [['sell', '38363.31', '0.48980000']], 'time': '2021-05-20T03:56:18.492102Z'}
{'type': 'l2update', 'product_id': 'BTC-USD', 'changes': [['sell', '38528.09', '0.00000000']], 'time': '2021-05-20T03:56:18.494811Z'}
{'type': 'l2update', 'product_id': 'BTC-USD', 'changes': [['sell', '38501.40', '0.00000000']], 'time': '2021-05-20T03:56:18.500895Z'}
{'type': 'l2update', 'product_id': 'BTC-USD', 'changes': [['sell', '38514.91', '0.01000000']], 'time': '2021-05-20T03:56:18.507378Z'}
{'type': 'l2update', 'product_id': 'BTC-USD', 'changes': [['sell', '38484.66', '0.01873220']], 'time': '2021-05-20T03:56:18.513275Z'}
{'type': 'l2update', 'product_id': 'BTC-USD', 'changes': [['sell', '38393.32', '0.22600000']], 'time': '2021-05-20T03:56:18.516022Z'}
{'type': 'l2update', 'product_id': 'BTC-USD', 'changes': [['sell', '38514.91', '0.00000000']], 'time': '2021-05-20T03:56:18.517458Z'}
{'type': 'l2update', 'product_id': 'BTC-USD', 'changes': [['sell', '38488.75', '0.00000000']], 'time': '2021-05-20T03:56:18.520699Z'}
{'type': 'l2update', 'product_id': 'BTC-USD', 'changes': [['sell', '38503.79', '0.01000000']], 'time': '2021-05-20T03:56:18.539103Z'}
{'type': 'l2update', 'product_id': 'BTC-USD', 'changes': [['sell', '38528.09', '0.01000000']], 'time': '2021-05-20T03:56:18.539148Z'}
{'type': 'l2update', 'product_id': 'BTC-USD', 'changes': [['buy', '38310.71', '0.00000000']], 'time': '2021-05-20T03:56:18.556917Z'}
{'type': 'l2update', 'product_id': 'BTC-USD', 'changes': [['buy', '38313.59', '0.06368552']], 'time': '2021-05-20T03:56:18.563145Z'}
{'type': 'l2update', 'product_id': 'BTC-USD', 'changes': [['sell', '38503.79', '0.00000000']], 'time': '2021-05-20T03:56:18.570593Z'}
{'type': 'l2update', 'product_id': 'BTC-USD', 'changes': [['buy', '38308.40', '0.00000000']], 'time': '2021-05-20T03:56:18.574359Z'}
{'type': 'l2update', 'product_id': 'BTC-USD', 'changes': [['sell', '38488.75', '0.01000000']], 'time': '2021-05-20T03:56:18.581635Z'}
{'type': 'l2update', 'product_id': 'BTC-USD', 'changes': [['sell', '38435.37', '0.00000000']], 'time': '2021-05-20T03:56:18.592276Z'}
{'type': 'l2update', 'product_id': 'BTC-USD', 'changes': [['sell', '38344.13', '0.25422056']], 'time': '2021-05-20T03:56:18.596835Z'}
{'type': 'l2update', 'product_id': 'BTC-USD', 'changes': [['sell', '38389.09', '0.05444799']], 'time': '2021-05-20T03:56:18.604043Z'}
{'type': 'l2update', 'product_id': 'BTC-USD', 'changes': [['sell', '38453.07', '0.02473900']], 'time': '2021-05-20T03:56:18.607551Z'}
{'type': 'l2update', 'product_id': 'BTC-USD', 'changes': [['buy', '38308.99', '0.04635512']], 'time': '2021-05-20T03:56:18.627696Z'}
{'type': 'l2update', 'product_id': 'BTC-USD', 'changes': [['buy', '38324.72', '0.00000000']], 'time': '2021-05-20T03:56:18.633698Z'}
{'type': 'l2update', 'product_id': 'BTC-USD', 'changes': [['buy', '38326.91', '1.07340561']], 'time': '2021-05-20T03:56:18.647086Z'}
{'type': 'l2update', 'product_id': 'BTC-USD', 'changes': [['buy', '38326.90', '0.00000000']], 'time': '2021-05-20T03:56:18.653593Z'}
{'type': 'l2update', 'product_id': 'BTC-USD', 'changes': [['buy', '37469.35', '0.06630000']], 'time': '2021-05-20T03:56:18.660902Z'}
{'type': 'l2update', 'product_id': 'BTC-USD', 'changes': [['buy', '37654.92', '0.00740000']], 'time': '2021-05-20T03:56:18.660902Z'}
{'type': 'l2update', 'product_id': 'BTC-USD', 'changes': [['buy', '38302.43', '0.00000000']], 'time': '2021-05-20T03:56:18.663243Z'}
{'type': 'l2update', 'product_id': 'BTC-USD', 'changes': [['buy', '38326.92', '0.59116555']], 'time': '2021-05-20T03:56:18.674604Z'}
{'type': 'l2update', 'product_id': 'BTC-USD', 'changes': [['sell', '38528.09', '0.00000000']], 'time': '2021-05-20T03:56:18.708329Z'}
{'type': 'l2update', 'product_id': 'BTC-USD', 'changes': [['sell', '38514.91', '0.01000000']], 'time': '2021-05-20T03:56:18.721186Z'}
{'type': 'l2update', 'product_id': 'BTC-USD', 'changes': [['sell', '38514.91', '0.00000000']], 'time': '2021-05-20T03:56:18.729248Z'}
{'type': 'l2update', 'product_id': 'BTC-USD', 'changes': [['sell', '38344.13', '0.25398679']], 'time': '2021-05-20T03:56:18.729299Z'}
{'type': 'l2update', 'product_id': 'BTC-USD', 'changes': [['sell', '38344.13', '1.49937129']], 'time': '2021-05-20T03:56:18.732649Z'}
{'type': 'l2update', 'product_id': 'BTC-USD', 'changes': [['sell', '38367.68', '0.49389051']], 'time': '2021-05-20T03:56:18.737220Z'}
{'type': 'l2update', 'product_id': 'BTC-USD', 'changes': [['sell', '38344.13', '0.25398679']], 'time': '2021-05-20T03:56:18.738126Z'}
{'type': 'l2update', 'product_id': 'BTC-USD', 'changes': [['sell', '38528.09', '0.01000000']], 'time': '2021-05-20T03:56:18.741079Z'}
{'type': 'l2update', 'product_id': 'BTC-USD', 'changes': [['buy', '38315.90', '0.00000000']], 'time': '2021-05-20T03:56:18.741184Z'}
{'type': 'l2update', 'product_id': 'BTC-USD', 'changes': [['sell', '38367.69', '0.00000000']], 'time': '2021-05-20T03:56:18.746465Z'}
{'type': 'l2update', 'product_id': 'BTC-USD', 'changes': [['sell', '38363.31', '0.00000000']], 'time': '2021-05-20T03:56:18.746739Z'}
{'type': 'l2update', 'product_id': 'BTC-USD', 'changes': [['buy', '38310.71', '0.06368552']], 'time': '2021-05-20T03:56:18.748697Z'}
{'type': 'l2update', 'product_id': 'BTC-USD', 'changes': [['buy', '38313.59', '0.00000000']], 'time': '2021-05-20T03:56:18.754203Z'}
{'type': 'l2update', 'product_id': 'BTC-USD', 'changes': [['buy', '38310.71', '0.00000000']], 'time': '2021-05-20T03:56:18.756177Z'}
{'type': 'l2update', 'product_id': 'BTC-USD', 'changes': [['sell', '38367.67', '0.05000000']], 'time': '2021-05-20T03:56:18.756521Z'}
{'type': 'l2update', 'product_id': 'BTC-USD', 'changes': [['buy', '38313.59', '0.06368552']], 'time': '2021-05-20T03:56:18.768197Z'}
{'type': 'l2update', 'product_id': 'BTC-USD', 'changes': [['buy', '38326.91', '0.00000000']], 'time': '2021-05-20T03:56:18.775347Z'}
{'type': 'l2update', 'product_id': 'BTC-USD', 'changes': [['buy', '38326.92', '0.00000000']], 'time': '2021-05-20T03:56:18.781455Z'}
{'type': 'l2update', 'product_id': 'BTC-USD', 'changes': [['buy', '37535.87', '0.06685162']], 'time': '2021-05-20T03:56:18.782247Z'}
{'type': 'l2update', 'product_id': 'BTC-USD', 'changes': [['sell', '39133.90', '0.00000000']], 'time': '2021-05-20T03:56:18.787775Z'}
{'type': 'l2update', 'product_id': 'BTC-USD', 'changes': [['sell', '38344.13', '1.72222958']], 'time': '2021-05-20T03:56:18.791224Z'}
{'type': 'l2update', 'product_id': 'BTC-USD', 'changes': [['buy', '38325.95', '1.07340561']], 'time': '2021-05-20T03:56:18.795164Z'}
{'type': 'l2update', 'product_id': 'BTC-USD', 'changes': [['buy', '38313.59', '0.00000000']], 'time': '2021-05-20T03:56:18.797909Z'}
{'type': 'l2update', 'product_id': 'BTC-USD', 'changes': [['buy', '38326.88', '0.10000000']], 'time': '2021-05-20T03:56:18.798424Z'}
{'type': 'l2update', 'product_id': 'BTC-USD', 'changes': [['sell', '47836.52', '0.00000000']], 'time': '2021-05-20T03:56:18.801192Z'}
{'type': 'l2update', 'product_id': 'BTC-USD', 'changes': [['buy', '38326.88', '0.69116555']], 'time': '2021-05-20T03:56:18.802460Z'}
{'type': 'l2update', 'product_id': 'BTC-USD', 'changes': [['sell', '38344.13', '1.72172590']], 'time': '2021-05-20T03:56:18.802485Z'}
{'type': 'l2update', 'product_id': 'BTC-USD', 'changes': [['sell', '47833.09', '0.00000000']], 'time': '2021-05-20T03:56:18.803888Z'}
{'type': 'l2update', 'product_id': 'BTC-USD', 'changes': [['sell', '47829.68', '0.00000000']], 'time': '2021-05-20T03:56:18.806972Z'}
{'type': 'l2update', 'product_id': 'BTC-USD', 'changes': [['buy', '38325.95', '0.00000000']], 'time': '2021-05-20T03:56:18.808718Z'}
{'type': 'l2update', 'product_id': 'BTC-USD', 'changes': [['buy', '38310.71', '0.06368552']], 'time': '2021-05-20T03:56:18.810007Z'}
{'type': 'l2update', 'product_id': 'BTC-USD', 'changes': [['sell', '47826.26', '0.00000000']], 'time': '2021-05-20T03:56:18.810160Z'}
{'type': 'l2update', 'product_id': 'BTC-USD', 'changes': [['buy', '38344.12', '0.00139026']], 'time': '2021-05-20T03:56:18.813837Z'}
{'type': 'l2update', 'product_id': 'BTC-USD', 'changes': [['buy', '38344.12', '0.00000000']], 'time': '2021-05-20T03:56:18.813908Z'}
{'type': 'l2update', 'product_id': 'BTC-USD', 'changes': [['buy', '38336.71', '0.04288757']], 'time': '2021-05-20T03:56:18.813908Z'}
{'type': 'l2update', 'product_id': 'BTC-USD', 'changes': [['sell', '47822.84', '0.00000000']], 'time': '2021-05-20T03:56:18.815829Z'}
{'type': 'l2update', 'product_id': 'BTC-USD', 'changes': [['sell', '47811.82', '0.00000000']], 'time': '2021-05-20T03:56:18.819753Z'}
{'type': 'l2update', 'product_id': 'BTC-USD', 'changes': [['buy', '38324.72', '1.07340561']], 'time': '2021-05-20T03:56:18.822482Z'}
{'type': 'l2update', 'product_id': 'BTC-USD', 'changes': [['sell', '47800.43', '0.00000000']], 'time': '2021-05-20T03:56:18.824019Z'}
{'type': 'l2update', 'product_id': 'BTC-USD', 'changes': [['sell', '38466.57', '0.00000000']], 'time': '2021-05-20T03:56:18.826178Z'}
{'type': 'l2update', 'product_id': 'BTC-USD', 'changes': [['sell', '38344.12', '0.00573000']], 'time': '2021-05-20T03:56:18.826278Z'}
{'type': 'l2update', 'product_id': 'BTC-USD', 'changes': [['sell', '47786.78', '0.00000000']], 'time': '2021-05-20T03:56:18.828116Z'}
{'type': 'l2update', 'product_id': 'BTC-USD', 'changes': [['buy', '38310.71', '0.00000000']], 'time': '2021-05-20T03:56:18.828525Z'}
{'type': 'l2update', 'product_id': 'BTC-USD', 'changes': [['buy', '38315.89', '0.43720000']], 'time': '2021-05-20T03:56:18.830507Z'}
{'type': 'l2update', 'product_id': 'BTC-USD', 'changes': [['sell', '38344.13', '1.71599590']], 'time': '2021-05-20T03:56:18.831406Z'}
{'type': 'l2update', 'product_id': 'BTC-USD', 'changes': [['sell', '38344.13', '0.24775311']], 'time': '2021-05-20T03:56:18.831513Z'}
{'type': 'l2update', 'product_id': 'BTC-USD', 'changes': [['sell', '38344.13', '0.04775311']], 'time': '2021-05-20T03:56:18.832627Z'}
{'type': 'l2update', 'product_id': 'BTC-USD', 'changes': [['buy', '38307.71', '0.06368552']], 'time': '2021-05-20T03:56:18.834361Z'}
{'type': 'l2update', 'product_id': 'BTC-USD', 'changes': [['sell', '38344.12', '0.00000000']], 'time': '2021-05-20T03:56:18.835150Z'}
{'type': 'l2update', 'product_id': 'BTC-USD', 'changes': [['sell', '47776.53', '0.00000000']], 'time': '2021-05-20T03:56:18.836038Z'}
{'type': 'l2update', 'product_id': 'BTC-USD', 'changes': [['sell', '38344.13', '0.00000000']], 'time': '2021-05-20T03:56:18.836789Z'}
{'type': 'l2update', 'product_id': 'BTC-USD', 'changes': [['sell', '38466.57', '0.01000000']], 'time': '2021-05-20T03:56:18.838974Z'}
{'type': 'l2update', 'product_id': 'BTC-USD', 'changes': [['sell', '47752.58', '0.00000000']], 'time': '2021-05-20T03:56:18.842603Z'}
{'type': 'l2update', 'product_id': 'BTC-USD', 'changes': [['sell', '38363.52', '0.48940000']], 'time': '2021-05-20T03:56:18.844807Z'}
{'type': 'l2update', 'product_id': 'BTC-USD', 'changes': [['sell', '47738.94', '0.00000000']], 'time': '2021-05-20T03:56:18.846217Z'}
{'type': 'l2update', 'product_id': 'BTC-USD', 'changes': [['sell', '47721.88', '0.00000000']], 'time': '2021-05-20T03:56:18.849566Z'}
{'type': 'l2update', 'product_id': 'BTC-USD', 'changes': [['sell', '38344.13', '1.56000796']], 'time': '2021-05-20T03:56:18.850008Z'}
{'type': 'l2update', 'product_id': 'BTC-USD', 'changes': [['sell', '47500.17', '0.00000000']], 'time': '2021-05-20T03:56:18.852794Z'}
{'type': 'l2update', 'product_id': 'BTC-USD', 'changes': [['sell', '38367.67', '0.00000000']], 'time': '2021-05-20T03:56:18.855139Z'}
{'type': 'l2update', 'product_id': 'BTC-USD', 'changes': [['sell', '47476.42', '0.00000000']], 'time': '2021-05-20T03:56:18.855434Z'}
{'type': 'l2update', 'product_id': 'BTC-USD', 'changes': [['sell', '38344.13', '0.00000000']], 'time': '2021-05-20T03:56:18.856059Z'}
{'type': 'l2update', 'product_id': 'BTC-USD', 'changes': [['buy', '38310.71', '0.06368552']], 'time': '2021-05-20T03:56:18.856515Z'}
{'type': 'l2update', 'product_id': 'BTC-USD', 'changes': [['buy', '38326.88', '0.10000000']], 'time': '2021-05-20T03:56:18.857325Z'}
{'type': 'l2update', 'product_id': 'BTC-USD', 'changes': [['sell', '47466.24', '0.00000000']], 'time': '2021-05-20T03:56:18.861566Z'}
{'type': 'l2update', 'product_id': 'BTC-USD', 'changes': [['buy', '38307.71', '0.00000000']], 'time': '2021-05-20T03:56:18.863830Z'}
{'type': 'l2update', 'product_id': 'BTC-USD', 'changes': [['sell', '47393.59', '0.00000000']], 'time': '2021-05-20T03:56:18.867331Z'}
{'type': 'l2update', 'product_id': 'BTC-USD', 'changes': [['sell', '38345.49', '0.05004919']], 'time': '2021-05-20T03:56:18.869151Z'}
{'type': 'l2update', 'product_id': 'BTC-USD', 'changes': [['sell', '38363.51', '0.05000000']], 'time': '2021-05-20T03:56:18.869609Z'}
{'type': 'l2update', 'product_id': 'BTC-USD', 'changes': [['sell', '38419.17', '0.01000000']], 'time': '2021-05-20T03:56:18.869716Z'}
{'type': 'l2update', 'product_id': 'BTC-USD', 'changes': [['sell', '47369.89', '0.00000000']], 'time': '2021-05-20T03:56:18.870495Z'}
{'type': 'l2update', 'product_id': 'BTC-USD', 'changes': [['sell', '38439.40', '0.00000000']], 'time': '2021-05-20T03:56:18.873925Z'}
{'type': 'l2update', 'product_id': 'BTC-USD', 'changes': [['buy', '38326.89', '0.59116555']], 'time': '2021-05-20T03:56:18.881532Z'}
{'type': 'l2update', 'product_id': 'BTC-USD', 'changes': [['buy', '38165.47', '0.00000000']], 'time': '2021-05-20T03:56:18.892045Z'}
{'type': 'l2update', 'product_id': 'BTC-USD', 'changes': [['sell', '38349.61', '0.00000000']], 'time': '2021-05-20T03:56:18.892591Z'}
{'type': 'l2update', 'product_id': 'BTC-USD', 'changes': [['sell', '38374.89', '0.01302935']], 'time': '2021-05-20T03:56:18.894168Z'}
{'type': 'l2update', 'product_id': 'BTC-USD', 'changes': [['buy', '38326.90', '0.10000000']], 'time': '2021-05-20T03:56:18.903435Z'}
{'type': 'l2update', 'product_id': 'BTC-USD', 'changes': [['buy', '38316.28', '0.00000000']], 'time': '2021-05-20T03:56:18.918761Z'}
{'type': 'l2update', 'product_id': 'BTC-USD', 'changes': [['buy', '38315.14', '0.00000000']], 'time': '2021-05-20T03:56:18.918761Z'}
{'type': 'l2update', 'product_id': 'BTC-USD', 'changes': [['buy', '38314.33', '0.00000000']], 'time': '2021-05-20T03:56:18.918761Z'}
{'type': 'l2update', 'product_id': 'BTC-USD', 'changes': [['buy', '38301.14', '0.00000000']], 'time': '2021-05-20T03:56:18.921850Z'}
{'type': 'l2update', 'product_id': 'BTC-USD', 'changes': [['buy', '38198.19', '0.80355629']], 'time': '2021-05-20T03:56:18.923138Z'}
{'type': 'l2update', 'product_id': 'BTC-USD', 'changes': [['buy', '38300.72', '0.09000000']], 'time': '2021-05-20T03:56:18.924785Z'}
{'type': 'l2update', 'product_id': 'BTC-USD', 'changes': [['buy', '38300.72', '0.05000000']], 'time': '2021-05-20T03:56:18.928469Z'}
{'type': 'l2update', 'product_id': 'BTC-USD', 'changes': [['buy', '38300.72', '0.00000000']], 'time': '2021-05-20T03:56:18.931423Z'}
{'type': 'l2update', 'product_id': 'BTC-USD', 'changes': [['sell', '38372.47', '0.01000000']], 'time': '2021-05-20T03:56:18.935101Z'}
{'type': 'l2update', 'product_id': 'BTC-USD', 'changes': [['buy', '38320.82', '0.02400000']], 'time': '2021-05-20T03:56:18.937484Z'}
{'type': 'l2update', 'product_id': 'BTC-USD', 'changes': [['buy', '38320.01', '0.02400000']], 'time': '2021-05-20T03:56:18.937484Z'}
{'type': 'l2update', 'product_id': 'BTC-USD', 'changes': [['buy', '38319.21', '0.02400000']], 'time': '2021-05-20T03:56:18.937484Z'}
{'type': 'l2update', 'product_id': 'BTC-USD', 'changes': [['buy', '38296.25', '0.01000000']], 'time': '2021-05-20T03:56:18.944653Z'}
{'type': 'l2update', 'product_id': 'BTC-USD', 'changes': [['buy', '38292.96', '0.02000000']], 'time': '2021-05-20T03:56:18.958939Z'}
{'type': 'l2update', 'product_id': 'BTC-USD', 'changes': [['sell', '38466.57', '0.00000000']], 'time': '2021-05-20T03:56:18.966314Z'}
{'type': 'l2update', 'product_id': 'BTC-USD', 'changes': [['buy', '38291.02', '0.03000000']], 'time': '2021-05-20T03:56:18.970307Z'}
{'type': 'l2update', 'product_id': 'BTC-USD', 'changes': [['sell', '38480.34', '0.02409835']], 'time': '2021-05-20T03:56:18.978860Z'}
{'type': 'l2update', 'product_id': 'BTC-USD', 'changes': [['buy', '38291.02', '0.07000000']], 'time': '2021-05-20T03:56:18.982025Z'}
{'type': 'l2update', 'product_id': 'BTC-USD', 'changes': [['buy', '38291.02', '0.12000000']], 'time': '2021-05-20T03:56:18.994475Z'}
{'type': 'l2update', 'product_id': 'BTC-USD', 'changes': [['sell', '38344.64', '0.49739390']], 'time': '2021-05-20T03:56:18.999037Z'}
{'type': 'l2update', 'product_id': 'BTC-USD', 'changes': [['sell', '38376.36', '0.04000000']], 'time': '2021-05-20T03:56:19.006751Z'}
{'type': 'l2update', 'product_id': 'BTC-USD', 'changes': [['sell', '38344.64', '0.00000000']], 'time': '2021-05-20T03:56:19.006810Z'}
{'type': 'l2update', 'product_id': 'BTC-USD', 'changes': [['buy', '38326.89', '0.00000000']], 'time': '2021-05-20T03:56:19.011916Z'}
{'type': 'l2update', 'product_id': 'BTC-USD', 'changes': [['buy', '38291.02', '0.09000000']], 'time': '2021-05-20T03:56:19.012333Z'}
{'type': 'l2update', 'product_id': 'BTC-USD', 'changes': [['buy', '38308.99', '0.00000000']], 'time': '2021-05-20T03:56:19.012389Z'}
{'type': 'l2update', 'product_id': 'BTC-USD', 'changes': [['sell', '38351.59', '0.00000000']], 'time': '2021-05-20T03:56:19.012389Z'}
{'type': 'l2update', 'product_id': 'BTC-USD', 'changes': [['buy', '38291.02', '0.05000000']], 'time': '2021-05-20T03:56:19.015759Z'}
{'type': 'l2update', 'product_id': 'BTC-USD', 'changes': [['buy', '38291.02', '0.00000000']], 'time': '2021-05-20T03:56:19.018534Z'}
{'type': 'l2update', 'product_id': 'BTC-USD', 'changes': [['sell', '38344.65', '0.00000000']], 'time': '2021-05-20T03:56:19.020117Z'}
{'type': 'l2update', 'product_id': 'BTC-USD', 'changes': [['sell', '38344.64', '0.50000000']], 'time': '2021-05-20T03:56:19.022330Z'}
{'type': 'l2update', 'product_id': 'BTC-USD', 'changes': [['buy', '38320.82', '0.00000000']], 'time': '2021-05-20T03:56:19.027083Z'}
{'type': 'l2update', 'product_id': 'BTC-USD', 'changes': [['buy', '38320.01', '0.00000000']], 'time': '2021-05-20T03:56:19.027083Z'}
{'type': 'l2update', 'product_id': 'BTC-USD', 'changes': [['buy', '38319.21', '0.00000000']], 'time': '2021-05-20T03:56:19.027083Z'}
{'type': 'l2update', 'product_id': 'BTC-USD', 'changes': [['buy', '38298.62', '0.03000000']], 'time': '2021-05-20T03:56:19.030330Z'}
{'type': 'l2update', 'product_id': 'BTC-USD', 'changes': [['sell', '38344.64', '0.00000000']], 'time': '2021-05-20T03:56:19.034155Z'}
{'type': 'l2update', 'product_id': 'BTC-USD', 'changes': [['buy', '38310.09', '0.04447316']], 'time': '2021-05-20T03:56:19.034267Z'}
{'type': 'l2update', 'product_id': 'BTC-USD', 'changes': [['sell', '38351.98', '0.04158931']], 'time': '2021-05-20T03:56:19.034267Z'}
{'type': 'l2update', 'product_id': 'BTC-USD', 'changes': [['buy', '38326.91', '0.59116555']], 'time': '2021-05-20T03:56:19.035834Z'}
{'type': 'l2update', 'product_id': 'BTC-USD', 'changes': [['buy', '38313.59', '0.06368552']], 'time': '2021-05-20T03:56:19.035905Z'}
{'type': 'l2update', 'product_id': 'BTC-USD', 'changes': [['sell', '38345.48', '2.48969908']], 'time': '2021-05-20T03:56:19.035950Z'}
{'type': 'l2update', 'product_id': 'BTC-USD', 'changes': [['buy', '38337.33', '0.01492000']], 'time': '2021-05-20T03:56:19.036026Z'}
{'type': 'l2update', 'product_id': 'BTC-USD', 'changes': [['buy', '38337.14', '0.07460000']], 'time': '2021-05-20T03:56:19.036037Z'}
{'type': 'l2update', 'product_id': 'BTC-USD', 'changes': [['buy', '38337.14', '0.00000000']], 'time': '2021-05-20T03:56:19.042277Z'}
{'type': 'l2update', 'product_id': 'BTC-USD', 'changes': [['buy', '38310.71', '0.00000000']], 'time': '2021-05-20T03:56:19.042350Z'}
{'type': 'l2update', 'product_id': 'BTC-USD', 'changes': [['buy', '38337.33', '0.00000000']], 'time': '2021-05-20T03:56:19.042903Z'}
{'type': 'l2update', 'product_id': 'BTC-USD', 'changes': [['buy', '38298.62', '0.07000000']], 'time': '2021-05-20T03:56:19.043975Z'}
{'type': 'l2update', 'product_id': 'BTC-USD', 'changes': [['buy', '38326.27', '0.02400000']], 'time': '2021-05-20T03:56:19.044077Z'}
{'type': 'l2update', 'product_id': 'BTC-USD', 'changes': [['buy', '38325.46', '0.02400000']], 'time': '2021-05-20T03:56:19.044077Z'}
{'type': 'l2update', 'product_id': 'BTC-USD', 'changes': [['buy', '38324.65', '0.02400000']], 'time': '2021-05-20T03:56:19.044077Z'}
{'type': 'l2update', 'product_id': 'BTC-USD', 'changes': [['sell', '38344.95', '0.07460000']], 'time': '2021-05-20T03:56:19.047910Z'}
{'type': 'l2update', 'product_id': 'BTC-USD', 'changes': [['sell', '38347.86', '0.50000000']], 'time': '2021-05-20T03:56:19.048114Z'}
{'type': 'l2update', 'product_id': 'BTC-USD', 'changes': [['buy', '38326.27', '0.00000000']], 'time': '2021-05-20T03:56:19.050413Z'}
{'type': 'l2update', 'product_id': 'BTC-USD', 'changes': [['sell', '38345.24', '0.00140099']], 'time': '2021-05-20T03:56:19.052323Z'}
{'type': 'l2update', 'product_id': 'BTC-USD', 'changes': [['buy', '38326.88', '0.00000000']], 'time': '2021-05-20T03:56:19.052797Z'}
{'type': 'l2update', 'product_id': 'BTC-USD', 'changes': [['buy', '38337.35', '0.01492000']], 'time': '2021-05-20T03:56:19.055502Z'}
{'type': 'l2update', 'product_id': 'BTC-USD', 'changes': [['buy', '38336.95', '0.03207536']], 'time': '2021-05-20T03:56:19.055615Z'}
{'type': 'l2update', 'product_id': 'BTC-USD', 'changes': [['buy', '38340.44', '0.00874958']], 'time': '2021-05-20T03:56:19.055643Z'}
{'type': 'l2update', 'product_id': 'BTC-USD', 'changes': [['buy', '38298.62', '0.12000000']], 'time': '2021-05-20T03:56:19.055962Z'}
{'type': 'l2update', 'product_id': 'BTC-USD', 'changes': [['sell', '38345.24', '0.00000000']], 'time': '2021-05-20T03:56:19.056846Z'}
{'type': 'l2update', 'product_id': 'BTC-USD', 'changes': [['sell', '38344.95', '0.07449593']], 'time': '2021-05-20T03:56:19.059416Z'}
{'type': 'l2update', 'product_id': 'BTC-USD', 'changes': [['buy', '38326.92', '0.10000000']], 'time': '2021-05-20T03:56:19.059635Z'}
{'type': 'l2update', 'product_id': 'BTC-USD', 'changes': [['buy', '38336.95', '0.00000000']], 'time': '2021-05-20T03:56:19.060328Z'}
{'type': 'l2update', 'product_id': 'BTC-USD', 'changes': [['buy', '38325.94', '0.00000000']], 'time': '2021-05-20T03:56:19.061432Z'}
{'type': 'l2update', 'product_id': 'BTC-USD', 'changes': [['buy', '38325.46', '0.00000000']], 'time': '2021-05-20T03:56:19.062243Z'}
{'type': 'l2update', 'product_id': 'BTC-USD', 'changes': [['buy', '38324.65', '0.00000000']], 'time': '2021-05-20T03:56:19.062243Z'}
{'type': 'l2update', 'product_id': 'BTC-USD', 'changes': [['buy', '38337.35', '0.00000000']], 'time': '2021-05-20T03:56:19.062338Z'}
{'type': 'l2update', 'product_id': 'BTC-USD', 'changes': [['buy', '38313.59', '0.00000000']], 'time': '2021-05-20T03:56:19.063210Z'}
{'type': 'l2update', 'product_id': 'BTC-USD', 'changes': [['sell', '38344.95', '0.00000000']], 'time': '2021-05-20T03:56:19.064031Z'}
{'type': 'l2update', 'product_id': 'BTC-USD', 'changes': [['buy', '38315.90', '0.06368552']], 'time': '2021-05-20T03:56:19.071873Z'}
{'type': 'l2update', 'product_id': 'BTC-USD', 'changes': [['buy', '38337.32', '0.07460000']], 'time': '2021-05-20T03:56:19.075591Z'}
{'type': 'l2update', 'product_id': 'BTC-USD', 'changes': [['buy', '38337.09', '0.01492000']], 'time': '2021-05-20T03:56:19.075778Z'}
{'type': 'l2update', 'product_id': 'BTC-USD', 'changes': [['buy', '38344.90', '0.15000000']], 'time': '2021-05-20T03:56:19.075863Z'}
{'type': 'l2update', 'product_id': 'BTC-USD', 'changes': [['buy', '38315.90', '0.00000000']], 'time': '2021-05-20T03:56:19.079145Z'}
{'type': 'l2update', 'product_id': 'BTC-USD', 'changes': [['buy', '37535.87', '0.00000000']], 'time': '2021-05-20T03:56:19.079940Z'}
{'type': 'l2update', 'product_id': 'BTC-USD', 'changes': [['buy', '38321.75', '0.02400000']], 'time': '2021-05-20T03:56:19.080072Z'}
{'type': 'l2update', 'product_id': 'BTC-USD', 'changes': [['buy', '38320.94', '0.02400000']], 'time': '2021-05-20T03:56:19.080072Z'}
{'type': 'l2update', 'product_id': 'BTC-USD', 'changes': [['buy', '38320.14', '0.02400000']], 'time': '2021-05-20T03:56:19.080072Z'}
{'type': 'l2update', 'product_id': 'BTC-USD', 'changes': [['buy', '38337.32', '0.00000000']], 'time': '2021-05-20T03:56:19.081551Z'}
{'type': 'l2update', 'product_id': 'BTC-USD', 'changes': [['buy', '38337.09', '0.00000000']], 'time': '2021-05-20T03:56:19.083444Z'}
{'type': 'l2update', 'product_id': 'BTC-USD', 'changes': [['buy', '38326.90', '0.00000000']], 'time': '2021-05-20T03:56:19.084507Z'}
{'type': 'l2update', 'product_id': 'BTC-USD', 'changes': [['buy', '38328.54', '0.07090635']], 'time': '2021-05-20T03:56:19.085485Z'}
{'type': 'l2update', 'product_id': 'BTC-USD', 'changes': [['sell', '38345.49', '0.00000000']], 'time': '2021-05-20T03:56:19.087013Z'}
{'type': 'l2update', 'product_id': 'BTC-USD', 'changes': [['sell', '38363.51', '0.00000000']], 'time': '2021-05-20T03:56:19.087126Z'}
{'type': 'l2update', 'product_id': 'BTC-USD', 'changes': [['buy', '38326.91', '0.00000000']], 'time': '2021-05-20T03:56:19.089648Z'}
{'type': 'l2update', 'product_id': 'BTC-USD', 'changes': [['sell', '39133.90', '0.06575946']], 'time': '2021-05-20T03:56:19.091283Z'}
{'type': 'l2update', 'product_id': 'BTC-USD', 'changes': [['sell', '38366.58', '0.00000000']], 'time': '2021-05-20T03:56:19.094733Z'}
{'type': 'l2update', 'product_id': 'BTC-USD', 'changes': [['buy', '38313.59', '0.06368552']], 'time': '2021-05-20T03:56:19.095059Z'}
{'type': 'l2update', 'product_id': 'BTC-USD', 'changes': [['sell', '38369.98', '0.05000000']], 'time': '2021-05-20T03:56:19.098586Z'}
{'type': 'l2update', 'product_id': 'BTC-USD', 'changes': [['buy', '37541.56', '0.06519502']], 'time': '2021-05-20T03:56:19.101923Z'}
{'type': 'l2update', 'product_id': 'BTC-USD', 'changes': [['sell', '38347.87', '0.00000000']], 'time': '2021-05-20T03:56:19.102537Z'}
{'type': 'l2update', 'product_id': 'BTC-USD', 'changes': [['buy', '38326.93', '0.59116555']], 'time': '2021-05-20T03:56:19.110783Z'}
{'type': 'l2update', 'product_id': 'BTC-USD', 'changes': [['buy', '38313.59', '0.00000000']], 'time': '2021-05-20T03:56:19.115221Z'}
{'type': 'l2update', 'product_id': 'BTC-USD', 'changes': [['buy', '38336.71', '0.04465239']], 'time': '2021-05-20T03:56:19.124124Z'}
{'type': 'l2update', 'product_id': 'BTC-USD', 'changes': [['buy', '38336.72', '0.10000000']], 'time': '2021-05-20T03:56:19.139948Z'}
{'type': 'l2update', 'product_id': 'BTC-USD', 'changes': [['buy', '38345.47', '0.01492000']], 'time': '2021-05-20T03:56:19.185899Z'}
{'type': 'l2update', 'product_id': 'BTC-USD', 'changes': [['sell', '38345.48', '2.45689884']], 'time': '2021-05-20T03:56:19.198287Z'}
{'type': 'l2update', 'product_id': 'BTC-USD', 'changes': [['sell', '38350.80', '0.05006952']], 'time': '2021-05-20T03:56:19.201551Z'}
{'type': 'l2update', 'product_id': 'BTC-USD', 'changes': [['sell', '43100.00', '1.09530000']], 'time': '2021-05-20T03:56:19.215323Z'}
{'type': 'l2update', 'product_id': 'BTC-USD', 'changes': [['buy', '37505.01', '0.05020000']], 'time': '2021-05-20T03:56:19.217131Z'}
{'type': 'l2update', 'product_id': 'BTC-USD', 'changes': [['buy', '37506.22', '0.00300000']], 'time': '2021-05-20T03:56:19.217131Z'}
{'type': 'l2update', 'product_id': 'BTC-USD', 'changes': [['sell', '38528.09', '0.00000000']], 'time': '2021-05-20T03:56:19.217512Z'}
{'type': 'l2update', 'product_id': 'BTC-USD', 'changes': [['sell', '38345.48', '0.00000000']], 'time': '2021-05-20T03:56:19.219291Z'}
{'type': 'l2update', 'product_id': 'BTC-USD', 'changes': [['buy', '38324.72', '0.00000000']], 'time': '2021-05-20T03:56:19.227914Z'}
{'type': 'l2update', 'product_id': 'BTC-USD', 'changes': [['sell', '43100.00', '2.09880000']], 'time': '2021-05-20T03:56:19.231541Z'}
{'type': 'l2update', 'product_id': 'BTC-USD', 'changes': [['buy', '38310.09', '0.00000000']], 'time': '2021-05-20T03:56:19.233624Z'}
{'type': 'l2update', 'product_id': 'BTC-USD', 'changes': [['sell', '38351.98', '0.00000000']], 'time': '2021-05-20T03:56:19.233624Z'}
{'type': 'l2update', 'product_id': 'BTC-USD', 'changes': [['buy', '38345.47', '0.00000000']], 'time': '2021-05-20T03:56:19.235714Z'}
{'type': 'l2update', 'product_id': 'BTC-USD', 'changes': [['buy', '38345.59', '0.02262211']], 'time': '2021-05-20T03:56:19.239291Z'}
{'type': 'l2update', 'product_id': 'BTC-USD', 'changes': [['sell', '38514.91', '0.01000000']], 'time': '2021-05-20T03:56:19.243951Z'}
{'type': 'l2update', 'product_id': 'BTC-USD', 'changes': [['buy', '38345.59', '0.00000000']], 'time': '2021-05-20T03:56:19.243984Z'}
{'type': 'l2update', 'product_id': 'BTC-USD', 'changes': [['sell', '38345.59', '2.46707697']], 'time': '2021-05-20T03:56:19.243984Z'}
{'type': 'l2update', 'product_id': 'BTC-USD', 'changes': [['sell', '38345.59', '2.46684301']], 'time': '2021-05-20T03:56:19.251393Z'}
{'type': 'l2update', 'product_id': 'BTC-USD', 'changes': [['buy', '38340.65', '0.05095682']], 'time': '2021-05-20T03:56:19.255271Z'}
{'type': 'l2update', 'product_id': 'BTC-USD', 'changes': [['buy', '38324.72', '1.10620585']], 'time': '2021-05-20T03:56:19.255340Z'}
{'type': 'l2update', 'product_id': 'BTC-USD', 'changes': [['sell', '38514.91', '0.00000000']], 'time': '2021-05-20T03:56:19.255474Z'}
{'type': 'l2update', 'product_id': 'BTC-USD', 'changes': [['sell', '38345.59', '0.00000000']], 'time': '2021-05-20T03:56:19.260496Z'}
{'type': 'l2update', 'product_id': 'BTC-USD', 'changes': [['buy', '38310.87', '0.04355180']], 'time': '2021-05-20T03:56:19.262722Z'}
{'type': 'l2update', 'product_id': 'BTC-USD', 'changes': [['sell', '38353.86', '0.04615635']], 'time': '2021-05-20T03:56:19.262722Z'}
{'type': 'l2update', 'product_id': 'BTC-USD', 'changes': [['buy', '38336.71', '0.00176482']], 'time': '2021-05-20T03:56:19.266040Z'}
{'type': 'l2update', 'product_id': 'BTC-USD', 'changes': [['buy', '38324.72', '0.00000000']], 'time': '2021-05-20T03:56:19.266260Z'}
{'type': 'l2update', 'product_id': 'BTC-USD', 'changes': [['buy', '38315.89', '0.00000000']], 'time': '2021-05-20T03:56:19.266442Z'}
{'type': 'l2update', 'product_id': 'BTC-USD', 'changes': [['sell', '38529.97', '0.01000000']], 'time': '2021-05-20T03:56:19.266576Z'}
{'type': 'l2update', 'product_id': 'BTC-USD', 'changes': [['sell', '38345.60', '3.04269908']], 'time': '2021-05-20T03:56:19.279235Z'}
{'type': 'l2update', 'product_id': 'BTC-USD', 'changes': [['buy', '38318.00', '0.46620000']], 'time': '2021-05-20T03:56:19.279258Z'}
{'type': 'l2update', 'product_id': 'BTC-USD', 'changes': [['buy', '38345.59', '0.01492000']], 'time': '2021-05-20T03:56:19.285964Z'}
{'type': 'l2update', 'product_id': 'BTC-USD', 'changes': [['buy', '38321.75', '0.00000000']], 'time': '2021-05-20T03:56:19.290347Z'}
{'type': 'l2update', 'product_id': 'BTC-USD', 'changes': [['buy', '38324.72', '1.12906192']], 'time': '2021-05-20T03:56:19.290948Z'}
{'type': 'l2update', 'product_id': 'BTC-USD', 'changes': [['buy', '38284.49', '0.00000000']], 'time': '2021-05-20T03:56:19.295296Z'}
{'type': 'l2update', 'product_id': 'BTC-USD', 'changes': [['buy', '38320.94', '0.00000000']], 'time': '2021-05-20T03:56:19.296678Z'}
{'type': 'l2update', 'product_id': 'BTC-USD', 'changes': [['sell', '38345.60', '0.55300000']], 'time': '2021-05-20T03:56:19.299202Z'}
{'type': 'l2update', 'product_id': 'BTC-USD', 'changes': [['sell', '38366.88', '0.00000000']], 'time': '2021-05-20T03:56:19.299522Z'}
{'type': 'l2update', 'product_id': 'BTC-USD', 'changes': [['buy', '38282.50', '0.10000000']], 'time': '2021-05-20T03:56:19.308140Z'}
{'type': 'l2update', 'product_id': 'BTC-USD', 'changes': [['buy', '38319.21', '0.02400000']], 'time': '2021-05-20T03:56:19.308192Z'}
{'type': 'l2update', 'product_id': 'BTC-USD', 'changes': [['buy', '38318.40', '0.02400000']], 'time': '2021-05-20T03:56:19.308192Z'}
{'type': 'l2update', 'product_id': 'BTC-USD', 'changes': [['sell', '38372.47', '0.00000000']], 'time': '2021-05-20T03:56:19.311044Z'}
{'type': 'l2update', 'product_id': 'BTC-USD', 'changes': [['sell', '38379.00', '0.00000000']], 'time': '2021-05-20T03:56:19.311744Z'}
{'type': 'l2update', 'product_id': 'BTC-USD', 'changes': [['sell', '38373.64', '0.00000000']], 'time': '2021-05-20T03:56:19.315054Z'}
{'type': 'l2update', 'product_id': 'BTC-USD', 'changes': [['sell', '38347.85', '2.48969908']], 'time': '2021-05-20T03:56:19.317604Z'}
{'type': 'l2update', 'product_id': 'BTC-USD', 'changes': [['sell', '38347.86', '0.00000000']], 'time': '2021-05-20T03:56:19.317704Z'}
{'type': 'l2update', 'product_id': 'BTC-USD', 'changes': [['sell', '38361.54', '0.00000000']], 'time': '2021-05-20T03:56:19.318421Z'}
{'type': 'l2update', 'product_id': 'BTC-USD', 'changes': [['sell', '38363.52', '0.00000000']], 'time': '2021-05-20T03:56:19.320420Z'}
{'type': 'l2update', 'product_id': 'BTC-USD', 'changes': [['sell', '38372.37', '0.05119631']], 'time': '2021-05-20T03:56:19.322147Z'}
{'type': 'l2update', 'product_id': 'BTC-USD', 'changes': [['buy', '38174.33', '0.04919235']], 'time': '2021-05-20T03:56:19.322175Z'}
{'type': 'l2update', 'product_id': 'BTC-USD', 'changes': [['buy', '38267.79', '0.07800000']], 'time': '2021-05-20T03:56:19.322452Z'}
{'type': 'l2update', 'product_id': 'BTC-USD', 'changes': [['sell', '38378.36', '0.01000000']], 'time': '2021-05-20T03:56:19.325728Z'}
{'type': 'l2update', 'product_id': 'BTC-USD', 'changes': [['sell', '38347.85', '0.00000000']], 'time': '2021-05-20T03:56:19.326614Z'}
{'type': 'l2update', 'product_id': 'BTC-USD', 'changes': [['sell', '38350.96', '0.00000000']], 'time': '2021-05-20T03:56:19.328221Z'}
{'type': 'l2update', 'product_id': 'BTC-USD', 'changes': [['sell', '38353.85', '0.50000000']], 'time': '2021-05-20T03:56:19.329946Z'}
{'type': 'l2update', 'product_id': 'BTC-USD', 'changes': [['sell', '38365.38', '0.42240000']], 'time': '2021-05-20T03:56:19.330025Z'}
{'type': 'l2update', 'product_id': 'BTC-USD', 'changes': [['sell', '38365.38', '0.00000000']], 'time': '2021-05-20T03:56:19.336322Z'}
{'type': 'l2update', 'product_id': 'BTC-USD', 'changes': [['sell', '38353.85', '0.00000000']], 'time': '2021-05-20T03:56:19.337001Z'}
{'type': 'l2update', 'product_id': 'BTC-USD', 'changes': [['sell', '38379.47', '0.02000000']], 'time': '2021-05-20T03:56:19.338095Z'}
{'type': 'l2update', 'product_id': 'BTC-USD', 'changes': [['buy', '38310.87', '0.00000000']], 'time': '2021-05-20T03:56:19.339616Z'}
{'type': 'l2update', 'product_id': 'BTC-USD', 'changes': [['sell', '38353.86', '0.00000000']], 'time': '2021-05-20T03:56:19.339616Z'}
{'type': 'l2update', 'product_id': 'BTC-USD', 'changes': [['sell', '38345.60', '0.00000000']], 'time': '2021-05-20T03:56:19.340592Z'}
{'type': 'l2update', 'product_id': 'BTC-USD', 'changes': [['buy', '38345.59', '0.00000000']], 'time': '2021-05-20T03:56:19.346736Z'}
{'type': 'l2update', 'product_id': 'BTC-USD', 'changes': [['sell', '38368.30', '0.00000000']], 'time': '2021-05-20T03:56:19.346922Z'}
{'type': 'l2update', 'product_id': 'BTC-USD', 'changes': [['buy', '38318.00', '0.00000000']], 'time': '2021-05-20T03:56:19.347003Z'}
{'type': 'l2update', 'product_id': 'BTC-USD', 'changes': [['buy', '38326.92', '0.00000000']], 'time': '2021-05-20T03:56:19.348215Z'}
{'type': 'l2update', 'product_id': 'BTC-USD', 'changes': [['buy', '37469.35', '0.00000000']], 'time': '2021-05-20T03:56:19.348494Z'}
{'type': 'l2update', 'product_id': 'BTC-USD', 'changes': [['sell', '39499.99', '0.10880000']], 'time': '2021-05-20T03:56:19.348494Z'}
{'type': 'l2update', 'product_id': 'BTC-USD', 'changes': [['buy', '38336.71', '0.00000000']], 'time': '2021-05-20T03:56:19.348753Z'}
{'type': 'l2update', 'product_id': 'BTC-USD', 'changes': [['sell', '38349.54', '2.48969908']], 'time': '2021-05-20T03:56:19.349151Z'}
{'type': 'l2update', 'product_id': 'BTC-USD', 'changes': [['buy', '38326.98', '0.52000000']], 'time': '2021-05-20T03:56:19.349345Z'}
{'type': 'l2update', 'product_id': 'BTC-USD', 'changes': [['buy', '38000.00', '0.75184904']], 'time': '2021-05-20T03:56:19.349416Z'}
{'type': 'l2update', 'product_id': 'BTC-USD', 'changes': [['buy', '38019.23', '0.00000000']], 'time': '2021-05-20T03:56:19.349434Z'}
{'type': 'l2update', 'product_id': 'BTC-USD', 'changes': [['sell', '38350.80', '0.00000000']], 'time': '2021-05-20T03:56:19.349535Z'}
{'type': 'l2update', 'product_id': 'BTC-USD', 'changes': [['buy', '38170.39', '0.00000000']], 'time': '2021-05-20T03:56:19.350632Z'}
{'type': 'l2update', 'product_id': 'BTC-USD', 'changes': [['buy', '38300.02', '0.00000000']], 'time': '2021-05-20T03:56:19.351844Z'}
{'type': 'l2update', 'product_id': 'BTC-USD', 'changes': [['sell', '38361.02', '0.50000000']], 'time': '2021-05-20T03:56:19.353181Z'}
{'type': 'l2update', 'product_id': 'BTC-USD', 'changes': [['sell', '38354.75', '0.00000000']], 'time': '2021-05-20T03:56:19.354117Z'}
{'type': 'l2update', 'product_id': 'BTC-USD', 'changes': [['sell', '38350.75', '0.55300000']], 'time': '2021-05-20T03:56:19.355658Z'}
{'type': 'l2update', 'product_id': 'BTC-USD', 'changes': [['buy', '38320.96', '0.00000000']], 'time': '2021-05-20T03:56:19.355997Z'}
{'type': 'l2update', 'product_id': 'BTC-USD', 'changes': [['buy', '37541.56', '0.00000000']], 'time': '2021-05-20T03:56:19.356595Z'}
{'type': 'l2update', 'product_id': 'BTC-USD', 'changes': [['buy', '38326.93', '0.00000000']], 'time': '2021-05-20T03:56:19.356729Z'}
{'type': 'l2update', 'product_id': 'BTC-USD', 'changes': [['sell', '39133.90', '0.00000000']], 'time': '2021-05-20T03:56:19.364240Z'}
{'type': 'l2update', 'product_id': 'BTC-USD', 'changes': [['buy', '38283.00', '0.07800000']], 'time': '2021-05-20T03:56:19.366031Z'}
{'type': 'l2update', 'product_id': 'BTC-USD', 'changes': [['buy', '38340.66', '0.10000000']], 'time': '2021-05-20T03:56:19.366136Z'}
{'type': 'l2update', 'product_id': 'BTC-USD', 'changes': [['buy', '38032.11', '0.12683650']], 'time': '2021-05-20T03:56:19.366172Z'}
{'type': 'l2update', 'product_id': 'BTC-USD', 'changes': [['sell', '38355.45', '0.04988038']], 'time': '2021-05-20T03:56:19.370396Z'}
{'type': 'l2update', 'product_id': 'BTC-USD', 'changes': [['buy', '38290.36', '0.00000000']], 'time': '2021-05-20T03:56:19.374088Z'}
{'type': 'l2update', 'product_id': 'BTC-USD', 'changes': [['buy', '38314.10', '0.04989314']], 'time': '2021-05-20T03:56:19.374267Z'}
{'type': 'l2update', 'product_id': 'BTC-USD', 'changes': [['sell', '38360.28', '0.05747090']], 'time': '2021-05-20T03:56:19.374267Z'}
{'type': 'l2update', 'product_id': 'BTC-USD', 'changes': [['sell', '38376.36', '0.00000000']], 'time': '2021-05-20T03:56:19.383364Z'}
{'type': 'l2update', 'product_id': 'BTC-USD', 'changes': [['buy', '37712.98', '0.08370000']], 'time': '2021-05-20T03:56:19.388169Z'}
{'type': 'l2update', 'product_id': 'BTC-USD', 'changes': [['buy', '37229.79', '0.11840000']], 'time': '2021-05-20T03:56:19.388169Z'}
{'type': 'l2update', 'product_id': 'BTC-USD', 'changes': [['buy', '38307.70', '0.00000000']], 'time': '2021-05-20T03:56:19.388356Z'}
{'type': 'l2update', 'product_id': 'BTC-USD', 'changes': [['sell', '38371.59', '0.00000000']], 'time': '2021-05-20T03:56:19.393071Z'}
{'type': 'l2update', 'product_id': 'BTC-USD', 'changes': [['buy', '38326.99', '0.59116555']], 'time': '2021-05-20T03:56:19.393810Z'}
{'type': 'l2update', 'product_id': 'BTC-USD', 'changes': [['buy', '38301.89', '0.00000000']], 'time': '2021-05-20T03:56:19.397892Z'}
{'type': 'l2update', 'product_id': 'BTC-USD', 'changes': [['sell', '38369.99', '0.33792367']], 'time': '2021-05-20T03:56:19.398614Z'}
{'type': 'l2update', 'product_id': 'BTC-USD', 'changes': [['sell', '38382.98', '0.04000000']], 'time': '2021-05-20T03:56:19.399191Z'}
{'type': 'l2update', 'product_id': 'BTC-USD', 'changes': [['buy', '38336.71', '0.00176482']], 'time': '2021-05-20T03:56:19.399371Z'}
{'type': 'l2update', 'product_id': 'BTC-USD', 'changes': [['sell', '38448.37', '0.00000000']], 'time': '2021-05-20T03:56:19.399867Z'}
{'type': 'l2update', 'product_id': 'BTC-USD', 'changes': [['sell', '38349.56', '0.00000000']], 'time': '2021-05-20T03:56:19.401061Z'}
{'type': 'l2update', 'product_id': 'BTC-USD', 'changes': [['sell', '38378.51', '0.00000000']], 'time': '2021-05-20T03:56:19.403505Z'}
{'type': 'l2update', 'product_id': 'BTC-USD', 'changes': [['buy', '38315.40', '0.39490431']], 'time': '2021-05-20T03:56:19.405375Z'}
{'type': 'l2update', 'product_id': 'BTC-USD', 'changes': [['sell', '38349.55', '0.00000000']], 'time': '2021-05-20T03:56:19.405512Z'}
{'type': 'l2update', 'product_id': 'BTC-USD', 'changes': [['sell', '38383.76', '0.00000000']], 'time': '2021-05-20T03:56:19.406323Z'}
{'type': 'l2update', 'product_id': 'BTC-USD', 'changes': [['sell', '38464.70', '0.03680923']], 'time': '2021-05-20T03:56:19.406651Z'}
{'type': 'l2update', 'product_id': 'BTC-USD', 'changes': [['buy', '38225.75', '0.06217071']], 'time': '2021-05-20T03:56:19.406651Z'}
{'type': 'l2update', 'product_id': 'BTC-USD', 'changes': [['buy', '38297.14', '0.01197510']], 'time': '2021-05-20T03:56:19.406651Z'}
{'type': 'l2update', 'product_id': 'BTC-USD', 'changes': [['sell', '38372.37', '0.00000000']], 'time': '2021-05-20T03:56:19.408911Z'}
