{'type': 'l2update', 'product_id': 'BTC-USD', 'changes': [['sell', '38323.42', '0.50000000']], 'time': '2021-05-20T03:55:54.781014Z'}
{'type': 'l2update', 'product_id': 'BTC-USD', 'changes': [['sell', '38483.49', '0.00000000']], 'time': '2021-05-20T03:55:54.789244Z'}
{'type': 'l2update', 'product_id': 'BTC-USD', 'changes': [['sell', '38341.68', '0.00000000']], 'time': '2021-05-20T03:55:54.790649Z'}
{'type': 'l2update', 'product_id': 'BTC-USD', 'changes': [['buy', '38284.90', '0.00000000']], 'time': '2021-05-20T03:55:54.793213Z'}
{'type': 'l2update', 'product_id': 'BTC-USD', 'changes': [['buy', '38148.65', '0.05162437']], 'time': '2021-05-20T03:55:54.797002Z'}
{'type': 'l2update', 'product_id': 'BTC-USD', 'changes': [['sell', '38408.82', '0.01000000']], 'time': '2021-05-20T03:55:54.805646Z'}
{'type': 'l2update', 'product_id': 'BTC-USD', 'changes': [['sell', '38342.93', '0.02000000']], 'time': '2021-05-20T03:55:54.805906Z'}
{'type': 'l2update', 'product_id': 'BTC-USD', 'changes': [['buy', '38250.01', '0.00000000']], 'time': '2021-05-20T03:55:54.806672Z'}
{'type': 'l2update', 'product_id': 'BTC-USD', 'changes': [['buy', '38282.86', '0.48220000']], 'time': '2021-05-20T03:55:54.811918Z'}
{'type': 'l2update', 'product_id': 'BTC-USD', 'changes': [['buy', '37498.05', '0.06535600']], 'time': '2021-05-20T03:55:54.812118Z'}
{'type': 'l2update', 'product_id': 'BTC-USD', 'changes': [['sell', '38521.90', '0.01000000']], 'time': '2021-05-20T03:55:54.812132Z'}
{'type': 'l2update', 'product_id': 'BTC-USD', 'changes': [['sell', '38408.82', '0.00000000']], 'time': '2021-05-20T03:55:54.821597Z'}
{'type': 'l2update', 'product_id': 'BTC-USD', 'changes': [['sell', '39109.11', '0.06317598']], 'time': '2021-05-20T03:55:54.823101Z'}
{'type': 'l2update', 'product_id': 'BTC-USD', 'changes': [['sell', '38456.36', '0.01263289']], 'time': '2021-05-20T03:55:54.842508Z'}
{'type': 'l2update', 'product_id': 'BTC-USD', 'changes': [['buy', '38143.81', '0.00000000']], 'time': '2021-05-20T03:55:54.854004Z'}
{'type': 'l2update', 'product_id': 'BTC-USD', 'changes': [['sell', '38346.54', '0.04993952']], 'time': '2021-05-20T03:55:54.860726Z'}
{'type': 'l2update', 'product_id': 'BTC-USD', 'changes': [['sell', '38344.51', '0.00000000']], 'time': '2021-05-20T03:55:54.872766Z'}
{'type': 'l2update', 'product_id': 'BTC-USD', 'changes': [['sell', '38323.42', '0.00000000']], 'time': '2021-05-20T03:55:54.873286Z'}
{'type': 'l2update', 'product_id': 'BTC-USD', 'changes': [['sell', '38485.38', '0.00000000']], 'time': '2021-05-20T03:55:54.873371Z'}
{'type': 'l2update', 'product_id': 'BTC-USD', 'changes': [['sell', '38455.42', '0.00000000']], 'time': '2021-05-20T03:55:54.882168Z'}
{'type': 'l2update', 'product_id': 'BTC-USD', 'changes': [['sell', '38317.72', '0.50000000']], 'time': '2021-05-20T03:55:54.887522Z'}
{'type': 'l2update', 'product_id': 'BTC-USD', 'changes': [['sell', '38345.77', '0.43790000']], 'time': '2021-05-20T03:55:54.887908Z'}
{'type': 'l2update', 'product_id': 'BTC-USD', 'changes': [['sell', '38472.21', '0.01000000']], 'time': '2021-05-20T03:55:54.887959Z'}
{'type': 'l2update', 'product_id': 'BTC-USD', 'changes': [['sell', '38317.77', '0.00000000']], 'time': '2021-05-20T03:55:54.893511Z'}
{'type': 'l2update', 'product_id': 'BTC-USD', 'changes': [['buy', '38282.86', '0.00000000']], 'time': '2021-05-20T03:55:54.893994Z'}
{'type': 'l2update', 'product_id': 'BTC-USD', 'changes': [['sell', '38317.73', '0.00000000']], 'time': '2021-05-20T03:55:54.896460Z'}
{'type': 'l2update', 'product_id': 'BTC-USD', 'changes': [['sell', '38474.61', '0.01000000']], 'time': '2021-05-20T03:55:54.902000Z'}
{'type': 'l2update', 'product_id': 'BTC-USD', 'changes': [['buy', '38260.45', '0.00000000']], 'time': '2021-05-20T03:55:54.903429Z'}
{'type': 'l2update', 'product_id': 'BTC-USD', 'changes': [['buy', '38179.55', '0.00000000']], 'time': '2021-05-20T03:55:54.905119Z'}
{'type': 'l2update', 'product_id': 'BTC-USD', 'changes': [['sell', '38381.15', '0.00000000']], 'time': '2021-05-20T03:55:54.909219Z'}
{'type': 'l2update', 'product_id': 'BTC-USD', 'changes': [['buy', '38284.14', '0.00000000']], 'time': '2021-05-20T03:55:54.910658Z'}
{'type': 'l2update', 'product_id': 'BTC-USD', 'changes': [['sell', '38325.41', '0.00000000']], 'time': '2021-05-20T03:55:54.910658Z'}
{'type': 'l2update', 'product_id': 'BTC-USD', 'changes': [['sell', '38317.72', '0.00000000']], 'time': '2021-05-20T03:55:54.913016Z'}
{'type': 'l2update', 'product_id': 'BTC-USD', 'changes': [['sell', '38352.97', '0.00000000']], 'time': '2021-05-20T03:55:54.913776Z'}
{'type': 'l2update', 'product_id': 'BTC-USD', 'changes': [['sell', '38333.83', '1.30555569']], 'time': '2021-05-20T03:55:54.914378Z'}
{'type': 'l2update', 'product_id': 'BTC-USD', 'changes': [['buy', '38306.08', '0.04911045']], 'time': '2021-05-20T03:55:54.917145Z'}
{'type': 'l2update', 'product_id': 'BTC-USD', 'changes': [['sell', '38319.85', '0.04947719']], 'time': '2021-05-20T03:55:54.917248Z'}
{'type': 'l2update', 'product_id': 'BTC-USD', 'changes': [['buy', '38314.18', '0.01492000']], 'time': '2021-05-20T03:55:54.921228Z'}
{'type': 'l2update', 'product_id': 'BTC-USD', 'changes': [['sell', '38317.76', '0.00000000']], 'time': '2021-05-20T03:55:54.923112Z'}
{'type': 'l2update', 'product_id': 'BTC-USD', 'changes': [['buy', '38308.20', '0.07186082']], 'time': '2021-05-20T03:55:54.928807Z'}
{'type': 'l2update', 'product_id': 'BTC-USD', 'changes': [['sell', '38323.49', '0.00000000']], 'time': '2021-05-20T03:55:54.929075Z'}
{'type': 'l2update', 'product_id': 'BTC-USD', 'changes': [['sell', '38317.71', '0.18981474']], 'time': '2021-05-20T03:55:54.930107Z'}
{'type': 'l2update', 'product_id': 'BTC-USD', 'changes': [['buy', '38191.95', '0.01000000']], 'time': '2021-05-20T03:55:54.930268Z'}
{'type': 'l2update', 'product_id': 'BTC-USD', 'changes': [['buy', '38283.56', '0.39490431']], 'time': '2021-05-20T03:55:54.930418Z'}
{'type': 'l2update', 'product_id': 'BTC-USD', 'changes': [['sell', '38321.01', '0.50000000']], 'time': '2021-05-20T03:55:54.931131Z'}
{'type': 'l2update', 'product_id': 'BTC-USD', 'changes': [['sell', '38333.82', '0.00000000']], 'time': '2021-05-20T03:55:54.932852Z'}
{'type': 'l2update', 'product_id': 'BTC-USD', 'changes': [['buy', '38301.81', '0.00000000']], 'time': '2021-05-20T03:55:54.933346Z'}
{'type': 'l2update', 'product_id': 'BTC-USD', 'changes': [['sell', '38323.48', '0.00000000']], 'time': '2021-05-20T03:55:54.933649Z'}
{'type': 'l2update', 'product_id': 'BTC-USD', 'changes': [['buy', '38270.60', '0.00000000']], 'time': '2021-05-20T03:55:54.934708Z'}
{'type': 'l2update', 'product_id': 'BTC-USD', 'changes': [['buy', '38250.33', '1.28246240']], 'time': '2021-05-20T03:55:54.935454Z'}
{'type': 'l2update', 'product_id': 'BTC-USD', 'changes': [['buy', '38314.18', '0.04382000']], 'time': '2021-05-20T03:55:54.935666Z'}
{'type': 'l2update', 'product_id': 'BTC-USD', 'changes': [['buy', '38314.18', '0.14382000']], 'time': '2021-05-20T03:55:54.935832Z'}
{'type': 'l2update', 'product_id': 'BTC-USD', 'changes': [['buy', '38314.18', '0.19113571']], 'time': '2021-05-20T03:55:54.936211Z'}
{'type': 'l2update', 'product_id': 'BTC-USD', 'changes': [['sell', '38383.62', '0.20080000']], 'time': '2021-05-20T03:55:54.941846Z'}
{'type': 'l2update', 'product_id': 'BTC-USD', 'changes': [['sell', '38370.99', '0.61482416']], 'time': '2021-05-20T03:55:54.946455Z'}
{'type': 'l2update', 'product_id': 'BTC-USD', 'changes': [['buy', '38290.42', '0.02611619']], 'time': '2021-05-20T03:55:54.946627Z'}
{'type': 'l2update', 'product_id': 'BTC-USD', 'changes': [['sell', '38343.92', '0.05000000']], 'time': '2021-05-20T03:55:54.946697Z'}
{'type': 'l2update', 'product_id': 'BTC-USD', 'changes': [['buy', '38303.96', '0.84700000']], 'time': '2021-05-20T03:55:54.948049Z'}
{'type': 'l2update', 'product_id': 'BTC-USD', 'changes': [['buy', '38285.71', '0.05424340']], 'time': '2021-05-20T03:55:54.948096Z'}
{'type': 'l2update', 'product_id': 'BTC-USD', 'changes': [['sell', '38333.94', '0.05732778']], 'time': '2021-05-20T03:55:54.948096Z'}
{'type': 'l2update', 'product_id': 'BTC-USD', 'changes': [['sell', '38369.98', '0.00000000']], 'time': '2021-05-20T03:55:54.948451Z'}
{'type': 'l2update', 'product_id': 'BTC-USD', 'changes': [['sell', '38321.01', '2.98969908']], 'time': '2021-05-20T03:55:54.948705Z'}
{'type': 'l2update', 'product_id': 'BTC-USD', 'changes': [['sell', '38407.60', '0.00000000']], 'time': '2021-05-20T03:55:54.951263Z'}
{'type': 'l2update', 'product_id': 'BTC-USD', 'changes': [['buy', '38314.18', '0.39113571']], 'time': '2021-05-20T03:55:54.951953Z'}
{'type': 'l2update', 'product_id': 'BTC-USD', 'changes': [['buy', '38301.97', '0.15100000']], 'time': '2021-05-20T03:55:54.952167Z'}
{'type': 'l2update', 'product_id': 'BTC-USD', 'changes': [['sell', '38336.92', '0.06845011']], 'time': '2021-05-20T03:55:54.952508Z'}
{'type': 'l2update', 'product_id': 'BTC-USD', 'changes': [['sell', '38321.01', '2.48969908']], 'time': '2021-05-20T03:55:54.952671Z'}
{'type': 'l2update', 'product_id': 'BTC-USD', 'changes': [['sell', '38427.12', '0.00000000']], 'time': '2021-05-20T03:55:54.956675Z'}
{'type': 'l2update', 'product_id': 'BTC-USD', 'changes': [['buy', '38298.47', '0.00000000']], 'time': '2021-05-20T03:55:54.956690Z'}
{'type': 'l2update', 'product_id': 'BTC-USD', 'changes': [['sell', '38366.00', '2.54400000']], 'time': '2021-05-20T03:55:54.960263Z'}
{'type': 'l2update', 'product_id': 'BTC-USD', 'changes': [['sell', '38314.19', '0.00000000']], 'time': '2021-05-20T03:55:54.962908Z'}
{'type': 'l2update', 'product_id': 'BTC-USD', 'changes': [['buy', '38273.49', '0.00000000']], 'time': '2021-05-20T03:55:54.965383Z'}
{'type': 'l2update', 'product_id': 'BTC-USD', 'changes': [['buy', '38314.18', '0.45013571']], 'time': '2021-05-20T03:55:54.965678Z'}
{'type': 'l2update', 'product_id': 'BTC-USD', 'changes': [['buy', '38314.18', '0.40282000']], 'time': '2021-05-20T03:55:54.968643Z'}
{'type': 'l2update', 'product_id': 'BTC-USD', 'changes': [['sell', '38345.77', '0.00000000']], 'time': '2021-05-20T03:55:54.968902Z'}
{'type': 'l2update', 'product_id': 'BTC-USD', 'changes': [['buy', '38314.18', '0.38790000']], 'time': '2021-05-20T03:55:54.969689Z'}
{'type': 'l2update', 'product_id': 'BTC-USD', 'changes': [['sell', '38408.43', '0.00000000']], 'time': '2021-05-20T03:55:54.972972Z'}
{'type': 'l2update', 'product_id': 'BTC-USD', 'changes': [['buy', '38314.18', '0.32890000']], 'time': '2021-05-20T03:55:54.973223Z'}
{'type': 'l2update', 'product_id': 'BTC-USD', 'changes': [['sell', '38321.01', '0.00000000']], 'time': '2021-05-20T03:55:54.974917Z'}
{'type': 'l2update', 'product_id': 'BTC-USD', 'changes': [['buy', '38314.59', '0.02728429']], 'time': '2021-05-20T03:55:54.975393Z'}
{'type': 'l2update', 'product_id': 'BTC-USD', 'changes': [['sell', '38390.10', '0.06600000']], 'time': '2021-05-20T03:55:54.975601Z'}
{'type': 'l2update', 'product_id': 'BTC-USD', 'changes': [['sell', '38329.61', '0.50000000']], 'time': '2021-05-20T03:55:54.976240Z'}
{'type': 'l2update', 'product_id': 'BTC-USD', 'changes': [['sell', '38371.63', '0.00000000']], 'time': '2021-05-20T03:55:54.976556Z'}
{'type': 'l2update', 'product_id': 'BTC-USD', 'changes': [['sell', '38413.54', '0.01301624']], 'time': '2021-05-20T03:55:54.978938Z'}
{'type': 'l2update', 'product_id': 'BTC-USD', 'changes': [['buy', '38314.59', '0.22728429']], 'time': '2021-05-20T03:55:54.979075Z'}
{'type': 'l2update', 'product_id': 'BTC-USD', 'changes': [['buy', '38314.59', '0.28628429']], 'time': '2021-05-20T03:55:54.979094Z'}
{'type': 'l2update', 'product_id': 'BTC-USD', 'changes': [['buy', '38314.59', '0.31518429']], 'time': '2021-05-20T03:55:54.979213Z'}
{'type': 'l2update', 'product_id': 'BTC-USD', 'changes': [['sell', '38319.85', '0.00000000']], 'time': '2021-05-20T03:55:54.979293Z'}
{'type': 'l2update', 'product_id': 'BTC-USD', 'changes': [['sell', '38346.54', '0.00000000']], 'time': '2021-05-20T03:55:54.980247Z'}
{'type': 'l2update', 'product_id': 'BTC-USD', 'changes': [['sell', '38314.60', '0.00000000']], 'time': '2021-05-20T03:55:54.980612Z'}
{'type': 'l2update', 'product_id': 'BTC-USD', 'changes': [['buy', '38303.97', '0.40135082']], 'time': '2021-05-20T03:55:54.984869Z'}
{'type': 'l2update', 'product_id': 'BTC-USD', 'changes': [['buy', '38314.59', '0.33521571']], 'time': '2021-05-20T03:55:54.985743Z'}
{'type': 'l2update', 'product_id': 'BTC-USD', 'changes': [['buy', '38293.39', '0.46680000']], 'time': '2021-05-20T03:55:54.985829Z'}
{'type': 'l2update', 'product_id': 'BTC-USD', 'changes': [['buy', '38155.16', '0.04884502']], 'time': '2021-05-20T03:55:54.985876Z'}
{'type': 'l2update', 'product_id': 'BTC-USD', 'changes': [['sell', '38317.71', '0.00000000']], 'time': '2021-05-20T03:55:54.987761Z'}
{'type': 'l2update', 'product_id': 'BTC-USD', 'changes': [['buy', '38314.59', '0.30793142']], 'time': '2021-05-20T03:55:54.988028Z'}
{'type': 'l2update', 'product_id': 'BTC-USD', 'changes': [['buy', '38317.70', '0.02728429']], 'time': '2021-05-20T03:55:54.994304Z'}
{'type': 'l2update', 'product_id': 'BTC-USD', 'changes': [['sell', '38323.42', '2.48969908']], 'time': '2021-05-20T03:55:54.994605Z'}
{'type': 'l2update', 'product_id': 'BTC-USD', 'changes': [['buy', '38314.59', '0.32285142']], 'time': '2021-05-20T03:55:54.994781Z'}
{'type': 'l2update', 'product_id': 'BTC-USD', 'changes': [['buy', '38314.59', '0.52285142']], 'time': '2021-05-20T03:55:54.995020Z'}
{'type': 'l2update', 'product_id': 'BTC-USD', 'changes': [['buy', '38314.59', '0.62285142']], 'time': '2021-05-20T03:55:54.995209Z'}
{'type': 'l2update', 'product_id': 'BTC-USD', 'changes': [['buy', '38308.20', '0.00000000']], 'time': '2021-05-20T03:55:54.996277Z'}
{'type': 'l2update', 'product_id': 'BTC-USD', 'changes': [['buy', '38293.39', '0.00000000']], 'time': '2021-05-20T03:55:54.996638Z'}
{'type': 'l2update', 'product_id': 'BTC-USD', 'changes': [['sell', '38473.57', '0.00000000']], 'time': '2021-05-20T03:55:54.997691Z'}
{'type': 'l2update', 'product_id': 'BTC-USD', 'changes': [['sell', '38413.54', '0.00000000']], 'time': '2021-05-20T03:55:54.998194Z'}
{'type': 'l2update', 'product_id': 'BTC-USD', 'changes': [['buy', '38144.49', '0.00000000']], 'time': '2021-05-20T03:55:54.999904Z'}
{'type': 'l2update', 'product_id': 'BTC-USD', 'changes': [['buy', '38295.26', '0.06845011']], 'time': '2021-05-20T03:55:55.001519Z'}
{'type': 'l2update', 'product_id': 'BTC-USD', 'changes': [['buy', '38289.13', '0.00000000']], 'time': '2021-05-20T03:55:55.002216Z'}
{'type': 'l2update', 'product_id': 'BTC-USD', 'changes': [['sell', '38472.21', '0.00000000']], 'time': '2021-05-20T03:55:55.002585Z'}
{'type': 'l2update', 'product_id': 'BTC-USD', 'changes': [['buy', '38314.59', '0.60282000']], 'time': '2021-05-20T03:55:55.002800Z'}
{'type': 'l2update', 'product_id': 'BTC-USD', 'changes': [['buy', '38314.18', '0.30000000']], 'time': '2021-05-20T03:55:55.003360Z'}
{'type': 'l2update', 'product_id': 'BTC-USD', 'changes': [['buy', '38314.59', '0.57392000']], 'time': '2021-05-20T03:55:55.003691Z'}
{'type': 'l2update', 'product_id': 'BTC-USD', 'changes': [['buy', '38314.59', '0.55900000']], 'time': '2021-05-20T03:55:55.004618Z'}
{'type': 'l2update', 'product_id': 'BTC-USD', 'changes': [['sell', '38323.43', '0.00000000']], 'time': '2021-05-20T03:55:55.006080Z'}
{'type': 'l2update', 'product_id': 'BTC-USD', 'changes': [['sell', '38420.56', '0.00000000']], 'time': '2021-05-20T03:55:55.006580Z'}
{'type': 'l2update', 'product_id': 'BTC-USD', 'changes': [['buy', '38285.71', '0.00000000']], 'time': '2021-05-20T03:55:55.006954Z'}
{'type': 'l2update', 'product_id': 'BTC-USD', 'changes': [['sell', '38333.94', '0.00000000']], 'time': '2021-05-20T03:55:55.006954Z'}
{'type': 'l2update', 'product_id': 'BTC-USD', 'changes': [['buy', '38317.70', '0.12728429']], 'time': '2021-05-20T03:55:55.013181Z'}
{'type': 'l2update', 'product_id': 'BTC-USD', 'changes': [['sell', '38323.41', '0.18981474']], 'time': '2021-05-20T03:55:55.013877Z'}
{'type': 'l2update', 'product_id': 'BTC-USD', 'changes': [['sell', '38336.93', '0.00000000']], 'time': '2021-05-20T03:55:55.015150Z'}
{'type': 'l2update', 'product_id': 'BTC-USD', 'changes': [['buy', '38317.70', '0.10000000']], 'time': '2021-05-20T03:55:55.015256Z'}
{'type': 'l2update', 'product_id': 'BTC-USD', 'changes': [['buy', '38155.36', '0.00000000']], 'time': '2021-05-20T03:55:55.016555Z'}
{'type': 'l2update', 'product_id': 'BTC-USD', 'changes': [['sell', '38368.71', '0.00000000']], 'time': '2021-05-20T03:55:55.017137Z'}
{'type': 'l2update', 'product_id': 'BTC-USD', 'changes': [['sell', '38344.22', '0.00000000']], 'time': '2021-05-20T03:55:55.017302Z'}
{'type': 'l2update', 'product_id': 'BTC-USD', 'changes': [['sell', '38340.99', '0.00000000']], 'time': '2021-05-20T03:55:55.017302Z'}
{'type': 'l2update', 'product_id': 'BTC-USD', 'changes': [['buy', '38187.92', '0.00000000']], 'time': '2021-05-20T03:55:55.017302Z'}
{'type': 'l2update', 'product_id': 'BTC-USD', 'changes': [['buy', '38231.26', '0.00000000']], 'time': '2021-05-20T03:55:55.017302Z'}
{'type': 'l2update', 'product_id': 'BTC-USD', 'changes': [['buy', '38242.41', '0.00000000']], 'time': '2021-05-20T03:55:55.017302Z'}
{'type': 'l2update', 'product_id': 'BTC-USD', 'changes': [['buy', '38247.52', '0.00000000']], 'time': '2021-05-20T03:55:55.017302Z'}
{'type': 'l2update', 'product_id': 'BTC-USD', 'changes': [['sell', '38340.70', '0.06845011']], 'time': '2021-05-20T03:55:55.026455Z'}
{'type': 'l2update', 'product_id': 'BTC-USD', 'changes': [['sell', '38450.26', '0.01000000']], 'time': '2021-05-20T03:55:55.026706Z'}
{'type': 'l2update', 'product_id': 'BTC-USD', 'changes': [['buy', '38321.01', '0.02728429']], 'time': '2021-05-20T03:55:55.026769Z'}
{'type': 'l2update', 'product_id': 'BTC-USD', 'changes': [['sell', '38323.42', '0.00000000']], 'time': '2021-05-20T03:55:55.026885Z'}
{'type': 'l2update', 'product_id': 'BTC-USD', 'changes': [['buy', '38220.60', '0.35030393']], 'time': '2021-05-20T03:55:55.031612Z'}
{'type': 'l2update', 'product_id': 'BTC-USD', 'changes': [['buy', '38226.47', '0.42949806']], 'time': '2021-05-20T03:55:55.031612Z'}
{'type': 'l2update', 'product_id': 'BTC-USD', 'changes': [['buy', '38232.28', '0.31297093']], 'time': '2021-05-20T03:55:55.031612Z'}
{'type': 'l2update', 'product_id': 'BTC-USD', 'changes': [['buy', '38237.64', '0.14360275']], 'time': '2021-05-20T03:55:55.031612Z'}
{'type': 'l2update', 'product_id': 'BTC-USD', 'changes': [['buy', '38314.18', '0.38917588']], 'time': '2021-05-20T03:55:55.032166Z'}
{'type': 'l2update', 'product_id': 'BTC-USD', 'changes': [['sell', '38346.62', '0.10000000']], 'time': '2021-05-20T03:55:55.032188Z'}
{'type': 'l2update', 'product_id': 'BTC-USD', 'changes': [['sell', '38457.76', '0.01000000']], 'time': '2021-05-20T03:55:55.032247Z'}
{'type': 'l2update', 'product_id': 'BTC-USD', 'changes': [['sell', '38404.04', '0.00000000']], 'time': '2021-05-20T03:55:55.034357Z'}
{'type': 'l2update', 'product_id': 'BTC-USD', 'changes': [['sell', '38343.92', '0.00000000']], 'time': '2021-05-20T03:55:55.034462Z'}
{'type': 'l2update', 'product_id': 'BTC-USD', 'changes': [['sell', '38407.19', '0.00000000']], 'time': '2021-05-20T03:55:55.035081Z'}
{'type': 'l2update', 'product_id': 'BTC-USD', 'changes': [['buy', '38321.01', '0.04220429']], 'time': '2021-05-20T03:55:55.039736Z'}
{'type': 'l2update', 'product_id': 'BTC-USD', 'changes': [['buy', '38317.70', '0.30000000']], 'time': '2021-05-20T03:55:55.040020Z'}
{'type': 'l2update', 'product_id': 'BTC-USD', 'changes': [['buy', '38321.01', '0.06223571']], 'time': '2021-05-20T03:55:55.040053Z'}
{'type': 'l2update', 'product_id': 'BTC-USD', 'changes': [['buy', '38168.26', '0.01000000']], 'time': '2021-05-20T03:55:55.040129Z'}
{'type': 'l2update', 'product_id': 'BTC-USD', 'changes': [['sell', '38360.40', '0.00000000']], 'time': '2021-05-20T03:55:55.043143Z'}
{'type': 'l2update', 'product_id': 'BTC-USD', 'changes': [['sell', '38352.57', '0.00000000']], 'time': '2021-05-20T03:55:55.043243Z'}
{'type': 'l2update', 'product_id': 'BTC-USD', 'changes': [['sell', '38350.11', '0.00000000']], 'time': '2021-05-20T03:55:55.043243Z'}
{'type': 'l2update', 'product_id': 'BTC-USD', 'changes': [['sell', '38340.71', '0.00000000']], 'time': '2021-05-20T03:55:55.043914Z'}
{'type': 'l2update', 'product_id': 'BTC-USD', 'changes': [['buy', '38182.07', '0.39103232']], 'time': '2021-05-20T03:55:55.043914Z'}
{'type': 'l2update', 'product_id': 'BTC-USD', 'changes': [['buy', '38195.50', '0.00000000']], 'time': '2021-05-20T03:55:55.043914Z'}
{'type': 'l2update', 'product_id': 'BTC-USD', 'changes': [['buy', '38201.30', '0.00000000']], 'time': '2021-05-20T03:55:55.043914Z'}
{'type': 'l2update', 'product_id': 'BTC-USD', 'changes': [['buy', '38201.93', '0.00000000']], 'time': '2021-05-20T03:55:55.043914Z'}
{'type': 'l2update', 'product_id': 'BTC-USD', 'changes': [['buy', '38148.65', '0.00000000']], 'time': '2021-05-20T03:55:55.044371Z'}
{'type': 'l2update', 'product_id': 'BTC-USD', 'changes': [['sell', '38435.39', '0.01300884']], 'time': '2021-05-20T03:55:55.045055Z'}
{'type': 'l2update', 'product_id': 'BTC-USD', 'changes': [['sell', '38333.82', '2.48969908']], 'time': '2021-05-20T03:55:55.047111Z'}
{'type': 'l2update', 'product_id': 'BTC-USD', 'changes': [['buy', '38321.01', '0.09113571']], 'time': '2021-05-20T03:55:55.047362Z'}
{'type': 'l2update', 'product_id': 'BTC-USD', 'changes': [['sell', '38581.82', '0.00000000']], 'time': '2021-05-20T03:55:55.050195Z'}
{'type': 'l2update', 'product_id': 'BTC-USD', 'changes': [['sell', '38398.51', '0.01000000']], 'time': '2021-05-20T03:55:55.051026Z'}
{'type': 'l2update', 'product_id': 'BTC-USD', 'changes': [['sell', '38336.92', '0.00000000']], 'time': '2021-05-20T03:55:55.052089Z'}
{'type': 'l2update', 'product_id': 'BTC-USD', 'changes': [['sell', '38348.11', '0.14025653']], 'time': '2021-05-20T03:55:55.055652Z'}
{'type': 'l2update', 'product_id': 'BTC-USD', 'changes': [['buy', '38314.18', '0.30000000']], 'time': '2021-05-20T03:55:55.056756Z'}
{'type': 'l2update', 'product_id': 'BTC-USD', 'changes': [['buy', '38295.02', '0.06421591']], 'time': '2021-05-20T03:55:55.060376Z'}
{'type': 'l2update', 'product_id': 'BTC-USD', 'changes': [['sell', '38337.33', '0.04145757']], 'time': '2021-05-20T03:55:55.060376Z'}
{'type': 'l2update', 'product_id': 'BTC-USD', 'changes': [['buy', '38298.47', '0.06845011']], 'time': '2021-05-20T03:55:55.064997Z'}
{'type': 'l2update', 'product_id': 'BTC-USD', 'changes': [['sell', '38329.61', '0.00000000']], 'time': '2021-05-20T03:55:55.065159Z'}
{'type': 'l2update', 'product_id': 'BTC-USD', 'changes': [['sell', '38353.03', '0.42230000']], 'time': '2021-05-20T03:55:55.066839Z'}
{'type': 'l2update', 'product_id': 'BTC-USD', 'changes': [['buy', '38295.26', '0.00000000']], 'time': '2021-05-20T03:55:55.066921Z'}
{'type': 'l2update', 'product_id': 'BTC-USD', 'changes': [['sell', '38484.28', '0.00000000']], 'time': '2021-05-20T03:55:55.067968Z'}
{'type': 'l2update', 'product_id': 'BTC-USD', 'changes': [['sell', '38457.76', '0.00000000']], 'time': '2021-05-20T03:55:55.077631Z'}
{'type': 'l2update', 'product_id': 'BTC-USD', 'changes': [['sell', '38402.91', '0.00000000']], 'time': '2021-05-20T03:55:55.077893Z'}
{'type': 'l2update', 'product_id': 'BTC-USD', 'changes': [['buy', '38265.93', '0.05447732']], 'time': '2021-05-20T03:55:55.084635Z'}
{'type': 'l2update', 'product_id': 'BTC-USD', 'changes': [['buy', '38308.20', '0.52100000']], 'time': '2021-05-20T03:55:55.084937Z'}
{'type': 'l2update', 'product_id': 'BTC-USD', 'changes': [['sell', '38353.03', '0.00000000']], 'time': '2021-05-20T03:55:55.085956Z'}
{'type': 'l2update', 'product_id': 'BTC-USD', 'changes': [['sell', '38333.82', '2.98969908']], 'time': '2021-05-20T03:55:55.091097Z'}
{'type': 'l2update', 'product_id': 'BTC-USD', 'changes': [['buy', '38262.56', '0.06735169']], 'time': '2021-05-20T03:55:55.092304Z'}
{'type': 'l2update', 'product_id': 'BTC-USD', 'changes': [['sell', '38440.77', '0.02922346']], 'time': '2021-05-20T03:55:55.092334Z'}
{'type': 'l2update', 'product_id': 'BTC-USD', 'changes': [['buy', '38220.94', '0.02922346']], 'time': '2021-05-20T03:55:55.092334Z'}
{'type': 'l2update', 'product_id': 'BTC-USD', 'changes': [['buy', '38228.29', '0.05667607']], 'time': '2021-05-20T03:55:55.092334Z'}
{'type': 'l2update', 'product_id': 'BTC-USD', 'changes': [['buy', '38238.55', '0.03586941']], 'time': '2021-05-20T03:55:55.092334Z'}
{'type': 'l2update', 'product_id': 'BTC-USD', 'changes': [['buy', '38244.04', '0.03839292']], 'time': '2021-05-20T03:55:55.092334Z'}
{'type': 'l2update', 'product_id': 'BTC-USD', 'changes': [['buy', '38252.44', '0.03698957']], 'time': '2021-05-20T03:55:55.092334Z'}
{'type': 'l2update', 'product_id': 'BTC-USD', 'changes': [['buy', '38259.37', '0.03676004']], 'time': '2021-05-20T03:55:55.092334Z'}
{'type': 'l2update', 'product_id': 'BTC-USD', 'changes': [['buy', '38268.66', '0.03412278']], 'time': '2021-05-20T03:55:55.092334Z'}
{'type': 'l2update', 'product_id': 'BTC-USD', 'changes': [['buy', '38273.02', '0.02824212']], 'time': '2021-05-20T03:55:55.092334Z'}
{'type': 'l2update', 'product_id': 'BTC-USD', 'changes': [['buy', '38277.19', '0.01059612']], 'time': '2021-05-20T03:55:55.092334Z'}
{'type': 'l2update', 'product_id': 'BTC-USD', 'changes': [['sell', '38323.41', '0.00000000']], 'time': '2021-05-20T03:55:55.095231Z'}
{'type': 'l2update', 'product_id': 'BTC-USD', 'changes': [['buy', '38284.92', '0.02000000']], 'time': '2021-05-20T03:55:55.096578Z'}
{'type': 'l2update', 'product_id': 'BTC-USD', 'changes': [['sell', '38594.92', '0.12955075']], 'time': '2021-05-20T03:55:55.099686Z'}
{'type': 'l2update', 'product_id': 'BTC-USD', 'changes': [['sell', '38367.35', '0.00000000']], 'time': '2021-05-20T03:55:55.100802Z'}
{'type': 'l2update', 'product_id': 'BTC-USD', 'changes': [['sell', '38346.62', '0.00000000']], 'time': '2021-05-20T03:55:55.102415Z'}
{'type': 'l2update', 'product_id': 'BTC-USD', 'changes': [['sell', '38470.93', '0.01000000']], 'time': '2021-05-20T03:55:55.103827Z'}
{'type': 'l2update', 'product_id': 'BTC-USD', 'changes': [['buy', '38227.37', '0.00000000']], 'time': '2021-05-20T03:55:55.109761Z'}
{'type': 'l2update', 'product_id': 'BTC-USD', 'changes': [['buy', '38284.92', '0.00000000']], 'time': '2021-05-20T03:55:55.110334Z'}
{'type': 'l2update', 'product_id': 'BTC-USD', 'changes': [['buy', '38174.13', '0.00000000']], 'time': '2021-05-20T03:55:55.110824Z'}
{'type': 'l2update', 'product_id': 'BTC-USD', 'changes': [['buy', '38175.08', '0.00000000']], 'time': '2021-05-20T03:55:55.110824Z'}
{'type': 'l2update', 'product_id': 'BTC-USD', 'changes': [['buy', '38181.99', '0.00000000']], 'time': '2021-05-20T03:55:55.110824Z'}
{'type': 'l2update', 'product_id': 'BTC-USD', 'changes': [['buy', '38212.71', '0.03676004']], 'time': '2021-05-20T03:55:55.110824Z'}
{'type': 'l2update', 'product_id': 'BTC-USD', 'changes': [['buy', '38212.71', '0.00000000']], 'time': '2021-05-20T03:55:55.110824Z'}
{'type': 'l2update', 'product_id': 'BTC-USD', 'changes': [['buy', '38226.98', '0.00000000']], 'time': '2021-05-20T03:55:55.110824Z'}
{'type': 'l2update', 'product_id': 'BTC-USD', 'changes': [['buy', '38228.29', '0.02843395']], 'time': '2021-05-20T03:55:55.110824Z'}
{'type': 'l2update', 'product_id': 'BTC-USD', 'changes': [['buy', '38252.44', '0.02639345']], 'time': '2021-05-20T03:55:55.110824Z'}
{'type': 'l2update', 'product_id': 'BTC-USD', 'changes': [['sell', '38505.71', '0.01885050']], 'time': '2021-05-20T03:55:55.112637Z'}
{'type': 'l2update', 'product_id': 'BTC-USD', 'changes': [['buy', '38290.09', '0.45090000']], 'time': '2021-05-20T03:55:55.113500Z'}
{'type': 'l2update', 'product_id': 'BTC-USD', 'changes': [['buy', '38314.60', '0.08917588']], 'time': '2021-05-20T03:55:55.113954Z'}
{'type': 'l2update', 'product_id': 'BTC-USD', 'changes': [['buy', '38162.39', '0.00000000']], 'time': '2021-05-20T03:55:55.116795Z'}
{'type': 'l2update', 'product_id': 'BTC-USD', 'changes': [['sell', '38343.93', '0.00000000']], 'time': '2021-05-20T03:55:55.118207Z'}
{'type': 'l2update', 'product_id': 'BTC-USD', 'changes': [['buy', '38321.01', '0.74113571']], 'time': '2021-05-20T03:55:55.118622Z'}
{'type': 'l2update', 'product_id': 'BTC-USD', 'changes': [['sell', '38348.12', '0.00000000']], 'time': '2021-05-20T03:55:55.120041Z'}
{'type': 'l2update', 'product_id': 'BTC-USD', 'changes': [['buy', '38182.07', '0.00000000']], 'time': '2021-05-20T03:55:55.120041Z'}
{'type': 'l2update', 'product_id': 'BTC-USD', 'changes': [['sell', '38333.82', '0.50000000']], 'time': '2021-05-20T03:55:55.123455Z'}
{'type': 'l2update', 'product_id': 'BTC-USD', 'changes': [['sell', '38353.24', '0.00000000']], 'time': '2021-05-20T03:55:55.123984Z'}
{'type': 'l2update', 'product_id': 'BTC-USD', 'changes': [['buy', '38290.09', '0.00000000']], 'time': '2021-05-20T03:55:55.129170Z'}
{'type': 'l2update', 'product_id': 'BTC-USD', 'changes': [['sell', '38357.07', '0.00000000']], 'time': '2021-05-20T03:55:55.135791Z'}
{'type': 'l2update', 'product_id': 'BTC-USD', 'changes': [['sell', '38340.70', '0.13910626']], 'time': '2021-05-20T03:55:55.136253Z'}
{'type': 'l2update', 'product_id': 'BTC-USD', 'changes': [['sell', '38353.94', '0.00000000']], 'time': '2021-05-20T03:55:55.138067Z'}
{'type': 'l2update', 'product_id': 'BTC-USD', 'changes': [['buy', '38295.25', '0.84700000']], 'time': '2021-05-20T03:55:55.139148Z'}
{'type': 'l2update', 'product_id': 'BTC-USD', 'changes': [['buy', '38314.60', '0.00000000']], 'time': '2021-05-20T03:55:55.139200Z'}
{'type': 'l2update', 'product_id': 'BTC-USD', 'changes': [['sell', '38348.11', '0.09025653']], 'time': '2021-05-20T03:55:55.139646Z'}
{'type': 'l2update', 'product_id': 'BTC-USD', 'changes': [['sell', '38440.77', '0.06539834']], 'time': '2021-05-20T03:55:55.141571Z'}
{'type': 'l2update', 'product_id': 'BTC-USD', 'changes': [['sell', '38333.82', '0.00000000']], 'time': '2021-05-20T03:55:55.143311Z'}
{'type': 'l2update', 'product_id': 'BTC-USD', 'changes': [['buy', '38175.36', '0.04524520']], 'time': '2021-05-20T03:55:55.144397Z'}
{'type': 'l2update', 'product_id': 'BTC-USD', 'changes': [['buy', '38274.69', '0.00000000']], 'time': '2021-05-20T03:55:55.146549Z'}
{'type': 'l2update', 'product_id': 'BTC-USD', 'changes': [['sell', '38340.69', '2.48969908']], 'time': '2021-05-20T03:55:55.150731Z'}
{'type': 'l2update', 'product_id': 'BTC-USD', 'changes': [['sell', '38353.95', '0.00000000']], 'time': '2021-05-20T03:55:55.152595Z'}
{'type': 'l2update', 'product_id': 'BTC-USD', 'changes': [['sell', '38329.62', '0.00000000']], 'time': '2021-05-20T03:55:55.153970Z'}
{'type': 'l2update', 'product_id': 'BTC-USD', 'changes': [['sell', '38321.02', '0.78209030']], 'time': '2021-05-20T03:55:55.157141Z'}
{'type': 'l2update', 'product_id': 'BTC-USD', 'changes': [['sell', '38461.89', '0.29967511']], 'time': '2021-05-20T03:55:55.157752Z'}
{'type': 'l2update', 'product_id': 'BTC-USD', 'changes': [['buy', '38214.70', '0.33463993']], 'time': '2021-05-20T03:55:55.157752Z'}
{'type': 'l2update', 'product_id': 'BTC-USD', 'changes': [['sell', '38340.70', '0.07065615']], 'time': '2021-05-20T03:55:55.159799Z'}
{'type': 'l2update', 'product_id': 'BTC-USD', 'changes': [['sell', '38349.32', '0.05000000']], 'time': '2021-05-20T03:55:55.164384Z'}
{'type': 'l2update', 'product_id': 'BTC-USD', 'changes': [['buy', '38279.41', '1.20000000']], 'time': '2021-05-20T03:55:55.166083Z'}
{'type': 'l2update', 'product_id': 'BTC-USD', 'changes': [['sell', '38354.47', '0.00000000']], 'time': '2021-05-20T03:55:55.172651Z'}
{'type': 'l2update', 'product_id': 'BTC-USD', 'changes': [['sell', '38352.11', '0.00000000']], 'time': '2021-05-20T03:55:55.172651Z'}
{'type': 'l2update', 'product_id': 'BTC-USD', 'changes': [['buy', '38172.76', '0.00000000']], 'time': '2021-05-20T03:55:55.172651Z'}
{'type': 'l2update', 'product_id': 'BTC-USD', 'changes': [['sell', '38342.92', '0.50000000']], 'time': '2021-05-20T03:55:55.173197Z'}
{'type': 'l2update', 'product_id': 'BTC-USD', 'changes': [['sell', '38359.30', '0.01000000']], 'time': '2021-05-20T03:55:55.174128Z'}
{'type': 'l2update', 'product_id': 'BTC-USD', 'changes': [['buy', '38303.97', '0.00000000']], 'time': '2021-05-20T03:55:55.177323Z'}
{'type': 'l2update', 'product_id': 'BTC-USD', 'changes': [['sell', '38333.81', '0.18981474']], 'time': '2021-05-20T03:55:55.177963Z'}
{'type': 'l2update', 'product_id': 'BTC-USD', 'changes': [['buy', '38293.62', '0.01000000']], 'time': '2021-05-20T03:55:55.178000Z'}
{'type': 'l2update', 'product_id': 'BTC-USD', 'changes': [['sell', '38443.08', '0.01895000']], 'time': '2021-05-20T03:55:55.178309Z'}
{'type': 'l2update', 'product_id': 'BTC-USD', 'changes': [['buy', '38286.65', '0.00000000']], 'time': '2021-05-20T03:55:55.186216Z'}
{'type': 'l2update', 'product_id': 'BTC-USD', 'changes': [['sell', '38431.97', '0.00000000']], 'time': '2021-05-20T03:55:55.188596Z'}
{'type': 'l2update', 'product_id': 'BTC-USD', 'changes': [['sell', '38327.34', '0.78329997']], 'time': '2021-05-20T03:55:55.190704Z'}
{'type': 'l2update', 'product_id': 'BTC-USD', 'changes': [['sell', '38343.92', '0.06845011']], 'time': '2021-05-20T03:55:55.190965Z'}
{'type': 'l2update', 'product_id': 'BTC-USD', 'changes': [['sell', '38414.40', '1.20000000']], 'time': '2021-05-20T03:55:55.190986Z'}
{'type': 'l2update', 'product_id': 'BTC-USD', 'changes': [['sell', '38411.71', '0.00000000']], 'time': '2021-05-20T03:55:55.191411Z'}
{'type': 'l2update', 'product_id': 'BTC-USD', 'changes': [['sell', '38359.81', '0.46500000']], 'time': '2021-05-20T03:55:55.194871Z'}
{'type': 'l2update', 'product_id': 'BTC-USD', 'changes': [['sell', '38469.32', '0.42729725']], 'time': '2021-05-20T03:55:55.195444Z'}
{'type': 'l2update', 'product_id': 'BTC-USD', 'changes': [['buy', '38208.27', '0.49605408']], 'time': '2021-05-20T03:55:55.195444Z'}
{'type': 'l2update', 'product_id': 'BTC-USD', 'changes': [['sell', '38445.51', '0.00000000']], 'time': '2021-05-20T03:55:55.199229Z'}
{'type': 'l2update', 'product_id': 'BTC-USD', 'changes': [['buy', '38291.92', '0.02000000']], 'time': '2021-05-20T03:55:55.199360Z'}
{'type': 'l2update', 'product_id': 'BTC-USD', 'changes': [['buy', '38298.47', '0.00000000']], 'time': '2021-05-20T03:55:55.201988Z'}
{'type': 'l2update', 'product_id': 'BTC-USD', 'changes': [['buy', '38287.58', '0.00000000']], 'time': '2021-05-20T03:55:55.203505Z'}
{'type': 'l2update', 'product_id': 'BTC-USD', 'changes': [['buy', '38306.13', '0.84700000']], 'time': '2021-05-20T03:55:55.205617Z'}
{'type': 'l2update', 'product_id': 'BTC-USD', 'changes': [['buy', '38303.91', '0.65000000']], 'time': '2021-05-20T03:55:55.207278Z'}
{'type': 'l2update', 'product_id': 'BTC-USD', 'changes': [['buy', '38167.90', '0.00000000']], 'time': '2021-05-20T03:55:55.209675Z'}
{'type': 'l2update', 'product_id': 'BTC-USD', 'changes': [['buy', '38321.01', '0.74686571']], 'time': '2021-05-20T03:55:55.213243Z'}
{'type': 'l2update', 'product_id': 'BTC-USD', 'changes': [['sell', '38433.72', '0.01011164']], 'time': '2021-05-20T03:55:55.213264Z'}
{'type': 'l2update', 'product_id': 'BTC-USD', 'changes': [['sell', '38450.50', '0.01166830']], 'time': '2021-05-20T03:55:55.213517Z'}
{'type': 'l2update', 'product_id': 'BTC-USD', 'changes': [['sell', '38456.36', '0.00000000']], 'time': '2021-05-20T03:55:55.215809Z'}
{'type': 'l2update', 'product_id': 'BTC-USD', 'changes': [['sell', '38594.92', '0.00000000']], 'time': '2021-05-20T03:55:55.217545Z'}
{'type': 'l2update', 'product_id': 'BTC-USD', 'changes': [['buy', '38299.56', '0.52208136']], 'time': '2021-05-20T03:55:55.218169Z'}
{'type': 'l2update', 'product_id': 'BTC-USD', 'changes': [['buy', '38320.92', '0.18500000']], 'time': '2021-05-20T03:55:55.218218Z'}
{'type': 'l2update', 'product_id': 'BTC-USD', 'changes': [['buy', '38220.94', '0.06391614']], 'time': '2021-05-20T03:55:55.218656Z'}
{'type': 'l2update', 'product_id': 'BTC-USD', 'changes': [['buy', '38288.40', '0.00000000']], 'time': '2021-05-20T03:55:55.218951Z'}
{'type': 'l2update', 'product_id': 'BTC-USD', 'changes': [['buy', '38295.29', '0.00000000']], 'time': '2021-05-20T03:55:55.219077Z'}
{'type': 'l2update', 'product_id': 'BTC-USD', 'changes': [['buy', '38321.01', '0.83604159']], 'time': '2021-05-20T03:55:55.222839Z'}
{'type': 'l2update', 'product_id': 'BTC-USD', 'changes': [['buy', '38303.97', '0.40135082']], 'time': '2021-05-20T03:55:55.222969Z'}
{'type': 'l2update', 'product_id': 'BTC-USD', 'changes': [['sell', '38360.77', '0.04000000']], 'time': '2021-05-20T03:55:55.223067Z'}
{'type': 'l2update', 'product_id': 'BTC-USD', 'changes': [['sell', '38459.16', '0.01219214']], 'time': '2021-05-20T03:55:55.223152Z'}
{'type': 'l2update', 'product_id': 'BTC-USD', 'changes': [['sell', '43100.00', '2.99540000']], 'time': '2021-05-20T03:55:55.230351Z'}
{'type': 'l2update', 'product_id': 'BTC-USD', 'changes': [['buy', '38189.62', '0.00000000']], 'time': '2021-05-20T03:55:55.231865Z'}
{'type': 'l2update', 'product_id': 'BTC-USD', 'changes': [['sell', '38383.62', '0.00000000']], 'time': '2021-05-20T03:55:55.233880Z'}
{'type': 'l2update', 'product_id': 'BTC-USD', 'changes': [['sell', '39499.99', '0.00000000']], 'time': '2021-05-20T03:55:55.239633Z'}
{'type': 'l2update', 'product_id': 'BTC-USD', 'changes': [['buy', '38304.41', '0.42050000']], 'time': '2021-05-20T03:55:55.241521Z'}
{'type': 'l2update', 'product_id': 'BTC-USD', 'changes': [['buy', '38303.98', '0.06845011']], 'time': '2021-05-20T03:55:55.242368Z'}
{'type': 'l2update', 'product_id': 'BTC-USD', 'changes': [['sell', '38333.81', '0.00000000']], 'time': '2021-05-20T03:55:55.244605Z'}
{'type': 'l2update', 'product_id': 'BTC-USD', 'changes': [['sell', '38431.02', '0.00000000']], 'time': '2021-05-20T03:55:55.247020Z'}
{'type': 'l2update', 'product_id': 'BTC-USD', 'changes': [['buy', '37498.05', '0.00000000']], 'time': '2021-05-20T03:55:55.247100Z'}
{'type': 'l2update', 'product_id': 'BTC-USD', 'changes': [['sell', '38342.92', '0.00000000']], 'time': '2021-05-20T03:55:55.257588Z'}
{'type': 'l2update', 'product_id': 'BTC-USD', 'changes': [['sell', '39109.11', '0.00000000']], 'time': '2021-05-20T03:55:55.257867Z'}
{'type': 'l2update', 'product_id': 'BTC-USD', 'changes': [['sell', '38474.61', '0.00000000']], 'time': '2021-05-20T03:55:55.259076Z'}
{'type': 'l2update', 'product_id': 'BTC-USD', 'changes': [['sell', '38328.71', '0.52208136']], 'time': '2021-05-20T03:55:55.264099Z'}
{'type': 'l2update', 'product_id': 'BTC-USD', 'changes': [['buy', '38214.70', '0.36332080']], 'time': '2021-05-20T03:55:55.265710Z'}
{'type': 'l2update', 'product_id': 'BTC-USD', 'changes': [['buy', '38304.41', '0.00000000']], 'time': '2021-05-20T03:55:55.268243Z'}
{'type': 'l2update', 'product_id': 'BTC-USD', 'changes': [['sell', '38359.81', '0.00000000']], 'time': '2021-05-20T03:55:55.273667Z'}
{'type': 'l2update', 'product_id': 'BTC-USD', 'changes': [['buy', '38207.77', '0.02731687']], 'time': '2021-05-20T03:55:55.277618Z'}
{'type': 'l2update', 'product_id': 'BTC-USD', 'changes': [['sell', '38360.77', '0.07000000']], 'time': '2021-05-20T03:55:55.277861Z'}
{'type': 'l2update', 'product_id': 'BTC-USD', 'changes': [['sell', '38469.32', '0.85495073']], 'time': '2021-05-20T03:55:55.277985Z'}
{'type': 'l2update', 'product_id': 'BTC-USD', 'changes': [['sell', '38481.15', '0.01000000']], 'time': '2021-05-20T03:55:55.278005Z'}
{'type': 'l2update', 'product_id': 'BTC-USD', 'changes': [['sell', '39495.99', '0.05070000']], 'time': '2021-05-20T03:55:55.278049Z'}
{'type': 'l2update', 'product_id': 'BTC-USD', 'changes': [['buy', '38306.50', '0.02400000']], 'time': '2021-05-20T03:55:55.278200Z'}
{'type': 'l2update', 'product_id': 'BTC-USD', 'changes': [['buy', '38305.69', '0.02400000']], 'time': '2021-05-20T03:55:55.278200Z'}
{'type': 'l2update', 'product_id': 'BTC-USD', 'changes': [['buy', '38304.89', '0.02400000']], 'time': '2021-05-20T03:55:55.278200Z'}
{'type': 'l2update', 'product_id': 'BTC-USD', 'changes': [['buy', '38308.21', '0.99315797']], 'time': '2021-05-20T03:55:55.278370Z'}
{'type': 'l2update', 'product_id': 'BTC-USD', 'changes': [['sell', '38608.01', '0.01000000']], 'time': '2021-05-20T03:55:55.278657Z'}
{'type': 'l2update', 'product_id': 'BTC-USD', 'changes': [['buy', '38279.41', '0.00000000']], 'time': '2021-05-20T03:55:55.282337Z'}
{'type': 'l2update', 'product_id': 'BTC-USD', 'changes': [['sell', '38340.69', '0.00000000']], 'time': '2021-05-20T03:55:55.291837Z'}
{'type': 'l2update', 'product_id': 'BTC-USD', 'changes': [['sell', '38414.40', '0.00000000']], 'time': '2021-05-20T03:55:55.292620Z'}
{'type': 'l2update', 'product_id': 'BTC-USD', 'changes': [['buy', '38304.89', '0.00000000']], 'time': '2021-05-20T03:55:55.293239Z'}
{'type': 'l2update', 'product_id': 'BTC-USD', 'changes': [['buy', '38295.96', '0.52213155']], 'time': '2021-05-20T03:55:55.295546Z'}
{'type': 'l2update', 'product_id': 'BTC-USD', 'changes': [['sell', '38346.47', '0.50000000']], 'time': '2021-05-20T03:55:55.295557Z'}
{'type': 'l2update', 'product_id': 'BTC-USD', 'changes': [['buy', '38303.97', '0.00000000']], 'time': '2021-05-20T03:55:55.297501Z'}
{'type': 'l2update', 'product_id': 'BTC-USD', 'changes': [['buy', '38306.50', '0.00000000']], 'time': '2021-05-20T03:55:55.297962Z'}
{'type': 'l2update', 'product_id': 'BTC-USD', 'changes': [['buy', '38305.69', '0.00000000']], 'time': '2021-05-20T03:55:55.297962Z'}
{'type': 'l2update', 'product_id': 'BTC-USD', 'changes': [['buy', '38194.84', '0.39716381']], 'time': '2021-05-20T03:55:55.303775Z'}
{'type': 'l2update', 'product_id': 'BTC-USD', 'changes': [['sell', '38446.21', '0.01000000']], 'time': '2021-05-20T03:55:55.303943Z'}
{'type': 'l2update', 'product_id': 'BTC-USD', 'changes': [['sell', '38360.27', '0.02000000']], 'time': '2021-05-20T03:55:55.304294Z'}
{'type': 'l2update', 'product_id': 'BTC-USD', 'changes': [['sell', '38504.15', '0.01000000']], 'time': '2021-05-20T03:55:55.306314Z'}
{'type': 'l2update', 'product_id': 'BTC-USD', 'changes': [['sell', '38349.32', '0.00000000']], 'time': '2021-05-20T03:55:55.307489Z'}
{'type': 'l2update', 'product_id': 'BTC-USD', 'changes': [['sell', '38359.10', '0.00000000']], 'time': '2021-05-20T03:55:55.312845Z'}
{'type': 'l2update', 'product_id': 'BTC-USD', 'changes': [['buy', '38208.27', '0.52329763']], 'time': '2021-05-20T03:55:55.316343Z'}
{'type': 'l2update', 'product_id': 'BTC-USD', 'changes': [['sell', '38352.67', '0.00000000']], 'time': '2021-05-20T03:55:55.320358Z'}
{'type': 'l2update', 'product_id': 'BTC-USD', 'changes': [['buy', '38314.18', '0.20000000']], 'time': '2021-05-20T03:55:55.327546Z'}
{'type': 'l2update', 'product_id': 'BTC-USD', 'changes': [['sell', '38550.00', '0.00000000']], 'time': '2021-05-20T03:55:55.330469Z'}
{'type': 'l2update', 'product_id': 'BTC-USD', 'changes': [['sell', '38342.92', '2.48969908']], 'time': '2021-05-20T03:55:55.331986Z'}
{'type': 'l2update', 'product_id': 'BTC-USD', 'changes': [['sell', '38340.68', '0.06845011']], 'time': '2021-05-20T03:55:55.332367Z'}
{'type': 'l2update', 'product_id': 'BTC-USD', 'changes': [['buy', '38314.18', '0.00000000']], 'time': '2021-05-20T03:55:55.332803Z'}
{'type': 'l2update', 'product_id': 'BTC-USD', 'changes': [['sell', '38338.95', '1.30536919']], 'time': '2021-05-20T03:55:55.333257Z'}
{'type': 'l2update', 'product_id': 'BTC-USD', 'changes': [['buy', '38308.21', '1.06160808']], 'time': '2021-05-20T03:55:55.333448Z'}
{'type': 'l2update', 'product_id': 'BTC-USD', 'changes': [['buy', '38283.56', '0.00000000']], 'time': '2021-05-20T03:55:55.334398Z'}
{'type': 'l2update', 'product_id': 'BTC-USD', 'changes': [['sell', '38366.88', '0.05000000']], 'time': '2021-05-20T03:55:55.337446Z'}
{'type': 'l2update', 'product_id': 'BTC-USD', 'changes': [['sell', '38454.38', '0.01000000']], 'time': '2021-05-20T03:55:55.338615Z'}
{'type': 'l2update', 'product_id': 'BTC-USD', 'changes': [['buy', '38308.22', '0.40135082']], 'time': '2021-05-20T03:55:55.338689Z'}
{'type': 'l2update', 'product_id': 'BTC-USD', 'changes': [['sell', '38346.46', '0.05000000']], 'time': '2021-05-20T03:55:55.339091Z'}
{'type': 'l2update', 'product_id': 'BTC-USD', 'changes': [['buy', '38295.25', '0.00000000']], 'time': '2021-05-20T03:55:55.342122Z'}
{'type': 'l2update', 'product_id': 'BTC-USD', 'changes': [['buy', '38314.59', '0.35900000']], 'time': '2021-05-20T03:55:55.345317Z'}
{'type': 'l2update', 'product_id': 'BTC-USD', 'changes': [['sell', '38437.22', '0.00000000']], 'time': '2021-05-20T03:55:55.347913Z'}
{'type': 'l2update', 'product_id': 'BTC-USD', 'changes': [['buy', '38314.64', '0.84700000']], 'time': '2021-05-20T03:55:55.348403Z'}
{'type': 'l2update', 'product_id': 'BTC-USD', 'changes': [['buy', '38307.84', '0.02400000']], 'time': '2021-05-20T03:55:55.348528Z'}
{'type': 'l2update', 'product_id': 'BTC-USD', 'changes': [['buy', '38293.32', '0.52216681']], 'time': '2021-05-20T03:55:55.352590Z'}
{'type': 'l2update', 'product_id': 'BTC-USD', 'changes': [['sell', '38338.94', '0.18981474']], 'time': '2021-05-20T03:55:55.352727Z'}
{'type': 'l2update', 'product_id': 'BTC-USD', 'changes': [['sell', '38415.17', '0.00000000']], 'time': '2021-05-20T03:55:55.356665Z'}
{'type': 'l2update', 'product_id': 'BTC-USD', 'changes': [['sell', '38360.12', '0.01000000']], 'time': '2021-05-20T03:55:55.357034Z'}
{'type': 'l2update', 'product_id': 'BTC-USD', 'changes': [['sell', '38359.13', '0.00000000']], 'time': '2021-05-20T03:55:55.359792Z'}
{'type': 'l2update', 'product_id': 'BTC-USD', 'changes': [['buy', '38246.55', '2.55420000']], 'time': '2021-05-20T03:55:55.360419Z'}
{'type': 'l2update', 'product_id': 'BTC-USD', 'changes': [['buy', '38314.59', '0.25900000']], 'time': '2021-05-20T03:55:55.364462Z'}
{'type': 'l2update', 'product_id': 'BTC-USD', 'changes': [['buy', '38298.46', '0.52100000']], 'time': '2021-05-20T03:55:55.368383Z'}
{'type': 'l2update', 'product_id': 'BTC-USD', 'changes': [['buy', '38307.84', '0.00000000']], 'time': '2021-05-20T03:55:55.370428Z'}
{'type': 'l2update', 'product_id': 'BTC-USD', 'changes': [['sell', '38451.69', '0.01000000']], 'time': '2021-05-20T03:55:55.372907Z'}
{'type': 'l2update', 'product_id': 'BTC-USD', 'changes': [['sell', '38332.73', '0.04925560']], 'time': '2021-05-20T03:55:55.376427Z'}
{'type': 'l2update', 'product_id': 'BTC-USD', 'changes': [['buy', '38318.95', '0.05081050']], 'time': '2021-05-20T03:55:55.379380Z'}
{'type': 'l2update', 'product_id': 'BTC-USD', 'changes': [['sell', '38353.13', '2.61132294']], 'time': '2021-05-20T03:55:55.379521Z'}
{'type': 'l2update', 'product_id': 'BTC-USD', 'changes': [['buy', '38317.70', '0.20000000']], 'time': '2021-05-20T03:55:55.381191Z'}
{'type': 'l2update', 'product_id': 'BTC-USD', 'changes': [['sell', '38335.40', '0.00000000']], 'time': '2021-05-20T03:55:55.384218Z'}
{'type': 'l2update', 'product_id': 'BTC-USD', 'changes': [['sell', '38357.66', '0.04947745']], 'time': '2021-05-20T03:55:55.384860Z'}
{'type': 'l2update', 'product_id': 'BTC-USD', 'changes': [['sell', '38429.28', '0.01000000']], 'time': '2021-05-20T03:55:55.384894Z'}
{'type': 'l2update', 'product_id': 'BTC-USD', 'changes': [['sell', '38340.60', '0.05000000']], 'time': '2021-05-20T03:55:55.394083Z'}
{'type': 'l2update', 'product_id': 'BTC-USD', 'changes': [['buy', '38303.98', '0.00000000']], 'time': '2021-05-20T03:55:55.396895Z'}
{'type': 'l2update', 'product_id': 'BTC-USD', 'changes': [['buy', '38271.73', '1.30536919']], 'time': '2021-05-20T03:55:55.406160Z'}
{'type': 'l2update', 'product_id': 'BTC-USD', 'changes': [['buy', '38317.70', '0.00000000']], 'time': '2021-05-20T03:55:55.408784Z'}
{'type': 'l2update', 'product_id': 'BTC-USD', 'changes': [['buy', '38202.09', '0.00000000']], 'time': '2021-05-20T03:55:55.410867Z'}
{'type': 'l2update', 'product_id': 'BTC-USD', 'changes': [['buy', '38306.13', '0.87100000']], 'time': '2021-05-20T03:55:55.413059Z'}
{'type': 'l2update', 'product_id': 'BTC-USD', 'changes': [['buy', '38305.32', '0.02400000']], 'time': '2021-05-20T03:55:55.413059Z'}
{'type': 'l2update', 'product_id': 'BTC-USD', 'changes': [['buy', '38304.51', '0.02400000']], 'time': '2021-05-20T03:55:55.413059Z'}
{'type': 'l2update', 'product_id': 'BTC-USD', 'changes': [['buy', '38258.52', '0.00000000']], 'time': '2021-05-20T03:55:55.417672Z'}
{'type': 'l2update', 'product_id': 'BTC-USD', 'changes': [['buy', '38295.02', '0.00000000']], 'time': '2021-05-20T03:55:55.419260Z'}
{'type': 'l2update', 'product_id': 'BTC-USD', 'changes': [['sell', '38337.33', '0.00000000']], 'time': '2021-05-20T03:55:55.419260Z'}
{'type': 'l2update', 'product_id': 'BTC-USD', 'changes': [['sell', '38340.60', '0.00000000']], 'time': '2021-05-20T03:55:55.419689Z'}
{'type': 'l2update', 'product_id': 'BTC-USD', 'changes': [['sell', '38368.16', '2.61031906']], 'time': '2021-05-20T03:55:55.427819Z'}
{'type': 'l2update', 'product_id': 'BTC-USD', 'changes': [['sell', '38340.70', '0.00000000']], 'time': '2021-05-20T03:55:55.436267Z'}
{'type': 'l2update', 'product_id': 'BTC-USD', 'changes': [['buy', '38273.50', '0.10000000']], 'time': '2021-05-20T03:55:55.437410Z'}
{'type': 'l2update', 'product_id': 'BTC-USD', 'changes': [['sell', '38398.51', '0.00000000']], 'time': '2021-05-20T03:55:55.443457Z'}
{'type': 'l2update', 'product_id': 'BTC-USD', 'changes': [['sell', '38443.08', '0.00000000']], 'time': '2021-05-20T03:55:55.446491Z'}
{'type': 'l2update', 'product_id': 'BTC-USD', 'changes': [['buy', '38262.62', '2.61083404']], 'time': '2021-05-20T03:55:55.447097Z'}
{'type': 'l2update', 'product_id': 'BTC-USD', 'changes': [['sell', '38338.94', '0.00000000']], 'time': '2021-05-20T03:55:55.447682Z'}
{'type': 'l2update', 'product_id': 'BTC-USD', 'changes': [['buy', '38291.92', '0.00000000']], 'time': '2021-05-20T03:55:55.448953Z'}
{'type': 'l2update', 'product_id': 'BTC-USD', 'changes': [['buy', '38289.60', '2.37600000']], 'time': '2021-05-20T03:55:55.453981Z'}
{'type': 'l2update', 'product_id': 'BTC-USD', 'changes': [['buy', '38289.12', '0.08000000']], 'time': '2021-05-20T03:55:55.457940Z'}
{'type': 'l2update', 'product_id': 'BTC-USD', 'changes': [['sell', '38481.95', '0.00000000']], 'time': '2021-05-20T03:55:55.459007Z'}
{'type': 'l2update', 'product_id': 'BTC-USD', 'changes': [['buy', '38308.21', '0.99315797']], 'time': '2021-05-20T03:55:55.459491Z'}
{'type': 'l2update', 'product_id': 'BTC-USD', 'changes': [['buy', '37503.78', '0.00000000']], 'time': '2021-05-20T03:55:55.463640Z'}
{'type': 'l2update', 'product_id': 'BTC-USD', 'changes': [['buy', '38289.12', '0.03000000']], 'time': '2021-05-20T03:55:55.465172Z'}
{'type': 'l2update', 'product_id': 'BTC-USD', 'changes': [['sell', '38435.00', '0.01000000']], 'time': '2021-05-20T03:55:55.469248Z'}
{'type': 'l2update', 'product_id': 'BTC-USD', 'changes': [['sell', '38457.88', '0.01000000']], 'time': '2021-05-20T03:55:55.469640Z'}
{'type': 'l2update', 'product_id': 'BTC-USD', 'changes': [['sell', '38369.30', '2.61024060']], 'time': '2021-05-20T03:55:55.469654Z'}
{'type': 'l2update', 'product_id': 'BTC-USD', 'changes': [['sell', '38424.59', '0.02400000']], 'time': '2021-05-20T03:55:55.470311Z'}
{'type': 'l2update', 'product_id': 'BTC-USD', 'changes': [['sell', '39100.49', '0.00000000']], 'time': '2021-05-20T03:55:55.471336Z'}
{'type': 'l2update', 'product_id': 'BTC-USD', 'changes': [['sell', '38342.91', '0.18981474']], 'time': '2021-05-20T03:55:55.475776Z'}
{'type': 'l2update', 'product_id': 'BTC-USD', 'changes': [['sell', '38321.02', '0.00000000']], 'time': '2021-05-20T03:55:55.476809Z'}
{'type': 'l2update', 'product_id': 'BTC-USD', 'changes': [['buy', '38286.07', '0.02000000']], 'time': '2021-05-20T03:55:55.480701Z'}
{'type': 'l2update', 'product_id': 'BTC-USD', 'changes': [['buy', '38321.02', '0.00573000']], 'time': '2021-05-20T03:55:55.481021Z'}
{'type': 'l2update', 'product_id': 'BTC-USD', 'changes': [['buy', '38175.36', '0.00000000']], 'time': '2021-05-20T03:55:55.484955Z'}
{'type': 'l2update', 'product_id': 'BTC-USD', 'changes': [['buy', '38282.47', '0.00000000']], 'time': '2021-05-20T03:55:55.485185Z'}
{'type': 'l2update', 'product_id': 'BTC-USD', 'changes': [['buy', '38321.01', '0.81601017']], 'time': '2021-05-20T03:55:55.485872Z'}
{'type': 'l2update', 'product_id': 'BTC-USD', 'changes': [['buy', '38321.01', '0.78872588']], 'time': '2021-05-20T03:55:55.485903Z'}
{'type': 'l2update', 'product_id': 'BTC-USD', 'changes': [['buy', '38321.01', '0.77380588']], 'time': '2021-05-20T03:55:55.487449Z'}
{'type': 'l2update', 'product_id': 'BTC-USD', 'changes': [['buy', '38308.23', '0.06845011']], 'time': '2021-05-20T03:55:55.487634Z'}
{'type': 'l2update', 'product_id': 'BTC-USD', 'changes': [['sell', '38338.90', '0.55400000']], 'time': '2021-05-20T03:55:55.489031Z'}
{'type': 'l2update', 'product_id': 'BTC-USD', 'changes': [['sell', '38465.43', '0.01652476']], 'time': '2021-05-20T03:55:55.489404Z'}
{'type': 'l2update', 'product_id': 'BTC-USD', 'changes': [['buy', '38267.37', '0.00000000']], 'time': '2021-05-20T03:55:55.490906Z'}
{'type': 'l2update', 'product_id': 'BTC-USD', 'changes': [['buy', '38321.01', '0.76807588']], 'time': '2021-05-20T03:55:55.491385Z'}
{'type': 'l2update', 'product_id': 'BTC-USD', 'changes': [['buy', '38320.92', '0.00000000']], 'time': '2021-05-20T03:55:55.494046Z'}
{'type': 'l2update', 'product_id': 'BTC-USD', 'changes': [['sell', '38348.11', '0.00000000']], 'time': '2021-05-20T03:55:55.495351Z'}
{'type': 'l2update', 'product_id': 'BTC-USD', 'changes': [['sell', '38333.83', '0.00000000']], 'time': '2021-05-20T03:55:55.495376Z'}
{'type': 'l2update', 'product_id': 'BTC-USD', 'changes': [['buy', '38279.20', '0.04000000']], 'time': '2021-05-20T03:55:55.495815Z'}
{'type': 'l2update', 'product_id': 'BTC-USD', 'changes': [['sell', '38340.68', '0.00000000']], 'time': '2021-05-20T03:55:55.499080Z'}
{'type': 'l2update', 'product_id': 'BTC-USD', 'changes': [['buy', '38321.02', '0.00000000']], 'time': '2021-05-20T03:55:55.499374Z'}
{'type': 'l2update', 'product_id': 'BTC-USD', 'changes': [['buy', '38253.07', '0.00000000']], 'time': '2021-05-20T03:55:55.501382Z'}
{'type': 'l2update', 'product_id': 'BTC-USD', 'changes': [['buy', '38294.07', '0.39490431']], 'time': '2021-05-20T03:55:55.501688Z'}
{'type': 'l2update', 'product_id': 'BTC-USD', 'changes': [['buy', '38308.22', '0.00000000']], 'time': '2021-05-20T03:55:55.503264Z'}
{'type': 'l2update', 'product_id': 'BTC-USD', 'changes': [['buy', '38293.32', '0.00000000']], 'time': '2021-05-20T03:55:55.506446Z'}
{'type': 'l2update', 'product_id': 'BTC-USD', 'changes': [['buy', '38088.06', '0.00000000']], 'time': '2021-05-20T03:55:55.507722Z'}
{'type': 'l2update', 'product_id': 'BTC-USD', 'changes': [['buy', '38214.25', '0.01000000']], 'time': '2021-05-20T03:55:55.508728Z'}
{'type': 'l2update', 'product_id': 'BTC-USD', 'changes': [['sell', '38416.12', '0.05447566']], 'time': '2021-05-20T03:55:55.509029Z'}
{'type': 'l2update', 'product_id': 'BTC-USD', 'changes': [['buy', '38278.81', '0.05000000']], 'time': '2021-05-20T03:55:55.513787Z'}
{'type': 'l2update', 'product_id': 'BTC-USD', 'changes': [['buy', '38273.51', '0.02612773']], 'time': '2021-05-20T03:55:55.514508Z'}
{'type': 'l2update', 'product_id': 'BTC-USD', 'changes': [['buy', '38273.03', '0.09152558']], 'time': '2021-05-20T03:55:55.514735Z'}
{'type': 'l2update', 'product_id': 'BTC-USD', 'changes': [['sell', '38421.85', '0.12257024']], 'time': '2021-05-20T03:55:55.515663Z'}
{'type': 'l2update', 'product_id': 'BTC-USD', 'changes': [['buy', '38271.73', '0.00000000']], 'time': '2021-05-20T03:55:55.516345Z'}
{'type': 'l2update', 'product_id': 'BTC-USD', 'changes': [['buy', '38101.44', '0.01286850']], 'time': '2021-05-20T03:55:55.518532Z'}
{'type': 'l2update', 'product_id': 'BTC-USD', 'changes': [['sell', '38366.88', '0.00000000']], 'time': '2021-05-20T03:55:55.520388Z'}
{'type': 'l2update', 'product_id': 'BTC-USD', 'changes': [['sell', '38346.47', '0.00000000']], 'time': '2021-05-20T03:55:55.521136Z'}
{'type': 'l2update', 'product_id': 'BTC-USD', 'changes': [['sell', '38342.90', '0.06845011']], 'time': '2021-05-20T03:55:55.524982Z'}
{'type': 'l2update', 'product_id': 'BTC-USD', 'changes': [['buy', '38327.33', '0.04731571']], 'time': '2021-05-20T03:55:55.526017Z'}
{'type': 'l2update', 'product_id': 'BTC-USD', 'changes': [['buy', '38327.33', '0.06223571']], 'time': '2021-05-20T03:55:55.526122Z'}
{'type': 'l2update', 'product_id': 'BTC-USD', 'changes': [['buy', '38238.29', '0.01307589']], 'time': '2021-05-20T03:55:55.526172Z'}
{'type': 'l2update', 'product_id': 'BTC-USD', 'changes': [['buy', '38308.24', '0.40135082']], 'time': '2021-05-20T03:55:55.526477Z'}
{'type': 'l2update', 'product_id': 'BTC-USD', 'changes': [['sell', '38390.09', '0.02604839']], 'time': '2021-05-20T03:55:55.532897Z'}
{'type': 'l2update', 'product_id': 'BTC-USD', 'changes': [['sell', '38342.91', '0.00000000']], 'time': '2021-05-20T03:55:55.533416Z'}
{'type': 'l2update', 'product_id': 'BTC-USD', 'changes': [['sell', '38619.76', '0.00000000']], 'time': '2021-05-20T03:55:55.534970Z'}
{'type': 'l2update', 'product_id': 'BTC-USD', 'changes': [['buy', '38321.01', '0.73917588']], 'time': '2021-05-20T03:55:55.537918Z'}
{'type': 'l2update', 'product_id': 'BTC-USD', 'changes': [['sell', '38346.46', '0.00000000']], 'time': '2021-05-20T03:55:55.540403Z'}
{'type': 'l2update', 'product_id': 'BTC-USD', 'changes': [['sell', '38332.73', '0.00000000']], 'time': '2021-05-20T03:55:55.542083Z'}
{'type': 'l2update', 'product_id': 'BTC-USD', 'changes': [['sell', '38338.89', '0.50000000']], 'time': '2021-05-20T03:55:55.545995Z'}
{'type': 'l2update', 'product_id': 'BTC-USD', 'changes': [['sell', '38376.20', '0.14600000']], 'time': '2021-05-20T03:55:55.546082Z'}
{'type': 'l2update', 'product_id': 'BTC-USD', 'changes': [['sell', '38374.63', '0.05000000']], 'time': '2021-05-20T03:55:55.546111Z'}
{'type': 'l2update', 'product_id': 'BTC-USD', 'changes': [['buy', '38304.38', '0.42860000']], 'time': '2021-05-20T03:55:55.546239Z'}
{'type': 'l2update', 'product_id': 'BTC-USD', 'changes': [['sell', '38634.85', '0.01294168']], 'time': '2021-05-20T03:55:55.549406Z'}
{'type': 'l2update', 'product_id': 'BTC-USD', 'changes': [['sell', '38465.43', '0.00000000']], 'time': '2021-05-20T03:55:55.555060Z'}
{'type': 'l2update', 'product_id': 'BTC-USD', 'changes': [['sell', '38353.12', '0.05000000']], 'time': '2021-05-20T03:55:55.558011Z'}
{'type': 'l2update', 'product_id': 'BTC-USD', 'changes': [['sell', '38342.90', '0.00000000']], 'time': '2021-05-20T03:55:55.560781Z'}
{'type': 'l2update', 'product_id': 'BTC-USD', 'changes': [['sell', '38364.02', '0.45650000']], 'time': '2021-05-20T03:55:55.564374Z'}
{'type': 'l2update', 'product_id': 'BTC-USD', 'changes': [['sell', '38360.77', '0.03000000']], 'time': '2021-05-20T03:55:55.569810Z'}
{'type': 'l2update', 'product_id': 'BTC-USD', 'changes': [['sell', '38364.02', '0.00000000']], 'time': '2021-05-20T03:55:55.573312Z'}
{'type': 'l2update', 'product_id': 'BTC-USD', 'changes': [['sell', '38528.80', '0.01000000']], 'time': '2021-05-20T03:55:55.574826Z'}
{'type': 'l2update', 'product_id': 'BTC-USD', 'changes': [['buy', '38299.42', '0.04316886']], 'time': '2021-05-20T03:55:55.576135Z'}
{'type': 'l2update', 'product_id': 'BTC-USD', 'changes': [['sell', '38340.72', '0.04922313']], 'time': '2021-05-20T03:55:55.576135Z'}
{'type': 'l2update', 'product_id': 'BTC-USD', 'changes': [['buy', '38308.25', '0.07302467']], 'time': '2021-05-20T03:55:55.576613Z'}
{'type': 'l2update', 'product_id': 'BTC-USD', 'changes': [['sell', '38359.30', '0.00000000']], 'time': '2021-05-20T03:55:55.584515Z'}
{'type': 'l2update', 'product_id': 'BTC-USD', 'changes': [['buy', '38308.23', '0.00000000']], 'time': '2021-05-20T03:55:55.585749Z'}
{'type': 'l2update', 'product_id': 'BTC-USD', 'changes': [['buy', '38308.24', '0.00000000']], 'time': '2021-05-20T03:55:55.587961Z'}
{'type': 'l2update', 'product_id': 'BTC-USD', 'changes': [['sell', '38366.55', '0.04000000']], 'time': '2021-05-20T03:55:55.588740Z'}
{'type': 'l2update', 'product_id': 'BTC-USD', 'changes': [['sell', '38328.71', '0.00000000']], 'time': '2021-05-20T03:55:55.596105Z'}
{'type': 'l2update', 'product_id': 'BTC-USD', 'changes': [['sell', '38433.72', '0.00000000']], 'time': '2021-05-20T03:55:55.597393Z'}
{'type': 'l2update', 'product_id': 'BTC-USD', 'changes': [['sell', '38338.95', '0.00000000']], 'time': '2021-05-20T03:55:55.603388Z'}
{'type': 'l2update', 'product_id': 'BTC-USD', 'changes': [['buy', '38321.01', '0.65000000']], 'time': '2021-05-20T03:55:55.603543Z'}
{'type': 'l2update', 'product_id': 'BTC-USD', 'changes': [['sell', '38374.63', '0.00000000']], 'time': '2021-05-20T03:55:55.604523Z'}
{'type': 'l2update', 'product_id': 'BTC-USD', 'changes': [['sell', '38461.39', '0.03584250']], 'time': '2021-05-20T03:55:55.614088Z'}
{'type': 'l2update', 'product_id': 'BTC-USD', 'changes': [['sell', '38342.91', '0.07302467']], 'time': '2021-05-20T03:55:55.614289Z'}
{'type': 'l2update', 'product_id': 'BTC-USD', 'changes': [['buy', '28000.00', '160.72758040']], 'time': '2021-05-20T03:55:55.617496Z'}
{'type': 'l2update', 'product_id': 'BTC-USD', 'changes': [['sell', '38368.00', '0.05000000']], 'time': '2021-05-20T03:55:55.621332Z'}
{'type': 'l2update', 'product_id': 'BTC-USD', 'changes': [['sell', '38342.91', '0.14352025']], 'time': '2021-05-20T03:55:55.626234Z'}
{'type': 'l2update', 'product_id': 'BTC-USD', 'changes': [['buy', '38101.44', '0.00000000']], 'time': '2021-05-20T03:55:55.626452Z'}
{'type': 'l2update', 'product_id': 'BTC-USD', 'changes': [['sell', '38342.91', '0.07049558']], 'time': '2021-05-20T03:55:55.631144Z'}
{'type': 'l2update', 'product_id': 'BTC-USD', 'changes': [['buy', '38279.90', '0.00000000']], 'time': '2021-05-20T03:55:55.633252Z'}
{'type': 'l2update', 'product_id': 'BTC-USD', 'changes': [['sell', '38340.72', '0.00000000']], 'time': '2021-05-20T03:55:55.638386Z'}
{'type': 'l2update', 'product_id': 'BTC-USD', 'changes': [['buy', '38114.82', '0.01081700']], 'time': '2021-05-20T03:55:55.642613Z'}
{'type': 'l2update', 'product_id': 'BTC-USD', 'changes': [['buy', '38191.95', '0.00000000']], 'time': '2021-05-20T03:55:55.645025Z'}
{'type': 'l2update', 'product_id': 'BTC-USD', 'changes': [['buy', '38321.03', '0.08917588']], 'time': '2021-05-20T03:55:55.646953Z'}
{'type': 'l2update', 'product_id': 'BTC-USD', 'changes': [['buy', '38291.14', '0.52800000']], 'time': '2021-05-20T03:55:55.648713Z'}
{'type': 'l2update', 'product_id': 'BTC-USD', 'changes': [['buy', '38314.64', '1.36800000']], 'time': '2021-05-20T03:55:55.654520Z'}
{'type': 'l2update', 'product_id': 'BTC-USD', 'changes': [['buy', '38303.91', '0.00000000']], 'time': '2021-05-20T03:55:55.660888Z'}
{'type': 'l2update', 'product_id': 'BTC-USD', 'changes': [['buy', '38204.35', '0.02000000']], 'time': '2021-05-20T03:55:55.661060Z'}
{'type': 'l2update', 'product_id': 'BTC-USD', 'changes': [['sell', '38360.12', '0.00000000']], 'time': '2021-05-20T03:55:55.668404Z'}
{'type': 'l2update', 'product_id': 'BTC-USD', 'changes': [['sell', '38362.05', '0.45030000']], 'time': '2021-05-20T03:55:55.669811Z'}
{'type': 'l2update', 'product_id': 'BTC-USD', 'changes': [['sell', '38360.27', '0.00000000']], 'time': '2021-05-20T03:55:55.671010Z'}
{'type': 'l2update', 'product_id': 'BTC-USD', 'changes': [['sell', '38457.88', '0.00000000']], 'time': '2021-05-20T03:55:55.672802Z'}
{'type': 'l2update', 'product_id': 'BTC-USD', 'changes': [['buy', '38298.46', '0.00000000']], 'time': '2021-05-20T03:55:55.673802Z'}
{'type': 'l2update', 'product_id': 'BTC-USD', 'changes': [['sell', '38360.77', '0.00000000']], 'time': '2021-05-20T03:55:55.679596Z'}
{'type': 'l2update', 'product_id': 'BTC-USD', 'changes': [['sell', '38481.15', '0.00000000']], 'time': '2021-05-20T03:55:55.683730Z'}
{'type': 'l2update', 'product_id': 'BTC-USD', 'changes': [['buy', '38289.60', '0.00000000']], 'time': '2021-05-20T03:55:55.684717Z'}
{'type': 'l2update', 'product_id': 'BTC-USD', 'changes': [['sell', '38343.64', '0.04446257']], 'time': '2021-05-20T03:55:55.690109Z'}
{'type': 'l2update', 'product_id': 'BTC-USD', 'changes': [['sell', '38327.34', '0.00000000']], 'time': '2021-05-20T03:55:55.692531Z'}
{'type': 'l2update', 'product_id': 'BTC-USD', 'changes': [['sell', '38424.59', '0.00000000']], 'time': '2021-05-20T03:55:55.695620Z'}
{'type': 'l2update', 'product_id': 'BTC-USD', 'changes': [['buy', '38207.77', '0.00000000']], 'time': '2021-05-20T03:55:55.698779Z'}
{'type': 'l2update', 'product_id': 'BTC-USD', 'changes': [['sell', '38366.88', '0.01000000']], 'time': '2021-05-20T03:55:55.701390Z'}
{'type': 'l2update', 'product_id': 'BTC-USD', 'changes': [['buy', '38327.33', '0.04731571']], 'time': '2021-05-20T03:55:55.705666Z'}
{'type': 'l2update', 'product_id': 'BTC-USD', 'changes': [['sell', '38445.97', '0.01000000']], 'time': '2021-05-20T03:55:55.706749Z'}
{'type': 'l2update', 'product_id': 'BTC-USD', 'changes': [['sell', '38528.80', '0.00000000']], 'time': '2021-05-20T03:55:55.707146Z'}
{'type': 'l2update', 'product_id': 'BTC-USD', 'changes': [['sell', '38440.77', '0.07539834']], 'time': '2021-05-20T03:55:55.708389Z'}
{'type': 'l2update', 'product_id': 'BTC-USD', 'changes': [['buy', '38273.03', '0.00000000']], 'time': '2021-05-20T03:55:55.708754Z'}
{'type': 'l2update', 'product_id': 'BTC-USD', 'changes': [['sell', '38376.20', '0.00000000']], 'time': '2021-05-20T03:55:55.709376Z'}
{'type': 'l2update', 'product_id': 'BTC-USD', 'changes': [['buy', '38327.33', '0.00000000']], 'time': '2021-05-20T03:55:55.714724Z'}
{'type': 'l2update', 'product_id': 'BTC-USD', 'changes': [['sell', '38359.04', '0.00000000']], 'time': '2021-05-20T03:55:55.718211Z'}
{'type': 'l2update', 'product_id': 'BTC-USD', 'changes': [['sell', '38354.47', '0.04851432']], 'time': '2021-05-20T03:55:55.719303Z'}
{'type': 'l2update', 'product_id': 'BTC-USD', 'changes': [['sell', '38368.40', '0.39490432']], 'time': '2021-05-20T03:55:55.719536Z'}
{'type': 'l2update', 'product_id': 'BTC-USD', 'changes': [['sell', '38368.62', '0.02000000']], 'time': '2021-05-20T03:55:55.719983Z'}
{'type': 'l2update', 'product_id': 'BTC-USD', 'changes': [['buy', '38219.66', '0.01136687']], 'time': '2021-05-20T03:55:55.720039Z'}
{'type': 'l2update', 'product_id': 'BTC-USD', 'changes': [['sell', '38338.55', '0.07460000']], 'time': '2021-05-20T03:55:55.720078Z'}
{'type': 'l2update', 'product_id': 'BTC-USD', 'changes': [['sell', '38338.40', '0.01492000']], 'time': '2021-05-20T03:55:55.720495Z'}
{'type': 'l2update', 'product_id': 'BTC-USD', 'changes': [['buy', '38314.65', '0.07302467']], 'time': '2021-05-20T03:55:55.726096Z'}
{'type': 'l2update', 'product_id': 'BTC-USD', 'changes': [['sell', '38353.12', '0.00000000']], 'time': '2021-05-20T03:55:55.726420Z'}
{'type': 'l2update', 'product_id': 'BTC-USD', 'changes': [['sell', '38342.92', '0.00000000']], 'time': '2021-05-20T03:55:55.726609Z'}
{'type': 'l2update', 'product_id': 'BTC-USD', 'changes': [['sell', '38368.15', '0.09785552']], 'time': '2021-05-20T03:55:55.727317Z'}
{'type': 'l2update', 'product_id': 'BTC-USD', 'changes': [['buy', '38294.07', '0.00000000']], 'time': '2021-05-20T03:55:55.727479Z'}
{'type': 'l2update', 'product_id': 'BTC-USD', 'changes': [['sell', '38435.39', '0.00000000']], 'time': '2021-05-20T03:55:55.729761Z'}
{'type': 'l2update', 'product_id': 'BTC-USD', 'changes': [['sell', '38521.90', '0.00000000']], 'time': '2021-05-20T03:55:55.730171Z'}
{'type': 'l2update', 'product_id': 'BTC-USD', 'changes': [['buy', '38321.02', '0.10000000']], 'time': '2021-05-20T03:55:55.731938Z'}
{'type': 'l2update', 'product_id': 'BTC-USD', 'changes': [['buy', '38321.68', '0.04731571']], 'time': '2021-05-20T03:55:55.732481Z'}
{'type': 'l2update', 'product_id': 'BTC-USD', 'changes': [['sell', '38349.33', '0.00000000']], 'time': '2021-05-20T03:55:55.732714Z'}
{'type': 'l2update', 'product_id': 'BTC-USD', 'changes': [['buy', '38308.25', '0.00000000']], 'time': '2021-05-20T03:55:55.734041Z'}
{'type': 'l2update', 'product_id': 'BTC-USD', 'changes': [['buy', '38319.00', '0.84600000']], 'time': '2021-05-20T03:55:55.734306Z'}
{'type': 'l2update', 'product_id': 'BTC-USD', 'changes': [['sell', '38369.11', '0.03000000']], 'time': '2021-05-20T03:55:55.734829Z'}
{'type': 'l2update', 'product_id': 'BTC-USD', 'changes': [['sell', '38366.05', '0.00000000']], 'time': '2021-05-20T03:55:55.737668Z'}
{'type': 'l2update', 'product_id': 'BTC-USD', 'changes': [['buy', '38321.68', '0.07460000']], 'time': '2021-05-20T03:55:55.738534Z'}
{'type': 'l2update', 'product_id': 'BTC-USD', 'changes': [['buy', '38327.88', '0.01492000']], 'time': '2021-05-20T03:55:55.738631Z'}
{'type': 'l2update', 'product_id': 'BTC-USD', 'changes': [['sell', '38509.04', '0.01000000']], 'time': '2021-05-20T03:55:55.738728Z'}
{'type': 'l2update', 'product_id': 'BTC-USD', 'changes': [['sell', '38429.28', '0.00000000']], 'time': '2021-05-20T03:55:55.739369Z'}
{'type': 'l2update', 'product_id': 'BTC-USD', 'changes': [['buy', '38321.03', '0.00000000']], 'time': '2021-05-20T03:55:55.739835Z'}
{'type': 'l2update', 'product_id': 'BTC-USD', 'changes': [['buy', '38281.80', '0.09224288']], 'time': '2021-05-20T03:55:55.745304Z'}
{'type': 'l2update', 'product_id': 'BTC-USD', 'changes': [['sell', '38349.32', '0.05000000']], 'time': '2021-05-20T03:55:55.746705Z'}
{'type': 'l2update', 'product_id': 'BTC-USD', 'changes': [['sell', '38505.71', '0.00000000']], 'time': '2021-05-20T03:55:55.747550Z'}
{'type': 'l2update', 'product_id': 'BTC-USD', 'changes': [['sell', '38338.55', '0.00000000']], 'time': '2021-05-20T03:55:55.747624Z'}
{'type': 'l2update', 'product_id': 'BTC-USD', 'changes': [['buy', '38327.88', '0.00000000']], 'time': '2021-05-20T03:55:55.748023Z'}
{'type': 'l2update', 'product_id': 'BTC-USD', 'changes': [['buy', '38321.68', '0.04731571']], 'time': '2021-05-20T03:55:55.748863Z'}
{'type': 'l2update', 'product_id': 'BTC-USD', 'changes': [['sell', '38338.89', '0.00000000']], 'time': '2021-05-20T03:55:55.750897Z'}
{'type': 'l2update', 'product_id': 'BTC-USD', 'changes': [['sell', '38353.13', '0.00000000']], 'time': '2021-05-20T03:55:55.751438Z'}
{'type': 'l2update', 'product_id': 'BTC-USD', 'changes': [['sell', '38338.88', '2.48969908']], 'time': '2021-05-20T03:55:55.752916Z'}
{'type': 'l2update', 'product_id': 'BTC-USD', 'changes': [['sell', '38344.09', '0.00600000']], 'time': '2021-05-20T03:55:55.758200Z'}
{'type': 'l2update', 'product_id': 'BTC-USD', 'changes': [['sell', '38480.41', '0.00000000']], 'time': '2021-05-20T03:55:55.758721Z'}
{'type': 'l2update', 'product_id': 'BTC-USD', 'changes': [['sell', '38462.95', '0.01299952']], 'time': '2021-05-20T03:55:55.758779Z'}
{'type': 'l2update', 'product_id': 'BTC-USD', 'changes': [['buy', '38321.68', '0.00000000']], 'time': '2021-05-20T03:55:55.758984Z'}
{'type': 'l2update', 'product_id': 'BTC-USD', 'changes': [['buy', '38308.21', '0.00000000']], 'time': '2021-05-20T03:55:55.760623Z'}
{'type': 'l2update', 'product_id': 'BTC-USD', 'changes': [['buy', '38295.96', '0.00000000']], 'time': '2021-05-20T03:55:55.761945Z'}
{'type': 'l2update', 'product_id': 'BTC-USD', 'changes': [['sell', '38349.32', '0.00000000']], 'time': '2021-05-20T03:55:55.763309Z'}
{'type': 'l2update', 'product_id': 'BTC-USD', 'changes': [['sell', '38338.90', '0.00000000']], 'time': '2021-05-20T03:55:55.765373Z'}
{'type': 'l2update', 'product_id': 'BTC-USD', 'changes': [['buy', '38321.27', '0.02728429']], 'time': '2021-05-20T03:55:55.765436Z'}
{'type': 'l2update', 'product_id': 'BTC-USD', 'changes': [['sell', '38354.47', '0.00000000']], 'time': '2021-05-20T03:55:55.766779Z'}
{'type': 'l2update', 'product_id': 'BTC-USD', 'changes': [['buy', '38106.05', '0.00000000']], 'time': '2021-05-20T03:55:55.767498Z'}
{'type': 'l2update', 'product_id': 'BTC-USD', 'changes': [['buy', '38316.39', '0.00300000']], 'time': '2021-05-20T03:55:55.768715Z'}
{'type': 'l2update', 'product_id': 'BTC-USD', 'changes': [['sell', '38453.95', '0.02783585']], 'time': '2021-05-20T03:55:55.768809Z'}
{'type': 'l2update', 'product_id': 'BTC-USD', 'changes': [['sell', '38337.86', '0.07460000']], 'time': '2021-05-20T03:55:55.768941Z'}
{'type': 'l2update', 'product_id': 'BTC-USD', 'changes': [['sell', '38517.97', '0.01884450']], 'time': '2021-05-20T03:55:55.769030Z'}
{'type': 'l2update', 'product_id': 'BTC-USD', 'changes': [['sell', '38376.59', '0.03207306']], 'time': '2021-05-20T03:55:55.769620Z'}
{'type': 'l2update', 'product_id': 'BTC-USD', 'changes': [['sell', '38342.90', '0.50000000']], 'time': '2021-05-20T03:55:55.769910Z'}
{'type': 'l2update', 'product_id': 'BTC-USD', 'changes': [['buy', '38322.11', '0.01492000']], 'time': '2021-05-20T03:55:55.770097Z'}
{'type': 'l2update', 'product_id': 'BTC-USD', 'changes': [['buy', '38262.55', '0.00000000']], 'time': '2021-05-20T03:55:55.771269Z'}
{'type': 'l2update', 'product_id': 'BTC-USD', 'changes': [['buy', '38327.33', '0.12372588']], 'time': '2021-05-20T03:55:55.774101Z'}
{'type': 'l2update', 'product_id': 'BTC-USD', 'changes': [['buy', '38314.65', '0.00000000']], 'time': '2021-05-20T03:55:55.774553Z'}
{'type': 'l2update', 'product_id': 'BTC-USD', 'changes': [['sell', '38362.04', '0.05000000']], 'time': '2021-05-20T03:55:55.778846Z'}
{'type': 'l2update', 'product_id': 'BTC-USD', 'changes': [['sell', '38437.73', '0.01000000']], 'time': '2021-05-20T03:55:55.779263Z'}
{'type': 'l2update', 'product_id': 'BTC-USD', 'changes': [['sell', '38515.51', '0.01000000']], 'time': '2021-05-20T03:55:55.779426Z'}
{'type': 'l2update', 'product_id': 'BTC-USD', 'changes': [['buy', '38321.27', '0.07460000']], 'time': '2021-05-20T03:55:55.779530Z'}
{'type': 'l2update', 'product_id': 'BTC-USD', 'changes': [['sell', '38374.91', '0.00000000']], 'time': '2021-05-20T03:55:55.779735Z'}
{'type': 'l2update', 'product_id': 'BTC-USD', 'changes': [['sell', '38338.40', '0.00000000']], 'time': '2021-05-20T03:55:55.780373Z'}
{'type': 'l2update', 'product_id': 'BTC-USD', 'changes': [['buy', '38321.27', '0.04731571']], 'time': '2021-05-20T03:55:55.782419Z'}
{'type': 'l2update', 'product_id': 'BTC-USD', 'changes': [['sell', '38342.90', '0.00000000']], 'time': '2021-05-20T03:55:55.783400Z'}
{'type': 'l2update', 'product_id': 'BTC-USD', 'changes': [['buy', '38308.22', '0.07302467']], 'time': '2021-05-20T03:55:55.784582Z'}
{'type': 'l2update', 'product_id': 'BTC-USD', 'changes': [['buy', '38327.33', '0.12141927']], 'time': '2021-05-20T03:55:55.790678Z'}
{'type': 'l2update', 'product_id': 'BTC-USD', 'changes': [['sell', '38476.21', '0.29956217']], 'time': '2021-05-20T03:55:55.790981Z'}
{'type': 'l2update', 'product_id': 'BTC-USD', 'changes': [['buy', '38321.27', '0.00000000']], 'time': '2021-05-20T03:55:55.791403Z'}
{'type': 'l2update', 'product_id': 'BTC-USD', 'changes': [['buy', '38114.82', '0.00000000']], 'time': '2021-05-20T03:55:55.792105Z'}
{'type': 'l2update', 'product_id': 'BTC-USD', 'changes': [['buy', '38322.11', '0.00000000']], 'time': '2021-05-20T03:55:55.792442Z'}
{'type': 'l2update', 'product_id': 'BTC-USD', 'changes': [['buy', '38319.01', '0.99315797']], 'time': '2021-05-20T03:55:55.795608Z'}
{'type': 'l2update', 'product_id': 'BTC-USD', 'changes': [['sell', '38367.81', '0.46856481']], 'time': '2021-05-20T03:55:55.795830Z'}
{'type': 'l2update', 'product_id': 'BTC-USD', 'changes': [['buy', '37718.59', '0.04190000']], 'time': '2021-05-20T03:55:55.795954Z'}
{'type': 'l2update', 'product_id': 'BTC-USD', 'changes': [['buy', '37244.65', '0.05920000']], 'time': '2021-05-20T03:55:55.795954Z'}
{'type': 'l2update', 'product_id': 'BTC-USD', 'changes': [['buy', '38204.35', '0.01000000']], 'time': '2021-05-20T03:55:55.802170Z'}
{'type': 'l2update', 'product_id': 'BTC-USD', 'changes': [['sell', '38370.25', '0.00000000']], 'time': '2021-05-20T03:55:55.803547Z'}
{'type': 'l2update', 'product_id': 'BTC-USD', 'changes': [['sell', '38338.88', '0.00000000']], 'time': '2021-05-20T03:55:55.805153Z'}
{'type': 'l2update', 'product_id': 'BTC-USD', 'changes': [['sell', '38349.04', '0.50000000']], 'time': '2021-05-20T03:55:55.806860Z'}
{'type': 'l2update', 'product_id': 'BTC-USD', 'changes': [['buy', '37516.83', '0.06491207']], 'time': '2021-05-20T03:55:55.808072Z'}
{'type': 'l2update', 'product_id': 'BTC-USD', 'changes': [['sell', '38634.85', '0.00000000']], 'time': '2021-05-20T03:55:55.808306Z'}
{'type': 'l2update', 'product_id': 'BTC-USD', 'changes': [['sell', '38337.17', '0.01492000']], 'time': '2021-05-20T03:55:55.813228Z'}
{'type': 'l2update', 'product_id': 'BTC-USD', 'changes': [['buy', '38138.91', '0.01286850']], 'time': '2021-05-20T03:55:55.813594Z'}
{'type': 'l2update', 'product_id': 'BTC-USD', 'changes': [['buy', '38327.70', '0.02728429']], 'time': '2021-05-20T03:55:55.813687Z'}
{'type': 'l2update', 'product_id': 'BTC-USD', 'changes': [['sell', '38343.64', '0.00000000']], 'time': '2021-05-20T03:55:55.816187Z'}
{'type': 'l2update', 'product_id': 'BTC-USD', 'changes': [['sell', '38504.15', '0.00000000']], 'time': '2021-05-20T03:55:55.816473Z'}
{'type': 'l2update', 'product_id': 'BTC-USD', 'changes': [['sell', '38368.00', '0.00000000']], 'time': '2021-05-20T03:55:55.816686Z'}
{'type': 'l2update', 'product_id': 'BTC-USD', 'changes': [['sell', '38337.86', '0.00000000']], 'time': '2021-05-20T03:55:55.819401Z'}
{'type': 'l2update', 'product_id': 'BTC-USD', 'changes': [['buy', '38327.33', '0.00000000']], 'time': '2021-05-20T03:55:55.822563Z'}
{'type': 'l2update', 'product_id': 'BTC-USD', 'changes': [['buy', '38216.75', '0.01000000']], 'time': '2021-05-20T03:55:55.822905Z'}
{'type': 'l2update', 'product_id': 'BTC-USD', 'changes': [['buy', '38327.70', '0.07068245']], 'time': '2021-05-20T03:55:55.823127Z'}
{'type': 'l2update', 'product_id': 'BTC-USD', 'changes': [['sell', '39126.21', '0.06443648']], 'time': '2021-05-20T03:55:55.827359Z'}
{'type': 'l2update', 'product_id': 'BTC-USD', 'changes': [['sell', '38619.76', '0.01294674']], 'time': '2021-05-20T03:55:55.828208Z'}
{'type': 'l2update', 'product_id': 'BTC-USD', 'changes': [['sell', '38342.90', '2.48969908']], 'time': '2021-05-20T03:55:55.828272Z'}
{'type': 'l2update', 'product_id': 'BTC-USD', 'changes': [['buy', '38327.99', '0.01492000']], 'time': '2021-05-20T03:55:55.828871Z'}
{'type': 'l2update', 'product_id': 'BTC-USD', 'changes': [['buy', '38299.42', '0.00000000']], 'time': '2021-05-20T03:55:55.829525Z'}
{'type': 'l2update', 'product_id': 'BTC-USD', 'changes': [['buy', '38281.80', '0.00000000']], 'time': '2021-05-20T03:55:55.830156Z'}
{'type': 'l2update', 'product_id': 'BTC-USD', 'changes': [['buy', '38327.70', '0.07460000']], 'time': '2021-05-20T03:55:55.832290Z'}
{'type': 'l2update', 'product_id': 'BTC-USD', 'changes': [['sell', '38375.46', '0.05000000']], 'time': '2021-05-20T03:55:55.832323Z'}
{'type': 'l2update', 'product_id': 'BTC-USD', 'changes': [['buy', '38327.70', '0.04731571']], 'time': '2021-05-20T03:55:55.833014Z'}
{'type': 'l2update', 'product_id': 'BTC-USD', 'changes': [['sell', '38527.05', '0.01000000']], 'time': '2021-05-20T03:55:55.833050Z'}
{'type': 'l2update', 'product_id': 'BTC-USD', 'changes': [['buy', '38327.70', '0.00391755']], 'time': '2021-05-20T03:55:55.833211Z'}
{'type': 'l2update', 'product_id': 'BTC-USD', 'changes': [['sell', '38337.17', '0.00000000']], 'time': '2021-05-20T03:55:55.841414Z'}
{'type': 'l2update', 'product_id': 'BTC-USD', 'changes': [['sell', '38421.85', '0.00000000']], 'time': '2021-05-20T03:55:55.841934Z'}
{'type': 'l2update', 'product_id': 'BTC-USD', 'changes': [['buy', '38327.70', '0.00000000']], 'time': '2021-05-20T03:55:55.842011Z'}
{'type': 'l2update', 'product_id': 'BTC-USD', 'changes': [['sell', '38342.90', '2.48845195']], 'time': '2021-05-20T03:55:55.844384Z'}
{'type': 'l2update', 'product_id': 'BTC-USD', 'changes': [['buy', '38319.00', '0.00000000']], 'time': '2021-05-20T03:55:55.845023Z'}
{'type': 'l2update', 'product_id': 'BTC-USD', 'changes': [['buy', '38306.13', '0.02400000']], 'time': '2021-05-20T03:55:55.845412Z'}
{'type': 'l2update', 'product_id': 'BTC-USD', 'changes': [['buy', '38327.99', '0.00000000']], 'time': '2021-05-20T03:55:55.851585Z'}
{'type': 'l2update', 'product_id': 'BTC-USD', 'changes': [['buy', '38314.64', '0.52100000']], 'time': '2021-05-20T03:55:55.852472Z'}
{'type': 'l2update', 'product_id': 'BTC-USD', 'changes': [['buy', '38303.96', '0.00000000']], 'time': '2021-05-20T03:55:55.855250Z'}
{'type': 'l2update', 'product_id': 'BTC-USD', 'changes': [['buy', '38328.31', '0.04731571']], 'time': '2021-05-20T03:55:55.856914Z'}
{'type': 'l2update', 'product_id': 'BTC-USD', 'changes': [['sell', '38336.91', '0.02462218']], 'time': '2021-05-20T03:55:55.856945Z'}
{'type': 'l2update', 'product_id': 'BTC-USD', 'changes': [['sell', '38342.90', '0.00000000']], 'time': '2021-05-20T03:55:55.858271Z'}
{'type': 'l2update', 'product_id': 'BTC-USD', 'changes': [['sell', '38362.04', '0.00000000']], 'time': '2021-05-20T03:55:55.859654Z'}
{'type': 'l2update', 'product_id': 'BTC-USD', 'changes': [['buy', '38295.21', '0.09721550']], 'time': '2021-05-20T03:55:55.862159Z'}
{'type': 'l2update', 'product_id': 'BTC-USD', 'changes': [['sell', '38342.23', '0.01492000']], 'time': '2021-05-20T03:55:55.862956Z'}
{'type': 'l2update', 'product_id': 'BTC-USD', 'changes': [['sell', '38447.10', '0.03675348']], 'time': '2021-05-20T03:55:55.863076Z'}
{'type': 'l2update', 'product_id': 'BTC-USD', 'changes': [['sell', '38384.35', '0.03241112']], 'time': '2021-05-20T03:55:55.863076Z'}
{'type': 'l2update', 'product_id': 'BTC-USD', 'changes': [['buy', '38289.84', '0.02824212']], 'time': '2021-05-20T03:55:55.863076Z'}
{'type': 'l2update', 'product_id': 'BTC-USD', 'changes': [['buy', '38294.01', '0.01059612']], 'time': '2021-05-20T03:55:55.863076Z'}
{'type': 'l2update', 'product_id': 'BTC-USD', 'changes': [['buy', '38328.31', '0.04878056']], 'time': '2021-05-20T03:55:55.863936Z'}
{'type': 'l2update', 'product_id': 'BTC-USD', 'changes': [['sell', '38365.31', '0.04911832']], 'time': '2021-05-20T03:55:55.864434Z'}
{'type': 'l2update', 'product_id': 'BTC-USD', 'changes': [['buy', '38319.01', '0.00000000']], 'time': '2021-05-20T03:55:55.869495Z'}
{'type': 'l2update', 'product_id': 'BTC-USD', 'changes': [['buy', '38308.22', '0.00000000']], 'time': '2021-05-20T03:55:55.872824Z'}
{'type': 'l2update', 'product_id': 'BTC-USD', 'changes': [['sell', '38342.23', '0.00000000']], 'time': '2021-05-20T03:55:55.873380Z'}
{'type': 'l2update', 'product_id': 'BTC-USD', 'changes': [['sell', '38366.00', '0.00000000']], 'time': '2021-05-20T03:55:55.873932Z'}
{'type': 'l2update', 'product_id': 'BTC-USD', 'changes': [['sell', '38336.91', '0.07460000']], 'time': '2021-05-20T03:55:55.874550Z'}
{'type': 'l2update', 'product_id': 'BTC-USD', 'changes': [['buy', '38328.31', '0.05899668']], 'time': '2021-05-20T03:55:55.875003Z'}
{'type': 'l2update', 'product_id': 'BTC-USD', 'changes': [['sell', '38364.17', '0.01000000']], 'time': '2021-05-20T03:55:55.875524Z'}
{'type': 'l2update', 'product_id': 'BTC-USD', 'changes': [['buy', '38321.07', '0.84600000']], 'time': '2021-05-20T03:55:55.875834Z'}
{'type': 'l2update', 'product_id': 'BTC-USD', 'changes': [['buy', '38304.39', '0.07302467']], 'time': '2021-05-20T03:55:55.876181Z'}
{'type': 'l2update', 'product_id': 'BTC-USD', 'changes': [['sell', '38409.39', '0.03171410']], 'time': '2021-05-20T03:55:55.876249Z'}
{'type': 'l2update', 'product_id': 'BTC-USD', 'changes': [['sell', '38367.39', '0.00000000']], 'time': '2021-05-20T03:55:55.876249Z'}
{'type': 'l2update', 'product_id': 'BTC-USD', 'changes': [['buy', '38273.02', '0.00000000']], 'time': '2021-05-20T03:55:55.876249Z'}
{'type': 'l2update', 'product_id': 'BTC-USD', 'changes': [['buy', '38277.19', '0.00000000']], 'time': '2021-05-20T03:55:55.876249Z'}
{'type': 'l2update', 'product_id': 'BTC-USD', 'changes': [['buy', '38287.41', '1.20000000']], 'time': '2021-05-20T03:55:55.876293Z'}
{'type': 'l2update', 'product_id': 'BTC-USD', 'changes': [['buy', '38328.31', '0.05753183']], 'time': '2021-05-20T03:55:55.876506Z'}
{'type': 'l2update', 'product_id': 'BTC-USD', 'changes': [['buy', '38321.35', '0.01492000']], 'time': '2021-05-20T03:55:55.879541Z'}
{'type': 'l2update', 'product_id': 'BTC-USD', 'changes': [['sell', '38349.03', '0.05000000']], 'time': '2021-05-20T03:55:55.880016Z'}
{'type': 'l2update', 'product_id': 'BTC-USD', 'changes': [['sell', '38336.91', '0.02462218']], 'time': '2021-05-20T03:55:55.883442Z'}
{'type': 'l2update', 'product_id': 'BTC-USD', 'changes': [['buy', '38300.46', '0.06092019']], 'time': '2021-05-20T03:55:55.887191Z'}
{'type': 'l2update', 'product_id': 'BTC-USD', 'changes': [['sell', '38341.76', '0.06361006']], 'time': '2021-05-20T03:55:55.887191Z'}
{'type': 'l2update', 'product_id': 'BTC-USD', 'changes': [['sell', '38342.90', '2.48969908']], 'time': '2021-05-20T03:55:55.887415Z'}
{'type': 'l2update', 'product_id': 'BTC-USD', 'changes': [['buy', '38205.65', '0.00000000']], 'time': '2021-05-20T03:55:55.887613Z'}
{'type': 'l2update', 'product_id': 'BTC-USD', 'changes': [['buy', '38302.06', '0.00000000']], 'time': '2021-05-20T03:55:55.887871Z'}
{'type': 'l2update', 'product_id': 'BTC-USD', 'changes': [['buy', '38321.35', '0.00000000']], 'time': '2021-05-20T03:55:55.891416Z'}
{'type': 'l2update', 'product_id': 'BTC-USD', 'changes': [['buy', '38180.12', '0.11510000']], 'time': '2021-05-20T03:55:55.892057Z'}
{'type': 'l2update', 'product_id': 'BTC-USD', 'changes': [['buy', '38328.31', '0.07313515']], 'time': '2021-05-20T03:55:55.892300Z'}
{'type': 'l2update', 'product_id': 'BTC-USD', 'changes': [['sell', '38336.28', '0.01492000']], 'time': '2021-05-20T03:55:55.892751Z'}
{'type': 'l2update', 'product_id': 'BTC-USD', 'changes': [['buy', '38328.31', '0.06291903']], 'time': '2021-05-20T03:55:55.893120Z'}
{'type': 'l2update', 'product_id': 'BTC-USD', 'changes': [['buy', '38321.04', '0.12372588']], 'time': '2021-05-20T03:55:55.897067Z'}
{'type': 'l2update', 'product_id': 'BTC-USD', 'changes': [['buy', '38314.64', '0.00000000']], 'time': '2021-05-20T03:55:55.897221Z'}
{'type': 'l2update', 'product_id': 'BTC-USD', 'changes': [['sell', '38422.43', '1.20000000']], 'time': '2021-05-20T03:55:55.897749Z'}
{'type': 'l2update', 'product_id': 'BTC-USD', 'changes': [['buy', '38281.77', '0.01000000']], 'time': '2021-05-20T03:55:55.897822Z'}
{'type': 'l2update', 'product_id': 'BTC-USD', 'changes': [['buy', '38328.31', '0.01560332']], 'time': '2021-05-20T03:55:55.900361Z'}
{'type': 'l2update', 'product_id': 'BTC-USD', 'changes': [['buy', '38328.31', '0.00000000']], 'time': '2021-05-20T03:55:55.901001Z'}
{'type': 'l2update', 'product_id': 'BTC-USD', 'changes': [['buy', '38308.20', '0.00000000']], 'time': '2021-05-20T03:55:55.904165Z'}
{'type': 'l2update', 'product_id': 'BTC-USD', 'changes': [['sell', '38336.91', '0.00000000']], 'time': '2021-05-20T03:55:55.906923Z'}
{'type': 'l2update', 'product_id': 'BTC-USD', 'changes': [['buy', '38319.01', '0.99440510']], 'time': '2021-05-20T03:55:55.907579Z'}
{'type': 'l2update', 'product_id': 'BTC-USD', 'changes': [['buy', '38219.19', '0.01000000']], 'time': '2021-05-20T03:55:55.907610Z'}
{'type': 'l2update', 'product_id': 'BTC-USD', 'changes': [['buy', '38321.63', '0.00146485']], 'time': '2021-05-20T03:55:55.908619Z'}
{'type': 'l2update', 'product_id': 'BTC-USD', 'changes': [['sell', '38341.30', '0.04997782']], 'time': '2021-05-20T03:55:55.908716Z'}
{'type': 'l2update', 'product_id': 'BTC-USD', 'changes': [['buy', '38321.07', '0.00000000']], 'time': '2021-05-20T03:55:55.909320Z'}
{'type': 'l2update', 'product_id': 'BTC-USD', 'changes': [['sell', '38375.46', '0.00000000']], 'time': '2021-05-20T03:55:55.909433Z'}
{'type': 'l2update', 'product_id': 'BTC-USD', 'changes': [['buy', '38304.39', '0.00000000']], 'time': '2021-05-20T03:55:55.916110Z'}
{'type': 'l2update', 'product_id': 'BTC-USD', 'changes': [['sell', '38341.30', '0.00000000']], 'time': '2021-05-20T03:55:55.916437Z'}
{'type': 'l2update', 'product_id': 'BTC-USD', 'changes': [['sell', '38336.28', '0.00000000']], 'time': '2021-05-20T03:55:55.916818Z'}
{'type': 'l2update', 'product_id': 'BTC-USD', 'changes': [['buy', '38321.73', '0.01492000']], 'time': '2021-05-20T03:55:55.917070Z'}
{'type': 'l2update', 'product_id': 'BTC-USD', 'changes': [['buy', '38321.63', '0.00000000']], 'time': '2021-05-20T03:55:55.923233Z'}
{'type': 'l2update', 'product_id': 'BTC-USD', 'changes': [['sell', '38368.47', '0.05000000']], 'time': '2021-05-20T03:55:55.925359Z'}
{'type': 'l2update', 'product_id': 'BTC-USD', 'changes': [['buy', '38301.98', '0.07302467']], 'time': '2021-05-20T03:55:55.925463Z'}
{'type': 'l2update', 'product_id': 'BTC-USD', 'changes': [['buy', '38321.63', '0.07313515']], 'time': '2021-05-20T03:55:55.925638Z'}
{'type': 'l2update', 'product_id': 'BTC-USD', 'changes': [['buy', '38321.63', '0.00000000']], 'time': '2021-05-20T03:55:55.931714Z'}
{'type': 'l2update', 'product_id': 'BTC-USD', 'changes': [['buy', '38250.33', '0.00000000']], 'time': '2021-05-20T03:55:55.932810Z'}
{'type': 'l2update', 'product_id': 'BTC-USD', 'changes': [['buy', '38301.98', '0.00000000']], 'time': '2021-05-20T03:55:55.933223Z'}
{'type': 'l2update', 'product_id': 'BTC-USD', 'changes': [['sell', '38341.39', '0.01492000']], 'time': '2021-05-20T03:55:55.935100Z'}
{'type': 'l2update', 'product_id': 'BTC-USD', 'changes': [['buy', '38321.08', '0.10000000']], 'time': '2021-05-20T03:55:55.935570Z'}
{'type': 'l2update', 'product_id': 'BTC-USD', 'changes': [['buy', '38304.38', '0.00000000']], 'time': '2021-05-20T03:55:55.938144Z'}
{'type': 'l2update', 'product_id': 'BTC-USD', 'changes': [['sell', '38335.99', '0.02462218']], 'time': '2021-05-20T03:55:55.940520Z'}
{'type': 'l2update', 'product_id': 'BTC-USD', 'changes': [['sell', '38370.99', '0.00000000']], 'time': '2021-05-20T03:55:55.945575Z'}
{'type': 'l2update', 'product_id': 'BTC-USD', 'changes': [['sell', '38335.99', '0.00000000']], 'time': '2021-05-20T03:55:55.946410Z'}
{'type': 'l2update', 'product_id': 'BTC-USD', 'changes': [['sell', '38341.39', '0.00000000']], 'time': '2021-05-20T03:55:55.947883Z'}
{'type': 'l2update', 'product_id': 'BTC-USD', 'changes': [['buy', '38298.27', '0.46530000']], 'time': '2021-05-20T03:55:55.949038Z'}
{'type': 'l2update', 'product_id': 'BTC-USD', 'changes': [['buy', '38299.57', '0.07302467']], 'time': '2021-05-20T03:55:55.949110Z'}
{'type': 'l2update', 'product_id': 'BTC-USD', 'changes': [['sell', '38342.91', '0.00000000']], 'time': '2021-05-20T03:55:55.951221Z'}
{'type': 'l2update', 'product_id': 'BTC-USD', 'changes': [['sell', '38341.23', '0.04997782']], 'time': '2021-05-20T03:55:55.953700Z'}
{'type': 'l2update', 'product_id': 'BTC-USD', 'changes': [['buy', '38298.27', '0.00000000']], 'time': '2021-05-20T03:55:55.954399Z'}
{'type': 'l2update', 'product_id': 'BTC-USD', 'changes': [['sell', '38453.95', '0.06588498']], 'time': '2021-05-20T03:55:55.958889Z'}
{'type': 'l2update', 'product_id': 'BTC-USD', 'changes': [['buy', '38271.07', '1.28216430']], 'time': '2021-05-20T03:55:55.958926Z'}
{'type': 'l2update', 'product_id': 'BTC-USD', 'changes': [['sell', '38341.23', '0.07460000']], 'time': '2021-05-20T03:55:55.958982Z'}
{'type': 'l2update', 'product_id': 'BTC-USD', 'changes': [['sell', '38338.30', '0.04869904']], 'time': '2021-05-20T03:55:55.958994Z'}
{'type': 'l2update', 'product_id': 'BTC-USD', 'changes': [['buy', '38305.32', '0.00000000']], 'time': '2021-05-20T03:55:55.959175Z'}
{'type': 'l2update', 'product_id': 'BTC-USD', 'changes': [['buy', '38304.51', '0.00000000']], 'time': '2021-05-20T03:55:55.959175Z'}
{'type': 'l2update', 'product_id': 'BTC-USD', 'changes': [['buy', '38321.08', '0.00000000']], 'time': '2021-05-20T03:55:55.960910Z'}
{'type': 'l2update', 'product_id': 'BTC-USD', 'changes': [['sell', '38341.76', '0.00000000']], 'time': '2021-05-20T03:55:55.961087Z'}
{'type': 'l2update', 'product_id': 'BTC-USD', 'changes': [['buy', '38299.57', '0.00000000']], 'time': '2021-05-20T03:55:55.963070Z'}
{'type': 'l2update', 'product_id': 'BTC-USD', 'changes': [['sell', '38391.80', '0.61482416']], 'time': '2021-05-20T03:55:55.964016Z'}
{'type': 'l2update', 'product_id': 'BTC-USD', 'changes': [['buy', '38321.04', '0.00000000']], 'time': '2021-05-20T03:55:55.964724Z'}
{'type': 'l2update', 'product_id': 'BTC-USD', 'changes': [['sell', '38341.23', '0.04997782']], 'time': '2021-05-20T03:55:55.965348Z'}
{'type': 'l2update', 'product_id': 'BTC-USD', 'changes': [['buy', '38322.04', '0.07460000']], 'time': '2021-05-20T03:55:55.968276Z'}
{'type': 'l2update', 'product_id': 'BTC-USD', 'changes': [['sell', '38341.34', '0.01492000']], 'time': '2021-05-20T03:55:55.968301Z'}
{'type': 'l2update', 'product_id': 'BTC-USD', 'changes': [['buy', '37514.31', '0.06644023']], 'time': '2021-05-20T03:55:55.968377Z'}
{'type': 'l2update', 'product_id': 'BTC-USD', 'changes': [['sell', '38368.47', '0.00000000']], 'time': '2021-05-20T03:55:55.970306Z'}
{'type': 'l2update', 'product_id': 'BTC-USD', 'changes': [['buy', '38216.75', '0.00000000']], 'time': '2021-05-20T03:55:55.970712Z'}
{'type': 'l2update', 'product_id': 'BTC-USD', 'changes': [['buy', '38295.22', '0.07302467']], 'time': '2021-05-20T03:55:55.973416Z'}
{'type': 'l2update', 'product_id': 'BTC-USD', 'changes': [['buy', '38286.07', '0.00000000']], 'time': '2021-05-20T03:55:55.974184Z'}
{'type': 'l2update', 'product_id': 'BTC-USD', 'changes': [['sell', '38341.23', '0.00000000']], 'time': '2021-05-20T03:55:55.974584Z'}
{'type': 'l2update', 'product_id': 'BTC-USD', 'changes': [['sell', '38341.34', '0.00000000']], 'time': '2021-05-20T03:55:55.975250Z'}
{'type': 'l2update', 'product_id': 'BTC-USD', 'changes': [['buy', '38321.73', '0.00000000']], 'time': '2021-05-20T03:55:55.976839Z'}
{'type': 'l2update', 'product_id': 'BTC-USD', 'changes': [['buy', '38279.20', '0.00000000']], 'time': '2021-05-20T03:55:55.978827Z'}
{'type': 'l2update', 'product_id': 'BTC-USD', 'changes': [['buy', '38278.81', '0.00000000']], 'time': '2021-05-20T03:55:55.982809Z'}
{'type': 'l2update', 'product_id': 'BTC-USD', 'changes': [['buy', '38299.56', '0.00000000']], 'time': '2021-05-20T03:55:55.983586Z'}
{'type': 'l2update', 'product_id': 'BTC-USD', 'changes': [['sell', '38337.79', '0.02462218']], 'time': '2021-05-20T03:55:55.985124Z'}
{'type': 'l2update', 'product_id': 'BTC-USD', 'changes': [['sell', '39120.18', '0.06517356']], 'time': '2021-05-20T03:55:55.985195Z'}
{'type': 'l2update', 'product_id': 'BTC-USD', 'changes': [['buy', '38308.07', '0.02400000']], 'time': '2021-05-20T03:55:55.985234Z'}
{'type': 'l2update', 'product_id': 'BTC-USD', 'changes': [['buy', '38307.26', '0.02400000']], 'time': '2021-05-20T03:55:55.985234Z'}
{'type': 'l2update', 'product_id': 'BTC-USD', 'changes': [['buy', '38233.93', '0.01000000']], 'time': '2021-05-20T03:55:55.985328Z'}
{'type': 'l2update', 'product_id': 'BTC-USD', 'changes': [['buy', '38291.71', '0.00000000']], 'time': '2021-05-20T03:55:55.990716Z'}
{'type': 'l2update', 'product_id': 'BTC-USD', 'changes': [['sell', '38411.48', '0.00000000']], 'time': '2021-05-20T03:55:55.992719Z'}
{'type': 'l2update', 'product_id': 'BTC-USD', 'changes': [['sell', '38409.39', '0.00000000']], 'time': '2021-05-20T03:55:55.992719Z'}
{'type': 'l2update', 'product_id': 'BTC-USD', 'changes': [['sell', '38400.64', '0.00000000']], 'time': '2021-05-20T03:55:55.992719Z'}
{'type': 'l2update', 'product_id': 'BTC-USD', 'changes': [['buy', '38295.22', '0.00000000']], 'time': '2021-05-20T03:55:55.994006Z'}
{'type': 'l2update', 'product_id': 'BTC-USD', 'changes': [['sell', '38374.62', '0.05000000']], 'time': '2021-05-20T03:55:55.996388Z'}
{'type': 'l2update', 'product_id': 'BTC-USD', 'changes': [['sell', '38362.05', '0.00000000']], 'time': '2021-05-20T03:55:56.000817Z'}
{'type': 'l2update', 'product_id': 'BTC-USD', 'changes': [['buy', '38308.07', '0.00000000']], 'time': '2021-05-20T03:55:56.000983Z'}
{'type': 'l2update', 'product_id': 'BTC-USD', 'changes': [['buy', '38291.15', '0.07302467']], 'time': '2021-05-20T03:55:56.003170Z'}
{'type': 'l2update', 'product_id': 'BTC-USD', 'changes': [['sell', '38337.29', '0.01492000']], 'time': '2021-05-20T03:55:56.003188Z'}
{'type': 'l2update', 'product_id': 'BTC-USD', 'changes': [['buy', '38322.35', '0.01492000']], 'time': '2021-05-20T03:55:56.003351Z'}
{'type': 'l2update', 'product_id': 'BTC-USD', 'changes': [['sell', '38388.66', '0.04990465']], 'time': '2021-05-20T03:55:56.003372Z'}
{'type': 'l2update', 'product_id': 'BTC-USD', 'changes': [['sell', '38374.09', '0.00000000']], 'time': '2021-05-20T03:55:56.003397Z'}
{'type': 'l2update', 'product_id': 'BTC-USD', 'changes': [['sell', '38349.04', '0.00000000']], 'time': '2021-05-20T03:55:56.006670Z'}
{'type': 'l2update', 'product_id': 'BTC-USD', 'changes': [['buy', '38326.70', '0.04964674']], 'time': '2021-05-20T03:55:56.007930Z'}
{'type': 'l2update', 'product_id': 'BTC-USD', 'changes': [['buy', '38322.09', '0.84700000']], 'time': '2021-05-20T03:55:56.007983Z'}
{'type': 'l2update', 'product_id': 'BTC-USD', 'changes': [['buy', '38165.71', '0.04830503']], 'time': '2021-05-20T03:55:56.008073Z'}
{'type': 'l2update', 'product_id': 'BTC-USD', 'changes': [['buy', '38327.34', '0.12257258']], 'time': '2021-05-20T03:55:56.008210Z'}
{'type': 'l2update', 'product_id': 'BTC-USD', 'changes': [['sell', '38337.79', '0.00000000']], 'time': '2021-05-20T03:55:56.008921Z'}
{'type': 'l2update', 'product_id': 'BTC-USD', 'changes': [['buy', '38322.04', '0.00000000']], 'time': '2021-05-20T03:55:56.009218Z'}
{'type': 'l2update', 'product_id': 'BTC-USD', 'changes': [['sell', '38360.57', '0.46330000']], 'time': '2021-05-20T03:55:56.013068Z'}
{'type': 'l2update', 'product_id': 'BTC-USD', 'changes': [['sell', '38337.29', '0.01367260']], 'time': '2021-05-20T03:55:56.013485Z'}
{'type': 'l2update', 'product_id': 'BTC-USD', 'changes': [['buy', '38292.42', '0.02000000']], 'time': '2021-05-20T03:55:56.013760Z'}
{'type': 'l2update', 'product_id': 'BTC-USD', 'changes': [['buy', '38305.03', '0.02400000']], 'time': '2021-05-20T03:55:56.014239Z'}
{'type': 'l2update', 'product_id': 'BTC-USD', 'changes': [['sell', '38349.03', '0.00000000']], 'time': '2021-05-20T03:55:56.014957Z'}
{'type': 'l2update', 'product_id': 'BTC-USD', 'changes': [['buy', '38322.09', '0.00000000']], 'time': '2021-05-20T03:55:56.016045Z'}
{'type': 'l2update', 'product_id': 'BTC-USD', 'changes': [['buy', '38322.35', '0.00000000']], 'time': '2021-05-20T03:55:56.017417Z'}
{'type': 'l2update', 'product_id': 'BTC-USD', 'changes': [['buy', '38318.95', '0.00000000']], 'time': '2021-05-20T03:55:56.018592Z'}
{'type': 'l2update', 'product_id': 'BTC-USD', 'changes': [['sell', '38342.90', '0.00000000']], 'time': '2021-05-20T03:55:56.020445Z'}
{'type': 'l2update', 'product_id': 'BTC-USD', 'changes': [['sell', '38414.80', '0.02603163']], 'time': '2021-05-20T03:55:56.021264Z'}
{'type': 'l2update', 'product_id': 'BTC-USD', 'changes': [['sell', '38619.76', '0.00000000']], 'time': '2021-05-20T03:55:56.021631Z'}
{'type': 'l2update', 'product_id': 'BTC-USD', 'changes': [['sell', '38337.29', '0.00000000']], 'time': '2021-05-20T03:55:56.022491Z'}
{'type': 'l2update', 'product_id': 'BTC-USD', 'changes': [['sell', '38338.30', '0.00000000']], 'time': '2021-05-20T03:55:56.024260Z'}
{'type': 'l2update', 'product_id': 'BTC-USD', 'changes': [['buy', '38155.16', '0.00000000']], 'time': '2021-05-20T03:55:56.026517Z'}
{'type': 'l2update', 'product_id': 'BTC-USD', 'changes': [['sell', '38342.89', '0.50000000']], 'time': '2021-05-20T03:55:56.026526Z'}
{'type': 'l2update', 'product_id': 'BTC-USD', 'changes': [['sell', '38336.92', '0.04997782']], 'time': '2021-05-20T03:55:56.026562Z'}
{'type': 'l2update', 'product_id': 'BTC-USD', 'changes': [['buy', '38327.34', '0.00000000']], 'time': '2021-05-20T03:55:56.026804Z'}
{'type': 'l2update', 'product_id': 'BTC-USD', 'changes': [['buy', '38327.87', '0.07460000']], 'time': '2021-05-20T03:55:56.026902Z'}
{'type': 'l2update', 'product_id': 'BTC-USD', 'changes': [['sell', '38381.66', '0.20600000']], 'time': '2021-05-20T03:55:56.032371Z'}
{'type': 'l2update', 'product_id': 'BTC-USD', 'changes': [['buy', '38233.93', '0.00000000']], 'time': '2021-05-20T03:55:56.033501Z'}
{'type': 'l2update', 'product_id': 'BTC-USD', 'changes': [['buy', '38291.22', '0.04000000']], 'time': '2021-05-20T03:55:56.036747Z'}
{'type': 'l2update', 'product_id': 'BTC-USD', 'changes': [['sell', '38350.78', '0.04579201']], 'time': '2021-05-20T03:55:56.036887Z'}
{'type': 'l2update', 'product_id': 'BTC-USD', 'changes': [['sell', '38365.21', '0.05000000']], 'time': '2021-05-20T03:55:56.038142Z'}
{'type': 'l2update', 'product_id': 'BTC-USD', 'changes': [['sell', '38342.89', '0.00000000']], 'time': '2021-05-20T03:55:56.040285Z'}
{'type': 'l2update', 'product_id': 'BTC-USD', 'changes': [['buy', '38322.36', '0.10000000']], 'time': '2021-05-20T03:55:56.041249Z'}
{'type': 'l2update', 'product_id': 'BTC-USD', 'changes': [['sell', '38604.68', '0.01000000']], 'time': '2021-05-20T03:55:56.041769Z'}
{'type': 'l2update', 'product_id': 'BTC-USD', 'changes': [['sell', '38346.47', '2.48969908']], 'time': '2021-05-20T03:55:56.043380Z'}
{'type': 'l2update', 'product_id': 'BTC-USD', 'changes': [['sell', '38336.95', '0.02462218']], 'time': '2021-05-20T03:55:56.044031Z'}
{'type': 'l2update', 'product_id': 'BTC-USD', 'changes': [['sell', '38470.93', '0.00000000']], 'time': '2021-05-20T03:55:56.045126Z'}
{'type': 'l2update', 'product_id': 'BTC-USD', 'changes': [['buy', '38301.90', '0.46720000']], 'time': '2021-05-20T03:55:56.045962Z'}
{'type': 'l2update', 'product_id': 'BTC-USD', 'changes': [['sell', '38338.04', '0.00124740']], 'time': '2021-05-20T03:55:56.047438Z'}
{'type': 'l2update', 'product_id': 'BTC-USD', 'changes': [['buy', '38327.71', '0.01492000']], 'time': '2021-05-20T03:55:56.047674Z'}
{'type': 'l2update', 'product_id': 'BTC-USD', 'changes': [['sell', '38342.26', '0.01367260']], 'time': '2021-05-20T03:55:56.050186Z'}
{'type': 'l2update', 'product_id': 'BTC-USD', 'changes': [['buy', '38295.22', '0.07302467']], 'time': '2021-05-20T03:55:56.050214Z'}
{'type': 'l2update', 'product_id': 'BTC-USD', 'changes': [['sell', '38336.92', '0.00000000']], 'time': '2021-05-20T03:55:56.055146Z'}
{'type': 'l2update', 'product_id': 'BTC-USD', 'changes': [['buy', '38168.26', '0.00000000']], 'time': '2021-05-20T03:55:56.055532Z'}
{'type': 'l2update', 'product_id': 'BTC-USD', 'changes': [['sell', '38453.95', '0.02783585']], 'time': '2021-05-20T03:55:56.058520Z'}
{'type': 'l2update', 'product_id': 'BTC-USD', 'changes': [['sell', '38447.10', '0.00000000']], 'time': '2021-05-20T03:55:56.058520Z'}
{'type': 'l2update', 'product_id': 'BTC-USD', 'changes': [['sell', '38440.77', '0.04617488']], 'time': '2021-05-20T03:55:56.058520Z'}
{'type': 'l2update', 'product_id': 'BTC-USD', 'changes': [['sell', '38440.77', '0.01000000']], 'time': '2021-05-20T03:55:56.058520Z'}
{'type': 'l2update', 'product_id': 'BTC-USD', 'changes': [['sell', '38428.60', '0.29408965']], 'time': '2021-05-20T03:55:56.058520Z'}
{'type': 'l2update', 'product_id': 'BTC-USD', 'changes': [['sell', '38414.81', '0.00000000']], 'time': '2021-05-20T03:55:56.058520Z'}
{'type': 'l2update', 'product_id': 'BTC-USD', 'changes': [['sell', '38411.88', '0.00000000']], 'time': '2021-05-20T03:55:56.058520Z'}
{'type': 'l2update', 'product_id': 'BTC-USD', 'changes': [['buy', '38291.22', '0.09000000']], 'time': '2021-05-20T03:55:56.059631Z'}
{'type': 'l2update', 'product_id': 'BTC-USD', 'changes': [['buy', '38214.85', '0.01000000']], 'time': '2021-05-20T03:55:56.060336Z'}
{'type': 'l2update', 'product_id': 'BTC-USD', 'changes': [['buy', '38321.74', '0.12257258']], 'time': '2021-05-20T03:55:56.062935Z'}
{'type': 'l2update', 'product_id': 'BTC-USD', 'changes': [['sell', '38365.21', '0.00000000']], 'time': '2021-05-20T03:55:56.064089Z'}
{'type': 'l2update', 'product_id': 'BTC-USD', 'changes': [['buy', '38322.36', '0.00000000']], 'time': '2021-05-20T03:55:56.081904Z'}
{'type': 'l2update', 'product_id': 'BTC-USD', 'changes': [['sell', '38428.15', '0.12254352']], 'time': '2021-05-20T03:55:56.083415Z'}
{'type': 'l2update', 'product_id': 'BTC-USD', 'changes': [['sell', '38336.95', '0.00000000']], 'time': '2021-05-20T03:55:56.086065Z'}
{'type': 'l2update', 'product_id': 'BTC-USD', 'changes': [['sell', '38349.04', '0.50000000']], 'time': '2021-05-20T03:55:56.087194Z'}
{'type': 'l2update', 'product_id': 'BTC-USD', 'changes': [['buy', '37500.01', '0.06370000']], 'time': '2021-05-20T03:55:56.097215Z'}
{'type': 'l2update', 'product_id': 'BTC-USD', 'changes': [['sell', '38495.38', '0.01000000']], 'time': '2021-05-20T03:55:56.099506Z'}
{'type': 'l2update', 'product_id': 'BTC-USD', 'changes': [['buy', '37654.91', '0.00710000']], 'time': '2021-05-20T03:55:56.100716Z'}
{'type': 'l2update', 'product_id': 'BTC-USD', 'changes': [['buy', '38291.15', '0.00000000']], 'time': '2021-05-20T03:55:56.104838Z'}
{'type': 'l2update', 'product_id': 'BTC-USD', 'changes': [['sell', '38364.17', '0.00000000']], 'time': '2021-05-20T03:55:56.105605Z'}
{'type': 'l2update', 'product_id': 'BTC-USD', 'changes': [['sell', '38338.04', '0.00000000']], 'time': '2021-05-20T03:55:56.105912Z'}
{'type': 'l2update', 'product_id': 'BTC-USD', 'changes': [['sell', '38342.26', '0.00000000']], 'time': '2021-05-20T03:55:56.105984Z'}
{'type': 'l2update', 'product_id': 'BTC-USD', 'changes': [['buy', '38327.87', '0.00000000']], 'time': '2021-05-20T03:55:56.120573Z'}
{'type': 'l2update', 'product_id': 'BTC-USD', 'changes': [['sell', '38341.64', '0.04997782']], 'time': '2021-05-20T03:55:56.124101Z'}
{'type': 'l2update', 'product_id': 'BTC-USD', 'changes': [['sell', '38366.88', '0.00000000']], 'time': '2021-05-20T03:55:56.124206Z'}
{'type': 'l2update', 'product_id': 'BTC-USD', 'changes': [['buy', '38185.63', '0.01000000']], 'time': '2021-05-20T03:55:56.128846Z'}
{'type': 'l2update', 'product_id': 'BTC-USD', 'changes': [['sell', '38346.47', '2.56059254']], 'time': '2021-05-20T03:55:56.128903Z'}
{'type': 'l2update', 'product_id': 'BTC-USD', 'changes': [['sell', '38440.77', '0.04588249']], 'time': '2021-05-20T03:55:56.129113Z'}
{'type': 'l2update', 'product_id': 'BTC-USD', 'changes': [['sell', '38380.49', '0.50000000']], 'time': '2021-05-20T03:55:56.132649Z'}
{'type': 'l2update', 'product_id': 'BTC-USD', 'changes': [['sell', '38342.21', '0.55300000']], 'time': '2021-05-20T03:55:56.137120Z'}
{'type': 'l2update', 'product_id': 'BTC-USD', 'changes': [['buy', '38321.74', '0.00000000']], 'time': '2021-05-20T03:55:56.148906Z'}
{'type': 'l2update', 'product_id': 'BTC-USD', 'changes': [['sell', '38360.56', '0.05000000']], 'time': '2021-05-20T03:55:56.149731Z'}
{'type': 'l2update', 'product_id': 'BTC-USD', 'changes': [['buy', '38327.71', '0.01158930']], 'time': '2021-05-20T03:55:56.150096Z'}
{'type': 'l2update', 'product_id': 'BTC-USD', 'changes': [['buy', '38295.22', '0.00000000']], 'time': '2021-05-20T03:55:56.170958Z'}
{'type': 'l2update', 'product_id': 'BTC-USD', 'changes': [['buy', '38281.77', '0.00000000']], 'time': '2021-05-20T03:55:56.171396Z'}
{'type': 'l2update', 'product_id': 'BTC-USD', 'changes': [['buy', '38327.71', '0.00000000']], 'time': '2021-05-20T03:55:56.173528Z'}
{'type': 'l2update', 'product_id': 'BTC-USD', 'changes': [['buy', '38300.46', '0.00000000']], 'time': '2021-05-20T03:55:56.186056Z'}
{'type': 'l2update', 'product_id': 'BTC-USD', 'changes': [['buy', '38319.01', '0.00000000']], 'time': '2021-05-20T03:55:56.188559Z'}
{'type': 'l2update', 'product_id': 'BTC-USD', 'changes': [['buy', '38291.23', '0.07302467']], 'time': '2021-05-20T03:55:56.189781Z'}
{'type': 'l2update', 'product_id': 'BTC-USD', 'changes': [['sell', '38342.45', '0.01492000']], 'time': '2021-05-20T03:55:56.190930Z'}
{'type': 'l2update', 'product_id': 'BTC-USD', 'changes': [['sell', '38349.04', '0.00000000']], 'time': '2021-05-20T03:55:56.194699Z'}
{'type': 'l2update', 'product_id': 'BTC-USD', 'changes': [['buy', '38273.50', '0.00000000']], 'time': '2021-05-20T03:55:56.197061Z'}
{'type': 'l2update', 'product_id': 'BTC-USD', 'changes': [['sell', '38366.55', '0.00000000']], 'time': '2021-05-20T03:55:56.199402Z'}
{'type': 'l2update', 'product_id': 'BTC-USD', 'changes': [['sell', '38341.64', '0.00000000']], 'time': '2021-05-20T03:55:56.202041Z'}
{'type': 'l2update', 'product_id': 'BTC-USD', 'changes': [['buy', '38301.90', '0.00000000']], 'time': '2021-05-20T03:55:56.202173Z'}
{'type': 'l2update', 'product_id': 'BTC-USD', 'changes': [['sell', '38341.64', '0.02462218']], 'time': '2021-05-20T03:55:56.206778Z'}
{'type': 'l2update', 'product_id': 'BTC-USD', 'changes': [['buy', '38328.20', '0.07460000']], 'time': '2021-05-20T03:55:56.207243Z'}
{'type': 'l2update', 'product_id': 'BTC-USD', 'changes': [['sell', '38447.10', '0.03402194']], 'time': '2021-05-20T03:55:56.211064Z'}
{'type': 'l2update', 'product_id': 'BTC-USD', 'changes': [['sell', '43100.00', '1.09530000']], 'time': '2021-05-20T03:55:56.214777Z'}
{'type': 'l2update', 'product_id': 'BTC-USD', 'changes': [['buy', '38270.85', '0.50000000']], 'time': '2021-05-20T03:55:56.218786Z'}
{'type': 'l2update', 'product_id': 'BTC-USD', 'changes': [['sell', '38378.60', '0.07302467']], 'time': '2021-05-20T03:55:56.219430Z'}
{'type': 'l2update', 'product_id': 'BTC-USD', 'changes': [['sell', '38462.95', '0.00000000']], 'time': '2021-05-20T03:55:56.249679Z'}
{'type': 'l2update', 'product_id': 'BTC-USD', 'changes': [['buy', '38327.38', '0.00333070']], 'time': '2021-05-20T03:55:56.260717Z'}
{'type': 'l2update', 'product_id': 'BTC-USD', 'changes': [['sell', '38341.64', '0.01765565']], 'time': '2021-05-20T03:55:56.263268Z'}
{'type': 'l2update', 'product_id': 'BTC-USD', 'changes': [['sell', '38549.75', '0.00648512']], 'time': '2021-05-20T03:55:56.271456Z'}
{'type': 'l2update', 'product_id': 'BTC-USD', 'changes': [['buy', '38307.26', '0.00000000']], 'time': '2021-05-20T03:55:56.274063Z'}
{'type': 'l2update', 'product_id': 'BTC-USD', 'changes': [['buy', '38306.13', '0.00000000']], 'time': '2021-05-20T03:55:56.274063Z'}
{'type': 'l2update', 'product_id': 'BTC-USD', 'changes': [['buy', '38305.03', '0.00000000']], 'time': '2021-05-20T03:55:56.274063Z'}
{'type': 'l2update', 'product_id': 'BTC-USD', 'changes': [['sell', '38342.45', '0.00000000']], 'time': '2021-05-20T03:55:56.274928Z'}
{'type': 'l2update', 'product_id': 'BTC-USD', 'changes': [['sell', '38360.57', '0.00000000']], 'time': '2021-05-20T03:55:56.283744Z'}
{'type': 'l2update', 'product_id': 'BTC-USD', 'changes': [['sell', '38342.92', '0.50000000']], 'time': '2021-05-20T03:55:56.284383Z'}
{'type': 'l2update', 'product_id': 'BTC-USD', 'changes': [['sell', '38416.12', '0.00000000']], 'time': '2021-05-20T03:55:56.285655Z'}
{'type': 'l2update', 'product_id': 'BTC-USD', 'changes': [['buy', '38274.50', '0.10000000']], 'time': '2021-05-20T03:55:56.287531Z'}
{'type': 'l2update', 'product_id': 'BTC-USD', 'changes': [['buy', '38287.42', '0.07302467']], 'time': '2021-05-20T03:55:56.289390Z'}
{'type': 'l2update', 'product_id': 'BTC-USD', 'changes': [['buy', '38319.06', '0.52000000']], 'time': '2021-05-20T03:55:56.289441Z'}
{'type': 'l2update', 'product_id': 'BTC-USD', 'changes': [['sell', '38341.64', '0.00000000']], 'time': '2021-05-20T03:55:56.290919Z'}
{'type': 'l2update', 'product_id': 'BTC-USD', 'changes': [['sell', '38341.93', '0.04997782']], 'time': '2021-05-20T03:55:56.291888Z'}
{'type': 'l2update', 'product_id': 'BTC-USD', 'changes': [['buy', '38314.60', '0.99440510']], 'time': '2021-05-20T03:55:56.292145Z'}
{'type': 'l2update', 'product_id': 'BTC-USD', 'changes': [['sell', '38405.03', '0.03173641']], 'time': '2021-05-20T03:55:56.299756Z'}
{'type': 'l2update', 'product_id': 'BTC-USD', 'changes': [['sell', '38399.71', '0.02783585']], 'time': '2021-05-20T03:55:56.299756Z'}
{'type': 'l2update', 'product_id': 'BTC-USD', 'changes': [['buy', '38219.66', '0.00000000']], 'time': '2021-05-20T03:55:56.300632Z'}
{'type': 'l2update', 'product_id': 'BTC-USD', 'changes': [['sell', '43100.00', '3.28880000']], 'time': '2021-05-20T03:55:56.303641Z'}
{'type': 'l2update', 'product_id': 'BTC-USD', 'changes': [['sell', '38437.73', '0.00000000']], 'time': '2021-05-20T03:55:56.325821Z'}
{'type': 'l2update', 'product_id': 'BTC-USD', 'changes': [['sell', '38343.92', '0.00000000']], 'time': '2021-05-20T03:55:56.350889Z'}
{'type': 'l2update', 'product_id': 'BTC-USD', 'changes': [['sell', '38350.78', '0.00000000']], 'time': '2021-05-20T03:55:56.351448Z'}
{'type': 'l2update', 'product_id': 'BTC-USD', 'changes': [['buy', '38327.38', '0.01492000']], 'time': '2021-05-20T03:55:56.351586Z'}
{'type': 'l2update', 'product_id': 'BTC-USD', 'changes': [['buy', '38291.23', '0.00000000']], 'time': '2021-05-20T03:55:56.354362Z'}
{'type': 'l2update', 'product_id': 'BTC-USD', 'changes': [['sell', '38366.81', '0.01000000']], 'time': '2021-05-20T03:55:56.355428Z'}
{'type': 'l2update', 'product_id': 'BTC-USD', 'changes': [['buy', '38271.07', '0.00000000']], 'time': '2021-05-20T03:55:56.361273Z'}
{'type': 'l2update', 'product_id': 'BTC-USD', 'changes': [['sell', '38454.38', '0.00000000']], 'time': '2021-05-20T03:55:56.361542Z'}
{'type': 'l2update', 'product_id': 'BTC-USD', 'changes': [['sell', '38341.93', '0.05694435']], 'time': '2021-05-20T03:55:56.363763Z'}
{'type': 'l2update', 'product_id': 'BTC-USD', 'changes': [['buy', '38328.20', '0.00000000']], 'time': '2021-05-20T03:55:56.372522Z'}
{'type': 'l2update', 'product_id': 'BTC-USD', 'changes': [['buy', '38303.77', '0.02400000']], 'time': '2021-05-20T03:55:56.375526Z'}
{'type': 'l2update', 'product_id': 'BTC-USD', 'changes': [['buy', '38302.96', '0.02400000']], 'time': '2021-05-20T03:55:56.375526Z'}
{'type': 'l2update', 'product_id': 'BTC-USD', 'changes': [['buy', '38302.15', '0.02400000']], 'time': '2021-05-20T03:55:56.375526Z'}
{'type': 'l2update', 'product_id': 'BTC-USD', 'changes': [['sell', '38341.84', '0.01492000']], 'time': '2021-05-20T03:55:56.382769Z'}
{'type': 'l2update', 'product_id': 'BTC-USD', 'changes': [['sell', '38341.93', '0.07460000']], 'time': '2021-05-20T03:55:56.382943Z'}
{'type': 'l2update', 'product_id': 'BTC-USD', 'changes': [['sell', '38342.97', '0.04895734']], 'time': '2021-05-20T03:55:56.387210Z'}
{'type': 'l2update', 'product_id': 'BTC-USD', 'changes': [['sell', '38495.38', '0.00000000']], 'time': '2021-05-20T03:55:56.392762Z'}
{'type': 'l2update', 'product_id': 'BTC-USD', 'changes': [['sell', '38453.95', '0.00000000']], 'time': '2021-05-20T03:55:56.395969Z'}
{'type': 'l2update', 'product_id': 'BTC-USD', 'changes': [['buy', '38232.18', '0.01136687']], 'time': '2021-05-20T03:55:56.402681Z'}
{'type': 'l2update', 'product_id': 'BTC-USD', 'changes': [['sell', '38437.37', '0.01300817']], 'time': '2021-05-20T03:55:56.425496Z'}
{'type': 'l2update', 'product_id': 'BTC-USD', 'changes': [['buy', '38327.38', '0.00333070']], 'time': '2021-05-20T03:55:56.426057Z'}
{'type': 'l2update', 'product_id': 'BTC-USD', 'changes': [['buy', '38327.38', '0.00000000']], 'time': '2021-05-20T03:55:56.426196Z'}
{'type': 'l2update', 'product_id': 'BTC-USD', 'changes': [['sell', '38367.76', '2.47500000']], 'time': '2021-05-20T03:55:56.431739Z'}
{'type': 'l2update', 'product_id': 'BTC-USD', 'changes': [['sell', '38370.53', '0.04000000']], 'time': '2021-05-20T03:55:56.435784Z'}
{'type': 'l2update', 'product_id': 'BTC-USD', 'changes': [['sell', '38346.47', '0.07089346']], 'time': '2021-05-20T03:55:56.438615Z'}
{'type': 'l2update', 'product_id': 'BTC-USD', 'changes': [['sell', '38527.05', '0.00000000']], 'time': '2021-05-20T03:55:56.454828Z'}
{'type': 'l2update', 'product_id': 'BTC-USD', 'changes': [['buy', '38328.21', '0.12257258']], 'time': '2021-05-20T03:55:56.462447Z'}
{'type': 'l2update', 'product_id': 'BTC-USD', 'changes': [['sell', '38341.93', '0.06763347']], 'time': '2021-05-20T03:55:56.464337Z'}
{'type': 'l2update', 'product_id': 'BTC-USD', 'changes': [['sell', '38341.93', '0.01765565']], 'time': '2021-05-20T03:55:56.464403Z'}
{'type': 'l2update', 'product_id': 'BTC-USD', 'changes': [['buy', '38327.87', '0.07460000']], 'time': '2021-05-20T03:55:56.474181Z'}
{'type': 'l2update', 'product_id': 'BTC-USD', 'changes': [['sell', '38482.22', '0.01000000']], 'time': '2021-05-20T03:55:56.475078Z'}
{'type': 'l2update', 'product_id': 'BTC-USD', 'changes': [['sell', '38416.24', '0.03077262']], 'time': '2021-05-20T03:55:56.479007Z'}
{'type': 'l2update', 'product_id': 'BTC-USD', 'changes': [['sell', '38426.00', '0.01000000']], 'time': '2021-05-20T03:55:56.499360Z'}
{'type': 'l2update', 'product_id': 'BTC-USD', 'changes': [['buy', '38273.38', '1.28179496']], 'time': '2021-05-20T03:55:56.510357Z'}
{'type': 'l2update', 'product_id': 'BTC-USD', 'changes': [['buy', '38319.06', '0.00000000']], 'time': '2021-05-20T03:55:56.511557Z'}
{'type': 'l2update', 'product_id': 'BTC-USD', 'changes': [['buy', '38327.22', '0.01492000']], 'time': '2021-05-20T03:55:56.517389Z'}
{'type': 'l2update', 'product_id': 'BTC-USD', 'changes': [['sell', '38366.81', '0.00000000']], 'time': '2021-05-20T03:55:56.520657Z'}
{'type': 'l2update', 'product_id': 'BTC-USD', 'changes': [['sell', '38341.92', '2.48969908']], 'time': '2021-05-20T03:55:56.525845Z'}
{'type': 'l2update', 'product_id': 'BTC-USD', 'changes': [['sell', '38341.93', '0.00000000']], 'time': '2021-05-20T03:55:56.526163Z'}
{'type': 'l2update', 'product_id': 'BTC-USD', 'changes': [['sell', '38482.13', '0.01000000']], 'time': '2021-05-20T03:55:56.528627Z'}
{'type': 'l2update', 'product_id': 'BTC-USD', 'changes': [['buy', '38327.87', '0.00000000']], 'time': '2021-05-20T03:55:56.538742Z'}
{'type': 'l2update', 'product_id': 'BTC-USD', 'changes': [['sell', '38365.31', '0.00000000']], 'time': '2021-05-20T03:55:56.538830Z'}
{'type': 'l2update', 'product_id': 'BTC-USD', 'changes': [['sell', '38357.66', '0.00000000']], 'time': '2021-05-20T03:55:56.539130Z'}
{'type': 'l2update', 'product_id': 'BTC-USD', 'changes': [['sell', '38450.26', '0.00000000']], 'time': '2021-05-20T03:55:56.539158Z'}
{'type': 'l2update', 'product_id': 'BTC-USD', 'changes': [['sell', '38334.27', '0.52193401']], 'time': '2021-05-20T03:55:56.539517Z'}
{'type': 'l2update', 'product_id': 'BTC-USD', 'changes': [['sell', '38422.14', '0.03215272']], 'time': '2021-05-20T03:55:56.542209Z'}
{'type': 'l2update', 'product_id': 'BTC-USD', 'changes': [['buy', '38331.12', '0.05032997']], 'time': '2021-05-20T03:55:56.542325Z'}
{'type': 'l2update', 'product_id': 'BTC-USD', 'changes': [['sell', '38342.92', '0.00000000']], 'time': '2021-05-20T03:55:56.545157Z'}
{'type': 'l2update', 'product_id': 'BTC-USD', 'changes': [['sell', '38378.60', '0.00000000']], 'time': '2021-05-20T03:55:56.557887Z'}
{'type': 'l2update', 'product_id': 'BTC-USD', 'changes': [['sell', '38370.65', '0.01000000']], 'time': '2021-05-20T03:55:56.564875Z'}
{'type': 'l2update', 'product_id': 'BTC-USD', 'changes': [['buy', '38321.03', '0.40135082']], 'time': '2021-05-20T03:55:56.565322Z'}
{'type': 'l2update', 'product_id': 'BTC-USD', 'changes': [['sell', '38341.38', '0.05694435']], 'time': '2021-05-20T03:55:56.565578Z'}
{'type': 'l2update', 'product_id': 'BTC-USD', 'changes': [['buy', '38327.22', '0.00000000']], 'time': '2021-05-20T03:55:56.565982Z'}
{'type': 'l2update', 'product_id': 'BTC-USD', 'changes': [['sell', '38509.04', '0.00000000']], 'time': '2021-05-20T03:55:56.568038Z'}
{'type': 'l2update', 'product_id': 'BTC-USD', 'changes': [['buy', '38314.65', '0.52100000']], 'time': '2021-05-20T03:55:56.571012Z'}
{'type': 'l2update', 'product_id': 'BTC-USD', 'changes': [['sell', '38517.17', '0.00778873']], 'time': '2021-05-20T03:55:56.571175Z'}
{'type': 'l2update', 'product_id': 'BTC-USD', 'changes': [['sell', '38391.80', '0.00000000']], 'time': '2021-05-20T03:55:56.571644Z'}
{'type': 'l2update', 'product_id': 'BTC-USD', 'changes': [['buy', '38321.75', '0.10000000']], 'time': '2021-05-20T03:55:56.578565Z'}
{'type': 'l2update', 'product_id': 'BTC-USD', 'changes': [['sell', '38369.33', '0.01000000']], 'time': '2021-05-20T03:55:56.578682Z'}
{'type': 'l2update', 'product_id': 'BTC-USD', 'changes': [['buy', '38310.54', '0.52193264']], 'time': '2021-05-20T03:55:56.578867Z'}
{'type': 'l2update', 'product_id': 'BTC-USD', 'changes': [['sell', '38342.20', '0.18981474']], 'time': '2021-05-20T03:55:56.579326Z'}
{'type': 'l2update', 'product_id': 'BTC-USD', 'changes': [['sell', '38341.84', '0.00000000']], 'time': '2021-05-20T03:55:56.579803Z'}
{'type': 'l2update', 'product_id': 'BTC-USD', 'changes': [['buy', '38219.19', '0.00000000']], 'time': '2021-05-20T03:55:56.582344Z'}
{'type': 'l2update', 'product_id': 'BTC-USD', 'changes': [['sell', '38450.26', '0.01000000']], 'time': '2021-05-20T03:55:56.584456Z'}
{'type': 'l2update', 'product_id': 'BTC-USD', 'changes': [['buy', '38326.70', '0.00000000']], 'time': '2021-05-20T03:55:56.585289Z'}
{'type': 'l2update', 'product_id': 'BTC-USD', 'changes': [['sell', '38428.07', '0.02748259']], 'time': '2021-05-20T03:55:56.585404Z'}
{'type': 'l2update', 'product_id': 'BTC-USD', 'changes': [['sell', '38404.87', '0.03588249']], 'time': '2021-05-20T03:55:56.585404Z'}
{'type': 'l2update', 'product_id': 'BTC-USD', 'changes': [['sell', '38381.65', '0.05351656']], 'time': '2021-05-20T03:55:56.585704Z'}
{'type': 'l2update', 'product_id': 'BTC-USD', 'changes': [['buy', '38262.56', '0.00000000']], 'time': '2021-05-20T03:55:56.587846Z'}
{'type': 'l2update', 'product_id': 'BTC-USD', 'changes': [['buy', '38273.51', '0.00000000']], 'time': '2021-05-20T03:55:56.590383Z'}
{'type': 'l2update', 'product_id': 'BTC-USD', 'changes': [['buy', '38214.85', '0.00000000']], 'time': '2021-05-20T03:55:56.615393Z'}
{'type': 'l2update', 'product_id': 'BTC-USD', 'changes': [['sell', '38346.46', '0.50000000']], 'time': '2021-05-20T03:55:56.616338Z'}
{'type': 'l2update', 'product_id': 'BTC-USD', 'changes': [['buy', '38291.23', '0.45607711']], 'time': '2021-05-20T03:55:56.616554Z'}
{'type': 'l2update', 'product_id': 'BTC-USD', 'changes': [['buy', '38288.24', '0.01000000']], 'time': '2021-05-20T03:55:56.618702Z'}
{'type': 'l2update', 'product_id': 'BTC-USD', 'changes': [['sell', '38440.77', '0.01000000']], 'time': '2021-05-20T03:55:56.619687Z'}
{'type': 'l2update', 'product_id': 'BTC-USD', 'changes': [['buy', '38273.38', '0.00000000']], 'time': '2021-05-20T03:55:56.619720Z'}
{'type': 'l2update', 'product_id': 'BTC-USD', 'changes': [['buy', '38305.37', '0.04358603']], 'time': '2021-05-20T03:55:56.620087Z'}
{'type': 'l2update', 'product_id': 'BTC-USD', 'changes': [['sell', '38346.67', '0.04740205']], 'time': '2021-05-20T03:55:56.620087Z'}
{'type': 'l2update', 'product_id': 'BTC-USD', 'changes': [['sell', '38337.06', '0.52196513']], 'time': '2021-05-20T03:55:56.620602Z'}
{'type': 'l2update', 'product_id': 'BTC-USD', 'changes': [['buy', '38289.13', '0.06730961']], 'time': '2021-05-20T03:55:56.621315Z'}
{'type': 'l2update', 'product_id': 'BTC-USD', 'changes': [['buy', '38289.85', '0.02611658']], 'time': '2021-05-20T03:55:56.621547Z'}
{'type': 'l2update', 'product_id': 'BTC-USD', 'changes': [['buy', '38280.61', '0.05351656']], 'time': '2021-05-20T03:55:56.622224Z'}
{'type': 'l2update', 'product_id': 'BTC-USD', 'changes': [['sell', '38445.97', '0.00000000']], 'time': '2021-05-20T03:55:56.622620Z'}
{'type': 'l2update', 'product_id': 'BTC-USD', 'changes': [['sell', '38341.38', '0.00000000']], 'time': '2021-05-20T03:55:56.623153Z'}
{'type': 'l2update', 'product_id': 'BTC-USD', 'changes': [['sell', '38380.34', '0.05351656']], 'time': '2021-05-20T03:55:56.632709Z'}
{'type': 'l2update', 'product_id': 'BTC-USD', 'changes': [['buy', '38321.03', '0.00000000']], 'time': '2021-05-20T03:55:56.637760Z'}
{'type': 'l2update', 'product_id': 'BTC-USD', 'changes': [['sell', '38381.65', '0.00000000']], 'time': '2021-05-20T03:55:56.637775Z'}
{'type': 'l2update', 'product_id': 'BTC-USD', 'changes': [['sell', '38346.46', '0.00000000']], 'time': '2021-05-20T03:55:56.641373Z'}
{'type': 'l2update', 'product_id': 'BTC-USD', 'changes': [['buy', '38198.22', '0.01000000']], 'time': '2021-05-20T03:55:56.642933Z'}
{'type': 'l2update', 'product_id': 'BTC-USD', 'changes': [['sell', '38484.49', '0.01654178']], 'time': '2021-05-20T03:55:56.642965Z'}
{'type': 'l2update', 'product_id': 'BTC-USD', 'changes': [['buy', '38307.09', '0.52198108']], 'time': '2021-05-20T03:55:56.643314Z'}
{'type': 'l2update', 'product_id': 'BTC-USD', 'changes': [['sell', '38440.77', '0.04640197']], 'time': '2021-05-20T03:55:56.643442Z'}
{'type': 'l2update', 'product_id': 'BTC-USD', 'changes': [['buy', '38304.93', '0.49370000']], 'time': '2021-05-20T03:55:56.655490Z'}
{'type': 'l2update', 'product_id': 'BTC-USD', 'changes': [['buy', '38228.20', '0.01000000']], 'time': '2021-05-20T03:55:56.655803Z'}
{'type': 'l2update', 'product_id': 'BTC-USD', 'changes': [['buy', '38287.42', '0.00000000']], 'time': '2021-05-20T03:55:56.658230Z'}
{'type': 'l2update', 'product_id': 'BTC-USD', 'changes': [['sell', '38421.71', '0.05446174']], 'time': '2021-05-20T03:55:56.659210Z'}
{'type': 'l2update', 'product_id': 'BTC-USD', 'changes': [['sell', '38338.29', '0.52194931']], 'time': '2021-05-20T03:55:56.667926Z'}
{'type': 'l2update', 'product_id': 'BTC-USD', 'changes': [['sell', '38458.35', '0.01000000']], 'time': '2021-05-20T03:55:56.668455Z'}
{'type': 'l2update', 'product_id': 'BTC-USD', 'changes': [['buy', '38280.61', '0.00000000']], 'time': '2021-05-20T03:55:56.668995Z'}
{'type': 'l2update', 'product_id': 'BTC-USD', 'changes': [['sell', '38357.92', '0.43380000']], 'time': '2021-05-20T03:55:56.678124Z'}
{'type': 'l2update', 'product_id': 'BTC-USD', 'changes': [['sell', '38360.55', '0.50000000']], 'time': '2021-05-20T03:55:56.678194Z'}
{'type': 'l2update', 'product_id': 'BTC-USD', 'changes': [['buy', '38314.65', '1.36800000']], 'time': '2021-05-20T03:55:56.678248Z'}
{'type': 'l2update', 'product_id': 'BTC-USD', 'changes': [['sell', '38446.47', '0.03639543']], 'time': '2021-05-20T03:55:56.682437Z'}
{'type': 'l2update', 'product_id': 'BTC-USD', 'changes': [['buy', '38270.84', '1.28179496']], 'time': '2021-05-20T03:55:56.684595Z'}
{'type': 'l2update', 'product_id': 'BTC-USD', 'changes': [['buy', '38321.02', '0.00000000']], 'time': '2021-05-20T03:55:56.684810Z'}
{'type': 'l2update', 'product_id': 'BTC-USD', 'changes': [['buy', '38328.21', '0.00000000']], 'time': '2021-05-20T03:55:56.685989Z'}
{'type': 'l2update', 'product_id': 'BTC-USD', 'changes': [['buy', '38304.93', '0.00000000']], 'time': '2021-05-20T03:55:56.689349Z'}
{'type': 'l2update', 'product_id': 'BTC-USD', 'changes': [['buy', '38314.66', '0.40135082']], 'time': '2021-05-20T03:55:56.690350Z'}
{'type': 'l2update', 'product_id': 'BTC-USD', 'changes': [['sell', '38378.60', '0.05351656']], 'time': '2021-05-20T03:55:56.690374Z'}
{'type': 'l2update', 'product_id': 'BTC-USD', 'changes': [['sell', '38360.56', '0.00000000']], 'time': '2021-05-20T03:55:56.691673Z'}
{'type': 'l2update', 'product_id': 'BTC-USD', 'changes': [['sell', '38342.20', '0.00000000']], 'time': '2021-05-20T03:55:56.692670Z'}
{'type': 'l2update', 'product_id': 'BTC-USD', 'changes': [['buy', '38303.28', '0.52203067']], 'time': '2021-05-20T03:55:56.695065Z'}
{'type': 'l2update', 'product_id': 'BTC-USD', 'changes': [['sell', '38391.58', '0.61482417']], 'time': '2021-05-20T03:55:56.696544Z'}
{'type': 'l2update', 'product_id': 'BTC-USD', 'changes': [['sell', '38380.34', '0.00000000']], 'time': '2021-05-20T03:55:56.697574Z'}
{'type': 'l2update', 'product_id': 'BTC-USD', 'changes': [['sell', '38357.92', '0.00000000']], 'time': '2021-05-20T03:55:56.698782Z'}
{'type': 'l2update', 'product_id': 'BTC-USD', 'changes': [['buy', '38198.22', '0.00000000']], 'time': '2021-05-20T03:55:56.699326Z'}
{'type': 'l2update', 'product_id': 'BTC-USD', 'changes': [['sell', '38482.22', '0.00000000']], 'time': '2021-05-20T03:55:56.705091Z'}
{'type': 'l2update', 'product_id': 'BTC-USD', 'changes': [['sell', '38453.95', '0.03544496']], 'time': '2021-05-20T03:55:56.705765Z'}
{'type': 'l2update', 'product_id': 'BTC-USD', 'changes': [['sell', '38380.66', '0.01113434']], 'time': '2021-05-20T03:55:56.705765Z'}
{'type': 'l2update', 'product_id': 'BTC-USD', 'changes': [['buy', '38228.20', '0.00000000']], 'time': '2021-05-20T03:55:56.708691Z'}
{'type': 'l2update', 'product_id': 'BTC-USD', 'changes': [['sell', '38347.70', '1.30507667']], 'time': '2021-05-20T03:55:56.713291Z'}
{'type': 'l2update', 'product_id': 'BTC-USD', 'changes': [['sell', '38357.91', '0.05000000']], 'time': '2021-05-20T03:55:56.713404Z'}
{'type': 'l2update', 'product_id': 'BTC-USD', 'changes': [['sell', '38399.71', '0.00000000']], 'time': '2021-05-20T03:55:56.720611Z'}
{'type': 'l2update', 'product_id': 'BTC-USD', 'changes': [['sell', '38341.91', '0.18981474']], 'time': '2021-05-20T03:55:56.723368Z'}
{'type': 'l2update', 'product_id': 'BTC-USD', 'changes': [['buy', '38214.42', '0.01000000']], 'time': '2021-05-20T03:55:56.723500Z'}
{'type': 'l2update', 'product_id': 'BTC-USD', 'changes': [['buy', '38287.43', '0.05351656']], 'time': '2021-05-20T03:55:56.723737Z'}
{'type': 'l2update', 'product_id': 'BTC-USD', 'changes': [['sell', '38491.62', '0.01000000']], 'time': '2021-05-20T03:55:56.725500Z'}
{'type': 'l2update', 'product_id': 'BTC-USD', 'changes': [['sell', '38357.91', '0.00000000']], 'time': '2021-05-20T03:55:56.726580Z'}
{'type': 'l2update', 'product_id': 'BTC-USD', 'changes': [['buy', '38239.96', '0.01000000']], 'time': '2021-05-20T03:55:56.728755Z'}
{'type': 'l2update', 'product_id': 'BTC-USD', 'changes': [['buy', '38293.66', '0.78293137']], 'time': '2021-05-20T03:55:56.733970Z'}
{'type': 'l2update', 'product_id': 'BTC-USD', 'changes': [['sell', '38360.55', '0.00000000']], 'time': '2021-05-20T03:55:56.739586Z'}
{'type': 'l2update', 'product_id': 'BTC-USD', 'changes': [['buy', '38287.43', '0.00000000']], 'time': '2021-05-20T03:55:56.740238Z'}
{'type': 'l2update', 'product_id': 'BTC-USD', 'changes': [['buy', '38327.88', '0.10000000']], 'time': '2021-05-20T03:55:56.742396Z'}
{'type': 'l2update', 'product_id': 'BTC-USD', 'changes': [['sell', '38360.54', '0.05000000']], 'time': '2021-05-20T03:55:56.742516Z'}
{'type': 'l2update', 'product_id': 'BTC-USD', 'changes': [['sell', '38453.95', '0.06396814']], 'time': '2021-05-20T03:55:56.742634Z'}
{'type': 'l2update', 'product_id': 'BTC-USD', 'changes': [['sell', '38390.09', '0.00000000']], 'time': '2021-05-20T03:55:56.746906Z'}
{'type': 'l2update', 'product_id': 'BTC-USD', 'changes': [['buy', '38327.88', '0.00000000']], 'time': '2021-05-20T03:55:56.750656Z'}
{'type': 'l2update', 'product_id': 'BTC-USD', 'changes': [['sell', '38352.33', '1.30491281']], 'time': '2021-05-20T03:55:56.754757Z'}
{'type': 'l2update', 'product_id': 'BTC-USD', 'changes': [['sell', '38337.05', '0.50000000']], 'time': '2021-05-20T03:55:56.759836Z'}
{'type': 'l2update', 'product_id': 'BTC-USD', 'changes': [['buy', '38289.14', '0.05351656']], 'time': '2021-05-20T03:55:56.760020Z'}
{'type': 'l2update', 'product_id': 'BTC-USD', 'changes': [['buy', '38331.13', '0.12257258']], 'time': '2021-05-20T03:55:56.760704Z'}
{'type': 'l2update', 'product_id': 'BTC-USD', 'changes': [['buy', '33000.00', '122.31906605']], 'time': '2021-05-20T03:55:56.762097Z'}
{'type': 'l2update', 'product_id': 'BTC-USD', 'changes': [['buy', '38281.70', '1.30503579']], 'time': '2021-05-20T03:55:56.767423Z'}
{'type': 'l2update', 'product_id': 'BTC-USD', 'changes': [['sell', '38458.35', '0.00000000']], 'time': '2021-05-20T03:55:56.767596Z'}
{'type': 'l2update', 'product_id': 'BTC-USD', 'changes': [['sell', '38482.13', '0.00000000']], 'time': '2021-05-20T03:55:56.768160Z'}
{'type': 'l2update', 'product_id': 'BTC-USD', 'changes': [['buy', '37516.83', '0.00000000']], 'time': '2021-05-20T03:55:56.771290Z'}
{'type': 'l2update', 'product_id': 'BTC-USD', 'changes': [['buy', '38334.26', '0.01492000']], 'time': '2021-05-20T03:55:56.773023Z'}
{'type': 'l2update', 'product_id': 'BTC-USD', 'changes': [['buy', '38334.26', '0.06920224']], 'time': '2021-05-20T03:55:56.775330Z'}
{'type': 'l2update', 'product_id': 'BTC-USD', 'changes': [['sell', '39126.21', '0.00000000']], 'time': '2021-05-20T03:55:56.777900Z'}
{'type': 'l2update', 'product_id': 'BTC-USD', 'changes': [['sell', '38346.67', '0.00000000']], 'time': '2021-05-20T03:55:56.779961Z'}
{'type': 'l2update', 'product_id': 'BTC-USD', 'changes': [['buy', '38314.59', '0.05900000']], 'time': '2021-05-20T03:55:56.780348Z'}
{'type': 'l2update', 'product_id': 'BTC-USD', 'changes': [['buy', '38321.01', '0.00000000']], 'time': '2021-05-20T03:55:56.780964Z'}
{'type': 'l2update', 'product_id': 'BTC-USD', 'changes': [['sell', '38404.87', '0.00000000']], 'time': '2021-05-20T03:55:56.781912Z'}
{'type': 'l2update', 'product_id': 'BTC-USD', 'changes': [['sell', '38341.91', '0.00000000']], 'time': '2021-05-20T03:55:56.783309Z'}
{'type': 'l2update', 'product_id': 'BTC-USD', 'changes': [['sell', '38498.62', '0.01000000']], 'time': '2021-05-20T03:55:56.784634Z'}
{'type': 'l2update', 'product_id': 'BTC-USD', 'changes': [['sell', '38445.97', '0.01000000']], 'time': '2021-05-20T03:55:56.784715Z'}
{'type': 'l2update', 'product_id': 'BTC-USD', 'changes': [['buy', '38291.24', '0.05351656']], 'time': '2021-05-20T03:55:56.785170Z'}
{'type': 'l2update', 'product_id': 'BTC-USD', 'changes': [['sell', '38372.32', '0.05147290']], 'time': '2021-05-20T03:55:56.785391Z'}
{'type': 'l2update', 'product_id': 'BTC-USD', 'changes': [['sell', '38377.79', '2.60966320']], 'time': '2021-05-20T03:55:56.785609Z'}
{'type': 'l2update', 'product_id': 'BTC-USD', 'changes': [['buy', '38174.28', '0.05027295']], 'time': '2021-05-20T03:55:56.785696Z'}
{'type': 'l2update', 'product_id': 'BTC-USD', 'changes': [['buy', '38304.57', '0.45860000']], 'time': '2021-05-20T03:55:56.790291Z'}
{'type': 'l2update', 'product_id': 'BTC-USD', 'changes': [['buy', '38334.26', '0.66920224']], 'time': '2021-05-20T03:55:56.790544Z'}
{'type': 'l2update', 'product_id': 'BTC-USD', 'changes': [['buy', '38289.14', '0.00000000']], 'time': '2021-05-20T03:55:56.795061Z'}
{'type': 'l2update', 'product_id': 'BTC-USD', 'changes': [['buy', '38334.26', '0.06920224']], 'time': '2021-05-20T03:55:56.799689Z'}
{'type': 'l2update', 'product_id': 'BTC-USD', 'changes': [['buy', '38272.58', '2.61015333']], 'time': '2021-05-20T03:55:56.801404Z'}
{'type': 'l2update', 'product_id': 'BTC-USD', 'changes': [['buy', '38291.24', '0.00000000']], 'time': '2021-05-20T03:55:56.802750Z'}
{'type': 'l2update', 'product_id': 'BTC-USD', 'changes': [['buy', '38165.71', '0.00000000']], 'time': '2021-05-20T03:55:56.805095Z'}
{'type': 'l2update', 'product_id': 'BTC-USD', 'changes': [['buy', '38290.42', '0.00000000']], 'time': '2021-05-20T03:55:56.806637Z'}
{'type': 'l2update', 'product_id': 'BTC-USD', 'changes': [['sell', '38358.04', '0.43700000']], 'time': '2021-05-20T03:55:56.807161Z'}
{'type': 'l2update', 'product_id': 'BTC-USD', 'changes': [['sell', '38337.04', '0.18981474']], 'time': '2021-05-20T03:55:56.807251Z'}
{'type': 'l2update', 'product_id': 'BTC-USD', 'changes': [['sell', '38338.24', '0.55400000']], 'time': '2021-05-20T03:55:56.807385Z'}
{'type': 'l2update', 'product_id': 'BTC-USD', 'changes': [['sell', '38437.37', '0.00000000']], 'time': '2021-05-20T03:55:56.811726Z'}
{'type': 'l2update', 'product_id': 'BTC-USD', 'changes': [['sell', '38377.78', '0.05351656']], 'time': '2021-05-20T03:55:56.811928Z'}
{'type': 'l2update', 'product_id': 'BTC-USD', 'changes': [['buy', '38295.22', '0.05351656']], 'time': '2021-05-20T03:55:56.816338Z'}
{'type': 'l2update', 'product_id': 'BTC-USD', 'changes': [['sell', '38360.54', '0.00000000']], 'time': '2021-05-20T03:55:56.816509Z'}
{'type': 'l2update', 'product_id': 'BTC-USD', 'changes': [['sell', '38378.60', '0.00000000']], 'time': '2021-05-20T03:55:56.819777Z'}
{'type': 'l2update', 'product_id': 'BTC-USD', 'changes': [['buy', '38272.28', '2.60966320']], 'time': '2021-05-20T03:55:56.821059Z'}
{'type': 'l2update', 'product_id': 'BTC-USD', 'changes': [['sell', '38451.69', '0.00000000']], 'time': '2021-05-20T03:55:56.821199Z'}
{'type': 'l2update', 'product_id': 'BTC-USD', 'changes': [['sell', '38460.89', '0.02978105']], 'time': '2021-05-20T03:55:56.825649Z'}
{'type': 'l2update', 'product_id': 'BTC-USD', 'changes': [['sell', '38358.03', '0.05000000']], 'time': '2021-05-20T03:55:56.833255Z'}
{'type': 'l2update', 'product_id': 'BTC-USD', 'changes': [['sell', '38377.78', '0.00000000']], 'time': '2021-05-20T03:55:56.835704Z'}
{'type': 'l2update', 'product_id': 'BTC-USD', 'changes': [['sell', '38457.04', '0.01300152']], 'time': '2021-05-20T03:55:56.845766Z'}
{'type': 'l2update', 'product_id': 'BTC-USD', 'changes': [['buy', '38287.41', '0.00000000']], 'time': '2021-05-20T03:55:56.848388Z'}
{'type': 'l2update', 'product_id': 'BTC-USD', 'changes': [['sell', '38432.55', '0.01000000']], 'time': '2021-05-20T03:55:56.851271Z'}
{'type': 'l2update', 'product_id': 'BTC-USD', 'changes': [['sell', '38368.39', '0.05351656']], 'time': '2021-05-20T03:55:56.851502Z'}
{'type': 'l2update', 'product_id': 'BTC-USD', 'changes': [['sell', '38440.77', '0.01000000']], 'time': '2021-05-20T03:55:56.852347Z'}
{'type': 'l2update', 'product_id': 'BTC-USD', 'changes': [['sell', '38405.03', '0.00000000']], 'time': '2021-05-20T03:55:56.852347Z'}
{'type': 'l2update', 'product_id': 'BTC-USD', 'changes': [['sell', '38350.27', '0.04647353']], 'time': '2021-05-20T03:55:56.856203Z'}
{'type': 'l2update', 'product_id': 'BTC-USD', 'changes': [['sell', '38604.68', '0.00000000']], 'time': '2021-05-20T03:55:56.857055Z'}
{'type': 'l2update', 'product_id': 'BTC-USD', 'changes': [['sell', '38422.43', '0.00000000']], 'time': '2021-05-20T03:55:56.857111Z'}
{'type': 'l2update', 'product_id': 'BTC-USD', 'changes': [['sell', '38367.75', '0.05351656']], 'time': '2021-05-20T03:55:56.860418Z'}
{'type': 'l2update', 'product_id': 'BTC-USD', 'changes': [['sell', '38368.39', '0.00000000']], 'time': '2021-05-20T03:55:56.861739Z'}
{'type': 'l2update', 'product_id': 'BTC-USD', 'changes': [['buy', '38334.26', '0.16920224']], 'time': '2021-05-20T03:55:56.867087Z'}
{'type': 'l2update', 'product_id': 'BTC-USD', 'changes': [['buy', '38305.37', '0.00000000']], 'time': '2021-05-20T03:55:56.869091Z'}
{'type': 'l2update', 'product_id': 'BTC-USD', 'changes': [['sell', '38368.62', '0.00000000']], 'time': '2021-05-20T03:55:56.876769Z'}
{'type': 'l2update', 'product_id': 'BTC-USD', 'changes': [['buy', '38321.75', '0.00000000']], 'time': '2021-05-20T03:55:56.877967Z'}
{'type': 'l2update', 'product_id': 'BTC-USD', 'changes': [['sell', '38457.04', '0.00000000']], 'time': '2021-05-20T03:55:56.878477Z'}
{'type': 'l2update', 'product_id': 'BTC-USD', 'changes': [['buy', '38302.96', '0.00000000']], 'time': '2021-05-20T03:55:56.878513Z'}
{'type': 'l2update', 'product_id': 'BTC-USD', 'changes': [['buy', '38302.15', '0.00000000']], 'time': '2021-05-20T03:55:56.878513Z'}
{'type': 'l2update', 'product_id': 'BTC-USD', 'changes': [['sell', '38418.85', '0.20090000']], 'time': '2021-05-20T03:55:56.881481Z'}
{'type': 'l2update', 'product_id': 'BTC-USD', 'changes': [['sell', '38369.11', '0.00000000']], 'time': '2021-05-20T03:55:56.884345Z'}
{'type': 'l2update', 'product_id': 'BTC-USD', 'changes': [['buy', '38331.13', '0.00000000']], 'time': '2021-05-20T03:55:56.885019Z'}
{'type': 'l2update', 'product_id': 'BTC-USD', 'changes': [['sell', '38388.66', '0.00000000']], 'time': '2021-05-20T03:55:56.887708Z'}
{'type': 'l2update', 'product_id': 'BTC-USD', 'changes': [['buy', '38303.77', '0.00000000']], 'time': '2021-05-20T03:55:56.887884Z'}
{'type': 'l2update', 'product_id': 'BTC-USD', 'changes': [['buy', '38274.50', '0.00000000']], 'time': '2021-05-20T03:55:56.894855Z'}
{'type': 'l2update', 'product_id': 'BTC-USD', 'changes': [['sell', '38662.91', '0.01000000']], 'time': '2021-05-20T03:55:56.895985Z'}
{'type': 'l2update', 'product_id': 'BTC-USD', 'changes': [['sell', '38374.74', '0.02000000']], 'time': '2021-05-20T03:55:56.896484Z'}
{'type': 'l2update', 'product_id': 'BTC-USD', 'changes': [['buy', '38257.91', '0.00000000']], 'time': '2021-05-20T03:55:56.897521Z'}
{'type': 'l2update', 'product_id': 'BTC-USD', 'changes': [['sell', '38367.75', '0.00000000']], 'time': '2021-05-20T03:55:56.901063Z'}
{'type': 'l2update', 'product_id': 'BTC-USD', 'changes': [['sell', '38432.55', '0.00000000']], 'time': '2021-05-20T03:55:56.905036Z'}
{'type': 'l2update', 'product_id': 'BTC-USD', 'changes': [['sell', '38365.21', '0.05351656']], 'time': '2021-05-20T03:55:56.907974Z'}
{'type': 'l2update', 'product_id': 'BTC-USD', 'changes': [['sell', '38375.27', '0.03000000']], 'time': '2021-05-20T03:55:56.911838Z'}
{'type': 'l2update', 'product_id': 'BTC-USD', 'changes': [['sell', '38441.81', '0.01300667']], 'time': '2021-05-20T03:55:56.912003Z'}
{'type': 'l2update', 'product_id': 'BTC-USD', 'changes': [['buy', '38334.26', '0.29177482']], 'time': '2021-05-20T03:55:56.912022Z'}
{'type': 'l2update', 'product_id': 'BTC-USD', 'changes': [['sell', '38453.95', '0.03544496']], 'time': '2021-05-20T03:55:56.914681Z'}
{'type': 'l2update', 'product_id': 'BTC-USD', 'changes': [['sell', '38447.10', '0.00000000']], 'time': '2021-05-20T03:55:56.914681Z'}
{'type': 'l2update', 'product_id': 'BTC-USD', 'changes': [['sell', '38446.47', '0.00000000']], 'time': '2021-05-20T03:55:56.914681Z'}
{'type': 'l2update', 'product_id': 'BTC-USD', 'changes': [['sell', '38428.07', '0.00000000']], 'time': '2021-05-20T03:55:56.914681Z'}
{'type': 'l2update', 'product_id': 'BTC-USD', 'changes': [['sell', '38422.14', '0.00000000']], 'time': '2021-05-20T03:55:56.914681Z'}
{'type': 'l2update', 'product_id': 'BTC-USD', 'changes': [['sell', '38416.24', '0.00000000']], 'time': '2021-05-20T03:55:56.914681Z'}
{'type': 'l2update', 'product_id': 'BTC-USD', 'changes': [['buy', '38307.48', '0.02400000']], 'time': '2021-05-20T03:55:56.916202Z'}
{'type': 'l2update', 'product_id': 'BTC-USD', 'changes': [['buy', '38306.68', '0.02400000']], 'time': '2021-05-20T03:55:56.916202Z'}
{'type': 'l2update', 'product_id': 'BTC-USD', 'changes': [['buy', '38305.87', '0.02400000']], 'time': '2021-05-20T03:55:56.916202Z'}
{'type': 'l2update', 'product_id': 'BTC-USD', 'changes': [['buy', '38239.96', '0.00000000']], 'time': '2021-05-20T03:55:56.923248Z'}
{'type': 'l2update', 'product_id': 'BTC-USD', 'changes': [['sell', '38491.62', '0.00000000']], 'time': '2021-05-20T03:55:56.923969Z'}
{'type': 'l2update', 'product_id': 'BTC-USD', 'changes': [['buy', '38276.50', '0.10000000']], 'time': '2021-05-20T03:55:56.924861Z'}
{'type': 'l2update', 'product_id': 'BTC-USD', 'changes': [['buy', '38309.51', '0.04073482']], 'time': '2021-05-20T03:55:56.924911Z'}
{'type': 'l2update', 'product_id': 'BTC-USD', 'changes': [['sell', '38338.24', '0.00000000']], 'time': '2021-05-20T03:55:56.934736Z'}
{'type': 'l2update', 'product_id': 'BTC-USD', 'changes': [['sell', '38468.36', '0.01000000']], 'time': '2021-05-20T03:55:56.935688Z'}
{'type': 'l2update', 'product_id': 'BTC-USD', 'changes': [['buy', '27272.00', '1.00729779']], 'time': '2021-05-20T03:55:56.935869Z'}
{'type': 'l2update', 'product_id': 'BTC-USD', 'changes': [['sell', '38478.45', '0.01000000']], 'time': '2021-05-20T03:55:56.939963Z'}
{'type': 'l2update', 'product_id': 'BTC-USD', 'changes': [['buy', '38258.09', '0.01000000']], 'time': '2021-05-20T03:55:56.941231Z'}
{'type': 'l2update', 'product_id': 'BTC-USD', 'changes': [['sell', '38341.87', '0.55300000']], 'time': '2021-05-20T03:55:56.944654Z'}
{'type': 'l2update', 'product_id': 'BTC-USD', 'changes': [['buy', '38321.76', '0.06696720']], 'time': '2021-05-20T03:55:56.949562Z'}
{'type': 'l2update', 'product_id': 'BTC-USD', 'changes': [['sell', '38478.45', '0.00000000']], 'time': '2021-05-20T03:55:56.950729Z'}
{'type': 'l2update', 'product_id': 'BTC-USD', 'changes': [['sell', '38346.47', '0.00000000']], 'time': '2021-05-20T03:55:56.954549Z'}
{'type': 'l2update', 'product_id': 'BTC-USD', 'changes': [['sell', '38406.10', '0.03808490']], 'time': '2021-05-20T03:55:56.968733Z'}
{'type': 'l2update', 'product_id': 'BTC-USD', 'changes': [['sell', '38396.03', '0.02978105']], 'time': '2021-05-20T03:55:56.968733Z'}
{'type': 'l2update', 'product_id': 'BTC-USD', 'changes': [['sell', '38391.28', '0.03544496']], 'time': '2021-05-20T03:55:56.968733Z'}
{'type': 'l2update', 'product_id': 'BTC-USD', 'changes': [['sell', '38370.53', '0.00000000']], 'time': '2021-05-20T03:55:56.969220Z'}
{'type': 'l2update', 'product_id': 'BTC-USD', 'changes': [['sell', '38491.62', '0.01000000']], 'time': '2021-05-20T03:55:56.969531Z'}
{'type': 'l2update', 'product_id': 'BTC-USD', 'changes': [['sell', '38460.89', '0.00000000']], 'time': '2021-05-20T03:55:56.974344Z'}
{'type': 'l2update', 'product_id': 'BTC-USD', 'changes': [['sell', '38453.95', '0.00000000']], 'time': '2021-05-20T03:55:56.974344Z'}
{'type': 'l2update', 'product_id': 'BTC-USD', 'changes': [['sell', '38376.59', '0.00000000']], 'time': '2021-05-20T03:55:56.975483Z'}
{'type': 'l2update', 'product_id': 'BTC-USD', 'changes': [['buy', '38232.18', '0.00000000']], 'time': '2021-05-20T03:55:56.978176Z'}
{'type': 'l2update', 'product_id': 'BTC-USD', 'changes': [['buy', '37514.31', '0.00000000']], 'time': '2021-05-20T03:55:56.981043Z'}
{'type': 'l2update', 'product_id': 'BTC-USD', 'changes': [['sell', '38376.60', '0.04000000']], 'time': '2021-05-20T03:55:56.983585Z'}
{'type': 'l2update', 'product_id': 'BTC-USD', 'changes': [['buy', '38295.22', '0.00000000']], 'time': '2021-05-20T03:55:56.983774Z'}
{'type': 'l2update', 'product_id': 'BTC-USD', 'changes': [['sell', '39120.18', '0.00000000']], 'time': '2021-05-20T03:55:56.985296Z'}
{'type': 'l2update', 'product_id': 'BTC-USD', 'changes': [['buy', '38301.98', '0.05351656']], 'time': '2021-05-20T03:55:56.991912Z'}
{'type': 'l2update', 'product_id': 'BTC-USD', 'changes': [['buy', '38244.70', '0.01136687']], 'time': '2021-05-20T03:55:56.992030Z'}
{'type': 'l2update', 'product_id': 'BTC-USD', 'changes': [['sell', '38350.27', '0.00000000']], 'time': '2021-05-20T03:55:56.993381Z'}
{'type': 'l2update', 'product_id': 'BTC-USD', 'changes': [['sell', '38428.15', '0.00000000']], 'time': '2021-05-20T03:55:56.995987Z'}
{'type': 'l2update', 'product_id': 'BTC-USD', 'changes': [['sell', '38428.54', '0.03683089']], 'time': '2021-05-20T03:55:56.996433Z'}
{'type': 'l2update', 'product_id': 'BTC-USD', 'changes': [['buy', '38297.60', '2.37600000']], 'time': '2021-05-20T03:55:57.020376Z'}
{'type': 'l2update', 'product_id': 'BTC-USD', 'changes': [['sell', '38416.93', '0.03721549']], 'time': '2021-05-20T03:55:57.020483Z'}
{'type': 'l2update', 'product_id': 'BTC-USD', 'changes': [['buy', '38304.57', '0.00000000']], 'time': '2021-05-20T03:55:57.027950Z'}
{'type': 'l2update', 'product_id': 'BTC-USD', 'changes': [['buy', '38305.87', '0.00000000']], 'time': '2021-05-20T03:55:57.030573Z'}
{'type': 'l2update', 'product_id': 'BTC-USD', 'changes': [['sell', '38432.62', '0.02400000']], 'time': '2021-05-20T03:55:57.035893Z'}
{'type': 'l2update', 'product_id': 'BTC-USD', 'changes': [['buy', '38262.62', '0.00000000']], 'time': '2021-05-20T03:55:57.037081Z'}
{'type': 'l2update', 'product_id': 'BTC-USD', 'changes': [['buy', '38310.55', '0.02610247']], 'time': '2021-05-20T03:55:57.039606Z'}
{'type': 'l2update', 'product_id': 'BTC-USD', 'changes': [['buy', '38306.19', '0.47740000']], 'time': '2021-05-20T03:55:57.040737Z'}
{'type': 'l2update', 'product_id': 'BTC-USD', 'changes': [['sell', '38484.49', '0.00000000']], 'time': '2021-05-20T03:55:57.042982Z'}
{'type': 'l2update', 'product_id': 'BTC-USD', 'changes': [['buy', '38314.60', '0.00000000']], 'time': '2021-05-20T03:55:57.043988Z'}
{'type': 'l2update', 'product_id': 'BTC-USD', 'changes': [['buy', '38309.51', '0.05466645']], 'time': '2021-05-20T03:55:57.044646Z'}
{'type': 'l2update', 'product_id': 'BTC-USD', 'changes': [['sell', '38353.17', '0.04988319']], 'time': '2021-05-20T03:55:57.044646Z'}
{'type': 'l2update', 'product_id': 'BTC-USD', 'changes': [['buy', '38301.98', '0.00000000']], 'time': '2021-05-20T03:55:57.047188Z'}
{'type': 'l2update', 'product_id': 'BTC-USD', 'changes': [['buy', '37487.22', '0.00000000']], 'time': '2021-05-20T03:55:57.047513Z'}
{'type': 'l2update', 'product_id': 'BTC-USD', 'changes': [['buy', '36785.98', '0.00000000']], 'time': '2021-05-20T03:55:57.047513Z'}
{'type': 'l2update', 'product_id': 'BTC-USD', 'changes': [['sell', '38381.66', '0.00000000']], 'time': '2021-05-20T03:55:57.048084Z'}
{'type': 'l2update', 'product_id': 'BTC-USD', 'changes': [['buy', '38291.14', '0.00000000']], 'time': '2021-05-20T03:55:57.048334Z'}
{'type': 'l2update', 'product_id': 'BTC-USD', 'changes': [['buy', '38320.85', '0.21200000']], 'time': '2021-05-20T03:55:57.050292Z'}
{'type': 'l2update', 'product_id': 'BTC-USD', 'changes': [['sell', '38428.54', '0.07281337']], 'time': '2021-05-20T03:55:57.050463Z'}
{'type': 'l2update', 'product_id': 'BTC-USD', 'changes': [['buy', '38306.19', '0.00000000']], 'time': '2021-05-20T03:55:57.051727Z'}
{'type': 'l2update', 'product_id': 'BTC-USD', 'changes': [['buy', '38308.95', '0.02400000']], 'time': '2021-05-20T03:55:57.054944Z'}
{'type': 'l2update', 'product_id': 'BTC-USD', 'changes': [['buy', '38309.51', '0.01393163']], 'time': '2021-05-20T03:55:57.056881Z'}
{'type': 'l2update', 'product_id': 'BTC-USD', 'changes': [['buy', '38302.46', '0.61100000']], 'time': '2021-05-20T03:55:57.061776Z'}
{'type': 'l2update', 'product_id': 'BTC-USD', 'changes': [['sell', '38513.64', '0.03604027']], 'time': '2021-05-20T03:55:57.062243Z'}
{'type': 'l2update', 'product_id': 'BTC-USD', 'changes': [['buy', '38303.29', '0.05351656']], 'time': '2021-05-20T03:55:57.062300Z'}
{'type': 'l2update', 'product_id': 'BTC-USD', 'changes': [['buy', '38308.95', '0.00000000']], 'time': '2021-05-20T03:55:57.062416Z'}
{'type': 'l2update', 'product_id': 'BTC-USD', 'changes': [['buy', '38316.40', '0.99440510']], 'time': '2021-05-20T03:55:57.066389Z'}
{'type': 'l2update', 'product_id': 'BTC-USD', 'changes': [['buy', '38314.66', '0.00000000']], 'time': '2021-05-20T03:55:57.076417Z'}
{'type': 'l2update', 'product_id': 'BTC-USD', 'changes': [['sell', '38400.96', '0.04735406']], 'time': '2021-05-20T03:55:57.077727Z'}
{'type': 'l2update', 'product_id': 'BTC-USD', 'changes': [['sell', '38434.63', '0.03139093']], 'time': '2021-05-20T03:55:57.081301Z'}
{'type': 'l2update', 'product_id': 'BTC-USD', 'changes': [['sell', '38372.32', '0.00000000']], 'time': '2021-05-20T03:55:57.081518Z'}
{'type': 'l2update', 'product_id': 'BTC-USD', 'changes': [['buy', '38161.65', '0.00000000']], 'time': '2021-05-20T03:55:57.083515Z'}
{'type': 'l2update', 'product_id': 'BTC-USD', 'changes': [['buy', '38256.90', '0.00000000']], 'time': '2021-05-20T03:55:57.083515Z'}
{'type': 'l2update', 'product_id': 'BTC-USD', 'changes': [['sell', '38367.82', '0.00000000']], 'time': '2021-05-20T03:55:57.083515Z'}
{'type': 'l2update', 'product_id': 'BTC-USD', 'changes': [['sell', '38342.93', '0.00000000']], 'time': '2021-05-20T03:55:57.088983Z'}
{'type': 'l2update', 'product_id': 'BTC-USD', 'changes': [['buy', '38281.79', '0.00000000']], 'time': '2021-05-20T03:55:57.088983Z'}
{'type': 'l2update', 'product_id': 'BTC-USD', 'changes': [['buy', '38180.79', '0.05192584']], 'time': '2021-05-20T03:55:57.090864Z'}
{'type': 'l2update', 'product_id': 'BTC-USD', 'changes': [['buy', '38316.41', '0.40135082']], 'time': '2021-05-20T03:55:57.100909Z'}
{'type': 'l2update', 'product_id': 'BTC-USD', 'changes': [['sell', '38517.17', '0.00000000']], 'time': '2021-05-20T03:55:57.103763Z'}
{'type': 'l2update', 'product_id': 'BTC-USD', 'changes': [['sell', '38370.65', '0.00000000']], 'time': '2021-05-20T03:55:57.106160Z'}
{'type': 'l2update', 'product_id': 'BTC-USD', 'changes': [['buy', '37664.43', '0.00000000']], 'time': '2021-05-20T03:55:57.107791Z'}
{'type': 'l2update', 'product_id': 'BTC-USD', 'changes': [['buy', '37138.44', '0.00000000']], 'time': '2021-05-20T03:55:57.107791Z'}
{'type': 'l2update', 'product_id': 'BTC-USD', 'changes': [['buy', '38288.24', '0.00000000']], 'time': '2021-05-20T03:55:57.111491Z'}
{'type': 'l2update', 'product_id': 'BTC-USD', 'changes': [['sell', '38447.38', '0.03844990']], 'time': '2021-05-20T03:55:57.113305Z'}
{'type': 'l2update', 'product_id': 'BTC-USD', 'changes': [['buy', '38309.51', '0.00000000']], 'time': '2021-05-20T03:55:57.113683Z'}
{'type': 'l2update', 'product_id': 'BTC-USD', 'changes': [['sell', '38353.17', '0.00000000']], 'time': '2021-05-20T03:55:57.113683Z'}
{'type': 'l2update', 'product_id': 'BTC-USD', 'changes': [['buy', '38293.66', '0.00000000']], 'time': '2021-05-20T03:55:57.114599Z'}
{'type': 'l2update', 'product_id': 'BTC-USD', 'changes': [['sell', '38352.32', '0.07079383']], 'time': '2021-05-20T03:55:57.118727Z'}
{'type': 'l2update', 'product_id': 'BTC-USD', 'changes': [['buy', '38320.90', '0.84700000']], 'time': '2021-05-20T03:55:57.118834Z'}
{'type': 'l2update', 'product_id': 'BTC-USD', 'changes': [['sell', '38538.04', '0.00778451']], 'time': '2021-05-20T03:55:57.118984Z'}
{'type': 'l2update', 'product_id': 'BTC-USD', 'changes': [['buy', '38281.70', '0.00000000']], 'time': '2021-05-20T03:55:57.119526Z'}
{'type': 'l2update', 'product_id': 'BTC-USD', 'changes': [['buy', '38306.22', '0.02400000']], 'time': '2021-05-20T03:55:57.120807Z'}
{'type': 'l2update', 'product_id': 'BTC-USD', 'changes': [['buy', '38303.29', '0.00000000']], 'time': '2021-05-20T03:55:57.121434Z'}
{'type': 'l2update', 'product_id': 'BTC-USD', 'changes': [['sell', '38373.21', '0.01000000']], 'time': '2021-05-20T03:55:57.124552Z'}
{'type': 'l2update', 'product_id': 'BTC-USD', 'changes': [['buy', '38307.09', '0.57549764']], 'time': '2021-05-20T03:55:57.129908Z'}
{'type': 'l2update', 'product_id': 'BTC-USD', 'changes': [['buy', '38307.09', '0.52198108']], 'time': '2021-05-20T03:55:57.136217Z'}
{'type': 'l2update', 'product_id': 'BTC-USD', 'changes': [['buy', '38290.79', '0.01000000']], 'time': '2021-05-20T03:55:57.137535Z'}
{'type': 'l2update', 'product_id': 'BTC-USD', 'changes': [['buy', '38307.10', '0.05351656']], 'time': '2021-05-20T03:55:57.143430Z'}
{'type': 'l2update', 'product_id': 'BTC-USD', 'changes': [['buy', '38306.14', '0.46500000']], 'time': '2021-05-20T03:55:57.143961Z'}
{'type': 'l2update', 'product_id': 'BTC-USD', 'changes': [['buy', '38229.82', '0.00000000']], 'time': '2021-05-20T03:55:57.149834Z'}
{'type': 'l2update', 'product_id': 'BTC-USD', 'changes': [['buy', '38260.84', '0.01000000']], 'time': '2021-05-20T03:55:57.161106Z'}
{'type': 'l2update', 'product_id': 'BTC-USD', 'changes': [['buy', '38277.69', '0.32000000']], 'time': '2021-05-20T03:55:57.170611Z'}
{'type': 'l2update', 'product_id': 'BTC-USD', 'changes': [['sell', '38387.75', '0.32000000']], 'time': '2021-05-20T03:55:57.170611Z'}
{'type': 'l2update', 'product_id': 'BTC-USD', 'changes': [['buy', '38183.04', '0.80000000']], 'time': '2021-05-20T03:55:57.170611Z'}
{'type': 'l2update', 'product_id': 'BTC-USD', 'changes': [['sell', '38454.04', '0.03862473']], 'time': '2021-05-20T03:55:57.170635Z'}
{'type': 'l2update', 'product_id': 'BTC-USD', 'changes': [['buy', '37537.22', '0.06480429']], 'time': '2021-05-20T03:55:57.178890Z'}
{'type': 'l2update', 'product_id': 'BTC-USD', 'changes': [['buy', '38308.30', '0.04951650']], 'time': '2021-05-20T03:55:57.181194Z'}
{'type': 'l2update', 'product_id': 'BTC-USD', 'changes': [['sell', '38350.81', '0.05064431']], 'time': '2021-05-20T03:55:57.181194Z'}
{'type': 'l2update', 'product_id': 'BTC-USD', 'changes': [['buy', '38180.79', '0.00000000']], 'time': '2021-05-20T03:55:57.182453Z'}
{'type': 'l2update', 'product_id': 'BTC-USD', 'changes': [['buy', '38302.59', '0.02000000']], 'time': '2021-05-20T03:55:57.182908Z'}
{'type': 'l2update', 'product_id': 'BTC-USD', 'changes': [['sell', '38362.85', '0.02000000']], 'time': '2021-05-20T03:55:57.182908Z'}
{'type': 'l2update', 'product_id': 'BTC-USD', 'changes': [['sell', '39135.11', '0.06342860']], 'time': '2021-05-20T03:55:57.191322Z'}
{'type': 'l2update', 'product_id': 'BTC-USD', 'changes': [['buy', '38306.14', '0.00000000']], 'time': '2021-05-20T03:55:57.194732Z'}
{'type': 'l2update', 'product_id': 'BTC-USD', 'changes': [['sell', '38365.21', '0.00000000']], 'time': '2021-05-20T03:55:57.194928Z'}
{'type': 'l2update', 'product_id': 'BTC-USD', 'changes': [['sell', '38380.35', '0.00000000']], 'time': '2021-05-20T03:55:57.196052Z'}
{'type': 'l2update', 'product_id': 'BTC-USD', 'changes': [['sell', '38358.03', '0.10351656']], 'time': '2021-05-20T03:55:57.204773Z'}
{'type': 'l2update', 'product_id': 'BTC-USD', 'changes': [['sell', '38460.89', '0.03728018']], 'time': '2021-05-20T03:55:57.204805Z'}
{'type': 'l2update', 'product_id': 'BTC-USD', 'changes': [['sell', '43100.00', '1.09530000']], 'time': '2021-05-20T03:55:57.214651Z'}
{'type': 'l2update', 'product_id': 'BTC-USD', 'changes': [['sell', '38434.22', '0.12252948']], 'time': '2021-05-20T03:55:57.227291Z'}
{'type': 'l2update', 'product_id': 'BTC-USD', 'changes': [['sell', '43100.00', '4.65190000']], 'time': '2021-05-20T03:55:57.235300Z'}
{'type': 'l2update', 'product_id': 'BTC-USD', 'changes': [['sell', '38513.64', '0.00000000']], 'time': '2021-05-20T03:55:57.237810Z'}
{'type': 'l2update', 'product_id': 'BTC-USD', 'changes': [['buy', '38244.70', '0.00000000']], 'time': '2021-05-20T03:55:57.239071Z'}
{'type': 'l2update', 'product_id': 'BTC-USD', 'changes': [['sell', '38494.08', '0.01263906']], 'time': '2021-05-20T03:55:57.247847Z'}
{'type': 'l2update', 'product_id': 'BTC-USD', 'changes': [['buy', '38257.21', '0.01136687']], 'time': '2021-05-20T03:55:57.252332Z'}
{'type': 'l2update', 'product_id': 'BTC-USD', 'changes': [['sell', '38358.04', '0.00000000']], 'time': '2021-05-20T03:55:57.259284Z'}
{'type': 'l2update', 'product_id': 'BTC-USD', 'changes': [['sell', '38358.03', '0.05000000']], 'time': '2021-05-20T03:55:57.265774Z'}
{'type': 'l2update', 'product_id': 'BTC-USD', 'changes': [['buy', '38307.10', '0.00000000']], 'time': '2021-05-20T03:55:57.272529Z'}
{'type': 'l2update', 'product_id': 'BTC-USD', 'changes': [['buy', '38297.60', '0.00000000']], 'time': '2021-05-20T03:55:57.274722Z'}
{'type': 'l2update', 'product_id': 'BTC-USD', 'changes': [['sell', '38365.21', '0.05351656']], 'time': '2021-05-20T03:55:57.275919Z'}
{'type': 'l2update', 'product_id': 'BTC-USD', 'changes': [['sell', '38432.62', '0.00000000']], 'time': '2021-05-20T03:55:57.278233Z'}
{'type': 'l2update', 'product_id': 'BTC-USD', 'changes': [['buy', '38310.55', '0.07961903']], 'time': '2021-05-20T03:55:57.283730Z'}
{'type': 'l2update', 'product_id': 'BTC-USD', 'changes': [['buy', '38307.77', '0.47810000']], 'time': '2021-05-20T03:55:57.288297Z'}
{'type': 'l2update', 'product_id': 'BTC-USD', 'changes': [['sell', '38491.62', '0.00000000']], 'time': '2021-05-20T03:55:57.304250Z'}
{'type': 'l2update', 'product_id': 'BTC-USD', 'changes': [['buy', '37500.01', '0.00000000']], 'time': '2021-05-20T03:55:57.312082Z'}
{'type': 'l2update', 'product_id': 'BTC-USD', 'changes': [['sell', '39485.48', '0.00000000']], 'time': '2021-05-20T03:55:57.312082Z'}
{'type': 'l2update', 'product_id': 'BTC-USD', 'changes': [['sell', '39486.71', '0.00000000']], 'time': '2021-05-20T03:55:57.312082Z'}
{'type': 'l2update', 'product_id': 'BTC-USD', 'changes': [['sell', '39488.99', '0.00000000']], 'time': '2021-05-20T03:55:57.312082Z'}
{'type': 'l2update', 'product_id': 'BTC-USD', 'changes': [['sell', '38478.45', '0.01000000']], 'time': '2021-05-20T03:55:57.317206Z'}
{'type': 'l2update', 'product_id': 'BTC-USD', 'changes': [['sell', '39495.99', '0.10960000']], 'time': '2021-05-20T03:55:57.320219Z'}
{'type': 'l2update', 'product_id': 'BTC-USD', 'changes': [['sell', '39499.99', '0.06410000']], 'time': '2021-05-20T03:55:57.320219Z'}
{'type': 'l2update', 'product_id': 'BTC-USD', 'changes': [['buy', '37485.34', '0.05620000']], 'time': '2021-05-20T03:55:57.320219Z'}
{'type': 'l2update', 'product_id': 'BTC-USD', 'changes': [['sell', '39495.98', '0.00240000']], 'time': '2021-05-20T03:55:57.320219Z'}
{'type': 'l2update', 'product_id': 'BTC-USD', 'changes': [['buy', '37487.46', '0.01100000']], 'time': '2021-05-20T03:55:57.320219Z'}
{'type': 'l2update', 'product_id': 'BTC-USD', 'changes': [['buy', '37491.66', '0.00090000']], 'time': '2021-05-20T03:55:57.320219Z'}
{'type': 'l2update', 'product_id': 'BTC-USD', 'changes': [['sell', '38478.45', '0.00000000']], 'time': '2021-05-20T03:55:57.324267Z'}
{'type': 'l2update', 'product_id': 'BTC-USD', 'changes': [['sell', '38491.62', '0.01000000']], 'time': '2021-05-20T03:55:57.337486Z'}
{'type': 'l2update', 'product_id': 'BTC-USD', 'changes': [['buy', '38280.60', '0.00000000']], 'time': '2021-05-20T03:55:57.344737Z'}
{'type': 'l2update', 'product_id': 'BTC-USD', 'changes': [['sell', '38357.83', '0.45290000']], 'time': '2021-05-20T03:55:57.349554Z'}
{'type': 'l2update', 'product_id': 'BTC-USD', 'changes': [['sell', '38334.27', '0.47002094']], 'time': '2021-05-20T03:55:57.353706Z'}
{'type': 'l2update', 'product_id': 'BTC-USD', 'changes': [['sell', '38358.03', '0.00000000']], 'time': '2021-05-20T03:55:57.358125Z'}
{'type': 'l2update', 'product_id': 'BTC-USD', 'changes': [['sell', '38357.82', '0.05351656']], 'time': '2021-05-20T03:55:57.361120Z'}
{'type': 'l2update', 'product_id': 'BTC-USD', 'changes': [['sell', '38365.21', '0.00000000']], 'time': '2021-05-20T03:55:57.361719Z'}
{'type': 'l2update', 'product_id': 'BTC-USD', 'changes': [['buy', '38334.26', '0.94177482']], 'time': '2021-05-20T03:55:57.365158Z'}
{'type': 'l2update', 'product_id': 'BTC-USD', 'changes': [['sell', '38357.82', '0.10351656']], 'time': '2021-05-20T03:55:57.375901Z'}
{'type': 'l2update', 'product_id': 'BTC-USD', 'changes': [['sell', '38369.09', '0.05177251']], 'time': '2021-05-20T03:55:57.376976Z'}
{'type': 'l2update', 'product_id': 'BTC-USD', 'changes': [['sell', '38639.99', '0.00000000']], 'time': '2021-05-20T03:55:57.391650Z'}
{'type': 'l2update', 'product_id': 'BTC-USD', 'changes': [['buy', '38151.78', '0.00000000']], 'time': '2021-05-20T03:55:57.391768Z'}
{'type': 'l2update', 'product_id': 'BTC-USD', 'changes': [['buy', '38334.26', '0.29177482']], 'time': '2021-05-20T03:55:57.397187Z'}
{'type': 'l2update', 'product_id': 'BTC-USD', 'changes': [['sell', '38334.27', '0.46490221']], 'time': '2021-05-20T03:55:57.407749Z'}
{'type': 'l2update', 'product_id': 'BTC-USD', 'changes': [['sell', '38338.29', '0.00000000']], 'time': '2021-05-20T03:55:57.425437Z'}
{'type': 'l2update', 'product_id': 'BTC-USD', 'changes': [['sell', '38446.21', '0.00000000']], 'time': '2021-05-20T03:55:57.431536Z'}
{'type': 'l2update', 'product_id': 'BTC-USD', 'changes': [['sell', '38337.04', '0.00000000']], 'time': '2021-05-20T03:55:57.437586Z'}
{'type': 'l2update', 'product_id': 'BTC-USD', 'changes': [['sell', '38647.43', '3.23362444']], 'time': '2021-05-20T03:55:57.438192Z'}
{'type': 'l2update', 'product_id': 'BTC-USD', 'changes': [['buy', '38183.77', '0.80355629']], 'time': '2021-05-20T03:55:57.438219Z'}
{'type': 'l2update', 'product_id': 'BTC-USD', 'changes': [['buy', '38302.20', '2.37600000']], 'time': '2021-05-20T03:55:57.438232Z'}
{'type': 'l2update', 'product_id': 'BTC-USD', 'changes': [['sell', '38459.98', '0.01000000']], 'time': '2021-05-20T03:55:57.444815Z'}
{'type': 'l2update', 'product_id': 'BTC-USD', 'changes': [['sell', '38437.23', '0.02400000']], 'time': '2021-05-20T03:55:57.448916Z'}
{'type': 'l2update', 'product_id': 'BTC-USD', 'changes': [['buy', '38302.20', '0.00000000']], 'time': '2021-05-20T03:55:57.453452Z'}
{'type': 'l2update', 'product_id': 'BTC-USD', 'changes': [['sell', '38341.86', '0.18981474']], 'time': '2021-05-20T03:55:57.456424Z'}
{'type': 'l2update', 'product_id': 'BTC-USD', 'changes': [['sell', '38437.23', '0.00000000']], 'time': '2021-05-20T03:55:57.457167Z'}
{'type': 'l2update', 'product_id': 'BTC-USD', 'changes': [['sell', '38334.27', '0.46391582']], 'time': '2021-05-20T03:55:57.465009Z'}
{'type': 'l2update', 'product_id': 'BTC-USD', 'changes': [['buy', '37537.22', '0.00000000']], 'time': '2021-05-20T03:55:57.466709Z'}
{'type': 'l2update', 'product_id': 'BTC-USD', 'changes': [['buy', '38307.77', '0.00000000']], 'time': '2021-05-20T03:55:57.469636Z'}
{'type': 'l2update', 'product_id': 'BTC-USD', 'changes': [['sell', '39135.11', '0.00000000']], 'time': '2021-05-20T03:55:57.471006Z'}
{'type': 'l2update', 'product_id': 'BTC-USD', 'changes': [['buy', '38310.55', '0.02610247']], 'time': '2021-05-20T03:55:57.475374Z'}
{'type': 'l2update', 'product_id': 'BTC-USD', 'changes': [['buy', '38306.38', '0.40480000']], 'time': '2021-05-20T03:55:57.477309Z'}
{'type': 'l2update', 'product_id': 'BTC-USD', 'changes': [['buy', '38314.66', '0.05351656']], 'time': '2021-05-20T03:55:57.481479Z'}
{'type': 'l2update', 'product_id': 'BTC-USD', 'changes': [['buy', '37540.96', '0.06588611']], 'time': '2021-05-20T03:55:57.497891Z'}
{'type': 'l2update', 'product_id': 'BTC-USD', 'changes': [['sell', '39132.50', '0.06358820']], 'time': '2021-05-20T03:55:57.509886Z'}
{'type': 'l2update', 'product_id': 'BTC-USD', 'changes': [['sell', '38426.00', '0.00000000']], 'time': '2021-05-20T03:55:57.520623Z'}
{'type': 'l2update', 'product_id': 'BTC-USD', 'changes': [['sell', '38441.10', '0.01000000']], 'time': '2021-05-20T03:55:57.530362Z'}
{'type': 'l2update', 'product_id': 'BTC-USD', 'changes': [['buy', '38257.21', '0.00000000']], 'time': '2021-05-20T03:55:57.534587Z'}
{'type': 'l2update', 'product_id': 'BTC-USD', 'changes': [['buy', '38231.55', '0.01136687']], 'time': '2021-05-20T03:55:57.547493Z'}
{'type': 'l2update', 'product_id': 'BTC-USD', 'changes': [['buy', '38294.07', '0.05455914']], 'time': '2021-05-20T03:55:57.556412Z'}
{'type': 'l2update', 'product_id': 'BTC-USD', 'changes': [['buy', '38320.85', '0.00000000']], 'time': '2021-05-20T03:55:57.570550Z'}
{'type': 'l2update', 'product_id': 'BTC-USD', 'changes': [['buy', '38320.90', '0.00000000']], 'time': '2021-05-20T03:55:57.576442Z'}
{'type': 'l2update', 'product_id': 'BTC-USD', 'changes': [['buy', '38268.83', '0.05445925']], 'time': '2021-05-20T03:55:57.579481Z'}
{'type': 'l2update', 'product_id': 'BTC-USD', 'changes': [['sell', '38662.91', '0.00000000']], 'time': '2021-05-20T03:55:57.581421Z'}
{'type': 'l2update', 'product_id': 'BTC-USD', 'changes': [['buy', '38265.44', '0.12253332']], 'time': '2021-05-20T03:55:57.583354Z'}
{'type': 'l2update', 'product_id': 'BTC-USD', 'changes': [['buy', '38316.46', '0.84700000']], 'time': '2021-05-20T03:55:57.587336Z'}
{'type': 'l2update', 'product_id': 'BTC-USD', 'changes': [['buy', '38271.05', '0.02722963']], 'time': '2021-05-20T03:55:57.587630Z'}
{'type': 'l2update', 'product_id': 'BTC-USD', 'changes': [['buy', '38308.30', '0.00000000']], 'time': '2021-05-20T03:55:57.588113Z'}
{'type': 'l2update', 'product_id': 'BTC-USD', 'changes': [['buy', '38314.66', '0.00000000']], 'time': '2021-05-20T03:55:57.593842Z'}
{'type': 'l2update', 'product_id': 'BTC-USD', 'changes': [['sell', '38459.98', '0.00000000']], 'time': '2021-05-20T03:55:57.596885Z'}
{'type': 'l2update', 'product_id': 'BTC-USD', 'changes': [['sell', '38604.68', '0.01000000']], 'time': '2021-05-20T03:55:57.602891Z'}
{'type': 'l2update', 'product_id': 'BTC-USD', 'changes': [['buy', '38291.22', '0.04000000']], 'time': '2021-05-20T03:55:57.603260Z'}
{'type': 'l2update', 'product_id': 'BTC-USD', 'changes': [['buy', '38316.41', '0.00000000']], 'time': '2021-05-20T03:55:57.604291Z'}
{'type': 'l2update', 'product_id': 'BTC-USD', 'changes': [['buy', '38310.55', '0.08934127']], 'time': '2021-05-20T03:55:57.607374Z'}
{'type': 'l2update', 'product_id': 'BTC-USD', 'changes': [['buy', '37529.32', '0.06511627']], 'time': '2021-05-20T03:55:57.607411Z'}
{'type': 'l2update', 'product_id': 'BTC-USD', 'changes': [['buy', '38282.03', '0.05000000']], 'time': '2021-05-20T03:55:57.616023Z'}
{'type': 'l2update', 'product_id': 'BTC-USD', 'changes': [['buy', '38301.01', '0.05697257']], 'time': '2021-05-20T03:55:57.616278Z'}
{'type': 'l2update', 'product_id': 'BTC-USD', 'changes': [['sell', '38538.04', '0.00000000']], 'time': '2021-05-20T03:55:57.616290Z'}
{'type': 'l2update', 'product_id': 'BTC-USD', 'changes': [['sell', '38437.18', '0.01000000']], 'time': '2021-05-20T03:55:57.623120Z'}
{'type': 'l2update', 'product_id': 'BTC-USD', 'changes': [['buy', '38316.47', '0.40135082']], 'time': '2021-05-20T03:55:57.624883Z'}
{'type': 'l2update', 'product_id': 'BTC-USD', 'changes': [['sell', '38352.32', '0.13403263']], 'time': '2021-05-20T03:55:57.624930Z'}
{'type': 'l2update', 'product_id': 'BTC-USD', 'changes': [['buy', '38292.01', '1.20000000']], 'time': '2021-05-20T03:55:57.628792Z'}
{'type': 'l2update', 'product_id': 'BTC-USD', 'changes': [['sell', '38524.96', '0.01000000']], 'time': '2021-05-20T03:55:57.628824Z'}
{'type': 'l2update', 'product_id': 'BTC-USD', 'changes': [['sell', '38357.82', '0.05000000']], 'time': '2021-05-20T03:55:57.630828Z'}
{'type': 'l2update', 'product_id': 'BTC-USD', 'changes': [['sell', '38427.05', '1.20000000']], 'time': '2021-05-20T03:55:57.640548Z'}
{'type': 'l2update', 'product_id': 'BTC-USD', 'changes': [['buy', '37529.32', '0.00000000']], 'time': '2021-05-20T03:55:57.643229Z'}
{'type': 'l2update', 'product_id': 'BTC-USD', 'changes': [['buy', '38314.66', '0.06323880']], 'time': '2021-05-20T03:55:57.648586Z'}
{'type': 'l2update', 'product_id': 'BTC-USD', 'changes': [['sell', '38352.32', '0.07079383']], 'time': '2021-05-20T03:55:57.648836Z'}
{'type': 'l2update', 'product_id': 'BTC-USD', 'changes': [['sell', '38337.00', '0.55300000']], 'time': '2021-05-20T03:55:57.648945Z'}
{'type': 'l2update', 'product_id': 'BTC-USD', 'changes': [['buy', '38310.55', '0.02610247']], 'time': '2021-05-20T03:55:57.650682Z'}
{'type': 'l2update', 'product_id': 'BTC-USD', 'changes': [['sell', '38405.84', '0.02603771']], 'time': '2021-05-20T03:55:57.653450Z'}
{'type': 'l2update', 'product_id': 'BTC-USD', 'changes': [['buy', '38306.38', '0.00000000']], 'time': '2021-05-20T03:55:57.654734Z'}
{'type': 'l2update', 'product_id': 'BTC-USD', 'changes': [['sell', '38341.86', '0.00000000']], 'time': '2021-05-20T03:55:57.656425Z'}
{'type': 'l2update', 'product_id': 'BTC-USD', 'changes': [['sell', '38352.31', '0.06323880']], 'time': '2021-05-20T03:55:57.657824Z'}
{'type': 'l2update', 'product_id': 'BTC-USD', 'changes': [['buy', '38276.50', '0.00000000']], 'time': '2021-05-20T03:55:57.659964Z'}
{'type': 'l2update', 'product_id': 'BTC-USD', 'changes': [['buy', '38260.84', '0.00000000']], 'time': '2021-05-20T03:55:57.664212Z'}
{'type': 'l2update', 'product_id': 'BTC-USD', 'changes': [['buy', '38305.16', '0.42390000']], 'time': '2021-05-20T03:55:57.665367Z'}
{'type': 'l2update', 'product_id': 'BTC-USD', 'changes': [['buy', '38301.01', '0.00000000']], 'time': '2021-05-20T03:55:57.669531Z'}
{'type': 'l2update', 'product_id': 'BTC-USD', 'changes': [['sell', '38350.81', '0.00000000']], 'time': '2021-05-20T03:55:57.669531Z'}
{'type': 'l2update', 'product_id': 'BTC-USD', 'changes': [['sell', '38491.62', '0.00000000']], 'time': '2021-05-20T03:55:57.670317Z'}
{'type': 'l2update', 'product_id': 'BTC-USD', 'changes': [['buy', '38279.11', '0.01000000']], 'time': '2021-05-20T03:55:57.678246Z'}
{'type': 'l2update', 'product_id': 'BTC-USD', 'changes': [['sell', '38336.99', '0.18981474']], 'time': '2021-05-20T03:55:57.678435Z'}
{'type': 'l2update', 'product_id': 'BTC-USD', 'changes': [['sell', '38478.45', '0.01000000']], 'time': '2021-05-20T03:55:57.683287Z'}
{'type': 'l2update', 'product_id': 'BTC-USD', 'changes': [['buy', '38314.59', '0.00000000']], 'time': '2021-05-20T03:55:57.685796Z'}
{'type': 'l2update', 'product_id': 'BTC-USD', 'changes': [['buy', '38174.28', '0.00000000']], 'time': '2021-05-20T03:55:57.686045Z'}
{'type': 'l2update', 'product_id': 'BTC-USD', 'changes': [['buy', '38277.50', '0.10000000']], 'time': '2021-05-20T03:55:57.688031Z'}
{'type': 'l2update', 'product_id': 'BTC-USD', 'changes': [['sell', '38478.45', '0.00000000']], 'time': '2021-05-20T03:55:57.692376Z'}
{'type': 'l2update', 'product_id': 'BTC-USD', 'changes': [['buy', '38294.07', '0.00000000']], 'time': '2021-05-20T03:55:57.699261Z'}
{'type': 'l2update', 'product_id': 'BTC-USD', 'changes': [['buy', '38321.76', '0.00000000']], 'time': '2021-05-20T03:55:57.701350Z'}
{'type': 'l2update', 'product_id': 'BTC-USD', 'changes': [['buy', '38258.09', '0.00000000']], 'time': '2021-05-20T03:55:57.703066Z'}
{'type': 'l2update', 'product_id': 'BTC-USD', 'changes': [['buy', '38303.28', '0.00000000']], 'time': '2021-05-20T03:55:57.706968Z'}
{'type': 'l2update', 'product_id': 'BTC-USD', 'changes': [['sell', '38491.62', '0.01000000']], 'time': '2021-05-20T03:55:57.708074Z'}
{'type': 'l2update', 'product_id': 'BTC-USD', 'changes': [['sell', '38498.62', '0.00000000']], 'time': '2021-05-20T03:55:57.712170Z'}
{'type': 'l2update', 'product_id': 'BTC-USD', 'changes': [['buy', '38300.48', '0.05101936']], 'time': '2021-05-20T03:55:57.713855Z'}
{'type': 'l2update', 'product_id': 'BTC-USD', 'changes': [['sell', '38346.67', '0.03946185']], 'time': '2021-05-20T03:55:57.713855Z'}
{'type': 'l2update', 'product_id': 'BTC-USD', 'changes': [['sell', '38373.21', '0.00000000']], 'time': '2021-05-20T03:55:57.715728Z'}
{'type': 'l2update', 'product_id': 'BTC-USD', 'changes': [['sell', '38441.10', '0.00000000']], 'time': '2021-05-20T03:55:57.719948Z'}
{'type': 'l2update', 'product_id': 'BTC-USD', 'changes': [['buy', '38301.97', '0.00000000']], 'time': '2021-05-20T03:55:57.722177Z'}
{'type': 'l2update', 'product_id': 'BTC-USD', 'changes': [['buy', '38286.38', '0.00000000']], 'time': '2021-05-20T03:55:57.723242Z'}
{'type': 'l2update', 'product_id': 'BTC-USD', 'changes': [['buy', '38182.72', '0.01000000']], 'time': '2021-05-20T03:55:57.729067Z'}
{'type': 'l2update', 'product_id': 'BTC-USD', 'changes': [['buy', '38270.53', '0.16000000']], 'time': '2021-05-20T03:55:57.729110Z'}
{'type': 'l2update', 'product_id': 'BTC-USD', 'changes': [['sell', '38479.28', '0.01000000']], 'time': '2021-05-20T03:55:57.730346Z'}
{'type': 'l2update', 'product_id': 'BTC-USD', 'changes': [['buy', '38290.79', '0.00000000']], 'time': '2021-05-20T03:55:57.730403Z'}
{'type': 'l2update', 'product_id': 'BTC-USD', 'changes': [['sell', '38368.40', '0.00000000']], 'time': '2021-05-20T03:55:57.730600Z'}
{'type': 'l2update', 'product_id': 'BTC-USD', 'changes': [['sell', '38428.96', '0.01000000']], 'time': '2021-05-20T03:55:57.734654Z'}
{'type': 'l2update', 'product_id': 'BTC-USD', 'changes': [['buy', '38305.16', '0.00000000']], 'time': '2021-05-20T03:55:57.736251Z'}
{'type': 'l2update', 'product_id': 'BTC-USD', 'changes': [['sell', '38441.81', '0.00000000']], 'time': '2021-05-20T03:55:57.741420Z'}
{'type': 'l2update', 'product_id': 'BTC-USD', 'changes': [['sell', '38428.96', '0.00000000']], 'time': '2021-05-20T03:55:57.745481Z'}
{'type': 'l2update', 'product_id': 'BTC-USD', 'changes': [['sell', '38357.83', '0.00000000']], 'time': '2021-05-20T03:55:57.745641Z'}
{'type': 'l2update', 'product_id': 'BTC-USD', 'changes': [['sell', '38372.33', '0.01000000']], 'time': '2021-05-20T03:55:57.750713Z'}
{'type': 'l2update', 'product_id': 'BTC-USD', 'changes': [['buy', '38316.46', '0.00000000']], 'time': '2021-05-20T03:55:57.756904Z'}
{'type': 'l2update', 'product_id': 'BTC-USD', 'changes': [['sell', '38357.82', '0.00000000']], 'time': '2021-05-20T03:55:57.758902Z'}
{'type': 'l2update', 'product_id': 'BTC-USD', 'changes': [['sell', '38346.67', '0.00000000']], 'time': '2021-05-20T03:55:57.759583Z'}
{'type': 'l2update', 'product_id': 'BTC-USD', 'changes': [['buy', '38314.65', '0.84700000']], 'time': '2021-05-20T03:55:57.759604Z'}
{'type': 'l2update', 'product_id': 'BTC-USD', 'changes': [['sell', '38453.80', '0.01300261']], 'time': '2021-05-20T03:55:57.759786Z'}
{'type': 'l2update', 'product_id': 'BTC-USD', 'changes': [['buy', '38214.25', '0.00000000']], 'time': '2021-05-20T03:55:57.763544Z'}
{'type': 'l2update', 'product_id': 'BTC-USD', 'changes': [['sell', '38355.86', '0.46090000']], 'time': '2021-05-20T03:55:57.766213Z'}
{'type': 'l2update', 'product_id': 'BTC-USD', 'changes': [['sell', '38411.53', '0.01000000']], 'time': '2021-05-20T03:55:57.766528Z'}
{'type': 'l2update', 'product_id': 'BTC-USD', 'changes': [['buy', '38316.47', '0.00000000']], 'time': '2021-05-20T03:55:57.766568Z'}
{'type': 'l2update', 'product_id': 'BTC-USD', 'changes': [['buy', '38334.26', '0.27685482']], 'time': '2021-05-20T03:55:57.770754Z'}
{'type': 'l2update', 'product_id': 'BTC-USD', 'changes': [['buy', '38334.26', '0.22257258']], 'time': '2021-05-20T03:55:57.770754Z'}
{'type': 'l2update', 'product_id': 'BTC-USD', 'changes': [['buy', '38334.26', '0.12257258']], 'time': '2021-05-20T03:55:57.770754Z'}
{'type': 'l2update', 'product_id': 'BTC-USD', 'changes': [['buy', '38334.26', '0.00007482']], 'time': '2021-05-20T03:55:57.770754Z'}
{'type': 'l2update', 'product_id': 'BTC-USD', 'changes': [['sell', '38355.86', '0.00000000']], 'time': '2021-05-20T03:55:57.772798Z'}
{'type': 'l2update', 'product_id': 'BTC-USD', 'changes': [['sell', '38374.74', '0.00000000']], 'time': '2021-05-20T03:55:57.775108Z'}
{'type': 'l2update', 'product_id': 'BTC-USD', 'changes': [['buy', '38314.71', '0.84700000']], 'time': '2021-05-20T03:55:57.775943Z'}
{'type': 'l2update', 'product_id': 'BTC-USD', 'changes': [['sell', '38365.21', '0.05000000']], 'time': '2021-05-20T03:55:57.776613Z'}
{'type': 'l2update', 'product_id': 'BTC-USD', 'changes': [['buy', '38194.80', '0.04358200']], 'time': '2021-05-20T03:55:57.780516Z'}
{'type': 'l2update', 'product_id': 'BTC-USD', 'changes': [['buy', '38310.60', '0.52000000']], 'time': '2021-05-20T03:55:57.780934Z'}
{'type': 'l2update', 'product_id': 'BTC-USD', 'changes': [['sell', '38375.27', '0.00000000']], 'time': '2021-05-20T03:55:57.783594Z'}
{'type': 'l2update', 'product_id': 'BTC-USD', 'changes': [['buy', '38331.12', '0.00000000']], 'time': '2021-05-20T03:55:57.785952Z'}
{'type': 'l2update', 'product_id': 'BTC-USD', 'changes': [['buy', '38167.02', '0.04860027']], 'time': '2021-05-20T03:55:57.788169Z'}
{'type': 'l2update', 'product_id': 'BTC-USD', 'changes': [['buy', '38314.71', '0.00000000']], 'time': '2021-05-20T03:55:57.790331Z'}
{'type': 'l2update', 'product_id': 'BTC-USD', 'changes': [['buy', '38292.01', '0.00000000']], 'time': '2021-05-20T03:55:57.790399Z'}
{'type': 'l2update', 'product_id': 'BTC-USD', 'changes': [['sell', '38334.27', '0.49391582']], 'time': '2021-05-20T03:55:57.790573Z'}
{'type': 'l2update', 'product_id': 'BTC-USD', 'changes': [['buy', '38316.40', '0.00000000']], 'time': '2021-05-20T03:55:57.793853Z'}
{'type': 'l2update', 'product_id': 'BTC-USD', 'changes': [['buy', '38270.53', '0.00000000']], 'time': '2021-05-20T03:55:57.794071Z'}
{'type': 'l2update', 'product_id': 'BTC-USD', 'changes': [['buy', '38307.48', '0.00000000']], 'time': '2021-05-20T03:55:57.794275Z'}
{'type': 'l2update', 'product_id': 'BTC-USD', 'changes': [['buy', '38306.22', '0.00000000']], 'time': '2021-05-20T03:55:57.794275Z'}
{'type': 'l2update', 'product_id': 'BTC-USD', 'changes': [['buy', '38182.72', '0.00000000']], 'time': '2021-05-20T03:55:57.794696Z'}
{'type': 'l2update', 'product_id': 'BTC-USD', 'changes': [['buy', '38316.41', '0.40135082']], 'time': '2021-05-20T03:55:57.795453Z'}
{'type': 'l2update', 'product_id': 'BTC-USD', 'changes': [['sell', '38440.77', '0.00000000']], 'time': '2021-05-20T03:55:57.796176Z'}
{'type': 'l2update', 'product_id': 'BTC-USD', 'changes': [['sell', '38376.60', '0.00000000']], 'time': '2021-05-20T03:55:57.796446Z'}
{'type': 'l2update', 'product_id': 'BTC-USD', 'changes': [['buy', '38334.26', '0.00000000']], 'time': '2021-05-20T03:55:57.796866Z'}
{'type': 'l2update', 'product_id': 'BTC-USD', 'changes': [['sell', '38334.26', '0.19992518']], 'time': '2021-05-20T03:55:57.796866Z'}
{'type': 'l2update', 'product_id': 'BTC-USD', 'changes': [['sell', '38389.46', '0.33521284']], 'time': '2021-05-20T03:55:57.797914Z'}
{'type': 'l2update', 'product_id': 'BTC-USD', 'changes': [['buy', '38300.48', '0.00000000']], 'time': '2021-05-20T03:55:57.800108Z'}
{'type': 'l2update', 'product_id': 'BTC-USD', 'changes': [['buy', '38310.60', '0.00000000']], 'time': '2021-05-20T03:55:57.806650Z'}
{'type': 'l2update', 'product_id': 'BTC-USD', 'changes': [['buy', '38272.28', '0.00000000']], 'time': '2021-05-20T03:55:57.807029Z'}
{'type': 'l2update', 'product_id': 'BTC-USD', 'changes': [['buy', '38314.65', '0.00000000']], 'time': '2021-05-20T03:55:57.807324Z'}
{'type': 'l2update', 'product_id': 'BTC-USD', 'changes': [['sell', '38427.05', '0.00000000']], 'time': '2021-05-20T03:55:57.807353Z'}
{'type': 'l2update', 'product_id': 'BTC-USD', 'changes': [['sell', '38524.96', '0.00000000']], 'time': '2021-05-20T03:55:57.809220Z'}
{'type': 'l2update', 'product_id': 'BTC-USD', 'changes': [['buy', '38316.94', '0.07460000']], 'time': '2021-05-20T03:55:57.810317Z'}
{'type': 'l2update', 'product_id': 'BTC-USD', 'changes': [['buy', '38326.52', '0.04976866']], 'time': '2021-05-20T03:55:57.810454Z'}
{'type': 'l2update', 'product_id': 'BTC-USD', 'changes': [['buy', '38306.68', '0.00000000']], 'time': '2021-05-20T03:55:57.810874Z'}
{'type': 'l2update', 'product_id': 'BTC-USD', 'changes': [['sell', '38334.27', '0.49964582']], 'time': '2021-05-20T03:55:57.810940Z'}
{'type': 'l2update', 'product_id': 'BTC-USD', 'changes': [['sell', '38334.27', '1.87997445']], 'time': '2021-05-20T03:55:57.811268Z'}
{'type': 'l2update', 'product_id': 'BTC-USD', 'changes': [['sell', '38372.33', '0.00000000']], 'time': '2021-05-20T03:55:57.813722Z'}
{'type': 'l2update', 'product_id': 'BTC-USD', 'changes': [['buy', '38310.60', '0.84600000']], 'time': '2021-05-20T03:55:57.814894Z'}
{'type': 'l2update', 'product_id': 'BTC-USD', 'changes': [['buy', '38200.49', '0.01000000']], 'time': '2021-05-20T03:55:57.815105Z'}
{'type': 'l2update', 'product_id': 'BTC-USD', 'changes': [['sell', '38336.99', '0.00000000']], 'time': '2021-05-20T03:55:57.816716Z'}
{'type': 'l2update', 'product_id': 'BTC-USD', 'changes': [['sell', '38368.24', '0.02000000']], 'time': '2021-05-20T03:55:57.819735Z'}
{'type': 'l2update', 'product_id': 'BTC-USD', 'changes': [['sell', '38365.21', '0.00000000']], 'time': '2021-05-20T03:55:57.819798Z'}
{'type': 'l2update', 'product_id': 'BTC-USD', 'changes': [['buy', '38316.94', '0.00000000']], 'time': '2021-05-20T03:55:57.825350Z'}
{'type': 'l2update', 'product_id': 'BTC-USD', 'changes': [['buy', '38314.67', '0.99440510']], 'time': '2021-05-20T03:55:57.825620Z'}
{'type': 'l2update', 'product_id': 'BTC-USD', 'changes': [['sell', '38358.07', '0.04808415']], 'time': '2021-05-20T03:55:57.825660Z'}
{'type': 'l2update', 'product_id': 'BTC-USD', 'changes': [['buy', '38317.02', '0.01492000']], 'time': '2021-05-20T03:55:57.825708Z'}
{'type': 'l2update', 'product_id': 'BTC-USD', 'changes': [['sell', '38334.00', '0.01492000']], 'time': '2021-05-20T03:55:57.825916Z'}
{'type': 'l2update', 'product_id': 'BTC-USD', 'changes': [['buy', '38167.02', '0.00000000']], 'time': '2021-05-20T03:55:57.826527Z'}
{'type': 'l2update', 'product_id': 'BTC-USD', 'changes': [['buy', '37529.32', '0.06403807']], 'time': '2021-05-20T03:55:57.829938Z'}
{'type': 'l2update', 'product_id': 'BTC-USD', 'changes': [['sell', '38334.27', '2.06297445']], 'time': '2021-05-20T03:55:57.830684Z'}
{'type': 'l2update', 'product_id': 'BTC-USD', 'changes': [['buy', '38326.52', '0.00000000']], 'time': '2021-05-20T03:55:57.830717Z'}
{'type': 'l2update', 'product_id': 'BTC-USD', 'changes': [['sell', '38336.98', '1.19907335']], 'time': '2021-05-20T03:55:57.833976Z'}
{'type': 'l2update', 'product_id': 'BTC-USD', 'changes': [['sell', '38408.62', '0.00000000']], 'time': '2021-05-20T03:55:57.834567Z'}
{'type': 'l2update', 'product_id': 'BTC-USD', 'changes': [['sell', '38389.46', '0.00000000']], 'time': '2021-05-20T03:55:57.834567Z'}
{'type': 'l2update', 'product_id': 'BTC-USD', 'changes': [['sell', '38378.61', '0.00000000']], 'time': '2021-05-20T03:55:57.834567Z'}
{'type': 'l2update', 'product_id': 'BTC-USD', 'changes': [['buy', '38300.35', '0.42630000']], 'time': '2021-05-20T03:55:57.835949Z'}
{'type': 'l2update', 'product_id': 'BTC-USD', 'changes': [['sell', '38489.91', '0.30082770']], 'time': '2021-05-20T03:55:57.836064Z'}
{'type': 'l2update', 'product_id': 'BTC-USD', 'changes': [['buy', '38283.61', '0.01000000']], 'time': '2021-05-20T03:55:57.836242Z'}
{'type': 'l2update', 'product_id': 'BTC-USD', 'changes': [['sell', '38333.63', '0.04983500']], 'time': '2021-05-20T03:55:57.836511Z'}
{'type': 'l2update', 'product_id': 'BTC-USD', 'changes': [['sell', '38333.87', '0.07460000']], 'time': '2021-05-20T03:55:57.836699Z'}
{'type': 'l2update', 'product_id': 'BTC-USD', 'changes': [['sell', '38366.77', '0.01113434']], 'time': '2021-05-20T03:55:57.836720Z'}
{'type': 'l2update', 'product_id': 'BTC-USD', 'changes': [['sell', '38334.26', '0.20565518']], 'time': '2021-05-20T03:55:57.836768Z'}
{'type': 'l2update', 'product_id': 'BTC-USD', 'changes': [['sell', '38359.01', '0.39490432']], 'time': '2021-05-20T03:55:57.836783Z'}
{'type': 'l2update', 'product_id': 'BTC-USD', 'changes': [['sell', '38512.32', '0.01000000']], 'time': '2021-05-20T03:55:57.837134Z'}
{'type': 'l2update', 'product_id': 'BTC-USD', 'changes': [['buy', '38310.54', '0.00000000']], 'time': '2021-05-20T03:55:57.837288Z'}
{'type': 'l2update', 'product_id': 'BTC-USD', 'changes': [['buy', '38200.49', '0.00000000']], 'time': '2021-05-20T03:55:57.839564Z'}
{'type': 'l2update', 'product_id': 'BTC-USD', 'changes': [['buy', '38279.11', '0.00000000']], 'time': '2021-05-20T03:55:57.839945Z'}
{'type': 'l2update', 'product_id': 'BTC-USD', 'changes': [['buy', '38310.60', '0.00000000']], 'time': '2021-05-20T03:55:57.840353Z'}
{'type': 'l2update', 'product_id': 'BTC-USD', 'changes': [['sell', '38401.72', '0.00000000']], 'time': '2021-05-20T03:55:57.841853Z'}
{'type': 'l2update', 'product_id': 'BTC-USD', 'changes': [['sell', '38368.24', '0.05000000']], 'time': '2021-05-20T03:55:57.842728Z'}
{'type': 'l2update', 'product_id': 'BTC-USD', 'changes': [['buy', '38300.82', '0.02400000']], 'time': '2021-05-20T03:55:57.843100Z'}
{'type': 'l2update', 'product_id': 'BTC-USD', 'changes': [['buy', '38300.01', '0.02400000']], 'time': '2021-05-20T03:55:57.843100Z'}
{'type': 'l2update', 'product_id': 'BTC-USD', 'changes': [['buy', '38299.21', '0.02400000']], 'time': '2021-05-20T03:55:57.843100Z'}
{'type': 'l2update', 'product_id': 'BTC-USD', 'changes': [['sell', '38608.01', '0.00000000']], 'time': '2021-05-20T03:55:57.843655Z'}
{'type': 'l2update', 'product_id': 'BTC-USD', 'changes': [['sell', '38334.00', '0.00000000']], 'time': '2021-05-20T03:55:57.844092Z'}
{'type': 'l2update', 'product_id': 'BTC-USD', 'changes': [['buy', '38317.02', '0.00000000']], 'time': '2021-05-20T03:55:57.844323Z'}
{'type': 'l2update', 'product_id': 'BTC-USD', 'changes': [['sell', '38334.26', '0.00573000']], 'time': '2021-05-20T03:55:57.844921Z'}
{'type': 'l2update', 'product_id': 'BTC-USD', 'changes': [['buy', '38314.67', '0.00000000']], 'time': '2021-05-20T03:55:57.845008Z'}
{'type': 'l2update', 'product_id': 'BTC-USD', 'changes': [['sell', '38341.86', '0.05000000']], 'time': '2021-05-20T03:55:57.848494Z'}
{'type': 'l2update', 'product_id': 'BTC-USD', 'changes': [['sell', '38428.09', '0.02938800']], 'time': '2021-05-20T03:55:57.848688Z'}
{'type': 'l2update', 'product_id': 'BTC-USD', 'changes': [['sell', '38334.27', '0.68264582']], 'time': '2021-05-20T03:55:57.850500Z'}
{'type': 'l2update', 'product_id': 'BTC-USD', 'changes': [['buy', '38300.35', '0.00000000']], 'time': '2021-05-20T03:55:57.850857Z'}
{'type': 'l2update', 'product_id': 'BTC-USD', 'changes': [['sell', '38344.09', '0.00000000']], 'time': '2021-05-20T03:55:57.852502Z'}
{'type': 'l2update', 'product_id': 'BTC-USD', 'changes': [['sell', '38333.63', '0.04471627']], 'time': '2021-05-20T03:55:57.853401Z'}
{'type': 'l2update', 'product_id': 'BTC-USD', 'changes': [['buy', '38316.39', '0.00000000']], 'time': '2021-05-20T03:55:57.853723Z'}
{'type': 'l2update', 'product_id': 'BTC-USD', 'changes': [['sell', '38333.87', '0.00000000']], 'time': '2021-05-20T03:55:57.854507Z'}
{'type': 'l2update', 'product_id': 'BTC-USD', 'changes': [['sell', '38334.25', '0.18981474']], 'time': '2021-05-20T03:55:57.855030Z'}
{'type': 'l2update', 'product_id': 'BTC-USD', 'changes': [['buy', '38317.59', '0.07460000']], 'time': '2021-05-20T03:55:57.855192Z'}
{'type': 'l2update', 'product_id': 'BTC-USD', 'changes': [['sell', '38334.27', '0.67691582']], 'time': '2021-05-20T03:55:57.855482Z'}
{'type': 'l2update', 'product_id': 'BTC-USD', 'changes': [['sell', '38416.93', '0.00000000']], 'time': '2021-05-20T03:55:57.856011Z'}
{'type': 'l2update', 'product_id': 'BTC-USD', 'changes': [['sell', '38391.28', '0.00000000']], 'time': '2021-05-20T03:55:57.856011Z'}
{'type': 'l2update', 'product_id': 'BTC-USD', 'changes': [['sell', '38384.35', '0.00000000']], 'time': '2021-05-20T03:55:57.856011Z'}
{'type': 'l2update', 'product_id': 'BTC-USD', 'changes': [['sell', '38380.66', '0.00000000']], 'time': '2021-05-20T03:55:57.856011Z'}
{'type': 'l2update', 'product_id': 'BTC-USD', 'changes': [['buy', '38294.01', '0.00000000']], 'time': '2021-05-20T03:55:57.856011Z'}
{'type': 'l2update', 'product_id': 'BTC-USD', 'changes': [['sell', '38489.91', '0.00000000']], 'time': '2021-05-20T03:55:57.857812Z'}
{'type': 'l2update', 'product_id': 'BTC-USD', 'changes': [['sell', '38377.79', '0.00000000']], 'time': '2021-05-20T03:55:57.858072Z'}
{'type': 'l2update', 'product_id': 'BTC-USD', 'changes': [['sell', '38549.75', '0.00000000']], 'time': '2021-05-20T03:55:57.860100Z'}
{'type': 'l2update', 'product_id': 'BTC-USD', 'changes': [['sell', '38374.62', '0.00000000']], 'time': '2021-05-20T03:55:57.861083Z'}
{'type': 'l2update', 'product_id': 'BTC-USD', 'changes': [['sell', '38352.31', '0.00000000']], 'time': '2021-05-20T03:55:57.862687Z'}
{'type': 'l2update', 'product_id': 'BTC-USD', 'changes': [['buy', '38300.82', '0.00000000']], 'time': '2021-05-20T03:55:57.864447Z'}
{'type': 'l2update', 'product_id': 'BTC-USD', 'changes': [['buy', '38283.61', '0.00000000']], 'time': '2021-05-20T03:55:57.865846Z'}
{'type': 'l2update', 'product_id': 'BTC-USD', 'changes': [['sell', '38341.86', '0.00000000']], 'time': '2021-05-20T03:55:57.867127Z'}
{'type': 'l2update', 'product_id': 'BTC-USD', 'changes': [['buy', '38138.91', '0.00000000']], 'time': '2021-05-20T03:55:57.868385Z'}
{'type': 'l2update', 'product_id': 'BTC-USD', 'changes': [['buy', '38241.71', '0.01000000']], 'time': '2021-05-20T03:55:57.870871Z'}
{'type': 'l2update', 'product_id': 'BTC-USD', 'changes': [['buy', '38319.51', '0.05074074']], 'time': '2021-05-20T03:55:57.871407Z'}
{'type': 'l2update', 'product_id': 'BTC-USD', 'changes': [['sell', '38342.97', '0.00000000']], 'time': '2021-05-20T03:55:57.872553Z'}
{'type': 'l2update', 'product_id': 'BTC-USD', 'changes': [['sell', '38341.92', '0.00000000']], 'time': '2021-05-20T03:55:57.875245Z'}
{'type': 'l2update', 'product_id': 'BTC-USD', 'changes': [['buy', '37529.32', '0.00000000']], 'time': '2021-05-20T03:55:57.875628Z'}
{'type': 'l2update', 'product_id': 'BTC-USD', 'changes': [['sell', '38337.05', '0.00000000']], 'time': '2021-05-20T03:55:57.875871Z'}
{'type': 'l2update', 'product_id': 'BTC-USD', 'changes': [['sell', '38334.26', '0.00000000']], 'time': '2021-05-20T03:55:57.876352Z'}
{'type': 'l2update', 'product_id': 'BTC-USD', 'changes': [['buy', '38317.59', '0.00000000']], 'time': '2021-05-20T03:55:57.878219Z'}
{'type': 'l2update', 'product_id': 'BTC-USD', 'changes': [['sell', '38359.03', '0.15535761']], 'time': '2021-05-20T03:55:57.880781Z'}
{'type': 'l2update', 'product_id': 'BTC-USD', 'changes': [['sell', '38353.12', '0.44210000']], 'time': '2021-05-20T03:55:57.881515Z'}
{'type': 'l2update', 'product_id': 'BTC-USD', 'changes': [['buy', '38316.83', '0.00444677']], 'time': '2021-05-20T03:55:57.881570Z'}
{'type': 'l2update', 'product_id': 'BTC-USD', 'changes': [['sell', '38334.25', '1.50042980']], 'time': '2021-05-20T03:55:57.881899Z'}
{'type': 'l2update', 'product_id': 'BTC-USD', 'changes': [['buy', '38300.01', '0.00000000']], 'time': '2021-05-20T03:55:57.883605Z'}
{'type': 'l2update', 'product_id': 'BTC-USD', 'changes': [['buy', '38299.21', '0.00000000']], 'time': '2021-05-20T03:55:57.883605Z'}
{'type': 'l2update', 'product_id': 'BTC-USD', 'changes': [['sell', '38428.54', '0.03683089']], 'time': '2021-05-20T03:55:57.883713Z'}
{'type': 'l2update', 'product_id': 'BTC-USD', 'changes': [['sell', '38406.10', '0.00000000']], 'time': '2021-05-20T03:55:57.883713Z'}
{'type': 'l2update', 'product_id': 'BTC-USD', 'changes': [['buy', '38289.84', '0.00000000']], 'time': '2021-05-20T03:55:57.883713Z'}
{'type': 'l2update', 'product_id': 'BTC-USD', 'changes': [['buy', '38317.91', '0.00315085']], 'time': '2021-05-20T03:55:57.887408Z'}
{'type': 'l2update', 'product_id': 'BTC-USD', 'changes': [['buy', '38238.59', '0.00653789']], 'time': '2021-05-20T03:55:57.887515Z'}
{'type': 'l2update', 'product_id': 'BTC-USD', 'changes': [['buy', '38307.14', '0.84700000']], 'time': '2021-05-20T03:55:57.887960Z'}
{'type': 'l2update', 'product_id': 'BTC-USD', 'changes': [['buy', '38316.41', '0.00000000']], 'time': '2021-05-20T03:55:57.891239Z'}
{'type': 'l2update', 'product_id': 'BTC-USD', 'changes': [['sell', '38368.24', '0.09000000']], 'time': '2021-05-20T03:55:57.891850Z'}
{'type': 'l2update', 'product_id': 'BTC-USD', 'changes': [['buy', '38310.55', '0.08934127']], 'time': '2021-05-20T03:55:57.892120Z'}
{'type': 'l2update', 'product_id': 'BTC-USD', 'changes': [['sell', '38352.32', '0.12079383']], 'time': '2021-05-20T03:55:57.893476Z'}
{'type': 'l2update', 'product_id': 'BTC-USD', 'changes': [['buy', '38117.50', '0.01000000']], 'time': '2021-05-20T03:55:57.893700Z'}
{'type': 'l2update', 'product_id': 'BTC-USD', 'changes': [['sell', '38329.14', '0.52197364']], 'time': '2021-05-20T03:55:57.893723Z'}
{'type': 'l2update', 'product_id': 'BTC-USD', 'changes': [['sell', '38347.69', '0.06323880']], 'time': '2021-05-20T03:55:57.893847Z'}
{'type': 'l2update', 'product_id': 'BTC-USD', 'changes': [['buy', '38306.08', '0.00000000']], 'time': '2021-05-20T03:55:57.897725Z'}
{'type': 'l2update', 'product_id': 'BTC-USD', 'changes': [['sell', '38469.32', '0.42765348']], 'time': '2021-05-20T03:55:57.898294Z'}
{'type': 'l2update', 'product_id': 'BTC-USD', 'changes': [['sell', '38469.32', '0.00000000']], 'time': '2021-05-20T03:55:57.898294Z'}
{'type': 'l2update', 'product_id': 'BTC-USD', 'changes': [['sell', '38461.89', '0.00000000']], 'time': '2021-05-20T03:55:57.898294Z'}
{'type': 'l2update', 'product_id': 'BTC-USD', 'changes': [['sell', '38444.77', '0.00000000']], 'time': '2021-05-20T03:55:57.898294Z'}
{'type': 'l2update', 'product_id': 'BTC-USD', 'changes': [['sell', '38435.64', '0.32595503']], 'time': '2021-05-20T03:55:57.898294Z'}
{'type': 'l2update', 'product_id': 'BTC-USD', 'changes': [['sell', '38435.64', '0.00000000']], 'time': '2021-05-20T03:55:57.898294Z'}
{'type': 'l2update', 'product_id': 'BTC-USD', 'changes': [['sell', '38428.60', '0.00000000']], 'time': '2021-05-20T03:55:57.898294Z'}
{'type': 'l2update', 'product_id': 'BTC-USD', 'changes': [['sell', '38421.74', '0.00000000']], 'time': '2021-05-20T03:55:57.898294Z'}
{'type': 'l2update', 'product_id': 'BTC-USD', 'changes': [['sell', '38396.28', '0.00000000']], 'time': '2021-05-20T03:55:57.898294Z'}
{'type': 'l2update', 'product_id': 'BTC-USD', 'changes': [['sell', '38369.99', '0.00000000']], 'time': '2021-05-20T03:55:57.898294Z'}
{'type': 'l2update', 'product_id': 'BTC-USD', 'changes': [['sell', '38334.26', '0.35000000']], 'time': '2021-05-20T03:55:57.898397Z'}
{'type': 'l2update', 'product_id': 'BTC-USD', 'changes': [['sell', '38401.19', '0.18380000']], 'time': '2021-05-20T03:55:57.898512Z'}
{'type': 'l2update', 'product_id': 'BTC-USD', 'changes': [['sell', '38333.62', '0.50000000']], 'time': '2021-05-20T03:55:57.906596Z'}
{'type': 'l2update', 'product_id': 'BTC-USD', 'changes': [['sell', '38332.95', '0.07460000']], 'time': '2021-05-20T03:55:57.907474Z'}
{'type': 'l2update', 'product_id': 'BTC-USD', 'changes': [['buy', '38310.56', '0.99440510']], 'time': '2021-05-20T03:55:57.907521Z'}
{'type': 'l2update', 'product_id': 'BTC-USD', 'changes': [['sell', '38594.92', '0.12955075']], 'time': '2021-05-20T03:55:57.908068Z'}
{'type': 'l2update', 'product_id': 'BTC-USD', 'changes': [['sell', '38353.12', '0.00000000']], 'time': '2021-05-20T03:55:57.913003Z'}
{'type': 'l2update', 'product_id': 'BTC-USD', 'changes': [['buy', '38293.62', '0.00000000']], 'time': '2021-05-20T03:55:57.913839Z'}
{'type': 'l2update', 'product_id': 'BTC-USD', 'changes': [['sell', '38352.32', '0.07079383']], 'time': '2021-05-20T03:55:57.914968Z'}
{'type': 'l2update', 'product_id': 'BTC-USD', 'changes': [['sell', '38333.21', '0.01492000']], 'time': '2021-05-20T03:55:57.917684Z'}
{'type': 'l2update', 'product_id': 'BTC-USD', 'changes': [['buy', '38326.53', '0.07154422']], 'time': '2021-05-20T03:55:57.917713Z'}
{'type': 'l2update', 'product_id': 'BTC-USD', 'changes': [['sell', '38512.32', '0.00000000']], 'time': '2021-05-20T03:55:57.918812Z'}
{'type': 'l2update', 'product_id': 'BTC-USD', 'changes': [['buy', '38307.14', '0.00000000']], 'time': '2021-05-20T03:55:57.919008Z'}
{'type': 'l2update', 'product_id': 'BTC-USD', 'changes': [['sell', '38335.37', '0.00600000']], 'time': '2021-05-20T03:55:57.919073Z'}
{'type': 'l2update', 'product_id': 'BTC-USD', 'changes': [['sell', '38460.89', '0.00000000']], 'time': '2021-05-20T03:55:57.923229Z'}
{'type': 'l2update', 'product_id': 'BTC-USD', 'changes': [['sell', '38454.04', '0.00000000']], 'time': '2021-05-20T03:55:57.923229Z'}
{'type': 'l2update', 'product_id': 'BTC-USD', 'changes': [['sell', '38447.38', '0.00000000']], 'time': '2021-05-20T03:55:57.923229Z'}
{'type': 'l2update', 'product_id': 'BTC-USD', 'changes': [['sell', '38434.63', '0.00000000']], 'time': '2021-05-20T03:55:57.923229Z'}
{'type': 'l2update', 'product_id': 'BTC-USD', 'changes': [['sell', '38428.54', '0.00000000']], 'time': '2021-05-20T03:55:57.923229Z'}
{'type': 'l2update', 'product_id': 'BTC-USD', 'changes': [['sell', '38396.03', '0.00000000']], 'time': '2021-05-20T03:55:57.923229Z'}
{'type': 'l2update', 'product_id': 'BTC-USD', 'changes': [['buy', '38320.02', '0.00315085']], 'time': '2021-05-20T03:55:57.923592Z'}
{'type': 'l2update', 'product_id': 'BTC-USD', 'changes': [['buy', '38316.10', '0.04341146']], 'time': '2021-05-20T03:55:57.923834Z'}
{'type': 'l2update', 'product_id': 'BTC-USD', 'changes': [['sell', '38568.14', '0.01000000']], 'time': '2021-05-20T03:55:57.924466Z'}
{'type': 'l2update', 'product_id': 'BTC-USD', 'changes': [['sell', '38333.62', '1.79667235']], 'time': '2021-05-20T03:55:57.924684Z'}
{'type': 'l2update', 'product_id': 'BTC-USD', 'changes': [['sell', '38332.95', '0.00000000']], 'time': '2021-05-20T03:55:57.928133Z'}
{'type': 'l2update', 'product_id': 'BTC-USD', 'changes': [['buy', '38303.67', '0.52191956']], 'time': '2021-05-20T03:55:57.928314Z'}
{'type': 'l2update', 'product_id': 'BTC-USD', 'changes': [['sell', '38334.25', '1.31061506']], 'time': '2021-05-20T03:55:57.928596Z'}
{'type': 'l2update', 'product_id': 'BTC-USD', 'changes': [['sell', '38604.68', '0.00000000']], 'time': '2021-05-20T03:55:57.931164Z'}
{'type': 'l2update', 'product_id': 'BTC-USD', 'changes': [['buy', '38292.42', '0.00000000']], 'time': '2021-05-20T03:55:57.931385Z'}
{'type': 'l2update', 'product_id': 'BTC-USD', 'changes': [['buy', '38307.15', '0.40135082']], 'time': '2021-05-20T03:55:57.934831Z'}
{'type': 'l2update', 'product_id': 'BTC-USD', 'changes': [['buy', '37525.42', '0.06791242']], 'time': '2021-05-20T03:55:57.935849Z'}
{'type': 'l2update', 'product_id': 'BTC-USD', 'changes': [['buy', '38316.83', '0.00000000']], 'time': '2021-05-20T03:55:57.937051Z'}
{'type': 'l2update', 'product_id': 'BTC-USD', 'changes': [['sell', '38333.62', '4.28637143']], 'time': '2021-05-20T03:55:57.937123Z'}
{'type': 'l2update', 'product_id': 'BTC-USD', 'changes': [['buy', '37544.84', '0.02090000']], 'time': '2021-05-20T03:55:57.937260Z'}
{'type': 'l2update', 'product_id': 'BTC-USD', 'changes': [['buy', '36899.32', '0.02960000']], 'time': '2021-05-20T03:55:57.937260Z'}
{'type': 'l2update', 'product_id': 'BTC-USD', 'changes': [['sell', '38453.80', '0.00000000']], 'time': '2021-05-20T03:55:57.938794Z'}
{'type': 'l2update', 'product_id': 'BTC-USD', 'changes': [['sell', '38334.27', '0.64691582']], 'time': '2021-05-20T03:55:57.938921Z'}
{'type': 'l2update', 'product_id': 'BTC-USD', 'changes': [['sell', '38411.53', '0.00000000']], 'time': '2021-05-20T03:55:57.940219Z'}
{'type': 'l2update', 'product_id': 'BTC-USD', 'changes': [['buy', '38314.66', '0.00000000']], 'time': '2021-05-20T03:55:57.940253Z'}
{'type': 'l2update', 'product_id': 'BTC-USD', 'changes': [['buy', '38320.02', '0.00000000']], 'time': '2021-05-20T03:55:57.940479Z'}
{'type': 'l2update', 'product_id': 'BTC-USD', 'changes': [['buy', '38294.11', '0.02400000']], 'time': '2021-05-20T03:55:57.943559Z'}
{'type': 'l2update', 'product_id': 'BTC-USD', 'changes': [['buy', '38293.31', '0.02400000']], 'time': '2021-05-20T03:55:57.943559Z'}
{'type': 'l2update', 'product_id': 'BTC-USD', 'changes': [['buy', '38292.50', '0.02400000']], 'time': '2021-05-20T03:55:57.943559Z'}
{'type': 'l2update', 'product_id': 'BTC-USD', 'changes': [['sell', '38326.54', '0.20000000']], 'time': '2021-05-20T03:55:57.943667Z'}
{'type': 'l2update', 'product_id': 'BTC-USD', 'changes': [['sell', '38327.22', '0.03000000']], 'time': '2021-05-20T03:55:57.943830Z'}
