{'type': 'l2update', 'product_id': 'BTC-USD', 'changes': [['buy', '38274.83', '0.02612683']], 'time': '2021-05-20T03:56:01.509586Z'}
{'type': 'l2update', 'product_id': 'BTC-USD', 'changes': [['sell', '38455.51', '0.00000000']], 'time': '2021-05-20T03:56:01.512869Z'}
{'type': 'l2update', 'product_id': 'BTC-USD', 'changes': [['buy', '38314.72', '0.40135082']], 'time': '2021-05-20T03:56:01.515738Z'}
{'type': 'l2update', 'product_id': 'BTC-USD', 'changes': [['sell', '38337.68', '0.07460000']], 'time': '2021-05-20T03:56:01.516281Z'}
{'type': 'l2update', 'product_id': 'BTC-USD', 'changes': [['sell', '38337.49', '0.01492000']], 'time': '2021-05-20T03:56:01.517192Z'}
{'type': 'l2update', 'product_id': 'BTC-USD', 'changes': [['sell', '38342.88', '1.25720417']], 'time': '2021-05-20T03:56:01.520569Z'}
{'type': 'l2update', 'product_id': 'BTC-USD', 'changes': [['sell', '38445.04', '0.01000000']], 'time': '2021-05-20T03:56:01.521015Z'}
{'type': 'l2update', 'product_id': 'BTC-USD', 'changes': [['buy', '38327.64', '0.00000000']], 'time': '2021-05-20T03:56:01.521920Z'}
{'type': 'l2update', 'product_id': 'BTC-USD', 'changes': [['sell', '38426.41', '0.03118982']], 'time': '2021-05-20T03:56:01.522045Z'}
{'type': 'l2update', 'product_id': 'BTC-USD', 'changes': [['sell', '38419.74', '0.00000000']], 'time': '2021-05-20T03:56:01.522045Z'}
{'type': 'l2update', 'product_id': 'BTC-USD', 'changes': [['sell', '38407.00', '0.03217755']], 'time': '2021-05-20T03:56:01.522045Z'}
{'type': 'l2update', 'product_id': 'BTC-USD', 'changes': [['sell', '38400.92', '0.03355073']], 'time': '2021-05-20T03:56:01.522045Z'}
{'type': 'l2update', 'product_id': 'BTC-USD', 'changes': [['sell', '38395.03', '0.00000000']], 'time': '2021-05-20T03:56:01.522045Z'}
{'type': 'l2update', 'product_id': 'BTC-USD', 'changes': [['buy', '38295.46', '0.00000000']], 'time': '2021-05-20T03:56:01.522188Z'}
{'type': 'l2update', 'product_id': 'BTC-USD', 'changes': [['buy', '38240.23', '0.00000000']], 'time': '2021-05-20T03:56:01.522647Z'}
{'type': 'l2update', 'product_id': 'BTC-USD', 'changes': [['sell', '38418.52', '1.20000000']], 'time': '2021-05-20T03:56:01.527995Z'}
{'type': 'l2update', 'product_id': 'BTC-USD', 'changes': [['sell', '38395.51', '0.22300000']], 'time': '2021-05-20T03:56:01.528148Z'}
{'type': 'l2update', 'product_id': 'BTC-USD', 'changes': [['buy', '38320.02', '0.46000000']], 'time': '2021-05-20T03:56:01.528479Z'}
{'type': 'l2update', 'product_id': 'BTC-USD', 'changes': [['sell', '38338.02', '0.00000000']], 'time': '2021-05-20T03:56:01.530079Z'}
{'type': 'l2update', 'product_id': 'BTC-USD', 'changes': [['sell', '38408.82', '0.00000000']], 'time': '2021-05-20T03:56:01.531613Z'}
{'type': 'l2update', 'product_id': 'BTC-USD', 'changes': [['sell', '38337.68', '0.00000000']], 'time': '2021-05-20T03:56:01.532439Z'}
{'type': 'l2update', 'product_id': 'BTC-USD', 'changes': [['sell', '38369.80', '0.03000000']], 'time': '2021-05-20T03:56:01.535148Z'}
{'type': 'l2update', 'product_id': 'BTC-USD', 'changes': [['buy', '38327.08', '0.07460000']], 'time': '2021-05-20T03:56:01.535455Z'}
{'type': 'l2update', 'product_id': 'BTC-USD', 'changes': [['buy', '38224.22', '0.03619226']], 'time': '2021-05-20T03:56:01.535718Z'}
{'type': 'l2update', 'product_id': 'BTC-USD', 'changes': [['buy', '38295.18', '0.01375906']], 'time': '2021-05-20T03:56:01.535718Z'}
{'type': 'l2update', 'product_id': 'BTC-USD', 'changes': [['buy', '38300.06', '0.00000000']], 'time': '2021-05-20T03:56:01.539309Z'}
{'type': 'l2update', 'product_id': 'BTC-USD', 'changes': [['buy', '38294.30', '0.00000000']], 'time': '2021-05-20T03:56:01.539489Z'}
{'type': 'l2update', 'product_id': 'BTC-USD', 'changes': [['sell', '38343.51', '0.00600000']], 'time': '2021-05-20T03:56:01.539859Z'}
{'type': 'l2update', 'product_id': 'BTC-USD', 'changes': [['sell', '38375.77', '0.03207306']], 'time': '2021-05-20T03:56:01.540978Z'}
{'type': 'l2update', 'product_id': 'BTC-USD', 'changes': [['buy', '38314.71', '0.52100000']], 'time': '2021-05-20T03:56:01.543851Z'}
{'type': 'l2update', 'product_id': 'BTC-USD', 'changes': [['buy', '38306.73', '0.00000000']], 'time': '2021-05-20T03:56:01.545208Z'}
{'type': 'l2update', 'product_id': 'BTC-USD', 'changes': [['sell', '38510.51', '0.30081122']], 'time': '2021-05-20T03:56:01.548070Z'}
{'type': 'l2update', 'product_id': 'BTC-USD', 'changes': [['buy', '38307.91', '0.99440510']], 'time': '2021-05-20T03:56:01.549078Z'}
{'type': 'l2update', 'product_id': 'BTC-USD', 'changes': [['buy', '38300.05', '0.52000000']], 'time': '2021-05-20T03:56:01.549412Z'}
{'type': 'l2update', 'product_id': 'BTC-USD', 'changes': [['sell', '38400.92', '0.00000000']], 'time': '2021-05-20T03:56:01.549443Z'}
{'type': 'l2update', 'product_id': 'BTC-USD', 'changes': [['buy', '38280.18', '0.01168938']], 'time': '2021-05-20T03:56:01.549443Z'}
{'type': 'l2update', 'product_id': 'BTC-USD', 'changes': [['buy', '38300.05', '0.00000000']], 'time': '2021-05-20T03:56:01.550042Z'}
{'type': 'l2update', 'product_id': 'BTC-USD', 'changes': [['sell', '38368.07', '0.00000000']], 'time': '2021-05-20T03:56:01.550445Z'}
{'type': 'l2update', 'product_id': 'BTC-USD', 'changes': [['buy', '38238.80', '0.00000000']], 'time': '2021-05-20T03:56:01.551313Z'}
{'type': 'l2update', 'product_id': 'BTC-USD', 'changes': [['sell', '38342.88', '1.75720417']], 'time': '2021-05-20T03:56:01.551876Z'}
{'type': 'l2update', 'product_id': 'BTC-USD', 'changes': [['sell', '38469.52', '0.00000000']], 'time': '2021-05-20T03:56:01.552208Z'}
{'type': 'l2update', 'product_id': 'BTC-USD', 'changes': [['sell', '38369.81', '0.04000000']], 'time': '2021-05-20T03:56:01.552399Z'}
{'type': 'l2update', 'product_id': 'BTC-USD', 'changes': [['sell', '38474.41', '0.01000000']], 'time': '2021-05-20T03:56:01.552706Z'}
{'type': 'l2update', 'product_id': 'BTC-USD', 'changes': [['buy', '38307.90', '0.00000000']], 'time': '2021-05-20T03:56:01.555255Z'}
{'type': 'l2update', 'product_id': 'BTC-USD', 'changes': [['sell', '38337.01', '0.07460000']], 'time': '2021-05-20T03:56:01.559068Z'}
{'type': 'l2update', 'product_id': 'BTC-USD', 'changes': [['sell', '38549.87', '0.00000000']], 'time': '2021-05-20T03:56:01.559536Z'}
{'type': 'l2update', 'product_id': 'BTC-USD', 'changes': [['sell', '38338.01', '0.00000000']], 'time': '2021-05-20T03:56:01.565342Z'}
{'type': 'l2update', 'product_id': 'BTC-USD', 'changes': [['sell', '38342.89', '0.00000000']], 'time': '2021-05-20T03:56:01.565480Z'}
{'type': 'l2update', 'product_id': 'BTC-USD', 'changes': [['buy', '38307.88', '0.00000000']], 'time': '2021-05-20T03:56:01.565551Z'}
{'type': 'l2update', 'product_id': 'BTC-USD', 'changes': [['sell', '38407.00', '0.00000000']], 'time': '2021-05-20T03:56:01.565585Z'}
{'type': 'l2update', 'product_id': 'BTC-USD', 'changes': [['sell', '38474.69', '0.00000000']], 'time': '2021-05-20T03:56:01.565964Z'}
{'type': 'l2update', 'product_id': 'BTC-USD', 'changes': [['buy', '38251.41', '0.00000000']], 'time': '2021-05-20T03:56:01.566021Z'}
{'type': 'l2update', 'product_id': 'BTC-USD', 'changes': [['buy', '38314.71', '0.00000000']], 'time': '2021-05-20T03:56:01.567111Z'}
{'type': 'l2update', 'product_id': 'BTC-USD', 'changes': [['sell', '38349.42', '0.00000000']], 'time': '2021-05-20T03:56:01.567586Z'}
{'type': 'l2update', 'product_id': 'BTC-USD', 'changes': [['sell', '38344.95', '0.00000000']], 'time': '2021-05-20T03:56:01.572637Z'}
{'type': 'l2update', 'product_id': 'BTC-USD', 'changes': [['sell', '38433.59', '0.01000000']], 'time': '2021-05-20T03:56:01.575603Z'}
{'type': 'l2update', 'product_id': 'BTC-USD', 'changes': [['sell', '38510.51', '0.00000000']], 'time': '2021-05-20T03:56:01.575905Z'}
{'type': 'l2update', 'product_id': 'BTC-USD', 'changes': [['sell', '38601.46', '0.00000000']], 'time': '2021-05-20T03:56:01.576205Z'}
{'type': 'l2update', 'product_id': 'BTC-USD', 'changes': [['buy', '38167.93', '0.00000000']], 'time': '2021-05-20T03:56:01.576522Z'}
{'type': 'l2update', 'product_id': 'BTC-USD', 'changes': [['sell', '38348.34', '0.00000000']], 'time': '2021-05-20T03:56:01.577712Z'}
{'type': 'l2update', 'product_id': 'BTC-USD', 'changes': [['buy', '38327.54', '0.00315085']], 'time': '2021-05-20T03:56:01.580381Z'}
{'type': 'l2update', 'product_id': 'BTC-USD', 'changes': [['sell', '38488.26', '0.01299097']], 'time': '2021-05-20T03:56:01.580429Z'}
{'type': 'l2update', 'product_id': 'BTC-USD', 'changes': [['sell', '38349.49', '0.00000000']], 'time': '2021-05-20T03:56:01.581324Z'}
{'type': 'l2update', 'product_id': 'BTC-USD', 'changes': [['sell', '38546.63', '0.00000000']], 'time': '2021-05-20T03:56:01.583211Z'}
{'type': 'l2update', 'product_id': 'BTC-USD', 'changes': [['sell', '38367.56', '0.16567862']], 'time': '2021-05-20T03:56:01.584835Z'}
{'type': 'l2update', 'product_id': 'BTC-USD', 'changes': [['buy', '38265.99', '0.02923483']], 'time': '2021-05-20T03:56:01.585218Z'}
{'type': 'l2update', 'product_id': 'BTC-USD', 'changes': [['buy', '38326.51', '0.10000000']], 'time': '2021-05-20T03:56:01.585432Z'}
{'type': 'l2update', 'product_id': 'BTC-USD', 'changes': [['sell', '38491.62', '0.01000000']], 'time': '2021-05-20T03:56:01.589487Z'}
{'type': 'l2update', 'product_id': 'BTC-USD', 'changes': [['buy', '38167.42', '0.00000000']], 'time': '2021-05-20T03:56:01.590394Z'}
{'type': 'l2update', 'product_id': 'BTC-USD', 'changes': [['sell', '38347.94', '0.00000000']], 'time': '2021-05-20T03:56:01.590451Z'}
{'type': 'l2update', 'product_id': 'BTC-USD', 'changes': [['sell', '38337.49', '0.00000000']], 'time': '2021-05-20T03:56:01.593164Z'}
{'type': 'l2update', 'product_id': 'BTC-USD', 'changes': [['buy', '38307.86', '0.00000000']], 'time': '2021-05-20T03:56:01.593433Z'}
{'type': 'l2update', 'product_id': 'BTC-USD', 'changes': [['buy', '38246.15', '0.00000000']], 'time': '2021-05-20T03:56:01.594138Z'}
{'type': 'l2update', 'product_id': 'BTC-USD', 'changes': [['sell', '38337.48', '2.48969908']], 'time': '2021-05-20T03:56:01.594298Z'}
{'type': 'l2update', 'product_id': 'BTC-USD', 'changes': [['sell', '38475.95', '0.29717492']], 'time': '2021-05-20T03:56:01.594600Z'}
{'type': 'l2update', 'product_id': 'BTC-USD', 'changes': [['sell', '38475.95', '0.00000000']], 'time': '2021-05-20T03:56:01.594600Z'}
{'type': 'l2update', 'product_id': 'BTC-USD', 'changes': [['sell', '38462.95', '0.00000000']], 'time': '2021-05-20T03:56:01.594600Z'}
{'type': 'l2update', 'product_id': 'BTC-USD', 'changes': [['sell', '38453.67', '0.00000000']], 'time': '2021-05-20T03:56:01.594600Z'}
{'type': 'l2update', 'product_id': 'BTC-USD', 'changes': [['sell', '38441.26', '0.00000000']], 'time': '2021-05-20T03:56:01.594600Z'}
{'type': 'l2update', 'product_id': 'BTC-USD', 'changes': [['sell', '38440.30', '0.00000000']], 'time': '2021-05-20T03:56:01.594600Z'}
{'type': 'l2update', 'product_id': 'BTC-USD', 'changes': [['sell', '38433.26', '0.03123514']], 'time': '2021-05-20T03:56:01.594600Z'}
{'type': 'l2update', 'product_id': 'BTC-USD', 'changes': [['sell', '38383.82', '0.00000000']], 'time': '2021-05-20T03:56:01.594600Z'}
{'type': 'l2update', 'product_id': 'BTC-USD', 'changes': [['buy', '38326.52', '0.00000000']], 'time': '2021-05-20T03:56:01.595556Z'}
{'type': 'l2update', 'product_id': 'BTC-USD', 'changes': [['sell', '38614.56', '0.12948486']], 'time': '2021-05-20T03:56:01.598890Z'}
{'type': 'l2update', 'product_id': 'BTC-USD', 'changes': [['sell', '38336.96', '0.55400000']], 'time': '2021-05-20T03:56:01.601896Z'}
{'type': 'l2update', 'product_id': 'BTC-USD', 'changes': [['sell', '38531.56', '0.01000000']], 'time': '2021-05-20T03:56:01.602085Z'}
{'type': 'l2update', 'product_id': 'BTC-USD', 'changes': [['buy', '38301.49', '0.00000000']], 'time': '2021-05-20T03:56:01.603613Z'}
{'type': 'l2update', 'product_id': 'BTC-USD', 'changes': [['buy', '38288.36', '0.45970000']], 'time': '2021-05-20T03:56:01.606303Z'}
{'type': 'l2update', 'product_id': 'BTC-USD', 'changes': [['buy', '38255.95', '0.03009023']], 'time': '2021-05-20T03:56:01.606376Z'}
{'type': 'l2update', 'product_id': 'BTC-USD', 'changes': [['buy', '38314.67', '0.55350000']], 'time': '2021-05-20T03:56:01.610081Z'}
{'type': 'l2update', 'product_id': 'BTC-USD', 'changes': [['sell', '38337.48', '3.69164153']], 'time': '2021-05-20T03:56:01.610254Z'}
{'type': 'l2update', 'product_id': 'BTC-USD', 'changes': [['sell', '38356.29', '0.04800668']], 'time': '2021-05-20T03:56:01.610597Z'}
{'type': 'l2update', 'product_id': 'BTC-USD', 'changes': [['buy', '38307.91', '0.00000000']], 'time': '2021-05-20T03:56:01.613642Z'}
{'type': 'l2update', 'product_id': 'BTC-USD', 'changes': [['sell', '38342.88', '1.25720417']], 'time': '2021-05-20T03:56:01.614373Z'}
{'type': 'l2update', 'product_id': 'BTC-USD', 'changes': [['sell', '38337.01', '0.00000000']], 'time': '2021-05-20T03:56:01.617058Z'}
{'type': 'l2update', 'product_id': 'BTC-USD', 'changes': [['buy', '38293.20', '0.00000000']], 'time': '2021-05-20T03:56:01.617099Z'}
{'type': 'l2update', 'product_id': 'BTC-USD', 'changes': [['sell', '38433.26', '0.45171827']], 'time': '2021-05-20T03:56:01.617216Z'}
{'type': 'l2update', 'product_id': 'BTC-USD', 'changes': [['buy', '38301.65', '0.04961916']], 'time': '2021-05-20T03:56:01.617417Z'}
{'type': 'l2update', 'product_id': 'BTC-USD', 'changes': [['sell', '38344.28', '0.04377763']], 'time': '2021-05-20T03:56:01.617417Z'}
{'type': 'l2update', 'product_id': 'BTC-USD', 'changes': [['buy', '38314.67', '0.45350000']], 'time': '2021-05-20T03:56:01.622540Z'}
{'type': 'l2update', 'product_id': 'BTC-USD', 'changes': [['sell', '38429.51', '0.00000000']], 'time': '2021-05-20T03:56:01.623965Z'}
{'type': 'l2update', 'product_id': 'BTC-USD', 'changes': [['buy', '38230.89', '0.00000000']], 'time': '2021-05-20T03:56:01.624775Z'}
{'type': 'l2update', 'product_id': 'BTC-USD', 'changes': [['buy', '38291.66', '0.00000000']], 'time': '2021-05-20T03:56:01.625366Z'}
{'type': 'l2update', 'product_id': 'BTC-USD', 'changes': [['sell', '38336.60', '0.01492000']], 'time': '2021-05-20T03:56:01.628737Z'}
{'type': 'l2update', 'product_id': 'BTC-USD', 'changes': [['buy', '37534.95', '0.06892282']], 'time': '2021-05-20T03:56:01.629590Z'}
{'type': 'l2update', 'product_id': 'BTC-USD', 'changes': [['buy', '38290.75', '0.00000000']], 'time': '2021-05-20T03:56:01.631064Z'}
{'type': 'l2update', 'product_id': 'BTC-USD', 'changes': [['buy', '38320.02', '0.36000000']], 'time': '2021-05-20T03:56:01.631725Z'}
{'type': 'l2update', 'product_id': 'BTC-USD', 'changes': [['buy', '38314.72', '0.00000000']], 'time': '2021-05-20T03:56:01.634085Z'}
{'type': 'l2update', 'product_id': 'BTC-USD', 'changes': [['buy', '38245.16', '0.02737679']], 'time': '2021-05-20T03:56:01.634616Z'}
{'type': 'l2update', 'product_id': 'BTC-USD', 'changes': [['sell', '38363.75', '0.11520888']], 'time': '2021-05-20T03:56:01.634652Z'}
{'type': 'l2update', 'product_id': 'BTC-USD', 'changes': [['buy', '38197.46', '0.01000000']], 'time': '2021-05-20T03:56:01.635629Z'}
{'type': 'l2update', 'product_id': 'BTC-USD', 'changes': [['sell', '38337.00', '1.14668073']], 'time': '2021-05-20T03:56:01.635875Z'}
{'type': 'l2update', 'product_id': 'BTC-USD', 'changes': [['buy', '38294.72', '0.00000000']], 'time': '2021-05-20T03:56:01.636935Z'}
{'type': 'l2update', 'product_id': 'BTC-USD', 'changes': [['sell', '38371.72', '0.00000000']], 'time': '2021-05-20T03:56:01.637009Z'}
{'type': 'l2update', 'product_id': 'BTC-USD', 'changes': [['sell', '38336.43', '0.07460000']], 'time': '2021-05-20T03:56:01.638283Z'}
{'type': 'l2update', 'product_id': 'BTC-USD', 'changes': [['sell', '38353.42', '0.50000000']], 'time': '2021-05-20T03:56:01.638421Z'}
{'type': 'l2update', 'product_id': 'BTC-USD', 'changes': [['sell', '38342.87', '0.18981474']], 'time': '2021-05-20T03:56:01.638930Z'}
{'type': 'l2update', 'product_id': 'BTC-USD', 'changes': [['buy', '38327.65', '0.10516754']], 'time': '2021-05-20T03:56:01.638980Z'}
{'type': 'l2update', 'product_id': 'BTC-USD', 'changes': [['sell', '38443.25', '0.01300618']], 'time': '2021-05-20T03:56:01.643234Z'}
{'type': 'l2update', 'product_id': 'BTC-USD', 'changes': [['sell', '38503.16', '0.30082309']], 'time': '2021-05-20T03:56:01.643276Z'}
{'type': 'l2update', 'product_id': 'BTC-USD', 'changes': [['sell', '38445.04', '0.00000000']], 'time': '2021-05-20T03:56:01.644107Z'}
{'type': 'l2update', 'product_id': 'BTC-USD', 'changes': [['buy', '38306.67', '0.99440510']], 'time': '2021-05-20T03:56:01.644122Z'}
{'type': 'l2update', 'product_id': 'BTC-USD', 'changes': [['buy', '38288.36', '0.00000000']], 'time': '2021-05-20T03:56:01.645903Z'}
{'type': 'l2update', 'product_id': 'BTC-USD', 'changes': [['sell', '38364.58', '0.01000000']], 'time': '2021-05-20T03:56:01.647887Z'}
{'type': 'l2update', 'product_id': 'BTC-USD', 'changes': [['buy', '38295.53', '0.00000000']], 'time': '2021-05-20T03:56:01.650132Z'}
{'type': 'l2update', 'product_id': 'BTC-USD', 'changes': [['sell', '38375.49', '0.99177055']], 'time': '2021-05-20T03:56:01.651447Z'}
{'type': 'l2update', 'product_id': 'BTC-USD', 'changes': [['buy', '38239.48', '0.03696012']], 'time': '2021-05-20T03:56:01.651986Z'}
{'type': 'l2update', 'product_id': 'BTC-USD', 'changes': [['sell', '38330.96', '0.15000000']], 'time': '2021-05-20T03:56:01.652418Z'}
{'type': 'l2update', 'product_id': 'BTC-USD', 'changes': [['sell', '38336.60', '0.00000000']], 'time': '2021-05-20T03:56:01.652590Z'}
{'type': 'l2update', 'product_id': 'BTC-USD', 'changes': [['buy', '38327.08', '0.00000000']], 'time': '2021-05-20T03:56:01.653567Z'}
{'type': 'l2update', 'product_id': 'BTC-USD', 'changes': [['buy', '38327.54', '0.00000000']], 'time': '2021-05-20T03:56:01.654588Z'}
{'type': 'l2update', 'product_id': 'BTC-USD', 'changes': [['sell', '38344.94', '0.05335150']], 'time': '2021-05-20T03:56:01.656002Z'}
{'type': 'l2update', 'product_id': 'BTC-USD', 'changes': [['buy', '38320.02', '0.16000000']], 'time': '2021-05-20T03:56:01.656329Z'}
{'type': 'l2update', 'product_id': 'BTC-USD', 'changes': [['sell', '38363.75', '0.06520888']], 'time': '2021-05-20T03:56:01.659430Z'}
{'type': 'l2update', 'product_id': 'BTC-USD', 'changes': [['buy', '38297.08', '0.00000000']], 'time': '2021-05-20T03:56:01.665236Z'}
{'type': 'l2update', 'product_id': 'BTC-USD', 'changes': [['sell', '38503.16', '0.00000000']], 'time': '2021-05-20T03:56:01.665677Z'}
{'type': 'l2update', 'product_id': 'BTC-USD', 'changes': [['sell', '38336.43', '0.00000000']], 'time': '2021-05-20T03:56:01.667438Z'}
{'type': 'l2update', 'product_id': 'BTC-USD', 'changes': [['buy', '38320.02', '0.06000000']], 'time': '2021-05-20T03:56:01.670455Z'}
{'type': 'l2update', 'product_id': 'BTC-USD', 'changes': [['sell', '38367.68', '0.05000000']], 'time': '2021-05-20T03:56:01.673146Z'}
{'type': 'l2update', 'product_id': 'BTC-USD', 'changes': [['sell', '38353.17', '0.49660000']], 'time': '2021-05-20T03:56:01.673297Z'}
{'type': 'l2update', 'product_id': 'BTC-USD', 'changes': [['buy', '38295.21', '0.40135082']], 'time': '2021-05-20T03:56:01.673531Z'}
{'type': 'l2update', 'product_id': 'BTC-USD', 'changes': [['sell', '38473.33', '0.02198003']], 'time': '2021-05-20T03:56:01.673561Z'}
{'type': 'l2update', 'product_id': 'BTC-USD', 'changes': [['sell', '38375.48', '0.49781454']], 'time': '2021-05-20T03:56:01.674433Z'}
{'type': 'l2update', 'product_id': 'BTC-USD', 'changes': [['sell', '38380.00', '0.37972791']], 'time': '2021-05-20T03:56:01.677606Z'}
{'type': 'l2update', 'product_id': 'BTC-USD', 'changes': [['sell', '38370.17', '0.79710114']], 'time': '2021-05-20T03:56:01.677606Z'}
{'type': 'l2update', 'product_id': 'BTC-USD', 'changes': [['sell', '38440.75', '0.03308506']], 'time': '2021-05-20T03:56:01.678136Z'}
{'type': 'l2update', 'product_id': 'BTC-USD', 'changes': [['sell', '38426.41', '0.05880304']], 'time': '2021-05-20T03:56:01.678136Z'}
{'type': 'l2update', 'product_id': 'BTC-USD', 'changes': [['buy', '38227.55', '0.03308506']], 'time': '2021-05-20T03:56:01.678136Z'}
{'type': 'l2update', 'product_id': 'BTC-USD', 'changes': [['buy', '37534.95', '0.00000000']], 'time': '2021-05-20T03:56:01.678252Z'}
{'type': 'l2update', 'product_id': 'BTC-USD', 'changes': [['sell', '38364.29', '0.00000000']], 'time': '2021-05-20T03:56:01.680513Z'}
{'type': 'l2update', 'product_id': 'BTC-USD', 'changes': [['buy', '38326.51', '0.00000000']], 'time': '2021-05-20T03:56:01.681410Z'}
{'type': 'l2update', 'product_id': 'BTC-USD', 'changes': [['sell', '38327.66', '0.01492000']], 'time': '2021-05-20T03:56:01.685381Z'}
{'type': 'l2update', 'product_id': 'BTC-USD', 'changes': [['buy', '38314.73', '0.06520888']], 'time': '2021-05-20T03:56:01.685515Z'}
{'type': 'l2update', 'product_id': 'BTC-USD', 'changes': [['sell', '38353.41', '0.05000000']], 'time': '2021-05-20T03:56:01.685594Z'}
{'type': 'l2update', 'product_id': 'BTC-USD', 'changes': [['buy', '38301.65', '0.00000000']], 'time': '2021-05-20T03:56:01.686961Z'}
{'type': 'l2update', 'product_id': 'BTC-USD', 'changes': [['sell', '38344.28', '0.00000000']], 'time': '2021-05-20T03:56:01.686961Z'}
{'type': 'l2update', 'product_id': 'BTC-USD', 'changes': [['buy', '38295.84', '0.02400000']], 'time': '2021-05-20T03:56:01.689885Z'}
{'type': 'l2update', 'product_id': 'BTC-USD', 'changes': [['buy', '38295.03', '0.02400000']], 'time': '2021-05-20T03:56:01.689885Z'}
{'type': 'l2update', 'product_id': 'BTC-USD', 'changes': [['buy', '38294.22', '0.02400000']], 'time': '2021-05-20T03:56:01.689885Z'}
{'type': 'l2update', 'product_id': 'BTC-USD', 'changes': [['buy', '38289.64', '0.09623382']], 'time': '2021-05-20T03:56:01.690174Z'}
{'type': 'l2update', 'product_id': 'BTC-USD', 'changes': [['buy', '38322.12', '0.01000000']], 'time': '2021-05-20T03:56:01.690283Z'}
{'type': 'l2update', 'product_id': 'BTC-USD', 'changes': [['sell', '38460.90', '0.00000000']], 'time': '2021-05-20T03:56:01.690882Z'}
{'type': 'l2update', 'product_id': 'BTC-USD', 'changes': [['buy', '38274.32', '1.28232407']], 'time': '2021-05-20T03:56:01.691357Z'}
{'type': 'l2update', 'product_id': 'BTC-USD', 'changes': [['sell', '38433.26', '0.03123514']], 'time': '2021-05-20T03:56:01.693437Z'}
{'type': 'l2update', 'product_id': 'BTC-USD', 'changes': [['sell', '38491.62', '0.00000000']], 'time': '2021-05-20T03:56:01.693486Z'}
{'type': 'l2update', 'product_id': 'BTC-USD', 'changes': [['sell', '38327.66', '0.04300157']], 'time': '2021-05-20T03:56:01.693729Z'}
{'type': 'l2update', 'product_id': 'BTC-USD', 'changes': [['sell', '38353.17', '0.00000000']], 'time': '2021-05-20T03:56:01.693798Z'}
{'type': 'l2update', 'product_id': 'BTC-USD', 'changes': [['sell', '38362.72', '0.05162204']], 'time': '2021-05-20T03:56:01.697935Z'}
{'type': 'l2update', 'product_id': 'BTC-USD', 'changes': [['sell', '38327.66', '0.02808157']], 'time': '2021-05-20T03:56:01.699353Z'}
{'type': 'l2update', 'product_id': 'BTC-USD', 'changes': [['buy', '38320.02', '0.00000000']], 'time': '2021-05-20T03:56:01.699459Z'}
{'type': 'l2update', 'product_id': 'BTC-USD', 'changes': [['sell', '38353.41', '0.00000000']], 'time': '2021-05-20T03:56:01.699566Z'}
{'type': 'l2update', 'product_id': 'BTC-USD', 'changes': [['sell', '38337.78', '0.04979696']], 'time': '2021-05-20T03:56:01.704601Z'}
{'type': 'l2update', 'product_id': 'BTC-USD', 'changes': [['sell', '38330.96', '0.25000000']], 'time': '2021-05-20T03:56:01.705021Z'}
{'type': 'l2update', 'product_id': 'BTC-USD', 'changes': [['sell', '38327.66', '0.05698157']], 'time': '2021-05-20T03:56:01.705240Z'}
{'type': 'l2update', 'product_id': 'BTC-USD', 'changes': [['buy', '38306.67', '0.00000000']], 'time': '2021-05-20T03:56:01.705278Z'}
{'type': 'l2update', 'product_id': 'BTC-USD', 'changes': [['buy', '38325.80', '0.00000000']], 'time': '2021-05-20T03:56:01.705339Z'}
{'type': 'l2update', 'product_id': 'BTC-USD', 'changes': [['sell', '38342.87', '0.00000000']], 'time': '2021-05-20T03:56:01.705390Z'}
{'type': 'l2update', 'product_id': 'BTC-USD', 'changes': [['sell', '38327.66', '0.02890000']], 'time': '2021-05-20T03:56:01.708691Z'}
{'type': 'l2update', 'product_id': 'BTC-USD', 'changes': [['sell', '38327.66', '0.67890000']], 'time': '2021-05-20T03:56:01.709766Z'}
{'type': 'l2update', 'product_id': 'BTC-USD', 'changes': [['buy', '38318.13', '0.02000000']], 'time': '2021-05-20T03:56:01.713976Z'}
{'type': 'l2update', 'product_id': 'BTC-USD', 'changes': [['sell', '38327.66', '0.68463000']], 'time': '2021-05-20T03:56:01.714443Z'}
{'type': 'l2update', 'product_id': 'BTC-USD', 'changes': [['sell', '38478.45', '0.01000000']], 'time': '2021-05-20T03:56:01.717405Z'}
{'type': 'l2update', 'product_id': 'BTC-USD', 'changes': [['sell', '38399.49', '0.37418419']], 'time': '2021-05-20T03:56:01.717563Z'}
{'type': 'l2update', 'product_id': 'BTC-USD', 'changes': [['sell', '38433.26', '0.06288276']], 'time': '2021-05-20T03:56:01.717796Z'}
{'type': 'l2update', 'product_id': 'BTC-USD', 'changes': [['sell', '38416.01', '0.03157048']], 'time': '2021-05-20T03:56:01.717796Z'}
{'type': 'l2update', 'product_id': 'BTC-USD', 'changes': [['sell', '38399.48', '0.03123514']], 'time': '2021-05-20T03:56:01.717796Z'}
{'type': 'l2update', 'product_id': 'BTC-USD', 'changes': [['sell', '38394.35', '0.03118982']], 'time': '2021-05-20T03:56:01.717796Z'}
{'type': 'l2update', 'product_id': 'BTC-USD', 'changes': [['sell', '38384.66', '0.01133129']], 'time': '2021-05-20T03:56:01.717796Z'}
{'type': 'l2update', 'product_id': 'BTC-USD', 'changes': [['buy', '38221.30', '0.03164762']], 'time': '2021-05-20T03:56:01.717796Z'}
{'type': 'l2update', 'product_id': 'BTC-USD', 'changes': [['buy', '38197.46', '0.00000000']], 'time': '2021-05-20T03:56:01.721579Z'}
{'type': 'l2update', 'product_id': 'BTC-USD', 'changes': [['sell', '38353.16', '0.05000000']], 'time': '2021-05-20T03:56:01.723279Z'}
{'type': 'l2update', 'product_id': 'BTC-USD', 'changes': [['sell', '38355.48', '0.39490432']], 'time': '2021-05-20T03:56:01.723306Z'}
{'type': 'l2update', 'product_id': 'BTC-USD', 'changes': [['sell', '38330.96', '0.45000000']], 'time': '2021-05-20T03:56:01.724650Z'}
{'type': 'l2update', 'product_id': 'BTC-USD', 'changes': [['buy', '38283.51', '0.00000000']], 'time': '2021-05-20T03:56:01.727136Z'}
{'type': 'l2update', 'product_id': 'BTC-USD', 'changes': [['buy', '38295.84', '0.00000000']], 'time': '2021-05-20T03:56:01.732486Z'}
{'type': 'l2update', 'product_id': 'BTC-USD', 'changes': [['buy', '38295.03', '0.00000000']], 'time': '2021-05-20T03:56:01.732486Z'}
{'type': 'l2update', 'product_id': 'BTC-USD', 'changes': [['sell', '38448.30', '0.00000000']], 'time': '2021-05-20T03:56:01.733486Z'}
{'type': 'l2update', 'product_id': 'BTC-USD', 'changes': [['sell', '38433.26', '0.03164762']], 'time': '2021-05-20T03:56:01.733486Z'}
{'type': 'l2update', 'product_id': 'BTC-USD', 'changes': [['sell', '38426.41', '0.02761322']], 'time': '2021-05-20T03:56:01.733486Z'}
{'type': 'l2update', 'product_id': 'BTC-USD', 'changes': [['sell', '38419.75', '0.00000000']], 'time': '2021-05-20T03:56:01.733486Z'}
{'type': 'l2update', 'product_id': 'BTC-USD', 'changes': [['buy', '38318.13', '0.05000000']], 'time': '2021-05-20T03:56:01.734354Z'}
{'type': 'l2update', 'product_id': 'BTC-USD', 'changes': [['sell', '38379.14', '0.20200000']], 'time': '2021-05-20T03:56:01.734417Z'}
{'type': 'l2update', 'product_id': 'BTC-USD', 'changes': [['buy', '38300.97', '0.99440510']], 'time': '2021-05-20T03:56:01.734556Z'}
{'type': 'l2update', 'product_id': 'BTC-USD', 'changes': [['sell', '38478.45', '0.00000000']], 'time': '2021-05-20T03:56:01.735527Z'}
{'type': 'l2update', 'product_id': 'BTC-USD', 'changes': [['sell', '38353.42', '0.00000000']], 'time': '2021-05-20T03:56:01.737354Z'}
{'type': 'l2update', 'product_id': 'BTC-USD', 'changes': [['sell', '38488.26', '0.00000000']], 'time': '2021-05-20T03:56:01.738346Z'}
{'type': 'l2update', 'product_id': 'BTC-USD', 'changes': [['sell', '38418.52', '0.00000000']], 'time': '2021-05-20T03:56:01.740691Z'}
{'type': 'l2update', 'product_id': 'BTC-USD', 'changes': [['sell', '38336.95', '0.18981474']], 'time': '2021-05-20T03:56:01.741225Z'}
{'type': 'l2update', 'product_id': 'BTC-USD', 'changes': [['sell', '38494.63', '0.30083185']], 'time': '2021-05-20T03:56:01.741460Z'}
{'type': 'l2update', 'product_id': 'BTC-USD', 'changes': [['buy', '38306.71', '0.84700000']], 'time': '2021-05-20T03:56:01.741997Z'}
{'type': 'l2update', 'product_id': 'BTC-USD', 'changes': [['sell', '38363.75', '0.00000000']], 'time': '2021-05-20T03:56:01.744392Z'}
{'type': 'l2update', 'product_id': 'BTC-USD', 'changes': [['sell', '38404.81', '0.38345163']], 'time': '2021-05-20T03:56:01.744752Z'}
{'type': 'l2update', 'product_id': 'BTC-USD', 'changes': [['sell', '38327.66', '0.78463000']], 'time': '2021-05-20T03:56:01.746669Z'}
{'type': 'l2update', 'product_id': 'BTC-USD', 'changes': [['buy', '38294.22', '0.00000000']], 'time': '2021-05-20T03:56:01.747646Z'}
{'type': 'l2update', 'product_id': 'BTC-USD', 'changes': [['buy', '38289.36', '0.47540000']], 'time': '2021-05-20T03:56:01.750224Z'}
{'type': 'l2update', 'product_id': 'BTC-USD', 'changes': [['buy', '38214.87', '0.02604873']], 'time': '2021-05-20T03:56:01.756534Z'}
{'type': 'l2update', 'product_id': 'BTC-USD', 'changes': [['buy', '38318.13', '0.09000000']], 'time': '2021-05-20T03:56:01.756580Z'}
{'type': 'l2update', 'product_id': 'BTC-USD', 'changes': [['sell', '38353.16', '0.00000000']], 'time': '2021-05-20T03:56:01.757292Z'}
{'type': 'l2update', 'product_id': 'BTC-USD', 'changes': [['sell', '38494.63', '0.00000000']], 'time': '2021-05-20T03:56:01.757762Z'}
{'type': 'l2update', 'product_id': 'BTC-USD', 'changes': [['sell', '38330.96', '0.35000000']], 'time': '2021-05-20T03:56:01.760212Z'}
{'type': 'l2update', 'product_id': 'BTC-USD', 'changes': [['buy', '38300.97', '1.05961398']], 'time': '2021-05-20T03:56:01.763168Z'}
{'type': 'l2update', 'product_id': 'BTC-USD', 'changes': [['sell', '38491.62', '0.01000000']], 'time': '2021-05-20T03:56:01.765055Z'}
{'type': 'l2update', 'product_id': 'BTC-USD', 'changes': [['buy', '38290.23', '0.04450584']], 'time': '2021-05-20T03:56:01.765386Z'}
{'type': 'l2update', 'product_id': 'BTC-USD', 'changes': [['sell', '38334.31', '0.05367425']], 'time': '2021-05-20T03:56:01.765386Z'}
{'type': 'l2update', 'product_id': 'BTC-USD', 'changes': [['sell', '38330.95', '0.50000000']], 'time': '2021-05-20T03:56:01.765550Z'}
{'type': 'l2update', 'product_id': 'BTC-USD', 'changes': [['sell', '38404.81', '0.78861439']], 'time': '2021-05-20T03:56:01.765661Z'}
{'type': 'l2update', 'product_id': 'BTC-USD', 'changes': [['sell', '38330.96', '0.15000000']], 'time': '2021-05-20T03:56:01.770999Z'}
{'type': 'l2update', 'product_id': 'BTC-USD', 'changes': [['buy', '38290.55', '0.02400000']], 'time': '2021-05-20T03:56:01.773744Z'}
{'type': 'l2update', 'product_id': 'BTC-USD', 'changes': [['buy', '38289.75', '0.02400000']], 'time': '2021-05-20T03:56:01.773744Z'}
{'type': 'l2update', 'product_id': 'BTC-USD', 'changes': [['buy', '38288.94', '0.02400000']], 'time': '2021-05-20T03:56:01.773744Z'}
{'type': 'l2update', 'product_id': 'BTC-USD', 'changes': [['sell', '38449.85', '0.01300395']], 'time': '2021-05-20T03:56:01.778385Z'}
{'type': 'l2update', 'product_id': 'BTC-USD', 'changes': [['buy', '38023.31', '0.01000000']], 'time': '2021-05-20T03:56:01.778505Z'}
{'type': 'l2update', 'product_id': 'BTC-USD', 'changes': [['buy', '38318.13', '0.14000000']], 'time': '2021-05-20T03:56:01.778522Z'}
{'type': 'l2update', 'product_id': 'BTC-USD', 'changes': [['sell', '38355.47', '0.05000000']], 'time': '2021-05-20T03:56:01.778738Z'}
{'type': 'l2update', 'product_id': 'BTC-USD', 'changes': [['buy', '38208.25', '0.02825582']], 'time': '2021-05-20T03:56:01.779104Z'}
{'type': 'l2update', 'product_id': 'BTC-USD', 'changes': [['buy', '38306.71', '0.00000000']], 'time': '2021-05-20T03:56:01.779923Z'}
{'type': 'l2update', 'product_id': 'BTC-USD', 'changes': [['sell', '38353.41', '0.06520888']], 'time': '2021-05-20T03:56:01.783301Z'}
{'type': 'l2update', 'product_id': 'BTC-USD', 'changes': [['buy', '38327.65', '0.00000000']], 'time': '2021-05-20T03:56:01.786301Z'}
{'type': 'l2update', 'product_id': 'BTC-USD', 'changes': [['sell', '38416.02', '0.43574811']], 'time': '2021-05-20T03:56:01.787170Z'}
{'type': 'l2update', 'product_id': 'BTC-USD', 'changes': [['sell', '38327.65', '0.00549631']], 'time': '2021-05-20T03:56:01.787800Z'}
{'type': 'l2update', 'product_id': 'BTC-USD', 'changes': [['buy', '38295.21', '0.00000000']], 'time': '2021-05-20T03:56:01.788071Z'}
{'type': 'l2update', 'product_id': 'BTC-USD', 'changes': [['sell', '38368.22', '0.00000000']], 'time': '2021-05-20T03:56:01.790418Z'}
{'type': 'l2update', 'product_id': 'BTC-USD', 'changes': [['buy', '38280.18', '0.00000000']], 'time': '2021-05-20T03:56:01.795122Z'}
{'type': 'l2update', 'product_id': 'BTC-USD', 'changes': [['buy', '38314.67', '0.40350000']], 'time': '2021-05-20T03:56:01.796999Z'}
{'type': 'l2update', 'product_id': 'BTC-USD', 'changes': [['buy', '38314.67', '0.30000000']], 'time': '2021-05-20T03:56:01.797586Z'}
{'type': 'l2update', 'product_id': 'BTC-USD', 'changes': [['sell', '38351.56', '0.49260000']], 'time': '2021-05-20T03:56:01.797939Z'}
{'type': 'l2update', 'product_id': 'BTC-USD', 'changes': [['buy', '38314.66', '0.26000000']], 'time': '2021-05-20T03:56:01.798189Z'}
{'type': 'l2update', 'product_id': 'BTC-USD', 'changes': [['sell', '38327.66', '0.68463000']], 'time': '2021-05-20T03:56:01.800780Z'}
{'type': 'l2update', 'product_id': 'BTC-USD', 'changes': [['sell', '38327.66', '0.67890000']], 'time': '2021-05-20T03:56:01.805438Z'}
{'type': 'l2update', 'product_id': 'BTC-USD', 'changes': [['sell', '38369.80', '0.00000000']], 'time': '2021-05-20T03:56:01.806037Z'}
{'type': 'l2update', 'product_id': 'BTC-USD', 'changes': [['sell', '38428.01', '0.42018610']], 'time': '2021-05-20T03:56:01.807184Z'}
{'type': 'l2update', 'product_id': 'BTC-USD', 'changes': [['buy', '38224.49', '0.07700000']], 'time': '2021-05-20T03:56:01.810042Z'}
{'type': 'l2update', 'product_id': 'BTC-USD', 'changes': [['buy', '38300.97', '0.99440510']], 'time': '2021-05-20T03:56:01.818280Z'}
{'type': 'l2update', 'product_id': 'BTC-USD', 'changes': [['sell', '38416.24', '0.00000000']], 'time': '2021-05-20T03:56:01.819352Z'}
{'type': 'l2update', 'product_id': 'BTC-USD', 'changes': [['buy', '38300.98', '0.40135082']], 'time': '2021-05-20T03:56:01.820139Z'}
{'type': 'l2update', 'product_id': 'BTC-USD', 'changes': [['buy', '38314.67', '0.00000000']], 'time': '2021-05-20T03:56:01.820772Z'}
{'type': 'l2update', 'product_id': 'BTC-USD', 'changes': [['sell', '38569.63', '0.01000000']], 'time': '2021-05-20T03:56:01.826598Z'}
{'type': 'l2update', 'product_id': 'BTC-USD', 'changes': [['buy', '38197.58', '0.03099042']], 'time': '2021-05-20T03:56:01.827095Z'}
{'type': 'l2update', 'product_id': 'BTC-USD', 'changes': [['sell', '38355.47', '0.00000000']], 'time': '2021-05-20T03:56:01.831437Z'}
{'type': 'l2update', 'product_id': 'BTC-USD', 'changes': [['buy', '38306.66', '0.00367349']], 'time': '2021-05-20T03:56:01.832200Z'}
{'type': 'l2update', 'product_id': 'BTC-USD', 'changes': [['sell', '38327.65', '0.00000000']], 'time': '2021-05-20T03:56:01.836079Z'}
{'type': 'l2update', 'product_id': 'BTC-USD', 'changes': [['buy', '38314.73', '0.00000000']], 'time': '2021-05-20T03:56:01.837820Z'}
{'type': 'l2update', 'product_id': 'BTC-USD', 'changes': [['sell', '38369.81', '0.00000000']], 'time': '2021-05-20T03:56:01.839274Z'}
{'type': 'l2update', 'product_id': 'BTC-USD', 'changes': [['sell', '38330.96', '0.00000000']], 'time': '2021-05-20T03:56:01.843645Z'}
{'type': 'l2update', 'product_id': 'BTC-USD', 'changes': [['sell', '38474.41', '0.00000000']], 'time': '2021-05-20T03:56:01.865641Z'}
{'type': 'l2update', 'product_id': 'BTC-USD', 'changes': [['buy', '38255.52', '0.00000000']], 'time': '2021-05-20T03:56:01.870351Z'}
{'type': 'l2update', 'product_id': 'BTC-USD', 'changes': [['sell', '38327.66', '0.67765260']], 'time': '2021-05-20T03:56:01.873527Z'}
{'type': 'l2update', 'product_id': 'BTC-USD', 'changes': [['buy', '38295.18', '0.00000000']], 'time': '2021-05-20T03:56:01.877552Z'}
{'type': 'l2update', 'product_id': 'BTC-USD', 'changes': [['sell', '38351.55', '0.05000000']], 'time': '2021-05-20T03:56:01.881311Z'}
{'type': 'l2update', 'product_id': 'BTC-USD', 'changes': [['sell', '38387.41', '0.18300000']], 'time': '2021-05-20T03:56:01.881513Z'}
{'type': 'l2update', 'product_id': 'BTC-USD', 'changes': [['buy', '38301.03', '0.84600000']], 'time': '2021-05-20T03:56:01.881553Z'}
{'type': 'l2update', 'product_id': 'BTC-USD', 'changes': [['sell', '38360.92', '0.02000000']], 'time': '2021-05-20T03:56:01.890449Z'}
{'type': 'l2update', 'product_id': 'BTC-USD', 'changes': [['sell', '38351.56', '0.00000000']], 'time': '2021-05-20T03:56:01.891486Z'}
{'type': 'l2update', 'product_id': 'BTC-USD', 'changes': [['sell', '38336.95', '0.00000000']], 'time': '2021-05-20T03:56:01.896267Z'}
{'type': 'l2update', 'product_id': 'BTC-USD', 'changes': [['sell', '38330.95', '0.00000000']], 'time': '2021-05-20T03:56:01.906642Z'}
{'type': 'l2update', 'product_id': 'BTC-USD', 'changes': [['buy', '38263.51', '0.10000000']], 'time': '2021-05-20T03:56:01.927202Z'}
{'type': 'l2update', 'product_id': 'BTC-USD', 'changes': [['sell', '38493.69', '0.01000000']], 'time': '2021-05-20T03:56:01.930086Z'}
{'type': 'l2update', 'product_id': 'BTC-USD', 'changes': [['sell', '38327.66', '0.65000000']], 'time': '2021-05-20T03:56:01.930561Z'}
{'type': 'l2update', 'product_id': 'BTC-USD', 'changes': [['buy', '38197.58', '0.06672162']], 'time': '2021-05-20T03:56:01.934349Z'}
{'type': 'l2update', 'product_id': 'BTC-USD', 'changes': [['sell', '38446.78', '0.01000000']], 'time': '2021-05-20T03:56:01.934459Z'}
{'type': 'l2update', 'product_id': 'BTC-USD', 'changes': [['buy', '37529.32', '0.06743767']], 'time': '2021-05-20T03:56:01.938433Z'}
{'type': 'l2update', 'product_id': 'BTC-USD', 'changes': [['sell', '38327.66', '0.00000000']], 'time': '2021-05-20T03:56:01.938685Z'}
{'type': 'l2update', 'product_id': 'BTC-USD', 'changes': [['buy', '38154.00', '0.05025236']], 'time': '2021-05-20T03:56:01.944907Z'}
{'type': 'l2update', 'product_id': 'BTC-USD', 'changes': [['sell', '38351.93', '0.04865531']], 'time': '2021-05-20T03:56:01.944926Z'}
{'type': 'l2update', 'product_id': 'BTC-USD', 'changes': [['sell', '38364.58', '0.00000000']], 'time': '2021-05-20T03:56:01.945931Z'}
{'type': 'l2update', 'product_id': 'BTC-USD', 'changes': [['buy', '38289.36', '0.00000000']], 'time': '2021-05-20T03:56:01.959655Z'}
{'type': 'l2update', 'product_id': 'BTC-USD', 'changes': [['buy', '38106.80', '0.00000000']], 'time': '2021-05-20T03:56:01.963727Z'}
{'type': 'l2update', 'product_id': 'BTC-USD', 'changes': [['sell', '38327.65', '0.50000000']], 'time': '2021-05-20T03:56:01.978185Z'}
{'type': 'l2update', 'product_id': 'BTC-USD', 'changes': [['sell', '38337.48', '1.20194245']], 'time': '2021-05-20T03:56:01.991824Z'}
{'type': 'l2update', 'product_id': 'BTC-USD', 'changes': [['sell', '38446.05', '0.00000000']], 'time': '2021-05-20T03:56:01.997913Z'}
{'type': 'l2update', 'product_id': 'BTC-USD', 'changes': [['buy', '38300.98', '0.00000000']], 'time': '2021-05-20T03:56:01.998094Z'}
{'type': 'l2update', 'product_id': 'BTC-USD', 'changes': [['sell', '38337.48', '0.00000000']], 'time': '2021-05-20T03:56:01.998152Z'}
{'type': 'l2update', 'product_id': 'BTC-USD', 'changes': [['buy', '38239.70', '0.02400000']], 'time': '2021-05-20T03:56:02.001559Z'}
{'type': 'l2update', 'product_id': 'BTC-USD', 'changes': [['sell', '38447.41', '0.03320847']], 'time': '2021-05-20T03:56:02.001674Z'}
{'type': 'l2update', 'product_id': 'BTC-USD', 'changes': [['sell', '38367.68', '0.00000000']], 'time': '2021-05-20T03:56:02.002944Z'}
{'type': 'l2update', 'product_id': 'BTC-USD', 'changes': [['sell', '38379.14', '0.00000000']], 'time': '2021-05-20T03:56:02.007605Z'}
{'type': 'l2update', 'product_id': 'BTC-USD', 'changes': [['sell', '38473.33', '0.00000000']], 'time': '2021-05-20T03:56:02.007819Z'}
{'type': 'l2update', 'product_id': 'BTC-USD', 'changes': [['sell', '38375.48', '0.00000000']], 'time': '2021-05-20T03:56:02.007867Z'}
{'type': 'l2update', 'product_id': 'BTC-USD', 'changes': [['sell', '38333.90', '0.07460000']], 'time': '2021-05-20T03:56:02.009708Z'}
{'type': 'l2update', 'product_id': 'BTC-USD', 'changes': [['buy', '38322.58', '0.07460000']], 'time': '2021-05-20T03:56:02.009884Z'}
{'type': 'l2update', 'product_id': 'BTC-USD', 'changes': [['sell', '38333.77', '0.01492000']], 'time': '2021-05-20T03:56:02.010522Z'}
{'type': 'l2update', 'product_id': 'BTC-USD', 'changes': [['buy', '38322.46', '0.00315085']], 'time': '2021-05-20T03:56:02.010711Z'}
{'type': 'l2update', 'product_id': 'BTC-USD', 'changes': [['buy', '38323.15', '0.05186588']], 'time': '2021-05-20T03:56:02.013588Z'}
{'type': 'l2update', 'product_id': 'BTC-USD', 'changes': [['buy', '38322.13', '0.10516754']], 'time': '2021-05-20T03:56:02.018033Z'}
{'type': 'l2update', 'product_id': 'BTC-USD', 'changes': [['buy', '38290.93', '0.47820000']], 'time': '2021-05-20T03:56:02.021108Z'}
{'type': 'l2update', 'product_id': 'BTC-USD', 'changes': [['buy', '38120.18', '0.02623282']], 'time': '2021-05-20T03:56:02.026072Z'}
{'type': 'l2update', 'product_id': 'BTC-USD', 'changes': [['sell', '38387.41', '0.00000000']], 'time': '2021-05-20T03:56:02.029948Z'}
{'type': 'l2update', 'product_id': 'BTC-USD', 'changes': [['sell', '38355.48', '0.00000000']], 'time': '2021-05-20T03:56:02.031977Z'}
{'type': 'l2update', 'product_id': 'BTC-USD', 'changes': [['buy', '38151.72', '0.00000000']], 'time': '2021-05-20T03:56:02.034594Z'}
{'type': 'l2update', 'product_id': 'BTC-USD', 'changes': [['sell', '38327.65', '0.00000000']], 'time': '2021-05-20T03:56:02.034824Z'}
{'type': 'l2update', 'product_id': 'BTC-USD', 'changes': [['sell', '38351.93', '0.00000000']], 'time': '2021-05-20T03:56:02.035190Z'}
{'type': 'l2update', 'product_id': 'BTC-USD', 'changes': [['sell', '38356.29', '0.00000000']], 'time': '2021-05-20T03:56:02.035969Z'}
{'type': 'l2update', 'product_id': 'BTC-USD', 'changes': [['buy', '38306.48', '0.84700000']], 'time': '2021-05-20T03:56:02.037516Z'}
{'type': 'l2update', 'product_id': 'BTC-USD', 'changes': [['sell', '38498.29', '0.30082961']], 'time': '2021-05-20T03:56:02.041454Z'}
{'type': 'l2update', 'product_id': 'BTC-USD', 'changes': [['sell', '38491.62', '0.00000000']], 'time': '2021-05-20T03:56:02.055505Z'}
{'type': 'l2update', 'product_id': 'BTC-USD', 'changes': [['sell', '38342.88', '0.00000000']], 'time': '2021-05-20T03:56:02.057001Z'}
{'type': 'l2update', 'product_id': 'BTC-USD', 'changes': [['sell', '38334.30', '2.48969908']], 'time': '2021-05-20T03:56:02.057830Z'}
{'type': 'l2update', 'product_id': 'BTC-USD', 'changes': [['sell', '38336.95', '0.18981474']], 'time': '2021-05-20T03:56:02.063821Z'}
{'type': 'l2update', 'product_id': 'BTC-USD', 'changes': [['sell', '38389.42', '0.02761322']], 'time': '2021-05-20T03:56:02.064188Z'}
{'type': 'l2update', 'product_id': 'BTC-USD', 'changes': [['sell', '38354.91', '0.03000000']], 'time': '2021-05-20T03:56:02.064523Z'}
{'type': 'l2update', 'product_id': 'BTC-USD', 'changes': [['sell', '38374.70', '2.16932808']], 'time': '2021-05-20T03:56:02.064697Z'}
{'type': 'l2update', 'product_id': 'BTC-USD', 'changes': [['buy', '38142.61', '0.00000000']], 'time': '2021-05-20T03:56:02.065858Z'}
{'type': 'l2update', 'product_id': 'BTC-USD', 'changes': [['buy', '38290.93', '0.00000000']], 'time': '2021-05-20T03:56:02.068177Z'}
{'type': 'l2update', 'product_id': 'BTC-USD', 'changes': [['buy', '38322.46', '0.01492000']], 'time': '2021-05-20T03:56:02.068759Z'}
{'type': 'l2update', 'product_id': 'BTC-USD', 'changes': [['sell', '38342.87', '0.06520888']], 'time': '2021-05-20T03:56:02.069759Z'}
{'type': 'l2update', 'product_id': 'BTC-USD', 'changes': [['sell', '38333.90', '0.00000000']], 'time': '2021-05-20T03:56:02.072081Z'}
{'type': 'l2update', 'product_id': 'BTC-USD', 'changes': [['buy', '38300.98', '0.06520888']], 'time': '2021-05-20T03:56:02.073884Z'}
{'type': 'l2update', 'product_id': 'BTC-USD', 'changes': [['buy', '38322.58', '0.00000000']], 'time': '2021-05-20T03:56:02.074480Z'}
{'type': 'l2update', 'product_id': 'BTC-USD', 'changes': [['sell', '38333.77', '0.00000000']], 'time': '2021-05-20T03:56:02.074970Z'}
{'type': 'l2update', 'product_id': 'BTC-USD', 'changes': [['buy', '38242.81', '0.00000000']], 'time': '2021-05-20T03:56:02.076631Z'}
{'type': 'l2update', 'product_id': 'BTC-USD', 'changes': [['sell', '38461.39', '0.05379110']], 'time': '2021-05-20T03:56:02.080050Z'}
{'type': 'l2update', 'product_id': 'BTC-USD', 'changes': [['buy', '38207.36', '0.00000000']], 'time': '2021-05-20T03:56:02.084719Z'}
{'type': 'l2update', 'product_id': 'BTC-USD', 'changes': [['buy', '38154.00', '0.00000000']], 'time': '2021-05-20T03:56:02.085072Z'}
{'type': 'l2update', 'product_id': 'BTC-USD', 'changes': [['sell', '38363.75', '0.48747734']], 'time': '2021-05-20T03:56:02.086713Z'}
{'type': 'l2update', 'product_id': 'BTC-USD', 'changes': [['buy', '38314.67', '0.10000000']], 'time': '2021-05-20T03:56:02.087731Z'}
{'type': 'l2update', 'product_id': 'BTC-USD', 'changes': [['sell', '38498.29', '0.00000000']], 'time': '2021-05-20T03:56:02.112262Z'}
{'type': 'l2update', 'product_id': 'BTC-USD', 'changes': [['sell', '38334.30', '2.98969908']], 'time': '2021-05-20T03:56:02.115986Z'}
{'type': 'l2update', 'product_id': 'BTC-USD', 'changes': [['buy', '38163.46', '0.01000000']], 'time': '2021-05-20T03:56:02.116213Z'}
{'type': 'l2update', 'product_id': 'BTC-USD', 'changes': [['sell', '38337.00', '0.00000000']], 'time': '2021-05-20T03:56:02.118768Z'}
{'type': 'l2update', 'product_id': 'BTC-USD', 'changes': [['buy', '37529.32', '0.00000000']], 'time': '2021-05-20T03:56:02.121670Z'}
{'type': 'l2update', 'product_id': 'BTC-USD', 'changes': [['sell', '38478.45', '0.01000000']], 'time': '2021-05-20T03:56:02.125480Z'}
{'type': 'l2update', 'product_id': 'BTC-USD', 'changes': [['buy', '37491.66', '0.00000000']], 'time': '2021-05-20T03:56:02.128966Z'}
{'type': 'l2update', 'product_id': 'BTC-USD', 'changes': [['buy', '37487.46', '0.00000000']], 'time': '2021-05-20T03:56:02.128966Z'}
{'type': 'l2update', 'product_id': 'BTC-USD', 'changes': [['buy', '37485.34', '0.00000000']], 'time': '2021-05-20T03:56:02.128966Z'}
{'type': 'l2update', 'product_id': 'BTC-USD', 'changes': [['sell', '39495.98', '0.00000000']], 'time': '2021-05-20T03:56:02.128966Z'}
{'type': 'l2update', 'product_id': 'BTC-USD', 'changes': [['sell', '39499.99', '0.00000000']], 'time': '2021-05-20T03:56:02.128966Z'}
{'type': 'l2update', 'product_id': 'BTC-USD', 'changes': [['sell', '38647.42', '3.22892175']], 'time': '2021-05-20T03:56:02.129871Z'}
{'type': 'l2update', 'product_id': 'BTC-USD', 'changes': [['sell', '38426.41', '0.00000000']], 'time': '2021-05-20T03:56:02.132719Z'}
{'type': 'l2update', 'product_id': 'BTC-USD', 'changes': [['buy', '38322.58', '0.21800000']], 'time': '2021-05-20T03:56:02.133615Z'}
{'type': 'l2update', 'product_id': 'BTC-USD', 'changes': [['buy', '38218.02', '0.50000000']], 'time': '2021-05-20T03:56:02.133670Z'}
{'type': 'l2update', 'product_id': 'BTC-USD', 'changes': [['buy', '37500.01', '0.11720000']], 'time': '2021-05-20T03:56:02.135517Z'}
{'type': 'l2update', 'product_id': 'BTC-USD', 'changes': [['sell', '39495.99', '0.12710000']], 'time': '2021-05-20T03:56:02.135517Z'}
{'type': 'l2update', 'product_id': 'BTC-USD', 'changes': [['buy', '37500.02', '0.02310000']], 'time': '2021-05-20T03:56:02.135517Z'}
{'type': 'l2update', 'product_id': 'BTC-USD', 'changes': [['buy', '38314.71', '0.52000000']], 'time': '2021-05-20T03:56:02.135637Z'}
{'type': 'l2update', 'product_id': 'BTC-USD', 'changes': [['buy', '38239.70', '0.00000000']], 'time': '2021-05-20T03:56:02.136390Z'}
{'type': 'l2update', 'product_id': 'BTC-USD', 'changes': [['buy', '38322.46', '0.01176915']], 'time': '2021-05-20T03:56:02.139912Z'}
{'type': 'l2update', 'product_id': 'BTC-USD', 'changes': [['sell', '38354.94', '0.04000000']], 'time': '2021-05-20T03:56:02.143953Z'}
{'type': 'l2update', 'product_id': 'BTC-USD', 'changes': [['sell', '38355.42', '0.49770000']], 'time': '2021-05-20T03:56:02.144415Z'}
{'type': 'l2update', 'product_id': 'BTC-USD', 'changes': [['sell', '38353.41', '0.00000000']], 'time': '2021-05-20T03:56:02.145631Z'}
{'type': 'l2update', 'product_id': 'BTC-USD', 'changes': [['sell', '38334.31', '0.00000000']], 'time': '2021-05-20T03:56:02.151592Z'}
{'type': 'l2update', 'product_id': 'BTC-USD', 'changes': [['buy', '38301.03', '0.00000000']], 'time': '2021-05-20T03:56:02.151870Z'}
{'type': 'l2update', 'product_id': 'BTC-USD', 'changes': [['buy', '38322.46', '0.00000000']], 'time': '2021-05-20T03:56:02.152591Z'}
{'type': 'l2update', 'product_id': 'BTC-USD', 'changes': [['sell', '38333.25', '0.02554191']], 'time': '2021-05-20T03:56:02.155749Z'}
{'type': 'l2update', 'product_id': 'BTC-USD', 'changes': [['sell', '38333.25', '0.07460000']], 'time': '2021-05-20T03:56:02.159907Z'}
{'type': 'l2update', 'product_id': 'BTC-USD', 'changes': [['buy', '38323.38', '0.07460000']], 'time': '2021-05-20T03:56:02.160041Z'}
{'type': 'l2update', 'product_id': 'BTC-USD', 'changes': [['buy', '38301.04', '0.40135082']], 'time': '2021-05-20T03:56:02.160312Z'}
{'type': 'l2update', 'product_id': 'BTC-USD', 'changes': [['sell', '38351.55', '0.00000000']], 'time': '2021-05-20T03:56:02.181703Z'}
{'type': 'l2update', 'product_id': 'BTC-USD', 'changes': [['buy', '38306.48', '0.00000000']], 'time': '2021-05-20T03:56:02.182551Z'}
{'type': 'l2update', 'product_id': 'BTC-USD', 'changes': [['sell', '38437.01', '0.00000000']], 'time': '2021-05-20T03:56:02.190517Z'}
{'type': 'l2update', 'product_id': 'BTC-USD', 'changes': [['buy', '38327.38', '0.04983070']], 'time': '2021-05-20T03:56:02.191259Z'}
{'type': 'l2update', 'product_id': 'BTC-USD', 'changes': [['sell', '38449.76', '0.33744021']], 'time': '2021-05-20T03:56:02.191324Z'}
{'type': 'l2update', 'product_id': 'BTC-USD', 'changes': [['buy', '38300.97', '0.00000000']], 'time': '2021-05-20T03:56:02.200271Z'}
{'type': 'l2update', 'product_id': 'BTC-USD', 'changes': [['sell', '38367.65', '0.01000000']], 'time': '2021-05-20T03:56:02.212187Z'}
{'type': 'l2update', 'product_id': 'BTC-USD', 'changes': [['sell', '38334.30', '2.48969908']], 'time': '2021-05-20T03:56:02.215391Z'}
{'type': 'l2update', 'product_id': 'BTC-USD', 'changes': [['sell', '43100.00', '1.09530000']], 'time': '2021-05-20T03:56:02.215475Z'}
{'type': 'l2update', 'product_id': 'BTC-USD', 'changes': [['sell', '38419.45', '0.01000000']], 'time': '2021-05-20T03:56:02.224376Z'}
{'type': 'l2update', 'product_id': 'BTC-USD', 'changes': [['sell', '38416.01', '0.00000000']], 'time': '2021-05-20T03:56:02.228114Z'}
{'type': 'l2update', 'product_id': 'BTC-USD', 'changes': [['sell', '38399.48', '0.00000000']], 'time': '2021-05-20T03:56:02.228114Z'}
{'type': 'l2update', 'product_id': 'BTC-USD', 'changes': [['sell', '38394.35', '0.00000000']], 'time': '2021-05-20T03:56:02.228114Z'}
{'type': 'l2update', 'product_id': 'BTC-USD', 'changes': [['sell', '38384.66', '0.00000000']], 'time': '2021-05-20T03:56:02.228114Z'}
{'type': 'l2update', 'product_id': 'BTC-USD', 'changes': [['sell', '38846.76', '0.00000000']], 'time': '2021-05-20T03:56:02.228201Z'}
{'type': 'l2update', 'product_id': 'BTC-USD', 'changes': [['sell', '38395.51', '0.00000000']], 'time': '2021-05-20T03:56:02.232152Z'}
{'type': 'l2update', 'product_id': 'BTC-USD', 'changes': [['sell', '38374.70', '0.00000000']], 'time': '2021-05-20T03:56:02.232926Z'}
{'type': 'l2update', 'product_id': 'BTC-USD', 'changes': [['buy', '38322.12', '0.00000000']], 'time': '2021-05-20T03:56:02.237279Z'}
{'type': 'l2update', 'product_id': 'BTC-USD', 'changes': [['sell', '38355.42', '0.00000000']], 'time': '2021-05-20T03:56:02.239782Z'}
{'type': 'l2update', 'product_id': 'BTC-USD', 'changes': [['sell', '38333.25', '0.04905809']], 'time': '2021-05-20T03:56:02.250016Z'}
{'type': 'l2update', 'product_id': 'BTC-USD', 'changes': [['sell', '38333.25', '0.00000000']], 'time': '2021-05-20T03:56:02.251571Z'}
{'type': 'l2update', 'product_id': 'BTC-USD', 'changes': [['sell', '38333.65', '0.01492000']], 'time': '2021-05-20T03:56:02.253860Z'}
{'type': 'l2update', 'product_id': 'BTC-USD', 'changes': [['buy', '38323.72', '0.01492000']], 'time': '2021-05-20T03:56:02.257562Z'}
{'type': 'l2update', 'product_id': 'BTC-USD', 'changes': [['sell', '38363.74', '0.05000000']], 'time': '2021-05-20T03:56:02.274805Z'}
{'type': 'l2update', 'product_id': 'BTC-USD', 'changes': [['sell', '38499.89', '0.00000000']], 'time': '2021-05-20T03:56:02.276561Z'}
{'type': 'l2update', 'product_id': 'BTC-USD', 'changes': [['buy', '38160.65', '0.00000000']], 'time': '2021-05-20T03:56:02.282426Z'}
{'type': 'l2update', 'product_id': 'BTC-USD', 'changes': [['sell', '38336.96', '0.00000000']], 'time': '2021-05-20T03:56:02.287758Z'}
{'type': 'l2update', 'product_id': 'BTC-USD', 'changes': [['sell', '38367.51', '2.15600000']], 'time': '2021-05-20T03:56:02.289300Z'}
{'type': 'l2update', 'product_id': 'BTC-USD', 'changes': [['sell', '38449.56', '0.01000000']], 'time': '2021-05-20T03:56:02.294216Z'}
{'type': 'l2update', 'product_id': 'BTC-USD', 'changes': [['sell', '38456.80', '0.42322847']], 'time': '2021-05-20T03:56:02.294509Z'}
{'type': 'l2update', 'product_id': 'BTC-USD', 'changes': [['buy', '38314.68', '0.99440510']], 'time': '2021-05-20T03:56:02.310494Z'}
{'type': 'l2update', 'product_id': 'BTC-USD', 'changes': [['sell', '38336.95', '0.00000000']], 'time': '2021-05-20T03:56:02.320191Z'}
{'type': 'l2update', 'product_id': 'BTC-USD', 'changes': [['sell', '43100.00', '2.87630000']], 'time': '2021-05-20T03:56:02.320655Z'}
{'type': 'l2update', 'product_id': 'BTC-USD', 'changes': [['buy', '38285.25', '0.01000000']], 'time': '2021-05-20T03:56:02.321110Z'}
{'type': 'l2update', 'product_id': 'BTC-USD', 'changes': [['sell', '38468.33', '0.00000000']], 'time': '2021-05-20T03:56:02.321860Z'}
{'type': 'l2update', 'product_id': 'BTC-USD', 'changes': [['sell', '38440.75', '0.00000000']], 'time': '2021-05-20T03:56:02.321860Z'}
{'type': 'l2update', 'product_id': 'BTC-USD', 'changes': [['sell', '38433.26', '0.00000000']], 'time': '2021-05-20T03:56:02.321860Z'}
{'type': 'l2update', 'product_id': 'BTC-USD', 'changes': [['buy', '38318.13', '0.09000000']], 'time': '2021-05-20T03:56:02.323919Z'}
{'type': 'l2update', 'product_id': 'BTC-USD', 'changes': [['buy', '38322.13', '0.00000000']], 'time': '2021-05-20T03:56:02.328273Z'}
{'type': 'l2update', 'product_id': 'BTC-USD', 'changes': [['buy', '38323.38', '0.00000000']], 'time': '2021-05-20T03:56:02.332399Z'}
{'type': 'l2update', 'product_id': 'BTC-USD', 'changes': [['buy', '38023.31', '0.00000000']], 'time': '2021-05-20T03:56:02.332652Z'}
{'type': 'l2update', 'product_id': 'BTC-USD', 'changes': [['buy', '38323.72', '0.00000000']], 'time': '2021-05-20T03:56:02.337109Z'}
{'type': 'l2update', 'product_id': 'BTC-USD', 'changes': [['buy', '38300.99', '0.06520888']], 'time': '2021-05-20T03:56:02.337912Z'}
{'type': 'l2update', 'product_id': 'BTC-USD', 'changes': [['sell', '38344.93', '0.50000000']], 'time': '2021-05-20T03:56:02.338587Z'}
{'type': 'l2update', 'product_id': 'BTC-USD', 'changes': [['sell', '38333.65', '0.00000000']], 'time': '2021-05-20T03:56:02.341238Z'}
{'type': 'l2update', 'product_id': 'BTC-USD', 'changes': [['sell', '38363.74', '0.00000000']], 'time': '2021-05-20T03:56:02.344927Z'}
{'type': 'l2update', 'product_id': 'BTC-USD', 'changes': [['buy', '38275.28', '0.00000000']], 'time': '2021-05-20T03:56:02.356374Z'}
{'type': 'l2update', 'product_id': 'BTC-USD', 'changes': [['sell', '38334.30', '0.00000000']], 'time': '2021-05-20T03:56:02.358410Z'}
{'type': 'l2update', 'product_id': 'BTC-USD', 'changes': [['sell', '38464.03', '0.36044685']], 'time': '2021-05-20T03:56:02.361350Z'}
{'type': 'l2update', 'product_id': 'BTC-USD', 'changes': [['buy', '38323.15', '0.00000000']], 'time': '2021-05-20T03:56:02.362095Z'}
{'type': 'l2update', 'product_id': 'BTC-USD', 'changes': [['buy', '38245.16', '0.00000000']], 'time': '2021-05-20T03:56:02.364998Z'}
{'type': 'l2update', 'product_id': 'BTC-USD', 'changes': [['sell', '38360.92', '0.00000000']], 'time': '2021-05-20T03:56:02.365348Z'}
{'type': 'l2update', 'product_id': 'BTC-USD', 'changes': [['buy', '38309.46', '0.52197214']], 'time': '2021-05-20T03:56:02.366615Z'}
{'type': 'l2update', 'product_id': 'BTC-USD', 'changes': [['sell', '38569.63', '0.00000000']], 'time': '2021-05-20T03:56:02.368660Z'}
{'type': 'l2update', 'product_id': 'BTC-USD', 'changes': [['buy', '38301.04', '0.00000000']], 'time': '2021-05-20T03:56:02.371678Z'}
{'type': 'l2update', 'product_id': 'BTC-USD', 'changes': [['sell', '38419.45', '0.00000000']], 'time': '2021-05-20T03:56:02.371779Z'}
{'type': 'l2update', 'product_id': 'BTC-USD', 'changes': [['sell', '38344.93', '0.00000000']], 'time': '2021-05-20T03:56:02.380194Z'}
{'type': 'l2update', 'product_id': 'BTC-USD', 'changes': [['buy', '38290.23', '0.00000000']], 'time': '2021-05-20T03:56:02.381688Z'}
{'type': 'l2update', 'product_id': 'BTC-USD', 'changes': [['sell', '38647.42', '3.87469565']], 'time': '2021-05-20T03:56:02.384032Z'}
{'type': 'l2update', 'product_id': 'BTC-USD', 'changes': [['sell', '38846.76', '2.58313679']], 'time': '2021-05-20T03:56:02.384032Z'}
{'type': 'l2update', 'product_id': 'BTC-USD', 'changes': [['sell', '38355.41', '0.05000000']], 'time': '2021-05-20T03:56:02.401034Z'}
{'type': 'l2update', 'product_id': 'BTC-USD', 'changes': [['sell', '38482.73', '0.01000000']], 'time': '2021-05-20T03:56:02.401069Z'}
{'type': 'l2update', 'product_id': 'BTC-USD', 'changes': [['sell', '38410.98', '0.02603422']], 'time': '2021-05-20T03:56:02.401654Z'}
{'type': 'l2update', 'product_id': 'BTC-USD', 'changes': [['sell', '38449.85', '0.00000000']], 'time': '2021-05-20T03:56:02.403040Z'}
{'type': 'l2update', 'product_id': 'BTC-USD', 'changes': [['sell', '38375.49', '0.67468711']], 'time': '2021-05-20T03:56:02.403440Z'}
{'type': 'l2update', 'product_id': 'BTC-USD', 'changes': [['buy', '38174.71', '0.00000000']], 'time': '2021-05-20T03:56:02.403440Z'}
{'type': 'l2update', 'product_id': 'BTC-USD', 'changes': [['buy', '38181.38', '0.00000000']], 'time': '2021-05-20T03:56:02.403440Z'}
{'type': 'l2update', 'product_id': 'BTC-USD', 'changes': [['buy', '38188.52', '0.00000000']], 'time': '2021-05-20T03:56:02.403440Z'}
{'type': 'l2update', 'product_id': 'BTC-USD', 'changes': [['buy', '38194.62', '0.37661801']], 'time': '2021-05-20T03:56:02.403440Z'}
{'type': 'l2update', 'product_id': 'BTC-USD', 'changes': [['buy', '38194.62', '0.00000000']], 'time': '2021-05-20T03:56:02.403440Z'}
{'type': 'l2update', 'product_id': 'BTC-USD', 'changes': [['buy', '38224.22', '0.00000000']], 'time': '2021-05-20T03:56:02.403630Z'}
{'type': 'l2update', 'product_id': 'BTC-USD', 'changes': [['buy', '38227.55', '0.00000000']], 'time': '2021-05-20T03:56:02.403630Z'}
{'type': 'l2update', 'product_id': 'BTC-USD', 'changes': [['buy', '38239.48', '0.00000000']], 'time': '2021-05-20T03:56:02.403630Z'}
{'type': 'l2update', 'product_id': 'BTC-USD', 'changes': [['buy', '38255.95', '0.00000000']], 'time': '2021-05-20T03:56:02.403630Z'}
{'type': 'l2update', 'product_id': 'BTC-USD', 'changes': [['sell', '38337.78', '0.00000000']], 'time': '2021-05-20T03:56:02.406954Z'}
{'type': 'l2update', 'product_id': 'BTC-USD', 'changes': [['buy', '38327.74', '0.01492000']], 'time': '2021-05-20T03:56:02.409328Z'}
{'type': 'l2update', 'product_id': 'BTC-USD', 'changes': [['buy', '38306.80', '0.52200564']], 'time': '2021-05-20T03:56:02.409653Z'}
{'type': 'l2update', 'product_id': 'BTC-USD', 'changes': [['buy', '38048.73', '0.01000000']], 'time': '2021-05-20T03:56:02.409765Z'}
{'type': 'l2update', 'product_id': 'BTC-USD', 'changes': [['sell', '38362.16', '0.39490432']], 'time': '2021-05-20T03:56:02.409814Z'}
{'type': 'l2update', 'product_id': 'BTC-USD', 'changes': [['sell', '38337.32', '0.00607145']], 'time': '2021-05-20T03:56:02.410267Z'}
{'type': 'l2update', 'product_id': 'BTC-USD', 'changes': [['buy', '38327.65', '0.07460000']], 'time': '2021-05-20T03:56:02.410299Z'}
{'type': 'l2update', 'product_id': 'BTC-USD', 'changes': [['sell', '38363.25', '0.01000000']], 'time': '2021-05-20T03:56:02.411159Z'}
{'type': 'l2update', 'product_id': 'BTC-USD', 'changes': [['sell', '38337.46', '0.07460000']], 'time': '2021-05-20T03:56:02.411227Z'}
{'type': 'l2update', 'product_id': 'BTC-USD', 'changes': [['sell', '38444.80', '0.01000000']], 'time': '2021-05-20T03:56:02.413841Z'}
{'type': 'l2update', 'product_id': 'BTC-USD', 'changes': [['buy', '38295.21', '0.46337026']], 'time': '2021-05-20T03:56:02.414019Z'}
{'type': 'l2update', 'product_id': 'BTC-USD', 'changes': [['sell', '38435.12', '0.00000000']], 'time': '2021-05-20T03:56:02.417329Z'}
{'type': 'l2update', 'product_id': 'BTC-USD', 'changes': [['sell', '38342.86', '2.48969908']], 'time': '2021-05-20T03:56:02.425266Z'}
{'type': 'l2update', 'product_id': 'BTC-USD', 'changes': [['sell', '38349.04', '0.50000000']], 'time': '2021-05-20T03:56:02.425457Z'}
{'type': 'l2update', 'product_id': 'BTC-USD', 'changes': [['sell', '38380.00', '0.00000000']], 'time': '2021-05-20T03:56:02.427221Z'}
{'type': 'l2update', 'product_id': 'BTC-USD', 'changes': [['buy', '38265.99', '0.00000000']], 'time': '2021-05-20T03:56:02.427774Z'}
{'type': 'l2update', 'product_id': 'BTC-USD', 'changes': [['buy', '38327.43', '0.84600000']], 'time': '2021-05-20T03:56:02.437546Z'}
{'type': 'l2update', 'product_id': 'BTC-USD', 'changes': [['buy', '38288.88', '0.01173710']], 'time': '2021-05-20T03:56:02.437574Z'}
{'type': 'l2update', 'product_id': 'BTC-USD', 'changes': [['buy', '38288.94', '0.00000000']], 'time': '2021-05-20T03:56:02.439113Z'}
{'type': 'l2update', 'product_id': 'BTC-USD', 'changes': [['sell', '38337.32', '0.00000000']], 'time': '2021-05-20T03:56:02.439764Z'}
{'type': 'l2update', 'product_id': 'BTC-USD', 'changes': [['buy', '38327.65', '0.00000000']], 'time': '2021-05-20T03:56:02.441197Z'}
{'type': 'l2update', 'product_id': 'BTC-USD', 'changes': [['sell', '38337.46', '0.00000000']], 'time': '2021-05-20T03:56:02.441288Z'}
{'type': 'l2update', 'product_id': 'BTC-USD', 'changes': [['sell', '38433.59', '0.00000000']], 'time': '2021-05-20T03:56:02.441705Z'}
{'type': 'l2update', 'product_id': 'BTC-USD', 'changes': [['sell', '38418.33', '0.14700000']], 'time': '2021-05-20T03:56:02.442474Z'}
{'type': 'l2update', 'product_id': 'BTC-USD', 'changes': [['buy', '37529.31', '0.06322192']], 'time': '2021-05-20T03:56:02.445102Z'}
{'type': 'l2update', 'product_id': 'BTC-USD', 'changes': [['sell', '38637.83', '0.00647034']], 'time': '2021-05-20T03:56:02.445517Z'}
{'type': 'l2update', 'product_id': 'BTC-USD', 'changes': [['sell', '38342.29', '0.00884855']], 'time': '2021-05-20T03:56:02.445569Z'}
{'type': 'l2update', 'product_id': 'BTC-USD', 'changes': [['buy', '38303.90', '0.52204495']], 'time': '2021-05-20T03:56:02.445635Z'}
{'type': 'l2update', 'product_id': 'BTC-USD', 'changes': [['sell', '38355.41', '0.00000000']], 'time': '2021-05-20T03:56:02.447645Z'}
{'type': 'l2update', 'product_id': 'BTC-USD', 'changes': [['sell', '38370.84', '0.05000000']], 'time': '2021-05-20T03:56:02.450704Z'}
{'type': 'l2update', 'product_id': 'BTC-USD', 'changes': [['buy', '38300.98', '0.00000000']], 'time': '2021-05-20T03:56:02.450892Z'}
{'type': 'l2update', 'product_id': 'BTC-USD', 'changes': [['sell', '38334.29', '0.18981474']], 'time': '2021-05-20T03:56:02.455441Z'}
{'type': 'l2update', 'product_id': 'BTC-USD', 'changes': [['sell', '38395.06', '0.61482417']], 'time': '2021-05-20T03:56:02.463068Z'}
{'type': 'l2update', 'product_id': 'BTC-USD', 'changes': [['sell', '38514.36', '0.30079538']], 'time': '2021-05-20T03:56:02.463189Z'}
{'type': 'l2update', 'product_id': 'BTC-USD', 'changes': [['buy', '38120.18', '0.00000000']], 'time': '2021-05-20T03:56:02.466601Z'}
{'type': 'l2update', 'product_id': 'BTC-USD', 'changes': [['buy', '38289.75', '0.00000000']], 'time': '2021-05-20T03:56:02.467291Z'}
{'type': 'l2update', 'product_id': 'BTC-USD', 'changes': [['sell', '38433.26', '0.02770418']], 'time': '2021-05-20T03:56:02.468643Z'}
{'type': 'l2update', 'product_id': 'BTC-USD', 'changes': [['sell', '38471.69', '0.30612898']], 'time': '2021-05-20T03:56:02.468693Z'}
{'type': 'l2update', 'product_id': 'BTC-USD', 'changes': [['buy', '38200.03', '0.30612898']], 'time': '2021-05-20T03:56:02.468693Z'}
{'type': 'l2update', 'product_id': 'BTC-USD', 'changes': [['sell', '38367.65', '0.00000000']], 'time': '2021-05-20T03:56:02.469994Z'}
{'type': 'l2update', 'product_id': 'BTC-USD', 'changes': [['sell', '38342.29', '0.00000000']], 'time': '2021-05-20T03:56:02.473562Z'}
{'type': 'l2update', 'product_id': 'BTC-USD', 'changes': [['buy', '38321.98', '0.00300000']], 'time': '2021-05-20T03:56:02.476795Z'}
{'type': 'l2update', 'product_id': 'BTC-USD', 'changes': [['sell', '38354.91', '0.00000000']], 'time': '2021-05-20T03:56:02.476883Z'}
{'type': 'l2update', 'product_id': 'BTC-USD', 'changes': [['sell', '38488.26', '0.01299097']], 'time': '2021-05-20T03:56:02.477407Z'}
{'type': 'l2update', 'product_id': 'BTC-USD', 'changes': [['sell', '38342.48', '0.00607145']], 'time': '2021-05-20T03:56:02.481772Z'}
{'type': 'l2update', 'product_id': 'BTC-USD', 'changes': [['buy', '38292.96', '0.52208978']], 'time': '2021-05-20T03:56:02.482102Z'}
{'type': 'l2update', 'product_id': 'BTC-USD', 'changes': [['buy', '38314.69', '0.46620000']], 'time': '2021-05-20T03:56:02.482128Z'}
{'type': 'l2update', 'product_id': 'BTC-USD', 'changes': [['sell', '38362.15', '0.05000000']], 'time': '2021-05-20T03:56:02.482145Z'}
{'type': 'l2update', 'product_id': 'BTC-USD', 'changes': [['sell', '38342.51', '0.07460000']], 'time': '2021-05-20T03:56:02.482742Z'}
{'type': 'l2update', 'product_id': 'BTC-USD', 'changes': [['buy', '38328.31', '0.07460000']], 'time': '2021-05-20T03:56:02.482775Z'}
{'type': 'l2update', 'product_id': 'BTC-USD', 'changes': [['sell', '38362.16', '0.00000000']], 'time': '2021-05-20T03:56:02.483726Z'}
{'type': 'l2update', 'product_id': 'BTC-USD', 'changes': [['buy', '38327.74', '0.00000000']], 'time': '2021-05-20T03:56:02.484781Z'}
{'type': 'l2update', 'product_id': 'BTC-USD', 'changes': [['buy', '38293.70', '2.37600000']], 'time': '2021-05-20T03:56:02.488751Z'}
{'type': 'l2update', 'product_id': 'BTC-USD', 'changes': [['sell', '38410.65', '0.01000000']], 'time': '2021-05-20T03:56:02.490250Z'}
{'type': 'l2update', 'product_id': 'BTC-USD', 'changes': [['buy', '38314.72', '0.40135082']], 'time': '2021-05-20T03:56:02.490386Z'}
{'type': 'l2update', 'product_id': 'BTC-USD', 'changes': [['sell', '38349.04', '0.00000000']], 'time': '2021-05-20T03:56:02.491806Z'}
{'type': 'l2update', 'product_id': 'BTC-USD', 'changes': [['sell', '38514.36', '0.00000000']], 'time': '2021-05-20T03:56:02.491903Z'}
{'type': 'l2update', 'product_id': 'BTC-USD', 'changes': [['buy', '38327.43', '0.00000000']], 'time': '2021-05-20T03:56:02.492317Z'}
{'type': 'l2update', 'product_id': 'BTC-USD', 'changes': [['buy', '38290.55', '0.00000000']], 'time': '2021-05-20T03:56:02.494410Z'}
{'type': 'l2update', 'product_id': 'BTC-USD', 'changes': [['sell', '38404.81', '0.40516276']], 'time': '2021-05-20T03:56:02.494708Z'}
{'type': 'l2update', 'product_id': 'BTC-USD', 'changes': [['sell', '38478.45', '0.00000000']], 'time': '2021-05-20T03:56:02.497405Z'}
{'type': 'l2update', 'product_id': 'BTC-USD', 'changes': [['buy', '38285.25', '0.00000000']], 'time': '2021-05-20T03:56:02.498176Z'}
{'type': 'l2update', 'product_id': 'BTC-USD', 'changes': [['sell', '38354.94', '0.00000000']], 'time': '2021-05-20T03:56:02.502569Z'}
{'type': 'l2update', 'product_id': 'BTC-USD', 'changes': [['sell', '38447.41', '0.05939612']], 'time': '2021-05-20T03:56:02.504640Z'}
{'type': 'l2update', 'product_id': 'BTC-USD', 'changes': [['buy', '38245.16', '0.02604873']], 'time': '2021-05-20T03:56:02.504640Z'}
{'type': 'l2update', 'product_id': 'BTC-USD', 'changes': [['buy', '38251.80', '0.03164762']], 'time': '2021-05-20T03:56:02.504640Z'}
{'type': 'l2update', 'product_id': 'BTC-USD', 'changes': [['sell', '38342.51', '0.00000000']], 'time': '2021-05-20T03:56:02.512088Z'}
{'type': 'l2update', 'product_id': 'BTC-USD', 'changes': [['buy', '38328.31', '0.00000000']], 'time': '2021-05-20T03:56:02.512669Z'}
{'type': 'l2update', 'product_id': 'BTC-USD', 'changes': [['sell', '38342.48', '0.00000000']], 'time': '2021-05-20T03:56:02.515594Z'}
{'type': 'l2update', 'product_id': 'BTC-USD', 'changes': [['sell', '38481.15', '0.01272581']], 'time': '2021-05-20T03:56:02.517890Z'}
{'type': 'l2update', 'product_id': 'BTC-USD', 'changes': [['sell', '38343.71', '0.05032884']], 'time': '2021-05-20T03:56:02.518034Z'}
{'type': 'l2update', 'product_id': 'BTC-USD', 'changes': [['buy', '38282.28', '1.30502491']], 'time': '2021-05-20T03:56:02.519335Z'}
{'type': 'l2update', 'product_id': 'BTC-USD', 'changes': [['sell', '38360.29', '0.41470000']], 'time': '2021-05-20T03:56:02.519411Z'}
{'type': 'l2update', 'product_id': 'BTC-USD', 'changes': [['buy', '38218.02', '0.00000000']], 'time': '2021-05-20T03:56:02.520007Z'}
{'type': 'l2update', 'product_id': 'BTC-USD', 'changes': [['sell', '38342.87', '0.00000000']], 'time': '2021-05-20T03:56:02.522607Z'}
{'type': 'l2update', 'product_id': 'BTC-USD', 'changes': [['sell', '38428.70', '0.02400000']], 'time': '2021-05-20T03:56:02.524290Z'}
{'type': 'l2update', 'product_id': 'BTC-USD', 'changes': [['buy', '38136.24', '0.02622177']], 'time': '2021-05-20T03:56:02.530873Z'}
{'type': 'l2update', 'product_id': 'BTC-USD', 'changes': [['buy', '38334.28', '0.00315085']], 'time': '2021-05-20T03:56:02.532221Z'}
{'type': 'l2update', 'product_id': 'BTC-USD', 'changes': [['buy', '38214.87', '0.00000000']], 'time': '2021-05-20T03:56:02.536558Z'}
{'type': 'l2update', 'product_id': 'BTC-USD', 'changes': [['buy', '38221.30', '0.00000000']], 'time': '2021-05-20T03:56:02.536558Z'}
{'type': 'l2update', 'product_id': 'BTC-USD', 'changes': [['sell', '38475.71', '0.37009745']], 'time': '2021-05-20T03:56:02.536975Z'}
{'type': 'l2update', 'product_id': 'BTC-USD', 'changes': [['buy', '38236.49', '0.37009745']], 'time': '2021-05-20T03:56:02.536975Z'}
{'type': 'l2update', 'product_id': 'BTC-USD', 'changes': [['sell', '38353.42', '0.50000000']], 'time': '2021-05-20T03:56:02.537416Z'}
{'type': 'l2update', 'product_id': 'BTC-USD', 'changes': [['buy', '38315.20', '0.01000000']], 'time': '2021-05-20T03:56:02.538778Z'}
{'type': 'l2update', 'product_id': 'BTC-USD', 'changes': [['sell', '38449.56', '0.00000000']], 'time': '2021-05-20T03:56:02.540593Z'}
{'type': 'l2update', 'product_id': 'BTC-USD', 'changes': [['sell', '38495.38', '0.01000000']], 'time': '2021-05-20T03:56:02.545650Z'}
{'type': 'l2update', 'product_id': 'BTC-USD', 'changes': [['buy', '38303.99', '0.05354295']], 'time': '2021-05-20T03:56:02.545711Z'}
{'type': 'l2update', 'product_id': 'BTC-USD', 'changes': [['sell', '38345.30', '0.05996573']], 'time': '2021-05-20T03:56:02.545711Z'}
{'type': 'l2update', 'product_id': 'BTC-USD', 'changes': [['buy', '38322.63', '0.84600000']], 'time': '2021-05-20T03:56:02.545825Z'}
{'type': 'l2update', 'product_id': 'BTC-USD', 'changes': [['sell', '38373.11', '0.01000000']], 'time': '2021-05-20T03:56:02.545997Z'}
{'type': 'l2update', 'product_id': 'BTC-USD', 'changes': [['buy', '38313.18', '0.02400000']], 'time': '2021-05-20T03:56:02.546027Z'}
{'type': 'l2update', 'product_id': 'BTC-USD', 'changes': [['buy', '38312.37', '0.02400000']], 'time': '2021-05-20T03:56:02.546027Z'}
{'type': 'l2update', 'product_id': 'BTC-USD', 'changes': [['buy', '38311.57', '0.02400000']], 'time': '2021-05-20T03:56:02.546027Z'}
{'type': 'l2update', 'product_id': 'BTC-USD', 'changes': [['buy', '38327.75', '0.10516754']], 'time': '2021-05-20T03:56:02.549932Z'}
{'type': 'l2update', 'product_id': 'BTC-USD', 'changes': [['buy', '38314.69', '0.00000000']], 'time': '2021-05-20T03:56:02.552958Z'}
{'type': 'l2update', 'product_id': 'BTC-USD', 'changes': [['sell', '38467.39', '0.00000000']], 'time': '2021-05-20T03:56:02.554428Z'}
{'type': 'l2update', 'product_id': 'BTC-USD', 'changes': [['sell', '38647.42', '0.64577390']], 'time': '2021-05-20T03:56:02.556509Z'}
{'type': 'l2update', 'product_id': 'BTC-USD', 'changes': [['buy', '38273.10', '2.61014878']], 'time': '2021-05-20T03:56:02.561218Z'}
{'type': 'l2update', 'product_id': 'BTC-USD', 'changes': [['sell', '38362.15', '0.00000000']], 'time': '2021-05-20T03:56:02.561390Z'}
{'type': 'l2update', 'product_id': 'BTC-USD', 'changes': [['sell', '38363.74', '0.06520888']], 'time': '2021-05-20T03:56:02.562938Z'}
{'type': 'l2update', 'product_id': 'BTC-USD', 'changes': [['sell', '38367.51', '0.00000000']], 'time': '2021-05-20T03:56:02.566733Z'}
{'type': 'l2update', 'product_id': 'BTC-USD', 'changes': [['buy', '38334.28', '0.07775085']], 'time': '2021-05-20T03:56:02.571403Z'}
{'type': 'l2update', 'product_id': 'BTC-USD', 'changes': [['sell', '38447.41', '0.08557085']], 'time': '2021-05-20T03:56:02.571634Z'}
{'type': 'l2update', 'product_id': 'BTC-USD', 'changes': [['buy', '38312.37', '0.00000000']], 'time': '2021-05-20T03:56:02.575459Z'}
{'type': 'l2update', 'product_id': 'BTC-USD', 'changes': [['buy', '38311.57', '0.00000000']], 'time': '2021-05-20T03:56:02.575459Z'}
{'type': 'l2update', 'product_id': 'BTC-USD', 'changes': [['sell', '38437.36', '0.01000000']], 'time': '2021-05-20T03:56:02.577688Z'}
{'type': 'l2update', 'product_id': 'BTC-USD', 'changes': [['sell', '38471.69', '0.71459343']], 'time': '2021-05-20T03:56:02.577952Z'}
{'type': 'l2update', 'product_id': 'BTC-USD', 'changes': [['buy', '38224.52', '0.40846445']], 'time': '2021-05-20T03:56:02.577952Z'}
{'type': 'l2update', 'product_id': 'BTC-USD', 'changes': [['sell', '38647.43', '0.00000000']], 'time': '2021-05-20T03:56:02.578008Z'}
{'type': 'l2update', 'product_id': 'BTC-USD', 'changes': [['buy', '38183.77', '0.00000000']], 'time': '2021-05-20T03:56:02.578032Z'}
{'type': 'l2update', 'product_id': 'BTC-USD', 'changes': [['buy', '38290.70', '0.01000000']], 'time': '2021-05-20T03:56:02.586045Z'}
{'type': 'l2update', 'product_id': 'BTC-USD', 'changes': [['sell', '38360.28', '0.05000000']], 'time': '2021-05-20T03:56:02.596555Z'}
{'type': 'l2update', 'product_id': 'BTC-USD', 'changes': [['buy', '38272.21', '2.61028511']], 'time': '2021-05-20T03:56:02.596660Z'}
{'type': 'l2update', 'product_id': 'BTC-USD', 'changes': [['buy', '38288.88', '0.00000000']], 'time': '2021-05-20T03:56:02.604061Z'}
{'type': 'l2update', 'product_id': 'BTC-USD', 'changes': [['buy', '38313.18', '0.00000000']], 'time': '2021-05-20T03:56:02.604384Z'}
{'type': 'l2update', 'product_id': 'BTC-USD', 'changes': [['buy', '38292.51', '0.00000000']], 'time': '2021-05-20T03:56:02.615563Z'}
{'type': 'l2update', 'product_id': 'BTC-USD', 'changes': [['sell', '38334.29', '0.00000000']], 'time': '2021-05-20T03:56:02.615801Z'}
{'type': 'l2update', 'product_id': 'BTC-USD', 'changes': [['buy', '38214.88', '0.41322041']], 'time': '2021-05-20T03:56:02.617664Z'}
{'type': 'l2update', 'product_id': 'BTC-USD', 'changes': [['sell', '38363.76', '0.00000000']], 'time': '2021-05-20T03:56:02.623090Z'}
{'type': 'l2update', 'product_id': 'BTC-USD', 'changes': [['buy', '38313.02', '0.05000000']], 'time': '2021-05-20T03:56:02.630886Z'}
{'type': 'l2update', 'product_id': 'BTC-USD', 'changes': [['sell', '38447.41', '0.11532767']], 'time': '2021-05-20T03:56:02.631131Z'}
{'type': 'l2update', 'product_id': 'BTC-USD', 'changes': [['buy', '38334.28', '0.00315085']], 'time': '2021-05-20T03:56:02.643615Z'}
{'type': 'l2update', 'product_id': 'BTC-USD', 'changes': [['buy', '38048.73', '0.00000000']], 'time': '2021-05-20T03:56:02.645362Z'}
{'type': 'l2update', 'product_id': 'BTC-USD', 'changes': [['sell', '38343.71', '0.00000000']], 'time': '2021-05-20T03:56:02.649036Z'}
{'type': 'l2update', 'product_id': 'BTC-USD', 'changes': [['sell', '38495.38', '0.00000000']], 'time': '2021-05-20T03:56:02.650123Z'}
{'type': 'l2update', 'product_id': 'BTC-USD', 'changes': [['sell', '38342.32', '0.07460000']], 'time': '2021-05-20T03:56:02.651935Z'}
{'type': 'l2update', 'product_id': 'BTC-USD', 'changes': [['sell', '38342.26', '0.01492000']], 'time': '2021-05-20T03:56:02.652004Z'}
{'type': 'l2update', 'product_id': 'BTC-USD', 'changes': [['buy', '38208.07', '0.30441818']], 'time': '2021-05-20T03:56:02.652307Z'}
{'type': 'l2update', 'product_id': 'BTC-USD', 'changes': [['buy', '38300.96', '0.00000000']], 'time': '2021-05-20T03:56:02.652715Z'}
{'type': 'l2update', 'product_id': 'BTC-USD', 'changes': [['sell', '38437.36', '0.00000000']], 'time': '2021-05-20T03:56:02.653675Z'}
{'type': 'l2update', 'product_id': 'BTC-USD', 'changes': [['buy', '38300.99', '0.00000000']], 'time': '2021-05-20T03:56:02.653832Z'}
{'type': 'l2update', 'product_id': 'BTC-USD', 'changes': [['buy', '38263.51', '0.00000000']], 'time': '2021-05-20T03:56:02.654780Z'}
{'type': 'l2update', 'product_id': 'BTC-USD', 'changes': [['buy', '38172.86', '0.04824263']], 'time': '2021-05-20T03:56:02.656463Z'}
{'type': 'l2update', 'product_id': 'BTC-USD', 'changes': [['buy', '38303.91', '0.06520888']], 'time': '2021-05-20T03:56:02.657048Z'}
{'type': 'l2update', 'product_id': 'BTC-USD', 'changes': [['sell', '38370.89', '0.04841588']], 'time': '2021-05-20T03:56:02.657063Z'}
{'type': 'l2update', 'product_id': 'BTC-USD', 'changes': [['buy', '38314.68', '0.00000000']], 'time': '2021-05-20T03:56:02.657216Z'}
{'type': 'l2update', 'product_id': 'BTC-USD', 'changes': [['sell', '38371.70', '0.02000000']], 'time': '2021-05-20T03:56:02.660787Z'}
{'type': 'l2update', 'product_id': 'BTC-USD', 'changes': [['sell', '38457.03', '0.03318340']], 'time': '2021-05-20T03:56:02.661089Z'}
{'type': 'l2update', 'product_id': 'BTC-USD', 'changes': [['buy', '38311.71', '0.02400000']], 'time': '2021-05-20T03:56:02.664443Z'}
{'type': 'l2update', 'product_id': 'BTC-USD', 'changes': [['buy', '38310.90', '0.02400000']], 'time': '2021-05-20T03:56:02.664443Z'}
{'type': 'l2update', 'product_id': 'BTC-USD', 'changes': [['buy', '38310.10', '0.02400000']], 'time': '2021-05-20T03:56:02.664443Z'}
{'type': 'l2update', 'product_id': 'BTC-USD', 'changes': [['buy', '38310.39', '0.44810000']], 'time': '2021-05-20T03:56:02.670324Z'}
{'type': 'l2update', 'product_id': 'BTC-USD', 'changes': [['sell', '38494.19', '0.01000000']], 'time': '2021-05-20T03:56:02.670668Z'}
{'type': 'l2update', 'product_id': 'BTC-USD', 'changes': [['buy', '38301.20', '0.01182167']], 'time': '2021-05-20T03:56:02.672633Z'}
{'type': 'l2update', 'product_id': 'BTC-USD', 'changes': [['buy', '38334.28', '0.00000000']], 'time': '2021-05-20T03:56:02.674812Z'}
{'type': 'l2update', 'product_id': 'BTC-USD', 'changes': [['buy', '38068.65', '0.01000000']], 'time': '2021-05-20T03:56:02.676813Z'}
{'type': 'l2update', 'product_id': 'BTC-USD', 'changes': [['buy', '38328.07', '0.01176915']], 'time': '2021-05-20T03:56:02.678583Z'}
{'type': 'l2update', 'product_id': 'BTC-USD', 'changes': [['sell', '38342.85', '1.18818641']], 'time': '2021-05-20T03:56:02.678912Z'}
{'type': 'l2update', 'product_id': 'BTC-USD', 'changes': [['buy', '37529.31', '0.00000000']], 'time': '2021-05-20T03:56:02.679018Z'}
{'type': 'l2update', 'product_id': 'BTC-USD', 'changes': [['sell', '38462.13', '0.01000000']], 'time': '2021-05-20T03:56:02.681828Z'}
{'type': 'l2update', 'product_id': 'BTC-USD', 'changes': [['buy', '38312.61', '0.38100000']], 'time': '2021-05-20T03:56:02.681939Z'}
{'type': 'l2update', 'product_id': 'BTC-USD', 'changes': [['sell', '38475.71', '0.78116150']], 'time': '2021-05-20T03:56:02.682083Z'}
{'type': 'l2update', 'product_id': 'BTC-USD', 'changes': [['buy', '38201.07', '0.41106405']], 'time': '2021-05-20T03:56:02.682083Z'}
{'type': 'l2update', 'product_id': 'BTC-USD', 'changes': [['sell', '38400.01', '0.21100000']], 'time': '2021-05-20T03:56:02.682168Z'}
{'type': 'l2update', 'product_id': 'BTC-USD', 'changes': [['buy', '38328.43', '0.07460000']], 'time': '2021-05-20T03:56:02.682441Z'}
{'type': 'l2update', 'product_id': 'BTC-USD', 'changes': [['sell', '38426.64', '0.00000000']], 'time': '2021-05-20T03:56:02.683919Z'}
{'type': 'l2update', 'product_id': 'BTC-USD', 'changes': [['sell', '38367.51', '2.21800000']], 'time': '2021-05-20T03:56:02.687016Z'}
{'type': 'l2update', 'product_id': 'BTC-USD', 'changes': [['buy', '38287.49', '0.10000000']], 'time': '2021-05-20T03:56:02.687123Z'}
{'type': 'l2update', 'product_id': 'BTC-USD', 'changes': [['sell', '38454.31', '0.01000000']], 'time': '2021-05-20T03:56:02.687436Z'}
{'type': 'l2update', 'product_id': 'BTC-USD', 'changes': [['sell', '38371.70', '0.05000000']], 'time': '2021-05-20T03:56:02.691960Z'}
{'type': 'l2update', 'product_id': 'BTC-USD', 'changes': [['sell', '38488.51', '0.00000000']], 'time': '2021-05-20T03:56:02.693041Z'}
{'type': 'l2update', 'product_id': 'BTC-USD', 'changes': [['sell', '38447.15', '0.03649767']], 'time': '2021-05-20T03:56:02.696651Z'}
{'type': 'l2update', 'product_id': 'BTC-USD', 'changes': [['buy', '38310.39', '0.00000000']], 'time': '2021-05-20T03:56:02.696688Z'}
{'type': 'l2update', 'product_id': 'BTC-USD', 'changes': [['sell', '38342.26', '0.00000000']], 'time': '2021-05-20T03:56:02.698521Z'}
{'type': 'l2update', 'product_id': 'BTC-USD', 'changes': [['buy', '38322.64', '0.99440510']], 'time': '2021-05-20T03:56:02.699901Z'}
{'type': 'l2update', 'product_id': 'BTC-USD', 'changes': [['sell', '38360.28', '0.00000000']], 'time': '2021-05-20T03:56:02.703929Z'}
{'type': 'l2update', 'product_id': 'BTC-USD', 'changes': [['sell', '38342.32', '0.00000000']], 'time': '2021-05-20T03:56:02.704542Z'}
{'type': 'l2update', 'product_id': 'BTC-USD', 'changes': [['buy', '38328.07', '0.01492000']], 'time': '2021-05-20T03:56:02.708121Z'}
{'type': 'l2update', 'product_id': 'BTC-USD', 'changes': [['buy', '38328.43', '0.02755319']], 'time': '2021-05-20T03:56:02.708173Z'}
{'type': 'l2update', 'product_id': 'BTC-USD', 'changes': [['buy', '38328.07', '0.00315085']], 'time': '2021-05-20T03:56:02.709397Z'}
{'type': 'l2update', 'product_id': 'BTC-USD', 'changes': [['sell', '38493.69', '0.00000000']], 'time': '2021-05-20T03:56:02.710022Z'}
{'type': 'l2update', 'product_id': 'BTC-USD', 'changes': [['buy', '38311.71', '0.00000000']], 'time': '2021-05-20T03:56:02.711224Z'}
{'type': 'l2update', 'product_id': 'BTC-USD', 'changes': [['buy', '38331.51', '0.04922956']], 'time': '2021-05-20T03:56:02.712309Z'}
{'type': 'l2update', 'product_id': 'BTC-USD', 'changes': [['sell', '38342.25', '1.32634762']], 'time': '2021-05-20T03:56:02.712348Z'}
{'type': 'l2update', 'product_id': 'BTC-USD', 'changes': [['sell', '38345.49', '0.05126289']], 'time': '2021-05-20T03:56:02.712494Z'}
{'type': 'l2update', 'product_id': 'BTC-USD', 'changes': [['sell', '38417.87', '0.00000000']], 'time': '2021-05-20T03:56:02.715982Z'}
{'type': 'l2update', 'product_id': 'BTC-USD', 'changes': [['sell', '38441.62', '0.01000000']], 'time': '2021-05-20T03:56:02.716268Z'}
{'type': 'l2update', 'product_id': 'BTC-USD', 'changes': [['buy', '38241.64', '0.00000000']], 'time': '2021-05-20T03:56:02.717549Z'}
{'type': 'l2update', 'product_id': 'BTC-USD', 'changes': [['buy', '38303.90', '0.00000000']], 'time': '2021-05-20T03:56:02.719828Z'}
{'type': 'l2update', 'product_id': 'BTC-USD', 'changes': [['sell', '38371.87', '0.04000000']], 'time': '2021-05-20T03:56:02.722029Z'}
{'type': 'l2update', 'product_id': 'BTC-USD', 'changes': [['buy', '38328.07', '0.00000000']], 'time': '2021-05-20T03:56:02.725891Z'}
{'type': 'l2update', 'product_id': 'BTC-USD', 'changes': [['sell', '38373.11', '0.00000000']], 'time': '2021-05-20T03:56:02.725971Z'}
{'type': 'l2update', 'product_id': 'BTC-USD', 'changes': [['sell', '38454.00', '0.03441391']], 'time': '2021-05-20T03:56:02.726873Z'}
{'type': 'l2update', 'product_id': 'BTC-USD', 'changes': [['sell', '38510.11', '0.01000000']], 'time': '2021-05-20T03:56:02.727025Z'}
{'type': 'l2update', 'product_id': 'BTC-USD', 'changes': [['sell', '38342.85', '1.37800115']], 'time': '2021-05-20T03:56:02.728184Z'}
{'type': 'l2update', 'product_id': 'BTC-USD', 'changes': [['sell', '38342.09', '0.01492000']], 'time': '2021-05-20T03:56:02.728431Z'}
{'type': 'l2update', 'product_id': 'BTC-USD', 'changes': [['sell', '38353.41', '0.05000000']], 'time': '2021-05-20T03:56:02.728448Z'}
{'type': 'l2update', 'product_id': 'BTC-USD', 'changes': [['buy', '38327.75', '0.00000000']], 'time': '2021-05-20T03:56:02.729673Z'}
{'type': 'l2update', 'product_id': 'BTC-USD', 'changes': [['sell', '38342.55', '0.07460000']], 'time': '2021-05-20T03:56:02.732465Z'}
{'type': 'l2update', 'product_id': 'BTC-USD', 'changes': [['buy', '38328.43', '0.00000000']], 'time': '2021-05-20T03:56:02.732553Z'}
{'type': 'l2update', 'product_id': 'BTC-USD', 'changes': [['sell', '38342.25', '0.00000000']], 'time': '2021-05-20T03:56:02.734060Z'}
{'type': 'l2update', 'product_id': 'BTC-USD', 'changes': [['buy', '38322.64', '0.00000000']], 'time': '2021-05-20T03:56:02.737551Z'}
{'type': 'l2update', 'product_id': 'BTC-USD', 'changes': [['buy', '38327.38', '0.00000000']], 'time': '2021-05-20T03:56:02.737826Z'}
{'type': 'l2update', 'product_id': 'BTC-USD', 'changes': [['sell', '38446.78', '0.00000000']], 'time': '2021-05-20T03:56:02.740223Z'}
{'type': 'l2update', 'product_id': 'BTC-USD', 'changes': [['buy', '38308.82', '0.02400000']], 'time': '2021-05-20T03:56:02.741486Z'}
{'type': 'l2update', 'product_id': 'BTC-USD', 'changes': [['sell', '38363.25', '0.00000000']], 'time': '2021-05-20T03:56:02.742925Z'}
{'type': 'l2update', 'product_id': 'BTC-USD', 'changes': [['buy', '38290.70', '0.00000000']], 'time': '2021-05-20T03:56:02.743705Z'}
{'type': 'l2update', 'product_id': 'BTC-USD', 'changes': [['buy', '38314.72', '0.00000000']], 'time': '2021-05-20T03:56:02.750555Z'}
{'type': 'l2update', 'product_id': 'BTC-USD', 'changes': [['sell', '38342.55', '0.00000000']], 'time': '2021-05-20T03:56:02.751874Z'}
{'type': 'l2update', 'product_id': 'BTC-USD', 'changes': [['sell', '38360.29', '0.00000000']], 'time': '2021-05-20T03:56:02.752315Z'}
{'type': 'l2update', 'product_id': 'BTC-USD', 'changes': [['sell', '38637.83', '0.00000000']], 'time': '2021-05-20T03:56:02.752883Z'}
{'type': 'l2update', 'product_id': 'BTC-USD', 'changes': [['buy', '38263.27', '0.00000000']], 'time': '2021-05-20T03:56:02.757291Z'}
{'type': 'l2update', 'product_id': 'BTC-USD', 'changes': [['sell', '38434.02', '0.03580901']], 'time': '2021-05-20T03:56:02.759224Z'}
{'type': 'l2update', 'product_id': 'BTC-USD', 'changes': [['sell', '38415.75', '0.03320847']], 'time': '2021-05-20T03:56:02.759224Z'}
{'type': 'l2update', 'product_id': 'BTC-USD', 'changes': [['buy', '38331.94', '0.00315085']], 'time': '2021-05-20T03:56:02.759378Z'}
{'type': 'l2update', 'product_id': 'BTC-USD', 'changes': [['buy', '38310.90', '0.00000000']], 'time': '2021-05-20T03:56:02.760678Z'}
{'type': 'l2update', 'product_id': 'BTC-USD', 'changes': [['buy', '38331.51', '0.00000000']], 'time': '2021-05-20T03:56:02.764084Z'}
{'type': 'l2update', 'product_id': 'BTC-USD', 'changes': [['buy', '38293.70', '0.00000000']], 'time': '2021-05-20T03:56:02.764256Z'}
{'type': 'l2update', 'product_id': 'BTC-USD', 'changes': [['sell', '38474.94', '0.01891066']], 'time': '2021-05-20T03:56:02.764928Z'}
{'type': 'l2update', 'product_id': 'BTC-USD', 'changes': [['sell', '38342.24', '1.50571361']], 'time': '2021-05-20T03:56:02.765354Z'}
{'type': 'l2update', 'product_id': 'BTC-USD', 'changes': [['sell', '38468.35', '0.01000000']], 'time': '2021-05-20T03:56:02.765583Z'}
{'type': 'l2update', 'product_id': 'BTC-USD', 'changes': [['buy', '38303.99', '0.00000000']], 'time': '2021-05-20T03:56:02.767586Z'}
{'type': 'l2update', 'product_id': 'BTC-USD', 'changes': [['sell', '38345.30', '0.00000000']], 'time': '2021-05-20T03:56:02.767586Z'}
{'type': 'l2update', 'product_id': 'BTC-USD', 'changes': [['buy', '38292.96', '0.00000000']], 'time': '2021-05-20T03:56:02.769177Z'}
{'type': 'l2update', 'product_id': 'BTC-USD', 'changes': [['sell', '38371.70', '0.06000000']], 'time': '2021-05-20T03:56:02.769997Z'}
{'type': 'l2update', 'product_id': 'BTC-USD', 'changes': [['sell', '38367.55', '0.05975907']], 'time': '2021-05-20T03:56:02.770615Z'}
{'type': 'l2update', 'product_id': 'BTC-USD', 'changes': [['sell', '38449.76', '0.00000000']], 'time': '2021-05-20T03:56:02.770846Z'}
{'type': 'l2update', 'product_id': 'BTC-USD', 'changes': [['sell', '38344.94', '0.00000000']], 'time': '2021-05-20T03:56:02.770878Z'}
{'type': 'l2update', 'product_id': 'BTC-USD', 'changes': [['sell', '38444.80', '0.00000000']], 'time': '2021-05-20T03:56:02.772391Z'}
{'type': 'l2update', 'product_id': 'BTC-USD', 'changes': [['sell', '38447.41', '0.08211920']], 'time': '2021-05-20T03:56:02.773071Z'}
{'type': 'l2update', 'product_id': 'BTC-USD', 'changes': [['sell', '38358.14', '0.45460000']], 'time': '2021-05-20T03:56:02.777116Z'}
{'type': 'l2update', 'product_id': 'BTC-USD', 'changes': [['buy', '38310.10', '0.00000000']], 'time': '2021-05-20T03:56:02.777649Z'}
{'type': 'l2update', 'product_id': 'BTC-USD', 'changes': [['sell', '38428.70', '0.00000000']], 'time': '2021-05-20T03:56:02.778907Z'}
{'type': 'l2update', 'product_id': 'BTC-USD', 'changes': [['buy', '38315.21', '0.99440510']], 'time': '2021-05-20T03:56:02.781875Z'}
{'type': 'l2update', 'product_id': 'BTC-USD', 'changes': [['sell', '38341.86', '0.07460000']], 'time': '2021-05-20T03:56:02.782455Z'}
{'type': 'l2update', 'product_id': 'BTC-USD', 'changes': [['buy', '38178.57', '0.80355629']], 'time': '2021-05-20T03:56:02.785495Z'}
{'type': 'l2update', 'product_id': 'BTC-USD', 'changes': [['sell', '38341.86', '0.07398976']], 'time': '2021-05-20T03:56:02.785635Z'}
{'type': 'l2update', 'product_id': 'BTC-USD', 'changes': [['buy', '38322.63', '0.00000000']], 'time': '2021-05-20T03:56:02.787037Z'}
{'type': 'l2update', 'product_id': 'BTC-USD', 'changes': [['buy', '38282.28', '0.00000000']], 'time': '2021-05-20T03:56:02.788356Z'}
{'type': 'l2update', 'product_id': 'BTC-USD', 'changes': [['buy', '38314.71', '0.00000000']], 'time': '2021-05-20T03:56:02.788524Z'}
{'type': 'l2update', 'product_id': 'BTC-USD', 'changes': [['buy', '38323.20', '0.07460000']], 'time': '2021-05-20T03:56:02.790109Z'}
{'type': 'l2update', 'product_id': 'BTC-USD', 'changes': [['sell', '38342.54', '1.54715527']], 'time': '2021-05-20T03:56:02.790328Z'}
{'type': 'l2update', 'product_id': 'BTC-USD', 'changes': [['buy', '38322.64', '0.40135082']], 'time': '2021-05-20T03:56:02.794564Z'}
{'type': 'l2update', 'product_id': 'BTC-USD', 'changes': [['sell', '38353.42', '0.00000000']], 'time': '2021-05-20T03:56:02.794894Z'}
{'type': 'l2update', 'product_id': 'BTC-USD', 'changes': [['buy', '38172.86', '0.00000000']], 'time': '2021-05-20T03:56:02.797301Z'}
{'type': 'l2update', 'product_id': 'BTC-USD', 'changes': [['buy', '38308.82', '0.00000000']], 'time': '2021-05-20T03:56:02.798306Z'}
{'type': 'l2update', 'product_id': 'BTC-USD', 'changes': [['sell', '38353.41', '0.00000000']], 'time': '2021-05-20T03:56:02.798813Z'}
{'type': 'l2update', 'product_id': 'BTC-USD', 'changes': [['sell', '38487.04', '0.12991387']], 'time': '2021-05-20T03:56:02.799890Z'}
{'type': 'l2update', 'product_id': 'BTC-USD', 'changes': [['sell', '38447.15', '0.06532518']], 'time': '2021-05-20T03:56:02.800344Z'}
{'type': 'l2update', 'product_id': 'BTC-USD', 'changes': [['sell', '38371.70', '0.05000000']], 'time': '2021-05-20T03:56:02.801609Z'}
{'type': 'l2update', 'product_id': 'BTC-USD', 'changes': [['buy', '38331.94', '0.00000000']], 'time': '2021-05-20T03:56:02.804605Z'}
{'type': 'l2update', 'product_id': 'BTC-USD', 'changes': [['buy', '38309.09', '0.42370000']], 'time': '2021-05-20T03:56:02.805555Z'}
{'type': 'l2update', 'product_id': 'BTC-USD', 'changes': [['sell', '38342.84', '0.60000000']], 'time': '2021-05-20T03:56:02.805691Z'}
{'type': 'l2update', 'product_id': 'BTC-USD', 'changes': [['sell', '38379.60', '0.37418419']], 'time': '2021-05-20T03:56:02.805863Z'}
{'type': 'l2update', 'product_id': 'BTC-USD', 'changes': [['sell', '38435.64', '0.00000000']], 'time': '2021-05-20T03:56:02.806327Z'}
{'type': 'l2update', 'product_id': 'BTC-USD', 'changes': [['sell', '38367.51', '0.00000000']], 'time': '2021-05-20T03:56:02.808589Z'}
{'type': 'l2update', 'product_id': 'BTC-USD', 'changes': [['buy', '38309.46', '0.00000000']], 'time': '2021-05-20T03:56:02.809474Z'}
{'type': 'l2update', 'product_id': 'BTC-USD', 'changes': [['buy', '38303.91', '0.00000000']], 'time': '2021-05-20T03:56:02.812607Z'}
{'type': 'l2update', 'product_id': 'BTC-USD', 'changes': [['buy', '38318.18', '0.84700000']], 'time': '2021-05-20T03:56:02.818066Z'}
{'type': 'l2update', 'product_id': 'BTC-USD', 'changes': [['sell', '38622.90', '0.01000000']], 'time': '2021-05-20T03:56:02.818282Z'}
{'type': 'l2update', 'product_id': 'BTC-USD', 'changes': [['sell', '38342.85', '1.18818641']], 'time': '2021-05-20T03:56:02.819954Z'}
{'type': 'l2update', 'product_id': 'BTC-USD', 'changes': [['sell', '38399.49', '0.00000000']], 'time': '2021-05-20T03:56:02.824790Z'}
{'type': 'l2update', 'product_id': 'BTC-USD', 'changes': [['sell', '38443.25', '0.00000000']], 'time': '2021-05-20T03:56:02.826639Z'}
{'type': 'l2update', 'product_id': 'BTC-USD', 'changes': [['sell', '38358.13', '0.05000000']], 'time': '2021-05-20T03:56:02.828279Z'}
{'type': 'l2update', 'product_id': 'BTC-USD', 'changes': [['sell', '38342.08', '0.50000000']], 'time': '2021-05-20T03:56:02.829098Z'}
{'type': 'l2update', 'product_id': 'BTC-USD', 'changes': [['buy', '38323.06', '0.01176915']], 'time': '2021-05-20T03:56:02.834329Z'}
{'type': 'l2update', 'product_id': 'BTC-USD', 'changes': [['sell', '38370.56', '0.01000000']], 'time': '2021-05-20T03:56:02.834491Z'}
{'type': 'l2update', 'product_id': 'BTC-USD', 'changes': [['buy', '38299.14', '0.02400000']], 'time': '2021-05-20T03:56:02.834847Z'}
{'type': 'l2update', 'product_id': 'BTC-USD', 'changes': [['buy', '38298.33', '0.02400000']], 'time': '2021-05-20T03:56:02.834847Z'}
{'type': 'l2update', 'product_id': 'BTC-USD', 'changes': [['buy', '38297.53', '0.02400000']], 'time': '2021-05-20T03:56:02.834847Z'}
{'type': 'l2update', 'product_id': 'BTC-USD', 'changes': [['sell', '38450.54', '0.01000000']], 'time': '2021-05-20T03:56:02.835030Z'}
{'type': 'l2update', 'product_id': 'BTC-USD', 'changes': [['sell', '38457.03', '0.06324059']], 'time': '2021-05-20T03:56:02.835150Z'}
{'type': 'l2update', 'product_id': 'BTC-USD', 'changes': [['buy', '38237.66', '0.03005719']], 'time': '2021-05-20T03:56:02.835150Z'}
{'type': 'l2update', 'product_id': 'BTC-USD', 'changes': [['buy', '38245.16', '0.05703915']], 'time': '2021-05-20T03:56:02.835150Z'}
{'type': 'l2update', 'product_id': 'BTC-USD', 'changes': [['buy', '38255.27', '0.03573120']], 'time': '2021-05-20T03:56:02.835150Z'}
{'type': 'l2update', 'product_id': 'BTC-USD', 'changes': [['buy', '38260.76', '0.02825582']], 'time': '2021-05-20T03:56:02.835150Z'}
{'type': 'l2update', 'product_id': 'BTC-USD', 'changes': [['sell', '38358.14', '0.00000000']], 'time': '2021-05-20T03:56:02.840664Z'}
{'type': 'l2update', 'product_id': 'BTC-USD', 'changes': [['buy', '38306.81', '0.05975907']], 'time': '2021-05-20T03:56:02.841536Z'}
{'type': 'l2update', 'product_id': 'BTC-USD', 'changes': [['buy', '38323.46', '0.00315085']], 'time': '2021-05-20T03:56:02.841684Z'}
{'type': 'l2update', 'product_id': 'BTC-USD', 'changes': [['buy', '38318.18', '0.00000000']], 'time': '2021-05-20T03:56:02.843793Z'}
{'type': 'l2update', 'product_id': 'BTC-USD', 'changes': [['sell', '38363.74', '0.00000000']], 'time': '2021-05-20T03:56:02.845770Z'}
{'type': 'l2update', 'product_id': 'BTC-USD', 'changes': [['sell', '38342.09', '0.00000000']], 'time': '2021-05-20T03:56:02.846590Z'}
{'type': 'l2update', 'product_id': 'BTC-USD', 'changes': [['buy', '38197.58', '0.03573120']], 'time': '2021-05-20T03:56:02.850464Z'}
{'type': 'l2update', 'product_id': 'BTC-USD', 'changes': [['buy', '38197.58', '0.00000000']], 'time': '2021-05-20T03:56:02.850464Z'}
{'type': 'l2update', 'product_id': 'BTC-USD', 'changes': [['buy', '38208.25', '0.00000000']], 'time': '2021-05-20T03:56:02.850464Z'}
{'type': 'l2update', 'product_id': 'BTC-USD', 'changes': [['sell', '38457.19', '0.01300147']], 'time': '2021-05-20T03:56:02.855384Z'}
{'type': 'l2update', 'product_id': 'BTC-USD', 'changes': [['buy', '38323.06', '0.00000000']], 'time': '2021-05-20T03:56:02.857018Z'}
{'type': 'l2update', 'product_id': 'BTC-USD', 'changes': [['sell', '38341.85', '0.18981474']], 'time': '2021-05-20T03:56:02.857151Z'}
{'type': 'l2update', 'product_id': 'BTC-USD', 'changes': [['sell', '38358.13', '0.00000000']], 'time': '2021-05-20T03:56:02.859550Z'}
{'type': 'l2update', 'product_id': 'BTC-USD', 'changes': [['sell', '38474.94', '0.00000000']], 'time': '2021-05-20T03:56:02.867007Z'}
{'type': 'l2update', 'product_id': 'BTC-USD', 'changes': [['buy', '38322.64', '0.00000000']], 'time': '2021-05-20T03:56:02.871662Z'}
{'type': 'l2update', 'product_id': 'BTC-USD', 'changes': [['buy', '38322.58', '0.00000000']], 'time': '2021-05-20T03:56:02.871894Z'}
{'type': 'l2update', 'product_id': 'BTC-USD', 'changes': [['sell', '38341.86', '0.00000000']], 'time': '2021-05-20T03:56:02.872014Z'}
{'type': 'l2update', 'product_id': 'BTC-USD', 'changes': [['buy', '38218.36', '0.03161243']], 'time': '2021-05-20T03:56:02.873879Z'}
{'type': 'l2update', 'product_id': 'BTC-USD', 'changes': [['buy', '38174.92', '0.12180000']], 'time': '2021-05-20T03:56:02.881822Z'}
{'type': 'l2update', 'product_id': 'BTC-USD', 'changes': [['sell', '38384.43', '0.19100000']], 'time': '2021-05-20T03:56:02.882955Z'}
{'type': 'l2update', 'product_id': 'BTC-USD', 'changes': [['sell', '38363.74', '0.05000000']], 'time': '2021-05-20T03:56:02.883225Z'}
{'type': 'l2update', 'product_id': 'BTC-USD', 'changes': [['buy', '38323.46', '0.01492000']], 'time': '2021-05-20T03:56:02.883385Z'}
{'type': 'l2update', 'product_id': 'BTC-USD', 'changes': [['buy', '38295.57', '0.05021860']], 'time': '2021-05-20T03:56:02.883446Z'}
{'type': 'l2update', 'product_id': 'BTC-USD', 'changes': [['sell', '38342.57', '0.04312131']], 'time': '2021-05-20T03:56:02.883446Z'}
{'type': 'l2update', 'product_id': 'BTC-USD', 'changes': [['sell', '38501.61', '0.01000000']], 'time': '2021-05-20T03:56:02.887135Z'}
{'type': 'l2update', 'product_id': 'BTC-USD', 'changes': [['sell', '38410.65', '0.00000000']], 'time': '2021-05-20T03:56:02.887476Z'}
{'type': 'l2update', 'product_id': 'BTC-USD', 'changes': [['buy', '38299.14', '0.00000000']], 'time': '2021-05-20T03:56:02.894115Z'}
{'type': 'l2update', 'product_id': 'BTC-USD', 'changes': [['sell', '38428.01', '0.78063295']], 'time': '2021-05-20T03:56:02.898026Z'}
{'type': 'l2update', 'product_id': 'BTC-USD', 'changes': [['sell', '38389.42', '0.05531740']], 'time': '2021-05-20T03:56:02.898114Z'}
{'type': 'l2update', 'product_id': 'BTC-USD', 'changes': [['buy', '38323.20', '0.00000000']], 'time': '2021-05-20T03:56:02.898469Z'}
{'type': 'l2update', 'product_id': 'BTC-USD', 'changes': [['sell', '38367.55', '0.00000000']], 'time': '2021-05-20T03:56:02.901547Z'}
{'type': 'l2update', 'product_id': 'BTC-USD', 'changes': [['buy', '38315.22', '0.40135082']], 'time': '2021-05-20T03:56:02.906949Z'}
{'type': 'l2update', 'product_id': 'BTC-USD', 'changes': [['sell', '38341.31', '0.07460000']], 'time': '2021-05-20T03:56:02.909410Z'}
{'type': 'l2update', 'product_id': 'BTC-USD', 'changes': [['sell', '38341.51', '0.01492000']], 'time': '2021-05-20T03:56:02.909497Z'}
{'type': 'l2update', 'product_id': 'BTC-USD', 'changes': [['sell', '38464.03', '0.00000000']], 'time': '2021-05-20T03:56:02.911881Z'}
{'type': 'l2update', 'product_id': 'BTC-USD', 'changes': [['sell', '38433.26', '0.00000000']], 'time': '2021-05-20T03:56:02.913258Z'}
{'type': 'l2update', 'product_id': 'BTC-USD', 'changes': [['sell', '38444.16', '0.01000000']], 'time': '2021-05-20T03:56:02.913837Z'}
{'type': 'l2update', 'product_id': 'BTC-USD', 'changes': [['buy', '38272.21', '0.00000000']], 'time': '2021-05-20T03:56:02.914048Z'}
{'type': 'l2update', 'product_id': 'BTC-USD', 'changes': [['buy', '38296.60', '0.02400000']], 'time': '2021-05-20T03:56:02.919599Z'}
{'type': 'l2update', 'product_id': 'BTC-USD', 'changes': [['buy', '38323.46', '0.01176915']], 'time': '2021-05-20T03:56:02.920879Z'}
{'type': 'l2update', 'product_id': 'BTC-USD', 'changes': [['buy', '38323.46', '0.00000000']], 'time': '2021-05-20T03:56:02.921674Z'}
{'type': 'l2update', 'product_id': 'BTC-USD', 'changes': [['sell', '38341.51', '0.00000000']], 'time': '2021-05-20T03:56:02.921861Z'}
{'type': 'l2update', 'product_id': 'BTC-USD', 'changes': [['sell', '38341.85', '0.00000000']], 'time': '2021-05-20T03:56:02.922349Z'}
{'type': 'l2update', 'product_id': 'BTC-USD', 'changes': [['buy', '38324.07', '0.07460000']], 'time': '2021-05-20T03:56:02.928242Z'}
{'type': 'l2update', 'product_id': 'BTC-USD', 'changes': [['sell', '38462.13', '0.00000000']], 'time': '2021-05-20T03:56:02.929189Z'}
{'type': 'l2update', 'product_id': 'BTC-USD', 'changes': [['buy', '38306.81', '0.00000000']], 'time': '2021-05-20T03:56:02.929226Z'}
{'type': 'l2update', 'product_id': 'BTC-USD', 'changes': [['buy', '38272.62', '0.01265905']], 'time': '2021-05-20T03:56:02.932832Z'}
{'type': 'l2update', 'product_id': 'BTC-USD', 'changes': [['sell', '38468.35', '0.00000000']], 'time': '2021-05-20T03:56:02.937107Z'}
{'type': 'l2update', 'product_id': 'BTC-USD', 'changes': [['buy', '38324.07', '0.00000000']], 'time': '2021-05-20T03:56:02.937951Z'}
{'type': 'l2update', 'product_id': 'BTC-USD', 'changes': [['buy', '38251.80', '0.00000000']], 'time': '2021-05-20T03:56:02.942660Z'}
{'type': 'l2update', 'product_id': 'BTC-USD', 'changes': [['sell', '38367.51', '2.54300000']], 'time': '2021-05-20T03:56:02.943170Z'}
{'type': 'l2update', 'product_id': 'BTC-USD', 'changes': [['sell', '38357.76', '0.43240000']], 'time': '2021-05-20T03:56:02.943442Z'}
{'type': 'l2update', 'product_id': 'BTC-USD', 'changes': [['sell', '38494.19', '0.00000000']], 'time': '2021-05-20T03:56:02.944790Z'}
{'type': 'l2update', 'product_id': 'BTC-USD', 'changes': [['sell', '38364.04', '0.04814231']], 'time': '2021-05-20T03:56:02.945006Z'}
{'type': 'l2update', 'product_id': 'BTC-USD', 'changes': [['sell', '39132.50', '0.00000000']], 'time': '2021-05-20T03:56:02.948391Z'}
{'type': 'l2update', 'product_id': 'BTC-USD', 'changes': [['sell', '38484.69', '0.01000000']], 'time': '2021-05-20T03:56:02.949015Z'}
{'type': 'l2update', 'product_id': 'BTC-USD', 'changes': [['sell', '38341.30', '0.18981474']], 'time': '2021-05-20T03:56:02.949198Z'}
{'type': 'l2update', 'product_id': 'BTC-USD', 'changes': [['buy', '38318.46', '0.01492000']], 'time': '2021-05-20T03:56:02.950326Z'}
{'type': 'l2update', 'product_id': 'BTC-USD', 'changes': [['buy', '38309.09', '0.00000000']], 'time': '2021-05-20T03:56:02.950407Z'}
{'type': 'l2update', 'product_id': 'BTC-USD', 'changes': [['sell', '38371.69', '0.05975907']], 'time': '2021-05-20T03:56:02.950595Z'}
{'type': 'l2update', 'product_id': 'BTC-USD', 'changes': [['sell', '38363.74', '0.00000000']], 'time': '2021-05-20T03:56:02.952417Z'}
{'type': 'l2update', 'product_id': 'BTC-USD', 'changes': [['buy', '38318.78', '0.07460000']], 'time': '2021-05-20T03:56:02.953433Z'}
{'type': 'l2update', 'product_id': 'BTC-USD', 'changes': [['sell', '38492.87', '0.01000000']], 'time': '2021-05-20T03:56:02.953934Z'}
{'type': 'l2update', 'product_id': 'BTC-USD', 'changes': [['buy', '37540.96', '0.00000000']], 'time': '2021-05-20T03:56:02.955888Z'}
{'type': 'l2update', 'product_id': 'BTC-USD', 'changes': [['buy', '38323.47', '0.10516754']], 'time': '2021-05-20T03:56:02.957030Z'}
{'type': 'l2update', 'product_id': 'BTC-USD', 'changes': [['buy', '38218.36', '0.06156355']], 'time': '2021-05-20T03:56:02.957102Z'}
{'type': 'l2update', 'product_id': 'BTC-USD', 'changes': [['sell', '38370.89', '0.00000000']], 'time': '2021-05-20T03:56:02.958979Z'}
{'type': 'l2update', 'product_id': 'BTC-USD', 'changes': [['buy', '38318.46', '0.00000000']], 'time': '2021-05-20T03:56:02.960339Z'}
{'type': 'l2update', 'product_id': 'BTC-USD', 'changes': [['sell', '38341.31', '0.00000000']], 'time': '2021-05-20T03:56:02.961258Z'}
{'type': 'l2update', 'product_id': 'BTC-USD', 'changes': [['sell', '38511.08', '0.01000000']], 'time': '2021-05-20T03:56:02.961822Z'}
{'type': 'l2update', 'product_id': 'BTC-USD', 'changes': [['buy', '38298.33', '0.00000000']], 'time': '2021-05-20T03:56:02.962964Z'}
{'type': 'l2update', 'product_id': 'BTC-USD', 'changes': [['sell', '38444.16', '0.00000000']], 'time': '2021-05-20T03:56:02.964018Z'}
{'type': 'l2update', 'product_id': 'BTC-USD', 'changes': [['sell', '38357.75', '0.05000000']], 'time': '2021-05-20T03:56:02.964707Z'}
{'type': 'l2update', 'product_id': 'BTC-USD', 'changes': [['buy', '38307.30', '0.45430000']], 'time': '2021-05-20T03:56:02.966534Z'}
{'type': 'l2update', 'product_id': 'BTC-USD', 'changes': [['buy', '38315.21', '1.03257945']], 'time': '2021-05-20T03:56:02.966601Z'}
{'type': 'l2update', 'product_id': 'BTC-USD', 'changes': [['sell', '38341.02', '0.01492000']], 'time': '2021-05-20T03:56:02.966952Z'}
{'type': 'l2update', 'product_id': 'BTC-USD', 'changes': [['buy', '38318.78', '0.00000000']], 'time': '2021-05-20T03:56:02.967291Z'}
{'type': 'l2update', 'product_id': 'BTC-USD', 'changes': [['buy', '38289.65', '0.05975907']], 'time': '2021-05-20T03:56:02.970079Z'}
{'type': 'l2update', 'product_id': 'BTC-USD', 'changes': [['buy', '38283.51', '1.20000000']], 'time': '2021-05-20T03:56:02.970391Z'}
{'type': 'l2update', 'product_id': 'BTC-USD', 'changes': [['buy', '38307.30', '0.00000000']], 'time': '2021-05-20T03:56:02.973653Z'}
{'type': 'l2update', 'product_id': 'BTC-USD', 'changes': [['sell', '38411.10', '0.03649767']], 'time': '2021-05-20T03:56:02.974769Z'}
{'type': 'l2update', 'product_id': 'BTC-USD', 'changes': [['sell', '38460.99', '0.01000000']], 'time': '2021-05-20T03:56:02.978921Z'}
{'type': 'l2update', 'product_id': 'BTC-USD', 'changes': [['buy', '38295.24', '0.02400000']], 'time': '2021-05-20T03:56:02.981572Z'}
{'type': 'l2update', 'product_id': 'BTC-USD', 'changes': [['sell', '38340.62', '0.07460000']], 'time': '2021-05-20T03:56:02.982373Z'}
{'type': 'l2update', 'product_id': 'BTC-USD', 'changes': [['buy', '38224.67', '0.00000000']], 'time': '2021-05-20T03:56:02.982997Z'}
{'type': 'l2update', 'product_id': 'BTC-USD', 'changes': [['sell', '38447.15', '0.02882751']], 'time': '2021-05-20T03:56:02.983277Z'}
{'type': 'l2update', 'product_id': 'BTC-USD', 'changes': [['buy', '38324.14', '0.01492000']], 'time': '2021-05-20T03:56:02.985650Z'}
{'type': 'l2update', 'product_id': 'BTC-USD', 'changes': [['sell', '38418.52', '1.20000000']], 'time': '2021-05-20T03:56:02.985800Z'}
{'type': 'l2update', 'product_id': 'BTC-USD', 'changes': [['sell', '38501.61', '0.00000000']], 'time': '2021-05-20T03:56:02.990732Z'}
{'type': 'l2update', 'product_id': 'BTC-USD', 'changes': [['sell', '38341.02', '0.00000000']], 'time': '2021-05-20T03:56:02.992327Z'}
{'type': 'l2update', 'product_id': 'BTC-USD', 'changes': [['sell', '38434.02', '0.00000000']], 'time': '2021-05-20T03:56:02.994978Z'}
{'type': 'l2update', 'product_id': 'BTC-USD', 'changes': [['sell', '38415.75', '0.00000000']], 'time': '2021-05-20T03:56:02.994978Z'}
{'type': 'l2update', 'product_id': 'BTC-USD', 'changes': [['buy', '38236.56', '0.01000000']], 'time': '2021-05-20T03:56:03.000658Z'}
{'type': 'l2update', 'product_id': 'BTC-USD', 'changes': [['buy', '38324.14', '0.08952000']], 'time': '2021-05-20T03:56:03.000755Z'}
{'type': 'l2update', 'product_id': 'BTC-USD', 'changes': [['sell', '38507.58', '0.03038779']], 'time': '2021-05-20T03:56:03.006190Z'}
{'type': 'l2update', 'product_id': 'BTC-USD', 'changes': [['buy', '38324.14', '0.01492000']], 'time': '2021-05-20T03:56:03.006999Z'}
{'type': 'l2update', 'product_id': 'BTC-USD', 'changes': [['sell', '38341.30', '0.00000000']], 'time': '2021-05-20T03:56:03.009330Z'}
{'type': 'l2update', 'product_id': 'BTC-USD', 'changes': [['sell', '38371.69', '0.00000000']], 'time': '2021-05-20T03:56:03.009952Z'}
{'type': 'l2update', 'product_id': 'BTC-USD', 'changes': [['buy', '38274.32', '0.00000000']], 'time': '2021-05-20T03:56:03.010009Z'}
{'type': 'l2update', 'product_id': 'BTC-USD', 'changes': [['sell', '38340.62', '0.07078409']], 'time': '2021-05-20T03:56:03.011743Z'}
{'type': 'l2update', 'product_id': 'BTC-USD', 'changes': [['buy', '38229.04', '0.03714881']], 'time': '2021-05-20T03:56:03.011944Z'}
{'type': 'l2update', 'product_id': 'BTC-USD', 'changes': [['buy', '38313.02', '0.00000000']], 'time': '2021-05-20T03:56:03.012195Z'}
{'type': 'l2update', 'product_id': 'BTC-USD', 'changes': [['sell', '38367.51', '0.00000000']], 'time': '2021-05-20T03:56:03.016611Z'}
{'type': 'l2update', 'product_id': 'BTC-USD', 'changes': [['sell', '38395.06', '0.00000000']], 'time': '2021-05-20T03:56:03.019045Z'}
{'type': 'l2update', 'product_id': 'BTC-USD', 'changes': [['sell', '38339.96', '0.01492000']], 'time': '2021-05-20T03:56:03.022553Z'}
{'type': 'l2update', 'product_id': 'BTC-USD', 'changes': [['buy', '38324.74', '0.07460000']], 'time': '2021-05-20T03:56:03.026896Z'}
{'type': 'l2update', 'product_id': 'BTC-USD', 'changes': [['sell', '38341.69', '0.00381591']], 'time': '2021-05-20T03:56:03.027206Z'}
{'type': 'l2update', 'product_id': 'BTC-USD', 'changes': [['sell', '38340.62', '0.00000000']], 'time': '2021-05-20T03:56:03.033720Z'}
{'type': 'l2update', 'product_id': 'BTC-USD', 'changes': [['sell', '38341.69', '0.00000000']], 'time': '2021-05-20T03:56:03.033950Z'}
{'type': 'l2update', 'product_id': 'BTC-USD', 'changes': [['buy', '38315.21', '0.03817435']], 'time': '2021-05-20T03:56:03.034524Z'}
{'type': 'l2update', 'product_id': 'BTC-USD', 'changes': [['buy', '38324.14', '0.00000000']], 'time': '2021-05-20T03:56:03.034764Z'}
{'type': 'l2update', 'product_id': 'BTC-USD', 'changes': [['sell', '38342.07', '0.18981474']], 'time': '2021-05-20T03:56:03.035737Z'}
{'type': 'l2update', 'product_id': 'BTC-USD', 'changes': [['buy', '38319.83', '0.05000000']], 'time': '2021-05-20T03:56:03.036060Z'}
{'type': 'l2update', 'product_id': 'BTC-USD', 'changes': [['buy', '38218.36', '0.09254529']], 'time': '2021-05-20T03:56:03.036164Z'}
{'type': 'l2update', 'product_id': 'BTC-USD', 'changes': [['buy', '37529.32', '0.06580253']], 'time': '2021-05-20T03:56:03.040646Z'}
{'type': 'l2update', 'product_id': 'BTC-USD', 'changes': [['buy', '38315.22', '0.00000000']], 'time': '2021-05-20T03:56:03.040973Z'}
{'type': 'l2update', 'product_id': 'BTC-USD', 'changes': [['sell', '38358.74', '0.05097046']], 'time': '2021-05-20T03:56:03.041415Z'}
{'type': 'l2update', 'product_id': 'BTC-USD', 'changes': [['buy', '38297.53', '0.00000000']], 'time': '2021-05-20T03:56:03.041484Z'}
{'type': 'l2update', 'product_id': 'BTC-USD', 'changes': [['buy', '38296.60', '0.00000000']], 'time': '2021-05-20T03:56:03.041484Z'}
{'type': 'l2update', 'product_id': 'BTC-USD', 'changes': [['buy', '38324.74', '0.00000000']], 'time': '2021-05-20T03:56:03.041805Z'}
{'type': 'l2update', 'product_id': 'BTC-USD', 'changes': [['sell', '38379.59', '0.05975907']], 'time': '2021-05-20T03:56:03.046969Z'}
{'type': 'l2update', 'product_id': 'BTC-USD', 'changes': [['sell', '38339.96', '0.00000000']], 'time': '2021-05-20T03:56:03.048174Z'}
{'type': 'l2update', 'product_id': 'BTC-USD', 'changes': [['sell', '38339.36', '0.07460000']], 'time': '2021-05-20T03:56:03.051166Z'}
{'type': 'l2update', 'product_id': 'BTC-USD', 'changes': [['buy', '38289.65', '0.00000000']], 'time': '2021-05-20T03:56:03.055275Z'}
{'type': 'l2update', 'product_id': 'BTC-USD', 'changes': [['sell', '38339.36', '0.00000000']], 'time': '2021-05-20T03:56:03.057930Z'}
{'type': 'l2update', 'product_id': 'BTC-USD', 'changes': [['buy', '38325.20', '0.01492000']], 'time': '2021-05-20T03:56:03.059394Z'}
{'type': 'l2update', 'product_id': 'BTC-USD', 'changes': [['sell', '38364.04', '0.00000000']], 'time': '2021-05-20T03:56:03.059729Z'}
{'type': 'l2update', 'product_id': 'BTC-USD', 'changes': [['sell', '38369.89', '0.01000000']], 'time': '2021-05-20T03:56:03.059740Z'}
{'type': 'l2update', 'product_id': 'BTC-USD', 'changes': [['sell', '38345.29', '0.07705518']], 'time': '2021-05-20T03:56:03.059915Z'}
{'type': 'l2update', 'product_id': 'BTC-USD', 'changes': [['sell', '38411.10', '0.06532518']], 'time': '2021-05-20T03:56:03.060015Z'}
{'type': 'l2update', 'product_id': 'BTC-USD', 'changes': [['sell', '38371.55', '0.02761322']], 'time': '2021-05-20T03:56:03.060015Z'}
{'type': 'l2update', 'product_id': 'BTC-USD', 'changes': [['buy', '38323.74', '0.07460000']], 'time': '2021-05-20T03:56:03.063435Z'}
{'type': 'l2update', 'product_id': 'BTC-USD', 'changes': [['buy', '38312.62', '0.99440510']], 'time': '2021-05-20T03:56:03.063504Z'}
{'type': 'l2update', 'product_id': 'BTC-USD', 'changes': [['buy', '38294.46', '0.02400000']], 'time': '2021-05-20T03:56:03.063896Z'}
{'type': 'l2update', 'product_id': 'BTC-USD', 'changes': [['buy', '38293.65', '0.02400000']], 'time': '2021-05-20T03:56:03.063896Z'}
{'type': 'l2update', 'product_id': 'BTC-USD', 'changes': [['sell', '38341.56', '0.01492000']], 'time': '2021-05-20T03:56:03.068525Z'}
{'type': 'l2update', 'product_id': 'BTC-USD', 'changes': [['buy', '38314.68', '0.40135082']], 'time': '2021-05-20T03:56:03.070511Z'}
{'type': 'l2update', 'product_id': 'BTC-USD', 'changes': [['buy', '38276.81', '0.05975907']], 'time': '2021-05-20T03:56:03.070528Z'}
{'type': 'l2update', 'product_id': 'BTC-USD', 'changes': [['sell', '38341.83', '0.07460000']], 'time': '2021-05-20T03:56:03.070734Z'}
{'type': 'l2update', 'product_id': 'BTC-USD', 'changes': [['buy', '38248.77', '1.65290000']], 'time': '2021-05-20T03:56:03.070791Z'}
{'type': 'l2update', 'product_id': 'BTC-USD', 'changes': [['sell', '38339.91', '0.55300000']], 'time': '2021-05-20T03:56:03.070861Z'}
{'type': 'l2update', 'product_id': 'BTC-USD', 'changes': [['buy', '38306.29', '0.49970000']], 'time': '2021-05-20T03:56:03.070937Z'}
{'type': 'l2update', 'product_id': 'BTC-USD', 'changes': [['buy', '38323.74', '0.00000000']], 'time': '2021-05-20T03:56:03.071341Z'}
{'type': 'l2update', 'product_id': 'BTC-USD', 'changes': [['buy', '38287.48', '0.01000000']], 'time': '2021-05-20T03:56:03.072219Z'}
{'type': 'l2update', 'product_id': 'BTC-USD', 'changes': [['buy', '38295.24', '0.00000000']], 'time': '2021-05-20T03:56:03.073750Z'}
{'type': 'l2update', 'product_id': 'BTC-USD', 'changes': [['buy', '38325.20', '0.01140686']], 'time': '2021-05-20T03:56:03.075884Z'}
{'type': 'l2update', 'product_id': 'BTC-USD', 'changes': [['buy', '38325.20', '0.00000000']], 'time': '2021-05-20T03:56:03.076352Z'}
{'type': 'l2update', 'product_id': 'BTC-USD', 'changes': [['sell', '38341.56', '0.00000000']], 'time': '2021-05-20T03:56:03.076455Z'}
{'type': 'l2update', 'product_id': 'BTC-USD', 'changes': [['sell', '38341.83', '0.00000000']], 'time': '2021-05-20T03:56:03.077811Z'}
{'type': 'l2update', 'product_id': 'BTC-USD', 'changes': [['sell', '38371.55', '0.03869489']], 'time': '2021-05-20T03:56:03.077937Z'}
{'type': 'l2update', 'product_id': 'BTC-USD', 'changes': [['buy', '38208.06', '0.03766825']], 'time': '2021-05-20T03:56:03.077937Z'}
{'type': 'l2update', 'product_id': 'BTC-USD', 'changes': [['buy', '38295.57', '0.00000000']], 'time': '2021-05-20T03:56:03.079481Z'}
{'type': 'l2update', 'product_id': 'BTC-USD', 'changes': [['sell', '38342.57', '0.00000000']], 'time': '2021-05-20T03:56:03.079481Z'}
{'type': 'l2update', 'product_id': 'BTC-USD', 'changes': [['sell', '38531.56', '0.00000000']], 'time': '2021-05-20T03:56:03.080459Z'}
{'type': 'l2update', 'product_id': 'BTC-USD', 'changes': [['buy', '38312.62', '0.00000000']], 'time': '2021-05-20T03:56:03.083268Z'}
{'type': 'l2update', 'product_id': 'BTC-USD', 'changes': [['sell', '38447.15', '0.00000000']], 'time': '2021-05-20T03:56:03.086572Z'}
{'type': 'l2update', 'product_id': 'BTC-USD', 'changes': [['sell', '38389.42', '0.02770418']], 'time': '2021-05-20T03:56:03.086572Z'}
{'type': 'l2update', 'product_id': 'BTC-USD', 'changes': [['sell', '38389.42', '0.00000000']], 'time': '2021-05-20T03:56:03.086572Z'}
{'type': 'l2update', 'product_id': 'BTC-USD', 'changes': [['sell', '38339.91', '0.00000000']], 'time': '2021-05-20T03:56:03.087497Z'}
{'type': 'l2update', 'product_id': 'BTC-USD', 'changes': [['sell', '38358.74', '0.00000000']], 'time': '2021-05-20T03:56:03.089493Z'}
{'type': 'l2update', 'product_id': 'BTC-USD', 'changes': [['sell', '38342.07', '0.00000000']], 'time': '2021-05-20T03:56:03.092296Z'}
{'type': 'l2update', 'product_id': 'BTC-USD', 'changes': [['sell', '38447.41', '0.05236238']], 'time': '2021-05-20T03:56:03.093043Z'}
{'type': 'l2update', 'product_id': 'BTC-USD', 'changes': [['buy', '38245.16', '0.02604873']], 'time': '2021-05-20T03:56:03.093043Z'}
{'type': 'l2update', 'product_id': 'BTC-USD', 'changes': [['buy', '38255.27', '0.00000000']], 'time': '2021-05-20T03:56:03.093043Z'}
{'type': 'l2update', 'product_id': 'BTC-USD', 'changes': [['buy', '38260.76', '0.00000000']], 'time': '2021-05-20T03:56:03.093043Z'}
{'type': 'l2update', 'product_id': 'BTC-USD', 'changes': [['buy', '38160.79', '0.05198257']], 'time': '2021-05-20T03:56:03.093279Z'}
{'type': 'l2update', 'product_id': 'BTC-USD', 'changes': [['sell', '38606.88', '0.01000000']], 'time': '2021-05-20T03:56:03.093333Z'}
{'type': 'l2update', 'product_id': 'BTC-USD', 'changes': [['buy', '38325.45', '0.07460000']], 'time': '2021-05-20T03:56:03.093519Z'}
{'type': 'l2update', 'product_id': 'BTC-USD', 'changes': [['sell', '38339.39', '0.07460000']], 'time': '2021-05-20T03:56:03.093594Z'}
{'type': 'l2update', 'product_id': 'BTC-USD', 'changes': [['buy', '38292.15', '0.02400000']], 'time': '2021-05-20T03:56:03.094537Z'}
{'type': 'l2update', 'product_id': 'BTC-USD', 'changes': [['buy', '38323.94', '0.00351314']], 'time': '2021-05-20T03:56:03.094629Z'}
{'type': 'l2update', 'product_id': 'BTC-USD', 'changes': [['buy', '38270.89', '1.28192572']], 'time': '2021-05-20T03:56:03.098743Z'}
{'type': 'l2update', 'product_id': 'BTC-USD', 'changes': [['buy', '38323.94', '0.01492000']], 'time': '2021-05-20T03:56:03.098836Z'}
{'type': 'l2update', 'product_id': 'BTC-USD', 'changes': [['buy', '38306.29', '0.00000000']], 'time': '2021-05-20T03:56:03.099511Z'}
{'type': 'l2update', 'product_id': 'BTC-USD', 'changes': [['buy', '38325.45', '0.00000000']], 'time': '2021-05-20T03:56:03.101209Z'}
{'type': 'l2update', 'product_id': 'BTC-USD', 'changes': [['sell', '38339.39', '0.00000000']], 'time': '2021-05-20T03:56:03.102014Z'}
{'type': 'l2update', 'product_id': 'BTC-USD', 'changes': [['buy', '38323.94', '0.01140686']], 'time': '2021-05-20T03:56:03.105242Z'}
{'type': 'l2update', 'product_id': 'BTC-USD', 'changes': [['sell', '38342.86', '0.00000000']], 'time': '2021-05-20T03:56:03.105847Z'}
{'type': 'l2update', 'product_id': 'BTC-USD', 'changes': [['buy', '38283.51', '0.00000000']], 'time': '2021-05-20T03:56:03.108213Z'}
{'type': 'l2update', 'product_id': 'BTC-USD', 'changes': [['buy', '38323.94', '0.00000000']], 'time': '2021-05-20T03:56:03.108484Z'}
{'type': 'l2update', 'product_id': 'BTC-USD', 'changes': [['sell', '38482.73', '0.00000000']], 'time': '2021-05-20T03:56:03.108636Z'}
{'type': 'l2update', 'product_id': 'BTC-USD', 'changes': [['sell', '38339.61', '0.01492000']], 'time': '2021-05-20T03:56:03.114070Z'}
{'type': 'l2update', 'product_id': 'BTC-USD', 'changes': [['buy', '38295.20', '0.00000000']], 'time': '2021-05-20T03:56:03.114550Z'}
{'type': 'l2update', 'product_id': 'BTC-USD', 'changes': [['sell', '38418.52', '0.00000000']], 'time': '2021-05-20T03:56:03.114824Z'}
{'type': 'l2update', 'product_id': 'BTC-USD', 'changes': [['buy', '38324.33', '0.07460000']], 'time': '2021-05-20T03:56:03.119272Z'}
{'type': 'l2update', 'product_id': 'BTC-USD', 'changes': [['buy', '38302.37', '0.04368093']], 'time': '2021-05-20T03:56:03.119797Z'}
{'type': 'l2update', 'product_id': 'BTC-USD', 'changes': [['sell', '38346.77', '0.04802518']], 'time': '2021-05-20T03:56:03.119797Z'}
{'type': 'l2update', 'product_id': 'BTC-USD', 'changes': [['buy', '38306.81', '0.99440510']], 'time': '2021-05-20T03:56:03.120073Z'}
{'type': 'l2update', 'product_id': 'BTC-USD', 'changes': [['sell', '38342.07', '0.18981474']], 'time': '2021-05-20T03:56:03.120486Z'}
{'type': 'l2update', 'product_id': 'BTC-USD', 'changes': [['sell', '38339.61', '0.00000000']], 'time': '2021-05-20T03:56:03.120942Z'}
{'type': 'l2update', 'product_id': 'BTC-USD', 'changes': [['buy', '38323.47', '0.00000000']], 'time': '2021-05-20T03:56:03.121012Z'}
{'type': 'l2update', 'product_id': 'BTC-USD', 'changes': [['buy', '38324.03', '0.01492000']], 'time': '2021-05-20T03:56:03.124489Z'}
{'type': 'l2update', 'product_id': 'BTC-USD', 'changes': [['sell', '38341.67', '0.07460000']], 'time': '2021-05-20T03:56:03.124634Z'}
{'type': 'l2update', 'product_id': 'BTC-USD', 'changes': [['sell', '38470.57', '0.01000000']], 'time': '2021-05-20T03:56:03.124843Z'}
{'type': 'l2update', 'product_id': 'BTC-USD', 'changes': [['sell', '38386.57', '0.08580985']], 'time': '2021-05-20T03:56:03.124920Z'}
{'type': 'l2update', 'product_id': 'BTC-USD', 'changes': [['sell', '38379.59', '0.00000000']], 'time': '2021-05-20T03:56:03.125341Z'}
{'type': 'l2update', 'product_id': 'BTC-USD', 'changes': [['buy', '38314.68', '0.00000000']], 'time': '2021-05-20T03:56:03.126945Z'}
{'type': 'l2update', 'product_id': 'BTC-USD', 'changes': [['sell', '38384.43', '0.00000000']], 'time': '2021-05-20T03:56:03.128506Z'}
{'type': 'l2update', 'product_id': 'BTC-USD', 'changes': [['buy', '38273.11', '0.05975907']], 'time': '2021-05-20T03:56:03.129037Z'}
{'type': 'l2update', 'product_id': 'BTC-USD', 'changes': [['buy', '38324.03', '0.00000000']], 'time': '2021-05-20T03:56:03.131219Z'}
{'type': 'l2update', 'product_id': 'BTC-USD', 'changes': [['buy', '38221.21', '0.50000000']], 'time': '2021-05-20T03:56:03.133377Z'}
{'type': 'l2update', 'product_id': 'BTC-USD', 'changes': [['sell', '38339.60', '2.48969908']], 'time': '2021-05-20T03:56:03.133397Z'}
{'type': 'l2update', 'product_id': 'BTC-USD', 'changes': [['sell', '38341.67', '0.00000000']], 'time': '2021-05-20T03:56:03.133631Z'}
{'type': 'l2update', 'product_id': 'BTC-USD', 'changes': [['sell', '38341.71', '0.01492000']], 'time': '2021-05-20T03:56:03.138127Z'}
{'type': 'l2update', 'product_id': 'BTC-USD', 'changes': [['buy', '38324.33', '0.00000000']], 'time': '2021-05-20T03:56:03.143521Z'}
{'type': 'l2update', 'product_id': 'BTC-USD', 'changes': [['sell', '38457.03', '0.03318340']], 'time': '2021-05-20T03:56:03.144458Z'}
{'type': 'l2update', 'product_id': 'BTC-USD', 'changes': [['sell', '38454.00', '0.00000000']], 'time': '2021-05-20T03:56:03.144458Z'}
{'type': 'l2update', 'product_id': 'BTC-USD', 'changes': [['sell', '38447.41', '0.02617473']], 'time': '2021-05-20T03:56:03.144458Z'}
{'type': 'l2update', 'product_id': 'BTC-USD', 'changes': [['sell', '38447.41', '0.00000000']], 'time': '2021-05-20T03:56:03.144458Z'}
{'type': 'l2update', 'product_id': 'BTC-USD', 'changes': [['sell', '38411.10', '0.03649767']], 'time': '2021-05-20T03:56:03.144458Z'}
{'type': 'l2update', 'product_id': 'BTC-USD', 'changes': [['buy', '38208.06', '0.00000000']], 'time': '2021-05-20T03:56:03.144458Z'}
{'type': 'l2update', 'product_id': 'BTC-USD', 'changes': [['buy', '38218.36', '0.06093286']], 'time': '2021-05-20T03:56:03.144458Z'}
{'type': 'l2update', 'product_id': 'BTC-USD', 'changes': [['buy', '38218.36', '0.03098174']], 'time': '2021-05-20T03:56:03.144458Z'}
{'type': 'l2update', 'product_id': 'BTC-USD', 'changes': [['buy', '38218.36', '0.00000000']], 'time': '2021-05-20T03:56:03.144458Z'}
{'type': 'l2update', 'product_id': 'BTC-USD', 'changes': [['buy', '38229.04', '0.00000000']], 'time': '2021-05-20T03:56:03.144458Z'}
{'type': 'l2update', 'product_id': 'BTC-USD', 'changes': [['buy', '38324.15', '0.10516754']], 'time': '2021-05-20T03:56:03.144960Z'}
{'type': 'l2update', 'product_id': 'BTC-USD', 'changes': [['sell', '38492.87', '0.00000000']], 'time': '2021-05-20T03:56:03.145400Z'}
{'type': 'l2update', 'product_id': 'BTC-USD', 'changes': [['buy', '37500.01', '0.11640000']], 'time': '2021-05-20T03:56:03.146641Z'}
{'type': 'l2update', 'product_id': 'BTC-USD', 'changes': [['sell', '39495.99', '0.06820000']], 'time': '2021-05-20T03:56:03.146641Z'}
{'type': 'l2update', 'product_id': 'BTC-USD', 'changes': [['sell', '38341.71', '0.00000000']], 'time': '2021-05-20T03:56:03.149398Z'}
{'type': 'l2update', 'product_id': 'BTC-USD', 'changes': [['buy', '38237.66', '0.00000000']], 'time': '2021-05-20T03:56:03.153826Z'}
{'type': 'l2update', 'product_id': 'BTC-USD', 'changes': [['buy', '38245.16', '0.00000000']], 'time': '2021-05-20T03:56:03.153826Z'}
{'type': 'l2update', 'product_id': 'BTC-USD', 'changes': [['buy', '38294.46', '0.00000000']], 'time': '2021-05-20T03:56:03.156132Z'}
{'type': 'l2update', 'product_id': 'BTC-USD', 'changes': [['sell', '39499.99', '0.05690000']], 'time': '2021-05-20T03:56:03.156308Z'}
{'type': 'l2update', 'product_id': 'BTC-USD', 'changes': [['sell', '39495.99', '0.07190000']], 'time': '2021-05-20T03:56:03.156308Z'}
{'type': 'l2update', 'product_id': 'BTC-USD', 'changes': [['buy', '37654.91', '0.00080000']], 'time': '2021-05-20T03:56:03.156308Z'}
{'type': 'l2update', 'product_id': 'BTC-USD', 'changes': [['buy', '38324.99', '0.01492000']], 'time': '2021-05-20T03:56:03.156393Z'}
{'type': 'l2update', 'product_id': 'BTC-USD', 'changes': [['buy', '38314.68', '0.40135082']], 'time': '2021-05-20T03:56:03.156521Z'}
{'type': 'l2update', 'product_id': 'BTC-USD', 'changes': [['buy', '38276.81', '0.00000000']], 'time': '2021-05-20T03:56:03.158922Z'}
{'type': 'l2update', 'product_id': 'BTC-USD', 'changes': [['sell', '38339.60', '0.00000000']], 'time': '2021-05-20T03:56:03.159764Z'}
{'type': 'l2update', 'product_id': 'BTC-USD', 'changes': [['sell', '38339.07', '0.07460000']], 'time': '2021-05-20T03:56:03.160914Z'}
{'type': 'l2update', 'product_id': 'BTC-USD', 'changes': [['buy', '38320.35', '0.07460000']], 'time': '2021-05-20T03:56:03.161122Z'}
{'type': 'l2update', 'product_id': 'BTC-USD', 'changes': [['buy', '38324.99', '0.00000000']], 'time': '2021-05-20T03:56:03.165478Z'}
{'type': 'l2update', 'product_id': 'BTC-USD', 'changes': [['sell', '38457.03', '0.00000000']], 'time': '2021-05-20T03:56:03.166927Z'}
{'type': 'l2update', 'product_id': 'BTC-USD', 'changes': [['sell', '38411.10', '0.00000000']], 'time': '2021-05-20T03:56:03.166927Z'}
{'type': 'l2update', 'product_id': 'BTC-USD', 'changes': [['sell', '38339.07', '0.00000000']], 'time': '2021-05-20T03:56:03.170997Z'}
{'type': 'l2update', 'product_id': 'BTC-USD', 'changes': [['buy', '38320.35', '0.00000000']], 'time': '2021-05-20T03:56:03.171038Z'}
{'type': 'l2update', 'product_id': 'BTC-USD', 'changes': [['buy', '38291.81', '0.02400000']], 'time': '2021-05-20T03:56:03.173200Z'}
{'type': 'l2update', 'product_id': 'BTC-USD', 'changes': [['sell', '38339.09', '0.01492000']], 'time': '2021-05-20T03:56:03.173681Z'}
{'type': 'l2update', 'product_id': 'BTC-USD', 'changes': [['buy', '38273.11', '0.00000000']], 'time': '2021-05-20T03:56:03.175666Z'}
{'type': 'l2update', 'product_id': 'BTC-USD', 'changes': [['buy', '38302.37', '0.06072731']], 'time': '2021-05-20T03:56:03.176609Z'}
{'type': 'l2update', 'product_id': 'BTC-USD', 'changes': [['sell', '38341.70', '2.48969908']], 'time': '2021-05-20T03:56:03.179809Z'}
{'type': 'l2update', 'product_id': 'BTC-USD', 'changes': [['sell', '38466.83', '0.01000000']], 'time': '2021-05-20T03:56:03.180326Z'}
{'type': 'l2update', 'product_id': 'BTC-USD', 'changes': [['sell', '38435.82', '0.00000000']], 'time': '2021-05-20T03:56:03.180609Z'}
{'type': 'l2update', 'product_id': 'BTC-USD', 'changes': [['sell', '38386.57', '0.02605078']], 'time': '2021-05-20T03:56:03.184712Z'}
{'type': 'l2update', 'product_id': 'BTC-USD', 'changes': [['sell', '38339.09', '0.00000000']], 'time': '2021-05-20T03:56:03.185000Z'}
{'type': 'l2update', 'product_id': 'BTC-USD', 'changes': [['buy', '38324.45', '0.01492000']], 'time': '2021-05-20T03:56:03.187293Z'}
{'type': 'l2update', 'product_id': 'BTC-USD', 'changes': [['sell', '38399.99', '0.05975907']], 'time': '2021-05-20T03:56:03.187369Z'}
{'type': 'l2update', 'product_id': 'BTC-USD', 'changes': [['sell', '38342.07', '0.00000000']], 'time': '2021-05-20T03:56:03.192590Z'}
{'type': 'l2update', 'product_id': 'BTC-USD', 'changes': [['buy', '38324.65', '0.07460000']], 'time': '2021-05-20T03:56:03.196403Z'}
{'type': 'l2update', 'product_id': 'BTC-USD', 'changes': [['sell', '38341.42', '0.07460000']], 'time': '2021-05-20T03:56:03.196457Z'}
{'type': 'l2update', 'product_id': 'BTC-USD', 'changes': [['sell', '38466.83', '0.00000000']], 'time': '2021-05-20T03:56:03.196860Z'}
{'type': 'l2update', 'product_id': 'BTC-USD', 'changes': [['sell', '38412.94', '0.00000000']], 'time': '2021-05-20T03:56:03.197003Z'}
{'type': 'l2update', 'product_id': 'BTC-USD', 'changes': [['sell', '38487.04', '0.00000000']], 'time': '2021-05-20T03:56:03.198536Z'}
{'type': 'l2update', 'product_id': 'BTC-USD', 'changes': [['sell', '38622.90', '0.00000000']], 'time': '2021-05-20T03:56:03.198971Z'}
{'type': 'l2update', 'product_id': 'BTC-USD', 'changes': [['sell', '38367.51', '2.49500000']], 'time': '2021-05-20T03:56:03.200859Z'}
{'type': 'l2update', 'product_id': 'BTC-USD', 'changes': [['buy', '38307.17', '0.49070000']], 'time': '2021-05-20T03:56:03.201983Z'}
{'type': 'l2update', 'product_id': 'BTC-USD', 'changes': [['sell', '38387.69', '0.01000000']], 'time': '2021-05-20T03:56:03.202222Z'}
{'type': 'l2update', 'product_id': 'BTC-USD', 'changes': [['sell', '38341.42', '0.00000000']], 'time': '2021-05-20T03:56:03.203679Z'}
{'type': 'l2update', 'product_id': 'BTC-USD', 'changes': [['buy', '38324.45', '0.00000000']], 'time': '2021-05-20T03:56:03.206573Z'}
{'type': 'l2update', 'product_id': 'BTC-USD', 'changes': [['sell', '38341.23', '0.01492000']], 'time': '2021-05-20T03:56:03.209039Z'}
{'type': 'l2update', 'product_id': 'BTC-USD', 'changes': [['sell', '38381.17', '0.03041313']], 'time': '2021-05-20T03:56:03.210862Z'}
{'type': 'l2update', 'product_id': 'BTC-USD', 'changes': [['buy', '38286.71', '0.03041313']], 'time': '2021-05-20T03:56:03.210862Z'}
{'type': 'l2update', 'product_id': 'BTC-USD', 'changes': [['buy', '38291.07', '0.01265905']], 'time': '2021-05-20T03:56:03.210862Z'}
{'type': 'l2update', 'product_id': 'BTC-USD', 'changes': [['sell', '43100.00', '1.09530000']], 'time': '2021-05-20T03:56:03.214693Z'}
{'type': 'l2update', 'product_id': 'BTC-USD', 'changes': [['buy', '38307.17', '0.00000000']], 'time': '2021-05-20T03:56:03.217033Z'}
{'type': 'l2update', 'product_id': 'BTC-USD', 'changes': [['sell', '38462.01', '0.01000000']], 'time': '2021-05-20T03:56:03.217560Z'}
{'type': 'l2update', 'product_id': 'BTC-USD', 'changes': [['sell', '38499.57', '0.01000000']], 'time': '2021-05-20T03:56:03.218468Z'}
{'type': 'l2update', 'product_id': 'BTC-USD', 'changes': [['sell', '38611.68', '0.01000000']], 'time': '2021-05-20T03:56:03.218501Z'}
{'type': 'l2update', 'product_id': 'BTC-USD', 'changes': [['sell', '38454.31', '0.00000000']], 'time': '2021-05-20T03:56:03.219114Z'}
{'type': 'l2update', 'product_id': 'BTC-USD', 'changes': [['buy', '38272.62', '0.00000000']], 'time': '2021-05-20T03:56:03.221054Z'}
{'type': 'l2update', 'product_id': 'BTC-USD', 'changes': [['sell', '38341.41', '0.18981474']], 'time': '2021-05-20T03:56:03.223655Z'}
{'type': 'l2update', 'product_id': 'BTC-USD', 'changes': [['sell', '38485.80', '0.01299180']], 'time': '2021-05-20T03:56:03.223674Z'}
{'type': 'l2update', 'product_id': 'BTC-USD', 'changes': [['sell', '38341.10', '0.07460000']], 'time': '2021-05-20T03:56:03.223828Z'}
{'type': 'l2update', 'product_id': 'BTC-USD', 'changes': [['buy', '38320.88', '0.17900000']], 'time': '2021-05-20T03:56:03.223870Z'}
{'type': 'l2update', 'product_id': 'BTC-USD', 'changes': [['sell', '38357.76', '0.00000000']], 'time': '2021-05-20T03:56:03.224626Z'}
{'type': 'l2update', 'product_id': 'BTC-USD', 'changes': [['buy', '38325.27', '0.01492000']], 'time': '2021-05-20T03:56:03.230095Z'}
{'type': 'l2update', 'product_id': 'BTC-USD', 'changes': [['sell', '43100.00', '2.62350000']], 'time': '2021-05-20T03:56:03.230287Z'}
{'type': 'l2update', 'product_id': 'BTC-USD', 'changes': [['buy', '38302.37', '0.04368093']], 'time': '2021-05-20T03:56:03.234735Z'}
{'type': 'l2update', 'product_id': 'BTC-USD', 'changes': [['buy', '38302.37', '0.00000000']], 'time': '2021-05-20T03:56:03.234735Z'}
{'type': 'l2update', 'product_id': 'BTC-USD', 'changes': [['sell', '38341.10', '0.07398978']], 'time': '2021-05-20T03:56:03.240033Z'}
{'type': 'l2update', 'product_id': 'BTC-USD', 'changes': [['sell', '38341.23', '0.00000000']], 'time': '2021-05-20T03:56:03.240995Z'}
{'type': 'l2update', 'product_id': 'BTC-USD', 'changes': [['sell', '38611.68', '0.00000000']], 'time': '2021-05-20T03:56:03.241732Z'}
{'type': 'l2update', 'product_id': 'BTC-USD', 'changes': [['buy', '38314.68', '0.00000000']], 'time': '2021-05-20T03:56:03.243325Z'}
{'type': 'l2update', 'product_id': 'BTC-USD', 'changes': [['sell', '38499.57', '0.00000000']], 'time': '2021-05-20T03:56:03.244431Z'}
{'type': 'l2update', 'product_id': 'BTC-USD', 'changes': [['buy', '38267.68', '0.05975907']], 'time': '2021-05-20T03:56:03.246546Z'}
{'type': 'l2update', 'product_id': 'BTC-USD', 'changes': [['sell', '38435.24', '0.03264844']], 'time': '2021-05-20T03:56:03.247321Z'}
{'type': 'l2update', 'product_id': 'BTC-USD', 'changes': [['buy', '38324.65', '0.00000000']], 'time': '2021-05-20T03:56:03.248364Z'}
{'type': 'l2update', 'product_id': 'BTC-USD', 'changes': [['buy', '38270.90', '0.05975907']], 'time': '2021-05-20T03:56:03.250974Z'}
{'type': 'l2update', 'product_id': 'BTC-USD', 'changes': [['buy', '37529.32', '0.00000000']], 'time': '2021-05-20T03:56:03.263259Z'}
{'type': 'l2update', 'product_id': 'BTC-USD', 'changes': [['sell', '38386.42', '0.03547879']], 'time': '2021-05-20T03:56:03.263517Z'}
{'type': 'l2update', 'product_id': 'BTC-USD', 'changes': [['buy', '38279.55', '0.03547879']], 'time': '2021-05-20T03:56:03.263517Z'}
{'type': 'l2update', 'product_id': 'BTC-USD', 'changes': [['sell', '38588.83', '0.00647855']], 'time': '2021-05-20T03:56:03.263553Z'}
{'type': 'l2update', 'product_id': 'BTC-USD', 'changes': [['buy', '38314.68', '0.40135082']], 'time': '2021-05-20T03:56:03.280038Z'}
{'type': 'l2update', 'product_id': 'BTC-USD', 'changes': [['sell', '38397.11', '0.03014176']], 'time': '2021-05-20T03:56:03.280181Z'}
{'type': 'l2update', 'product_id': 'BTC-USD', 'changes': [['buy', '38269.37', '0.03014176']], 'time': '2021-05-20T03:56:03.280181Z'}
{'type': 'l2update', 'product_id': 'BTC-USD', 'changes': [['sell', '38482.06', '0.01000000']], 'time': '2021-05-20T03:56:03.280941Z'}
{'type': 'l2update', 'product_id': 'BTC-USD', 'changes': [['buy', '38324.15', '0.00000000']], 'time': '2021-05-20T03:56:03.284163Z'}
{'type': 'l2update', 'product_id': 'BTC-USD', 'changes': [['buy', '38325.89', '0.07460000']], 'time': '2021-05-20T03:56:03.291626Z'}
{'type': 'l2update', 'product_id': 'BTC-USD', 'changes': [['sell', '38340.60', '0.01492000']], 'time': '2021-05-20T03:56:03.292632Z'}
{'type': 'l2update', 'product_id': 'BTC-USD', 'changes': [['sell', '38341.41', '0.00000000']], 'time': '2021-05-20T03:56:03.293296Z'}
{'type': 'l2update', 'product_id': 'BTC-USD', 'changes': [['buy', '38293.70', '2.37600000']], 'time': '2021-05-20T03:56:03.294519Z'}
{'type': 'l2update', 'product_id': 'BTC-USD', 'changes': [['buy', '38303.79', '0.06028436']], 'time': '2021-05-20T03:56:03.294791Z'}
{'type': 'l2update', 'product_id': 'BTC-USD', 'changes': [['sell', '38588.83', '0.00000000']], 'time': '2021-05-20T03:56:03.296917Z'}
{'type': 'l2update', 'product_id': 'BTC-USD', 'changes': [['buy', '38325.27', '0.00000000']], 'time': '2021-05-20T03:56:03.303000Z'}
{'type': 'l2update', 'product_id': 'BTC-USD', 'changes': [['sell', '38402.43', '0.03044449']], 'time': '2021-05-20T03:56:03.303691Z'}
{'type': 'l2update', 'product_id': 'BTC-USD', 'changes': [['buy', '38264.07', '0.03044449']], 'time': '2021-05-20T03:56:03.303691Z'}
{'type': 'l2update', 'product_id': 'BTC-USD', 'changes': [['sell', '38341.10', '0.00000000']], 'time': '2021-05-20T03:56:03.304487Z'}
{'type': 'l2update', 'product_id': 'BTC-USD', 'changes': [['sell', '38482.06', '0.00000000']], 'time': '2021-05-20T03:56:03.305782Z'}
{'type': 'l2update', 'product_id': 'BTC-USD', 'changes': [['sell', '38428.70', '0.02400000']], 'time': '2021-05-20T03:56:03.313328Z'}
{'type': 'l2update', 'product_id': 'BTC-USD', 'changes': [['buy', '38221.21', '0.00000000']], 'time': '2021-05-20T03:56:03.314192Z'}
{'type': 'l2update', 'product_id': 'BTC-USD', 'changes': [['sell', '38345.29', '0.00000000']], 'time': '2021-05-20T03:56:03.314779Z'}
{'type': 'l2update', 'product_id': 'BTC-USD', 'changes': [['buy', '38324.66', '0.10516754']], 'time': '2021-05-20T03:56:03.316434Z'}
{'type': 'l2update', 'product_id': 'BTC-USD', 'changes': [['buy', '38328.42', '0.04928573']], 'time': '2021-05-20T03:56:03.316650Z'}
{'type': 'l2update', 'product_id': 'BTC-USD', 'changes': [['buy', '38267.68', '0.00000000']], 'time': '2021-05-20T03:56:03.320481Z'}
{'type': 'l2update', 'product_id': 'BTC-USD', 'changes': [['sell', '38341.09', '0.18981474']], 'time': '2021-05-20T03:56:03.320551Z'}
{'type': 'l2update', 'product_id': 'BTC-USD', 'changes': [['sell', '38650.28', '0.01000000']], 'time': '2021-05-20T03:56:03.320593Z'}
{'type': 'l2update', 'product_id': 'BTC-USD', 'changes': [['buy', '38326.13', '0.01492000']], 'time': '2021-05-20T03:56:03.320753Z'}
{'type': 'l2update', 'product_id': 'BTC-USD', 'changes': [['buy', '38307.82', '0.49690000']], 'time': '2021-05-20T03:56:03.320951Z'}
{'type': 'l2update', 'product_id': 'BTC-USD', 'changes': [['sell', '38407.94', '0.03642315']], 'time': '2021-05-20T03:56:03.326597Z'}
{'type': 'l2update', 'product_id': 'BTC-USD', 'changes': [['buy', '38258.58', '0.03642315']], 'time': '2021-05-20T03:56:03.326597Z'}
{'type': 'l2update', 'product_id': 'BTC-USD', 'changes': [['buy', '38314.68', '0.00000000']], 'time': '2021-05-20T03:56:03.327050Z'}
{'type': 'l2update', 'product_id': 'BTC-USD', 'changes': [['sell', '38382.56', '0.01000000']], 'time': '2021-05-20T03:56:03.327639Z'}
{'type': 'l2update', 'product_id': 'BTC-USD', 'changes': [['sell', '38481.15', '0.00000000']], 'time': '2021-05-20T03:56:03.327951Z'}
{'type': 'l2update', 'product_id': 'BTC-USD', 'changes': [['buy', '38325.89', '0.00000000']], 'time': '2021-05-20T03:56:03.328414Z'}
{'type': 'l2update', 'product_id': 'BTC-USD', 'changes': [['buy', '38326.13', '0.00000000']], 'time': '2021-05-20T03:56:03.330027Z'}
{'type': 'l2update', 'product_id': 'BTC-USD', 'changes': [['sell', '38340.03', '0.07460000']], 'time': '2021-05-20T03:56:03.336072Z'}
{'type': 'l2update', 'product_id': 'BTC-USD', 'changes': [['sell', '38357.09', '0.42550000']], 'time': '2021-05-20T03:56:03.336192Z'}
{'type': 'l2update', 'product_id': 'BTC-USD', 'changes': [['buy', '38318.18', '0.52100000']], 'time': '2021-05-20T03:56:03.336564Z'}
{'type': 'l2update', 'product_id': 'BTC-USD', 'changes': [['sell', '38507.58', '0.00000000']], 'time': '2021-05-20T03:56:03.338518Z'}
{'type': 'l2update', 'product_id': 'BTC-USD', 'changes': [['buy', '38321.99', '0.10000000']], 'time': '2021-05-20T03:56:03.339207Z'}
{'type': 'l2update', 'product_id': 'BTC-USD', 'changes': [['sell', '38493.55', '0.01164438']], 'time': '2021-05-20T03:56:03.343829Z'}
{'type': 'l2update', 'product_id': 'BTC-USD', 'changes': [['sell', '38485.80', '0.00000000']], 'time': '2021-05-20T03:56:03.347063Z'}
{'type': 'l2update', 'product_id': 'BTC-USD', 'changes': [['sell', '38340.60', '0.00000000']], 'time': '2021-05-20T03:56:03.347490Z'}
{'type': 'l2update', 'product_id': 'BTC-USD', 'changes': [['sell', '38357.75', '0.00000000']], 'time': '2021-05-20T03:56:03.347825Z'}
{'type': 'l2update', 'product_id': 'BTC-USD', 'changes': [['buy', '38328.83', '0.07460000']], 'time': '2021-05-20T03:56:03.350315Z'}
{'type': 'l2update', 'product_id': 'BTC-USD', 'changes': [['buy', '38324.66', '0.00000000']], 'time': '2021-05-20T03:56:03.350707Z'}
{'type': 'l2update', 'product_id': 'BTC-USD', 'changes': [['buy', '36000.00', '32.50572223']], 'time': '2021-05-20T03:56:03.350884Z'}
{'type': 'l2update', 'product_id': 'BTC-USD', 'changes': [['buy', '38307.83', '0.40135082']], 'time': '2021-05-20T03:56:03.362607Z'}
{'type': 'l2update', 'product_id': 'BTC-USD', 'changes': [['sell', '38357.08', '0.05000000']], 'time': '2021-05-20T03:56:03.369518Z'}
{'type': 'l2update', 'product_id': 'BTC-USD', 'changes': [['buy', '38163.46', '0.00000000']], 'time': '2021-05-20T03:56:03.369662Z'}
{'type': 'l2update', 'product_id': 'BTC-USD', 'changes': [['sell', '38462.87', '0.01000000']], 'time': '2021-05-20T03:56:03.370040Z'}
{'type': 'l2update', 'product_id': 'BTC-USD', 'changes': [['buy', '38325.28', '0.10516754']], 'time': '2021-05-20T03:56:03.370190Z'}
{'type': 'l2update', 'product_id': 'BTC-USD', 'changes': [['buy', '38328.79', '0.01492000']], 'time': '2021-05-20T03:56:03.370227Z'}
{'type': 'l2update', 'product_id': 'BTC-USD', 'changes': [['sell', '38487.83', '0.01263974']], 'time': '2021-05-20T03:56:03.370812Z'}
{'type': 'l2update', 'product_id': 'BTC-USD', 'changes': [['sell', '38339.55', '0.01492000']], 'time': '2021-05-20T03:56:03.374599Z'}
{'type': 'l2update', 'product_id': 'BTC-USD', 'changes': [['buy', '38328.79', '0.00000000']], 'time': '2021-05-20T03:56:03.378429Z'}
{'type': 'l2update', 'product_id': 'BTC-USD', 'changes': [['sell', '38341.09', '0.00000000']], 'time': '2021-05-20T03:56:03.381556Z'}
{'type': 'l2update', 'product_id': 'BTC-USD', 'changes': [['sell', '38462.87', '0.00000000']], 'time': '2021-05-20T03:56:03.383673Z'}
{'type': 'l2update', 'product_id': 'BTC-USD', 'changes': [['buy', '38068.65', '0.00000000']], 'time': '2021-05-20T03:56:03.384766Z'}
{'type': 'l2update', 'product_id': 'BTC-USD', 'changes': [['buy', '38175.34', '0.01000000']], 'time': '2021-05-20T03:56:03.385529Z'}
{'type': 'l2update', 'product_id': 'BTC-USD', 'changes': [['sell', '38340.03', '0.00000000']], 'time': '2021-05-20T03:56:03.385648Z'}
{'type': 'l2update', 'product_id': 'BTC-USD', 'changes': [['sell', '38396.76', '0.50000000']], 'time': '2021-05-20T03:56:03.386377Z'}
{'type': 'l2update', 'product_id': 'BTC-USD', 'changes': [['sell', '38417.20', '0.03172821']], 'time': '2021-05-20T03:56:03.394953Z'}
{'type': 'l2update', 'product_id': 'BTC-USD', 'changes': [['buy', '38251.83', '0.03172821']], 'time': '2021-05-20T03:56:03.394953Z'}
{'type': 'l2update', 'product_id': 'BTC-USD', 'changes': [['sell', '38339.55', '0.00000000']], 'time': '2021-05-20T03:56:03.398355Z'}
{'type': 'l2update', 'product_id': 'BTC-USD', 'changes': [['sell', '38386.58', '0.00000000']], 'time': '2021-05-20T03:56:03.399809Z'}
{'type': 'l2update', 'product_id': 'BTC-USD', 'changes': [['buy', '38092.36', '0.01000000']], 'time': '2021-05-20T03:56:03.400241Z'}
{'type': 'l2update', 'product_id': 'BTC-USD', 'changes': [['sell', '38443.90', '0.01000000']], 'time': '2021-05-20T03:56:03.400533Z'}
{'type': 'l2update', 'product_id': 'BTC-USD', 'changes': [['sell', '38421.71', '0.00000000']], 'time': '2021-05-20T03:56:03.400893Z'}
{'type': 'l2update', 'product_id': 'BTC-USD', 'changes': [['buy', '38325.28', '0.00000000']], 'time': '2021-05-20T03:56:03.406431Z'}
{'type': 'l2update', 'product_id': 'BTC-USD', 'changes': [['sell', '38338.90', '0.07460000']], 'time': '2021-05-20T03:56:03.407607Z'}
{'type': 'l2update', 'product_id': 'BTC-USD', 'changes': [['sell', '38341.69', '0.18981474']], 'time': '2021-05-20T03:56:03.407644Z'}
{'type': 'l2update', 'product_id': 'BTC-USD', 'changes': [['sell', '38382.56', '0.00000000']], 'time': '2021-05-20T03:56:03.412784Z'}
{'type': 'l2update', 'product_id': 'BTC-USD', 'changes': [['sell', '38338.90', '0.00000000']], 'time': '2021-05-20T03:56:03.414708Z'}
{'type': 'l2update', 'product_id': 'BTC-USD', 'changes': [['sell', '38429.19', '0.03313054']], 'time': '2021-05-20T03:56:03.417834Z'}
{'type': 'l2update', 'product_id': 'BTC-USD', 'changes': [['buy', '38245.49', '0.03313054']], 'time': '2021-05-20T03:56:03.417834Z'}
{'type': 'l2update', 'product_id': 'BTC-USD', 'changes': [['sell', '38341.28', '0.01492000']], 'time': '2021-05-20T03:56:03.417901Z'}
{'type': 'l2update', 'product_id': 'BTC-USD', 'changes': [['sell', '38650.28', '0.00000000']], 'time': '2021-05-20T03:56:03.419529Z'}
{'type': 'l2update', 'product_id': 'BTC-USD', 'changes': [['sell', '38346.77', '0.00000000']], 'time': '2021-05-20T03:56:03.423791Z'}
{'type': 'l2update', 'product_id': 'BTC-USD', 'changes': [['sell', '38341.28', '0.00000000']], 'time': '2021-05-20T03:56:03.424517Z'}
{'type': 'l2update', 'product_id': 'BTC-USD', 'changes': [['buy', '38238.29', '0.00000000']], 'time': '2021-05-20T03:56:03.425982Z'}
{'type': 'l2update', 'product_id': 'BTC-USD', 'changes': [['sell', '38464.56', '0.01000000']], 'time': '2021-05-20T03:56:03.427444Z'}
{'type': 'l2update', 'product_id': 'BTC-USD', 'changes': [['buy', '38236.56', '0.00000000']], 'time': '2021-05-20T03:56:03.427955Z'}
{'type': 'l2update', 'product_id': 'BTC-USD', 'changes': [['buy', '38328.43', '0.10516754']], 'time': '2021-05-20T03:56:03.430366Z'}
{'type': 'l2update', 'product_id': 'BTC-USD', 'changes': [['buy', '38329.15', '0.00169679']], 'time': '2021-05-20T03:56:03.430632Z'}
{'type': 'l2update', 'product_id': 'BTC-USD', 'changes': [['sell', '38341.31', '0.07460000']], 'time': '2021-05-20T03:56:03.430804Z'}
{'type': 'l2update', 'product_id': 'BTC-USD', 'changes': [['sell', '38625.51', '0.00647240']], 'time': '2021-05-20T03:56:03.434698Z'}
{'type': 'l2update', 'product_id': 'BTC-USD', 'changes': [['buy', '38314.67', '0.00000000']], 'time': '2021-05-20T03:56:03.434836Z'}
{'type': 'l2update', 'product_id': 'BTC-USD', 'changes': [['buy', '38329.15', '0.01345955']], 'time': '2021-05-20T03:56:03.439259Z'}
{'type': 'l2update', 'product_id': 'BTC-USD', 'changes': [['sell', '38341.31', '0.00000000']], 'time': '2021-05-20T03:56:03.439558Z'}
{'type': 'l2update', 'product_id': 'BTC-USD', 'changes': [['buy', '38248.45', '0.01136687']], 'time': '2021-05-20T03:56:03.443599Z'}
{'type': 'l2update', 'product_id': 'BTC-USD', 'changes': [['sell', '38435.47', '0.03264335']], 'time': '2021-05-20T03:56:03.443796Z'}
{'type': 'l2update', 'product_id': 'BTC-USD', 'changes': [['buy', '38235.32', '0.03264335']], 'time': '2021-05-20T03:56:03.443796Z'}
{'type': 'l2update', 'product_id': 'BTC-USD', 'changes': [['buy', '38223.30', '0.01308102']], 'time': '2021-05-20T03:56:03.443924Z'}
{'type': 'l2update', 'product_id': 'BTC-USD', 'changes': [['buy', '38329.15', '0.01492000']], 'time': '2021-05-20T03:56:03.448139Z'}
{'type': 'l2update', 'product_id': 'BTC-USD', 'changes': [['buy', '37523.86', '0.06895801']], 'time': '2021-05-20T03:56:03.448565Z'}
{'type': 'l2update', 'product_id': 'BTC-USD', 'changes': [['buy', '38328.83', '0.00000000']], 'time': '2021-05-20T03:56:03.449045Z'}
{'type': 'l2update', 'product_id': 'BTC-USD', 'changes': [['sell', '38464.56', '0.00000000']], 'time': '2021-05-20T03:56:03.453281Z'}
{'type': 'l2update', 'product_id': 'BTC-USD', 'changes': [['sell', '38341.69', '0.18721959']], 'time': '2021-05-20T03:56:03.454092Z'}
{'type': 'l2update', 'product_id': 'BTC-USD', 'changes': [['buy', '38318.13', '0.07000000']], 'time': '2021-05-20T03:56:03.458185Z'}
{'type': 'l2update', 'product_id': 'BTC-USD', 'changes': [['sell', '38341.45', '0.01492000']], 'time': '2021-05-20T03:56:03.458344Z'}
{'type': 'l2update', 'product_id': 'BTC-USD', 'changes': [['sell', '38341.08', '0.07460000']], 'time': '2021-05-20T03:56:03.461742Z'}
{'type': 'l2update', 'product_id': 'BTC-USD', 'changes': [['sell', '39131.01', '0.06549397']], 'time': '2021-05-20T03:56:03.462228Z'}
{'type': 'l2update', 'product_id': 'BTC-USD', 'changes': [['buy', '38318.13', '0.04000000']], 'time': '2021-05-20T03:56:03.463946Z'}
{'type': 'l2update', 'product_id': 'BTC-USD', 'changes': [['sell', '38341.45', '0.00000000']], 'time': '2021-05-20T03:56:03.466664Z'}
{'type': 'l2update', 'product_id': 'BTC-USD', 'changes': [['buy', '38318.13', '0.00000000']], 'time': '2021-05-20T03:56:03.468305Z'}
{'type': 'l2update', 'product_id': 'BTC-USD', 'changes': [['sell', '38341.69', '0.00000000']], 'time': '2021-05-20T03:56:03.468887Z'}
{'type': 'l2update', 'product_id': 'BTC-USD', 'changes': [['buy', '38328.44', '0.10000000']], 'time': '2021-05-20T03:56:03.469235Z'}
{'type': 'l2update', 'product_id': 'BTC-USD', 'changes': [['sell', '38396.23', '0.01000000']], 'time': '2021-05-20T03:56:03.469289Z'}
{'type': 'l2update', 'product_id': 'BTC-USD', 'changes': [['buy', '38322.04', '0.84600000']], 'time': '2021-05-20T03:56:03.470103Z'}
{'type': 'l2update', 'product_id': 'BTC-USD', 'changes': [['buy', '38319.83', '0.00000000']], 'time': '2021-05-20T03:56:03.470839Z'}
{'type': 'l2update', 'product_id': 'BTC-USD', 'changes': [['buy', '38329.58', '0.07460000']], 'time': '2021-05-20T03:56:03.473545Z'}
{'type': 'l2update', 'product_id': 'BTC-USD', 'changes': [['sell', '38346.47', '0.07681978']], 'time': '2021-05-20T03:56:03.478042Z'}
{'type': 'l2update', 'product_id': 'BTC-USD', 'changes': [['buy', '38328.43', '0.00000000']], 'time': '2021-05-20T03:56:03.478524Z'}
{'type': 'l2update', 'product_id': 'BTC-USD', 'changes': [['buy', '38329.15', '0.01345955']], 'time': '2021-05-20T03:56:03.479788Z'}
{'type': 'l2update', 'product_id': 'BTC-USD', 'changes': [['buy', '38329.15', '0.00169679']], 'time': '2021-05-20T03:56:03.480667Z'}
{'type': 'l2update', 'product_id': 'BTC-USD', 'changes': [['sell', '38340.57', '0.01492000']], 'time': '2021-05-20T03:56:03.482639Z'}
{'type': 'l2update', 'product_id': 'BTC-USD', 'changes': [['buy', '38306.93', '0.02000000']], 'time': '2021-05-20T03:56:03.486021Z'}
{'type': 'l2update', 'product_id': 'BTC-USD', 'changes': [['buy', '38329.15', '0.00000000']], 'time': '2021-05-20T03:56:03.490109Z'}
{'type': 'l2update', 'product_id': 'BTC-USD', 'changes': [['sell', '38341.07', '0.18721958']], 'time': '2021-05-20T03:56:03.491277Z'}
{'type': 'l2update', 'product_id': 'BTC-USD', 'changes': [['sell', '38341.08', '0.00000000']], 'time': '2021-05-20T03:56:03.491302Z'}
{'type': 'l2update', 'product_id': 'BTC-USD', 'changes': [['buy', '38223.30', '0.00000000']], 'time': '2021-05-20T03:56:03.491585Z'}
{'type': 'l2update', 'product_id': 'BTC-USD', 'changes': [['buy', '38321.99', '0.00000000']], 'time': '2021-05-20T03:56:03.491808Z'}
{'type': 'l2update', 'product_id': 'BTC-USD', 'changes': [['buy', '38287.49', '0.00000000']], 'time': '2021-05-20T03:56:03.492071Z'}
{'type': 'l2update', 'product_id': 'BTC-USD', 'changes': [['buy', '38306.81', '0.00000000']], 'time': '2021-05-20T03:56:03.494122Z'}
{'type': 'l2update', 'product_id': 'BTC-USD', 'changes': [['buy', '38270.90', '0.00000000']], 'time': '2021-05-20T03:56:03.494232Z'}
{'type': 'l2update', 'product_id': 'BTC-USD', 'changes': [['sell', '38350.31', '0.06485011']], 'time': '2021-05-20T03:56:03.494988Z'}
{'type': 'l2update', 'product_id': 'BTC-USD', 'changes': [['sell', '38404.80', '0.05975907']], 'time': '2021-05-20T03:56:03.495032Z'}
{'type': 'l2update', 'product_id': 'BTC-USD', 'changes': [['sell', '38442.26', '0.02610293']], 'time': '2021-05-20T03:56:03.498663Z'}
{'type': 'l2update', 'product_id': 'BTC-USD', 'changes': [['buy', '38228.87', '0.02610293']], 'time': '2021-05-20T03:56:03.498663Z'}
{'type': 'l2update', 'product_id': 'BTC-USD', 'changes': [['buy', '38273.11', '0.05975907']], 'time': '2021-05-20T03:56:03.498834Z'}
{'type': 'l2update', 'product_id': 'BTC-USD', 'changes': [['sell', '38399.99', '0.00000000']], 'time': '2021-05-20T03:56:03.500161Z'}
{'type': 'l2update', 'product_id': 'BTC-USD', 'changes': [['sell', '38404.80', '0.00000000']], 'time': '2021-05-20T03:56:03.501045Z'}
{'type': 'l2update', 'product_id': 'BTC-USD', 'changes': [['buy', '38307.83', '0.00000000']], 'time': '2021-05-20T03:56:03.501391Z'}
{'type': 'l2update', 'product_id': 'BTC-USD', 'changes': [['buy', '38322.04', '0.00000000']], 'time': '2021-05-20T03:56:03.503291Z'}
{'type': 'l2update', 'product_id': 'BTC-USD', 'changes': [['buy', '38306.83', '0.03000000']], 'time': '2021-05-20T03:56:03.503773Z'}
{'type': 'l2update', 'product_id': 'BTC-USD', 'changes': [['buy', '38307.82', '0.00000000']], 'time': '2021-05-20T03:56:03.507195Z'}
{'type': 'l2update', 'product_id': 'BTC-USD', 'changes': [['buy', '38329.58', '0.00000000']], 'time': '2021-05-20T03:56:03.507239Z'}
{'type': 'l2update', 'product_id': 'BTC-USD', 'changes': [['sell', '38487.83', '0.00000000']], 'time': '2021-05-20T03:56:03.507774Z'}
{'type': 'l2update', 'product_id': 'BTC-USD', 'changes': [['buy', '38278.50', '0.10000000']], 'time': '2021-05-20T03:56:03.508104Z'}
{'type': 'l2update', 'product_id': 'BTC-USD', 'changes': [['buy', '38238.29', '0.01307589']], 'time': '2021-05-20T03:56:03.509619Z'}
{'type': 'l2update', 'product_id': 'BTC-USD', 'changes': [['buy', '38328.84', '0.10516754']], 'time': '2021-05-20T03:56:03.509815Z'}
{'type': 'l2update', 'product_id': 'BTC-USD', 'changes': [['sell', '38340.20', '0.07460000']], 'time': '2021-05-20T03:56:03.510701Z'}
{'type': 'l2update', 'product_id': 'BTC-USD', 'changes': [['buy', '38303.27', '0.04000000']], 'time': '2021-05-20T03:56:03.516488Z'}
{'type': 'l2update', 'product_id': 'BTC-USD', 'changes': [['sell', '38399.98', '0.05975907']], 'time': '2021-05-20T03:56:03.516670Z'}
{'type': 'l2update', 'product_id': 'BTC-USD', 'changes': [['sell', '38340.57', '0.00000000']], 'time': '2021-05-20T03:56:03.517448Z'}
{'type': 'l2update', 'product_id': 'BTC-USD', 'changes': [['buy', '38318.19', '0.99440510']], 'time': '2021-05-20T03:56:03.519095Z'}
{'type': 'l2update', 'product_id': 'BTC-USD', 'changes': [['sell', '38503.61', '0.01000000']], 'time': '2021-05-20T03:56:03.519306Z'}
{'type': 'l2update', 'product_id': 'BTC-USD', 'changes': [['buy', '37534.01', '0.06750127']], 'time': '2021-05-20T03:56:03.519574Z'}
{'type': 'l2update', 'product_id': 'BTC-USD', 'changes': [['buy', '38306.59', '0.44450000']], 'time': '2021-05-20T03:56:03.519649Z'}
{'type': 'l2update', 'product_id': 'BTC-USD', 'changes': [['buy', '38328.89', '0.03258956']], 'time': '2021-05-20T03:56:03.519710Z'}
{'type': 'l2update', 'product_id': 'BTC-USD', 'changes': [['buy', '38306.94', '0.40394597']], 'time': '2021-05-20T03:56:03.523382Z'}
{'type': 'l2update', 'product_id': 'BTC-USD', 'changes': [['sell', '38503.61', '0.00000000']], 'time': '2021-05-20T03:56:03.527757Z'}
{'type': 'l2update', 'product_id': 'BTC-USD', 'changes': [['buy', '38300.20', '0.05000000']], 'time': '2021-05-20T03:56:03.529873Z'}
{'type': 'l2update', 'product_id': 'BTC-USD', 'changes': [['sell', '38449.35', '0.02897989']], 'time': '2021-05-20T03:56:03.529954Z'}
{'type': 'l2update', 'product_id': 'BTC-USD', 'changes': [['buy', '38221.13', '0.02897989']], 'time': '2021-05-20T03:56:03.529954Z'}
{'type': 'l2update', 'product_id': 'BTC-USD', 'changes': [['buy', '38092.36', '0.00000000']], 'time': '2021-05-20T03:56:03.531393Z'}
{'type': 'l2update', 'product_id': 'BTC-USD', 'changes': [['sell', '38339.82', '0.01492000']], 'time': '2021-05-20T03:56:03.537910Z'}
{'type': 'l2update', 'product_id': 'BTC-USD', 'changes': [['sell', '38488.81', '0.01263974']], 'time': '2021-05-20T03:56:03.538038Z'}
{'type': 'l2update', 'product_id': 'BTC-USD', 'changes': [['buy', '38328.84', '0.00000000']], 'time': '2021-05-20T03:56:03.543811Z'}
{'type': 'l2update', 'product_id': 'BTC-USD', 'changes': [['sell', '38340.20', '0.00000000']], 'time': '2021-05-20T03:56:03.543869Z'}
{'type': 'l2update', 'product_id': 'BTC-USD', 'changes': [['sell', '38341.07', '0.00000000']], 'time': '2021-05-20T03:56:03.546013Z'}
{'type': 'l2update', 'product_id': 'BTC-USD', 'changes': [['buy', '38329.22', '0.00325311']], 'time': '2021-05-20T03:56:03.549918Z'}
{'type': 'l2update', 'product_id': 'BTC-USD', 'changes': [['buy', '38329.22', '0.01492000']], 'time': '2021-05-20T03:56:03.555941Z'}
{'type': 'l2update', 'product_id': 'BTC-USD', 'changes': [['buy', '38239.56', '0.01000000']], 'time': '2021-05-20T03:56:03.556081Z'}
{'type': 'l2update', 'product_id': 'BTC-USD', 'changes': [['sell', '38339.82', '0.00000000']], 'time': '2021-05-20T03:56:03.558101Z'}
{'type': 'l2update', 'product_id': 'BTC-USD', 'changes': [['buy', '38320.88', '0.00000000']], 'time': '2021-05-20T03:56:03.559900Z'}
{'type': 'l2update', 'product_id': 'BTC-USD', 'changes': [['buy', '38328.89', '0.00000000']], 'time': '2021-05-20T03:56:03.562841Z'}
{'type': 'l2update', 'product_id': 'BTC-USD', 'changes': [['sell', '38455.51', '0.02986441']], 'time': '2021-05-20T03:56:03.564116Z'}
{'type': 'l2update', 'product_id': 'BTC-USD', 'changes': [['buy', '38213.95', '0.02986441']], 'time': '2021-05-20T03:56:03.564116Z'}
{'type': 'l2update', 'product_id': 'BTC-USD', 'changes': [['sell', '38339.48', '0.07460000']], 'time': '2021-05-20T03:56:03.564132Z'}
{'type': 'l2update', 'product_id': 'BTC-USD', 'changes': [['buy', '38263.31', '0.00000000']], 'time': '2021-05-20T03:56:03.568632Z'}
{'type': 'l2update', 'product_id': 'BTC-USD', 'changes': [['buy', '38329.59', '0.10516754']], 'time': '2021-05-20T03:56:03.569392Z'}
{'type': 'l2update', 'product_id': 'BTC-USD', 'changes': [['buy', '38212.10', '0.00000000']], 'time': '2021-05-20T03:56:03.570572Z'}
{'type': 'l2update', 'product_id': 'BTC-USD', 'changes': [['sell', '38341.07', '0.01492000']], 'time': '2021-05-20T03:56:03.570948Z'}
{'type': 'l2update', 'product_id': 'BTC-USD', 'changes': [['buy', '38329.70', '0.04201044']], 'time': '2021-05-20T03:56:03.571076Z'}
{'type': 'l2update', 'product_id': 'BTC-USD', 'changes': [['sell', '38339.48', '0.00000000']], 'time': '2021-05-20T03:56:03.576413Z'}
{'type': 'l2update', 'product_id': 'BTC-USD', 'changes': [['buy', '38329.22', '0.01166689']], 'time': '2021-05-20T03:56:03.577537Z'}
{'type': 'l2update', 'product_id': 'BTC-USD', 'changes': [['sell', '38341.07', '0.00000000']], 'time': '2021-05-20T03:56:03.577714Z'}
{'type': 'l2update', 'product_id': 'BTC-USD', 'changes': [['buy', '38329.22', '0.00000000']], 'time': '2021-05-20T03:56:03.578145Z'}
{'type': 'l2update', 'product_id': 'BTC-USD', 'changes': [['buy', '38306.94', '0.00000000']], 'time': '2021-05-20T03:56:03.581278Z'}
{'type': 'l2update', 'product_id': 'BTC-USD', 'changes': [['buy', '38329.70', '0.07460000']], 'time': '2021-05-20T03:56:03.582047Z'}
{'type': 'l2update', 'product_id': 'BTC-USD', 'changes': [['buy', '38293.70', '2.41295151']], 'time': '2021-05-20T03:56:03.582283Z'}
{'type': 'l2update', 'product_id': 'BTC-USD', 'changes': [['sell', '38380.59', '0.19200000']], 'time': '2021-05-20T03:56:03.582796Z'}
{'type': 'l2update', 'product_id': 'BTC-USD', 'changes': [['buy', '38225.44', '0.01000000']], 'time': '2021-05-20T03:56:03.587701Z'}
{'type': 'l2update', 'product_id': 'BTC-USD', 'changes': [['sell', '38340.48', '0.07460000']], 'time': '2021-05-20T03:56:03.587947Z'}
{'type': 'l2update', 'product_id': 'BTC-USD', 'changes': [['sell', '38396.75', '0.04344618']], 'time': '2021-05-20T03:56:03.592180Z'}
{'type': 'l2update', 'product_id': 'BTC-USD', 'changes': [['sell', '38341.09', '0.01492000']], 'time': '2021-05-20T03:56:03.592200Z'}
{'type': 'l2update', 'product_id': 'BTC-USD', 'changes': [['sell', '38399.98', '0.00000000']], 'time': '2021-05-20T03:56:03.596095Z'}
{'type': 'l2update', 'product_id': 'BTC-USD', 'changes': [['buy', '38306.59', '0.00000000']], 'time': '2021-05-20T03:56:03.596517Z'}
{'type': 'l2update', 'product_id': 'BTC-USD', 'changes': [['sell', '38341.09', '0.00000000']], 'time': '2021-05-20T03:56:03.599667Z'}
{'type': 'l2update', 'product_id': 'BTC-USD', 'changes': [['sell', '38340.43', '0.55300000']], 'time': '2021-05-20T03:56:03.608713Z'}
{'type': 'l2update', 'product_id': 'BTC-USD', 'changes': [['sell', '38340.48', '0.00000000']], 'time': '2021-05-20T03:56:03.608960Z'}
{'type': 'l2update', 'product_id': 'BTC-USD', 'changes': [['sell', '38340.43', '0.54008844']], 'time': '2021-05-20T03:56:03.615094Z'}
{'type': 'l2update', 'product_id': 'BTC-USD', 'changes': [['sell', '38340.03', '0.01492000']], 'time': '2021-05-20T03:56:03.618929Z'}
{'type': 'l2update', 'product_id': 'BTC-USD', 'changes': [['sell', '38339.98', '0.07460000']], 'time': '2021-05-20T03:56:03.626373Z'}
{'type': 'l2update', 'product_id': 'BTC-USD', 'changes': [['sell', '38340.03', '0.00000000']], 'time': '2021-05-20T03:56:03.633206Z'}
{'type': 'l2update', 'product_id': 'BTC-USD', 'changes': [['buy', '37534.01', '0.00000000']], 'time': '2021-05-20T03:56:03.634163Z'}
{'type': 'l2update', 'product_id': 'BTC-USD', 'changes': [['sell', '38339.31', '0.01492000']], 'time': '2021-05-20T03:56:03.649685Z'}
{'type': 'l2update', 'product_id': 'BTC-USD', 'changes': [['sell', '38339.98', '0.00000000']], 'time': '2021-05-20T03:56:03.656037Z'}
{'type': 'l2update', 'product_id': 'BTC-USD', 'changes': [['sell', '38606.88', '0.00000000']], 'time': '2021-05-20T03:56:03.665769Z'}
{'type': 'l2update', 'product_id': 'BTC-USD', 'changes': [['buy', '38318.18', '0.00000000']], 'time': '2021-05-20T03:56:03.666772Z'}
{'type': 'l2update', 'product_id': 'BTC-USD', 'changes': [['sell', '38362.37', '0.04864184']], 'time': '2021-05-20T03:56:03.667695Z'}
{'type': 'l2update', 'product_id': 'BTC-USD', 'changes': [['buy', '38329.59', '0.00000000']], 'time': '2021-05-20T03:56:03.670668Z'}
{'type': 'l2update', 'product_id': 'BTC-USD', 'changes': [['sell', '38625.51', '0.00000000']], 'time': '2021-05-20T03:56:03.677862Z'}
{'type': 'l2update', 'product_id': 'BTC-USD', 'changes': [['sell', '38591.82', '0.01000000']], 'time': '2021-05-20T03:56:03.678761Z'}
{'type': 'l2update', 'product_id': 'BTC-USD', 'changes': [['sell', '38338.82', '0.07460000']], 'time': '2021-05-20T03:56:03.683091Z'}
{'type': 'l2update', 'product_id': 'BTC-USD', 'changes': [['buy', '38318.19', '0.00000000']], 'time': '2021-05-20T03:56:03.683532Z'}
{'type': 'l2update', 'product_id': 'BTC-USD', 'changes': [['sell', '38339.31', '0.00000000']], 'time': '2021-05-20T03:56:03.690122Z'}
{'type': 'l2update', 'product_id': 'BTC-USD', 'changes': [['buy', '38306.52', '0.47340000']], 'time': '2021-05-20T03:56:03.691787Z'}
{'type': 'l2update', 'product_id': 'BTC-USD', 'changes': [['buy', '38329.71', '0.10516754']], 'time': '2021-05-20T03:56:03.693636Z'}
{'type': 'l2update', 'product_id': 'BTC-USD', 'changes': [['buy', '38329.70', '0.04201044']], 'time': '2021-05-20T03:56:03.700884Z'}
{'type': 'l2update', 'product_id': 'BTC-USD', 'changes': [['sell', '38338.82', '0.00000000']], 'time': '2021-05-20T03:56:03.701158Z'}
{'type': 'l2update', 'product_id': 'BTC-USD', 'changes': [['buy', '38329.70', '0.00000000']], 'time': '2021-05-20T03:56:03.701696Z'}
{'type': 'l2update', 'product_id': 'BTC-USD', 'changes': [['sell', '38342.08', '0.00000000']], 'time': '2021-05-20T03:56:03.704269Z'}
{'type': 'l2update', 'product_id': 'BTC-USD', 'changes': [['buy', '38315.22', '0.99440510']], 'time': '2021-05-20T03:56:03.704901Z'}
{'type': 'l2update', 'product_id': 'BTC-USD', 'changes': [['sell', '38338.13', '0.01492000']], 'time': '2021-05-20T03:56:03.711922Z'}
{'type': 'l2update', 'product_id': 'BTC-USD', 'changes': [['buy', '38330.04', '0.03258956']], 'time': '2021-05-20T03:56:03.716967Z'}
{'type': 'l2update', 'product_id': 'BTC-USD', 'changes': [['sell', '38338.81', '0.50000000']], 'time': '2021-05-20T03:56:03.717266Z'}
{'type': 'l2update', 'product_id': 'BTC-USD', 'changes': [['sell', '38338.13', '0.00000000']], 'time': '2021-05-20T03:56:03.717686Z'}
{'type': 'l2update', 'product_id': 'BTC-USD', 'changes': [['sell', '38380.59', '0.00000000']], 'time': '2021-05-20T03:56:03.721414Z'}
{'type': 'l2update', 'product_id': 'BTC-USD', 'changes': [['buy', '38248.45', '0.00000000']], 'time': '2021-05-20T03:56:03.723972Z'}
{'type': 'l2update', 'product_id': 'BTC-USD', 'changes': [['sell', '38339.99', '0.07460000']], 'time': '2021-05-20T03:56:03.729718Z'}
{'type': 'l2update', 'product_id': 'BTC-USD', 'changes': [['sell', '38338.21', '0.01492000']], 'time': '2021-05-20T03:56:03.732013Z'}
{'type': 'l2update', 'product_id': 'BTC-USD', 'changes': [['sell', '38339.99', '0.00000000']], 'time': '2021-05-20T03:56:03.734568Z'}
{'type': 'l2update', 'product_id': 'BTC-USD', 'changes': [['buy', '38232.18', '0.01000000']], 'time': '2021-05-20T03:56:03.737131Z'}
{'type': 'l2update', 'product_id': 'BTC-USD', 'changes': [['sell', '38396.23', '0.00000000']], 'time': '2021-05-20T03:56:03.746883Z'}
{'type': 'l2update', 'product_id': 'BTC-USD', 'changes': [['buy', '38315.27', '0.84600000']], 'time': '2021-05-20T03:56:03.748174Z'}
{'type': 'l2update', 'product_id': 'BTC-USD', 'changes': [['buy', '37534.21', '0.06402132']], 'time': '2021-05-20T03:56:03.748192Z'}
{'type': 'l2update', 'product_id': 'BTC-USD', 'changes': [['sell', '38591.82', '0.00000000']], 'time': '2021-05-20T03:56:03.748371Z'}
{'type': 'l2update', 'product_id': 'BTC-USD', 'changes': [['buy', '38306.52', '0.00000000']], 'time': '2021-05-20T03:56:03.755332Z'}
{'type': 'l2update', 'product_id': 'BTC-USD', 'changes': [['buy', '38291.81', '0.00000000']], 'time': '2021-05-20T03:56:03.756493Z'}
{'type': 'l2update', 'product_id': 'BTC-USD', 'changes': [['sell', '38357.09', '0.00000000']], 'time': '2021-05-20T03:56:03.759845Z'}
{'type': 'l2update', 'product_id': 'BTC-USD', 'changes': [['buy', '38292.15', '0.00000000']], 'time': '2021-05-20T03:56:03.762815Z'}
{'type': 'l2update', 'product_id': 'BTC-USD', 'changes': [['sell', '38612.38', '0.01000000']], 'time': '2021-05-20T03:56:03.767826Z'}
{'type': 'l2update', 'product_id': 'BTC-USD', 'changes': [['sell', '38464.56', '0.01000000']], 'time': '2021-05-20T03:56:03.768211Z'}
{'type': 'l2update', 'product_id': 'BTC-USD', 'changes': [['sell', '38576.75', '0.01000000']], 'time': '2021-05-20T03:56:03.768231Z'}
{'type': 'l2update', 'product_id': 'BTC-USD', 'changes': [['buy', '38293.65', '0.00000000']], 'time': '2021-05-20T03:56:03.768781Z'}
{'type': 'l2update', 'product_id': 'BTC-USD', 'changes': [['sell', '38337.88', '0.07460000']], 'time': '2021-05-20T03:56:03.780380Z'}
{'type': 'l2update', 'product_id': 'BTC-USD', 'changes': [['buy', '38300.53', '0.02400000']], 'time': '2021-05-20T03:56:03.784777Z'}
{'type': 'l2update', 'product_id': 'BTC-USD', 'changes': [['buy', '38299.72', '0.02400000']], 'time': '2021-05-20T03:56:03.784777Z'}
{'type': 'l2update', 'product_id': 'BTC-USD', 'changes': [['buy', '38298.92', '0.02400000']], 'time': '2021-05-20T03:56:03.784777Z'}
{'type': 'l2update', 'product_id': 'BTC-USD', 'changes': [['sell', '38337.88', '0.00000000']], 'time': '2021-05-20T03:56:03.785905Z'}
{'type': 'l2update', 'product_id': 'BTC-USD', 'changes': [['sell', '38338.21', '0.00000000']], 'time': '2021-05-20T03:56:03.787160Z'}
{'type': 'l2update', 'product_id': 'BTC-USD', 'changes': [['sell', '38338.51', '0.07460000']], 'time': '2021-05-20T03:56:03.801244Z'}
{'type': 'l2update', 'product_id': 'BTC-USD', 'changes': [['sell', '38338.27', '0.01492000']], 'time': '2021-05-20T03:56:03.801348Z'}
{'type': 'l2update', 'product_id': 'BTC-USD', 'changes': [['buy', '38165.28', '0.04812572']], 'time': '2021-05-20T03:56:03.805433Z'}
{'type': 'l2update', 'product_id': 'BTC-USD', 'changes': [['sell', '38338.51', '0.00000000']], 'time': '2021-05-20T03:56:03.808105Z'}
{'type': 'l2update', 'product_id': 'BTC-USD', 'changes': [['buy', '37534.21', '0.00000000']], 'time': '2021-05-20T03:56:03.810490Z'}
{'type': 'l2update', 'product_id': 'BTC-USD', 'changes': [['sell', '38338.27', '0.00000000']], 'time': '2021-05-20T03:56:03.826630Z'}
{'type': 'l2update', 'product_id': 'BTC-USD', 'changes': [['sell', '38338.81', '0.48896633']], 'time': '2021-05-20T03:56:03.826630Z'}
{'type': 'l2update', 'product_id': 'BTC-USD', 'changes': [['sell', '38338.81', '0.00000000']], 'time': '2021-05-20T03:56:03.834540Z'}
{'type': 'l2update', 'product_id': 'BTC-USD', 'changes': [['sell', '38337.96', '0.07460000']], 'time': '2021-05-20T03:56:03.838963Z'}
{'type': 'l2update', 'product_id': 'BTC-USD', 'changes': [['buy', '38160.79', '0.00000000']], 'time': '2021-05-20T03:56:03.839540Z'}
{'type': 'l2update', 'product_id': 'BTC-USD', 'changes': [['buy', '38330.42', '0.01455771']], 'time': '2021-05-20T03:56:03.839844Z'}
{'type': 'l2update', 'product_id': 'BTC-USD', 'changes': [['sell', '38338.13', '0.01310831']], 'time': '2021-05-20T03:56:03.840150Z'}
{'type': 'l2update', 'product_id': 'BTC-USD', 'changes': [['buy', '38293.70', '2.37600000']], 'time': '2021-05-20T03:56:03.843531Z'}
{'type': 'l2update', 'product_id': 'BTC-USD', 'changes': [['sell', '38337.96', '0.00000000']], 'time': '2021-05-20T03:56:03.843914Z'}
{'type': 'l2update', 'product_id': 'BTC-USD', 'changes': [['buy', '38330.42', '0.00000000']], 'time': '2021-05-20T03:56:03.846078Z'}
{'type': 'l2update', 'product_id': 'BTC-USD', 'changes': [['buy', '38330.04', '0.00000000']], 'time': '2021-05-20T03:56:03.846536Z'}
{'type': 'l2update', 'product_id': 'BTC-USD', 'changes': [['sell', '38338.13', '0.00000000']], 'time': '2021-05-20T03:56:03.846784Z'}
{'type': 'l2update', 'product_id': 'BTC-USD', 'changes': [['sell', '38340.42', '0.50000000']], 'time': '2021-05-20T03:56:03.847063Z'}
{'type': 'l2update', 'product_id': 'BTC-USD', 'changes': [['buy', '38307.43', '0.45240000']], 'time': '2021-05-20T03:56:03.847144Z'}
{'type': 'l2update', 'product_id': 'BTC-USD', 'changes': [['sell', '38339.98', '0.00181169']], 'time': '2021-05-20T03:56:03.847263Z'}
{'type': 'l2update', 'product_id': 'BTC-USD', 'changes': [['sell', '38339.98', '0.00000000']], 'time': '2021-05-20T03:56:03.852124Z'}
{'type': 'l2update', 'product_id': 'BTC-USD', 'changes': [['buy', '38330.22', '0.03258956']], 'time': '2021-05-20T03:56:03.858986Z'}
{'type': 'l2update', 'product_id': 'BTC-USD', 'changes': [['sell', '38357.84', '0.40710000']], 'time': '2021-05-20T03:56:03.859110Z'}
{'type': 'l2update', 'product_id': 'BTC-USD', 'changes': [['buy', '38330.40', '0.01455771']], 'time': '2021-05-20T03:56:03.859158Z'}
{'type': 'l2update', 'product_id': 'BTC-USD', 'changes': [['sell', '38337.81', '0.07460000']], 'time': '2021-05-20T03:56:03.859169Z'}
{'type': 'l2update', 'product_id': 'BTC-USD', 'changes': [['buy', '38295.21', '0.50032031']], 'time': '2021-05-20T03:56:03.859275Z'}
{'type': 'l2update', 'product_id': 'BTC-USD', 'changes': [['sell', '38337.81', '0.00000000']], 'time': '2021-05-20T03:56:03.864622Z'}
{'type': 'l2update', 'product_id': 'BTC-USD', 'changes': [['buy', '38330.22', '0.00000000']], 'time': '2021-05-20T03:56:03.865583Z'}
{'type': 'l2update', 'product_id': 'BTC-USD', 'changes': [['sell', '38339.74', '0.01310831']], 'time': '2021-05-20T03:56:03.866379Z'}
{'type': 'l2update', 'product_id': 'BTC-USD', 'changes': [['sell', '38357.08', '0.00000000']], 'time': '2021-05-20T03:56:03.867494Z'}
{'type': 'l2update', 'product_id': 'BTC-USD', 'changes': [['buy', '38330.40', '0.00000000']], 'time': '2021-05-20T03:56:03.868244Z'}
{'type': 'l2update', 'product_id': 'BTC-USD', 'changes': [['buy', '38329.71', '0.00000000']], 'time': '2021-05-20T03:56:03.869483Z'}
{'type': 'l2update', 'product_id': 'BTC-USD', 'changes': [['buy', '38312.66', '0.52000000']], 'time': '2021-05-20T03:56:03.869798Z'}
{'type': 'l2update', 'product_id': 'BTC-USD', 'changes': [['sell', '38339.74', '0.00000000']], 'time': '2021-05-20T03:56:03.871329Z'}
{'type': 'l2update', 'product_id': 'BTC-USD', 'changes': [['sell', '38339.74', '0.00181169']], 'time': '2021-05-20T03:56:03.874204Z'}
{'type': 'l2update', 'product_id': 'BTC-USD', 'changes': [['buy', '38330.74', '0.03258956']], 'time': '2021-05-20T03:56:03.874561Z'}
{'type': 'l2update', 'product_id': 'BTC-USD', 'changes': [['sell', '38357.83', '0.05000000']], 'time': '2021-05-20T03:56:03.877553Z'}
{'type': 'l2update', 'product_id': 'BTC-USD', 'changes': [['buy', '38330.92', '0.00942088']], 'time': '2021-05-20T03:56:03.877616Z'}
{'type': 'l2update', 'product_id': 'BTC-USD', 'changes': [['sell', '38339.74', '0.00000000']], 'time': '2021-05-20T03:56:03.878827Z'}
{'type': 'l2update', 'product_id': 'BTC-USD', 'changes': [['buy', '38330.34', '0.01455771']], 'time': '2021-05-20T03:56:03.881168Z'}
{'type': 'l2update', 'product_id': 'BTC-USD', 'changes': [['buy', '38235.33', '0.50000000']], 'time': '2021-05-20T03:56:03.881283Z'}
{'type': 'l2update', 'product_id': 'BTC-USD', 'changes': [['buy', '38330.92', '0.00000000']], 'time': '2021-05-20T03:56:03.882038Z'}
{'type': 'l2update', 'product_id': 'BTC-USD', 'changes': [['buy', '38330.92', '0.02316868']], 'time': '2021-05-20T03:56:03.884738Z'}
{'type': 'l2update', 'product_id': 'BTC-USD', 'changes': [['sell', '38339.94', '0.07460000']], 'time': '2021-05-20T03:56:03.884784Z'}
{'type': 'l2update', 'product_id': 'BTC-USD', 'changes': [['sell', '38340.11', '0.01310831']], 'time': '2021-05-20T03:56:03.884832Z'}
{'type': 'l2update', 'product_id': 'BTC-USD', 'changes': [['sell', '38411.55', '0.16460000']], 'time': '2021-05-20T03:56:03.884960Z'}
{'type': 'l2update', 'product_id': 'BTC-USD', 'changes': [['buy', '38330.34', '0.00000000']], 'time': '2021-05-20T03:56:03.886954Z'}
{'type': 'l2update', 'product_id': 'BTC-USD', 'changes': [['buy', '38330.03', '0.00942088']], 'time': '2021-05-20T03:56:03.889225Z'}
{'type': 'l2update', 'product_id': 'BTC-USD', 'changes': [['buy', '38330.92', '0.00000000']], 'time': '2021-05-20T03:56:03.889357Z'}
{'type': 'l2update', 'product_id': 'BTC-USD', 'changes': [['buy', '38273.11', '0.00000000']], 'time': '2021-05-20T03:56:03.889950Z'}
{'type': 'l2update', 'product_id': 'BTC-USD', 'changes': [['sell', '38339.94', '0.00000000']], 'time': '2021-05-20T03:56:03.890642Z'}
{'type': 'l2update', 'product_id': 'BTC-USD', 'changes': [['sell', '38340.11', '0.00000000']], 'time': '2021-05-20T03:56:03.891674Z'}
{'type': 'l2update', 'product_id': 'BTC-USD', 'changes': [['buy', '38330.74', '0.00000000']], 'time': '2021-05-20T03:56:03.893820Z'}
{'type': 'l2update', 'product_id': 'BTC-USD', 'changes': [['buy', '38330.05', '0.10516754']], 'time': '2021-05-20T03:56:03.893849Z'}
{'type': 'l2update', 'product_id': 'BTC-USD', 'changes': [['sell', '38340.11', '0.00181169']], 'time': '2021-05-20T03:56:03.893885Z'}
{'type': 'l2update', 'product_id': 'BTC-USD', 'changes': [['buy', '38276.81', '0.04344618']], 'time': '2021-05-20T03:56:03.893919Z'}
{'type': 'l2update', 'product_id': 'BTC-USD', 'changes': [['buy', '37537.72', '0.06903739']], 'time': '2021-05-20T03:56:03.896963Z'}
{'type': 'l2update', 'product_id': 'BTC-USD', 'changes': [['sell', '38642.37', '3.23362444']], 'time': '2021-05-20T03:56:03.897446Z'}
{'type': 'l2update', 'product_id': 'BTC-USD', 'changes': [['sell', '38340.11', '0.00000000']], 'time': '2021-05-20T03:56:03.900220Z'}
{'type': 'l2update', 'product_id': 'BTC-USD', 'changes': [['buy', '38331.08', '0.01455771']], 'time': '2021-05-20T03:56:03.902908Z'}
{'type': 'l2update', 'product_id': 'BTC-USD', 'changes': [['buy', '38328.76', '0.02316868']], 'time': '2021-05-20T03:56:03.902956Z'}
{'type': 'l2update', 'product_id': 'BTC-USD', 'changes': [['sell', '38339.99', '0.07460000']], 'time': '2021-05-20T03:56:03.902986Z'}
{'type': 'l2update', 'product_id': 'BTC-USD', 'changes': [['buy', '38298.92', '0.00000000']], 'time': '2021-05-20T03:56:03.904683Z'}
{'type': 'l2update', 'product_id': 'BTC-USD', 'changes': [['buy', '38328.76', '0.00000000']], 'time': '2021-05-20T03:56:03.908346Z'}
{'type': 'l2update', 'product_id': 'BTC-USD', 'changes': [['sell', '38339.82', '0.01310831']], 'time': '2021-05-20T03:56:03.910131Z'}
{'type': 'l2update', 'product_id': 'BTC-USD', 'changes': [['buy', '38330.87', '0.00942088']], 'time': '2021-05-20T03:56:03.910712Z'}
{'type': 'l2update', 'product_id': 'BTC-USD', 'changes': [['buy', '38330.03', '0.00000000']], 'time': '2021-05-20T03:56:03.913922Z'}
{'type': 'l2update', 'product_id': 'BTC-USD', 'changes': [['sell', '38339.82', '0.01492000']], 'time': '2021-05-20T03:56:03.914602Z'}
{'type': 'l2update', 'product_id': 'BTC-USD', 'changes': [['buy', '38328.76', '0.03258956']], 'time': '2021-05-20T03:56:03.914654Z'}
{'type': 'l2update', 'product_id': 'BTC-USD', 'changes': [['buy', '38330.87', '0.00000000']], 'time': '2021-05-20T03:56:03.915143Z'}
{'type': 'l2update', 'product_id': 'BTC-USD', 'changes': [['sell', '38339.99', '0.00000000']], 'time': '2021-05-20T03:56:03.917318Z'}
{'type': 'l2update', 'product_id': 'BTC-USD', 'changes': [['buy', '38301.60', '0.02400000']], 'time': '2021-05-20T03:56:03.918799Z'}
{'type': 'l2update', 'product_id': 'BTC-USD', 'changes': [['buy', '38328.76', '0.00000000']], 'time': '2021-05-20T03:56:03.919479Z'}
{'type': 'l2update', 'product_id': 'BTC-USD', 'changes': [['buy', '38330.05', '0.00000000']], 'time': '2021-05-20T03:56:03.919565Z'}
{'type': 'l2update', 'product_id': 'BTC-USD', 'changes': [['buy', '37523.86', '0.00000000']], 'time': '2021-05-20T03:56:03.920688Z'}
{'type': 'l2update', 'product_id': 'BTC-USD', 'changes': [['buy', '38276.81', '0.00000000']], 'time': '2021-05-20T03:56:03.920849Z'}
{'type': 'l2update', 'product_id': 'BTC-USD', 'changes': [['buy', '38331.08', '0.00000000']], 'time': '2021-05-20T03:56:03.920869Z'}
{'type': 'l2update', 'product_id': 'BTC-USD', 'changes': [['sell', '38517.97', '0.00000000']], 'time': '2021-05-20T03:56:03.921461Z'}
{'type': 'l2update', 'product_id': 'BTC-USD', 'changes': [['buy', '38278.51', '0.04344618']], 'time': '2021-05-20T03:56:03.923930Z'}
{'type': 'l2update', 'product_id': 'BTC-USD', 'changes': [['buy', '38331.59', '0.02316868']], 'time': '2021-05-20T03:56:03.930123Z'}
{'type': 'l2update', 'product_id': 'BTC-USD', 'changes': [['sell', '38505.71', '0.01000000']], 'time': '2021-05-20T03:56:03.932540Z'}
{'type': 'l2update', 'product_id': 'BTC-USD', 'changes': [['sell', '38339.29', '0.07460000']], 'time': '2021-05-20T03:56:03.932562Z'}
{'type': 'l2update', 'product_id': 'BTC-USD', 'changes': [['buy', '38331.59', '0.00000000']], 'time': '2021-05-20T03:56:03.936111Z'}
{'type': 'l2update', 'product_id': 'BTC-USD', 'changes': [['buy', '38328.68', '0.05143132']], 'time': '2021-05-20T03:56:03.936527Z'}
{'type': 'l2update', 'product_id': 'BTC-USD', 'changes': [['buy', '38329.09', '0.01455771']], 'time': '2021-05-20T03:56:03.936841Z'}
{'type': 'l2update', 'product_id': 'BTC-USD', 'changes': [['sell', '38339.29', '0.00000000']], 'time': '2021-05-20T03:56:03.938475Z'}
{'type': 'l2update', 'product_id': 'BTC-USD', 'changes': [['sell', '38339.82', '0.00181169']], 'time': '2021-05-20T03:56:03.940130Z'}
{'type': 'l2update', 'product_id': 'BTC-USD', 'changes': [['buy', '38330.23', '0.10516754']], 'time': '2021-05-20T03:56:03.940331Z'}
{'type': 'l2update', 'product_id': 'BTC-USD', 'changes': [['buy', '38306.93', '0.00000000']], 'time': '2021-05-20T03:56:03.941413Z'}
{'type': 'l2update', 'product_id': 'BTC-USD', 'changes': [['sell', '38339.82', '0.00000000']], 'time': '2021-05-20T03:56:03.943035Z'}
{'type': 'l2update', 'product_id': 'BTC-USD', 'changes': [['buy', '38328.68', '0.00000000']], 'time': '2021-05-20T03:56:03.943897Z'}
{'type': 'l2update', 'product_id': 'BTC-USD', 'changes': [['buy', '38329.09', '0.00000000']], 'time': '2021-05-20T03:56:03.945268Z'}
{'type': 'l2update', 'product_id': 'BTC-USD', 'changes': [['buy', '38306.83', '0.00000000']], 'time': '2021-05-20T03:56:03.945333Z'}
{'type': 'l2update', 'product_id': 'BTC-USD', 'changes': [['sell', '38576.75', '0.00000000']], 'time': '2021-05-20T03:56:03.947606Z'}
{'type': 'l2update', 'product_id': 'BTC-USD', 'changes': [['buy', '38328.68', '0.02316868']], 'time': '2021-05-20T03:56:03.947805Z'}
{'type': 'l2update', 'product_id': 'BTC-USD', 'changes': [['buy', '38303.27', '0.00000000']], 'time': '2021-05-20T03:56:03.948333Z'}
{'type': 'l2update', 'product_id': 'BTC-USD', 'changes': [['buy', '38300.20', '0.00000000']], 'time': '2021-05-20T03:56:03.952561Z'}
{'type': 'l2update', 'product_id': 'BTC-USD', 'changes': [['buy', '38328.68', '0.00000000']], 'time': '2021-05-20T03:56:03.953398Z'}
{'type': 'l2update', 'product_id': 'BTC-USD', 'changes': [['sell', '38339.24', '0.07460000']], 'time': '2021-05-20T03:56:03.953423Z'}
{'type': 'l2update', 'product_id': 'BTC-USD', 'changes': [['sell', '38339.24', '0.00000000']], 'time': '2021-05-20T03:56:03.959958Z'}
{'type': 'l2update', 'product_id': 'BTC-USD', 'changes': [['sell', '38561.69', '0.01000000']], 'time': '2021-05-20T03:56:03.960018Z'}
{'type': 'l2update', 'product_id': 'BTC-USD', 'changes': [['sell', '38340.04', '0.01310831']], 'time': '2021-05-20T03:56:03.960286Z'}
{'type': 'l2update', 'product_id': 'BTC-USD', 'changes': [['buy', '38330.77', '0.01492000']], 'time': '2021-05-20T03:56:03.961011Z'}
{'type': 'l2update', 'product_id': 'BTC-USD', 'changes': [['sell', '38340.04', '0.01492000']], 'time': '2021-05-20T03:56:03.963565Z'}
{'type': 'l2update', 'product_id': 'BTC-USD', 'changes': [['buy', '38314.33', '0.02000000']], 'time': '2021-05-20T03:56:03.963752Z'}
{'type': 'l2update', 'product_id': 'BTC-USD', 'changes': [['buy', '38330.78', '0.05143132']], 'time': '2021-05-20T03:56:03.963790Z'}
{'type': 'l2update', 'product_id': 'BTC-USD', 'changes': [['sell', '38340.04', '0.00181169']], 'time': '2021-05-20T03:56:03.965712Z'}
{'type': 'l2update', 'product_id': 'BTC-USD', 'changes': [['sell', '38462.01', '0.00000000']], 'time': '2021-05-20T03:56:03.967088Z'}
{'type': 'l2update', 'product_id': 'BTC-USD', 'changes': [['sell', '38340.04', '0.00000000']], 'time': '2021-05-20T03:56:03.968780Z'}
{'type': 'l2update', 'product_id': 'BTC-USD', 'changes': [['buy', '38330.77', '0.00000000']], 'time': '2021-05-20T03:56:03.969825Z'}
{'type': 'l2update', 'product_id': 'BTC-USD', 'changes': [['buy', '38330.23', '0.00000000']], 'time': '2021-05-20T03:56:03.970289Z'}
{'type': 'l2update', 'product_id': 'BTC-USD', 'changes': [['buy', '38140.57', '0.05132436']], 'time': '2021-05-20T03:56:03.971556Z'}
{'type': 'l2update', 'product_id': 'BTC-USD', 'changes': [['sell', '38340.02', '0.07460000']], 'time': '2021-05-20T03:56:03.975679Z'}
{'type': 'l2update', 'product_id': 'BTC-USD', 'changes': [['buy', '38314.33', '0.05000000']], 'time': '2021-05-20T03:56:03.975693Z'}
{'type': 'l2update', 'product_id': 'BTC-USD', 'changes': [['buy', '38330.78', '0.00000000']], 'time': '2021-05-20T03:56:03.982376Z'}
{'type': 'l2update', 'product_id': 'BTC-USD', 'changes': [['buy', '38331.34', '0.01492000']], 'time': '2021-05-20T03:56:03.983348Z'}
{'type': 'l2update', 'product_id': 'BTC-USD', 'changes': [['buy', '38232.18', '0.00000000']], 'time': '2021-05-20T03:56:03.986699Z'}
{'type': 'l2update', 'product_id': 'BTC-USD', 'changes': [['buy', '38314.33', '0.09000000']], 'time': '2021-05-20T03:56:03.988204Z'}
{'type': 'l2update', 'product_id': 'BTC-USD', 'changes': [['sell', '38433.85', '0.01000000']], 'time': '2021-05-20T03:56:03.988582Z'}
{'type': 'l2update', 'product_id': 'BTC-USD', 'changes': [['buy', '38329.05', '0.02316868']], 'time': '2021-05-20T03:56:03.992518Z'}
{'type': 'l2update', 'product_id': 'BTC-USD', 'changes': [['sell', '38339.71', '0.01454745']], 'time': '2021-05-20T03:56:03.996143Z'}
{'type': 'l2update', 'product_id': 'BTC-USD', 'changes': [['buy', '38244.07', '0.01000000']], 'time': '2021-05-20T03:56:03.996461Z'}
{'type': 'l2update', 'product_id': 'BTC-USD', 'changes': [['buy', '38331.09', '0.10516754']], 'time': '2021-05-20T03:56:03.996538Z'}
{'type': 'l2update', 'product_id': 'BTC-USD', 'changes': [['buy', '38329.05', '0.00000000']], 'time': '2021-05-20T03:56:03.997381Z'}
{'type': 'l2update', 'product_id': 'BTC-USD', 'changes': [['buy', '38331.34', '0.00000000']], 'time': '2021-05-20T03:56:04.000451Z'}
{'type': 'l2update', 'product_id': 'BTC-USD', 'changes': [['buy', '38314.33', '0.14000000']], 'time': '2021-05-20T03:56:04.000976Z'}
{'type': 'l2update', 'product_id': 'BTC-USD', 'changes': [['buy', '38329.05', '0.05143132']], 'time': '2021-05-20T03:56:04.000993Z'}
{'type': 'l2update', 'product_id': 'BTC-USD', 'changes': [['sell', '38340.02', '0.00000000']], 'time': '2021-05-20T03:56:04.001462Z'}
{'type': 'l2update', 'product_id': 'BTC-USD', 'changes': [['buy', '37537.72', '0.00000000']], 'time': '2021-05-20T03:56:04.006596Z'}
{'type': 'l2update', 'product_id': 'BTC-USD', 'changes': [['sell', '38464.56', '0.00000000']], 'time': '2021-05-20T03:56:04.008870Z'}
{'type': 'l2update', 'product_id': 'BTC-USD', 'changes': [['sell', '38367.51', '0.00000000']], 'time': '2021-05-20T03:56:04.011281Z'}
{'type': 'l2update', 'product_id': 'BTC-USD', 'changes': [['buy', '38331.32', '0.02316868']], 'time': '2021-05-20T03:56:04.012830Z'}
{'type': 'l2update', 'product_id': 'BTC-USD', 'changes': [['buy', '38331.70', '0.01455771']], 'time': '2021-05-20T03:56:04.013014Z'}
{'type': 'l2update', 'product_id': 'BTC-USD', 'changes': [['buy', '38329.05', '0.00000000']], 'time': '2021-05-20T03:56:04.015883Z'}
{'type': 'l2update', 'product_id': 'BTC-USD', 'changes': [['sell', '38353.43', '0.00000000']], 'time': '2021-05-20T03:56:04.018467Z'}
{'type': 'l2update', 'product_id': 'BTC-USD', 'changes': [['buy', '38315.27', '0.00000000']], 'time': '2021-05-20T03:56:04.019217Z'}
{'type': 'l2update', 'product_id': 'BTC-USD', 'changes': [['sell', '38341.70', '0.00000000']], 'time': '2021-05-20T03:56:04.019415Z'}
{'type': 'l2update', 'product_id': 'BTC-USD', 'changes': [['buy', '38331.32', '0.00000000']], 'time': '2021-05-20T03:56:04.019569Z'}
{'type': 'l2update', 'product_id': 'BTC-USD', 'changes': [['buy', '38315.20', '0.53000000']], 'time': '2021-05-20T03:56:04.021150Z'}
{'type': 'l2update', 'product_id': 'BTC-USD', 'changes': [['buy', '38312.66', '0.00000000']], 'time': '2021-05-20T03:56:04.021577Z'}
{'type': 'l2update', 'product_id': 'BTC-USD', 'changes': [['sell', '38339.30', '0.07460000']], 'time': '2021-05-20T03:56:04.025403Z'}
{'type': 'l2update', 'product_id': 'BTC-USD', 'changes': [['sell', '38340.43', '0.00000000']], 'time': '2021-05-20T03:56:04.028226Z'}
{'type': 'l2update', 'product_id': 'BTC-USD', 'changes': [['buy', '38301.60', '0.00000000']], 'time': '2021-05-20T03:56:04.028909Z'}
{'type': 'l2update', 'product_id': 'BTC-USD', 'changes': [['sell', '38339.30', '0.00000000']], 'time': '2021-05-20T03:56:04.031191Z'}
{'type': 'l2update', 'product_id': 'BTC-USD', 'changes': [['sell', '38339.71', '0.00000000']], 'time': '2021-05-20T03:56:04.032636Z'}
{'type': 'l2update', 'product_id': 'BTC-USD', 'changes': [['sell', '38442.52', '0.01000000']], 'time': '2021-05-20T03:56:04.033820Z'}
{'type': 'l2update', 'product_id': 'BTC-USD', 'changes': [['buy', '38315.20', '0.01000000']], 'time': '2021-05-20T03:56:04.035915Z'}
{'type': 'l2update', 'product_id': 'BTC-USD', 'changes': [['sell', '38339.70', '2.48969908']], 'time': '2021-05-20T03:56:04.039060Z'}
{'type': 'l2update', 'product_id': 'BTC-USD', 'changes': [['buy', '38298.33', '0.02400000']], 'time': '2021-05-20T03:56:04.042503Z'}
{'type': 'l2update', 'product_id': 'BTC-USD', 'changes': [['sell', '38388.41', '0.05208059']], 'time': '2021-05-20T03:56:04.042553Z'}
{'type': 'l2update', 'product_id': 'BTC-USD', 'changes': [['sell', '38340.19', '0.07460000']], 'time': '2021-05-20T03:56:04.046319Z'}
{'type': 'l2update', 'product_id': 'BTC-USD', 'changes': [['sell', '38339.86', '0.01281082']], 'time': '2021-05-20T03:56:04.047989Z'}
{'type': 'l2update', 'product_id': 'BTC-USD', 'changes': [['buy', '38332.01', '0.03258956']], 'time': '2021-05-20T03:56:04.048034Z'}
{'type': 'l2update', 'product_id': 'BTC-USD', 'changes': [['buy', '38300.53', '0.00000000']], 'time': '2021-05-20T03:56:04.049781Z'}
{'type': 'l2update', 'product_id': 'BTC-USD', 'changes': [['sell', '38340.19', '0.00000000']], 'time': '2021-05-20T03:56:04.050515Z'}
{'type': 'l2update', 'product_id': 'BTC-USD', 'changes': [['sell', '38339.70', '0.00000000']], 'time': '2021-05-20T03:56:04.051774Z'}
{'type': 'l2update', 'product_id': 'BTC-USD', 'changes': [['sell', '38339.86', '0.00000000']], 'time': '2021-05-20T03:56:04.053535Z'}
{'type': 'l2update', 'product_id': 'BTC-USD', 'changes': [['buy', '38332.01', '0.00000000']], 'time': '2021-05-20T03:56:04.054292Z'}
{'type': 'l2update', 'product_id': 'BTC-USD', 'changes': [['buy', '38331.70', '0.00000000']], 'time': '2021-05-20T03:56:04.055344Z'}
{'type': 'l2update', 'product_id': 'BTC-USD', 'changes': [['sell', '38396.75', '0.00000000']], 'time': '2021-05-20T03:56:04.061447Z'}
{'type': 'l2update', 'product_id': 'BTC-USD', 'changes': [['buy', '38297.75', '0.02400000']], 'time': '2021-05-20T03:56:04.064500Z'}
{'type': 'l2update', 'product_id': 'BTC-USD', 'changes': [['buy', '38332.29', '0.03258956']], 'time': '2021-05-20T03:56:04.064520Z'}
{'type': 'l2update', 'product_id': 'BTC-USD', 'changes': [['sell', '38340.41', '2.48969908']], 'time': '2021-05-20T03:56:04.064844Z'}
{'type': 'l2update', 'product_id': 'BTC-USD', 'changes': [['buy', '37500.00', '13.35391442']], 'time': '2021-05-20T03:56:04.064872Z'}
{'type': 'l2update', 'product_id': 'BTC-USD', 'changes': [['sell', '38340.00', '0.00210918']], 'time': '2021-05-20T03:56:04.064900Z'}
{'type': 'l2update', 'product_id': 'BTC-USD', 'changes': [['buy', '38332.29', '0.00000000']], 'time': '2021-05-20T03:56:04.068909Z'}
{'type': 'l2update', 'product_id': 'BTC-USD', 'changes': [['buy', '38331.59', '0.01455771']], 'time': '2021-05-20T03:56:04.069077Z'}
{'type': 'l2update', 'product_id': 'BTC-USD', 'changes': [['sell', '38339.88', '0.07460000']], 'time': '2021-05-20T03:56:04.069242Z'}
{'type': 'l2update', 'product_id': 'BTC-USD', 'changes': [['buy', '38331.09', '0.00000000']], 'time': '2021-05-20T03:56:04.072468Z'}
{'type': 'l2update', 'product_id': 'BTC-USD', 'changes': [['sell', '38390.09', '0.04344618']], 'time': '2021-05-20T03:56:04.072690Z'}
{'type': 'l2update', 'product_id': 'BTC-USD', 'changes': [['sell', '38340.00', '0.01492000']], 'time': '2021-05-20T03:56:04.074016Z'}
{'type': 'l2update', 'product_id': 'BTC-USD', 'changes': [['buy', '38331.59', '0.00000000']], 'time': '2021-05-20T03:56:04.074438Z'}
{'type': 'l2update', 'product_id': 'BTC-USD', 'changes': [['buy', '38136.24', '0.00000000']], 'time': '2021-05-20T03:56:04.076179Z'}
{'type': 'l2update', 'product_id': 'BTC-USD', 'changes': [['buy', '38331.32', '0.00942088']], 'time': '2021-05-20T03:56:04.077083Z'}
{'type': 'l2update', 'product_id': 'BTC-USD', 'changes': [['sell', '38390.09', '0.00000000']], 'time': '2021-05-20T03:56:04.078559Z'}
{'type': 'l2update', 'product_id': 'BTC-USD', 'changes': [['sell', '38340.00', '0.01281082']], 'time': '2021-05-20T03:56:04.079090Z'}
{'type': 'l2update', 'product_id': 'BTC-USD', 'changes': [['sell', '38340.00', '0.00000000']], 'time': '2021-05-20T03:56:04.079458Z'}
{'type': 'l2update', 'product_id': 'BTC-USD', 'changes': [['buy', '38331.32', '0.04201044']], 'time': '2021-05-20T03:56:04.081902Z'}
{'type': 'l2update', 'product_id': 'BTC-USD', 'changes': [['sell', '38396.75', '0.04344618']], 'time': '2021-05-20T03:56:04.085979Z'}
{'type': 'l2update', 'product_id': 'BTC-USD', 'changes': [['buy', '38332.10', '0.03258956']], 'time': '2021-05-20T03:56:04.086276Z'}
{'type': 'l2update', 'product_id': 'BTC-USD', 'changes': [['sell', '38339.88', '0.00000000']], 'time': '2021-05-20T03:56:04.087930Z'}
{'type': 'l2update', 'product_id': 'BTC-USD', 'changes': [['buy', '38328.91', '0.01492000']], 'time': '2021-05-20T03:56:04.090185Z'}
{'type': 'l2update', 'product_id': 'BTC-USD', 'changes': [['buy', '38149.62', '0.01000000']], 'time': '2021-05-20T03:56:04.090492Z'}
{'type': 'l2update', 'product_id': 'BTC-USD', 'changes': [['buy', '38332.10', '0.00000000']], 'time': '2021-05-20T03:56:04.091881Z'}
{'type': 'l2update', 'product_id': 'BTC-USD', 'changes': [['buy', '38331.32', '0.03258956']], 'time': '2021-05-20T03:56:04.093211Z'}
{'type': 'l2update', 'product_id': 'BTC-USD', 'changes': [['sell', '38396.75', '0.00000000']], 'time': '2021-05-20T03:56:04.093534Z'}
{'type': 'l2update', 'product_id': 'BTC-USD', 'changes': [['sell', '38390.09', '0.04344618']], 'time': '2021-05-20T03:56:04.093702Z'}
{'type': 'l2update', 'product_id': 'BTC-USD', 'changes': [['buy', '38328.91', '0.00000000']], 'time': '2021-05-20T03:56:04.096570Z'}
{'type': 'l2update', 'product_id': 'BTC-USD', 'changes': [['buy', '38331.32', '0.00000000']], 'time': '2021-05-20T03:56:04.097734Z'}
{'type': 'l2update', 'product_id': 'BTC-USD', 'changes': [['buy', '38331.71', '0.10516754']], 'time': '2021-05-20T03:56:04.098144Z'}
{'type': 'l2update', 'product_id': 'BTC-USD', 'changes': [['sell', '38339.54', '0.01492000']], 'time': '2021-05-20T03:56:04.099570Z'}
{'type': 'l2update', 'product_id': 'BTC-USD', 'changes': [['sell', '38390.09', '0.00000000']], 'time': '2021-05-20T03:56:04.099802Z'}
{'type': 'l2update', 'product_id': 'BTC-USD', 'changes': [['sell', '38339.84', '0.07460000']], 'time': '2021-05-20T03:56:04.104491Z'}
{'type': 'l2update', 'product_id': 'BTC-USD', 'changes': [['sell', '38339.54', '0.00000000']], 'time': '2021-05-20T03:56:04.106293Z'}
{'type': 'l2update', 'product_id': 'BTC-USD', 'changes': [['buy', '38329.38', '0.04201044']], 'time': '2021-05-20T03:56:04.107864Z'}
{'type': 'l2update', 'product_id': 'BTC-USD', 'changes': [['sell', '38339.84', '0.00000000']], 'time': '2021-05-20T03:56:04.108738Z'}
{'type': 'l2update', 'product_id': 'BTC-USD', 'changes': [['sell', '38396.74', '0.04344618']], 'time': '2021-05-20T03:56:04.111530Z'}
{'type': 'l2update', 'product_id': 'BTC-USD', 'changes': [['buy', '38329.38', '0.00000000']], 'time': '2021-05-20T03:56:04.112687Z'}
{'type': 'l2update', 'product_id': 'BTC-USD', 'changes': [['buy', '38278.50', '0.00000000']], 'time': '2021-05-20T03:56:04.116652Z'}
{'type': 'l2update', 'product_id': 'BTC-USD', 'changes': [['buy', '38328.76', '0.01492000']], 'time': '2021-05-20T03:56:04.117120Z'}
{'type': 'l2update', 'product_id': 'BTC-USD', 'changes': [['sell', '38390.09', '0.04344618']], 'time': '2021-05-20T03:56:04.117272Z'}
{'type': 'l2update', 'product_id': 'BTC-USD', 'changes': [['buy', '38329.38', '0.03258956']], 'time': '2021-05-20T03:56:04.117320Z'}
{'type': 'l2update', 'product_id': 'BTC-USD', 'changes': [['sell', '38339.47', '0.01492000']], 'time': '2021-05-20T03:56:04.119006Z'}
{'type': 'l2update', 'product_id': 'BTC-USD', 'changes': [['buy', '38328.76', '0.00000000']], 'time': '2021-05-20T03:56:04.122726Z'}
{'type': 'l2update', 'product_id': 'BTC-USD', 'changes': [['buy', '38329.38', '0.00000000']], 'time': '2021-05-20T03:56:04.123416Z'}
{'type': 'l2update', 'product_id': 'BTC-USD', 'changes': [['sell', '38339.91', '0.07460000']], 'time': '2021-05-20T03:56:04.123583Z'}
{'type': 'l2update', 'product_id': 'BTC-USD', 'changes': [['sell', '38339.91', '0.00000000']], 'time': '2021-05-20T03:56:04.128261Z'}
{'type': 'l2update', 'product_id': 'BTC-USD', 'changes': [['buy', '37539.16', '0.06876425']], 'time': '2021-05-20T03:56:04.128273Z'}
{'type': 'l2update', 'product_id': 'BTC-USD', 'changes': [['sell', '38396.74', '0.00000000']], 'time': '2021-05-20T03:56:04.128977Z'}
{'type': 'l2update', 'product_id': 'BTC-USD', 'changes': [['buy', '38332.02', '0.03258956']], 'time': '2021-05-20T03:56:04.136981Z'}
{'type': 'l2update', 'product_id': 'BTC-USD', 'changes': [['sell', '38367.51', '2.54400000']], 'time': '2021-05-20T03:56:04.137271Z'}
{'type': 'l2update', 'product_id': 'BTC-USD', 'changes': [['sell', '38390.09', '0.00000000']], 'time': '2021-05-20T03:56:04.137327Z'}
{'type': 'l2update', 'product_id': 'BTC-USD', 'changes': [['buy', '38332.02', '0.00000000']], 'time': '2021-05-20T03:56:04.141831Z'}
{'type': 'l2update', 'product_id': 'BTC-USD', 'changes': [['buy', '38272.50', '0.10000000']], 'time': '2021-05-20T03:56:04.144836Z'}
{'type': 'l2update', 'product_id': 'BTC-USD', 'changes': [['sell', '38388.41', '0.09552677']], 'time': '2021-05-20T03:56:04.145130Z'}
{'type': 'l2update', 'product_id': 'BTC-USD', 'changes': [['sell', '38339.47', '0.00000000']], 'time': '2021-05-20T03:56:04.147937Z'}
{'type': 'l2update', 'product_id': 'BTC-USD', 'changes': [['buy', '38307.43', '0.00000000']], 'time': '2021-05-20T03:56:04.152137Z'}
{'type': 'l2update', 'product_id': 'BTC-USD', 'changes': [['sell', '38357.84', '0.00000000']], 'time': '2021-05-20T03:56:04.155158Z'}
{'type': 'l2update', 'product_id': 'BTC-USD', 'changes': [['sell', '38340.14', '0.07460000']], 'time': '2021-05-20T03:56:04.158545Z'}
{'type': 'l2update', 'product_id': 'BTC-USD', 'changes': [['buy', '38332.07', '0.03258956']], 'time': '2021-05-20T03:56:04.161489Z'}
{'type': 'l2update', 'product_id': 'BTC-USD', 'changes': [['sell', '38339.79', '0.01492000']], 'time': '2021-05-20T03:56:04.161814Z'}
{'type': 'l2update', 'product_id': 'BTC-USD', 'changes': [['buy', '38332.05', '0.01455771']], 'time': '2021-05-20T03:56:04.161957Z'}
{'type': 'l2update', 'product_id': 'BTC-USD', 'changes': [['sell', '38388.41', '0.05208059']], 'time': '2021-05-20T03:56:04.162969Z'}
{'type': 'l2update', 'product_id': 'BTC-USD', 'changes': [['buy', '38332.05', '0.00000000']], 'time': '2021-05-20T03:56:04.167564Z'}
{'type': 'l2update', 'product_id': 'BTC-USD', 'changes': [['sell', '38340.14', '0.00000000']], 'time': '2021-05-20T03:56:04.168084Z'}
{'type': 'l2update', 'product_id': 'BTC-USD', 'changes': [['buy', '38332.07', '0.00000000']], 'time': '2021-05-20T03:56:04.168634Z'}
{'type': 'l2update', 'product_id': 'BTC-USD', 'changes': [['sell', '38339.79', '0.00000000']], 'time': '2021-05-20T03:56:04.168888Z'}
{'type': 'l2update', 'product_id': 'BTC-USD', 'changes': [['sell', '38388.40', '0.04344618']], 'time': '2021-05-20T03:56:04.170380Z'}
{'type': 'l2update', 'product_id': 'BTC-USD', 'changes': [['buy', '38332.01', '0.03258956']], 'time': '2021-05-20T03:56:04.179059Z'}
{'type': 'l2update', 'product_id': 'BTC-USD', 'changes': [['sell', '38339.53', '0.07460000']], 'time': '2021-05-20T03:56:04.179197Z'}
{'type': 'l2update', 'product_id': 'BTC-USD', 'changes': [['buy', '38332.25', '0.01455771']], 'time': '2021-05-20T03:56:04.183431Z'}
{'type': 'l2update', 'product_id': 'BTC-USD', 'changes': [['sell', '38340.11', '0.01492000']], 'time': '2021-05-20T03:56:04.183739Z'}
{'type': 'l2update', 'product_id': 'BTC-USD', 'changes': [['buy', '38332.01', '0.00000000']], 'time': '2021-05-20T03:56:04.184889Z'}
{'type': 'l2update', 'product_id': 'BTC-USD', 'changes': [['buy', '38331.71', '0.00000000']], 'time': '2021-05-20T03:56:04.188301Z'}
{'type': 'l2update', 'product_id': 'BTC-USD', 'changes': [['buy', '38332.25', '0.00000000']], 'time': '2021-05-20T03:56:04.189101Z'}
{'type': 'l2update', 'product_id': 'BTC-USD', 'changes': [['sell', '38340.11', '0.00000000']], 'time': '2021-05-20T03:56:04.189464Z'}
{'type': 'l2update', 'product_id': 'BTC-USD', 'changes': [['buy', '38299.72', '0.00000000']], 'time': '2021-05-20T03:56:04.202277Z'}
{'type': 'l2update', 'product_id': 'BTC-USD', 'changes': [['buy', '38328.95', '0.07460000']], 'time': '2021-05-20T03:56:04.203796Z'}
{'type': 'l2update', 'product_id': 'BTC-USD', 'changes': [['buy', '38328.85', '0.01492000']], 'time': '2021-05-20T03:56:04.203994Z'}
{'type': 'l2update', 'product_id': 'BTC-USD', 'changes': [['buy', '37539.16', '0.00000000']], 'time': '2021-05-20T03:56:04.206163Z'}
{'type': 'l2update', 'product_id': 'BTC-USD', 'changes': [['buy', '38329.39', '0.10516754']], 'time': '2021-05-20T03:56:04.208395Z'}
{'type': 'l2update', 'product_id': 'BTC-USD', 'changes': [['buy', '38328.85', '0.00000000']], 'time': '2021-05-20T03:56:04.210073Z'}
{'type': 'l2update', 'product_id': 'BTC-USD', 'changes': [['buy', '38296.69', '0.02400000']], 'time': '2021-05-20T03:56:04.215410Z'}
{'type': 'l2update', 'product_id': 'BTC-USD', 'changes': [['buy', '38328.95', '0.00000000']], 'time': '2021-05-20T03:56:04.215461Z'}
{'type': 'l2update', 'product_id': 'BTC-USD', 'changes': [['sell', '38339.24', '0.01492000']], 'time': '2021-05-20T03:56:04.215714Z'}
{'type': 'l2update', 'product_id': 'BTC-USD', 'changes': [['sell', '43100.00', '1.09530000']], 'time': '2021-05-20T03:56:04.215794Z'}
{'type': 'l2update', 'product_id': 'BTC-USD', 'changes': [['buy', '38248.77', '0.00000000']], 'time': '2021-05-20T03:56:04.232207Z'}
{'type': 'l2update', 'product_id': 'BTC-USD', 'changes': [['buy', '38330.03', '0.01455771']], 'time': '2021-05-20T03:56:04.239251Z'}
{'type': 'l2update', 'product_id': 'BTC-USD', 'changes': [['buy', '38329.74', '0.03451436']], 'time': '2021-05-20T03:56:04.239603Z'}
{'type': 'l2update', 'product_id': 'BTC-USD', 'changes': [['sell', '43100.00', '2.02710000']], 'time': '2021-05-20T03:56:04.239653Z'}
{'type': 'l2update', 'product_id': 'BTC-USD', 'changes': [['buy', '38329.74', '0.04910797']], 'time': '2021-05-20T03:56:04.243012Z'}
{'type': 'l2update', 'product_id': 'BTC-USD', 'changes': [['buy', '38307.72', '0.40520000']], 'time': '2021-05-20T03:56:04.243047Z'}
{'type': 'l2update', 'product_id': 'BTC-USD', 'changes': [['sell', '38442.52', '0.00000000']], 'time': '2021-05-20T03:56:04.243098Z'}
{'type': 'l2update', 'product_id': 'BTC-USD', 'changes': [['sell', '38339.53', '0.00000000']], 'time': '2021-05-20T03:56:04.244015Z'}
{'type': 'l2update', 'product_id': 'BTC-USD', 'changes': [['buy', '38315.20', '0.00000000']], 'time': '2021-05-20T03:56:04.244311Z'}
{'type': 'l2update', 'product_id': 'BTC-USD', 'changes': [['buy', '38314.33', '0.12000000']], 'time': '2021-05-20T03:56:04.248630Z'}
