{'type': 'l2update', 'product_id': 'BTC-USD', 'changes': [['buy', '38325.80', '0.52179501']], 'time': '2021-05-20T03:56:19.411018Z'}
{'type': 'l2update', 'product_id': 'BTC-USD', 'changes': [['buy', '38321.76', '0.02609483']], 'time': '2021-05-20T03:56:19.411153Z'}
{'type': 'l2update', 'product_id': 'BTC-USD', 'changes': [['buy', '38314.10', '0.00000000']], 'time': '2021-05-20T03:56:19.411265Z'}
{'type': 'l2update', 'product_id': 'BTC-USD', 'changes': [['buy', '38305.23', '0.06600000']], 'time': '2021-05-20T03:56:19.411278Z'}
{'type': 'l2update', 'product_id': 'BTC-USD', 'changes': [['sell', '38372.17', '0.00000000']], 'time': '2021-05-20T03:56:19.412476Z'}
{'type': 'l2update', 'product_id': 'BTC-USD', 'changes': [['buy', '38279.13', '0.00000000']], 'time': '2021-05-20T03:56:19.412476Z'}
{'type': 'l2update', 'product_id': 'BTC-USD', 'changes': [['sell', '38349.54', '0.00000000']], 'time': '2021-05-20T03:56:19.414193Z'}
{'type': 'l2update', 'product_id': 'BTC-USD', 'changes': [['buy', '38283.00', '0.00000000']], 'time': '2021-05-20T03:56:19.414783Z'}
{'type': 'l2update', 'product_id': 'BTC-USD', 'changes': [['sell', '38384.35', '0.38105453']], 'time': '2021-05-20T03:56:19.414832Z'}
{'type': 'l2update', 'product_id': 'BTC-USD', 'changes': [['sell', '38467.89', '0.12997856']], 'time': '2021-05-20T03:56:19.414994Z'}
{'type': 'l2update', 'product_id': 'BTC-USD', 'changes': [['buy', '38179.73', '0.04994645']], 'time': '2021-05-20T03:56:19.415334Z'}
{'type': 'l2update', 'product_id': 'BTC-USD', 'changes': [['buy', '38311.84', '0.00000000']], 'time': '2021-05-20T03:56:19.416631Z'}
{'type': 'l2update', 'product_id': 'BTC-USD', 'changes': [['sell', '38355.40', '1.07700000']], 'time': '2021-05-20T03:56:19.419145Z'}
{'type': 'l2update', 'product_id': 'BTC-USD', 'changes': [['buy', '38336.72', '0.00000000']], 'time': '2021-05-20T03:56:19.422295Z'}
{'type': 'l2update', 'product_id': 'BTC-USD', 'changes': [['sell', '38393.32', '0.00000000']], 'time': '2021-05-20T03:56:19.426997Z'}
{'type': 'l2update', 'product_id': 'BTC-USD', 'changes': [['sell', '38372.06', '0.40390000']], 'time': '2021-05-20T03:56:19.430359Z'}
{'type': 'l2update', 'product_id': 'BTC-USD', 'changes': [['sell', '38355.40', '1.63000000']], 'time': '2021-05-20T03:56:19.430538Z'}
{'type': 'l2update', 'product_id': 'BTC-USD', 'changes': [['sell', '38369.99', '0.00000000']], 'time': '2021-05-20T03:56:19.433819Z'}
{'type': 'l2update', 'product_id': 'BTC-USD', 'changes': [['sell', '38355.44', '2.48969908']], 'time': '2021-05-20T03:56:19.434710Z'}
{'type': 'l2update', 'product_id': 'BTC-USD', 'changes': [['buy', '38350.74', '0.01492000']], 'time': '2021-05-20T03:56:19.435011Z'}
{'type': 'l2update', 'product_id': 'BTC-USD', 'changes': [['buy', '38336.77', '0.84700000']], 'time': '2021-05-20T03:56:19.435828Z'}
{'type': 'l2update', 'product_id': 'BTC-USD', 'changes': [['sell', '38380.80', '0.05171009']], 'time': '2021-05-20T03:56:19.435858Z'}
{'type': 'l2update', 'product_id': 'BTC-USD', 'changes': [['sell', '38369.98', '0.00000000']], 'time': '2021-05-20T03:56:19.441271Z'}
{'type': 'l2update', 'product_id': 'BTC-USD', 'changes': [['buy', '38327.05', '0.46730000']], 'time': '2021-05-20T03:56:19.444377Z'}
{'type': 'l2update', 'product_id': 'BTC-USD', 'changes': [['buy', '38323.96', '0.52100000']], 'time': '2021-05-20T03:56:19.445006Z'}
{'type': 'l2update', 'product_id': 'BTC-USD', 'changes': [['buy', '38324.71', '0.00000000']], 'time': '2021-05-20T03:56:19.445439Z'}
{'type': 'l2update', 'product_id': 'BTC-USD', 'changes': [['buy', '38174.33', '0.00000000']], 'time': '2021-05-20T03:56:19.446828Z'}
{'type': 'l2update', 'product_id': 'BTC-USD', 'changes': [['buy', '37654.92', '0.00000000']], 'time': '2021-05-20T03:56:19.447110Z'}
{'type': 'l2update', 'product_id': 'BTC-USD', 'changes': [['sell', '38350.75', '0.00000000']], 'time': '2021-05-20T03:56:19.448360Z'}
{'type': 'l2update', 'product_id': 'BTC-USD', 'changes': [['buy', '38326.99', '0.00000000']], 'time': '2021-05-20T03:56:19.452111Z'}
{'type': 'l2update', 'product_id': 'BTC-USD', 'changes': [['buy', '38336.77', '0.00000000']], 'time': '2021-05-20T03:56:19.452155Z'}
{'type': 'l2update', 'product_id': 'BTC-USD', 'changes': [['buy', '38318.77', '0.06420512']], 'time': '2021-05-20T03:56:19.453300Z'}
{'type': 'l2update', 'product_id': 'BTC-USD', 'changes': [['buy', '38324.72', '0.00000000']], 'time': '2021-05-20T03:56:19.454149Z'}
{'type': 'l2update', 'product_id': 'BTC-USD', 'changes': [['sell', '38361.02', '0.00000000']], 'time': '2021-05-20T03:56:19.454649Z'}
{'type': 'l2update', 'product_id': 'BTC-USD', 'changes': [['buy', '38350.74', '0.00000000']], 'time': '2021-05-20T03:56:19.454684Z'}
{'type': 'l2update', 'product_id': 'BTC-USD', 'changes': [['buy', '38315.40', '0.00000000']], 'time': '2021-05-20T03:56:19.456537Z'}
{'type': 'l2update', 'product_id': 'BTC-USD', 'changes': [['buy', '38301.90', '0.00000000']], 'time': '2021-05-20T03:56:19.458256Z'}
{'type': 'l2update', 'product_id': 'BTC-USD', 'changes': [['sell', '38373.44', '0.00000000']], 'time': '2021-05-20T03:56:19.459160Z'}
{'type': 'l2update', 'product_id': 'BTC-USD', 'changes': [['sell', '38372.05', '0.05000000']], 'time': '2021-05-20T03:56:19.459332Z'}
{'type': 'l2update', 'product_id': 'BTC-USD', 'changes': [['sell', '38360.23', '0.55300000']], 'time': '2021-05-20T03:56:19.464091Z'}
{'type': 'l2update', 'product_id': 'BTC-USD', 'changes': [['sell', '38372.05', '0.00000000']], 'time': '2021-05-20T03:56:19.466181Z'}
{'type': 'l2update', 'product_id': 'BTC-USD', 'changes': [['buy', '38317.89', '0.09476202']], 'time': '2021-05-20T03:56:19.467957Z'}
{'type': 'l2update', 'product_id': 'BTC-USD', 'changes': [['buy', '38328.59', '0.84600000']], 'time': '2021-05-20T03:56:19.468021Z'}
{'type': 'l2update', 'product_id': 'BTC-USD', 'changes': [['buy', '37547.32', '0.06947320']], 'time': '2021-05-20T03:56:19.468534Z'}
{'type': 'l2update', 'product_id': 'BTC-USD', 'changes': [['buy', '38277.63', '0.00000000']], 'time': '2021-05-20T03:56:19.468562Z'}
{'type': 'l2update', 'product_id': 'BTC-USD', 'changes': [['sell', '38477.81', '0.67768265']], 'time': '2021-05-20T03:56:19.468644Z'}
{'type': 'l2update', 'product_id': 'BTC-USD', 'changes': [['buy', '38293.80', '0.03808479']], 'time': '2021-05-20T03:56:19.469982Z'}
{'type': 'l2update', 'product_id': 'BTC-USD', 'changes': [['sell', '38354.72', '0.01492000']], 'time': '2021-05-20T03:56:19.470181Z'}
{'type': 'l2update', 'product_id': 'BTC-USD', 'changes': [['sell', '38354.75', '0.07460000']], 'time': '2021-05-20T03:56:19.470335Z'}
{'type': 'l2update', 'product_id': 'BTC-USD', 'changes': [['sell', '38355.40', '0.55300000']], 'time': '2021-05-20T03:56:19.471468Z'}
{'type': 'l2update', 'product_id': 'BTC-USD', 'changes': [['sell', '38355.40', '0.00000000']], 'time': '2021-05-20T03:56:19.472925Z'}
{'type': 'l2update', 'product_id': 'BTC-USD', 'changes': [['buy', '38328.55', '1.12906192']], 'time': '2021-05-20T03:56:19.474507Z'}
{'type': 'l2update', 'product_id': 'BTC-USD', 'changes': [['sell', '38372.06', '0.00000000']], 'time': '2021-05-20T03:56:19.474542Z'}
{'type': 'l2update', 'product_id': 'BTC-USD', 'changes': [['buy', '38327.06', '0.59116555']], 'time': '2021-05-20T03:56:19.474701Z'}
{'type': 'l2update', 'product_id': 'BTC-USD', 'changes': [['sell', '38355.39', '0.50000000']], 'time': '2021-05-20T03:56:19.474764Z'}
{'type': 'l2update', 'product_id': 'BTC-USD', 'changes': [['buy', '38345.47', '0.01492000']], 'time': '2021-05-20T03:56:19.474913Z'}
{'type': 'l2update', 'product_id': 'BTC-USD', 'changes': [['sell', '38372.22', '0.00000000']], 'time': '2021-05-20T03:56:19.476110Z'}
{'type': 'l2update', 'product_id': 'BTC-USD', 'changes': [['sell', '38398.39', '0.00000000']], 'time': '2021-05-20T03:56:19.477327Z'}
{'type': 'l2update', 'product_id': 'BTC-USD', 'changes': [['buy', '38274.39', '0.00000000']], 'time': '2021-05-20T03:56:19.477355Z'}
{'type': 'l2update', 'product_id': 'BTC-USD', 'changes': [['sell', '38360.23', '0.00000000']], 'time': '2021-05-20T03:56:19.477634Z'}
{'type': 'l2update', 'product_id': 'BTC-USD', 'changes': [['sell', '38354.75', '0.00000000']], 'time': '2021-05-20T03:56:19.477921Z'}
{'type': 'l2update', 'product_id': 'BTC-USD', 'changes': [['sell', '38379.97', '0.05000000']], 'time': '2021-05-20T03:56:19.481456Z'}
{'type': 'l2update', 'product_id': 'BTC-USD', 'changes': [['sell', '38384.34', '0.09912891']], 'time': '2021-05-20T03:56:19.481844Z'}
{'type': 'l2update', 'product_id': 'BTC-USD', 'changes': [['sell', '38354.72', '0.01240366']], 'time': '2021-05-20T03:56:19.482056Z'}
{'type': 'l2update', 'product_id': 'BTC-USD', 'changes': [['sell', '39147.57', '0.06876103']], 'time': '2021-05-20T03:56:19.482182Z'}
{'type': 'l2update', 'product_id': 'BTC-USD', 'changes': [['sell', '38379.97', '0.00000000']], 'time': '2021-05-20T03:56:19.487420Z'}
{'type': 'l2update', 'product_id': 'BTC-USD', 'changes': [['buy', '38340.71', '0.84600000']], 'time': '2021-05-20T03:56:19.488434Z'}
{'type': 'l2update', 'product_id': 'BTC-USD', 'changes': [['sell', '38355.39', '0.00000000']], 'time': '2021-05-20T03:56:19.493596Z'}
{'type': 'l2update', 'product_id': 'BTC-USD', 'changes': [['sell', '38360.23', '1.02300000']], 'time': '2021-05-20T03:56:19.494229Z'}
{'type': 'l2update', 'product_id': 'BTC-USD', 'changes': [['buy', '38289.47', '1.28132197']], 'time': '2021-05-20T03:56:19.494433Z'}
{'type': 'l2update', 'product_id': 'BTC-USD', 'changes': [['sell', '38410.26', '0.61482417']], 'time': '2021-05-20T03:56:19.494478Z'}
{'type': 'l2update', 'product_id': 'BTC-USD', 'changes': [['buy', '38345.73', '0.05119209']], 'time': '2021-05-20T03:56:19.494527Z'}
{'type': 'l2update', 'product_id': 'BTC-USD', 'changes': [['sell', '38397.64', '0.00000000']], 'time': '2021-05-20T03:56:19.495950Z'}
{'type': 'l2update', 'product_id': 'BTC-USD', 'changes': [['sell', '38372.05', '0.05000000']], 'time': '2021-05-20T03:56:19.498042Z'}
{'type': 'l2update', 'product_id': 'BTC-USD', 'changes': [['buy', '38345.73', '0.07460000']], 'time': '2021-05-20T03:56:19.498180Z'}
{'type': 'l2update', 'product_id': 'BTC-USD', 'changes': [['sell', '38360.23', '1.57600000']], 'time': '2021-05-20T03:56:19.502528Z'}
{'type': 'l2update', 'product_id': 'BTC-USD', 'changes': [['sell', '38378.36', '0.00000000']], 'time': '2021-05-20T03:56:19.503074Z'}
{'type': 'l2update', 'product_id': 'BTC-USD', 'changes': [['buy', '38317.88', '0.00000000']], 'time': '2021-05-20T03:56:19.503125Z'}
{'type': 'l2update', 'product_id': 'BTC-USD', 'changes': [['buy', '38296.41', '0.00000000']], 'time': '2021-05-20T03:56:19.504233Z'}
{'type': 'l2update', 'product_id': 'BTC-USD', 'changes': [['sell', '38355.44', '0.00000000']], 'time': '2021-05-20T03:56:19.504314Z'}
{'type': 'l2update', 'product_id': 'BTC-USD', 'changes': [['buy', '38345.47', '0.00000000']], 'time': '2021-05-20T03:56:19.504450Z'}
{'type': 'l2update', 'product_id': 'BTC-USD', 'changes': [['sell', '38372.05', '0.00000000']], 'time': '2021-05-20T03:56:19.505681Z'}
{'type': 'l2update', 'product_id': 'BTC-USD', 'changes': [['sell', '38360.27', '0.50000000']], 'time': '2021-05-20T03:56:19.509619Z'}
{'type': 'l2update', 'product_id': 'BTC-USD', 'changes': [['buy', '38328.54', '0.00000000']], 'time': '2021-05-20T03:56:19.510004Z'}
{'type': 'l2update', 'product_id': 'BTC-USD', 'changes': [['sell', '38377.76', '0.00000000']], 'time': '2021-05-20T03:56:19.510352Z'}
{'type': 'l2update', 'product_id': 'BTC-USD', 'changes': [['buy', '38340.71', '0.00000000']], 'time': '2021-05-20T03:56:19.510401Z'}
{'type': 'l2update', 'product_id': 'BTC-USD', 'changes': [['buy', '38321.94', '0.00000000']], 'time': '2021-05-20T03:56:19.512402Z'}
{'type': 'l2update', 'product_id': 'BTC-USD', 'changes': [['sell', '38360.23', '1.02300000']], 'time': '2021-05-20T03:56:19.513146Z'}
{'type': 'l2update', 'product_id': 'BTC-USD', 'changes': [['sell', '38431.46', '0.00000000']], 'time': '2021-05-20T03:56:19.514287Z'}
{'type': 'l2update', 'product_id': 'BTC-USD', 'changes': [['buy', '38324.01', '0.00000000']], 'time': '2021-05-20T03:56:19.516589Z'}
{'type': 'l2update', 'product_id': 'BTC-USD', 'changes': [['sell', '38389.20', '0.01000000']], 'time': '2021-05-20T03:56:19.518212Z'}
{'type': 'l2update', 'product_id': 'BTC-USD', 'changes': [['buy', '38345.73', '0.07446899']], 'time': '2021-05-20T03:56:19.518503Z'}
{'type': 'l2update', 'product_id': 'BTC-USD', 'changes': [['sell', '38367.67', '0.09521871']], 'time': '2021-05-20T03:56:19.518531Z'}
{'type': 'l2update', 'product_id': 'BTC-USD', 'changes': [['buy', '38323.96', '0.00000000']], 'time': '2021-05-20T03:56:19.520342Z'}
{'type': 'l2update', 'product_id': 'BTC-USD', 'changes': [['buy', '38032.11', '0.00000000']], 'time': '2021-05-20T03:56:19.520682Z'}
{'type': 'l2update', 'product_id': 'BTC-USD', 'changes': [['buy', '38281.33', '0.00000000']], 'time': '2021-05-20T03:56:19.522011Z'}
{'type': 'l2update', 'product_id': 'BTC-USD', 'changes': [['sell', '38434.73', '0.00000000']], 'time': '2021-05-20T03:56:19.522301Z'}
{'type': 'l2update', 'product_id': 'BTC-USD', 'changes': [['buy', '38326.98', '0.00000000']], 'time': '2021-05-20T03:56:19.525057Z'}
{'type': 'l2update', 'product_id': 'BTC-USD', 'changes': [['sell', '38372.21', '0.05000000']], 'time': '2021-05-20T03:56:19.526095Z'}
{'type': 'l2update', 'product_id': 'BTC-USD', 'changes': [['sell', '38384.39', '0.01000000']], 'time': '2021-05-20T03:56:19.526421Z'}
{'type': 'l2update', 'product_id': 'BTC-USD', 'changes': [['sell', '38477.81', '1.01412423']], 'time': '2021-05-20T03:56:19.526541Z'}
{'type': 'l2update', 'product_id': 'BTC-USD', 'changes': [['sell', '38360.27', '2.98969908']], 'time': '2021-05-20T03:56:19.531478Z'}
{'type': 'l2update', 'product_id': 'BTC-USD', 'changes': [['buy', '38327.06', '0.00000000']], 'time': '2021-05-20T03:56:19.532808Z'}
{'type': 'l2update', 'product_id': 'BTC-USD', 'changes': [['sell', '38355.45', '0.00000000']], 'time': '2021-05-20T03:56:19.535824Z'}
{'type': 'l2update', 'product_id': 'BTC-USD', 'changes': [['buy', '38045.00', '0.02325000']], 'time': '2021-05-20T03:56:19.538144Z'}
{'type': 'l2update', 'product_id': 'BTC-USD', 'changes': [['buy', '38282.97', '0.03526465']], 'time': '2021-05-20T03:56:19.538273Z'}
{'type': 'l2update', 'product_id': 'BTC-USD', 'changes': [['buy', '38288.09', '0.02864374']], 'time': '2021-05-20T03:56:19.538273Z'}
{'type': 'l2update', 'product_id': 'BTC-USD', 'changes': [['buy', '38306.75', '0.01000000']], 'time': '2021-05-20T03:56:19.538474Z'}
{'type': 'l2update', 'product_id': 'BTC-USD', 'changes': [['sell', '38518.73', '0.30077530']], 'time': '2021-05-20T03:56:19.538549Z'}
{'type': 'l2update', 'product_id': 'BTC-USD', 'changes': [['buy', '38328.60', '0.84600000']], 'time': '2021-05-20T03:56:19.542002Z'}
{'type': 'l2update', 'product_id': 'BTC-USD', 'changes': [['sell', '38384.39', '0.04000000']], 'time': '2021-05-20T03:56:19.542596Z'}
{'type': 'l2update', 'product_id': 'BTC-USD', 'changes': [['sell', '38446.35', '0.00000000']], 'time': '2021-05-20T03:56:19.544312Z'}
{'type': 'l2update', 'product_id': 'BTC-USD', 'changes': [['buy', '38259.04', '0.00000000']], 'time': '2021-05-20T03:56:19.545594Z'}
{'type': 'l2update', 'product_id': 'BTC-USD', 'changes': [['buy', '38264.34', '0.00000000']], 'time': '2021-05-20T03:56:19.545594Z'}
{'type': 'l2update', 'product_id': 'BTC-USD', 'changes': [['buy', '37547.32', '0.00000000']], 'time': '2021-05-20T03:56:19.546264Z'}
{'type': 'l2update', 'product_id': 'BTC-USD', 'changes': [['buy', '38346.05', '0.01492000']], 'time': '2021-05-20T03:56:19.547682Z'}
{'type': 'l2update', 'product_id': 'BTC-USD', 'changes': [['sell', '38367.68', '0.00000000']], 'time': '2021-05-20T03:56:19.548544Z'}
{'type': 'l2update', 'product_id': 'BTC-USD', 'changes': [['buy', '38344.91', '0.10000000']], 'time': '2021-05-20T03:56:19.554005Z'}
{'type': 'l2update', 'product_id': 'BTC-USD', 'changes': [['sell', '39147.57', '0.00000000']], 'time': '2021-05-20T03:56:19.554466Z'}
{'type': 'l2update', 'product_id': 'BTC-USD', 'changes': [['buy', '38323.92', '0.49148286']], 'time': '2021-05-20T03:56:19.554886Z'}
{'type': 'l2update', 'product_id': 'BTC-USD', 'changes': [['buy', '38345.73', '0.02340791']], 'time': '2021-05-20T03:56:19.556448Z'}
{'type': 'l2update', 'product_id': 'BTC-USD', 'changes': [['buy', '38345.73', '0.00000000']], 'time': '2021-05-20T03:56:19.557558Z'}
{'type': 'l2update', 'product_id': 'BTC-USD', 'changes': [['sell', '38354.72', '0.00000000']], 'time': '2021-05-20T03:56:19.557595Z'}
{'type': 'l2update', 'product_id': 'BTC-USD', 'changes': [['sell', '38465.24', '0.06515940']], 'time': '2021-05-20T03:56:19.557961Z'}
{'type': 'l2update', 'product_id': 'BTC-USD', 'changes': [['sell', '38367.70', '0.00000000']], 'time': '2021-05-20T03:56:19.558533Z'}
{'type': 'l2update', 'product_id': 'BTC-USD', 'changes': [['sell', '38359.80', '0.00251634']], 'time': '2021-05-20T03:56:19.562226Z'}
{'type': 'l2update', 'product_id': 'BTC-USD', 'changes': [['sell', '38360.23', '0.00000000']], 'time': '2021-05-20T03:56:19.562595Z'}
{'type': 'l2update', 'product_id': 'BTC-USD', 'changes': [['buy', '38346.05', '0.00000000']], 'time': '2021-05-20T03:56:19.564626Z'}
{'type': 'l2update', 'product_id': 'BTC-USD', 'changes': [['sell', '38518.73', '0.00000000']], 'time': '2021-05-20T03:56:19.566757Z'}
{'type': 'l2update', 'product_id': 'BTC-USD', 'changes': [['sell', '38373.92', '0.42090000']], 'time': '2021-05-20T03:56:19.566947Z'}
{'type': 'l2update', 'product_id': 'BTC-USD', 'changes': [['buy', '38346.69', '0.07460000']], 'time': '2021-05-20T03:56:19.570622Z'}
{'type': 'l2update', 'product_id': 'BTC-USD', 'changes': [['sell', '38354.41', '0.00998606']], 'time': '2021-05-20T03:56:19.570724Z'}
{'type': 'l2update', 'product_id': 'BTC-USD', 'changes': [['sell', '38379.98', '0.41807384']], 'time': '2021-05-20T03:56:19.571644Z'}
{'type': 'l2update', 'product_id': 'BTC-USD', 'changes': [['sell', '38359.70', '0.06461394']], 'time': '2021-05-20T03:56:19.575456Z'}
{'type': 'l2update', 'product_id': 'BTC-USD', 'changes': [['sell', '38395.57', '0.03207306']], 'time': '2021-05-20T03:56:19.575488Z'}
{'type': 'l2update', 'product_id': 'BTC-USD', 'changes': [['sell', '38359.80', '0.01492000']], 'time': '2021-05-20T03:56:19.575588Z'}
{'type': 'l2update', 'product_id': 'BTC-USD', 'changes': [['buy', '38346.69', '0.00000000']], 'time': '2021-05-20T03:56:19.575674Z'}
{'type': 'l2update', 'product_id': 'BTC-USD', 'changes': [['sell', '38372.21', '0.00000000']], 'time': '2021-05-20T03:56:19.576570Z'}
{'type': 'l2update', 'product_id': 'BTC-USD', 'changes': [['sell', '38354.41', '0.00000000']], 'time': '2021-05-20T03:56:19.576785Z'}
{'type': 'l2update', 'product_id': 'BTC-USD', 'changes': [['sell', '38360.27', '2.48969908']], 'time': '2021-05-20T03:56:19.581680Z'}
{'type': 'l2update', 'product_id': 'BTC-USD', 'changes': [['sell', '38359.80', '0.00251634']], 'time': '2021-05-20T03:56:19.583202Z'}
{'type': 'l2update', 'product_id': 'BTC-USD', 'changes': [['sell', '38359.80', '0.00000000']], 'time': '2021-05-20T03:56:19.583412Z'}
{'type': 'l2update', 'product_id': 'BTC-USD', 'changes': [['buy', '38340.66', '0.00000000']], 'time': '2021-05-20T03:56:19.585654Z'}
{'type': 'l2update', 'product_id': 'BTC-USD', 'changes': [['buy', '38328.55', '1.19384321']], 'time': '2021-05-20T03:56:19.586424Z'}
{'type': 'l2update', 'product_id': 'BTC-USD', 'changes': [['buy', '38340.67', '0.59116555']], 'time': '2021-05-20T03:56:19.586458Z'}
{'type': 'l2update', 'product_id': 'BTC-USD', 'changes': [['buy', '38345.55', '0.01492000']], 'time': '2021-05-20T03:56:19.586491Z'}
{'type': 'l2update', 'product_id': 'BTC-USD', 'changes': [['buy', '38331.82', '0.07091213']], 'time': '2021-05-20T03:56:19.586742Z'}
{'type': 'l2update', 'product_id': 'BTC-USD', 'changes': [['buy', '38199.58', '0.01000000']], 'time': '2021-05-20T03:56:19.586822Z'}
{'type': 'l2update', 'product_id': 'BTC-USD', 'changes': [['buy', '38262.30', '0.00000000']], 'time': '2021-05-20T03:56:19.589761Z'}
{'type': 'l2update', 'product_id': 'BTC-USD', 'changes': [['buy', '38345.55', '0.08952000']], 'time': '2021-05-20T03:56:19.591118Z'}
{'type': 'l2update', 'product_id': 'BTC-USD', 'changes': [['sell', '38373.91', '0.05000000']], 'time': '2021-05-20T03:56:19.591227Z'}
{'type': 'l2update', 'product_id': 'BTC-USD', 'changes': [['sell', '38379.47', '0.00000000']], 'time': '2021-05-20T03:56:19.591285Z'}
{'type': 'l2update', 'product_id': 'BTC-USD', 'changes': [['buy', '38345.55', '0.07460000']], 'time': '2021-05-20T03:56:19.592980Z'}
{'type': 'l2update', 'product_id': 'BTC-USD', 'changes': [['buy', '38214.23', '0.43317308']], 'time': '2021-05-20T03:56:19.593511Z'}
{'type': 'l2update', 'product_id': 'BTC-USD', 'changes': [['buy', '38260.61', '0.33003093']], 'time': '2021-05-20T03:56:19.593511Z'}
{'type': 'l2update', 'product_id': 'BTC-USD', 'changes': [['buy', '38266.48', '0.33825624']], 'time': '2021-05-20T03:56:19.593511Z'}
{'type': 'l2update', 'product_id': 'BTC-USD', 'changes': [['buy', '38272.16', '0.12753130']], 'time': '2021-05-20T03:56:19.593511Z'}
{'type': 'l2update', 'product_id': 'BTC-USD', 'changes': [['sell', '38359.70', '0.06400386']], 'time': '2021-05-20T03:56:19.593785Z'}
{'type': 'l2update', 'product_id': 'BTC-USD', 'changes': [['sell', '38367.66', '0.50000000']], 'time': '2021-05-20T03:56:19.597034Z'}
{'type': 'l2update', 'product_id': 'BTC-USD', 'changes': [['buy', '38323.03', '0.00000000']], 'time': '2021-05-20T03:56:19.597317Z'}
{'type': 'l2update', 'product_id': 'BTC-USD', 'changes': [['buy', '38345.55', '0.00000000']], 'time': '2021-05-20T03:56:19.599512Z'}
{'type': 'l2update', 'product_id': 'BTC-USD', 'changes': [['buy', '38226.01', '0.41463942']], 'time': '2021-05-20T03:56:19.602857Z'}
{'type': 'l2update', 'product_id': 'BTC-USD', 'changes': [['buy', '38232.82', '0.03142865']], 'time': '2021-05-20T03:56:19.602857Z'}
{'type': 'l2update', 'product_id': 'BTC-USD', 'changes': [['buy', '38239.45', '0.00000000']], 'time': '2021-05-20T03:56:19.602857Z'}
{'type': 'l2update', 'product_id': 'BTC-USD', 'changes': [['sell', '38359.20', '0.01492000']], 'time': '2021-05-20T03:56:19.602968Z'}
{'type': 'l2update', 'product_id': 'BTC-USD', 'changes': [['sell', '38359.65', '1.09000000']], 'time': '2021-05-20T03:56:19.603079Z'}
{'type': 'l2update', 'product_id': 'BTC-USD', 'changes': [['sell', '38364.02', '0.00600000']], 'time': '2021-05-20T03:56:19.603264Z'}
{'type': 'l2update', 'product_id': 'BTC-USD', 'changes': [['buy', '38299.14', '0.00000000']], 'time': '2021-05-20T03:56:19.606149Z'}
{'type': 'l2update', 'product_id': 'BTC-USD', 'changes': [['sell', '38359.70', '0.00000000']], 'time': '2021-05-20T03:56:19.609576Z'}
{'type': 'l2update', 'product_id': 'BTC-USD', 'changes': [['sell', '38472.71', '0.03381731']], 'time': '2021-05-20T03:56:19.609889Z'}
{'type': 'l2update', 'product_id': 'BTC-USD', 'changes': [['sell', '38380.80', '0.00000000']], 'time': '2021-05-20T03:56:19.612722Z'}
{'type': 'l2update', 'product_id': 'BTC-USD', 'changes': [['buy', '38305.23', '0.00000000']], 'time': '2021-05-20T03:56:19.614352Z'}
{'type': 'l2update', 'product_id': 'BTC-USD', 'changes': [['sell', '38399.10', '0.00000000']], 'time': '2021-05-20T03:56:19.614352Z'}
{'type': 'l2update', 'product_id': 'BTC-USD', 'changes': [['buy', '38279.44', '0.00000000']], 'time': '2021-05-20T03:56:19.614352Z'}
{'type': 'l2update', 'product_id': 'BTC-USD', 'changes': [['buy', '38219.33', '0.00000000']], 'time': '2021-05-20T03:56:19.614352Z'}
{'type': 'l2update', 'product_id': 'BTC-USD', 'changes': [['sell', '38439.63', '0.00000000']], 'time': '2021-05-20T03:56:19.614753Z'}
{'type': 'l2update', 'product_id': 'BTC-USD', 'changes': [['sell', '38465.16', '0.00000000']], 'time': '2021-05-20T03:56:19.614753Z'}
{'type': 'l2update', 'product_id': 'BTC-USD', 'changes': [['sell', '38384.35', '0.34247068']], 'time': '2021-05-20T03:56:19.614775Z'}
{'type': 'l2update', 'product_id': 'BTC-USD', 'changes': [['buy', '38345.82', '0.01492000']], 'time': '2021-05-20T03:56:19.616789Z'}
{'type': 'l2update', 'product_id': 'BTC-USD', 'changes': [['sell', '38387.97', '0.02000000']], 'time': '2021-05-20T03:56:19.616817Z'}
{'type': 'l2update', 'product_id': 'BTC-USD', 'changes': [['buy', '38345.55', '0.07460000']], 'time': '2021-05-20T03:56:19.617793Z'}
{'type': 'l2update', 'product_id': 'BTC-USD', 'changes': [['sell', '38358.81', '0.01059614']], 'time': '2021-05-20T03:56:19.617922Z'}
{'type': 'l2update', 'product_id': 'BTC-USD', 'changes': [['buy', '38336.71', '0.00000000']], 'time': '2021-05-20T03:56:19.618322Z'}
{'type': 'l2update', 'product_id': 'BTC-USD', 'changes': [['buy', '38338.27', '0.00300000']], 'time': '2021-05-20T03:56:19.622285Z'}
{'type': 'l2update', 'product_id': 'BTC-USD', 'changes': [['sell', '38359.20', '0.00000000']], 'time': '2021-05-20T03:56:19.627049Z'}
{'type': 'l2update', 'product_id': 'BTC-USD', 'changes': [['sell', '38358.81', '0.07460000']], 'time': '2021-05-20T03:56:19.634569Z'}
{'type': 'l2update', 'product_id': 'BTC-USD', 'changes': [['sell', '38518.10', '0.30077479']], 'time': '2021-05-20T03:56:19.634875Z'}
{'type': 'l2update', 'product_id': 'BTC-USD', 'changes': [['sell', '38479.43', '0.01113060']], 'time': '2021-05-20T03:56:19.636660Z'}
{'type': 'l2update', 'product_id': 'BTC-USD', 'changes': [['buy', '38279.27', '0.00000000']], 'time': '2021-05-20T03:56:19.639307Z'}
{'type': 'l2update', 'product_id': 'BTC-USD', 'changes': [['buy', '38345.55', '0.00000000']], 'time': '2021-05-20T03:56:19.639627Z'}
{'type': 'l2update', 'product_id': 'BTC-USD', 'changes': [['buy', '38271.75', '0.00000000']], 'time': '2021-05-20T03:56:19.639976Z'}
{'type': 'l2update', 'product_id': 'BTC-USD', 'changes': [['buy', '38129.10', '0.00000000']], 'time': '2021-05-20T03:56:19.640025Z'}
{'type': 'l2update', 'product_id': 'BTC-USD', 'changes': [['sell', '38428.38', '0.00000000']], 'time': '2021-05-20T03:56:19.640461Z'}
{'type': 'l2update', 'product_id': 'BTC-USD', 'changes': [['buy', '38340.67', '0.00000000']], 'time': '2021-05-20T03:56:19.640989Z'}
{'type': 'l2update', 'product_id': 'BTC-USD', 'changes': [['sell', '38431.58', '0.00000000']], 'time': '2021-05-20T03:56:19.644525Z'}
{'type': 'l2update', 'product_id': 'BTC-USD', 'changes': [['sell', '38612.30', '0.00000000']], 'time': '2021-05-20T03:56:19.645046Z'}
{'type': 'l2update', 'product_id': 'BTC-USD', 'changes': [['sell', '38373.92', '0.00000000']], 'time': '2021-05-20T03:56:19.646290Z'}
{'type': 'l2update', 'product_id': 'BTC-USD', 'changes': [['buy', '38002.42', '0.00000000']], 'time': '2021-05-20T03:56:19.650455Z'}
{'type': 'l2update', 'product_id': 'BTC-USD', 'changes': [['sell', '38358.15', '0.01492000']], 'time': '2021-05-20T03:56:19.650569Z'}
{'type': 'l2update', 'product_id': 'BTC-USD', 'changes': [['buy', '37654.90', '0.00000000']], 'time': '2021-05-20T03:56:19.656642Z'}
{'type': 'l2update', 'product_id': 'BTC-USD', 'changes': [['sell', '38358.81', '0.06400386']], 'time': '2021-05-20T03:56:19.657952Z'}
{'type': 'l2update', 'product_id': 'BTC-USD', 'changes': [['buy', '38036.24', '0.95058042']], 'time': '2021-05-20T03:56:19.660225Z'}
{'type': 'l2update', 'product_id': 'BTC-USD', 'changes': [['buy', '37469.34', '0.00000000']], 'time': '2021-05-20T03:56:19.663269Z'}
{'type': 'l2update', 'product_id': 'BTC-USD', 'changes': [['buy', '38328.61', '0.59116555']], 'time': '2021-05-20T03:56:19.664894Z'}
{'type': 'l2update', 'product_id': 'BTC-USD', 'changes': [['buy', '38346.37', '0.07460000']], 'time': '2021-05-20T03:56:19.664978Z'}
{'type': 'l2update', 'product_id': 'BTC-USD', 'changes': [['buy', '38129.11', '0.00000000']], 'time': '2021-05-20T03:56:19.668611Z'}
{'type': 'l2update', 'product_id': 'BTC-USD', 'changes': [['sell', '38358.81', '0.00000000']], 'time': '2021-05-20T03:56:19.672492Z'}
{'type': 'l2update', 'product_id': 'BTC-USD', 'changes': [['buy', '38345.82', '0.00000000']], 'time': '2021-05-20T03:56:19.673909Z'}
{'type': 'l2update', 'product_id': 'BTC-USD', 'changes': [['sell', '38465.62', '0.03208242']], 'time': '2021-05-20T03:56:19.676879Z'}
{'type': 'l2update', 'product_id': 'BTC-USD', 'changes': [['sell', '38357.91', '0.01059614']], 'time': '2021-05-20T03:56:19.676938Z'}
{'type': 'l2update', 'product_id': 'BTC-USD', 'changes': [['buy', '38306.60', '2.37600000']], 'time': '2021-05-20T03:56:19.678769Z'}
{'type': 'l2update', 'product_id': 'BTC-USD', 'changes': [['buy', '38248.20', '0.66500000']], 'time': '2021-05-20T03:56:19.678964Z'}
{'type': 'l2update', 'product_id': 'BTC-USD', 'changes': [['sell', '38421.80', '0.20400000']], 'time': '2021-05-20T03:56:19.678964Z'}
{'type': 'l2update', 'product_id': 'BTC-USD', 'changes': [['sell', '38460.17', '0.66500000']], 'time': '2021-05-20T03:56:19.678964Z'}
{'type': 'l2update', 'product_id': 'BTC-USD', 'changes': [['buy', '38305.71', '0.06600000']], 'time': '2021-05-20T03:56:19.678964Z'}
{'type': 'l2update', 'product_id': 'BTC-USD', 'changes': [['buy', '38286.54', '0.20400000']], 'time': '2021-05-20T03:56:19.678964Z'}
{'type': 'l2update', 'product_id': 'BTC-USD', 'changes': [['sell', '38402.62', '0.06600000']], 'time': '2021-05-20T03:56:19.678964Z'}
{'type': 'l2update', 'product_id': 'BTC-USD', 'changes': [['buy', '38346.37', '0.00000000']], 'time': '2021-05-20T03:56:19.683473Z'}
{'type': 'l2update', 'product_id': 'BTC-USD', 'changes': [['sell', '38358.15', '0.00000000']], 'time': '2021-05-20T03:56:19.683742Z'}
{'type': 'l2update', 'product_id': 'BTC-USD', 'changes': [['buy', '38346.86', '0.01492000']], 'time': '2021-05-20T03:56:19.690373Z'}
{'type': 'l2update', 'product_id': 'BTC-USD', 'changes': [['sell', '38441.65', '0.02400000']], 'time': '2021-05-20T03:56:19.690638Z'}
{'type': 'l2update', 'product_id': 'BTC-USD', 'changes': [['sell', '38521.71', '2.87000000']], 'time': '2021-05-20T03:56:19.690736Z'}
{'type': 'l2update', 'product_id': 'BTC-USD', 'changes': [['buy', '38346.86', '0.00000000']], 'time': '2021-05-20T03:56:19.697242Z'}
{'type': 'l2update', 'product_id': 'BTC-USD', 'changes': [['buy', '38345.46', '0.07460000']], 'time': '2021-05-20T03:56:19.701742Z'}
{'type': 'l2update', 'product_id': 'BTC-USD', 'changes': [['sell', '38359.30', '0.06400386']], 'time': '2021-05-20T03:56:19.701886Z'}
{'type': 'l2update', 'product_id': 'BTC-USD', 'changes': [['sell', '38357.32', '0.01492000']], 'time': '2021-05-20T03:56:19.705958Z'}
{'type': 'l2update', 'product_id': 'BTC-USD', 'changes': [['buy', '38173.00', '4.44000000']], 'time': '2021-05-20T03:56:19.706090Z'}
{'type': 'l2update', 'product_id': 'BTC-USD', 'changes': [['buy', '38345.46', '0.00000000']], 'time': '2021-05-20T03:56:19.706291Z'}
{'type': 'l2update', 'product_id': 'BTC-USD', 'changes': [['sell', '38357.91', '0.00000000']], 'time': '2021-05-20T03:56:19.706313Z'}
{'type': 'l2update', 'product_id': 'BTC-USD', 'changes': [['sell', '38679.31', '3.22892252']], 'time': '2021-05-20T03:56:19.706341Z'}
{'type': 'l2update', 'product_id': 'BTC-USD', 'changes': [['sell', '38359.30', '0.00000000']], 'time': '2021-05-20T03:56:19.711785Z'}
{'type': 'l2update', 'product_id': 'BTC-USD', 'changes': [['sell', '38599.99', '0.00000000']], 'time': '2021-05-20T03:56:19.713896Z'}
{'type': 'l2update', 'product_id': 'BTC-USD', 'changes': [['buy', '38326.87', '0.00000000']], 'time': '2021-05-20T03:56:19.715750Z'}
{'type': 'l2update', 'product_id': 'BTC-USD', 'changes': [['buy', '38328.60', '0.00000000']], 'time': '2021-05-20T03:56:19.715792Z'}
{'type': 'l2update', 'product_id': 'BTC-USD', 'changes': [['buy', '38328.59', '0.00000000']], 'time': '2021-05-20T03:56:19.716370Z'}
{'type': 'l2update', 'product_id': 'BTC-USD', 'changes': [['sell', '38357.07', '0.01059614']], 'time': '2021-05-20T03:56:19.717410Z'}
{'type': 'l2update', 'product_id': 'BTC-USD', 'changes': [['buy', '38345.34', '0.01492000']], 'time': '2021-05-20T03:56:19.717477Z'}
{'type': 'l2update', 'product_id': 'BTC-USD', 'changes': [['sell', '38578.89', '20.42000000']], 'time': '2021-05-20T03:56:19.717646Z'}
{'type': 'l2update', 'product_id': 'BTC-USD', 'changes': [['sell', '38367.66', '0.00000000']], 'time': '2021-05-20T03:56:19.719512Z'}
{'type': 'l2update', 'product_id': 'BTC-USD', 'changes': [['sell', '38359.65', '0.00000000']], 'time': '2021-05-20T03:56:19.719579Z'}
{'type': 'l2update', 'product_id': 'BTC-USD', 'changes': [['sell', '38357.32', '0.00000000']], 'time': '2021-05-20T03:56:19.722469Z'}
{'type': 'l2update', 'product_id': 'BTC-USD', 'changes': [['buy', '38345.19', '0.07460000']], 'time': '2021-05-20T03:56:19.722490Z'}
{'type': 'l2update', 'product_id': 'BTC-USD', 'changes': [['buy', '38345.34', '0.00000000']], 'time': '2021-05-20T03:56:19.723186Z'}
{'type': 'l2update', 'product_id': 'BTC-USD', 'changes': [['sell', '38579.99', '0.64578801']], 'time': '2021-05-20T03:56:19.726559Z'}
{'type': 'l2update', 'product_id': 'BTC-USD', 'changes': [['sell', '38679.31', '5.81207343']], 'time': '2021-05-20T03:56:19.726559Z'}
{'type': 'l2update', 'product_id': 'BTC-USD', 'changes': [['buy', '38345.19', '0.00000000']], 'time': '2021-05-20T03:56:19.728004Z'}
{'type': 'l2update', 'product_id': 'BTC-USD', 'changes': [['sell', '38419.17', '0.00000000']], 'time': '2021-05-20T03:56:19.728711Z'}
{'type': 'l2update', 'product_id': 'BTC-USD', 'changes': [['sell', '38357.07', '0.00000000']], 'time': '2021-05-20T03:56:19.729773Z'}
{'type': 'l2update', 'product_id': 'BTC-USD', 'changes': [['buy', '38115.82', '23.66000000']], 'time': '2021-05-20T03:56:19.732964Z'}
{'type': 'l2update', 'product_id': 'BTC-USD', 'changes': [['sell', '38679.31', '2.58315091']], 'time': '2021-05-20T03:56:19.733863Z'}
{'type': 'l2update', 'product_id': 'BTC-USD', 'changes': [['sell', '38359.64', '0.50000000']], 'time': '2021-05-20T03:56:19.735367Z'}
{'type': 'l2update', 'product_id': 'BTC-USD', 'changes': [['buy', '38345.46', '0.01492000']], 'time': '2021-05-20T03:56:19.735398Z'}
{'type': 'l2update', 'product_id': 'BTC-USD', 'changes': [['sell', '38359.81', '0.06400386']], 'time': '2021-05-20T03:56:19.735433Z'}
{'type': 'l2update', 'product_id': 'BTC-USD', 'changes': [['sell', '38379.22', '0.49940000']], 'time': '2021-05-20T03:56:19.735514Z'}
{'type': 'l2update', 'product_id': 'BTC-USD', 'changes': [['sell', '38443.96', '0.01000000']], 'time': '2021-05-20T03:56:19.739509Z'}
{'type': 'l2update', 'product_id': 'BTC-USD', 'changes': [['buy', '38331.87', '0.52000000']], 'time': '2021-05-20T03:56:19.739579Z'}
{'type': 'l2update', 'product_id': 'BTC-USD', 'changes': [['buy', '38345.34', '0.07460000']], 'time': '2021-05-20T03:56:19.739760Z'}
{'type': 'l2update', 'product_id': 'BTC-USD', 'changes': [['sell', '38359.81', '0.07460000']], 'time': '2021-05-20T03:56:19.739805Z'}
{'type': 'l2update', 'product_id': 'BTC-USD', 'changes': [['sell', '38359.81', '0.01059614']], 'time': '2021-05-20T03:56:19.740786Z'}
{'type': 'l2update', 'product_id': 'BTC-USD', 'changes': [['sell', '38578.88', '3.22892979']], 'time': '2021-05-20T03:56:19.743328Z'}
{'type': 'l2update', 'product_id': 'BTC-USD', 'changes': [['buy', '37925.57', '34.68000000']], 'time': '2021-05-20T03:56:19.743437Z'}
{'type': 'l2update', 'product_id': 'BTC-USD', 'changes': [['sell', '38359.81', '0.02506355']], 'time': '2021-05-20T03:56:19.743555Z'}
{'type': 'l2update', 'product_id': 'BTC-USD', 'changes': [['buy', '38331.87', '0.00000000']], 'time': '2021-05-20T03:56:19.745237Z'}
{'type': 'l2update', 'product_id': 'BTC-USD', 'changes': [['buy', '38345.34', '0.00000000']], 'time': '2021-05-20T03:56:19.746017Z'}
{'type': 'l2update', 'product_id': 'BTC-USD', 'changes': [['sell', '38373.91', '0.00000000']], 'time': '2021-05-20T03:56:19.746316Z'}
{'type': 'l2update', 'product_id': 'BTC-USD', 'changes': [['buy', '38328.61', '0.00000000']], 'time': '2021-05-20T03:56:19.746943Z'}
{'type': 'l2update', 'product_id': 'BTC-USD', 'changes': [['sell', '38359.81', '0.01059614']], 'time': '2021-05-20T03:56:19.749097Z'}
{'type': 'l2update', 'product_id': 'BTC-USD', 'changes': [['sell', '38359.81', '0.00000000']], 'time': '2021-05-20T03:56:19.749932Z'}
{'type': 'l2update', 'product_id': 'BTC-USD', 'changes': [['buy', '37734.49', '17.26000000']], 'time': '2021-05-20T03:56:19.751567Z'}
{'type': 'l2update', 'product_id': 'BTC-USD', 'changes': [['sell', '38379.21', '0.05000000']], 'time': '2021-05-20T03:56:19.756724Z'}
{'type': 'l2update', 'product_id': 'BTC-USD', 'changes': [['buy', '38115.83', '0.95058943']], 'time': '2021-05-20T03:56:19.756736Z'}
{'type': 'l2update', 'product_id': 'BTC-USD', 'changes': [['sell', '38360.28', '0.00000000']], 'time': '2021-05-20T03:56:19.756762Z'}
{'type': 'l2update', 'product_id': 'BTC-USD', 'changes': [['buy', '38323.91', '0.00000000']], 'time': '2021-05-20T03:56:19.759846Z'}
{'type': 'l2update', 'product_id': 'BTC-USD', 'changes': [['sell', '38579.99', '0.00000000']], 'time': '2021-05-20T03:56:19.761696Z'}
{'type': 'l2update', 'product_id': 'BTC-USD', 'changes': [['sell', '38679.31', '0.00000000']], 'time': '2021-05-20T03:56:19.761696Z'}
{'type': 'l2update', 'product_id': 'BTC-USD', 'changes': [['sell', '38444.43', '0.12249312']], 'time': '2021-05-20T03:56:19.763756Z'}
{'type': 'l2update', 'product_id': 'BTC-USD', 'changes': [['buy', '38036.24', '0.00000000']], 'time': '2021-05-20T03:56:19.765656Z'}
{'type': 'l2update', 'product_id': 'BTC-USD', 'changes': [['buy', '38328.56', '0.59116555']], 'time': '2021-05-20T03:56:19.767762Z'}
{'type': 'l2update', 'product_id': 'BTC-USD', 'changes': [['sell', '38359.64', '0.49976604']], 'time': '2021-05-20T03:56:19.768062Z'}
{'type': 'l2update', 'product_id': 'BTC-USD', 'changes': [['buy', '38323.91', '0.00231535']], 'time': '2021-05-20T03:56:19.768265Z'}
{'type': 'l2update', 'product_id': 'BTC-USD', 'changes': [['buy', '38345.81', '0.07460000']], 'time': '2021-05-20T03:56:19.771659Z'}
{'type': 'l2update', 'product_id': 'BTC-USD', 'changes': [['buy', '38335.74', '0.44600000']], 'time': '2021-05-20T03:56:19.771821Z'}
{'type': 'l2update', 'product_id': 'BTC-USD', 'changes': [['sell', '38359.31', '0.07460000']], 'time': '2021-05-20T03:56:19.771910Z'}
{'type': 'l2update', 'product_id': 'BTC-USD', 'changes': [['sell', '38359.31', '0.08952000']], 'time': '2021-05-20T03:56:19.775013Z'}
{'type': 'l2update', 'product_id': 'BTC-USD', 'changes': [['buy', '38261.19', '0.00000000']], 'time': '2021-05-20T03:56:19.777281Z'}
{'type': 'l2update', 'product_id': 'BTC-USD', 'changes': [['buy', '38345.46', '0.00000000']], 'time': '2021-05-20T03:56:19.778672Z'}
{'type': 'l2update', 'product_id': 'BTC-USD', 'changes': [['sell', '38359.31', '0.07460000']], 'time': '2021-05-20T03:56:19.781580Z'}
{'type': 'l2update', 'product_id': 'BTC-USD', 'changes': [['sell', '38441.88', '0.00000000']], 'time': '2021-05-20T03:56:19.787593Z'}
{'type': 'l2update', 'product_id': 'BTC-USD', 'changes': [['sell', '38363.02', '0.04073317']], 'time': '2021-05-20T03:56:19.790255Z'}
{'type': 'l2update', 'product_id': 'BTC-USD', 'changes': [['buy', '38273.06', '0.01000000']], 'time': '2021-05-20T03:56:19.790291Z'}
{'type': 'l2update', 'product_id': 'BTC-USD', 'changes': [['sell', '38453.71', '0.01000000']], 'time': '2021-05-20T03:56:19.798802Z'}
{'type': 'l2update', 'product_id': 'BTC-USD', 'changes': [['sell', '38358.94', '0.01492000']], 'time': '2021-05-20T03:56:19.807396Z'}
{'type': 'l2update', 'product_id': 'BTC-USD', 'changes': [['buy', '38045.00', '0.00000000']], 'time': '2021-05-20T03:56:19.808777Z'}
{'type': 'l2update', 'product_id': 'BTC-USD', 'changes': [['sell', '38518.10', '0.00000000']], 'time': '2021-05-20T03:56:19.809862Z'}
{'type': 'l2update', 'product_id': 'BTC-USD', 'changes': [['sell', '38359.30', '1.28471244']], 'time': '2021-05-20T03:56:19.811419Z'}
{'type': 'l2update', 'product_id': 'BTC-USD', 'changes': [['sell', '38359.31', '0.00000000']], 'time': '2021-05-20T03:56:19.813106Z'}
{'type': 'l2update', 'product_id': 'BTC-USD', 'changes': [['buy', '38346.43', '0.01492000']], 'time': '2021-05-20T03:56:19.815054Z'}
{'type': 'l2update', 'product_id': 'BTC-USD', 'changes': [['buy', '38057.88', '0.02325000']], 'time': '2021-05-20T03:56:19.819042Z'}
{'type': 'l2update', 'product_id': 'BTC-USD', 'changes': [['buy', '38345.81', '0.00000000']], 'time': '2021-05-20T03:56:19.821105Z'}
{'type': 'l2update', 'product_id': 'BTC-USD', 'changes': [['sell', '38363.02', '0.00000000']], 'time': '2021-05-20T03:56:19.823791Z'}
{'type': 'l2update', 'product_id': 'BTC-USD', 'changes': [['sell', '38358.93', '1.41580554']], 'time': '2021-05-20T03:56:19.827353Z'}
{'type': 'l2update', 'product_id': 'BTC-USD', 'changes': [['sell', '38358.35', '0.07460000']], 'time': '2021-05-20T03:56:19.827490Z'}
{'type': 'l2update', 'product_id': 'BTC-USD', 'changes': [['buy', '38346.75', '0.07460000']], 'time': '2021-05-20T03:56:19.832968Z'}
{'type': 'l2update', 'product_id': 'BTC-USD', 'changes': [['sell', '38358.94', '0.00000000']], 'time': '2021-05-20T03:56:19.834812Z'}
{'type': 'l2update', 'product_id': 'BTC-USD', 'changes': [['buy', '38346.43', '0.00000000']], 'time': '2021-05-20T03:56:19.834972Z'}
{'type': 'l2update', 'product_id': 'BTC-USD', 'changes': [['buy', '38298.62', '0.09000000']], 'time': '2021-05-20T03:56:19.835520Z'}
{'type': 'l2update', 'product_id': 'BTC-USD', 'changes': [['buy', '38298.62', '0.05000000']], 'time': '2021-05-20T03:56:19.839961Z'}
{'type': 'l2update', 'product_id': 'BTC-USD', 'changes': [['buy', '38298.62', '0.00000000']], 'time': '2021-05-20T03:56:19.844231Z'}
{'type': 'l2update', 'product_id': 'BTC-USD', 'changes': [['buy', '38346.75', '0.00000000']], 'time': '2021-05-20T03:56:19.844246Z'}
{'type': 'l2update', 'product_id': 'BTC-USD', 'changes': [['sell', '38358.34', '1.04874485']], 'time': '2021-05-20T03:56:19.846280Z'}
{'type': 'l2update', 'product_id': 'BTC-USD', 'changes': [['sell', '38358.35', '0.00000000']], 'time': '2021-05-20T03:56:19.851128Z'}
{'type': 'l2update', 'product_id': 'BTC-USD', 'changes': [['sell', '38360.60', '0.04395610']], 'time': '2021-05-20T03:56:19.851537Z'}
{'type': 'l2update', 'product_id': 'BTC-USD', 'changes': [['buy', '37279.25', '0.00000000']], 'time': '2021-05-20T03:56:19.852846Z'}
{'type': 'l2update', 'product_id': 'BTC-USD', 'changes': [['buy', '38345.60', '0.04098585']], 'time': '2021-05-20T03:56:19.855539Z'}
{'type': 'l2update', 'product_id': 'BTC-USD', 'changes': [['sell', '38357.95', '0.01492000']], 'time': '2021-05-20T03:56:19.855616Z'}
{'type': 'l2update', 'product_id': 'BTC-USD', 'changes': [['buy', '38291.02', '0.03000000']], 'time': '2021-05-20T03:56:19.855803Z'}
{'type': 'l2update', 'product_id': 'BTC-USD', 'changes': [['buy', '38347.07', '0.01492000']], 'time': '2021-05-20T03:56:19.855872Z'}
{'type': 'l2update', 'product_id': 'BTC-USD', 'changes': [['sell', '39068.93', '0.00000000']], 'time': '2021-05-20T03:56:19.857165Z'}
{'type': 'l2update', 'product_id': 'BTC-USD', 'changes': [['sell', '38480.34', '0.00000000']], 'time': '2021-05-20T03:56:19.858417Z'}
{'type': 'l2update', 'product_id': 'BTC-USD', 'changes': [['buy', '38347.07', '0.00000000']], 'time': '2021-05-20T03:56:19.861108Z'}
{'type': 'l2update', 'product_id': 'BTC-USD', 'changes': [['buy', '37089.14', '0.00000000']], 'time': '2021-05-20T03:56:19.861185Z'}
{'type': 'l2update', 'product_id': 'BTC-USD', 'changes': [['buy', '37279.26', '0.05780000']], 'time': '2021-05-20T03:56:19.861515Z'}
{'type': 'l2update', 'product_id': 'BTC-USD', 'changes': [['buy', '37281.28', '0.01510000']], 'time': '2021-05-20T03:56:19.861515Z'}
{'type': 'l2update', 'product_id': 'BTC-USD', 'changes': [['sell', '39779.99', '0.01090000']], 'time': '2021-05-20T03:56:19.861515Z'}
{'type': 'l2update', 'product_id': 'BTC-USD', 'changes': [['buy', '37283.80', '0.00130000']], 'time': '2021-05-20T03:56:19.861515Z'}
{'type': 'l2update', 'product_id': 'BTC-USD', 'changes': [['buy', '38345.60', '0.00000000']], 'time': '2021-05-20T03:56:19.861951Z'}
{'type': 'l2update', 'product_id': 'BTC-USD', 'changes': [['sell', '38389.20', '0.00000000']], 'time': '2021-05-20T03:56:19.865670Z'}
{'type': 'l2update', 'product_id': 'BTC-USD', 'changes': [['sell', '38357.83', '0.07460000']], 'time': '2021-05-20T03:56:19.867119Z'}
{'type': 'l2update', 'product_id': 'BTC-USD', 'changes': [['buy', '38291.02', '0.07000000']], 'time': '2021-05-20T03:56:19.867258Z'}
{'type': 'l2update', 'product_id': 'BTC-USD', 'changes': [['buy', '38331.87', '0.84700000']], 'time': '2021-05-20T03:56:19.867576Z'}
{'type': 'l2update', 'product_id': 'BTC-USD', 'changes': [['buy', '38306.75', '0.00000000']], 'time': '2021-05-20T03:56:19.868921Z'}
{'type': 'l2update', 'product_id': 'BTC-USD', 'changes': [['buy', '38345.34', '0.02397939']], 'time': '2021-05-20T03:56:19.872652Z'}
{'type': 'l2update', 'product_id': 'BTC-USD', 'changes': [['sell', '38357.95', '0.00000000']], 'time': '2021-05-20T03:56:19.873144Z'}
{'type': 'l2update', 'product_id': 'BTC-USD', 'changes': [['buy', '38331.87', '0.00000000']], 'time': '2021-05-20T03:56:19.874416Z'}
{'type': 'l2update', 'product_id': 'BTC-USD', 'changes': [['sell', '38438.43', '0.05443837']], 'time': '2021-05-20T03:56:19.874724Z'}
{'type': 'l2update', 'product_id': 'BTC-USD', 'changes': [['sell', '38400.29', '0.15500000']], 'time': '2021-05-20T03:56:19.875568Z'}
{'type': 'l2update', 'product_id': 'BTC-USD', 'changes': [['buy', '38328.56', '0.00000000']], 'time': '2021-05-20T03:56:19.875828Z'}
{'type': 'l2update', 'product_id': 'BTC-USD', 'changes': [['buy', '38345.85', '0.01492000']], 'time': '2021-05-20T03:56:19.880060Z'}
{'type': 'l2update', 'product_id': 'BTC-USD', 'changes': [['buy', '38290.75', '0.02721919']], 'time': '2021-05-20T03:56:19.880087Z'}
{'type': 'l2update', 'product_id': 'BTC-USD', 'changes': [['buy', '38291.02', '0.12000000']], 'time': '2021-05-20T03:56:19.880156Z'}
{'type': 'l2update', 'product_id': 'BTC-USD', 'changes': [['buy', '38345.34', '0.00000000']], 'time': '2021-05-20T03:56:19.885004Z'}
{'type': 'l2update', 'product_id': 'BTC-USD', 'changes': [['buy', '38285.61', '0.05443837']], 'time': '2021-05-20T03:56:19.886549Z'}
{'type': 'l2update', 'product_id': 'BTC-USD', 'changes': [['buy', '38328.55', '0.06478129']], 'time': '2021-05-20T03:56:19.893524Z'}
{'type': 'l2update', 'product_id': 'BTC-USD', 'changes': [['sell', '38357.46', '0.01492000']], 'time': '2021-05-20T03:56:19.894476Z'}
{'type': 'l2update', 'product_id': 'BTC-USD', 'changes': [['buy', '38318.40', '0.00000000']], 'time': '2021-05-20T03:56:19.894745Z'}
{'type': 'l2update', 'product_id': 'BTC-USD', 'changes': [['buy', '37543.97', '41.89000000']], 'time': '2021-05-20T03:56:19.895010Z'}
{'type': 'l2update', 'product_id': 'BTC-USD', 'changes': [['buy', '38328.56', '0.59116555']], 'time': '2021-05-20T03:56:19.898393Z'}
{'type': 'l2update', 'product_id': 'BTC-USD', 'changes': [['sell', '38433.33', '0.02721919']], 'time': '2021-05-20T03:56:19.898872Z'}
{'type': 'l2update', 'product_id': 'BTC-USD', 'changes': [['sell', '38357.83', '0.00000000']], 'time': '2021-05-20T03:56:19.899999Z'}
{'type': 'l2update', 'product_id': 'BTC-USD', 'changes': [['buy', '38321.50', '0.02400000']], 'time': '2021-05-20T03:56:19.908416Z'}
{'type': 'l2update', 'product_id': 'BTC-USD', 'changes': [['sell', '39346.40', '0.10000000']], 'time': '2021-05-20T03:56:19.908597Z'}
{'type': 'l2update', 'product_id': 'BTC-USD', 'changes': [['buy', '38327.05', '0.00000000']], 'time': '2021-05-20T03:56:19.910232Z'}
{'type': 'l2update', 'product_id': 'BTC-USD', 'changes': [['sell', '38397.37', '0.32338471']], 'time': '2021-05-20T03:56:19.912665Z'}
{'type': 'l2update', 'product_id': 'BTC-USD', 'changes': [['buy', '38331.83', '1.12906192']], 'time': '2021-05-20T03:56:19.914200Z'}
{'type': 'l2update', 'product_id': 'BTC-USD', 'changes': [['buy', '38346.20', '0.00597317']], 'time': '2021-05-20T03:56:19.914331Z'}
{'type': 'l2update', 'product_id': 'BTC-USD', 'changes': [['buy', '38321.50', '0.00000000']], 'time': '2021-05-20T03:56:19.915459Z'}
{'type': 'l2update', 'product_id': 'BTC-USD', 'changes': [['buy', '38320.14', '0.00000000']], 'time': '2021-05-20T03:56:19.915459Z'}
{'type': 'l2update', 'product_id': 'BTC-USD', 'changes': [['buy', '38276.80', '1.61210000']], 'time': '2021-05-20T03:56:19.917096Z'}
{'type': 'l2update', 'product_id': 'BTC-USD', 'changes': [['sell', '38415.23', '0.00000000']], 'time': '2021-05-20T03:56:19.919138Z'}
{'type': 'l2update', 'product_id': 'BTC-USD', 'changes': [['buy', '38346.20', '0.02114179']], 'time': '2021-05-20T03:56:19.922308Z'}
{'type': 'l2update', 'product_id': 'BTC-USD', 'changes': [['sell', '38356.92', '0.07460000']], 'time': '2021-05-20T03:56:19.922328Z'}
{'type': 'l2update', 'product_id': 'BTC-USD', 'changes': [['sell', '38527.63', '0.01000000']], 'time': '2021-05-20T03:56:19.923229Z'}
{'type': 'l2update', 'product_id': 'BTC-USD', 'changes': [['buy', '38320.90', '0.48360000']], 'time': '2021-05-20T03:56:19.923316Z'}
{'type': 'l2update', 'product_id': 'BTC-USD', 'changes': [['buy', '37352.89', '91.28000000']], 'time': '2021-05-20T03:56:19.923640Z'}
{'type': 'l2update', 'product_id': 'BTC-USD', 'changes': [['buy', '38306.60', '0.00000000']], 'time': '2021-05-20T03:56:19.924534Z'}
{'type': 'l2update', 'product_id': 'BTC-USD', 'changes': [['buy', '38346.20', '0.07460000']], 'time': '2021-05-20T03:56:19.926896Z'}
{'type': 'l2update', 'product_id': 'BTC-USD', 'changes': [['buy', '38320.90', '0.00000000']], 'time': '2021-05-20T03:56:19.928596Z'}
{'type': 'l2update', 'product_id': 'BTC-USD', 'changes': [['buy', '38345.85', '0.00000000']], 'time': '2021-05-20T03:56:19.928755Z'}
{'type': 'l2update', 'product_id': 'BTC-USD', 'changes': [['sell', '38441.65', '0.00000000']], 'time': '2021-05-20T03:56:19.928822Z'}
{'type': 'l2update', 'product_id': 'BTC-USD', 'changes': [['sell', '38357.46', '0.00000000']], 'time': '2021-05-20T03:56:19.929310Z'}
{'type': 'l2update', 'product_id': 'BTC-USD', 'changes': [['sell', '38379.22', '0.00000000']], 'time': '2021-05-20T03:56:19.932999Z'}
{'type': 'l2update', 'product_id': 'BTC-USD', 'changes': [['sell', '38378.00', '0.42650000']], 'time': '2021-05-20T03:56:19.943796Z'}
{'type': 'l2update', 'product_id': 'BTC-USD', 'changes': [['buy', '38346.20', '0.02114179']], 'time': '2021-05-20T03:56:19.944237Z'}
{'type': 'l2update', 'product_id': 'BTC-USD', 'changes': [['buy', '38346.20', '0.00597317']], 'time': '2021-05-20T03:56:19.944655Z'}
{'type': 'l2update', 'product_id': 'BTC-USD', 'changes': [['buy', '38267.79', '0.00000000']], 'time': '2021-05-20T03:56:19.944741Z'}
{'type': 'l2update', 'product_id': 'BTC-USD', 'changes': [['buy', '38346.20', '0.00000000']], 'time': '2021-05-20T03:56:19.945213Z'}
{'type': 'l2update', 'product_id': 'BTC-USD', 'changes': [['sell', '38356.92', '0.00000000']], 'time': '2021-05-20T03:56:19.948839Z'}
{'type': 'l2update', 'product_id': 'BTC-USD', 'changes': [['buy', '38282.50', '0.00000000']], 'time': '2021-05-20T03:56:19.949387Z'}
{'type': 'l2update', 'product_id': 'BTC-USD', 'changes': [['buy', '38328.56', '0.00000000']], 'time': '2021-05-20T03:56:19.951623Z'}
{'type': 'l2update', 'product_id': 'BTC-USD', 'changes': [['buy', '38346.45', '0.01492000']], 'time': '2021-05-20T03:56:19.952181Z'}
{'type': 'l2update', 'product_id': 'BTC-USD', 'changes': [['sell', '38379.21', '0.00000000']], 'time': '2021-05-20T03:56:19.952994Z'}
{'type': 'l2update', 'product_id': 'BTC-USD', 'changes': [['buy', '38346.45', '0.00000000']], 'time': '2021-05-20T03:56:19.958165Z'}
{'type': 'l2update', 'product_id': 'BTC-USD', 'changes': [['buy', '38291.49', '0.10000000']], 'time': '2021-05-20T03:56:19.960188Z'}
{'type': 'l2update', 'product_id': 'BTC-USD', 'changes': [['sell', '38357.82', '0.01492000']], 'time': '2021-05-20T03:56:19.960213Z'}
{'type': 'l2update', 'product_id': 'BTC-USD', 'changes': [['sell', '38360.60', '0.00000000']], 'time': '2021-05-20T03:56:19.960798Z'}
{'type': 'l2update', 'product_id': 'BTC-USD', 'changes': [['buy', '38345.38', '0.07460000']], 'time': '2021-05-20T03:56:19.963555Z'}
{'type': 'l2update', 'product_id': 'BTC-USD', 'changes': [['sell', '38377.99', '0.05000000']], 'time': '2021-05-20T03:56:19.963789Z'}
{'type': 'l2update', 'product_id': 'BTC-USD', 'changes': [['sell', '38527.63', '0.00000000']], 'time': '2021-05-20T03:56:19.968590Z'}
{'type': 'l2update', 'product_id': 'BTC-USD', 'changes': [['buy', '38345.38', '0.00000000']], 'time': '2021-05-20T03:56:19.969043Z'}
{'type': 'l2update', 'product_id': 'BTC-USD', 'changes': [['buy', '38331.84', '0.59116555']], 'time': '2021-05-20T03:56:19.971660Z'}
{'type': 'l2update', 'product_id': 'BTC-USD', 'changes': [['sell', '38357.79', '0.07460000']], 'time': '2021-05-20T03:56:19.971784Z'}
{'type': 'l2update', 'product_id': 'BTC-USD', 'changes': [['buy', '38318.43', '0.02400000']], 'time': '2021-05-20T03:56:19.971881Z'}
{'type': 'l2update', 'product_id': 'BTC-USD', 'changes': [['buy', '38317.62', '0.02400000']], 'time': '2021-05-20T03:56:19.971881Z'}
{'type': 'l2update', 'product_id': 'BTC-USD', 'changes': [['buy', '38345.41', '0.01492000']], 'time': '2021-05-20T03:56:19.971899Z'}
{'type': 'l2update', 'product_id': 'BTC-USD', 'changes': [['sell', '38357.82', '0.00000000']], 'time': '2021-05-20T03:56:19.978592Z'}
{'type': 'l2update', 'product_id': 'BTC-USD', 'changes': [['sell', '38468.04', '0.02413004']], 'time': '2021-05-20T03:56:19.980337Z'}
{'type': 'l2update', 'product_id': 'BTC-USD', 'changes': [['buy', '38345.51', '0.07460000']], 'time': '2021-05-20T03:56:19.980358Z'}
{'type': 'l2update', 'product_id': 'BTC-USD', 'changes': [['buy', '38345.41', '0.00000000']], 'time': '2021-05-20T03:56:19.986799Z'}
{'type': 'l2update', 'product_id': 'BTC-USD', 'changes': [['sell', '38367.30', '0.06001465']], 'time': '2021-05-20T03:56:19.988151Z'}
{'type': 'l2update', 'product_id': 'BTC-USD', 'changes': [['sell', '38388.82', '0.01257146']], 'time': '2021-05-20T03:56:19.998264Z'}
{'type': 'l2update', 'product_id': 'BTC-USD', 'changes': [['sell', '38357.47', '0.01492000']], 'time': '2021-05-20T03:56:19.998316Z'}
{'type': 'l2update', 'product_id': 'BTC-USD', 'changes': [['sell', '38415.39', '0.00000000']], 'time': '2021-05-20T03:56:20.001603Z'}
{'type': 'l2update', 'product_id': 'BTC-USD', 'changes': [['sell', '38409.34', '0.00000000']], 'time': '2021-05-20T03:56:20.001603Z'}
{'type': 'l2update', 'product_id': 'BTC-USD', 'changes': [['sell', '38404.02', '0.35558801']], 'time': '2021-05-20T03:56:20.001603Z'}
{'type': 'l2update', 'product_id': 'BTC-USD', 'changes': [['sell', '38357.79', '0.00000000']], 'time': '2021-05-20T03:56:20.003674Z'}
{'type': 'l2update', 'product_id': 'BTC-USD', 'changes': [['buy', '38345.99', '0.01492000']], 'time': '2021-05-20T03:56:20.004197Z'}
{'type': 'l2update', 'product_id': 'BTC-USD', 'changes': [['buy', '38345.51', '0.00000000']], 'time': '2021-05-20T03:56:20.010528Z'}
{'type': 'l2update', 'product_id': 'BTC-USD', 'changes': [['buy', '38057.88', '0.00000000']], 'time': '2021-05-20T03:56:20.011474Z'}
{'type': 'l2update', 'product_id': 'BTC-USD', 'changes': [['sell', '38358.29', '1.54100000']], 'time': '2021-05-20T03:56:20.012033Z'}
{'type': 'l2update', 'product_id': 'BTC-USD', 'changes': [['sell', '38357.20', '0.07460000']], 'time': '2021-05-20T03:56:20.016455Z'}
{'type': 'l2update', 'product_id': 'BTC-USD', 'changes': [['buy', '38320.94', '0.48210000']], 'time': '2021-05-20T03:56:20.020615Z'}
{'type': 'l2update', 'product_id': 'BTC-USD', 'changes': [['sell', '38357.47', '0.00000000']], 'time': '2021-05-20T03:56:20.022879Z'}
{'type': 'l2update', 'product_id': 'BTC-USD', 'changes': [['buy', '38045.00', '0.01162500']], 'time': '2021-05-20T03:56:20.024598Z'}
{'type': 'l2update', 'product_id': 'BTC-USD', 'changes': [['buy', '38319.21', '0.00000000']], 'time': '2021-05-20T03:56:20.026176Z'}
{'type': 'l2update', 'product_id': 'BTC-USD', 'changes': [['buy', '38346.49', '0.07460000']], 'time': '2021-05-20T03:56:20.027639Z'}
{'type': 'l2update', 'product_id': 'BTC-USD', 'changes': [['sell', '38357.20', '0.00000000']], 'time': '2021-05-20T03:56:20.030497Z'}
{'type': 'l2update', 'product_id': 'BTC-USD', 'changes': [['buy', '38345.99', '0.00000000']], 'time': '2021-05-20T03:56:20.030635Z'}
{'type': 'l2update', 'product_id': 'BTC-USD', 'changes': [['buy', '38316.15', '0.02400000']], 'time': '2021-05-20T03:56:20.035943Z'}
{'type': 'l2update', 'product_id': 'BTC-USD', 'changes': [['sell', '38356.64', '0.01492000']], 'time': '2021-05-20T03:56:20.040971Z'}
{'type': 'l2update', 'product_id': 'BTC-USD', 'changes': [['buy', '38313.58', '0.55658312']], 'time': '2021-05-20T03:56:20.042742Z'}
{'type': 'l2update', 'product_id': 'BTC-USD', 'changes': [['sell', '38356.64', '0.00000000']], 'time': '2021-05-20T03:56:20.045654Z'}
{'type': 'l2update', 'product_id': 'BTC-USD', 'changes': [['sell', '38357.98', '0.07460000']], 'time': '2021-05-20T03:56:20.045751Z'}
{'type': 'l2update', 'product_id': 'BTC-USD', 'changes': [['sell', '38367.30', '0.00000000']], 'time': '2021-05-20T03:56:20.049437Z'}
{'type': 'l2update', 'product_id': 'BTC-USD', 'changes': [['sell', '38357.98', '0.00000000']], 'time': '2021-05-20T03:56:20.049727Z'}
{'type': 'l2update', 'product_id': 'BTC-USD', 'changes': [['buy', '38346.49', '0.00000000']], 'time': '2021-05-20T03:56:20.050196Z'}
{'type': 'l2update', 'product_id': 'BTC-USD', 'changes': [['buy', '38346.77', '0.01492000']], 'time': '2021-05-20T03:56:20.050286Z'}
{'type': 'l2update', 'product_id': 'BTC-USD', 'changes': [['sell', '38384.34', '0.56333560']], 'time': '2021-05-20T03:56:20.054312Z'}
{'type': 'l2update', 'product_id': 'BTC-USD', 'changes': [['buy', '38346.77', '0.00000000']], 'time': '2021-05-20T03:56:20.056182Z'}
{'type': 'l2update', 'product_id': 'BTC-USD', 'changes': [['buy', '38289.47', '0.00000000']], 'time': '2021-05-20T03:56:20.058474Z'}
{'type': 'l2update', 'product_id': 'BTC-USD', 'changes': [['sell', '38357.66', '0.01492000']], 'time': '2021-05-20T03:56:20.058958Z'}
{'type': 'l2update', 'product_id': 'BTC-USD', 'changes': [['buy', '37547.32', '0.06845612']], 'time': '2021-05-20T03:56:20.063660Z'}
{'type': 'l2update', 'product_id': 'BTC-USD', 'changes': [['sell', '38357.76', '0.07460000']], 'time': '2021-05-20T03:56:20.063797Z'}
{'type': 'l2update', 'product_id': 'BTC-USD', 'changes': [['buy', '38345.35', '0.07460000']], 'time': '2021-05-20T03:56:20.063824Z'}
{'type': 'l2update', 'product_id': 'BTC-USD', 'changes': [['sell', '38472.71', '0.00000000']], 'time': '2021-05-20T03:56:20.066527Z'}
{'type': 'l2update', 'product_id': 'BTC-USD', 'changes': [['sell', '38465.62', '0.00000000']], 'time': '2021-05-20T03:56:20.066527Z'}
{'type': 'l2update', 'product_id': 'BTC-USD', 'changes': [['sell', '38464.70', '0.01010000']], 'time': '2021-05-20T03:56:20.066527Z'}
{'type': 'l2update', 'product_id': 'BTC-USD', 'changes': [['sell', '38451.72', '0.00000000']], 'time': '2021-05-20T03:56:20.066527Z'}
{'type': 'l2update', 'product_id': 'BTC-USD', 'changes': [['sell', '38438.97', '0.00000000']], 'time': '2021-05-20T03:56:20.066527Z'}
{'type': 'l2update', 'product_id': 'BTC-USD', 'changes': [['sell', '38432.88', '0.35675509']], 'time': '2021-05-20T03:56:20.066527Z'}
{'type': 'l2update', 'product_id': 'BTC-USD', 'changes': [['sell', '38426.98', '0.39456207']], 'time': '2021-05-20T03:56:20.066527Z'}
{'type': 'l2update', 'product_id': 'BTC-USD', 'changes': [['sell', '38421.10', '0.39914717']], 'time': '2021-05-20T03:56:20.066527Z'}
{'type': 'l2update', 'product_id': 'BTC-USD', 'changes': [['sell', '38357.76', '0.00000000']], 'time': '2021-05-20T03:56:20.068856Z'}
{'type': 'l2update', 'product_id': 'BTC-USD', 'changes': [['buy', '38345.35', '0.00000000']], 'time': '2021-05-20T03:56:20.069522Z'}
{'type': 'l2update', 'product_id': 'BTC-USD', 'changes': [['sell', '38468.04', '0.00000000']], 'time': '2021-05-20T03:56:20.069566Z'}
{'type': 'l2update', 'product_id': 'BTC-USD', 'changes': [['buy', '38345.18', '0.01492000']], 'time': '2021-05-20T03:56:20.073367Z'}
{'type': 'l2update', 'product_id': 'BTC-USD', 'changes': [['buy', '38345.18', '0.00000000']], 'time': '2021-05-20T03:56:20.078660Z'}
{'type': 'l2update', 'product_id': 'BTC-USD', 'changes': [['sell', '38366.66', '0.04646053']], 'time': '2021-05-20T03:56:20.078977Z'}
{'type': 'l2update', 'product_id': 'BTC-USD', 'changes': [['sell', '39145.54', '0.06721982']], 'time': '2021-05-20T03:56:20.078993Z'}
{'type': 'l2update', 'product_id': 'BTC-USD', 'changes': [['buy', '38331.82', '0.00000000']], 'time': '2021-05-20T03:56:20.081693Z'}
{'type': 'l2update', 'product_id': 'BTC-USD', 'changes': [['sell', '38357.40', '0.07460000']], 'time': '2021-05-20T03:56:20.085745Z'}
{'type': 'l2update', 'product_id': 'BTC-USD', 'changes': [['sell', '38481.79', '0.02413004']], 'time': '2021-05-20T03:56:20.086010Z'}
{'type': 'l2update', 'product_id': 'BTC-USD', 'changes': [['buy', '38345.54', '0.07460000']], 'time': '2021-05-20T03:56:20.086048Z'}
{'type': 'l2update', 'product_id': 'BTC-USD', 'changes': [['buy', '38296.41', '1.20000000']], 'time': '2021-05-20T03:56:20.087236Z'}
{'type': 'l2update', 'product_id': 'BTC-USD', 'changes': [['buy', '38345.34', '0.01492000']], 'time': '2021-05-20T03:56:20.091078Z'}
{'type': 'l2update', 'product_id': 'BTC-USD', 'changes': [['sell', '38357.66', '0.00000000']], 'time': '2021-05-20T03:56:20.092736Z'}
{'type': 'l2update', 'product_id': 'BTC-USD', 'changes': [['buy', '38345.34', '0.00000000']], 'time': '2021-05-20T03:56:20.097794Z'}
{'type': 'l2update', 'product_id': 'BTC-USD', 'changes': [['sell', '38431.46', '1.20000000']], 'time': '2021-05-20T03:56:20.099709Z'}
{'type': 'l2update', 'product_id': 'BTC-USD', 'changes': [['buy', '38291.14', '1.28113226']], 'time': '2021-05-20T03:56:20.099735Z'}
{'type': 'l2update', 'product_id': 'BTC-USD', 'changes': [['sell', '38421.10', '0.00000000']], 'time': '2021-05-20T03:56:20.102590Z'}
{'type': 'l2update', 'product_id': 'BTC-USD', 'changes': [['sell', '38356.64', '0.04999509']], 'time': '2021-05-20T03:56:20.103963Z'}
{'type': 'l2update', 'product_id': 'BTC-USD', 'changes': [['sell', '38393.00', '0.03791781']], 'time': '2021-05-20T03:56:20.108266Z'}
{'type': 'l2update', 'product_id': 'BTC-USD', 'changes': [['buy', '38334.34', '0.07083508']], 'time': '2021-05-20T03:56:20.108452Z'}
{'type': 'l2update', 'product_id': 'BTC-USD', 'changes': [['sell', '38357.40', '0.00000000']], 'time': '2021-05-20T03:56:20.109270Z'}
{'type': 'l2update', 'product_id': 'BTC-USD', 'changes': [['buy', '38199.58', '0.00000000']], 'time': '2021-05-20T03:56:20.109875Z'}
{'type': 'l2update', 'product_id': 'BTC-USD', 'changes': [['buy', '38345.90', '0.01492000']], 'time': '2021-05-20T03:56:20.120144Z'}
{'type': 'l2update', 'product_id': 'BTC-USD', 'changes': [['buy', '38350.13', '0.01116274']], 'time': '2021-05-20T03:56:20.121583Z'}
{'type': 'l2update', 'product_id': 'BTC-USD', 'changes': [['buy', '38345.54', '0.00000000']], 'time': '2021-05-20T03:56:20.125608Z'}
{'type': 'l2update', 'product_id': 'BTC-USD', 'changes': [['sell', '38356.58', '0.01068591']], 'time': '2021-05-20T03:56:20.126692Z'}
{'type': 'l2update', 'product_id': 'BTC-USD', 'changes': [['buy', '38345.90', '0.00000000']], 'time': '2021-05-20T03:56:20.130371Z'}
{'type': 'l2update', 'product_id': 'BTC-USD', 'changes': [['buy', '38344.90', '0.00000000']], 'time': '2021-05-20T03:56:20.130971Z'}
{'type': 'l2update', 'product_id': 'BTC-USD', 'changes': [['sell', '38366.66', '0.00000000']], 'time': '2021-05-20T03:56:20.131384Z'}
{'type': 'l2update', 'product_id': 'BTC-USD', 'changes': [['buy', '38328.60', '0.84700000']], 'time': '2021-05-20T03:56:20.133732Z'}
{'type': 'l2update', 'product_id': 'BTC-USD', 'changes': [['sell', '38356.24', '0.07460000']], 'time': '2021-05-20T03:56:20.133770Z'}
{'type': 'l2update', 'product_id': 'BTC-USD', 'changes': [['sell', '38402.56', '0.03618130']], 'time': '2021-05-20T03:56:20.133916Z'}
{'type': 'l2update', 'product_id': 'BTC-USD', 'changes': [['sell', '38410.26', '0.00000000']], 'time': '2021-05-20T03:56:20.134880Z'}
{'type': 'l2update', 'product_id': 'BTC-USD', 'changes': [['buy', '38340.44', '0.00000000']], 'time': '2021-05-20T03:56:20.135387Z'}
{'type': 'l2update', 'product_id': 'BTC-USD', 'changes': [['buy', '38291.14', '0.00000000']], 'time': '2021-05-20T03:56:20.135734Z'}
{'type': 'l2update', 'product_id': 'BTC-USD', 'changes': [['sell', '38356.24', '0.00000000']], 'time': '2021-05-20T03:56:20.138345Z'}
{'type': 'l2update', 'product_id': 'BTC-USD', 'changes': [['sell', '38356.58', '0.00000000']], 'time': '2021-05-20T03:56:20.146726Z'}
{'type': 'l2update', 'product_id': 'BTC-USD', 'changes': [['buy', '38291.70', '1.28113226']], 'time': '2021-05-20T03:56:20.151306Z'}
{'type': 'l2update', 'product_id': 'BTC-USD', 'changes': [['sell', '38412.50', '0.61482417']], 'time': '2021-05-20T03:56:20.151338Z'}
{'type': 'l2update', 'product_id': 'BTC-USD', 'changes': [['sell', '38360.27', '0.00000000']], 'time': '2021-05-20T03:56:20.153224Z'}
{'type': 'l2update', 'product_id': 'BTC-USD', 'changes': [['sell', '38481.79', '0.00000000']], 'time': '2021-05-20T03:56:20.155444Z'}
{'type': 'l2update', 'product_id': 'BTC-USD', 'changes': [['sell', '38358.29', '0.00000000']], 'time': '2021-05-20T03:56:20.155907Z'}
{'type': 'l2update', 'product_id': 'BTC-USD', 'changes': [['buy', '38328.60', '0.00000000']], 'time': '2021-05-20T03:56:20.156377Z'}
{'type': 'l2update', 'product_id': 'BTC-USD', 'changes': [['sell', '38412.25', '0.02779425']], 'time': '2021-05-20T03:56:20.159310Z'}
{'type': 'l2update', 'product_id': 'BTC-USD', 'changes': [['sell', '38426.98', '0.00000000']], 'time': '2021-05-20T03:56:20.167748Z'}
{'type': 'l2update', 'product_id': 'BTC-USD', 'changes': [['sell', '38356.63', '2.48969908']], 'time': '2021-05-20T03:56:20.168066Z'}
{'type': 'l2update', 'product_id': 'BTC-USD', 'changes': [['sell', '38513.88', '0.02414075']], 'time': '2021-05-20T03:56:20.168200Z'}
{'type': 'l2update', 'product_id': 'BTC-USD', 'changes': [['sell', '38416.84', '0.02846577']], 'time': '2021-05-20T03:56:20.190483Z'}
{'type': 'l2update', 'product_id': 'BTC-USD', 'changes': [['sell', '38467.89', '0.00000000']], 'time': '2021-05-20T03:56:20.204162Z'}
{'type': 'l2update', 'product_id': 'BTC-USD', 'changes': [['sell', '38359.64', '0.00000000']], 'time': '2021-05-20T03:56:20.204628Z'}
{'type': 'l2update', 'product_id': 'BTC-USD', 'changes': [['sell', '38454.88', '0.13002253']], 'time': '2021-05-20T03:56:20.215228Z'}
{'type': 'l2update', 'product_id': 'BTC-USD', 'changes': [['sell', '38421.97', '0.02685821']], 'time': '2021-05-20T03:56:20.215265Z'}
{'type': 'l2update', 'product_id': 'BTC-USD', 'changes': [['sell', '43100.00', '1.09530000']], 'time': '2021-05-20T03:56:20.215462Z'}
{'type': 'l2update', 'product_id': 'BTC-USD', 'changes': [['sell', '38356.62', '0.50000000']], 'time': '2021-05-20T03:56:20.218273Z'}
{'type': 'l2update', 'product_id': 'BTC-USD', 'changes': [['buy', '38347.03', '0.04864175']], 'time': '2021-05-20T03:56:20.218616Z'}
{'type': 'l2update', 'product_id': 'BTC-USD', 'changes': [['buy', '38296.25', '0.00000000']], 'time': '2021-05-20T03:56:20.224339Z'}
{'type': 'l2update', 'product_id': 'BTC-USD', 'changes': [['buy', '38292.96', '0.00000000']], 'time': '2021-05-20T03:56:20.227961Z'}
{'type': 'l2update', 'product_id': 'BTC-USD', 'changes': [['sell', '38477.81', '0.67768265']], 'time': '2021-05-20T03:56:20.228049Z'}
{'type': 'l2update', 'product_id': 'BTC-USD', 'changes': [['sell', '38458.96', '0.00000000']], 'time': '2021-05-20T03:56:20.228049Z'}
{'type': 'l2update', 'product_id': 'BTC-USD', 'changes': [['sell', '38452.30', '0.00000000']], 'time': '2021-05-20T03:56:20.228049Z'}
{'type': 'l2update', 'product_id': 'BTC-USD', 'changes': [['sell', '38445.25', '0.00000000']], 'time': '2021-05-20T03:56:20.228049Z'}
{'type': 'l2update', 'product_id': 'BTC-USD', 'changes': [['sell', '38432.88', '0.00000000']], 'time': '2021-05-20T03:56:20.228049Z'}
{'type': 'l2update', 'product_id': 'BTC-USD', 'changes': [['buy', '38291.02', '0.09000000']], 'time': '2021-05-20T03:56:20.231467Z'}
{'type': 'l2update', 'product_id': 'BTC-USD', 'changes': [['sell', '43100.00', '3.49750000']], 'time': '2021-05-20T03:56:20.234055Z'}
{'type': 'l2update', 'product_id': 'BTC-USD', 'changes': [['buy', '38291.02', '0.05000000']], 'time': '2021-05-20T03:56:20.235310Z'}
{'type': 'l2update', 'product_id': 'BTC-USD', 'changes': [['buy', '38291.02', '0.00000000']], 'time': '2021-05-20T03:56:20.240473Z'}
{'type': 'l2update', 'product_id': 'BTC-USD', 'changes': [['buy', '38296.41', '0.00000000']], 'time': '2021-05-20T03:56:20.241178Z'}
{'type': 'l2update', 'product_id': 'BTC-USD', 'changes': [['sell', '38427.30', '0.02599329']], 'time': '2021-05-20T03:56:20.241388Z'}
{'type': 'l2update', 'product_id': 'BTC-USD', 'changes': [['sell', '38387.97', '0.00000000']], 'time': '2021-05-20T03:56:20.243502Z'}
{'type': 'l2update', 'product_id': 'BTC-USD', 'changes': [['sell', '38431.46', '0.00000000']], 'time': '2021-05-20T03:56:20.244691Z'}
{'type': 'l2update', 'product_id': 'BTC-USD', 'changes': [['buy', '38287.64', '0.01000000']], 'time': '2021-05-20T03:56:20.253947Z'}
{'type': 'l2update', 'product_id': 'BTC-USD', 'changes': [['buy', '38285.12', '0.02000000']], 'time': '2021-05-20T03:56:20.266024Z'}
{'type': 'l2update', 'product_id': 'BTC-USD', 'changes': [['sell', '38432.82', '0.02714779']], 'time': '2021-05-20T03:56:20.270829Z'}
{'type': 'l2update', 'product_id': 'BTC-USD', 'changes': [['buy', '38282.43', '0.03000000']], 'time': '2021-05-20T03:56:20.278745Z'}
{'type': 'l2update', 'product_id': 'BTC-USD', 'changes': [['sell', '38432.82', '0.39459685']], 'time': '2021-05-20T03:56:20.283532Z'}
{'type': 'l2update', 'product_id': 'BTC-USD', 'changes': [['sell', '38421.97', '0.32741257']], 'time': '2021-05-20T03:56:20.283532Z'}
{'type': 'l2update', 'product_id': 'BTC-USD', 'changes': [['sell', '38416.84', '0.40559406']], 'time': '2021-05-20T03:56:20.283532Z'}
{'type': 'l2update', 'product_id': 'BTC-USD', 'changes': [['sell', '38404.02', '0.74216080']], 'time': '2021-05-20T03:56:20.283532Z'}
{'type': 'l2update', 'product_id': 'BTC-USD', 'changes': [['buy', '38278.25', '0.04000000']], 'time': '2021-05-20T03:56:20.286742Z'}
{'type': 'l2update', 'product_id': 'BTC-USD', 'changes': [['sell', '38356.57', '1.11400000']], 'time': '2021-05-20T03:56:20.290952Z'}
{'type': 'l2update', 'product_id': 'BTC-USD', 'changes': [['buy', '38323.91', '0.00000000']], 'time': '2021-05-20T03:56:20.291361Z'}
{'type': 'l2update', 'product_id': 'BTC-USD', 'changes': [['sell', '38477.81', '0.37712829']], 'time': '2021-05-20T03:56:20.291706Z'}
{'type': 'l2update', 'product_id': 'BTC-USD', 'changes': [['sell', '38477.81', '0.00000000']], 'time': '2021-05-20T03:56:20.291706Z'}
{'type': 'l2update', 'product_id': 'BTC-USD', 'changes': [['sell', '38465.81', '0.00000000']], 'time': '2021-05-20T03:56:20.291706Z'}
{'type': 'l2update', 'product_id': 'BTC-USD', 'changes': [['sell', '38513.88', '0.00000000']], 'time': '2021-05-20T03:56:20.293640Z'}
{'type': 'l2update', 'product_id': 'BTC-USD', 'changes': [['sell', '38385.67', '0.01000000']], 'time': '2021-05-20T03:56:20.298121Z'}
{'type': 'l2update', 'product_id': 'BTC-USD', 'changes': [['sell', '38378.00', '0.00000000']], 'time': '2021-05-20T03:56:20.317722Z'}
{'type': 'l2update', 'product_id': 'BTC-USD', 'changes': [['buy', '38277.17', '0.05000000']], 'time': '2021-05-20T03:56:20.321288Z'}
{'type': 'l2update', 'product_id': 'BTC-USD', 'changes': [['sell', '38438.53', '0.03040787']], 'time': '2021-05-20T03:56:20.321392Z'}
{'type': 'l2update', 'product_id': 'BTC-USD', 'changes': [['buy', '38318.77', '0.00000000']], 'time': '2021-05-20T03:56:20.336777Z'}
{'type': 'l2update', 'product_id': 'BTC-USD', 'changes': [['buy', '38303.23', '0.01000000']], 'time': '2021-05-20T03:56:20.359901Z'}
{'type': 'l2update', 'product_id': 'BTC-USD', 'changes': [['buy', '38184.17', '0.04996121']], 'time': '2021-05-20T03:56:20.360024Z'}
{'type': 'l2update', 'product_id': 'BTC-USD', 'changes': [['sell', '38463.27', '0.30589859']], 'time': '2021-05-20T03:56:20.360210Z'}
{'type': 'l2update', 'product_id': 'BTC-USD', 'changes': [['sell', '38376.19', '0.44320000']], 'time': '2021-05-20T03:56:20.367799Z'}
{'type': 'l2update', 'product_id': 'BTC-USD', 'changes': [['sell', '38450.52', '0.03011008']], 'time': '2021-05-20T03:56:20.368065Z'}
{'type': 'l2update', 'product_id': 'BTC-USD', 'changes': [['sell', '38382.01', '0.02000000']], 'time': '2021-05-20T03:56:20.368096Z'}
{'type': 'l2update', 'product_id': 'BTC-USD', 'changes': [['sell', '38376.19', '0.00000000']], 'time': '2021-05-20T03:56:20.373750Z'}
{'type': 'l2update', 'product_id': 'BTC-USD', 'changes': [['sell', '38377.99', '0.00000000']], 'time': '2021-05-20T03:56:20.378495Z'}
{'type': 'l2update', 'product_id': 'BTC-USD', 'changes': [['sell', '38496.26', '0.02415180']], 'time': '2021-05-20T03:56:20.380015Z'}
{'type': 'l2update', 'product_id': 'BTC-USD', 'changes': [['sell', '38356.57', '1.11112310']], 'time': '2021-05-20T03:56:20.380627Z'}
{'type': 'l2update', 'product_id': 'BTC-USD', 'changes': [['sell', '38444.43', '0.54799050']], 'time': '2021-05-20T03:56:20.380874Z'}
{'type': 'l2update', 'product_id': 'BTC-USD', 'changes': [['sell', '38456.80', '0.02846376']], 'time': '2021-05-20T03:56:20.385617Z'}
{'type': 'l2update', 'product_id': 'BTC-USD', 'changes': [['buy', '37500.01', '0.06750000']], 'time': '2021-05-20T03:56:20.386565Z'}
{'type': 'l2update', 'product_id': 'BTC-USD', 'changes': [['buy', '38356.52', '0.15000000']], 'time': '2021-05-20T03:56:20.390493Z'}
{'type': 'l2update', 'product_id': 'BTC-USD', 'changes': [['buy', '38340.65', '0.00000000']], 'time': '2021-05-20T03:56:20.393678Z'}
{'type': 'l2update', 'product_id': 'BTC-USD', 'changes': [['buy', '38331.83', '0.00000000']], 'time': '2021-05-20T03:56:20.394251Z'}
{'type': 'l2update', 'product_id': 'BTC-USD', 'changes': [['buy', '38179.73', '0.00000000']], 'time': '2021-05-20T03:56:20.394699Z'}
{'type': 'l2update', 'product_id': 'BTC-USD', 'changes': [['buy', '38320.94', '0.00000000']], 'time': '2021-05-20T03:56:20.394979Z'}
{'type': 'l2update', 'product_id': 'BTC-USD', 'changes': [['buy', '37279.26', '0.06310000']], 'time': '2021-05-20T03:56:20.395726Z'}
{'type': 'l2update', 'product_id': 'BTC-USD', 'changes': [['sell', '38376.18', '0.05000000']], 'time': '2021-05-20T03:56:20.395883Z'}
{'type': 'l2update', 'product_id': 'BTC-USD', 'changes': [['sell', '38456.80', '0.40395662']], 'time': '2021-05-20T03:56:20.396083Z'}
{'type': 'l2update', 'product_id': 'BTC-USD', 'changes': [['sell', '38384.35', '0.39323057']], 'time': '2021-05-20T03:56:20.396800Z'}
{'type': 'l2update', 'product_id': 'BTC-USD', 'changes': [['sell', '38463.27', '0.33612170']], 'time': '2021-05-20T03:56:20.397041Z'}
{'type': 'l2update', 'product_id': 'BTC-USD', 'changes': [['sell', '38529.97', '0.00000000']], 'time': '2021-05-20T03:56:20.399714Z'}
{'type': 'l2update', 'product_id': 'BTC-USD', 'changes': [['buy', '38331.84', '0.00000000']], 'time': '2021-05-20T03:56:20.400402Z'}
{'type': 'l2update', 'product_id': 'BTC-USD', 'changes': [['sell', '38356.64', '0.00000000']], 'time': '2021-05-20T03:56:20.402343Z'}
{'type': 'l2update', 'product_id': 'BTC-USD', 'changes': [['sell', '38376.18', '0.00000000']], 'time': '2021-05-20T03:56:20.403814Z'}
{'type': 'l2update', 'product_id': 'BTC-USD', 'changes': [['sell', '38463.27', '0.72237093']], 'time': '2021-05-20T03:56:20.411463Z'}
{'type': 'l2update', 'product_id': 'BTC-USD', 'changes': [['buy', '38306.60', '2.37600000']], 'time': '2021-05-20T03:56:20.412246Z'}
{'type': 'l2update', 'product_id': 'BTC-USD', 'changes': [['buy', '38319.64', '0.49420000']], 'time': '2021-05-20T03:56:20.412432Z'}
{'type': 'l2update', 'product_id': 'BTC-USD', 'changes': [['buy', '38335.79', '0.84700000']], 'time': '2021-05-20T03:56:20.412520Z'}
{'type': 'l2update', 'product_id': 'BTC-USD', 'changes': [['sell', '38379.97', '0.05000000']], 'time': '2021-05-20T03:56:20.415684Z'}
{'type': 'l2update', 'product_id': 'BTC-USD', 'changes': [['sell', '38356.53', '0.00573000']], 'time': '2021-05-20T03:56:20.415875Z'}
{'type': 'l2update', 'product_id': 'BTC-USD', 'changes': [['sell', '38516.79', '0.01000000']], 'time': '2021-05-20T03:56:20.416316Z'}
{'type': 'l2update', 'product_id': 'BTC-USD', 'changes': [['sell', '38362.18', '0.01490000']], 'time': '2021-05-20T03:56:20.423554Z'}
{'type': 'l2update', 'product_id': 'BTC-USD', 'changes': [['buy', '38325.81', '0.59116555']], 'time': '2021-05-20T03:56:20.423755Z'}
{'type': 'l2update', 'product_id': 'BTC-USD', 'changes': [['buy', '38331.85', '1.12906192']], 'time': '2021-05-20T03:56:20.423984Z'}
{'type': 'l2update', 'product_id': 'BTC-USD', 'changes': [['sell', '38499.86', '0.00000000']], 'time': '2021-05-20T03:56:20.424750Z'}
{'type': 'l2update', 'product_id': 'BTC-USD', 'changes': [['sell', '38441.65', '0.02400000']], 'time': '2021-05-20T03:56:20.427724Z'}
{'type': 'l2update', 'product_id': 'BTC-USD', 'changes': [['sell', '38469.93', '0.31783697']], 'time': '2021-05-20T03:56:20.428205Z'}
{'type': 'l2update', 'product_id': 'BTC-USD', 'changes': [['buy', '38319.64', '0.00000000']], 'time': '2021-05-20T03:56:20.428829Z'}
{'type': 'l2update', 'product_id': 'BTC-USD', 'changes': [['buy', '38318.43', '0.00000000']], 'time': '2021-05-20T03:56:20.430064Z'}
{'type': 'l2update', 'product_id': 'BTC-USD', 'changes': [['buy', '38317.62', '0.00000000']], 'time': '2021-05-20T03:56:20.430064Z'}
{'type': 'l2update', 'product_id': 'BTC-USD', 'changes': [['sell', '38356.53', '0.40573000']], 'time': '2021-05-20T03:56:20.431272Z'}
{'type': 'l2update', 'product_id': 'BTC-USD', 'changes': [['sell', '38356.53', '0.43463000']], 'time': '2021-05-20T03:56:20.431289Z'}
{'type': 'l2update', 'product_id': 'BTC-USD', 'changes': [['sell', '38516.79', '0.00000000']], 'time': '2021-05-20T03:56:20.432575Z'}
{'type': 'l2update', 'product_id': 'BTC-USD', 'changes': [['sell', '38496.26', '0.00000000']], 'time': '2021-05-20T03:56:20.437180Z'}
{'type': 'l2update', 'product_id': 'BTC-USD', 'changes': [['buy', '38316.15', '0.00000000']], 'time': '2021-05-20T03:56:20.438809Z'}
{'type': 'l2update', 'product_id': 'BTC-USD', 'changes': [['buy', '38331.85', '0.00000000']], 'time': '2021-05-20T03:56:20.439612Z'}
{'type': 'l2update', 'product_id': 'BTC-USD', 'changes': [['sell', '38483.20', '0.34954182']], 'time': '2021-05-20T03:56:20.446232Z'}
{'type': 'l2update', 'product_id': 'BTC-USD', 'changes': [['sell', '38529.97', '0.01000000']], 'time': '2021-05-20T03:56:20.449802Z'}
{'type': 'l2update', 'product_id': 'BTC-USD', 'changes': [['sell', '38513.74', '0.01298238']], 'time': '2021-05-20T03:56:20.451647Z'}
{'type': 'l2update', 'product_id': 'BTC-USD', 'changes': [['sell', '38519.88', '0.09938624']], 'time': '2021-05-20T03:56:20.451703Z'}
{'type': 'l2update', 'product_id': 'BTC-USD', 'changes': [['buy', '38314.19', '0.02400000']], 'time': '2021-05-20T03:56:20.456159Z'}
{'type': 'l2update', 'product_id': 'BTC-USD', 'changes': [['buy', '38313.39', '0.02400000']], 'time': '2021-05-20T03:56:20.456159Z'}
{'type': 'l2update', 'product_id': 'BTC-USD', 'changes': [['buy', '38312.58', '0.02400000']], 'time': '2021-05-20T03:56:20.456159Z'}
{'type': 'l2update', 'product_id': 'BTC-USD', 'changes': [['buy', '38328.56', '1.12906192']], 'time': '2021-05-20T03:56:20.456235Z'}
{'type': 'l2update', 'product_id': 'BTC-USD', 'changes': [['buy', '37547.32', '0.00000000']], 'time': '2021-05-20T03:56:20.458109Z'}
{'type': 'l2update', 'product_id': 'BTC-USD', 'changes': [['sell', '38513.74', '0.00000000']], 'time': '2021-05-20T03:56:20.458824Z'}
{'type': 'l2update', 'product_id': 'BTC-USD', 'changes': [['buy', '38347.04', '0.10000000']], 'time': '2021-05-20T03:56:20.461379Z'}
{'type': 'l2update', 'product_id': 'BTC-USD', 'changes': [['sell', '39145.54', '0.00000000']], 'time': '2021-05-20T03:56:20.461590Z'}
{'type': 'l2update', 'product_id': 'BTC-USD', 'changes': [['sell', '38469.67', '0.03770996']], 'time': '2021-05-20T03:56:20.462711Z'}
{'type': 'l2update', 'product_id': 'BTC-USD', 'changes': [['sell', '38370.11', '0.49250000']], 'time': '2021-05-20T03:56:20.467117Z'}
{'type': 'l2update', 'product_id': 'BTC-USD', 'changes': [['sell', '38499.01', '0.01000000']], 'time': '2021-05-20T03:56:20.473561Z'}
{'type': 'l2update', 'product_id': 'BTC-USD', 'changes': [['sell', '38385.87', '0.00000000']], 'time': '2021-05-20T03:56:20.478780Z'}
{'type': 'l2update', 'product_id': 'BTC-USD', 'changes': [['sell', '38389.68', '0.00000000']], 'time': '2021-05-20T03:56:20.484971Z'}
{'type': 'l2update', 'product_id': 'BTC-USD', 'changes': [['sell', '38519.88', '0.00000000']], 'time': '2021-05-20T03:56:20.486701Z'}
{'type': 'l2update', 'product_id': 'BTC-USD', 'changes': [['buy', '32868.00', '0.00000000']], 'time': '2021-05-20T03:56:20.490387Z'}
{'type': 'l2update', 'product_id': 'BTC-USD', 'changes': [['sell', '38361.10', '0.05148403']], 'time': '2021-05-20T03:56:20.506954Z'}
{'type': 'l2update', 'product_id': 'BTC-USD', 'changes': [['buy', '38331.10', '0.52171485']], 'time': '2021-05-20T03:56:20.510759Z'}
{'type': 'l2update', 'product_id': 'BTC-USD', 'changes': [['sell', '38484.69', '0.01000000']], 'time': '2021-05-20T03:56:20.510784Z'}
{'type': 'l2update', 'product_id': 'BTC-USD', 'changes': [['buy', '38325.81', '0.00000000']], 'time': '2021-05-20T03:56:20.517021Z'}
{'type': 'l2update', 'product_id': 'BTC-USD', 'changes': [['buy', '38320.38', '0.49330000']], 'time': '2021-05-20T03:56:20.527719Z'}
{'type': 'l2update', 'product_id': 'BTC-USD', 'changes': [['sell', '38484.66', '0.00000000']], 'time': '2021-05-20T03:56:20.528870Z'}
{'type': 'l2update', 'product_id': 'BTC-USD', 'changes': [['buy', '38328.52', '0.52175460']], 'time': '2021-05-20T03:56:20.542350Z'}
{'type': 'l2update', 'product_id': 'BTC-USD', 'changes': [['buy', '38335.80', '0.59116555']], 'time': '2021-05-20T03:56:20.542473Z'}
{'type': 'l2update', 'product_id': 'BTC-USD', 'changes': [['sell', '38519.50', '0.01000000']], 'time': '2021-05-20T03:56:20.542648Z'}
{'type': 'l2update', 'product_id': 'BTC-USD', 'changes': [['sell', '38356.53', '0.03463000']], 'time': '2021-05-20T03:56:20.548712Z'}
{'type': 'l2update', 'product_id': 'BTC-USD', 'changes': [['sell', '38519.50', '0.00000000']], 'time': '2021-05-20T03:56:20.550222Z'}
{'type': 'l2update', 'product_id': 'BTC-USD', 'changes': [['buy', '38335.79', '0.00000000']], 'time': '2021-05-20T03:56:20.550301Z'}
{'type': 'l2update', 'product_id': 'BTC-USD', 'changes': [['sell', '38357.06', '0.52169886']], 'time': '2021-05-20T03:56:20.555279Z'}
{'type': 'l2update', 'product_id': 'BTC-USD', 'changes': [['buy', '38344.91', '0.00000000']], 'time': '2021-05-20T03:56:20.556608Z'}
{'type': 'l2update', 'product_id': 'BTC-USD', 'changes': [['sell', '38500.43', '0.01869618']], 'time': '2021-05-20T03:56:20.563504Z'}
{'type': 'l2update', 'product_id': 'BTC-USD', 'changes': [['buy', '38334.39', '0.84700000']], 'time': '2021-05-20T03:56:20.563523Z'}
{'type': 'l2update', 'product_id': 'BTC-USD', 'changes': [['buy', '38308.46', '1.30429692']], 'time': '2021-05-20T03:56:20.567720Z'}
{'type': 'l2update', 'product_id': 'BTC-USD', 'changes': [['sell', '38385.67', '0.00000000']], 'time': '2021-05-20T03:56:20.577442Z'}
{'type': 'l2update', 'product_id': 'BTC-USD', 'changes': [['sell', '38453.07', '0.00000000']], 'time': '2021-05-20T03:56:20.577850Z'}
{'type': 'l2update', 'product_id': 'BTC-USD', 'changes': [['buy', '38303.23', '0.00000000']], 'time': '2021-05-20T03:56:20.581065Z'}
{'type': 'l2update', 'product_id': 'BTC-USD', 'changes': [['sell', '38362.96', '1.30456823']], 'time': '2021-05-20T03:56:20.583955Z'}
{'type': 'l2update', 'product_id': 'BTC-USD', 'changes': [['sell', '38474.13', '0.02949650']], 'time': '2021-05-20T03:56:20.591729Z'}
{'type': 'l2update', 'product_id': 'BTC-USD', 'changes': [['buy', '38299.45', '2.60867771']], 'time': '2021-05-20T03:56:20.596046Z'}
{'type': 'l2update', 'product_id': 'BTC-USD', 'changes': [['sell', '38358.34', '0.00000000']], 'time': '2021-05-20T03:56:20.596550Z'}
{'type': 'l2update', 'product_id': 'BTC-USD', 'changes': [['buy', '38287.64', '0.00000000']], 'time': '2021-05-20T03:56:20.597387Z'}
{'type': 'l2update', 'product_id': 'BTC-USD', 'changes': [['buy', '38285.12', '0.00000000']], 'time': '2021-05-20T03:56:20.603334Z'}
{'type': 'l2update', 'product_id': 'BTC-USD', 'changes': [['buy', '38356.52', '0.13283442']], 'time': '2021-05-20T03:56:20.606114Z'}
{'type': 'l2update', 'product_id': 'BTC-USD', 'changes': [['buy', '38282.43', '0.00000000']], 'time': '2021-05-20T03:56:20.606781Z'}
{'type': 'l2update', 'product_id': 'BTC-USD', 'changes': [['sell', '38370.27', '1.30433886']], 'time': '2021-05-20T03:56:20.610769Z'}
{'type': 'l2update', 'product_id': 'BTC-USD', 'changes': [['sell', '38358.93', '0.00000000']], 'time': '2021-05-20T03:56:20.611073Z'}
{'type': 'l2update', 'product_id': 'BTC-USD', 'changes': [['buy', '38278.25', '0.00000000']], 'time': '2021-05-20T03:56:20.612263Z'}
{'type': 'l2update', 'product_id': 'BTC-USD', 'changes': [['sell', '38484.69', '0.00000000']], 'time': '2021-05-20T03:56:20.613565Z'}
{'type': 'l2update', 'product_id': 'BTC-USD', 'changes': [['buy', '38335.80', '0.00000000']], 'time': '2021-05-20T03:56:20.614388Z'}
{'type': 'l2update', 'product_id': 'BTC-USD', 'changes': [['buy', '38277.17', '0.00000000']], 'time': '2021-05-20T03:56:20.616191Z'}
{'type': 'l2update', 'product_id': 'BTC-USD', 'changes': [['sell', '38359.30', '0.00000000']], 'time': '2021-05-20T03:56:20.616324Z'}
{'type': 'l2update', 'product_id': 'BTC-USD', 'changes': [['sell', '38400.29', '0.00000000']], 'time': '2021-05-20T03:56:20.616719Z'}
{'type': 'l2update', 'product_id': 'BTC-USD', 'changes': [['sell', '38580.00', '1.00000000']], 'time': '2021-05-20T03:56:20.621075Z'}
{'type': 'l2update', 'product_id': 'BTC-USD', 'changes': [['sell', '38382.85', '0.05096993']], 'time': '2021-05-20T03:56:20.624617Z'}
{'type': 'l2update', 'product_id': 'BTC-USD', 'changes': [['sell', '38558.59', '0.03562451']], 'time': '2021-05-20T03:56:20.624758Z'}
{'type': 'l2update', 'product_id': 'BTC-USD', 'changes': [['sell', '38374.51', '2.60943747']], 'time': '2021-05-20T03:56:20.624802Z'}
{'type': 'l2update', 'product_id': 'BTC-USD', 'changes': [['sell', '38407.81', '0.04983706']], 'time': '2021-05-20T03:56:20.628966Z'}
{'type': 'l2update', 'product_id': 'BTC-USD', 'changes': [['buy', '38263.22', '0.01000000']], 'time': '2021-05-20T03:56:20.629208Z'}
{'type': 'l2update', 'product_id': 'BTC-USD', 'changes': [['buy', '38335.75', '0.59116555']], 'time': '2021-05-20T03:56:20.638080Z'}
{'type': 'l2update', 'product_id': 'BTC-USD', 'changes': [['sell', '38370.11', '0.00000000']], 'time': '2021-05-20T03:56:20.640743Z'}
{'type': 'l2update', 'product_id': 'BTC-USD', 'changes': [['sell', '38383.94', '2.60926893']], 'time': '2021-05-20T03:56:20.642033Z'}
{'type': 'l2update', 'product_id': 'BTC-USD', 'changes': [['buy', '38263.11', '0.02000000']], 'time': '2021-05-20T03:56:20.642441Z'}
{'type': 'l2update', 'product_id': 'BTC-USD', 'changes': [['sell', '38384.39', '0.03000000']], 'time': '2021-05-20T03:56:20.647774Z'}
{'type': 'l2update', 'product_id': 'BTC-USD', 'changes': [['sell', '38390.61', '2.60887038']], 'time': '2021-05-20T03:56:20.652732Z'}
{'type': 'l2update', 'product_id': 'BTC-USD', 'changes': [['sell', '38453.71', '0.00000000']], 'time': '2021-05-20T03:56:20.653207Z'}
{'type': 'l2update', 'product_id': 'BTC-USD', 'changes': [['sell', '38382.01', '0.00000000']], 'time': '2021-05-20T03:56:20.653548Z'}
{'type': 'l2update', 'product_id': 'BTC-USD', 'changes': [['sell', '38384.39', '0.00000000']], 'time': '2021-05-20T03:56:20.661706Z'}
{'type': 'l2update', 'product_id': 'BTC-USD', 'changes': [['sell', '38390.98', '0.01000000']], 'time': '2021-05-20T03:56:20.664558Z'}
{'type': 'l2update', 'product_id': 'BTC-USD', 'changes': [['buy', '38306.60', '0.00000000']], 'time': '2021-05-20T03:56:20.665129Z'}
{'type': 'l2update', 'product_id': 'BTC-USD', 'changes': [['sell', '38382.98', '0.00000000']], 'time': '2021-05-20T03:56:20.667154Z'}
{'type': 'l2update', 'product_id': 'BTC-USD', 'changes': [['sell', '38441.65', '0.00000000']], 'time': '2021-05-20T03:56:20.669512Z'}
{'type': 'l2update', 'product_id': 'BTC-USD', 'changes': [['sell', '38362.18', '0.00000000']], 'time': '2021-05-20T03:56:20.670012Z'}
{'type': 'l2update', 'product_id': 'BTC-USD', 'changes': [['sell', '38467.71', '0.51991660']], 'time': '2021-05-20T03:56:20.670063Z'}
{'type': 'l2update', 'product_id': 'BTC-USD', 'changes': [['sell', '38384.35', '0.34323057']], 'time': '2021-05-20T03:56:20.674019Z'}
{'type': 'l2update', 'product_id': 'BTC-USD', 'changes': [['buy', '38308.53', '0.01000000']], 'time': '2021-05-20T03:56:20.677529Z'}
{'type': 'l2update', 'product_id': 'BTC-USD', 'changes': [['sell', '38386.40', '0.00000000']], 'time': '2021-05-20T03:56:20.679572Z'}
{'type': 'l2update', 'product_id': 'BTC-USD', 'changes': [['sell', '38356.57', '1.72912310']], 'time': '2021-05-20T03:56:20.681482Z'}
{'type': 'l2update', 'product_id': 'BTC-USD', 'changes': [['buy', '38261.69', '0.03000000']], 'time': '2021-05-20T03:56:20.685044Z'}
{'type': 'l2update', 'product_id': 'BTC-USD', 'changes': [['sell', '38390.98', '0.00000000']], 'time': '2021-05-20T03:56:20.686837Z'}
{'type': 'l2update', 'product_id': 'BTC-USD', 'changes': [['sell', '38364.02', '0.00000000']], 'time': '2021-05-20T03:56:20.694253Z'}
{'type': 'l2update', 'product_id': 'BTC-USD', 'changes': [['sell', '38377.64', '0.44960000']], 'time': '2021-05-20T03:56:20.695683Z'}
{'type': 'l2update', 'product_id': 'BTC-USD', 'changes': [['sell', '38558.59', '0.00000000']], 'time': '2021-05-20T03:56:20.698782Z'}
{'type': 'l2update', 'product_id': 'BTC-USD', 'changes': [['buy', '38261.31', '0.04000000']], 'time': '2021-05-20T03:56:20.701009Z'}
{'type': 'l2update', 'product_id': 'BTC-USD', 'changes': [['buy', '38325.80', '0.00000000']], 'time': '2021-05-20T03:56:20.702465Z'}
{'type': 'l2update', 'product_id': 'BTC-USD', 'changes': [['buy', '38335.74', '0.00000000']], 'time': '2021-05-20T03:56:20.702794Z'}
{'type': 'l2update', 'product_id': 'BTC-USD', 'changes': [['sell', '38377.64', '0.00000000']], 'time': '2021-05-20T03:56:20.703415Z'}
{'type': 'l2update', 'product_id': 'BTC-USD', 'changes': [['sell', '38356.53', '0.00573000']], 'time': '2021-05-20T03:56:20.703559Z'}
{'type': 'l2update', 'product_id': 'BTC-USD', 'changes': [['sell', '38356.57', '0.61800000']], 'time': '2021-05-20T03:56:20.703575Z'}
{'type': 'l2update', 'product_id': 'BTC-USD', 'changes': [['sell', '38356.57', '0.00000000']], 'time': '2021-05-20T03:56:20.706943Z'}
{'type': 'l2update', 'product_id': 'BTC-USD', 'changes': [['buy', '38320.38', '0.00000000']], 'time': '2021-05-20T03:56:20.710892Z'}
{'type': 'l2update', 'product_id': 'BTC-USD', 'changes': [['buy', '38335.75', '0.00000000']], 'time': '2021-05-20T03:56:20.713593Z'}
{'type': 'l2update', 'product_id': 'BTC-USD', 'changes': [['sell', '38467.71', '0.00000000']], 'time': '2021-05-20T03:56:20.716555Z'}
{'type': 'l2update', 'product_id': 'BTC-USD', 'changes': [['sell', '38382.85', '0.00000000']], 'time': '2021-05-20T03:56:20.716795Z'}
{'type': 'l2update', 'product_id': 'BTC-USD', 'changes': [['buy', '38261.31', '0.09000000']], 'time': '2021-05-20T03:56:20.717369Z'}
{'type': 'l2update', 'product_id': 'BTC-USD', 'changes': [['sell', '38427.05', '0.17980000']], 'time': '2021-05-20T03:56:20.717388Z'}
{'type': 'l2update', 'product_id': 'BTC-USD', 'changes': [['sell', '38361.10', '0.00000000']], 'time': '2021-05-20T03:56:20.718388Z'}
{'type': 'l2update', 'product_id': 'BTC-USD', 'changes': [['buy', '38140.59', '0.00000000']], 'time': '2021-05-20T03:56:20.719479Z'}
{'type': 'l2update', 'product_id': 'BTC-USD', 'changes': [['sell', '38454.88', '0.00000000']], 'time': '2021-05-20T03:56:20.721457Z'}
{'type': 'l2update', 'product_id': 'BTC-USD', 'changes': [['buy', '38351.28', '0.05061126']], 'time': '2021-05-20T03:56:20.722801Z'}
{'type': 'l2update', 'product_id': 'BTC-USD', 'changes': [['buy', '38329.19', '0.39490431']], 'time': '2021-05-20T03:56:20.723084Z'}
{'type': 'l2update', 'product_id': 'BTC-USD', 'changes': [['buy', '38356.52', '0.19283442']], 'time': '2021-05-20T03:56:20.723153Z'}
{'type': 'l2update', 'product_id': 'BTC-USD', 'changes': [['buy', '38193.14', '0.05148846']], 'time': '2021-05-20T03:56:20.723737Z'}
{'type': 'l2update', 'product_id': 'BTC-USD', 'changes': [['buy', '38321.71', '0.43450000']], 'time': '2021-05-20T03:56:20.724215Z'}
{'type': 'l2update', 'product_id': 'BTC-USD', 'changes': [['sell', '38356.63', '0.00000000']], 'time': '2021-05-20T03:56:20.724382Z'}
{'type': 'l2update', 'product_id': 'BTC-USD', 'changes': [['sell', '38356.53', '0.00000000']], 'time': '2021-05-20T03:56:20.727780Z'}
{'type': 'l2update', 'product_id': 'BTC-USD', 'changes': [['sell', '38356.53', '0.01000000']], 'time': '2021-05-20T03:56:20.734129Z'}
{'type': 'l2update', 'product_id': 'BTC-USD', 'changes': [['sell', '38505.85', '0.01000000']], 'time': '2021-05-20T03:56:20.734667Z'}
{'type': 'l2update', 'product_id': 'BTC-USD', 'changes': [['buy', '38301.88', '0.00000000']], 'time': '2021-05-20T03:56:20.735150Z'}
{'type': 'l2update', 'product_id': 'BTC-USD', 'changes': [['buy', '38334.40', '0.59116555']], 'time': '2021-05-20T03:56:20.735417Z'}
{'type': 'l2update', 'product_id': 'BTC-USD', 'changes': [['buy', '38347.05', '0.98587534']], 'time': '2021-05-20T03:56:20.735437Z'}
{'type': 'l2update', 'product_id': 'BTC-USD', 'changes': [['buy', '38321.71', '0.00000000']], 'time': '2021-05-20T03:56:20.736062Z'}
{'type': 'l2update', 'product_id': 'BTC-USD', 'changes': [['buy', '38290.65', '0.00000000']], 'time': '2021-05-20T03:56:20.737237Z'}
{'type': 'l2update', 'product_id': 'BTC-USD', 'changes': [['buy', '38347.03', '0.00000000']], 'time': '2021-05-20T03:56:20.737962Z'}
{'type': 'l2update', 'product_id': 'BTC-USD', 'changes': [['sell', '38467.89', '0.12997856']], 'time': '2021-05-20T03:56:20.739277Z'}
{'type': 'l2update', 'product_id': 'BTC-USD', 'changes': [['buy', '38356.52', '0.13283442']], 'time': '2021-05-20T03:56:20.740247Z'}
{'type': 'l2update', 'product_id': 'BTC-USD', 'changes': [['buy', '38197.48', '0.05008082']], 'time': '2021-05-20T03:56:20.743665Z'}
{'type': 'l2update', 'product_id': 'BTC-USD', 'changes': [['sell', '38356.62', '0.00000000']], 'time': '2021-05-20T03:56:20.746012Z'}
{'type': 'l2update', 'product_id': 'BTC-USD', 'changes': [['sell', '38420.80', '0.00000000']], 'time': '2021-05-20T03:56:20.749111Z'}
{'type': 'l2update', 'product_id': 'BTC-USD', 'changes': [['sell', '38356.53', '0.03000000']], 'time': '2021-05-20T03:56:20.752724Z'}
{'type': 'l2update', 'product_id': 'BTC-USD', 'changes': [['buy', '38313.58', '0.03473956']], 'time': '2021-05-20T03:56:20.758621Z'}
{'type': 'l2update', 'product_id': 'BTC-USD', 'changes': [['sell', '38356.53', '0.02000000']], 'time': '2021-05-20T03:56:20.761086Z'}
{'type': 'l2update', 'product_id': 'BTC-USD', 'changes': [['sell', '38356.53', '0.00000000']], 'time': '2021-05-20T03:56:20.761086Z'}
{'type': 'l2update', 'product_id': 'BTC-USD', 'changes': [['sell', '38357.06', '0.50169886']], 'time': '2021-05-20T03:56:20.761086Z'}
{'type': 'l2update', 'product_id': 'BTC-USD', 'changes': [['sell', '38362.95', '2.48969908']], 'time': '2021-05-20T03:56:20.761373Z'}
{'type': 'l2update', 'product_id': 'BTC-USD', 'changes': [['sell', '38437.25', '0.21500000']], 'time': '2021-05-20T03:56:20.761423Z'}
{'type': 'l2update', 'product_id': 'BTC-USD', 'changes': [['buy', '38306.67', '0.02610511']], 'time': '2021-05-20T03:56:20.761584Z'}
{'type': 'l2update', 'product_id': 'BTC-USD', 'changes': [['buy', '38350.14', '1.09150484']], 'time': '2021-05-20T03:56:20.761638Z'}
{'type': 'l2update', 'product_id': 'BTC-USD', 'changes': [['sell', '38455.76', '0.03412139']], 'time': '2021-05-20T03:56:20.761892Z'}
{'type': 'l2update', 'product_id': 'BTC-USD', 'changes': [['sell', '38529.97', '0.00000000']], 'time': '2021-05-20T03:56:20.762956Z'}
{'type': 'l2update', 'product_id': 'BTC-USD', 'changes': [['sell', '38395.57', '0.00000000']], 'time': '2021-05-20T03:56:20.767678Z'}
{'type': 'l2update', 'product_id': 'BTC-USD', 'changes': [['buy', '38338.27', '0.00000000']], 'time': '2021-05-20T03:56:20.769246Z'}
{'type': 'l2update', 'product_id': 'BTC-USD', 'changes': [['sell', '38407.31', '0.05453463']], 'time': '2021-05-20T03:56:20.771561Z'}
{'type': 'l2update', 'product_id': 'BTC-USD', 'changes': [['buy', '38202.34', '0.17950000']], 'time': '2021-05-20T03:56:20.771887Z'}
{'type': 'l2update', 'product_id': 'BTC-USD', 'changes': [['sell', '38379.98', '0.00000000']], 'time': '2021-05-20T03:56:20.772642Z'}
{'type': 'l2update', 'product_id': 'BTC-USD', 'changes': [['buy', '38357.05', '0.04330000']], 'time': '2021-05-20T03:56:20.775943Z'}
{'type': 'l2update', 'product_id': 'BTC-USD', 'changes': [['buy', '38334.34', '0.00000000']], 'time': '2021-05-20T03:56:20.779053Z'}
{'type': 'l2update', 'product_id': 'BTC-USD', 'changes': [['sell', '38393.95', '0.33444977']], 'time': '2021-05-20T03:56:20.779883Z'}
{'type': 'l2update', 'product_id': 'BTC-USD', 'changes': [['buy', '38258.03', '0.00000000']], 'time': '2021-05-20T03:56:20.779883Z'}
{'type': 'l2update', 'product_id': 'BTC-USD', 'changes': [['buy', '38297.14', '0.00000000']], 'time': '2021-05-20T03:56:20.779883Z'}
{'type': 'l2update', 'product_id': 'BTC-USD', 'changes': [['buy', '38308.53', '0.00000000']], 'time': '2021-05-20T03:56:20.783668Z'}
{'type': 'l2update', 'product_id': 'BTC-USD', 'changes': [['sell', '38406.75', '0.00000000']], 'time': '2021-05-20T03:56:20.783704Z'}
{'type': 'l2update', 'product_id': 'BTC-USD', 'changes': [['buy', '38357.05', '0.11790000']], 'time': '2021-05-20T03:56:20.783795Z'}
{'type': 'l2update', 'product_id': 'BTC-USD', 'changes': [['sell', '38414.85', '0.01363366']], 'time': '2021-05-20T03:56:20.783832Z'}
{'type': 'l2update', 'product_id': 'BTC-USD', 'changes': [['buy', '38351.29', '1.06803161']], 'time': '2021-05-20T03:56:20.783851Z'}
{'type': 'l2update', 'product_id': 'BTC-USD', 'changes': [['buy', '38356.53', '0.00570000']], 'time': '2021-05-20T03:56:20.784078Z'}
{'type': 'l2update', 'product_id': 'BTC-USD', 'changes': [['buy', '38356.61', '0.10000000']], 'time': '2021-05-20T03:56:20.784432Z'}
{'type': 'l2update', 'product_id': 'BTC-USD', 'changes': [['buy', '38356.61', '0.11440000']], 'time': '2021-05-20T03:56:20.784480Z'}
{'type': 'l2update', 'product_id': 'BTC-USD', 'changes': [['buy', '38355.98', '0.19800000']], 'time': '2021-05-20T03:56:20.784507Z'}
{'type': 'l2update', 'product_id': 'BTC-USD', 'changes': [['sell', '38357.06', '0.11739886']], 'time': '2021-05-20T03:56:20.784758Z'}
{'type': 'l2update', 'product_id': 'BTC-USD', 'changes': [['buy', '38349.78', '0.00060000']], 'time': '2021-05-20T03:56:20.784881Z'}
{'type': 'l2update', 'product_id': 'BTC-USD', 'changes': [['sell', '38357.06', '0.06739886']], 'time': '2021-05-20T03:56:20.785158Z'}
{'type': 'l2update', 'product_id': 'BTC-USD', 'changes': [['sell', '38362.95', '2.98969908']], 'time': '2021-05-20T03:56:20.785396Z'}
{'type': 'l2update', 'product_id': 'BTC-USD', 'changes': [['sell', '38379.97', '0.00000000']], 'time': '2021-05-20T03:56:20.788043Z'}
{'type': 'l2update', 'product_id': 'BTC-USD', 'changes': [['buy', '38356.53', '0.01000000']], 'time': '2021-05-20T03:56:20.789232Z'}
{'type': 'l2update', 'product_id': 'BTC-USD', 'changes': [['sell', '38516.79', '0.01000000']], 'time': '2021-05-20T03:56:20.789705Z'}
{'type': 'l2update', 'product_id': 'BTC-USD', 'changes': [['sell', '38679.32', '0.00000000']], 'time': '2021-05-20T03:56:20.790047Z'}
{'type': 'l2update', 'product_id': 'BTC-USD', 'changes': [['buy', '38357.05', '0.13282000']], 'time': '2021-05-20T03:56:20.790109Z'}
{'type': 'l2update', 'product_id': 'BTC-USD', 'changes': [['buy', '38347.05', '0.00000000']], 'time': '2021-05-20T03:56:20.791868Z'}
{'type': 'l2update', 'product_id': 'BTC-USD', 'changes': [['buy', '38356.61', '0.10000000']], 'time': '2021-05-20T03:56:20.793377Z'}
{'type': 'l2update', 'product_id': 'BTC-USD', 'changes': [['sell', '38362.96', '0.00000000']], 'time': '2021-05-20T03:56:20.793550Z'}
{'type': 'l2update', 'product_id': 'BTC-USD', 'changes': [['buy', '38334.40', '0.00000000']], 'time': '2021-05-20T03:56:20.797069Z'}
{'type': 'l2update', 'product_id': 'BTC-USD', 'changes': [['sell', '38407.81', '0.00000000']], 'time': '2021-05-20T03:56:20.798402Z'}
{'type': 'l2update', 'product_id': 'BTC-USD', 'changes': [['sell', '38362.95', '2.48969908']], 'time': '2021-05-20T03:56:20.799379Z'}
{'type': 'l2update', 'product_id': 'BTC-USD', 'changes': [['sell', '38367.67', '0.00000000']], 'time': '2021-05-20T03:56:20.801571Z'}
{'type': 'l2update', 'product_id': 'BTC-USD', 'changes': [['buy', '38328.55', '0.00000000']], 'time': '2021-05-20T03:56:20.801571Z'}
{'type': 'l2update', 'product_id': 'BTC-USD', 'changes': [['buy', '38350.14', '0.00000000']], 'time': '2021-05-20T03:56:20.804625Z'}
{'type': 'l2update', 'product_id': 'BTC-USD', 'changes': [['buy', '38182.16', '0.00000000']], 'time': '2021-05-20T03:56:20.804732Z'}
{'type': 'l2update', 'product_id': 'BTC-USD', 'changes': [['buy', '38276.81', '0.00000000']], 'time': '2021-05-20T03:56:20.804732Z'}
{'type': 'l2update', 'product_id': 'BTC-USD', 'changes': [['sell', '38385.94', '0.00000000']], 'time': '2021-05-20T03:56:20.804732Z'}
{'type': 'l2update', 'product_id': 'BTC-USD', 'changes': [['sell', '38480.59', '0.00000000']], 'time': '2021-05-20T03:56:20.804732Z'}
{'type': 'l2update', 'product_id': 'BTC-USD', 'changes': [['buy', '38347.10', '0.84500000']], 'time': '2021-05-20T03:56:20.805124Z'}
{'type': 'l2update', 'product_id': 'BTC-USD', 'changes': [['buy', '38343.51', '0.07083245']], 'time': '2021-05-20T03:56:20.805447Z'}
{'type': 'l2update', 'product_id': 'BTC-USD', 'changes': [['buy', '38356.61', '0.30000000']], 'time': '2021-05-20T03:56:20.805849Z'}
{'type': 'l2update', 'product_id': 'BTC-USD', 'changes': [['sell', '38388.06', '0.41030000']], 'time': '2021-05-20T03:56:20.805943Z'}
{'type': 'l2update', 'product_id': 'BTC-USD', 'changes': [['buy', '38328.52', '0.00000000']], 'time': '2021-05-20T03:56:20.806044Z'}
{'type': 'l2update', 'product_id': 'BTC-USD', 'changes': [['sell', '38383.93', '0.05000000']], 'time': '2021-05-20T03:56:20.808969Z'}
{'type': 'l2update', 'product_id': 'BTC-USD', 'changes': [['sell', '38490.25', '0.35060577']], 'time': '2021-05-20T03:56:20.810346Z'}
{'type': 'l2update', 'product_id': 'BTC-USD', 'changes': [['buy', '38256.36', '0.43639355']], 'time': '2021-05-20T03:56:20.810346Z'}
{'type': 'l2update', 'product_id': 'BTC-USD', 'changes': [['buy', '38262.42', '0.41463942']], 'time': '2021-05-20T03:56:20.810346Z'}
{'type': 'l2update', 'product_id': 'BTC-USD', 'changes': [['sell', '38374.89', '0.00000000']], 'time': '2021-05-20T03:56:20.813320Z'}
{'type': 'l2update', 'product_id': 'BTC-USD', 'changes': [['sell', '38361.03', '0.00000000']], 'time': '2021-05-20T03:56:20.817558Z'}
{'type': 'l2update', 'product_id': 'BTC-USD', 'changes': [['buy', '38301.72', '0.00000000']], 'time': '2021-05-20T03:56:20.817558Z'}
{'type': 'l2update', 'product_id': 'BTC-USD', 'changes': [['sell', '38388.06', '0.00000000']], 'time': '2021-05-20T03:56:20.819591Z'}
{'type': 'l2update', 'product_id': 'BTC-USD', 'changes': [['sell', '38505.85', '0.00000000']], 'time': '2021-05-20T03:56:20.819782Z'}
{'type': 'l2update', 'product_id': 'BTC-USD', 'changes': [['sell', '38374.51', '0.00000000']], 'time': '2021-05-20T03:56:20.819959Z'}
{'type': 'l2update', 'product_id': 'BTC-USD', 'changes': [['sell', '38357.06', '0.00000000']], 'time': '2021-05-20T03:56:20.822384Z'}
{'type': 'l2update', 'product_id': 'BTC-USD', 'changes': [['sell', '38362.95', '2.15119908']], 'time': '2021-05-20T03:56:20.823519Z'}
{'type': 'l2update', 'product_id': 'BTC-USD', 'changes': [['sell', '38443.96', '0.00000000']], 'time': '2021-05-20T03:56:20.823644Z'}
{'type': 'l2update', 'product_id': 'BTC-USD', 'changes': [['sell', '38404.02', '0.38657279']], 'time': '2021-05-20T03:56:20.826518Z'}
{'type': 'l2update', 'product_id': 'BTC-USD', 'changes': [['sell', '38384.35', '0.05075989']], 'time': '2021-05-20T03:56:20.826518Z'}
{'type': 'l2update', 'product_id': 'BTC-USD', 'changes': [['buy', '38219.19', '0.00000000']], 'time': '2021-05-20T03:56:20.826518Z'}
{'type': 'l2update', 'product_id': 'BTC-USD', 'changes': [['buy', '38226.01', '0.00000000']], 'time': '2021-05-20T03:56:20.826518Z'}
{'type': 'l2update', 'product_id': 'BTC-USD', 'changes': [['sell', '38362.95', '0.00000000']], 'time': '2021-05-20T03:56:20.827735Z'}
{'type': 'l2update', 'product_id': 'BTC-USD', 'changes': [['buy', '38289.15', '0.00000000']], 'time': '2021-05-20T03:56:20.831522Z'}
{'type': 'l2update', 'product_id': 'BTC-USD', 'changes': [['buy', '38357.05', '0.05822000']], 'time': '2021-05-20T03:56:20.834570Z'}
{'type': 'l2update', 'product_id': 'BTC-USD', 'changes': [['buy', '38357.05', '0.04330000']], 'time': '2021-05-20T03:56:20.837293Z'}
{'type': 'l2update', 'product_id': 'BTC-USD', 'changes': [['buy', '38343.51', '0.00000000']], 'time': '2021-05-20T03:56:20.838587Z'}
{'type': 'l2update', 'product_id': 'BTC-USD', 'changes': [['buy', '38357.05', '1.05264856']], 'time': '2021-05-20T03:56:20.839059Z'}
{'type': 'l2update', 'product_id': 'BTC-USD', 'changes': [['sell', '38483.20', '0.38099600']], 'time': '2021-05-20T03:56:20.839087Z'}
{'type': 'l2update', 'product_id': 'BTC-USD', 'changes': [['buy', '38243.67', '0.03145418']], 'time': '2021-05-20T03:56:20.839087Z'}
{'type': 'l2update', 'product_id': 'BTC-USD', 'changes': [['buy', '38262.42', '0.44134865']], 'time': '2021-05-20T03:56:20.839087Z'}
{'type': 'l2update', 'product_id': 'BTC-USD', 'changes': [['buy', '38268.29', '0.03142865']], 'time': '2021-05-20T03:56:20.839087Z'}
{'type': 'l2update', 'product_id': 'BTC-USD', 'changes': [['buy', '38279.47', '0.03384776']], 'time': '2021-05-20T03:56:20.839087Z'}
{'type': 'l2update', 'product_id': 'BTC-USD', 'changes': [['buy', '38288.09', '0.06722759']], 'time': '2021-05-20T03:56:20.839087Z'}
{'type': 'l2update', 'product_id': 'BTC-USD', 'changes': [['buy', '38304.12', '0.03526465']], 'time': '2021-05-20T03:56:20.839087Z'}
{'type': 'l2update', 'product_id': 'BTC-USD', 'changes': [['sell', '38435.32', '0.01000000']], 'time': '2021-05-20T03:56:20.839181Z'}
{'type': 'l2update', 'product_id': 'BTC-USD', 'changes': [['buy', '38357.06', '0.20000000']], 'time': '2021-05-20T03:56:20.839405Z'}
{'type': 'l2update', 'product_id': 'BTC-USD', 'changes': [['sell', '38374.50', '0.50000000']], 'time': '2021-05-20T03:56:20.839574Z'}
{'type': 'l2update', 'product_id': 'BTC-USD', 'changes': [['buy', '38316.18', '1.20000000']], 'time': '2021-05-20T03:56:20.839617Z'}
{'type': 'l2update', 'product_id': 'BTC-USD', 'changes': [['sell', '38392.31', '0.00000000']], 'time': '2021-05-20T03:56:20.839859Z'}
{'type': 'l2update', 'product_id': 'BTC-USD', 'changes': [['sell', '38384.35', '0.00000000']], 'time': '2021-05-20T03:56:20.840102Z'}
{'type': 'l2update', 'product_id': 'BTC-USD', 'changes': [['buy', '38165.30', '0.00000000']], 'time': '2021-05-20T03:56:20.842126Z'}
{'type': 'l2update', 'product_id': 'BTC-USD', 'changes': [['buy', '38331.10', '0.00000000']], 'time': '2021-05-20T03:56:20.842194Z'}
{'type': 'l2update', 'product_id': 'BTC-USD', 'changes': [['sell', '38393.95', '0.00000000']], 'time': '2021-05-20T03:56:20.845169Z'}
{'type': 'l2update', 'product_id': 'BTC-USD', 'changes': [['buy', '38266.48', '0.00000000']], 'time': '2021-05-20T03:56:20.845169Z'}
{'type': 'l2update', 'product_id': 'BTC-USD', 'changes': [['sell', '38490.49', '0.00000000']], 'time': '2021-05-20T03:56:20.846141Z'}
{'type': 'l2update', 'product_id': 'BTC-USD', 'changes': [['sell', '38384.34', '0.46420669']], 'time': '2021-05-20T03:56:20.846598Z'}
{'type': 'l2update', 'product_id': 'BTC-USD', 'changes': [['buy', '38370.26', '0.04330000']], 'time': '2021-05-20T03:56:20.847261Z'}
{'type': 'l2update', 'product_id': 'BTC-USD', 'changes': [['sell', '38468.76', '0.01000000']], 'time': '2021-05-20T03:56:20.847526Z'}
{'type': 'l2update', 'product_id': 'BTC-USD', 'changes': [['buy', '38357.06', '0.31730000']], 'time': '2021-05-20T03:56:20.849374Z'}
{'type': 'l2update', 'product_id': 'BTC-USD', 'changes': [['sell', '38465.24', '0.00000000']], 'time': '2021-05-20T03:56:20.849555Z'}
{'type': 'l2update', 'product_id': 'BTC-USD', 'changes': [['buy', '38357.05', '1.05837856']], 'time': '2021-05-20T03:56:20.854753Z'}
{'type': 'l2update', 'product_id': 'BTC-USD', 'changes': [['sell', '38550.77', '0.00000000']], 'time': '2021-05-20T03:56:20.855858Z'}
{'type': 'l2update', 'product_id': 'BTC-USD', 'changes': [['sell', '38374.50', '0.00000000']], 'time': '2021-05-20T03:56:20.856772Z'}
{'type': 'l2update', 'product_id': 'BTC-USD', 'changes': [['buy', '38290.21', '0.00000000']], 'time': '2021-05-20T03:56:20.857244Z'}
{'type': 'l2update', 'product_id': 'BTC-USD', 'changes': [['sell', '38384.34', '0.00000000']], 'time': '2021-05-20T03:56:20.857723Z'}
{'type': 'l2update', 'product_id': 'BTC-USD', 'changes': [['buy', '38357.30', '0.07460000']], 'time': '2021-05-20T03:56:20.860651Z'}
{'type': 'l2update', 'product_id': 'BTC-USD', 'changes': [['buy', '38235.33', '0.00000000']], 'time': '2021-05-20T03:56:20.860864Z'}
{'type': 'l2update', 'product_id': 'BTC-USD', 'changes': [['sell', '38623.29', '0.05913859']], 'time': '2021-05-20T03:56:20.861272Z'}
{'type': 'l2update', 'product_id': 'BTC-USD', 'changes': [['buy', '38317.89', '0.00000000']], 'time': '2021-05-20T03:56:20.861645Z'}
{'type': 'l2update', 'product_id': 'BTC-USD', 'changes': [['buy', '38357.05', '1.01507856']], 'time': '2021-05-20T03:56:20.862058Z'}
{'type': 'l2update', 'product_id': 'BTC-USD', 'changes': [['sell', '38383.93', '0.00000000']], 'time': '2021-05-20T03:56:20.862937Z'}
{'type': 'l2update', 'product_id': 'BTC-USD', 'changes': [['buy', '38353.41', '0.07083827']], 'time': '2021-05-20T03:56:20.866283Z'}
{'type': 'l2update', 'product_id': 'BTC-USD', 'changes': [['sell', '38502.50', '0.01000000']], 'time': '2021-05-20T03:56:20.866299Z'}
{'type': 'l2update', 'product_id': 'BTC-USD', 'changes': [['sell', '38470.31', '1.20000000']], 'time': '2021-05-20T03:56:20.866765Z'}
{'type': 'l2update', 'product_id': 'BTC-USD', 'changes': [['sell', '38370.27', '1.30052558']], 'time': '2021-05-20T03:56:20.866955Z'}
{'type': 'l2update', 'product_id': 'BTC-USD', 'changes': [['buy', '38357.06', '0.41730000']], 'time': '2021-05-20T03:56:20.867061Z'}
{'type': 'l2update', 'product_id': 'BTC-USD', 'changes': [['buy', '38357.59', '0.01492000']], 'time': '2021-05-20T03:56:20.867111Z'}
{'type': 'l2update', 'product_id': 'BTC-USD', 'changes': [['buy', '38356.62', '1.20887095']], 'time': '2021-05-20T03:56:20.867156Z'}
{'type': 'l2update', 'product_id': 'BTC-USD', 'changes': [['buy', '38183.00', '0.00000000']], 'time': '2021-05-20T03:56:20.867852Z'}
{'type': 'l2update', 'product_id': 'BTC-USD', 'changes': [['buy', '38276.80', '0.00000000']], 'time': '2021-05-20T03:56:20.867875Z'}
{'type': 'l2update', 'product_id': 'BTC-USD', 'changes': [['buy', '38328.56', '0.00000000']], 'time': '2021-05-20T03:56:20.871470Z'}
{'type': 'l2update', 'product_id': 'BTC-USD', 'changes': [['buy', '38304.12', '0.04643005']], 'time': '2021-05-20T03:56:20.873775Z'}
{'type': 'l2update', 'product_id': 'BTC-USD', 'changes': [['buy', '38312.65', '0.02864374']], 'time': '2021-05-20T03:56:20.873775Z'}
{'type': 'l2update', 'product_id': 'BTC-USD', 'changes': [['buy', '38316.63', '0.01523392']], 'time': '2021-05-20T03:56:20.873775Z'}
{'type': 'l2update', 'product_id': 'BTC-USD', 'changes': [['buy', '38334.40', '0.59116555']], 'time': '2021-05-20T03:56:20.873881Z'}
{'type': 'l2update', 'product_id': 'BTC-USD', 'changes': [['sell', '38370.27', '0.00000000']], 'time': '2021-05-20T03:56:20.874717Z'}
{'type': 'l2update', 'product_id': 'BTC-USD', 'changes': [['sell', '38399.99', '0.00000000']], 'time': '2021-05-20T03:56:20.876049Z'}
{'type': 'l2update', 'product_id': 'BTC-USD', 'changes': [['buy', '38357.30', '0.00000000']], 'time': '2021-05-20T03:56:20.876698Z'}
{'type': 'l2update', 'product_id': 'BTC-USD', 'changes': [['sell', '38451.98', '0.01000000']], 'time': '2021-05-20T03:56:20.878947Z'}
{'type': 'l2update', 'product_id': 'BTC-USD', 'changes': [['buy', '38010.00', '0.29888104']], 'time': '2021-05-20T03:56:20.883823Z'}
{'type': 'l2update', 'product_id': 'BTC-USD', 'changes': [['buy', '38349.78', '0.00000000']], 'time': '2021-05-20T03:56:20.885970Z'}
{'type': 'l2update', 'product_id': 'BTC-USD', 'changes': [['buy', '38316.18', '0.00000000']], 'time': '2021-05-20T03:56:20.888765Z'}
{'type': 'l2update', 'product_id': 'BTC-USD', 'changes': [['sell', '38383.92', '0.50000000']], 'time': '2021-05-20T03:56:20.890039Z'}
{'type': 'l2update', 'product_id': 'BTC-USD', 'changes': [['buy', '38177.68', '0.01000000']], 'time': '2021-05-20T03:56:20.890680Z'}
{'type': 'l2update', 'product_id': 'BTC-USD', 'changes': [['sell', '38513.07', '0.30397211']], 'time': '2021-05-20T03:56:20.890784Z'}
{'type': 'l2update', 'product_id': 'BTC-USD', 'changes': [['buy', '38295.36', '0.12753130']], 'time': '2021-05-20T03:56:20.890784Z'}
{'type': 'l2update', 'product_id': 'BTC-USD', 'changes': [['buy', '38362.94', '0.00573000']], 'time': '2021-05-20T03:56:20.891213Z'}
{'type': 'l2update', 'product_id': 'BTC-USD', 'changes': [['buy', '38357.59', '0.00000000']], 'time': '2021-05-20T03:56:20.891468Z'}
{'type': 'l2update', 'product_id': 'BTC-USD', 'changes': [['sell', '38393.00', '0.00000000']], 'time': '2021-05-20T03:56:20.897944Z'}
{'type': 'l2update', 'product_id': 'BTC-USD', 'changes': [['sell', '38388.82', '0.00000000']], 'time': '2021-05-20T03:56:20.897944Z'}
{'type': 'l2update', 'product_id': 'BTC-USD', 'changes': [['buy', '38225.75', '0.03546148']], 'time': '2021-05-20T03:56:20.897944Z'}
{'type': 'l2update', 'product_id': 'BTC-USD', 'changes': [['buy', '38232.82', '0.00000000']], 'time': '2021-05-20T03:56:20.897944Z'}
{'type': 'l2update', 'product_id': 'BTC-USD', 'changes': [['buy', '38239.26', '0.00000000']], 'time': '2021-05-20T03:56:20.897944Z'}
{'type': 'l2update', 'product_id': 'BTC-USD', 'changes': [['buy', '38252.16', '0.00000000']], 'time': '2021-05-20T03:56:20.897944Z'}
{'type': 'l2update', 'product_id': 'BTC-USD', 'changes': [['buy', '38282.97', '0.00000000']], 'time': '2021-05-20T03:56:20.897944Z'}
{'type': 'l2update', 'product_id': 'BTC-USD', 'changes': [['buy', '38283.68', '0.00000000']], 'time': '2021-05-20T03:56:20.897944Z'}
{'type': 'l2update', 'product_id': 'BTC-USD', 'changes': [['buy', '38288.09', '0.03858385']], 'time': '2021-05-20T03:56:20.897944Z'}
{'type': 'l2update', 'product_id': 'BTC-USD', 'changes': [['buy', '38293.80', '0.00000000']], 'time': '2021-05-20T03:56:20.897944Z'}
{'type': 'l2update', 'product_id': 'BTC-USD', 'changes': [['buy', '38308.46', '0.00000000']], 'time': '2021-05-20T03:56:20.900468Z'}
{'type': 'l2update', 'product_id': 'BTC-USD', 'changes': [['sell', '38383.93', '2.48969908']], 'time': '2021-05-20T03:56:20.903213Z'}
{'type': 'l2update', 'product_id': 'BTC-USD', 'changes': [['buy', '38357.05', '1.11507856']], 'time': '2021-05-20T03:56:20.904259Z'}
{'type': 'l2update', 'product_id': 'BTC-USD', 'changes': [['sell', '38397.36', '0.05000000']], 'time': '2021-05-20T03:56:20.904274Z'}
{'type': 'l2update', 'product_id': 'BTC-USD', 'changes': [['sell', '38437.25', '0.00000000']], 'time': '2021-05-20T03:56:20.907889Z'}
{'type': 'l2update', 'product_id': 'BTC-USD', 'changes': [['sell', '38470.31', '0.00000000']], 'time': '2021-05-20T03:56:20.908694Z'}
{'type': 'l2update', 'product_id': 'BTC-USD', 'changes': [['sell', '38623.29', '0.00000000']], 'time': '2021-05-20T03:56:20.912799Z'}
{'type': 'l2update', 'product_id': 'BTC-USD', 'changes': [['sell', '38451.98', '0.00000000']], 'time': '2021-05-20T03:56:20.914158Z'}
{'type': 'l2update', 'product_id': 'BTC-USD', 'changes': [['buy', '38329.19', '0.00000000']], 'time': '2021-05-20T03:56:20.914206Z'}
{'type': 'l2update', 'product_id': 'BTC-USD', 'changes': [['buy', '37548.82', '0.06439153']], 'time': '2021-05-20T03:56:20.915153Z'}
{'type': 'l2update', 'product_id': 'BTC-USD', 'changes': [['sell', '38431.60', '0.02602025']], 'time': '2021-05-20T03:56:20.915399Z'}
{'type': 'l2update', 'product_id': 'BTC-USD', 'changes': [['buy', '38370.72', '0.07460000']], 'time': '2021-05-20T03:56:20.915430Z'}
{'type': 'l2update', 'product_id': 'BTC-USD', 'changes': [['sell', '38383.92', '0.00000000']], 'time': '2021-05-20T03:56:20.915954Z'}
{'type': 'l2update', 'product_id': 'BTC-USD', 'changes': [['sell', '38398.89', '0.00000000']], 'time': '2021-05-20T03:56:20.918602Z'}
{'type': 'l2update', 'product_id': 'BTC-USD', 'changes': [['sell', '38397.37', '0.00000000']], 'time': '2021-05-20T03:56:20.918602Z'}
{'type': 'l2update', 'product_id': 'BTC-USD', 'changes': [['buy', '38272.16', '0.00000000']], 'time': '2021-05-20T03:56:20.918602Z'}
{'type': 'l2update', 'product_id': 'BTC-USD', 'changes': [['sell', '38383.94', '0.00000000']], 'time': '2021-05-20T03:56:20.922694Z'}
{'type': 'l2update', 'product_id': 'BTC-USD', 'changes': [['sell', '38402.55', '0.46269787']], 'time': '2021-05-20T03:56:20.924514Z'}
{'type': 'l2update', 'product_id': 'BTC-USD', 'changes': [['sell', '38516.79', '0.00000000']], 'time': '2021-05-20T03:56:20.926599Z'}
{'type': 'l2update', 'product_id': 'BTC-USD', 'changes': [['buy', '38370.26', '0.04903000']], 'time': '2021-05-20T03:56:20.930233Z'}
{'type': 'l2update', 'product_id': 'BTC-USD', 'changes': [['sell', '38398.88', '0.09562855']], 'time': '2021-05-20T03:56:20.930801Z'}
{'type': 'l2update', 'product_id': 'BTC-USD', 'changes': [['sell', '38414.70', '0.01000000']], 'time': '2021-05-20T03:56:20.930929Z'}
{'type': 'l2update', 'product_id': 'BTC-USD', 'changes': [['buy', '38365.97', '0.00300000']], 'time': '2021-05-20T03:56:20.936938Z'}
{'type': 'l2update', 'product_id': 'BTC-USD', 'changes': [['buy', '38370.56', '0.01492000']], 'time': '2021-05-20T03:56:20.937641Z'}
{'type': 'l2update', 'product_id': 'BTC-USD', 'changes': [['buy', '38351.30', '1.46756192']], 'time': '2021-05-20T03:56:20.938046Z'}
{'type': 'l2update', 'product_id': 'BTC-USD', 'changes': [['buy', '38370.26', '0.00573000']], 'time': '2021-05-20T03:56:20.941617Z'}
{'type': 'l2update', 'product_id': 'BTC-USD', 'changes': [['sell', '38397.36', '0.00000000']], 'time': '2021-05-20T03:56:20.947143Z'}
{'type': 'l2update', 'product_id': 'BTC-USD', 'changes': [['sell', '39170.60', '0.06973169']], 'time': '2021-05-20T03:56:20.948309Z'}
{'type': 'l2update', 'product_id': 'BTC-USD', 'changes': [['sell', '38390.61', '0.00000000']], 'time': '2021-05-20T03:56:20.949086Z'}
{'type': 'l2update', 'product_id': 'BTC-USD', 'changes': [['sell', '38691.17', '3.23362444']], 'time': '2021-05-20T03:56:20.949140Z'}
{'type': 'l2update', 'product_id': 'BTC-USD', 'changes': [['buy', '38357.06', '0.51570000']], 'time': '2021-05-20T03:56:20.950002Z'}
{'type': 'l2update', 'product_id': 'BTC-USD', 'changes': [['buy', '38362.99', '1.35100000']], 'time': '2021-05-20T03:56:20.950546Z'}
{'type': 'l2update', 'product_id': 'BTC-USD', 'changes': [['buy', '38357.05', '1.10934856']], 'time': '2021-05-20T03:56:20.953260Z'}
{'type': 'l2update', 'product_id': 'BTC-USD', 'changes': [['buy', '38323.92', '0.00000000']], 'time': '2021-05-20T03:56:20.953953Z'}
{'type': 'l2update', 'product_id': 'BTC-USD', 'changes': [['sell', '38565.17', '0.00648253']], 'time': '2021-05-20T03:56:20.957469Z'}
{'type': 'l2update', 'product_id': 'BTC-USD', 'changes': [['sell', '38455.66', '0.00000000']], 'time': '2021-05-20T03:56:20.957950Z'}
{'type': 'l2update', 'product_id': 'BTC-USD', 'changes': [['sell', '38388.81', '0.50000000']], 'time': '2021-05-20T03:56:20.958388Z'}
{'type': 'l2update', 'product_id': 'BTC-USD', 'changes': [['sell', '38427.05', '0.00000000']], 'time': '2021-05-20T03:56:20.958485Z'}
{'type': 'l2update', 'product_id': 'BTC-USD', 'changes': [['buy', '38334.40', '0.00000000']], 'time': '2021-05-20T03:56:20.959654Z'}
{'type': 'l2update', 'product_id': 'BTC-USD', 'changes': [['sell', '38402.56', '0.00000000']], 'time': '2021-05-20T03:56:20.960277Z'}
{'type': 'l2update', 'product_id': 'BTC-USD', 'changes': [['buy', '38370.56', '0.00000000']], 'time': '2021-05-20T03:56:20.963240Z'}
{'type': 'l2update', 'product_id': 'BTC-USD', 'changes': [['sell', '38533.73', '0.01000000']], 'time': '2021-05-20T03:56:20.963586Z'}
{'type': 'l2update', 'product_id': 'BTC-USD', 'changes': [['sell', '38496.98', '0.31367179']], 'time': '2021-05-20T03:56:20.963610Z'}
{'type': 'l2update', 'product_id': 'BTC-USD', 'changes': [['buy', '38256.36', '0.75006534']], 'time': '2021-05-20T03:56:20.963610Z'}
{'type': 'l2update', 'product_id': 'BTC-USD', 'changes': [['buy', '38263.82', '0.40181652']], 'time': '2021-05-20T03:56:20.963610Z'}
{'type': 'l2update', 'product_id': 'BTC-USD', 'changes': [['buy', '38272.16', '0.34398213']], 'time': '2021-05-20T03:56:20.963610Z'}
{'type': 'l2update', 'product_id': 'BTC-USD', 'changes': [['buy', '38282.00', '0.43317308']], 'time': '2021-05-20T03:56:20.963610Z'}
{'type': 'l2update', 'product_id': 'BTC-USD', 'changes': [['sell', '38383.93', '0.00000000']], 'time': '2021-05-20T03:56:20.964656Z'}
{'type': 'l2update', 'product_id': 'BTC-USD', 'changes': [['sell', '38423.72', '0.00000000']], 'time': '2021-05-20T03:56:20.966694Z'}
{'type': 'l2update', 'product_id': 'BTC-USD', 'changes': [['buy', '38332.19', '0.01000000']], 'time': '2021-05-20T03:56:20.970828Z'}
{'type': 'l2update', 'product_id': 'BTC-USD', 'changes': [['sell', '38487.99', '0.58714762']], 'time': '2021-05-20T03:56:20.971106Z'}
{'type': 'l2update', 'product_id': 'BTC-USD', 'changes': [['sell', '38605.67', '0.05819738']], 'time': '2021-05-20T03:56:20.971164Z'}
{'type': 'l2update', 'product_id': 'BTC-USD', 'changes': [['sell', '38407.67', '0.00000000']], 'time': '2021-05-20T03:56:20.971238Z'}
{'type': 'l2update', 'product_id': 'BTC-USD', 'changes': [['buy', '38357.38', '0.26000000']], 'time': '2021-05-20T03:56:20.971944Z'}
{'type': 'l2update', 'product_id': 'BTC-USD', 'changes': [['buy', '38299.45', '0.00000000']], 'time': '2021-05-20T03:56:20.975306Z'}
{'type': 'l2update', 'product_id': 'BTC-USD', 'changes': [['sell', '38399.99', '0.05000000']], 'time': '2021-05-20T03:56:20.975505Z'}
{'type': 'l2update', 'product_id': 'BTC-USD', 'changes': [['buy', '38356.61', '0.20000000']], 'time': '2021-05-20T03:56:20.977850Z'}
{'type': 'l2update', 'product_id': 'BTC-USD', 'changes': [['buy', '38362.94', '0.00000000']], 'time': '2021-05-20T03:56:20.979840Z'}
{'type': 'l2update', 'product_id': 'BTC-USD', 'changes': [['buy', '38299.42', '0.32000000']], 'time': '2021-05-20T03:56:20.980806Z'}
{'type': 'l2update', 'product_id': 'BTC-USD', 'changes': [['buy', '38204.71', '0.80000000']], 'time': '2021-05-20T03:56:20.980806Z'}
{'type': 'l2update', 'product_id': 'BTC-USD', 'changes': [['sell', '38409.84', '0.32000000']], 'time': '2021-05-20T03:56:20.980806Z'}
{'type': 'l2update', 'product_id': 'BTC-USD', 'changes': [['sell', '38504.54', '0.80000000']], 'time': '2021-05-20T03:56:20.980806Z'}
{'type': 'l2update', 'product_id': 'BTC-USD', 'changes': [['sell', '38455.76', '0.00000000']], 'time': '2021-05-20T03:56:20.981067Z'}
{'type': 'l2update', 'product_id': 'BTC-USD', 'changes': [['buy', '38347.10', '0.00000000']], 'time': '2021-05-20T03:56:20.983475Z'}
{'type': 'l2update', 'product_id': 'BTC-USD', 'changes': [['buy', '38362.99', '0.00000000']], 'time': '2021-05-20T03:56:20.984022Z'}
{'type': 'l2update', 'product_id': 'BTC-USD', 'changes': [['sell', '38388.81', '0.00000000']], 'time': '2021-05-20T03:56:20.988642Z'}
{'type': 'l2update', 'product_id': 'BTC-USD', 'changes': [['buy', '38066.82', '0.01000000']], 'time': '2021-05-20T03:56:20.992208Z'}
{'type': 'l2update', 'product_id': 'BTC-USD', 'changes': [['buy', '38370.72', '0.00000000']], 'time': '2021-05-20T03:56:20.994506Z'}
{'type': 'l2update', 'product_id': 'BTC-USD', 'changes': [['buy', '38334.39', '0.00000000']], 'time': '2021-05-20T03:56:20.997182Z'}
{'type': 'l2update', 'product_id': 'BTC-USD', 'changes': [['buy', '38334.41', '0.09049348']], 'time': '2021-05-20T03:56:20.997427Z'}
{'type': 'l2update', 'product_id': 'BTC-USD', 'changes': [['buy', '38325.98', '0.06467780']], 'time': '2021-05-20T03:56:20.998635Z'}
{'type': 'l2update', 'product_id': 'BTC-USD', 'changes': [['sell', '38370.36', '0.04870241']], 'time': '2021-05-20T03:56:20.998635Z'}
{'type': 'l2update', 'product_id': 'BTC-USD', 'changes': [['sell', '38414.70', '0.00000000']], 'time': '2021-05-20T03:56:21.004310Z'}
{'type': 'l2update', 'product_id': 'BTC-USD', 'changes': [['sell', '38474.13', '0.00000000']], 'time': '2021-05-20T03:56:21.004484Z'}
{'type': 'l2update', 'product_id': 'BTC-USD', 'changes': [['buy', '38282.00', '0.59472180']], 'time': '2021-05-20T03:56:21.006006Z'}
{'type': 'l2update', 'product_id': 'BTC-USD', 'changes': [['buy', '38295.36', '0.56392485']], 'time': '2021-05-20T03:56:21.006006Z'}
{'type': 'l2update', 'product_id': 'BTC-USD', 'changes': [['buy', '38303.62', '0.33003093']], 'time': '2021-05-20T03:56:21.006006Z'}
{'type': 'l2update', 'product_id': 'BTC-USD', 'changes': [['buy', '38308.55', '0.16585577']], 'time': '2021-05-20T03:56:21.006006Z'}
{'type': 'l2update', 'product_id': 'BTC-USD', 'changes': [['buy', '38321.76', '0.00000000']], 'time': '2021-05-20T03:56:21.006922Z'}
{'type': 'l2update', 'product_id': 'BTC-USD', 'changes': [['buy', '38356.61', '0.00000000']], 'time': '2021-05-20T03:56:21.007216Z'}
{'type': 'l2update', 'product_id': 'BTC-USD', 'changes': [['sell', '38389.15', '0.00000000']], 'time': '2021-05-20T03:56:21.010429Z'}
{'type': 'l2update', 'product_id': 'BTC-USD', 'changes': [['sell', '38469.17', '0.01299742']], 'time': '2021-05-20T03:56:21.026213Z'}
{'type': 'l2update', 'product_id': 'BTC-USD', 'changes': [['sell', '38398.87', '2.48969908']], 'time': '2021-05-20T03:56:21.026515Z'}
{'type': 'l2update', 'product_id': 'BTC-USD', 'changes': [['sell', '38498.02', '0.03250474']], 'time': '2021-05-20T03:56:21.026648Z'}
{'type': 'l2update', 'product_id': 'BTC-USD', 'changes': [['buy', '38262.76', '0.02834435']], 'time': '2021-05-20T03:56:21.026648Z'}
{'type': 'l2update', 'product_id': 'BTC-USD', 'changes': [['buy', '38324.34', '0.02000000']], 'time': '2021-05-20T03:56:21.026873Z'}
{'type': 'l2update', 'product_id': 'BTC-USD', 'changes': [['sell', '38384.91', '0.02000000']], 'time': '2021-05-20T03:56:21.026873Z'}
{'type': 'l2update', 'product_id': 'BTC-USD', 'changes': [['sell', '38398.87', '2.98969908']], 'time': '2021-05-20T03:56:21.032414Z'}
{'type': 'l2update', 'product_id': 'BTC-USD', 'changes': [['buy', '38332.19', '0.00000000']], 'time': '2021-05-20T03:56:21.034457Z'}
{'type': 'l2update', 'product_id': 'BTC-USD', 'changes': [['buy', '38313.39', '0.00000000']], 'time': '2021-05-20T03:56:21.035633Z'}
{'type': 'l2update', 'product_id': 'BTC-USD', 'changes': [['buy', '38312.58', '0.00000000']], 'time': '2021-05-20T03:56:21.035633Z'}
{'type': 'l2update', 'product_id': 'BTC-USD', 'changes': [['buy', '38357.67', '0.07460000']], 'time': '2021-05-20T03:56:21.037166Z'}
{'type': 'l2update', 'product_id': 'BTC-USD', 'changes': [['sell', '38416.84', '0.02846577']], 'time': '2021-05-20T03:56:21.040242Z'}
{'type': 'l2update', 'product_id': 'BTC-USD', 'changes': [['sell', '38404.02', '0.00000000']], 'time': '2021-05-20T03:56:21.040242Z'}
{'type': 'l2update', 'product_id': 'BTC-USD', 'changes': [['buy', '38204.52', '0.00000000']], 'time': '2021-05-20T03:56:21.040242Z'}
{'type': 'l2update', 'product_id': 'BTC-USD', 'changes': [['buy', '38213.70', '0.00000000']], 'time': '2021-05-20T03:56:21.040242Z'}
{'type': 'l2update', 'product_id': 'BTC-USD', 'changes': [['buy', '38214.23', '0.00000000']], 'time': '2021-05-20T03:56:21.040242Z'}
{'type': 'l2update', 'product_id': 'BTC-USD', 'changes': [['buy', '38247.18', '0.00000000']], 'time': '2021-05-20T03:56:21.040242Z'}
{'type': 'l2update', 'product_id': 'BTC-USD', 'changes': [['buy', '38256.36', '0.31367179']], 'time': '2021-05-20T03:56:21.040242Z'}
{'type': 'l2update', 'product_id': 'BTC-USD', 'changes': [['buy', '38260.61', '0.00000000']], 'time': '2021-05-20T03:56:21.040242Z'}
{'type': 'l2update', 'product_id': 'BTC-USD', 'changes': [['buy', '38262.42', '0.02670923']], 'time': '2021-05-20T03:56:21.040242Z'}
{'type': 'l2update', 'product_id': 'BTC-USD', 'changes': [['buy', '38291.70', '0.00000000']], 'time': '2021-05-20T03:56:21.040396Z'}
{'type': 'l2update', 'product_id': 'BTC-USD', 'changes': [['buy', '38357.06', '0.31570000']], 'time': '2021-05-20T03:56:21.041763Z'}
{'type': 'l2update', 'product_id': 'BTC-USD', 'changes': [['buy', '38363.00', '0.59116555']], 'time': '2021-05-20T03:56:21.044053Z'}
{'type': 'l2update', 'product_id': 'BTC-USD', 'changes': [['sell', '38370.36', '0.00000000']], 'time': '2021-05-20T03:56:21.044327Z'}
{'type': 'l2update', 'product_id': 'BTC-USD', 'changes': [['buy', '38353.41', '0.00000000']], 'time': '2021-05-20T03:56:21.044482Z'}
{'type': 'l2update', 'product_id': 'BTC-USD', 'changes': [['buy', '38313.59', '0.47679550']], 'time': '2021-05-20T03:56:21.051367Z'}
{'type': 'l2update', 'product_id': 'BTC-USD', 'changes': [['sell', '38384.91', '0.00000000']], 'time': '2021-05-20T03:56:21.051386Z'}
{'type': 'l2update', 'product_id': 'BTC-USD', 'changes': [['sell', '38389.09', '0.04844595']], 'time': '2021-05-20T03:56:21.051386Z'}
{'type': 'l2update', 'product_id': 'BTC-USD', 'changes': [['sell', '39499.99', '0.06140000']], 'time': '2021-05-20T03:56:21.052531Z'}
{'type': 'l2update', 'product_id': 'BTC-USD', 'changes': [['buy', '35053.00', '0.00611749']], 'time': '2021-05-20T03:56:21.055391Z'}
{'type': 'l2update', 'product_id': 'BTC-USD', 'changes': [['sell', '38467.89', '0.00000000']], 'time': '2021-05-20T03:56:21.059101Z'}
{'type': 'l2update', 'product_id': 'BTC-USD', 'changes': [['buy', '38370.26', '0.00000000']], 'time': '2021-05-20T03:56:21.059866Z'}
{'type': 'l2update', 'product_id': 'BTC-USD', 'changes': [['sell', '38399.99', '0.00000000']], 'time': '2021-05-20T03:56:21.062926Z'}
{'type': 'l2update', 'product_id': 'BTC-USD', 'changes': [['buy', '38370.26', '0.00260709']], 'time': '2021-05-20T03:56:21.064939Z'}
{'type': 'l2update', 'product_id': 'BTC-USD', 'changes': [['buy', '38327.66', '0.01298051']], 'time': '2021-05-20T03:56:21.065122Z'}
{'type': 'l2update', 'product_id': 'BTC-USD', 'changes': [['sell', '39499.99', '0.11110000']], 'time': '2021-05-20T03:56:21.065851Z'}
{'type': 'l2update', 'product_id': 'BTC-USD', 'changes': [['sell', '38469.39', '0.01404236']], 'time': '2021-05-20T03:56:21.065961Z'}
{'type': 'l2update', 'product_id': 'BTC-USD', 'changes': [['buy', '38203.15', '0.00000000']], 'time': '2021-05-20T03:56:21.068490Z'}
{'type': 'l2update', 'product_id': 'BTC-USD', 'changes': [['buy', '38314.19', '0.00000000']], 'time': '2021-05-20T03:56:21.069538Z'}
{'type': 'l2update', 'product_id': 'BTC-USD', 'changes': [['buy', '38357.43', '1.23300000']], 'time': '2021-05-20T03:56:21.069555Z'}
{'type': 'l2update', 'product_id': 'BTC-USD', 'changes': [['sell', '38605.67', '0.00000000']], 'time': '2021-05-20T03:56:21.073013Z'}
{'type': 'l2update', 'product_id': 'BTC-USD', 'changes': [['sell', '38486.76', '0.01000000']], 'time': '2021-05-20T03:56:21.075990Z'}
{'type': 'l2update', 'product_id': 'BTC-USD', 'changes': [['buy', '38357.62', '0.01492000']], 'time': '2021-05-20T03:56:21.077711Z'}
{'type': 'l2update', 'product_id': 'BTC-USD', 'changes': [['buy', '38357.67', '0.00000000']], 'time': '2021-05-20T03:56:21.078190Z'}
{'type': 'l2update', 'product_id': 'BTC-USD', 'changes': [['buy', '38370.26', '0.10260709']], 'time': '2021-05-20T03:56:21.081627Z'}
{'type': 'l2update', 'product_id': 'BTC-USD', 'changes': [['buy', '38349.61', '2.37600000']], 'time': '2021-05-20T03:56:21.087632Z'}
{'type': 'l2update', 'product_id': 'BTC-USD', 'changes': [['buy', '38384.90', '0.02890000']], 'time': '2021-05-20T03:56:21.087662Z'}
{'type': 'l2update', 'product_id': 'BTC-USD', 'changes': [['buy', '38262.76', '0.06380583']], 'time': '2021-05-20T03:56:21.087775Z'}
{'type': 'l2update', 'product_id': 'BTC-USD', 'changes': [['sell', '38526.34', '0.43658099']], 'time': '2021-05-20T03:56:21.089432Z'}
{'type': 'l2update', 'product_id': 'BTC-USD', 'changes': [['sell', '38412.50', '0.00000000']], 'time': '2021-05-20T03:56:21.091964Z'}
{'type': 'l2update', 'product_id': 'BTC-USD', 'changes': [['buy', '38045.00', '0.00000000']], 'time': '2021-05-20T03:56:21.092180Z'}
{'type': 'l2update', 'product_id': 'BTC-USD', 'changes': [['buy', '37548.82', '0.00000000']], 'time': '2021-05-20T03:56:21.092646Z'}
{'type': 'l2update', 'product_id': 'BTC-USD', 'changes': [['buy', '38329.13', '0.51400000']], 'time': '2021-05-20T03:56:21.097515Z'}
{'type': 'l2update', 'product_id': 'BTC-USD', 'changes': [['sell', '38398.86', '0.05000000']], 'time': '2021-05-20T03:56:21.101745Z'}
{'type': 'l2update', 'product_id': 'BTC-USD', 'changes': [['buy', '38383.92', '0.00573000']], 'time': '2021-05-20T03:56:21.101924Z'}
{'type': 'l2update', 'product_id': 'BTC-USD', 'changes': [['sell', '38407.31', '0.00000000']], 'time': '2021-05-20T03:56:21.104322Z'}
{'type': 'l2update', 'product_id': 'BTC-USD', 'changes': [['buy', '38254.93', '0.00000000']], 'time': '2021-05-20T03:56:21.110140Z'}
{'type': 'l2update', 'product_id': 'BTC-USD', 'changes': [['sell', '38533.73', '0.00000000']], 'time': '2021-05-20T03:56:21.110258Z'}
{'type': 'l2update', 'product_id': 'BTC-USD', 'changes': [['sell', '38398.88', '0.00000000']], 'time': '2021-05-20T03:56:21.110321Z'}
{'type': 'l2update', 'product_id': 'BTC-USD', 'changes': [['buy', '38357.62', '0.00000000']], 'time': '2021-05-20T03:56:21.111690Z'}
{'type': 'l2update', 'product_id': 'BTC-USD', 'changes': [['buy', '38357.06', '0.21570000']], 'time': '2021-05-20T03:56:21.114352Z'}
{'type': 'l2update', 'product_id': 'BTC-USD', 'changes': [['buy', '38177.68', '0.00000000']], 'time': '2021-05-20T03:56:21.116179Z'}
{'type': 'l2update', 'product_id': 'BTC-USD', 'changes': [['sell', '38402.55', '0.00000000']], 'time': '2021-05-20T03:56:21.120675Z'}
{'type': 'l2update', 'product_id': 'BTC-USD', 'changes': [['sell', '38427.30', '0.00000000']], 'time': '2021-05-20T03:56:21.121880Z'}
{'type': 'l2update', 'product_id': 'BTC-USD', 'changes': [['sell', '38421.97', '0.30055436']], 'time': '2021-05-20T03:56:21.121880Z'}
{'type': 'l2update', 'product_id': 'BTC-USD', 'changes': [['sell', '38416.84', '0.00000000']], 'time': '2021-05-20T03:56:21.121880Z'}
{'type': 'l2update', 'product_id': 'BTC-USD', 'changes': [['sell', '38412.25', '0.00000000']], 'time': '2021-05-20T03:56:21.121880Z'}
{'type': 'l2update', 'product_id': 'BTC-USD', 'changes': [['buy', '38219.75', '0.00000000']], 'time': '2021-05-20T03:56:21.121880Z'}
{'type': 'l2update', 'product_id': 'BTC-USD', 'changes': [['buy', '38225.75', '0.00000000']], 'time': '2021-05-20T03:56:21.121880Z'}
{'type': 'l2update', 'product_id': 'BTC-USD', 'changes': [['buy', '38341.53', '0.02390000']], 'time': '2021-05-20T03:56:21.123404Z'}
{'type': 'l2update', 'product_id': 'BTC-USD', 'changes': [['buy', '38340.72', '0.02390000']], 'time': '2021-05-20T03:56:21.123404Z'}
{'type': 'l2update', 'product_id': 'BTC-USD', 'changes': [['buy', '38339.92', '0.02390000']], 'time': '2021-05-20T03:56:21.123404Z'}
{'type': 'l2update', 'product_id': 'BTC-USD', 'changes': [['buy', '38356.62', '0.00000000']], 'time': '2021-05-20T03:56:21.124904Z'}
{'type': 'l2update', 'product_id': 'BTC-USD', 'changes': [['sell', '38421.97', '0.00000000']], 'time': '2021-05-20T03:56:21.125808Z'}
{'type': 'l2update', 'product_id': 'BTC-USD', 'changes': [['buy', '38363.00', '0.00000000']], 'time': '2021-05-20T03:56:21.127630Z'}
{'type': 'l2update', 'product_id': 'BTC-USD', 'changes': [['buy', '38370.69', '0.07460000']], 'time': '2021-05-20T03:56:21.128089Z'}
{'type': 'l2update', 'product_id': 'BTC-USD', 'changes': [['sell', '38484.81', '0.02400000']], 'time': '2021-05-20T03:56:21.128194Z'}
{'type': 'l2update', 'product_id': 'BTC-USD', 'changes': [['buy', '38313.59', '0.00000000']], 'time': '2021-05-20T03:56:21.128796Z'}
{'type': 'l2update', 'product_id': 'BTC-USD', 'changes': [['sell', '38431.60', '0.00000000']], 'time': '2021-05-20T03:56:21.130510Z'}
{'type': 'l2update', 'product_id': 'BTC-USD', 'changes': [['buy', '38288.04', '1.72250000']], 'time': '2021-05-20T03:56:21.134686Z'}
{'type': 'l2update', 'product_id': 'BTC-USD', 'changes': [['sell', '38398.86', '0.00000000']], 'time': '2021-05-20T03:56:21.136434Z'}
{'type': 'l2update', 'product_id': 'BTC-USD', 'changes': [['buy', '34000.00', '80.51833099']], 'time': '2021-05-20T03:56:21.142779Z'}
{'type': 'l2update', 'product_id': 'BTC-USD', 'changes': [['sell', '38493.91', '0.12989070']], 'time': '2021-05-20T03:56:21.143189Z'}
{'type': 'l2update', 'product_id': 'BTC-USD', 'changes': [['buy', '37992.87', '0.00000000']], 'time': '2021-05-20T03:56:21.145339Z'}
{'type': 'l2update', 'product_id': 'BTC-USD', 'changes': [['buy', '38388.80', '0.00573000']], 'time': '2021-05-20T03:56:21.151305Z'}
{'type': 'l2update', 'product_id': 'BTC-USD', 'changes': [['sell', '38463.27', '0.69214782']], 'time': '2021-05-20T03:56:21.155651Z'}
{'type': 'l2update', 'product_id': 'BTC-USD', 'changes': [['sell', '38456.80', '0.37549286']], 'time': '2021-05-20T03:56:21.155651Z'}
{'type': 'l2update', 'product_id': 'BTC-USD', 'changes': [['sell', '38450.52', '0.00000000']], 'time': '2021-05-20T03:56:21.155651Z'}
{'type': 'l2update', 'product_id': 'BTC-USD', 'changes': [['sell', '38438.53', '0.00000000']], 'time': '2021-05-20T03:56:21.155651Z'}
{'type': 'l2update', 'product_id': 'BTC-USD', 'changes': [['sell', '38432.82', '0.36744906']], 'time': '2021-05-20T03:56:21.155651Z'}
{'type': 'l2update', 'product_id': 'BTC-USD', 'changes': [['buy', '38243.67', '0.00000000']], 'time': '2021-05-20T03:56:21.155651Z'}
{'type': 'l2update', 'product_id': 'BTC-USD', 'changes': [['buy', '38268.29', '0.00000000']], 'time': '2021-05-20T03:56:21.155651Z'}
{'type': 'l2update', 'product_id': 'BTC-USD', 'changes': [['buy', '38279.47', '0.00000000']], 'time': '2021-05-20T03:56:21.155651Z'}
{'type': 'l2update', 'product_id': 'BTC-USD', 'changes': [['buy', '38288.09', '0.00000000']], 'time': '2021-05-20T03:56:21.155651Z'}
{'type': 'l2update', 'product_id': 'BTC-USD', 'changes': [['buy', '38304.12', '0.01116540']], 'time': '2021-05-20T03:56:21.155651Z'}
{'type': 'l2update', 'product_id': 'BTC-USD', 'changes': [['sell', '38435.32', '0.00000000']], 'time': '2021-05-20T03:56:21.156972Z'}
{'type': 'l2update', 'product_id': 'BTC-USD', 'changes': [['sell', '38588.07', '0.01392576']], 'time': '2021-05-20T03:56:21.158659Z'}
{'type': 'l2update', 'product_id': 'BTC-USD', 'changes': [['buy', '38224.56', '0.02616118']], 'time': '2021-05-20T03:56:21.158916Z'}
{'type': 'l2update', 'product_id': 'BTC-USD', 'changes': [['sell', '38547.48', '0.01000000']], 'time': '2021-05-20T03:56:21.159297Z'}
{'type': 'l2update', 'product_id': 'BTC-USD', 'changes': [['buy', '38339.92', '0.00000000']], 'time': '2021-05-20T03:56:21.160594Z'}
{'type': 'l2update', 'product_id': 'BTC-USD', 'changes': [['buy', '38357.05', '0.10000000']], 'time': '2021-05-20T03:56:21.162279Z'}
{'type': 'l2update', 'product_id': 'BTC-USD', 'changes': [['buy', '38370.69', '0.00000000']], 'time': '2021-05-20T03:56:21.165110Z'}
{'type': 'l2update', 'product_id': 'BTC-USD', 'changes': [['buy', '38389.08', '0.01492000']], 'time': '2021-05-20T03:56:21.171853Z'}
{'type': 'l2update', 'product_id': 'BTC-USD', 'changes': [['sell', '38534.16', '0.30838260']], 'time': '2021-05-20T03:56:21.172469Z'}
{'type': 'l2update', 'product_id': 'BTC-USD', 'changes': [['buy', '38384.90', '0.00000000']], 'time': '2021-05-20T03:56:21.175193Z'}
{'type': 'l2update', 'product_id': 'BTC-USD', 'changes': [['sell', '38409.83', '0.05000000']], 'time': '2021-05-20T03:56:21.182990Z'}
{'type': 'l2update', 'product_id': 'BTC-USD', 'changes': [['buy', '38357.44', '0.59116555']], 'time': '2021-05-20T03:56:21.184587Z'}
{'type': 'l2update', 'product_id': 'BTC-USD', 'changes': [['buy', '38234.32', '0.28541821']], 'time': '2021-05-20T03:56:21.185293Z'}
{'type': 'l2update', 'product_id': 'BTC-USD', 'changes': [['sell', '38483.20', '0.34954182']], 'time': '2021-05-20T03:56:21.189939Z'}
{'type': 'l2update', 'product_id': 'BTC-USD', 'changes': [['sell', '38469.67', '0.00000000']], 'time': '2021-05-20T03:56:21.189939Z'}
{'type': 'l2update', 'product_id': 'BTC-USD', 'changes': [['buy', '38304.12', '0.00000000']], 'time': '2021-05-20T03:56:21.189939Z'}
{'type': 'l2update', 'product_id': 'BTC-USD', 'changes': [['buy', '38312.65', '0.00000000']], 'time': '2021-05-20T03:56:21.189939Z'}
{'type': 'l2update', 'product_id': 'BTC-USD', 'changes': [['buy', '38316.63', '0.00000000']], 'time': '2021-05-20T03:56:21.189939Z'}
{'type': 'l2update', 'product_id': 'BTC-USD', 'changes': [['buy', '38357.05', '0.00000000']], 'time': '2021-05-20T03:56:21.194739Z'}
{'type': 'l2update', 'product_id': 'BTC-USD', 'changes': [['buy', '38370.35', '0.00573000']], 'time': '2021-05-20T03:56:21.195888Z'}
{'type': 'l2update', 'product_id': 'BTC-USD', 'changes': [['sell', '38425.09', '0.01000000']], 'time': '2021-05-20T03:56:21.195996Z'}
{'type': 'l2update', 'product_id': 'BTC-USD', 'changes': [['buy', '38341.53', '0.00000000']], 'time': '2021-05-20T03:56:21.197787Z'}
{'type': 'l2update', 'product_id': 'BTC-USD', 'changes': [['buy', '38340.72', '0.00000000']], 'time': '2021-05-20T03:56:21.197787Z'}
{'type': 'l2update', 'product_id': 'BTC-USD', 'changes': [['buy', '38351.29', '0.00000000']], 'time': '2021-05-20T03:56:21.197800Z'}
{'type': 'l2update', 'product_id': 'BTC-USD', 'changes': [['buy', '38263.22', '0.00000000']], 'time': '2021-05-20T03:56:21.197910Z'}
{'type': 'l2update', 'product_id': 'BTC-USD', 'changes': [['sell', '38402.62', '0.00000000']], 'time': '2021-05-20T03:56:21.200280Z'}
{'type': 'l2update', 'product_id': 'BTC-USD', 'changes': [['sell', '38416.90', '0.01301510']], 'time': '2021-05-20T03:56:21.200848Z'}
{'type': 'l2update', 'product_id': 'BTC-USD', 'changes': [['buy', '38271.13', '0.01000000']], 'time': '2021-05-20T03:56:21.201393Z'}
{'type': 'l2update', 'product_id': 'BTC-USD', 'changes': [['sell', '38444.43', '0.12249312']], 'time': '2021-05-20T03:56:21.209720Z'}
{'type': 'l2update', 'product_id': 'BTC-USD', 'changes': [['sell', '38432.82', '0.00000000']], 'time': '2021-05-20T03:56:21.209720Z'}
{'type': 'l2update', 'product_id': 'BTC-USD', 'changes': [['sell', '38389.09', '0.00000000']], 'time': '2021-05-20T03:56:21.212181Z'}
{'type': 'l2update', 'product_id': 'BTC-USD', 'changes': [['buy', '38299.42', '0.00000000']], 'time': '2021-05-20T03:56:21.214395Z'}
{'type': 'l2update', 'product_id': 'BTC-USD', 'changes': [['sell', '38402.57', '1.02900000']], 'time': '2021-05-20T03:56:21.215385Z'}
{'type': 'l2update', 'product_id': 'BTC-USD', 'changes': [['sell', '43100.00', '1.09530000']], 'time': '2021-05-20T03:56:21.215486Z'}
{'type': 'l2update', 'product_id': 'BTC-USD', 'changes': [['sell', '38409.83', '0.00000000']], 'time': '2021-05-20T03:56:21.216347Z'}
{'type': 'l2update', 'product_id': 'BTC-USD', 'changes': [['buy', '38269.77', '0.07700000']], 'time': '2021-05-20T03:56:21.220417Z'}
{'type': 'l2update', 'product_id': 'BTC-USD', 'changes': [['buy', '38057.88', '0.03981949']], 'time': '2021-05-20T03:56:21.220563Z'}
{'type': 'l2update', 'product_id': 'BTC-USD', 'changes': [['buy', '38263.33', '0.00000000']], 'time': '2021-05-20T03:56:21.222596Z'}
{'type': 'l2update', 'product_id': 'BTC-USD', 'changes': [['buy', '38262.42', '0.00000000']], 'time': '2021-05-20T03:56:21.222875Z'}
{'type': 'l2update', 'product_id': 'BTC-USD', 'changes': [['sell', '38432.81', '0.49333810']], 'time': '2021-05-20T03:56:21.225928Z'}
{'type': 'l2update', 'product_id': 'BTC-USD', 'changes': [['buy', '38351.31', '0.45852609']], 'time': '2021-05-20T03:56:21.226195Z'}
{'type': 'l2update', 'product_id': 'BTC-USD', 'changes': [['buy', '38357.06', '0.11730000']], 'time': '2021-05-20T03:56:21.226839Z'}
{'type': 'l2update', 'product_id': 'BTC-USD', 'changes': [['buy', '38389.08', '0.00000000']], 'time': '2021-05-20T03:56:21.229038Z'}
{'type': 'l2update', 'product_id': 'BTC-USD', 'changes': [['buy', '38194.99', '0.09933675']], 'time': '2021-05-20T03:56:21.231352Z'}
{'type': 'l2update', 'product_id': 'BTC-USD', 'changes': [['sell', '38433.33', '0.00000000']], 'time': '2021-05-20T03:56:21.233342Z'}
{'type': 'l2update', 'product_id': 'BTC-USD', 'changes': [['buy', '38263.11', '0.00000000']], 'time': '2021-05-20T03:56:21.233982Z'}
{'type': 'l2update', 'product_id': 'BTC-USD', 'changes': [['buy', '38384.90', '0.00573000']], 'time': '2021-05-20T03:56:21.236761Z'}
{'type': 'l2update', 'product_id': 'BTC-USD', 'changes': [['buy', '38342.57', '0.01000000']], 'time': '2021-05-20T03:56:21.237067Z'}
{'type': 'l2update', 'product_id': 'BTC-USD', 'changes': [['buy', '38384.48', '0.16800000']], 'time': '2021-05-20T03:56:21.237347Z'}
{'type': 'l2update', 'product_id': 'BTC-USD', 'changes': [['sell', '38438.43', '0.00000000']], 'time': '2021-05-20T03:56:21.237656Z'}
{'type': 'l2update', 'product_id': 'BTC-USD', 'changes': [['buy', '38290.75', '0.00000000']], 'time': '2021-05-20T03:56:21.237759Z'}
{'type': 'l2update', 'product_id': 'BTC-USD', 'changes': [['sell', '38421.79', '0.06173969']], 'time': '2021-05-20T03:56:21.238354Z'}
{'type': 'l2update', 'product_id': 'BTC-USD', 'changes': [['sell', '38398.86', '1.46791646']], 'time': '2021-05-20T03:56:21.238549Z'}
{'type': 'l2update', 'product_id': 'BTC-USD', 'changes': [['buy', '38325.98', '0.00000000']], 'time': '2021-05-20T03:56:21.242435Z'}
{'type': 'l2update', 'product_id': 'BTC-USD', 'changes': [['buy', '38202.34', '0.00000000']], 'time': '2021-05-20T03:56:21.242444Z'}
{'type': 'l2update', 'product_id': 'BTC-USD', 'changes': [['sell', '38436.35', '0.61482417']], 'time': '2021-05-20T03:56:21.246705Z'}
{'type': 'l2update', 'product_id': 'BTC-USD', 'changes': [['buy', '38204.71', '0.00000000']], 'time': '2021-05-20T03:56:21.247543Z'}
{'type': 'l2update', 'product_id': 'BTC-USD', 'changes': [['sell', '38504.54', '0.00000000']], 'time': '2021-05-20T03:56:21.247543Z'}
{'type': 'l2update', 'product_id': 'BTC-USD', 'changes': [['sell', '38409.84', '0.00000000']], 'time': '2021-05-20T03:56:21.247543Z'}
{'type': 'l2update', 'product_id': 'BTC-USD', 'changes': [['buy', '38384.48', '0.00000000']], 'time': '2021-05-20T03:56:21.250694Z'}
{'type': 'l2update', 'product_id': 'BTC-USD', 'changes': [['sell', '38542.63', '0.41751524']], 'time': '2021-05-20T03:56:21.252072Z'}
{'type': 'l2update', 'product_id': 'BTC-USD', 'changes': [['buy', '38349.61', '0.00000000']], 'time': '2021-05-20T03:56:21.252455Z'}
{'type': 'l2update', 'product_id': 'BTC-USD', 'changes': [['sell', '38398.36', '0.01492000']], 'time': '2021-05-20T03:56:21.256590Z'}
{'type': 'l2update', 'product_id': 'BTC-USD', 'changes': [['buy', '38285.61', '0.00000000']], 'time': '2021-05-20T03:56:21.256808Z'}
{'type': 'l2update', 'product_id': 'BTC-USD', 'changes': [['buy', '38389.50', '0.04595331']], 'time': '2021-05-20T03:56:21.257008Z'}
{'type': 'l2update', 'product_id': 'BTC-USD', 'changes': [['sell', '38421.79', '0.11173969']], 'time': '2021-05-20T03:56:21.257546Z'}
{'type': 'l2update', 'product_id': 'BTC-USD', 'changes': [['sell', '43100.00', '1.12170000']], 'time': '2021-05-20T03:56:21.263147Z'}
{'type': 'l2update', 'product_id': 'BTC-USD', 'changes': [['buy', '38389.50', '0.06099122']], 'time': '2021-05-20T03:56:21.266602Z'}
{'type': 'l2update', 'product_id': 'BTC-USD', 'changes': [['buy', '38365.97', '0.00000000']], 'time': '2021-05-20T03:56:21.267074Z'}
{'type': 'l2update', 'product_id': 'BTC-USD', 'changes': [['sell', '38534.62', '0.03328605']], 'time': '2021-05-20T03:56:21.269465Z'}
{'type': 'l2update', 'product_id': 'BTC-USD', 'changes': [['buy', '38261.69', '0.00000000']], 'time': '2021-05-20T03:56:21.270209Z'}
{'type': 'l2update', 'product_id': 'BTC-USD', 'changes': [['buy', '38294.38', '0.00000000']], 'time': '2021-05-20T03:56:21.272601Z'}
{'type': 'l2update', 'product_id': 'BTC-USD', 'changes': [['sell', '38588.07', '0.00000000']], 'time': '2021-05-20T03:56:21.273129Z'}
{'type': 'l2update', 'product_id': 'BTC-USD', 'changes': [['sell', '38425.09', '0.00000000']], 'time': '2021-05-20T03:56:21.273162Z'}
{'type': 'l2update', 'product_id': 'BTC-USD', 'changes': [['sell', '38444.43', '0.00000000']], 'time': '2021-05-20T03:56:21.275131Z'}
{'type': 'l2update', 'product_id': 'BTC-USD', 'changes': [['buy', '38351.30', '0.00000000']], 'time': '2021-05-20T03:56:21.277127Z'}
{'type': 'l2update', 'product_id': 'BTC-USD', 'changes': [['buy', '38389.08', '0.00573000']], 'time': '2021-05-20T03:56:21.277858Z'}
{'type': 'l2update', 'product_id': 'BTC-USD', 'changes': [['buy', '38384.24', '0.01360878']], 'time': '2021-05-20T03:56:21.278362Z'}
{'type': 'l2update', 'product_id': 'BTC-USD', 'changes': [['sell', '38502.50', '0.00000000']], 'time': '2021-05-20T03:56:21.282075Z'}
{'type': 'l2update', 'product_id': 'BTC-USD', 'changes': [['sell', '38469.39', '0.00000000']], 'time': '2021-05-20T03:56:21.282178Z'}
{'type': 'l2update', 'product_id': 'BTC-USD', 'changes': [['buy', '38118.25', '0.00000000']], 'time': '2021-05-20T03:56:21.282264Z'}
{'type': 'l2update', 'product_id': 'BTC-USD', 'changes': [['buy', '38356.53', '0.04183279']], 'time': '2021-05-20T03:56:21.282755Z'}
{'type': 'l2update', 'product_id': 'BTC-USD', 'changes': [['buy', '38370.95', '0.01492000']], 'time': '2021-05-20T03:56:21.282905Z'}
{'type': 'l2update', 'product_id': 'BTC-USD', 'changes': [['buy', '38324.34', '0.00000000']], 'time': '2021-05-20T03:56:21.284504Z'}
{'type': 'l2update', 'product_id': 'BTC-USD', 'changes': [['sell', '38484.81', '0.00000000']], 'time': '2021-05-20T03:56:21.287848Z'}
{'type': 'l2update', 'product_id': 'BTC-USD', 'changes': [['buy', '38356.53', '0.03753279']], 'time': '2021-05-20T03:56:21.288356Z'}
{'type': 'l2update', 'product_id': 'BTC-USD', 'changes': [['sell', '38407.20', '0.73950000']], 'time': '2021-05-20T03:56:21.288859Z'}
{'type': 'l2update', 'product_id': 'BTC-USD', 'changes': [['buy', '38368.54', '0.02390000']], 'time': '2021-05-20T03:56:21.289104Z'}
{'type': 'l2update', 'product_id': 'BTC-USD', 'changes': [['buy', '38367.74', '0.02390000']], 'time': '2021-05-20T03:56:21.289104Z'}
{'type': 'l2update', 'product_id': 'BTC-USD', 'changes': [['buy', '38366.93', '0.02390000']], 'time': '2021-05-20T03:56:21.289104Z'}
{'type': 'l2update', 'product_id': 'BTC-USD', 'changes': [['sell', '38499.01', '0.00000000']], 'time': '2021-05-20T03:56:21.289154Z'}
{'type': 'l2update', 'product_id': 'BTC-USD', 'changes': [['sell', '38463.27', '0.38624923']], 'time': '2021-05-20T03:56:21.289281Z'}
{'type': 'l2update', 'product_id': 'BTC-USD', 'changes': [['buy', '38389.50', '0.01503791']], 'time': '2021-05-20T03:56:21.293499Z'}
{'type': 'l2update', 'product_id': 'BTC-USD', 'changes': [['buy', '38356.53', '0.03183279']], 'time': '2021-05-20T03:56:21.293666Z'}
{'type': 'l2update', 'product_id': 'BTC-USD', 'changes': [['buy', '38315.47', '1.28010652']], 'time': '2021-05-20T03:56:21.295503Z'}
{'type': 'l2update', 'product_id': 'BTC-USD', 'changes': [['sell', '38493.91', '0.00000000']], 'time': '2021-05-20T03:56:21.300979Z'}
{'type': 'l2update', 'product_id': 'BTC-USD', 'changes': [['buy', '38347.05', '0.06173969']], 'time': '2021-05-20T03:56:21.303996Z'}
{'type': 'l2update', 'product_id': 'BTC-USD', 'changes': [['sell', '38398.20', '0.07460000']], 'time': '2021-05-20T03:56:21.304325Z'}
{'type': 'l2update', 'product_id': 'BTC-USD', 'changes': [['buy', '38261.31', '0.05000000']], 'time': '2021-05-20T03:56:21.306119Z'}
{'type': 'l2update', 'product_id': 'BTC-USD', 'changes': [['buy', '38342.57', '0.00000000']], 'time': '2021-05-20T03:56:21.307887Z'}
{'type': 'l2update', 'product_id': 'BTC-USD', 'changes': [['sell', '38486.76', '0.00000000']], 'time': '2021-05-20T03:56:21.309215Z'}
{'type': 'l2update', 'product_id': 'BTC-USD', 'changes': [['sell', '38395.24', '0.15000000']], 'time': '2021-05-20T03:56:21.309739Z'}
{'type': 'l2update', 'product_id': 'BTC-USD', 'changes': [['buy', '38389.50', '0.00000000']], 'time': '2021-05-20T03:56:21.312369Z'}
{'type': 'l2update', 'product_id': 'BTC-USD', 'changes': [['buy', '38383.92', '0.00000000']], 'time': '2021-05-20T03:56:21.312575Z'}
{'type': 'l2update', 'product_id': 'BTC-USD', 'changes': [['buy', '38370.95', '0.00000000']], 'time': '2021-05-20T03:56:21.318600Z'}
{'type': 'l2update', 'product_id': 'BTC-USD', 'changes': [['sell', '39170.60', '0.00000000']], 'time': '2021-05-20T03:56:21.320303Z'}
{'type': 'l2update', 'product_id': 'BTC-USD', 'changes': [['sell', '38533.62', '0.01000000']], 'time': '2021-05-20T03:56:21.323435Z'}
{'type': 'l2update', 'product_id': 'BTC-USD', 'changes': [['buy', '38357.43', '0.00000000']], 'time': '2021-05-20T03:56:21.325367Z'}
{'type': 'l2update', 'product_id': 'BTC-USD', 'changes': [['buy', '38368.54', '0.00000000']], 'time': '2021-05-20T03:56:21.326176Z'}
{'type': 'l2update', 'product_id': 'BTC-USD', 'changes': [['buy', '38367.74', '0.00000000']], 'time': '2021-05-20T03:56:21.326176Z'}
{'type': 'l2update', 'product_id': 'BTC-USD', 'changes': [['buy', '38317.12', '0.01304899']], 'time': '2021-05-20T03:56:21.329220Z'}
{'type': 'l2update', 'product_id': 'BTC-USD', 'changes': [['sell', '38412.34', '0.02000000']], 'time': '2021-05-20T03:56:21.329446Z'}
{'type': 'l2update', 'product_id': 'BTC-USD', 'changes': [['buy', '38370.37', '0.00601059']], 'time': '2021-05-20T03:56:21.331397Z'}
{'type': 'l2update', 'product_id': 'BTC-USD', 'changes': [['buy', '38371.55', '0.01310169']], 'time': '2021-05-20T03:56:21.331397Z'}
{'type': 'l2update', 'product_id': 'BTC-USD', 'changes': [['buy', '38373.91', '0.01969051']], 'time': '2021-05-20T03:56:21.331397Z'}
{'type': 'l2update', 'product_id': 'BTC-USD', 'changes': [['buy', '38377.45', '0.01966604']], 'time': '2021-05-20T03:56:21.331397Z'}
{'type': 'l2update', 'product_id': 'BTC-USD', 'changes': [['sell', '38529.09', '0.01297720']], 'time': '2021-05-20T03:56:21.331470Z'}
{'type': 'l2update', 'product_id': 'BTC-USD', 'changes': [['buy', '38371.00', '0.84500000']], 'time': '2021-05-20T03:56:21.337546Z'}
{'type': 'l2update', 'product_id': 'BTC-USD', 'changes': [['sell', '38550.83', '0.40431494']], 'time': '2021-05-20T03:56:21.337603Z'}
{'type': 'l2update', 'product_id': 'BTC-USD', 'changes': [['buy', '38384.24', '0.00000000']], 'time': '2021-05-20T03:56:21.338488Z'}
{'type': 'l2update', 'product_id': 'BTC-USD', 'changes': [['sell', '38398.36', '0.00000000']], 'time': '2021-05-20T03:56:21.339035Z'}
{'type': 'l2update', 'product_id': 'BTC-USD', 'changes': [['buy', '38261.31', '0.00000000']], 'time': '2021-05-20T03:56:21.340064Z'}
{'type': 'l2update', 'product_id': 'BTC-USD', 'changes': [['sell', '38403.22', '0.00600000']], 'time': '2021-05-20T03:56:21.340915Z'}
{'type': 'l2update', 'product_id': 'BTC-USD', 'changes': [['sell', '38398.20', '0.00000000']], 'time': '2021-05-20T03:56:21.343889Z'}
{'type': 'l2update', 'product_id': 'BTC-USD', 'changes': [['buy', '38388.80', '0.00000000']], 'time': '2021-05-20T03:56:21.345280Z'}
{'type': 'l2update', 'product_id': 'BTC-USD', 'changes': [['sell', '38547.48', '0.00000000']], 'time': '2021-05-20T03:56:21.346874Z'}
{'type': 'l2update', 'product_id': 'BTC-USD', 'changes': [['sell', '38542.39', '0.10551729']], 'time': '2021-05-20T03:56:21.349603Z'}
{'type': 'l2update', 'product_id': 'BTC-USD', 'changes': [['buy', '38370.35', '0.10573000']], 'time': '2021-05-20T03:56:21.354431Z'}
{'type': 'l2update', 'product_id': 'BTC-USD', 'changes': [['sell', '38473.60', '0.12995925']], 'time': '2021-05-20T03:56:21.354855Z'}
{'type': 'l2update', 'product_id': 'BTC-USD', 'changes': [['buy', '38384.53', '0.01492000']], 'time': '2021-05-20T03:56:21.360617Z'}
{'type': 'l2update', 'product_id': 'BTC-USD', 'changes': [['buy', '38366.93', '0.00000000']], 'time': '2021-05-20T03:56:21.361846Z'}
{'type': 'l2update', 'product_id': 'BTC-USD', 'changes': [['sell', '38389.51', '1.43670746']], 'time': '2021-05-20T03:56:21.362991Z'}
{'type': 'l2update', 'product_id': 'BTC-USD', 'changes': [['buy', '38368.55', '1.46756192']], 'time': '2021-05-20T03:56:21.363320Z'}
{'type': 'l2update', 'product_id': 'BTC-USD', 'changes': [['sell', '38425.98', '0.39490432']], 'time': '2021-05-20T03:56:21.366914Z'}
{'type': 'l2update', 'product_id': 'BTC-USD', 'changes': [['buy', '38262.76', '0.03546148']], 'time': '2021-05-20T03:56:21.370081Z'}
{'type': 'l2update', 'product_id': 'BTC-USD', 'changes': [['buy', '38371.00', '0.00000000']], 'time': '2021-05-20T03:56:21.376090Z'}
{'type': 'l2update', 'product_id': 'BTC-USD', 'changes': [['sell', '38469.93', '0.00000000']], 'time': '2021-05-20T03:56:21.376297Z'}
{'type': 'l2update', 'product_id': 'BTC-USD', 'changes': [['buy', '38357.44', '0.00000000']], 'time': '2021-05-20T03:56:21.376396Z'}
{'type': 'l2update', 'product_id': 'BTC-USD', 'changes': [['sell', '38488.75', '0.00000000']], 'time': '2021-05-20T03:56:21.379023Z'}
{'type': 'l2update', 'product_id': 'BTC-USD', 'changes': [['sell', '38480.90', '0.04730880']], 'time': '2021-05-20T03:56:21.379130Z'}
{'type': 'l2update', 'product_id': 'BTC-USD', 'changes': [['buy', '38370.35', '0.10000000']], 'time': '2021-05-20T03:56:21.381468Z'}
{'type': 'l2update', 'product_id': 'BTC-USD', 'changes': [['sell', '38412.49', '0.06173969']], 'time': '2021-05-20T03:56:21.388229Z'}
{'type': 'l2update', 'product_id': 'BTC-USD', 'changes': [['sell', '38418.44', '0.06600000']], 'time': '2021-05-20T03:56:21.388317Z'}
{'type': 'l2update', 'product_id': 'BTC-USD', 'changes': [['buy', '38194.99', '0.00000000']], 'time': '2021-05-20T03:56:21.390793Z'}
{'type': 'l2update', 'product_id': 'BTC-USD', 'changes': [['sell', '38398.87', '2.48969908']], 'time': '2021-05-20T03:56:21.391130Z'}
{'type': 'l2update', 'product_id': 'BTC-USD', 'changes': [['buy', '38384.53', '0.00000000']], 'time': '2021-05-20T03:56:21.394559Z'}
{'type': 'l2update', 'product_id': 'BTC-USD', 'changes': [['sell', '38585.12', '0.01000000']], 'time': '2021-05-20T03:56:21.395030Z'}
{'type': 'l2update', 'product_id': 'BTC-USD', 'changes': [['sell', '38389.09', '0.02038714']], 'time': '2021-05-20T03:56:21.403630Z'}
{'type': 'l2update', 'product_id': 'BTC-USD', 'changes': [['buy', '38370.26', '0.30260709']], 'time': '2021-05-20T03:56:21.403691Z'}
{'type': 'l2update', 'product_id': 'BTC-USD', 'changes': [['sell', '38416.30', '0.00000000']], 'time': '2021-05-20T03:56:21.405413Z'}
{'type': 'l2update', 'product_id': 'BTC-USD', 'changes': [['sell', '38402.57', '0.00000000']], 'time': '2021-05-20T03:56:21.406200Z'}
{'type': 'l2update', 'product_id': 'BTC-USD', 'changes': [['buy', '38368.55', '0.00000000']], 'time': '2021-05-20T03:56:21.407538Z'}
{'type': 'l2update', 'product_id': 'BTC-USD', 'changes': [['buy', '38384.90', '0.00000000']], 'time': '2021-05-20T03:56:21.410635Z'}
{'type': 'l2update', 'product_id': 'BTC-USD', 'changes': [['sell', '38456.80', '0.00000000']], 'time': '2021-05-20T03:56:21.410978Z'}
{'type': 'l2update', 'product_id': 'BTC-USD', 'changes': [['buy', '38263.82', '0.00000000']], 'time': '2021-05-20T03:56:21.410978Z'}
{'type': 'l2update', 'product_id': 'BTC-USD', 'changes': [['buy', '38272.16', '0.00000000']], 'time': '2021-05-20T03:56:21.410978Z'}
{'type': 'l2update', 'product_id': 'BTC-USD', 'changes': [['buy', '38282.00', '0.16154872']], 'time': '2021-05-20T03:56:21.410978Z'}
{'type': 'l2update', 'product_id': 'BTC-USD', 'changes': [['buy', '38295.36', '0.43639355']], 'time': '2021-05-20T03:56:21.410978Z'}
{'type': 'l2update', 'product_id': 'BTC-USD', 'changes': [['buy', '38334.41', '0.00000000']], 'time': '2021-05-20T03:56:21.411299Z'}
{'type': 'l2update', 'product_id': 'BTC-USD', 'changes': [['sell', '38389.09', '0.07460000']], 'time': '2021-05-20T03:56:21.414298Z'}
{'type': 'l2update', 'product_id': 'BTC-USD', 'changes': [['buy', '38382.20', '0.04975459']], 'time': '2021-05-20T03:56:21.414437Z'}
{'type': 'l2update', 'product_id': 'BTC-USD', 'changes': [['buy', '38221.96', '0.04932896']], 'time': '2021-05-20T03:56:21.415118Z'}
{'type': 'l2update', 'product_id': 'BTC-USD', 'changes': [['buy', '38358.98', '0.39490431']], 'time': '2021-05-20T03:56:21.415130Z'}
{'type': 'l2update', 'product_id': 'BTC-USD', 'changes': [['buy', '38389.08', '0.00000000']], 'time': '2021-05-20T03:56:21.415237Z'}
{'type': 'l2update', 'product_id': 'BTC-USD', 'changes': [['sell', '38389.09', '1.36429332']], 'time': '2021-05-20T03:56:21.415603Z'}
{'type': 'l2update', 'product_id': 'BTC-USD', 'changes': [['sell', '38548.91', '0.01000000']], 'time': '2021-05-20T03:56:21.419502Z'}
{'type': 'l2update', 'product_id': 'BTC-USD', 'changes': [['sell', '38479.29', '0.00000000']], 'time': '2021-05-20T03:56:21.424469Z'}
{'type': 'l2update', 'product_id': 'BTC-USD', 'changes': [['sell', '38566.82', '0.30067152']], 'time': '2021-05-20T03:56:21.426151Z'}
{'type': 'l2update', 'product_id': 'BTC-USD', 'changes': [['sell', '38389.09', '1.38429332']], 'time': '2021-05-20T03:56:21.426663Z'}
{'type': 'l2update', 'product_id': 'BTC-USD', 'changes': [['sell', '43353.81', '0.03000670']], 'time': '2021-05-20T03:56:21.426796Z'}
{'type': 'l2update', 'product_id': 'BTC-USD', 'changes': [['buy', '38367.95', '0.07099044']], 'time': '2021-05-20T03:56:21.426814Z'}
{'type': 'l2update', 'product_id': 'BTC-USD', 'changes': [['sell', '38504.80', '0.03697812']], 'time': '2021-05-20T03:56:21.426955Z'}
{'type': 'l2update', 'product_id': 'BTC-USD', 'changes': [['buy', '38370.26', '0.20260709']], 'time': '2021-05-20T03:56:21.431472Z'}
{'type': 'l2update', 'product_id': 'BTC-USD', 'changes': [['sell', '38423.73', '0.00000000']], 'time': '2021-05-20T03:56:21.433171Z'}
{'type': 'l2update', 'product_id': 'BTC-USD', 'changes': [['sell', '38463.27', '0.00000000']], 'time': '2021-05-20T03:56:21.438008Z'}
{'type': 'l2update', 'product_id': 'BTC-USD', 'changes': [['sell', '38389.09', '1.41319332']], 'time': '2021-05-20T03:56:21.439464Z'}
{'type': 'l2update', 'product_id': 'BTC-USD', 'changes': [['sell', '38389.09', '1.91319332']], 'time': '2021-05-20T03:56:21.440587Z'}
{'type': 'l2update', 'product_id': 'BTC-USD', 'changes': [['sell', '38395.23', '0.50000000']], 'time': '2021-05-20T03:56:21.441244Z'}
{'type': 'l2update', 'product_id': 'BTC-USD', 'changes': [['sell', '38389.09', '1.92811332']], 'time': '2021-05-20T03:56:21.441519Z'}
{'type': 'l2update', 'product_id': 'BTC-USD', 'changes': [['sell', '38469.17', '0.00000000']], 'time': '2021-05-20T03:56:21.442281Z'}
{'type': 'l2update', 'product_id': 'BTC-USD', 'changes': [['buy', '38370.26', '0.20000000']], 'time': '2021-05-20T03:56:21.443209Z'}
{'type': 'l2update', 'product_id': 'BTC-USD', 'changes': [['sell', '38389.09', '1.87390046']], 'time': '2021-05-20T03:56:21.444100Z'}
{'type': 'l2update', 'product_id': 'BTC-USD', 'changes': [['sell', '38421.79', '0.06173969']], 'time': '2021-05-20T03:56:21.447086Z'}
{'type': 'l2update', 'product_id': 'BTC-USD', 'changes': [['sell', '38487.44', '0.45027023']], 'time': '2021-05-20T03:56:21.449565Z'}
{'type': 'l2update', 'product_id': 'BTC-USD', 'changes': [['sell', '38382.21', '0.02890000']], 'time': '2021-05-20T03:56:21.449585Z'}
{'type': 'l2update', 'product_id': 'BTC-USD', 'changes': [['buy', '38378.06', '0.01492000']], 'time': '2021-05-20T03:56:21.450260Z'}
{'type': 'l2update', 'product_id': 'BTC-USD', 'changes': [['buy', '38357.39', '1.46756192']], 'time': '2021-05-20T03:56:21.450309Z'}
{'type': 'l2update', 'product_id': 'BTC-USD', 'changes': [['buy', '38357.39', '2.05872747']], 'time': '2021-05-20T03:56:21.450374Z'}
{'type': 'l2update', 'product_id': 'BTC-USD', 'changes': [['buy', '38377.92', '0.07460000']], 'time': '2021-05-20T03:56:21.450450Z'}
{'type': 'l2update', 'product_id': 'BTC-USD', 'changes': [['sell', '38432.81', '0.59278315']], 'time': '2021-05-20T03:56:21.451011Z'}
{'type': 'l2update', 'product_id': 'BTC-USD', 'changes': [['buy', '38382.20', '0.00000000']], 'time': '2021-05-20T03:56:21.451279Z'}
{'type': 'l2update', 'product_id': 'BTC-USD', 'changes': [['buy', '38221.96', '0.00000000']], 'time': '2021-05-20T03:56:21.452454Z'}
{'type': 'l2update', 'product_id': 'BTC-USD', 'changes': [['buy', '38342.31', '0.02390000']], 'time': '2021-05-20T03:56:21.459581Z'}
{'type': 'l2update', 'product_id': 'BTC-USD', 'changes': [['buy', '38341.50', '0.02390000']], 'time': '2021-05-20T03:56:21.459581Z'}
{'type': 'l2update', 'product_id': 'BTC-USD', 'changes': [['buy', '38340.69', '0.02390000']], 'time': '2021-05-20T03:56:21.459581Z'}
{'type': 'l2update', 'product_id': 'BTC-USD', 'changes': [['buy', '38295.36', '0.00000000']], 'time': '2021-05-20T03:56:21.463271Z'}
{'type': 'l2update', 'product_id': 'BTC-USD', 'changes': [['buy', '38303.62', '0.00000000']], 'time': '2021-05-20T03:56:21.463271Z'}
{'type': 'l2update', 'product_id': 'BTC-USD', 'changes': [['buy', '38308.55', '0.00000000']], 'time': '2021-05-20T03:56:21.463271Z'}
{'type': 'l2update', 'product_id': 'BTC-USD', 'changes': [['buy', '38349.62', '0.06173969']], 'time': '2021-05-20T03:56:21.464650Z'}
{'type': 'l2update', 'product_id': 'BTC-USD', 'changes': [['sell', '38508.91', '0.01000000']], 'time': '2021-05-20T03:56:21.465326Z'}
{'type': 'l2update', 'product_id': 'BTC-USD', 'changes': [['sell', '38388.81', '0.20000000']], 'time': '2021-05-20T03:56:21.466774Z'}
{'type': 'l2update', 'product_id': 'BTC-USD', 'changes': [['sell', '38389.09', '1.87963046']], 'time': '2021-05-20T03:56:21.470658Z'}
{'type': 'l2update', 'product_id': 'BTC-USD', 'changes': [['sell', '38511.66', '0.02802275']], 'time': '2021-05-20T03:56:21.470749Z'}
{'type': 'l2update', 'product_id': 'BTC-USD', 'changes': [['buy', '38350.40', '0.04796664']], 'time': '2021-05-20T03:56:21.470878Z'}
{'type': 'l2update', 'product_id': 'BTC-USD', 'changes': [['sell', '38397.46', '0.03921473']], 'time': '2021-05-20T03:56:21.470878Z'}
{'type': 'l2update', 'product_id': 'BTC-USD', 'changes': [['sell', '38452.23', '0.00000000']], 'time': '2021-05-20T03:56:21.470936Z'}
{'type': 'l2update', 'product_id': 'BTC-USD', 'changes': [['sell', '38407.20', '0.00000000']], 'time': '2021-05-20T03:56:21.471347Z'}
{'type': 'l2update', 'product_id': 'BTC-USD', 'changes': [['buy', '38359.03', '0.84600000']], 'time': '2021-05-20T03:56:21.475649Z'}
{'type': 'l2update', 'product_id': 'BTC-USD', 'changes': [['buy', '38041.67', '5.00000000']], 'time': '2021-05-20T03:56:21.476059Z'}
{'type': 'l2update', 'product_id': 'BTC-USD', 'changes': [['sell', '38403.22', '0.00000000']], 'time': '2021-05-20T03:56:21.476640Z'}
{'type': 'l2update', 'product_id': 'BTC-USD', 'changes': [['sell', '38389.09', '1.85073046']], 'time': '2021-05-20T03:56:21.478350Z'}
{'type': 'l2update', 'product_id': 'BTC-USD', 'changes': [['buy', '38378.06', '0.00000000']], 'time': '2021-05-20T03:56:21.478773Z'}
{'type': 'l2update', 'product_id': 'BTC-USD', 'changes': [['sell', '38398.87', '0.00000000']], 'time': '2021-05-20T03:56:21.479223Z'}
{'type': 'l2update', 'product_id': 'BTC-USD', 'changes': [['sell', '38389.09', '1.83581046']], 'time': '2021-05-20T03:56:21.479289Z'}
{'type': 'l2update', 'product_id': 'BTC-USD', 'changes': [['buy', '38377.92', '0.00000000']], 'time': '2021-05-20T03:56:21.479391Z'}
{'type': 'l2update', 'product_id': 'BTC-USD', 'changes': [['sell', '38389.09', '1.81542332']], 'time': '2021-05-20T03:56:21.479931Z'}
{'type': 'l2update', 'product_id': 'BTC-USD', 'changes': [['sell', '38407.19', '0.05000000']], 'time': '2021-05-20T03:56:21.481048Z'}
{'type': 'l2update', 'product_id': 'BTC-USD', 'changes': [['buy', '38338.40', '1.20000000']], 'time': '2021-05-20T03:56:21.481505Z'}
{'type': 'l2update', 'product_id': 'BTC-USD', 'changes': [['sell', '38482.96', '0.01299276']], 'time': '2021-05-20T03:56:21.481687Z'}
{'type': 'l2update', 'product_id': 'BTC-USD', 'changes': [['buy', '38347.28', '0.39400000']], 'time': '2021-05-20T03:56:21.482826Z'}
{'type': 'l2update', 'product_id': 'BTC-USD', 'changes': [['buy', '38210.13', '0.01000000']], 'time': '2021-05-20T03:56:21.485440Z'}
{'type': 'l2update', 'product_id': 'BTC-USD', 'changes': [['buy', '38347.05', '0.00000000']], 'time': '2021-05-20T03:56:21.486912Z'}
{'type': 'l2update', 'product_id': 'BTC-USD', 'changes': [['buy', '38342.31', '0.00000000']], 'time': '2021-05-20T03:56:21.490801Z'}
{'type': 'l2update', 'product_id': 'BTC-USD', 'changes': [['buy', '38341.50', '0.00000000']], 'time': '2021-05-20T03:56:21.490801Z'}
{'type': 'l2update', 'product_id': 'BTC-USD', 'changes': [['buy', '38291.49', '0.00000000']], 'time': '2021-05-20T03:56:21.491990Z'}
{'type': 'l2update', 'product_id': 'BTC-USD', 'changes': [['sell', '38436.35', '0.00000000']], 'time': '2021-05-20T03:56:21.504191Z'}
{'type': 'l2update', 'product_id': 'BTC-USD', 'changes': [['sell', '38388.81', '0.30000000']], 'time': '2021-05-20T03:56:21.505163Z'}
{'type': 'l2update', 'product_id': 'BTC-USD', 'changes': [['sell', '38542.17', '0.41059991']], 'time': '2021-05-20T03:56:21.505286Z'}
{'type': 'l2update', 'product_id': 'BTC-USD', 'changes': [['sell', '38382.21', '0.02703223']], 'time': '2021-05-20T03:56:21.508462Z'}
{'type': 'l2update', 'product_id': 'BTC-USD', 'changes': [['buy', '37548.82', '0.06351598']], 'time': '2021-05-20T03:56:21.508522Z'}
{'type': 'l2update', 'product_id': 'BTC-USD', 'changes': [['sell', '38389.08', '0.00573000']], 'time': '2021-05-20T03:56:21.508702Z'}
{'type': 'l2update', 'product_id': 'BTC-USD', 'changes': [['sell', '38389.09', '1.85542332']], 'time': '2021-05-20T03:56:21.511999Z'}
{'type': 'l2update', 'product_id': 'BTC-USD', 'changes': [['sell', '38471.56', '0.03487620']], 'time': '2021-05-20T03:56:21.512257Z'}
{'type': 'l2update', 'product_id': 'BTC-USD', 'changes': [['sell', '38450.62', '0.01300190']], 'time': '2021-05-20T03:56:21.512257Z'}
{'type': 'l2update', 'product_id': 'BTC-USD', 'changes': [['buy', '38294.91', '0.03487620']], 'time': '2021-05-20T03:56:21.512257Z'}
{'type': 'l2update', 'product_id': 'BTC-USD', 'changes': [['buy', '38306.48', '0.03546148']], 'time': '2021-05-20T03:56:21.512257Z'}
{'type': 'l2update', 'product_id': 'BTC-USD', 'changes': [['buy', '37568.18', '0.00000000']], 'time': '2021-05-20T03:56:21.512826Z'}
{'type': 'l2update', 'product_id': 'BTC-USD', 'changes': [['sell', '38395.23', '0.00000000']], 'time': '2021-05-20T03:56:21.517211Z'}
{'type': 'l2update', 'product_id': 'BTC-USD', 'changes': [['buy', '38379.85', '0.00854523']], 'time': '2021-05-20T03:56:21.521040Z'}
{'type': 'l2update', 'product_id': 'BTC-USD', 'changes': [['sell', '38476.59', '1.20000000']], 'time': '2021-05-20T03:56:21.539224Z'}
{'type': 'l2update', 'product_id': 'BTC-USD', 'changes': [['buy', '38340.69', '0.00000000']], 'time': '2021-05-20T03:56:21.546163Z'}
{'type': 'l2update', 'product_id': 'BTC-USD', 'changes': [['buy', '38333.45', '0.10000000']], 'time': '2021-05-20T03:56:21.555019Z'}
{'type': 'l2update', 'product_id': 'BTC-USD', 'changes': [['sell', '38389.08', '2.49542908']], 'time': '2021-05-20T03:56:21.555187Z'}
{'type': 'l2update', 'product_id': 'BTC-USD', 'changes': [['buy', '38357.39', '1.46756192']], 'time': '2021-05-20T03:56:21.556238Z'}
{'type': 'l2update', 'product_id': 'BTC-USD', 'changes': [['sell', '38421.79', '0.00000000']], 'time': '2021-05-20T03:56:21.567155Z'}
{'type': 'l2update', 'product_id': 'BTC-USD', 'changes': [['sell', '38566.82', '0.00000000']], 'time': '2021-05-20T03:56:21.575712Z'}
{'type': 'l2update', 'product_id': 'BTC-USD', 'changes': [['sell', '38498.02', '0.00000000']], 'time': '2021-05-20T03:56:21.586404Z'}
{'type': 'l2update', 'product_id': 'BTC-USD', 'changes': [['buy', '38262.76', '0.00000000']], 'time': '2021-05-20T03:56:21.586404Z'}
{'type': 'l2update', 'product_id': 'BTC-USD', 'changes': [['sell', '38431.03', '0.03207306']], 'time': '2021-05-20T03:56:21.586886Z'}
{'type': 'l2update', 'product_id': 'BTC-USD', 'changes': [['sell', '38382.20', '0.00573000']], 'time': '2021-05-20T03:56:21.589802Z'}
{'type': 'l2update', 'product_id': 'BTC-USD', 'changes': [['buy', '38241.67', '0.01000000']], 'time': '2021-05-20T03:56:21.595050Z'}
{'type': 'l2update', 'product_id': 'BTC-USD', 'changes': [['sell', '38541.03', '0.38120889']], 'time': '2021-05-20T03:56:21.595780Z'}
{'type': 'l2update', 'product_id': 'BTC-USD', 'changes': [['sell', '38490.25', '0.78718676']], 'time': '2021-05-20T03:56:21.595780Z'}
{'type': 'l2update', 'product_id': 'BTC-USD', 'changes': [['sell', '38388.76', '1.50900000']], 'time': '2021-05-20T03:56:21.606324Z'}
{'type': 'l2update', 'product_id': 'BTC-USD', 'changes': [['buy', '38325.94', '0.32000000']], 'time': '2021-05-20T03:56:21.613540Z'}
{'type': 'l2update', 'product_id': 'BTC-USD', 'changes': [['buy', '38338.40', '0.00000000']], 'time': '2021-05-20T03:56:21.615723Z'}
{'type': 'l2update', 'product_id': 'BTC-USD', 'changes': [['buy', '38272.90', '0.50000000']], 'time': '2021-05-20T03:56:21.629364Z'}
{'type': 'l2update', 'product_id': 'BTC-USD', 'changes': [['sell', '38382.21', '0.00000000']], 'time': '2021-05-20T03:56:21.629897Z'}
{'type': 'l2update', 'product_id': 'BTC-USD', 'changes': [['buy', '38213.39', '0.05023980']], 'time': '2021-05-20T03:56:21.641237Z'}
{'type': 'l2update', 'product_id': 'BTC-USD', 'changes': [['buy', '38350.13', '0.00000000']], 'time': '2021-05-20T03:56:21.644416Z'}
{'type': 'l2update', 'product_id': 'BTC-USD', 'changes': [['sell', '38388.80', '0.50000000']], 'time': '2021-05-20T03:56:21.645290Z'}
{'type': 'l2update', 'product_id': 'BTC-USD', 'changes': [['buy', '38351.31', '0.00000000']], 'time': '2021-05-20T03:56:21.662280Z'}
{'type': 'l2update', 'product_id': 'BTC-USD', 'changes': [['sell', '38425.98', '0.00000000']], 'time': '2021-05-20T03:56:21.666820Z'}
{'type': 'l2update', 'product_id': 'BTC-USD', 'changes': [['sell', '38585.12', '0.00000000']], 'time': '2021-05-20T03:56:21.668293Z'}
{'type': 'l2update', 'product_id': 'BTC-USD', 'changes': [['sell', '38526.34', '0.00000000']], 'time': '2021-05-20T03:56:21.668657Z'}
{'type': 'l2update', 'product_id': 'BTC-USD', 'changes': [['sell', '38470.43', '0.01000000']], 'time': '2021-05-20T03:56:21.670643Z'}
{'type': 'l2update', 'product_id': 'BTC-USD', 'changes': [['sell', '38483.20', '0.37698487']], 'time': '2021-05-20T03:56:21.671787Z'}
{'type': 'l2update', 'product_id': 'BTC-USD', 'changes': [['buy', '38269.51', '0.02744305']], 'time': '2021-05-20T03:56:21.671787Z'}
{'type': 'l2update', 'product_id': 'BTC-USD', 'changes': [['sell', '38382.21', '0.00573000']], 'time': '2021-05-20T03:56:21.672273Z'}
{'type': 'l2update', 'product_id': 'BTC-USD', 'changes': [['buy', '38241.30', '0.02000000']], 'time': '2021-05-20T03:56:21.675002Z'}
{'type': 'l2update', 'product_id': 'BTC-USD', 'changes': [['sell', '38476.59', '0.00000000']], 'time': '2021-05-20T03:56:21.703711Z'}
{'type': 'l2update', 'product_id': 'BTC-USD', 'changes': [['buy', '38315.47', '0.00000000']], 'time': '2021-05-20T03:56:21.705610Z'}
{'type': 'l2update', 'product_id': 'BTC-USD', 'changes': [['buy', '38357.39', '0.00000000']], 'time': '2021-05-20T03:56:21.707143Z'}
{'type': 'l2update', 'product_id': 'BTC-USD', 'changes': [['buy', '38231.18', '0.80000000']], 'time': '2021-05-20T03:56:21.714137Z'}
{'type': 'l2update', 'product_id': 'BTC-USD', 'changes': [['buy', '38239.85', '0.16640000']], 'time': '2021-05-20T03:56:21.717062Z'}
{'type': 'l2update', 'product_id': 'BTC-USD', 'changes': [['buy', '38336.23', '0.02390000']], 'time': '2021-05-20T03:56:21.730937Z'}
{'type': 'l2update', 'product_id': 'BTC-USD', 'changes': [['buy', '38335.43', '0.02390000']], 'time': '2021-05-20T03:56:21.730937Z'}
{'type': 'l2update', 'product_id': 'BTC-USD', 'changes': [['buy', '38334.62', '0.02390000']], 'time': '2021-05-20T03:56:21.730937Z'}
{'type': 'l2update', 'product_id': 'BTC-USD', 'changes': [['sell', '38427.48', '0.50000000']], 'time': '2021-05-20T03:56:21.733839Z'}
{'type': 'l2update', 'product_id': 'BTC-USD', 'changes': [['sell', '38382.15', '0.65900000']], 'time': '2021-05-20T03:56:21.737861Z'}
{'type': 'l2update', 'product_id': 'BTC-USD', 'changes': [['buy', '38223.85', '0.04899735']], 'time': '2021-05-20T03:56:21.745349Z'}
{'type': 'l2update', 'product_id': 'BTC-USD', 'changes': [['sell', '38398.86', '0.00000000']], 'time': '2021-05-20T03:56:21.748792Z'}
{'type': 'l2update', 'product_id': 'BTC-USD', 'changes': [['sell', '38422.14', '0.05115837']], 'time': '2021-05-20T03:56:21.750683Z'}
{'type': 'l2update', 'product_id': 'BTC-USD', 'changes': [['buy', '38370.35', '0.00000000']], 'time': '2021-05-20T03:56:21.755870Z'}
{'type': 'l2update', 'product_id': 'BTC-USD', 'changes': [['buy', '38377.47', '0.05020936']], 'time': '2021-05-20T03:56:21.762426Z'}
{'type': 'l2update', 'product_id': 'BTC-USD', 'changes': [['sell', '38413.96', '0.05112543']], 'time': '2021-05-20T03:56:21.763526Z'}
{'type': 'l2update', 'product_id': 'BTC-USD', 'changes': [['buy', '38358.98', '0.00000000']], 'time': '2021-05-20T03:56:21.764498Z'}
{'type': 'l2update', 'product_id': 'BTC-USD', 'changes': [['sell', '38388.99', '0.04949615']], 'time': '2021-05-20T03:56:21.765907Z'}
{'type': 'l2update', 'product_id': 'BTC-USD', 'changes': [['sell', '38483.20', '0.02744305']], 'time': '2021-05-20T03:56:21.766742Z'}
{'type': 'l2update', 'product_id': 'BTC-USD', 'changes': [['buy', '37609.90', '0.00131298']], 'time': '2021-05-20T03:56:21.769546Z'}
{'type': 'l2update', 'product_id': 'BTC-USD', 'changes': [['sell', '38389.09', '1.84969332']], 'time': '2021-05-20T03:56:21.773482Z'}
{'type': 'l2update', 'product_id': 'BTC-USD', 'changes': [['buy', '38241.30', '0.05000000']], 'time': '2021-05-20T03:56:21.782414Z'}
{'type': 'l2update', 'product_id': 'BTC-USD', 'changes': [['sell', '38388.35', '0.07460000']], 'time': '2021-05-20T03:56:21.782976Z'}
{'type': 'l2update', 'product_id': 'BTC-USD', 'changes': [['sell', '39187.40', '0.06291777']], 'time': '2021-05-20T03:56:21.783013Z'}
{'type': 'l2update', 'product_id': 'BTC-USD', 'changes': [['sell', '38471.56', '0.06334387']], 'time': '2021-05-20T03:56:21.783098Z'}
{'type': 'l2update', 'product_id': 'BTC-USD', 'changes': [['buy', '38276.14', '0.02846767']], 'time': '2021-05-20T03:56:21.783098Z'}
{'type': 'l2update', 'product_id': 'BTC-USD', 'changes': [['sell', '38388.39', '0.01492000']], 'time': '2021-05-20T03:56:21.790941Z'}
{'type': 'l2update', 'product_id': 'BTC-USD', 'changes': [['sell', '38382.15', '0.65388127']], 'time': '2021-05-20T03:56:21.795278Z'}
{'type': 'l2update', 'product_id': 'BTC-USD', 'changes': [['sell', '38388.80', '0.00000000']], 'time': '2021-05-20T03:56:21.807668Z'}
{'type': 'l2update', 'product_id': 'BTC-USD', 'changes': [['buy', '38340.70', '0.02608194']], 'time': '2021-05-20T03:56:21.809631Z'}
{'type': 'l2update', 'product_id': 'BTC-USD', 'changes': [['sell', '38473.60', '0.00000000']], 'time': '2021-05-20T03:56:21.813500Z'}
{'type': 'l2update', 'product_id': 'BTC-USD', 'changes': [['buy', '38359.04', '0.59116555']], 'time': '2021-05-20T03:56:21.813688Z'}
{'type': 'l2update', 'product_id': 'BTC-USD', 'changes': [['sell', '38389.09', '1.34969332']], 'time': '2021-05-20T03:56:21.822710Z'}
{'type': 'l2update', 'product_id': 'BTC-USD', 'changes': [['buy', '38229.03', '0.05029989']], 'time': '2021-05-20T03:56:21.825544Z'}
{'type': 'l2update', 'product_id': 'BTC-USD', 'changes': [['sell', '38447.12', '0.05062555']], 'time': '2021-05-20T03:56:21.826056Z'}
{'type': 'l2update', 'product_id': 'BTC-USD', 'changes': [['sell', '38437.28', '0.32000000']], 'time': '2021-05-20T03:56:21.828877Z'}
{'type': 'l2update', 'product_id': 'BTC-USD', 'changes': [['sell', '38532.04', '0.80000000']], 'time': '2021-05-20T03:56:21.828877Z'}
{'type': 'l2update', 'product_id': 'BTC-USD', 'changes': [['buy', '38336.23', '0.00000000']], 'time': '2021-05-20T03:56:21.849591Z'}
{'type': 'l2update', 'product_id': 'BTC-USD', 'changes': [['buy', '38335.43', '0.00000000']], 'time': '2021-05-20T03:56:21.849591Z'}
{'type': 'l2update', 'product_id': 'BTC-USD', 'changes': [['buy', '38334.62', '0.00000000']], 'time': '2021-05-20T03:56:21.849591Z'}
{'type': 'l2update', 'product_id': 'BTC-USD', 'changes': [['sell', '38487.99', '0.56441481']], 'time': '2021-05-20T03:56:21.850834Z'}
{'type': 'l2update', 'product_id': 'BTC-USD', 'changes': [['sell', '38389.09', '0.06000000']], 'time': '2021-05-20T03:56:21.856061Z'}
{'type': 'l2update', 'product_id': 'BTC-USD', 'changes': [['buy', '38355.99', '1.46756192']], 'time': '2021-05-20T03:56:21.873220Z'}
{'type': 'l2update', 'product_id': 'BTC-USD', 'changes': [['sell', '38453.36', '0.05440371']], 'time': '2021-05-20T03:56:21.874003Z'}
{'type': 'l2update', 'product_id': 'BTC-USD', 'changes': [['buy', '38357.06', '0.00000000']], 'time': '2021-05-20T03:56:21.874764Z'}
{'type': 'l2update', 'product_id': 'BTC-USD', 'changes': [['buy', '38359.03', '1.36500000']], 'time': '2021-05-20T03:56:21.874850Z'}
{'type': 'l2update', 'product_id': 'BTC-USD', 'changes': [['sell', '38389.09', '0.16000000']], 'time': '2021-05-20T03:56:21.874878Z'}
{'type': 'l2update', 'product_id': 'BTC-USD', 'changes': [['buy', '38367.95', '0.00000000']], 'time': '2021-05-20T03:56:21.875668Z'}
{'type': 'l2update', 'product_id': 'BTC-USD', 'changes': [['sell', '38412.49', '0.00000000']], 'time': '2021-05-20T03:56:21.877015Z'}
{'type': 'l2update', 'product_id': 'BTC-USD', 'changes': [['buy', '38300.01', '0.00000000']], 'time': '2021-05-20T03:56:21.877746Z'}
{'type': 'l2update', 'product_id': 'BTC-USD', 'changes': [['sell', '38548.27', '0.30069832']], 'time': '2021-05-20T03:56:21.880270Z'}
{'type': 'l2update', 'product_id': 'BTC-USD', 'changes': [['sell', '38382.15', '0.63853872']], 'time': '2021-05-20T03:56:21.880326Z'}
{'type': 'l2update', 'product_id': 'BTC-USD', 'changes': [['sell', '38395.24', '0.00000000']], 'time': '2021-05-20T03:56:21.892207Z'}
{'type': 'l2update', 'product_id': 'BTC-USD', 'changes': [['sell', '38389.08', '2.48969908']], 'time': '2021-05-20T03:56:21.893197Z'}
{'type': 'l2update', 'product_id': 'BTC-USD', 'changes': [['sell', '38522.90', '0.35551301']], 'time': '2021-05-20T03:56:21.895871Z'}
{'type': 'l2update', 'product_id': 'BTC-USD', 'changes': [['sell', '38477.55', '0.30838260']], 'time': '2021-05-20T03:56:21.895871Z'}
{'type': 'l2update', 'product_id': 'BTC-USD', 'changes': [['sell', '38460.99', '0.30397211']], 'time': '2021-05-20T03:56:21.895871Z'}
{'type': 'l2update', 'product_id': 'BTC-USD', 'changes': [['sell', '38450.90', '0.31367179']], 'time': '2021-05-20T03:56:21.895871Z'}
{'type': 'l2update', 'product_id': 'BTC-USD', 'changes': [['sell', '38470.43', '0.00000000']], 'time': '2021-05-20T03:56:21.901769Z'}
{'type': 'l2update', 'product_id': 'BTC-USD', 'changes': [['sell', '38514.06', '0.01000000']], 'time': '2021-05-20T03:56:21.904449Z'}
{'type': 'l2update', 'product_id': 'BTC-USD', 'changes': [['buy', '38350.40', '0.00000000']], 'time': '2021-05-20T03:56:21.909497Z'}
{'type': 'l2update', 'product_id': 'BTC-USD', 'changes': [['sell', '38397.46', '0.00000000']], 'time': '2021-05-20T03:56:21.909497Z'}
{'type': 'l2update', 'product_id': 'BTC-USD', 'changes': [['buy', '38241.30', '0.09000000']], 'time': '2021-05-20T03:56:21.917889Z'}
{'type': 'l2update', 'product_id': 'BTC-USD', 'changes': [['sell', '38477.55', '0.34332180']], 'time': '2021-05-20T03:56:21.919539Z'}
{'type': 'l2update', 'product_id': 'BTC-USD', 'changes': [['buy', '38269.51', '0.06238225']], 'time': '2021-05-20T03:56:21.919539Z'}
{'type': 'l2update', 'product_id': 'BTC-USD', 'changes': [['sell', '38382.15', '0.63792864']], 'time': '2021-05-20T03:56:21.920559Z'}
{'type': 'l2update', 'product_id': 'BTC-USD', 'changes': [['sell', '38388.35', '0.00000000']], 'time': '2021-05-20T03:56:21.920681Z'}
{'type': 'l2update', 'product_id': 'BTC-USD', 'changes': [['buy', '38382.14', '0.02890000']], 'time': '2021-05-20T03:56:21.936292Z'}
{'type': 'l2update', 'product_id': 'BTC-USD', 'changes': [['sell', '38442.46', '0.02601290']], 'time': '2021-05-20T03:56:21.947437Z'}
{'type': 'l2update', 'product_id': 'BTC-USD', 'changes': [['sell', '38388.75', '0.50000000']], 'time': '2021-05-20T03:56:21.951312Z'}
{'type': 'l2update', 'product_id': 'BTC-USD', 'changes': [['buy', '38272.90', '0.00000000']], 'time': '2021-05-20T03:56:21.955514Z'}
{'type': 'l2update', 'product_id': 'BTC-USD', 'changes': [['sell', '38388.39', '0.00000000']], 'time': '2021-05-20T03:56:21.961047Z'}
{'type': 'l2update', 'product_id': 'BTC-USD', 'changes': [['buy', '38350.88', '0.02000000']], 'time': '2021-05-20T03:56:21.967754Z'}
{'type': 'l2update', 'product_id': 'BTC-USD', 'changes': [['sell', '38389.51', '0.00000000']], 'time': '2021-05-20T03:56:21.977645Z'}
{'type': 'l2update', 'product_id': 'BTC-USD', 'changes': [['sell', '38388.76', '0.00000000']], 'time': '2021-05-20T03:56:21.979262Z'}
{'type': 'l2update', 'product_id': 'BTC-USD', 'changes': [['buy', '38382.14', '0.04382000']], 'time': '2021-05-20T03:56:21.984547Z'}
{'type': 'l2update', 'product_id': 'BTC-USD', 'changes': [['sell', '38513.41', '0.01000000']], 'time': '2021-05-20T03:56:21.995352Z'}
{'type': 'l2update', 'product_id': 'BTC-USD', 'changes': [['sell', '38382.15', '0.00000000']], 'time': '2021-05-20T03:56:21.996902Z'}
{'type': 'l2update', 'product_id': 'BTC-USD', 'changes': [['buy', '38370.26', '0.00000000']], 'time': '2021-05-20T03:56:21.997197Z'}
{'type': 'l2update', 'product_id': 'BTC-USD', 'changes': [['sell', '38565.17', '0.00000000']], 'time': '2021-05-20T03:56:22.006796Z'}
{'type': 'l2update', 'product_id': 'BTC-USD', 'changes': [['buy', '38382.10', '0.05118163']], 'time': '2021-05-20T03:56:22.017884Z'}
{'type': 'l2update', 'product_id': 'BTC-USD', 'changes': [['sell', '38388.99', '0.00000000']], 'time': '2021-05-20T03:56:22.017929Z'}
{'type': 'l2update', 'product_id': 'BTC-USD', 'changes': [['buy', '30354.26', '0.00000000']], 'time': '2021-05-20T03:56:22.018041Z'}
{'type': 'l2update', 'product_id': 'BTC-USD', 'changes': [['sell', '38382.20', '0.00000000']], 'time': '2021-05-20T03:56:22.020553Z'}
{'type': 'l2update', 'product_id': 'BTC-USD', 'changes': [['sell', '38542.39', '0.00000000']], 'time': '2021-05-20T03:56:22.032319Z'}
{'type': 'l2update', 'product_id': 'BTC-USD', 'changes': [['buy', '38382.14', '0.11223208']], 'time': '2021-05-20T03:56:22.033120Z'}
{'type': 'l2update', 'product_id': 'BTC-USD', 'changes': [['buy', '38382.19', '0.04330000']], 'time': '2021-05-20T03:56:22.033347Z'}
{'type': 'l2update', 'product_id': 'BTC-USD', 'changes': [['sell', '38450.90', '0.45391410']], 'time': '2021-05-20T03:56:22.033523Z'}
{'type': 'l2update', 'product_id': 'BTC-USD', 'changes': [['sell', '38457.43', '0.01000000']], 'time': '2021-05-20T03:56:22.036303Z'}
{'type': 'l2update', 'product_id': 'BTC-USD', 'changes': [['buy', '38382.14', '0.11842000']], 'time': '2021-05-20T03:56:22.036370Z'}
{'type': 'l2update', 'product_id': 'BTC-USD', 'changes': [['sell', '38483.20', '0.05863195']], 'time': '2021-05-20T03:56:22.040621Z'}
{'type': 'l2update', 'product_id': 'BTC-USD', 'changes': [['sell', '38382.21', '0.00549623']], 'time': '2021-05-20T03:56:22.040805Z'}
{'type': 'l2update', 'product_id': 'BTC-USD', 'changes': [['buy', '38241.30', '0.14000000']], 'time': '2021-05-20T03:56:22.041154Z'}
{'type': 'l2update', 'product_id': 'BTC-USD', 'changes': [['buy', '38213.39', '0.00000000']], 'time': '2021-05-20T03:56:22.046837Z'}
{'type': 'l2update', 'product_id': 'BTC-USD', 'changes': [['sell', '38388.75', '0.00000000']], 'time': '2021-05-20T03:56:22.054885Z'}
{'type': 'l2update', 'product_id': 'BTC-USD', 'changes': [['sell', '38548.27', '0.00000000']], 'time': '2021-05-20T03:56:22.062459Z'}
{'type': 'l2update', 'product_id': 'BTC-USD', 'changes': [['buy', '38349.62', '0.00000000']], 'time': '2021-05-20T03:56:22.066007Z'}
{'type': 'l2update', 'product_id': 'BTC-USD', 'changes': [['buy', '38184.17', '0.00000000']], 'time': '2021-05-20T03:56:22.066098Z'}
{'type': 'l2update', 'product_id': 'BTC-USD', 'changes': [['buy', '38377.48', '0.98587534']], 'time': '2021-05-20T03:56:22.070749Z'}
{'type': 'l2update', 'product_id': 'BTC-USD', 'changes': [['buy', '38329.22', '0.02400000']], 'time': '2021-05-20T03:56:22.071014Z'}
{'type': 'l2update', 'product_id': 'BTC-USD', 'changes': [['buy', '38328.42', '0.02400000']], 'time': '2021-05-20T03:56:22.071014Z'}
{'type': 'l2update', 'product_id': 'BTC-USD', 'changes': [['buy', '38327.61', '0.02400000']], 'time': '2021-05-20T03:56:22.071014Z'}
{'type': 'l2update', 'product_id': 'BTC-USD', 'changes': [['sell', '38382.21', '0.10549623']], 'time': '2021-05-20T03:56:22.071615Z'}
{'type': 'l2update', 'product_id': 'BTC-USD', 'changes': [['sell', '38382.21', '0.10000000']], 'time': '2021-05-20T03:56:22.072284Z'}
{'type': 'l2update', 'product_id': 'BTC-USD', 'changes': [['buy', '38382.14', '0.10350000']], 'time': '2021-05-20T03:56:22.072350Z'}
{'type': 'l2update', 'product_id': 'BTC-USD', 'changes': [['buy', '38334.42', '0.06722592']], 'time': '2021-05-20T03:56:22.075407Z'}
{'type': 'l2update', 'product_id': 'BTC-USD', 'changes': [['sell', '38534.16', '0.00000000']], 'time': '2021-05-20T03:56:22.079509Z'}
{'type': 'l2update', 'product_id': 'BTC-USD', 'changes': [['sell', '38513.07', '0.00000000']], 'time': '2021-05-20T03:56:22.079509Z'}
{'type': 'l2update', 'product_id': 'BTC-USD', 'changes': [['sell', '38496.98', '0.00000000']], 'time': '2021-05-20T03:56:22.079509Z'}
{'type': 'l2update', 'product_id': 'BTC-USD', 'changes': [['sell', '38490.25', '0.43658099']], 'time': '2021-05-20T03:56:22.079509Z'}
{'type': 'l2update', 'product_id': 'BTC-USD', 'changes': [['buy', '38382.14', '0.03508792']], 'time': '2021-05-20T03:56:22.081658Z'}
{'type': 'l2update', 'product_id': 'BTC-USD', 'changes': [['buy', '38382.19', '0.10330000']], 'time': '2021-05-20T03:56:22.084113Z'}
{'type': 'l2update', 'product_id': 'BTC-USD', 'changes': [['sell', '38403.43', '0.39490432']], 'time': '2021-05-20T03:56:22.084484Z'}
{'type': 'l2update', 'product_id': 'BTC-USD', 'changes': [['buy', '38382.14', '0.22308792']], 'time': '2021-05-20T03:56:22.084515Z'}
{'type': 'l2update', 'product_id': 'BTC-USD', 'changes': [['buy', '38382.14', '0.21690000']], 'time': '2021-05-20T03:56:22.084553Z'}
{'type': 'l2update', 'product_id': 'BTC-USD', 'changes': [['sell', '38500.43', '0.00000000']], 'time': '2021-05-20T03:56:22.084974Z'}
{'type': 'l2update', 'product_id': 'BTC-USD', 'changes': [['buy', '38377.47', '0.00000000']], 'time': '2021-05-20T03:56:22.091231Z'}
{'type': 'l2update', 'product_id': 'BTC-USD', 'changes': [['buy', '38364.79', '0.52128258']], 'time': '2021-05-20T03:56:22.091788Z'}
{'type': 'l2update', 'product_id': 'BTC-USD', 'changes': [['buy', '38382.20', '0.06000000']], 'time': '2021-05-20T03:56:22.092453Z'}
{'type': 'l2update', 'product_id': 'BTC-USD', 'changes': [['buy', '38373.96', '0.84500000']], 'time': '2021-05-20T03:56:22.092651Z'}
{'type': 'l2update', 'product_id': 'BTC-USD', 'changes': [['sell', '38513.41', '0.00000000']], 'time': '2021-05-20T03:56:22.099671Z'}
{'type': 'l2update', 'product_id': 'BTC-USD', 'changes': [['sell', '38389.51', '0.01000000']], 'time': '2021-05-20T03:56:22.099809Z'}
{'type': 'l2update', 'product_id': 'BTC-USD', 'changes': [['buy', '38369.41', '0.09420323']], 'time': '2021-05-20T03:56:22.100896Z'}
{'type': 'l2update', 'product_id': 'BTC-USD', 'changes': [['sell', '38422.14', '0.00000000']], 'time': '2021-05-20T03:56:22.107879Z'}
{'type': 'l2update', 'product_id': 'BTC-USD', 'changes': [['sell', '38483.88', '0.03256779']], 'time': '2021-05-20T03:56:22.108895Z'}
{'type': 'l2update', 'product_id': 'BTC-USD', 'changes': [['sell', '38413.95', '0.50000000']], 'time': '2021-05-20T03:56:22.109032Z'}
{'type': 'l2update', 'product_id': 'BTC-USD', 'changes': [['buy', '38377.48', '0.00000000']], 'time': '2021-05-20T03:56:22.110352Z'}
{'type': 'l2update', 'product_id': 'BTC-USD', 'changes': [['sell', '38429.95', '0.01000000']], 'time': '2021-05-20T03:56:22.114428Z'}
{'type': 'l2update', 'product_id': 'BTC-USD', 'changes': [['buy', '38192.12', '0.09933870']], 'time': '2021-05-20T03:56:22.114465Z'}
{'type': 'l2update', 'product_id': 'BTC-USD', 'changes': [['sell', '38389.08', '0.00000000']], 'time': '2021-05-20T03:56:22.117023Z'}
{'type': 'l2update', 'product_id': 'BTC-USD', 'changes': [['sell', '38382.21', '0.30000000']], 'time': '2021-05-20T03:56:22.121558Z'}
{'type': 'l2update', 'product_id': 'BTC-USD', 'changes': [['buy', '38382.14', '0.22263000']], 'time': '2021-05-20T03:56:22.122065Z'}
{'type': 'l2update', 'product_id': 'BTC-USD', 'changes': [['buy', '38382.19', '0.04330000']], 'time': '2021-05-20T03:56:22.124374Z'}
{'type': 'l2update', 'product_id': 'BTC-USD', 'changes': [['buy', '38306.67', '0.00000000']], 'time': '2021-05-20T03:56:22.125037Z'}
{'type': 'l2update', 'product_id': 'BTC-USD', 'changes': [['buy', '38348.61', '2.37600000']], 'time': '2021-05-20T03:56:22.130065Z'}
{'type': 'l2update', 'product_id': 'BTC-USD', 'changes': [['sell', '38515.69', '0.01000000']], 'time': '2021-05-20T03:56:22.130146Z'}
{'type': 'l2update', 'product_id': 'BTC-USD', 'changes': [['sell', '38508.99', '0.40431494']], 'time': '2021-05-20T03:56:22.130739Z'}
{'type': 'l2update', 'product_id': 'BTC-USD', 'changes': [['buy', '38359.04', '0.00000000']], 'time': '2021-05-20T03:56:22.138226Z'}
{'type': 'l2update', 'product_id': 'BTC-USD', 'changes': [['sell', '38528.67', '0.01783423']], 'time': '2021-05-20T03:56:22.145255Z'}
{'type': 'l2update', 'product_id': 'BTC-USD', 'changes': [['sell', '38533.62', '0.00000000']], 'time': '2021-05-20T03:56:22.147117Z'}
{'type': 'l2update', 'product_id': 'BTC-USD', 'changes': [['sell', '38389.51', '0.06000000']], 'time': '2021-05-20T03:56:22.147615Z'}
{'type': 'l2update', 'product_id': 'BTC-USD', 'changes': [['buy', '38199.57', '0.01000000']], 'time': '2021-05-20T03:56:22.151085Z'}
{'type': 'l2update', 'product_id': 'BTC-USD', 'changes': [['sell', '38522.28', '0.01000000']], 'time': '2021-05-20T03:56:22.151305Z'}
{'type': 'l2update', 'product_id': 'BTC-USD', 'changes': [['buy', '38361.08', '0.52125336']], 'time': '2021-05-20T03:56:22.151324Z'}
{'type': 'l2update', 'product_id': 'BTC-USD', 'changes': [['buy', '38351.32', '0.06020080']], 'time': '2021-05-20T03:56:22.151692Z'}
{'type': 'l2update', 'product_id': 'BTC-USD', 'changes': [['sell', '38407.19', '0.00000000']], 'time': '2021-05-20T03:56:22.151865Z'}
{'type': 'l2update', 'product_id': 'BTC-USD', 'changes': [['buy', '38347.41', '0.01000000']], 'time': '2021-05-20T03:56:22.157097Z'}
{'type': 'l2update', 'product_id': 'BTC-USD', 'changes': [['sell', '38496.27', '0.03217293']], 'time': '2021-05-20T03:56:22.157184Z'}
{'type': 'l2update', 'product_id': 'BTC-USD', 'changes': [['sell', '38483.88', '0.06585384']], 'time': '2021-05-20T03:56:22.157184Z'}
{'type': 'l2update', 'product_id': 'BTC-USD', 'changes': [['buy', '38355.99', '0.00000000']], 'time': '2021-05-20T03:56:22.158168Z'}
{'type': 'l2update', 'product_id': 'BTC-USD', 'changes': [['sell', '38388.81', '0.10000000']], 'time': '2021-05-20T03:56:22.159660Z'}
{'type': 'l2update', 'product_id': 'BTC-USD', 'changes': [['sell', '38529.09', '0.00000000']], 'time': '2021-05-20T03:56:22.169157Z'}
{'type': 'l2update', 'product_id': 'BTC-USD', 'changes': [['sell', '38550.83', '0.00000000']], 'time': '2021-05-20T03:56:22.170103Z'}
{'type': 'l2update', 'product_id': 'BTC-USD', 'changes': [['sell', '38483.81', '0.02400000']], 'time': '2021-05-20T03:56:22.174470Z'}
{'type': 'l2update', 'product_id': 'BTC-USD', 'changes': [['buy', '38382.19', '0.04903000']], 'time': '2021-05-20T03:56:22.174641Z'}
{'type': 'l2update', 'product_id': 'BTC-USD', 'changes': [['sell', '38453.36', '0.00000000']], 'time': '2021-05-20T03:56:22.180538Z'}
{'type': 'l2update', 'product_id': 'BTC-USD', 'changes': [['buy', '38310.59', '0.00000000']], 'time': '2021-05-20T03:56:22.180576Z'}
{'type': 'l2update', 'product_id': 'BTC-USD', 'changes': [['sell', '38389.09', '0.14000000']], 'time': '2021-05-20T03:56:22.184394Z'}
{'type': 'l2update', 'product_id': 'BTC-USD', 'changes': [['sell', '38514.06', '0.00000000']], 'time': '2021-05-20T03:56:22.189759Z'}
{'type': 'l2update', 'product_id': 'BTC-USD', 'changes': [['buy', '38223.85', '0.00000000']], 'time': '2021-05-20T03:56:22.189912Z'}
{'type': 'l2update', 'product_id': 'BTC-USD', 'changes': [['sell', '38521.90', '0.01000000']], 'time': '2021-05-20T03:56:22.192695Z'}
{'type': 'l2update', 'product_id': 'BTC-USD', 'changes': [['sell', '38534.62', '0.00000000']], 'time': '2021-05-20T03:56:22.193120Z'}
{'type': 'l2update', 'product_id': 'BTC-USD', 'changes': [['buy', '38333.45', '0.00000000']], 'time': '2021-05-20T03:56:22.194519Z'}
{'type': 'l2update', 'product_id': 'BTC-USD', 'changes': [['sell', '38477.85', '0.00000000']], 'time': '2021-05-20T03:56:22.194910Z'}
{'type': 'l2update', 'product_id': 'BTC-USD', 'changes': [['sell', '38388.81', '0.00000000']], 'time': '2021-05-20T03:56:22.195101Z'}
{'type': 'l2update', 'product_id': 'BTC-USD', 'changes': [['buy', '38370.42', '0.52100000']], 'time': '2021-05-20T03:56:22.197372Z'}
{'type': 'l2update', 'product_id': 'BTC-USD', 'changes': [['buy', '38192.12', '0.00000000']], 'time': '2021-05-20T03:56:22.197678Z'}
{'type': 'l2update', 'product_id': 'BTC-USD', 'changes': [['sell', '38413.94', '0.05000000']], 'time': '2021-05-20T03:56:22.198048Z'}
{'type': 'l2update', 'product_id': 'BTC-USD', 'changes': [['buy', '38369.41', '0.00000000']], 'time': '2021-05-20T03:56:22.201814Z'}
{'type': 'l2update', 'product_id': 'BTC-USD', 'changes': [['buy', '38357.48', '0.52130206']], 'time': '2021-05-20T03:56:22.202643Z'}
{'type': 'l2update', 'product_id': 'BTC-USD', 'changes': [['buy', '38014.52', '0.00000000']], 'time': '2021-05-20T03:56:22.202955Z'}
{'type': 'l2update', 'product_id': 'BTC-USD', 'changes': [['buy', '38348.61', '0.00000000']], 'time': '2021-05-20T03:56:22.206792Z'}
{'type': 'l2update', 'product_id': 'BTC-USD', 'changes': [['sell', '38398.99', '2.48969908']], 'time': '2021-05-20T03:56:22.206969Z'}
{'type': 'l2update', 'product_id': 'BTC-USD', 'changes': [['sell', '38429.95', '0.00000000']], 'time': '2021-05-20T03:56:22.207112Z'}
{'type': 'l2update', 'product_id': 'BTC-USD', 'changes': [['buy', '38262.69', '0.41050817']], 'time': '2021-05-20T03:56:22.211657Z'}
{'type': 'l2update', 'product_id': 'BTC-USD', 'changes': [['sell', '38554.00', '0.01000000']], 'time': '2021-05-20T03:56:22.212320Z'}
{'type': 'l2update', 'product_id': 'BTC-USD', 'changes': [['buy', '38317.12', '0.00000000']], 'time': '2021-05-20T03:56:22.213504Z'}
{'type': 'l2update', 'product_id': 'BTC-USD', 'changes': [['sell', '43100.00', '1.09530000']], 'time': '2021-05-20T03:56:22.215669Z'}
{'type': 'l2update', 'product_id': 'BTC-USD', 'changes': [['buy', '38382.20', '0.06573000']], 'time': '2021-05-20T03:56:22.219313Z'}
{'type': 'l2update', 'product_id': 'BTC-USD', 'changes': [['sell', '38382.21', '0.33000000']], 'time': '2021-05-20T03:56:22.225037Z'}
{'type': 'l2update', 'product_id': 'BTC-USD', 'changes': [['sell', '38550.22', '0.01000000']], 'time': '2021-05-20T03:56:22.236523Z'}
{'type': 'l2update', 'product_id': 'BTC-USD', 'changes': [['sell', '38438.63', '0.61482417']], 'time': '2021-05-20T03:56:22.236548Z'}
{'type': 'l2update', 'product_id': 'BTC-USD', 'changes': [['buy', '38282.28', '0.02669354']], 'time': '2021-05-20T03:56:22.240159Z'}
{'type': 'l2update', 'product_id': 'BTC-USD', 'changes': [['sell', '38502.34', '0.01000000']], 'time': '2021-05-20T03:56:22.240298Z'}
{'type': 'l2update', 'product_id': 'BTC-USD', 'changes': [['buy', '38331.45', '0.10000000']], 'time': '2021-05-20T03:56:22.240507Z'}
{'type': 'l2update', 'product_id': 'BTC-USD', 'changes': [['buy', '38356.23', '0.06435602']], 'time': '2021-05-20T03:56:22.241885Z'}
{'type': 'l2update', 'product_id': 'BTC-USD', 'changes': [['sell', '38397.33', '0.05520632']], 'time': '2021-05-20T03:56:22.241885Z'}
{'type': 'l2update', 'product_id': 'BTC-USD', 'changes': [['buy', '38329.14', '0.09019730']], 'time': '2021-05-20T03:56:22.241992Z'}
{'type': 'l2update', 'product_id': 'BTC-USD', 'changes': [['sell', '38483.81', '0.00000000']], 'time': '2021-05-20T03:56:22.244095Z'}
{'type': 'l2update', 'product_id': 'BTC-USD', 'changes': [['buy', '38347.41', '0.00000000']], 'time': '2021-05-20T03:56:22.245460Z'}
{'type': 'l2update', 'product_id': 'BTC-USD', 'changes': [['sell', '38418.43', '0.06020080']], 'time': '2021-05-20T03:56:22.249484Z'}
{'type': 'l2update', 'product_id': 'BTC-USD', 'changes': [['buy', '38352.50', '0.78184483']], 'time': '2021-05-20T03:56:22.249508Z'}
{'type': 'l2update', 'product_id': 'BTC-USD', 'changes': [['buy', '38364.80', '1.46756192']], 'time': '2021-05-20T03:56:22.250959Z'}
{'type': 'l2update', 'product_id': 'BTC-USD', 'changes': [['buy', '38382.20', '0.65689555']], 'time': '2021-05-20T03:56:22.255398Z'}
{'type': 'l2update', 'product_id': 'BTC-USD', 'changes': [['buy', '38248.48', '0.30097307']], 'time': '2021-05-20T03:56:22.259330Z'}
{'type': 'l2update', 'product_id': 'BTC-USD', 'changes': [['sell', '43100.00', '3.00560000']], 'time': '2021-05-20T03:56:22.262621Z'}
{'type': 'l2update', 'product_id': 'BTC-USD', 'changes': [['buy', '38337.51', '0.01170634']], 'time': '2021-05-20T03:56:22.263646Z'}
{'type': 'l2update', 'product_id': 'BTC-USD', 'changes': [['sell', '38389.09', '0.10000000']], 'time': '2021-05-20T03:56:22.266774Z'}
{'type': 'l2update', 'product_id': 'BTC-USD', 'changes': [['buy', '38173.01', '0.94966326']], 'time': '2021-05-20T03:56:22.266875Z'}
