{'type': 'l2update', 'product_id': 'BTC-USD', 'changes': [['buy', '38258.71', '0.09000000']], 'time': '2021-05-20T03:56:25.282942Z'}
{'type': 'l2update', 'product_id': 'BTC-USD', 'changes': [['sell', '38503.79', '0.00000000']], 'time': '2021-05-20T03:56:25.282965Z'}
{'type': 'l2update', 'product_id': 'BTC-USD', 'changes': [['sell', '38386.50', '0.05117075']], 'time': '2021-05-20T03:56:25.295658Z'}
{'type': 'l2update', 'product_id': 'BTC-USD', 'changes': [['sell', '38488.75', '0.01299081']], 'time': '2021-05-20T03:56:25.300906Z'}
{'type': 'l2update', 'product_id': 'BTC-USD', 'changes': [['buy', '38257.82', '0.05000000']], 'time': '2021-05-20T03:56:25.301188Z'}
{'type': 'l2update', 'product_id': 'BTC-USD', 'changes': [['buy', '38025.67', '0.00000000']], 'time': '2021-05-20T03:56:25.317187Z'}
{'type': 'l2update', 'product_id': 'BTC-USD', 'changes': [['buy', '38346.52', '0.00000000']], 'time': '2021-05-20T03:56:25.349095Z'}
{'type': 'l2update', 'product_id': 'BTC-USD', 'changes': [['buy', '38347.90', '0.04915733']], 'time': '2021-05-20T03:56:25.451094Z'}
{'type': 'l2update', 'product_id': 'BTC-USD', 'changes': [['sell', '38495.81', '0.44717527']], 'time': '2021-05-20T03:56:25.451206Z'}
{'type': 'l2update', 'product_id': 'BTC-USD', 'changes': [['buy', '38038.56', '0.03487500']], 'time': '2021-05-20T03:56:25.451319Z'}
{'type': 'l2update', 'product_id': 'BTC-USD', 'changes': [['sell', '38509.72', '0.80689216']], 'time': '2021-05-20T03:56:25.451714Z'}
{'type': 'l2update', 'product_id': 'BTC-USD', 'changes': [['buy', '33000.00', '122.52970787']], 'time': '2021-05-20T03:56:25.456619Z'}
{'type': 'l2update', 'product_id': 'BTC-USD', 'changes': [['buy', '38206.01', '0.04826223']], 'time': '2021-05-20T03:56:25.457643Z'}
{'type': 'l2update', 'product_id': 'BTC-USD', 'changes': [['buy', '38334.74', '0.01362444']], 'time': '2021-05-20T03:56:25.459012Z'}
{'type': 'l2update', 'product_id': 'BTC-USD', 'changes': [['sell', '38413.04', '0.01000000']], 'time': '2021-05-20T03:56:25.459666Z'}
{'type': 'l2update', 'product_id': 'BTC-USD', 'changes': [['sell', '38397.25', '0.04915733']], 'time': '2021-05-20T03:56:25.462501Z'}
{'type': 'l2update', 'product_id': 'BTC-USD', 'changes': [['sell', '38399.98', '0.00000000']], 'time': '2021-05-20T03:56:25.479652Z'}
{'type': 'l2update', 'product_id': 'BTC-USD', 'changes': [['buy', '38330.54', '0.01000000']], 'time': '2021-05-20T03:56:25.484922Z'}
{'type': 'l2update', 'product_id': 'BTC-USD', 'changes': [['sell', '38404.44', '0.39490432']], 'time': '2021-05-20T03:56:25.486796Z'}
{'type': 'l2update', 'product_id': 'BTC-USD', 'changes': [['buy', '38345.96', '0.00000000']], 'time': '2021-05-20T03:56:25.500801Z'}
{'type': 'l2update', 'product_id': 'BTC-USD', 'changes': [['sell', '38572.18', '0.00000000']], 'time': '2021-05-20T03:56:25.505966Z'}
{'type': 'l2update', 'product_id': 'BTC-USD', 'changes': [['buy', '38258.71', '0.07000000']], 'time': '2021-05-20T03:56:25.521231Z'}
{'type': 'l2update', 'product_id': 'BTC-USD', 'changes': [['sell', '38590.68', '0.01295649']], 'time': '2021-05-20T03:56:25.526052Z'}
{'type': 'l2update', 'product_id': 'BTC-USD', 'changes': [['buy', '38349.06', '0.04915733']], 'time': '2021-05-20T03:56:25.526139Z'}
{'type': 'l2update', 'product_id': 'BTC-USD', 'changes': [['buy', '38258.71', '0.04000000']], 'time': '2021-05-20T03:56:25.529921Z'}
{'type': 'l2update', 'product_id': 'BTC-USD', 'changes': [['sell', '38541.77', '0.00000000']], 'time': '2021-05-20T03:56:25.530627Z'}
{'type': 'l2update', 'product_id': 'BTC-USD', 'changes': [['sell', '38386.45', '0.59200000']], 'time': '2021-05-20T03:56:25.535046Z'}
{'type': 'l2update', 'product_id': 'BTC-USD', 'changes': [['buy', '38349.05', '0.00000000']], 'time': '2021-05-20T03:56:25.535214Z'}
{'type': 'l2update', 'product_id': 'BTC-USD', 'changes': [['sell', '38386.50', '0.00000000']], 'time': '2021-05-20T03:56:25.535214Z'}
{'type': 'l2update', 'product_id': 'BTC-USD', 'changes': [['buy', '38347.90', '0.00000000']], 'time': '2021-05-20T03:56:25.535281Z'}
{'type': 'l2update', 'product_id': 'BTC-USD', 'changes': [['buy', '38258.71', '0.00000000']], 'time': '2021-05-20T03:56:25.536545Z'}
{'type': 'l2update', 'product_id': 'BTC-USD', 'changes': [['buy', '38228.41', '0.00000000']], 'time': '2021-05-20T03:56:25.537535Z'}
{'type': 'l2update', 'product_id': 'BTC-USD', 'changes': [['buy', '38341.54', '0.00000000']], 'time': '2021-05-20T03:56:25.540507Z'}
{'type': 'l2update', 'product_id': 'BTC-USD', 'changes': [['sell', '38530.04', '0.00000000']], 'time': '2021-05-20T03:56:25.541095Z'}
{'type': 'l2update', 'product_id': 'BTC-USD', 'changes': [['buy', '38257.82', '0.00000000']], 'time': '2021-05-20T03:56:25.541591Z'}
{'type': 'l2update', 'product_id': 'BTC-USD', 'changes': [['sell', '38402.53', '0.00000000']], 'time': '2021-05-20T03:56:25.546876Z'}
{'type': 'l2update', 'product_id': 'BTC-USD', 'changes': [['sell', '38526.12', '0.01000000']], 'time': '2021-05-20T03:56:25.550087Z'}
{'type': 'l2update', 'product_id': 'BTC-USD', 'changes': [['sell', '38399.98', '0.04915733']], 'time': '2021-05-20T03:56:25.550481Z'}
{'type': 'l2update', 'product_id': 'BTC-USD', 'changes': [['sell', '38419.96', '0.00000000']], 'time': '2021-05-20T03:56:25.552205Z'}
{'type': 'l2update', 'product_id': 'BTC-USD', 'changes': [['sell', '38640.99', '0.00000000']], 'time': '2021-05-20T03:56:25.558402Z'}
{'type': 'l2update', 'product_id': 'BTC-USD', 'changes': [['buy', '38249.38', '0.02000000']], 'time': '2021-05-20T03:56:25.558971Z'}
{'type': 'l2update', 'product_id': 'BTC-USD', 'changes': [['sell', '38517.20', '0.01783846']], 'time': '2021-05-20T03:56:25.563112Z'}
{'type': 'l2update', 'product_id': 'BTC-USD', 'changes': [['sell', '38438.53', '0.16300000']], 'time': '2021-05-20T03:56:25.563208Z'}
{'type': 'l2update', 'product_id': 'BTC-USD', 'changes': [['sell', '38397.25', '0.00000000']], 'time': '2021-05-20T03:56:25.565796Z'}
{'type': 'l2update', 'product_id': 'BTC-USD', 'changes': [['buy', '38249.03', '0.03000000']], 'time': '2021-05-20T03:56:25.573667Z'}
{'type': 'l2update', 'product_id': 'BTC-USD', 'changes': [['buy', '38349.06', '0.00000000']], 'time': '2021-05-20T03:56:25.580049Z'}
{'type': 'l2update', 'product_id': 'BTC-USD', 'changes': [['sell', '38526.12', '0.00000000']], 'time': '2021-05-20T03:56:25.584306Z'}
{'type': 'l2update', 'product_id': 'BTC-USD', 'changes': [['sell', '38627.53', '0.01000000']], 'time': '2021-05-20T03:56:25.587051Z'}
{'type': 'l2update', 'product_id': 'BTC-USD', 'changes': [['buy', '38246.53', '0.04000000']], 'time': '2021-05-20T03:56:25.587205Z'}
{'type': 'l2update', 'product_id': 'BTC-USD', 'changes': [['buy', '38346.16', '0.05128905']], 'time': '2021-05-20T03:56:25.590920Z'}
{'type': 'l2update', 'product_id': 'BTC-USD', 'changes': [['sell', '38514.22', '0.01000000']], 'time': '2021-05-20T03:56:25.596683Z'}
{'type': 'l2update', 'product_id': 'BTC-USD', 'changes': [['sell', '38399.98', '0.00000000']], 'time': '2021-05-20T03:56:25.599309Z'}
{'type': 'l2update', 'product_id': 'BTC-USD', 'changes': [['buy', '38246.10', '0.05000000']], 'time': '2021-05-20T03:56:25.600126Z'}
{'type': 'l2update', 'product_id': 'BTC-USD', 'changes': [['buy', '38315.47', '0.00000000']], 'time': '2021-05-20T03:56:25.610515Z'}
{'type': 'l2update', 'product_id': 'BTC-USD', 'changes': [['sell', '38396.76', '0.05128905']], 'time': '2021-05-20T03:56:25.616938Z'}
{'type': 'l2update', 'product_id': 'BTC-USD', 'changes': [['buy', '38348.82', '0.00000000']], 'time': '2021-05-20T03:56:25.621719Z'}
{'type': 'l2update', 'product_id': 'BTC-USD', 'changes': [['buy', '38347.96', '0.00000000']], 'time': '2021-05-20T03:56:25.621719Z'}
{'type': 'l2update', 'product_id': 'BTC-USD', 'changes': [['buy', '38346.54', '0.00000000']], 'time': '2021-05-20T03:56:25.621719Z'}
{'type': 'l2update', 'product_id': 'BTC-USD', 'changes': [['sell', '38396.77', '0.55128905']], 'time': '2021-05-20T03:56:25.626003Z'}
{'type': 'l2update', 'product_id': 'BTC-USD', 'changes': [['buy', '38321.46', '0.10000000']], 'time': '2021-05-20T03:56:25.631134Z'}
{'type': 'l2update', 'product_id': 'BTC-USD', 'changes': [['buy', '38343.02', '0.41610000']], 'time': '2021-05-20T03:56:25.637797Z'}
{'type': 'l2update', 'product_id': 'BTC-USD', 'changes': [['sell', '38375.94', '0.36233284']], 'time': '2021-05-20T03:56:25.637865Z'}
{'type': 'l2update', 'product_id': 'BTC-USD', 'changes': [['sell', '38396.77', '0.50000000']], 'time': '2021-05-20T03:56:25.643369Z'}
{'type': 'l2update', 'product_id': 'BTC-USD', 'changes': [['buy', '38354.13', '0.02390000']], 'time': '2021-05-20T03:56:25.646131Z'}
{'type': 'l2update', 'product_id': 'BTC-USD', 'changes': [['buy', '38353.32', '0.02390000']], 'time': '2021-05-20T03:56:25.646131Z'}
{'type': 'l2update', 'product_id': 'BTC-USD', 'changes': [['buy', '38352.51', '0.02390000']], 'time': '2021-05-20T03:56:25.646131Z'}
{'type': 'l2update', 'product_id': 'BTC-USD', 'changes': [['sell', '38396.76', '0.00000000']], 'time': '2021-05-20T03:56:25.648574Z'}
{'type': 'l2update', 'product_id': 'BTC-USD', 'changes': [['sell', '38402.59', '0.42290000']], 'time': '2021-05-20T03:56:25.651802Z'}
{'type': 'l2update', 'product_id': 'BTC-USD', 'changes': [['buy', '38353.32', '0.00000000']], 'time': '2021-05-20T03:56:25.652582Z'}
{'type': 'l2update', 'product_id': 'BTC-USD', 'changes': [['buy', '38352.51', '0.00000000']], 'time': '2021-05-20T03:56:25.652582Z'}
{'type': 'l2update', 'product_id': 'BTC-USD', 'changes': [['buy', '38358.11', '0.00000000']], 'time': '2021-05-20T03:56:25.655911Z'}
{'type': 'l2update', 'product_id': 'BTC-USD', 'changes': [['sell', '38399.98', '0.05128905']], 'time': '2021-05-20T03:56:25.656655Z'}
{'type': 'l2update', 'product_id': 'BTC-USD', 'changes': [['buy', '38354.13', '0.00000000']], 'time': '2021-05-20T03:56:25.659886Z'}
{'type': 'l2update', 'product_id': 'BTC-USD', 'changes': [['buy', '38360.14', '1.46756192']], 'time': '2021-05-20T03:56:25.680693Z'}
{'type': 'l2update', 'product_id': 'BTC-USD', 'changes': [['buy', '38358.51', '0.02390000']], 'time': '2021-05-20T03:56:25.683622Z'}
{'type': 'l2update', 'product_id': 'BTC-USD', 'changes': [['buy', '38357.71', '0.02390000']], 'time': '2021-05-20T03:56:25.683622Z'}
{'type': 'l2update', 'product_id': 'BTC-USD', 'changes': [['buy', '38356.90', '0.02390000']], 'time': '2021-05-20T03:56:25.683622Z'}
{'type': 'l2update', 'product_id': 'BTC-USD', 'changes': [['sell', '38502.34', '0.00000000']], 'time': '2021-05-20T03:56:25.686860Z'}
{'type': 'l2update', 'product_id': 'BTC-USD', 'changes': [['buy', '38358.51', '0.00000000']], 'time': '2021-05-20T03:56:25.690640Z'}
{'type': 'l2update', 'product_id': 'BTC-USD', 'changes': [['sell', '38489.15', '0.03588750']], 'time': '2021-05-20T03:56:25.703211Z'}
{'type': 'l2update', 'product_id': 'BTC-USD', 'changes': [['buy', '38355.64', '0.02390000']], 'time': '2021-05-20T03:56:25.707838Z'}
{'type': 'l2update', 'product_id': 'BTC-USD', 'changes': [['sell', '38403.99', '0.05122255']], 'time': '2021-05-20T03:56:25.711270Z'}
{'type': 'l2update', 'product_id': 'BTC-USD', 'changes': [['sell', '38455.07', '0.19820000']], 'time': '2021-05-20T03:56:25.719419Z'}
{'type': 'l2update', 'product_id': 'BTC-USD', 'changes': [['sell', '38378.87', '0.28700000']], 'time': '2021-05-20T03:56:25.728780Z'}
{'type': 'l2update', 'product_id': 'BTC-USD', 'changes': [['sell', '38488.75', '0.00000000']], 'time': '2021-05-20T03:56:25.735027Z'}
{'type': 'l2update', 'product_id': 'BTC-USD', 'changes': [['sell', '38396.76', '0.05128905']], 'time': '2021-05-20T03:56:25.743429Z'}
{'type': 'l2update', 'product_id': 'BTC-USD', 'changes': [['sell', '38473.71', '0.01299588']], 'time': '2021-05-20T03:56:25.747364Z'}
{'type': 'l2update', 'product_id': 'BTC-USD', 'changes': [['sell', '38399.98', '0.00000000']], 'time': '2021-05-20T03:56:25.748272Z'}
{'type': 'l2update', 'product_id': 'BTC-USD', 'changes': [['buy', '38345.60', '0.05365572']], 'time': '2021-05-20T03:56:25.760217Z'}
{'type': 'l2update', 'product_id': 'BTC-USD', 'changes': [['sell', '38390.81', '0.05096545']], 'time': '2021-05-20T03:56:25.760217Z'}
{'type': 'l2update', 'product_id': 'BTC-USD', 'changes': [['buy', '38343.02', '0.00000000']], 'time': '2021-05-20T03:56:25.784073Z'}
{'type': 'l2update', 'product_id': 'BTC-USD', 'changes': [['sell', '38402.59', '0.00000000']], 'time': '2021-05-20T03:56:25.788176Z'}
{'type': 'l2update', 'product_id': 'BTC-USD', 'changes': [['sell', '39152.26', '0.00000000']], 'time': '2021-05-20T03:56:25.797041Z'}
{'type': 'l2update', 'product_id': 'BTC-USD', 'changes': [['buy', '38347.41', '0.43690000']], 'time': '2021-05-20T03:56:25.800551Z'}
{'type': 'l2update', 'product_id': 'BTC-USD', 'changes': [['buy', '38346.16', '0.00000000']], 'time': '2021-05-20T03:56:25.806918Z'}
{'type': 'l2update', 'product_id': 'BTC-USD', 'changes': [['sell', '38398.67', '0.42350000']], 'time': '2021-05-20T03:56:25.811746Z'}
{'type': 'l2update', 'product_id': 'BTC-USD', 'changes': [['buy', '38347.42', '0.05128905']], 'time': '2021-05-20T03:56:25.811849Z'}
{'type': 'l2update', 'product_id': 'BTC-USD', 'changes': [['buy', '38345.60', '0.00000000']], 'time': '2021-05-20T03:56:25.814219Z'}
{'type': 'l2update', 'product_id': 'BTC-USD', 'changes': [['sell', '38390.81', '0.00000000']], 'time': '2021-05-20T03:56:25.814219Z'}
{'type': 'l2update', 'product_id': 'BTC-USD', 'changes': [['buy', '38347.41', '0.00000000']], 'time': '2021-05-20T03:56:25.816016Z'}
{'type': 'l2update', 'product_id': 'BTC-USD', 'changes': [['sell', '38398.67', '0.00000000']], 'time': '2021-05-20T03:56:25.819885Z'}
{'type': 'l2update', 'product_id': 'BTC-USD', 'changes': [['sell', '38497.44', '0.00000000']], 'time': '2021-05-20T03:56:25.834376Z'}
{'type': 'l2update', 'product_id': 'BTC-USD', 'changes': [['buy', '38349.47', '0.06083042']], 'time': '2021-05-20T03:56:25.840450Z'}
{'type': 'l2update', 'product_id': 'BTC-USD', 'changes': [['sell', '38390.39', '0.05099539']], 'time': '2021-05-20T03:56:25.840450Z'}
{'type': 'l2update', 'product_id': 'BTC-USD', 'changes': [['sell', '38485.85', '0.01330000']], 'time': '2021-05-20T03:56:25.846213Z'}
{'type': 'l2update', 'product_id': 'BTC-USD', 'changes': [['buy', '38347.42', '0.00000000']], 'time': '2021-05-20T03:56:25.847819Z'}
{'type': 'l2update', 'product_id': 'BTC-USD', 'changes': [['buy', '38349.48', '0.05128905']], 'time': '2021-05-20T03:56:25.852484Z'}
{'type': 'l2update', 'product_id': 'BTC-USD', 'changes': [['buy', '38291.89', '0.00000000']], 'time': '2021-05-20T03:56:25.866476Z'}
{'type': 'l2update', 'product_id': 'BTC-USD', 'changes': [['sell', '39499.99', '0.06640000']], 'time': '2021-05-20T03:56:25.869314Z'}
{'type': 'l2update', 'product_id': 'BTC-USD', 'changes': [['buy', '37279.26', '0.00000000']], 'time': '2021-05-20T03:56:25.869314Z'}
{'type': 'l2update', 'product_id': 'BTC-USD', 'changes': [['sell', '39449.99', '0.04620000']], 'time': '2021-05-20T03:56:25.876845Z'}
{'type': 'l2update', 'product_id': 'BTC-USD', 'changes': [['sell', '38422.18', '0.50000000']], 'time': '2021-05-20T03:56:25.880256Z'}
{'type': 'l2update', 'product_id': 'BTC-USD', 'changes': [['sell', '38404.44', '0.00000000']], 'time': '2021-05-20T03:56:25.895387Z'}
{'type': 'l2update', 'product_id': 'BTC-USD', 'changes': [['buy', '37811.48', '0.00000000']], 'time': '2021-05-20T03:56:25.904190Z'}
{'type': 'l2update', 'product_id': 'BTC-USD', 'changes': [['buy', '38347.91', '0.42060000']], 'time': '2021-05-20T03:56:25.908773Z'}
{'type': 'l2update', 'product_id': 'BTC-USD', 'changes': [['sell', '38398.95', '0.45440000']], 'time': '2021-05-20T03:56:25.920718Z'}
{'type': 'l2update', 'product_id': 'BTC-USD', 'changes': [['sell', '38413.04', '0.00000000']], 'time': '2021-05-20T03:56:25.942012Z'}
{'type': 'l2update', 'product_id': 'BTC-USD', 'changes': [['buy', '38330.54', '0.00000000']], 'time': '2021-05-20T03:56:25.946946Z'}
{'type': 'l2update', 'product_id': 'BTC-USD', 'changes': [['sell', '38422.92', '0.00000000']], 'time': '2021-05-20T03:56:26.011173Z'}
{'type': 'l2update', 'product_id': 'BTC-USD', 'changes': [['buy', '38337.12', '0.00000000']], 'time': '2021-05-20T03:56:26.020383Z'}
{'type': 'l2update', 'product_id': 'BTC-USD', 'changes': [['sell', '38590.68', '0.00000000']], 'time': '2021-05-20T03:56:26.021140Z'}
{'type': 'l2update', 'product_id': 'BTC-USD', 'changes': [['buy', '38312.51', '0.49439109']], 'time': '2021-05-20T03:56:26.027664Z'}
{'type': 'l2update', 'product_id': 'BTC-USD', 'changes': [['sell', '38562.93', '0.01296581']], 'time': '2021-05-20T03:56:26.035572Z'}
{'type': 'l2update', 'product_id': 'BTC-USD', 'changes': [['sell', '38437.57', '0.06600000']], 'time': '2021-05-20T03:56:26.048430Z'}
{'type': 'l2update', 'product_id': 'BTC-USD', 'changes': [['buy', '38303.84', '0.05439471']], 'time': '2021-05-20T03:56:26.092511Z'}
{'type': 'l2update', 'product_id': 'BTC-USD', 'changes': [['buy', '37877.04', '0.00066061']], 'time': '2021-05-20T03:56:26.097147Z'}
{'type': 'l2update', 'product_id': 'BTC-USD', 'changes': [['sell', '38382.22', '0.59200000']], 'time': '2021-05-20T03:56:26.117080Z'}
{'type': 'l2update', 'product_id': 'BTC-USD', 'changes': [['sell', '38454.88', '0.00000000']], 'time': '2021-05-20T03:56:26.124419Z'}
{'type': 'l2update', 'product_id': 'BTC-USD', 'changes': [['sell', '38562.93', '0.00000000']], 'time': '2021-05-20T03:56:26.131822Z'}
{'type': 'l2update', 'product_id': 'BTC-USD', 'changes': [['sell', '38467.89', '0.01299760']], 'time': '2021-05-20T03:56:26.137090Z'}
{'type': 'l2update', 'product_id': 'BTC-USD', 'changes': [['sell', '38378.87', '0.00000000']], 'time': '2021-05-20T03:56:26.137527Z'}
{'type': 'l2update', 'product_id': 'BTC-USD', 'changes': [['buy', '30000.00', '497.99370624']], 'time': '2021-05-20T03:56:26.142567Z'}
{'type': 'l2update', 'product_id': 'BTC-USD', 'changes': [['sell', '38538.07', '0.01000000']], 'time': '2021-05-20T03:56:26.145699Z'}
{'type': 'l2update', 'product_id': 'BTC-USD', 'changes': [['sell', '38538.93', '0.01297389']], 'time': '2021-05-20T03:56:26.145823Z'}
{'type': 'l2update', 'product_id': 'BTC-USD', 'changes': [['sell', '38390.39', '0.00000000']], 'time': '2021-05-20T03:56:26.148057Z'}
{'type': 'l2update', 'product_id': 'BTC-USD', 'changes': [['buy', '38249.38', '0.00000000']], 'time': '2021-05-20T03:56:26.148969Z'}
{'type': 'l2update', 'product_id': 'BTC-USD', 'changes': [['sell', '38377.17', '0.28600000']], 'time': '2021-05-20T03:56:26.150436Z'}
{'type': 'l2update', 'product_id': 'BTC-USD', 'changes': [['buy', '38249.03', '0.00000000']], 'time': '2021-05-20T03:56:26.152753Z'}
{'type': 'l2update', 'product_id': 'BTC-USD', 'changes': [['buy', '38246.53', '0.00000000']], 'time': '2021-05-20T03:56:26.155833Z'}
{'type': 'l2update', 'product_id': 'BTC-USD', 'changes': [['buy', '38246.10', '0.00000000']], 'time': '2021-05-20T03:56:26.159331Z'}
{'type': 'l2update', 'product_id': 'BTC-USD', 'changes': [['sell', '38395.10', '0.06136238']], 'time': '2021-05-20T03:56:26.169883Z'}
{'type': 'l2update', 'product_id': 'BTC-USD', 'changes': [['buy', '38262.81', '0.02000000']], 'time': '2021-05-20T03:56:26.169954Z'}
{'type': 'l2update', 'product_id': 'BTC-USD', 'changes': [['sell', '38382.28', '0.00000000']], 'time': '2021-05-20T03:56:26.175442Z'}
{'type': 'l2update', 'product_id': 'BTC-USD', 'changes': [['sell', '38375.94', '0.17000000']], 'time': '2021-05-20T03:56:26.178414Z'}
{'type': 'l2update', 'product_id': 'BTC-USD', 'changes': [['buy', '38347.91', '0.00000000']], 'time': '2021-05-20T03:56:26.179281Z'}
{'type': 'l2update', 'product_id': 'BTC-USD', 'changes': [['buy', '38349.47', '0.00000000']], 'time': '2021-05-20T03:56:26.180715Z'}
{'type': 'l2update', 'product_id': 'BTC-USD', 'changes': [['buy', '38262.81', '0.05000000']], 'time': '2021-05-20T03:56:26.180750Z'}
{'type': 'l2update', 'product_id': 'BTC-USD', 'changes': [['buy', '38375.13', '0.04939660']], 'time': '2021-05-20T03:56:26.181048Z'}
{'type': 'l2update', 'product_id': 'BTC-USD', 'changes': [['sell', '38375.94', '0.07000000']], 'time': '2021-05-20T03:56:26.183314Z'}
{'type': 'l2update', 'product_id': 'BTC-USD', 'changes': [['sell', '38501.99', '0.00000000']], 'time': '2021-05-20T03:56:26.185568Z'}
{'type': 'l2update', 'product_id': 'BTC-USD', 'changes': [['sell', '38538.93', '0.00000000']], 'time': '2021-05-20T03:56:26.187176Z'}
{'type': 'l2update', 'product_id': 'BTC-USD', 'changes': [['buy', '38349.48', '0.00000000']], 'time': '2021-05-20T03:56:26.187548Z'}
{'type': 'l2update', 'product_id': 'BTC-USD', 'changes': [['buy', '38262.81', '0.09000000']], 'time': '2021-05-20T03:56:26.190146Z'}
{'type': 'l2update', 'product_id': 'BTC-USD', 'changes': [['buy', '38350.78', '0.44110000']], 'time': '2021-05-20T03:56:26.190273Z'}
{'type': 'l2update', 'product_id': 'BTC-USD', 'changes': [['buy', '38346.16', '0.05128905']], 'time': '2021-05-20T03:56:26.193258Z'}
{'type': 'l2update', 'product_id': 'BTC-USD', 'changes': [['buy', '38350.78', '0.00000000']], 'time': '2021-05-20T03:56:26.194414Z'}
{'type': 'l2update', 'product_id': 'BTC-USD', 'changes': [['sell', '38520.26', '0.01000000']], 'time': '2021-05-20T03:56:26.197409Z'}
{'type': 'l2update', 'product_id': 'BTC-USD', 'changes': [['sell', '38396.76', '0.00000000']], 'time': '2021-05-20T03:56:26.198334Z'}
{'type': 'l2update', 'product_id': 'BTC-USD', 'changes': [['sell', '38530.51', '0.00000000']], 'time': '2021-05-20T03:56:26.199955Z'}
{'type': 'l2update', 'product_id': 'BTC-USD', 'changes': [['sell', '38398.94', '0.05128905']], 'time': '2021-05-20T03:56:26.200792Z'}
{'type': 'l2update', 'product_id': 'BTC-USD', 'changes': [['buy', '38349.49', '0.05128905']], 'time': '2021-05-20T03:56:26.200937Z'}
{'type': 'l2update', 'product_id': 'BTC-USD', 'changes': [['buy', '38262.81', '0.14000000']], 'time': '2021-05-20T03:56:26.201154Z'}
{'type': 'l2update', 'product_id': 'BTC-USD', 'changes': [['sell', '38526.93', '0.01297793']], 'time': '2021-05-20T03:56:26.201256Z'}
{'type': 'l2update', 'product_id': 'BTC-USD', 'changes': [['buy', '38346.16', '0.00000000']], 'time': '2021-05-20T03:56:26.203490Z'}
{'type': 'l2update', 'product_id': 'BTC-USD', 'changes': [['buy', '38349.49', '0.00000000']], 'time': '2021-05-20T03:56:26.207214Z'}
{'type': 'l2update', 'product_id': 'BTC-USD', 'changes': [['sell', '38515.66', '0.01000000']], 'time': '2021-05-20T03:56:26.211956Z'}
{'type': 'l2update', 'product_id': 'BTC-USD', 'changes': [['sell', '38398.95', '0.00000000']], 'time': '2021-05-20T03:56:26.212595Z'}
{'type': 'l2update', 'product_id': 'BTC-USD', 'changes': [['sell', '43100.00', '1.09530000']], 'time': '2021-05-20T03:56:26.215840Z'}
{'type': 'l2update', 'product_id': 'BTC-USD', 'changes': [['sell', '38377.17', '0.00000000']], 'time': '2021-05-20T03:56:26.215997Z'}
{'type': 'l2update', 'product_id': 'BTC-USD', 'changes': [['buy', '38351.05', '0.06361890']], 'time': '2021-05-20T03:56:26.216074Z'}
{'type': 'l2update', 'product_id': 'BTC-USD', 'changes': [['buy', '38351.29', '0.05128905']], 'time': '2021-05-20T03:56:26.216438Z'}
{'type': 'l2update', 'product_id': 'BTC-USD', 'changes': [['sell', '38401.28', '0.43130000']], 'time': '2021-05-20T03:56:26.223296Z'}
{'type': 'l2update', 'product_id': 'BTC-USD', 'changes': [['sell', '38395.10', '0.00000000']], 'time': '2021-05-20T03:56:26.227491Z'}
{'type': 'l2update', 'product_id': 'BTC-USD', 'changes': [['sell', '38401.28', '0.00000000']], 'time': '2021-05-20T03:56:26.231143Z'}
{'type': 'l2update', 'product_id': 'BTC-USD', 'changes': [['sell', '38382.27', '0.00000000']], 'time': '2021-05-20T03:56:26.231856Z'}
{'type': 'l2update', 'product_id': 'BTC-USD', 'changes': [['sell', '43100.00', '1.34420000']], 'time': '2021-05-20T03:56:26.239444Z'}
{'type': 'l2update', 'product_id': 'BTC-USD', 'changes': [['sell', '38386.44', '2.48969908']], 'time': '2021-05-20T03:56:26.247354Z'}
{'type': 'l2update', 'product_id': 'BTC-USD', 'changes': [['sell', '38387.17', '0.00000000']], 'time': '2021-05-20T03:56:26.258895Z'}
{'type': 'l2update', 'product_id': 'BTC-USD', 'changes': [['sell', '38375.94', '0.06870285']], 'time': '2021-05-20T03:56:26.263137Z'}
{'type': 'l2update', 'product_id': 'BTC-USD', 'changes': [['sell', '38396.83', '0.06120175']], 'time': '2021-05-20T03:56:26.263312Z'}
{'type': 'l2update', 'product_id': 'BTC-USD', 'changes': [['sell', '38407.88', '0.00000000']], 'time': '2021-05-20T03:56:26.278162Z'}
{'type': 'l2update', 'product_id': 'BTC-USD', 'changes': [['buy', '38370.68', '0.00000000']], 'time': '2021-05-20T03:56:26.278808Z'}
{'type': 'l2update', 'product_id': 'BTC-USD', 'changes': [['sell', '38382.22', '0.00000000']], 'time': '2021-05-20T03:56:26.280472Z'}
{'type': 'l2update', 'product_id': 'BTC-USD', 'changes': [['sell', '38386.91', '0.05111104']], 'time': '2021-05-20T03:56:26.282846Z'}
{'type': 'l2update', 'product_id': 'BTC-USD', 'changes': [['buy', '38350.31', '0.48140000']], 'time': '2021-05-20T03:56:26.287093Z'}
{'type': 'l2update', 'product_id': 'BTC-USD', 'changes': [['buy', '38363.49', '0.52000000']], 'time': '2021-05-20T03:56:26.287267Z'}
{'type': 'l2update', 'product_id': 'BTC-USD', 'changes': [['buy', '38321.46', '0.00000000']], 'time': '2021-05-20T03:56:26.288591Z'}
{'type': 'l2update', 'product_id': 'BTC-USD', 'changes': [['sell', '38386.39', '0.59200000']], 'time': '2021-05-20T03:56:26.290728Z'}
{'type': 'l2update', 'product_id': 'BTC-USD', 'changes': [['buy', '38351.05', '0.00000000']], 'time': '2021-05-20T03:56:26.291117Z'}
{'type': 'l2update', 'product_id': 'BTC-USD', 'changes': [['buy', '38363.44', '0.00000000']], 'time': '2021-05-20T03:56:26.293447Z'}
{'type': 'l2update', 'product_id': 'BTC-USD', 'changes': [['sell', '38521.90', '0.00000000']], 'time': '2021-05-20T03:56:26.294076Z'}
{'type': 'l2update', 'product_id': 'BTC-USD', 'changes': [['buy', '38318.46', '0.10000000']], 'time': '2021-05-20T03:56:26.300389Z'}
{'type': 'l2update', 'product_id': 'BTC-USD', 'changes': [['sell', '38403.99', '0.00000000']], 'time': '2021-05-20T03:56:26.300826Z'}
{'type': 'l2update', 'product_id': 'BTC-USD', 'changes': [['sell', '38400.12', '0.00000000']], 'time': '2021-05-20T03:56:26.301877Z'}
{'type': 'l2update', 'product_id': 'BTC-USD', 'changes': [['sell', '38533.62', '0.01000000']], 'time': '2021-05-20T03:56:26.306956Z'}
{'type': 'l2update', 'product_id': 'BTC-USD', 'changes': [['buy', '38210.52', '0.04864950']], 'time': '2021-05-20T03:56:26.307018Z'}
{'type': 'l2update', 'product_id': 'BTC-USD', 'changes': [['sell', '38508.35', '0.00000000']], 'time': '2021-05-20T03:56:26.310369Z'}
{'type': 'l2update', 'product_id': 'BTC-USD', 'changes': [['buy', '38066.82', '0.00000000']], 'time': '2021-05-20T03:56:26.312502Z'}
{'type': 'l2update', 'product_id': 'BTC-USD', 'changes': [['buy', '38363.50', '0.59116555']], 'time': '2021-05-20T03:56:26.315627Z'}
{'type': 'l2update', 'product_id': 'BTC-USD', 'changes': [['sell', '38380.87', '0.28700000']], 'time': '2021-05-20T03:56:26.315748Z'}
{'type': 'l2update', 'product_id': 'BTC-USD', 'changes': [['sell', '38408.85', '0.05190093']], 'time': '2021-05-20T03:56:26.319459Z'}
{'type': 'l2update', 'product_id': 'BTC-USD', 'changes': [['sell', '38407.51', '0.45840000']], 'time': '2021-05-20T03:56:26.322906Z'}
{'type': 'l2update', 'product_id': 'BTC-USD', 'changes': [['sell', '38521.71', '2.88203011']], 'time': '2021-05-20T03:56:26.322933Z'}
{'type': 'l2update', 'product_id': 'BTC-USD', 'changes': [['buy', '38123.81', '0.01311516']], 'time': '2021-05-20T03:56:26.323321Z'}
{'type': 'l2update', 'product_id': 'BTC-USD', 'changes': [['sell', '38420.66', '0.01000000']], 'time': '2021-05-20T03:56:26.330884Z'}
{'type': 'l2update', 'product_id': 'BTC-USD', 'changes': [['buy', '38338.15', '0.01000000']], 'time': '2021-05-20T03:56:26.342888Z'}
{'type': 'l2update', 'product_id': 'BTC-USD', 'changes': [['sell', '38473.71', '0.00000000']], 'time': '2021-05-20T03:56:26.351071Z'}
{'type': 'l2update', 'product_id': 'BTC-USD', 'changes': [['buy', '38351.05', '0.04633787']], 'time': '2021-05-20T03:56:26.354797Z'}
{'type': 'l2update', 'product_id': 'BTC-USD', 'changes': [['sell', '38396.83', '0.00000000']], 'time': '2021-05-20T03:56:26.361237Z'}
{'type': 'l2update', 'product_id': 'BTC-USD', 'changes': [['buy', '38265.77', '0.00000000']], 'time': '2021-05-20T03:56:26.361563Z'}
{'type': 'l2update', 'product_id': 'BTC-USD', 'changes': [['sell', '38458.67', '0.33379259']], 'time': '2021-05-20T03:56:26.364769Z'}
{'type': 'l2update', 'product_id': 'BTC-USD', 'changes': [['buy', '38367.87', '0.00000000']], 'time': '2021-05-20T03:56:26.370238Z'}
{'type': 'l2update', 'product_id': 'BTC-USD', 'changes': [['sell', '38395.64', '0.04291981']], 'time': '2021-05-20T03:56:26.385654Z'}
{'type': 'l2update', 'product_id': 'BTC-USD', 'changes': [['buy', '38251.62', '0.01000000']], 'time': '2021-05-20T03:56:26.385733Z'}
{'type': 'l2update', 'product_id': 'BTC-USD', 'changes': [['sell', '38538.07', '0.00000000']], 'time': '2021-05-20T03:56:26.388974Z'}
{'type': 'l2update', 'product_id': 'BTC-USD', 'changes': [['buy', '38373.67', '0.07103321']], 'time': '2021-05-20T03:56:26.399085Z'}
{'type': 'l2update', 'product_id': 'BTC-USD', 'changes': [['sell', '38558.77', '0.01000000']], 'time': '2021-05-20T03:56:26.401803Z'}
{'type': 'l2update', 'product_id': 'BTC-USD', 'changes': [['sell', '38558.77', '0.00000000']], 'time': '2021-05-20T03:56:26.417410Z'}
{'type': 'l2update', 'product_id': 'BTC-USD', 'changes': [['buy', '38351.05', '0.00000000']], 'time': '2021-05-20T03:56:26.418427Z'}
{'type': 'l2update', 'product_id': 'BTC-USD', 'changes': [['buy', '38375.93', '0.15573000']], 'time': '2021-05-20T03:56:26.427470Z'}
{'type': 'l2update', 'product_id': 'BTC-USD', 'changes': [['sell', '38573.83', '0.01000000']], 'time': '2021-05-20T03:56:26.427533Z'}
{'type': 'l2update', 'product_id': 'BTC-USD', 'changes': [['buy', '38350.31', '0.00000000']], 'time': '2021-05-20T03:56:26.440241Z'}
{'type': 'l2update', 'product_id': 'BTC-USD', 'changes': [['sell', '38396.77', '0.00000000']], 'time': '2021-05-20T03:56:26.443366Z'}
{'type': 'l2update', 'product_id': 'BTC-USD', 'changes': [['sell', '38407.51', '0.00000000']], 'time': '2021-05-20T03:56:26.444356Z'}
{'type': 'l2update', 'product_id': 'BTC-USD', 'changes': [['buy', '38375.93', '0.20573000']], 'time': '2021-05-20T03:56:26.445261Z'}
{'type': 'l2update', 'product_id': 'BTC-USD', 'changes': [['sell', '38386.38', '0.50000000']], 'time': '2021-05-20T03:56:26.456659Z'}
{'type': 'l2update', 'product_id': 'BTC-USD', 'changes': [['sell', '38406.50', '0.05128905']], 'time': '2021-05-20T03:56:26.460072Z'}
{'type': 'l2update', 'product_id': 'BTC-USD', 'changes': [['sell', '38398.94', '0.00000000']], 'time': '2021-05-20T03:56:26.464862Z'}
{'type': 'l2update', 'product_id': 'BTC-USD', 'changes': [['buy', '38375.93', '0.30573000']], 'time': '2021-05-20T03:56:26.464937Z'}
{'type': 'l2update', 'product_id': 'BTC-USD', 'changes': [['sell', '38386.38', '0.00000000']], 'time': '2021-05-20T03:56:26.464968Z'}
{'type': 'l2update', 'product_id': 'BTC-USD', 'changes': [['sell', '38406.50', '0.00000000']], 'time': '2021-05-20T03:56:26.466287Z'}
{'type': 'l2update', 'product_id': 'BTC-USD', 'changes': [['sell', '38399.98', '0.05128905']], 'time': '2021-05-20T03:56:26.477562Z'}
{'type': 'l2update', 'product_id': 'BTC-USD', 'changes': [['sell', '38398.93', '0.50000000']], 'time': '2021-05-20T03:56:26.481748Z'}
{'type': 'l2update', 'product_id': 'BTC-USD', 'changes': [['sell', '38399.98', '0.00000000']], 'time': '2021-05-20T03:56:26.490897Z'}
{'type': 'l2update', 'product_id': 'BTC-USD', 'changes': [['sell', '38406.50', '0.05128905']], 'time': '2021-05-20T03:56:26.494334Z'}
{'type': 'l2update', 'product_id': 'BTC-USD', 'changes': [['sell', '38380.87', '0.00000000']], 'time': '2021-05-20T03:56:26.514751Z'}
{'type': 'l2update', 'product_id': 'BTC-USD', 'changes': [['buy', '38349.64', '0.44870000']], 'time': '2021-05-20T03:56:26.529680Z'}
{'type': 'l2update', 'product_id': 'BTC-USD', 'changes': [['buy', '38258.89', '0.00000000']], 'time': '2021-05-20T03:56:26.537890Z'}
{'type': 'l2update', 'product_id': 'BTC-USD', 'changes': [['sell', '38382.47', '0.28700000']], 'time': '2021-05-20T03:56:26.541969Z'}
{'type': 'l2update', 'product_id': 'BTC-USD', 'changes': [['buy', '38312.51', '0.00000000']], 'time': '2021-05-20T03:56:26.545745Z'}
{'type': 'l2update', 'product_id': 'BTC-USD', 'changes': [['buy', '38346.16', '0.68281243']], 'time': '2021-05-20T03:56:26.546325Z'}
{'type': 'l2update', 'product_id': 'BTC-USD', 'changes': [['sell', '38407.51', '0.40290000']], 'time': '2021-05-20T03:56:26.546457Z'}
{'type': 'l2update', 'product_id': 'BTC-USD', 'changes': [['buy', '38349.64', '0.00000000']], 'time': '2021-05-20T03:56:26.554824Z'}
{'type': 'l2update', 'product_id': 'BTC-USD', 'changes': [['buy', '38356.92', '0.00000000']], 'time': '2021-05-20T03:56:26.558863Z'}
{'type': 'l2update', 'product_id': 'BTC-USD', 'changes': [['buy', '38267.89', '0.01000000']], 'time': '2021-05-20T03:56:26.561519Z'}
{'type': 'l2update', 'product_id': 'BTC-USD', 'changes': [['buy', '38356.93', '0.04655713']], 'time': '2021-05-20T03:56:26.566312Z'}
{'type': 'l2update', 'product_id': 'BTC-USD', 'changes': [['buy', '38344.51', '0.00000000']], 'time': '2021-05-20T03:56:26.571189Z'}
{'type': 'l2update', 'product_id': 'BTC-USD', 'changes': [['buy', '38351.29', '0.00000000']], 'time': '2021-05-20T03:56:26.581147Z'}
{'type': 'l2update', 'product_id': 'BTC-USD', 'changes': [['sell', '38383.51', '0.52134532']], 'time': '2021-05-20T03:56:26.601729Z'}
{'type': 'l2update', 'product_id': 'BTC-USD', 'changes': [['buy', '38351.29', '0.04655713']], 'time': '2021-05-20T03:56:26.610255Z'}
{'type': 'l2update', 'product_id': 'BTC-USD', 'changes': [['buy', '38360.14', '0.00000000']], 'time': '2021-05-20T03:56:26.612866Z'}
{'type': 'l2update', 'product_id': 'BTC-USD', 'changes': [['buy', '38270.30', '0.00000000']], 'time': '2021-05-20T03:56:26.613378Z'}
{'type': 'l2update', 'product_id': 'BTC-USD', 'changes': [['buy', '38356.93', '0.00000000']], 'time': '2021-05-20T03:56:26.625173Z'}
{'type': 'l2update', 'product_id': 'BTC-USD', 'changes': [['sell', '38399.99', '0.76418530']], 'time': '2021-05-20T03:56:26.626340Z'}
{'type': 'l2update', 'product_id': 'BTC-USD', 'changes': [['buy', '38365.88', '0.52127389']], 'time': '2021-05-20T03:56:26.629620Z'}
{'type': 'l2update', 'product_id': 'BTC-USD', 'changes': [['buy', '38357.71', '0.00000000']], 'time': '2021-05-20T03:56:26.640207Z'}
{'type': 'l2update', 'product_id': 'BTC-USD', 'changes': [['sell', '38573.83', '0.00000000']], 'time': '2021-05-20T03:56:26.641389Z'}
{'type': 'l2update', 'product_id': 'BTC-USD', 'changes': [['buy', '38363.51', '1.46756192']], 'time': '2021-05-20T03:56:26.646708Z'}
{'type': 'l2update', 'product_id': 'BTC-USD', 'changes': [['sell', '38406.50', '0.00000000']], 'time': '2021-05-20T03:56:26.648623Z'}
{'type': 'l2update', 'product_id': 'BTC-USD', 'changes': [['buy', '38350.80', '0.49360000']], 'time': '2021-05-20T03:56:26.650723Z'}
{'type': 'l2update', 'product_id': 'BTC-USD', 'changes': [['sell', '38388.03', '0.52135561']], 'time': '2021-05-20T03:56:26.666837Z'}
{'type': 'l2update', 'product_id': 'BTC-USD', 'changes': [['buy', '38365.93', '0.84500000']], 'time': '2021-05-20T03:56:26.671048Z'}
{'type': 'l2update', 'product_id': 'BTC-USD', 'changes': [['sell', '38407.51', '0.00000000']], 'time': '2021-05-20T03:56:26.678018Z'}
{'type': 'l2update', 'product_id': 'BTC-USD', 'changes': [['buy', '38363.50', '0.00000000']], 'time': '2021-05-20T03:56:26.679256Z'}
{'type': 'l2update', 'product_id': 'BTC-USD', 'changes': [['sell', '38560.66', '0.01000000']], 'time': '2021-05-20T03:56:26.679807Z'}
{'type': 'l2update', 'product_id': 'BTC-USD', 'changes': [['buy', '38355.08', '0.02390000']], 'time': '2021-05-20T03:56:26.680032Z'}
{'type': 'l2update', 'product_id': 'BTC-USD', 'changes': [['sell', '38375.94', '0.26870285']], 'time': '2021-05-20T03:56:26.692693Z'}
{'type': 'l2update', 'product_id': 'BTC-USD', 'changes': [['buy', '38346.16', '0.00000000']], 'time': '2021-05-20T03:56:26.696941Z'}
{'type': 'l2update', 'product_id': 'BTC-USD', 'changes': [['sell', '38382.47', '0.00000000']], 'time': '2021-05-20T03:56:26.701193Z'}
{'type': 'l2update', 'product_id': 'BTC-USD', 'changes': [['sell', '38399.99', '0.71762817']], 'time': '2021-05-20T03:56:26.702744Z'}
{'type': 'l2update', 'product_id': 'BTC-USD', 'changes': [['buy', '38329.01', '0.00000000']], 'time': '2021-05-20T03:56:26.704675Z'}
{'type': 'l2update', 'product_id': 'BTC-USD', 'changes': [['buy', '38350.53', '0.78191083']], 'time': '2021-05-20T03:56:26.704702Z'}
{'type': 'l2update', 'product_id': 'BTC-USD', 'changes': [['buy', '38363.51', '0.00000000']], 'time': '2021-05-20T03:56:26.707985Z'}
{'type': 'l2update', 'product_id': 'BTC-USD', 'changes': [['sell', '38409.56', '0.42430000']], 'time': '2021-05-20T03:56:26.709349Z'}
{'type': 'l2update', 'product_id': 'BTC-USD', 'changes': [['sell', '38375.94', '1.40266035']], 'time': '2021-05-20T03:56:26.718139Z'}
{'type': 'l2update', 'product_id': 'BTC-USD', 'changes': [['buy', '38206.01', '0.00000000']], 'time': '2021-05-20T03:56:26.718290Z'}
{'type': 'l2update', 'product_id': 'BTC-USD', 'changes': [['buy', '38365.94', '0.59116555']], 'time': '2021-05-20T03:56:26.722325Z'}
{'type': 'l2update', 'product_id': 'BTC-USD', 'changes': [['sell', '38375.94', '1.50266035']], 'time': '2021-05-20T03:56:26.726936Z'}
{'type': 'l2update', 'product_id': 'BTC-USD', 'changes': [['buy', '38375.13', '0.00000000']], 'time': '2021-05-20T03:56:26.727608Z'}
{'type': 'l2update', 'product_id': 'BTC-USD', 'changes': [['buy', '38210.52', '0.00000000']], 'time': '2021-05-20T03:56:26.728191Z'}
{'type': 'l2update', 'product_id': 'BTC-USD', 'changes': [['sell', '38420.66', '0.00000000']], 'time': '2021-05-20T03:56:26.730895Z'}
{'type': 'l2update', 'product_id': 'BTC-USD', 'changes': [['buy', '38375.93', '0.25573000']], 'time': '2021-05-20T03:56:26.730969Z'}
{'type': 'l2update', 'product_id': 'BTC-USD', 'changes': [['sell', '38464.18', '0.00000000']], 'time': '2021-05-20T03:56:26.732625Z'}
{'type': 'l2update', 'product_id': 'BTC-USD', 'changes': [['buy', '38375.93', '0.10573000']], 'time': '2021-05-20T03:56:26.732705Z'}
{'type': 'l2update', 'product_id': 'BTC-USD', 'changes': [['buy', '38296.99', '0.00000000']], 'time': '2021-05-20T03:56:26.733257Z'}
{'type': 'l2update', 'product_id': 'BTC-USD', 'changes': [['sell', '38420.77', '0.00000000']], 'time': '2021-05-20T03:56:26.733272Z'}
{'type': 'l2update', 'product_id': 'BTC-USD', 'changes': [['buy', '38357.43', '0.00000000']], 'time': '2021-05-20T03:56:26.733309Z'}
{'type': 'l2update', 'product_id': 'BTC-USD', 'changes': [['sell', '38381.47', '0.28700000']], 'time': '2021-05-20T03:56:26.735034Z'}
{'type': 'l2update', 'product_id': 'BTC-USD', 'changes': [['sell', '38401.06', '0.05179558']], 'time': '2021-05-20T03:56:26.735116Z'}
{'type': 'l2update', 'product_id': 'BTC-USD', 'changes': [['sell', '38381.99', '0.04873548']], 'time': '2021-05-20T03:56:26.735223Z'}
{'type': 'l2update', 'product_id': 'BTC-USD', 'changes': [['sell', '38406.49', '0.04655713']], 'time': '2021-05-20T03:56:26.737453Z'}
{'type': 'l2update', 'product_id': 'BTC-USD', 'changes': [['sell', '38396.22', '0.04948389']], 'time': '2021-05-20T03:56:26.737760Z'}
{'type': 'l2update', 'product_id': 'BTC-USD', 'changes': [['sell', '38386.44', '0.00000000']], 'time': '2021-05-20T03:56:26.737818Z'}
{'type': 'l2update', 'product_id': 'BTC-USD', 'changes': [['buy', '38363.49', '0.00000000']], 'time': '2021-05-20T03:56:26.738660Z'}
{'type': 'l2update', 'product_id': 'BTC-USD', 'changes': [['sell', '38409.56', '0.00000000']], 'time': '2021-05-20T03:56:26.739217Z'}
{'type': 'l2update', 'product_id': 'BTC-USD', 'changes': [['sell', '38393.95', '0.78207596']], 'time': '2021-05-20T03:56:26.743007Z'}
{'type': 'l2update', 'product_id': 'BTC-USD', 'changes': [['buy', '38357.39', '0.20655713']], 'time': '2021-05-20T03:56:26.745421Z'}
{'type': 'l2update', 'product_id': 'BTC-USD', 'changes': [['buy', '38375.93', '0.10000000']], 'time': '2021-05-20T03:56:26.745743Z'}
{'type': 'l2update', 'product_id': 'BTC-USD', 'changes': [['buy', '38375.93', '0.00000000']], 'time': '2021-05-20T03:56:26.745743Z'}
{'type': 'l2update', 'product_id': 'BTC-USD', 'changes': [['sell', '38375.93', '0.19997000']], 'time': '2021-05-20T03:56:26.745743Z'}
{'type': 'l2update', 'product_id': 'BTC-USD', 'changes': [['buy', '38358.10', '0.00000000']], 'time': '2021-05-20T03:56:26.748518Z'}
{'type': 'l2update', 'product_id': 'BTC-USD', 'changes': [['buy', '38351.29', '0.00000000']], 'time': '2021-05-20T03:56:26.755502Z'}
{'type': 'l2update', 'product_id': 'BTC-USD', 'changes': [['sell', '38417.47', '0.17600000']], 'time': '2021-05-20T03:56:26.755591Z'}
{'type': 'l2update', 'product_id': 'BTC-USD', 'changes': [['sell', '38378.00', '0.05009495']], 'time': '2021-05-20T03:56:26.759905Z'}
{'type': 'l2update', 'product_id': 'BTC-USD', 'changes': [['sell', '38381.36', '0.00600000']], 'time': '2021-05-20T03:56:26.763200Z'}
{'type': 'l2update', 'product_id': 'BTC-USD', 'changes': [['sell', '38375.49', '1.15943969']], 'time': '2021-05-20T03:56:26.763281Z'}
{'type': 'l2update', 'product_id': 'BTC-USD', 'changes': [['sell', '38401.76', '0.39490432']], 'time': '2021-05-20T03:56:26.763667Z'}
{'type': 'l2update', 'product_id': 'BTC-USD', 'changes': [['buy', '38356.90', '0.00000000']], 'time': '2021-05-20T03:56:26.768932Z'}
{'type': 'l2update', 'product_id': 'BTC-USD', 'changes': [['buy', '38338.15', '0.00000000']], 'time': '2021-05-20T03:56:26.772702Z'}
{'type': 'l2update', 'product_id': 'BTC-USD', 'changes': [['sell', '38375.94', '1.60266035']], 'time': '2021-05-20T03:56:26.773833Z'}
{'type': 'l2update', 'product_id': 'BTC-USD', 'changes': [['buy', '38350.80', '0.00000000']], 'time': '2021-05-20T03:56:26.783092Z'}
{'type': 'l2update', 'product_id': 'BTC-USD', 'changes': [['sell', '38691.17', '0.00000000']], 'time': '2021-05-20T03:56:26.783280Z'}
{'type': 'l2update', 'product_id': 'BTC-USD', 'changes': [['buy', '38359.47', '0.00000000']], 'time': '2021-05-20T03:56:26.787819Z'}
{'type': 'l2update', 'product_id': 'BTC-USD', 'changes': [['sell', '38375.94', '1.60335929']], 'time': '2021-05-20T03:56:26.795454Z'}
{'type': 'l2update', 'product_id': 'BTC-USD', 'changes': [['sell', '38398.74', '0.78196149']], 'time': '2021-05-20T03:56:26.796608Z'}
{'type': 'l2update', 'product_id': 'BTC-USD', 'changes': [['sell', '38399.99', '0.66762817']], 'time': '2021-05-20T03:56:26.799869Z'}
{'type': 'l2update', 'product_id': 'BTC-USD', 'changes': [['sell', '38424.37', '0.00000000']], 'time': '2021-05-20T03:56:26.801620Z'}
{'type': 'l2update', 'product_id': 'BTC-USD', 'changes': [['sell', '38373.68', '0.04330000']], 'time': '2021-05-20T03:56:26.802057Z'}
{'type': 'l2update', 'product_id': 'BTC-USD', 'changes': [['sell', '38386.91', '0.00000000']], 'time': '2021-05-20T03:56:26.802262Z'}
{'type': 'l2update', 'product_id': 'BTC-USD', 'changes': [['sell', '38373.68', '0.11790000']], 'time': '2021-05-20T03:56:26.802521Z'}
{'type': 'l2update', 'product_id': 'BTC-USD', 'changes': [['sell', '38560.66', '0.00000000']], 'time': '2021-05-20T03:56:26.806345Z'}
{'type': 'l2update', 'product_id': 'BTC-USD', 'changes': [['sell', '38373.68', '0.13282000']], 'time': '2021-05-20T03:56:26.809902Z'}
{'type': 'l2update', 'product_id': 'BTC-USD', 'changes': [['buy', '38365.94', '0.00000000']], 'time': '2021-05-20T03:56:26.810065Z'}
{'type': 'l2update', 'product_id': 'BTC-USD', 'changes': [['buy', '38204.30', '0.11490000']], 'time': '2021-05-20T03:56:26.810152Z'}
{'type': 'l2update', 'product_id': 'BTC-USD', 'changes': [['sell', '38373.68', '0.24662000']], 'time': '2021-05-20T03:56:26.810354Z'}
{'type': 'l2update', 'product_id': 'BTC-USD', 'changes': [['buy', '38373.67', '0.00000000']], 'time': '2021-05-20T03:56:26.815131Z'}
{'type': 'l2update', 'product_id': 'BTC-USD', 'changes': [['buy', '38239.26', '0.48273767']], 'time': '2021-05-20T03:56:26.822215Z'}
{'type': 'l2update', 'product_id': 'BTC-USD', 'changes': [['buy', '38176.39', '0.00000000']], 'time': '2021-05-20T03:56:26.822677Z'}
{'type': 'l2update', 'product_id': 'BTC-USD', 'changes': [['sell', '38432.97', '0.35567087']], 'time': '2021-05-20T03:56:26.828364Z'}
{'type': 'l2update', 'product_id': 'BTC-USD', 'changes': [['sell', '38399.98', '0.04655713']], 'time': '2021-05-20T03:56:26.830183Z'}
{'type': 'l2update', 'product_id': 'BTC-USD', 'changes': [['sell', '38379.42', '2.48969908']], 'time': '2021-05-20T03:56:26.830930Z'}
{'type': 'l2update', 'product_id': 'BTC-USD', 'changes': [['buy', '38365.93', '0.00000000']], 'time': '2021-05-20T03:56:26.831044Z'}
{'type': 'l2update', 'product_id': 'BTC-USD', 'changes': [['buy', '38365.88', '0.00000000']], 'time': '2021-05-20T03:56:26.831044Z'}
{'type': 'l2update', 'product_id': 'BTC-USD', 'changes': [['sell', '38398.93', '0.00000000']], 'time': '2021-05-20T03:56:26.833073Z'}
{'type': 'l2update', 'product_id': 'BTC-USD', 'changes': [['sell', '38533.62', '0.00000000']], 'time': '2021-05-20T03:56:26.833974Z'}
{'type': 'l2update', 'product_id': 'BTC-USD', 'changes': [['sell', '38375.37', '1.04476983']], 'time': '2021-05-20T03:56:26.843018Z'}
{'type': 'l2update', 'product_id': 'BTC-USD', 'changes': [['sell', '38422.18', '0.00000000']], 'time': '2021-05-20T03:56:26.847496Z'}
{'type': 'l2update', 'product_id': 'BTC-USD', 'changes': [['buy', '38355.64', '0.00000000']], 'time': '2021-05-20T03:56:26.851460Z'}
{'type': 'l2update', 'product_id': 'BTC-USD', 'changes': [['buy', '38355.08', '0.00000000']], 'time': '2021-05-20T03:56:26.851460Z'}
{'type': 'l2update', 'product_id': 'BTC-USD', 'changes': [['sell', '38474.61', '0.00000000']], 'time': '2021-05-20T03:56:26.854161Z'}
{'type': 'l2update', 'product_id': 'BTC-USD', 'changes': [['sell', '38375.93', '0.39997000']], 'time': '2021-05-20T03:56:26.861493Z'}
{'type': 'l2update', 'product_id': 'BTC-USD', 'changes': [['sell', '38381.99', '0.00000000']], 'time': '2021-05-20T03:56:26.863241Z'}
{'type': 'l2update', 'product_id': 'BTC-USD', 'changes': [['sell', '38427.94', '0.02970825']], 'time': '2021-05-20T03:56:26.866904Z'}
{'type': 'l2update', 'product_id': 'BTC-USD', 'changes': [['sell', '38423.76', '0.03317846']], 'time': '2021-05-20T03:56:26.866904Z'}
{'type': 'l2update', 'product_id': 'BTC-USD', 'changes': [['sell', '38423.76', '0.00000000']], 'time': '2021-05-20T03:56:26.866904Z'}
{'type': 'l2update', 'product_id': 'BTC-USD', 'changes': [['buy', '38359.39', '0.00000000']], 'time': '2021-05-20T03:56:26.868205Z'}
{'type': 'l2update', 'product_id': 'BTC-USD', 'changes': [['sell', '38381.65', '0.05000000']], 'time': '2021-05-20T03:56:26.872089Z'}
{'type': 'l2update', 'product_id': 'BTC-USD', 'changes': [['sell', '38373.68', '0.22745234']], 'time': '2021-05-20T03:56:26.873662Z'}
{'type': 'l2update', 'product_id': 'BTC-USD', 'changes': [['buy', '38267.89', '0.00000000']], 'time': '2021-05-20T03:56:26.873879Z'}
{'type': 'l2update', 'product_id': 'BTC-USD', 'changes': [['buy', '38312.10', '0.00000000']], 'time': '2021-05-20T03:56:26.879370Z'}
{'type': 'l2update', 'product_id': 'BTC-USD', 'changes': [['sell', '38375.93', '0.40570000']], 'time': '2021-05-20T03:56:26.883148Z'}
{'type': 'l2update', 'product_id': 'BTC-USD', 'changes': [['sell', '38406.38', '1.30326915']], 'time': '2021-05-20T03:56:26.883687Z'}
{'type': 'l2update', 'product_id': 'BTC-USD', 'changes': [['sell', '38398.92', '0.05000000']], 'time': '2021-05-20T03:56:26.886655Z'}
{'type': 'l2update', 'product_id': 'BTC-USD', 'changes': [['sell', '38455.07', '0.00000000']], 'time': '2021-05-20T03:56:26.892601Z'}
{'type': 'l2update', 'product_id': 'BTC-USD', 'changes': [['sell', '38373.68', '0.15285234']], 'time': '2021-05-20T03:56:26.894060Z'}
{'type': 'l2update', 'product_id': 'BTC-USD', 'changes': [['sell', '38373.68', '0.13793234']], 'time': '2021-05-20T03:56:26.895341Z'}
{'type': 'l2update', 'product_id': 'BTC-USD', 'changes': [['sell', '38573.83', '0.01000000']], 'time': '2021-05-20T03:56:26.896073Z'}
{'type': 'l2update', 'product_id': 'BTC-USD', 'changes': [['sell', '38526.93', '0.00000000']], 'time': '2021-05-20T03:56:26.913483Z'}
{'type': 'l2update', 'product_id': 'BTC-USD', 'changes': [['buy', '38340.71', '1.46756192']], 'time': '2021-05-20T03:56:26.923226Z'}
{'type': 'l2update', 'product_id': 'BTC-USD', 'changes': [['sell', '38365.89', '0.11380000']], 'time': '2021-05-20T03:56:26.923486Z'}
{'type': 'l2update', 'product_id': 'BTC-USD', 'changes': [['buy', '38231.18', '0.00000000']], 'time': '2021-05-20T03:56:26.925066Z'}
{'type': 'l2update', 'product_id': 'BTC-USD', 'changes': [['buy', '38325.94', '0.00000000']], 'time': '2021-05-20T03:56:26.925066Z'}
{'type': 'l2update', 'product_id': 'BTC-USD', 'changes': [['sell', '38437.28', '0.00000000']], 'time': '2021-05-20T03:56:26.925066Z'}
{'type': 'l2update', 'product_id': 'BTC-USD', 'changes': [['sell', '38532.04', '0.00000000']], 'time': '2021-05-20T03:56:26.925066Z'}
{'type': 'l2update', 'product_id': 'BTC-USD', 'changes': [['sell', '38519.93', '0.01000000']], 'time': '2021-05-20T03:56:26.929026Z'}
{'type': 'l2update', 'product_id': 'BTC-USD', 'changes': [['sell', '38402.09', '0.15000000']], 'time': '2021-05-20T03:56:26.929496Z'}
{'type': 'l2update', 'product_id': 'BTC-USD', 'changes': [['sell', '38365.89', '0.14270000']], 'time': '2021-05-20T03:56:26.929568Z'}
{'type': 'l2update', 'product_id': 'BTC-USD', 'changes': [['sell', '38399.53', '0.14024231']], 'time': '2021-05-20T03:56:26.929616Z'}
{'type': 'l2update', 'product_id': 'BTC-USD', 'changes': [['sell', '38375.92', '0.50000000']], 'time': '2021-05-20T03:56:26.929822Z'}
{'type': 'l2update', 'product_id': 'BTC-USD', 'changes': [['sell', '38375.03', '0.30077257']], 'time': '2021-05-20T03:56:26.933012Z'}
{'type': 'l2update', 'product_id': 'BTC-USD', 'changes': [['buy', '38305.41', '1.20000000']], 'time': '2021-05-20T03:56:26.939353Z'}
{'type': 'l2update', 'product_id': 'BTC-USD', 'changes': [['sell', '38407.99', '0.03207306']], 'time': '2021-05-20T03:56:26.939408Z'}
{'type': 'l2update', 'product_id': 'BTC-USD', 'changes': [['sell', '38379.38', '2.31300000']], 'time': '2021-05-20T03:56:26.940054Z'}
{'type': 'l2update', 'product_id': 'BTC-USD', 'changes': [['sell', '38408.05', '0.10000000']], 'time': '2021-05-20T03:56:26.940307Z'}
{'type': 'l2update', 'product_id': 'BTC-USD', 'changes': [['buy', '38360.14', '0.59116555']], 'time': '2021-05-20T03:56:26.943935Z'}
{'type': 'l2update', 'product_id': 'BTC-USD', 'changes': [['sell', '38486.82', '0.01000000']], 'time': '2021-05-20T03:56:26.950556Z'}
{'type': 'l2update', 'product_id': 'BTC-USD', 'changes': [['buy', '38345.56', '0.02390000']], 'time': '2021-05-20T03:56:26.951045Z'}
{'type': 'l2update', 'product_id': 'BTC-USD', 'changes': [['buy', '38344.75', '0.02390000']], 'time': '2021-05-20T03:56:26.951045Z'}
{'type': 'l2update', 'product_id': 'BTC-USD', 'changes': [['buy', '38343.94', '0.02390000']], 'time': '2021-05-20T03:56:26.951045Z'}
{'type': 'l2update', 'product_id': 'BTC-USD', 'changes': [['sell', '38375.13', '0.25000000']], 'time': '2021-05-20T03:56:26.954387Z'}
{'type': 'l2update', 'product_id': 'BTC-USD', 'changes': [['sell', '38424.03', '0.00000000']], 'time': '2021-05-20T03:56:26.955962Z'}
{'type': 'l2update', 'product_id': 'BTC-USD', 'changes': [['buy', '38346.15', '0.00000000']], 'time': '2021-05-20T03:56:26.956008Z'}
{'type': 'l2update', 'product_id': 'BTC-USD', 'changes': [['sell', '38470.28', '0.31066420']], 'time': '2021-05-20T03:56:26.964896Z'}
{'type': 'l2update', 'product_id': 'BTC-USD', 'changes': [['sell', '38464.38', '0.00000000']], 'time': '2021-05-20T03:56:26.964896Z'}
{'type': 'l2update', 'product_id': 'BTC-USD', 'changes': [['sell', '38458.67', '0.30444075']], 'time': '2021-05-20T03:56:26.964896Z'}
{'type': 'l2update', 'product_id': 'BTC-USD', 'changes': [['sell', '38447.82', '0.47047048']], 'time': '2021-05-20T03:56:26.964896Z'}
{'type': 'l2update', 'product_id': 'BTC-USD', 'changes': [['sell', '38447.82', '0.43675359']], 'time': '2021-05-20T03:56:26.964896Z'}
{'type': 'l2update', 'product_id': 'BTC-USD', 'changes': [['sell', '38437.73', '0.00000000']], 'time': '2021-05-20T03:56:26.964896Z'}
{'type': 'l2update', 'product_id': 'BTC-USD', 'changes': [['sell', '38427.94', '0.00000000']], 'time': '2021-05-20T03:56:26.964896Z'}
{'type': 'l2update', 'product_id': 'BTC-USD', 'changes': [['buy', '38318.95', '0.02681954']], 'time': '2021-05-20T03:56:26.964896Z'}
{'type': 'l2update', 'product_id': 'BTC-USD', 'changes': [['buy', '38318.95', '0.00000000']], 'time': '2021-05-20T03:56:26.964896Z'}
{'type': 'l2update', 'product_id': 'BTC-USD', 'changes': [['buy', '38323.50', '0.00000000']], 'time': '2021-05-20T03:56:26.964896Z'}
{'type': 'l2update', 'product_id': 'BTC-USD', 'changes': [['sell', '38531.41', '0.23223332']], 'time': '2021-05-20T03:56:26.968652Z'}
{'type': 'l2update', 'product_id': 'BTC-USD', 'changes': [['buy', '38262.81', '0.12000000']], 'time': '2021-05-20T03:56:26.973349Z'}
{'type': 'l2update', 'product_id': 'BTC-USD', 'changes': [['sell', '38406.49', '0.00000000']], 'time': '2021-05-20T03:56:26.975328Z'}
{'type': 'l2update', 'product_id': 'BTC-USD', 'changes': [['buy', '38357.39', '0.16000000']], 'time': '2021-05-20T03:56:26.976391Z'}
{'type': 'l2update', 'product_id': 'BTC-USD', 'changes': [['sell', '38467.89', '0.00000000']], 'time': '2021-05-20T03:56:26.983701Z'}
{'type': 'l2update', 'product_id': 'BTC-USD', 'changes': [['sell', '38363.48', '0.15000000']], 'time': '2021-05-20T03:56:26.988524Z'}
{'type': 'l2update', 'product_id': 'BTC-USD', 'changes': [['sell', '38375.94', '1.60839035']], 'time': '2021-05-20T03:56:26.988649Z'}
{'type': 'l2update', 'product_id': 'BTC-USD', 'changes': [['buy', '38363.43', '0.00000000']], 'time': '2021-05-20T03:56:26.988828Z'}
{'type': 'l2update', 'product_id': 'BTC-USD', 'changes': [['sell', '38414.66', '2.60663502']], 'time': '2021-05-20T03:56:26.990228Z'}
{'type': 'l2update', 'product_id': 'BTC-USD', 'changes': [['sell', '38654.06', '3.23362444']], 'time': '2021-05-20T03:56:26.992444Z'}
{'type': 'l2update', 'product_id': 'BTC-USD', 'changes': [['sell', '38573.83', '0.00000000']], 'time': '2021-05-20T03:56:27.005709Z'}
{'type': 'l2update', 'product_id': 'BTC-USD', 'changes': [['sell', '38373.01', '0.07460000']], 'time': '2021-05-20T03:56:27.008373Z'}
{'type': 'l2update', 'product_id': 'BTC-USD', 'changes': [['sell', '38373.28', '0.01492000']], 'time': '2021-05-20T03:56:27.008991Z'}
{'type': 'l2update', 'product_id': 'BTC-USD', 'changes': [['sell', '38395.64', '0.00000000']], 'time': '2021-05-20T03:56:27.022842Z'}
{'type': 'l2update', 'product_id': 'BTC-USD', 'changes': [['sell', '38365.89', '0.02890000']], 'time': '2021-05-20T03:56:27.025224Z'}
{'type': 'l2update', 'product_id': 'BTC-USD', 'changes': [['sell', '38412.34', '0.00000000']], 'time': '2021-05-20T03:56:27.033962Z'}
{'type': 'l2update', 'product_id': 'BTC-USD', 'changes': [['buy', '38350.88', '0.00000000']], 'time': '2021-05-20T03:56:27.033962Z'}
{'type': 'l2update', 'product_id': 'BTC-USD', 'changes': [['sell', '38373.68', '0.11380000']], 'time': '2021-05-20T03:56:27.035898Z'}
{'type': 'l2update', 'product_id': 'BTC-USD', 'changes': [['sell', '38403.70', '2.79990000']], 'time': '2021-05-20T03:56:27.036299Z'}
{'type': 'l2update', 'product_id': 'BTC-USD', 'changes': [['sell', '38508.10', '0.01000000']], 'time': '2021-05-20T03:56:27.036440Z'}
{'type': 'l2update', 'product_id': 'BTC-USD', 'changes': [['buy', '38351.28', '0.00000000']], 'time': '2021-05-20T03:56:27.037311Z'}
{'type': 'l2update', 'product_id': 'BTC-USD', 'changes': [['sell', '38399.53', '0.25882110']], 'time': '2021-05-20T03:56:27.039493Z'}
{'type': 'l2update', 'product_id': 'BTC-USD', 'changes': [['buy', '38220.42', '0.31926729']], 'time': '2021-05-20T03:56:27.039493Z'}
{'type': 'l2update', 'product_id': 'BTC-USD', 'changes': [['buy', '38345.56', '0.00000000']], 'time': '2021-05-20T03:56:27.039958Z'}
{'type': 'l2update', 'product_id': 'BTC-USD', 'changes': [['buy', '38344.75', '0.00000000']], 'time': '2021-05-20T03:56:27.039958Z'}
{'type': 'l2update', 'product_id': 'BTC-USD', 'changes': [['sell', '38440.49', '1.20000000']], 'time': '2021-05-20T03:56:27.040419Z'}
{'type': 'l2update', 'product_id': 'BTC-USD', 'changes': [['sell', '38373.67', '0.05000000']], 'time': '2021-05-20T03:56:27.040464Z'}
{'type': 'l2update', 'product_id': 'BTC-USD', 'changes': [['sell', '38387.12', '0.00000000']], 'time': '2021-05-20T03:56:27.041775Z'}
{'type': 'l2update', 'product_id': 'BTC-USD', 'changes': [['buy', '38262.81', '0.09000000']], 'time': '2021-05-20T03:56:27.043281Z'}
{'type': 'l2update', 'product_id': 'BTC-USD', 'changes': [['sell', '38375.93', '0.50570000']], 'time': '2021-05-20T03:56:27.044935Z'}
{'type': 'l2update', 'product_id': 'BTC-USD', 'changes': [['buy', '38269.77', '0.00000000']], 'time': '2021-05-20T03:56:27.048836Z'}
{'type': 'l2update', 'product_id': 'BTC-USD', 'changes': [['buy', '38255.22', '1.95290000']], 'time': '2021-05-20T03:56:27.051890Z'}
{'type': 'l2update', 'product_id': 'BTC-USD', 'changes': [['sell', '38447.82', '0.47510375']], 'time': '2021-05-20T03:56:27.052053Z'}
{'type': 'l2update', 'product_id': 'BTC-USD', 'changes': [['buy', '38346.16', '0.04655713']], 'time': '2021-05-20T03:56:27.052683Z'}
{'type': 'l2update', 'product_id': 'BTC-USD', 'changes': [['buy', '38221.93', '0.00000000']], 'time': '2021-05-20T03:56:27.055291Z'}
{'type': 'l2update', 'product_id': 'BTC-USD', 'changes': [['sell', '38365.89', '0.00000000']], 'time': '2021-05-20T03:56:27.059851Z'}
{'type': 'l2update', 'product_id': 'BTC-USD', 'changes': [['sell', '38375.94', '1.67219012']], 'time': '2021-05-20T03:56:27.064442Z'}
{'type': 'l2update', 'product_id': 'BTC-USD', 'changes': [['sell', '38424.89', '2.60645446']], 'time': '2021-05-20T03:56:27.064814Z'}
{'type': 'l2update', 'product_id': 'BTC-USD', 'changes': [['sell', '38373.68', '0.11953000']], 'time': '2021-05-20T03:56:27.064890Z'}
{'type': 'l2update', 'product_id': 'BTC-USD', 'changes': [['sell', '38373.01', '0.00000000']], 'time': '2021-05-20T03:56:27.065204Z'}
{'type': 'l2update', 'product_id': 'BTC-USD', 'changes': [['sell', '38373.28', '0.00000000']], 'time': '2021-05-20T03:56:27.068915Z'}
{'type': 'l2update', 'product_id': 'BTC-USD', 'changes': [['sell', '38373.68', '0.00573000']], 'time': '2021-05-20T03:56:27.069426Z'}
{'type': 'l2update', 'product_id': 'BTC-USD', 'changes': [['sell', '38379.42', '0.00000000']], 'time': '2021-05-20T03:56:27.070471Z'}
{'type': 'l2update', 'product_id': 'BTC-USD', 'changes': [['buy', '38340.70', '0.00000000']], 'time': '2021-05-20T03:56:27.073109Z'}
{'type': 'l2update', 'product_id': 'BTC-USD', 'changes': [['sell', '38373.63', '1.56400000']], 'time': '2021-05-20T03:56:27.078958Z'}
{'type': 'l2update', 'product_id': 'BTC-USD', 'changes': [['sell', '38363.39', '0.02890000']], 'time': '2021-05-20T03:56:27.080036Z'}
{'type': 'l2update', 'product_id': 'BTC-USD', 'changes': [['sell', '38470.28', '0.00000000']], 'time': '2021-05-20T03:56:27.080073Z'}
{'type': 'l2update', 'product_id': 'BTC-USD', 'changes': [['sell', '38458.67', '0.01000000']], 'time': '2021-05-20T03:56:27.080073Z'}
{'type': 'l2update', 'product_id': 'BTC-USD', 'changes': [['sell', '38447.82', '0.03835016']], 'time': '2021-05-20T03:56:27.080073Z'}
{'type': 'l2update', 'product_id': 'BTC-USD', 'changes': [['sell', '38442.68', '0.00000000']], 'time': '2021-05-20T03:56:27.080073Z'}
{'type': 'l2update', 'product_id': 'BTC-USD', 'changes': [['sell', '38432.97', '0.00000000']], 'time': '2021-05-20T03:56:27.080073Z'}
{'type': 'l2update', 'product_id': 'BTC-USD', 'changes': [['sell', '38424.02', '0.37877170']], 'time': '2021-05-20T03:56:27.080073Z'}
{'type': 'l2update', 'product_id': 'BTC-USD', 'changes': [['sell', '38424.02', '0.00000000']], 'time': '2021-05-20T03:56:27.080073Z'}
{'type': 'l2update', 'product_id': 'BTC-USD', 'changes': [['sell', '38419.84', '0.00000000']], 'time': '2021-05-20T03:56:27.080073Z'}
{'type': 'l2update', 'product_id': 'BTC-USD', 'changes': [['sell', '38415.97', '0.00000000']], 'time': '2021-05-20T03:56:27.080073Z'}
{'type': 'l2update', 'product_id': 'BTC-USD', 'changes': [['sell', '38415.85', '0.00000000']], 'time': '2021-05-20T03:56:27.080073Z'}
{'type': 'l2update', 'product_id': 'BTC-USD', 'changes': [['buy', '38305.41', '0.00000000']], 'time': '2021-05-20T03:56:27.081258Z'}
{'type': 'l2update', 'product_id': 'BTC-USD', 'changes': [['sell', '38406.51', '0.00000000']], 'time': '2021-05-20T03:56:27.082059Z'}
{'type': 'l2update', 'product_id': 'BTC-USD', 'changes': [['buy', '38262.81', '0.05000000']], 'time': '2021-05-20T03:56:27.082507Z'}
{'type': 'l2update', 'product_id': 'BTC-USD', 'changes': [['buy', '38318.46', '0.00000000']], 'time': '2021-05-20T03:56:27.092592Z'}
{'type': 'l2update', 'product_id': 'BTC-USD', 'changes': [['sell', '38432.96', '0.00000000']], 'time': '2021-05-20T03:56:27.108252Z'}
{'type': 'l2update', 'product_id': 'BTC-USD', 'changes': [['sell', '38398.92', '0.00000000']], 'time': '2021-05-20T03:56:27.108592Z'}
{'type': 'l2update', 'product_id': 'BTC-USD', 'changes': [['sell', '38375.94', '1.67149118']], 'time': '2021-05-20T03:56:27.108766Z'}
{'type': 'l2update', 'product_id': 'BTC-USD', 'changes': [['sell', '38373.67', '0.25000000']], 'time': '2021-05-20T03:56:27.108940Z'}
{'type': 'l2update', 'product_id': 'BTC-USD', 'changes': [['buy', '38255.48', '1.94690000']], 'time': '2021-05-20T03:56:27.109469Z'}
{'type': 'l2update', 'product_id': 'BTC-USD', 'changes': [['buy', '38340.71', '0.00000000']], 'time': '2021-05-20T03:56:27.110864Z'}
{'type': 'l2update', 'product_id': 'BTC-USD', 'changes': [['sell', '38431.93', '2.60636943']], 'time': '2021-05-20T03:56:27.112018Z'}
{'type': 'l2update', 'product_id': 'BTC-USD', 'changes': [['sell', '38465.66', '0.01000000']], 'time': '2021-05-20T03:56:27.112177Z'}
{'type': 'l2update', 'product_id': 'BTC-USD', 'changes': [['sell', '38447.82', '0.07094662']], 'time': '2021-05-20T03:56:27.112571Z'}
{'type': 'l2update', 'product_id': 'BTC-USD', 'changes': [['sell', '38549.37', '0.01000000']], 'time': '2021-05-20T03:56:27.114187Z'}
{'type': 'l2update', 'product_id': 'BTC-USD', 'changes': [['buy', '38312.51', '0.02610114']], 'time': '2021-05-20T03:56:27.114313Z'}
{'type': 'l2update', 'product_id': 'BTC-USD', 'changes': [['sell', '38363.39', '0.10350000']], 'time': '2021-05-20T03:56:27.114336Z'}
{'type': 'l2update', 'product_id': 'BTC-USD', 'changes': [['sell', '38440.49', '0.00000000']], 'time': '2021-05-20T03:56:27.118466Z'}
{'type': 'l2update', 'product_id': 'BTC-USD', 'changes': [['buy', '38299.61', '0.00000000']], 'time': '2021-05-20T03:56:27.119120Z'}
{'type': 'l2update', 'product_id': 'BTC-USD', 'changes': [['buy', '38310.70', '0.00000000']], 'time': '2021-05-20T03:56:27.120051Z'}
{'type': 'l2update', 'product_id': 'BTC-USD', 'changes': [['buy', '38262.81', '0.00000000']], 'time': '2021-05-20T03:56:27.120317Z'}
{'type': 'l2update', 'product_id': 'BTC-USD', 'changes': [['sell', '38381.65', '0.00000000']], 'time': '2021-05-20T03:56:27.121251Z'}
{'type': 'l2update', 'product_id': 'BTC-USD', 'changes': [['sell', '38381.36', '0.00000000']], 'time': '2021-05-20T03:56:27.123847Z'}
{'type': 'l2update', 'product_id': 'BTC-USD', 'changes': [['buy', '38342.57', '0.02390000']], 'time': '2021-05-20T03:56:27.132742Z'}
{'type': 'l2update', 'product_id': 'BTC-USD', 'changes': [['buy', '38341.76', '0.02390000']], 'time': '2021-05-20T03:56:27.132742Z'}
{'type': 'l2update', 'product_id': 'BTC-USD', 'changes': [['sell', '38375.92', '0.00000000']], 'time': '2021-05-20T03:56:27.134703Z'}
{'type': 'l2update', 'product_id': 'BTC-USD', 'changes': [['buy', '38277.50', '0.10000000']], 'time': '2021-05-20T03:56:27.139682Z'}
{'type': 'l2update', 'product_id': 'BTC-USD', 'changes': [['sell', '38453.49', '0.05451179']], 'time': '2021-05-20T03:56:27.140421Z'}
{'type': 'l2update', 'product_id': 'BTC-USD', 'changes': [['sell', '38398.73', '0.05000000']], 'time': '2021-05-20T03:56:27.144266Z'}
{'type': 'l2update', 'product_id': 'BTC-USD', 'changes': [['buy', '38360.14', '0.00000000']], 'time': '2021-05-20T03:56:27.145493Z'}
{'type': 'l2update', 'product_id': 'BTC-USD', 'changes': [['buy', '38363.38', '0.00000000']], 'time': '2021-05-20T03:56:27.149650Z'}
{'type': 'l2update', 'product_id': 'BTC-USD', 'changes': [['buy', '38357.38', '0.00000000']], 'time': '2021-05-20T03:56:27.149948Z'}
{'type': 'l2update', 'product_id': 'BTC-USD', 'changes': [['sell', '38454.88', '0.01299760']], 'time': '2021-05-20T03:56:27.150409Z'}
{'type': 'l2update', 'product_id': 'BTC-USD', 'changes': [['sell', '38373.67', '0.35000000']], 'time': '2021-05-20T03:56:27.150854Z'}
{'type': 'l2update', 'product_id': 'BTC-USD', 'changes': [['sell', '38375.94', '1.64278833']], 'time': '2021-05-20T03:56:27.155077Z'}
{'type': 'l2update', 'product_id': 'BTC-USD', 'changes': [['buy', '38360.13', '0.49527381']], 'time': '2021-05-20T03:56:27.157258Z'}
{'type': 'l2update', 'product_id': 'BTC-USD', 'changes': [['sell', '38438.04', '0.01362795']], 'time': '2021-05-20T03:56:27.157388Z'}
{'type': 'l2update', 'product_id': 'BTC-USD', 'changes': [['buy', '38343.94', '0.00000000']], 'time': '2021-05-20T03:56:27.165198Z'}
{'type': 'l2update', 'product_id': 'BTC-USD', 'changes': [['sell', '38505.84', '0.00000000']], 'time': '2021-05-20T03:56:27.166887Z'}
{'type': 'l2update', 'product_id': 'BTC-USD', 'changes': [['buy', '38204.30', '0.00000000']], 'time': '2021-05-20T03:56:27.167783Z'}
{'type': 'l2update', 'product_id': 'BTC-USD', 'changes': [['sell', '38447.82', '0.09783807']], 'time': '2021-05-20T03:56:27.172914Z'}
{'type': 'l2update', 'product_id': 'BTC-USD', 'changes': [['sell', '38398.73', '0.00000000']], 'time': '2021-05-20T03:56:27.176407Z'}
{'type': 'l2update', 'product_id': 'BTC-USD', 'changes': [['sell', '38543.21', '0.00000000']], 'time': '2021-05-20T03:56:27.176762Z'}
{'type': 'l2update', 'product_id': 'BTC-USD', 'changes': [['sell', '38399.98', '0.00000000']], 'time': '2021-05-20T03:56:27.180076Z'}
{'type': 'l2update', 'product_id': 'BTC-USD', 'changes': [['sell', '38363.39', '0.02890000']], 'time': '2021-05-20T03:56:27.180197Z'}
{'type': 'l2update', 'product_id': 'BTC-USD', 'changes': [['sell', '38374.98', '2.54300000']], 'time': '2021-05-20T03:56:27.181528Z'}
{'type': 'l2update', 'product_id': 'BTC-USD', 'changes': [['sell', '38363.39', '0.52890000']], 'time': '2021-05-20T03:56:27.182300Z'}
{'type': 'l2update', 'product_id': 'BTC-USD', 'changes': [['sell', '38375.94', '1.60278833']], 'time': '2021-05-20T03:56:27.186655Z'}
{'type': 'l2update', 'product_id': 'BTC-USD', 'changes': [['sell', '38360.14', '0.02890000']], 'time': '2021-05-20T03:56:27.189262Z'}
{'type': 'l2update', 'product_id': 'BTC-USD', 'changes': [['sell', '38379.42', '2.14452857']], 'time': '2021-05-20T03:56:27.190312Z'}
{'type': 'l2update', 'product_id': 'BTC-USD', 'changes': [['sell', '38360.14', '0.04382000']], 'time': '2021-05-20T03:56:27.190650Z'}
{'type': 'l2update', 'product_id': 'BTC-USD', 'changes': [['buy', '38265.90', '0.00000000']], 'time': '2021-05-20T03:56:27.190817Z'}
{'type': 'l2update', 'product_id': 'BTC-USD', 'changes': [['sell', '38418.48', '0.00000000']], 'time': '2021-05-20T03:56:27.191319Z'}
{'type': 'l2update', 'product_id': 'BTC-USD', 'changes': [['buy', '38041.67', '0.00000000']], 'time': '2021-05-20T03:56:27.191447Z'}
{'type': 'l2update', 'product_id': 'BTC-USD', 'changes': [['sell', '38381.45', '0.10000000']], 'time': '2021-05-20T03:56:27.193560Z'}
{'type': 'l2update', 'product_id': 'BTC-USD', 'changes': [['sell', '38363.44', '0.10000000']], 'time': '2021-05-20T03:56:27.193598Z'}
{'type': 'l2update', 'product_id': 'BTC-USD', 'changes': [['sell', '38363.44', '0.10573000']], 'time': '2021-05-20T03:56:27.193846Z'}
{'type': 'l2update', 'product_id': 'BTC-USD', 'changes': [['sell', '38521.82', '0.33000000']], 'time': '2021-05-20T03:56:27.194101Z'}
{'type': 'l2update', 'product_id': 'BTC-USD', 'changes': [['buy', '38357.39', '0.00000000']], 'time': '2021-05-20T03:56:27.197128Z'}
{'type': 'l2update', 'product_id': 'BTC-USD', 'changes': [['buy', '38342.57', '0.00000000']], 'time': '2021-05-20T03:56:27.201228Z'}
{'type': 'l2update', 'product_id': 'BTC-USD', 'changes': [['buy', '38341.76', '0.00000000']], 'time': '2021-05-20T03:56:27.201228Z'}
{'type': 'l2update', 'product_id': 'BTC-USD', 'changes': [['sell', '38383.51', '0.00000000']], 'time': '2021-05-20T03:56:27.209915Z'}
{'type': 'l2update', 'product_id': 'BTC-USD', 'changes': [['sell', '38381.47', '0.00000000']], 'time': '2021-05-20T03:56:27.212299Z'}
{'type': 'l2update', 'product_id': 'BTC-USD', 'changes': [['sell', '43100.00', '1.09530000']], 'time': '2021-05-20T03:56:27.215453Z'}
{'type': 'l2update', 'product_id': 'BTC-USD', 'changes': [['buy', '38300.60', '1.28013724']], 'time': '2021-05-20T03:56:27.216838Z'}
{'type': 'l2update', 'product_id': 'BTC-USD', 'changes': [['sell', '38474.10', '0.42774447']], 'time': '2021-05-20T03:56:27.217292Z'}
{'type': 'l2update', 'product_id': 'BTC-USD', 'changes': [['sell', '38401.76', '0.00000000']], 'time': '2021-05-20T03:56:27.218986Z'}
{'type': 'l2update', 'product_id': 'BTC-USD', 'changes': [['sell', '38379.43', '0.03000000']], 'time': '2021-05-20T03:56:27.219398Z'}
{'type': 'l2update', 'product_id': 'BTC-USD', 'changes': [['sell', '38363.39', '0.50000000']], 'time': '2021-05-20T03:56:27.223360Z'}
{'type': 'l2update', 'product_id': 'BTC-USD', 'changes': [['sell', '38384.04', '0.21800000']], 'time': '2021-05-20T03:56:27.223600Z'}
{'type': 'l2update', 'product_id': 'BTC-USD', 'changes': [['sell', '38393.94', '0.05000000']], 'time': '2021-05-20T03:56:27.224115Z'}
{'type': 'l2update', 'product_id': 'BTC-USD', 'changes': [['sell', '38360.14', '0.11842000']], 'time': '2021-05-20T03:56:27.224319Z'}
{'type': 'l2update', 'product_id': 'BTC-USD', 'changes': [['sell', '38517.20', '0.00000000']], 'time': '2021-05-20T03:56:27.226670Z'}
{'type': 'l2update', 'product_id': 'BTC-USD', 'changes': [['sell', '38447.82', '0.12546519']], 'time': '2021-05-20T03:56:27.229081Z'}
{'type': 'l2update', 'product_id': 'BTC-USD', 'changes': [['buy', '38225.74', '0.03249783']], 'time': '2021-05-20T03:56:27.229081Z'}
{'type': 'l2update', 'product_id': 'BTC-USD', 'changes': [['sell', '38365.70', '0.08478693']], 'time': '2021-05-20T03:56:27.229081Z'}
{'type': 'l2update', 'product_id': 'BTC-USD', 'changes': [['sell', '38375.93', '0.49997000']], 'time': '2021-05-20T03:56:27.229180Z'}
{'type': 'l2update', 'product_id': 'BTC-USD', 'changes': [['sell', '38531.41', '0.00000000']], 'time': '2021-05-20T03:56:27.230931Z'}
{'type': 'l2update', 'product_id': 'BTC-USD', 'changes': [['buy', '38312.51', '1.49366306']], 'time': '2021-05-20T03:56:27.233497Z'}
{'type': 'l2update', 'product_id': 'BTC-USD', 'changes': [['sell', '38363.44', '0.30573000']], 'time': '2021-05-20T03:56:27.238262Z'}
{'type': 'l2update', 'product_id': 'BTC-USD', 'changes': [['sell', '38386.45', '0.00000000']], 'time': '2021-05-20T03:56:27.240278Z'}
{'type': 'l2update', 'product_id': 'BTC-USD', 'changes': [['buy', '38312.50', '0.00000000']], 'time': '2021-05-20T03:56:27.242878Z'}
{'type': 'l2update', 'product_id': 'BTC-USD', 'changes': [['sell', '38379.38', '0.00000000']], 'time': '2021-05-20T03:56:27.243108Z'}
{'type': 'l2update', 'product_id': 'BTC-USD', 'changes': [['sell', '38521.71', '2.87000000']], 'time': '2021-05-20T03:56:27.244158Z'}
{'type': 'l2update', 'product_id': 'BTC-USD', 'changes': [['buy', '38360.13', '0.00000000']], 'time': '2021-05-20T03:56:27.246978Z'}
{'type': 'l2update', 'product_id': 'BTC-USD', 'changes': [['buy', '38359.72', '0.08912099']], 'time': '2021-05-20T03:56:27.246978Z'}
{'type': 'l2update', 'product_id': 'BTC-USD', 'changes': [['buy', '38274.15', '0.01000000']], 'time': '2021-05-20T03:56:27.250749Z'}
{'type': 'l2update', 'product_id': 'BTC-USD', 'changes': [['sell', '38373.63', '0.00000000']], 'time': '2021-05-20T03:56:27.251560Z'}
{'type': 'l2update', 'product_id': 'BTC-USD', 'changes': [['buy', '38315.04', '0.04369614']], 'time': '2021-05-20T03:56:27.252052Z'}
{'type': 'l2update', 'product_id': 'BTC-USD', 'changes': [['sell', '38363.88', '0.05006438']], 'time': '2021-05-20T03:56:27.252052Z'}
{'type': 'l2update', 'product_id': 'BTC-USD', 'changes': [['sell', '43100.00', '2.73280000']], 'time': '2021-05-20T03:56:27.255419Z'}
{'type': 'l2update', 'product_id': 'BTC-USD', 'changes': [['buy', '38337.12', '0.59116555']], 'time': '2021-05-20T03:56:27.262196Z'}
{'type': 'l2update', 'product_id': 'BTC-USD', 'changes': [['sell', '38476.98', '0.01000000']], 'time': '2021-05-20T03:56:27.263811Z'}
{'type': 'l2update', 'product_id': 'BTC-USD', 'changes': [['buy', '31313.00', '0.04345000']], 'time': '2021-05-20T03:56:27.263851Z'}
{'type': 'l2update', 'product_id': 'BTC-USD', 'changes': [['sell', '38393.94', '0.00000000']], 'time': '2021-05-20T03:56:27.264504Z'}
{'type': 'l2update', 'product_id': 'BTC-USD', 'changes': [['sell', '38517.31', '0.00000000']], 'time': '2021-05-20T03:56:27.265442Z'}
{'type': 'l2update', 'product_id': 'BTC-USD', 'changes': [['buy', '38277.82', '0.01000000']], 'time': '2021-05-20T03:56:27.267527Z'}
{'type': 'l2update', 'product_id': 'BTC-USD', 'changes': [['sell', '38474.10', '0.80689216']], 'time': '2021-05-20T03:56:27.267581Z'}
{'type': 'l2update', 'product_id': 'BTC-USD', 'changes': [['buy', '38204.27', '0.42039654']], 'time': '2021-05-20T03:56:27.267581Z'}
{'type': 'l2update', 'product_id': 'BTC-USD', 'changes': [['sell', '38373.44', '1.76537385']], 'time': '2021-05-20T03:56:27.267581Z'}
{'type': 'l2update', 'product_id': 'BTC-USD', 'changes': [['sell', '38499.18', '0.00000000']], 'time': '2021-05-20T03:56:27.269141Z'}
{'type': 'l2update', 'product_id': 'BTC-USD', 'changes': [['sell', '38375.94', '1.59775727']], 'time': '2021-05-20T03:56:27.269644Z'}
{'type': 'l2update', 'product_id': 'BTC-USD', 'changes': [['sell', '38495.81', '0.40882511']], 'time': '2021-05-20T03:56:27.269944Z'}
{'type': 'l2update', 'product_id': 'BTC-USD', 'changes': [['sell', '38489.14', '0.00000000']], 'time': '2021-05-20T03:56:27.269944Z'}
{'type': 'l2update', 'product_id': 'BTC-USD', 'changes': [['sell', '38482.66', '0.34517721']], 'time': '2021-05-20T03:56:27.269944Z'}
{'type': 'l2update', 'product_id': 'BTC-USD', 'changes': [['sell', '38476.37', '0.34116439']], 'time': '2021-05-20T03:56:27.269944Z'}
{'type': 'l2update', 'product_id': 'BTC-USD', 'changes': [['buy', '38260.30', '0.03690719']], 'time': '2021-05-20T03:56:27.269944Z'}
{'type': 'l2update', 'product_id': 'BTC-USD', 'changes': [['buy', '38260.30', '0.00000000']], 'time': '2021-05-20T03:56:27.269944Z'}
{'type': 'l2update', 'product_id': 'BTC-USD', 'changes': [['buy', '38293.35', '0.00000000']], 'time': '2021-05-20T03:56:27.269944Z'}
{'type': 'l2update', 'product_id': 'BTC-USD', 'changes': [['buy', '38298.85', '0.00000000']], 'time': '2021-05-20T03:56:27.269944Z'}
{'type': 'l2update', 'product_id': 'BTC-USD', 'changes': [['buy', '38304.16', '0.00000000']], 'time': '2021-05-20T03:56:27.269944Z'}
{'type': 'l2update', 'product_id': 'BTC-USD', 'changes': [['sell', '38379.42', '0.00000000']], 'time': '2021-05-20T03:56:27.274481Z'}
{'type': 'l2update', 'product_id': 'BTC-USD', 'changes': [['sell', '38494.88', '0.01680929']], 'time': '2021-05-20T03:56:27.277121Z'}
{'type': 'l2update', 'product_id': 'BTC-USD', 'changes': [['sell', '38519.53', '0.01000000']], 'time': '2021-05-20T03:56:27.277518Z'}
{'type': 'l2update', 'product_id': 'BTC-USD', 'changes': [['buy', '38352.16', '0.07124467']], 'time': '2021-05-20T03:56:27.286102Z'}
{'type': 'l2update', 'product_id': 'BTC-USD', 'changes': [['sell', '38360.14', '0.04382000']], 'time': '2021-05-20T03:56:27.288539Z'}
{'type': 'l2update', 'product_id': 'BTC-USD', 'changes': [['sell', '38363.39', '0.00000000']], 'time': '2021-05-20T03:56:27.289930Z'}
{'type': 'l2update', 'product_id': 'BTC-USD', 'changes': [['sell', '38363.38', '0.20000000']], 'time': '2021-05-20T03:56:27.290076Z'}
{'type': 'l2update', 'product_id': 'BTC-USD', 'changes': [['buy', '38336.95', '0.02400000']], 'time': '2021-05-20T03:56:27.290286Z'}
{'type': 'l2update', 'product_id': 'BTC-USD', 'changes': [['buy', '38336.14', '0.02400000']], 'time': '2021-05-20T03:56:27.290286Z'}
{'type': 'l2update', 'product_id': 'BTC-USD', 'changes': [['buy', '38335.33', '0.02400000']], 'time': '2021-05-20T03:56:27.290286Z'}
{'type': 'l2update', 'product_id': 'BTC-USD', 'changes': [['sell', '38360.14', '0.02890000']], 'time': '2021-05-20T03:56:27.290542Z'}
{'type': 'l2update', 'product_id': 'BTC-USD', 'changes': [['buy', '38184.87', '0.80000000']], 'time': '2021-05-20T03:56:27.294693Z'}
{'type': 'l2update', 'product_id': 'BTC-USD', 'changes': [['buy', '28750.00', '3.42306906']], 'time': '2021-05-20T03:56:27.298906Z'}
{'type': 'l2update', 'product_id': 'BTC-USD', 'changes': [['buy', '38239.26', '0.00000000']], 'time': '2021-05-20T03:56:27.307488Z'}
{'type': 'l2update', 'product_id': 'BTC-USD', 'changes': [['sell', '38509.72', '0.37914769']], 'time': '2021-05-20T03:56:27.307575Z'}
{'type': 'l2update', 'product_id': 'BTC-USD', 'changes': [['sell', '38509.72', '0.00000000']], 'time': '2021-05-20T03:56:27.307575Z'}
{'type': 'l2update', 'product_id': 'BTC-USD', 'changes': [['buy', '38249.58', '0.35994915']], 'time': '2021-05-20T03:56:27.307575Z'}
{'type': 'l2update', 'product_id': 'BTC-USD', 'changes': [['buy', '38269.47', '0.02864075']], 'time': '2021-05-20T03:56:27.307575Z'}
{'type': 'l2update', 'product_id': 'BTC-USD', 'changes': [['buy', '38281.78', '0.00000000']], 'time': '2021-05-20T03:56:27.307575Z'}
{'type': 'l2update', 'product_id': 'BTC-USD', 'changes': [['sell', '38379.43', '0.02000000']], 'time': '2021-05-20T03:56:27.307852Z'}
{'type': 'l2update', 'product_id': 'BTC-USD', 'changes': [['sell', '38386.38', '0.04655713']], 'time': '2021-05-20T03:56:27.309901Z'}
{'type': 'l2update', 'product_id': 'BTC-USD', 'changes': [['buy', '38160.66', '0.04997806']], 'time': '2021-05-20T03:56:27.309952Z'}
{'type': 'l2update', 'product_id': 'BTC-USD', 'changes': [['sell', '38363.39', '0.00573000']], 'time': '2021-05-20T03:56:27.315141Z'}
{'type': 'l2update', 'product_id': 'BTC-USD', 'changes': [['buy', '38343.35', '0.05192856']], 'time': '2021-05-20T03:56:27.315153Z'}
{'type': 'l2update', 'product_id': 'BTC-USD', 'changes': [['sell', '38454.88', '0.00000000']], 'time': '2021-05-20T03:56:27.315770Z'}
{'type': 'l2update', 'product_id': 'BTC-USD', 'changes': [['buy', '38255.22', '0.00000000']], 'time': '2021-05-20T03:56:27.316563Z'}
{'type': 'l2update', 'product_id': 'BTC-USD', 'changes': [['buy', '38312.51', '0.02610114']], 'time': '2021-05-20T03:56:27.317151Z'}
{'type': 'l2update', 'product_id': 'BTC-USD', 'changes': [['buy', '38312.51', '0.00000000']], 'time': '2021-05-20T03:56:27.317422Z'}
{'type': 'l2update', 'product_id': 'BTC-USD', 'changes': [['buy', '38359.72', '0.00000000']], 'time': '2021-05-20T03:56:27.324372Z'}
{'type': 'l2update', 'product_id': 'BTC-USD', 'changes': [['buy', '38251.62', '0.00000000']], 'time': '2021-05-20T03:56:27.324517Z'}
{'type': 'l2update', 'product_id': 'BTC-USD', 'changes': [['sell', '38484.06', '0.01000000']], 'time': '2021-05-20T03:56:27.324553Z'}
{'type': 'l2update', 'product_id': 'BTC-USD', 'changes': [['buy', '38202.47', '0.03286105']], 'time': '2021-05-20T03:56:27.324597Z'}
{'type': 'l2update', 'product_id': 'BTC-USD', 'changes': [['sell', '38363.20', '0.04377332']], 'time': '2021-05-20T03:56:27.324597Z'}
{'type': 'l2update', 'product_id': 'BTC-USD', 'changes': [['buy', '38336.95', '0.00000000']], 'time': '2021-05-20T03:56:27.326559Z'}
{'type': 'l2update', 'product_id': 'BTC-USD', 'changes': [['buy', '38336.14', '0.00000000']], 'time': '2021-05-20T03:56:27.326559Z'}
{'type': 'l2update', 'product_id': 'BTC-USD', 'changes': [['sell', '38386.44', '0.05000000']], 'time': '2021-05-20T03:56:27.328741Z'}
{'type': 'l2update', 'product_id': 'BTC-USD', 'changes': [['sell', '38386.39', '0.00000000']], 'time': '2021-05-20T03:56:27.329567Z'}
{'type': 'l2update', 'product_id': 'BTC-USD', 'changes': [['sell', '38363.38', '0.35150000']], 'time': '2021-05-20T03:56:27.334952Z'}
{'type': 'l2update', 'product_id': 'BTC-USD', 'changes': [['sell', '38359.73', '0.07460000']], 'time': '2021-05-20T03:56:27.335020Z'}
{'type': 'l2update', 'product_id': 'BTC-USD', 'changes': [['sell', '38360.14', '0.52890000']], 'time': '2021-05-20T03:56:27.339798Z'}
{'type': 'l2update', 'product_id': 'BTC-USD', 'changes': [['buy', '38255.08', '0.02400000']], 'time': '2021-05-20T03:56:27.340031Z'}
{'type': 'l2update', 'product_id': 'BTC-USD', 'changes': [['sell', '38379.43', '0.00000000']], 'time': '2021-05-20T03:56:27.341339Z'}
{'type': 'l2update', 'product_id': 'BTC-USD', 'changes': [['buy', '38249.58', '0.00000000']], 'time': '2021-05-20T03:56:27.341999Z'}
{'type': 'l2update', 'product_id': 'BTC-USD', 'changes': [['buy', '38256.40', '0.02924881']], 'time': '2021-05-20T03:56:27.341999Z'}
{'type': 'l2update', 'product_id': 'BTC-USD', 'changes': [['buy', '38263.03', '0.05722983']], 'time': '2021-05-20T03:56:27.341999Z'}
{'type': 'l2update', 'product_id': 'BTC-USD', 'changes': [['buy', '38326.97', '0.52000000']], 'time': '2021-05-20T03:56:27.345530Z'}
{'type': 'l2update', 'product_id': 'BTC-USD', 'changes': [['buy', '38279.53', '0.32000000']], 'time': '2021-05-20T03:56:27.345594Z'}
{'type': 'l2update', 'product_id': 'BTC-USD', 'changes': [['sell', '38392.77', '0.32000000']], 'time': '2021-05-20T03:56:27.345594Z'}
{'type': 'l2update', 'product_id': 'BTC-USD', 'changes': [['sell', '38487.42', '0.80000000']], 'time': '2021-05-20T03:56:27.345594Z'}
{'type': 'l2update', 'product_id': 'BTC-USD', 'changes': [['sell', '38373.68', '0.00000000']], 'time': '2021-05-20T03:56:27.351519Z'}
{'type': 'l2update', 'product_id': 'BTC-USD', 'changes': [['buy', '38067.28', '0.00000000']], 'time': '2021-05-20T03:56:27.352233Z'}
{'type': 'l2update', 'product_id': 'BTC-USD', 'changes': [['sell', '38499.21', '0.02459730']], 'time': '2021-05-20T03:56:27.356513Z'}
{'type': 'l2update', 'product_id': 'BTC-USD', 'changes': [['buy', '38326.93', '0.04655713']], 'time': '2021-05-20T03:56:27.356553Z'}
{'type': 'l2update', 'product_id': 'BTC-USD', 'changes': [['sell', '38359.76', '0.05035858']], 'time': '2021-05-20T03:56:27.356902Z'}
{'type': 'l2update', 'product_id': 'BTC-USD', 'changes': [['buy', '38256.40', '0.00000000']], 'time': '2021-05-20T03:56:27.361244Z'}
{'type': 'l2update', 'product_id': 'BTC-USD', 'changes': [['buy', '38263.03', '0.03055082']], 'time': '2021-05-20T03:56:27.361244Z'}
{'type': 'l2update', 'product_id': 'BTC-USD', 'changes': [['buy', '38263.03', '0.00000000']], 'time': '2021-05-20T03:56:27.361244Z'}
{'type': 'l2update', 'product_id': 'BTC-USD', 'changes': [['buy', '38269.47', '0.00000000']], 'time': '2021-05-20T03:56:27.361244Z'}
{'type': 'l2update', 'product_id': 'BTC-USD', 'changes': [['sell', '38386.44', '0.00000000']], 'time': '2021-05-20T03:56:27.363880Z'}
{'type': 'l2update', 'product_id': 'BTC-USD', 'changes': [['sell', '38359.73', '0.08952000']], 'time': '2021-05-20T03:56:27.365083Z'}
{'type': 'l2update', 'product_id': 'BTC-USD', 'changes': [['sell', '38379.42', '2.48969908']], 'time': '2021-05-20T03:56:27.366074Z'}
{'type': 'l2update', 'product_id': 'BTC-USD', 'changes': [['sell', '38402.84', '0.01299760']], 'time': '2021-05-20T03:56:27.366334Z'}
{'type': 'l2update', 'product_id': 'BTC-USD', 'changes': [['sell', '38463.64', '0.00000000']], 'time': '2021-05-20T03:56:27.369784Z'}
{'type': 'l2update', 'product_id': 'BTC-USD', 'changes': [['sell', '38549.37', '0.00000000']], 'time': '2021-05-20T03:56:27.369847Z'}
{'type': 'l2update', 'product_id': 'BTC-USD', 'changes': [['sell', '38388.38', '0.39490432']], 'time': '2021-05-20T03:56:27.371507Z'}
{'type': 'l2update', 'product_id': 'BTC-USD', 'changes': [['sell', '38504.76', '0.01000000']], 'time': '2021-05-20T03:56:27.372322Z'}
{'type': 'l2update', 'product_id': 'BTC-USD', 'changes': [['sell', '38359.73', '0.01492000']], 'time': '2021-05-20T03:56:27.372575Z'}
{'type': 'l2update', 'product_id': 'BTC-USD', 'changes': [['buy', '38255.49', '0.49121967']], 'time': '2021-05-20T03:56:27.375545Z'}
{'type': 'l2update', 'product_id': 'BTC-USD', 'changes': [['buy', '38346.16', '0.00000000']], 'time': '2021-05-20T03:56:27.377055Z'}
{'type': 'l2update', 'product_id': 'BTC-USD', 'changes': [['sell', '38359.73', '0.21492000']], 'time': '2021-05-20T03:56:27.380713Z'}
{'type': 'l2update', 'product_id': 'BTC-USD', 'changes': [['sell', '38466.30', '0.42239315']], 'time': '2021-05-20T03:56:27.388002Z'}
{'type': 'l2update', 'product_id': 'BTC-USD', 'changes': [['sell', '38403.70', '0.00000000']], 'time': '2021-05-20T03:56:27.388319Z'}
{'type': 'l2update', 'product_id': 'BTC-USD', 'changes': [['sell', '38421.42', '0.61482417']], 'time': '2021-05-20T03:56:27.388513Z'}
{'type': 'l2update', 'product_id': 'BTC-USD', 'changes': [['buy', '38239.57', '0.50000000']], 'time': '2021-05-20T03:56:27.388790Z'}
{'type': 'l2update', 'product_id': 'BTC-USD', 'changes': [['sell', '38390.14', '2.16932808']], 'time': '2021-05-20T03:56:27.389296Z'}
{'type': 'l2update', 'product_id': 'BTC-USD', 'changes': [['buy', '38277.81', '0.02000000']], 'time': '2021-05-20T03:56:27.389443Z'}
{'type': 'l2update', 'product_id': 'BTC-USD', 'changes': [['sell', '38367.86', '0.02000000']], 'time': '2021-05-20T03:56:27.393662Z'}
{'type': 'l2update', 'product_id': 'BTC-USD', 'changes': [['sell', '38388.03', '0.00000000']], 'time': '2021-05-20T03:56:27.394425Z'}
{'type': 'l2update', 'product_id': 'BTC-USD', 'changes': [['sell', '38359.73', '0.20000000']], 'time': '2021-05-20T03:56:27.398363Z'}
{'type': 'l2update', 'product_id': 'BTC-USD', 'changes': [['sell', '38363.38', '0.35723000']], 'time': '2021-05-20T03:56:27.398686Z'}
{'type': 'l2update', 'product_id': 'BTC-USD', 'changes': [['sell', '38374.98', '0.00000000']], 'time': '2021-05-20T03:56:27.402248Z'}
{'type': 'l2update', 'product_id': 'BTC-USD', 'changes': [['buy', '38038.56', '0.00000000']], 'time': '2021-05-20T03:56:27.402734Z'}
{'type': 'l2update', 'product_id': 'BTC-USD', 'changes': [['sell', '38407.99', '0.00000000']], 'time': '2021-05-20T03:56:27.404022Z'}
{'type': 'l2update', 'product_id': 'BTC-USD', 'changes': [['sell', '38440.81', '0.04542540']], 'time': '2021-05-20T03:56:27.411897Z'}
{'type': 'l2update', 'product_id': 'BTC-USD', 'changes': [['buy', '38266.69', '0.01000000']], 'time': '2021-05-20T03:56:27.411971Z'}
{'type': 'l2update', 'product_id': 'BTC-USD', 'changes': [['buy', '38356.20', '0.00000000']], 'time': '2021-05-20T03:56:27.412059Z'}
{'type': 'l2update', 'product_id': 'BTC-USD', 'changes': [['sell', '38408.85', '0.00000000']], 'time': '2021-05-20T03:56:27.412575Z'}
{'type': 'l2update', 'product_id': 'BTC-USD', 'changes': [['sell', '38383.50', '0.05000000']], 'time': '2021-05-20T03:56:27.413432Z'}
{'type': 'l2update', 'product_id': 'BTC-USD', 'changes': [['buy', '38312.51', '1.98886958']], 'time': '2021-05-20T03:56:27.414080Z'}
{'type': 'l2update', 'product_id': 'BTC-USD', 'changes': [['sell', '38363.43', '0.00585118']], 'time': '2021-05-20T03:56:27.414227Z'}
{'type': 'l2update', 'product_id': 'BTC-USD', 'changes': [['sell', '38363.20', '0.05620786']], 'time': '2021-05-20T03:56:27.414227Z'}
{'type': 'l2update', 'product_id': 'BTC-USD', 'changes': [['buy', '38160.66', '0.00000000']], 'time': '2021-05-20T03:56:27.415138Z'}
{'type': 'l2update', 'product_id': 'BTC-USD', 'changes': [['sell', '38485.85', '0.00000000']], 'time': '2021-05-20T03:56:27.415202Z'}
{'type': 'l2update', 'product_id': 'BTC-USD', 'changes': [['sell', '38375.94', '1.39775727']], 'time': '2021-05-20T03:56:27.415530Z'}
{'type': 'l2update', 'product_id': 'BTC-USD', 'changes': [['sell', '38356.21', '0.07460000']], 'time': '2021-05-20T03:56:27.418180Z'}
{'type': 'l2update', 'product_id': 'BTC-USD', 'changes': [['buy', '38333.99', '0.02400000']], 'time': '2021-05-20T03:56:27.419063Z'}
{'type': 'l2update', 'product_id': 'BTC-USD', 'changes': [['buy', '38333.18', '0.02400000']], 'time': '2021-05-20T03:56:27.419063Z'}
{'type': 'l2update', 'product_id': 'BTC-USD', 'changes': [['sell', '38502.67', '0.00000000']], 'time': '2021-05-20T03:56:27.421388Z'}
{'type': 'l2update', 'product_id': 'BTC-USD', 'changes': [['buy', '38235.38', '0.00000000']], 'time': '2021-05-20T03:56:27.421388Z'}
{'type': 'l2update', 'product_id': 'BTC-USD', 'changes': [['sell', '38521.82', '0.00000000']], 'time': '2021-05-20T03:56:27.425221Z'}
{'type': 'l2update', 'product_id': 'BTC-USD', 'changes': [['buy', '38255.08', '0.00000000']], 'time': '2021-05-20T03:56:27.425341Z'}
{'type': 'l2update', 'product_id': 'BTC-USD', 'changes': [['buy', '38326.97', '0.00000000']], 'time': '2021-05-20T03:56:27.427949Z'}
{'type': 'l2update', 'product_id': 'BTC-USD', 'changes': [['buy', '38304.43', '0.02000000']], 'time': '2021-05-20T03:56:27.443258Z'}
{'type': 'l2update', 'product_id': 'BTC-USD', 'changes': [['buy', '38277.81', '0.05000000']], 'time': '2021-05-20T03:56:27.444334Z'}
{'type': 'l2update', 'product_id': 'BTC-USD', 'changes': [['sell', '38383.50', '0.00000000']], 'time': '2021-05-20T03:56:27.445461Z'}
{'type': 'l2update', 'product_id': 'BTC-USD', 'changes': [['sell', '38379.42', '0.00000000']], 'time': '2021-05-20T03:56:27.446162Z'}
{'type': 'l2update', 'product_id': 'BTC-USD', 'changes': [['buy', '38334.74', '0.00000000']], 'time': '2021-05-20T03:56:27.449209Z'}
{'type': 'l2update', 'product_id': 'BTC-USD', 'changes': [['sell', '38352.27', '0.02890000']], 'time': '2021-05-20T03:56:27.449965Z'}
{'type': 'l2update', 'product_id': 'BTC-USD', 'changes': [['sell', '38356.21', '0.08952000']], 'time': '2021-05-20T03:56:27.450335Z'}
{'type': 'l2update', 'product_id': 'BTC-USD', 'changes': [['buy', '38012.79', '0.08695500']], 'time': '2021-05-20T03:56:27.450352Z'}
{'type': 'l2update', 'product_id': 'BTC-USD', 'changes': [['sell', '38365.65', '1.92100000']], 'time': '2021-05-20T03:56:27.450628Z'}
{'type': 'l2update', 'product_id': 'BTC-USD', 'changes': [['sell', '38520.26', '0.00000000']], 'time': '2021-05-20T03:56:27.451526Z'}
{'type': 'l2update', 'product_id': 'BTC-USD', 'changes': [['buy', '38255.48', '0.00000000']], 'time': '2021-05-20T03:56:27.452982Z'}
{'type': 'l2update', 'product_id': 'BTC-USD', 'changes': [['sell', '38356.21', '0.01492000']], 'time': '2021-05-20T03:56:27.453103Z'}
{'type': 'l2update', 'product_id': 'BTC-USD', 'changes': [['sell', '38360.14', '0.50000000']], 'time': '2021-05-20T03:56:27.454796Z'}
{'type': 'l2update', 'product_id': 'BTC-USD', 'changes': [['sell', '38504.76', '0.00000000']], 'time': '2021-05-20T03:56:27.456284Z'}
{'type': 'l2update', 'product_id': 'BTC-USD', 'changes': [['sell', '38390.14', '0.00000000']], 'time': '2021-05-20T03:56:27.460156Z'}
{'type': 'l2update', 'product_id': 'BTC-USD', 'changes': [['sell', '38528.67', '0.01000000']], 'time': '2021-05-20T03:56:27.460338Z'}
{'type': 'l2update', 'product_id': 'BTC-USD', 'changes': [['sell', '38453.69', '0.02600625']], 'time': '2021-05-20T03:56:27.460407Z'}
{'type': 'l2update', 'product_id': 'BTC-USD', 'changes': [['sell', '38375.03', '0.00000000']], 'time': '2021-05-20T03:56:27.462085Z'}
{'type': 'l2update', 'product_id': 'BTC-USD', 'changes': [['buy', '38343.35', '0.00000000']], 'time': '2021-05-20T03:56:27.462235Z'}
{'type': 'l2update', 'product_id': 'BTC-USD', 'changes': [['buy', '38195.12', '0.00000000']], 'time': '2021-05-20T03:56:27.465535Z'}
{'type': 'l2update', 'product_id': 'BTC-USD', 'changes': [['sell', '38398.74', '0.00000000']], 'time': '2021-05-20T03:56:27.465679Z'}
{'type': 'l2update', 'product_id': 'BTC-USD', 'changes': [['sell', '38457.76', '0.40882511']], 'time': '2021-05-20T03:56:27.466125Z'}
{'type': 'l2update', 'product_id': 'BTC-USD', 'changes': [['sell', '38363.20', '0.36742436']], 'time': '2021-05-20T03:56:27.466125Z'}
{'type': 'l2update', 'product_id': 'BTC-USD', 'changes': [['sell', '38506.66', '0.30078656']], 'time': '2021-05-20T03:56:27.470312Z'}
{'type': 'l2update', 'product_id': 'BTC-USD', 'changes': [['buy', '38129.78', '0.00200516']], 'time': '2021-05-20T03:56:27.470495Z'}
{'type': 'l2update', 'product_id': 'BTC-USD', 'changes': [['sell', '38363.33', '0.00653605']], 'time': '2021-05-20T03:56:27.471661Z'}
{'type': 'l2update', 'product_id': 'BTC-USD', 'changes': [['sell', '38363.20', '0.41461953']], 'time': '2021-05-20T03:56:27.471661Z'}
{'type': 'l2update', 'product_id': 'BTC-USD', 'changes': [['buy', '38312.51', '0.00000000']], 'time': '2021-05-20T03:56:27.478463Z'}
{'type': 'l2update', 'product_id': 'BTC-USD', 'changes': [['buy', '38173.01', '0.00000000']], 'time': '2021-05-20T03:56:27.482543Z'}
{'type': 'l2update', 'product_id': 'BTC-USD', 'changes': [['sell', '38356.21', '0.00000000']], 'time': '2021-05-20T03:56:27.484893Z'}
{'type': 'l2update', 'product_id': 'BTC-USD', 'changes': [['buy', '38277.81', '0.09000000']], 'time': '2021-05-20T03:56:27.485756Z'}
{'type': 'l2update', 'product_id': 'BTC-USD', 'changes': [['sell', '38386.38', '0.09655713']], 'time': '2021-05-20T03:56:27.485899Z'}
{'type': 'l2update', 'product_id': 'BTC-USD', 'changes': [['sell', '38360.14', '0.50573000']], 'time': '2021-05-20T03:56:27.486833Z'}
{'type': 'l2update', 'product_id': 'BTC-USD', 'changes': [['sell', '38375.94', '1.29775727']], 'time': '2021-05-20T03:56:27.487634Z'}
{'type': 'l2update', 'product_id': 'BTC-USD', 'changes': [['sell', '38399.99', '0.00000000']], 'time': '2021-05-20T03:56:27.487904Z'}
{'type': 'l2update', 'product_id': 'BTC-USD', 'changes': [['buy', '38335.33', '0.00000000']], 'time': '2021-05-20T03:56:27.490744Z'}
{'type': 'l2update', 'product_id': 'BTC-USD', 'changes': [['buy', '38333.99', '0.00000000']], 'time': '2021-05-20T03:56:27.490744Z'}
{'type': 'l2update', 'product_id': 'BTC-USD', 'changes': [['sell', '38364.47', '0.00600000']], 'time': '2021-05-20T03:56:27.493992Z'}
{'type': 'l2update', 'product_id': 'BTC-USD', 'changes': [['sell', '38476.98', '0.00000000']], 'time': '2021-05-20T03:56:27.495283Z'}
{'type': 'l2update', 'product_id': 'BTC-USD', 'changes': [['buy', '38315.04', '0.00000000']], 'time': '2021-05-20T03:56:27.496777Z'}
{'type': 'l2update', 'product_id': 'BTC-USD', 'changes': [['sell', '38363.88', '0.00000000']], 'time': '2021-05-20T03:56:27.496777Z'}
{'type': 'l2update', 'product_id': 'BTC-USD', 'changes': [['buy', '38329.20', '0.00000000']], 'time': '2021-05-20T03:56:27.497117Z'}
{'type': 'l2update', 'product_id': 'BTC-USD', 'changes': [['sell', '38393.95', '0.00000000']], 'time': '2021-05-20T03:56:27.497856Z'}
{'type': 'l2update', 'product_id': 'BTC-USD', 'changes': [['sell', '38352.27', '0.14270000']], 'time': '2021-05-20T03:56:27.499596Z'}
{'type': 'l2update', 'product_id': 'BTC-USD', 'changes': [['sell', '38489.43', '0.01000000']], 'time': '2021-05-20T03:56:27.499891Z'}
{'type': 'l2update', 'product_id': 'BTC-USD', 'changes': [['sell', '38495.81', '0.00000000']], 'time': '2021-05-20T03:56:27.501423Z'}
{'type': 'l2update', 'product_id': 'BTC-USD', 'changes': [['sell', '38408.05', '0.00000000']], 'time': '2021-05-20T03:56:27.505013Z'}
{'type': 'l2update', 'product_id': 'BTC-USD', 'changes': [['sell', '38359.37', '0.32206089']], 'time': '2021-05-20T03:56:27.511939Z'}
{'type': 'l2update', 'product_id': 'BTC-USD', 'changes': [['buy', '38179.06', '0.02619236']], 'time': '2021-05-20T03:56:27.513757Z'}
{'type': 'l2update', 'product_id': 'BTC-USD', 'changes': [['sell', '38388.38', '0.00000000']], 'time': '2021-05-20T03:56:27.515550Z'}
{'type': 'l2update', 'product_id': 'BTC-USD', 'changes': [['sell', '38386.38', '0.04655713']], 'time': '2021-05-20T03:56:27.515617Z'}
{'type': 'l2update', 'product_id': 'BTC-USD', 'changes': [['buy', '38352.26', '0.00000000']], 'time': '2021-05-20T03:56:27.516029Z'}
{'type': 'l2update', 'product_id': 'BTC-USD', 'changes': [['buy', '38352.16', '0.00000001']], 'time': '2021-05-20T03:56:27.516029Z'}
{'type': 'l2update', 'product_id': 'BTC-USD', 'changes': [['buy', '38159.08', '0.95045544']], 'time': '2021-05-20T03:56:27.516141Z'}
{'type': 'l2update', 'product_id': 'BTC-USD', 'changes': [['sell', '38375.48', '0.04655713']], 'time': '2021-05-20T03:56:27.518607Z'}
{'type': 'l2update', 'product_id': 'BTC-USD', 'changes': [['sell', '38363.43', '0.01255528']], 'time': '2021-05-20T03:56:27.519177Z'}
{'type': 'l2update', 'product_id': 'BTC-USD', 'changes': [['sell', '38363.44', '0.30000000']], 'time': '2021-05-20T03:56:27.521608Z'}
{'type': 'l2update', 'product_id': 'BTC-USD', 'changes': [['sell', '38375.94', '1.19775727']], 'time': '2021-05-20T03:56:27.521755Z'}
{'type': 'l2update', 'product_id': 'BTC-USD', 'changes': [['sell', '38494.88', '0.00000000']], 'time': '2021-05-20T03:56:27.523615Z'}
{'type': 'l2update', 'product_id': 'BTC-USD', 'changes': [['buy', '38277.81', '0.14000000']], 'time': '2021-05-20T03:56:27.525756Z'}
{'type': 'l2update', 'product_id': 'BTC-USD', 'changes': [['sell', '38360.13', '2.48969908']], 'time': '2021-05-20T03:56:27.526593Z'}
{'type': 'l2update', 'product_id': 'BTC-USD', 'changes': [['sell', '38365.65', '0.00000000']], 'time': '2021-05-20T03:56:27.526677Z'}
{'type': 'l2update', 'product_id': 'BTC-USD', 'changes': [['sell', '38498.14', '0.05913220']], 'time': '2021-05-20T03:56:27.530437Z'}
{'type': 'l2update', 'product_id': 'BTC-USD', 'changes': [['buy', '38331.96', '0.02400000']], 'time': '2021-05-20T03:56:27.532665Z'}
{'type': 'l2update', 'product_id': 'BTC-USD', 'changes': [['buy', '38331.15', '0.02400000']], 'time': '2021-05-20T03:56:27.532665Z'}
{'type': 'l2update', 'product_id': 'BTC-USD', 'changes': [['buy', '38337.11', '0.00000000']], 'time': '2021-05-20T03:56:27.532731Z'}
{'type': 'l2update', 'product_id': 'BTC-USD', 'changes': [['sell', '38457.75', '0.01229727']], 'time': '2021-05-20T03:56:27.536125Z'}
{'type': 'l2update', 'product_id': 'BTC-USD', 'changes': [['sell', '38443.30', '0.00000000']], 'time': '2021-05-20T03:56:27.537404Z'}
{'type': 'l2update', 'product_id': 'BTC-USD', 'changes': [['buy', '38255.49', '0.00000000']], 'time': '2021-05-20T03:56:27.538949Z'}
{'type': 'l2update', 'product_id': 'BTC-USD', 'changes': [['sell', '38458.67', '0.00000000']], 'time': '2021-05-20T03:56:27.543888Z'}
{'type': 'l2update', 'product_id': 'BTC-USD', 'changes': [['sell', '38451.86', '0.34517721']], 'time': '2021-05-20T03:56:27.545984Z'}
{'type': 'l2update', 'product_id': 'BTC-USD', 'changes': [['sell', '38363.20', '0.70605051']], 'time': '2021-05-20T03:56:27.545984Z'}
{'type': 'l2update', 'product_id': 'BTC-USD', 'changes': [['sell', '38447.82', '0.09286873']], 'time': '2021-05-20T03:56:27.557996Z'}
{'type': 'l2update', 'product_id': 'BTC-USD', 'changes': [['sell', '38447.82', '0.05451857']], 'time': '2021-05-20T03:56:27.557996Z'}
{'type': 'l2update', 'product_id': 'BTC-USD', 'changes': [['sell', '38363.39', '0.00000000']], 'time': '2021-05-20T03:56:27.560485Z'}
{'type': 'l2update', 'product_id': 'BTC-USD', 'changes': [['sell', '38375.93', '0.29997000']], 'time': '2021-05-20T03:56:27.560767Z'}
{'type': 'l2update', 'product_id': 'BTC-USD', 'changes': [['sell', '38360.14', '0.00573000']], 'time': '2021-05-20T03:56:27.561799Z'}
{'type': 'l2update', 'product_id': 'BTC-USD', 'changes': [['sell', '38627.53', '0.00000000']], 'time': '2021-05-20T03:56:27.562028Z'}
{'type': 'l2update', 'product_id': 'BTC-USD', 'changes': [['sell', '38352.27', '0.11716108']], 'time': '2021-05-20T03:56:27.566552Z'}
{'type': 'l2update', 'product_id': 'BTC-USD', 'changes': [['sell', '38352.17', '0.02890000']], 'time': '2021-05-20T03:56:27.566614Z'}
{'type': 'l2update', 'product_id': 'BTC-USD', 'changes': [['sell', '38352.17', '0.04382000']], 'time': '2021-05-20T03:56:27.567007Z'}
{'type': 'l2update', 'product_id': 'BTC-USD', 'changes': [['sell', '38384.03', '0.05000000']], 'time': '2021-05-20T03:56:27.567718Z'}
{'type': 'l2update', 'product_id': 'BTC-USD', 'changes': [['sell', '38352.17', '0.11842000']], 'time': '2021-05-20T03:56:27.567818Z'}
{'type': 'l2update', 'product_id': 'BTC-USD', 'changes': [['sell', '38401.06', '0.00000000']], 'time': '2021-05-20T03:56:27.567927Z'}
{'type': 'l2update', 'product_id': 'BTC-USD', 'changes': [['sell', '38495.68', '0.00000000']], 'time': '2021-05-20T03:56:27.571014Z'}
{'type': 'l2update', 'product_id': 'BTC-USD', 'changes': [['sell', '38465.50', '0.01262370']], 'time': '2021-05-20T03:56:27.574240Z'}
{'type': 'l2update', 'product_id': 'BTC-USD', 'changes': [['sell', '38383.70', '0.03000000']], 'time': '2021-05-20T03:56:27.574536Z'}
{'type': 'l2update', 'product_id': 'BTC-USD', 'changes': [['sell', '38360.20', '0.05000000']], 'time': '2021-05-20T03:56:27.574565Z'}
{'type': 'l2update', 'product_id': 'BTC-USD', 'changes': [['buy', '38350.53', '0.00000000']], 'time': '2021-05-20T03:56:27.574661Z'}
{'type': 'l2update', 'product_id': 'BTC-USD', 'changes': [['buy', '38304.96', '1.98886958']], 'time': '2021-05-20T03:56:27.583865Z'}
{'type': 'l2update', 'product_id': 'BTC-USD', 'changes': [['buy', '37991.17', '5.00000000']], 'time': '2021-05-20T03:56:27.583978Z'}
{'type': 'l2update', 'product_id': 'BTC-USD', 'changes': [['buy', '38352.16', '0.00000000']], 'time': '2021-05-20T03:56:27.584043Z'}
{'type': 'l2update', 'product_id': 'BTC-USD', 'changes': [['sell', '38350.53', '0.78190000']], 'time': '2021-05-20T03:56:27.584056Z'}
{'type': 'l2update', 'product_id': 'BTC-USD', 'changes': [['sell', '38482.66', '0.00000000']], 'time': '2021-05-20T03:56:27.585577Z'}
{'type': 'l2update', 'product_id': 'BTC-USD', 'changes': [['buy', '38333.18', '0.00000000']], 'time': '2021-05-20T03:56:27.588482Z'}
{'type': 'l2update', 'product_id': 'BTC-USD', 'changes': [['buy', '38331.96', '0.00000000']], 'time': '2021-05-20T03:56:27.588482Z'}
{'type': 'l2update', 'product_id': 'BTC-USD', 'changes': [['buy', '38331.15', '0.00000000']], 'time': '2021-05-20T03:56:27.588482Z'}
{'type': 'l2update', 'product_id': 'BTC-USD', 'changes': [['sell', '38447.82', '0.02762712']], 'time': '2021-05-20T03:56:27.593572Z'}
{'type': 'l2update', 'product_id': 'BTC-USD', 'changes': [['sell', '38375.13', '0.00000000']], 'time': '2021-05-20T03:56:27.594791Z'}
{'type': 'l2update', 'product_id': 'BTC-USD', 'changes': [['sell', '38363.71', '0.20100000']], 'time': '2021-05-20T03:56:27.598850Z'}
{'type': 'l2update', 'product_id': 'BTC-USD', 'changes': [['sell', '38548.91', '0.01000000']], 'time': '2021-05-20T03:56:27.599073Z'}
{'type': 'l2update', 'product_id': 'BTC-USD', 'changes': [['sell', '38352.27', '0.00336108']], 'time': '2021-05-20T03:56:27.602464Z'}
{'type': 'l2update', 'product_id': 'BTC-USD', 'changes': [['sell', '38356.21', '0.00573000']], 'time': '2021-05-20T03:56:27.604530Z'}
{'type': 'l2update', 'product_id': 'BTC-USD', 'changes': [['sell', '38384.03', '0.00000000']], 'time': '2021-05-20T03:56:27.604900Z'}
{'type': 'l2update', 'product_id': 'BTC-USD', 'changes': [['sell', '38609.69', '0.01000000']], 'time': '2021-05-20T03:56:27.610904Z'}
{'type': 'l2update', 'product_id': 'BTC-USD', 'changes': [['sell', '38352.27', '0.50336108']], 'time': '2021-05-20T03:56:27.611132Z'}
{'type': 'l2update', 'product_id': 'BTC-USD', 'changes': [['buy', '38321.82', '0.00000000']], 'time': '2021-05-20T03:56:27.613408Z'}
{'type': 'l2update', 'product_id': 'BTC-USD', 'changes': [['sell', '38386.65', '0.03207306']], 'time': '2021-05-20T03:56:27.618858Z'}
{'type': 'l2update', 'product_id': 'BTC-USD', 'changes': [['sell', '38377.22', '0.01000000']], 'time': '2021-05-20T03:56:27.619234Z'}
{'type': 'l2update', 'product_id': 'BTC-USD', 'changes': [['sell', '38360.13', '0.00000000']], 'time': '2021-05-20T03:56:27.619400Z'}
{'type': 'l2update', 'product_id': 'BTC-USD', 'changes': [['sell', '38489.43', '0.00000000']], 'time': '2021-05-20T03:56:27.620066Z'}
{'type': 'l2update', 'product_id': 'BTC-USD', 'changes': [['sell', '38352.17', '0.04382000']], 'time': '2021-05-20T03:56:27.620527Z'}
{'type': 'l2update', 'product_id': 'BTC-USD', 'changes': [['sell', '38352.17', '0.02890000']], 'time': '2021-05-20T03:56:27.621409Z'}
{'type': 'l2update', 'product_id': 'BTC-USD', 'changes': [['sell', '38352.17', '0.00000000']], 'time': '2021-05-20T03:56:27.622551Z'}
{'type': 'l2update', 'product_id': 'BTC-USD', 'changes': [['sell', '38365.70', '0.00000000']], 'time': '2021-05-20T03:56:27.623283Z'}
{'type': 'l2update', 'product_id': 'BTC-USD', 'changes': [['sell', '38352.27', '0.50000000']], 'time': '2021-05-20T03:56:27.624543Z'}
{'type': 'l2update', 'product_id': 'BTC-USD', 'changes': [['buy', '38337.12', '0.00000000']], 'time': '2021-05-20T03:56:27.627226Z'}
{'type': 'l2update', 'product_id': 'BTC-USD', 'changes': [['sell', '38506.66', '0.00000000']], 'time': '2021-05-20T03:56:27.627519Z'}
{'type': 'l2update', 'product_id': 'BTC-USD', 'changes': [['buy', '38337.47', '0.01492000']], 'time': '2021-05-20T03:56:27.630488Z'}
{'type': 'l2update', 'product_id': 'BTC-USD', 'changes': [['sell', '38349.82', '0.05000000']], 'time': '2021-05-20T03:56:27.630968Z'}
{'type': 'l2update', 'product_id': 'BTC-USD', 'changes': [['sell', '38376.02', '0.04000000']], 'time': '2021-05-20T03:56:27.631251Z'}
{'type': 'l2update', 'product_id': 'BTC-USD', 'changes': [['sell', '38519.53', '0.00000000']], 'time': '2021-05-20T03:56:27.634544Z'}
{'type': 'l2update', 'product_id': 'BTC-USD', 'changes': [['sell', '38453.69', '0.00000000']], 'time': '2021-05-20T03:56:27.634696Z'}
{'type': 'l2update', 'product_id': 'BTC-USD', 'changes': [['sell', '38363.38', '0.35150000']], 'time': '2021-05-20T03:56:27.634719Z'}
{'type': 'l2update', 'product_id': 'BTC-USD', 'changes': [['sell', '38499.21', '0.00000000']], 'time': '2021-05-20T03:56:27.637434Z'}
{'type': 'l2update', 'product_id': 'BTC-USD', 'changes': [['sell', '38376.07', '0.50000000']], 'time': '2021-05-20T03:56:27.639347Z'}
{'type': 'l2update', 'product_id': 'BTC-USD', 'changes': [['buy', '38325.02', '0.02400000']], 'time': '2021-05-20T03:56:27.639498Z'}
{'type': 'l2update', 'product_id': 'BTC-USD', 'changes': [['buy', '38324.21', '0.02400000']], 'time': '2021-05-20T03:56:27.639498Z'}
{'type': 'l2update', 'product_id': 'BTC-USD', 'changes': [['buy', '38323.40', '0.02400000']], 'time': '2021-05-20T03:56:27.639498Z'}
{'type': 'l2update', 'product_id': 'BTC-USD', 'changes': [['sell', '38392.76', '0.49852335']], 'time': '2021-05-20T03:56:27.639592Z'}
{'type': 'l2update', 'product_id': 'BTC-USD', 'changes': [['buy', '38326.92', '0.00000000']], 'time': '2021-05-20T03:56:27.645647Z'}
{'type': 'l2update', 'product_id': 'BTC-USD', 'changes': [['sell', '38379.41', '0.05000000']], 'time': '2021-05-20T03:56:27.647898Z'}
{'type': 'l2update', 'product_id': 'BTC-USD', 'changes': [['sell', '38365.65', '2.54400000']], 'time': '2021-05-20T03:56:27.648691Z'}
{'type': 'l2update', 'product_id': 'BTC-USD', 'changes': [['sell', '38364.47', '0.00000000']], 'time': '2021-05-20T03:56:27.652635Z'}
{'type': 'l2update', 'product_id': 'BTC-USD', 'changes': [['sell', '38367.85', '0.10000000']], 'time': '2021-05-20T03:56:27.653612Z'}
{'type': 'l2update', 'product_id': 'BTC-USD', 'changes': [['buy', '38238.70', '0.02400000']], 'time': '2021-05-20T03:56:27.653816Z'}
{'type': 'l2update', 'product_id': 'BTC-USD', 'changes': [['buy', '38277.83', '0.48485117']], 'time': '2021-05-20T03:56:27.654054Z'}
{'type': 'l2update', 'product_id': 'BTC-USD', 'changes': [['sell', '38447.82', '0.00000000']], 'time': '2021-05-20T03:56:27.656673Z'}
{'type': 'l2update', 'product_id': 'BTC-USD', 'changes': [['sell', '38363.20', '0.78088200']], 'time': '2021-05-20T03:56:27.656852Z'}
{'type': 'l2update', 'product_id': 'BTC-USD', 'changes': [['sell', '38375.93', '0.19997000']], 'time': '2021-05-20T03:56:27.657065Z'}
{'type': 'l2update', 'product_id': 'BTC-USD', 'changes': [['buy', '38294.79', '0.01000000']], 'time': '2021-05-20T03:56:27.661077Z'}
{'type': 'l2update', 'product_id': 'BTC-USD', 'changes': [['buy', '38337.47', '0.00000000']], 'time': '2021-05-20T03:56:27.663072Z'}
{'type': 'l2update', 'product_id': 'BTC-USD', 'changes': [['sell', '38496.56', '0.33000000']], 'time': '2021-05-20T03:56:27.664325Z'}
{'type': 'l2update', 'product_id': 'BTC-USD', 'changes': [['sell', '38478.63', '0.01192726']], 'time': '2021-05-20T03:56:27.664598Z'}
{'type': 'l2update', 'product_id': 'BTC-USD', 'changes': [['buy', '38347.28', '0.57900000']], 'time': '2021-05-20T03:56:27.664669Z'}
{'type': 'l2update', 'product_id': 'BTC-USD', 'changes': [['sell', '38349.85', '0.07460000']], 'time': '2021-05-20T03:56:27.665319Z'}
{'type': 'l2update', 'product_id': 'BTC-USD', 'changes': [['sell', '38350.03', '0.01492000']], 'time': '2021-05-20T03:56:27.665618Z'}
{'type': 'l2update', 'product_id': 'BTC-USD', 'changes': [['sell', '38372.84', '0.47639409']], 'time': '2021-05-20T03:56:27.665762Z'}
{'type': 'l2update', 'product_id': 'BTC-USD', 'changes': [['sell', '38373.67', '0.30000000']], 'time': '2021-05-20T03:56:27.667066Z'}
{'type': 'l2update', 'product_id': 'BTC-USD', 'changes': [['buy', '38333.46', '0.00000000']], 'time': '2021-05-20T03:56:27.667488Z'}
{'type': 'l2update', 'product_id': 'BTC-USD', 'changes': [['buy', '38266.69', '0.00000000']], 'time': '2021-05-20T03:56:27.669339Z'}
{'type': 'l2update', 'product_id': 'BTC-USD', 'changes': [['sell', '38373.43', '0.67332131']], 'time': '2021-05-20T03:56:27.671362Z'}
{'type': 'l2update', 'product_id': 'BTC-USD', 'changes': [['buy', '38239.57', '0.00000000']], 'time': '2021-05-20T03:56:27.673203Z'}
{'type': 'l2update', 'product_id': 'BTC-USD', 'changes': [['buy', '38325.02', '0.00000000']], 'time': '2021-05-20T03:56:27.673391Z'}
{'type': 'l2update', 'product_id': 'BTC-USD', 'changes': [['buy', '38324.21', '0.00000000']], 'time': '2021-05-20T03:56:27.673391Z'}
{'type': 'l2update', 'product_id': 'BTC-USD', 'changes': [['buy', '38323.40', '0.00000000']], 'time': '2021-05-20T03:56:27.673391Z'}
{'type': 'l2update', 'product_id': 'BTC-USD', 'changes': [['sell', '38376.04', '0.05000000']], 'time': '2021-05-20T03:56:27.678749Z'}
{'type': 'l2update', 'product_id': 'BTC-USD', 'changes': [['sell', '38352.27', '0.50573000']], 'time': '2021-05-20T03:56:27.679524Z'}
{'type': 'l2update', 'product_id': 'BTC-USD', 'changes': [['sell', '38406.38', '0.00000000']], 'time': '2021-05-20T03:56:27.680267Z'}
{'type': 'l2update', 'product_id': 'BTC-USD', 'changes': [['sell', '38379.41', '0.00000000']], 'time': '2021-05-20T03:56:27.682344Z'}
{'type': 'l2update', 'product_id': 'BTC-USD', 'changes': [['sell', '38486.82', '0.00000000']], 'time': '2021-05-20T03:56:27.689426Z'}
{'type': 'l2update', 'product_id': 'BTC-USD', 'changes': [['sell', '38373.70', '2.16932808']], 'time': '2021-05-20T03:56:27.696228Z'}
{'type': 'l2update', 'product_id': 'BTC-USD', 'changes': [['buy', '38296.51', '0.05472665']], 'time': '2021-05-20T03:56:27.696889Z'}
{'type': 'l2update', 'product_id': 'BTC-USD', 'changes': [['sell', '38352.27', '0.56074140']], 'time': '2021-05-20T03:56:27.696889Z'}
{'type': 'l2update', 'product_id': 'BTC-USD', 'changes': [['sell', '38476.37', '0.00000000']], 'time': '2021-05-20T03:56:27.698395Z'}
{'type': 'l2update', 'product_id': 'BTC-USD', 'changes': [['sell', '38386.38', '0.00000000']], 'time': '2021-05-20T03:56:27.698618Z'}
{'type': 'l2update', 'product_id': 'BTC-USD', 'changes': [['buy', '38304.96', '0.00000000']], 'time': '2021-05-20T03:56:27.698682Z'}
{'type': 'l2update', 'product_id': 'BTC-USD', 'changes': [['sell', '38349.85', '0.00000000']], 'time': '2021-05-20T03:56:27.704135Z'}
{'type': 'l2update', 'product_id': 'BTC-USD', 'changes': [['buy', '38123.81', '0.00000000']], 'time': '2021-05-20T03:56:27.704726Z'}
{'type': 'l2update', 'product_id': 'BTC-USD', 'changes': [['buy', '38266.02', '0.03497333']], 'time': '2021-05-20T03:56:27.704804Z'}
{'type': 'l2update', 'product_id': 'BTC-USD', 'changes': [['buy', '38271.89', '0.01299913']], 'time': '2021-05-20T03:56:27.704804Z'}
{'type': 'l2update', 'product_id': 'BTC-USD', 'changes': [['sell', '38350.03', '0.00000000']], 'time': '2021-05-20T03:56:27.705085Z'}
{'type': 'l2update', 'product_id': 'BTC-USD', 'changes': [['buy', '38304.95', '0.00000000']], 'time': '2021-05-20T03:56:27.705795Z'}
{'type': 'l2update', 'product_id': 'BTC-USD', 'changes': [['sell', '38396.22', '0.00000000']], 'time': '2021-05-20T03:56:27.706890Z'}
{'type': 'l2update', 'product_id': 'BTC-USD', 'changes': [['sell', '38377.22', '0.00000000']], 'time': '2021-05-20T03:56:27.712407Z'}
{'type': 'l2update', 'product_id': 'BTC-USD', 'changes': [['sell', '38504.42', '0.01587657']], 'time': '2021-05-20T03:56:27.713486Z'}
{'type': 'l2update', 'product_id': 'BTC-USD', 'changes': [['buy', '38241.51', '0.01000000']], 'time': '2021-05-20T03:56:27.714229Z'}
{'type': 'l2update', 'product_id': 'BTC-USD', 'changes': [['sell', '38360.14', '0.00000000']], 'time': '2021-05-20T03:56:27.715564Z'}
{'type': 'l2update', 'product_id': 'BTC-USD', 'changes': [['sell', '38375.36', '0.05000000']], 'time': '2021-05-20T03:56:27.725350Z'}
{'type': 'l2update', 'product_id': 'BTC-USD', 'changes': [['sell', '38374.63', '0.01000000']], 'time': '2021-05-20T03:56:27.725542Z'}
{'type': 'l2update', 'product_id': 'BTC-USD', 'changes': [['sell', '38446.52', '0.11810000']], 'time': '2021-05-20T03:56:27.725963Z'}
{'type': 'l2update', 'product_id': 'BTC-USD', 'changes': [['buy', '38347.28', '0.00000000']], 'time': '2021-05-20T03:56:27.726707Z'}
{'type': 'l2update', 'product_id': 'BTC-USD', 'changes': [['sell', '38352.32', '0.00600000']], 'time': '2021-05-20T03:56:27.726911Z'}
{'type': 'l2update', 'product_id': 'BTC-USD', 'changes': [['sell', '38479.17', '0.02459730']], 'time': '2021-05-20T03:56:27.727132Z'}
{'type': 'l2update', 'product_id': 'BTC-USD', 'changes': [['buy', '38300.61', '0.02610924']], 'time': '2021-05-20T03:56:27.727150Z'}
{'type': 'l2update', 'product_id': 'BTC-USD', 'changes': [['sell', '38350.52', '0.05000000']], 'time': '2021-05-20T03:56:27.727670Z'}
{'type': 'l2update', 'product_id': 'BTC-USD', 'changes': [['buy', '38184.87', '0.00000000']], 'time': '2021-05-20T03:56:27.729370Z'}
{'type': 'l2update', 'product_id': 'BTC-USD', 'changes': [['buy', '38279.53', '0.00000000']], 'time': '2021-05-20T03:56:27.729370Z'}
{'type': 'l2update', 'product_id': 'BTC-USD', 'changes': [['sell', '38392.77', '0.00000000']], 'time': '2021-05-20T03:56:27.729370Z'}
{'type': 'l2update', 'product_id': 'BTC-USD', 'changes': [['sell', '38487.42', '0.00000000']], 'time': '2021-05-20T03:56:27.729370Z'}
{'type': 'l2update', 'product_id': 'BTC-USD', 'changes': [['sell', '38373.67', '0.10000000']], 'time': '2021-05-20T03:56:27.729926Z'}
{'type': 'l2update', 'product_id': 'BTC-USD', 'changes': [['buy', '38326.93', '0.00000000']], 'time': '2021-05-20T03:56:27.734163Z'}
{'type': 'l2update', 'product_id': 'BTC-USD', 'changes': [['sell', '38399.53', '0.11857879']], 'time': '2021-05-20T03:56:27.734333Z'}
{'type': 'l2update', 'product_id': 'BTC-USD', 'changes': [['sell', '38495.07', '0.01000000']], 'time': '2021-05-20T03:56:27.736512Z'}
{'type': 'l2update', 'product_id': 'BTC-USD', 'changes': [['sell', '38465.66', '0.00000000']], 'time': '2021-05-20T03:56:27.736627Z'}
{'type': 'l2update', 'product_id': 'BTC-USD', 'changes': [['sell', '38469.86', '0.01000000']], 'time': '2021-05-20T03:56:27.736655Z'}
{'type': 'l2update', 'product_id': 'BTC-USD', 'changes': [['buy', '38225.74', '0.00000000']], 'time': '2021-05-20T03:56:27.739957Z'}
{'type': 'l2update', 'product_id': 'BTC-USD', 'changes': [['sell', '38484.06', '0.00000000']], 'time': '2021-05-20T03:56:27.741911Z'}
{'type': 'l2update', 'product_id': 'BTC-USD', 'changes': [['buy', '38294.79', '0.00000000']], 'time': '2021-05-20T03:56:27.744690Z'}
{'type': 'l2update', 'product_id': 'BTC-USD', 'changes': [['sell', '38360.13', '2.20861773']], 'time': '2021-05-20T03:56:27.747972Z'}
{'type': 'l2update', 'product_id': 'BTC-USD', 'changes': [['sell', '38414.66', '0.00000000']], 'time': '2021-05-20T03:56:27.750358Z'}
{'type': 'l2update', 'product_id': 'BTC-USD', 'changes': [['sell', '38347.29', '0.07460000']], 'time': '2021-05-20T03:56:27.753693Z'}
{'type': 'l2update', 'product_id': 'BTC-USD', 'changes': [['buy', '38326.94', '0.59116555']], 'time': '2021-05-20T03:56:27.754145Z'}
{'type': 'l2update', 'product_id': 'BTC-USD', 'changes': [['buy', '38323.32', '0.04996388']], 'time': '2021-05-20T03:56:27.757855Z'}
{'type': 'l2update', 'product_id': 'BTC-USD', 'changes': [['sell', '38352.17', '0.00573000']], 'time': '2021-05-20T03:56:27.757944Z'}
{'type': 'l2update', 'product_id': 'BTC-USD', 'changes': [['buy', '38321.83', '0.04655713']], 'time': '2021-05-20T03:56:27.758671Z'}
{'type': 'l2update', 'product_id': 'BTC-USD', 'changes': [['sell', '38347.29', '0.08952000']], 'time': '2021-05-20T03:56:27.758756Z'}
{'type': 'l2update', 'product_id': 'BTC-USD', 'changes': [['sell', '38375.36', '0.00000000']], 'time': '2021-05-20T03:56:27.759272Z'}
{'type': 'l2update', 'product_id': 'BTC-USD', 'changes': [['sell', '38352.27', '0.06074140']], 'time': '2021-05-20T03:56:27.760259Z'}
{'type': 'l2update', 'product_id': 'BTC-USD', 'changes': [['sell', '38367.86', '0.00000000']], 'time': '2021-05-20T03:56:27.762383Z'}
{'type': 'l2update', 'product_id': 'BTC-USD', 'changes': [['buy', '38304.43', '0.00000000']], 'time': '2021-05-20T03:56:27.762383Z'}
{'type': 'l2update', 'product_id': 'BTC-USD', 'changes': [['buy', '38296.52', '0.02400000']], 'time': '2021-05-20T03:56:27.763812Z'}
{'type': 'l2update', 'product_id': 'BTC-USD', 'changes': [['buy', '38295.71', '0.02400000']], 'time': '2021-05-20T03:56:27.763812Z'}
{'type': 'l2update', 'product_id': 'BTC-USD', 'changes': [['buy', '38294.90', '0.02400000']], 'time': '2021-05-20T03:56:27.763812Z'}
{'type': 'l2update', 'product_id': 'BTC-USD', 'changes': [['sell', '38365.65', '0.00000000']], 'time': '2021-05-20T03:56:27.764421Z'}
{'type': 'l2update', 'product_id': 'BTC-USD', 'changes': [['sell', '38392.76', '0.00000000']], 'time': '2021-05-20T03:56:27.764660Z'}
{'type': 'l2update', 'product_id': 'BTC-USD', 'changes': [['buy', '38300.63', '0.13000000']], 'time': '2021-05-20T03:56:27.765846Z'}
{'type': 'l2update', 'product_id': 'BTC-USD', 'changes': [['sell', '38374.73', '0.02000000']], 'time': '2021-05-20T03:56:27.766046Z'}
{'type': 'l2update', 'product_id': 'BTC-USD', 'changes': [['sell', '38349.84', '0.05000000']], 'time': '2021-05-20T03:56:27.766265Z'}
{'type': 'l2update', 'product_id': 'BTC-USD', 'changes': [['sell', '38429.49', '0.69256892']], 'time': '2021-05-20T03:56:27.766537Z'}
{'type': 'l2update', 'product_id': 'BTC-USD', 'changes': [['sell', '38399.53', '0.00000000']], 'time': '2021-05-20T03:56:27.767838Z'}
{'type': 'l2update', 'product_id': 'BTC-USD', 'changes': [['buy', '38220.42', '0.00000000']], 'time': '2021-05-20T03:56:27.767838Z'}
{'type': 'l2update', 'product_id': 'BTC-USD', 'changes': [['sell', '38422.89', '0.01301307']], 'time': '2021-05-20T03:56:27.780052Z'}
{'type': 'l2update', 'product_id': 'BTC-USD', 'changes': [['sell', '38424.89', '0.00000000']], 'time': '2021-05-20T03:56:27.780788Z'}
{'type': 'l2update', 'product_id': 'BTC-USD', 'changes': [['sell', '38486.30', '0.30082885']], 'time': '2021-05-20T03:56:27.783882Z'}
{'type': 'l2update', 'product_id': 'BTC-USD', 'changes': [['sell', '38440.81', '0.00000000']], 'time': '2021-05-20T03:56:27.783908Z'}
{'type': 'l2update', 'product_id': 'BTC-USD', 'changes': [['sell', '38347.29', '0.01492000']], 'time': '2021-05-20T03:56:27.784097Z'}
{'type': 'l2update', 'product_id': 'BTC-USD', 'changes': [['buy', '38247.27', '0.03232374']], 'time': '2021-05-20T03:56:27.784837Z'}
{'type': 'l2update', 'product_id': 'BTC-USD', 'changes': [['sell', '38356.21', '0.00000000']], 'time': '2021-05-20T03:56:27.787587Z'}
{'type': 'l2update', 'product_id': 'BTC-USD', 'changes': [['buy', '38328.09', '0.01492000']], 'time': '2021-05-20T03:56:27.790275Z'}
{'type': 'l2update', 'product_id': 'BTC-USD', 'changes': [['sell', '38347.29', '0.00000000']], 'time': '2021-05-20T03:56:27.791519Z'}
{'type': 'l2update', 'product_id': 'BTC-USD', 'changes': [['sell', '38375.37', '0.00000000']], 'time': '2021-05-20T03:56:27.791724Z'}
{'type': 'l2update', 'product_id': 'BTC-USD', 'changes': [['sell', '38373.67', '0.00000000']], 'time': '2021-05-20T03:56:27.795259Z'}
{'type': 'l2update', 'product_id': 'BTC-USD', 'changes': [['buy', '38296.52', '0.00000000']], 'time': '2021-05-20T03:56:27.796626Z'}
{'type': 'l2update', 'product_id': 'BTC-USD', 'changes': [['buy', '38295.71', '0.00000000']], 'time': '2021-05-20T03:56:27.796626Z'}
{'type': 'l2update', 'product_id': 'BTC-USD', 'changes': [['buy', '38294.90', '0.00000000']], 'time': '2021-05-20T03:56:27.796626Z'}
{'type': 'l2update', 'product_id': 'BTC-USD', 'changes': [['buy', '38281.82', '0.01000000']], 'time': '2021-05-20T03:56:27.800028Z'}
{'type': 'l2update', 'product_id': 'BTC-USD', 'changes': [['buy', '38138.75', '0.01000000']], 'time': '2021-05-20T03:56:27.801127Z'}
{'type': 'l2update', 'product_id': 'BTC-USD', 'changes': [['buy', '38285.33', '0.01000000']], 'time': '2021-05-20T03:56:27.801363Z'}
{'type': 'l2update', 'product_id': 'BTC-USD', 'changes': [['sell', '38360.12', '0.05000000']], 'time': '2021-05-20T03:56:27.801779Z'}
{'type': 'l2update', 'product_id': 'BTC-USD', 'changes': [['sell', '38360.20', '0.00000000']], 'time': '2021-05-20T03:56:27.802032Z'}
{'type': 'l2update', 'product_id': 'BTC-USD', 'changes': [['buy', '38277.81', '0.12000000']], 'time': '2021-05-20T03:56:27.802481Z'}
{'type': 'l2update', 'product_id': 'BTC-USD', 'changes': [['sell', '38373.44', '0.00000000']], 'time': '2021-05-20T03:56:27.802720Z'}
{'type': 'l2update', 'product_id': 'BTC-USD', 'changes': [['sell', '38347.49', '0.21400000']], 'time': '2021-05-20T03:56:27.806761Z'}
{'type': 'l2update', 'product_id': 'BTC-USD', 'changes': [['sell', '38438.53', '0.00000000']], 'time': '2021-05-20T03:56:27.808556Z'}
{'type': 'l2update', 'product_id': 'BTC-USD', 'changes': [['sell', '38381.45', '0.00000000']], 'time': '2021-05-20T03:56:27.811706Z'}
{'type': 'l2update', 'product_id': 'BTC-USD', 'changes': [['sell', '38431.93', '0.00000000']], 'time': '2021-05-20T03:56:27.813118Z'}
{'type': 'l2update', 'product_id': 'BTC-USD', 'changes': [['sell', '38577.61', '0.00000000']], 'time': '2021-05-20T03:56:27.820334Z'}
{'type': 'l2update', 'product_id': 'BTC-USD', 'changes': [['sell', '38498.14', '0.00000000']], 'time': '2021-05-20T03:56:27.820800Z'}
{'type': 'l2update', 'product_id': 'BTC-USD', 'changes': [['sell', '38421.52', '0.03578776']], 'time': '2021-05-20T03:56:27.820970Z'}
{'type': 'l2update', 'product_id': 'BTC-USD', 'changes': [['sell', '38476.88', '0.02600625']], 'time': '2021-05-20T03:56:27.821826Z'}
{'type': 'l2update', 'product_id': 'BTC-USD', 'changes': [['sell', '38375.94', '0.06379977']], 'time': '2021-05-20T03:56:27.825023Z'}
{'type': 'l2update', 'product_id': 'BTC-USD', 'changes': [['buy', '38300.61', '2.01497882']], 'time': '2021-05-20T03:56:27.826462Z'}
{'type': 'l2update', 'product_id': 'BTC-USD', 'changes': [['sell', '38346.95', '0.07460000']], 'time': '2021-05-20T03:56:27.826523Z'}
{'type': 'l2update', 'product_id': 'BTC-USD', 'changes': [['buy', '38240.64', '0.03711256']], 'time': '2021-05-20T03:56:27.826547Z'}
{'type': 'l2update', 'product_id': 'BTC-USD', 'changes': [['sell', '38466.36', '0.01000000']], 'time': '2021-05-20T03:56:27.827053Z'}
{'type': 'l2update', 'product_id': 'BTC-USD', 'changes': [['sell', '38347.29', '0.00573000']], 'time': '2021-05-20T03:56:27.827069Z'}
{'type': 'l2update', 'product_id': 'BTC-USD', 'changes': [['buy', '38333.79', '0.03884941']], 'time': '2021-05-20T03:56:27.830831Z'}
{'type': 'l2update', 'product_id': 'BTC-USD', 'changes': [['buy', '38323.32', '0.00000000']], 'time': '2021-05-20T03:56:27.831382Z'}
{'type': 'l2update', 'product_id': 'BTC-USD', 'changes': [['sell', '38360.12', '0.00000000']], 'time': '2021-05-20T03:56:27.836477Z'}
{'type': 'l2update', 'product_id': 'BTC-USD', 'changes': [['buy', '38277.82', '0.00000000']], 'time': '2021-05-20T03:56:27.838222Z'}
{'type': 'l2update', 'product_id': 'BTC-USD', 'changes': [['buy', '38328.47', '0.01021576']], 'time': '2021-05-20T03:56:27.840161Z'}
{'type': 'l2update', 'product_id': 'BTC-USD', 'changes': [['sell', '38342.71', '0.05061672']], 'time': '2021-05-20T03:56:27.840439Z'}
{'type': 'l2update', 'product_id': 'BTC-USD', 'changes': [['sell', '38349.42', '0.01492000']], 'time': '2021-05-20T03:56:27.841065Z'}
{'type': 'l2update', 'product_id': 'BTC-USD', 'changes': [['buy', '38144.83', '0.05000996']], 'time': '2021-05-20T03:56:27.846010Z'}
{'type': 'l2update', 'product_id': 'BTC-USD', 'changes': [['buy', '38220.42', '0.32227403']], 'time': '2021-05-20T03:56:27.847004Z'}
{'type': 'l2update', 'product_id': 'BTC-USD', 'changes': [['buy', '38241.87', '0.50000000']], 'time': '2021-05-20T03:56:27.847477Z'}
{'type': 'l2update', 'product_id': 'BTC-USD', 'changes': [['buy', '38281.59', '0.00000000']], 'time': '2021-05-20T03:56:27.854258Z'}
{'type': 'l2update', 'product_id': 'BTC-USD', 'changes': [['sell', '38375.49', '0.00000000']], 'time': '2021-05-20T03:56:27.861563Z'}
{'type': 'l2update', 'product_id': 'BTC-USD', 'changes': [['sell', '38360.13', '0.00000000']], 'time': '2021-05-20T03:56:27.862735Z'}
{'type': 'l2update', 'product_id': 'BTC-USD', 'changes': [['sell', '38475.32', '0.02287387']], 'time': '2021-05-20T03:56:27.864489Z'}
{'type': 'l2update', 'product_id': 'BTC-USD', 'changes': [['sell', '38346.95', '0.00000000']], 'time': '2021-05-20T03:56:27.864722Z'}
{'type': 'l2update', 'product_id': 'BTC-USD', 'changes': [['sell', '38363.44', '0.20000000']], 'time': '2021-05-20T03:56:27.865526Z'}
{'type': 'l2update', 'product_id': 'BTC-USD', 'changes': [['sell', '38352.27', '0.05501140']], 'time': '2021-05-20T03:56:27.865799Z'}
{'type': 'l2update', 'product_id': 'BTC-USD', 'changes': [['buy', '38328.09', '0.00000000']], 'time': '2021-05-20T03:56:27.869587Z'}
{'type': 'l2update', 'product_id': 'BTC-USD', 'changes': [['sell', '38417.47', '0.00000000']], 'time': '2021-05-20T03:56:27.869595Z'}
{'type': 'l2update', 'product_id': 'BTC-USD', 'changes': [['buy', '38277.81', '0.09000000']], 'time': '2021-05-20T03:56:27.871540Z'}
{'type': 'l2update', 'product_id': 'BTC-USD', 'changes': [['buy', '38328.47', '0.00000000']], 'time': '2021-05-20T03:56:27.873486Z'}
{'type': 'l2update', 'product_id': 'BTC-USD', 'changes': [['sell', '38367.80', '2.54300000']], 'time': '2021-05-20T03:56:27.875236Z'}
{'type': 'l2update', 'product_id': 'BTC-USD', 'changes': [['sell', '38375.93', '0.00000000']], 'time': '2021-05-20T03:56:27.875266Z'}
{'type': 'l2update', 'product_id': 'BTC-USD', 'changes': [['buy', '38233.82', '0.03708562']], 'time': '2021-05-20T03:56:27.875480Z'}
{'type': 'l2update', 'product_id': 'BTC-USD', 'changes': [['buy', '38328.47', '0.00558392']], 'time': '2021-05-20T03:56:27.875817Z'}
{'type': 'l2update', 'product_id': 'BTC-USD', 'changes': [['sell', '38349.42', '0.00000000']], 'time': '2021-05-20T03:56:27.877873Z'}
{'type': 'l2update', 'product_id': 'BTC-USD', 'changes': [['buy', '38241.51', '0.00000000']], 'time': '2021-05-20T03:56:27.879143Z'}
{'type': 'l2update', 'product_id': 'BTC-USD', 'changes': [['sell', '38363.19', '0.05000000']], 'time': '2021-05-20T03:56:27.880535Z'}
{'type': 'l2update', 'product_id': 'BTC-USD', 'changes': [['buy', '38290.20', '0.02611634']], 'time': '2021-05-20T03:56:27.880590Z'}
{'type': 'l2update', 'product_id': 'BTC-USD', 'changes': [['buy', '38274.15', '0.00000000']], 'time': '2021-05-20T03:56:27.881037Z'}
{'type': 'l2update', 'product_id': 'BTC-USD', 'changes': [['buy', '38279.72', '0.02400000']], 'time': '2021-05-20T03:56:27.883134Z'}
{'type': 'l2update', 'product_id': 'BTC-USD', 'changes': [['buy', '38278.92', '0.02400000']], 'time': '2021-05-20T03:56:27.883134Z'}
{'type': 'l2update', 'product_id': 'BTC-USD', 'changes': [['buy', '38278.11', '0.02400000']], 'time': '2021-05-20T03:56:27.883134Z'}
{'type': 'l2update', 'product_id': 'BTC-USD', 'changes': [['sell', '38528.67', '0.00000000']], 'time': '2021-05-20T03:56:27.888192Z'}
{'type': 'l2update', 'product_id': 'BTC-USD', 'changes': [['buy', '38161.69', '0.80000000']], 'time': '2021-05-20T03:56:27.890449Z'}
{'type': 'l2update', 'product_id': 'BTC-USD', 'changes': [['buy', '38238.70', '0.00000000']], 'time': '2021-05-20T03:56:27.891601Z'}
{'type': 'l2update', 'product_id': 'BTC-USD', 'changes': [['sell', '38375.48', '0.00000000']], 'time': '2021-05-20T03:56:27.892286Z'}
{'type': 'l2update', 'product_id': 'BTC-USD', 'changes': [['buy', '38211.84', '0.39452502']], 'time': '2021-05-20T03:56:27.895817Z'}
{'type': 'l2update', 'product_id': 'BTC-USD', 'changes': [['sell', '38349.81', '0.00040000']], 'time': '2021-05-20T03:56:27.896225Z'}
{'type': 'l2update', 'product_id': 'BTC-USD', 'changes': [['sell', '38350.52', '0.41000000']], 'time': '2021-05-20T03:56:27.896329Z'}
{'type': 'l2update', 'product_id': 'BTC-USD', 'changes': [['sell', '38342.71', '0.00000000']], 'time': '2021-05-20T03:56:27.896575Z'}
{'type': 'l2update', 'product_id': 'BTC-USD', 'changes': [['sell', '38486.30', '0.00000000']], 'time': '2021-05-20T03:56:27.897249Z'}
{'type': 'l2update', 'product_id': 'BTC-USD', 'changes': [['buy', '38296.51', '0.00000000']], 'time': '2021-05-20T03:56:27.898475Z'}
{'type': 'l2update', 'product_id': 'BTC-USD', 'changes': [['sell', '38352.27', '0.00000000']], 'time': '2021-05-20T03:56:27.898475Z'}
{'type': 'l2update', 'product_id': 'BTC-USD', 'changes': [['sell', '38564.10', '0.02593085']], 'time': '2021-05-20T03:56:27.900757Z'}
{'type': 'l2update', 'product_id': 'BTC-USD', 'changes': [['buy', '38326.38', '0.04908630']], 'time': '2021-05-20T03:56:27.900775Z'}
{'type': 'l2update', 'product_id': 'BTC-USD', 'changes': [['sell', '38352.17', '0.00000000']], 'time': '2021-05-20T03:56:27.901886Z'}
{'type': 'l2update', 'product_id': 'BTC-USD', 'changes': [['sell', '38504.42', '0.00000000']], 'time': '2021-05-20T03:56:27.902015Z'}
{'type': 'l2update', 'product_id': 'BTC-USD', 'changes': [['sell', '38363.44', '0.00000000']], 'time': '2021-05-20T03:56:27.902153Z'}
{'type': 'l2update', 'product_id': 'BTC-USD', 'changes': [['buy', '38277.81', '0.05000000']], 'time': '2021-05-20T03:56:27.905934Z'}
{'type': 'l2update', 'product_id': 'BTC-USD', 'changes': [['buy', '38334.30', '0.01492000']], 'time': '2021-05-20T03:56:27.915028Z'}
{'type': 'l2update', 'product_id': 'BTC-USD', 'changes': [['sell', '38342.33', '0.07460000']], 'time': '2021-05-20T03:56:27.916281Z'}
{'type': 'l2update', 'product_id': 'BTC-USD', 'changes': [['buy', '38328.47', '0.06438424']], 'time': '2021-05-20T03:56:27.916298Z'}
{'type': 'l2update', 'product_id': 'BTC-USD', 'changes': [['sell', '38369.92', '0.01000000']], 'time': '2021-05-20T03:56:27.916348Z'}
{'type': 'l2update', 'product_id': 'BTC-USD', 'changes': [['sell', '38363.19', '0.00000000']], 'time': '2021-05-20T03:56:27.916905Z'}
{'type': 'l2update', 'product_id': 'BTC-USD', 'changes': [['sell', '38349.81', '2.49009908']], 'time': '2021-05-20T03:56:27.920605Z'}
{'type': 'l2update', 'product_id': 'BTC-USD', 'changes': [['buy', '38205.83', '0.01000000']], 'time': '2021-05-20T03:56:27.921025Z'}
{'type': 'l2update', 'product_id': 'BTC-USD', 'changes': [['sell', '38356.74', '0.06659154']], 'time': '2021-05-20T03:56:27.921363Z'}
{'type': 'l2update', 'product_id': 'BTC-USD', 'changes': [['sell', '38469.35', '0.03610677']], 'time': '2021-05-20T03:56:27.921616Z'}
{'type': 'l2update', 'product_id': 'BTC-USD', 'changes': [['buy', '38226.82', '0.03610677']], 'time': '2021-05-20T03:56:27.921616Z'}
{'type': 'l2update', 'product_id': 'BTC-USD', 'changes': [['sell', '38342.48', '0.01492000']], 'time': '2021-05-20T03:56:27.926023Z'}
{'type': 'l2update', 'product_id': 'BTC-USD', 'changes': [['sell', '38386.37', '0.02605091']], 'time': '2021-05-20T03:56:27.926418Z'}
{'type': 'l2update', 'product_id': 'BTC-USD', 'changes': [['sell', '38373.70', '0.00000000']], 'time': '2021-05-20T03:56:27.929795Z'}
{'type': 'l2update', 'product_id': 'BTC-USD', 'changes': [['sell', '38446.52', '0.00000000']], 'time': '2021-05-20T03:56:27.933251Z'}
{'type': 'l2update', 'product_id': 'BTC-USD', 'changes': [['buy', '38241.87', '0.00000000']], 'time': '2021-05-20T03:56:27.933377Z'}
{'type': 'l2update', 'product_id': 'BTC-USD', 'changes': [['buy', '38326.94', '0.00000000']], 'time': '2021-05-20T03:56:27.936040Z'}
{'type': 'l2update', 'product_id': 'BTC-USD', 'changes': [['sell', '38515.49', '0.01000000']], 'time': '2021-05-20T03:56:27.936285Z'}
{'type': 'l2update', 'product_id': 'BTC-USD', 'changes': [['sell', '38337.38', '0.05052080']], 'time': '2021-05-20T03:56:27.936554Z'}
{'type': 'l2update', 'product_id': 'BTC-USD', 'changes': [['sell', '38347.29', '0.00000000']], 'time': '2021-05-20T03:56:27.937001Z'}
{'type': 'l2update', 'product_id': 'BTC-USD', 'changes': [['buy', '38277.81', '0.00000000']], 'time': '2021-05-20T03:56:27.940766Z'}
{'type': 'l2update', 'product_id': 'BTC-USD', 'changes': [['sell', '38421.52', '0.00000000']], 'time': '2021-05-20T03:56:27.940948Z'}
{'type': 'l2update', 'product_id': 'BTC-USD', 'changes': [['buy', '38256.30', '0.32000000']], 'time': '2021-05-20T03:56:27.941747Z'}
{'type': 'l2update', 'product_id': 'BTC-USD', 'changes': [['sell', '38369.01', '0.32000000']], 'time': '2021-05-20T03:56:27.941747Z'}
{'type': 'l2update', 'product_id': 'BTC-USD', 'changes': [['sell', '38463.62', '0.80000000']], 'time': '2021-05-20T03:56:27.941747Z'}
{'type': 'l2update', 'product_id': 'BTC-USD', 'changes': [['sell', '38476.88', '0.00000000']], 'time': '2021-05-20T03:56:27.942070Z'}
{'type': 'l2update', 'product_id': 'BTC-USD', 'changes': [['sell', '38359.37', '0.00000000']], 'time': '2021-05-20T03:56:27.943235Z'}
{'type': 'l2update', 'product_id': 'BTC-USD', 'changes': [['sell', '38337.38', '0.00000000']], 'time': '2021-05-20T03:56:27.943603Z'}
{'type': 'l2update', 'product_id': 'BTC-USD', 'changes': [['sell', '38342.33', '0.07399737']], 'time': '2021-05-20T03:56:27.943603Z'}
{'type': 'l2update', 'product_id': 'BTC-USD', 'changes': [['sell', '38475.47', '0.01000000']], 'time': '2021-05-20T03:56:27.948102Z'}
{'type': 'l2update', 'product_id': 'BTC-USD', 'changes': [['buy', '38246.67', '0.01000000']], 'time': '2021-05-20T03:56:27.948839Z'}
{'type': 'l2update', 'product_id': 'BTC-USD', 'changes': [['buy', '38328.47', '0.05880032']], 'time': '2021-05-20T03:56:27.949914Z'}
{'type': 'l2update', 'product_id': 'BTC-USD', 'changes': [['sell', '38342.33', '0.00000000']], 'time': '2021-05-20T03:56:27.951125Z'}
{'type': 'l2update', 'product_id': 'BTC-USD', 'changes': [['buy', '38220.42', '0.69040214']], 'time': '2021-05-20T03:56:27.954218Z'}
{'type': 'l2update', 'product_id': 'BTC-USD', 'changes': [['sell', '38478.63', '0.00000000']], 'time': '2021-05-20T03:56:27.954664Z'}
{'type': 'l2update', 'product_id': 'BTC-USD', 'changes': [['sell', '38363.20', '0.73710868']], 'time': '2021-05-20T03:56:27.955990Z'}
{'type': 'l2update', 'product_id': 'BTC-USD', 'changes': [['sell', '38342.48', '0.00000000']], 'time': '2021-05-20T03:56:27.959613Z'}
{'type': 'l2update', 'product_id': 'BTC-USD', 'changes': [['sell', '38350.52', '0.05000000']], 'time': '2021-05-20T03:56:27.962556Z'}
{'type': 'l2update', 'product_id': 'BTC-USD', 'changes': [['buy', '38287.51', '0.01000000']], 'time': '2021-05-20T03:56:27.964111Z'}
{'type': 'l2update', 'product_id': 'BTC-USD', 'changes': [['sell', '38359.36', '0.05000000']], 'time': '2021-05-20T03:56:27.964340Z'}
{'type': 'l2update', 'product_id': 'BTC-USD', 'changes': [['buy', '38220.00', '0.00000000']], 'time': '2021-05-20T03:56:27.964922Z'}
{'type': 'l2update', 'product_id': 'BTC-USD', 'changes': [['buy', '38334.30', '0.00000000']], 'time': '2021-05-20T03:56:27.967011Z'}
{'type': 'l2update', 'product_id': 'BTC-USD', 'changes': [['sell', '38363.38', '0.15150000']], 'time': '2021-05-20T03:56:27.967830Z'}
{'type': 'l2update', 'product_id': 'BTC-USD', 'changes': [['sell', '38383.70', '0.00000000']], 'time': '2021-05-20T03:56:27.967941Z'}
{'type': 'l2update', 'product_id': 'BTC-USD', 'changes': [['buy', '38237.94', '0.01000000']], 'time': '2021-05-20T03:56:27.967974Z'}
{'type': 'l2update', 'product_id': 'BTC-USD', 'changes': [['buy', '38277.50', '0.00000000']], 'time': '2021-05-20T03:56:27.970179Z'}
{'type': 'l2update', 'product_id': 'BTC-USD', 'changes': [['buy', '38279.54', '0.69337787']], 'time': '2021-05-20T03:56:27.971158Z'}
{'type': 'l2update', 'product_id': 'BTC-USD', 'changes': [['buy', '38285.33', '0.00000000']], 'time': '2021-05-20T03:56:27.980947Z'}
{'type': 'l2update', 'product_id': 'BTC-USD', 'changes': [['buy', '38328.47', '0.00000000']], 'time': '2021-05-20T03:56:27.981338Z'}
{'type': 'l2update', 'product_id': 'BTC-USD', 'changes': [['sell', '38451.73', '0.00000000']], 'time': '2021-05-20T03:56:27.981779Z'}
{'type': 'l2update', 'product_id': 'BTC-USD', 'changes': [['sell', '38342.32', '1.13883979']], 'time': '2021-05-20T03:56:27.982124Z'}
{'type': 'l2update', 'product_id': 'BTC-USD', 'changes': [['buy', '38281.20', '0.02000000']], 'time': '2021-05-20T03:56:27.982388Z'}
{'type': 'l2update', 'product_id': 'BTC-USD', 'changes': [['sell', '38347.28', '0.02000000']], 'time': '2021-05-20T03:56:27.982388Z'}
{'type': 'l2update', 'product_id': 'BTC-USD', 'changes': [['sell', '38363.48', '0.00000000']], 'time': '2021-05-20T03:56:27.984302Z'}
{'type': 'l2update', 'product_id': 'BTC-USD', 'changes': [['buy', '38205.83', '0.00000000']], 'time': '2021-05-20T03:56:27.985491Z'}
{'type': 'l2update', 'product_id': 'BTC-USD', 'changes': [['sell', '38367.80', '0.00000000']], 'time': '2021-05-20T03:56:27.992582Z'}
{'type': 'l2update', 'product_id': 'BTC-USD', 'changes': [['buy', '38333.79', '0.00000000']], 'time': '2021-05-20T03:56:27.994050Z'}
{'type': 'l2update', 'product_id': 'BTC-USD', 'changes': [['buy', '38211.84', '0.82744898']], 'time': '2021-05-20T03:56:27.994460Z'}
{'type': 'l2update', 'product_id': 'BTC-USD', 'changes': [['buy', '38321.83', '0.00000000']], 'time': '2021-05-20T03:56:27.995507Z'}
{'type': 'l2update', 'product_id': 'BTC-USD', 'changes': [['sell', '38359.36', '0.00000000']], 'time': '2021-05-20T03:56:27.995524Z'}
{'type': 'l2update', 'product_id': 'BTC-USD', 'changes': [['sell', '38376.02', '0.00000000']], 'time': '2021-05-20T03:56:27.996899Z'}
{'type': 'l2update', 'product_id': 'BTC-USD', 'changes': [['sell', '38373.43', '0.00000000']], 'time': '2021-05-20T03:56:28.000459Z'}
{'type': 'l2update', 'product_id': 'BTC-USD', 'changes': [['buy', '38240.64', '0.06654968']], 'time': '2021-05-20T03:56:28.000979Z'}
{'type': 'l2update', 'product_id': 'BTC-USD', 'changes': [['buy', '38247.27', '0.06518479']], 'time': '2021-05-20T03:56:28.000979Z'}
{'type': 'l2update', 'product_id': 'BTC-USD', 'changes': [['sell', '38347.18', '0.01492000']], 'time': '2021-05-20T03:56:28.004565Z'}
{'type': 'l2update', 'product_id': 'BTC-USD', 'changes': [['buy', '38334.11', '0.01492000']], 'time': '2021-05-20T03:56:28.004740Z'}
{'type': 'l2update', 'product_id': 'BTC-USD', 'changes': [['sell', '38346.92', '0.07460000']], 'time': '2021-05-20T03:56:28.005058Z'}
{'type': 'l2update', 'product_id': 'BTC-USD', 'changes': [['sell', '38365.89', '0.39490432']], 'time': '2021-05-20T03:56:28.005182Z'}
{'type': 'l2update', 'product_id': 'BTC-USD', 'changes': [['buy', '38246.67', '0.00000000']], 'time': '2021-05-20T03:56:28.006428Z'}
{'type': 'l2update', 'product_id': 'BTC-USD', 'changes': [['sell', '38349.84', '0.00000000']], 'time': '2021-05-20T03:56:28.009122Z'}
{'type': 'l2update', 'product_id': 'BTC-USD', 'changes': [['sell', '38446.61', '0.03790625']], 'time': '2021-05-20T03:56:28.010047Z'}
{'type': 'l2update', 'product_id': 'BTC-USD', 'changes': [['buy', '38259.52', '0.10000000']], 'time': '2021-05-20T03:56:28.010370Z'}
{'type': 'l2update', 'product_id': 'BTC-USD', 'changes': [['sell', '38371.72', '0.10000000']], 'time': '2021-05-20T03:56:28.011142Z'}
{'type': 'l2update', 'product_id': 'BTC-USD', 'changes': [['sell', '38350.53', '0.00000000']], 'time': '2021-05-20T03:56:28.011400Z'}
{'type': 'l2update', 'product_id': 'BTC-USD', 'changes': [['buy', '38306.67', '0.50000000']], 'time': '2021-05-20T03:56:28.011458Z'}
{'type': 'l2update', 'product_id': 'BTC-USD', 'changes': [['buy', '38306.76', '0.06270929']], 'time': '2021-05-20T03:56:28.014751Z'}
{'type': 'l2update', 'product_id': 'BTC-USD', 'changes': [['sell', '38347.63', '0.04766418']], 'time': '2021-05-20T03:56:28.014751Z'}
{'type': 'l2update', 'product_id': 'BTC-USD', 'changes': [['sell', '38337.37', '1.16661637']], 'time': '2021-05-20T03:56:28.019612Z'}
{'type': 'l2update', 'product_id': 'BTC-USD', 'changes': [['sell', '38376.04', '0.00000000']], 'time': '2021-05-20T03:56:28.023872Z'}
{'type': 'l2update', 'product_id': 'BTC-USD', 'changes': [['sell', '38363.38', '0.00000000']], 'time': '2021-05-20T03:56:28.024339Z'}
{'type': 'l2update', 'product_id': 'BTC-USD', 'changes': [['buy', '38326.38', '0.00000000']], 'time': '2021-05-20T03:56:28.025965Z'}
{'type': 'l2update', 'product_id': 'BTC-USD', 'changes': [['buy', '38305.76', '0.52100000']], 'time': '2021-05-20T03:56:28.028641Z'}
{'type': 'l2update', 'product_id': 'BTC-USD', 'changes': [['sell', '38356.74', '0.12000000']], 'time': '2021-05-20T03:56:28.028710Z'}
{'type': 'l2update', 'product_id': 'BTC-USD', 'changes': [['buy', '38328.11', '0.07460000']], 'time': '2021-05-20T03:56:28.029185Z'}
{'type': 'l2update', 'product_id': 'BTC-USD', 'changes': [['buy', '38277.83', '0.57813546']], 'time': '2021-05-20T03:56:28.029245Z'}
{'type': 'l2update', 'product_id': 'BTC-USD', 'changes': [['buy', '38202.47', '0.00000000']], 'time': '2021-05-20T03:56:28.029893Z'}
{'type': 'l2update', 'product_id': 'BTC-USD', 'changes': [['sell', '38350.52', '0.00000000']], 'time': '2021-05-20T03:56:28.030115Z'}
{'type': 'l2update', 'product_id': 'BTC-USD', 'changes': [['sell', '38372.83', '0.05000000']], 'time': '2021-05-20T03:56:28.030353Z'}
{'type': 'l2update', 'product_id': 'BTC-USD', 'changes': [['sell', '38347.18', '0.00000000']], 'time': '2021-05-20T03:56:28.031339Z'}
{'type': 'l2update', 'product_id': 'BTC-USD', 'changes': [['buy', '38277.83', '0.09328429']], 'time': '2021-05-20T03:56:28.032180Z'}
{'type': 'l2update', 'product_id': 'BTC-USD', 'changes': [['buy', '38334.11', '0.00000000']], 'time': '2021-05-20T03:56:28.032295Z'}
{'type': 'l2update', 'product_id': 'BTC-USD', 'changes': [['sell', '38508.10', '0.00000000']], 'time': '2021-05-20T03:56:28.032567Z'}
{'type': 'l2update', 'product_id': 'BTC-USD', 'changes': [['sell', '38346.92', '0.00000000']], 'time': '2021-05-20T03:56:28.033539Z'}
{'type': 'l2update', 'product_id': 'BTC-USD', 'changes': [['buy', '38304.50', '0.03884941']], 'time': '2021-05-20T03:56:28.034762Z'}
{'type': 'l2update', 'product_id': 'BTC-USD', 'changes': [['buy', '38204.27', '0.83443642']], 'time': '2021-05-20T03:56:28.035321Z'}
{'type': 'l2update', 'product_id': 'BTC-USD', 'changes': [['buy', '38179.06', '0.00000000']], 'time': '2021-05-20T03:56:28.040933Z'}
{'type': 'l2update', 'product_id': 'BTC-USD', 'changes': [['sell', '38435.76', '0.02600625']], 'time': '2021-05-20T03:56:28.041038Z'}
{'type': 'l2update', 'product_id': 'BTC-USD', 'changes': [['sell', '38367.79', '0.48552453']], 'time': '2021-05-20T03:56:28.041150Z'}
{'type': 'l2update', 'product_id': 'BTC-USD', 'changes': [['buy', '38300.63', '0.00000000']], 'time': '2021-05-20T03:56:28.041375Z'}
{'type': 'l2update', 'product_id': 'BTC-USD', 'changes': [['sell', '38342.47', '0.50000000']], 'time': '2021-05-20T03:56:28.053574Z'}
{'type': 'l2update', 'product_id': 'BTC-USD', 'changes': [['sell', '38461.59', '0.01141257']], 'time': '2021-05-20T03:56:28.053820Z'}
{'type': 'l2update', 'product_id': 'BTC-USD', 'changes': [['buy', '38250.99', '0.01151731']], 'time': '2021-05-20T03:56:28.054354Z'}
{'type': 'l2update', 'product_id': 'BTC-USD', 'changes': [['sell', '38374.63', '0.00000000']], 'time': '2021-05-20T03:56:28.054538Z'}
{'type': 'l2update', 'product_id': 'BTC-USD', 'changes': [['buy', '38300.64', '0.59116555']], 'time': '2021-05-20T03:56:28.054754Z'}
{'type': 'l2update', 'product_id': 'BTC-USD', 'changes': [['buy', '38193.73', '0.01000000']], 'time': '2021-05-20T03:56:28.055210Z'}
{'type': 'l2update', 'product_id': 'BTC-USD', 'changes': [['sell', '38359.73', '0.00000000']], 'time': '2021-05-20T03:56:28.055405Z'}
{'type': 'l2update', 'product_id': 'BTC-USD', 'changes': [['buy', '38328.11', '0.00000000']], 'time': '2021-05-20T03:56:28.057667Z'}
{'type': 'l2update', 'product_id': 'BTC-USD', 'changes': [['sell', '38342.47', '1.81938756']], 'time': '2021-05-20T03:56:28.059113Z'}
{'type': 'l2update', 'product_id': 'BTC-USD', 'changes': [['sell', '38462.45', '0.00000000']], 'time': '2021-05-20T03:56:28.060151Z'}
{'type': 'l2update', 'product_id': 'BTC-USD', 'changes': [['buy', '38253.52', '0.46500000']], 'time': '2021-05-20T03:56:28.060332Z'}
{'type': 'l2update', 'product_id': 'BTC-USD', 'changes': [['sell', '38372.83', '0.00000000']], 'time': '2021-05-20T03:56:28.061798Z'}
{'type': 'l2update', 'product_id': 'BTC-USD', 'changes': [['buy', '38225.74', '0.03570076']], 'time': '2021-05-20T03:56:28.068994Z'}
{'type': 'l2update', 'product_id': 'BTC-USD', 'changes': [['sell', '38363.20', '0.42589218']], 'time': '2021-05-20T03:56:28.069072Z'}
{'type': 'l2update', 'product_id': 'BTC-USD', 'changes': [['sell', '38367.85', '0.00000000']], 'time': '2021-05-20T03:56:28.070693Z'}
{'type': 'l2update', 'product_id': 'BTC-USD', 'changes': [['sell', '38488.90', '0.01000000']], 'time': '2021-05-20T03:56:28.072950Z'}
{'type': 'l2update', 'product_id': 'BTC-USD', 'changes': [['buy', '38328.71', '0.01492000']], 'time': '2021-05-20T03:56:28.073215Z'}
{'type': 'l2update', 'product_id': 'BTC-USD', 'changes': [['sell', '38360.19', '0.04750731']], 'time': '2021-05-20T03:56:28.073233Z'}
{'type': 'l2update', 'product_id': 'BTC-USD', 'changes': [['sell', '38496.56', '0.00000000']], 'time': '2021-05-20T03:56:28.073536Z'}
{'type': 'l2update', 'product_id': 'BTC-USD', 'changes': [['buy', '38279.73', '0.47465004']], 'time': '2021-05-20T03:56:28.077519Z'}
{'type': 'l2update', 'product_id': 'BTC-USD', 'changes': [['sell', '38336.69', '0.04922510']], 'time': '2021-05-20T03:56:28.077745Z'}
{'type': 'l2update', 'product_id': 'BTC-USD', 'changes': [['sell', '39499.99', '0.00000000']], 'time': '2021-05-20T03:56:28.077784Z'}
{'type': 'l2update', 'product_id': 'BTC-USD', 'changes': [['sell', '38361.29', '0.05000000']], 'time': '2021-05-20T03:56:28.077881Z'}
{'type': 'l2update', 'product_id': 'BTC-USD', 'changes': [['sell', '38349.81', '2.48969908']], 'time': '2021-05-20T03:56:28.079367Z'}
{'type': 'l2update', 'product_id': 'BTC-USD', 'changes': [['buy', '38165.68', '0.01000000']], 'time': '2021-05-20T03:56:28.081203Z'}
{'type': 'l2update', 'product_id': 'BTC-USD', 'changes': [['sell', '38342.47', '1.31938756']], 'time': '2021-05-20T03:56:28.083434Z'}
{'type': 'l2update', 'product_id': 'BTC-USD', 'changes': [['sell', '38374.73', '0.00000000']], 'time': '2021-05-20T03:56:28.083461Z'}
{'type': 'l2update', 'product_id': 'BTC-USD', 'changes': [['sell', '38369.92', '0.00000000']], 'time': '2021-05-20T03:56:28.086310Z'}
{'type': 'l2update', 'product_id': 'BTC-USD', 'changes': [['sell', '38336.75', '0.00273187']], 'time': '2021-05-20T03:56:28.086905Z'}
{'type': 'l2update', 'product_id': 'BTC-USD', 'changes': [['sell', '38336.69', '0.07460000']], 'time': '2021-05-20T03:56:28.086959Z'}
{'type': 'l2update', 'product_id': 'BTC-USD', 'changes': [['sell', '39431.86', '0.10380000']], 'time': '2021-05-20T03:56:28.088643Z'}
{'type': 'l2update', 'product_id': 'BTC-USD', 'changes': [['buy', '37558.01', '0.05240000']], 'time': '2021-05-20T03:56:28.088643Z'}
{'type': 'l2update', 'product_id': 'BTC-USD', 'changes': [['buy', '37555.99', '0.01420000']], 'time': '2021-05-20T03:56:28.088643Z'}
{'type': 'l2update', 'product_id': 'BTC-USD', 'changes': [['buy', '37950.00', '0.31396777']], 'time': '2021-05-20T03:56:28.088728Z'}
{'type': 'l2update', 'product_id': 'BTC-USD', 'changes': [['sell', '38352.32', '0.00000000']], 'time': '2021-05-20T03:56:28.092830Z'}
{'type': 'l2update', 'product_id': 'BTC-USD', 'changes': [['buy', '38327.94', '0.01154779']], 'time': '2021-05-20T03:56:28.093763Z'}
{'type': 'l2update', 'product_id': 'BTC-USD', 'changes': [['sell', '38352.27', '0.10000000']], 'time': '2021-05-20T03:56:28.094067Z'}
{'type': 'l2update', 'product_id': 'BTC-USD', 'changes': [['buy', '38252.13', '0.01000000']], 'time': '2021-05-20T03:56:28.094167Z'}
{'type': 'l2update', 'product_id': 'BTC-USD', 'changes': [['sell', '38363.43', '0.00670410']], 'time': '2021-05-20T03:56:28.102914Z'}
{'type': 'l2update', 'product_id': 'BTC-USD', 'changes': [['sell', '38363.20', '0.41345764']], 'time': '2021-05-20T03:56:28.102914Z'}
{'type': 'l2update', 'product_id': 'BTC-USD', 'changes': [['buy', '38012.79', '0.00000000']], 'time': '2021-05-20T03:56:28.108561Z'}
{'type': 'l2update', 'product_id': 'BTC-USD', 'changes': [['buy', '38328.71', '0.00000000']], 'time': '2021-05-20T03:56:28.108739Z'}
{'type': 'l2update', 'product_id': 'BTC-USD', 'changes': [['sell', '38352.03', '0.21443426']], 'time': '2021-05-20T03:56:28.111379Z'}
{'type': 'l2update', 'product_id': 'BTC-USD', 'changes': [['sell', '38352.26', '0.05000000']], 'time': '2021-05-20T03:56:28.111684Z'}
{'type': 'l2update', 'product_id': 'BTC-USD', 'changes': [['buy', '38287.51', '0.00000000']], 'time': '2021-05-20T03:56:28.116392Z'}
{'type': 'l2update', 'product_id': 'BTC-USD', 'changes': [['sell', '38386.65', '0.00000000']], 'time': '2021-05-20T03:56:28.117006Z'}
{'type': 'l2update', 'product_id': 'BTC-USD', 'changes': [['sell', '38336.75', '0.01492000']], 'time': '2021-05-20T03:56:28.117428Z'}
{'type': 'l2update', 'product_id': 'BTC-USD', 'changes': [['sell', '38499.35', '0.30081232']], 'time': '2021-05-20T03:56:28.117545Z'}
{'type': 'l2update', 'product_id': 'BTC-USD', 'changes': [['buy', '38282.51', '1.20000000']], 'time': '2021-05-20T03:56:28.118940Z'}
{'type': 'l2update', 'product_id': 'BTC-USD', 'changes': [['buy', '38165.68', '0.00000000']], 'time': '2021-05-20T03:56:28.122513Z'}
{'type': 'l2update', 'product_id': 'BTC-USD', 'changes': [['sell', '38337.37', '0.00000000']], 'time': '2021-05-20T03:56:28.122925Z'}
{'type': 'l2update', 'product_id': 'BTC-USD', 'changes': [['buy', '38265.95', '0.02000000']], 'time': '2021-05-20T03:56:28.123376Z'}
{'type': 'l2update', 'product_id': 'BTC-USD', 'changes': [['buy', '38327.94', '0.00000000']], 'time': '2021-05-20T03:56:28.125376Z'}
{'type': 'l2update', 'product_id': 'BTC-USD', 'changes': [['buy', '38300.61', '0.02610924']], 'time': '2021-05-20T03:56:28.129001Z'}
{'type': 'l2update', 'product_id': 'BTC-USD', 'changes': [['sell', '38337.36', '0.50000000']], 'time': '2021-05-20T03:56:28.130585Z'}
{'type': 'l2update', 'product_id': 'BTC-USD', 'changes': [['sell', '38336.75', '0.01218813']], 'time': '2021-05-20T03:56:28.135848Z'}
{'type': 'l2update', 'product_id': 'BTC-USD', 'changes': [['sell', '38352.17', '0.20000000']], 'time': '2021-05-20T03:56:28.135889Z'}
{'type': 'l2update', 'product_id': 'BTC-USD', 'changes': [['sell', '38488.90', '0.00000000']], 'time': '2021-05-20T03:56:28.136827Z'}
{'type': 'l2update', 'product_id': 'BTC-USD', 'changes': [['sell', '38446.57', '0.03093914']], 'time': '2021-05-20T03:56:28.141109Z'}
{'type': 'l2update', 'product_id': 'BTC-USD', 'changes': [['sell', '38479.17', '0.00000000']], 'time': '2021-05-20T03:56:28.144225Z'}
{'type': 'l2update', 'product_id': 'BTC-USD', 'changes': [['sell', '38352.26', '0.00000000']], 'time': '2021-05-20T03:56:28.144346Z'}
{'type': 'l2update', 'product_id': 'BTC-USD', 'changes': [['buy', '38327.93', '0.02079030']], 'time': '2021-05-20T03:56:28.145537Z'}
{'type': 'l2update', 'product_id': 'BTC-USD', 'changes': [['buy', '37974.15', '0.02061500']], 'time': '2021-05-20T03:56:28.145959Z'}
{'type': 'l2update', 'product_id': 'BTC-USD', 'changes': [['buy', '38300.61', '0.00000000']], 'time': '2021-05-20T03:56:28.153787Z'}
{'type': 'l2update', 'product_id': 'BTC-USD', 'changes': [['sell', '38564.10', '0.00000000']], 'time': '2021-05-20T03:56:28.154567Z'}
{'type': 'l2update', 'product_id': 'BTC-USD', 'changes': [['sell', '38352.03', '0.44036736']], 'time': '2021-05-20T03:56:28.154985Z'}
{'type': 'l2update', 'product_id': 'BTC-USD', 'changes': [['buy', '38327.93', '0.06305221']], 'time': '2021-05-20T03:56:28.155547Z'}
{'type': 'l2update', 'product_id': 'BTC-USD', 'changes': [['sell', '38365.84', '2.49100000']], 'time': '2021-05-20T03:56:28.161569Z'}
{'type': 'l2update', 'product_id': 'BTC-USD', 'changes': [['sell', '38417.51', '1.20000000']], 'time': '2021-05-20T03:56:28.162225Z'}
{'type': 'l2update', 'product_id': 'BTC-USD', 'changes': [['buy', '38328.57', '0.01492000']], 'time': '2021-05-20T03:56:28.162398Z'}
{'type': 'l2update', 'product_id': 'BTC-USD', 'changes': [['buy', '38289.05', '0.06731062']], 'time': '2021-05-20T03:56:28.162616Z'}
{'type': 'l2update', 'product_id': 'BTC-USD', 'changes': [['buy', '38328.57', '0.01478334']], 'time': '2021-05-20T03:56:28.162665Z'}
{'type': 'l2update', 'product_id': 'BTC-USD', 'changes': [['sell', '38438.04', '0.00000000']], 'time': '2021-05-20T03:56:28.163316Z'}
{'type': 'l2update', 'product_id': 'BTC-USD', 'changes': [['buy', '38271.98', '0.01000000']], 'time': '2021-05-20T03:56:28.166017Z'}
{'type': 'l2update', 'product_id': 'BTC-USD', 'changes': [['sell', '38465.50', '0.00000000']], 'time': '2021-05-20T03:56:28.166950Z'}
{'type': 'l2update', 'product_id': 'BTC-USD', 'changes': [['buy', '38159.08', '0.00000000']], 'time': '2021-05-20T03:56:28.170270Z'}
{'type': 'l2update', 'product_id': 'BTC-USD', 'changes': [['buy', '38306.77', '1.98886958']], 'time': '2021-05-20T03:56:28.170645Z'}
{'type': 'l2update', 'product_id': 'BTC-USD', 'changes': [['buy', '38279.54', '0.00000000']], 'time': '2021-05-20T03:56:28.170850Z'}
{'type': 'l2update', 'product_id': 'BTC-USD', 'changes': [['buy', '38300.64', '0.00000000']], 'time': '2021-05-20T03:56:28.170934Z'}
{'type': 'l2update', 'product_id': 'BTC-USD', 'changes': [['sell', '38499.35', '0.00000000']], 'time': '2021-05-20T03:56:28.171107Z'}
{'type': 'l2update', 'product_id': 'BTC-USD', 'changes': [['sell', '38363.33', '0.00000000']], 'time': '2021-05-20T03:56:28.172423Z'}
{'type': 'l2update', 'product_id': 'BTC-USD', 'changes': [['sell', '38347.29', '0.10000000']], 'time': '2021-05-20T03:56:28.175536Z'}
{'type': 'l2update', 'product_id': 'BTC-USD', 'changes': [['sell', '38402.84', '0.00000000']], 'time': '2021-05-20T03:56:28.176753Z'}
{'type': 'l2update', 'product_id': 'BTC-USD', 'changes': [['sell', '38475.32', '0.00000000']], 'time': '2021-05-20T03:56:28.179939Z'}
{'type': 'l2update', 'product_id': 'BTC-USD', 'changes': [['sell', '38336.38', '0.00273187']], 'time': '2021-05-20T03:56:28.180234Z'}
{'type': 'l2update', 'product_id': 'BTC-USD', 'changes': [['sell', '38359.72', '0.05000000']], 'time': '2021-05-20T03:56:28.180732Z'}
{'type': 'l2update', 'product_id': 'BTC-USD', 'changes': [['sell', '38503.30', '0.01000000']], 'time': '2021-05-20T03:56:28.180799Z'}
{'type': 'l2update', 'product_id': 'BTC-USD', 'changes': [['buy', '38304.50', '0.00000000']], 'time': '2021-05-20T03:56:28.184670Z'}
{'type': 'l2update', 'product_id': 'BTC-USD', 'changes': [['sell', '38363.20', '0.12202666']], 'time': '2021-05-20T03:56:28.185270Z'}
{'type': 'l2update', 'product_id': 'BTC-USD', 'changes': [['sell', '38342.32', '0.00000000']], 'time': '2021-05-20T03:56:28.188395Z'}
{'type': 'l2update', 'product_id': 'BTC-USD', 'changes': [['buy', '38146.94', '0.02621441']], 'time': '2021-05-20T03:56:28.189386Z'}
{'type': 'l2update', 'product_id': 'BTC-USD', 'changes': [['buy', '38241.97', '1.95140000']], 'time': '2021-05-20T03:56:28.189728Z'}
{'type': 'l2update', 'product_id': 'BTC-USD', 'changes': [['buy', '38305.72', '0.04750731']], 'time': '2021-05-20T03:56:28.190118Z'}
{'type': 'l2update', 'product_id': 'BTC-USD', 'changes': [['sell', '38609.69', '0.00000000']], 'time': '2021-05-20T03:56:28.190833Z'}
{'type': 'l2update', 'product_id': 'BTC-USD', 'changes': [['sell', '38458.97', '0.01745729']], 'time': '2021-05-20T03:56:28.191014Z'}
{'type': 'l2update', 'product_id': 'BTC-USD', 'changes': [['sell', '38336.75', '0.00000000']], 'time': '2021-05-20T03:56:28.191265Z'}
{'type': 'l2update', 'product_id': 'BTC-USD', 'changes': [['buy', '38327.93', '0.04226191']], 'time': '2021-05-20T03:56:28.192295Z'}
{'type': 'l2update', 'product_id': 'BTC-USD', 'changes': [['sell', '38336.69', '0.04922510']], 'time': '2021-05-20T03:56:28.192690Z'}
{'type': 'l2update', 'product_id': 'BTC-USD', 'changes': [['sell', '38457.75', '0.00000000']], 'time': '2021-05-20T03:56:28.192807Z'}
{'type': 'l2update', 'product_id': 'BTC-USD', 'changes': [['buy', '38327.93', '0.00000000']], 'time': '2021-05-20T03:56:28.193602Z'}
{'type': 'l2update', 'product_id': 'BTC-USD', 'changes': [['sell', '38453.49', '0.00000000']], 'time': '2021-05-20T03:56:28.193781Z'}
{'type': 'l2update', 'product_id': 'BTC-USD', 'changes': [['buy', '38306.76', '0.00000000']], 'time': '2021-05-20T03:56:28.195869Z'}
{'type': 'l2update', 'product_id': 'BTC-USD', 'changes': [['sell', '38347.63', '0.00000000']], 'time': '2021-05-20T03:56:28.195869Z'}
{'type': 'l2update', 'product_id': 'BTC-USD', 'changes': [['sell', '38515.49', '0.00000000']], 'time': '2021-05-20T03:56:28.199733Z'}
{'type': 'l2update', 'product_id': 'BTC-USD', 'changes': [['buy', '38328.83', '0.01154779']], 'time': '2021-05-20T03:56:28.201762Z'}
{'type': 'l2update', 'product_id': 'BTC-USD', 'changes': [['sell', '38386.37', '0.00000000']], 'time': '2021-05-20T03:56:28.203792Z'}
{'type': 'l2update', 'product_id': 'BTC-USD', 'changes': [['buy', '38261.17', '0.03000000']], 'time': '2021-05-20T03:56:28.205009Z'}
{'type': 'l2update', 'product_id': 'BTC-USD', 'changes': [['sell', '38363.43', '0.00000000']], 'time': '2021-05-20T03:56:28.205337Z'}
{'type': 'l2update', 'product_id': 'BTC-USD', 'changes': [['sell', '38336.38', '0.00000000']], 'time': '2021-05-20T03:56:28.211476Z'}
{'type': 'l2update', 'product_id': 'BTC-USD', 'changes': [['sell', '38610.00', '0.19720000']], 'time': '2021-05-20T03:56:28.212619Z'}
{'type': 'l2update', 'product_id': 'BTC-USD', 'changes': [['sell', '38446.24', '0.01680929']], 'time': '2021-05-20T03:56:28.212804Z'}
{'type': 'l2update', 'product_id': 'BTC-USD', 'changes': [['buy', '38129.89', '0.95068475']], 'time': '2021-05-20T03:56:28.212830Z'}
{'type': 'l2update', 'product_id': 'BTC-USD', 'changes': [['sell', '38446.61', '0.00000000']], 'time': '2021-05-20T03:56:28.212911Z'}
{'type': 'l2update', 'product_id': 'BTC-USD', 'changes': [['sell', '38359.72', '0.00000000']], 'time': '2021-05-20T03:56:28.213186Z'}
{'type': 'l2update', 'product_id': 'BTC-USD', 'changes': [['sell', '38359.72', '0.69047693']], 'time': '2021-05-20T03:56:28.213984Z'}
{'type': 'l2update', 'product_id': 'BTC-USD', 'changes': [['sell', '43100.00', '1.09530000']], 'time': '2021-05-20T03:56:28.215403Z'}
{'type': 'l2update', 'product_id': 'BTC-USD', 'changes': [['sell', '38342.47', '0.00000000']], 'time': '2021-05-20T03:56:28.215900Z'}
{'type': 'l2update', 'product_id': 'BTC-USD', 'changes': [['sell', '38422.36', '0.01299760']], 'time': '2021-05-20T03:56:28.217824Z'}
{'type': 'l2update', 'product_id': 'BTC-USD', 'changes': [['sell', '38347.29', '0.30000000']], 'time': '2021-05-20T03:56:28.218980Z'}
{'type': 'l2update', 'product_id': 'BTC-USD', 'changes': [['sell', '38416.13', '0.34517721']], 'time': '2021-05-20T03:56:28.222834Z'}
{'type': 'l2update', 'product_id': 'BTC-USD', 'changes': [['sell', '38361.29', '0.00000000']], 'time': '2021-05-20T03:56:28.223587Z'}
{'type': 'l2update', 'product_id': 'BTC-USD', 'changes': [['sell', '38336.69', '0.00000000']], 'time': '2021-05-20T03:56:28.225090Z'}
{'type': 'l2update', 'product_id': 'BTC-USD', 'changes': [['sell', '38542.51', '0.02594538']], 'time': '2021-05-20T03:56:28.232162Z'}
{'type': 'l2update', 'product_id': 'BTC-USD', 'changes': [['sell', '38372.37', '0.03207306']], 'time': '2021-05-20T03:56:28.232628Z'}
{'type': 'l2update', 'product_id': 'BTC-USD', 'changes': [['buy', '38328.83', '0.00000000']], 'time': '2021-05-20T03:56:28.234585Z'}
{'type': 'l2update', 'product_id': 'BTC-USD', 'changes': [['buy', '38328.57', '0.00000000']], 'time': '2021-05-20T03:56:28.235583Z'}
{'type': 'l2update', 'product_id': 'BTC-USD', 'changes': [['sell', '38363.20', '0.07483149']], 'time': '2021-05-20T03:56:28.237444Z'}
{'type': 'l2update', 'product_id': 'BTC-USD', 'changes': [['buy', '38259.48', '0.04000000']], 'time': '2021-05-20T03:56:28.245990Z'}
{'type': 'l2update', 'product_id': 'BTC-USD', 'changes': [['sell', '38365.62', '0.05000000']], 'time': '2021-05-20T03:56:28.246133Z'}
{'type': 'l2update', 'product_id': 'BTC-USD', 'changes': [['sell', '38457.80', '0.01282442']], 'time': '2021-05-20T03:56:28.251850Z'}
{'type': 'l2update', 'product_id': 'BTC-USD', 'changes': [['sell', '38363.19', '0.05000000']], 'time': '2021-05-20T03:56:28.252543Z'}
{'type': 'l2update', 'product_id': 'BTC-USD', 'changes': [['buy', '38307.22', '0.03884941']], 'time': '2021-05-20T03:56:28.253017Z'}
{'type': 'l2update', 'product_id': 'BTC-USD', 'changes': [['sell', '38434.35', '0.03053712']], 'time': '2021-05-20T03:56:28.255739Z'}
{'type': 'l2update', 'product_id': 'BTC-USD', 'changes': [['sell', '38451.86', '0.00000000']], 'time': '2021-05-20T03:56:28.259083Z'}
{'type': 'l2update', 'product_id': 'BTC-USD', 'changes': [['sell', '38349.81', '0.00000000']], 'time': '2021-05-20T03:56:28.260060Z'}
{'type': 'l2update', 'product_id': 'BTC-USD', 'changes': [['sell', '38347.29', '0.40000000']], 'time': '2021-05-20T03:56:28.261559Z'}
{'type': 'l2update', 'product_id': 'BTC-USD', 'changes': [['buy', '38146.94', '0.00000000']], 'time': '2021-05-20T03:56:28.264307Z'}
{'type': 'l2update', 'product_id': 'BTC-USD', 'changes': [['sell', '38337.36', '0.50050000']], 'time': '2021-05-20T03:56:28.267802Z'}
{'type': 'l2update', 'product_id': 'BTC-USD', 'changes': [['sell', '38337.36', '0.00050000']], 'time': '2021-05-20T03:56:28.274994Z'}
{'type': 'l2update', 'product_id': 'BTC-USD', 'changes': [['sell', '38502.81', '0.30081059']], 'time': '2021-05-20T03:56:28.276290Z'}
{'type': 'l2update', 'product_id': 'BTC-USD', 'changes': [['sell', '38502.32', '0.01000000']], 'time': '2021-05-20T03:56:28.276348Z'}
{'type': 'l2update', 'product_id': 'BTC-USD', 'changes': [['sell', '38495.76', '0.01176253']], 'time': '2021-05-20T03:56:28.276478Z'}
{'type': 'l2update', 'product_id': 'BTC-USD', 'changes': [['sell', '38405.25', '0.02616620']], 'time': '2021-05-20T03:56:28.281564Z'}
{'type': 'l2update', 'product_id': 'BTC-USD', 'changes': [['buy', '38209.35', '0.02616620']], 'time': '2021-05-20T03:56:28.281564Z'}
{'type': 'l2update', 'product_id': 'BTC-USD', 'changes': [['buy', '38328.04', '0.01492000']], 'time': '2021-05-20T03:56:28.281755Z'}
{'type': 'l2update', 'product_id': 'BTC-USD', 'changes': [['buy', '38328.82', '0.06305221']], 'time': '2021-05-20T03:56:28.282414Z'}
{'type': 'l2update', 'product_id': 'BTC-USD', 'changes': [['sell', '38347.23', '0.59200000']], 'time': '2021-05-20T03:56:28.282582Z'}
{'type': 'l2update', 'product_id': 'BTC-USD', 'changes': [['buy', '38329.21', '0.01154779']], 'time': '2021-05-20T03:56:28.287036Z'}
{'type': 'l2update', 'product_id': 'BTC-USD', 'changes': [['sell', '38363.19', '0.00000000']], 'time': '2021-05-20T03:56:28.289482Z'}
{'type': 'l2update', 'product_id': 'BTC-USD', 'changes': [['sell', '38421.42', '0.00000000']], 'time': '2021-05-20T03:56:28.292237Z'}
{'type': 'l2update', 'product_id': 'BTC-USD', 'changes': [['buy', '38257.93', '0.05000000']], 'time': '2021-05-20T03:56:28.293610Z'}
{'type': 'l2update', 'product_id': 'BTC-USD', 'changes': [['sell', '38360.19', '0.00000000']], 'time': '2021-05-20T03:56:28.298668Z'}
{'type': 'l2update', 'product_id': 'BTC-USD', 'changes': [['sell', '38337.09', '0.03356437']], 'time': '2021-05-20T03:56:28.304845Z'}
{'type': 'l2update', 'product_id': 'BTC-USD', 'changes': [['buy', '38334.30', '0.10000000']], 'time': '2021-05-20T03:56:28.306035Z'}
{'type': 'l2update', 'product_id': 'BTC-USD', 'changes': [['buy', '38154.97', '0.01000000']], 'time': '2021-05-20T03:56:28.308931Z'}
{'type': 'l2update', 'product_id': 'BTC-USD', 'changes': [['buy', '38306.78', '0.59116555']], 'time': '2021-05-20T03:56:28.309306Z'}
{'type': 'l2update', 'product_id': 'BTC-USD', 'changes': [['buy', '38191.89', '0.31002012']], 'time': '2021-05-20T03:56:28.310791Z'}
{'type': 'l2update', 'product_id': 'BTC-USD', 'changes': [['buy', '38328.04', '0.00000000']], 'time': '2021-05-20T03:56:28.316752Z'}
{'type': 'l2update', 'product_id': 'BTC-USD', 'changes': [['buy', '38329.21', '0.00000000']], 'time': '2021-05-20T03:56:28.317263Z'}
{'type': 'l2update', 'product_id': 'BTC-USD', 'changes': [['sell', '38347.27', '0.50000000']], 'time': '2021-05-20T03:56:28.318516Z'}
{'type': 'l2update', 'product_id': 'BTC-USD', 'changes': [['sell', '38346.93', '0.01492000']], 'time': '2021-05-20T03:56:28.318898Z'}
{'type': 'l2update', 'product_id': 'BTC-USD', 'changes': [['sell', '38410.76', '0.02717115']], 'time': '2021-05-20T03:56:28.319408Z'}
{'type': 'l2update', 'product_id': 'BTC-USD', 'changes': [['sell', '38372.35', '0.01000000']], 'time': '2021-05-20T03:56:28.319726Z'}
{'type': 'l2update', 'product_id': 'BTC-USD', 'changes': [['sell', '38498.21', '0.33000000']], 'time': '2021-05-20T03:56:28.320413Z'}
{'type': 'l2update', 'product_id': 'BTC-USD', 'changes': [['sell', '38337.09', '0.03852218']], 'time': '2021-05-20T03:56:28.323682Z'}
{'type': 'l2update', 'product_id': 'BTC-USD', 'changes': [['sell', '38457.80', '0.00000000']], 'time': '2021-05-20T03:56:28.326923Z'}
{'type': 'l2update', 'product_id': 'BTC-USD', 'changes': [['sell', '38352.02', '0.05000000']], 'time': '2021-05-20T03:56:28.327206Z'}
{'type': 'l2update', 'product_id': 'BTC-USD', 'changes': [['sell', '38347.27', '2.98969908']], 'time': '2021-05-20T03:56:28.327462Z'}
{'type': 'l2update', 'product_id': 'BTC-USD', 'changes': [['sell', '38369.67', '0.03000000']], 'time': '2021-05-20T03:56:28.328132Z'}
{'type': 'l2update', 'product_id': 'BTC-USD', 'changes': [['sell', '38489.15', '0.00000000']], 'time': '2021-05-20T03:56:28.333455Z'}
{'type': 'l2update', 'product_id': 'BTC-USD', 'changes': [['sell', '38365.88', '0.04750731']], 'time': '2021-05-20T03:56:28.334997Z'}
{'type': 'l2update', 'product_id': 'BTC-USD', 'changes': [['sell', '38435.76', '0.00000000']], 'time': '2021-05-20T03:56:28.336489Z'}
{'type': 'l2update', 'product_id': 'BTC-USD', 'changes': [['buy', '38307.22', '0.00000000']], 'time': '2021-05-20T03:56:28.336961Z'}
{'type': 'l2update', 'product_id': 'BTC-USD', 'changes': [['buy', '38305.76', '0.00000000']], 'time': '2021-05-20T03:56:28.342446Z'}
{'type': 'l2update', 'product_id': 'BTC-USD', 'changes': [['sell', '38337.09', '0.00495781']], 'time': '2021-05-20T03:56:28.342654Z'}
{'type': 'l2update', 'product_id': 'BTC-USD', 'changes': [['sell', '38474.10', '0.42774447']], 'time': '2021-05-20T03:56:28.343701Z'}
{'type': 'l2update', 'product_id': 'BTC-USD', 'changes': [['sell', '38474.10', '0.00000000']], 'time': '2021-05-20T03:56:28.343701Z'}
{'type': 'l2update', 'product_id': 'BTC-USD', 'changes': [['sell', '38466.30', '0.00000000']], 'time': '2021-05-20T03:56:28.343701Z'}
{'type': 'l2update', 'product_id': 'BTC-USD', 'changes': [['sell', '38457.76', '0.00000000']], 'time': '2021-05-20T03:56:28.343701Z'}
{'type': 'l2update', 'product_id': 'BTC-USD', 'changes': [['sell', '38346.92', '0.03607782']], 'time': '2021-05-20T03:56:28.345509Z'}
{'type': 'l2update', 'product_id': 'BTC-USD', 'changes': [['buy', '38334.30', '0.30000000']], 'time': '2021-05-20T03:56:28.345640Z'}
{'type': 'l2update', 'product_id': 'BTC-USD', 'changes': [['sell', '38346.93', '0.00000000']], 'time': '2021-05-20T03:56:28.346538Z'}
{'type': 'l2update', 'product_id': 'BTC-USD', 'changes': [['buy', '38151.22', '0.04812152']], 'time': '2021-05-20T03:56:28.347191Z'}
{'type': 'l2update', 'product_id': 'BTC-USD', 'changes': [['sell', '38502.81', '0.00000000']], 'time': '2021-05-20T03:56:28.351527Z'}
{'type': 'l2update', 'product_id': 'BTC-USD', 'changes': [['sell', '38638.65', '0.01000000']], 'time': '2021-05-20T03:56:28.353164Z'}
{'type': 'l2update', 'product_id': 'BTC-USD', 'changes': [['sell', '38337.09', '0.00000000']], 'time': '2021-05-20T03:56:28.353598Z'}
{'type': 'l2update', 'product_id': 'BTC-USD', 'changes': [['sell', '38352.02', '0.00000000']], 'time': '2021-05-20T03:56:28.356385Z'}
{'type': 'l2update', 'product_id': 'BTC-USD', 'changes': [['sell', '38347.49', '0.00000000']], 'time': '2021-05-20T03:56:28.356858Z'}
{'type': 'l2update', 'product_id': 'BTC-USD', 'changes': [['sell', '38422.17', '0.02861932']], 'time': '2021-05-20T03:56:28.358067Z'}
{'type': 'l2update', 'product_id': 'BTC-USD', 'changes': [['buy', '38289.94', '0.01000000']], 'time': '2021-05-20T03:56:28.358313Z'}
{'type': 'l2update', 'product_id': 'BTC-USD', 'changes': [['buy', '38334.30', '0.30176475']], 'time': '2021-05-20T03:56:28.363588Z'}
{'type': 'l2update', 'product_id': 'BTC-USD', 'changes': [['sell', '38477.22', '0.03588750']], 'time': '2021-05-20T03:56:28.371091Z'}
{'type': 'l2update', 'product_id': 'BTC-USD', 'changes': [['sell', '38361.27', '0.05000000']], 'time': '2021-05-20T03:56:28.371239Z'}
{'type': 'l2update', 'product_id': 'BTC-USD', 'changes': [['sell', '38369.75', '0.04000000']], 'time': '2021-05-20T03:56:28.371434Z'}
{'type': 'l2update', 'product_id': 'BTC-USD', 'changes': [['sell', '38578.88', '3.22892979']], 'time': '2021-05-20T03:56:28.371648Z'}
{'type': 'l2update', 'product_id': 'BTC-USD', 'changes': [['buy', '38328.82', '0.00000000']], 'time': '2021-05-20T03:56:28.374043Z'}
{'type': 'l2update', 'product_id': 'BTC-USD', 'changes': [['sell', '38352.27', '0.00000000']], 'time': '2021-05-20T03:56:28.374917Z'}
{'type': 'l2update', 'product_id': 'BTC-USD', 'changes': [['sell', '38498.21', '0.00000000']], 'time': '2021-05-20T03:56:28.379946Z'}
{'type': 'l2update', 'product_id': 'BTC-USD', 'changes': [['buy', '38337.08', '0.01492000']], 'time': '2021-05-20T03:56:28.384931Z'}
{'type': 'l2update', 'product_id': 'BTC-USD', 'changes': [['buy', '38286.55', '0.04750731']], 'time': '2021-05-20T03:56:28.384981Z'}
{'type': 'l2update', 'product_id': 'BTC-USD', 'changes': [['buy', '38229.08', '0.50000000']], 'time': '2021-05-20T03:56:28.385068Z'}
{'type': 'l2update', 'product_id': 'BTC-USD', 'changes': [['buy', '38302.82', '0.04842984']], 'time': '2021-05-20T03:56:28.385145Z'}
{'type': 'l2update', 'product_id': 'BTC-USD', 'changes': [['sell', '38354.48', '0.04121506']], 'time': '2021-05-20T03:56:28.385145Z'}
{'type': 'l2update', 'product_id': 'BTC-USD', 'changes': [['sell', '38428.45', '0.42040229']], 'time': '2021-05-20T03:56:28.385394Z'}
{'type': 'l2update', 'product_id': 'BTC-USD', 'changes': [['sell', '38466.36', '0.00000000']], 'time': '2021-05-20T03:56:28.387699Z'}
{'type': 'l2update', 'product_id': 'BTC-USD', 'changes': [['sell', '38510.41', '0.01280690']], 'time': '2021-05-20T03:56:28.392939Z'}
{'type': 'l2update', 'product_id': 'BTC-USD', 'changes': [['sell', '38359.71', '0.05000000']], 'time': '2021-05-20T03:56:28.393142Z'}
{'type': 'l2update', 'product_id': 'BTC-USD', 'changes': [['buy', '38317.57', '0.03884941']], 'time': '2021-05-20T03:56:28.393223Z'}
{'type': 'l2update', 'product_id': 'BTC-USD', 'changes': [['sell', '38346.48', '1.20000000']], 'time': '2021-05-20T03:56:28.394077Z'}
{'type': 'l2update', 'product_id': 'BTC-USD', 'changes': [['sell', '38428.07', '0.03224201']], 'time': '2021-05-20T03:56:28.394613Z'}
{'type': 'l2update', 'product_id': 'BTC-USD', 'changes': [['sell', '38346.54', '0.01492000']], 'time': '2021-05-20T03:56:28.394842Z'}
{'type': 'l2update', 'product_id': 'BTC-USD', 'changes': [['sell', '38446.24', '0.00000000']], 'time': '2021-05-20T03:56:28.395512Z'}
{'type': 'l2update', 'product_id': 'BTC-USD', 'changes': [['buy', '38281.82', '0.00000000']], 'time': '2021-05-20T03:56:28.396884Z'}
{'type': 'l2update', 'product_id': 'BTC-USD', 'changes': [['sell', '38519.93', '0.00000000']], 'time': '2021-05-20T03:56:28.397090Z'}
{'type': 'l2update', 'product_id': 'BTC-USD', 'changes': [['buy', '38279.72', '0.00000000']], 'time': '2021-05-20T03:56:28.397355Z'}
{'type': 'l2update', 'product_id': 'BTC-USD', 'changes': [['buy', '38278.92', '0.00000000']], 'time': '2021-05-20T03:56:28.397355Z'}
{'type': 'l2update', 'product_id': 'BTC-USD', 'changes': [['buy', '38278.11', '0.00000000']], 'time': '2021-05-20T03:56:28.397355Z'}
{'type': 'l2update', 'product_id': 'BTC-USD', 'changes': [['sell', '38352.17', '0.00000000']], 'time': '2021-05-20T03:56:28.400760Z'}
{'type': 'l2update', 'product_id': 'BTC-USD', 'changes': [['sell', '38374.42', '0.05000000']], 'time': '2021-05-20T03:56:28.407911Z'}
{'type': 'l2update', 'product_id': 'BTC-USD', 'changes': [['buy', '38308.00', '0.52100000']], 'time': '2021-05-20T03:56:28.408684Z'}
{'type': 'l2update', 'product_id': 'BTC-USD', 'changes': [['buy', '38337.08', '0.00000000']], 'time': '2021-05-20T03:56:28.410285Z'}
{'type': 'l2update', 'product_id': 'BTC-USD', 'changes': [['sell', '38456.00', '0.02599256']], 'time': '2021-05-20T03:56:28.413019Z'}
{'type': 'l2update', 'product_id': 'BTC-USD', 'changes': [['sell', '38347.27', '2.48969908']], 'time': '2021-05-20T03:56:28.413057Z'}
{'type': 'l2update', 'product_id': 'BTC-USD', 'changes': [['buy', '38144.83', '0.00000000']], 'time': '2021-05-20T03:56:28.417095Z'}
{'type': 'l2update', 'product_id': 'BTC-USD', 'changes': [['sell', '38359.71', '0.00000000']], 'time': '2021-05-20T03:56:28.419028Z'}
{'type': 'l2update', 'product_id': 'BTC-USD', 'changes': [['sell', '38349.50', '0.04852228']], 'time': '2021-05-20T03:56:28.425443Z'}
{'type': 'l2update', 'product_id': 'BTC-USD', 'changes': [['sell', '38445.88', '0.01300529']], 'time': '2021-05-20T03:56:28.426085Z'}
{'type': 'l2update', 'product_id': 'BTC-USD', 'changes': [['sell', '38346.92', '0.00000000']], 'time': '2021-05-20T03:56:28.426773Z'}
{'type': 'l2update', 'product_id': 'BTC-USD', 'changes': [['sell', '38347.29', '0.30000000']], 'time': '2021-05-20T03:56:28.428261Z'}
{'type': 'l2update', 'product_id': 'BTC-USD', 'changes': [['sell', '38376.07', '0.00000000']], 'time': '2021-05-20T03:56:28.428955Z'}
{'type': 'l2update', 'product_id': 'BTC-USD', 'changes': [['sell', '38434.16', '0.31218496']], 'time': '2021-05-20T03:56:28.429894Z'}
{'type': 'l2update', 'product_id': 'BTC-USD', 'changes': [['sell', '38434.16', '0.34845462']], 'time': '2021-05-20T03:56:28.435946Z'}
{'type': 'l2update', 'product_id': 'BTC-USD', 'changes': [['buy', '38309.19', '0.52192236']], 'time': '2021-05-20T03:56:28.436609Z'}
{'type': 'l2update', 'product_id': 'BTC-USD', 'changes': [['buy', '38269.31', '0.01000000']], 'time': '2021-05-20T03:56:28.437634Z'}
{'type': 'l2update', 'product_id': 'BTC-USD', 'changes': [['sell', '38429.70', '0.01680929']], 'time': '2021-05-20T03:56:28.437707Z'}
{'type': 'l2update', 'product_id': 'BTC-USD', 'changes': [['sell', '38346.54', '0.00000000']], 'time': '2021-05-20T03:56:28.438460Z'}
{'type': 'l2update', 'product_id': 'BTC-USD', 'changes': [['buy', '38305.72', '0.00000000']], 'time': '2021-05-20T03:56:28.441730Z'}
{'type': 'l2update', 'product_id': 'BTC-USD', 'changes': [['sell', '38369.67', '0.04000000']], 'time': '2021-05-20T03:56:28.445291Z'}
{'type': 'l2update', 'product_id': 'BTC-USD', 'changes': [['buy', '38293.64', '0.02400000']], 'time': '2021-05-20T03:56:28.445370Z'}
{'type': 'l2update', 'product_id': 'BTC-USD', 'changes': [['buy', '38292.83', '0.02400000']], 'time': '2021-05-20T03:56:28.445370Z'}
{'type': 'l2update', 'product_id': 'BTC-USD', 'changes': [['buy', '38292.03', '0.02400000']], 'time': '2021-05-20T03:56:28.445370Z'}
{'type': 'l2update', 'product_id': 'BTC-USD', 'changes': [['buy', '38317.57', '0.00000000']], 'time': '2021-05-20T03:56:28.447160Z'}
{'type': 'l2update', 'product_id': 'BTC-USD', 'changes': [['sell', '38337.36', '0.00000000']], 'time': '2021-05-20T03:56:28.448942Z'}
{'type': 'l2update', 'product_id': 'BTC-USD', 'changes': [['sell', '38510.41', '0.00000000']], 'time': '2021-05-20T03:56:28.452178Z'}
{'type': 'l2update', 'product_id': 'BTC-USD', 'changes': [['sell', '38337.35', '0.50000000']], 'time': '2021-05-20T03:56:28.452953Z'}
{'type': 'l2update', 'product_id': 'BTC-USD', 'changes': [['sell', '38363.70', '0.05000000']], 'time': '2021-05-20T03:56:28.453167Z'}
{'type': 'l2update', 'product_id': 'BTC-USD', 'changes': [['sell', '38347.29', '0.10000000']], 'time': '2021-05-20T03:56:28.454758Z'}
{'type': 'l2update', 'product_id': 'BTC-USD', 'changes': [['sell', '38508.09', '0.01000000']], 'time': '2021-05-20T03:56:28.456953Z'}
{'type': 'l2update', 'product_id': 'BTC-USD', 'changes': [['sell', '38346.21', '0.03852218']], 'time': '2021-05-20T03:56:28.462832Z'}
{'type': 'l2update', 'product_id': 'BTC-USD', 'changes': [['sell', '38365.62', '0.00000000']], 'time': '2021-05-20T03:56:28.464344Z'}
{'type': 'l2update', 'product_id': 'BTC-USD', 'changes': [['sell', '38365.88', '0.00000000']], 'time': '2021-05-20T03:56:28.469774Z'}
{'type': 'l2update', 'product_id': 'BTC-USD', 'changes': [['sell', '38375.94', '0.00000000']], 'time': '2021-05-20T03:56:28.469992Z'}
{'type': 'l2update', 'product_id': 'BTC-USD', 'changes': [['sell', '38456.00', '0.00000000']], 'time': '2021-05-20T03:56:28.470400Z'}
{'type': 'l2update', 'product_id': 'BTC-USD', 'changes': [['buy', '38306.78', '0.00000000']], 'time': '2021-05-20T03:56:28.471359Z'}
{'type': 'l2update', 'product_id': 'BTC-USD', 'changes': [['sell', '38446.57', '0.06616035']], 'time': '2021-05-20T03:56:28.473116Z'}
{'type': 'l2update', 'product_id': 'BTC-USD', 'changes': [['sell', '38446.91', '0.39993079']], 'time': '2021-05-20T03:56:28.473515Z'}
{'type': 'l2update', 'product_id': 'BTC-USD', 'changes': [['buy', '38292.03', '0.00000000']], 'time': '2021-05-20T03:56:28.476229Z'}
{'type': 'l2update', 'product_id': 'BTC-USD', 'changes': [['sell', '38334.99', '0.52193868']], 'time': '2021-05-20T03:56:28.479399Z'}
{'type': 'l2update', 'product_id': 'BTC-USD', 'changes': [['sell', '38363.70', '0.00000000']], 'time': '2021-05-20T03:56:28.481792Z'}
{'type': 'l2update', 'product_id': 'BTC-USD', 'changes': [['sell', '38369.67', '0.06000000']], 'time': '2021-05-20T03:56:28.483599Z'}
{'type': 'l2update', 'product_id': 'BTC-USD', 'changes': [['sell', '38347.29', '0.00000000']], 'time': '2021-05-20T03:56:28.483895Z'}
{'type': 'l2update', 'product_id': 'BTC-USD', 'changes': [['sell', '38347.28', '0.00000000']], 'time': '2021-05-20T03:56:28.485108Z'}
{'type': 'l2update', 'product_id': 'BTC-USD', 'changes': [['sell', '38359.76', '0.00000000']], 'time': '2021-05-20T03:56:28.487388Z'}
{'type': 'l2update', 'product_id': 'BTC-USD', 'changes': [['sell', '38337.35', '0.00000000']], 'time': '2021-05-20T03:56:28.489762Z'}
{'type': 'l2update', 'product_id': 'BTC-USD', 'changes': [['sell', '38346.21', '0.00000000']], 'time': '2021-05-20T03:56:28.490115Z'}
{'type': 'l2update', 'product_id': 'BTC-USD', 'changes': [['buy', '38334.57', '0.01492000']], 'time': '2021-05-20T03:56:28.491818Z'}
{'type': 'l2update', 'product_id': 'BTC-USD', 'changes': [['sell', '38346.24', '0.01492000']], 'time': '2021-05-20T03:56:28.492240Z'}
{'type': 'l2update', 'product_id': 'BTC-USD', 'changes': [['sell', '38346.21', '0.03607782']], 'time': '2021-05-20T03:56:28.492334Z'}
{'type': 'l2update', 'product_id': 'BTC-USD', 'changes': [['sell', '38346.47', '1.17964178']], 'time': '2021-05-20T03:56:28.497590Z'}
{'type': 'l2update', 'product_id': 'BTC-USD', 'changes': [['buy', '38330.14', '0.04975858']], 'time': '2021-05-20T03:56:28.497854Z'}
{'type': 'l2update', 'product_id': 'BTC-USD', 'changes': [['buy', '38306.35', '0.03884941']], 'time': '2021-05-20T03:56:28.498188Z'}
{'type': 'l2update', 'product_id': 'BTC-USD', 'changes': [['buy', '38293.64', '0.00000000']], 'time': '2021-05-20T03:56:28.498562Z'}
{'type': 'l2update', 'product_id': 'BTC-USD', 'changes': [['buy', '38292.83', '0.00000000']], 'time': '2021-05-20T03:56:28.498562Z'}
{'type': 'l2update', 'product_id': 'BTC-USD', 'changes': [['sell', '38372.35', '0.00000000']], 'time': '2021-05-20T03:56:28.499381Z'}
{'type': 'l2update', 'product_id': 'BTC-USD', 'changes': [['sell', '38371.71', '0.04750731']], 'time': '2021-05-20T03:56:28.502457Z'}
{'type': 'l2update', 'product_id': 'BTC-USD', 'changes': [['buy', '38265.95', '0.00000000']], 'time': '2021-05-20T03:56:28.506105Z'}
{'type': 'l2update', 'product_id': 'BTC-USD', 'changes': [['sell', '38514.22', '0.00000000']], 'time': '2021-05-20T03:56:28.507908Z'}
{'type': 'l2update', 'product_id': 'BTC-USD', 'changes': [['sell', '38523.41', '0.02147020']], 'time': '2021-05-20T03:56:28.512704Z'}
{'type': 'l2update', 'product_id': 'BTC-USD', 'changes': [['sell', '38359.71', '0.05000000']], 'time': '2021-05-20T03:56:28.512834Z'}
{'type': 'l2update', 'product_id': 'BTC-USD', 'changes': [['buy', '38303.86', '0.52199955']], 'time': '2021-05-20T03:56:28.513292Z'}
{'type': 'l2update', 'product_id': 'BTC-USD', 'changes': [['sell', '38453.57', '0.33830537']], 'time': '2021-05-20T03:56:28.514152Z'}
{'type': 'l2update', 'product_id': 'BTC-USD', 'changes': [['buy', '38334.57', '0.00000000']], 'time': '2021-05-20T03:56:28.514808Z'}
{'type': 'l2update', 'product_id': 'BTC-USD', 'changes': [['sell', '38346.24', '0.00000000']], 'time': '2021-05-20T03:56:28.514876Z'}
{'type': 'l2update', 'product_id': 'BTC-USD', 'changes': [['buy', '38286.55', '0.00000000']], 'time': '2021-05-20T03:56:28.515013Z'}
{'type': 'l2update', 'product_id': 'BTC-USD', 'changes': [['sell', '38454.08', '0.03389150']], 'time': '2021-05-20T03:56:28.515080Z'}
{'type': 'l2update', 'product_id': 'BTC-USD', 'changes': [['buy', '38216.08', '0.03389150']], 'time': '2021-05-20T03:56:28.515080Z'}
{'type': 'l2update', 'product_id': 'BTC-USD', 'changes': [['buy', '38271.89', '0.04532287']], 'time': '2021-05-20T03:56:28.515080Z'}
{'type': 'l2update', 'product_id': 'BTC-USD', 'changes': [['buy', '38285.39', '0.01398933']], 'time': '2021-05-20T03:56:28.515080Z'}
{'type': 'l2update', 'product_id': 'BTC-USD', 'changes': [['sell', '38346.21', '0.00000000']], 'time': '2021-05-20T03:56:28.515119Z'}
{'type': 'l2update', 'product_id': 'BTC-USD', 'changes': [['sell', '38503.30', '0.00000000']], 'time': '2021-05-20T03:56:28.520920Z'}
{'type': 'l2update', 'product_id': 'BTC-USD', 'changes': [['sell', '38344.11', '0.02000000']], 'time': '2021-05-20T03:56:28.523105Z'}
{'type': 'l2update', 'product_id': 'BTC-USD', 'changes': [['sell', '38346.47', '1.67964178']], 'time': '2021-05-20T03:56:28.524839Z'}
{'type': 'l2update', 'product_id': 'BTC-USD', 'changes': [['buy', '38289.94', '0.00000000']], 'time': '2021-05-20T03:56:28.524915Z'}
{'type': 'l2update', 'product_id': 'BTC-USD', 'changes': [['buy', '38271.98', '0.00000000']], 'time': '2021-05-20T03:56:28.532009Z'}
{'type': 'l2update', 'product_id': 'BTC-USD', 'changes': [['sell', '38350.70', '0.00600000']], 'time': '2021-05-20T03:56:28.537111Z'}
{'type': 'l2update', 'product_id': 'BTC-USD', 'changes': [['sell', '38475.73', '0.02161855']], 'time': '2021-05-20T03:56:28.537767Z'}
{'type': 'l2update', 'product_id': 'BTC-USD', 'changes': [['buy', '38247.27', '0.03286105']], 'time': '2021-05-20T03:56:28.542566Z'}
{'type': 'l2update', 'product_id': 'BTC-USD', 'changes': [['buy', '38266.02', '0.00000000']], 'time': '2021-05-20T03:56:28.542566Z'}
{'type': 'l2update', 'product_id': 'BTC-USD', 'changes': [['sell', '38638.65', '0.00000000']], 'time': '2021-05-20T03:56:28.546388Z'}
{'type': 'l2update', 'product_id': 'BTC-USD', 'changes': [['sell', '38335.00', '0.52193868']], 'time': '2021-05-20T03:56:28.547416Z'}
{'type': 'l2update', 'product_id': 'BTC-USD', 'changes': [['buy', '38330.14', '0.00000000']], 'time': '2021-05-20T03:56:28.548775Z'}
{'type': 'l2update', 'product_id': 'BTC-USD', 'changes': [['buy', '38334.30', '0.20176475']], 'time': '2021-05-20T03:56:28.550008Z'}
{'type': 'l2update', 'product_id': 'BTC-USD', 'changes': [['buy', '38309.20', '0.59116555']], 'time': '2021-05-20T03:56:28.552849Z'}
{'type': 'l2update', 'product_id': 'BTC-USD', 'changes': [['buy', '38290.20', '0.07362365']], 'time': '2021-05-20T03:56:28.553194Z'}
{'type': 'l2update', 'product_id': 'BTC-USD', 'changes': [['sell', '38466.30', '0.29322995']], 'time': '2021-05-20T03:56:28.553219Z'}
{'type': 'l2update', 'product_id': 'BTC-USD', 'changes': [['buy', '37997.34', '0.38800000']], 'time': '2021-05-20T03:56:28.553980Z'}
{'type': 'l2update', 'product_id': 'BTC-USD', 'changes': [['sell', '38470.47', '0.01299698']], 'time': '2021-05-20T03:56:28.558375Z'}
{'type': 'l2update', 'product_id': 'BTC-USD', 'changes': [['buy', '38261.17', '0.00000000']], 'time': '2021-05-20T03:56:28.558762Z'}
{'type': 'l2update', 'product_id': 'BTC-USD', 'changes': [['buy', '38252.13', '0.00000000']], 'time': '2021-05-20T03:56:28.563005Z'}
{'type': 'l2update', 'product_id': 'BTC-USD', 'changes': [['buy', '38304.75', '0.02400000']], 'time': '2021-05-20T03:56:28.568412Z'}
{'type': 'l2update', 'product_id': 'BTC-USD', 'changes': [['buy', '38303.94', '0.02400000']], 'time': '2021-05-20T03:56:28.568412Z'}
{'type': 'l2update', 'product_id': 'BTC-USD', 'changes': [['buy', '38303.14', '0.02400000']], 'time': '2021-05-20T03:56:28.568412Z'}
{'type': 'l2update', 'product_id': 'BTC-USD', 'changes': [['sell', '38503.20', '0.30081009']], 'time': '2021-05-20T03:56:28.575146Z'}
{'type': 'l2update', 'product_id': 'BTC-USD', 'changes': [['buy', '38334.98', '0.01492000']], 'time': '2021-05-20T03:56:28.576292Z'}
{'type': 'l2update', 'product_id': 'BTC-USD', 'changes': [['buy', '38306.35', '0.00000000']], 'time': '2021-05-20T03:56:28.580133Z'}
{'type': 'l2update', 'product_id': 'BTC-USD', 'changes': [['sell', '38344.06', '0.59300000']], 'time': '2021-05-20T03:56:28.583168Z'}
{'type': 'l2update', 'product_id': 'BTC-USD', 'changes': [['buy', '38259.48', '0.00000000']], 'time': '2021-05-20T03:56:28.583727Z'}
{'type': 'l2update', 'product_id': 'BTC-USD', 'changes': [['sell', '38484.92', '0.01000000']], 'time': '2021-05-20T03:56:28.584069Z'}
{'type': 'l2update', 'product_id': 'BTC-USD', 'changes': [['sell', '38622.32', '0.00647294']], 'time': '2021-05-20T03:56:28.584435Z'}
{'type': 'l2update', 'product_id': 'BTC-USD', 'changes': [['buy', '38299.17', '0.52193868']], 'time': '2021-05-20T03:56:28.584897Z'}
{'type': 'l2update', 'product_id': 'BTC-USD', 'changes': [['sell', '38446.57', '0.10168387']], 'time': '2021-05-20T03:56:28.588792Z'}
{'type': 'l2update', 'product_id': 'BTC-USD', 'changes': [['buy', '38290.21', '0.67035046']], 'time': '2021-05-20T03:56:28.589144Z'}
{'type': 'l2update', 'product_id': 'BTC-USD', 'changes': [['buy', '38301.18', '0.47430000']], 'time': '2021-05-20T03:56:28.589635Z'}
{'type': 'l2update', 'product_id': 'BTC-USD', 'changes': [['buy', '38259.52', '0.00000000']], 'time': '2021-05-20T03:56:28.594362Z'}
{'type': 'l2update', 'product_id': 'BTC-USD', 'changes': [['sell', '38502.32', '0.00000000']], 'time': '2021-05-20T03:56:28.598190Z'}
{'type': 'l2update', 'product_id': 'BTC-USD', 'changes': [['sell', '38346.47', '1.17964178']], 'time': '2021-05-20T03:56:28.599402Z'}
{'type': 'l2update', 'product_id': 'BTC-USD', 'changes': [['buy', '38230.04', '0.01000000']], 'time': '2021-05-20T03:56:28.600642Z'}
{'type': 'l2update', 'product_id': 'BTC-USD', 'changes': [['buy', '38257.93', '0.00000000']], 'time': '2021-05-20T03:56:28.605426Z'}
{'type': 'l2update', 'product_id': 'BTC-USD', 'changes': [['sell', '38497.15', '0.33000000']], 'time': '2021-05-20T03:56:28.606655Z'}
{'type': 'l2update', 'product_id': 'BTC-USD', 'changes': [['buy', '38192.09', '0.39655971']], 'time': '2021-05-20T03:56:28.606785Z'}
{'type': 'l2update', 'product_id': 'BTC-USD', 'changes': [['buy', '38253.40', '0.14725124']], 'time': '2021-05-20T03:56:28.606785Z'}
{'type': 'l2update', 'product_id': 'BTC-USD', 'changes': [['buy', '38302.83', '0.03522338']], 'time': '2021-05-20T03:56:28.611599Z'}
{'type': 'l2update', 'product_id': 'BTC-USD', 'changes': [['buy', '38334.30', '0.00176475']], 'time': '2021-05-20T03:56:28.613545Z'}
{'type': 'l2update', 'product_id': 'BTC-USD', 'changes': [['sell', '38335.97', '0.52193868']], 'time': '2021-05-20T03:56:28.618039Z'}
{'type': 'l2update', 'product_id': 'BTC-USD', 'changes': [['sell', '38441.68', '0.03736810']], 'time': '2021-05-20T03:56:28.618231Z'}
{'type': 'l2update', 'product_id': 'BTC-USD', 'changes': [['sell', '38368.26', '0.44210000']], 'time': '2021-05-20T03:56:28.622321Z'}
{'type': 'l2update', 'product_id': 'BTC-USD', 'changes': [['sell', '38503.20', '0.00000000']], 'time': '2021-05-20T03:56:28.631116Z'}
{'type': 'l2update', 'product_id': 'BTC-USD', 'changes': [['buy', '38220.42', '0.32227403']], 'time': '2021-05-20T03:56:28.632291Z'}
{'type': 'l2update', 'product_id': 'BTC-USD', 'changes': [['buy', '38288.42', '0.02000000']], 'time': '2021-05-20T03:56:28.633092Z'}
{'type': 'l2update', 'product_id': 'BTC-USD', 'changes': [['sell', '38489.15', '0.01000000']], 'time': '2021-05-20T03:56:28.633838Z'}
{'type': 'l2update', 'product_id': 'BTC-USD', 'changes': [['buy', '38276.50', '0.10000000']], 'time': '2021-05-20T03:56:28.634264Z'}
{'type': 'l2update', 'product_id': 'BTC-USD', 'changes': [['sell', '38334.99', '1.02193868']], 'time': '2021-05-20T03:56:28.634512Z'}
{'type': 'l2update', 'product_id': 'BTC-USD', 'changes': [['buy', '38290.20', '0.02611634']], 'time': '2021-05-20T03:56:28.636186Z'}
{'type': 'l2update', 'product_id': 'BTC-USD', 'changes': [['sell', '38475.73', '0.00000000']], 'time': '2021-05-20T03:56:28.648370Z'}
{'type': 'l2update', 'product_id': 'BTC-USD', 'changes': [['buy', '38290.46', '0.78297231']], 'time': '2021-05-20T03:56:28.650327Z'}
{'type': 'l2update', 'product_id': 'BTC-USD', 'changes': [['sell', '38368.26', '0.00000000']], 'time': '2021-05-20T03:56:28.651342Z'}
{'type': 'l2update', 'product_id': 'BTC-USD', 'changes': [['buy', '38334.30', '0.00000000']], 'time': '2021-05-20T03:56:28.651675Z'}
{'type': 'l2update', 'product_id': 'BTC-USD', 'changes': [['sell', '38497.15', '0.00000000']], 'time': '2021-05-20T03:56:28.652924Z'}
{'type': 'l2update', 'product_id': 'BTC-USD', 'changes': [['sell', '38371.71', '0.00000000']], 'time': '2021-05-20T03:56:28.653093Z'}
{'type': 'l2update', 'product_id': 'BTC-USD', 'changes': [['sell', '38469.35', '0.00000000']], 'time': '2021-05-20T03:56:28.654190Z'}
{'type': 'l2update', 'product_id': 'BTC-USD', 'changes': [['sell', '38446.57', '0.07074473']], 'time': '2021-05-20T03:56:28.654190Z'}
{'type': 'l2update', 'product_id': 'BTC-USD', 'changes': [['buy', '38288.42', '0.03000000']], 'time': '2021-05-20T03:56:28.662618Z'}
{'type': 'l2update', 'product_id': 'BTC-USD', 'changes': [['sell', '38369.00', '0.09983842']], 'time': '2021-05-20T03:56:28.663893Z'}
{'type': 'l2update', 'product_id': 'BTC-USD', 'changes': [['sell', '38451.86', '0.35505994']], 'time': '2021-05-20T03:56:28.669876Z'}
{'type': 'l2update', 'product_id': 'BTC-USD', 'changes': [['buy', '38303.08', '0.03884941']], 'time': '2021-05-20T03:56:28.671188Z'}
{'type': 'l2update', 'product_id': 'BTC-USD', 'changes': [['sell', '38343.11', '1.30512591']], 'time': '2021-05-20T03:56:28.681024Z'}
{'type': 'l2update', 'product_id': 'BTC-USD', 'changes': [['sell', '38429.49', '0.00000000']], 'time': '2021-05-20T03:56:28.684665Z'}
{'type': 'l2update', 'product_id': 'BTC-USD', 'changes': [['buy', '38138.75', '0.00000000']], 'time': '2021-05-20T03:56:28.686736Z'}
{'type': 'l2update', 'product_id': 'BTC-USD', 'changes': [['sell', '38470.47', '0.00000000']], 'time': '2021-05-20T03:56:28.691220Z'}
{'type': 'l2update', 'product_id': 'BTC-USD', 'changes': [['buy', '38288.42', '0.06000000']], 'time': '2021-05-20T03:56:28.693616Z'}
{'type': 'l2update', 'product_id': 'BTC-USD', 'changes': [['sell', '38365.33', '0.01046648']], 'time': '2021-05-20T03:56:28.694293Z'}
{'type': 'l2update', 'product_id': 'BTC-USD', 'changes': [['buy', '38302.83', '0.00000000']], 'time': '2021-05-20T03:56:28.694393Z'}
{'type': 'l2update', 'product_id': 'BTC-USD', 'changes': [['sell', '38454.56', '0.41876284']], 'time': '2021-05-20T03:56:28.702064Z'}
{'type': 'l2update', 'product_id': 'BTC-USD', 'changes': [['sell', '38335.92', '0.59300000']], 'time': '2021-05-20T03:56:28.702292Z'}
{'type': 'l2update', 'product_id': 'BTC-USD', 'changes': [['sell', '38447.56', '0.02599256']], 'time': '2021-05-20T03:56:28.706416Z'}
{'type': 'l2update', 'product_id': 'BTC-USD', 'changes': [['buy', '38306.77', '0.00000000']], 'time': '2021-05-20T03:56:28.713096Z'}
{'type': 'l2update', 'product_id': 'BTC-USD', 'changes': [['buy', '38283.03', '2.60872263']], 'time': '2021-05-20T03:56:28.715327Z'}
{'type': 'l2update', 'product_id': 'BTC-USD', 'changes': [['buy', '38126.05', '0.05134289']], 'time': '2021-05-20T03:56:28.719056Z'}
{'type': 'l2update', 'product_id': 'BTC-USD', 'changes': [['sell', '38458.47', '0.01300103']], 'time': '2021-05-20T03:56:28.719660Z'}
{'type': 'l2update', 'product_id': 'BTC-USD', 'changes': [['buy', '38123.81', '0.01311516']], 'time': '2021-05-20T03:56:28.719709Z'}
{'type': 'l2update', 'product_id': 'BTC-USD', 'changes': [['buy', '38328.57', '0.00176475']], 'time': '2021-05-20T03:56:28.719759Z'}
{'type': 'l2update', 'product_id': 'BTC-USD', 'changes': [['sell', '38403.93', '0.19810000']], 'time': '2021-05-20T03:56:28.719835Z'}
{'type': 'l2update', 'product_id': 'BTC-USD', 'changes': [['sell', '38405.25', '0.00000000']], 'time': '2021-05-20T03:56:28.720898Z'}
{'type': 'l2update', 'product_id': 'BTC-USD', 'changes': [['buy', '38253.52', '0.00000000']], 'time': '2021-05-20T03:56:28.720926Z'}
{'type': 'l2update', 'product_id': 'BTC-USD', 'changes': [['buy', '38288.42', '0.10000000']], 'time': '2021-05-20T03:56:28.730675Z'}
{'type': 'l2update', 'product_id': 'BTC-USD', 'changes': [['sell', '38455.19', '0.38568267']], 'time': '2021-05-20T03:56:28.734814Z'}
{'type': 'l2update', 'product_id': 'BTC-USD', 'changes': [['sell', '38334.99', '1.01683228']], 'time': '2021-05-20T03:56:28.735276Z'}
{'type': 'l2update', 'product_id': 'BTC-USD', 'changes': [['sell', '38347.27', '0.00000000']], 'time': '2021-05-20T03:56:28.735481Z'}
{'type': 'l2update', 'product_id': 'BTC-USD', 'changes': [['sell', '38599.99', '0.00000000']], 'time': '2021-05-20T03:56:28.735585Z'}
{'type': 'l2update', 'product_id': 'BTC-USD', 'changes': [['buy', '38267.68', '0.02613171']], 'time': '2021-05-20T03:56:28.740282Z'}
{'type': 'l2update', 'product_id': 'BTC-USD', 'changes': [['buy', '36037.00', '0.00101687']], 'time': '2021-05-20T03:56:28.745079Z'}
{'type': 'l2update', 'product_id': 'BTC-USD', 'changes': [['sell', '38351.53', '2.61025182']], 'time': '2021-05-20T03:56:28.748639Z'}
{'type': 'l2update', 'product_id': 'BTC-USD', 'changes': [['buy', '38301.18', '0.00000000']], 'time': '2021-05-20T03:56:28.750291Z'}
{'type': 'l2update', 'product_id': 'BTC-USD', 'changes': [['buy', '38304.75', '0.00000000']], 'time': '2021-05-20T03:56:28.752442Z'}
{'type': 'l2update', 'product_id': 'BTC-USD', 'changes': [['buy', '38303.94', '0.00000000']], 'time': '2021-05-20T03:56:28.752442Z'}
{'type': 'l2update', 'product_id': 'BTC-USD', 'changes': [['buy', '38303.14', '0.00000000']], 'time': '2021-05-20T03:56:28.752442Z'}
{'type': 'l2update', 'product_id': 'BTC-USD', 'changes': [['sell', '38458.47', '0.00000000']], 'time': '2021-05-20T03:56:28.756540Z'}
{'type': 'l2update', 'product_id': 'BTC-USD', 'changes': [['sell', '38469.86', '0.00000000']], 'time': '2021-05-20T03:56:28.758531Z'}
{'type': 'l2update', 'product_id': 'BTC-USD', 'changes': [['sell', '38370.42', '0.02717115']], 'time': '2021-05-20T03:56:28.759336Z'}
{'type': 'l2update', 'product_id': 'BTC-USD', 'changes': [['buy', '38334.98', '0.00000000']], 'time': '2021-05-20T03:56:28.759404Z'}
{'type': 'l2update', 'product_id': 'BTC-USD', 'changes': [['sell', '38461.59', '0.00000000']], 'time': '2021-05-20T03:56:28.763820Z'}
{'type': 'l2update', 'product_id': 'BTC-USD', 'changes': [['buy', '38309.21', '1.98886958']], 'time': '2021-05-20T03:56:28.767811Z'}
{'type': 'l2update', 'product_id': 'BTC-USD', 'changes': [['buy', '38287.49', '0.05000000']], 'time': '2021-05-20T03:56:28.768330Z'}
{'type': 'l2update', 'product_id': 'BTC-USD', 'changes': [['buy', '38303.87', '0.03522338']], 'time': '2021-05-20T03:56:28.769365Z'}
{'type': 'l2update', 'product_id': 'BTC-USD', 'changes': [['buy', '38325.14', '0.04997917']], 'time': '2021-05-20T03:56:28.773251Z'}
{'type': 'l2update', 'product_id': 'BTC-USD', 'changes': [['sell', '38410.75', '0.02603438']], 'time': '2021-05-20T03:56:28.773288Z'}
{'type': 'l2update', 'product_id': 'BTC-USD', 'changes': [['buy', '38303.78', '0.43440000']], 'time': '2021-05-20T03:56:28.780118Z'}
{'type': 'l2update', 'product_id': 'BTC-USD', 'changes': [['sell', '38360.17', '0.34517721']], 'time': '2021-05-20T03:56:28.780202Z'}
{'type': 'l2update', 'product_id': 'BTC-USD', 'changes': [['buy', '38272.40', '2.60917706']], 'time': '2021-05-20T03:56:28.780623Z'}
{'type': 'l2update', 'product_id': 'BTC-USD', 'changes': [['sell', '38410.76', '0.00000000']], 'time': '2021-05-20T03:56:28.781627Z'}
{'type': 'l2update', 'product_id': 'BTC-USD', 'changes': [['sell', '38504.57', '0.01298547']], 'time': '2021-05-20T03:56:28.788121Z'}
{'type': 'l2update', 'product_id': 'BTC-USD', 'changes': [['sell', '38359.71', '0.00000000']], 'time': '2021-05-20T03:56:28.790075Z'}
{'type': 'l2update', 'product_id': 'BTC-USD', 'changes': [['sell', '38443.00', '0.01000000']], 'time': '2021-05-20T03:56:28.797110Z'}
{'type': 'l2update', 'product_id': 'BTC-USD', 'changes': [['sell', '38334.99', '3.50653136']], 'time': '2021-05-20T03:56:28.798139Z'}
{'type': 'l2update', 'product_id': 'BTC-USD', 'changes': [['sell', '38446.67', '0.01153008']], 'time': '2021-05-20T03:56:28.798239Z'}
{'type': 'l2update', 'product_id': 'BTC-USD', 'changes': [['sell', '38346.47', '0.00000000']], 'time': '2021-05-20T03:56:28.800888Z'}
{'type': 'l2update', 'product_id': 'BTC-USD', 'changes': [['sell', '38515.66', '0.00000000']], 'time': '2021-05-20T03:56:28.801446Z'}
{'type': 'l2update', 'product_id': 'BTC-USD', 'changes': [['buy', '38303.78', '0.00000000']], 'time': '2021-05-20T03:56:28.801887Z'}
{'type': 'l2update', 'product_id': 'BTC-USD', 'changes': [['sell', '38416.13', '0.00000000']], 'time': '2021-05-20T03:56:28.802181Z'}
{'type': 'l2update', 'product_id': 'BTC-USD', 'changes': [['buy', '38301.77', '0.02400000']], 'time': '2021-05-20T03:56:28.805819Z'}
{'type': 'l2update', 'product_id': 'BTC-USD', 'changes': [['buy', '38300.96', '0.02400000']], 'time': '2021-05-20T03:56:28.805819Z'}
{'type': 'l2update', 'product_id': 'BTC-USD', 'changes': [['buy', '38300.15', '0.02400000']], 'time': '2021-05-20T03:56:28.805819Z'}
{'type': 'l2update', 'product_id': 'BTC-USD', 'changes': [['sell', '38396.07', '0.02861932']], 'time': '2021-05-20T03:56:28.817131Z'}
{'type': 'l2update', 'product_id': 'BTC-USD', 'changes': [['sell', '38352.02', '0.05000000']], 'time': '2021-05-20T03:56:28.817682Z'}
{'type': 'l2update', 'product_id': 'BTC-USD', 'changes': [['sell', '38352.56', '1.30480589']], 'time': '2021-05-20T03:56:28.818097Z'}
{'type': 'l2update', 'product_id': 'BTC-USD', 'changes': [['buy', '38300.61', '0.03522338']], 'time': '2021-05-20T03:56:28.818466Z'}
{'type': 'l2update', 'product_id': 'BTC-USD', 'changes': [['buy', '38230.04', '0.00000000']], 'time': '2021-05-20T03:56:28.820655Z'}
{'type': 'l2update', 'product_id': 'BTC-USD', 'changes': [['sell', '38334.99', '1.01683228']], 'time': '2021-05-20T03:56:28.826970Z'}
{'type': 'l2update', 'product_id': 'BTC-USD', 'changes': [['sell', '38502.78', '0.01000000']], 'time': '2021-05-20T03:56:28.832859Z'}
{'type': 'l2update', 'product_id': 'BTC-USD', 'changes': [['sell', '38366.40', '0.40990000']], 'time': '2021-05-20T03:56:28.833729Z'}
{'type': 'l2update', 'product_id': 'BTC-USD', 'changes': [['sell', '38489.15', '0.00000000']], 'time': '2021-05-20T03:56:28.834909Z'}
{'type': 'l2update', 'product_id': 'BTC-USD', 'changes': [['sell', '38422.17', '0.00000000']], 'time': '2021-05-20T03:56:28.835695Z'}
{'type': 'l2update', 'product_id': 'BTC-USD', 'changes': [['sell', '38334.98', '0.65000000']], 'time': '2021-05-20T03:56:28.838537Z'}
{'type': 'l2update', 'product_id': 'BTC-USD', 'changes': [['sell', '38434.16', '0.65404216']], 'time': '2021-05-20T03:56:28.838961Z'}
{'type': 'l2update', 'product_id': 'BTC-USD', 'changes': [['buy', '38309.20', '0.00000000']], 'time': '2021-05-20T03:56:28.841067Z'}
{'type': 'l2update', 'product_id': 'BTC-USD', 'changes': [['buy', '38303.87', '0.00000000']], 'time': '2021-05-20T03:56:28.846519Z'}
{'type': 'l2update', 'product_id': 'BTC-USD', 'changes': [['buy', '38250.99', '0.00000000']], 'time': '2021-05-20T03:56:28.850305Z'}
{'type': 'l2update', 'product_id': 'BTC-USD', 'changes': [['sell', '38366.40', '0.00000000']], 'time': '2021-05-20T03:56:28.851668Z'}
{'type': 'l2update', 'product_id': 'BTC-USD', 'changes': [['buy', '38262.93', '2.60971031']], 'time': '2021-05-20T03:56:28.855177Z'}
{'type': 'l2update', 'product_id': 'BTC-USD', 'changes': [['buy', '38252.56', '0.01000000']], 'time': '2021-05-20T03:56:28.855830Z'}
{'type': 'l2update', 'product_id': 'BTC-USD', 'changes': [['sell', '38508.09', '0.00000000']], 'time': '2021-05-20T03:56:28.857718Z'}
