{'type': 'l2update', 'product_id': 'BTC-USD', 'changes': [['buy', '38319.61', '0.52000000']], 'time': '2021-05-20T03:55:47.803520Z'}
{'type': 'l2update', 'product_id': 'BTC-USD', 'changes': [['sell', '38349.04', '2.98969908']], 'time': '2021-05-20T03:55:47.804111Z'}
{'type': 'l2update', 'product_id': 'BTC-USD', 'changes': [['sell', '38349.03', '0.00000000']], 'time': '2021-05-20T03:55:47.809128Z'}
{'type': 'l2update', 'product_id': 'BTC-USD', 'changes': [['sell', '38513.45', '0.00000000']], 'time': '2021-05-20T03:55:47.809540Z'}
{'type': 'l2update', 'product_id': 'BTC-USD', 'changes': [['sell', '38367.33', '0.02000000']], 'time': '2021-05-20T03:55:47.812042Z'}
{'type': 'l2update', 'product_id': 'BTC-USD', 'changes': [['buy', '38295.19', '0.00000000']], 'time': '2021-05-20T03:55:47.815920Z'}
{'type': 'l2update', 'product_id': 'BTC-USD', 'changes': [['sell', '38339.24', '0.00000000']], 'time': '2021-05-20T03:55:47.815920Z'}
{'type': 'l2update', 'product_id': 'BTC-USD', 'changes': [['buy', '38232.95', '0.39800000']], 'time': '2021-05-20T03:55:47.817540Z'}
{'type': 'l2update', 'product_id': 'BTC-USD', 'changes': [['buy', '38319.57', '0.00000000']], 'time': '2021-05-20T03:55:47.818000Z'}
{'type': 'l2update', 'product_id': 'BTC-USD', 'changes': [['buy', '38320.19', '0.07242891']], 'time': '2021-05-20T03:55:47.826232Z'}
{'type': 'l2update', 'product_id': 'BTC-USD', 'changes': [['buy', '38311.03', '0.99315797']], 'time': '2021-05-20T03:55:47.826735Z'}
{'type': 'l2update', 'product_id': 'BTC-USD', 'changes': [['buy', '38320.18', '0.00000000']], 'time': '2021-05-20T03:55:47.828493Z'}
{'type': 'l2update', 'product_id': 'BTC-USD', 'changes': [['sell', '38467.32', '0.33283603']], 'time': '2021-05-20T03:55:47.829597Z'}
{'type': 'l2update', 'product_id': 'BTC-USD', 'changes': [['buy', '38114.82', '0.02368550']], 'time': '2021-05-20T03:55:47.829678Z'}
{'type': 'l2update', 'product_id': 'BTC-USD', 'changes': [['sell', '38420.38', '0.00000000']], 'time': '2021-05-20T03:55:47.834154Z'}
{'type': 'l2update', 'product_id': 'BTC-USD', 'changes': [['sell', '38449.58', '0.00000000']], 'time': '2021-05-20T03:55:47.835606Z'}
{'type': 'l2update', 'product_id': 'BTC-USD', 'changes': [['buy', '38315.31', '0.00000000']], 'time': '2021-05-20T03:55:47.837999Z'}
{'type': 'l2update', 'product_id': 'BTC-USD', 'changes': [['buy', '38314.50', '0.00000000']], 'time': '2021-05-20T03:55:47.837999Z'}
{'type': 'l2update', 'product_id': 'BTC-USD', 'changes': [['sell', '38369.48', '0.01000000']], 'time': '2021-05-20T03:55:47.840838Z'}
{'type': 'l2update', 'product_id': 'BTC-USD', 'changes': [['sell', '38338.95', '0.01278283']], 'time': '2021-05-20T03:55:47.841831Z'}
{'type': 'l2update', 'product_id': 'BTC-USD', 'changes': [['sell', '38338.95', '0.00148558']], 'time': '2021-05-20T03:55:47.841863Z'}
{'type': 'l2update', 'product_id': 'BTC-USD', 'changes': [['sell', '38424.10', '0.37758212']], 'time': '2021-05-20T03:55:47.843598Z'}
{'type': 'l2update', 'product_id': 'BTC-USD', 'changes': [['sell', '38417.63', '0.00000000']], 'time': '2021-05-20T03:55:47.843598Z'}
{'type': 'l2update', 'product_id': 'BTC-USD', 'changes': [['buy', '38256.39', '2.42020000']], 'time': '2021-05-20T03:55:47.844695Z'}
{'type': 'l2update', 'product_id': 'BTC-USD', 'changes': [['buy', '38315.49', '0.00000000']], 'time': '2021-05-20T03:55:47.844861Z'}
{'type': 'l2update', 'product_id': 'BTC-USD', 'changes': [['sell', '38349.04', '2.48969908']], 'time': '2021-05-20T03:55:47.847046Z'}
{'type': 'l2update', 'product_id': 'BTC-USD', 'changes': [['sell', '38423.71', '0.08232289']], 'time': '2021-05-20T03:55:47.848447Z'}
{'type': 'l2update', 'product_id': 'BTC-USD', 'changes': [['sell', '38599.99', '3.22892558']], 'time': '2021-05-20T03:55:47.848981Z'}
{'type': 'l2update', 'product_id': 'BTC-USD', 'changes': [['buy', '38311.01', '0.00000000']], 'time': '2021-05-20T03:55:47.861777Z'}
{'type': 'l2update', 'product_id': 'BTC-USD', 'changes': [['sell', '38348.98', '0.05000000']], 'time': '2021-05-20T03:55:47.861891Z'}
{'type': 'l2update', 'product_id': 'BTC-USD', 'changes': [['buy', '38188.23', '0.01000000']], 'time': '2021-05-20T03:55:47.862069Z'}
{'type': 'l2update', 'product_id': 'BTC-USD', 'changes': [['sell', '38489.25', '0.01000000']], 'time': '2021-05-20T03:55:47.862420Z'}
{'type': 'l2update', 'product_id': 'BTC-USD', 'changes': [['sell', '38367.61', '0.03000000']], 'time': '2021-05-20T03:55:47.862793Z'}
{'type': 'l2update', 'product_id': 'BTC-USD', 'changes': [['sell', '38480.11', '0.00000000']], 'time': '2021-05-20T03:55:47.865045Z'}
{'type': 'l2update', 'product_id': 'BTC-USD', 'changes': [['sell', '38416.31', '0.00000000']], 'time': '2021-05-20T03:55:47.865689Z'}
{'type': 'l2update', 'product_id': 'BTC-USD', 'changes': [['sell', '38493.91', '0.01398670']], 'time': '2021-05-20T03:55:47.872975Z'}
{'type': 'l2update', 'product_id': 'BTC-USD', 'changes': [['buy', '38321.02', '0.01192699']], 'time': '2021-05-20T03:55:47.873053Z'}
{'type': 'l2update', 'product_id': 'BTC-USD', 'changes': [['buy', '38290.41', '1.20000000']], 'time': '2021-05-20T03:55:47.876071Z'}
{'type': 'l2update', 'product_id': 'BTC-USD', 'changes': [['sell', '38338.95', '0.00000000']], 'time': '2021-05-20T03:55:47.879730Z'}
{'type': 'l2update', 'product_id': 'BTC-USD', 'changes': [['buy', '38319.61', '0.00000000']], 'time': '2021-05-20T03:55:47.882250Z'}
{'type': 'l2update', 'product_id': 'BTC-USD', 'changes': [['buy', '38287.08', '0.01000000']], 'time': '2021-05-20T03:55:47.884579Z'}
{'type': 'l2update', 'product_id': 'BTC-USD', 'changes': [['buy', '38321.02', '0.07460000']], 'time': '2021-05-20T03:55:47.884849Z'}
{'type': 'l2update', 'product_id': 'BTC-USD', 'changes': [['sell', '38338.34', '0.00000000']], 'time': '2021-05-20T03:55:47.888824Z'}
{'type': 'l2update', 'product_id': 'BTC-USD', 'changes': [['buy', '38199.65', '0.67736303']], 'time': '2021-05-20T03:55:47.893477Z'}
{'type': 'l2update', 'product_id': 'BTC-USD', 'changes': [['sell', '38362.47', '0.00000000']], 'time': '2021-05-20T03:55:47.893705Z'}
{'type': 'l2update', 'product_id': 'BTC-USD', 'changes': [['buy', '38311.03', '0.00000000']], 'time': '2021-05-20T03:55:47.896141Z'}
{'type': 'l2update', 'product_id': 'BTC-USD', 'changes': [['buy', '38304.88', '0.42670000']], 'time': '2021-05-20T03:55:47.898080Z'}
{'type': 'l2update', 'product_id': 'BTC-USD', 'changes': [['sell', '38342.90', '0.50000000']], 'time': '2021-05-20T03:55:47.898123Z'}
{'type': 'l2update', 'product_id': 'BTC-USD', 'changes': [['buy', '38320.19', '0.00000000']], 'time': '2021-05-20T03:55:47.900711Z'}
{'type': 'l2update', 'product_id': 'BTC-USD', 'changes': [['buy', '37948.74', '0.00000000']], 'time': '2021-05-20T03:55:47.903832Z'}
{'type': 'l2update', 'product_id': 'BTC-USD', 'changes': [['sell', '38337.99', '0.01343442']], 'time': '2021-05-20T03:55:47.906835Z'}
{'type': 'l2update', 'product_id': 'BTC-USD', 'changes': [['sell', '38608.01', '0.00000000']], 'time': '2021-05-20T03:55:47.910273Z'}
{'type': 'l2update', 'product_id': 'BTC-USD', 'changes': [['sell', '38498.69', '0.01000000']], 'time': '2021-05-20T03:55:47.911418Z'}
{'type': 'l2update', 'product_id': 'BTC-USD', 'changes': [['buy', '38320.20', '0.40135082']], 'time': '2021-05-20T03:55:47.912047Z'}
{'type': 'l2update', 'product_id': 'BTC-USD', 'changes': [['sell', '38459.89', '0.44299432']], 'time': '2021-05-20T03:55:47.912092Z'}
{'type': 'l2update', 'product_id': 'BTC-USD', 'changes': [['buy', '38320.57', '0.00000000']], 'time': '2021-05-20T03:55:47.913760Z'}
{'type': 'l2update', 'product_id': 'BTC-USD', 'changes': [['buy', '38319.01', '0.21352786']], 'time': '2021-05-20T03:55:47.914645Z'}
{'type': 'l2update', 'product_id': 'BTC-USD', 'changes': [['sell', '38425.44', '1.20000000']], 'time': '2021-05-20T03:55:47.919653Z'}
{'type': 'l2update', 'product_id': 'BTC-USD', 'changes': [['sell', '38550.71', '0.00000000']], 'time': '2021-05-20T03:55:47.920234Z'}
{'type': 'l2update', 'product_id': 'BTC-USD', 'changes': [['sell', '38338.29', '1.26100000']], 'time': '2021-05-20T03:55:47.924293Z'}
{'type': 'l2update', 'product_id': 'BTC-USD', 'changes': [['sell', '38434.03', '0.00000000']], 'time': '2021-05-20T03:55:47.924898Z'}
{'type': 'l2update', 'product_id': 'BTC-USD', 'changes': [['sell', '38429.05', '0.00000000']], 'time': '2021-05-20T03:55:47.924937Z'}
{'type': 'l2update', 'product_id': 'BTC-USD', 'changes': [['sell', '38606.88', '0.00000000']], 'time': '2021-05-20T03:55:47.932196Z'}
{'type': 'l2update', 'product_id': 'BTC-USD', 'changes': [['sell', '38349.04', '0.00000000']], 'time': '2021-05-20T03:55:47.934794Z'}
{'type': 'l2update', 'product_id': 'BTC-USD', 'changes': [['sell', '38451.88', '0.30646492']], 'time': '2021-05-20T03:55:47.935350Z'}
{'type': 'l2update', 'product_id': 'BTC-USD', 'changes': [['sell', '38424.10', '0.00000000']], 'time': '2021-05-20T03:55:47.935350Z'}
{'type': 'l2update', 'product_id': 'BTC-USD', 'changes': [['sell', '38405.27', '0.00000000']], 'time': '2021-05-20T03:55:47.935350Z'}
{'type': 'l2update', 'product_id': 'BTC-USD', 'changes': [['buy', '38319.55', '0.00176497']], 'time': '2021-05-20T03:55:47.935734Z'}
{'type': 'l2update', 'product_id': 'BTC-USD', 'changes': [['sell', '38338.96', '0.07460000']], 'time': '2021-05-20T03:55:47.935788Z'}
{'type': 'l2update', 'product_id': 'BTC-USD', 'changes': [['sell', '38376.81', '0.04000000']], 'time': '2021-05-20T03:55:47.935865Z'}
{'type': 'l2update', 'product_id': 'BTC-USD', 'changes': [['sell', '38339.56', '1.30896934']], 'time': '2021-05-20T03:55:47.936259Z'}
{'type': 'l2update', 'product_id': 'BTC-USD', 'changes': [['sell', '38337.99', '0.01492000']], 'time': '2021-05-20T03:55:47.936812Z'}
{'type': 'l2update', 'product_id': 'BTC-USD', 'changes': [['buy', '38308.03', '0.02400000']], 'time': '2021-05-20T03:55:47.937045Z'}
{'type': 'l2update', 'product_id': 'BTC-USD', 'changes': [['buy', '38307.22', '0.02400000']], 'time': '2021-05-20T03:55:47.937045Z'}
{'type': 'l2update', 'product_id': 'BTC-USD', 'changes': [['buy', '38306.42', '0.02400000']], 'time': '2021-05-20T03:55:47.937045Z'}
{'type': 'l2update', 'product_id': 'BTC-USD', 'changes': [['sell', '38364.47', '0.00000000']], 'time': '2021-05-20T03:55:47.938537Z'}
{'type': 'l2update', 'product_id': 'BTC-USD', 'changes': [['sell', '38362.18', '0.47707109']], 'time': '2021-05-20T03:55:47.940429Z'}
{'type': 'l2update', 'product_id': 'BTC-USD', 'changes': [['sell', '38366.87', '0.40300000']], 'time': '2021-05-20T03:55:47.941032Z'}
{'type': 'l2update', 'product_id': 'BTC-USD', 'changes': [['buy', '38194.80', '0.00000000']], 'time': '2021-05-20T03:55:47.944476Z'}
{'type': 'l2update', 'product_id': 'BTC-USD', 'changes': [['buy', '38261.51', '0.00000000']], 'time': '2021-05-20T03:55:47.944602Z'}
{'type': 'l2update', 'product_id': 'BTC-USD', 'changes': [['sell', '38421.43', '0.00000000']], 'time': '2021-05-20T03:55:47.947327Z'}
{'type': 'l2update', 'product_id': 'BTC-USD', 'changes': [['sell', '38337.99', '0.00148558']], 'time': '2021-05-20T03:55:47.950632Z'}
{'type': 'l2update', 'product_id': 'BTC-USD', 'changes': [['buy', '38275.19', '0.00000000']], 'time': '2021-05-20T03:55:47.950692Z'}
{'type': 'l2update', 'product_id': 'BTC-USD', 'changes': [['sell', '38346.76', '0.08193946']], 'time': '2021-05-20T03:55:47.958546Z'}
{'type': 'l2update', 'product_id': 'BTC-USD', 'changes': [['sell', '38482.09', '0.00000000']], 'time': '2021-05-20T03:55:47.962384Z'}
{'type': 'l2update', 'product_id': 'BTC-USD', 'changes': [['buy', '38321.58', '0.01492000']], 'time': '2021-05-20T03:55:47.963709Z'}
{'type': 'l2update', 'product_id': 'BTC-USD', 'changes': [['buy', '38320.58', '0.07242891']], 'time': '2021-05-20T03:55:47.966084Z'}
{'type': 'l2update', 'product_id': 'BTC-USD', 'changes': [['buy', '38275.61', '0.00000000']], 'time': '2021-05-20T03:55:47.968813Z'}
{'type': 'l2update', 'product_id': 'BTC-USD', 'changes': [['buy', '38296.23', '0.02611223']], 'time': '2021-05-20T03:55:47.969051Z'}
{'type': 'l2update', 'product_id': 'BTC-USD', 'changes': [['sell', '38342.90', '0.68981474']], 'time': '2021-05-20T03:55:47.969307Z'}
{'type': 'l2update', 'product_id': 'BTC-USD', 'changes': [['sell', '38338.96', '0.00000000']], 'time': '2021-05-20T03:55:47.969461Z'}
{'type': 'l2update', 'product_id': 'BTC-USD', 'changes': [['sell', '38454.34', '0.02047476']], 'time': '2021-05-20T03:55:47.970434Z'}
{'type': 'l2update', 'product_id': 'BTC-USD', 'changes': [['sell', '38484.28', '0.01234517']], 'time': '2021-05-20T03:55:47.970793Z'}
{'type': 'l2update', 'product_id': 'BTC-USD', 'changes': [['sell', '38337.99', '0.00000000']], 'time': '2021-05-20T03:55:47.972562Z'}
{'type': 'l2update', 'product_id': 'BTC-USD', 'changes': [['sell', '38459.05', '0.00000000']], 'time': '2021-05-20T03:55:47.973169Z'}
{'type': 'l2update', 'product_id': 'BTC-USD', 'changes': [['sell', '38369.48', '0.00000000']], 'time': '2021-05-20T03:55:47.973633Z'}
{'type': 'l2update', 'product_id': 'BTC-USD', 'changes': [['buy', '38308.03', '0.00000000']], 'time': '2021-05-20T03:55:47.974525Z'}
{'type': 'l2update', 'product_id': 'BTC-USD', 'changes': [['buy', '38303.72', '0.99315797']], 'time': '2021-05-20T03:55:47.976029Z'}
{'type': 'l2update', 'product_id': 'BTC-USD', 'changes': [['sell', '38591.82', '0.01000000']], 'time': '2021-05-20T03:55:47.976677Z'}
{'type': 'l2update', 'product_id': 'BTC-USD', 'changes': [['buy', '38304.88', '0.00000000']], 'time': '2021-05-20T03:55:47.976784Z'}
{'type': 'l2update', 'product_id': 'BTC-USD', 'changes': [['sell', '38488.01', '0.00000000']], 'time': '2021-05-20T03:55:47.979797Z'}
{'type': 'l2update', 'product_id': 'BTC-USD', 'changes': [['sell', '38519.17', '0.00000000']], 'time': '2021-05-20T03:55:47.980568Z'}
{'type': 'l2update', 'product_id': 'BTC-USD', 'changes': [['sell', '38337.98', '1.75520889']], 'time': '2021-05-20T03:55:47.981029Z'}
{'type': 'l2update', 'product_id': 'BTC-USD', 'changes': [['buy', '38271.02', '0.00000000']], 'time': '2021-05-20T03:55:47.983601Z'}
{'type': 'l2update', 'product_id': 'BTC-USD', 'changes': [['sell', '38407.37', '0.01000000']], 'time': '2021-05-20T03:55:47.990407Z'}
{'type': 'l2update', 'product_id': 'BTC-USD', 'changes': [['sell', '38634.20', '0.12941903']], 'time': '2021-05-20T03:55:47.990672Z'}
{'type': 'l2update', 'product_id': 'BTC-USD', 'changes': [['buy', '38285.49', '0.10000000']], 'time': '2021-05-20T03:55:47.991050Z'}
{'type': 'l2update', 'product_id': 'BTC-USD', 'changes': [['buy', '38321.02', '0.01192699']], 'time': '2021-05-20T03:55:47.997226Z'}
{'type': 'l2update', 'product_id': 'BTC-USD', 'changes': [['buy', '38321.02', '0.00000000']], 'time': '2021-05-20T03:55:47.997722Z'}
{'type': 'l2update', 'product_id': 'BTC-USD', 'changes': [['buy', '38294.65', '0.58596956']], 'time': '2021-05-20T03:55:47.998545Z'}
{'type': 'l2update', 'product_id': 'BTC-USD', 'changes': [['sell', '38474.94', '0.00000000']], 'time': '2021-05-20T03:55:47.999347Z'}
{'type': 'l2update', 'product_id': 'BTC-USD', 'changes': [['sell', '38467.32', '0.03573040']], 'time': '2021-05-20T03:55:47.999347Z'}
{'type': 'l2update', 'product_id': 'BTC-USD', 'changes': [['sell', '38459.89', '0.05759297']], 'time': '2021-05-20T03:55:47.999347Z'}
{'type': 'l2update', 'product_id': 'BTC-USD', 'changes': [['sell', '38451.88', '0.00000000']], 'time': '2021-05-20T03:55:47.999347Z'}
{'type': 'l2update', 'product_id': 'BTC-USD', 'changes': [['sell', '38437.61', '0.00000000']], 'time': '2021-05-20T03:55:47.999347Z'}
{'type': 'l2update', 'product_id': 'BTC-USD', 'changes': [['sell', '38430.76', '0.00000000']], 'time': '2021-05-20T03:55:47.999347Z'}
{'type': 'l2update', 'product_id': 'BTC-USD', 'changes': [['sell', '38337.87', '0.01343442']], 'time': '2021-05-20T03:55:48.000888Z'}
{'type': 'l2update', 'product_id': 'BTC-USD', 'changes': [['buy', '38256.24', '0.00000000']], 'time': '2021-05-20T03:55:48.005158Z'}
{'type': 'l2update', 'product_id': 'BTC-USD', 'changes': [['buy', '38307.22', '0.00000000']], 'time': '2021-05-20T03:55:48.006467Z'}
{'type': 'l2update', 'product_id': 'BTC-USD', 'changes': [['buy', '38306.42', '0.00000000']], 'time': '2021-05-20T03:55:48.006467Z'}
{'type': 'l2update', 'product_id': 'BTC-USD', 'changes': [['buy', '38287.08', '0.00000000']], 'time': '2021-05-20T03:55:48.006596Z'}
{'type': 'l2update', 'product_id': 'BTC-USD', 'changes': [['sell', '38366.87', '0.00000000']], 'time': '2021-05-20T03:55:48.008125Z'}
{'type': 'l2update', 'product_id': 'BTC-USD', 'changes': [['sell', '38512.96', '0.00000000']], 'time': '2021-05-20T03:55:48.009606Z'}
{'type': 'l2update', 'product_id': 'BTC-USD', 'changes': [['sell', '38367.26', '0.05000000']], 'time': '2021-05-20T03:55:48.009851Z'}
{'type': 'l2update', 'product_id': 'BTC-USD', 'changes': [['sell', '38401.41', '0.02604071']], 'time': '2021-05-20T03:55:48.009879Z'}
{'type': 'l2update', 'product_id': 'BTC-USD', 'changes': [['buy', '38311.07', '0.84700000']], 'time': '2021-05-20T03:55:48.010218Z'}
{'type': 'l2update', 'product_id': 'BTC-USD', 'changes': [['sell', '38377.36', '0.03207306']], 'time': '2021-05-20T03:55:48.016435Z'}
{'type': 'l2update', 'product_id': 'BTC-USD', 'changes': [['sell', '38338.33', '2.48969908']], 'time': '2021-05-20T03:55:48.017121Z'}
{'type': 'l2update', 'product_id': 'BTC-USD', 'changes': [['sell', '38513.59', '0.01000000']], 'time': '2021-05-20T03:55:48.023103Z'}
{'type': 'l2update', 'product_id': 'BTC-USD', 'changes': [['buy', '38320.20', '0.00000000']], 'time': '2021-05-20T03:55:48.023856Z'}
{'type': 'l2update', 'product_id': 'BTC-USD', 'changes': [['sell', '38339.57', '0.00000000']], 'time': '2021-05-20T03:55:48.031136Z'}
{'type': 'l2update', 'product_id': 'BTC-USD', 'changes': [['buy', '38281.13', '0.00000000']], 'time': '2021-05-20T03:55:48.031136Z'}
{'type': 'l2update', 'product_id': 'BTC-USD', 'changes': [['sell', '38407.37', '0.00000000']], 'time': '2021-05-20T03:55:48.033621Z'}
{'type': 'l2update', 'product_id': 'BTC-USD', 'changes': [['sell', '38376.81', '0.00000000']], 'time': '2021-05-20T03:55:48.037204Z'}
{'type': 'l2update', 'product_id': 'BTC-USD', 'changes': [['sell', '38558.40', '0.00648367']], 'time': '2021-05-20T03:55:48.037348Z'}
{'type': 'l2update', 'product_id': 'BTC-USD', 'changes': [['sell', '38371.01', '0.09373595']], 'time': '2021-05-20T03:55:48.037408Z'}
{'type': 'l2update', 'product_id': 'BTC-USD', 'changes': [['sell', '38337.75', '0.07460000']], 'time': '2021-05-20T03:55:48.037728Z'}
{'type': 'l2update', 'product_id': 'BTC-USD', 'changes': [['buy', '38207.77', '0.13086342']], 'time': '2021-05-20T03:55:48.037914Z'}
{'type': 'l2update', 'product_id': 'BTC-USD', 'changes': [['buy', '38320.58', '0.00000000']], 'time': '2021-05-20T03:55:48.038254Z'}
{'type': 'l2update', 'product_id': 'BTC-USD', 'changes': [['sell', '38337.87', '0.01492000']], 'time': '2021-05-20T03:55:48.042681Z'}
{'type': 'l2update', 'product_id': 'BTC-USD', 'changes': [['sell', '38466.78', '0.00000000']], 'time': '2021-05-20T03:55:48.046653Z'}
{'type': 'l2update', 'product_id': 'BTC-USD', 'changes': [['buy', '38321.93', '0.07460000']], 'time': '2021-05-20T03:55:48.046667Z'}
{'type': 'l2update', 'product_id': 'BTC-USD', 'changes': [['sell', '38489.25', '0.00000000']], 'time': '2021-05-20T03:55:48.055166Z'}
{'type': 'l2update', 'product_id': 'BTC-USD', 'changes': [['sell', '38342.90', '0.18981474']], 'time': '2021-05-20T03:55:48.061666Z'}
{'type': 'l2update', 'product_id': 'BTC-USD', 'changes': [['buy', '38298.21', '0.04852859']], 'time': '2021-05-20T03:55:48.064807Z'}
{'type': 'l2update', 'product_id': 'BTC-USD', 'changes': [['sell', '38340.54', '0.06464156']], 'time': '2021-05-20T03:55:48.064807Z'}
{'type': 'l2update', 'product_id': 'BTC-USD', 'changes': [['sell', '38464.92', '0.01000000']], 'time': '2021-05-20T03:55:48.065100Z'}
{'type': 'l2update', 'product_id': 'BTC-USD', 'changes': [['buy', '38295.20', '0.04282797']], 'time': '2021-05-20T03:55:48.065647Z'}
{'type': 'l2update', 'product_id': 'BTC-USD', 'changes': [['sell', '38337.87', '0.00148558']], 'time': '2021-05-20T03:55:48.066758Z'}
{'type': 'l2update', 'product_id': 'BTC-USD', 'changes': [['sell', '38421.51', '0.01000000']], 'time': '2021-05-20T03:55:48.071512Z'}
{'type': 'l2update', 'product_id': 'BTC-USD', 'changes': [['buy', '38283.25', '0.01000000']], 'time': '2021-05-20T03:55:48.071558Z'}
{'type': 'l2update', 'product_id': 'BTC-USD', 'changes': [['buy', '38212.71', '0.03497657']], 'time': '2021-05-20T03:55:48.071938Z'}
{'type': 'l2update', 'product_id': 'BTC-USD', 'changes': [['buy', '38321.93', '0.05924270']], 'time': '2021-05-20T03:55:48.072529Z'}
{'type': 'l2update', 'product_id': 'BTC-USD', 'changes': [['sell', '38348.99', '0.00000000']], 'time': '2021-05-20T03:55:48.074806Z'}
{'type': 'l2update', 'product_id': 'BTC-USD', 'changes': [['buy', '38261.01', '0.00000000']], 'time': '2021-05-20T03:55:48.076559Z'}
{'type': 'l2update', 'product_id': 'BTC-USD', 'changes': [['buy', '38278.18', '0.05445916']], 'time': '2021-05-20T03:55:48.076648Z'}
{'type': 'l2update', 'product_id': 'BTC-USD', 'changes': [['buy', '38321.58', '0.00000000']], 'time': '2021-05-20T03:55:48.076944Z'}
{'type': 'l2update', 'product_id': 'BTC-USD', 'changes': [['buy', '38301.48', '0.02400000']], 'time': '2021-05-20T03:55:48.079164Z'}
{'type': 'l2update', 'product_id': 'BTC-USD', 'changes': [['buy', '38300.68', '0.02400000']], 'time': '2021-05-20T03:55:48.079164Z'}
{'type': 'l2update', 'product_id': 'BTC-USD', 'changes': [['buy', '38299.87', '0.02400000']], 'time': '2021-05-20T03:55:48.079164Z'}
{'type': 'l2update', 'product_id': 'BTC-USD', 'changes': [['buy', '38319.62', '0.10000000']], 'time': '2021-05-20T03:55:48.079781Z'}
{'type': 'l2update', 'product_id': 'BTC-USD', 'changes': [['sell', '38495.57', '0.03040850']], 'time': '2021-05-20T03:55:48.081733Z'}
{'type': 'l2update', 'product_id': 'BTC-USD', 'changes': [['sell', '38342.90', '0.00000000']], 'time': '2021-05-20T03:55:48.082349Z'}
{'type': 'l2update', 'product_id': 'BTC-USD', 'changes': [['sell', '38428.21', '0.40202211']], 'time': '2021-05-20T03:55:48.083224Z'}
{'type': 'l2update', 'product_id': 'BTC-USD', 'changes': [['sell', '38421.93', '0.33127880']], 'time': '2021-05-20T03:55:48.083224Z'}
{'type': 'l2update', 'product_id': 'BTC-USD', 'changes': [['buy', '38322.92', '0.05125072']], 'time': '2021-05-20T03:55:48.087800Z'}
{'type': 'l2update', 'product_id': 'BTC-USD', 'changes': [['buy', '38321.03', '0.07242891']], 'time': '2021-05-20T03:55:48.087820Z'}
{'type': 'l2update', 'product_id': 'BTC-USD', 'changes': [['buy', '38311.08', '0.40135082']], 'time': '2021-05-20T03:55:48.092579Z'}
{'type': 'l2update', 'product_id': 'BTC-USD', 'changes': [['buy', '38275.64', '0.00000000']], 'time': '2021-05-20T03:55:48.093541Z'}
{'type': 'l2update', 'product_id': 'BTC-USD', 'changes': [['sell', '38337.87', '0.00000000']], 'time': '2021-05-20T03:55:48.094045Z'}
{'type': 'l2update', 'product_id': 'BTC-USD', 'changes': [['buy', '38092.62', '0.00000000']], 'time': '2021-05-20T03:55:48.094161Z'}
{'type': 'l2update', 'product_id': 'BTC-USD', 'changes': [['buy', '38320.19', '0.26000000']], 'time': '2021-05-20T03:55:48.098209Z'}
{'type': 'l2update', 'product_id': 'BTC-USD', 'changes': [['sell', '38506.20', '0.01000000']], 'time': '2021-05-20T03:55:48.098307Z'}
{'type': 'l2update', 'product_id': 'BTC-USD', 'changes': [['buy', '38303.14', '0.48880000']], 'time': '2021-05-20T03:55:48.098331Z'}
{'type': 'l2update', 'product_id': 'BTC-USD', 'changes': [['sell', '38337.86', '0.50000000']], 'time': '2021-05-20T03:55:48.099604Z'}
{'type': 'l2update', 'product_id': 'BTC-USD', 'changes': [['buy', '38296.22', '0.00000000']], 'time': '2021-05-20T03:55:48.100297Z'}
{'type': 'l2update', 'product_id': 'BTC-USD', 'changes': [['buy', '38211.23', '0.00000000']], 'time': '2021-05-20T03:55:48.104145Z'}
{'type': 'l2update', 'product_id': 'BTC-USD', 'changes': [['sell', '38342.91', '0.00000000']], 'time': '2021-05-20T03:55:48.106620Z'}
{'type': 'l2update', 'product_id': 'BTC-USD', 'changes': [['sell', '38348.98', '0.00000000']], 'time': '2021-05-20T03:55:48.108452Z'}
{'type': 'l2update', 'product_id': 'BTC-USD', 'changes': [['sell', '38336.69', '0.04821762']], 'time': '2021-05-20T03:55:48.109397Z'}
{'type': 'l2update', 'product_id': 'BTC-USD', 'changes': [['sell', '38366.65', '0.04000000']], 'time': '2021-05-20T03:55:48.109576Z'}
{'type': 'l2update', 'product_id': 'BTC-USD', 'changes': [['buy', '38301.48', '0.00000000']], 'time': '2021-05-20T03:55:48.110604Z'}
{'type': 'l2update', 'product_id': 'BTC-USD', 'changes': [['sell', '38337.21', '0.01343442']], 'time': '2021-05-20T03:55:48.113771Z'}
{'type': 'l2update', 'product_id': 'BTC-USD', 'changes': [['sell', '38482.75', '0.00000000']], 'time': '2021-05-20T03:55:48.114147Z'}
{'type': 'l2update', 'product_id': 'BTC-USD', 'changes': [['buy', '38321.93', '0.00000000']], 'time': '2021-05-20T03:55:48.118394Z'}
{'type': 'l2update', 'product_id': 'BTC-USD', 'changes': [['buy', '38168.42', '0.05172663']], 'time': '2021-05-20T03:55:48.123496Z'}
{'type': 'l2update', 'product_id': 'BTC-USD', 'changes': [['sell', '38366.43', '0.04927612']], 'time': '2021-05-20T03:55:48.123550Z'}
{'type': 'l2update', 'product_id': 'BTC-USD', 'changes': [['sell', '38361.63', '0.04984658']], 'time': '2021-05-20T03:55:48.123781Z'}
{'type': 'l2update', 'product_id': 'BTC-USD', 'changes': [['buy', '38207.21', '0.00000000']], 'time': '2021-05-20T03:55:48.125895Z'}
{'type': 'l2update', 'product_id': 'BTC-USD', 'changes': [['buy', '38322.21', '0.01492000']], 'time': '2021-05-20T03:55:48.130781Z'}
{'type': 'l2update', 'product_id': 'BTC-USD', 'changes': [['buy', '38320.11', '0.01535730']], 'time': '2021-05-20T03:55:48.131151Z'}
{'type': 'l2update', 'product_id': 'BTC-USD', 'changes': [['buy', '38303.14', '0.00000000']], 'time': '2021-05-20T03:55:48.131172Z'}
{'type': 'l2update', 'product_id': 'BTC-USD', 'changes': [['sell', '38337.98', '0.00000000']], 'time': '2021-05-20T03:55:48.137169Z'}
{'type': 'l2update', 'product_id': 'BTC-USD', 'changes': [['buy', '38207.11', '0.00000000']], 'time': '2021-05-20T03:55:48.137197Z'}
{'type': 'l2update', 'product_id': 'BTC-USD', 'changes': [['buy', '38315.49', '0.84800000']], 'time': '2021-05-20T03:55:48.139846Z'}
{'type': 'l2update', 'product_id': 'BTC-USD', 'changes': [['buy', '38320.21', '0.10000000']], 'time': '2021-05-20T03:55:48.140154Z'}
{'type': 'l2update', 'product_id': 'BTC-USD', 'changes': [['buy', '38315.44', '0.00000000']], 'time': '2021-05-20T03:55:48.142128Z'}
{'type': 'l2update', 'product_id': 'BTC-USD', 'changes': [['sell', '38337.75', '0.00000000']], 'time': '2021-05-20T03:55:48.142858Z'}
{'type': 'l2update', 'product_id': 'BTC-USD', 'changes': [['buy', '38300.68', '0.00000000']], 'time': '2021-05-20T03:55:48.144240Z'}
{'type': 'l2update', 'product_id': 'BTC-USD', 'changes': [['sell', '38337.21', '0.00000000']], 'time': '2021-05-20T03:55:48.147443Z'}
{'type': 'l2update', 'product_id': 'BTC-USD', 'changes': [['sell', '38365.48', '0.00000000']], 'time': '2021-05-20T03:55:48.147863Z'}
{'type': 'l2update', 'product_id': 'BTC-USD', 'changes': [['sell', '38362.17', '0.05000000']], 'time': '2021-05-20T03:55:48.154126Z'}
{'type': 'l2update', 'product_id': 'BTC-USD', 'changes': [['buy', '38321.59', '0.07213373']], 'time': '2021-05-20T03:55:48.154947Z'}
{'type': 'l2update', 'product_id': 'BTC-USD', 'changes': [['buy', '38279.18', '0.02612386']], 'time': '2021-05-20T03:55:48.155077Z'}
{'type': 'l2update', 'product_id': 'BTC-USD', 'changes': [['sell', '38484.28', '0.00000000']], 'time': '2021-05-20T03:55:48.155205Z'}
{'type': 'l2update', 'product_id': 'BTC-USD', 'changes': [['buy', '38321.03', '0.00000000']], 'time': '2021-05-20T03:55:48.156832Z'}
{'type': 'l2update', 'product_id': 'BTC-USD', 'changes': [['sell', '38336.69', '0.00000000']], 'time': '2021-05-20T03:55:48.160005Z'}
{'type': 'l2update', 'product_id': 'BTC-USD', 'changes': [['sell', '38362.19', '0.00000000']], 'time': '2021-05-20T03:55:48.161467Z'}
{'type': 'l2update', 'product_id': 'BTC-USD', 'changes': [['buy', '38322.21', '0.00000000']], 'time': '2021-05-20T03:55:48.163922Z'}
{'type': 'l2update', 'product_id': 'BTC-USD', 'changes': [['buy', '38307.70', '0.52195094']], 'time': '2021-05-20T03:55:48.164995Z'}
{'type': 'l2update', 'product_id': 'BTC-USD', 'changes': [['buy', '38320.11', '0.00000000']], 'time': '2021-05-20T03:55:48.165340Z'}
{'type': 'l2update', 'product_id': 'BTC-USD', 'changes': [['sell', '38339.56', '0.00000000']], 'time': '2021-05-20T03:55:48.167601Z'}
{'type': 'l2update', 'product_id': 'BTC-USD', 'changes': [['sell', '38398.74', '0.37247717']], 'time': '2021-05-20T03:55:48.169596Z'}
{'type': 'l2update', 'product_id': 'BTC-USD', 'changes': [['buy', '38311.08', '0.00000000']], 'time': '2021-05-20T03:55:48.172811Z'}
{'type': 'l2update', 'product_id': 'BTC-USD', 'changes': [['sell', '38453.83', '0.02817074']], 'time': '2021-05-20T03:55:48.174184Z'}
{'type': 'l2update', 'product_id': 'BTC-USD', 'changes': [['sell', '38366.57', '0.42630000']], 'time': '2021-05-20T03:55:48.174205Z'}
{'type': 'l2update', 'product_id': 'BTC-USD', 'changes': [['buy', '37992.97', '5.00000000']], 'time': '2021-05-20T03:55:48.174978Z'}
{'type': 'l2update', 'product_id': 'BTC-USD', 'changes': [['sell', '38444.62', '0.00000000']], 'time': '2021-05-20T03:55:48.178115Z'}
{'type': 'l2update', 'product_id': 'BTC-USD', 'changes': [['sell', '38367.33', '0.00000000']], 'time': '2021-05-20T03:55:48.178575Z'}
{'type': 'l2update', 'product_id': 'BTC-USD', 'changes': [['sell', '38337.86', '0.00000000']], 'time': '2021-05-20T03:55:48.180962Z'}
{'type': 'l2update', 'product_id': 'BTC-USD', 'changes': [['buy', '38228.69', '0.01000000']], 'time': '2021-05-20T03:55:48.183165Z'}
{'type': 'l2update', 'product_id': 'BTC-USD', 'changes': [['sell', '38425.56', '0.14990000']], 'time': '2021-05-20T03:55:48.184631Z'}
{'type': 'l2update', 'product_id': 'BTC-USD', 'changes': [['buy', '38328.66', '0.04982169']], 'time': '2021-05-20T03:55:48.184770Z'}
{'type': 'l2update', 'product_id': 'BTC-USD', 'changes': [['buy', '38323.53', '0.05924270']], 'time': '2021-05-20T03:55:48.185635Z'}
{'type': 'l2update', 'product_id': 'BTC-USD', 'changes': [['buy', '38295.20', '0.74105794']], 'time': '2021-05-20T03:55:48.186113Z'}
{'type': 'l2update', 'product_id': 'BTC-USD', 'changes': [['sell', '38382.13', '0.00000000']], 'time': '2021-05-20T03:55:48.186740Z'}
{'type': 'l2update', 'product_id': 'BTC-USD', 'changes': [['sell', '38337.74', '0.18981474']], 'time': '2021-05-20T03:55:48.192446Z'}
{'type': 'l2update', 'product_id': 'BTC-USD', 'changes': [['buy', '38321.59', '0.00000000']], 'time': '2021-05-20T03:55:48.197518Z'}
{'type': 'l2update', 'product_id': 'BTC-USD', 'changes': [['sell', '38385.83', '0.00000000']], 'time': '2021-05-20T03:55:48.199275Z'}
{'type': 'l2update', 'product_id': 'BTC-USD', 'changes': [['buy', '38303.78', '0.52197088']], 'time': '2021-05-20T03:55:48.202018Z'}
{'type': 'l2update', 'product_id': 'BTC-USD', 'changes': [['sell', '38423.71', '0.00000000']], 'time': '2021-05-20T03:55:48.203347Z'}
{'type': 'l2update', 'product_id': 'BTC-USD', 'changes': [['buy', '38311.07', '0.00000000']], 'time': '2021-05-20T03:55:48.203389Z'}
{'type': 'l2update', 'product_id': 'BTC-USD', 'changes': [['sell', '38366.57', '0.00000000']], 'time': '2021-05-20T03:55:48.204518Z'}
{'type': 'l2update', 'product_id': 'BTC-USD', 'changes': [['sell', '38367.61', '0.00000000']], 'time': '2021-05-20T03:55:48.208468Z'}
{'type': 'l2update', 'product_id': 'BTC-USD', 'changes': [['buy', '38114.82', '0.00000000']], 'time': '2021-05-20T03:55:48.208781Z'}
{'type': 'l2update', 'product_id': 'BTC-USD', 'changes': [['sell', '43100.00', '1.09530000']], 'time': '2021-05-20T03:55:48.215171Z'}
{'type': 'l2update', 'product_id': 'BTC-USD', 'changes': [['buy', '38323.53', '0.00000000']], 'time': '2021-05-20T03:55:48.217599Z'}
{'type': 'l2update', 'product_id': 'BTC-USD', 'changes': [['buy', '38323.53', '0.01535730']], 'time': '2021-05-20T03:55:48.218250Z'}
{'type': 'l2update', 'product_id': 'BTC-USD', 'changes': [['buy', '38323.41', '0.01492000']], 'time': '2021-05-20T03:55:48.218285Z'}
{'type': 'l2update', 'product_id': 'BTC-USD', 'changes': [['sell', '38453.83', '0.06607744']], 'time': '2021-05-20T03:55:48.218492Z'}
{'type': 'l2update', 'product_id': 'BTC-USD', 'changes': [['sell', '38387.24', '0.32000000']], 'time': '2021-05-20T03:55:48.218724Z'}
{'type': 'l2update', 'product_id': 'BTC-USD', 'changes': [['sell', '38462.68', '0.01299961']], 'time': '2021-05-20T03:55:48.219393Z'}
{'type': 'l2update', 'product_id': 'BTC-USD', 'changes': [['buy', '38319.01', '0.06352786']], 'time': '2021-05-20T03:55:48.219655Z'}
{'type': 'l2update', 'product_id': 'BTC-USD', 'changes': [['buy', '38321.94', '0.07213613']], 'time': '2021-05-20T03:55:48.222052Z'}
{'type': 'l2update', 'product_id': 'BTC-USD', 'changes': [['sell', '38409.95', '0.36593177']], 'time': '2021-05-20T03:55:48.222365Z'}
{'type': 'l2update', 'product_id': 'BTC-USD', 'changes': [['sell', '38361.62', '0.50000000']], 'time': '2021-05-20T03:55:48.222391Z'}
{'type': 'l2update', 'product_id': 'BTC-USD', 'changes': [['buy', '38322.92', '0.00000000']], 'time': '2021-05-20T03:55:48.225785Z'}
{'type': 'l2update', 'product_id': 'BTC-USD', 'changes': [['buy', '38319.55', '0.00000000']], 'time': '2021-05-20T03:55:48.227203Z'}
{'type': 'l2update', 'product_id': 'BTC-USD', 'changes': [['buy', '38209.84', '0.00000000']], 'time': '2021-05-20T03:55:48.227599Z'}
{'type': 'l2update', 'product_id': 'BTC-USD', 'changes': [['sell', '38344.02', '0.00000000']], 'time': '2021-05-20T03:55:48.230483Z'}
{'type': 'l2update', 'product_id': 'BTC-USD', 'changes': [['buy', '38319.02', '0.01870000']], 'time': '2021-05-20T03:55:48.234862Z'}
{'type': 'l2update', 'product_id': 'BTC-USD', 'changes': [['buy', '38187.00', '0.05068183']], 'time': '2021-05-20T03:55:48.234884Z'}
{'type': 'l2update', 'product_id': 'BTC-USD', 'changes': [['sell', '38449.85', '0.01238088']], 'time': '2021-05-20T03:55:48.235918Z'}
{'type': 'l2update', 'product_id': 'BTC-USD', 'changes': [['sell', '38366.65', '0.00000000']], 'time': '2021-05-20T03:55:48.239456Z'}
{'type': 'l2update', 'product_id': 'BTC-USD', 'changes': [['sell', '38338.29', '0.00000000']], 'time': '2021-05-20T03:55:48.239620Z'}
{'type': 'l2update', 'product_id': 'BTC-USD', 'changes': [['sell', '38366.43', '0.00000000']], 'time': '2021-05-20T03:55:48.242904Z'}
{'type': 'l2update', 'product_id': 'BTC-USD', 'changes': [['buy', '38298.39', '0.02400000']], 'time': '2021-05-20T03:55:48.245472Z'}
{'type': 'l2update', 'product_id': 'BTC-USD', 'changes': [['buy', '38297.58', '0.02400000']], 'time': '2021-05-20T03:55:48.245472Z'}
{'type': 'l2update', 'product_id': 'BTC-USD', 'changes': [['buy', '38328.66', '0.27882169']], 'time': '2021-05-20T03:55:48.245498Z'}
{'type': 'l2update', 'product_id': 'BTC-USD', 'changes': [['buy', '38299.43', '0.78279579']], 'time': '2021-05-20T03:55:48.246114Z'}
{'type': 'l2update', 'product_id': 'BTC-USD', 'changes': [['buy', '38128.21', '0.01000000']], 'time': '2021-05-20T03:55:48.249579Z'}
{'type': 'l2update', 'product_id': 'BTC-USD', 'changes': [['buy', '38313.52', '0.44620000']], 'time': '2021-05-20T03:55:48.253991Z'}
{'type': 'l2update', 'product_id': 'BTC-USD', 'changes': [['sell', '43100.00', '4.36070000']], 'time': '2021-05-20T03:55:48.257983Z'}
{'type': 'l2update', 'product_id': 'BTC-USD', 'changes': [['buy', '38212.71', '0.06137002']], 'time': '2021-05-20T03:55:48.261011Z'}
{'type': 'l2update', 'product_id': 'BTC-USD', 'changes': [['buy', '38323.53', '0.00000000']], 'time': '2021-05-20T03:55:48.261490Z'}
{'type': 'l2update', 'product_id': 'BTC-USD', 'changes': [['buy', '38323.41', '0.00000000']], 'time': '2021-05-20T03:55:48.261890Z'}
{'type': 'l2update', 'product_id': 'BTC-USD', 'changes': [['buy', '38290.41', '0.00000000']], 'time': '2021-05-20T03:55:48.262227Z'}
{'type': 'l2update', 'product_id': 'BTC-USD', 'changes': [['sell', '38481.88', '0.80000000']], 'time': '2021-05-20T03:55:48.265844Z'}
{'type': 'l2update', 'product_id': 'BTC-USD', 'changes': [['sell', '38362.17', '0.00000000']], 'time': '2021-05-20T03:55:48.268343Z'}
{'type': 'l2update', 'product_id': 'BTC-USD', 'changes': [['buy', '38320.22', '0.40135082']], 'time': '2021-05-20T03:55:48.268834Z'}
{'type': 'l2update', 'product_id': 'BTC-USD', 'changes': [['sell', '38416.19', '0.34453232']], 'time': '2021-05-20T03:55:48.268996Z'}
{'type': 'l2update', 'product_id': 'BTC-USD', 'changes': [['buy', '38329.34', '0.05924270']], 'time': '2021-05-20T03:55:48.269773Z'}
{'type': 'l2update', 'product_id': 'BTC-USD', 'changes': [['buy', '38323.58', '0.90100000']], 'time': '2021-05-20T03:55:48.274501Z'}
{'type': 'l2update', 'product_id': 'BTC-USD', 'changes': [['sell', '38338.33', '0.00000000']], 'time': '2021-05-20T03:55:48.275025Z'}
{'type': 'l2update', 'product_id': 'BTC-USD', 'changes': [['buy', '38321.94', '0.00000000']], 'time': '2021-05-20T03:55:48.276482Z'}
{'type': 'l2update', 'product_id': 'BTC-USD', 'changes': [['buy', '38233.64', '0.01142934']], 'time': '2021-05-20T03:55:48.278903Z'}
{'type': 'l2update', 'product_id': 'BTC-USD', 'changes': [['buy', '38298.21', '0.00000000']], 'time': '2021-05-20T03:55:48.278941Z'}
{'type': 'l2update', 'product_id': 'BTC-USD', 'changes': [['sell', '38340.54', '0.00000000']], 'time': '2021-05-20T03:55:48.278941Z'}
{'type': 'l2update', 'product_id': 'BTC-USD', 'changes': [['sell', '38367.26', '0.00000000']], 'time': '2021-05-20T03:55:48.279033Z'}
{'type': 'l2update', 'product_id': 'BTC-USD', 'changes': [['buy', '38315.49', '0.00000000']], 'time': '2021-05-20T03:55:48.280314Z'}
{'type': 'l2update', 'product_id': 'BTC-USD', 'changes': [['buy', '38322.93', '0.07213613']], 'time': '2021-05-20T03:55:48.282783Z'}
{'type': 'l2update', 'product_id': 'BTC-USD', 'changes': [['buy', '38313.52', '0.00000000']], 'time': '2021-05-20T03:55:48.292423Z'}
{'type': 'l2update', 'product_id': 'BTC-USD', 'changes': [['sell', '38413.46', '0.04922953']], 'time': '2021-05-20T03:55:48.294267Z'}
{'type': 'l2update', 'product_id': 'BTC-USD', 'changes': [['sell', '38407.49', '0.01000000']], 'time': '2021-05-20T03:55:48.294308Z'}
{'type': 'l2update', 'product_id': 'BTC-USD', 'changes': [['buy', '38295.03', '0.78287651']], 'time': '2021-05-20T03:55:48.294810Z'}
{'type': 'l2update', 'product_id': 'BTC-USD', 'changes': [['buy', '38296.23', '0.00000000']], 'time': '2021-05-20T03:55:48.299688Z'}
{'type': 'l2update', 'product_id': 'BTC-USD', 'changes': [['sell', '38425.44', '0.00000000']], 'time': '2021-05-20T03:55:48.299785Z'}
{'type': 'l2update', 'product_id': 'BTC-USD', 'changes': [['buy', '38275.22', '0.53500000']], 'time': '2021-05-20T03:55:48.300685Z'}
{'type': 'l2update', 'product_id': 'BTC-USD', 'changes': [['sell', '38337.74', '0.00000000']], 'time': '2021-05-20T03:55:48.305364Z'}
{'type': 'l2update', 'product_id': 'BTC-USD', 'changes': [['sell', '38361.61', '0.05000000']], 'time': '2021-05-20T03:55:48.311988Z'}
{'type': 'l2update', 'product_id': 'BTC-USD', 'changes': [['buy', '38320.18', '0.00176497']], 'time': '2021-05-20T03:55:48.312236Z'}
{'type': 'l2update', 'product_id': 'BTC-USD', 'changes': [['sell', '38422.28', '0.29521271']], 'time': '2021-05-20T03:55:48.312267Z'}
{'type': 'l2update', 'product_id': 'BTC-USD', 'changes': [['buy', '38276.90', '0.32000000']], 'time': '2021-05-20T03:55:48.312422Z'}
{'type': 'l2update', 'product_id': 'BTC-USD', 'changes': [['sell', '38386.58', '0.00000000']], 'time': '2021-05-20T03:55:48.314151Z'}
{'type': 'l2update', 'product_id': 'BTC-USD', 'changes': [['buy', '38330.03', '0.01492000']], 'time': '2021-05-20T03:55:48.323274Z'}
{'type': 'l2update', 'product_id': 'BTC-USD', 'changes': [['buy', '38322.93', '0.00000000']], 'time': '2021-05-20T03:55:48.325053Z'}
{'type': 'l2update', 'product_id': 'BTC-USD', 'changes': [['sell', '38375.23', '0.01000000']], 'time': '2021-05-20T03:55:48.328947Z'}
{'type': 'l2update', 'product_id': 'BTC-USD', 'changes': [['buy', '38311.03', '0.09209765']], 'time': '2021-05-20T03:55:48.329562Z'}
{'type': 'l2update', 'product_id': 'BTC-USD', 'changes': [['sell', '38374.34', '0.01000000']], 'time': '2021-05-20T03:55:48.329720Z'}
{'type': 'l2update', 'product_id': 'BTC-USD', 'changes': [['buy', '38231.37', '0.03628277']], 'time': '2021-05-20T03:55:48.329789Z'}
{'type': 'l2update', 'product_id': 'BTC-USD', 'changes': [['buy', '38260.72', '0.03322977']], 'time': '2021-05-20T03:55:48.329789Z'}
{'type': 'l2update', 'product_id': 'BTC-USD', 'changes': [['buy', '38266.02', '0.02921656']], 'time': '2021-05-20T03:55:48.329789Z'}
{'type': 'l2update', 'product_id': 'BTC-USD', 'changes': [['buy', '38271.14', '0.03675829']], 'time': '2021-05-20T03:55:48.329789Z'}
{'type': 'l2update', 'product_id': 'BTC-USD', 'changes': [['buy', '38280.81', '0.03316030']], 'time': '2021-05-20T03:55:48.329789Z'}
{'type': 'l2update', 'product_id': 'BTC-USD', 'changes': [['buy', '38289.72', '0.03754172']], 'time': '2021-05-20T03:55:48.329789Z'}
{'type': 'l2update', 'product_id': 'BTC-USD', 'changes': [['buy', '38293.89', '0.01462349']], 'time': '2021-05-20T03:55:48.329789Z'}
{'type': 'l2update', 'product_id': 'BTC-USD', 'changes': [['sell', '38401.41', '0.00000000']], 'time': '2021-05-20T03:55:48.331083Z'}
{'type': 'l2update', 'product_id': 'BTC-USD', 'changes': [['buy', '38232.95', '0.00000000']], 'time': '2021-05-20T03:55:48.332155Z'}
{'type': 'l2update', 'product_id': 'BTC-USD', 'changes': [['sell', '38382.14', '0.00000000']], 'time': '2021-05-20T03:55:48.336762Z'}
{'type': 'l2update', 'product_id': 'BTC-USD', 'changes': [['sell', '38361.61', '2.53969908']], 'time': '2021-05-20T03:55:48.343981Z'}
{'type': 'l2update', 'product_id': 'BTC-USD', 'changes': [['buy', '38284.74', '1.30487735']], 'time': '2021-05-20T03:55:48.344230Z'}
{'type': 'l2update', 'product_id': 'BTC-USD', 'changes': [['sell', '38373.00', '0.00000000']], 'time': '2021-05-20T03:55:48.344822Z'}
{'type': 'l2update', 'product_id': 'BTC-USD', 'changes': [['sell', '38462.68', '0.00000000']], 'time': '2021-05-20T03:55:48.345894Z'}
{'type': 'l2update', 'product_id': 'BTC-USD', 'changes': [['buy', '38342.91', '0.02890000']], 'time': '2021-05-20T03:55:48.351961Z'}
{'type': 'l2update', 'product_id': 'BTC-USD', 'changes': [['sell', '38434.95', '0.00000000']], 'time': '2021-05-20T03:55:48.352677Z'}
{'type': 'l2update', 'product_id': 'BTC-USD', 'changes': [['buy', '38329.34', '0.00000000']], 'time': '2021-05-20T03:55:48.353001Z'}
{'type': 'l2update', 'product_id': 'BTC-USD', 'changes': [['sell', '38362.33', '0.02000000']], 'time': '2021-05-20T03:55:48.357997Z'}
{'type': 'l2update', 'product_id': 'BTC-USD', 'changes': [['sell', '38376.72', '0.00000000']], 'time': '2021-05-20T03:55:48.361766Z'}
{'type': 'l2update', 'product_id': 'BTC-USD', 'changes': [['buy', '38230.87', '0.00000000']], 'time': '2021-05-20T03:55:48.361766Z'}
{'type': 'l2update', 'product_id': 'BTC-USD', 'changes': [['buy', '38236.55', '0.36017473']], 'time': '2021-05-20T03:55:48.361766Z'}
{'type': 'l2update', 'product_id': 'BTC-USD', 'changes': [['buy', '38247.34', '0.00000000']], 'time': '2021-05-20T03:55:48.361766Z'}
{'type': 'l2update', 'product_id': 'BTC-USD', 'changes': [['buy', '38252.45', '0.00000000']], 'time': '2021-05-20T03:55:48.361766Z'}
{'type': 'l2update', 'product_id': 'BTC-USD', 'changes': [['buy', '38262.11', '0.16919620']], 'time': '2021-05-20T03:55:48.361766Z'}
{'type': 'l2update', 'product_id': 'BTC-USD', 'changes': [['buy', '38279.17', '0.00000000']], 'time': '2021-05-20T03:55:48.361766Z'}
{'type': 'l2update', 'product_id': 'BTC-USD', 'changes': [['buy', '38330.51', '0.01535730']], 'time': '2021-05-20T03:55:48.365336Z'}
{'type': 'l2update', 'product_id': 'BTC-USD', 'changes': [['sell', '38375.23', '0.03000000']], 'time': '2021-05-20T03:55:48.378721Z'}
{'type': 'l2update', 'product_id': 'BTC-USD', 'changes': [['buy', '38291.93', '0.01000000']], 'time': '2021-05-20T03:55:48.378743Z'}
{'type': 'l2update', 'product_id': 'BTC-USD', 'changes': [['buy', '38328.67', '0.07213613']], 'time': '2021-05-20T03:55:48.384406Z'}
{'type': 'l2update', 'product_id': 'BTC-USD', 'changes': [['sell', '38393.10', '0.50000000']], 'time': '2021-05-20T03:55:48.384546Z'}
{'type': 'l2update', 'product_id': 'BTC-USD', 'changes': [['buy', '38275.47', '2.60983881']], 'time': '2021-05-20T03:55:48.385003Z'}
{'type': 'l2update', 'product_id': 'BTC-USD', 'changes': [['sell', '38379.68', '0.46820000']], 'time': '2021-05-20T03:55:48.385617Z'}
{'type': 'l2update', 'product_id': 'BTC-USD', 'changes': [['sell', '38429.55', '0.41330877']], 'time': '2021-05-20T03:55:48.385644Z'}
{'type': 'l2update', 'product_id': 'BTC-USD', 'changes': [['sell', '38506.20', '0.00000000']], 'time': '2021-05-20T03:55:48.387690Z'}
{'type': 'l2update', 'product_id': 'BTC-USD', 'changes': [['buy', '38330.03', '0.00000000']], 'time': '2021-05-20T03:55:48.387893Z'}
{'type': 'l2update', 'product_id': 'BTC-USD', 'changes': [['sell', '38361.61', '2.48969908']], 'time': '2021-05-20T03:55:48.388047Z'}
{'type': 'l2update', 'product_id': 'BTC-USD', 'changes': [['buy', '38319.62', '0.00000000']], 'time': '2021-05-20T03:55:48.388219Z'}
{'type': 'l2update', 'product_id': 'BTC-USD', 'changes': [['buy', '36500.00', '23.28482195']], 'time': '2021-05-20T03:55:48.389007Z'}
{'type': 'l2update', 'product_id': 'BTC-USD', 'changes': [['sell', '38362.18', '0.00000000']], 'time': '2021-05-20T03:55:48.389934Z'}
{'type': 'l2update', 'product_id': 'BTC-USD', 'changes': [['sell', '38407.28', '0.00000000']], 'time': '2021-05-20T03:55:48.389958Z'}
{'type': 'l2update', 'product_id': 'BTC-USD', 'changes': [['sell', '38492.51', '0.01133319']], 'time': '2021-05-20T03:55:48.391702Z'}
{'type': 'l2update', 'product_id': 'BTC-USD', 'changes': [['sell', '38396.82', '0.05080165']], 'time': '2021-05-20T03:55:48.391788Z'}
{'type': 'l2update', 'product_id': 'BTC-USD', 'changes': [['sell', '38446.57', '0.01402927']], 'time': '2021-05-20T03:55:48.392216Z'}
{'type': 'l2update', 'product_id': 'BTC-USD', 'changes': [['sell', '38382.61', '0.00000000']], 'time': '2021-05-20T03:55:48.393371Z'}
{'type': 'l2update', 'product_id': 'BTC-USD', 'changes': [['sell', '38407.56', '0.03832102']], 'time': '2021-05-20T03:55:48.393749Z'}
{'type': 'l2update', 'product_id': 'BTC-USD', 'changes': [['buy', '38330.51', '0.00000000']], 'time': '2021-05-20T03:55:48.397937Z'}
{'type': 'l2update', 'product_id': 'BTC-USD', 'changes': [['buy', '38301.81', '0.02000000']], 'time': '2021-05-20T03:55:48.402699Z'}
{'type': 'l2update', 'product_id': 'BTC-USD', 'changes': [['sell', '38342.92', '0.21000000']], 'time': '2021-05-20T03:55:48.410144Z'}
{'type': 'l2update', 'product_id': 'BTC-USD', 'changes': [['buy', '38315.86', '0.00000000']], 'time': '2021-05-20T03:55:48.411137Z'}
{'type': 'l2update', 'product_id': 'BTC-USD', 'changes': [['sell', '38379.80', '0.00000000']], 'time': '2021-05-20T03:55:48.411444Z'}
{'type': 'l2update', 'product_id': 'BTC-USD', 'changes': [['sell', '38379.68', '0.00000000']], 'time': '2021-05-20T03:55:48.414382Z'}
{'type': 'l2update', 'product_id': 'BTC-USD', 'changes': [['buy', '38328.67', '0.17213613']], 'time': '2021-05-20T03:55:48.414951Z'}
{'type': 'l2update', 'product_id': 'BTC-USD', 'changes': [['sell', '38371.82', '0.03000000']], 'time': '2021-05-20T03:55:48.416127Z'}
{'type': 'l2update', 'product_id': 'BTC-USD', 'changes': [['buy', '38330.08', '1.07800000']], 'time': '2021-05-20T03:55:48.416329Z'}
{'type': 'l2update', 'product_id': 'BTC-USD', 'changes': [['sell', '38448.01', '0.00000000']], 'time': '2021-05-20T03:55:48.416377Z'}
{'type': 'l2update', 'product_id': 'BTC-USD', 'changes': [['buy', '38275.46', '2.60983881']], 'time': '2021-05-20T03:55:48.418321Z'}
{'type': 'l2update', 'product_id': 'BTC-USD', 'changes': [['buy', '38262.12', '0.04282797']], 'time': '2021-05-20T03:55:48.418352Z'}
{'type': 'l2update', 'product_id': 'BTC-USD', 'changes': [['buy', '38328.67', '0.10000000']], 'time': '2021-05-20T03:55:48.419915Z'}
{'type': 'l2update', 'product_id': 'BTC-USD', 'changes': [['buy', '38320.22', '0.00000000']], 'time': '2021-05-20T03:55:48.424076Z'}
{'type': 'l2update', 'product_id': 'BTC-USD', 'changes': [['sell', '38436.02', '0.31939407']], 'time': '2021-05-20T03:55:48.425947Z'}
{'type': 'l2update', 'product_id': 'BTC-USD', 'changes': [['sell', '38361.60', '0.18981474']], 'time': '2021-05-20T03:55:48.427211Z'}
{'type': 'l2update', 'product_id': 'BTC-USD', 'changes': [['buy', '38301.76', '0.00000000']], 'time': '2021-05-20T03:55:48.430268Z'}
{'type': 'l2update', 'product_id': 'BTC-USD', 'changes': [['sell', '38372.77', '0.05000000']], 'time': '2021-05-20T03:55:48.430524Z'}
{'type': 'l2update', 'product_id': 'BTC-USD', 'changes': [['sell', '38491.73', '0.01000000']], 'time': '2021-05-20T03:55:48.431111Z'}
{'type': 'l2update', 'product_id': 'BTC-USD', 'changes': [['sell', '38493.91', '0.00000000']], 'time': '2021-05-20T03:55:48.431533Z'}
{'type': 'l2update', 'product_id': 'BTC-USD', 'changes': [['buy', '38329.35', '0.07213613']], 'time': '2021-05-20T03:55:48.450394Z'}
{'type': 'l2update', 'product_id': 'BTC-USD', 'changes': [['sell', '38342.92', '0.31000000']], 'time': '2021-05-20T03:55:48.451416Z'}
{'type': 'l2update', 'product_id': 'BTC-USD', 'changes': [['buy', '38305.26', '0.01385106']], 'time': '2021-05-20T03:55:48.453164Z'}
{'type': 'l2update', 'product_id': 'BTC-USD', 'changes': [['sell', '38372.77', '0.53208164']], 'time': '2021-05-20T03:55:48.459691Z'}
{'type': 'l2update', 'product_id': 'BTC-USD', 'changes': [['buy', '38265.19', '2.61053955']], 'time': '2021-05-20T03:55:48.459917Z'}
{'type': 'l2update', 'product_id': 'BTC-USD', 'changes': [['buy', '38314.65', '0.43420000']], 'time': '2021-05-20T03:55:48.460230Z'}
{'type': 'l2update', 'product_id': 'BTC-USD', 'changes': [['sell', '38362.18', '0.64136451']], 'time': '2021-05-20T03:55:48.460329Z'}
{'type': 'l2update', 'product_id': 'BTC-USD', 'changes': [['sell', '38371.82', '0.07000000']], 'time': '2021-05-20T03:55:48.460555Z'}
{'type': 'l2update', 'product_id': 'BTC-USD', 'changes': [['sell', '38355.77', '0.05108944']], 'time': '2021-05-20T03:55:48.461655Z'}
{'type': 'l2update', 'product_id': 'BTC-USD', 'changes': [['sell', '38454.34', '0.00000000']], 'time': '2021-05-20T03:55:48.462480Z'}
{'type': 'l2update', 'product_id': 'BTC-USD', 'changes': [['buy', '38323.58', '0.00000000']], 'time': '2021-05-20T03:55:48.463226Z'}
{'type': 'l2update', 'product_id': 'BTC-USD', 'changes': [['sell', '38374.34', '0.00000000']], 'time': '2021-05-20T03:55:48.463250Z'}
{'type': 'l2update', 'product_id': 'BTC-USD', 'changes': [['buy', '38330.08', '0.00000000']], 'time': '2021-05-20T03:55:48.463343Z'}
{'type': 'l2update', 'product_id': 'BTC-USD', 'changes': [['sell', '38449.53', '0.36700714']], 'time': '2021-05-20T03:55:48.466942Z'}
{'type': 'l2update', 'product_id': 'BTC-USD', 'changes': [['buy', '38236.57', '0.35700538']], 'time': '2021-05-20T03:55:48.466942Z'}
{'type': 'l2update', 'product_id': 'BTC-USD', 'changes': [['buy', '38158.93', '0.00000000']], 'time': '2021-05-20T03:55:48.467264Z'}
{'type': 'l2update', 'product_id': 'BTC-USD', 'changes': [['buy', '38233.64', '0.00000000']], 'time': '2021-05-20T03:55:48.469242Z'}
{'type': 'l2update', 'product_id': 'BTC-USD', 'changes': [['buy', '38342.91', '0.10103613']], 'time': '2021-05-20T03:55:48.473979Z'}
{'type': 'l2update', 'product_id': 'BTC-USD', 'changes': [['sell', '38421.51', '0.00000000']], 'time': '2021-05-20T03:55:48.474788Z'}
{'type': 'l2update', 'product_id': 'BTC-USD', 'changes': [['buy', '38342.91', '0.25103613']], 'time': '2021-05-20T03:55:48.479867Z'}
{'type': 'l2update', 'product_id': 'BTC-USD', 'changes': [['sell', '38401.42', '0.02717448']], 'time': '2021-05-20T03:55:48.485363Z'}
{'type': 'l2update', 'product_id': 'BTC-USD', 'changes': [['buy', '38293.19', '0.00000000']], 'time': '2021-05-20T03:55:48.485363Z'}
{'type': 'l2update', 'product_id': 'BTC-USD', 'changes': [['buy', '38314.65', '0.00000000']], 'time': '2021-05-20T03:55:48.490785Z'}
{'type': 'l2update', 'product_id': 'BTC-USD', 'changes': [['buy', '38295.20', '0.69822997']], 'time': '2021-05-20T03:55:48.492675Z'}
{'type': 'l2update', 'product_id': 'BTC-USD', 'changes': [['buy', '38291.93', '0.00000000']], 'time': '2021-05-20T03:55:48.493656Z'}
{'type': 'l2update', 'product_id': 'BTC-USD', 'changes': [['buy', '38199.65', '0.32035765']], 'time': '2021-05-20T03:55:48.497223Z'}
{'type': 'l2update', 'product_id': 'BTC-USD', 'changes': [['sell', '38371.82', '0.12000000']], 'time': '2021-05-20T03:55:48.498381Z'}
{'type': 'l2update', 'product_id': 'BTC-USD', 'changes': [['sell', '38492.51', '0.00000000']], 'time': '2021-05-20T03:55:48.500043Z'}
{'type': 'l2update', 'product_id': 'BTC-USD', 'changes': [['sell', '38477.84', '0.01000000']], 'time': '2021-05-20T03:55:48.504596Z'}
{'type': 'l2update', 'product_id': 'BTC-USD', 'changes': [['sell', '38407.49', '0.00000000']], 'time': '2021-05-20T03:55:48.504635Z'}
{'type': 'l2update', 'product_id': 'BTC-USD', 'changes': [['buy', '38247.66', '0.01130248']], 'time': '2021-05-20T03:55:48.510917Z'}
{'type': 'l2update', 'product_id': 'BTC-USD', 'changes': [['buy', '38195.76', '0.04801783']], 'time': '2021-05-20T03:55:48.511021Z'}
{'type': 'l2update', 'product_id': 'BTC-USD', 'changes': [['sell', '38541.10', '0.01000000']], 'time': '2021-05-20T03:55:48.511273Z'}
{'type': 'l2update', 'product_id': 'BTC-USD', 'changes': [['sell', '38361.63', '0.00000000']], 'time': '2021-05-20T03:55:48.512084Z'}
{'type': 'l2update', 'product_id': 'BTC-USD', 'changes': [['buy', '38329.35', '0.00000000']], 'time': '2021-05-20T03:55:48.512603Z'}
{'type': 'l2update', 'product_id': 'BTC-USD', 'changes': [['sell', '38439.61', '0.01239980']], 'time': '2021-05-20T03:55:48.515814Z'}
{'type': 'l2update', 'product_id': 'BTC-USD', 'changes': [['sell', '38612.28', '3.22893377']], 'time': '2021-05-20T03:55:48.516271Z'}
{'type': 'l2update', 'product_id': 'BTC-USD', 'changes': [['buy', '38303.72', '0.00000000']], 'time': '2021-05-20T03:55:48.520849Z'}
{'type': 'l2update', 'product_id': 'BTC-USD', 'changes': [['sell', '38478.36', '0.03289689']], 'time': '2021-05-20T03:55:48.524231Z'}
{'type': 'l2update', 'product_id': 'BTC-USD', 'changes': [['buy', '38306.83', '0.01462349']], 'time': '2021-05-20T03:55:48.524231Z'}
{'type': 'l2update', 'product_id': 'BTC-USD', 'changes': [['buy', '38316.65', '0.06091802']], 'time': '2021-05-20T03:55:48.524943Z'}
{'type': 'l2update', 'product_id': 'BTC-USD', 'changes': [['sell', '38359.32', '0.06398268']], 'time': '2021-05-20T03:55:48.524943Z'}
{'type': 'l2update', 'product_id': 'BTC-USD', 'changes': [['buy', '38342.91', '0.17890000']], 'time': '2021-05-20T03:55:48.526349Z'}
{'type': 'l2update', 'product_id': 'BTC-USD', 'changes': [['buy', '38303.78', '0.00000000']], 'time': '2021-05-20T03:55:48.528885Z'}
{'type': 'l2update', 'product_id': 'BTC-USD', 'changes': [['sell', '38445.45', '0.00000000']], 'time': '2021-05-20T03:55:48.529234Z'}
{'type': 'l2update', 'product_id': 'BTC-USD', 'changes': [['buy', '38330.09', '0.40135082']], 'time': '2021-05-20T03:55:48.530507Z'}
{'type': 'l2update', 'product_id': 'BTC-USD', 'changes': [['sell', '38385.63', '0.40250000']], 'time': '2021-05-20T03:55:48.539616Z'}
{'type': 'l2update', 'product_id': 'BTC-USD', 'changes': [['sell', '38456.57', '0.39632559']], 'time': '2021-05-20T03:55:48.541419Z'}
{'type': 'l2update', 'product_id': 'BTC-USD', 'changes': [['buy', '38275.71', '0.12000000']], 'time': '2021-05-20T03:55:48.545534Z'}
{'type': 'l2update', 'product_id': 'BTC-USD', 'changes': [['buy', '38304.90', '2.37600000']], 'time': '2021-05-20T03:55:48.551207Z'}
{'type': 'l2update', 'product_id': 'BTC-USD', 'changes': [['sell', '38460.76', '0.01000000']], 'time': '2021-05-20T03:55:48.551565Z'}
{'type': 'l2update', 'product_id': 'BTC-USD', 'changes': [['sell', '38447.64', '0.01000000']], 'time': '2021-05-20T03:55:48.552260Z'}
{'type': 'l2update', 'product_id': 'BTC-USD', 'changes': [['buy', '38329.40', '0.52100000']], 'time': '2021-05-20T03:55:48.552353Z'}
{'type': 'l2update', 'product_id': 'BTC-USD', 'changes': [['buy', '38320.18', '0.00000000']], 'time': '2021-05-20T03:55:48.557532Z'}
{'type': 'l2update', 'product_id': 'BTC-USD', 'changes': [['sell', '38346.76', '0.00000000']], 'time': '2021-05-20T03:55:48.558909Z'}
{'type': 'l2update', 'product_id': 'BTC-USD', 'changes': [['sell', '38407.56', '0.00000000']], 'time': '2021-05-20T03:55:48.559107Z'}
{'type': 'l2update', 'product_id': 'BTC-USD', 'changes': [['buy', '38293.89', '0.00000000']], 'time': '2021-05-20T03:55:48.559107Z'}
{'type': 'l2update', 'product_id': 'BTC-USD', 'changes': [['buy', '38285.49', '0.00000000']], 'time': '2021-05-20T03:55:48.559950Z'}
{'type': 'l2update', 'product_id': 'BTC-USD', 'changes': [['sell', '38495.57', '0.00000000']], 'time': '2021-05-20T03:55:48.562921Z'}
{'type': 'l2update', 'product_id': 'BTC-USD', 'changes': [['buy', '38307.70', '0.00000000']], 'time': '2021-05-20T03:55:48.563600Z'}
{'type': 'l2update', 'product_id': 'BTC-USD', 'changes': [['buy', '38328.68', '0.99315797']], 'time': '2021-05-20T03:55:48.568709Z'}
{'type': 'l2update', 'product_id': 'BTC-USD', 'changes': [['sell', '38377.36', '0.00000000']], 'time': '2021-05-20T03:55:48.571704Z'}
{'type': 'l2update', 'product_id': 'BTC-USD', 'changes': [['buy', '38320.21', '0.00000000']], 'time': '2021-05-20T03:55:48.572016Z'}
{'type': 'l2update', 'product_id': 'BTC-USD', 'changes': [['sell', '38361.62', '0.00000000']], 'time': '2021-05-20T03:55:48.572545Z'}
{'type': 'l2update', 'product_id': 'BTC-USD', 'changes': [['sell', '38385.63', '0.00000000']], 'time': '2021-05-20T03:55:48.573809Z'}
{'type': 'l2update', 'product_id': 'BTC-USD', 'changes': [['sell', '38453.39', '0.01000000']], 'time': '2021-05-20T03:55:48.575970Z'}
{'type': 'l2update', 'product_id': 'BTC-USD', 'changes': [['buy', '38311.05', '0.13000000']], 'time': '2021-05-20T03:55:48.576870Z'}
{'type': 'l2update', 'product_id': 'BTC-USD', 'changes': [['buy', '38275.71', '0.09000000']], 'time': '2021-05-20T03:55:48.579016Z'}
{'type': 'l2update', 'product_id': 'BTC-USD', 'changes': [['buy', '38330.09', '0.50135082']], 'time': '2021-05-20T03:55:48.581714Z'}
{'type': 'l2update', 'product_id': 'BTC-USD', 'changes': [['sell', '38469.56', '0.37953878']], 'time': '2021-05-20T03:55:48.585835Z'}
{'type': 'l2update', 'product_id': 'BTC-USD', 'changes': [['sell', '38460.76', '0.00000000']], 'time': '2021-05-20T03:55:48.590121Z'}
{'type': 'l2update', 'product_id': 'BTC-USD', 'changes': [['sell', '38439.61', '0.00000000']], 'time': '2021-05-20T03:55:48.592473Z'}
{'type': 'l2update', 'product_id': 'BTC-USD', 'changes': [['buy', '38314.03', '0.39490431']], 'time': '2021-05-20T03:55:48.598902Z'}
{'type': 'l2update', 'product_id': 'BTC-USD', 'changes': [['sell', '38439.94', '0.02400000']], 'time': '2021-05-20T03:55:48.599671Z'}
{'type': 'l2update', 'product_id': 'BTC-USD', 'changes': [['buy', '38295.03', '0.00000000']], 'time': '2021-05-20T03:55:48.599779Z'}
{'type': 'l2update', 'product_id': 'BTC-USD', 'changes': [['buy', '38303.48', '0.10000000']], 'time': '2021-05-20T03:55:48.604077Z'}
{'type': 'l2update', 'product_id': 'BTC-USD', 'changes': [['buy', '38328.68', '0.00000000']], 'time': '2021-05-20T03:55:48.609318Z'}
{'type': 'l2update', 'product_id': 'BTC-USD', 'changes': [['buy', '38275.71', '0.05000000']], 'time': '2021-05-20T03:55:48.610214Z'}
{'type': 'l2update', 'product_id': 'BTC-USD', 'changes': [['sell', '38453.83', '0.02817074']], 'time': '2021-05-20T03:55:48.612209Z'}
{'type': 'l2update', 'product_id': 'BTC-USD', 'changes': [['buy', '38314.79', '0.45320000']], 'time': '2021-05-20T03:55:48.617557Z'}
{'type': 'l2update', 'product_id': 'BTC-USD', 'changes': [['sell', '38355.76', '0.50000000']], 'time': '2021-05-20T03:55:48.620274Z'}
{'type': 'l2update', 'product_id': 'BTC-USD', 'changes': [['sell', '38371.01', '0.00000000']], 'time': '2021-05-20T03:55:48.623784Z'}
{'type': 'l2update', 'product_id': 'BTC-USD', 'changes': [['buy', '38279.18', '0.00000000']], 'time': '2021-05-20T03:55:48.624718Z'}
{'type': 'l2update', 'product_id': 'BTC-USD', 'changes': [['sell', '38476.99', '0.35805884']], 'time': '2021-05-20T03:55:48.629100Z'}
{'type': 'l2update', 'product_id': 'BTC-USD', 'changes': [['sell', '38405.72', '0.05455313']], 'time': '2021-05-20T03:55:48.629221Z'}
{'type': 'l2update', 'product_id': 'BTC-USD', 'changes': [['sell', '38464.92', '0.00000000']], 'time': '2021-05-20T03:55:48.629876Z'}
{'type': 'l2update', 'product_id': 'BTC-USD', 'changes': [['buy', '38319.01', '0.05900000']], 'time': '2021-05-20T03:55:48.630791Z'}
{'type': 'l2update', 'product_id': 'BTC-USD', 'changes': [['buy', '38284.74', '0.00000000']], 'time': '2021-05-20T03:55:48.631775Z'}
{'type': 'l2update', 'product_id': 'BTC-USD', 'changes': [['buy', '38304.90', '0.00000000']], 'time': '2021-05-20T03:55:48.631912Z'}
{'type': 'l2update', 'product_id': 'BTC-USD', 'changes': [['sell', '38458.72', '0.01000000']], 'time': '2021-05-20T03:55:48.636758Z'}
{'type': 'l2update', 'product_id': 'BTC-USD', 'changes': [['sell', '38488.55', '0.01299087']], 'time': '2021-05-20T03:55:48.637120Z'}
{'type': 'l2update', 'product_id': 'BTC-USD', 'changes': [['buy', '38228.69', '0.00000000']], 'time': '2021-05-20T03:55:48.638617Z'}
{'type': 'l2update', 'product_id': 'BTC-USD', 'changes': [['buy', '38275.71', '0.00000000']], 'time': '2021-05-20T03:55:48.639111Z'}
{'type': 'l2update', 'product_id': 'BTC-USD', 'changes': [['buy', '38321.93', '0.00176497']], 'time': '2021-05-20T03:55:48.641866Z'}
{'type': 'l2update', 'product_id': 'BTC-USD', 'changes': [['buy', '38320.22', '0.99315797']], 'time': '2021-05-20T03:55:48.653479Z'}
{'type': 'l2update', 'product_id': 'BTC-USD', 'changes': [['sell', '38478.36', '0.00000000']], 'time': '2021-05-20T03:55:48.655730Z'}
{'type': 'l2update', 'product_id': 'BTC-USD', 'changes': [['sell', '38459.89', '0.02609492']], 'time': '2021-05-20T03:55:48.655730Z'}
{'type': 'l2update', 'product_id': 'BTC-USD', 'changes': [['sell', '38459.89', '0.00000000']], 'time': '2021-05-20T03:55:48.655730Z'}
{'type': 'l2update', 'product_id': 'BTC-USD', 'changes': [['sell', '38453.83', '0.00000000']], 'time': '2021-05-20T03:55:48.655730Z'}
{'type': 'l2update', 'product_id': 'BTC-USD', 'changes': [['sell', '38429.88', '0.00000000']], 'time': '2021-05-20T03:55:48.655730Z'}
{'type': 'l2update', 'product_id': 'BTC-USD', 'changes': [['sell', '38423.16', '0.00000000']], 'time': '2021-05-20T03:55:48.655730Z'}
{'type': 'l2update', 'product_id': 'BTC-USD', 'changes': [['buy', '38299.43', '0.00000000']], 'time': '2021-05-20T03:55:48.658818Z'}
{'type': 'l2update', 'product_id': 'BTC-USD', 'changes': [['sell', '38439.94', '0.00000000']], 'time': '2021-05-20T03:55:48.659161Z'}
{'type': 'l2update', 'product_id': 'BTC-USD', 'changes': [['sell', '38394.01', '0.00000000']], 'time': '2021-05-20T03:55:48.660176Z'}
{'type': 'l2update', 'product_id': 'BTC-USD', 'changes': [['sell', '38484.61', '0.37294795']], 'time': '2021-05-20T03:55:48.662493Z'}
{'type': 'l2update', 'product_id': 'BTC-USD', 'changes': [['buy', '38299.87', '0.00000000']], 'time': '2021-05-20T03:55:48.671411Z'}
{'type': 'l2update', 'product_id': 'BTC-USD', 'changes': [['buy', '38298.39', '0.00000000']], 'time': '2021-05-20T03:55:48.671411Z'}
{'type': 'l2update', 'product_id': 'BTC-USD', 'changes': [['buy', '38297.58', '0.00000000']], 'time': '2021-05-20T03:55:48.671411Z'}
{'type': 'l2update', 'product_id': 'BTC-USD', 'changes': [['buy', '38330.09', '0.10000000']], 'time': '2021-05-20T03:55:48.673041Z'}
{'type': 'l2update', 'product_id': 'BTC-USD', 'changes': [['sell', '38492.40', '0.03499199']], 'time': '2021-05-20T03:55:48.673381Z'}
{'type': 'l2update', 'product_id': 'BTC-USD', 'changes': [['sell', '38476.47', '0.01000000']], 'time': '2021-05-20T03:55:48.673966Z'}
{'type': 'l2update', 'product_id': 'BTC-USD', 'changes': [['buy', '38243.00', '0.01000000']], 'time': '2021-05-20T03:55:48.674058Z'}
{'type': 'l2update', 'product_id': 'BTC-USD', 'changes': [['sell', '38342.92', '0.30852108']], 'time': '2021-05-20T03:55:48.678254Z'}
{'type': 'l2update', 'product_id': 'BTC-USD', 'changes': [['sell', '38372.78', '0.00000000']], 'time': '2021-05-20T03:55:48.694540Z'}
{'type': 'l2update', 'product_id': 'BTC-USD', 'changes': [['sell', '38384.25', '0.42340000']], 'time': '2021-05-20T03:55:48.695103Z'}
{'type': 'l2update', 'product_id': 'BTC-USD', 'changes': [['buy', '38315.11', '0.02400000']], 'time': '2021-05-20T03:55:48.710353Z'}
{'type': 'l2update', 'product_id': 'BTC-USD', 'changes': [['buy', '38314.31', '0.02400000']], 'time': '2021-05-20T03:55:48.710353Z'}
{'type': 'l2update', 'product_id': 'BTC-USD', 'changes': [['buy', '38313.50', '0.02400000']], 'time': '2021-05-20T03:55:48.710353Z'}
{'type': 'l2update', 'product_id': 'BTC-USD', 'changes': [['buy', '38328.66', '0.04982169']], 'time': '2021-05-20T03:55:48.716170Z'}
{'type': 'l2update', 'product_id': 'BTC-USD', 'changes': [['buy', '38328.72', '0.84700000']], 'time': '2021-05-20T03:55:48.716241Z'}
{'type': 'l2update', 'product_id': 'BTC-USD', 'changes': [['buy', '38275.46', '0.00000000']], 'time': '2021-05-20T03:55:48.721046Z'}
{'type': 'l2update', 'product_id': 'BTC-USD', 'changes': [['sell', '38518.73', '0.30077791']], 'time': '2021-05-20T03:55:48.722986Z'}
{'type': 'l2update', 'product_id': 'BTC-USD', 'changes': [['buy', '38262.12', '0.00000000']], 'time': '2021-05-20T03:55:48.726204Z'}
{'type': 'l2update', 'product_id': 'BTC-USD', 'changes': [['sell', '38372.77', '0.48208164']], 'time': '2021-05-20T03:55:48.726904Z'}
{'type': 'l2update', 'product_id': 'BTC-USD', 'changes': [['sell', '38443.29', '0.03796869']], 'time': '2021-05-20T03:55:48.729300Z'}
{'type': 'l2update', 'product_id': 'BTC-USD', 'changes': [['sell', '38425.59', '0.03573040']], 'time': '2021-05-20T03:55:48.729300Z'}
{'type': 'l2update', 'product_id': 'BTC-USD', 'changes': [['buy', '38223.48', '0.03796869']], 'time': '2021-05-20T03:55:48.729300Z'}
{'type': 'l2update', 'product_id': 'BTC-USD', 'changes': [['buy', '38187.00', '0.00000000']], 'time': '2021-05-20T03:55:48.731384Z'}
{'type': 'l2update', 'product_id': 'BTC-USD', 'changes': [['sell', '38355.76', '0.00000000']], 'time': '2021-05-20T03:55:48.733588Z'}
{'type': 'l2update', 'product_id': 'BTC-USD', 'changes': [['buy', '38218.32', '0.43292669']], 'time': '2021-05-20T03:55:48.736757Z'}
{'type': 'l2update', 'product_id': 'BTC-USD', 'changes': [['buy', '38225.00', '0.68891867']], 'time': '2021-05-20T03:55:48.736757Z'}
{'type': 'l2update', 'product_id': 'BTC-USD', 'changes': [['buy', '38262.11', '0.52937093']], 'time': '2021-05-20T03:55:48.736757Z'}
{'type': 'l2update', 'product_id': 'BTC-USD', 'changes': [['sell', '38382.17', '0.01363826']], 'time': '2021-05-20T03:55:48.736940Z'}
{'type': 'l2update', 'product_id': 'BTC-USD', 'changes': [['buy', '38315.11', '0.00000000']], 'time': '2021-05-20T03:55:48.742158Z'}
{'type': 'l2update', 'product_id': 'BTC-USD', 'changes': [['buy', '38314.31', '0.00000000']], 'time': '2021-05-20T03:55:48.742158Z'}
{'type': 'l2update', 'product_id': 'BTC-USD', 'changes': [['buy', '38313.50', '0.00000000']], 'time': '2021-05-20T03:55:48.742158Z'}
{'type': 'l2update', 'product_id': 'BTC-USD', 'changes': [['buy', '38265.19', '0.00000000']], 'time': '2021-05-20T03:55:48.748420Z'}
{'type': 'l2update', 'product_id': 'BTC-USD', 'changes': [['sell', '38467.32', '0.00000000']], 'time': '2021-05-20T03:55:48.756885Z'}
{'type': 'l2update', 'product_id': 'BTC-USD', 'changes': [['buy', '38111.21', '1.00900000']], 'time': '2021-05-20T03:55:48.759125Z'}
{'type': 'l2update', 'product_id': 'BTC-USD', 'changes': [['sell', '38377.71', '0.05000000']], 'time': '2021-05-20T03:55:48.765783Z'}
{'type': 'l2update', 'product_id': 'BTC-USD', 'changes': [['sell', '38377.72', '0.00000000']], 'time': '2021-05-20T03:55:48.766425Z'}
{'type': 'l2update', 'product_id': 'BTC-USD', 'changes': [['buy', '38177.91', '0.00000000']], 'time': '2021-05-20T03:55:48.766425Z'}
{'type': 'l2update', 'product_id': 'BTC-USD', 'changes': [['buy', '38185.60', '0.00000000']], 'time': '2021-05-20T03:55:48.766425Z'}
{'type': 'l2update', 'product_id': 'BTC-USD', 'changes': [['buy', '38236.55', '0.00000000']], 'time': '2021-05-20T03:55:48.766425Z'}
{'type': 'l2update', 'product_id': 'BTC-USD', 'changes': [['sell', '38359.31', '0.50000000']], 'time': '2021-05-20T03:55:48.772755Z'}
{'type': 'l2update', 'product_id': 'BTC-USD', 'changes': [['buy', '38328.67', '0.00000000']], 'time': '2021-05-20T03:55:48.784444Z'}
{'type': 'l2update', 'product_id': 'BTC-USD', 'changes': [['sell', '38420.07', '0.03570261']], 'time': '2021-05-20T03:55:48.788936Z'}
{'type': 'l2update', 'product_id': 'BTC-USD', 'changes': [['buy', '38329.41', '0.40135082']], 'time': '2021-05-20T03:55:48.789169Z'}
{'type': 'l2update', 'product_id': 'BTC-USD', 'changes': [['buy', '38275.22', '0.00000000']], 'time': '2021-05-20T03:55:48.789632Z'}
{'type': 'l2update', 'product_id': 'BTC-USD', 'changes': [['sell', '38377.71', '0.00000000']], 'time': '2021-05-20T03:55:48.790488Z'}
{'type': 'l2update', 'product_id': 'BTC-USD', 'changes': [['sell', '38391.00', '0.36593177']], 'time': '2021-05-20T03:55:48.799716Z'}
{'type': 'l2update', 'product_id': 'BTC-USD', 'changes': [['sell', '38359.27', '1.15300000']], 'time': '2021-05-20T03:55:48.805024Z'}
{'type': 'l2update', 'product_id': 'BTC-USD', 'changes': [['sell', '38342.92', '0.30000000']], 'time': '2021-05-20T03:55:48.806537Z'}
{'type': 'l2update', 'product_id': 'BTC-USD', 'changes': [['sell', '38342.92', '0.29705286']], 'time': '2021-05-20T03:55:48.806537Z'}
{'type': 'l2update', 'product_id': 'BTC-USD', 'changes': [['sell', '38491.73', '0.00000000']], 'time': '2021-05-20T03:55:48.815953Z'}
{'type': 'l2update', 'product_id': 'BTC-USD', 'changes': [['sell', '38425.59', '0.06974344']], 'time': '2021-05-20T03:55:48.820589Z'}
{'type': 'l2update', 'product_id': 'BTC-USD', 'changes': [['buy', '38211.71', '0.50300000']], 'time': '2021-05-20T03:55:48.820876Z'}
{'type': 'l2update', 'product_id': 'BTC-USD', 'changes': [['sell', '38372.76', '0.05000000']], 'time': '2021-05-20T03:55:48.824215Z'}
{'type': 'l2update', 'product_id': 'BTC-USD', 'changes': [['sell', '38409.95', '0.00000000']], 'time': '2021-05-20T03:55:48.825428Z'}
{'type': 'l2update', 'product_id': 'BTC-USD', 'changes': [['buy', '38327.30', '0.02400000']], 'time': '2021-05-20T03:55:48.827480Z'}
{'type': 'l2update', 'product_id': 'BTC-USD', 'changes': [['buy', '38326.50', '0.02400000']], 'time': '2021-05-20T03:55:48.827480Z'}
{'type': 'l2update', 'product_id': 'BTC-USD', 'changes': [['buy', '38325.69', '0.02400000']], 'time': '2021-05-20T03:55:48.827480Z'}
{'type': 'l2update', 'product_id': 'BTC-USD', 'changes': [['sell', '38361.60', '0.00000000']], 'time': '2021-05-20T03:55:48.831442Z'}
{'type': 'l2update', 'product_id': 'BTC-USD', 'changes': [['buy', '38282.93', '0.02000000']], 'time': '2021-05-20T03:55:48.838498Z'}
{'type': 'l2update', 'product_id': 'BTC-USD', 'changes': [['buy', '38293.76', '0.02975895']], 'time': '2021-05-20T03:55:48.846303Z'}
{'type': 'l2update', 'product_id': 'BTC-USD', 'changes': [['buy', '38327.30', '0.00000000']], 'time': '2021-05-20T03:55:48.852821Z'}
{'type': 'l2update', 'product_id': 'BTC-USD', 'changes': [['sell', '38421.93', '0.00000000']], 'time': '2021-05-20T03:55:48.853892Z'}
{'type': 'l2update', 'product_id': 'BTC-USD', 'changes': [['sell', '38416.19', '0.00000000']], 'time': '2021-05-20T03:55:48.853892Z'}
{'type': 'l2update', 'product_id': 'BTC-USD', 'changes': [['sell', '38431.30', '0.03600288']], 'time': '2021-05-20T03:55:48.854529Z'}
{'type': 'l2update', 'product_id': 'BTC-USD', 'changes': [['buy', '38297.91', '1.20000000']], 'time': '2021-05-20T03:55:48.855566Z'}
{'type': 'l2update', 'product_id': 'BTC-USD', 'changes': [['buy', '38295.21', '0.66188429']], 'time': '2021-05-20T03:55:48.855591Z'}
{'type': 'l2update', 'product_id': 'BTC-USD', 'changes': [['sell', '38542.86', '0.01000000']], 'time': '2021-05-20T03:55:48.855739Z'}
{'type': 'l2update', 'product_id': 'BTC-USD', 'changes': [['sell', '38492.40', '0.00000000']], 'time': '2021-05-20T03:55:48.858756Z'}
{'type': 'l2update', 'product_id': 'BTC-USD', 'changes': [['sell', '38384.25', '0.00000000']], 'time': '2021-05-20T03:55:48.864195Z'}
{'type': 'l2update', 'product_id': 'BTC-USD', 'changes': [['buy', '38342.91', '0.18342786']], 'time': '2021-05-20T03:55:48.868831Z'}
{'type': 'l2update', 'product_id': 'BTC-USD', 'changes': [['buy', '38219.84', '0.00000000']], 'time': '2021-05-20T03:55:48.868917Z'}
{'type': 'l2update', 'product_id': 'BTC-USD', 'changes': [['buy', '38326.50', '0.00000000']], 'time': '2021-05-20T03:55:48.871675Z'}
{'type': 'l2update', 'product_id': 'BTC-USD', 'changes': [['buy', '38325.69', '0.00000000']], 'time': '2021-05-20T03:55:48.871675Z'}
{'type': 'l2update', 'product_id': 'BTC-USD', 'changes': [['sell', '38591.82', '0.00000000']], 'time': '2021-05-20T03:55:48.873528Z'}
{'type': 'l2update', 'product_id': 'BTC-USD', 'changes': [['buy', '38282.12', '0.03000000']], 'time': '2021-05-20T03:55:48.874350Z'}
{'type': 'l2update', 'product_id': 'BTC-USD', 'changes': [['buy', '38098.25', '0.01000000']], 'time': '2021-05-20T03:55:48.881385Z'}
{'type': 'l2update', 'product_id': 'BTC-USD', 'changes': [['sell', '38361.61', '0.00000000']], 'time': '2021-05-20T03:55:48.881682Z'}
{'type': 'l2update', 'product_id': 'BTC-USD', 'changes': [['sell', '38474.81', '0.01000000']], 'time': '2021-05-20T03:55:48.889269Z'}
{'type': 'l2update', 'product_id': 'BTC-USD', 'changes': [['buy', '38195.76', '0.00000000']], 'time': '2021-05-20T03:55:48.889425Z'}
{'type': 'l2update', 'product_id': 'BTC-USD', 'changes': [['buy', '38292.37', '0.60600000']], 'time': '2021-05-20T03:55:48.889978Z'}
{'type': 'l2update', 'product_id': 'BTC-USD', 'changes': [['sell', '38432.97', '1.20000000']], 'time': '2021-05-20T03:55:48.890007Z'}
{'type': 'l2update', 'product_id': 'BTC-USD', 'changes': [['buy', '38329.40', '0.00000000']], 'time': '2021-05-20T03:55:48.896220Z'}
{'type': 'l2update', 'product_id': 'BTC-USD', 'changes': [['buy', '38188.23', '0.00000000']], 'time': '2021-05-20T03:55:48.896236Z'}
{'type': 'l2update', 'product_id': 'BTC-USD', 'changes': [['sell', '38606.88', '0.01295106']], 'time': '2021-05-20T03:55:48.899240Z'}
{'type': 'l2update', 'product_id': 'BTC-USD', 'changes': [['buy', '38282.12', '0.07000000']], 'time': '2021-05-20T03:55:48.899344Z'}
{'type': 'l2update', 'product_id': 'BTC-USD', 'changes': [['buy', '38237.38', '0.01134690']], 'time': '2021-05-20T03:55:48.899663Z'}
{'type': 'l2update', 'product_id': 'BTC-USD', 'changes': [['sell', '38476.60', '0.43100837']], 'time': '2021-05-20T03:55:48.900445Z'}
{'type': 'l2update', 'product_id': 'BTC-USD', 'changes': [['sell', '38399.93', '0.29521271']], 'time': '2021-05-20T03:55:48.900445Z'}
{'type': 'l2update', 'product_id': 'BTC-USD', 'changes': [['sell', '38437.20', '0.03114054']], 'time': '2021-05-20T03:55:48.900757Z'}
{'type': 'l2update', 'product_id': 'BTC-USD', 'changes': [['sell', '38359.26', '0.18981474']], 'time': '2021-05-20T03:55:48.909295Z'}
{'type': 'l2update', 'product_id': 'BTC-USD', 'changes': [['sell', '38347.72', '0.01303858']], 'time': '2021-05-20T03:55:48.913805Z'}
{'type': 'l2update', 'product_id': 'BTC-USD', 'changes': [['sell', '38382.70', '0.46140000']], 'time': '2021-05-20T03:55:48.913889Z'}
{'type': 'l2update', 'product_id': 'BTC-USD', 'changes': [['buy', '38128.21', '0.00000000']], 'time': '2021-05-20T03:55:48.918302Z'}
{'type': 'l2update', 'product_id': 'BTC-USD', 'changes': [['buy', '38228.19', '0.50000000']], 'time': '2021-05-20T03:55:48.921924Z'}
{'type': 'l2update', 'product_id': 'BTC-USD', 'changes': [['sell', '38355.76', '2.48969908']], 'time': '2021-05-20T03:55:48.923397Z'}
{'type': 'l2update', 'product_id': 'BTC-USD', 'changes': [['buy', '38206.73', '0.01000000']], 'time': '2021-05-20T03:55:48.923789Z'}
{'type': 'l2update', 'product_id': 'BTC-USD', 'changes': [['sell', '38422.28', '0.00000000']], 'time': '2021-05-20T03:55:48.924112Z'}
{'type': 'l2update', 'product_id': 'BTC-USD', 'changes': [['buy', '38328.72', '0.00000000']], 'time': '2021-05-20T03:55:48.924696Z'}
{'type': 'l2update', 'product_id': 'BTC-USD', 'changes': [['buy', '38329.41', '0.00000000']], 'time': '2021-05-20T03:55:48.927578Z'}
{'type': 'l2update', 'product_id': 'BTC-USD', 'changes': [['buy', '38282.12', '0.12000000']], 'time': '2021-05-20T03:55:48.931138Z'}
{'type': 'l2update', 'product_id': 'BTC-USD', 'changes': [['buy', '38303.72', '0.02975895']], 'time': '2021-05-20T03:55:48.932700Z'}
{'type': 'l2update', 'product_id': 'BTC-USD', 'changes': [['sell', '38467.28', '0.00000000']], 'time': '2021-05-20T03:55:48.933160Z'}
{'type': 'l2update', 'product_id': 'BTC-USD', 'changes': [['sell', '38349.00', '0.55300000']], 'time': '2021-05-20T03:55:48.938922Z'}
{'type': 'l2update', 'product_id': 'BTC-USD', 'changes': [['sell', '38460.75', '0.00000000']], 'time': '2021-05-20T03:55:48.941887Z'}
{'type': 'l2update', 'product_id': 'BTC-USD', 'changes': [['buy', '38320.19', '0.00000000']], 'time': '2021-05-20T03:55:48.942045Z'}
{'type': 'l2update', 'product_id': 'BTC-USD', 'changes': [['sell', '38542.86', '0.00000000']], 'time': '2021-05-20T03:55:48.947040Z'}
{'type': 'l2update', 'product_id': 'BTC-USD', 'changes': [['sell', '38618.90', '0.00000000']], 'time': '2021-05-20T03:55:48.948297Z'}
{'type': 'l2update', 'product_id': 'BTC-USD', 'changes': [['buy', '38342.91', '0.15452786']], 'time': '2021-05-20T03:55:48.950936Z'}
{'type': 'l2update', 'product_id': 'BTC-USD', 'changes': [['buy', '38323.58', '0.02400000']], 'time': '2021-05-20T03:55:48.953206Z'}
{'type': 'l2update', 'product_id': 'BTC-USD', 'changes': [['buy', '38322.78', '0.02400000']], 'time': '2021-05-20T03:55:48.953206Z'}
{'type': 'l2update', 'product_id': 'BTC-USD', 'changes': [['buy', '38321.97', '0.02400000']], 'time': '2021-05-20T03:55:48.953206Z'}
{'type': 'l2update', 'product_id': 'BTC-USD', 'changes': [['sell', '38447.64', '0.00000000']], 'time': '2021-05-20T03:55:48.955629Z'}
{'type': 'l2update', 'product_id': 'BTC-USD', 'changes': [['sell', '38477.84', '0.00000000']], 'time': '2021-05-20T03:55:48.956205Z'}
{'type': 'l2update', 'product_id': 'BTC-USD', 'changes': [['sell', '38443.29', '0.07666056']], 'time': '2021-05-20T03:55:48.958013Z'}
{'type': 'l2update', 'product_id': 'BTC-USD', 'changes': [['sell', '38394.96', '0.07098902']], 'time': '2021-05-20T03:55:48.958013Z'}
{'type': 'l2update', 'product_id': 'BTC-USD', 'changes': [['buy', '38220.00', '0.19720000']], 'time': '2021-05-20T03:55:48.958149Z'}
{'type': 'l2update', 'product_id': 'BTC-USD', 'changes': [['sell', '38476.60', '0.74852677']], 'time': '2021-05-20T03:55:48.962274Z'}
{'type': 'l2update', 'product_id': 'BTC-USD', 'changes': [['sell', '38398.74', '0.77449928']], 'time': '2021-05-20T03:55:48.962274Z'}
{'type': 'l2update', 'product_id': 'BTC-USD', 'changes': [['buy', '38141.59', '0.01000000']], 'time': '2021-05-20T03:55:48.969243Z'}
{'type': 'l2update', 'product_id': 'BTC-USD', 'changes': [['buy', '38316.65', '0.00000000']], 'time': '2021-05-20T03:55:48.969648Z'}
{'type': 'l2update', 'product_id': 'BTC-USD', 'changes': [['sell', '38359.32', '0.00000000']], 'time': '2021-05-20T03:55:48.969648Z'}
{'type': 'l2update', 'product_id': 'BTC-USD', 'changes': [['buy', '38338.82', '0.10000000']], 'time': '2021-05-20T03:55:48.969667Z'}
{'type': 'l2update', 'product_id': 'BTC-USD', 'changes': [['buy', '38311.06', '0.02610212']], 'time': '2021-05-20T03:55:48.969771Z'}
{'type': 'l2update', 'product_id': 'BTC-USD', 'changes': [['sell', '38480.51', '0.01000000']], 'time': '2021-05-20T03:55:48.969847Z'}
{'type': 'l2update', 'product_id': 'BTC-USD', 'changes': [['buy', '38323.58', '0.00000000']], 'time': '2021-05-20T03:55:48.972476Z'}
{'type': 'l2update', 'product_id': 'BTC-USD', 'changes': [['buy', '38322.78', '0.00000000']], 'time': '2021-05-20T03:55:48.972476Z'}
{'type': 'l2update', 'product_id': 'BTC-USD', 'changes': [['sell', '38359.26', '0.00000000']], 'time': '2021-05-20T03:55:48.973064Z'}
{'type': 'l2update', 'product_id': 'BTC-USD', 'changes': [['buy', '38283.25', '0.00000000']], 'time': '2021-05-20T03:55:48.975331Z'}
{'type': 'l2update', 'product_id': 'BTC-USD', 'changes': [['buy', '38320.23', '0.40135082']], 'time': '2021-05-20T03:55:48.977972Z'}
{'type': 'l2update', 'product_id': 'BTC-USD', 'changes': [['sell', '38420.07', '0.00000000']], 'time': '2021-05-20T03:55:48.978017Z'}
{'type': 'l2update', 'product_id': 'BTC-USD', 'changes': [['buy', '38342.91', '0.14632786']], 'time': '2021-05-20T03:55:48.978124Z'}
{'type': 'l2update', 'product_id': 'BTC-USD', 'changes': [['sell', '38428.21', '0.00000000']], 'time': '2021-05-20T03:55:48.980500Z'}
{'type': 'l2update', 'product_id': 'BTC-USD', 'changes': [['sell', '38474.06', '0.02938800']], 'time': '2021-05-20T03:55:48.981505Z'}
{'type': 'l2update', 'product_id': 'BTC-USD', 'changes': [['sell', '38492.02', '0.01000000']], 'time': '2021-05-20T03:55:48.982933Z'}
{'type': 'l2update', 'product_id': 'BTC-USD', 'changes': [['buy', '38323.03', '0.26000000']], 'time': '2021-05-20T03:55:48.983006Z'}
{'type': 'l2update', 'product_id': 'BTC-USD', 'changes': [['sell', '38488.55', '0.00000000']], 'time': '2021-05-20T03:55:48.984463Z'}
{'type': 'l2update', 'product_id': 'BTC-USD', 'changes': [['sell', '38465.62', '0.01000000']], 'time': '2021-05-20T03:55:48.990262Z'}
{'type': 'l2update', 'product_id': 'BTC-USD', 'changes': [['buy', '38321.93', '0.00000000']], 'time': '2021-05-20T03:55:48.990750Z'}
{'type': 'l2update', 'product_id': 'BTC-USD', 'changes': [['buy', '38282.93', '0.00000000']], 'time': '2021-05-20T03:55:48.992130Z'}
{'type': 'l2update', 'product_id': 'BTC-USD', 'changes': [['buy', '38321.97', '0.00000000']], 'time': '2021-05-20T03:55:48.992323Z'}
{'type': 'l2update', 'product_id': 'BTC-USD', 'changes': [['sell', '38416.18', '0.02603070']], 'time': '2021-05-20T03:55:48.994714Z'}
{'type': 'l2update', 'product_id': 'BTC-USD', 'changes': [['sell', '38359.31', '0.55351056']], 'time': '2021-05-20T03:55:49.000751Z'}
{'type': 'l2update', 'product_id': 'BTC-USD', 'changes': [['buy', '38320.22', '0.00000000']], 'time': '2021-05-20T03:55:49.002775Z'}
{'type': 'l2update', 'product_id': 'BTC-USD', 'changes': [['buy', '38338.82', '0.00000000']], 'time': '2021-05-20T03:55:49.003293Z'}
{'type': 'l2update', 'product_id': 'BTC-USD', 'changes': [['sell', '38355.75', '0.18981474']], 'time': '2021-05-20T03:55:49.011543Z'}
{'type': 'l2update', 'product_id': 'BTC-USD', 'changes': [['buy', '38282.12', '0.09000000']], 'time': '2021-05-20T03:55:49.012946Z'}
{'type': 'l2update', 'product_id': 'BTC-USD', 'changes': [['sell', '38476.10', '0.01299508']], 'time': '2021-05-20T03:55:49.016938Z'}
{'type': 'l2update', 'product_id': 'BTC-USD', 'changes': [['sell', '38462.70', '0.03419343']], 'time': '2021-05-20T03:55:49.016971Z'}
{'type': 'l2update', 'product_id': 'BTC-USD', 'changes': [['sell', '38382.17', '0.00000000']], 'time': '2021-05-20T03:55:49.021582Z'}
{'type': 'l2update', 'product_id': 'BTC-USD', 'changes': [['buy', '38293.76', '0.00000000']], 'time': '2021-05-20T03:55:49.024619Z'}
{'type': 'l2update', 'product_id': 'BTC-USD', 'changes': [['buy', '38260.34', '0.00000000']], 'time': '2021-05-20T03:55:49.025400Z'}
{'type': 'l2update', 'product_id': 'BTC-USD', 'changes': [['buy', '38098.25', '0.00000000']], 'time': '2021-05-20T03:55:49.030295Z'}
{'type': 'l2update', 'product_id': 'BTC-USD', 'changes': [['sell', '38382.70', '0.00000000']], 'time': '2021-05-20T03:55:49.030894Z'}
{'type': 'l2update', 'product_id': 'BTC-USD', 'changes': [['buy', '38282.12', '0.05000000']], 'time': '2021-05-20T03:55:49.034453Z'}
{'type': 'l2update', 'product_id': 'BTC-USD', 'changes': [['buy', '38256.53', '0.00000000']], 'time': '2021-05-20T03:55:49.037646Z'}
{'type': 'l2update', 'product_id': 'BTC-USD', 'changes': [['sell', '38469.56', '0.00000000']], 'time': '2021-05-20T03:55:49.037725Z'}
{'type': 'l2update', 'product_id': 'BTC-USD', 'changes': [['sell', '38456.57', '0.00000000']], 'time': '2021-05-20T03:55:49.037725Z'}
{'type': 'l2update', 'product_id': 'BTC-USD', 'changes': [['sell', '38449.53', '0.00000000']], 'time': '2021-05-20T03:55:49.037725Z'}
{'type': 'l2update', 'product_id': 'BTC-USD', 'changes': [['sell', '38436.02', '0.00000000']], 'time': '2021-05-20T03:55:49.037725Z'}
{'type': 'l2update', 'product_id': 'BTC-USD', 'changes': [['sell', '38429.55', '0.00000000']], 'time': '2021-05-20T03:55:49.037725Z'}
{'type': 'l2update', 'product_id': 'BTC-USD', 'changes': [['buy', '38342.91', '0.13722701']], 'time': '2021-05-20T03:55:49.043387Z'}
{'type': 'l2update', 'product_id': 'BTC-USD', 'changes': [['sell', '38453.39', '0.00000000']], 'time': '2021-05-20T03:55:49.043660Z'}
{'type': 'l2update', 'product_id': 'BTC-USD', 'changes': [['buy', '38321.98', '0.99315797']], 'time': '2021-05-20T03:55:49.047119Z'}
{'type': 'l2update', 'product_id': 'BTC-USD', 'changes': [['sell', '38469.55', '0.03650518']], 'time': '2021-05-20T03:55:49.047187Z'}
{'type': 'l2update', 'product_id': 'BTC-USD', 'changes': [['sell', '38541.10', '0.00000000']], 'time': '2021-05-20T03:55:49.047637Z'}
{'type': 'l2update', 'product_id': 'BTC-USD', 'changes': [['buy', '38206.73', '0.00000000']], 'time': '2021-05-20T03:55:49.048089Z'}
{'type': 'l2update', 'product_id': 'BTC-USD', 'changes': [['sell', '38375.23', '0.02000000']], 'time': '2021-05-20T03:55:49.053161Z'}
{'type': 'l2update', 'product_id': 'BTC-USD', 'changes': [['sell', '38359.31', '0.05351056']], 'time': '2021-05-20T03:55:49.054004Z'}
{'type': 'l2update', 'product_id': 'BTC-USD', 'changes': [['buy', '38320.23', '0.00000000']], 'time': '2021-05-20T03:55:49.055978Z'}
{'type': 'l2update', 'product_id': 'BTC-USD', 'changes': [['sell', '38380.67', '0.44870000']], 'time': '2021-05-20T03:55:49.057748Z'}
{'type': 'l2update', 'product_id': 'BTC-USD', 'changes': [['buy', '38319.02', '0.04270000']], 'time': '2021-05-20T03:55:49.058538Z'}
{'type': 'l2update', 'product_id': 'BTC-USD', 'changes': [['buy', '38318.21', '0.02400000']], 'time': '2021-05-20T03:55:49.058538Z'}
{'type': 'l2update', 'product_id': 'BTC-USD', 'changes': [['buy', '38317.40', '0.02400000']], 'time': '2021-05-20T03:55:49.058538Z'}
{'type': 'l2update', 'product_id': 'BTC-USD', 'changes': [['sell', '38730.00', '0.19720000']], 'time': '2021-05-20T03:55:49.065618Z'}
{'type': 'l2update', 'product_id': 'BTC-USD', 'changes': [['sell', '38492.02', '0.00000000']], 'time': '2021-05-20T03:55:49.071279Z'}
{'type': 'l2update', 'product_id': 'BTC-USD', 'changes': [['buy', '38307.75', '0.05806175']], 'time': '2021-05-20T03:55:49.071659Z'}
{'type': 'l2update', 'product_id': 'BTC-USD', 'changes': [['sell', '38353.83', '0.04723477']], 'time': '2021-05-20T03:55:49.071659Z'}
{'type': 'l2update', 'product_id': 'BTC-USD', 'changes': [['sell', '38375.23', '0.00000000']], 'time': '2021-05-20T03:55:49.072375Z'}
{'type': 'l2update', 'product_id': 'BTC-USD', 'changes': [['sell', '38380.67', '0.00000000']], 'time': '2021-05-20T03:55:49.073829Z'}
{'type': 'l2update', 'product_id': 'BTC-USD', 'changes': [['sell', '38404.68', '0.03401304']], 'time': '2021-05-20T03:55:49.077878Z'}
{'type': 'l2update', 'product_id': 'BTC-USD', 'changes': [['buy', '38110.11', '0.01000000']], 'time': '2021-05-20T03:55:49.077917Z'}
{'type': 'l2update', 'product_id': 'BTC-USD', 'changes': [['sell', '38465.20', '0.01299876']], 'time': '2021-05-20T03:55:49.078048Z'}
{'type': 'l2update', 'product_id': 'BTC-USD', 'changes': [['sell', '38476.47', '0.00000000']], 'time': '2021-05-20T03:55:49.078520Z'}
{'type': 'l2update', 'product_id': 'BTC-USD', 'changes': [['buy', '38320.28', '0.52000000']], 'time': '2021-05-20T03:55:49.079316Z'}
{'type': 'l2update', 'product_id': 'BTC-USD', 'changes': [['buy', '38220.02', '0.01000000']], 'time': '2021-05-20T03:55:49.079561Z'}
{'type': 'l2update', 'product_id': 'BTC-USD', 'changes': [['buy', '38319.02', '0.01870000']], 'time': '2021-05-20T03:55:49.080613Z'}
{'type': 'l2update', 'product_id': 'BTC-USD', 'changes': [['sell', '38347.71', '0.50000000']], 'time': '2021-05-20T03:55:49.084194Z'}
{'type': 'l2update', 'product_id': 'BTC-USD', 'changes': [['sell', '38371.82', '0.09000000']], 'time': '2021-05-20T03:55:49.091886Z'}
{'type': 'l2update', 'product_id': 'BTC-USD', 'changes': [['buy', '38314.79', '0.00000000']], 'time': '2021-05-20T03:55:49.092211Z'}
{'type': 'l2update', 'product_id': 'BTC-USD', 'changes': [['sell', '38425.59', '0.03573040']], 'time': '2021-05-20T03:55:49.094872Z'}
{'type': 'l2update', 'product_id': 'BTC-USD', 'changes': [['sell', '38342.92', '0.29800369']], 'time': '2021-05-20T03:55:49.095718Z'}
{'type': 'l2update', 'product_id': 'BTC-USD', 'changes': [['sell', '38342.92', '0.94800369']], 'time': '2021-05-20T03:55:49.096402Z'}
{'type': 'l2update', 'product_id': 'BTC-USD', 'changes': [['buy', '38303.72', '0.00000000']], 'time': '2021-05-20T03:55:49.097356Z'}
{'type': 'l2update', 'product_id': 'BTC-USD', 'changes': [['sell', '38431.30', '0.44771134']], 'time': '2021-05-20T03:55:49.100483Z'}
{'type': 'l2update', 'product_id': 'BTC-USD', 'changes': [['sell', '38425.59', '0.40867835']], 'time': '2021-05-20T03:55:49.100483Z'}
{'type': 'l2update', 'product_id': 'BTC-USD', 'changes': [['sell', '38414.75', '0.35805884']], 'time': '2021-05-20T03:55:49.100483Z'}
{'type': 'l2update', 'product_id': 'BTC-USD', 'changes': [['sell', '38404.68', '0.46502141']], 'time': '2021-05-20T03:55:49.100483Z'}
{'type': 'l2update', 'product_id': 'BTC-USD', 'changes': [['sell', '38395.37', '0.31751840']], 'time': '2021-05-20T03:55:49.100483Z'}
{'type': 'l2update', 'product_id': 'BTC-USD', 'changes': [['sell', '38560.23', '0.01000000']], 'time': '2021-05-20T03:55:49.100810Z'}
{'type': 'l2update', 'product_id': 'BTC-USD', 'changes': [['buy', '38323.04', '0.40135082']], 'time': '2021-05-20T03:55:49.101328Z'}
{'type': 'l2update', 'product_id': 'BTC-USD', 'changes': [['sell', '38540.98', '0.01000000']], 'time': '2021-05-20T03:55:49.101767Z'}
{'type': 'l2update', 'product_id': 'BTC-USD', 'changes': [['sell', '38449.85', '0.00000000']], 'time': '2021-05-20T03:55:49.101946Z'}
{'type': 'l2update', 'product_id': 'BTC-USD', 'changes': [['sell', '38371.82', '0.05000000']], 'time': '2021-05-20T03:55:49.106722Z'}
{'type': 'l2update', 'product_id': 'BTC-USD', 'changes': [['buy', '38295.21', '0.68799722']], 'time': '2021-05-20T03:55:49.108463Z'}
{'type': 'l2update', 'product_id': 'BTC-USD', 'changes': [['sell', '38511.74', '0.01000000']], 'time': '2021-05-20T03:55:49.108630Z'}
{'type': 'l2update', 'product_id': 'BTC-USD', 'changes': [['sell', '38484.61', '0.00000000']], 'time': '2021-05-20T03:55:49.119772Z'}
{'type': 'l2update', 'product_id': 'BTC-USD', 'changes': [['sell', '38476.99', '0.00000000']], 'time': '2021-05-20T03:55:49.119772Z'}
{'type': 'l2update', 'product_id': 'BTC-USD', 'changes': [['sell', '38476.60', '0.31751840']], 'time': '2021-05-20T03:55:49.119772Z'}
{'type': 'l2update', 'product_id': 'BTC-USD', 'changes': [['sell', '38476.60', '0.00000000']], 'time': '2021-05-20T03:55:49.119772Z'}
{'type': 'l2update', 'product_id': 'BTC-USD', 'changes': [['sell', '38355.75', '0.00000000']], 'time': '2021-05-20T03:55:49.122934Z'}
{'type': 'l2update', 'product_id': 'BTC-USD', 'changes': [['buy', '38321.98', '0.00000000']], 'time': '2021-05-20T03:55:49.123659Z'}
{'type': 'l2update', 'product_id': 'BTC-USD', 'changes': [['sell', '38371.82', '0.00000000']], 'time': '2021-05-20T03:55:49.126003Z'}
{'type': 'l2update', 'product_id': 'BTC-USD', 'changes': [['buy', '38316.60', '0.02400000']], 'time': '2021-05-20T03:55:49.135728Z'}
{'type': 'l2update', 'product_id': 'BTC-USD', 'changes': [['sell', '38429.54', '0.02602165']], 'time': '2021-05-20T03:55:49.140479Z'}
{'type': 'l2update', 'product_id': 'BTC-USD', 'changes': [['sell', '38476.60', '0.36322396']], 'time': '2021-05-20T03:55:49.146010Z'}
{'type': 'l2update', 'product_id': 'BTC-USD', 'changes': [['sell', '38511.74', '0.00000000']], 'time': '2021-05-20T03:55:49.153462Z'}
{'type': 'l2update', 'product_id': 'BTC-USD', 'changes': [['sell', '38342.92', '0.29800369']], 'time': '2021-05-20T03:55:49.154613Z'}
{'type': 'l2update', 'product_id': 'BTC-USD', 'changes': [['buy', '38301.92', '0.01000000']], 'time': '2021-05-20T03:55:49.155760Z'}
{'type': 'l2update', 'product_id': 'BTC-USD', 'changes': [['buy', '38318.21', '0.00000000']], 'time': '2021-05-20T03:55:49.156794Z'}
{'type': 'l2update', 'product_id': 'BTC-USD', 'changes': [['buy', '38317.40', '0.00000000']], 'time': '2021-05-20T03:55:49.156794Z'}
{'type': 'l2update', 'product_id': 'BTC-USD', 'changes': [['buy', '38320.29', '0.99315797']], 'time': '2021-05-20T03:55:49.162589Z'}
{'type': 'l2update', 'product_id': 'BTC-USD', 'changes': [['sell', '38467.72', '0.01026591']], 'time': '2021-05-20T03:55:49.163172Z'}
{'type': 'l2update', 'product_id': 'BTC-USD', 'changes': [['buy', '38110.11', '0.00000000']], 'time': '2021-05-20T03:55:49.163186Z'}
{'type': 'l2update', 'product_id': 'BTC-USD', 'changes': [['sell', '38446.57', '0.00000000']], 'time': '2021-05-20T03:55:49.168392Z'}
{'type': 'l2update', 'product_id': 'BTC-USD', 'changes': [['sell', '38599.99', '0.00000000']], 'time': '2021-05-20T03:55:49.169056Z'}
{'type': 'l2update', 'product_id': 'BTC-USD', 'changes': [['sell', '38342.92', '0.29909486']], 'time': '2021-05-20T03:55:49.172248Z'}
{'type': 'l2update', 'product_id': 'BTC-USD', 'changes': [['buy', '38323.04', '0.00000000']], 'time': '2021-05-20T03:55:49.174896Z'}
{'type': 'l2update', 'product_id': 'BTC-USD', 'changes': [['buy', '38162.07', '0.00000000']], 'time': '2021-05-20T03:55:49.178619Z'}
{'type': 'l2update', 'product_id': 'BTC-USD', 'changes': [['sell', '38449.57', '0.40758107']], 'time': '2021-05-20T03:55:49.180990Z'}
{'type': 'l2update', 'product_id': 'BTC-USD', 'changes': [['sell', '38347.70', '0.18981474']], 'time': '2021-05-20T03:55:49.181243Z'}
{'type': 'l2update', 'product_id': 'BTC-USD', 'changes': [['sell', '38372.08', '0.42830000']], 'time': '2021-05-20T03:55:49.187813Z'}
{'type': 'l2update', 'product_id': 'BTC-USD', 'changes': [['sell', '38498.49', '0.01951654']], 'time': '2021-05-20T03:55:49.188026Z'}
{'type': 'l2update', 'product_id': 'BTC-USD', 'changes': [['buy', '38299.23', '0.02000000']], 'time': '2021-05-20T03:55:49.188045Z'}
{'type': 'l2update', 'product_id': 'BTC-USD', 'changes': [['sell', '38476.10', '0.00000000']], 'time': '2021-05-20T03:55:49.188743Z'}
{'type': 'l2update', 'product_id': 'BTC-USD', 'changes': [['buy', '38237.38', '0.00000000']], 'time': '2021-05-20T03:55:49.190436Z'}
{'type': 'l2update', 'product_id': 'BTC-USD', 'changes': [['buy', '38314.04', '0.02975895']], 'time': '2021-05-20T03:55:49.194301Z'}
{'type': 'l2update', 'product_id': 'BTC-USD', 'changes': [['buy', '38315.62', '0.02400000']], 'time': '2021-05-20T03:55:49.194657Z'}
{'type': 'l2update', 'product_id': 'BTC-USD', 'changes': [['buy', '38314.82', '0.02400000']], 'time': '2021-05-20T03:55:49.194657Z'}
{'type': 'l2update', 'product_id': 'BTC-USD', 'changes': [['sell', '38433.59', '0.03738634']], 'time': '2021-05-20T03:55:49.199115Z'}
{'type': 'l2update', 'product_id': 'BTC-USD', 'changes': [['buy', '38177.20', '0.05034451']], 'time': '2021-05-20T03:55:49.199314Z'}
{'type': 'l2update', 'product_id': 'BTC-USD', 'changes': [['sell', '38381.14', '0.01000000']], 'time': '2021-05-20T03:55:49.199420Z'}
{'type': 'l2update', 'product_id': 'BTC-USD', 'changes': [['buy', '38305.26', '0.00000000']], 'time': '2021-05-20T03:55:49.200069Z'}
{'type': 'l2update', 'product_id': 'BTC-USD', 'changes': [['sell', '38375.25', '0.04834405']], 'time': '2021-05-20T03:55:49.203757Z'}
{'type': 'l2update', 'product_id': 'BTC-USD', 'changes': [['sell', '38652.92', '0.43270000']], 'time': '2021-05-20T03:55:49.203905Z'}
{'type': 'l2update', 'product_id': 'BTC-USD', 'changes': [['sell', '38405.72', '0.00000000']], 'time': '2021-05-20T03:55:49.204607Z'}
{'type': 'l2update', 'product_id': 'BTC-USD', 'changes': [['buy', '38323.08', '0.84700000']], 'time': '2021-05-20T03:55:49.207311Z'}
{'type': 'l2update', 'product_id': 'BTC-USD', 'changes': [['sell', '38372.76', '0.00000000']], 'time': '2021-05-20T03:55:49.211115Z'}
{'type': 'l2update', 'product_id': 'BTC-USD', 'changes': [['sell', '38606.88', '0.00000000']], 'time': '2021-05-20T03:55:49.211170Z'}
{'type': 'l2update', 'product_id': 'BTC-USD', 'changes': [['sell', '38456.04', '0.42486854']], 'time': '2021-05-20T03:55:49.211678Z'}
{'type': 'l2update', 'product_id': 'BTC-USD', 'changes': [['buy', '38315.26', '0.47800000']], 'time': '2021-05-20T03:55:49.213179Z'}
{'type': 'l2update', 'product_id': 'BTC-USD', 'changes': [['buy', '38320.30', '0.40135082']], 'time': '2021-05-20T03:55:49.213625Z'}
{'type': 'l2update', 'product_id': 'BTC-USD', 'changes': [['sell', '43100.00', '1.09530000']], 'time': '2021-05-20T03:55:49.214976Z'}
{'type': 'l2update', 'product_id': 'BTC-USD', 'changes': [['buy', '38293.51', '0.03000000']], 'time': '2021-05-20T03:55:49.217451Z'}
{'type': 'l2update', 'product_id': 'BTC-USD', 'changes': [['sell', '38448.32', '0.01167699']], 'time': '2021-05-20T03:55:49.218080Z'}
{'type': 'l2update', 'product_id': 'BTC-USD', 'changes': [['buy', '37654.92', '0.05790000']], 'time': '2021-05-20T03:55:49.224350Z'}
{'type': 'l2update', 'product_id': 'BTC-USD', 'changes': [['buy', '37500.01', '0.07080000']], 'time': '2021-05-20T03:55:49.224350Z'}
{'type': 'l2update', 'product_id': 'BTC-USD', 'changes': [['sell', '39499.98', '0.00000000']], 'time': '2021-05-20T03:55:49.224350Z'}
{'type': 'l2update', 'product_id': 'BTC-USD', 'changes': [['sell', '38540.98', '0.00000000']], 'time': '2021-05-20T03:55:49.225134Z'}
{'type': 'l2update', 'product_id': 'BTC-USD', 'changes': [['buy', '38128.23', '0.01000000']], 'time': '2021-05-20T03:55:49.227485Z'}
{'type': 'l2update', 'product_id': 'BTC-USD', 'changes': [['sell', '38634.20', '0.00000000']], 'time': '2021-05-20T03:55:49.230471Z'}
{'type': 'l2update', 'product_id': 'BTC-USD', 'changes': [['buy', '37654.92', '0.11960000']], 'time': '2021-05-20T03:55:49.232081Z'}
{'type': 'l2update', 'product_id': 'BTC-USD', 'changes': [['sell', '39499.99', '0.11490000']], 'time': '2021-05-20T03:55:49.232081Z'}
{'type': 'l2update', 'product_id': 'BTC-USD', 'changes': [['buy', '38298.70', '0.01000000']], 'time': '2021-05-20T03:55:49.232292Z'}
{'type': 'l2update', 'product_id': 'BTC-USD', 'changes': [['buy', '38307.75', '0.00000000']], 'time': '2021-05-20T03:55:49.237310Z'}
{'type': 'l2update', 'product_id': 'BTC-USD', 'changes': [['sell', '38353.83', '0.00000000']], 'time': '2021-05-20T03:55:49.237310Z'}
{'type': 'l2update', 'product_id': 'BTC-USD', 'changes': [['sell', '38372.07', '0.05000000']], 'time': '2021-05-20T03:55:49.240985Z'}
{'type': 'l2update', 'product_id': 'BTC-USD', 'changes': [['sell', '38649.94', '0.01000000']], 'time': '2021-05-20T03:55:49.241032Z'}
{'type': 'l2update', 'product_id': 'BTC-USD', 'changes': [['sell', '38469.55', '0.39068010']], 'time': '2021-05-20T03:55:49.245076Z'}
{'type': 'l2update', 'product_id': 'BTC-USD', 'changes': [['buy', '38288.72', '0.04000000']], 'time': '2021-05-20T03:55:49.249815Z'}
{'type': 'l2update', 'product_id': 'BTC-USD', 'changes': [['sell', '43100.00', '1.64230000']], 'time': '2021-05-20T03:55:49.249874Z'}
{'type': 'l2update', 'product_id': 'BTC-USD', 'changes': [['buy', '38217.78', '0.01595000']], 'time': '2021-05-20T03:55:49.257471Z'}
{'type': 'l2update', 'product_id': 'BTC-USD', 'changes': [['sell', '38526.49', '0.01000000']], 'time': '2021-05-20T03:55:49.276047Z'}
{'type': 'l2update', 'product_id': 'BTC-USD', 'changes': [['sell', '38621.11', '0.12946291']], 'time': '2021-05-20T03:55:49.276517Z'}
{'type': 'l2update', 'product_id': 'BTC-USD', 'changes': [['sell', '38412.97', '0.00000000']], 'time': '2021-05-20T03:55:49.278041Z'}
{'type': 'l2update', 'product_id': 'BTC-USD', 'changes': [['sell', '38377.50', '0.01000000']], 'time': '2021-05-20T03:55:49.282083Z'}
{'type': 'l2update', 'product_id': 'BTC-USD', 'changes': [['sell', '38476.60', '0.75296102']], 'time': '2021-05-20T03:55:49.282124Z'}
{'type': 'l2update', 'product_id': 'BTC-USD', 'changes': [['buy', '38303.48', '0.00000000']], 'time': '2021-05-20T03:55:49.289332Z'}
{'type': 'l2update', 'product_id': 'BTC-USD', 'changes': [['buy', '38323.08', '0.00000000']], 'time': '2021-05-20T03:55:49.296123Z'}
{'type': 'l2update', 'product_id': 'BTC-USD', 'changes': [['buy', '38211.71', '0.00000000']], 'time': '2021-05-20T03:55:49.300941Z'}
{'type': 'l2update', 'product_id': 'BTC-USD', 'changes': [['buy', '38168.42', '0.00000000']], 'time': '2021-05-20T03:55:49.301663Z'}
{'type': 'l2update', 'product_id': 'BTC-USD', 'changes': [['sell', '38481.84', '0.00000000']], 'time': '2021-05-20T03:55:49.303681Z'}
{'type': 'l2update', 'product_id': 'BTC-USD', 'changes': [['sell', '38461.39', '0.06368970']], 'time': '2021-05-20T03:55:49.304824Z'}
{'type': 'l2update', 'product_id': 'BTC-USD', 'changes': [['sell', '38489.48', '0.01000000']], 'time': '2021-05-20T03:55:49.312667Z'}
{'type': 'l2update', 'product_id': 'BTC-USD', 'changes': [['sell', '38377.50', '0.03000000']], 'time': '2021-05-20T03:55:49.312733Z'}
{'type': 'l2update', 'product_id': 'BTC-USD', 'changes': [['buy', '38278.50', '0.10000000']], 'time': '2021-05-20T03:55:49.319427Z'}
{'type': 'l2update', 'product_id': 'BTC-USD', 'changes': [['sell', '38498.12', '0.01000000']], 'time': '2021-05-20T03:55:49.329915Z'}
{'type': 'l2update', 'product_id': 'BTC-USD', 'changes': [['sell', '38342.92', '0.30141057']], 'time': '2021-05-20T03:55:49.330719Z'}
{'type': 'l2update', 'product_id': 'BTC-USD', 'changes': [['sell', '38376.35', '0.03000000']], 'time': '2021-05-20T03:55:49.337083Z'}
{'type': 'l2update', 'product_id': 'BTC-USD', 'changes': [['buy', '38314.04', '0.00000000']], 'time': '2021-05-20T03:55:49.338944Z'}
{'type': 'l2update', 'product_id': 'BTC-USD', 'changes': [['buy', '38307.74', '0.03932119']], 'time': '2021-05-20T03:55:49.339217Z'}
{'type': 'l2update', 'product_id': 'BTC-USD', 'changes': [['sell', '38349.16', '0.05311268']], 'time': '2021-05-20T03:55:49.339217Z'}
{'type': 'l2update', 'product_id': 'BTC-USD', 'changes': [['buy', '38295.21', '0.02611293']], 'time': '2021-05-20T03:55:49.346462Z'}
{'type': 'l2update', 'product_id': 'BTC-USD', 'changes': [['buy', '38319.02', '0.04845895']], 'time': '2021-05-20T03:55:49.354128Z'}
{'type': 'l2update', 'product_id': 'BTC-USD', 'changes': [['sell', '38376.35', '0.07000000']], 'time': '2021-05-20T03:55:49.365233Z'}
{'type': 'l2update', 'product_id': 'BTC-USD', 'changes': [['sell', '38355.76', '0.00000000']], 'time': '2021-05-20T03:55:49.365898Z'}
{'type': 'l2update', 'product_id': 'BTC-USD', 'changes': [['sell', '38558.40', '0.00000000']], 'time': '2021-05-20T03:55:49.381577Z'}
{'type': 'l2update', 'product_id': 'BTC-USD', 'changes': [['sell', '38376.35', '0.12000000']], 'time': '2021-05-20T03:55:49.391386Z'}
{'type': 'l2update', 'product_id': 'BTC-USD', 'changes': [['sell', '38498.69', '0.00000000']], 'time': '2021-05-20T03:55:49.391733Z'}
{'type': 'l2update', 'product_id': 'BTC-USD', 'changes': [['sell', '38347.71', '0.00000000']], 'time': '2021-05-20T03:55:49.393537Z'}
{'type': 'l2update', 'product_id': 'BTC-USD', 'changes': [['sell', '38526.49', '0.00000000']], 'time': '2021-05-20T03:55:49.398953Z'}
{'type': 'l2update', 'product_id': 'BTC-USD', 'changes': [['sell', '38342.92', '2.79110965']], 'time': '2021-05-20T03:55:49.403370Z'}
{'type': 'l2update', 'product_id': 'BTC-USD', 'changes': [['buy', '38293.51', '0.00000000']], 'time': '2021-05-20T03:55:49.409882Z'}
{'type': 'l2update', 'product_id': 'BTC-USD', 'changes': [['sell', '38536.31', '0.00648738']], 'time': '2021-05-20T03:55:49.412574Z'}
{'type': 'l2update', 'product_id': 'BTC-USD', 'changes': [['sell', '38347.70', '0.00000000']], 'time': '2021-05-20T03:55:49.416527Z'}
{'type': 'l2update', 'product_id': 'BTC-USD', 'changes': [['buy', '38128.23', '0.00000000']], 'time': '2021-05-20T03:55:49.416675Z'}
{'type': 'l2update', 'product_id': 'BTC-USD', 'changes': [['buy', '38315.26', '0.00000000']], 'time': '2021-05-20T03:55:49.417791Z'}
{'type': 'l2update', 'product_id': 'BTC-USD', 'changes': [['sell', '38513.32', '0.01000000']], 'time': '2021-05-20T03:55:49.424157Z'}
{'type': 'l2update', 'product_id': 'BTC-USD', 'changes': [['sell', '38485.97', '0.01000000']], 'time': '2021-05-20T03:55:49.424567Z'}
{'type': 'l2update', 'product_id': 'BTC-USD', 'changes': [['buy', '38320.35', '0.84600000']], 'time': '2021-05-20T03:55:49.429564Z'}
{'type': 'l2update', 'product_id': 'BTC-USD', 'changes': [['sell', '38355.76', '0.50000000']], 'time': '2021-05-20T03:55:49.429845Z'}
{'type': 'l2update', 'product_id': 'BTC-USD', 'changes': [['buy', '38319.01', '0.00000000']], 'time': '2021-05-20T03:55:49.434444Z'}
{'type': 'l2update', 'product_id': 'BTC-USD', 'changes': [['buy', '37931.24', '0.42120000']], 'time': '2021-05-20T03:55:49.449664Z'}
{'type': 'l2update', 'product_id': 'BTC-USD', 'changes': [['buy', '38301.05', '0.03000000']], 'time': '2021-05-20T03:55:49.451041Z'}
{'type': 'l2update', 'product_id': 'BTC-USD', 'changes': [['buy', '38314.10', '0.45150000']], 'time': '2021-05-20T03:55:49.451137Z'}
{'type': 'l2update', 'product_id': 'BTC-USD', 'changes': [['sell', '38461.39', '0.00000000']], 'time': '2021-05-20T03:55:49.451227Z'}
{'type': 'l2update', 'product_id': 'BTC-USD', 'changes': [['buy', '38320.30', '0.00000000']], 'time': '2021-05-20T03:55:49.451395Z'}
{'type': 'l2update', 'product_id': 'BTC-USD', 'changes': [['sell', '38342.92', '2.79248194']], 'time': '2021-05-20T03:55:49.461026Z'}
{'type': 'l2update', 'product_id': 'BTC-USD', 'changes': [['buy', '38319.02', '0.01870000']], 'time': '2021-05-20T03:55:49.464242Z'}
{'type': 'l2update', 'product_id': 'BTC-USD', 'changes': [['buy', '38314.10', '0.00000000']], 'time': '2021-05-20T03:55:49.464603Z'}
{'type': 'l2update', 'product_id': 'BTC-USD', 'changes': [['buy', '38152.56', '0.01000000']], 'time': '2021-05-20T03:55:49.474158Z'}
{'type': 'l2update', 'product_id': 'BTC-USD', 'changes': [['sell', '38439.38', '0.01000000']], 'time': '2021-05-20T03:55:49.482800Z'}
{'type': 'l2update', 'product_id': 'BTC-USD', 'changes': [['buy', '38256.93', '0.00000000']], 'time': '2021-05-20T03:55:49.483889Z'}
{'type': 'l2update', 'product_id': 'BTC-USD', 'changes': [['buy', '38320.31', '0.02975895']], 'time': '2021-05-20T03:55:49.486477Z'}
{'type': 'l2update', 'product_id': 'BTC-USD', 'changes': [['sell', '38608.57', '0.64577618']], 'time': '2021-05-20T03:55:49.490175Z'}
{'type': 'l2update', 'product_id': 'BTC-USD', 'changes': [['sell', '38612.28', '5.81208853']], 'time': '2021-05-20T03:55:49.490175Z'}
{'type': 'l2update', 'product_id': 'BTC-USD', 'changes': [['buy', '38342.91', '0.00452786']], 'time': '2021-05-20T03:55:49.498129Z'}
{'type': 'l2update', 'product_id': 'BTC-USD', 'changes': [['buy', '38342.91', '0.00274454']], 'time': '2021-05-20T03:55:49.498129Z'}
{'type': 'l2update', 'product_id': 'BTC-USD', 'changes': [['sell', '38372.08', '0.00000000']], 'time': '2021-05-20T03:55:49.498185Z'}
{'type': 'l2update', 'product_id': 'BTC-USD', 'changes': [['sell', '38467.72', '0.00000000']], 'time': '2021-05-20T03:55:49.510731Z'}
{'type': 'l2update', 'product_id': 'BTC-USD', 'changes': [['sell', '38649.94', '0.00000000']], 'time': '2021-05-20T03:55:49.517478Z'}
{'type': 'l2update', 'product_id': 'BTC-USD', 'changes': [['sell', '38387.23', '0.09856011']], 'time': '2021-05-20T03:55:49.517604Z'}
{'type': 'l2update', 'product_id': 'BTC-USD', 'changes': [['buy', '38243.00', '0.00000000']], 'time': '2021-05-20T03:55:49.524528Z'}
{'type': 'l2update', 'product_id': 'BTC-USD', 'changes': [['buy', '38330.53', '0.01492000']], 'time': '2021-05-20T03:55:49.529841Z'}
{'type': 'l2update', 'product_id': 'BTC-USD', 'changes': [['buy', '37900.00', '0.33116046']], 'time': '2021-05-20T03:55:49.530027Z'}
{'type': 'l2update', 'product_id': 'BTC-USD', 'changes': [['buy', '38150.55', '0.04839047']], 'time': '2021-05-20T03:55:49.530133Z'}
{'type': 'l2update', 'product_id': 'BTC-USD', 'changes': [['buy', '38335.87', '0.04978840']], 'time': '2021-05-20T03:55:49.530166Z'}
{'type': 'l2update', 'product_id': 'BTC-USD', 'changes': [['sell', '38349.66', '0.04840427']], 'time': '2021-05-20T03:55:49.530397Z'}
{'type': 'l2update', 'product_id': 'BTC-USD', 'changes': [['buy', '38330.46', '0.07460000']], 'time': '2021-05-20T03:55:49.530554Z'}
{'type': 'l2update', 'product_id': 'BTC-USD', 'changes': [['sell', '38370.92', '0.43280000']], 'time': '2021-05-20T03:55:49.530572Z'}
{'type': 'l2update', 'product_id': 'BTC-USD', 'changes': [['buy', '38311.07', '0.64736190']], 'time': '2021-05-20T03:55:49.530967Z'}
{'type': 'l2update', 'product_id': 'BTC-USD', 'changes': [['buy', '38342.91', '0.15274454']], 'time': '2021-05-20T03:55:49.531264Z'}
{'type': 'l2update', 'product_id': 'BTC-USD', 'changes': [['buy', '38342.91', '0.15000000']], 'time': '2021-05-20T03:55:49.535250Z'}
{'type': 'l2update', 'product_id': 'BTC-USD', 'changes': [['sell', '38461.27', '0.01175187']], 'time': '2021-05-20T03:55:49.537104Z'}
{'type': 'l2update', 'product_id': 'BTC-USD', 'changes': [['buy', '38330.46', '0.00000000']], 'time': '2021-05-20T03:55:49.544693Z'}
{'type': 'l2update', 'product_id': 'BTC-USD', 'changes': [['buy', '38330.53', '0.00000000']], 'time': '2021-05-20T03:55:49.545464Z'}
{'type': 'l2update', 'product_id': 'BTC-USD', 'changes': [['buy', '38255.08', '0.01000000']], 'time': '2021-05-20T03:55:49.546544Z'}
{'type': 'l2update', 'product_id': 'BTC-USD', 'changes': [['sell', '38372.07', '0.00000000']], 'time': '2021-05-20T03:55:49.546880Z'}
{'type': 'l2update', 'product_id': 'BTC-USD', 'changes': [['buy', '38328.66', '0.00000000']], 'time': '2021-05-20T03:55:49.555922Z'}
{'type': 'l2update', 'product_id': 'BTC-USD', 'changes': [['sell', '38355.77', '0.00000000']], 'time': '2021-05-20T03:55:49.557345Z'}
{'type': 'l2update', 'product_id': 'BTC-USD', 'changes': [['buy', '38311.07', '0.00000000']], 'time': '2021-05-20T03:55:49.563482Z'}
{'type': 'l2update', 'product_id': 'BTC-USD', 'changes': [['buy', '38306.38', '0.48370000']], 'time': '2021-05-20T03:55:49.572296Z'}
{'type': 'l2update', 'product_id': 'BTC-USD', 'changes': [['sell', '38370.91', '0.05000000']], 'time': '2021-05-20T03:55:49.572473Z'}
{'type': 'l2update', 'product_id': 'BTC-USD', 'changes': [['sell', '38708.23', '0.01000000']], 'time': '2021-05-20T03:55:49.572556Z'}
{'type': 'l2update', 'product_id': 'BTC-USD', 'changes': [['buy', '38320.36', '0.02975895']], 'time': '2021-05-20T03:55:49.572925Z'}
{'type': 'l2update', 'product_id': 'BTC-USD', 'changes': [['buy', '38217.78', '0.00000000']], 'time': '2021-05-20T03:55:49.579722Z'}
{'type': 'l2update', 'product_id': 'BTC-USD', 'changes': [['buy', '38307.74', '0.00000000']], 'time': '2021-05-20T03:55:49.580523Z'}
{'type': 'l2update', 'product_id': 'BTC-USD', 'changes': [['sell', '38349.16', '0.00000000']], 'time': '2021-05-20T03:55:49.580523Z'}
{'type': 'l2update', 'product_id': 'BTC-USD', 'changes': [['buy', '38276.35', '1.28129324']], 'time': '2021-05-20T03:55:49.583760Z'}
{'type': 'l2update', 'product_id': 'BTC-USD', 'changes': [['sell', '38355.76', '0.00000000']], 'time': '2021-05-20T03:55:49.584060Z'}
{'type': 'l2update', 'product_id': 'BTC-USD', 'changes': [['buy', '38230.90', '0.50300000']], 'time': '2021-05-20T03:55:49.585201Z'}
{'type': 'l2update', 'product_id': 'BTC-USD', 'changes': [['sell', '38536.31', '0.00000000']], 'time': '2021-05-20T03:55:49.592462Z'}
{'type': 'l2update', 'product_id': 'BTC-USD', 'changes': [['buy', '38320.31', '0.00000000']], 'time': '2021-05-20T03:55:49.597519Z'}
{'type': 'l2update', 'product_id': 'BTC-USD', 'changes': [['sell', '38513.32', '0.00000000']], 'time': '2021-05-20T03:55:49.599389Z'}
{'type': 'l2update', 'product_id': 'BTC-USD', 'changes': [['sell', '38480.51', '0.00000000']], 'time': '2021-05-20T03:55:49.600080Z'}
{'type': 'l2update', 'product_id': 'BTC-USD', 'changes': [['buy', '38229.68', '0.02731687']], 'time': '2021-05-20T03:55:49.603183Z'}
{'type': 'l2update', 'product_id': 'BTC-USD', 'changes': [['sell', '38359.26', '0.50000000']], 'time': '2021-05-20T03:55:49.610265Z'}
{'type': 'l2update', 'product_id': 'BTC-USD', 'changes': [['sell', '38347.71', '1.57134695']], 'time': '2021-05-20T03:55:49.616590Z'}
{'type': 'l2update', 'product_id': 'BTC-USD', 'changes': [['buy', '38323.08', '0.84700000']], 'time': '2021-05-20T03:55:49.616649Z'}
{'type': 'l2update', 'product_id': 'BTC-USD', 'changes': [['sell', '38500.14', '0.01000000']], 'time': '2021-05-20T03:55:49.616878Z'}
{'type': 'l2update', 'product_id': 'BTC-USD', 'changes': [['sell', '38451.49', '0.01300339']], 'time': '2021-05-20T03:55:49.620665Z'}
{'type': 'l2update', 'product_id': 'BTC-USD', 'changes': [['sell', '38381.14', '0.00000000']], 'time': '2021-05-20T03:55:49.624397Z'}
{'type': 'l2update', 'product_id': 'BTC-USD', 'changes': [['sell', '38342.92', '2.80149254']], 'time': '2021-05-20T03:55:49.625264Z'}
{'type': 'l2update', 'product_id': 'BTC-USD', 'changes': [['sell', '38474.81', '0.00000000']], 'time': '2021-05-20T03:55:49.625687Z'}
{'type': 'l2update', 'product_id': 'BTC-USD', 'changes': [['sell', '38342.92', '2.77030377']], 'time': '2021-05-20T03:55:49.629039Z'}
{'type': 'l2update', 'product_id': 'BTC-USD', 'changes': [['buy', '38316.60', '0.00000000']], 'time': '2021-05-20T03:55:49.630429Z'}
{'type': 'l2update', 'product_id': 'BTC-USD', 'changes': [['sell', '38500.14', '0.00000000']], 'time': '2021-05-20T03:55:49.632419Z'}
{'type': 'l2update', 'product_id': 'BTC-USD', 'changes': [['buy', '38298.70', '0.00000000']], 'time': '2021-05-20T03:55:49.632624Z'}
{'type': 'l2update', 'product_id': 'BTC-USD', 'changes': [['buy', '38307.86', '0.05349671']], 'time': '2021-05-20T03:55:49.640628Z'}
{'type': 'l2update', 'product_id': 'BTC-USD', 'changes': [['sell', '38351.53', '0.06430653']], 'time': '2021-05-20T03:55:49.640628Z'}
{'type': 'l2update', 'product_id': 'BTC-USD', 'changes': [['buy', '38303.29', '0.00000000']], 'time': '2021-05-20T03:55:49.644007Z'}
{'type': 'l2update', 'product_id': 'BTC-USD', 'changes': [['buy', '38320.29', '0.00000000']], 'time': '2021-05-20T03:55:49.646031Z'}
{'type': 'l2update', 'product_id': 'BTC-USD', 'changes': [['sell', '38461.07', '0.01000000']], 'time': '2021-05-20T03:55:49.647381Z'}
{'type': 'l2update', 'product_id': 'BTC-USD', 'changes': [['sell', '38355.75', '0.05561714']], 'time': '2021-05-20T03:55:49.647477Z'}
{'type': 'l2update', 'product_id': 'BTC-USD', 'changes': [['sell', '38528.38', '0.01000000']], 'time': '2021-05-20T03:55:49.649138Z'}
{'type': 'l2update', 'product_id': 'BTC-USD', 'changes': [['buy', '38313.94', '0.02400000']], 'time': '2021-05-20T03:55:49.649179Z'}
{'type': 'l2update', 'product_id': 'BTC-USD', 'changes': [['buy', '38311.11', '0.05066856']], 'time': '2021-05-20T03:55:49.655004Z'}
{'type': 'l2update', 'product_id': 'BTC-USD', 'changes': [['sell', '38374.76', '0.05049306']], 'time': '2021-05-20T03:55:49.655193Z'}
{'type': 'l2update', 'product_id': 'BTC-USD', 'changes': [['buy', '38306.38', '0.00000000']], 'time': '2021-05-20T03:55:49.659167Z'}
{'type': 'l2update', 'product_id': 'BTC-USD', 'changes': [['buy', '38323.09', '0.99315797']], 'time': '2021-05-20T03:55:49.665797Z'}
{'type': 'l2update', 'product_id': 'BTC-USD', 'changes': [['buy', '38323.09', '1.04877511']], 'time': '2021-05-20T03:55:49.671110Z'}
{'type': 'l2update', 'product_id': 'BTC-USD', 'changes': [['sell', '38439.38', '0.00000000']], 'time': '2021-05-20T03:55:49.676825Z'}
{'type': 'l2update', 'product_id': 'BTC-USD', 'changes': [['buy', '38256.39', '0.00000000']], 'time': '2021-05-20T03:55:49.678173Z'}
{'type': 'l2update', 'product_id': 'BTC-USD', 'changes': [['buy', '38320.36', '0.00000000']], 'time': '2021-05-20T03:55:49.679192Z'}
{'type': 'l2update', 'product_id': 'BTC-USD', 'changes': [['sell', '38459.50', '0.01000000']], 'time': '2021-05-20T03:55:49.692286Z'}
{'type': 'l2update', 'product_id': 'BTC-USD', 'changes': [['sell', '38580.00', '1.00000000']], 'time': '2021-05-20T03:55:49.696557Z'}
{'type': 'l2update', 'product_id': 'BTC-USD', 'changes': [['buy', '38228.19', '0.00000000']], 'time': '2021-05-20T03:55:49.700852Z'}
{'type': 'l2update', 'product_id': 'BTC-USD', 'changes': [['buy', '38323.09', '0.99315797']], 'time': '2021-05-20T03:55:49.700902Z'}
{'type': 'l2update', 'product_id': 'BTC-USD', 'changes': [['buy', '37560.11', '0.00000000']], 'time': '2021-05-20T03:55:49.705723Z'}
{'type': 'l2update', 'product_id': 'BTC-USD', 'changes': [['buy', '36930.72', '0.00013878']], 'time': '2021-05-20T03:55:49.705723Z'}
{'type': 'l2update', 'product_id': 'BTC-USD', 'changes': [['sell', '38528.38', '0.00000000']], 'time': '2021-05-20T03:55:49.708355Z'}
{'type': 'l2update', 'product_id': 'BTC-USD', 'changes': [['sell', '38359.25', '0.05561714']], 'time': '2021-05-20T03:55:49.712220Z'}
{'type': 'l2update', 'product_id': 'BTC-USD', 'changes': [['sell', '38355.75', '0.00000000']], 'time': '2021-05-20T03:55:49.716461Z'}
{'type': 'l2update', 'product_id': 'BTC-USD', 'changes': [['buy', '38335.88', '0.10000000']], 'time': '2021-05-20T03:55:49.716908Z'}
{'type': 'l2update', 'product_id': 'BTC-USD', 'changes': [['sell', '38708.23', '0.00000000']], 'time': '2021-05-20T03:55:49.719540Z'}
{'type': 'l2update', 'product_id': 'BTC-USD', 'changes': [['buy', '38255.08', '0.00000000']], 'time': '2021-05-20T03:55:49.720134Z'}
{'type': 'l2update', 'product_id': 'BTC-USD', 'changes': [['sell', '38515.20', '0.01000000']], 'time': '2021-05-20T03:55:49.724992Z'}
{'type': 'l2update', 'product_id': 'BTC-USD', 'changes': [['buy', '38323.10', '0.05561714']], 'time': '2021-05-20T03:55:49.730994Z'}
{'type': 'l2update', 'product_id': 'BTC-USD', 'changes': [['sell', '38515.20', '0.00000000']], 'time': '2021-05-20T03:55:49.733282Z'}
{'type': 'l2update', 'product_id': 'BTC-USD', 'changes': [['sell', '38342.92', '0.28060469']], 'time': '2021-05-20T03:55:49.734785Z'}
{'type': 'l2update', 'product_id': 'BTC-USD', 'changes': [['buy', '38323.14', '0.52100000']], 'time': '2021-05-20T03:55:49.737334Z'}
{'type': 'l2update', 'product_id': 'BTC-USD', 'changes': [['sell', '38648.13', '0.00000000']], 'time': '2021-05-20T03:55:49.741392Z'}
{'type': 'l2update', 'product_id': 'BTC-USD', 'changes': [['sell', '38528.38', '0.01000000']], 'time': '2021-05-20T03:55:49.746152Z'}
{'type': 'l2update', 'product_id': 'BTC-USD', 'changes': [['buy', '38264.62', '0.01000000']], 'time': '2021-05-20T03:55:49.746221Z'}
{'type': 'l2update', 'product_id': 'BTC-USD', 'changes': [['sell', '38387.24', '0.00000000']], 'time': '2021-05-20T03:55:49.748234Z'}
{'type': 'l2update', 'product_id': 'BTC-USD', 'changes': [['sell', '38649.94', '0.01000000']], 'time': '2021-05-20T03:55:49.750652Z'}
{'type': 'l2update', 'product_id': 'BTC-USD', 'changes': [['buy', '38304.46', '0.44950000']], 'time': '2021-05-20T03:55:49.755424Z'}
{'type': 'l2update', 'product_id': 'BTC-USD', 'changes': [['sell', '38347.70', '2.48969908']], 'time': '2021-05-20T03:55:49.755600Z'}
{'type': 'l2update', 'product_id': 'BTC-USD', 'changes': [['sell', '38481.88', '0.00000000']], 'time': '2021-05-20T03:55:49.756233Z'}
{'type': 'l2update', 'product_id': 'BTC-USD', 'changes': [['sell', '38489.48', '0.00000000']], 'time': '2021-05-20T03:55:49.761844Z'}
{'type': 'l2update', 'product_id': 'BTC-USD', 'changes': [['buy', '38307.86', '0.00000000']], 'time': '2021-05-20T03:55:49.771451Z'}
{'type': 'l2update', 'product_id': 'BTC-USD', 'changes': [['sell', '38351.53', '0.00000000']], 'time': '2021-05-20T03:55:49.771451Z'}
{'type': 'l2update', 'product_id': 'BTC-USD', 'changes': [['sell', '38612.28', '2.58315476']], 'time': '2021-05-20T03:55:49.772055Z'}
{'type': 'l2update', 'product_id': 'BTC-USD', 'changes': [['sell', '38371.33', '0.01000000']], 'time': '2021-05-20T03:55:49.772320Z'}
{'type': 'l2update', 'product_id': 'BTC-USD', 'changes': [['buy', '38323.15', '0.05561714']], 'time': '2021-05-20T03:55:49.776205Z'}
{'type': 'l2update', 'product_id': 'BTC-USD', 'changes': [['buy', '38323.10', '0.00000000']], 'time': '2021-05-20T03:55:49.776950Z'}
{'type': 'l2update', 'product_id': 'BTC-USD', 'changes': [['sell', '38489.79', '0.01218739']], 'time': '2021-05-20T03:55:49.780276Z'}
{'type': 'l2update', 'product_id': 'BTC-USD', 'changes': [['buy', '37544.90', '0.06845639']], 'time': '2021-05-20T03:55:49.780383Z'}
{'type': 'l2update', 'product_id': 'BTC-USD', 'changes': [['buy', '38316.24', '0.52185516']], 'time': '2021-05-20T03:55:49.785858Z'}
{'type': 'l2update', 'product_id': 'BTC-USD', 'changes': [['sell', '38347.69', '1.45264798']], 'time': '2021-05-20T03:55:49.786061Z'}
{'type': 'l2update', 'product_id': 'BTC-USD', 'changes': [['buy', '38288.92', '0.01000000']], 'time': '2021-05-20T03:55:49.789424Z'}
{'type': 'l2update', 'product_id': 'BTC-USD', 'changes': [['sell', '38362.33', '0.00000000']], 'time': '2021-05-20T03:55:49.789517Z'}
{'type': 'l2update', 'product_id': 'BTC-USD', 'changes': [['buy', '38299.23', '0.00000000']], 'time': '2021-05-20T03:55:49.795047Z'}
{'type': 'l2update', 'product_id': 'BTC-USD', 'changes': [['sell', '38474.06', '0.00000000']], 'time': '2021-05-20T03:55:49.797797Z'}
{'type': 'l2update', 'product_id': 'BTC-USD', 'changes': [['buy', '38301.05', '0.00000000']], 'time': '2021-05-20T03:55:49.800290Z'}
{'type': 'l2update', 'product_id': 'BTC-USD', 'changes': [['buy', '38310.61', '0.05661632']], 'time': '2021-05-20T03:55:49.800580Z'}
{'type': 'l2update', 'product_id': 'BTC-USD', 'changes': [['sell', '38353.12', '0.06329433']], 'time': '2021-05-20T03:55:49.800580Z'}
{'type': 'l2update', 'product_id': 'BTC-USD', 'changes': [['sell', '39158.81', '0.06314848']], 'time': '2021-05-20T03:55:49.800696Z'}
{'type': 'l2update', 'product_id': 'BTC-USD', 'changes': [['sell', '38461.07', '0.00000000']], 'time': '2021-05-20T03:55:49.802863Z'}
{'type': 'l2update', 'product_id': 'BTC-USD', 'changes': [['buy', '38288.72', '0.00000000']], 'time': '2021-05-20T03:55:49.803321Z'}
{'type': 'l2update', 'product_id': 'BTC-USD', 'changes': [['sell', '38433.59', '0.00000000']], 'time': '2021-05-20T03:55:49.806695Z'}
{'type': 'l2update', 'product_id': 'BTC-USD', 'changes': [['buy', '38282.12', '0.00000000']], 'time': '2021-05-20T03:55:49.807785Z'}
{'type': 'l2update', 'product_id': 'BTC-USD', 'changes': [['buy', '38330.09', '0.00000000']], 'time': '2021-05-20T03:55:49.807861Z'}
{'type': 'l2update', 'product_id': 'BTC-USD', 'changes': [['buy', '38312.65', '0.52180118']], 'time': '2021-05-20T03:55:49.811683Z'}
{'type': 'l2update', 'product_id': 'BTC-USD', 'changes': [['buy', '38305.73', '0.02000000']], 'time': '2021-05-20T03:55:49.819142Z'}
{'type': 'l2update', 'product_id': 'BTC-USD', 'changes': [['sell', '38474.81', '0.01000000']], 'time': '2021-05-20T03:55:49.820063Z'}
{'type': 'l2update', 'product_id': 'BTC-USD', 'changes': [['sell', '38453.20', '0.02684829']], 'time': '2021-05-20T03:55:49.825373Z'}
{'type': 'l2update', 'product_id': 'BTC-USD', 'changes': [['sell', '38529.01', '0.01000000']], 'time': '2021-05-20T03:55:49.825544Z'}
{'type': 'l2update', 'product_id': 'BTC-USD', 'changes': [['buy', '38310.01', '0.52183908']], 'time': '2021-05-20T03:55:49.825562Z'}
{'type': 'l2update', 'product_id': 'BTC-USD', 'changes': [['sell', '38452.72', '0.02267000']], 'time': '2021-05-20T03:55:49.829926Z'}
{'type': 'l2update', 'product_id': 'BTC-USD', 'changes': [['buy', '38301.84', '0.03000000']], 'time': '2021-05-20T03:55:49.834097Z'}
{'type': 'l2update', 'product_id': 'BTC-USD', 'changes': [['buy', '38304.86', '0.78270199']], 'time': '2021-05-20T03:55:49.843524Z'}
{'type': 'l2update', 'product_id': 'BTC-USD', 'changes': [['buy', '38299.02', '0.04000000']], 'time': '2021-05-20T03:55:49.854170Z'}
{'type': 'l2update', 'product_id': 'BTC-USD', 'changes': [['buy', '38304.46', '0.00000000']], 'time': '2021-05-20T03:55:49.855907Z'}
{'type': 'l2update', 'product_id': 'BTC-USD', 'changes': [['buy', '38294.56', '1.30458950']], 'time': '2021-05-20T03:55:49.862357Z'}
{'type': 'l2update', 'product_id': 'BTC-USD', 'changes': [['sell', '38461.27', '0.00000000']], 'time': '2021-05-20T03:55:49.863323Z'}
{'type': 'l2update', 'product_id': 'BTC-USD', 'changes': [['buy', '38278.50', '0.00000000']], 'time': '2021-05-20T03:55:49.867962Z'}
{'type': 'l2update', 'product_id': 'BTC-USD', 'changes': [['buy', '38306.88', '0.41330000']], 'time': '2021-05-20T03:55:49.870467Z'}
{'type': 'l2update', 'product_id': 'BTC-USD', 'changes': [['buy', '38295.29', '0.05000000']], 'time': '2021-05-20T03:55:49.871012Z'}
{'type': 'l2update', 'product_id': 'BTC-USD', 'changes': [['sell', '38528.38', '0.00000000']], 'time': '2021-05-20T03:55:49.876332Z'}
{'type': 'l2update', 'product_id': 'BTC-USD', 'changes': [['sell', '38371.33', '0.00000000']], 'time': '2021-05-20T03:55:49.876986Z'}
{'type': 'l2update', 'product_id': 'BTC-USD', 'changes': [['buy', '38306.88', '0.00000000']], 'time': '2021-05-20T03:55:49.878787Z'}
{'type': 'l2update', 'product_id': 'BTC-USD', 'changes': [['buy', '38285.53', '2.60927578']], 'time': '2021-05-20T03:55:49.880654Z'}
{'type': 'l2update', 'product_id': 'BTC-USD', 'changes': [['sell', '38359.26', '0.00000000']], 'time': '2021-05-20T03:55:49.880922Z'}
{'type': 'l2update', 'product_id': 'BTC-USD', 'changes': [['buy', '38288.92', '0.00000000']], 'time': '2021-05-20T03:55:49.884875Z'}
{'type': 'l2update', 'product_id': 'BTC-USD', 'changes': [['buy', '38282.50', '0.10000000']], 'time': '2021-05-20T03:55:49.890751Z'}
{'type': 'l2update', 'product_id': 'BTC-USD', 'changes': [['sell', '38608.57', '0.00000000']], 'time': '2021-05-20T03:55:49.891127Z'}
{'type': 'l2update', 'product_id': 'BTC-USD', 'changes': [['sell', '38612.28', '0.00000000']], 'time': '2021-05-20T03:55:49.891127Z'}
{'type': 'l2update', 'product_id': 'BTC-USD', 'changes': [['buy', '38284.87', '2.60882792']], 'time': '2021-05-20T03:55:49.897184Z'}
{'type': 'l2update', 'product_id': 'BTC-USD', 'changes': [['sell', '38515.20', '0.01000000']], 'time': '2021-05-20T03:55:49.897290Z'}
{'type': 'l2update', 'product_id': 'BTC-USD', 'changes': [['sell', '38479.72', '0.01174368']], 'time': '2021-05-20T03:55:49.902129Z'}
{'type': 'l2update', 'product_id': 'BTC-USD', 'changes': [['buy', '38333.67', '0.15500000']], 'time': '2021-05-20T03:55:49.902273Z'}
{'type': 'l2update', 'product_id': 'BTC-USD', 'changes': [['sell', '38347.68', '0.50000000']], 'time': '2021-05-20T03:55:49.903738Z'}
{'type': 'l2update', 'product_id': 'BTC-USD', 'changes': [['buy', '37898.94', '0.00000000']], 'time': '2021-05-20T03:55:49.910894Z'}
{'type': 'l2update', 'product_id': 'BTC-USD', 'changes': [['buy', '38310.61', '0.00000000']], 'time': '2021-05-20T03:55:49.913622Z'}
{'type': 'l2update', 'product_id': 'BTC-USD', 'changes': [['sell', '38515.20', '0.00000000']], 'time': '2021-05-20T03:55:49.926740Z'}
{'type': 'l2update', 'product_id': 'BTC-USD', 'changes': [['sell', '38347.63', '1.15600000']], 'time': '2021-05-20T03:55:49.927578Z'}
{'type': 'l2update', 'product_id': 'BTC-USD', 'changes': [['sell', '38528.38', '0.01000000']], 'time': '2021-05-20T03:55:49.943723Z'}
{'type': 'l2update', 'product_id': 'BTC-USD', 'changes': [['buy', '38311.80', '0.04347358']], 'time': '2021-05-20T03:55:49.955171Z'}
{'type': 'l2update', 'product_id': 'BTC-USD', 'changes': [['sell', '38518.73', '0.00000000']], 'time': '2021-05-20T03:55:49.959564Z'}
{'type': 'l2update', 'product_id': 'BTC-USD', 'changes': [['sell', '38393.78', '0.00000000']], 'time': '2021-05-20T03:55:49.963265Z'}
{'type': 'l2update', 'product_id': 'BTC-USD', 'changes': [['sell', '38374.61', '0.00000000']], 'time': '2021-05-20T03:55:49.963265Z'}
{'type': 'l2update', 'product_id': 'BTC-USD', 'changes': [['buy', '38264.62', '0.00000000']], 'time': '2021-05-20T03:55:49.968797Z'}
{'type': 'l2update', 'product_id': 'BTC-USD', 'changes': [['sell', '38846.76', '3.22893068']], 'time': '2021-05-20T03:55:49.969102Z'}
{'type': 'l2update', 'product_id': 'BTC-USD', 'changes': [['buy', '38306.19', '0.46700000']], 'time': '2021-05-20T03:55:49.979133Z'}
{'type': 'l2update', 'product_id': 'BTC-USD', 'changes': [['sell', '38342.92', '0.27421753']], 'time': '2021-05-20T03:55:49.979506Z'}
{'type': 'l2update', 'product_id': 'BTC-USD', 'changes': [['sell', '38649.94', '0.00000000']], 'time': '2021-05-20T03:55:49.983630Z'}
{'type': 'l2update', 'product_id': 'BTC-USD', 'changes': [['buy', '38282.74', '0.01000000']], 'time': '2021-05-20T03:55:49.985497Z'}
{'type': 'l2update', 'product_id': 'BTC-USD', 'changes': [['sell', '38423.98', '0.20400000']], 'time': '2021-05-20T03:55:49.985520Z'}
{'type': 'l2update', 'product_id': 'BTC-USD', 'changes': [['sell', '38404.79', '0.06600000']], 'time': '2021-05-20T03:55:49.985520Z'}
{'type': 'l2update', 'product_id': 'BTC-USD', 'changes': [['sell', '38665.02', '0.01293158']], 'time': '2021-05-20T03:55:49.997109Z'}
{'type': 'l2update', 'product_id': 'BTC-USD', 'changes': [['buy', '38229.68', '0.00000000']], 'time': '2021-05-20T03:55:50.014600Z'}
{'type': 'l2update', 'product_id': 'BTC-USD', 'changes': [['sell', '38474.81', '0.00000000']], 'time': '2021-05-20T03:55:50.016421Z'}
{'type': 'l2update', 'product_id': 'BTC-USD', 'changes': [['buy', '38212.15', '0.02731687']], 'time': '2021-05-20T03:55:50.027995Z'}
{'type': 'l2update', 'product_id': 'BTC-USD', 'changes': [['sell', '38665.02', '0.00000000']], 'time': '2021-05-20T03:55:50.034069Z'}
{'type': 'l2update', 'product_id': 'BTC-USD', 'changes': [['sell', '38561.79', '0.01000000']], 'time': '2021-05-20T03:55:50.040585Z'}
{'type': 'l2update', 'product_id': 'BTC-USD', 'changes': [['sell', '39158.81', '0.00000000']], 'time': '2021-05-20T03:55:50.049769Z'}
{'type': 'l2update', 'product_id': 'BTC-USD', 'changes': [['sell', '38370.92', '0.00000000']], 'time': '2021-05-20T03:55:50.050672Z'}
{'type': 'l2update', 'product_id': 'BTC-USD', 'changes': [['buy', '37544.90', '0.00000000']], 'time': '2021-05-20T03:55:50.053023Z'}
{'type': 'l2update', 'product_id': 'BTC-USD', 'changes': [['sell', '38649.94', '0.01000000']], 'time': '2021-05-20T03:55:50.053163Z'}
{'type': 'l2update', 'product_id': 'BTC-USD', 'changes': [['sell', '38374.20', '0.41820000']], 'time': '2021-05-20T03:55:50.062590Z'}
{'type': 'l2update', 'product_id': 'BTC-USD', 'changes': [['sell', '38561.79', '0.00000000']], 'time': '2021-05-20T03:55:50.065740Z'}
{'type': 'l2update', 'product_id': 'BTC-USD', 'changes': [['sell', '38374.20', '0.00000000']], 'time': '2021-05-20T03:55:50.068963Z'}
{'type': 'l2update', 'product_id': 'BTC-USD', 'changes': [['sell', '38397.10', '0.61482417']], 'time': '2021-05-20T03:55:50.072655Z'}
{'type': 'l2update', 'product_id': 'BTC-USD', 'changes': [['sell', '38488.54', '0.01000000']], 'time': '2021-05-20T03:55:50.082367Z'}
{'type': 'l2update', 'product_id': 'BTC-USD', 'changes': [['sell', '38376.35', '0.07000000']], 'time': '2021-05-20T03:55:50.086409Z'}
{'type': 'l2update', 'product_id': 'BTC-USD', 'changes': [['buy', '38306.19', '0.00000000']], 'time': '2021-05-20T03:55:50.094775Z'}
{'type': 'l2update', 'product_id': 'BTC-USD', 'changes': [['sell', '38380.05', '0.05000000']], 'time': '2021-05-20T03:55:50.101894Z'}
{'type': 'l2update', 'product_id': 'BTC-USD', 'changes': [['buy', '38307.82', '0.48720000']], 'time': '2021-05-20T03:55:50.103610Z'}
{'type': 'l2update', 'product_id': 'BTC-USD', 'changes': [['sell', '38488.54', '0.00000000']], 'time': '2021-05-20T03:55:50.107638Z'}
{'type': 'l2update', 'product_id': 'BTC-USD', 'changes': [['buy', '38233.66', '2.42890000']], 'time': '2021-05-20T03:55:50.124198Z'}
{'type': 'l2update', 'product_id': 'BTC-USD', 'changes': [['sell', '38528.38', '0.00000000']], 'time': '2021-05-20T03:55:50.132076Z'}
{'type': 'l2update', 'product_id': 'BTC-USD', 'changes': [['sell', '38457.97', '0.01000000']], 'time': '2021-05-20T03:55:50.133697Z'}
{'type': 'l2update', 'product_id': 'BTC-USD', 'changes': [['sell', '38452.72', '0.00000000']], 'time': '2021-05-20T03:55:50.141526Z'}
{'type': 'l2update', 'product_id': 'BTC-USD', 'changes': [['sell', '38459.50', '0.00000000']], 'time': '2021-05-20T03:55:50.142443Z'}
{'type': 'l2update', 'product_id': 'BTC-USD', 'changes': [['sell', '38515.20', '0.01000000']], 'time': '2021-05-20T03:55:50.143868Z'}
{'type': 'l2update', 'product_id': 'BTC-USD', 'changes': [['sell', '38470.14', '0.01000000']], 'time': '2021-05-20T03:55:50.157116Z'}
{'type': 'l2update', 'product_id': 'BTC-USD', 'changes': [['sell', '38446.29', '0.03584250']], 'time': '2021-05-20T03:55:50.165014Z'}
{'type': 'l2update', 'product_id': 'BTC-USD', 'changes': [['sell', '38374.16', '0.44160000']], 'time': '2021-05-20T03:55:50.165172Z'}
{'type': 'l2update', 'product_id': 'BTC-USD', 'changes': [['buy', '38307.82', '0.00000000']], 'time': '2021-05-20T03:55:50.172305Z'}
{'type': 'l2update', 'product_id': 'BTC-USD', 'changes': [['buy', '38282.74', '0.00000000']], 'time': '2021-05-20T03:55:50.178365Z'}
{'type': 'l2update', 'product_id': 'BTC-USD', 'changes': [['sell', '38374.16', '0.00000000']], 'time': '2021-05-20T03:55:50.179115Z'}
{'type': 'l2update', 'product_id': 'BTC-USD', 'changes': [['sell', '38416.18', '0.00000000']], 'time': '2021-05-20T03:55:50.180642Z'}
{'type': 'l2update', 'product_id': 'BTC-USD', 'changes': [['sell', '38457.97', '0.00000000']], 'time': '2021-05-20T03:55:50.186037Z'}
{'type': 'l2update', 'product_id': 'BTC-USD', 'changes': [['sell', '38353.12', '0.00000000']], 'time': '2021-05-20T03:55:50.191225Z'}
{'type': 'l2update', 'product_id': 'BTC-USD', 'changes': [['buy', '38297.05', '0.01000000']], 'time': '2021-05-20T03:55:50.192495Z'}
{'type': 'l2update', 'product_id': 'BTC-USD', 'changes': [['buy', '38301.92', '0.00000000']], 'time': '2021-05-20T03:55:50.192826Z'}
{'type': 'l2update', 'product_id': 'BTC-USD', 'changes': [['sell', '38394.95', '0.02604509']], 'time': '2021-05-20T03:55:50.197245Z'}
{'type': 'l2update', 'product_id': 'BTC-USD', 'changes': [['buy', '38305.73', '0.00000000']], 'time': '2021-05-20T03:55:50.202026Z'}
{'type': 'l2update', 'product_id': 'BTC-USD', 'changes': [['sell', '43100.00', '1.09530000']], 'time': '2021-05-20T03:55:50.215169Z'}
{'type': 'l2update', 'product_id': 'BTC-USD', 'changes': [['buy', '38312.93', '0.01000000']], 'time': '2021-05-20T03:55:50.219297Z'}
{'type': 'l2update', 'product_id': 'BTC-USD', 'changes': [['sell', '38378.18', '0.01000000']], 'time': '2021-05-20T03:55:50.219528Z'}
{'type': 'l2update', 'product_id': 'BTC-USD', 'changes': [['sell', '38508.99', '0.01000000']], 'time': '2021-05-20T03:55:50.220416Z'}
{'type': 'l2update', 'product_id': 'BTC-USD', 'changes': [['sell', '38347.63', '0.00000000']], 'time': '2021-05-20T03:55:50.223227Z'}
{'type': 'l2update', 'product_id': 'BTC-USD', 'changes': [['buy', '38310.01', '0.00000000']], 'time': '2021-05-20T03:55:50.223377Z'}
{'type': 'l2update', 'product_id': 'BTC-USD', 'changes': [['sell', '43100.00', '3.04780000']], 'time': '2021-05-20T03:55:50.237455Z'}
{'type': 'l2update', 'product_id': 'BTC-USD', 'changes': [['buy', '38311.54', '0.02000000']], 'time': '2021-05-20T03:55:50.237521Z'}
{'type': 'l2update', 'product_id': 'BTC-USD', 'changes': [['sell', '38347.71', '0.00000000']], 'time': '2021-05-20T03:55:50.237785Z'}
{'type': 'l2update', 'product_id': 'BTC-USD', 'changes': [['buy', '38295.76', '0.01000000']], 'time': '2021-05-20T03:55:50.237829Z'}
{'type': 'l2update', 'product_id': 'BTC-USD', 'changes': [['buy', '38283.45', '0.01363814']], 'time': '2021-05-20T03:55:50.253302Z'}
{'type': 'l2update', 'product_id': 'BTC-USD', 'changes': [['sell', '38359.20', '1.43700000']], 'time': '2021-05-20T03:55:50.253376Z'}
{'type': 'l2update', 'product_id': 'BTC-USD', 'changes': [['sell', '38347.69', '0.00000000']], 'time': '2021-05-20T03:55:50.253557Z'}
{'type': 'l2update', 'product_id': 'BTC-USD', 'changes': [['sell', '38401.05', '0.05455256']], 'time': '2021-05-20T03:55:50.254740Z'}
{'type': 'l2update', 'product_id': 'BTC-USD', 'changes': [['buy', '38280.60', '0.05455256']], 'time': '2021-05-20T03:55:50.254848Z'}
{'type': 'l2update', 'product_id': 'BTC-USD', 'changes': [['sell', '38356.55', '0.04269412']], 'time': '2021-05-20T03:55:50.262280Z'}
{'type': 'l2update', 'product_id': 'BTC-USD', 'changes': [['buy', '38313.94', '0.00000000']], 'time': '2021-05-20T03:55:50.264272Z'}
{'type': 'l2update', 'product_id': 'BTC-USD', 'changes': [['buy', '38309.12', '0.46110000']], 'time': '2021-05-20T03:55:50.267959Z'}
{'type': 'l2update', 'product_id': 'BTC-USD', 'changes': [['sell', '38347.68', '0.00000000']], 'time': '2021-05-20T03:55:50.269960Z'}
{'type': 'l2update', 'product_id': 'BTC-USD', 'changes': [['buy', '38315.62', '0.00000000']], 'time': '2021-05-20T03:55:50.277073Z'}
{'type': 'l2update', 'product_id': 'BTC-USD', 'changes': [['buy', '38314.82', '0.00000000']], 'time': '2021-05-20T03:55:50.277073Z'}
{'type': 'l2update', 'product_id': 'BTC-USD', 'changes': [['sell', '38375.25', '0.00000000']], 'time': '2021-05-20T03:55:50.279037Z'}
{'type': 'l2update', 'product_id': 'BTC-USD', 'changes': [['buy', '38333.72', '0.84700000']], 'time': '2021-05-20T03:55:50.279752Z'}
{'type': 'l2update', 'product_id': 'BTC-USD', 'changes': [['buy', '38183.20', '0.04954203']], 'time': '2021-05-20T03:55:50.282430Z'}
{'type': 'l2update', 'product_id': 'BTC-USD', 'changes': [['sell', '38373.64', '0.44260000']], 'time': '2021-05-20T03:55:50.282539Z'}
{'type': 'l2update', 'product_id': 'BTC-USD', 'changes': [['sell', '38347.70', '0.00000000']], 'time': '2021-05-20T03:55:50.282560Z'}
{'type': 'l2update', 'product_id': 'BTC-USD', 'changes': [['sell', '38349.00', '0.00000000']], 'time': '2021-05-20T03:55:50.288169Z'}
{'type': 'l2update', 'product_id': 'BTC-USD', 'changes': [['sell', '38359.25', '0.00000000']], 'time': '2021-05-20T03:55:50.293952Z'}
{'type': 'l2update', 'product_id': 'BTC-USD', 'changes': [['sell', '38359.19', '0.50000000']], 'time': '2021-05-20T03:55:50.295095Z'}
{'type': 'l2update', 'product_id': 'BTC-USD', 'changes': [['buy', '38311.80', '0.00000000']], 'time': '2021-05-20T03:55:50.296797Z'}
{'type': 'l2update', 'product_id': 'BTC-USD', 'changes': [['sell', '38362.18', '0.00000000']], 'time': '2021-05-20T03:55:50.296847Z'}
{'type': 'l2update', 'product_id': 'BTC-USD', 'changes': [['buy', '38141.59', '0.00000000']], 'time': '2021-05-20T03:55:50.298490Z'}
{'type': 'l2update', 'product_id': 'BTC-USD', 'changes': [['sell', '38508.99', '0.00000000']], 'time': '2021-05-20T03:55:50.298867Z'}
{'type': 'l2update', 'product_id': 'BTC-USD', 'changes': [['buy', '38318.29', '0.02400000']], 'time': '2021-05-20T03:55:50.301223Z'}
{'type': 'l2update', 'product_id': 'BTC-USD', 'changes': [['buy', '38317.49', '0.02400000']], 'time': '2021-05-20T03:55:50.301223Z'}
{'type': 'l2update', 'product_id': 'BTC-USD', 'changes': [['buy', '38316.68', '0.02400000']], 'time': '2021-05-20T03:55:50.301223Z'}
{'type': 'l2update', 'product_id': 'BTC-USD', 'changes': [['sell', '38356.54', '2.48969908']], 'time': '2021-05-20T03:55:50.306186Z'}
{'type': 'l2update', 'product_id': 'BTC-USD', 'changes': [['sell', '38359.20', '1.99100000']], 'time': '2021-05-20T03:55:50.306400Z'}
{'type': 'l2update', 'product_id': 'BTC-USD', 'changes': [['sell', '38359.19', '0.55561714']], 'time': '2021-05-20T03:55:50.307190Z'}
{'type': 'l2update', 'product_id': 'BTC-USD', 'changes': [['buy', '38309.12', '0.00000000']], 'time': '2021-05-20T03:55:50.308228Z'}
{'type': 'l2update', 'product_id': 'BTC-USD', 'changes': [['sell', '38376.35', '0.03000000']], 'time': '2021-05-20T03:55:50.310755Z'}
{'type': 'l2update', 'product_id': 'BTC-USD', 'changes': [['sell', '38482.28', '0.01000000']], 'time': '2021-05-20T03:55:50.316918Z'}
{'type': 'l2update', 'product_id': 'BTC-USD', 'changes': [['sell', '38373.64', '0.00000000']], 'time': '2021-05-20T03:55:50.316998Z'}
{'type': 'l2update', 'product_id': 'BTC-USD', 'changes': [['buy', '38154.97', '0.01081700']], 'time': '2021-05-20T03:55:50.317552Z'}
{'type': 'l2update', 'product_id': 'BTC-USD', 'changes': [['sell', '38479.72', '0.00000000']], 'time': '2021-05-20T03:55:50.318110Z'}
{'type': 'l2update', 'product_id': 'BTC-USD', 'changes': [['sell', '38465.20', '0.00000000']], 'time': '2021-05-20T03:55:50.318223Z'}
{'type': 'l2update', 'product_id': 'BTC-USD', 'changes': [['sell', '38380.05', '0.00000000']], 'time': '2021-05-20T03:55:50.320228Z'}
{'type': 'l2update', 'product_id': 'BTC-USD', 'changes': [['sell', '38387.42', '0.04000000']], 'time': '2021-05-20T03:55:50.335729Z'}
{'type': 'l2update', 'product_id': 'BTC-USD', 'changes': [['sell', '38448.84', '0.01300429']], 'time': '2021-05-20T03:55:50.340247Z'}
{'type': 'l2update', 'product_id': 'BTC-USD', 'changes': [['sell', '38376.35', '0.00000000']], 'time': '2021-05-20T03:55:50.341098Z'}
{'type': 'l2update', 'product_id': 'BTC-USD', 'changes': [['buy', '38177.20', '0.00000000']], 'time': '2021-05-20T03:55:50.341168Z'}
{'type': 'l2update', 'product_id': 'BTC-USD', 'changes': [['buy', '38297.05', '0.00000000']], 'time': '2021-05-20T03:55:50.353326Z'}
{'type': 'l2update', 'product_id': 'BTC-USD', 'changes': [['buy', '38292.37', '0.00000000']], 'time': '2021-05-20T03:55:50.404187Z'}
{'type': 'l2update', 'product_id': 'BTC-USD', 'changes': [['buy', '38312.65', '0.00000000']], 'time': '2021-05-20T03:55:50.404421Z'}
{'type': 'l2update', 'product_id': 'BTC-USD', 'changes': [['buy', '38342.91', '0.11248035']], 'time': '2021-05-20T03:55:50.404615Z'}
{'type': 'l2update', 'product_id': 'BTC-USD', 'changes': [['sell', '38387.53', '0.05000000']], 'time': '2021-05-20T03:55:50.404727Z'}
{'type': 'l2update', 'product_id': 'BTC-USD', 'changes': [['sell', '38385.92', '0.04887182']], 'time': '2021-05-20T03:55:50.404993Z'}
{'type': 'l2update', 'product_id': 'BTC-USD', 'changes': [['sell', '38460.13', '0.01174966']], 'time': '2021-05-20T03:55:50.405436Z'}
{'type': 'l2update', 'product_id': 'BTC-USD', 'changes': [['buy', '38187.81', '0.05161671']], 'time': '2021-05-20T03:55:50.405893Z'}
{'type': 'l2update', 'product_id': 'BTC-USD', 'changes': [['sell', '38359.19', '0.50000000']], 'time': '2021-05-20T03:55:50.416863Z'}
{'type': 'l2update', 'product_id': 'BTC-USD', 'changes': [['sell', '38396.82', '0.00000000']], 'time': '2021-05-20T03:55:50.420056Z'}
{'type': 'l2update', 'product_id': 'BTC-USD', 'changes': [['buy', '38212.15', '0.00000000']], 'time': '2021-05-20T03:55:50.421480Z'}
{'type': 'l2update', 'product_id': 'BTC-USD', 'changes': [['sell', '38378.18', '0.00000000']], 'time': '2021-05-20T03:55:50.430308Z'}
{'type': 'l2update', 'product_id': 'BTC-USD', 'changes': [['buy', '38295.76', '0.00000000']], 'time': '2021-05-20T03:55:50.433614Z'}
{'type': 'l2update', 'product_id': 'BTC-USD', 'changes': [['buy', '38187.81', '0.00000000']], 'time': '2021-05-20T03:55:50.479015Z'}
{'type': 'l2update', 'product_id': 'BTC-USD', 'changes': [['buy', '38233.01', '0.50000000']], 'time': '2021-05-20T03:55:50.482867Z'}
{'type': 'l2update', 'product_id': 'BTC-USD', 'changes': [['buy', '38309.45', '0.01000000']], 'time': '2021-05-20T03:55:50.483194Z'}
{'type': 'l2update', 'product_id': 'BTC-USD', 'changes': [['buy', '38308.45', '0.47600000']], 'time': '2021-05-20T03:55:50.484831Z'}
{'type': 'l2update', 'product_id': 'BTC-USD', 'changes': [['buy', '38224.67', '0.02731687']], 'time': '2021-05-20T03:55:50.487416Z'}
{'type': 'l2update', 'product_id': 'BTC-USD', 'changes': [['buy', '38306.25', '0.40700000']], 'time': '2021-05-20T03:55:50.488846Z'}
{'type': 'l2update', 'product_id': 'BTC-USD', 'changes': [['buy', '38335.93', '0.52100000']], 'time': '2021-05-20T03:55:50.488859Z'}
{'type': 'l2update', 'product_id': 'BTC-USD', 'changes': [['sell', '38387.38', '0.03000000']], 'time': '2021-05-20T03:55:50.489998Z'}
{'type': 'l2update', 'product_id': 'BTC-USD', 'changes': [['buy', '38342.91', '0.11214187']], 'time': '2021-05-20T03:55:50.490298Z'}
{'type': 'l2update', 'product_id': 'BTC-USD', 'changes': [['sell', '38356.55', '0.00000000']], 'time': '2021-05-20T03:55:50.492961Z'}
{'type': 'l2update', 'product_id': 'BTC-USD', 'changes': [['buy', '38183.20', '0.00000000']], 'time': '2021-05-20T03:55:50.494691Z'}
{'type': 'l2update', 'product_id': 'BTC-USD', 'changes': [['buy', '38308.45', '0.00000000']], 'time': '2021-05-20T03:55:50.494798Z'}
{'type': 'l2update', 'product_id': 'BTC-USD', 'changes': [['sell', '38518.21', '0.30077670']], 'time': '2021-05-20T03:55:50.504221Z'}
{'type': 'l2update', 'product_id': 'BTC-USD', 'changes': [['sell', '38377.50', '0.02000000']], 'time': '2021-05-20T03:55:50.508149Z'}
{'type': 'l2update', 'product_id': 'BTC-USD', 'changes': [['sell', '38401.05', '0.00000000']], 'time': '2021-05-20T03:55:50.516213Z'}
{'type': 'l2update', 'product_id': 'BTC-USD', 'changes': [['sell', '38356.53', '0.18981474']], 'time': '2021-05-20T03:55:50.520337Z'}
{'type': 'l2update', 'product_id': 'BTC-USD', 'changes': [['sell', '38376.08', '0.40130000']], 'time': '2021-05-20T03:55:50.523850Z'}
{'type': 'l2update', 'product_id': 'BTC-USD', 'changes': [['buy', '38335.94', '0.10000000']], 'time': '2021-05-20T03:55:50.524089Z'}
{'type': 'l2update', 'product_id': 'BTC-USD', 'changes': [['sell', '38356.54', '0.00000000']], 'time': '2021-05-20T03:55:50.525362Z'}
{'type': 'l2update', 'product_id': 'BTC-USD', 'changes': [['buy', '38335.93', '0.00000000']], 'time': '2021-05-20T03:55:50.528701Z'}
{'type': 'l2update', 'product_id': 'BTC-USD', 'changes': [['sell', '38377.50', '0.00000000']], 'time': '2021-05-20T03:55:50.528918Z'}
{'type': 'l2update', 'product_id': 'BTC-USD', 'changes': [['sell', '38359.18', '0.05561714']], 'time': '2021-05-20T03:55:50.541168Z'}
{'type': 'l2update', 'product_id': 'BTC-USD', 'changes': [['sell', '38356.49', '0.55300000']], 'time': '2021-05-20T03:55:50.541346Z'}
{'type': 'l2update', 'product_id': 'BTC-USD', 'changes': [['sell', '38518.21', '0.00000000']], 'time': '2021-05-20T03:55:50.550595Z'}
{'type': 'l2update', 'product_id': 'BTC-USD', 'changes': [['sell', '38359.18', '2.54531622']], 'time': '2021-05-20T03:55:50.556290Z'}
{'type': 'l2update', 'product_id': 'BTC-USD', 'changes': [['sell', '38383.78', '0.01000000']], 'time': '2021-05-20T03:55:50.562913Z'}
{'type': 'l2update', 'product_id': 'BTC-USD', 'changes': [['sell', '38388.44', '0.01363735']], 'time': '2021-05-20T03:55:50.562981Z'}
{'type': 'l2update', 'product_id': 'BTC-USD', 'changes': [['sell', '38342.92', '0.11474060']], 'time': '2021-05-20T03:55:50.569069Z'}
{'type': 'l2update', 'product_id': 'BTC-USD', 'changes': [['buy', '38335.94', '0.50135082']], 'time': '2021-05-20T03:55:50.572800Z'}
{'type': 'l2update', 'product_id': 'BTC-USD', 'changes': [['sell', '38482.28', '0.00000000']], 'time': '2021-05-20T03:55:50.575673Z'}
{'type': 'l2update', 'product_id': 'BTC-USD', 'changes': [['sell', '38529.01', '0.00000000']], 'time': '2021-05-20T03:55:50.576809Z'}
{'type': 'l2update', 'product_id': 'BTC-USD', 'changes': [['buy', '38282.50', '0.00000000']], 'time': '2021-05-20T03:55:50.578544Z'}
{'type': 'l2update', 'product_id': 'BTC-USD', 'changes': [['sell', '38349.66', '0.00000000']], 'time': '2021-05-20T03:55:50.585795Z'}
{'type': 'l2update', 'product_id': 'BTC-USD', 'changes': [['sell', '38386.37', '0.02000000']], 'time': '2021-05-20T03:55:50.586739Z'}
{'type': 'l2update', 'product_id': 'BTC-USD', 'changes': [['buy', '38152.56', '0.00000000']], 'time': '2021-05-20T03:55:50.591508Z'}
{'type': 'l2update', 'product_id': 'BTC-USD', 'changes': [['buy', '38340.64', '0.04908544']], 'time': '2021-05-20T03:55:50.592027Z'}
{'type': 'l2update', 'product_id': 'BTC-USD', 'changes': [['sell', '38356.53', '0.00000000']], 'time': '2021-05-20T03:55:50.593004Z'}
{'type': 'l2update', 'product_id': 'BTC-USD', 'changes': [['buy', '38312.93', '0.00000000']], 'time': '2021-05-20T03:55:50.597009Z'}
{'type': 'l2update', 'product_id': 'BTC-USD', 'changes': [['buy', '38220.02', '0.00000000']], 'time': '2021-05-20T03:55:50.599007Z'}
{'type': 'l2update', 'product_id': 'BTC-USD', 'changes': [['buy', '38296.48', '0.10000000']], 'time': '2021-05-20T03:55:50.600170Z'}
{'type': 'l2update', 'product_id': 'BTC-USD', 'changes': [['sell', '38547.91', '0.01000000']], 'time': '2021-05-20T03:55:50.600467Z'}
{'type': 'l2update', 'product_id': 'BTC-USD', 'changes': [['sell', '38422.88', '0.01000000']], 'time': '2021-05-20T03:55:50.600744Z'}
{'type': 'l2update', 'product_id': 'BTC-USD', 'changes': [['sell', '38359.17', '0.06657974']], 'time': '2021-05-20T03:55:50.600764Z'}
{'type': 'l2update', 'product_id': 'BTC-USD', 'changes': [['sell', '38649.94', '0.00000000']], 'time': '2021-05-20T03:55:50.603201Z'}
{'type': 'l2update', 'product_id': 'BTC-USD', 'changes': [['buy', '38311.54', '0.00000000']], 'time': '2021-05-20T03:55:50.606475Z'}
{'type': 'l2update', 'product_id': 'BTC-USD', 'changes': [['buy', '38233.02', '0.01000000']], 'time': '2021-05-20T03:55:50.615800Z'}
{'type': 'l2update', 'product_id': 'BTC-USD', 'changes': [['sell', '38359.18', '2.48969908']], 'time': '2021-05-20T03:55:50.615889Z'}
{'type': 'l2update', 'product_id': 'BTC-USD', 'changes': [['buy', '38311.58', '0.49390000']], 'time': '2021-05-20T03:55:50.615943Z'}
{'type': 'l2update', 'product_id': 'BTC-USD', 'changes': [['buy', '38315.21', '0.06350289']], 'time': '2021-05-20T03:55:50.615965Z'}
{'type': 'l2update', 'product_id': 'BTC-USD', 'changes': [['sell', '38363.52', '0.05559213']], 'time': '2021-05-20T03:55:50.615965Z'}
{'type': 'l2update', 'product_id': 'BTC-USD', 'changes': [['buy', '38167.19', '0.01000000']], 'time': '2021-05-20T03:55:50.616533Z'}
{'type': 'l2update', 'product_id': 'BTC-USD', 'changes': [['buy', '38335.88', '0.00000000']], 'time': '2021-05-20T03:55:50.616794Z'}
{'type': 'l2update', 'product_id': 'BTC-USD', 'changes': [['sell', '38665.02', '0.01293158']], 'time': '2021-05-20T03:55:50.622935Z'}
{'type': 'l2update', 'product_id': 'BTC-USD', 'changes': [['sell', '38446.29', '0.00000000']], 'time': '2021-05-20T03:55:50.627189Z'}
{'type': 'l2update', 'product_id': 'BTC-USD', 'changes': [['buy', '38306.65', '0.01000000']], 'time': '2021-05-20T03:55:50.628192Z'}
{'type': 'l2update', 'product_id': 'BTC-USD', 'changes': [['sell', '38422.88', '0.00000000']], 'time': '2021-05-20T03:55:50.629382Z'}
{'type': 'l2update', 'product_id': 'BTC-USD', 'changes': [['buy', '38303.71', '0.00000000']], 'time': '2021-05-20T03:55:50.634030Z'}
{'type': 'l2update', 'product_id': 'BTC-USD', 'changes': [['buy', '38335.94', '0.10000000']], 'time': '2021-05-20T03:55:50.640967Z'}
{'type': 'l2update', 'product_id': 'BTC-USD', 'changes': [['sell', '38359.17', '0.00000000']], 'time': '2021-05-20T03:55:50.641464Z'}
{'type': 'l2update', 'product_id': 'BTC-USD', 'changes': [['sell', '38486.85', '0.01000000']], 'time': '2021-05-20T03:55:50.649145Z'}
{'type': 'l2update', 'product_id': 'BTC-USD', 'changes': [['buy', '38300.97', '0.02000000']], 'time': '2021-05-20T03:55:50.649374Z'}
{'type': 'l2update', 'product_id': 'BTC-USD', 'changes': [['buy', '38233.66', '0.00000000']], 'time': '2021-05-20T03:55:50.653439Z'}
{'type': 'l2update', 'product_id': 'BTC-USD', 'changes': [['buy', '38297.91', '0.00000000']], 'time': '2021-05-20T03:55:50.661791Z'}
{'type': 'l2update', 'product_id': 'BTC-USD', 'changes': [['sell', '38665.02', '0.00000000']], 'time': '2021-05-20T03:55:50.663532Z'}
{'type': 'l2update', 'product_id': 'BTC-USD', 'changes': [['buy', '38260.72', '0.06951254']], 'time': '2021-05-20T03:55:50.668086Z'}
{'type': 'l2update', 'product_id': 'BTC-USD', 'changes': [['sell', '38432.97', '0.00000000']], 'time': '2021-05-20T03:55:50.671488Z'}
{'type': 'l2update', 'product_id': 'BTC-USD', 'changes': [['buy', '37544.90', '0.06392155']], 'time': '2021-05-20T03:55:50.675684Z'}
{'type': 'l2update', 'product_id': 'BTC-USD', 'changes': [['buy', '38231.37', '0.00000000']], 'time': '2021-05-20T03:55:50.676625Z'}
{'type': 'l2update', 'product_id': 'BTC-USD', 'changes': [['sell', '38634.85', '0.01294168']], 'time': '2021-05-20T03:55:50.686573Z'}
{'type': 'l2update', 'product_id': 'BTC-USD', 'changes': [['sell', '38470.14', '0.00000000']], 'time': '2021-05-20T03:55:50.686726Z'}
{'type': 'l2update', 'product_id': 'BTC-USD', 'changes': [['sell', '39154.96', '0.06564063']], 'time': '2021-05-20T03:55:50.692494Z'}
{'type': 'l2update', 'product_id': 'BTC-USD', 'changes': [['buy', '38323.09', '0.00000000']], 'time': '2021-05-20T03:55:50.719056Z'}
{'type': 'l2update', 'product_id': 'BTC-USD', 'changes': [['sell', '38445.65', '0.01000000']], 'time': '2021-05-20T03:55:50.723702Z'}
{'type': 'l2update', 'product_id': 'BTC-USD', 'changes': [['buy', '38309.45', '0.00000000']], 'time': '2021-05-20T03:55:50.733000Z'}
{'type': 'l2update', 'product_id': 'BTC-USD', 'changes': [['buy', '38315.21', '0.00000000']], 'time': '2021-05-20T03:55:50.742473Z'}
{'type': 'l2update', 'product_id': 'BTC-USD', 'changes': [['sell', '38363.52', '0.00000000']], 'time': '2021-05-20T03:55:50.742473Z'}
{'type': 'l2update', 'product_id': 'BTC-USD', 'changes': [['buy', '38260.80', '0.01000000']], 'time': '2021-05-20T03:55:50.748447Z'}
{'type': 'l2update', 'product_id': 'BTC-USD', 'changes': [['sell', '38487.80', '0.01033182']], 'time': '2021-05-20T03:55:50.748840Z'}
{'type': 'l2update', 'product_id': 'BTC-USD', 'changes': [['buy', '38333.73', '0.99315797']], 'time': '2021-05-20T03:55:50.748959Z'}
{'type': 'l2update', 'product_id': 'BTC-USD', 'changes': [['sell', '38401.72', '0.05454770']], 'time': '2021-05-20T03:55:50.758410Z'}
{'type': 'l2update', 'product_id': 'BTC-USD', 'changes': [['buy', '38318.06', '0.05633206']], 'time': '2021-05-20T03:55:50.759812Z'}
{'type': 'l2update', 'product_id': 'BTC-USD', 'changes': [['sell', '38359.39', '0.04842697']], 'time': '2021-05-20T03:55:50.759812Z'}
{'type': 'l2update', 'product_id': 'BTC-USD', 'changes': [['sell', '38465.62', '0.00000000']], 'time': '2021-05-20T03:55:50.760315Z'}
{'type': 'l2update', 'product_id': 'BTC-USD', 'changes': [['sell', '38487.80', '0.00000000']], 'time': '2021-05-20T03:55:50.771331Z'}
{'type': 'l2update', 'product_id': 'BTC-USD', 'changes': [['sell', '38473.33', '0.04278730']], 'time': '2021-05-20T03:55:50.789544Z'}
{'type': 'l2update', 'product_id': 'BTC-USD', 'changes': [['buy', '38335.99', '0.84600000']], 'time': '2021-05-20T03:55:50.802188Z'}
{'type': 'l2update', 'product_id': 'BTC-USD', 'changes': [['sell', '38485.97', '0.00000000']], 'time': '2021-05-20T03:55:50.823012Z'}
{'type': 'l2update', 'product_id': 'BTC-USD', 'changes': [['sell', '38376.16', '0.00000000']], 'time': '2021-05-20T03:55:50.825259Z'}
{'type': 'l2update', 'product_id': 'BTC-USD', 'changes': [['buy', '38320.35', '0.00000000']], 'time': '2021-05-20T03:55:50.830312Z'}
{'type': 'l2update', 'product_id': 'BTC-USD', 'changes': [['sell', '38388.44', '0.00000000']], 'time': '2021-05-20T03:55:50.832340Z'}
{'type': 'l2update', 'product_id': 'BTC-USD', 'changes': [['buy', '38336.00', '0.10000000']], 'time': '2021-05-20T03:55:50.834903Z'}
{'type': 'l2update', 'product_id': 'BTC-USD', 'changes': [['sell', '38474.35', '0.01000000']], 'time': '2021-05-20T03:55:50.835525Z'}
{'type': 'l2update', 'product_id': 'BTC-USD', 'changes': [['buy', '38333.68', '0.06657974']], 'time': '2021-05-20T03:55:50.835635Z'}
{'type': 'l2update', 'product_id': 'BTC-USD', 'changes': [['buy', '38323.15', '0.00000000']], 'time': '2021-05-20T03:55:50.838417Z'}
{'type': 'l2update', 'product_id': 'BTC-USD', 'changes': [['sell', '38448.84', '0.00000000']], 'time': '2021-05-20T03:55:50.844901Z'}
{'type': 'l2update', 'product_id': 'BTC-USD', 'changes': [['buy', '38297.91', '1.20000000']], 'time': '2021-05-20T03:55:50.848904Z'}
{'type': 'l2update', 'product_id': 'BTC-USD', 'changes': [['buy', '38333.78', '0.52000000']], 'time': '2021-05-20T03:55:50.848933Z'}
{'type': 'l2update', 'product_id': 'BTC-USD', 'changes': [['buy', '38333.68', '0.00000000']], 'time': '2021-05-20T03:55:50.852633Z'}
{'type': 'l2update', 'product_id': 'BTC-USD', 'changes': [['sell', '38498.49', '0.00000000']], 'time': '2021-05-20T03:55:50.852776Z'}
{'type': 'l2update', 'product_id': 'BTC-USD', 'changes': [['sell', '38472.65', '0.01299624']], 'time': '2021-05-20T03:55:50.858746Z'}
{'type': 'l2update', 'product_id': 'BTC-USD', 'changes': [['sell', '38432.97', '1.20000000']], 'time': '2021-05-20T03:55:50.858909Z'}
{'type': 'l2update', 'product_id': 'BTC-USD', 'changes': [['buy', '38333.74', '0.06657974']], 'time': '2021-05-20T03:55:50.863473Z'}
{'type': 'l2update', 'product_id': 'BTC-USD', 'changes': [['sell', '38534.59', '0.02210204']], 'time': '2021-05-20T03:55:50.863603Z'}
{'type': 'l2update', 'product_id': 'BTC-USD', 'changes': [['buy', '38316.68', '0.00000000']], 'time': '2021-05-20T03:55:50.874587Z'}
{'type': 'l2update', 'product_id': 'BTC-USD', 'changes': [['buy', '38198.00', '0.14810000']], 'time': '2021-05-20T03:55:50.876166Z'}
{'type': 'l2update', 'product_id': 'BTC-USD', 'changes': [['buy', '38333.74', '0.00000000']], 'time': '2021-05-20T03:55:50.877851Z'}
{'type': 'l2update', 'product_id': 'BTC-USD', 'changes': [['buy', '38318.29', '0.00000000']], 'time': '2021-05-20T03:55:50.879425Z'}
{'type': 'l2update', 'product_id': 'BTC-USD', 'changes': [['buy', '38317.49', '0.00000000']], 'time': '2021-05-20T03:55:50.879425Z'}
{'type': 'l2update', 'product_id': 'BTC-USD', 'changes': [['sell', '38468.76', '0.00000000']], 'time': '2021-05-20T03:55:50.883768Z'}
{'type': 'l2update', 'product_id': 'BTC-USD', 'changes': [['buy', '38258.18', '2.48540000']], 'time': '2021-05-20T03:55:50.895658Z'}
{'type': 'l2update', 'product_id': 'BTC-USD', 'changes': [['buy', '38323.15', '0.06657974']], 'time': '2021-05-20T03:55:50.895851Z'}
{'type': 'l2update', 'product_id': 'BTC-USD', 'changes': [['buy', '38323.85', '0.02400000']], 'time': '2021-05-20T03:55:50.902503Z'}
{'type': 'l2update', 'product_id': 'BTC-USD', 'changes': [['buy', '38323.04', '0.02400000']], 'time': '2021-05-20T03:55:50.902503Z'}
{'type': 'l2update', 'product_id': 'BTC-USD', 'changes': [['buy', '38322.24', '0.02400000']], 'time': '2021-05-20T03:55:50.902503Z'}
{'type': 'l2update', 'product_id': 'BTC-USD', 'changes': [['buy', '38322.24', '0.00000000']], 'time': '2021-05-20T03:55:50.910496Z'}
{'type': 'l2update', 'product_id': 'BTC-USD', 'changes': [['buy', '38323.04', '0.00000000']], 'time': '2021-05-20T03:55:50.916665Z'}
{'type': 'l2update', 'product_id': 'BTC-USD', 'changes': [['sell', '38359.39', '0.00000000']], 'time': '2021-05-20T03:55:50.921346Z'}
{'type': 'l2update', 'product_id': 'BTC-USD', 'changes': [['buy', '38323.85', '0.00000000']], 'time': '2021-05-20T03:55:50.922527Z'}
{'type': 'l2update', 'product_id': 'BTC-USD', 'changes': [['buy', '38316.24', '0.00000000']], 'time': '2021-05-20T03:55:50.925415Z'}
{'type': 'l2update', 'product_id': 'BTC-USD', 'changes': [['sell', '38513.59', '0.00000000']], 'time': '2021-05-20T03:55:50.928000Z'}
{'type': 'l2update', 'product_id': 'BTC-USD', 'changes': [['sell', '38433.59', '0.01000000']], 'time': '2021-05-20T03:55:50.929935Z'}
{'type': 'l2update', 'product_id': 'BTC-USD', 'changes': [['buy', '38304.86', '0.00000000']], 'time': '2021-05-20T03:55:50.931058Z'}
{'type': 'l2update', 'product_id': 'BTC-USD', 'changes': [['buy', '38275.47', '0.00000000']], 'time': '2021-05-20T03:55:50.937252Z'}
{'type': 'l2update', 'product_id': 'BTC-USD', 'changes': [['buy', '38294.56', '0.00000000']], 'time': '2021-05-20T03:55:50.941726Z'}
{'type': 'l2update', 'product_id': 'BTC-USD', 'changes': [['sell', '38537.67', '0.01000000']], 'time': '2021-05-20T03:55:50.950469Z'}
{'type': 'l2update', 'product_id': 'BTC-USD', 'changes': [['buy', '38327.68', '0.02400000']], 'time': '2021-05-20T03:55:50.950588Z'}
{'type': 'l2update', 'product_id': 'BTC-USD', 'changes': [['buy', '38326.87', '0.02400000']], 'time': '2021-05-20T03:55:50.950588Z'}
{'type': 'l2update', 'product_id': 'BTC-USD', 'changes': [['buy', '38326.07', '0.02400000']], 'time': '2021-05-20T03:55:50.950588Z'}
{'type': 'l2update', 'product_id': 'BTC-USD', 'changes': [['sell', '38359.18', '0.00000000']], 'time': '2021-05-20T03:55:50.953280Z'}
{'type': 'l2update', 'product_id': 'BTC-USD', 'changes': [['sell', '38364.52', '0.04331480']], 'time': '2021-05-20T03:55:50.959348Z'}
{'type': 'l2update', 'product_id': 'BTC-USD', 'changes': [['sell', '38345.07', '0.78292838']], 'time': '2021-05-20T03:55:50.959668Z'}
{'type': 'l2update', 'product_id': 'BTC-USD', 'changes': [['sell', '38537.67', '0.00000000']], 'time': '2021-05-20T03:55:50.959743Z'}
{'type': 'l2update', 'product_id': 'BTC-USD', 'changes': [['buy', '38335.94', '0.00000000']], 'time': '2021-05-20T03:55:50.962663Z'}
{'type': 'l2update', 'product_id': 'BTC-USD', 'changes': [['sell', '38359.19', '0.00000000']], 'time': '2021-05-20T03:55:50.966079Z'}
{'type': 'l2update', 'product_id': 'BTC-USD', 'changes': [['buy', '38327.68', '0.00000000']], 'time': '2021-05-20T03:55:50.967145Z'}
{'type': 'l2update', 'product_id': 'BTC-USD', 'changes': [['buy', '38326.87', '0.00000000']], 'time': '2021-05-20T03:55:50.967145Z'}
{'type': 'l2update', 'product_id': 'BTC-USD', 'changes': [['buy', '38326.07', '0.00000000']], 'time': '2021-05-20T03:55:50.967145Z'}
{'type': 'l2update', 'product_id': 'BTC-USD', 'changes': [['buy', '38335.99', '0.00000000']], 'time': '2021-05-20T03:55:50.968513Z'}
{'type': 'l2update', 'product_id': 'BTC-USD', 'changes': [['buy', '38335.87', '0.00000000']], 'time': '2021-05-20T03:55:50.972217Z'}
{'type': 'l2update', 'product_id': 'BTC-USD', 'changes': [['buy', '38326.26', '0.52172289']], 'time': '2021-05-20T03:55:50.983756Z'}
{'type': 'l2update', 'product_id': 'BTC-USD', 'changes': [['buy', '38333.78', '1.36600000']], 'time': '2021-05-20T03:55:50.983773Z'}
{'type': 'l2update', 'product_id': 'BTC-USD', 'changes': [['sell', '38510.53', '0.01000000']], 'time': '2021-05-20T03:55:50.983880Z'}
{'type': 'l2update', 'product_id': 'BTC-USD', 'changes': [['sell', '38359.19', '0.06657974']], 'time': '2021-05-20T03:55:50.983968Z'}
{'type': 'l2update', 'product_id': 'BTC-USD', 'changes': [['sell', '38355.66', '0.04814485']], 'time': '2021-05-20T03:55:50.983987Z'}
{'type': 'l2update', 'product_id': 'BTC-USD', 'changes': [['sell', '38342.92', '0.31474060']], 'time': '2021-05-20T03:55:50.984051Z'}
{'type': 'l2update', 'product_id': 'BTC-USD', 'changes': [['sell', '38370.90', '0.50000000']], 'time': '2021-05-20T03:55:50.984086Z'}
{'type': 'l2update', 'product_id': 'BTC-USD', 'changes': [['sell', '38356.48', '2.48969908']], 'time': '2021-05-20T03:55:50.984387Z'}
{'type': 'l2update', 'product_id': 'BTC-USD', 'changes': [['buy', '38330.16', '0.02400000']], 'time': '2021-05-20T03:55:50.984850Z'}
{'type': 'l2update', 'product_id': 'BTC-USD', 'changes': [['buy', '38329.36', '0.02400000']], 'time': '2021-05-20T03:55:50.984850Z'}
{'type': 'l2update', 'product_id': 'BTC-USD', 'changes': [['buy', '38328.56', '0.02400000']], 'time': '2021-05-20T03:55:50.984850Z'}
{'type': 'l2update', 'product_id': 'BTC-USD', 'changes': [['buy', '38224.67', '0.00000000']], 'time': '2021-05-20T03:55:50.985923Z'}
{'type': 'l2update', 'product_id': 'BTC-USD', 'changes': [['sell', '38517.95', '0.30077505']], 'time': '2021-05-20T03:55:50.987724Z'}
{'type': 'l2update', 'product_id': 'BTC-USD', 'changes': [['buy', '38311.58', '0.00000000']], 'time': '2021-05-20T03:55:50.988741Z'}
{'type': 'l2update', 'product_id': 'BTC-USD', 'changes': [['sell', '38510.53', '0.00000000']], 'time': '2021-05-20T03:55:50.993249Z'}
{'type': 'l2update', 'product_id': 'BTC-USD', 'changes': [['sell', '38370.91', '0.00000000']], 'time': '2021-05-20T03:55:50.993280Z'}
{'type': 'l2update', 'product_id': 'BTC-USD', 'changes': [['buy', '38333.73', '0.00000000']], 'time': '2021-05-20T03:55:50.994108Z'}
{'type': 'l2update', 'product_id': 'BTC-USD', 'changes': [['sell', '38352.46', '0.52175764']], 'time': '2021-05-20T03:55:50.994924Z'}
{'type': 'l2update', 'product_id': 'BTC-USD', 'changes': [['buy', '38333.67', '0.00000000']], 'time': '2021-05-20T03:55:50.996901Z'}
{'type': 'l2update', 'product_id': 'BTC-USD', 'changes': [['buy', '38330.16', '0.00000000']], 'time': '2021-05-20T03:55:50.998094Z'}
{'type': 'l2update', 'product_id': 'BTC-USD', 'changes': [['buy', '38329.36', '0.00000000']], 'time': '2021-05-20T03:55:50.998094Z'}
{'type': 'l2update', 'product_id': 'BTC-USD', 'changes': [['buy', '38328.56', '0.00000000']], 'time': '2021-05-20T03:55:50.998094Z'}
{'type': 'l2update', 'product_id': 'BTC-USD', 'changes': [['sell', '38517.95', '0.00000000']], 'time': '2021-05-20T03:55:51.000097Z'}
{'type': 'l2update', 'product_id': 'BTC-USD', 'changes': [['buy', '38237.19', '0.01136687']], 'time': '2021-05-20T03:55:51.003300Z'}
{'type': 'l2update', 'product_id': 'BTC-USD', 'changes': [['buy', '38310.42', '0.45110000']], 'time': '2021-05-20T03:55:51.003374Z'}
{'type': 'l2update', 'product_id': 'BTC-USD', 'changes': [['sell', '38359.27', '1.21957974']], 'time': '2021-05-20T03:55:51.003600Z'}
{'type': 'l2update', 'product_id': 'BTC-USD', 'changes': [['buy', '38333.79', '0.06657974']], 'time': '2021-05-20T03:55:51.003656Z'}
{'type': 'l2update', 'product_id': 'BTC-USD', 'changes': [['buy', '38318.06', '0.00000000']], 'time': '2021-05-20T03:55:51.004746Z'}
{'type': 'l2update', 'product_id': 'BTC-USD', 'changes': [['sell', '38364.52', '0.00000000']], 'time': '2021-05-20T03:55:51.004746Z'}
{'type': 'l2update', 'product_id': 'BTC-USD', 'changes': [['buy', '38323.15', '0.00000000']], 'time': '2021-05-20T03:55:51.004837Z'}
{'type': 'l2update', 'product_id': 'BTC-USD', 'changes': [['buy', '38260.80', '0.00000000']], 'time': '2021-05-20T03:55:51.010821Z'}
{'type': 'l2update', 'product_id': 'BTC-USD', 'changes': [['sell', '38359.27', '1.15300000']], 'time': '2021-05-20T03:55:51.012146Z'}
{'type': 'l2update', 'product_id': 'BTC-USD', 'changes': [['sell', '38537.67', '0.01000000']], 'time': '2021-05-20T03:55:51.012265Z'}
{'type': 'l2update', 'product_id': 'BTC-USD', 'changes': [['sell', '38370.89', '0.05000000']], 'time': '2021-05-20T03:55:51.012285Z'}
{'type': 'l2update', 'product_id': 'BTC-USD', 'changes': [['buy', '38322.46', '0.52177345']], 'time': '2021-05-20T03:55:51.012320Z'}
{'type': 'l2update', 'product_id': 'BTC-USD', 'changes': [['buy', '38333.79', '0.00000000']], 'time': '2021-05-20T03:55:51.012404Z'}
{'type': 'l2update', 'product_id': 'BTC-USD', 'changes': [['sell', '38359.19', '0.00000000']], 'time': '2021-05-20T03:55:51.012588Z'}
{'type': 'l2update', 'product_id': 'BTC-USD', 'changes': [['buy', '38323.16', '0.99315797']], 'time': '2021-05-20T03:55:51.018200Z'}
{'type': 'l2update', 'product_id': 'BTC-USD', 'changes': [['buy', '38273.20', '0.01000000']], 'time': '2021-05-20T03:55:51.022188Z'}
{'type': 'l2update', 'product_id': 'BTC-USD', 'changes': [['sell', '38356.47', '0.06657974']], 'time': '2021-05-20T03:55:51.026661Z'}
{'type': 'l2update', 'product_id': 'BTC-USD', 'changes': [['buy', '37544.90', '0.13051798']], 'time': '2021-05-20T03:55:51.026678Z'}
{'type': 'l2update', 'product_id': 'BTC-USD', 'changes': [['sell', '38354.07', '0.52173887']], 'time': '2021-05-20T03:55:51.026879Z'}
{'type': 'l2update', 'product_id': 'BTC-USD', 'changes': [['buy', '38333.78', '0.52000000']], 'time': '2021-05-20T03:55:51.028702Z'}
{'type': 'l2update', 'product_id': 'BTC-USD', 'changes': [['buy', '38333.72', '0.00000000']], 'time': '2021-05-20T03:55:51.028718Z'}
{'type': 'l2update', 'product_id': 'BTC-USD', 'changes': [['buy', '38318.07', '0.04077184']], 'time': '2021-05-20T03:55:51.034373Z'}
{'type': 'l2update', 'product_id': 'BTC-USD', 'changes': [['sell', '38359.40', '0.06074755']], 'time': '2021-05-20T03:55:51.034373Z'}
{'type': 'l2update', 'product_id': 'BTC-USD', 'changes': [['buy', '38326.27', '0.06657974']], 'time': '2021-05-20T03:55:51.034485Z'}
{'type': 'l2update', 'product_id': 'BTC-USD', 'changes': [['buy', '38325.03', '0.02400000']], 'time': '2021-05-20T03:55:51.034538Z'}
{'type': 'l2update', 'product_id': 'BTC-USD', 'changes': [['buy', '38324.22', '0.02400000']], 'time': '2021-05-20T03:55:51.034538Z'}
{'type': 'l2update', 'product_id': 'BTC-USD', 'changes': [['buy', '38323.42', '0.02400000']], 'time': '2021-05-20T03:55:51.034538Z'}
{'type': 'l2update', 'product_id': 'BTC-USD', 'changes': [['sell', '38356.47', '0.00000000']], 'time': '2021-05-20T03:55:51.036666Z'}
{'type': 'l2update', 'product_id': 'BTC-USD', 'changes': [['sell', '39145.04', '0.06412386']], 'time': '2021-05-20T03:55:51.038472Z'}
{'type': 'l2update', 'product_id': 'BTC-USD', 'changes': [['buy', '38318.93', '0.52182238']], 'time': '2021-05-20T03:55:51.038852Z'}
{'type': 'l2update', 'product_id': 'BTC-USD', 'changes': [['sell', '38534.59', '0.00000000']], 'time': '2021-05-20T03:55:51.040015Z'}
{'type': 'l2update', 'product_id': 'BTC-USD', 'changes': [['buy', '38325.03', '0.00000000']], 'time': '2021-05-20T03:55:51.041180Z'}
{'type': 'l2update', 'product_id': 'BTC-USD', 'changes': [['buy', '38324.22', '0.00000000']], 'time': '2021-05-20T03:55:51.041180Z'}
{'type': 'l2update', 'product_id': 'BTC-USD', 'changes': [['sell', '38354.07', '0.58831861']], 'time': '2021-05-20T03:55:51.045894Z'}
{'type': 'l2update', 'product_id': 'BTC-USD', 'changes': [['buy', '38323.42', '0.00000000']], 'time': '2021-05-20T03:55:51.047321Z'}
{'type': 'l2update', 'product_id': 'BTC-USD', 'changes': [['sell', '38365.44', '1.30447414']], 'time': '2021-05-20T03:55:51.049897Z'}
{'type': 'l2update', 'product_id': 'BTC-USD', 'changes': [['sell', '38354.06', '0.06657974']], 'time': '2021-05-20T03:55:51.049993Z'}
{'type': 'l2update', 'product_id': 'BTC-USD', 'changes': [['sell', '38354.07', '0.52173887']], 'time': '2021-05-20T03:55:51.053709Z'}
{'type': 'l2update', 'product_id': 'BTC-USD', 'changes': [['sell', '38515.49', '0.01971193']], 'time': '2021-05-20T03:55:51.054853Z'}
{'type': 'l2update', 'product_id': 'BTC-USD', 'changes': [['sell', '38448.32', '0.00000000']], 'time': '2021-05-20T03:55:51.058019Z'}
{'type': 'l2update', 'product_id': 'BTC-USD', 'changes': [['sell', '38393.56', '0.05444214']], 'time': '2021-05-20T03:55:51.059613Z'}
{'type': 'l2update', 'product_id': 'BTC-USD', 'changes': [['buy', '38310.92', '0.78258434']], 'time': '2021-05-20T03:55:51.067515Z'}
{'type': 'l2update', 'product_id': 'BTC-USD', 'changes': [['sell', '38468.21', '0.01000000']], 'time': '2021-05-20T03:55:51.072433Z'}
{'type': 'l2update', 'product_id': 'BTC-USD', 'changes': [['buy', '38319.80', '0.02400000']], 'time': '2021-05-20T03:55:51.073564Z'}
{'type': 'l2update', 'product_id': 'BTC-USD', 'changes': [['buy', '38319.00', '0.02400000']], 'time': '2021-05-20T03:55:51.073564Z'}
{'type': 'l2update', 'product_id': 'BTC-USD', 'changes': [['buy', '38318.19', '0.02400000']], 'time': '2021-05-20T03:55:51.073564Z'}
{'type': 'l2update', 'product_id': 'BTC-USD', 'changes': [['sell', '38354.06', '0.00000000']], 'time': '2021-05-20T03:55:51.076504Z'}
{'type': 'l2update', 'product_id': 'BTC-USD', 'changes': [['buy', '38310.42', '0.00000000']], 'time': '2021-05-20T03:55:51.078564Z'}
{'type': 'l2update', 'product_id': 'BTC-USD', 'changes': [['sell', '38537.67', '0.00000000']], 'time': '2021-05-20T03:55:51.078642Z'}
{'type': 'l2update', 'product_id': 'BTC-USD', 'changes': [['sell', '38370.33', '1.30430723']], 'time': '2021-05-20T03:55:51.084632Z'}
{'type': 'l2update', 'product_id': 'BTC-USD', 'changes': [['sell', '38356.47', '0.06657974']], 'time': '2021-05-20T03:55:51.085452Z'}
{'type': 'l2update', 'product_id': 'BTC-USD', 'changes': [['sell', '38370.89', '0.00000000']], 'time': '2021-05-20T03:55:51.096066Z'}
{'type': 'l2update', 'product_id': 'BTC-USD', 'changes': [['sell', '38582.38', '0.00777557']], 'time': '2021-05-20T03:55:51.096678Z'}
{'type': 'l2update', 'product_id': 'BTC-USD', 'changes': [['buy', '38295.54', '2.60861445']], 'time': '2021-05-20T03:55:51.096734Z'}
{'type': 'l2update', 'product_id': 'BTC-USD', 'changes': [['sell', '38370.90', '0.00000000']], 'time': '2021-05-20T03:55:51.100822Z'}
{'type': 'l2update', 'product_id': 'BTC-USD', 'changes': [['sell', '38582.38', '0.00000000']], 'time': '2021-05-20T03:55:51.104197Z'}
{'type': 'l2update', 'product_id': 'BTC-USD', 'changes': [['sell', '38515.20', '0.00000000']], 'time': '2021-05-20T03:55:51.108941Z'}
{'type': 'l2update', 'product_id': 'BTC-USD', 'changes': [['sell', '38370.32', '0.05000000']], 'time': '2021-05-20T03:55:51.110595Z'}
{'type': 'l2update', 'product_id': 'BTC-USD', 'changes': [['buy', '38333.78', '0.00000000']], 'time': '2021-05-20T03:55:51.110830Z'}
{'type': 'l2update', 'product_id': 'BTC-USD', 'changes': [['sell', '38354.02', '1.04500000']], 'time': '2021-05-20T03:55:51.115130Z'}
{'type': 'l2update', 'product_id': 'BTC-USD', 'changes': [['sell', '38374.79', '2.60975469']], 'time': '2021-05-20T03:55:51.116355Z'}
{'type': 'l2update', 'product_id': 'BTC-USD', 'changes': [['sell', '39451.86', '0.00000000']], 'time': '2021-05-20T03:55:51.116615Z'}
{'type': 'l2update', 'product_id': 'BTC-USD', 'changes': [['sell', '39449.99', '0.00000000']], 'time': '2021-05-20T03:55:51.116615Z'}
{'type': 'l2update', 'product_id': 'BTC-USD', 'changes': [['sell', '39499.99', '0.05000000']], 'time': '2021-05-20T03:55:51.116615Z'}
{'type': 'l2update', 'product_id': 'BTC-USD', 'changes': [['buy', '38326.27', '0.00000000']], 'time': '2021-05-20T03:55:51.120531Z'}
{'type': 'l2update', 'product_id': 'BTC-USD', 'changes': [['sell', '38502.03', '0.01000000']], 'time': '2021-05-20T03:55:51.123042Z'}
{'type': 'l2update', 'product_id': 'BTC-USD', 'changes': [['sell', '38349.04', '0.50000000']], 'time': '2021-05-20T03:55:51.123241Z'}
{'type': 'l2update', 'product_id': 'BTC-USD', 'changes': [['sell', '38515.49', '0.00000000']], 'time': '2021-05-20T03:55:51.126148Z'}
{'type': 'l2update', 'product_id': 'BTC-USD', 'changes': [['sell', '39488.99', '0.06390000']], 'time': '2021-05-20T03:55:51.128381Z'}
{'type': 'l2update', 'product_id': 'BTC-USD', 'changes': [['sell', '39486.71', '0.05430000']], 'time': '2021-05-20T03:55:51.128381Z'}
{'type': 'l2update', 'product_id': 'BTC-USD', 'changes': [['sell', '39485.48', '0.00650000']], 'time': '2021-05-20T03:55:51.128381Z'}
{'type': 'l2update', 'product_id': 'BTC-USD', 'changes': [['buy', '37500.01', '0.08320000']], 'time': '2021-05-20T03:55:51.128381Z'}
{'type': 'l2update', 'product_id': 'BTC-USD', 'changes': [['buy', '38295.53', '2.60861445']], 'time': '2021-05-20T03:55:51.129157Z'}
{'type': 'l2update', 'product_id': 'BTC-USD', 'changes': [['sell', '38433.59', '0.00000000']], 'time': '2021-05-20T03:55:51.129433Z'}
{'type': 'l2update', 'product_id': 'BTC-USD', 'changes': [['sell', '38634.85', '0.00000000']], 'time': '2021-05-20T03:55:51.129612Z'}
{'type': 'l2update', 'product_id': 'BTC-USD', 'changes': [['sell', '38502.03', '0.00000000']], 'time': '2021-05-20T03:55:51.131913Z'}
{'type': 'l2update', 'product_id': 'BTC-USD', 'changes': [['sell', '38354.06', '0.06657974']], 'time': '2021-05-20T03:55:51.133120Z'}
{'type': 'l2update', 'product_id': 'BTC-USD', 'changes': [['sell', '38396.22', '0.01363611']], 'time': '2021-05-20T03:55:51.133169Z'}
{'type': 'l2update', 'product_id': 'BTC-USD', 'changes': [['buy', '38319.80', '0.00000000']], 'time': '2021-05-20T03:55:51.133185Z'}
{'type': 'l2update', 'product_id': 'BTC-USD', 'changes': [['buy', '37544.90', '0.06659643']], 'time': '2021-05-20T03:55:51.134825Z'}
{'type': 'l2update', 'product_id': 'BTC-USD', 'changes': [['sell', '39154.96', '0.00000000']], 'time': '2021-05-20T03:55:51.140638Z'}
{'type': 'l2update', 'product_id': 'BTC-USD', 'changes': [['sell', '38354.06', '0.00000000']], 'time': '2021-05-20T03:55:51.142321Z'}
{'type': 'l2update', 'product_id': 'BTC-USD', 'changes': [['sell', '38382.35', '2.60935630']], 'time': '2021-05-20T03:55:51.143805Z'}
{'type': 'l2update', 'product_id': 'BTC-USD', 'changes': [['sell', '38458.35', '0.01213500']], 'time': '2021-05-20T03:55:51.143895Z'}
{'type': 'l2update', 'product_id': 'BTC-USD', 'changes': [['sell', '38665.02', '0.01293158']], 'time': '2021-05-20T03:55:51.144261Z'}
{'type': 'l2update', 'product_id': 'BTC-USD', 'changes': [['sell', '38509.85', '0.01000000']], 'time': '2021-05-20T03:55:51.149744Z'}
{'type': 'l2update', 'product_id': 'BTC-USD', 'changes': [['buy', '38317.11', '0.02400000']], 'time': '2021-05-20T03:55:51.149766Z'}
{'type': 'l2update', 'product_id': 'BTC-USD', 'changes': [['sell', '38498.79', '0.01722136']], 'time': '2021-05-20T03:55:51.152118Z'}
{'type': 'l2update', 'product_id': 'BTC-USD', 'changes': [['sell', '38541.79', '0.01000000']], 'time': '2021-05-20T03:55:51.155149Z'}
{'type': 'l2update', 'product_id': 'BTC-USD', 'changes': [['sell', '38387.52', '2.60900663']], 'time': '2021-05-20T03:55:51.155173Z'}
{'type': 'l2update', 'product_id': 'BTC-USD', 'changes': [['buy', '38059.02', '0.30000000']], 'time': '2021-05-20T03:55:51.163615Z'}
{'type': 'l2update', 'product_id': 'BTC-USD', 'changes': [['buy', '38318.07', '0.00000000']], 'time': '2021-05-20T03:55:51.167792Z'}
{'type': 'l2update', 'product_id': 'BTC-USD', 'changes': [['buy', '38312.72', '0.41010000']], 'time': '2021-05-20T03:55:51.171084Z'}
{'type': 'l2update', 'product_id': 'BTC-USD', 'changes': [['sell', '38354.07', '0.00000000']], 'time': '2021-05-20T03:55:51.173576Z'}
{'type': 'l2update', 'product_id': 'BTC-USD', 'changes': [['sell', '38370.33', '0.00000000']], 'time': '2021-05-20T03:55:51.179724Z'}
{'type': 'l2update', 'product_id': 'BTC-USD', 'changes': [['buy', '38273.20', '0.00000000']], 'time': '2021-05-20T03:55:51.180270Z'}
{'type': 'l2update', 'product_id': 'BTC-USD', 'changes': [['buy', '38285.60', '0.01000000']], 'time': '2021-05-20T03:55:51.195939Z'}
{'type': 'l2update', 'product_id': 'BTC-USD', 'changes': [['sell', '38509.85', '0.00000000']], 'time': '2021-05-20T03:55:51.203131Z'}
{'type': 'l2update', 'product_id': 'BTC-USD', 'changes': [['sell', '38486.85', '0.00000000']], 'time': '2021-05-20T03:55:51.205389Z'}
{'type': 'l2update', 'product_id': 'BTC-USD', 'changes': [['sell', '38496.67', '0.01000000']], 'time': '2021-05-20T03:55:51.214375Z'}
{'type': 'l2update', 'product_id': 'BTC-USD', 'changes': [['sell', '43100.00', '1.09530000']], 'time': '2021-05-20T03:55:51.214808Z'}
{'type': 'l2update', 'product_id': 'BTC-USD', 'changes': [['sell', '38349.04', '0.00000000']], 'time': '2021-05-20T03:55:51.227863Z'}
{'type': 'l2update', 'product_id': 'BTC-USD', 'changes': [['buy', '38296.48', '0.00000000']], 'time': '2021-05-20T03:55:51.229096Z'}
{'type': 'l2update', 'product_id': 'BTC-USD', 'changes': [['sell', '38496.67', '0.00000000']], 'time': '2021-05-20T03:55:51.234670Z'}
{'type': 'l2update', 'product_id': 'BTC-USD', 'changes': [['buy', '38318.06', '0.06122439']], 'time': '2021-05-20T03:55:51.238177Z'}
{'type': 'l2update', 'product_id': 'BTC-USD', 'changes': [['sell', '38469.30', '0.04447447']], 'time': '2021-05-20T03:55:51.238241Z'}
{'type': 'l2update', 'product_id': 'BTC-USD', 'changes': [['sell', '43100.00', '5.02120000']], 'time': '2021-05-20T03:55:51.244267Z'}
{'type': 'l2update', 'product_id': 'BTC-USD', 'changes': [['buy', '38289.49', '0.10000000']], 'time': '2021-05-20T03:55:51.248259Z'}
{'type': 'l2update', 'product_id': 'BTC-USD', 'changes': [['sell', '38509.85', '0.01000000']], 'time': '2021-05-20T03:55:51.249411Z'}
{'type': 'l2update', 'product_id': 'BTC-USD', 'changes': [['sell', '38345.06', '0.50000000']], 'time': '2021-05-20T03:55:51.249424Z'}
{'type': 'l2update', 'product_id': 'BTC-USD', 'changes': [['sell', '38376.08', '0.00000000']], 'time': '2021-05-20T03:55:51.263591Z'}
{'type': 'l2update', 'product_id': 'BTC-USD', 'changes': [['sell', '38374.08', '0.40720000']], 'time': '2021-05-20T03:55:51.274956Z'}
{'type': 'l2update', 'product_id': 'BTC-USD', 'changes': [['buy', '38312.72', '0.00000000']], 'time': '2021-05-20T03:55:51.280189Z'}
{'type': 'l2update', 'product_id': 'BTC-USD', 'changes': [['sell', '38541.79', '0.00000000']], 'time': '2021-05-20T03:55:51.282970Z'}
{'type': 'l2update', 'product_id': 'BTC-USD', 'changes': [['sell', '38374.08', '0.00000000']], 'time': '2021-05-20T03:55:51.284820Z'}
{'type': 'l2update', 'product_id': 'BTC-USD', 'changes': [['buy', '38326.31', '0.84600000']], 'time': '2021-05-20T03:55:51.289043Z'}
{'type': 'l2update', 'product_id': 'BTC-USD', 'changes': [['buy', '38326.26', '0.00000000']], 'time': '2021-05-20T03:55:51.291841Z'}
{'type': 'l2update', 'product_id': 'BTC-USD', 'changes': [['buy', '38310.97', '0.46320000']], 'time': '2021-05-20T03:55:51.296422Z'}
{'type': 'l2update', 'product_id': 'BTC-USD', 'changes': [['sell', '38529.51', '0.01000000']], 'time': '2021-05-20T03:55:51.296876Z'}
{'type': 'l2update', 'product_id': 'BTC-USD', 'changes': [['sell', '38509.85', '0.00000000']], 'time': '2021-05-20T03:55:51.296888Z'}
{'type': 'l2update', 'product_id': 'BTC-USD', 'changes': [['buy', '38310.97', '0.00000000']], 'time': '2021-05-20T03:55:51.300454Z'}
{'type': 'l2update', 'product_id': 'BTC-USD', 'changes': [['sell', '38612.29', '0.00000000']], 'time': '2021-05-20T03:55:51.303507Z'}
{'type': 'l2update', 'product_id': 'BTC-USD', 'changes': [['buy', '38318.06', '0.00000000']], 'time': '2021-05-20T03:55:51.305236Z'}
{'type': 'l2update', 'product_id': 'BTC-USD', 'changes': [['sell', '38359.40', '0.00000000']], 'time': '2021-05-20T03:55:51.305236Z'}
{'type': 'l2update', 'product_id': 'BTC-USD', 'changes': [['sell', '38496.67', '0.01000000']], 'time': '2021-05-20T03:55:51.314581Z'}
{'type': 'l2update', 'product_id': 'BTC-USD', 'changes': [['sell', '38665.02', '0.00000000']], 'time': '2021-05-20T03:55:51.320001Z'}
{'type': 'l2update', 'product_id': 'BTC-USD', 'changes': [['buy', '38326.31', '0.00000000']], 'time': '2021-05-20T03:55:51.320565Z'}
{'type': 'l2update', 'product_id': 'BTC-USD', 'changes': [['buy', '38319.00', '0.00000000']], 'time': '2021-05-20T03:55:51.329254Z'}
{'type': 'l2update', 'product_id': 'BTC-USD', 'changes': [['sell', '38619.76', '0.01000000']], 'time': '2021-05-20T03:55:51.334200Z'}
{'type': 'l2update', 'product_id': 'BTC-USD', 'changes': [['buy', '38295.29', '0.00000000']], 'time': '2021-05-20T03:55:51.335470Z'}
{'type': 'l2update', 'product_id': 'BTC-USD', 'changes': [['buy', '38308.50', '0.04830871']], 'time': '2021-05-20T03:55:51.341570Z'}
{'type': 'l2update', 'product_id': 'BTC-USD', 'changes': [['sell', '38353.17', '0.04390280']], 'time': '2021-05-20T03:55:51.341570Z'}
{'type': 'l2update', 'product_id': 'BTC-USD', 'changes': [['sell', '38342.92', '0.31222008']], 'time': '2021-05-20T03:55:51.341841Z'}
{'type': 'l2update', 'product_id': 'BTC-USD', 'changes': [['sell', '38347.67', '1.11400000']], 'time': '2021-05-20T03:55:51.342228Z'}
{'type': 'l2update', 'product_id': 'BTC-USD', 'changes': [['sell', '38387.38', '0.00000000']], 'time': '2021-05-20T03:55:51.342606Z'}
{'type': 'l2update', 'product_id': 'BTC-USD', 'changes': [['buy', '38323.14', '0.00000000']], 'time': '2021-05-20T03:55:51.342692Z'}
{'type': 'l2update', 'product_id': 'BTC-USD', 'changes': [['sell', '38374.47', '0.04882423']], 'time': '2021-05-20T03:55:51.346417Z'}
{'type': 'l2update', 'product_id': 'BTC-USD', 'changes': [['buy', '38176.42', '0.05036005']], 'time': '2021-05-20T03:55:51.346488Z'}
{'type': 'l2update', 'product_id': 'BTC-USD', 'changes': [['buy', '38316.03', '0.02400000']], 'time': '2021-05-20T03:55:51.346743Z'}
{'type': 'l2update', 'product_id': 'BTC-USD', 'changes': [['sell', '38387.42', '0.00000000']], 'time': '2021-05-20T03:55:51.349888Z'}
{'type': 'l2update', 'product_id': 'BTC-USD', 'changes': [['sell', '38351.55', '0.05083527']], 'time': '2021-05-20T03:55:51.350810Z'}
{'type': 'l2update', 'product_id': 'BTC-USD', 'changes': [['sell', '38387.53', '0.00000000']], 'time': '2021-05-20T03:55:51.354614Z'}
{'type': 'l2update', 'product_id': 'BTC-USD', 'changes': [['buy', '38323.08', '0.00000000']], 'time': '2021-05-20T03:55:51.360259Z'}
{'type': 'l2update', 'product_id': 'BTC-USD', 'changes': [['buy', '38306.83', '0.00000000']], 'time': '2021-05-20T03:55:51.361953Z'}
{'type': 'l2update', 'product_id': 'BTC-USD', 'changes': [['buy', '38302.30', '0.05000000']], 'time': '2021-05-20T03:55:51.367251Z'}
{'type': 'l2update', 'product_id': 'BTC-USD', 'changes': [['buy', '38318.19', '0.00000000']], 'time': '2021-05-20T03:55:51.367290Z'}
{'type': 'l2update', 'product_id': 'BTC-USD', 'changes': [['buy', '38317.11', '0.00000000']], 'time': '2021-05-20T03:55:51.367290Z'}
{'type': 'l2update', 'product_id': 'BTC-USD', 'changes': [['sell', '38453.20', '0.00000000']], 'time': '2021-05-20T03:55:51.369607Z'}
{'type': 'l2update', 'product_id': 'BTC-USD', 'changes': [['sell', '38458.72', '0.00000000']], 'time': '2021-05-20T03:55:51.369775Z'}
{'type': 'l2update', 'product_id': 'BTC-USD', 'changes': [['sell', '38376.72', '0.46080000']], 'time': '2021-05-20T03:55:51.377319Z'}
{'type': 'l2update', 'product_id': 'BTC-USD', 'changes': [['buy', '38176.42', '0.00000000']], 'time': '2021-05-20T03:55:51.379068Z'}
{'type': 'l2update', 'product_id': 'BTC-USD', 'changes': [['buy', '38320.28', '0.00000000']], 'time': '2021-05-20T03:55:51.383108Z'}
{'type': 'l2update', 'product_id': 'BTC-USD', 'changes': [['sell', '38380.80', '0.03000000']], 'time': '2021-05-20T03:55:51.387550Z'}
{'type': 'l2update', 'product_id': 'BTC-USD', 'changes': [['sell', '38441.06', '0.02526975']], 'time': '2021-05-20T03:55:51.388914Z'}
{'type': 'l2update', 'product_id': 'BTC-USD', 'changes': [['sell', '38373.48', '0.39490432']], 'time': '2021-05-20T03:55:51.388981Z'}
{'type': 'l2update', 'product_id': 'BTC-USD', 'changes': [['buy', '38315.40', '0.02400000']], 'time': '2021-05-20T03:55:51.389626Z'}
{'type': 'l2update', 'product_id': 'BTC-USD', 'changes': [['buy', '38314.60', '0.02400000']], 'time': '2021-05-20T03:55:51.389626Z'}
{'type': 'l2update', 'product_id': 'BTC-USD', 'changes': [['sell', '38370.42', '0.04838752']], 'time': '2021-05-20T03:55:51.389916Z'}
{'type': 'l2update', 'product_id': 'BTC-USD', 'changes': [['buy', '38284.87', '0.00000000']], 'time': '2021-05-20T03:55:51.391058Z'}
{'type': 'l2update', 'product_id': 'BTC-USD', 'changes': [['buy', '37544.90', '0.00000000']], 'time': '2021-05-20T03:55:51.392973Z'}
{'type': 'l2update', 'product_id': 'BTC-USD', 'changes': [['sell', '38442.39', '0.01000000']], 'time': '2021-05-20T03:55:51.395029Z'}
{'type': 'l2update', 'product_id': 'BTC-USD', 'changes': [['buy', '38309.43', '0.49500000']], 'time': '2021-05-20T03:55:51.395817Z'}
{'type': 'l2update', 'product_id': 'BTC-USD', 'changes': [['buy', '38314.03', '0.00000000']], 'time': '2021-05-20T03:55:51.397349Z'}
{'type': 'l2update', 'product_id': 'BTC-USD', 'changes': [['sell', '39145.04', '0.00000000']], 'time': '2021-05-20T03:55:51.399183Z'}
{'type': 'l2update', 'product_id': 'BTC-USD', 'changes': [['sell', '38380.86', '0.04000000']], 'time': '2021-05-20T03:55:51.399215Z'}
{'type': 'l2update', 'product_id': 'BTC-USD', 'changes': [['buy', '38316.03', '0.00000000']], 'time': '2021-05-20T03:55:51.400215Z'}
{'type': 'l2update', 'product_id': 'BTC-USD', 'changes': [['buy', '38309.43', '0.00000000']], 'time': '2021-05-20T03:55:51.402559Z'}
{'type': 'l2update', 'product_id': 'BTC-USD', 'changes': [['sell', '38547.91', '0.00000000']], 'time': '2021-05-20T03:55:51.403489Z'}
{'type': 'l2update', 'product_id': 'BTC-USD', 'changes': [['sell', '38381.30', '0.05000000']], 'time': '2021-05-20T03:55:51.414833Z'}
{'type': 'l2update', 'product_id': 'BTC-USD', 'changes': [['sell', '38356.48', '0.00000000']], 'time': '2021-05-20T03:55:51.415188Z'}
{'type': 'l2update', 'product_id': 'BTC-USD', 'changes': [['buy', '38342.91', '0.00004187']], 'time': '2021-05-20T03:55:51.417566Z'}
{'type': 'l2update', 'product_id': 'BTC-USD', 'changes': [['sell', '38534.41', '0.01000000']], 'time': '2021-05-20T03:55:51.418752Z'}
{'type': 'l2update', 'product_id': 'BTC-USD', 'changes': [['buy', '38313.37', '0.02400000']], 'time': '2021-05-20T03:55:51.418972Z'}
{'type': 'l2update', 'product_id': 'BTC-USD', 'changes': [['sell', '38383.78', '0.00000000']], 'time': '2021-05-20T03:55:51.420412Z'}
{'type': 'l2update', 'product_id': 'BTC-USD', 'changes': [['buy', '38323.16', '0.00000000']], 'time': '2021-05-20T03:55:51.420444Z'}
{'type': 'l2update', 'product_id': 'BTC-USD', 'changes': [['buy', '38322.46', '0.00000000']], 'time': '2021-05-20T03:55:51.421220Z'}
{'type': 'l2update', 'product_id': 'BTC-USD', 'changes': [['sell', '38398.74', '0.37247717']], 'time': '2021-05-20T03:55:51.426468Z'}
{'type': 'l2update', 'product_id': 'BTC-USD', 'changes': [['buy', '38315.40', '0.00000000']], 'time': '2021-05-20T03:55:51.427012Z'}
{'type': 'l2update', 'product_id': 'BTC-USD', 'changes': [['sell', '38386.37', '0.00000000']], 'time': '2021-05-20T03:55:51.427691Z'}
{'type': 'l2update', 'product_id': 'BTC-USD', 'changes': [['sell', '38342.92', '0.30320948']], 'time': '2021-05-20T03:55:51.429246Z'}
{'type': 'l2update', 'product_id': 'BTC-USD', 'changes': [['sell', '38352.46', '0.00000000']], 'time': '2021-05-20T03:55:51.429814Z'}
{'type': 'l2update', 'product_id': 'BTC-USD', 'changes': [['buy', '38340.64', '0.00000000']], 'time': '2021-05-20T03:55:51.431471Z'}
{'type': 'l2update', 'product_id': 'BTC-USD', 'changes': [['sell', '38355.66', '0.00000000']], 'time': '2021-05-20T03:55:51.431807Z'}
{'type': 'l2update', 'product_id': 'BTC-USD', 'changes': [['sell', '38374.47', '0.00000000']], 'time': '2021-05-20T03:55:51.433464Z'}
{'type': 'l2update', 'product_id': 'BTC-USD', 'changes': [['sell', '38376.35', '0.01000000']], 'time': '2021-05-20T03:55:51.442031Z'}
{'type': 'l2update', 'product_id': 'BTC-USD', 'changes': [['buy', '38172.19', '0.04861827']], 'time': '2021-05-20T03:55:51.442050Z'}
{'type': 'l2update', 'product_id': 'BTC-USD', 'changes': [['sell', '38342.92', '2.79290856']], 'time': '2021-05-20T03:55:51.442344Z'}
{'type': 'l2update', 'product_id': 'BTC-USD', 'changes': [['buy', '38318.93', '0.00000000']], 'time': '2021-05-20T03:55:51.443458Z'}
{'type': 'l2update', 'product_id': 'BTC-USD', 'changes': [['sell', '38342.92', '2.82290856']], 'time': '2021-05-20T03:55:51.446876Z'}
{'type': 'l2update', 'product_id': 'BTC-USD', 'changes': [['sell', '38376.72', '0.00000000']], 'time': '2021-05-20T03:55:51.446905Z'}
{'type': 'l2update', 'product_id': 'BTC-USD', 'changes': [['buy', '38334.78', '0.05008715']], 'time': '2021-05-20T03:55:51.450054Z'}
{'type': 'l2update', 'product_id': 'BTC-USD', 'changes': [['buy', '38312.33', '0.02400000']], 'time': '2021-05-20T03:55:51.450425Z'}
{'type': 'l2update', 'product_id': 'BTC-USD', 'changes': [['buy', '38295.53', '0.00000000']], 'time': '2021-05-20T03:55:51.453159Z'}
{'type': 'l2update', 'product_id': 'BTC-USD', 'changes': [['buy', '38308.50', '0.00000000']], 'time': '2021-05-20T03:55:51.453260Z'}
{'type': 'l2update', 'product_id': 'BTC-USD', 'changes': [['sell', '38353.17', '0.00000000']], 'time': '2021-05-20T03:55:51.453260Z'}
{'type': 'l2update', 'product_id': 'BTC-USD', 'changes': [['sell', '38496.67', '0.00000000']], 'time': '2021-05-20T03:55:51.453448Z'}
{'type': 'l2update', 'product_id': 'BTC-USD', 'changes': [['buy', '38309.57', '0.00000000']], 'time': '2021-05-20T03:55:51.453932Z'}
{'type': 'l2update', 'product_id': 'BTC-USD', 'changes': [['sell', '38441.06', '0.00000000']], 'time': '2021-05-20T03:55:51.456743Z'}
{'type': 'l2update', 'product_id': 'BTC-USD', 'changes': [['sell', '38376.35', '0.03000000']], 'time': '2021-05-20T03:55:51.457600Z'}
{'type': 'l2update', 'product_id': 'BTC-USD', 'changes': [['buy', '38319.03', '0.99315797']], 'time': '2021-05-20T03:55:51.458040Z'}
{'type': 'l2update', 'product_id': 'BTC-USD', 'changes': [['sell', '38425.59', '0.37294795']], 'time': '2021-05-20T03:55:51.464114Z'}
{'type': 'l2update', 'product_id': 'BTC-USD', 'changes': [['sell', '38394.96', '0.03528641']], 'time': '2021-05-20T03:55:51.464114Z'}
{'type': 'l2update', 'product_id': 'BTC-USD', 'changes': [['sell', '38509.85', '0.01000000']], 'time': '2021-05-20T03:55:51.467468Z'}
{'type': 'l2update', 'product_id': 'BTC-USD', 'changes': [['sell', '38473.33', '0.00000000']], 'time': '2021-05-20T03:55:51.468941Z'}
{'type': 'l2update', 'product_id': 'BTC-USD', 'changes': [['buy', '38314.60', '0.00000000']], 'time': '2021-05-20T03:55:51.470763Z'}
{'type': 'l2update', 'product_id': 'BTC-USD', 'changes': [['sell', '38429.54', '0.05129140']], 'time': '2021-05-20T03:55:51.471059Z'}
{'type': 'l2update', 'product_id': 'BTC-USD', 'changes': [['buy', '38314.65', '0.84700000']], 'time': '2021-05-20T03:55:51.471133Z'}
{'type': 'l2update', 'product_id': 'BTC-USD', 'changes': [['buy', '38313.37', '0.00000000']], 'time': '2021-05-20T03:55:51.477977Z'}
{'type': 'l2update', 'product_id': 'BTC-USD', 'changes': [['buy', '38312.33', '0.00000000']], 'time': '2021-05-20T03:55:51.477977Z'}
{'type': 'l2update', 'product_id': 'BTC-USD', 'changes': [['buy', '37544.90', '0.06337056']], 'time': '2021-05-20T03:55:51.478814Z'}
{'type': 'l2update', 'product_id': 'BTC-USD', 'changes': [['sell', '38460.13', '0.04759216']], 'time': '2021-05-20T03:55:51.487177Z'}
{'type': 'l2update', 'product_id': 'BTC-USD', 'changes': [['buy', '38311.05', '0.00000000']], 'time': '2021-05-20T03:55:51.488087Z'}
{'type': 'l2update', 'product_id': 'BTC-USD', 'changes': [['sell', '39155.12', '0.06628617']], 'time': '2021-05-20T03:55:51.495196Z'}
{'type': 'l2update', 'product_id': 'BTC-USD', 'changes': [['sell', '38379.03', '0.12700736']], 'time': '2021-05-20T03:55:51.495527Z'}
{'type': 'l2update', 'product_id': 'BTC-USD', 'changes': [['buy', '38302.85', '0.40150000']], 'time': '2021-05-20T03:55:51.495632Z'}
{'type': 'l2update', 'product_id': 'BTC-USD', 'changes': [['buy', '38307.86', '0.03934439']], 'time': '2021-05-20T03:55:51.495914Z'}
{'type': 'l2update', 'product_id': 'BTC-USD', 'changes': [['sell', '38352.53', '0.04423862']], 'time': '2021-05-20T03:55:51.495914Z'}
{'type': 'l2update', 'product_id': 'BTC-USD', 'changes': [['sell', '38472.65', '0.00000000']], 'time': '2021-05-20T03:55:51.499939Z'}
{'type': 'l2update', 'product_id': 'BTC-USD', 'changes': [['sell', '38425.59', '0.00000000']], 'time': '2021-05-20T03:55:51.504234Z'}
{'type': 'l2update', 'product_id': 'BTC-USD', 'changes': [['sell', '38414.75', '0.00000000']], 'time': '2021-05-20T03:55:51.504234Z'}
{'type': 'l2update', 'product_id': 'BTC-USD', 'changes': [['sell', '38404.68', '0.03401304']], 'time': '2021-05-20T03:55:51.504234Z'}
{'type': 'l2update', 'product_id': 'BTC-USD', 'changes': [['sell', '38399.93', '0.00000000']], 'time': '2021-05-20T03:55:51.504234Z'}
{'type': 'l2update', 'product_id': 'BTC-USD', 'changes': [['sell', '38398.74', '0.00000000']], 'time': '2021-05-20T03:55:51.504234Z'}
{'type': 'l2update', 'product_id': 'BTC-USD', 'changes': [['sell', '38395.37', '0.00000000']], 'time': '2021-05-20T03:55:51.504234Z'}
{'type': 'l2update', 'product_id': 'BTC-USD', 'changes': [['buy', '38302.85', '0.00000000']], 'time': '2021-05-20T03:55:51.504798Z'}
{'type': 'l2update', 'product_id': 'BTC-USD', 'changes': [['sell', '38445.65', '0.00000000']], 'time': '2021-05-20T03:55:51.510701Z'}
{'type': 'l2update', 'product_id': 'BTC-USD', 'changes': [['buy', '38336.01', '0.10543526']], 'time': '2021-05-20T03:55:51.511656Z'}
{'type': 'l2update', 'product_id': 'BTC-USD', 'changes': [['buy', '38308.91', '0.02400000']], 'time': '2021-05-20T03:55:51.511974Z'}
{'type': 'l2update', 'product_id': 'BTC-USD', 'changes': [['buy', '38308.11', '0.02400000']], 'time': '2021-05-20T03:55:51.511974Z'}
{'type': 'l2update', 'product_id': 'BTC-USD', 'changes': [['buy', '38307.31', '0.02400000']], 'time': '2021-05-20T03:55:51.511974Z'}
{'type': 'l2update', 'product_id': 'BTC-USD', 'changes': [['sell', '38388.17', '0.00000000']], 'time': '2021-05-20T03:55:51.515107Z'}
{'type': 'l2update', 'product_id': 'BTC-USD', 'changes': [['sell', '38459.77', '0.01300060']], 'time': '2021-05-20T03:55:51.520446Z'}
{'type': 'l2update', 'product_id': 'BTC-USD', 'changes': [['sell', '38457.47', '0.02940350']], 'time': '2021-05-20T03:55:51.524213Z'}
{'type': 'l2update', 'product_id': 'BTC-USD', 'changes': [['buy', '38297.91', '0.00000000']], 'time': '2021-05-20T03:55:51.530346Z'}
{'type': 'l2update', 'product_id': 'BTC-USD', 'changes': [['buy', '38237.19', '0.00000000']], 'time': '2021-05-20T03:55:51.532628Z'}
{'type': 'l2update', 'product_id': 'BTC-USD', 'changes': [['sell', '38619.76', '0.00000000']], 'time': '2021-05-20T03:55:51.536076Z'}
{'type': 'l2update', 'product_id': 'BTC-USD', 'changes': [['sell', '38432.97', '0.00000000']], 'time': '2021-05-20T03:55:51.537138Z'}
{'type': 'l2update', 'product_id': 'BTC-USD', 'changes': [['sell', '38621.11', '0.00000000']], 'time': '2021-05-20T03:55:51.539078Z'}
{'type': 'l2update', 'product_id': 'BTC-USD', 'changes': [['sell', '38365.44', '1.78667414']], 'time': '2021-05-20T03:55:51.542223Z'}
{'type': 'l2update', 'product_id': 'BTC-USD', 'changes': [['sell', '38571.84', '0.00648141']], 'time': '2021-05-20T03:55:51.542388Z'}
{'type': 'l2update', 'product_id': 'BTC-USD', 'changes': [['buy', '38219.66', '0.01136687']], 'time': '2021-05-20T03:55:51.546833Z'}
{'type': 'l2update', 'product_id': 'BTC-USD', 'changes': [['sell', '38379.03', '0.14112192']], 'time': '2021-05-20T03:55:51.546973Z'}
{'type': 'l2update', 'product_id': 'BTC-USD', 'changes': [['sell', '38437.20', '0.38280880']], 'time': '2021-05-20T03:55:51.550368Z'}
{'type': 'l2update', 'product_id': 'BTC-USD', 'changes': [['sell', '38431.30', '0.81093530']], 'time': '2021-05-20T03:55:51.550368Z'}
{'type': 'l2update', 'product_id': 'BTC-USD', 'changes': [['sell', '38420.07', '0.38973706']], 'time': '2021-05-20T03:55:51.550368Z'}
{'type': 'l2update', 'product_id': 'BTC-USD', 'changes': [['sell', '38409.62', '0.35417492']], 'time': '2021-05-20T03:55:51.550368Z'}
{'type': 'l2update', 'product_id': 'BTC-USD', 'changes': [['sell', '38391.00', '0.79080031']], 'time': '2021-05-20T03:55:51.550368Z'}
{'type': 'l2update', 'product_id': 'BTC-USD', 'changes': [['sell', '38382.83', '0.40758107']], 'time': '2021-05-20T03:55:51.550368Z'}
{'type': 'l2update', 'product_id': 'BTC-USD', 'changes': [['sell', '38379.03', '0.55283038']], 'time': '2021-05-20T03:55:51.550368Z'}
{'type': 'l2update', 'product_id': 'BTC-USD', 'changes': [['sell', '38469.55', '0.35417492']], 'time': '2021-05-20T03:55:51.553502Z'}
{'type': 'l2update', 'product_id': 'BTC-USD', 'changes': [['sell', '38462.70', '0.00000000']], 'time': '2021-05-20T03:55:51.553502Z'}
{'type': 'l2update', 'product_id': 'BTC-USD', 'changes': [['sell', '38443.29', '0.03869187']], 'time': '2021-05-20T03:55:51.553502Z'}
{'type': 'l2update', 'product_id': 'BTC-USD', 'changes': [['sell', '38443.29', '0.00000000']], 'time': '2021-05-20T03:55:51.553502Z'}
{'type': 'l2update', 'product_id': 'BTC-USD', 'changes': [['sell', '38437.20', '0.35166826']], 'time': '2021-05-20T03:55:51.553502Z'}
{'type': 'l2update', 'product_id': 'BTC-USD', 'changes': [['sell', '38431.30', '0.77493242']], 'time': '2021-05-20T03:55:51.553502Z'}
{'type': 'l2update', 'product_id': 'BTC-USD', 'changes': [['sell', '38404.68', '0.00000000']], 'time': '2021-05-20T03:55:51.553502Z'}
{'type': 'l2update', 'product_id': 'BTC-USD', 'changes': [['sell', '38401.42', '0.00000000']], 'time': '2021-05-20T03:55:51.553502Z'}
{'type': 'l2update', 'product_id': 'BTC-USD', 'changes': [['sell', '38394.96', '0.00000000']], 'time': '2021-05-20T03:55:51.553502Z'}
{'type': 'l2update', 'product_id': 'BTC-USD', 'changes': [['sell', '38608.01', '0.12950681']], 'time': '2021-05-20T03:55:51.553578Z'}
{'type': 'l2update', 'product_id': 'BTC-USD', 'changes': [['sell', '38665.02', '0.01293158']], 'time': '2021-05-20T03:55:51.554364Z'}
{'type': 'l2update', 'product_id': 'BTC-USD', 'changes': [['sell', '38476.60', '0.38973706']], 'time': '2021-05-20T03:55:51.557382Z'}
{'type': 'l2update', 'product_id': 'BTC-USD', 'changes': [['sell', '38476.60', '0.00000000']], 'time': '2021-05-20T03:55:51.557382Z'}
{'type': 'l2update', 'product_id': 'BTC-USD', 'changes': [['sell', '38469.55', '0.00000000']], 'time': '2021-05-20T03:55:51.557382Z'}
{'type': 'l2update', 'product_id': 'BTC-USD', 'changes': [['sell', '38456.04', '0.00000000']], 'time': '2021-05-20T03:55:51.557382Z'}
{'type': 'l2update', 'product_id': 'BTC-USD', 'changes': [['sell', '38449.57', '0.00000000']], 'time': '2021-05-20T03:55:51.557382Z'}
{'type': 'l2update', 'product_id': 'BTC-USD', 'changes': [['sell', '38431.30', '0.36322396']], 'time': '2021-05-20T03:55:51.557382Z'}
{'type': 'l2update', 'product_id': 'BTC-USD', 'changes': [['sell', '38380.80', '0.00000000']], 'time': '2021-05-20T03:55:51.567050Z'}
{'type': 'l2update', 'product_id': 'BTC-USD', 'changes': [['sell', '38458.35', '0.00000000']], 'time': '2021-05-20T03:55:51.569762Z'}
{'type': 'l2update', 'product_id': 'BTC-USD', 'changes': [['sell', '38380.86', '0.00000000']], 'time': '2021-05-20T03:55:51.572415Z'}
{'type': 'l2update', 'product_id': 'BTC-USD', 'changes': [['buy', '38342.91', '0.00000000']], 'time': '2021-05-20T03:55:51.576681Z'}
{'type': 'l2update', 'product_id': 'BTC-USD', 'changes': [['sell', '38445.97', '0.01000000']], 'time': '2021-05-20T03:55:51.583244Z'}
{'type': 'l2update', 'product_id': 'BTC-USD', 'changes': [['sell', '38374.10', '0.03000000']], 'time': '2021-05-20T03:55:51.583256Z'}
{'type': 'l2update', 'product_id': 'BTC-USD', 'changes': [['sell', '38342.92', '2.82195773']], 'time': '2021-05-20T03:55:51.584320Z'}
{'type': 'l2update', 'product_id': 'BTC-USD', 'changes': [['sell', '38665.02', '0.00000000']], 'time': '2021-05-20T03:55:51.588112Z'}
