{'type': 'l2update', 'product_id': 'BTC-USD', 'changes': [['sell', '38370.32', '0.00000000']], 'time': '2021-05-20T03:55:51.588451Z'}
{'type': 'l2update', 'product_id': 'BTC-USD', 'changes': [['sell', '38342.92', '2.82086656']], 'time': '2021-05-20T03:55:51.588997Z'}
{'type': 'l2update', 'product_id': 'BTC-USD', 'changes': [['sell', '38336.02', '0.02890000']], 'time': '2021-05-20T03:55:51.591415Z'}
{'type': 'l2update', 'product_id': 'BTC-USD', 'changes': [['sell', '38336.02', '0.10350000']], 'time': '2021-05-20T03:55:51.591573Z'}
{'type': 'l2update', 'product_id': 'BTC-USD', 'changes': [['sell', '38373.87', '0.01000000']], 'time': '2021-05-20T03:55:51.591596Z'}
{'type': 'l2update', 'product_id': 'BTC-USD', 'changes': [['sell', '38336.02', '0.11842000']], 'time': '2021-05-20T03:55:51.591644Z'}
{'type': 'l2update', 'product_id': 'BTC-USD', 'changes': [['sell', '38443.29', '0.03617526']], 'time': '2021-05-20T03:55:51.591801Z'}
{'type': 'l2update', 'product_id': 'BTC-USD', 'changes': [['buy', '38172.19', '0.00000000']], 'time': '2021-05-20T03:55:51.591815Z'}
{'type': 'l2update', 'product_id': 'BTC-USD', 'changes': [['sell', '38342.92', '2.81855085']], 'time': '2021-05-20T03:55:51.592735Z'}
{'type': 'l2update', 'product_id': 'BTC-USD', 'changes': [['buy', '38334.78', '0.00000000']], 'time': '2021-05-20T03:55:51.593156Z'}
{'type': 'l2update', 'product_id': 'BTC-USD', 'changes': [['sell', '38359.19', '0.05000000']], 'time': '2021-05-20T03:55:51.596961Z'}
{'type': 'l2update', 'product_id': 'BTC-USD', 'changes': [['sell', '38366.05', '0.05063468']], 'time': '2021-05-20T03:55:51.597233Z'}
{'type': 'l2update', 'product_id': 'BTC-USD', 'changes': [['sell', '38368.71', '0.15600000']], 'time': '2021-05-20T03:55:51.597261Z'}
{'type': 'l2update', 'product_id': 'BTC-USD', 'changes': [['sell', '38379.68', '0.03207306']], 'time': '2021-05-20T03:55:51.597548Z'}
{'type': 'l2update', 'product_id': 'BTC-USD', 'changes': [['sell', '38346.63', '0.04949979']], 'time': '2021-05-20T03:55:51.597714Z'}
{'type': 'l2update', 'product_id': 'BTC-USD', 'changes': [['sell', '38506.40', '0.30079435']], 'time': '2021-05-20T03:55:51.597742Z'}
{'type': 'l2update', 'product_id': 'BTC-USD', 'changes': [['sell', '38342.92', '2.81717856']], 'time': '2021-05-20T03:55:51.600194Z'}
{'type': 'l2update', 'product_id': 'BTC-USD', 'changes': [['buy', '38319.03', '0.00000000']], 'time': '2021-05-20T03:55:51.600511Z'}
{'type': 'l2update', 'product_id': 'BTC-USD', 'changes': [['buy', '38296.56', '0.46950000']], 'time': '2021-05-20T03:55:51.602642Z'}
{'type': 'l2update', 'product_id': 'BTC-USD', 'changes': [['buy', '38311.16', '0.52100000']], 'time': '2021-05-20T03:55:51.603003Z'}
{'type': 'l2update', 'product_id': 'BTC-USD', 'changes': [['sell', '38374.10', '0.07000000']], 'time': '2021-05-20T03:55:51.603313Z'}
{'type': 'l2update', 'product_id': 'BTC-USD', 'changes': [['sell', '38420.07', '0.74057538']], 'time': '2021-05-20T03:55:51.603614Z'}
{'type': 'l2update', 'product_id': 'BTC-USD', 'changes': [['sell', '38404.68', '0.36322396']], 'time': '2021-05-20T03:55:51.603614Z'}
{'type': 'l2update', 'product_id': 'BTC-USD', 'changes': [['sell', '38395.37', '0.38973706']], 'time': '2021-05-20T03:55:51.603614Z'}
{'type': 'l2update', 'product_id': 'BTC-USD', 'changes': [['sell', '38386.82', '0.35417492']], 'time': '2021-05-20T03:55:51.603614Z'}
{'type': 'l2update', 'product_id': 'BTC-USD', 'changes': [['sell', '38342.92', '4.31777186']], 'time': '2021-05-20T03:55:51.603652Z'}
{'type': 'l2update', 'product_id': 'BTC-USD', 'changes': [['buy', '38293.75', '0.00000000']], 'time': '2021-05-20T03:55:51.603780Z'}
{'type': 'l2update', 'product_id': 'BTC-USD', 'changes': [['sell', '38345.07', '0.00000000']], 'time': '2021-05-20T03:55:51.606405Z'}
{'type': 'l2update', 'product_id': 'BTC-USD', 'changes': [['sell', '38376.35', '0.02000000']], 'time': '2021-05-20T03:55:51.608939Z'}
{'type': 'l2update', 'product_id': 'BTC-USD', 'changes': [['buy', '38291.46', '0.01000000']], 'time': '2021-05-20T03:55:51.609951Z'}
{'type': 'l2update', 'product_id': 'BTC-USD', 'changes': [['sell', '38336.02', '0.76842000']], 'time': '2021-05-20T03:55:51.610002Z'}
{'type': 'l2update', 'product_id': 'BTC-USD', 'changes': [['sell', '38649.94', '0.01000000']], 'time': '2021-05-20T03:55:51.610498Z'}
{'type': 'l2update', 'product_id': 'BTC-USD', 'changes': [['sell', '38336.02', '0.86842000']], 'time': '2021-05-20T03:55:51.610865Z'}
{'type': 'l2update', 'product_id': 'BTC-USD', 'changes': [['sell', '38431.30', '0.00000000']], 'time': '2021-05-20T03:55:51.611158Z'}
{'type': 'l2update', 'product_id': 'BTC-USD', 'changes': [['sell', '38420.07', '0.35083832']], 'time': '2021-05-20T03:55:51.611158Z'}
{'type': 'l2update', 'product_id': 'BTC-USD', 'changes': [['sell', '38409.62', '0.00000000']], 'time': '2021-05-20T03:55:51.611158Z'}
{'type': 'l2update', 'product_id': 'BTC-USD', 'changes': [['buy', '38307.86', '0.00000000']], 'time': '2021-05-20T03:55:51.611309Z'}
{'type': 'l2update', 'product_id': 'BTC-USD', 'changes': [['sell', '38352.53', '0.00000000']], 'time': '2021-05-20T03:55:51.611309Z'}
{'type': 'l2update', 'product_id': 'BTC-USD', 'changes': [['sell', '38376.35', '0.00000000']], 'time': '2021-05-20T03:55:51.612902Z'}
{'type': 'l2update', 'product_id': 'BTC-USD', 'changes': [['sell', '38387.52', '0.00000000']], 'time': '2021-05-20T03:55:51.615967Z'}
{'type': 'l2update', 'product_id': 'BTC-USD', 'changes': [['sell', '38342.92', '4.28777186']], 'time': '2021-05-20T03:55:51.616846Z'}
{'type': 'l2update', 'product_id': 'BTC-USD', 'changes': [['sell', '38381.30', '0.00000000']], 'time': '2021-05-20T03:55:51.619386Z'}
{'type': 'l2update', 'product_id': 'BTC-USD', 'changes': [['sell', '38342.92', '4.19029238']], 'time': '2021-05-20T03:55:51.619952Z'}
{'type': 'l2update', 'product_id': 'BTC-USD', 'changes': [['sell', '38442.39', '0.00000000']], 'time': '2021-05-20T03:55:51.620015Z'}
{'type': 'l2update', 'product_id': 'BTC-USD', 'changes': [['sell', '38506.40', '0.00000000']], 'time': '2021-05-20T03:55:51.623131Z'}
{'type': 'l2update', 'product_id': 'BTC-USD', 'changes': [['sell', '38351.55', '0.00000000']], 'time': '2021-05-20T03:55:51.626064Z'}
{'type': 'l2update', 'product_id': 'BTC-USD', 'changes': [['sell', '38432.11', '0.00000000']], 'time': '2021-05-20T03:55:51.627922Z'}
{'type': 'l2update', 'product_id': 'BTC-USD', 'changes': [['sell', '38423.98', '0.00000000']], 'time': '2021-05-20T03:55:51.627922Z'}
{'type': 'l2update', 'product_id': 'BTC-USD', 'changes': [['buy', '38214.47', '0.00000000']], 'time': '2021-05-20T03:55:51.627922Z'}
{'type': 'l2update', 'product_id': 'BTC-USD', 'changes': [['buy', '38252.77', '0.00000000']], 'time': '2021-05-20T03:55:51.627922Z'}
{'type': 'l2update', 'product_id': 'BTC-USD', 'changes': [['sell', '38404.79', '0.00000000']], 'time': '2021-05-20T03:55:51.627922Z'}
{'type': 'l2update', 'product_id': 'BTC-USD', 'changes': [['buy', '38271.93', '0.00000000']], 'time': '2021-05-20T03:55:51.627922Z'}
{'type': 'l2update', 'product_id': 'BTC-USD', 'changes': [['sell', '38342.91', '0.18981474']], 'time': '2021-05-20T03:55:51.632116Z'}
{'type': 'l2update', 'product_id': 'BTC-USD', 'changes': [['buy', '38314.66', '0.40135082']], 'time': '2021-05-20T03:55:51.632230Z'}
{'type': 'l2update', 'product_id': 'BTC-USD', 'changes': [['buy', '38336.01', '0.00000000']], 'time': '2021-05-20T03:55:51.632350Z'}
{'type': 'l2update', 'product_id': 'BTC-USD', 'changes': [['buy', '38336.00', '0.00000000']], 'time': '2021-05-20T03:55:51.632350Z'}
{'type': 'l2update', 'product_id': 'BTC-USD', 'changes': [['buy', '38314.66', '1.39450879']], 'time': '2021-05-20T03:55:51.632406Z'}
{'type': 'l2update', 'product_id': 'BTC-USD', 'changes': [['sell', '38336.02', '0.89842000']], 'time': '2021-05-20T03:55:51.633318Z'}
{'type': 'l2update', 'product_id': 'BTC-USD', 'changes': [['sell', '38455.79', '0.29705635']], 'time': '2021-05-20T03:55:51.633413Z'}
{'type': 'l2update', 'product_id': 'BTC-USD', 'changes': [['sell', '38382.83', '0.44294184']], 'time': '2021-05-20T03:55:51.633589Z'}
{'type': 'l2update', 'product_id': 'BTC-USD', 'changes': [['sell', '38393.10', '0.00000000']], 'time': '2021-05-20T03:55:51.637968Z'}
{'type': 'l2update', 'product_id': 'BTC-USD', 'changes': [['sell', '38336.02', '1.09842000']], 'time': '2021-05-20T03:55:51.638339Z'}
{'type': 'l2update', 'product_id': 'BTC-USD', 'changes': [['sell', '38470.09', '0.01000000']], 'time': '2021-05-20T03:55:51.638828Z'}
{'type': 'l2update', 'product_id': 'BTC-USD', 'changes': [['sell', '38370.39', '0.01000000']], 'time': '2021-05-20T03:55:51.638863Z'}
{'type': 'l2update', 'product_id': 'BTC-USD', 'changes': [['sell', '38336.02', '1.02382000']], 'time': '2021-05-20T03:55:51.639478Z'}
{'type': 'l2update', 'product_id': 'BTC-USD', 'changes': [['sell', '38336.02', '0.99382000']], 'time': '2021-05-20T03:55:51.640442Z'}
{'type': 'l2update', 'product_id': 'BTC-USD', 'changes': [['sell', '38457.47', '0.00000000']], 'time': '2021-05-20T03:55:51.640466Z'}
{'type': 'l2update', 'product_id': 'BTC-USD', 'changes': [['sell', '38336.02', '0.97890000']], 'time': '2021-05-20T03:55:51.644514Z'}
{'type': 'l2update', 'product_id': 'BTC-USD', 'changes': [['sell', '38342.92', '3.99029238']], 'time': '2021-05-20T03:55:51.650272Z'}
{'type': 'l2update', 'product_id': 'BTC-USD', 'changes': [['sell', '38370.42', '0.00000000']], 'time': '2021-05-20T03:55:51.650370Z'}
{'type': 'l2update', 'product_id': 'BTC-USD', 'changes': [['sell', '38359.19', '0.00000000']], 'time': '2021-05-20T03:55:51.650510Z'}
{'type': 'l2update', 'product_id': 'BTC-USD', 'changes': [['sell', '38336.01', '0.65000000']], 'time': '2021-05-20T03:55:51.650699Z'}
{'type': 'l2update', 'product_id': 'BTC-USD', 'changes': [['sell', '38336.01', '0.68000000']], 'time': '2021-05-20T03:55:51.651680Z'}
{'type': 'l2update', 'product_id': 'BTC-USD', 'changes': [['sell', '38462.64', '0.38235442']], 'time': '2021-05-20T03:55:51.652048Z'}
{'type': 'l2update', 'product_id': 'BTC-USD', 'changes': [['sell', '38373.48', '0.00000000']], 'time': '2021-05-20T03:55:51.655533Z'}
{'type': 'l2update', 'product_id': 'BTC-USD', 'changes': [['sell', '38342.90', '1.41644788']], 'time': '2021-05-20T03:55:51.657273Z'}
{'type': 'l2update', 'product_id': 'BTC-USD', 'changes': [['sell', '38393.03', '0.03300600']], 'time': '2021-05-20T03:55:51.657736Z'}
{'type': 'l2update', 'product_id': 'BTC-USD', 'changes': [['sell', '38382.83', '0.47911710']], 'time': '2021-05-20T03:55:51.657736Z'}
{'type': 'l2update', 'product_id': 'BTC-USD', 'changes': [['sell', '38560.23', '0.00000000']], 'time': '2021-05-20T03:55:51.661288Z'}
{'type': 'l2update', 'product_id': 'BTC-USD', 'changes': [['sell', '38373.87', '0.00000000']], 'time': '2021-05-20T03:55:51.661515Z'}
{'type': 'l2update', 'product_id': 'BTC-USD', 'changes': [['sell', '38370.39', '0.03000000']], 'time': '2021-05-20T03:55:51.664662Z'}
{'type': 'l2update', 'product_id': 'BTC-USD', 'changes': [['buy', '38323.49', '0.04731571']], 'time': '2021-05-20T03:55:51.668059Z'}
{'type': 'l2update', 'product_id': 'BTC-USD', 'changes': [['sell', '38335.41', '0.07460000']], 'time': '2021-05-20T03:55:51.671133Z'}
{'type': 'l2update', 'product_id': 'BTC-USD', 'changes': [['sell', '38474.06', '0.02938800']], 'time': '2021-05-20T03:55:51.671395Z'}
{'type': 'l2update', 'product_id': 'BTC-USD', 'changes': [['sell', '38365.44', '0.48220000']], 'time': '2021-05-20T03:55:51.672656Z'}
{'type': 'l2update', 'product_id': 'BTC-USD', 'changes': [['sell', '38335.49', '0.01492000']], 'time': '2021-05-20T03:55:51.675850Z'}
{'type': 'l2update', 'product_id': 'BTC-USD', 'changes': [['sell', '38426.79', '0.20400000']], 'time': '2021-05-20T03:55:51.675997Z'}
{'type': 'l2update', 'product_id': 'BTC-USD', 'changes': [['sell', '38465.16', '0.66500000']], 'time': '2021-05-20T03:55:51.675997Z'}
{'type': 'l2update', 'product_id': 'BTC-USD', 'changes': [['sell', '38407.60', '0.06600000']], 'time': '2021-05-20T03:55:51.675997Z'}
{'type': 'l2update', 'product_id': 'BTC-USD', 'changes': [['buy', '38219.33', '0.66500000']], 'time': '2021-05-20T03:55:51.675997Z'}
{'type': 'l2update', 'product_id': 'BTC-USD', 'changes': [['buy', '38257.65', '0.20400000']], 'time': '2021-05-20T03:55:51.675997Z'}
{'type': 'l2update', 'product_id': 'BTC-USD', 'changes': [['buy', '38276.80', '0.06600000']], 'time': '2021-05-20T03:55:51.675997Z'}
{'type': 'l2update', 'product_id': 'BTC-USD', 'changes': [['sell', '38340.32', '0.00600000']], 'time': '2021-05-20T03:55:51.679114Z'}
{'type': 'l2update', 'product_id': 'BTC-USD', 'changes': [['buy', '38290.41', '0.00936247']], 'time': '2021-05-20T03:55:51.679280Z'}
{'type': 'l2update', 'product_id': 'BTC-USD', 'changes': [['buy', '38306.25', '0.00000000']], 'time': '2021-05-20T03:55:51.679564Z'}
{'type': 'l2update', 'product_id': 'BTC-USD', 'changes': [['sell', '38347.66', '0.05000000']], 'time': '2021-05-20T03:55:51.692409Z'}
{'type': 'l2update', 'product_id': 'BTC-USD', 'changes': [['sell', '38336.01', '0.78000000']], 'time': '2021-05-20T03:55:51.692457Z'}
{'type': 'l2update', 'product_id': 'BTC-USD', 'changes': [['sell', '38443.29', '0.00000000']], 'time': '2021-05-20T03:55:51.694127Z'}
{'type': 'l2update', 'product_id': 'BTC-USD', 'changes': [['sell', '38436.38', '0.42569755']], 'time': '2021-05-20T03:55:51.696661Z'}
{'type': 'l2update', 'product_id': 'BTC-USD', 'changes': [['sell', '38418.68', '0.29705635']], 'time': '2021-05-20T03:55:51.696661Z'}
{'type': 'l2update', 'product_id': 'BTC-USD', 'changes': [['sell', '38375.93', '0.16994742']], 'time': '2021-05-20T03:55:51.696661Z'}
{'type': 'l2update', 'product_id': 'BTC-USD', 'changes': [['buy', '38319.02', '0.00000000']], 'time': '2021-05-20T03:55:51.697378Z'}
{'type': 'l2update', 'product_id': 'BTC-USD', 'changes': [['buy', '38308.91', '0.00000000']], 'time': '2021-05-20T03:55:51.701299Z'}
{'type': 'l2update', 'product_id': 'BTC-USD', 'changes': [['sell', '38345.06', '0.00000000']], 'time': '2021-05-20T03:55:51.701324Z'}
{'type': 'l2update', 'product_id': 'BTC-USD', 'changes': [['buy', '38291.46', '0.00000000']], 'time': '2021-05-20T03:55:51.701339Z'}
{'type': 'l2update', 'product_id': 'BTC-USD', 'changes': [['buy', '38254.08', '0.02400000']], 'time': '2021-05-20T03:55:51.702845Z'}
{'type': 'l2update', 'product_id': 'BTC-USD', 'changes': [['buy', '38314.66', '0.99315797']], 'time': '2021-05-20T03:55:51.702937Z'}
{'type': 'l2update', 'product_id': 'BTC-USD', 'changes': [['sell', '38374.10', '0.12000000']], 'time': '2021-05-20T03:55:51.726312Z'}
{'type': 'l2update', 'product_id': 'BTC-USD', 'changes': [['sell', '38342.91', '0.00000000']], 'time': '2021-05-20T03:55:51.733211Z'}
{'type': 'l2update', 'product_id': 'BTC-USD', 'changes': [['sell', '38336.02', '0.95000000']], 'time': '2021-05-20T03:55:51.734315Z'}
{'type': 'l2update', 'product_id': 'BTC-USD', 'changes': [['buy', '38314.65', '0.00000000']], 'time': '2021-05-20T03:55:51.735257Z'}
{'type': 'l2update', 'product_id': 'BTC-USD', 'changes': [['buy', '38294.30', '0.56000000']], 'time': '2021-05-20T03:55:51.740401Z'}
{'type': 'l2update', 'product_id': 'BTC-USD', 'changes': [['sell', '38335.96', '1.03800000']], 'time': '2021-05-20T03:55:51.741011Z'}
{'type': 'l2update', 'product_id': 'BTC-USD', 'changes': [['sell', '38335.49', '0.00000000']], 'time': '2021-05-20T03:55:51.745209Z'}
{'type': 'l2update', 'product_id': 'BTC-USD', 'changes': [['buy', '38159.08', '0.00000000']], 'time': '2021-05-20T03:55:51.746840Z'}
{'type': 'l2update', 'product_id': 'BTC-USD', 'changes': [['sell', '38455.79', '0.00000000']], 'time': '2021-05-20T03:55:51.752115Z'}
{'type': 'l2update', 'product_id': 'BTC-USD', 'changes': [['sell', '38391.00', '0.36593177']], 'time': '2021-05-20T03:55:51.752115Z'}
{'type': 'l2update', 'product_id': 'BTC-USD', 'changes': [['buy', '38262.11', '0.36017473']], 'time': '2021-05-20T03:55:51.752115Z'}
{'type': 'l2update', 'product_id': 'BTC-USD', 'changes': [['sell', '38336.01', '0.98000000']], 'time': '2021-05-20T03:55:51.754281Z'}
{'type': 'l2update', 'product_id': 'BTC-USD', 'changes': [['sell', '38407.85', '0.03518469']], 'time': '2021-05-20T03:55:51.760366Z'}
{'type': 'l2update', 'product_id': 'BTC-USD', 'changes': [['sell', '38389.14', '2.16932808']], 'time': '2021-05-20T03:55:51.768453Z'}
{'type': 'l2update', 'product_id': 'BTC-USD', 'changes': [['sell', '38364.44', '0.01000000']], 'time': '2021-05-20T03:55:51.772349Z'}
{'type': 'l2update', 'product_id': 'BTC-USD', 'changes': [['sell', '38541.83', '0.02161868']], 'time': '2021-05-20T03:55:51.778119Z'}
{'type': 'l2update', 'product_id': 'BTC-USD', 'changes': [['buy', '38305.93', '0.02400000']], 'time': '2021-05-20T03:55:51.778496Z'}
{'type': 'l2update', 'product_id': 'BTC-USD', 'changes': [['sell', '38336.00', '0.50000000']], 'time': '2021-05-20T03:55:51.787830Z'}
{'type': 'l2update', 'product_id': 'BTC-USD', 'changes': [['buy', '38300.97', '0.00000000']], 'time': '2021-05-20T03:55:51.793720Z'}
{'type': 'l2update', 'product_id': 'BTC-USD', 'changes': [['sell', '38413.46', '0.00000000']], 'time': '2021-05-20T03:55:51.794110Z'}
{'type': 'l2update', 'product_id': 'BTC-USD', 'changes': [['sell', '38509.85', '0.00000000']], 'time': '2021-05-20T03:55:51.794360Z'}
{'type': 'l2update', 'product_id': 'BTC-USD', 'changes': [['sell', '38639.99', '3.23362444']], 'time': '2021-05-20T03:55:51.794625Z'}
{'type': 'l2update', 'product_id': 'BTC-USD', 'changes': [['sell', '38365.44', '0.00000000']], 'time': '2021-05-20T03:55:51.796401Z'}
{'type': 'l2update', 'product_id': 'BTC-USD', 'changes': [['sell', '38571.84', '0.00000000']], 'time': '2021-05-20T03:55:51.806850Z'}
{'type': 'l2update', 'product_id': 'BTC-USD', 'changes': [['sell', '38359.27', '0.00000000']], 'time': '2021-05-20T03:55:51.814809Z'}
{'type': 'l2update', 'product_id': 'BTC-USD', 'changes': [['buy', '38314.66', '0.00000000']], 'time': '2021-05-20T03:55:51.819218Z'}
{'type': 'l2update', 'product_id': 'BTC-USD', 'changes': [['buy', '38295.54', '0.00000000']], 'time': '2021-05-20T03:55:51.825170Z'}
{'type': 'l2update', 'product_id': 'BTC-USD', 'changes': [['sell', '38336.02', '0.75000000']], 'time': '2021-05-20T03:55:51.827413Z'}
{'type': 'l2update', 'product_id': 'BTC-USD', 'changes': [['sell', '38462.64', '0.72007650']], 'time': '2021-05-20T03:55:51.830540Z'}
{'type': 'l2update', 'product_id': 'BTC-USD', 'changes': [['sell', '38460.13', '0.03584250']], 'time': '2021-05-20T03:55:51.833334Z'}
{'type': 'l2update', 'product_id': 'BTC-USD', 'changes': [['sell', '38334.93', '0.01492000']], 'time': '2021-05-20T03:55:51.838896Z'}
{'type': 'l2update', 'product_id': 'BTC-USD', 'changes': [['sell', '38334.93', '0.01468585']], 'time': '2021-05-20T03:55:51.839046Z'}
{'type': 'l2update', 'product_id': 'BTC-USD', 'changes': [['sell', '38413.17', '0.03189647']], 'time': '2021-05-20T03:55:51.843356Z'}
{'type': 'l2update', 'product_id': 'BTC-USD', 'changes': [['buy', '38254.08', '0.00000000']], 'time': '2021-05-20T03:55:51.846861Z'}
{'type': 'l2update', 'product_id': 'BTC-USD', 'changes': [['buy', '38308.11', '0.00000000']], 'time': '2021-05-20T03:55:51.852153Z'}
{'type': 'l2update', 'product_id': 'BTC-USD', 'changes': [['buy', '38307.31', '0.00000000']], 'time': '2021-05-20T03:55:51.852153Z'}
{'type': 'l2update', 'product_id': 'BTC-USD', 'changes': [['buy', '38301.84', '0.00000000']], 'time': '2021-05-20T03:55:51.861183Z'}
{'type': 'l2update', 'product_id': 'BTC-USD', 'changes': [['sell', '38335.36', '0.55400000']], 'time': '2021-05-20T03:55:51.869967Z'}
{'type': 'l2update', 'product_id': 'BTC-USD', 'changes': [['sell', '38336.02', '0.10000000']], 'time': '2021-05-20T03:55:51.880028Z'}
{'type': 'l2update', 'product_id': 'BTC-USD', 'changes': [['sell', '38363.57', '0.44490000']], 'time': '2021-05-20T03:55:51.887409Z'}
{'type': 'l2update', 'product_id': 'BTC-USD', 'changes': [['sell', '38496.67', '0.01000000']], 'time': '2021-05-20T03:55:51.887465Z'}
{'type': 'l2update', 'product_id': 'BTC-USD', 'changes': [['buy', '38181.69', '0.16800000']], 'time': '2021-05-20T03:55:51.892428Z'}
{'type': 'l2update', 'product_id': 'BTC-USD', 'changes': [['sell', '38529.51', '0.00000000']], 'time': '2021-05-20T03:55:51.892547Z'}
{'type': 'l2update', 'product_id': 'BTC-USD', 'changes': [['sell', '38359.20', '0.55400000']], 'time': '2021-05-20T03:55:51.898096Z'}
{'type': 'l2update', 'product_id': 'BTC-USD', 'changes': [['buy', '38207.77', '0.00000000']], 'time': '2021-05-20T03:55:51.898950Z'}
{'type': 'l2update', 'product_id': 'BTC-USD', 'changes': [['sell', '38364.44', '0.00000000']], 'time': '2021-05-20T03:55:51.899739Z'}
{'type': 'l2update', 'product_id': 'BTC-USD', 'changes': [['sell', '38498.79', '0.00000000']], 'time': '2021-05-20T03:55:51.905918Z'}
{'type': 'l2update', 'product_id': 'BTC-USD', 'changes': [['sell', '38335.40', '0.18981474']], 'time': '2021-05-20T03:55:51.917449Z'}
{'type': 'l2update', 'product_id': 'BTC-USD', 'changes': [['buy', '38314.67', '0.40135082']], 'time': '2021-05-20T03:55:51.917933Z'}
{'type': 'l2update', 'product_id': 'BTC-USD', 'changes': [['sell', '38336.02', '0.00000000']], 'time': '2021-05-20T03:55:51.924117Z'}
{'type': 'l2update', 'product_id': 'BTC-USD', 'changes': [['buy', '38311.17', '0.99315797']], 'time': '2021-05-20T03:55:51.925625Z'}
{'type': 'l2update', 'product_id': 'BTC-USD', 'changes': [['buy', '38310.92', '0.00000000']], 'time': '2021-05-20T03:55:51.925718Z'}
{'type': 'l2update', 'product_id': 'BTC-USD', 'changes': [['sell', '38471.34', '0.32328516']], 'time': '2021-05-20T03:55:51.933127Z'}
{'type': 'l2update', 'product_id': 'BTC-USD', 'changes': [['sell', '38443.55', '0.01175473']], 'time': '2021-05-20T03:55:51.936492Z'}
{'type': 'l2update', 'product_id': 'BTC-USD', 'changes': [['sell', '38335.41', '0.00000000']], 'time': '2021-05-20T03:55:51.942617Z'}
{'type': 'l2update', 'product_id': 'BTC-USD', 'changes': [['sell', '38389.14', '0.00000000']], 'time': '2021-05-20T03:55:51.948398Z'}
{'type': 'l2update', 'product_id': 'BTC-USD', 'changes': [['sell', '38417.29', '0.03086184']], 'time': '2021-05-20T03:55:51.951844Z'}
{'type': 'l2update', 'product_id': 'BTC-USD', 'changes': [['buy', '38212.71', '0.09223186']], 'time': '2021-05-20T03:55:51.951844Z'}
{'type': 'l2update', 'product_id': 'BTC-USD', 'changes': [['buy', '38305.93', '0.00000000']], 'time': '2021-05-20T03:55:51.954988Z'}
{'type': 'l2update', 'product_id': 'BTC-USD', 'changes': [['buy', '38299.02', '0.00000000']], 'time': '2021-05-20T03:55:51.957328Z'}
{'type': 'l2update', 'product_id': 'BTC-USD', 'changes': [['sell', '38363.57', '0.00000000']], 'time': '2021-05-20T03:55:51.977854Z'}
{'type': 'l2update', 'product_id': 'BTC-USD', 'changes': [['sell', '38348.32', '0.05000000']], 'time': '2021-05-20T03:55:51.979477Z'}
{'type': 'l2update', 'product_id': 'BTC-USD', 'changes': [['sell', '38496.67', '0.00000000']], 'time': '2021-05-20T03:55:51.979528Z'}
{'type': 'l2update', 'product_id': 'BTC-USD', 'changes': [['buy', '38311.16', '0.00000000']], 'time': '2021-05-20T03:55:51.989983Z'}
{'type': 'l2update', 'product_id': 'BTC-USD', 'changes': [['buy', '38323.03', '0.00000000']], 'time': '2021-05-20T03:55:51.990483Z'}
{'type': 'l2update', 'product_id': 'BTC-USD', 'changes': [['buy', '38282.86', '0.01000000']], 'time': '2021-05-20T03:55:51.995737Z'}
{'type': 'l2update', 'product_id': 'BTC-USD', 'changes': [['sell', '38522.87', '0.00648965']], 'time': '2021-05-20T03:55:51.995764Z'}
{'type': 'l2update', 'product_id': 'BTC-USD', 'changes': [['buy', '38175.36', '0.13097452']], 'time': '2021-05-20T03:55:51.999574Z'}
{'type': 'l2update', 'product_id': 'BTC-USD', 'changes': [['sell', '38336.01', '0.88000000']], 'time': '2021-05-20T03:55:52.001328Z'}
{'type': 'l2update', 'product_id': 'BTC-USD', 'changes': [['sell', '38342.92', '1.50059330']], 'time': '2021-05-20T03:55:52.002439Z'}
{'type': 'l2update', 'product_id': 'BTC-USD', 'changes': [['sell', '38479.23', '0.01907260']], 'time': '2021-05-20T03:55:52.002763Z'}
{'type': 'l2update', 'product_id': 'BTC-USD', 'changes': [['buy', '38314.72', '0.84700000']], 'time': '2021-05-20T03:55:52.006195Z'}
{'type': 'l2update', 'product_id': 'BTC-USD', 'changes': [['buy', '38257.37', '0.00000000']], 'time': '2021-05-20T03:55:52.009218Z'}
{'type': 'l2update', 'product_id': 'BTC-USD', 'changes': [['sell', '38334.46', '0.07460000']], 'time': '2021-05-20T03:55:52.030858Z'}
{'type': 'l2update', 'product_id': 'BTC-USD', 'changes': [['buy', '38289.49', '0.00000000']], 'time': '2021-05-20T03:55:52.037048Z'}
{'type': 'l2update', 'product_id': 'BTC-USD', 'changes': [['buy', '38260.72', '0.03628277']], 'time': '2021-05-20T03:55:52.037083Z'}
{'type': 'l2update', 'product_id': 'BTC-USD', 'changes': [['sell', '38370.39', '0.02000000']], 'time': '2021-05-20T03:55:52.043214Z'}
{'type': 'l2update', 'product_id': 'BTC-USD', 'changes': [['buy', '38300.52', '0.02400000']], 'time': '2021-05-20T03:55:52.049968Z'}
{'type': 'l2update', 'product_id': 'BTC-USD', 'changes': [['buy', '38299.71', '0.02400000']], 'time': '2021-05-20T03:55:52.049968Z'}
{'type': 'l2update', 'product_id': 'BTC-USD', 'changes': [['buy', '38298.90', '0.02400000']], 'time': '2021-05-20T03:55:52.049968Z'}
{'type': 'l2update', 'product_id': 'BTC-USD', 'changes': [['buy', '38296.56', '0.00000000']], 'time': '2021-05-20T03:55:52.083102Z'}
{'type': 'l2update', 'product_id': 'BTC-USD', 'changes': [['buy', '38285.60', '0.00000000']], 'time': '2021-05-20T03:55:52.088255Z'}
{'type': 'l2update', 'product_id': 'BTC-USD', 'changes': [['sell', '38361.16', '0.10000000']], 'time': '2021-05-20T03:55:52.088700Z'}
{'type': 'l2update', 'product_id': 'BTC-USD', 'changes': [['sell', '38509.85', '0.01000000']], 'time': '2021-05-20T03:55:52.089610Z'}
{'type': 'l2update', 'product_id': 'BTC-USD', 'changes': [['sell', '38336.01', '0.68000000']], 'time': '2021-05-20T03:55:52.090414Z'}
{'type': 'l2update', 'product_id': 'BTC-USD', 'changes': [['buy', '38198.00', '0.00000000']], 'time': '2021-05-20T03:55:52.095742Z'}
{'type': 'l2update', 'product_id': 'BTC-USD', 'changes': [['sell', '38334.92', '2.48969908']], 'time': '2021-05-20T03:55:52.099522Z'}
{'type': 'l2update', 'product_id': 'BTC-USD', 'changes': [['sell', '38462.64', '1.07848669']], 'time': '2021-05-20T03:55:52.103431Z'}
{'type': 'l2update', 'product_id': 'BTC-USD', 'changes': [['buy', '38151.78', '0.80355629']], 'time': '2021-05-20T03:55:52.108111Z'}
{'type': 'l2update', 'product_id': 'BTC-USD', 'changes': [['sell', '38370.39', '0.00000000']], 'time': '2021-05-20T03:55:52.108984Z'}
{'type': 'l2update', 'product_id': 'BTC-USD', 'changes': [['buy', '38323.49', '0.00000000']], 'time': '2021-05-20T03:55:52.109001Z'}
{'type': 'l2update', 'product_id': 'BTC-USD', 'changes': [['sell', '38334.93', '0.00000000']], 'time': '2021-05-20T03:55:52.110877Z'}
{'type': 'l2update', 'product_id': 'BTC-USD', 'changes': [['sell', '38423.38', '0.03595575']], 'time': '2021-05-20T03:55:52.115321Z'}
{'type': 'l2update', 'product_id': 'BTC-USD', 'changes': [['buy', '38268.51', '0.10000000']], 'time': '2021-05-20T03:55:52.115350Z'}
{'type': 'l2update', 'product_id': 'BTC-USD', 'changes': [['sell', '38335.42', '0.05153093']], 'time': '2021-05-20T03:55:52.137221Z'}
{'type': 'l2update', 'product_id': 'BTC-USD', 'changes': [['buy', '38314.67', '0.00000000']], 'time': '2021-05-20T03:55:52.155496Z'}
{'type': 'l2update', 'product_id': 'BTC-USD', 'changes': [['buy', '38282.86', '0.00000000']], 'time': '2021-05-20T03:55:52.156131Z'}
{'type': 'l2update', 'product_id': 'BTC-USD', 'changes': [['sell', '38335.40', '0.00000000']], 'time': '2021-05-20T03:55:52.160486Z'}
{'type': 'l2update', 'product_id': 'BTC-USD', 'changes': [['sell', '38469.30', '0.00000000']], 'time': '2021-05-20T03:55:52.160985Z'}
{'type': 'l2update', 'product_id': 'BTC-USD', 'changes': [['buy', '38214.22', '0.01000000']], 'time': '2021-05-20T03:55:52.165508Z'}
{'type': 'l2update', 'product_id': 'BTC-USD', 'changes': [['sell', '38490.53', '0.01000000']], 'time': '2021-05-20T03:55:52.166050Z'}
{'type': 'l2update', 'product_id': 'BTC-USD', 'changes': [['sell', '38374.10', '0.09000000']], 'time': '2021-05-20T03:55:52.170935Z'}
{'type': 'l2update', 'product_id': 'BTC-USD', 'changes': [['sell', '38464.37', '0.29802836']], 'time': '2021-05-20T03:55:52.176289Z'}
{'type': 'l2update', 'product_id': 'BTC-USD', 'changes': [['buy', '37540.13', '0.06911287']], 'time': '2021-05-20T03:55:52.178080Z'}
{'type': 'l2update', 'product_id': 'BTC-USD', 'changes': [['buy', '38315.25', '0.02728429']], 'time': '2021-05-20T03:55:52.178192Z'}
{'type': 'l2update', 'product_id': 'BTC-USD', 'changes': [['sell', '38334.19', '0.01492000']], 'time': '2021-05-20T03:55:52.182381Z'}
{'type': 'l2update', 'product_id': 'BTC-USD', 'changes': [['buy', '38315.09', '0.01492000']], 'time': '2021-05-20T03:55:52.182694Z'}
{'type': 'l2update', 'product_id': 'BTC-USD', 'changes': [['sell', '38474.06', '0.00000000']], 'time': '2021-05-20T03:55:52.185872Z'}
{'type': 'l2update', 'product_id': 'BTC-USD', 'changes': [['sell', '38347.66', '0.00000000']], 'time': '2021-05-20T03:55:52.186633Z'}
{'type': 'l2update', 'product_id': 'BTC-USD', 'changes': [['sell', '38356.47', '0.00000000']], 'time': '2021-05-20T03:55:52.192708Z'}
{'type': 'l2update', 'product_id': 'BTC-USD', 'changes': [['sell', '38364.00', '0.01000000']], 'time': '2021-05-20T03:55:52.197213Z'}
{'type': 'l2update', 'product_id': 'BTC-USD', 'changes': [['sell', '38374.10', '0.05000000']], 'time': '2021-05-20T03:55:52.197750Z'}
{'type': 'l2update', 'product_id': 'BTC-USD', 'changes': [['buy', '38300.52', '0.00000000']], 'time': '2021-05-20T03:55:52.201238Z'}
{'type': 'l2update', 'product_id': 'BTC-USD', 'changes': [['buy', '38314.72', '0.00000000']], 'time': '2021-05-20T03:55:52.202451Z'}
{'type': 'l2update', 'product_id': 'BTC-USD', 'changes': [['sell', '38429.66', '0.03715672']], 'time': '2021-05-20T03:55:52.202872Z'}
{'type': 'l2update', 'product_id': 'BTC-USD', 'changes': [['buy', '38311.22', '0.52000000']], 'time': '2021-05-20T03:55:52.202890Z'}
{'type': 'l2update', 'product_id': 'BTC-USD', 'changes': [['sell', '38346.63', '0.00000000']], 'time': '2021-05-20T03:55:52.203671Z'}
{'type': 'l2update', 'product_id': 'BTC-USD', 'changes': [['sell', '38395.37', '0.00000000']], 'time': '2021-05-20T03:55:52.208076Z'}
{'type': 'l2update', 'product_id': 'BTC-USD', 'changes': [['sell', '38391.00', '0.00000000']], 'time': '2021-05-20T03:55:52.208076Z'}
{'type': 'l2update', 'product_id': 'BTC-USD', 'changes': [['buy', '38314.73', '0.40135082']], 'time': '2021-05-20T03:55:52.212810Z'}
{'type': 'l2update', 'product_id': 'BTC-USD', 'changes': [['buy', '38310.49', '0.00300000']], 'time': '2021-05-20T03:55:52.213094Z'}
{'type': 'l2update', 'product_id': 'BTC-USD', 'changes': [['sell', '39132.74', '0.06951161']], 'time': '2021-05-20T03:55:52.213560Z'}
{'type': 'l2update', 'product_id': 'BTC-USD', 'changes': [['buy', '38315.09', '0.00000000']], 'time': '2021-05-20T03:55:52.213943Z'}
{'type': 'l2update', 'product_id': 'BTC-USD', 'changes': [['sell', '38334.46', '0.00000000']], 'time': '2021-05-20T03:55:52.214437Z'}
{'type': 'l2update', 'product_id': 'BTC-USD', 'changes': [['sell', '43100.00', '1.09530000']], 'time': '2021-05-20T03:55:52.214950Z'}
{'type': 'l2update', 'product_id': 'BTC-USD', 'changes': [['sell', '38460.85', '0.03147900']], 'time': '2021-05-20T03:55:52.219842Z'}
{'type': 'l2update', 'product_id': 'BTC-USD', 'changes': [['buy', '38315.25', '0.07460000']], 'time': '2021-05-20T03:55:52.220045Z'}
{'type': 'l2update', 'product_id': 'BTC-USD', 'changes': [['buy', '38292.16', '0.16200000']], 'time': '2021-05-20T03:55:52.220596Z'}
{'type': 'l2update', 'product_id': 'BTC-USD', 'changes': [['buy', '38311.17', '0.00000000']], 'time': '2021-05-20T03:55:52.231819Z'}
{'type': 'l2update', 'product_id': 'BTC-USD', 'changes': [['sell', '38342.89', '0.05000000']], 'time': '2021-05-20T03:55:52.233006Z'}
{'type': 'l2update', 'product_id': 'BTC-USD', 'changes': [['sell', '38334.45', '0.18981474']], 'time': '2021-05-20T03:55:52.233891Z'}
{'type': 'l2update', 'product_id': 'BTC-USD', 'changes': [['buy', '38246.59', '0.02400000']], 'time': '2021-05-20T03:55:52.233996Z'}
{'type': 'l2update', 'product_id': 'BTC-USD', 'changes': [['buy', '38311.83', '0.02000000']], 'time': '2021-05-20T03:55:52.234035Z'}
{'type': 'l2update', 'product_id': 'BTC-USD', 'changes': [['buy', '38297.69', '0.02400000']], 'time': '2021-05-20T03:55:52.238002Z'}
{'type': 'l2update', 'product_id': 'BTC-USD', 'changes': [['sell', '38443.25', '0.03613923']], 'time': '2021-05-20T03:55:52.238159Z'}
{'type': 'l2update', 'product_id': 'BTC-USD', 'changes': [['buy', '38194.51', '0.41663404']], 'time': '2021-05-20T03:55:52.244253Z'}
{'type': 'l2update', 'product_id': 'BTC-USD', 'changes': [['sell', '43100.00', '1.96960000']], 'time': '2021-05-20T03:55:52.250768Z'}
{'type': 'l2update', 'product_id': 'BTC-USD', 'changes': [['buy', '38315.48', '0.01492000']], 'time': '2021-05-20T03:55:52.266164Z'}
{'type': 'l2update', 'product_id': 'BTC-USD', 'changes': [['buy', '38323.48', '0.00176482']], 'time': '2021-05-20T03:55:52.270885Z'}
{'type': 'l2update', 'product_id': 'BTC-USD', 'changes': [['buy', '38311.83', '0.05000000']], 'time': '2021-05-20T03:55:52.272453Z'}
{'type': 'l2update', 'product_id': 'BTC-USD', 'changes': [['sell', '38381.62', '2.16932808']], 'time': '2021-05-20T03:55:52.272754Z'}
{'type': 'l2update', 'product_id': 'BTC-USD', 'changes': [['buy', '38306.66', '0.99315797']], 'time': '2021-05-20T03:55:52.275657Z'}
{'type': 'l2update', 'product_id': 'BTC-USD', 'changes': [['sell', '38333.94', '0.07460000']], 'time': '2021-05-20T03:55:52.275852Z'}
{'type': 'l2update', 'product_id': 'BTC-USD', 'changes': [['sell', '38447.21', '0.01000000']], 'time': '2021-05-20T03:55:52.276487Z'}
{'type': 'l2update', 'product_id': 'BTC-USD', 'changes': [['buy', '38299.71', '0.00000000']], 'time': '2021-05-20T03:55:52.280527Z'}
{'type': 'l2update', 'product_id': 'BTC-USD', 'changes': [['buy', '38298.90', '0.00000000']], 'time': '2021-05-20T03:55:52.280527Z'}
{'type': 'l2update', 'product_id': 'BTC-USD', 'changes': [['buy', '38315.26', '0.07185092']], 'time': '2021-05-20T03:55:52.286731Z'}
{'type': 'l2update', 'product_id': 'BTC-USD', 'changes': [['sell', '38364.00', '0.00000000']], 'time': '2021-05-20T03:55:52.286983Z'}
{'type': 'l2update', 'product_id': 'BTC-USD', 'changes': [['sell', '38443.25', '0.07087753']], 'time': '2021-05-20T03:55:52.288088Z'}
{'type': 'l2update', 'product_id': 'BTC-USD', 'changes': [['buy', '38315.25', '0.02728429']], 'time': '2021-05-20T03:55:52.290687Z'}
{'type': 'l2update', 'product_id': 'BTC-USD', 'changes': [['buy', '38314.73', '0.00000000']], 'time': '2021-05-20T03:55:52.291474Z'}
{'type': 'l2update', 'product_id': 'BTC-USD', 'changes': [['buy', '38311.16', '0.84700000']], 'time': '2021-05-20T03:55:52.293989Z'}
{'type': 'l2update', 'product_id': 'BTC-USD', 'changes': [['sell', '38462.64', '0.72007650']], 'time': '2021-05-20T03:55:52.296903Z'}
{'type': 'l2update', 'product_id': 'BTC-USD', 'changes': [['sell', '38436.38', '0.00000000']], 'time': '2021-05-20T03:55:52.296903Z'}
{'type': 'l2update', 'product_id': 'BTC-USD', 'changes': [['sell', '38420.07', '0.00000000']], 'time': '2021-05-20T03:55:52.296903Z'}
{'type': 'l2update', 'product_id': 'BTC-USD', 'changes': [['sell', '38418.68', '0.00000000']], 'time': '2021-05-20T03:55:52.296903Z'}
{'type': 'l2update', 'product_id': 'BTC-USD', 'changes': [['sell', '38404.68', '0.00000000']], 'time': '2021-05-20T03:55:52.296903Z'}
{'type': 'l2update', 'product_id': 'BTC-USD', 'changes': [['buy', '38315.25', '0.00000000']], 'time': '2021-05-20T03:55:52.299319Z'}
{'type': 'l2update', 'product_id': 'BTC-USD', 'changes': [['sell', '38468.21', '0.00000000']], 'time': '2021-05-20T03:55:52.299336Z'}
{'type': 'l2update', 'product_id': 'BTC-USD', 'changes': [['sell', '38334.19', '0.00000000']], 'time': '2021-05-20T03:55:52.300733Z'}
{'type': 'l2update', 'product_id': 'BTC-USD', 'changes': [['buy', '38308.08', '0.04000000']], 'time': '2021-05-20T03:55:52.303766Z'}
{'type': 'l2update', 'product_id': 'BTC-USD', 'changes': [['sell', '38334.45', '0.00000000']], 'time': '2021-05-20T03:55:52.317295Z'}
{'type': 'l2update', 'product_id': 'BTC-USD', 'changes': [['buy', '38305.24', '0.49450000']], 'time': '2021-05-20T03:55:52.321467Z'}
{'type': 'l2update', 'product_id': 'BTC-USD', 'changes': [['buy', '38315.83', '0.04731571']], 'time': '2021-05-20T03:55:52.321622Z'}
{'type': 'l2update', 'product_id': 'BTC-USD', 'changes': [['buy', '38296.36', '0.02400000']], 'time': '2021-05-20T03:55:52.321765Z'}
{'type': 'l2update', 'product_id': 'BTC-USD', 'changes': [['buy', '38295.56', '0.02400000']], 'time': '2021-05-20T03:55:52.321765Z'}
{'type': 'l2update', 'product_id': 'BTC-USD', 'changes': [['sell', '38450.10', '0.03683800']], 'time': '2021-05-20T03:55:52.322214Z'}
{'type': 'l2update', 'product_id': 'BTC-USD', 'changes': [['sell', '38419.49', '0.05446501']], 'time': '2021-05-20T03:55:52.326854Z'}
{'type': 'l2update', 'product_id': 'BTC-USD', 'changes': [['buy', '38311.23', '0.40135082']], 'time': '2021-05-20T03:55:52.326891Z'}
{'type': 'l2update', 'product_id': 'BTC-USD', 'changes': [['sell', '38455.66', '0.01167620']], 'time': '2021-05-20T03:55:52.330367Z'}
{'type': 'l2update', 'product_id': 'BTC-USD', 'changes': [['sell', '38366.15', '0.01000000']], 'time': '2021-05-20T03:55:52.330873Z'}
{'type': 'l2update', 'product_id': 'BTC-USD', 'changes': [['sell', '38417.87', '0.02723251']], 'time': '2021-05-20T03:55:52.330927Z'}
{'type': 'l2update', 'product_id': 'BTC-USD', 'changes': [['sell', '38333.64', '0.01492000']], 'time': '2021-05-20T03:55:52.335762Z'}
{'type': 'l2update', 'product_id': 'BTC-USD', 'changes': [['buy', '38315.83', '0.07460000']], 'time': '2021-05-20T03:55:52.337054Z'}
{'type': 'l2update', 'product_id': 'BTC-USD', 'changes': [['sell', '38328.19', '0.52198528']], 'time': '2021-05-20T03:55:52.342342Z'}
{'type': 'l2update', 'product_id': 'BTC-USD', 'changes': [['buy', '38306.65', '0.00000000']], 'time': '2021-05-20T03:55:52.350013Z'}
{'type': 'l2update', 'product_id': 'BTC-USD', 'changes': [['buy', '38315.48', '0.00000000']], 'time': '2021-05-20T03:55:52.352681Z'}
{'type': 'l2update', 'product_id': 'BTC-USD', 'changes': [['buy', '38299.14', '0.04478988']], 'time': '2021-05-20T03:55:52.353595Z'}
{'type': 'l2update', 'product_id': 'BTC-USD', 'changes': [['sell', '38340.43', '0.04035580']], 'time': '2021-05-20T03:55:52.353595Z'}
{'type': 'l2update', 'product_id': 'BTC-USD', 'changes': [['sell', '38356.97', '0.45830000']], 'time': '2021-05-20T03:55:52.353900Z'}
{'type': 'l2update', 'product_id': 'BTC-USD', 'changes': [['buy', '38295.20', '0.73518003']], 'time': '2021-05-20T03:55:52.354405Z'}
{'type': 'l2update', 'product_id': 'BTC-USD', 'changes': [['sell', '38422.64', '0.12254627']], 'time': '2021-05-20T03:55:52.354685Z'}
{'type': 'l2update', 'product_id': 'BTC-USD', 'changes': [['sell', '38333.93', '0.18981474']], 'time': '2021-05-20T03:55:52.354780Z'}
{'type': 'l2update', 'product_id': 'BTC-USD', 'changes': [['sell', '38333.94', '0.00000000']], 'time': '2021-05-20T03:55:52.355235Z'}
{'type': 'l2update', 'product_id': 'BTC-USD', 'changes': [['sell', '38417.74', '0.38082202']], 'time': '2021-05-20T03:55:52.359935Z'}
{'type': 'l2update', 'product_id': 'BTC-USD', 'changes': [['sell', '38411.85', '0.32328516']], 'time': '2021-05-20T03:55:52.359935Z'}
{'type': 'l2update', 'product_id': 'BTC-USD', 'changes': [['sell', '38400.64', '0.29802836']], 'time': '2021-05-20T03:55:52.359935Z'}
{'type': 'l2update', 'product_id': 'BTC-USD', 'changes': [['sell', '38395.32', '0.38235442']], 'time': '2021-05-20T03:55:52.359935Z'}
{'type': 'l2update', 'product_id': 'BTC-USD', 'changes': [['sell', '38385.25', '0.33772208']], 'time': '2021-05-20T03:55:52.359935Z'}
{'type': 'l2update', 'product_id': 'BTC-USD', 'changes': [['sell', '38375.93', '0.52161568']], 'time': '2021-05-20T03:55:52.359935Z'}
{'type': 'l2update', 'product_id': 'BTC-USD', 'changes': [['sell', '38333.64', '0.00000000']], 'time': '2021-05-20T03:55:52.362360Z'}
{'type': 'l2update', 'product_id': 'BTC-USD', 'changes': [['buy', '38302.30', '0.00000000']], 'time': '2021-05-20T03:55:52.363105Z'}
{'type': 'l2update', 'product_id': 'BTC-USD', 'changes': [['sell', '38407.85', '0.00000000']], 'time': '2021-05-20T03:55:52.363898Z'}
{'type': 'l2update', 'product_id': 'BTC-USD', 'changes': [['sell', '38382.83', '0.44294184']], 'time': '2021-05-20T03:55:52.363898Z'}
{'type': 'l2update', 'product_id': 'BTC-USD', 'changes': [['buy', '38294.65', '0.48754432']], 'time': '2021-05-20T03:55:52.366396Z'}
{'type': 'l2update', 'product_id': 'BTC-USD', 'changes': [['buy', '38294.65', '0.00000000']], 'time': '2021-05-20T03:55:52.366482Z'}
{'type': 'l2update', 'product_id': 'BTC-USD', 'changes': [['buy', '38306.79', '0.78266655']], 'time': '2021-05-20T03:55:52.371045Z'}
{'type': 'l2update', 'product_id': 'BTC-USD', 'changes': [['sell', '38471.34', '0.00000000']], 'time': '2021-05-20T03:55:52.377589Z'}
{'type': 'l2update', 'product_id': 'BTC-USD', 'changes': [['sell', '38464.37', '0.00000000']], 'time': '2021-05-20T03:55:52.377589Z'}
{'type': 'l2update', 'product_id': 'BTC-USD', 'changes': [['sell', '38462.64', '0.33772208']], 'time': '2021-05-20T03:55:52.377589Z'}
{'type': 'l2update', 'product_id': 'BTC-USD', 'changes': [['sell', '38462.64', '0.00000000']], 'time': '2021-05-20T03:55:52.377589Z'}
{'type': 'l2update', 'product_id': 'BTC-USD', 'changes': [['sell', '38437.20', '0.00000000']], 'time': '2021-05-20T03:55:52.377589Z'}
{'type': 'l2update', 'product_id': 'BTC-USD', 'changes': [['buy', '38154.97', '0.00000000']], 'time': '2021-05-20T03:55:52.381086Z'}
{'type': 'l2update', 'product_id': 'BTC-USD', 'changes': [['sell', '38392.84', '0.50000000']], 'time': '2021-05-20T03:55:52.382160Z'}
{'type': 'l2update', 'product_id': 'BTC-USD', 'changes': [['sell', '38368.49', '0.01000000']], 'time': '2021-05-20T03:55:52.382654Z'}
{'type': 'l2update', 'product_id': 'BTC-USD', 'changes': [['sell', '38366.66', '0.02000000']], 'time': '2021-05-20T03:55:52.387025Z'}
{'type': 'l2update', 'product_id': 'BTC-USD', 'changes': [['buy', '38316.08', '0.01492000']], 'time': '2021-05-20T03:55:52.392374Z'}
{'type': 'l2update', 'product_id': 'BTC-USD', 'changes': [['sell', '38330.94', '0.52194773']], 'time': '2021-05-20T03:55:52.400261Z'}
{'type': 'l2update', 'product_id': 'BTC-USD', 'changes': [['sell', '38474.35', '0.00000000']], 'time': '2021-05-20T03:55:52.400783Z'}
{'type': 'l2update', 'product_id': 'BTC-USD', 'changes': [['buy', '38315.26', '0.00000000']], 'time': '2021-05-20T03:55:52.403017Z'}
{'type': 'l2update', 'product_id': 'BTC-USD', 'changes': [['buy', '38167.19', '0.00000000']], 'time': '2021-05-20T03:55:52.406674Z'}
{'type': 'l2update', 'product_id': 'BTC-USD', 'changes': [['sell', '38462.64', '0.32140239']], 'time': '2021-05-20T03:55:52.406983Z'}
{'type': 'l2update', 'product_id': 'BTC-USD', 'changes': [['buy', '38152.29', '0.02621074']], 'time': '2021-05-20T03:55:52.407604Z'}
{'type': 'l2update', 'product_id': 'BTC-USD', 'changes': [['sell', '38335.96', '0.00000000']], 'time': '2021-05-20T03:55:52.411443Z'}
{'type': 'l2update', 'product_id': 'BTC-USD', 'changes': [['sell', '38368.05', '0.03000000']], 'time': '2021-05-20T03:55:52.412328Z'}
{'type': 'l2update', 'product_id': 'BTC-USD', 'changes': [['buy', '38167.23', '0.04988991']], 'time': '2021-05-20T03:55:52.412475Z'}
{'type': 'l2update', 'product_id': 'BTC-USD', 'changes': [['sell', '38406.77', '0.17350000']], 'time': '2021-05-20T03:55:52.412708Z'}
{'type': 'l2update', 'product_id': 'BTC-USD', 'changes': [['buy', '38286.09', '0.01000000']], 'time': '2021-05-20T03:55:52.412954Z'}
{'type': 'l2update', 'product_id': 'BTC-USD', 'changes': [['buy', '38315.83', '0.02728429']], 'time': '2021-05-20T03:55:52.413359Z'}
{'type': 'l2update', 'product_id': 'BTC-USD', 'changes': [['sell', '38335.36', '0.00000000']], 'time': '2021-05-20T03:55:52.413829Z'}
{'type': 'l2update', 'product_id': 'BTC-USD', 'changes': [['sell', '38443.24', '0.02730472']], 'time': '2021-05-20T03:55:52.420800Z'}
{'type': 'l2update', 'product_id': 'BTC-USD', 'changes': [['sell', '38393.03', '0.06386784']], 'time': '2021-05-20T03:55:52.420800Z'}
{'type': 'l2update', 'product_id': 'BTC-USD', 'changes': [['sell', '38385.25', '0.36961855']], 'time': '2021-05-20T03:55:52.420800Z'}
{'type': 'l2update', 'product_id': 'BTC-USD', 'changes': [['sell', '38333.93', '0.00000000']], 'time': '2021-05-20T03:55:52.422183Z'}
{'type': 'l2update', 'product_id': 'BTC-USD', 'changes': [['sell', '38488.73', '0.01000000']], 'time': '2021-05-20T03:55:52.426593Z'}
{'type': 'l2update', 'product_id': 'BTC-USD', 'changes': [['buy', '38303.18', '0.78273703']], 'time': '2021-05-20T03:55:52.426826Z'}
{'type': 'l2update', 'product_id': 'BTC-USD', 'changes': [['sell', '38323.49', '0.00422238']], 'time': '2021-05-20T03:55:52.427218Z'}
{'type': 'l2update', 'product_id': 'BTC-USD', 'changes': [['sell', '38323.49', '0.05878681']], 'time': '2021-05-20T03:55:52.428519Z'}
{'type': 'l2update', 'product_id': 'BTC-USD', 'changes': [['buy', '38315.83', '0.00000000']], 'time': '2021-05-20T03:55:52.430323Z'}
{'type': 'l2update', 'product_id': 'BTC-USD', 'changes': [['sell', '38479.23', '0.00000000']], 'time': '2021-05-20T03:55:52.431599Z'}
{'type': 'l2update', 'product_id': 'BTC-USD', 'changes': [['buy', '38155.36', '0.01000000']], 'time': '2021-05-20T03:55:52.432081Z'}
{'type': 'l2update', 'product_id': 'BTC-USD', 'changes': [['sell', '38323.49', '0.06948443']], 'time': '2021-05-20T03:55:52.432304Z'}
{'type': 'l2update', 'product_id': 'BTC-USD', 'changes': [['sell', '38340.27', '1.01000000']], 'time': '2021-05-20T03:55:52.435809Z'}
{'type': 'l2update', 'product_id': 'BTC-USD', 'changes': [['sell', '38368.50', '0.04000000']], 'time': '2021-05-20T03:55:52.436283Z'}
{'type': 'l2update', 'product_id': 'BTC-USD', 'changes': [['sell', '38430.11', '0.42718501']], 'time': '2021-05-20T03:55:52.436418Z'}
{'type': 'l2update', 'product_id': 'BTC-USD', 'changes': [['sell', '38417.29', '0.00000000']], 'time': '2021-05-20T03:55:52.437116Z'}
{'type': 'l2update', 'product_id': 'BTC-USD', 'changes': [['sell', '38413.17', '0.00000000']], 'time': '2021-05-20T03:55:52.437116Z'}
{'type': 'l2update', 'product_id': 'BTC-USD', 'changes': [['buy', '38233.02', '0.00000000']], 'time': '2021-05-20T03:55:52.444140Z'}
{'type': 'l2update', 'product_id': 'BTC-USD', 'changes': [['sell', '38323.49', '0.01492000']], 'time': '2021-05-20T03:55:52.444222Z'}
{'type': 'l2update', 'product_id': 'BTC-USD', 'changes': [['buy', '38316.08', '0.00000000']], 'time': '2021-05-20T03:55:52.445484Z'}
{'type': 'l2update', 'product_id': 'BTC-USD', 'changes': [['sell', '38336.02', '0.52189576']], 'time': '2021-05-20T03:55:52.448617Z'}
{'type': 'l2update', 'product_id': 'BTC-USD', 'changes': [['sell', '38372.77', '0.00000000']], 'time': '2021-05-20T03:55:52.448669Z'}
{'type': 'l2update', 'product_id': 'BTC-USD', 'changes': [['buy', '38316.55', '0.04731571']], 'time': '2021-05-20T03:55:52.449163Z'}
{'type': 'l2update', 'product_id': 'BTC-USD', 'changes': [['sell', '38323.49', '0.11492000']], 'time': '2021-05-20T03:55:52.452389Z'}
{'type': 'l2update', 'product_id': 'BTC-USD', 'changes': [['sell', '38374.10', '0.00000000']], 'time': '2021-05-20T03:55:52.452416Z'}
{'type': 'l2update', 'product_id': 'BTC-USD', 'changes': [['sell', '38323.49', '0.14382000']], 'time': '2021-05-20T03:55:52.452674Z'}
{'type': 'l2update', 'product_id': 'BTC-USD', 'changes': [['sell', '38456.37', '0.01263967']], 'time': '2021-05-20T03:55:52.453432Z'}
{'type': 'l2update', 'product_id': 'BTC-USD', 'changes': [['buy', '38214.22', '0.00000000']], 'time': '2021-05-20T03:55:52.454178Z'}
{'type': 'l2update', 'product_id': 'BTC-USD', 'changes': [['buy', '38276.91', '0.09693319']], 'time': '2021-05-20T03:55:52.456088Z'}
{'type': 'l2update', 'product_id': 'BTC-USD', 'changes': [['sell', '38334.91', '0.18981474']], 'time': '2021-05-20T03:55:52.456439Z'}
{'type': 'l2update', 'product_id': 'BTC-USD', 'changes': [['buy', '38320.03', '0.05098184']], 'time': '2021-05-20T03:55:52.456984Z'}
{'type': 'l2update', 'product_id': 'BTC-USD', 'changes': [['sell', '38334.91', '1.67164878']], 'time': '2021-05-20T03:55:52.457066Z'}
{'type': 'l2update', 'product_id': 'BTC-USD', 'changes': [['sell', '38470.09', '0.00000000']], 'time': '2021-05-20T03:55:52.457158Z'}
{'type': 'l2update', 'product_id': 'BTC-USD', 'changes': [['sell', '38443.24', '0.36850007']], 'time': '2021-05-20T03:55:52.461746Z'}
{'type': 'l2update', 'product_id': 'BTC-USD', 'changes': [['sell', '38490.53', '0.00000000']], 'time': '2021-05-20T03:55:52.462193Z'}
{'type': 'l2update', 'product_id': 'BTC-USD', 'changes': [['buy', '38276.35', '0.00000000']], 'time': '2021-05-20T03:55:52.464698Z'}
{'type': 'l2update', 'product_id': 'BTC-USD', 'changes': [['buy', '38308.08', '0.00000000']], 'time': '2021-05-20T03:55:52.464772Z'}
{'type': 'l2update', 'product_id': 'BTC-USD', 'changes': [['sell', '38336.00', '0.00000000']], 'time': '2021-05-20T03:55:52.464922Z'}
{'type': 'l2update', 'product_id': 'BTC-USD', 'changes': [['buy', '38219.73', '0.01000000']], 'time': '2021-05-20T03:55:52.466326Z'}
{'type': 'l2update', 'product_id': 'BTC-USD', 'changes': [['buy', '38312.25', '0.02728429']], 'time': '2021-05-20T03:55:52.471051Z'}
{'type': 'l2update', 'product_id': 'BTC-USD', 'changes': [['buy', '38298.14', '0.78284363']], 'time': '2021-05-20T03:55:52.471326Z'}
{'type': 'l2update', 'product_id': 'BTC-USD', 'changes': [['sell', '38387.23', '0.00000000']], 'time': '2021-05-20T03:55:52.471910Z'}
{'type': 'l2update', 'product_id': 'BTC-USD', 'changes': [['sell', '38336.01', '0.65000000']], 'time': '2021-05-20T03:55:52.476826Z'}
{'type': 'l2update', 'product_id': 'BTC-USD', 'changes': [['sell', '38323.49', '0.34382000']], 'time': '2021-05-20T03:55:52.477901Z'}
{'type': 'l2update', 'product_id': 'BTC-USD', 'changes': [['sell', '38340.43', '0.00000000']], 'time': '2021-05-20T03:55:52.478430Z'}
{'type': 'l2update', 'product_id': 'BTC-USD', 'changes': [['sell', '38397.10', '0.00000000']], 'time': '2021-05-20T03:55:52.478729Z'}
{'type': 'l2update', 'product_id': 'BTC-USD', 'changes': [['buy', '38167.23', '0.00000000']], 'time': '2021-05-20T03:55:52.480075Z'}
{'type': 'l2update', 'product_id': 'BTC-USD', 'changes': [['buy', '38311.11', '0.00000000']], 'time': '2021-05-20T03:55:52.480557Z'}
{'type': 'l2update', 'product_id': 'BTC-USD', 'changes': [['sell', '38347.72', '0.00000000']], 'time': '2021-05-20T03:55:52.483436Z'}
{'type': 'l2update', 'product_id': 'BTC-USD', 'changes': [['buy', '38312.25', '0.00000000']], 'time': '2021-05-20T03:55:52.484382Z'}
{'type': 'l2update', 'product_id': 'BTC-USD', 'changes': [['buy', '38316.55', '0.00000000']], 'time': '2021-05-20T03:55:52.484700Z'}
{'type': 'l2update', 'product_id': 'BTC-USD', 'changes': [['sell', '38331.30', '0.05150972']], 'time': '2021-05-20T03:55:52.485179Z'}
{'type': 'l2update', 'product_id': 'BTC-USD', 'changes': [['sell', '38450.09', '0.40353284']], 'time': '2021-05-20T03:55:52.485243Z'}
{'type': 'l2update', 'product_id': 'BTC-USD', 'changes': [['buy', '38167.48', '0.01000000']], 'time': '2021-05-20T03:55:52.485315Z'}
{'type': 'l2update', 'product_id': 'BTC-USD', 'changes': [['sell', '38323.49', '0.37382000']], 'time': '2021-05-20T03:55:52.485406Z'}
{'type': 'l2update', 'product_id': 'BTC-USD', 'changes': [['sell', '38352.67', '0.05037802']], 'time': '2021-05-20T03:55:52.491007Z'}
{'type': 'l2update', 'product_id': 'BTC-USD', 'changes': [['sell', '38379.68', '0.00000000']], 'time': '2021-05-20T03:55:52.491950Z'}
{'type': 'l2update', 'product_id': 'BTC-USD', 'changes': [['sell', '38343.52', '0.78297792']], 'time': '2021-05-20T03:55:52.492822Z'}
{'type': 'l2update', 'product_id': 'BTC-USD', 'changes': [['buy', '38260.45', '1.28176324']], 'time': '2021-05-20T03:55:52.492913Z'}
{'type': 'l2update', 'product_id': 'BTC-USD', 'changes': [['sell', '38328.18', '0.50000000']], 'time': '2021-05-20T03:55:52.492954Z'}
{'type': 'l2update', 'product_id': 'BTC-USD', 'changes': [['buy', '35250.00', '1.05616223']], 'time': '2021-05-20T03:55:52.493138Z'}
{'type': 'l2update', 'product_id': 'BTC-USD', 'changes': [['buy', '38299.14', '0.00000000']], 'time': '2021-05-20T03:55:52.494790Z'}
{'type': 'l2update', 'product_id': 'BTC-USD', 'changes': [['sell', '38347.57', '0.39490432']], 'time': '2021-05-20T03:55:52.499249Z'}
{'type': 'l2update', 'product_id': 'BTC-USD', 'changes': [['sell', '38509.85', '0.00000000']], 'time': '2021-05-20T03:55:52.499627Z'}
{'type': 'l2update', 'product_id': 'BTC-USD', 'changes': [['sell', '38458.04', '0.02486199']], 'time': '2021-05-20T03:55:52.504147Z'}
{'type': 'l2update', 'product_id': 'BTC-USD', 'changes': [['buy', '38311.22', '0.00000000']], 'time': '2021-05-20T03:55:52.508527Z'}
{'type': 'l2update', 'product_id': 'BTC-USD', 'changes': [['sell', '38381.15', '0.61482416']], 'time': '2021-05-20T03:55:52.509001Z'}
{'type': 'l2update', 'product_id': 'BTC-USD', 'changes': [['sell', '38532.31', '0.01297612']], 'time': '2021-05-20T03:55:52.509077Z'}
{'type': 'l2update', 'product_id': 'BTC-USD', 'changes': [['sell', '38425.56', '0.00000000']], 'time': '2021-05-20T03:55:52.511694Z'}
{'type': 'l2update', 'product_id': 'BTC-USD', 'changes': [['sell', '38392.84', '0.00000000']], 'time': '2021-05-20T03:55:52.512601Z'}
{'type': 'l2update', 'product_id': 'BTC-USD', 'changes': [['sell', '38359.31', '0.00000000']], 'time': '2021-05-20T03:55:52.512946Z'}
{'type': 'l2update', 'product_id': 'BTC-USD', 'changes': [['sell', '38354.92', '0.10000000']], 'time': '2021-05-20T03:55:52.513836Z'}
{'type': 'l2update', 'product_id': 'BTC-USD', 'changes': [['sell', '38443.24', '0.34119535']], 'time': '2021-05-20T03:55:52.515527Z'}
{'type': 'l2update', 'product_id': 'BTC-USD', 'changes': [['sell', '38429.66', '0.00000000']], 'time': '2021-05-20T03:55:52.515527Z'}
{'type': 'l2update', 'product_id': 'BTC-USD', 'changes': [['sell', '38423.38', '0.00000000']], 'time': '2021-05-20T03:55:52.515527Z'}
{'type': 'l2update', 'product_id': 'BTC-USD', 'changes': [['sell', '38382.83', '0.40758107']], 'time': '2021-05-20T03:55:52.515527Z'}
{'type': 'l2update', 'product_id': 'BTC-USD', 'changes': [['buy', '38291.70', '0.78297470']], 'time': '2021-05-20T03:55:52.519521Z'}
{'type': 'l2update', 'product_id': 'BTC-USD', 'changes': [['buy', '38311.16', '0.00000000']], 'time': '2021-05-20T03:55:52.520953Z'}
{'type': 'l2update', 'product_id': 'BTC-USD', 'changes': [['sell', '38342.89', '0.00000000']], 'time': '2021-05-20T03:55:52.521692Z'}
{'type': 'l2update', 'product_id': 'BTC-USD', 'changes': [['buy', '38320.03', '0.00000000']], 'time': '2021-05-20T03:55:52.522935Z'}
{'type': 'l2update', 'product_id': 'BTC-USD', 'changes': [['sell', '38335.42', '0.00000000']], 'time': '2021-05-20T03:55:52.524325Z'}
{'type': 'l2update', 'product_id': 'BTC-USD', 'changes': [['sell', '38356.97', '0.00000000']], 'time': '2021-05-20T03:55:52.524399Z'}
{'type': 'l2update', 'product_id': 'BTC-USD', 'changes': [['sell', '38496.67', '0.01000000']], 'time': '2021-05-20T03:55:52.525868Z'}
{'type': 'l2update', 'product_id': 'BTC-USD', 'changes': [['buy', '38311.23', '0.00000000']], 'time': '2021-05-20T03:55:52.526542Z'}
{'type': 'l2update', 'product_id': 'BTC-USD', 'changes': [['buy', '38311.03', '0.00000000']], 'time': '2021-05-20T03:55:52.526733Z'}
{'type': 'l2update', 'product_id': 'BTC-USD', 'changes': [['sell', '38334.92', '0.00000000']], 'time': '2021-05-20T03:55:52.526905Z'}
{'type': 'l2update', 'product_id': 'BTC-USD', 'changes': [['buy', '38323.48', '0.15176482']], 'time': '2021-05-20T03:55:52.530067Z'}
{'type': 'l2update', 'product_id': 'BTC-USD', 'changes': [['sell', '38368.49', '0.00000000']], 'time': '2021-05-20T03:55:52.530250Z'}
{'type': 'l2update', 'product_id': 'BTC-USD', 'changes': [['sell', '38334.91', '1.48183404']], 'time': '2021-05-20T03:55:52.530387Z'}
{'type': 'l2update', 'product_id': 'BTC-USD', 'changes': [['sell', '38506.67', '0.01000000']], 'time': '2021-05-20T03:55:52.535777Z'}
{'type': 'l2update', 'product_id': 'BTC-USD', 'changes': [['sell', '38331.25', '1.02000000']], 'time': '2021-05-20T03:55:52.536298Z'}
{'type': 'l2update', 'product_id': 'BTC-USD', 'changes': [['buy', '38163.70', '0.00000000']], 'time': '2021-05-20T03:55:52.536930Z'}
{'type': 'l2update', 'product_id': 'BTC-USD', 'changes': [['sell', '38355.10', '1.30482541']], 'time': '2021-05-20T03:55:52.541485Z'}
{'type': 'l2update', 'product_id': 'BTC-USD', 'changes': [['sell', '38443.24', '0.37366641']], 'time': '2021-05-20T03:55:52.541605Z'}
{'type': 'l2update', 'product_id': 'BTC-USD', 'changes': [['sell', '38457.13', '0.35305660']], 'time': '2021-05-20T03:55:52.542006Z'}
{'type': 'l2update', 'product_id': 'BTC-USD', 'changes': [['buy', '38200.84', '0.07600000']], 'time': '2021-05-20T03:55:52.542212Z'}
{'type': 'l2update', 'product_id': 'BTC-USD', 'changes': [['buy', '38306.66', '0.00000000']], 'time': '2021-05-20T03:55:52.542932Z'}
{'type': 'l2update', 'product_id': 'BTC-USD', 'changes': [['sell', '38455.66', '0.00000000']], 'time': '2021-05-20T03:55:52.545628Z'}
{'type': 'l2update', 'product_id': 'BTC-USD', 'changes': [['sell', '38358.18', '0.46750000']], 'time': '2021-05-20T03:55:52.546906Z'}
{'type': 'l2update', 'product_id': 'BTC-USD', 'changes': [['sell', '38347.56', '0.05000000']], 'time': '2021-05-20T03:55:52.547363Z'}
{'type': 'l2update', 'product_id': 'BTC-USD', 'changes': [['buy', '38223.13', '0.07800000']], 'time': '2021-05-20T03:55:52.547522Z'}
{'type': 'l2update', 'product_id': 'BTC-USD', 'changes': [['buy', '38286.09', '0.00000000']], 'time': '2021-05-20T03:55:52.547608Z'}
{'type': 'l2update', 'product_id': 'BTC-USD', 'changes': [['buy', '38312.24', '0.07460000']], 'time': '2021-05-20T03:55:52.552426Z'}
{'type': 'l2update', 'product_id': 'BTC-USD', 'changes': [['buy', '38208.27', '0.07800000']], 'time': '2021-05-20T03:55:52.554598Z'}
{'type': 'l2update', 'product_id': 'BTC-USD', 'changes': [['sell', '38354.02', '0.00000000']], 'time': '2021-05-20T03:55:52.555850Z'}
{'type': 'l2update', 'product_id': 'BTC-USD', 'changes': [['sell', '38460.13', '0.00000000']], 'time': '2021-05-20T03:55:52.556608Z'}
{'type': 'l2update', 'product_id': 'BTC-USD', 'changes': [['sell', '38419.49', '0.00000000']], 'time': '2021-05-20T03:55:52.557901Z'}
{'type': 'l2update', 'product_id': 'BTC-USD', 'changes': [['sell', '38422.64', '0.00000000']], 'time': '2021-05-20T03:55:52.558713Z'}
{'type': 'l2update', 'product_id': 'BTC-USD', 'changes': [['sell', '38334.91', '0.00000000']], 'time': '2021-05-20T03:55:52.558884Z'}
{'type': 'l2update', 'product_id': 'BTC-USD', 'changes': [['sell', '38368.70', '0.49883766']], 'time': '2021-05-20T03:55:52.561248Z'}
{'type': 'l2update', 'product_id': 'BTC-USD', 'changes': [['sell', '38374.78', '0.09082787']], 'time': '2021-05-20T03:55:52.561401Z'}
{'type': 'l2update', 'product_id': 'BTC-USD', 'changes': [['buy', '38305.24', '0.00000000']], 'time': '2021-05-20T03:55:52.563141Z'}
{'type': 'l2update', 'product_id': 'BTC-USD', 'changes': [['sell', '38608.01', '0.00000000']], 'time': '2021-05-20T03:55:52.566147Z'}
{'type': 'l2update', 'product_id': 'BTC-USD', 'changes': [['sell', '38394.01', '0.07700000']], 'time': '2021-05-20T03:55:52.567182Z'}
{'type': 'l2update', 'product_id': 'BTC-USD', 'changes': [['buy', '38274.46', '2.60900107']], 'time': '2021-05-20T03:55:52.567894Z'}
{'type': 'l2update', 'product_id': 'BTC-USD', 'changes': [['buy', '38312.24', '0.00000000']], 'time': '2021-05-20T03:55:52.569123Z'}
{'type': 'l2update', 'product_id': 'BTC-USD', 'changes': [['sell', '38429.54', '0.02526975']], 'time': '2021-05-20T03:55:52.573077Z'}
{'type': 'l2update', 'product_id': 'BTC-USD', 'changes': [['sell', '38328.17', '0.18981474']], 'time': '2021-05-20T03:55:52.574536Z'}
{'type': 'l2update', 'product_id': 'BTC-USD', 'changes': [['sell', '38442.89', '0.01167699']], 'time': '2021-05-20T03:55:52.575063Z'}
{'type': 'l2update', 'product_id': 'BTC-USD', 'changes': [['sell', '38328.17', '2.67951382']], 'time': '2021-05-20T03:55:52.575260Z'}
{'type': 'l2update', 'product_id': 'BTC-USD', 'changes': [['sell', '38462.64', '0.63000697']], 'time': '2021-05-20T03:55:52.575444Z'}
{'type': 'l2update', 'product_id': 'BTC-USD', 'changes': [['buy', '38299.14', '0.04478988']], 'time': '2021-05-20T03:55:52.575460Z'}
{'type': 'l2update', 'product_id': 'BTC-USD', 'changes': [['sell', '38340.43', '0.05480459']], 'time': '2021-05-20T03:55:52.575460Z'}
{'type': 'l2update', 'product_id': 'BTC-USD', 'changes': [['buy', '38292.16', '0.00000000']], 'time': '2021-05-20T03:55:52.575835Z'}
{'type': 'l2update', 'product_id': 'BTC-USD', 'changes': [['sell', '38450.10', '0.00000000']], 'time': '2021-05-20T03:55:52.579667Z'}
{'type': 'l2update', 'product_id': 'BTC-USD', 'changes': [['sell', '38443.25', '0.03473830']], 'time': '2021-05-20T03:55:52.579667Z'}
{'type': 'l2update', 'product_id': 'BTC-USD', 'changes': [['sell', '38443.25', '0.00000000']], 'time': '2021-05-20T03:55:52.579667Z'}
{'type': 'l2update', 'product_id': 'BTC-USD', 'changes': [['sell', '38393.03', '0.03300600']], 'time': '2021-05-20T03:55:52.579667Z'}
{'type': 'l2update', 'product_id': 'BTC-USD', 'changes': [['sell', '38385.25', '0.33772208']], 'time': '2021-05-20T03:55:52.579667Z'}
{'type': 'l2update', 'product_id': 'BTC-USD', 'changes': [['sell', '38379.03', '0.53871582']], 'time': '2021-05-20T03:55:52.579667Z'}
{'type': 'l2update', 'product_id': 'BTC-USD', 'changes': [['buy', '38289.72', '0.00000000']], 'time': '2021-05-20T03:55:52.579667Z'}
{'type': 'l2update', 'product_id': 'BTC-USD', 'changes': [['buy', '37654.92', '0.06170000']], 'time': '2021-05-20T03:55:52.583514Z'}
{'type': 'l2update', 'product_id': 'BTC-USD', 'changes': [['buy', '37500.01', '0.01240000']], 'time': '2021-05-20T03:55:52.583514Z'}
{'type': 'l2update', 'product_id': 'BTC-USD', 'changes': [['buy', '38311.02', '0.00000000']], 'time': '2021-05-20T03:55:52.586283Z'}
{'type': 'l2update', 'product_id': 'BTC-USD', 'changes': [['sell', '38365.45', '2.60947876']], 'time': '2021-05-20T03:55:52.588725Z'}
{'type': 'l2update', 'product_id': 'BTC-USD', 'changes': [['sell', '38349.88', '0.15300000']], 'time': '2021-05-20T03:55:52.588868Z'}
{'type': 'l2update', 'product_id': 'BTC-USD', 'changes': [['sell', '38594.92', '0.12955075']], 'time': '2021-05-20T03:55:52.588981Z'}
{'type': 'l2update', 'product_id': 'BTC-USD', 'changes': [['sell', '38338.67', '0.05000000']], 'time': '2021-05-20T03:55:52.589124Z'}
{'type': 'l2update', 'product_id': 'BTC-USD', 'changes': [['sell', '38440.01', '0.01000000']], 'time': '2021-05-20T03:55:52.589493Z'}
{'type': 'l2update', 'product_id': 'BTC-USD', 'changes': [['buy', '38303.59', '0.48140000']], 'time': '2021-05-20T03:55:52.589940Z'}
{'type': 'l2update', 'product_id': 'BTC-USD', 'changes': [['buy', '37500.01', '0.07610000']], 'time': '2021-05-20T03:55:52.590887Z'}
{'type': 'l2update', 'product_id': 'BTC-USD', 'changes': [['sell', '38380.35', '0.07700000']], 'time': '2021-05-20T03:55:52.591063Z'}
{'type': 'l2update', 'product_id': 'BTC-USD', 'changes': [['sell', '38496.67', '0.00000000']], 'time': '2021-05-20T03:55:52.591435Z'}
{'type': 'l2update', 'product_id': 'BTC-USD', 'changes': [['buy', '38310.49', '0.00000000']], 'time': '2021-05-20T03:55:52.592458Z'}
{'type': 'l2update', 'product_id': 'BTC-USD', 'changes': [['sell', '38328.17', '3.79695908']], 'time': '2021-05-20T03:55:52.594392Z'}
{'type': 'l2update', 'product_id': 'BTC-USD', 'changes': [['buy', '38311.07', '0.40135082']], 'time': '2021-05-20T03:55:52.594421Z'}
{'type': 'l2update', 'product_id': 'BTC-USD', 'changes': [['buy', '38297.69', '0.00000000']], 'time': '2021-05-20T03:55:52.595517Z'}
{'type': 'l2update', 'product_id': 'BTC-USD', 'changes': [['buy', '38282.96', '0.00000000']], 'time': '2021-05-20T03:55:52.596306Z'}
{'type': 'l2update', 'product_id': 'BTC-USD', 'changes': [['buy', '38315.13', '0.01000000']], 'time': '2021-05-20T03:55:52.601462Z'}
{'type': 'l2update', 'product_id': 'BTC-USD', 'changes': [['buy', '38305.25', '0.99315797']], 'time': '2021-05-20T03:55:52.601565Z'}
{'type': 'l2update', 'product_id': 'BTC-USD', 'changes': [['buy', '38323.48', '0.15000000']], 'time': '2021-05-20T03:55:52.602158Z'}
{'type': 'l2update', 'product_id': 'BTC-USD', 'changes': [['buy', '38323.48', '0.08616482']], 'time': '2021-05-20T03:55:52.602158Z'}
{'type': 'l2update', 'product_id': 'BTC-USD', 'changes': [['buy', '38150.55', '0.00000000']], 'time': '2021-05-20T03:55:52.602332Z'}
{'type': 'l2update', 'product_id': 'BTC-USD', 'changes': [['buy', '38303.59', '0.00000000']], 'time': '2021-05-20T03:55:52.603207Z'}
{'type': 'l2update', 'product_id': 'BTC-USD', 'changes': [['buy', '38323.48', '0.00006482']], 'time': '2021-05-20T03:55:52.606085Z'}
{'type': 'l2update', 'product_id': 'BTC-USD', 'changes': [['sell', '38343.73', '0.04852393']], 'time': '2021-05-20T03:55:52.606150Z'}
{'type': 'l2update', 'product_id': 'BTC-USD', 'changes': [['buy', '38270.36', '2.60929285']], 'time': '2021-05-20T03:55:52.606354Z'}
{'type': 'l2update', 'product_id': 'BTC-USD', 'changes': [['sell', '38649.94', '0.00000000']], 'time': '2021-05-20T03:55:52.609006Z'}
{'type': 'l2update', 'product_id': 'BTC-USD', 'changes': [['sell', '38367.39', '0.16303243']], 'time': '2021-05-20T03:55:52.611781Z'}
{'type': 'l2update', 'product_id': 'BTC-USD', 'changes': [['buy', '38183.13', '0.30485796']], 'time': '2021-05-20T03:55:52.611781Z'}
{'type': 'l2update', 'product_id': 'BTC-USD', 'changes': [['buy', '37422.63', '0.00000000']], 'time': '2021-05-20T03:55:52.612275Z'}
{'type': 'l2update', 'product_id': 'BTC-USD', 'changes': [['buy', '36655.76', '0.00000000']], 'time': '2021-05-20T03:55:52.612275Z'}
{'type': 'l2update', 'product_id': 'BTC-USD', 'changes': [['buy', '38121.04', '0.05295049']], 'time': '2021-05-20T03:55:52.612428Z'}
{'type': 'l2update', 'product_id': 'BTC-USD', 'changes': [['sell', '38328.17', '2.67951382']], 'time': '2021-05-20T03:55:52.613382Z'}
{'type': 'l2update', 'product_id': 'BTC-USD', 'changes': [['buy', '38181.69', '0.00000000']], 'time': '2021-05-20T03:55:52.613564Z'}
{'type': 'l2update', 'product_id': 'BTC-USD', 'changes': [['buy', '38296.36', '0.00000000']], 'time': '2021-05-20T03:55:52.614353Z'}
{'type': 'l2update', 'product_id': 'BTC-USD', 'changes': [['sell', '38323.49', '0.37955000']], 'time': '2021-05-20T03:55:52.616879Z'}
{'type': 'l2update', 'product_id': 'BTC-USD', 'changes': [['sell', '38483.50', '0.01000000']], 'time': '2021-05-20T03:55:52.617362Z'}
{'type': 'l2update', 'product_id': 'BTC-USD', 'changes': [['sell', '38361.16', '0.00000000']], 'time': '2021-05-20T03:55:52.619806Z'}
{'type': 'l2update', 'product_id': 'BTC-USD', 'changes': [['sell', '38358.18', '0.00000000']], 'time': '2021-05-20T03:55:52.620592Z'}
{'type': 'l2update', 'product_id': 'BTC-USD', 'changes': [['buy', '38323.48', '0.00000000']], 'time': '2021-05-20T03:55:52.624809Z'}
{'type': 'l2update', 'product_id': 'BTC-USD', 'changes': [['buy', '38246.59', '0.00000000']], 'time': '2021-05-20T03:55:52.626628Z'}
{'type': 'l2update', 'product_id': 'BTC-USD', 'changes': [['sell', '38385.25', '0.00000000']], 'time': '2021-05-20T03:55:52.627210Z'}
{'type': 'l2update', 'product_id': 'BTC-USD', 'changes': [['sell', '38382.83', '0.00000000']], 'time': '2021-05-20T03:55:52.627210Z'}
{'type': 'l2update', 'product_id': 'BTC-USD', 'changes': [['buy', '38262.11', '0.00000000']], 'time': '2021-05-20T03:55:52.627210Z'}
{'type': 'l2update', 'product_id': 'BTC-USD', 'changes': [['buy', '38315.13', '0.05000000']], 'time': '2021-05-20T03:55:52.628766Z'}
{'type': 'l2update', 'product_id': 'BTC-USD', 'changes': [['sell', '38367.39', '0.19551082']], 'time': '2021-05-20T03:55:52.628840Z'}
{'type': 'l2update', 'product_id': 'BTC-USD', 'changes': [['sell', '38363.40', '0.03247106']], 'time': '2021-05-20T03:55:52.628840Z'}
{'type': 'l2update', 'product_id': 'BTC-USD', 'changes': [['sell', '38487.16', '0.30083406']], 'time': '2021-05-20T03:55:52.628933Z'}
{'type': 'l2update', 'product_id': 'BTC-USD', 'changes': [['sell', '38374.78', '0.00000000']], 'time': '2021-05-20T03:55:52.632694Z'}
{'type': 'l2update', 'product_id': 'BTC-USD', 'changes': [['buy', '38262.55', '2.60982290']], 'time': '2021-05-20T03:55:52.634106Z'}
{'type': 'l2update', 'product_id': 'BTC-USD', 'changes': [['sell', '38315.14', '0.04330000']], 'time': '2021-05-20T03:55:52.634172Z'}
{'type': 'l2update', 'product_id': 'BTC-USD', 'changes': [['sell', '38394.95', '0.00000000']], 'time': '2021-05-20T03:55:52.634881Z'}
{'type': 'l2update', 'product_id': 'BTC-USD', 'changes': [['sell', '38328.17', '2.48969908']], 'time': '2021-05-20T03:55:52.636901Z'}
{'type': 'l2update', 'product_id': 'BTC-USD', 'changes': [['buy', '38307.58', '0.05152268']], 'time': '2021-05-20T03:55:52.638287Z'}
{'type': 'l2update', 'product_id': 'BTC-USD', 'changes': [['sell', '38532.31', '0.00000000']], 'time': '2021-05-20T03:55:52.638670Z'}
{'type': 'l2update', 'product_id': 'BTC-USD', 'changes': [['sell', '38352.67', '0.00000000']], 'time': '2021-05-20T03:55:52.639258Z'}
{'type': 'l2update', 'product_id': 'BTC-USD', 'changes': [['sell', '38459.77', '0.00000000']], 'time': '2021-05-20T03:55:52.639403Z'}
{'type': 'l2update', 'product_id': 'BTC-USD', 'changes': [['sell', '38348.32', '0.00000000']], 'time': '2021-05-20T03:55:52.639616Z'}
{'type': 'l2update', 'product_id': 'BTC-USD', 'changes': [['sell', '38323.48', '0.00573000']], 'time': '2021-05-20T03:55:52.642880Z'}
{'type': 'l2update', 'product_id': 'BTC-USD', 'changes': [['sell', '38381.62', '0.00000000']], 'time': '2021-05-20T03:55:52.643267Z'}
{'type': 'l2update', 'product_id': 'BTC-USD', 'changes': [['sell', '38323.08', '0.07460000']], 'time': '2021-05-20T03:55:52.648454Z'}
{'type': 'l2update', 'product_id': 'BTC-USD', 'changes': [['sell', '38328.16', '1.41077464']], 'time': '2021-05-20T03:55:52.648499Z'}
{'type': 'l2update', 'product_id': 'BTC-USD', 'changes': [['sell', '38323.49', '0.77955000']], 'time': '2021-05-20T03:55:52.649596Z'}
{'type': 'l2update', 'product_id': 'BTC-USD', 'changes': [['buy', '38294.50', '0.02400000']], 'time': '2021-05-20T03:55:52.649758Z'}
{'type': 'l2update', 'product_id': 'BTC-USD', 'changes': [['buy', '38293.69', '0.02400000']], 'time': '2021-05-20T03:55:52.649758Z'}
{'type': 'l2update', 'product_id': 'BTC-USD', 'changes': [['sell', '38347.56', '0.00000000']], 'time': '2021-05-20T03:55:52.649831Z'}
{'type': 'l2update', 'product_id': 'BTC-USD', 'changes': [['buy', '38294.30', '0.00000000']], 'time': '2021-05-20T03:55:52.649856Z'}
{'type': 'l2update', 'product_id': 'BTC-USD', 'changes': [['sell', '38374.76', '0.00000000']], 'time': '2021-05-20T03:55:52.649878Z'}
{'type': 'l2update', 'product_id': 'BTC-USD', 'changes': [['sell', '38379.03', '0.41170846']], 'time': '2021-05-20T03:55:52.650556Z'}
{'type': 'l2update', 'product_id': 'BTC-USD', 'changes': [['sell', '38379.03', '0.00000000']], 'time': '2021-05-20T03:55:52.650556Z'}
{'type': 'l2update', 'product_id': 'BTC-USD', 'changes': [['buy', '38274.19', '0.00000000']], 'time': '2021-05-20T03:55:52.651732Z'}
{'type': 'l2update', 'product_id': 'BTC-USD', 'changes': [['sell', '38483.50', '0.00000000']], 'time': '2021-05-20T03:55:52.652248Z'}
{'type': 'l2update', 'product_id': 'BTC-USD', 'changes': [['sell', '38382.35', '0.00000000']], 'time': '2021-05-20T03:55:52.654434Z'}
{'type': 'l2update', 'product_id': 'BTC-USD', 'changes': [['sell', '38323.49', '0.75065000']], 'time': '2021-05-20T03:55:52.656672Z'}
{'type': 'l2update', 'product_id': 'BTC-USD', 'changes': [['buy', '38305.25', '0.00000000']], 'time': '2021-05-20T03:55:52.657345Z'}
{'type': 'l2update', 'product_id': 'BTC-USD', 'changes': [['sell', '38336.01', '0.00000000']], 'time': '2021-05-20T03:55:52.657362Z'}
{'type': 'l2update', 'product_id': 'BTC-USD', 'changes': [['buy', '38315.13', '0.10000000']], 'time': '2021-05-20T03:55:52.657590Z'}
{'type': 'l2update', 'product_id': 'BTC-USD', 'changes': [['sell', '38323.49', '0.74642762']], 'time': '2021-05-20T03:55:52.657626Z'}
{'type': 'l2update', 'product_id': 'BTC-USD', 'changes': [['sell', '38363.40', '0.04567346']], 'time': '2021-05-20T03:55:52.657655Z'}
{'type': 'l2update', 'product_id': 'BTC-USD', 'changes': [['buy', '38204.12', '0.03247839']], 'time': '2021-05-20T03:55:52.657655Z'}
{'type': 'l2update', 'product_id': 'BTC-USD', 'changes': [['sell', '38323.49', '0.73573000']], 'time': '2021-05-20T03:55:52.658116Z'}
{'type': 'l2update', 'product_id': 'BTC-USD', 'changes': [['sell', '38323.48', '0.20573000']], 'time': '2021-05-20T03:55:52.658187Z'}
{'type': 'l2update', 'product_id': 'BTC-USD', 'changes': [['sell', '38368.70', '0.00000000']], 'time': '2021-05-20T03:55:52.659683Z'}
{'type': 'l2update', 'product_id': 'BTC-USD', 'changes': [['buy', '37544.90', '0.00000000']], 'time': '2021-05-20T03:55:52.663855Z'}
{'type': 'l2update', 'product_id': 'BTC-USD', 'changes': [['buy', '38311.07', '0.00000000']], 'time': '2021-05-20T03:55:52.664442Z'}
{'type': 'l2update', 'product_id': 'BTC-USD', 'changes': [['sell', '38323.49', '0.73000000']], 'time': '2021-05-20T03:55:52.666381Z'}
{'type': 'l2update', 'product_id': 'BTC-USD', 'changes': [['sell', '38436.00', '0.01300863']], 'time': '2021-05-20T03:55:52.669109Z'}
{'type': 'l2update', 'product_id': 'BTC-USD', 'changes': [['sell', '38323.08', '0.00000000']], 'time': '2021-05-20T03:55:52.669623Z'}
{'type': 'l2update', 'product_id': 'BTC-USD', 'changes': [['buy', '38295.61', '0.52100000']], 'time': '2021-05-20T03:55:52.670073Z'}
{'type': 'l2update', 'product_id': 'BTC-USD', 'changes': [['sell', '38374.09', '0.02605925']], 'time': '2021-05-20T03:55:52.670160Z'}
{'type': 'l2update', 'product_id': 'BTC-USD', 'changes': [['sell', '38708.23', '0.01000000']], 'time': '2021-05-20T03:55:52.670441Z'}
{'type': 'l2update', 'product_id': 'BTC-USD', 'changes': [['sell', '38328.18', '0.00000000']], 'time': '2021-05-20T03:55:52.670743Z'}
{'type': 'l2update', 'product_id': 'BTC-USD', 'changes': [['sell', '38315.14', '0.07330000']], 'time': '2021-05-20T03:55:52.673887Z'}
{'type': 'l2update', 'product_id': 'BTC-USD', 'changes': [['sell', '38340.32', '0.00000000']], 'time': '2021-05-20T03:55:52.676376Z'}
{'type': 'l2update', 'product_id': 'BTC-USD', 'changes': [['sell', '38443.24', '0.34119535']], 'time': '2021-05-20T03:55:52.680858Z'}
{'type': 'l2update', 'product_id': 'BTC-USD', 'changes': [['sell', '38393.03', '0.00000000']], 'time': '2021-05-20T03:55:52.680858Z'}
{'type': 'l2update', 'product_id': 'BTC-USD', 'changes': [['sell', '38349.83', '0.10000000']], 'time': '2021-05-20T03:55:52.684182Z'}
{'type': 'l2update', 'product_id': 'BTC-USD', 'changes': [['buy', '38283.07', '0.47000000']], 'time': '2021-05-20T03:55:52.685252Z'}
{'type': 'l2update', 'product_id': 'BTC-USD', 'changes': [['sell', '38340.26', '0.05000000']], 'time': '2021-05-20T03:55:52.685760Z'}
{'type': 'l2update', 'product_id': 'BTC-USD', 'changes': [['sell', '38513.77', '0.01298237']], 'time': '2021-05-20T03:55:52.685976Z'}
{'type': 'l2update', 'product_id': 'BTC-USD', 'changes': [['sell', '39155.12', '0.00000000']], 'time': '2021-05-20T03:55:52.687224Z'}
{'type': 'l2update', 'product_id': 'BTC-USD', 'changes': [['sell', '38323.48', '0.20000000']], 'time': '2021-05-20T03:55:52.687800Z'}
{'type': 'l2update', 'product_id': 'BTC-USD', 'changes': [['sell', '38362.71', '0.05000000']], 'time': '2021-05-20T03:55:52.689423Z'}
{'type': 'l2update', 'product_id': 'BTC-USD', 'changes': [['sell', '38323.49', '0.70000000']], 'time': '2021-05-20T03:55:52.691806Z'}
{'type': 'l2update', 'product_id': 'BTC-USD', 'changes': [['sell', '38315.14', '0.17330000']], 'time': '2021-05-20T03:55:52.698398Z'}
{'type': 'l2update', 'product_id': 'BTC-USD', 'changes': [['sell', '38328.16', '1.60058938']], 'time': '2021-05-20T03:55:52.698902Z'}
{'type': 'l2update', 'product_id': 'BTC-USD', 'changes': [['sell', '38488.73', '0.00000000']], 'time': '2021-05-20T03:55:52.698977Z'}
{'type': 'l2update', 'product_id': 'BTC-USD', 'changes': [['buy', '38295.56', '0.00000000']], 'time': '2021-05-20T03:55:52.699786Z'}
{'type': 'l2update', 'product_id': 'BTC-USD', 'changes': [['sell', '38334.20', '0.21500000']], 'time': '2021-05-20T03:55:52.709828Z'}
{'type': 'l2update', 'product_id': 'BTC-USD', 'changes': [['sell', '38506.08', '0.01000000']], 'time': '2021-05-20T03:55:52.709896Z'}
{'type': 'l2update', 'product_id': 'BTC-USD', 'changes': [['sell', '38323.48', '0.70000000']], 'time': '2021-05-20T03:55:52.710018Z'}
{'type': 'l2update', 'product_id': 'BTC-USD', 'changes': [['sell', '38371.63', '0.07700000']], 'time': '2021-05-20T03:55:52.710407Z'}
{'type': 'l2update', 'product_id': 'BTC-USD', 'changes': [['sell', '38385.92', '0.00000000']], 'time': '2021-05-20T03:55:52.712800Z'}
{'type': 'l2update', 'product_id': 'BTC-USD', 'changes': [['sell', '38352.57', '0.16994742']], 'time': '2021-05-20T03:55:52.715306Z'}
{'type': 'l2update', 'product_id': 'BTC-USD', 'changes': [['sell', '38349.34', '0.35166826']], 'time': '2021-05-20T03:55:52.715306Z'}
{'type': 'l2update', 'product_id': 'BTC-USD', 'changes': [['sell', '38366.15', '0.00000000']], 'time': '2021-05-20T03:55:52.715339Z'}
{'type': 'l2update', 'product_id': 'BTC-USD', 'changes': [['sell', '38315.14', '0.16080731']], 'time': '2021-05-20T03:55:52.716967Z'}
{'type': 'l2update', 'product_id': 'BTC-USD', 'changes': [['buy', '38298.15', '0.99315797']], 'time': '2021-05-20T03:55:52.717129Z'}
{'type': 'l2update', 'product_id': 'BTC-USD', 'changes': [['sell', '38390.19', '0.03022225']], 'time': '2021-05-20T03:55:52.717381Z'}
{'type': 'l2update', 'product_id': 'BTC-USD', 'changes': [['buy', '38197.31', '0.03022225']], 'time': '2021-05-20T03:55:52.717381Z'}
{'type': 'l2update', 'product_id': 'BTC-USD', 'changes': [['buy', '38299.14', '0.00000000']], 'time': '2021-05-20T03:55:52.720357Z'}
{'type': 'l2update', 'product_id': 'BTC-USD', 'changes': [['sell', '38340.43', '0.00000000']], 'time': '2021-05-20T03:55:52.720357Z'}
{'type': 'l2update', 'product_id': 'BTC-USD', 'changes': [['buy', '38298.15', '1.39450879']], 'time': '2021-05-20T03:55:52.720754Z'}
{'type': 'l2update', 'product_id': 'BTC-USD', 'changes': [['sell', '38436.00', '0.00000000']], 'time': '2021-05-20T03:55:52.721547Z'}
{'type': 'l2update', 'product_id': 'BTC-USD', 'changes': [['buy', '38311.06', '0.00000000']], 'time': '2021-05-20T03:55:52.721631Z'}
{'type': 'l2update', 'product_id': 'BTC-USD', 'changes': [['buy', '38295.61', '0.00000000']], 'time': '2021-05-20T03:55:52.722000Z'}
{'type': 'l2update', 'product_id': 'BTC-USD', 'changes': [['sell', '38323.49', '0.60000000']], 'time': '2021-05-20T03:55:52.724500Z'}
{'type': 'l2update', 'product_id': 'BTC-USD', 'changes': [['sell', '38460.85', '0.00000000']], 'time': '2021-05-20T03:55:52.727708Z'}
{'type': 'l2update', 'product_id': 'BTC-USD', 'changes': [['buy', '38258.18', '0.00000000']], 'time': '2021-05-20T03:55:52.740585Z'}
{'type': 'l2update', 'product_id': 'BTC-USD', 'changes': [['sell', '38366.66', '0.00000000']], 'time': '2021-05-20T03:55:52.741280Z'}
{'type': 'l2update', 'product_id': 'BTC-USD', 'changes': [['buy', '38233.01', '0.00000000']], 'time': '2021-05-20T03:55:52.746999Z'}
{'type': 'l2update', 'product_id': 'BTC-USD', 'changes': [['sell', '38315.14', '0.13000000']], 'time': '2021-05-20T03:55:52.747051Z'}
{'type': 'l2update', 'product_id': 'BTC-USD', 'changes': [['sell', '38349.34', '0.51470069']], 'time': '2021-05-20T03:55:52.747605Z'}
{'type': 'l2update', 'product_id': 'BTC-USD', 'changes': [['buy', '38298.15', '0.40135082']], 'time': '2021-05-20T03:55:52.748268Z'}
{'type': 'l2update', 'product_id': 'BTC-USD', 'changes': [['buy', '38307.58', '0.00000000']], 'time': '2021-05-20T03:55:52.754365Z'}
{'type': 'l2update', 'product_id': 'BTC-USD', 'changes': [['sell', '38315.14', '0.33000000']], 'time': '2021-05-20T03:55:52.758598Z'}
{'type': 'l2update', 'product_id': 'BTC-USD', 'changes': [['sell', '38393.03', '0.02824212']], 'time': '2021-05-20T03:55:52.758946Z'}
{'type': 'l2update', 'product_id': 'BTC-USD', 'changes': [['buy', '38197.31', '0.05846437']], 'time': '2021-05-20T03:55:52.758946Z'}
{'type': 'l2update', 'product_id': 'BTC-USD', 'changes': [['buy', '38292.22', '0.02400000']], 'time': '2021-05-20T03:55:52.759965Z'}
{'type': 'l2update', 'product_id': 'BTC-USD', 'changes': [['sell', '38442.88', '0.04806375']], 'time': '2021-05-20T03:55:52.765575Z'}
{'type': 'l2update', 'product_id': 'BTC-USD', 'changes': [['sell', '38443.55', '0.00000000']], 'time': '2021-05-20T03:55:52.768412Z'}
{'type': 'l2update', 'product_id': 'BTC-USD', 'changes': [['sell', '38368.05', '0.00000000']], 'time': '2021-05-20T03:55:52.770263Z'}
{'type': 'l2update', 'product_id': 'BTC-USD', 'changes': [['sell', '38457.13', '0.00000000']], 'time': '2021-05-20T03:55:52.777323Z'}
{'type': 'l2update', 'product_id': 'BTC-USD', 'changes': [['sell', '38450.09', '0.00000000']], 'time': '2021-05-20T03:55:52.777323Z'}
{'type': 'l2update', 'product_id': 'BTC-USD', 'changes': [['sell', '38443.24', '0.00000000']], 'time': '2021-05-20T03:55:52.777323Z'}
{'type': 'l2update', 'product_id': 'BTC-USD', 'changes': [['sell', '38430.11', '0.00000000']], 'time': '2021-05-20T03:55:52.777323Z'}
{'type': 'l2update', 'product_id': 'BTC-USD', 'changes': [['sell', '38417.74', '0.00000000']], 'time': '2021-05-20T03:55:52.777323Z'}
{'type': 'l2update', 'product_id': 'BTC-USD', 'changes': [['sell', '38411.85', '0.00000000']], 'time': '2021-05-20T03:55:52.777323Z'}
{'type': 'l2update', 'product_id': 'BTC-USD', 'changes': [['sell', '38400.64', '0.00000000']], 'time': '2021-05-20T03:55:52.777323Z'}
{'type': 'l2update', 'product_id': 'BTC-USD', 'changes': [['sell', '38395.32', '0.00000000']], 'time': '2021-05-20T03:55:52.777323Z'}
{'type': 'l2update', 'product_id': 'BTC-USD', 'changes': [['sell', '38386.82', '0.00000000']], 'time': '2021-05-20T03:55:52.777323Z'}
{'type': 'l2update', 'product_id': 'BTC-USD', 'changes': [['sell', '38375.93', '0.35166826']], 'time': '2021-05-20T03:55:52.777323Z'}
{'type': 'l2update', 'product_id': 'BTC-USD', 'changes': [['sell', '38487.16', '0.00000000']], 'time': '2021-05-20T03:55:52.778140Z'}
{'type': 'l2update', 'product_id': 'BTC-USD', 'changes': [['sell', '38328.16', '1.41077464']], 'time': '2021-05-20T03:55:52.778310Z'}
{'type': 'l2update', 'product_id': 'BTC-USD', 'changes': [['sell', '38506.67', '0.00000000']], 'time': '2021-05-20T03:55:52.781787Z'}
{'type': 'l2update', 'product_id': 'BTC-USD', 'changes': [['buy', '38306.79', '0.00000000']], 'time': '2021-05-20T03:55:52.783212Z'}
{'type': 'l2update', 'product_id': 'BTC-USD', 'changes': [['sell', '38323.49', '0.40000000']], 'time': '2021-05-20T03:55:52.785103Z'}
{'type': 'l2update', 'product_id': 'BTC-USD', 'changes': [['buy', '38280.81', '0.00000000']], 'time': '2021-05-20T03:55:52.786348Z'}
{'type': 'l2update', 'product_id': 'BTC-USD', 'changes': [['buy', '38295.20', '0.69822997']], 'time': '2021-05-20T03:55:52.786422Z'}
{'type': 'l2update', 'product_id': 'BTC-USD', 'changes': [['sell', '38368.50', '0.00000000']], 'time': '2021-05-20T03:55:52.796114Z'}
{'type': 'l2update', 'product_id': 'BTC-USD', 'changes': [['sell', '38355.09', '0.09963691']], 'time': '2021-05-20T03:55:52.799926Z'}
{'type': 'l2update', 'product_id': 'BTC-USD', 'changes': [['sell', '38315.14', '0.33573000']], 'time': '2021-05-20T03:55:52.799955Z'}
{'type': 'l2update', 'product_id': 'BTC-USD', 'changes': [['sell', '38423.27', '0.01301294']], 'time': '2021-05-20T03:55:52.799983Z'}
{'type': 'l2update', 'product_id': 'BTC-USD', 'changes': [['buy', '38276.90', '0.00000000']], 'time': '2021-05-20T03:55:52.803735Z'}
{'type': 'l2update', 'product_id': 'BTC-USD', 'changes': [['sell', '38375.93', '0.00000000']], 'time': '2021-05-20T03:55:52.805213Z'}
{'type': 'l2update', 'product_id': 'BTC-USD', 'changes': [['sell', '38367.39', '0.03247839']], 'time': '2021-05-20T03:55:52.805213Z'}
{'type': 'l2update', 'product_id': 'BTC-USD', 'changes': [['buy', '38291.71', '0.99315797']], 'time': '2021-05-20T03:55:52.805609Z'}
{'type': 'l2update', 'product_id': 'BTC-USD', 'changes': [['sell', '38407.19', '0.12257264']], 'time': '2021-05-20T03:55:52.805660Z'}
{'type': 'l2update', 'product_id': 'BTC-USD', 'changes': [['sell', '38428.66', '0.01214277']], 'time': '2021-05-20T03:55:52.805834Z'}
{'type': 'l2update', 'product_id': 'BTC-USD', 'changes': [['sell', '38323.43', '0.88100000']], 'time': '2021-05-20T03:55:52.805856Z'}
{'type': 'l2update', 'product_id': 'BTC-USD', 'changes': [['sell', '38336.02', '0.00000000']], 'time': '2021-05-20T03:55:52.809265Z'}
{'type': 'l2update', 'product_id': 'BTC-USD', 'changes': [['sell', '38323.48', '0.50000000']], 'time': '2021-05-20T03:55:52.810276Z'}
{'type': 'l2update', 'product_id': 'BTC-USD', 'changes': [['sell', '38404.04', '0.05447673']], 'time': '2021-05-20T03:55:52.812778Z'}
{'type': 'l2update', 'product_id': 'BTC-USD', 'changes': [['sell', '38449.43', '0.01000000']], 'time': '2021-05-20T03:55:52.813560Z'}
{'type': 'l2update', 'product_id': 'BTC-USD', 'changes': [['sell', '38445.97', '0.00000000']], 'time': '2021-05-20T03:55:52.817368Z'}
{'type': 'l2update', 'product_id': 'BTC-USD', 'changes': [['sell', '38354.92', '0.00000000']], 'time': '2021-05-20T03:55:52.818798Z'}
{'type': 'l2update', 'product_id': 'BTC-USD', 'changes': [['sell', '38406.77', '0.00000000']], 'time': '2021-05-20T03:55:52.821698Z'}
{'type': 'l2update', 'product_id': 'BTC-USD', 'changes': [['sell', '38347.57', '0.00000000']], 'time': '2021-05-20T03:55:52.821713Z'}
{'type': 'l2update', 'product_id': 'BTC-USD', 'changes': [['sell', '38493.10', '0.01000000']], 'time': '2021-05-20T03:55:52.821751Z'}
{'type': 'l2update', 'product_id': 'BTC-USD', 'changes': [['buy', '38315.13', '0.09000000']], 'time': '2021-05-20T03:55:52.823219Z'}
{'type': 'l2update', 'product_id': 'BTC-USD', 'changes': [['buy', '38294.50', '0.00000000']], 'time': '2021-05-20T03:55:52.823355Z'}
{'type': 'l2update', 'product_id': 'BTC-USD', 'changes': [['sell', '38359.20', '0.00000000']], 'time': '2021-05-20T03:55:52.826896Z'}
{'type': 'l2update', 'product_id': 'BTC-USD', 'changes': [['sell', '38400.64', '0.03145764']], 'time': '2021-05-20T03:55:52.828585Z'}
{'type': 'l2update', 'product_id': 'BTC-USD', 'changes': [['buy', '38234.21', '0.02400000']], 'time': '2021-05-20T03:55:52.829010Z'}
{'type': 'l2update', 'product_id': 'BTC-USD', 'changes': [['buy', '38301.81', '0.00000000']], 'time': '2021-05-20T03:55:52.830353Z'}
{'type': 'l2update', 'product_id': 'BTC-USD', 'changes': [['buy', '38225.00', '0.38857469']], 'time': '2021-05-20T03:55:52.830437Z'}
{'type': 'l2update', 'product_id': 'BTC-USD', 'changes': [['sell', '38356.49', '0.00000000']], 'time': '2021-05-20T03:55:52.832821Z'}
{'type': 'l2update', 'product_id': 'BTC-USD', 'changes': [['sell', '38374.79', '0.00000000']], 'time': '2021-05-20T03:55:52.837536Z'}
{'type': 'l2update', 'product_id': 'BTC-USD', 'changes': [['sell', '38442.89', '0.00000000']], 'time': '2021-05-20T03:55:52.839173Z'}
{'type': 'l2update', 'product_id': 'BTC-USD', 'changes': [['buy', '38311.83', '0.03000000']], 'time': '2021-05-20T03:55:52.853172Z'}
{'type': 'l2update', 'product_id': 'BTC-USD', 'changes': [['buy', '38293.69', '0.00000000']], 'time': '2021-05-20T03:55:52.854639Z'}
{'type': 'l2update', 'product_id': 'BTC-USD', 'changes': [['sell', '38433.59', '0.01000000']], 'time': '2021-05-20T03:55:52.857303Z'}
{'type': 'l2update', 'product_id': 'BTC-USD', 'changes': [['buy', '38271.14', '0.00000000']], 'time': '2021-05-20T03:55:52.857990Z'}
{'type': 'l2update', 'product_id': 'BTC-USD', 'changes': [['buy', '38278.18', '0.00000000']], 'time': '2021-05-20T03:55:52.859395Z'}
{'type': 'l2update', 'product_id': 'BTC-USD', 'changes': [['buy', '38218.32', '0.00000000']], 'time': '2021-05-20T03:55:52.860816Z'}
{'type': 'l2update', 'product_id': 'BTC-USD', 'changes': [['sell', '38323.43', '0.00000000']], 'time': '2021-05-20T03:55:52.861788Z'}
{'type': 'l2update', 'product_id': 'BTC-USD', 'changes': [['buy', '38284.65', '0.05887077']], 'time': '2021-05-20T03:55:52.864043Z'}
{'type': 'l2update', 'product_id': 'BTC-USD', 'changes': [['sell', '38327.32', '0.05391925']], 'time': '2021-05-20T03:55:52.864043Z'}
{'type': 'l2update', 'product_id': 'BTC-USD', 'changes': [['sell', '38369.19', '2.16932808']], 'time': '2021-05-20T03:55:52.865372Z'}
{'type': 'l2update', 'product_id': 'BTC-USD', 'changes': [['sell', '38355.10', '0.00000000']], 'time': '2021-05-20T03:55:52.866678Z'}
{'type': 'l2update', 'product_id': 'BTC-USD', 'changes': [['buy', '38152.29', '0.00000000']], 'time': '2021-05-20T03:55:52.873710Z'}
{'type': 'l2update', 'product_id': 'BTC-USD', 'changes': [['sell', '38428.77', '0.01167778']], 'time': '2021-05-20T03:55:52.878552Z'}
{'type': 'l2update', 'product_id': 'BTC-USD', 'changes': [['buy', '38291.71', '0.00000000']], 'time': '2021-05-20T03:55:52.881063Z'}
{'type': 'l2update', 'product_id': 'BTC-USD', 'changes': [['buy', '38311.83', '0.00000000']], 'time': '2021-05-20T03:55:52.883952Z'}
{'type': 'l2update', 'product_id': 'BTC-USD', 'changes': [['sell', '38708.23', '0.00000000']], 'time': '2021-05-20T03:55:52.892459Z'}
{'type': 'l2update', 'product_id': 'BTC-USD', 'changes': [['buy', '38291.19', '0.02400000']], 'time': '2021-05-20T03:55:52.897696Z'}
{'type': 'l2update', 'product_id': 'BTC-USD', 'changes': [['buy', '38290.39', '0.02400000']], 'time': '2021-05-20T03:55:52.897696Z'}
{'type': 'l2update', 'product_id': 'BTC-USD', 'changes': [['buy', '38234.21', '0.00000000']], 'time': '2021-05-20T03:55:52.897843Z'}
{'type': 'l2update', 'product_id': 'BTC-USD', 'changes': [['buy', '38303.18', '0.00000000']], 'time': '2021-05-20T03:55:52.900326Z'}
{'type': 'l2update', 'product_id': 'BTC-USD', 'changes': [['sell', '38329.67', '0.05000000']], 'time': '2021-05-20T03:55:52.905969Z'}
{'type': 'l2update', 'product_id': 'BTC-USD', 'changes': [['sell', '38434.88', '0.33465019']], 'time': '2021-05-20T03:55:52.906208Z'}
{'type': 'l2update', 'product_id': 'BTC-USD', 'changes': [['sell', '38421.75', '0.30860458']], 'time': '2021-05-20T03:55:52.906208Z'}
{'type': 'l2update', 'product_id': 'BTC-USD', 'changes': [['buy', '38159.88', '0.33465019']], 'time': '2021-05-20T03:55:52.906208Z'}
{'type': 'l2update', 'product_id': 'BTC-USD', 'changes': [['sell', '38400.64', '0.06242099']], 'time': '2021-05-20T03:55:52.908191Z'}
{'type': 'l2update', 'product_id': 'BTC-USD', 'changes': [['sell', '38355.99', '0.03247839']], 'time': '2021-05-20T03:55:52.908191Z'}
{'type': 'l2update', 'product_id': 'BTC-USD', 'changes': [['sell', '38352.57', '0.18314982']], 'time': '2021-05-20T03:55:52.908191Z'}
{'type': 'l2update', 'product_id': 'BTC-USD', 'changes': [['buy', '38315.13', '0.05000000']], 'time': '2021-05-20T03:55:52.915129Z'}
{'type': 'l2update', 'product_id': 'BTC-USD', 'changes': [['sell', '38449.43', '0.00000000']], 'time': '2021-05-20T03:55:52.916068Z'}
{'type': 'l2update', 'product_id': 'BTC-USD', 'changes': [['buy', '38315.13', '0.00000000']], 'time': '2021-05-20T03:55:52.918356Z'}
{'type': 'l2update', 'product_id': 'BTC-USD', 'changes': [['buy', '38117.50', '0.01081700']], 'time': '2021-05-20T03:55:52.923068Z'}
{'type': 'l2update', 'product_id': 'BTC-USD', 'changes': [['sell', '38369.19', '0.00000000']], 'time': '2021-05-20T03:55:52.928951Z'}
{'type': 'l2update', 'product_id': 'BTC-USD', 'changes': [['sell', '38738.45', '0.01290707']], 'time': '2021-05-20T03:55:52.929563Z'}
{'type': 'l2update', 'product_id': 'BTC-USD', 'changes': [['sell', '38343.52', '0.00000000']], 'time': '2021-05-20T03:55:52.930614Z'}
{'type': 'l2update', 'product_id': 'BTC-USD', 'changes': [['buy', '38292.22', '0.00000000']], 'time': '2021-05-20T03:55:52.932913Z'}
{'type': 'l2update', 'product_id': 'BTC-USD', 'changes': [['sell', '38462.64', '0.32140239']], 'time': '2021-05-20T03:55:52.933999Z'}
{'type': 'l2update', 'product_id': 'BTC-USD', 'changes': [['buy', '38230.63', '0.00000000']], 'time': '2021-05-20T03:55:52.933999Z'}
{'type': 'l2update', 'product_id': 'BTC-USD', 'changes': [['buy', '38220.00', '0.00000000']], 'time': '2021-05-20T03:55:52.934428Z'}
{'type': 'l2update', 'product_id': 'BTC-USD', 'changes': [['sell', '38493.10', '0.00000000']], 'time': '2021-05-20T03:55:52.935439Z'}
{'type': 'l2update', 'product_id': 'BTC-USD', 'changes': [['sell', '38428.77', '0.00000000']], 'time': '2021-05-20T03:55:52.937255Z'}
{'type': 'l2update', 'product_id': 'BTC-USD', 'changes': [['buy', '38256.90', '0.32000000']], 'time': '2021-05-20T03:55:52.940999Z'}
{'type': 'l2update', 'product_id': 'BTC-USD', 'changes': [['buy', '38284.70', '0.52100000']], 'time': '2021-05-20T03:55:52.941672Z'}
{'type': 'l2update', 'product_id': 'BTC-USD', 'changes': [['buy', '38285.54', '0.99315797']], 'time': '2021-05-20T03:55:52.941866Z'}
{'type': 'l2update', 'product_id': 'BTC-USD', 'changes': [['sell', '38338.67', '0.00000000']], 'time': '2021-05-20T03:55:52.944056Z'}
{'type': 'l2update', 'product_id': 'BTC-USD', 'changes': [['sell', '38314.60', '0.05000000']], 'time': '2021-05-20T03:55:52.948917Z'}
{'type': 'l2update', 'product_id': 'BTC-USD', 'changes': [['sell', '38352.57', '0.19613824']], 'time': '2021-05-20T03:55:52.949149Z'}
{'type': 'l2update', 'product_id': 'BTC-USD', 'changes': [['sell', '38340.26', '0.00000000']], 'time': '2021-05-20T03:55:52.952879Z'}
{'type': 'l2update', 'product_id': 'BTC-USD', 'changes': [['sell', '38314.90', '0.07460000']], 'time': '2021-05-20T03:55:52.956277Z'}
{'type': 'l2update', 'product_id': 'BTC-USD', 'changes': [['sell', '38323.49', '0.46568516']], 'time': '2021-05-20T03:55:52.956304Z'}
{'type': 'l2update', 'product_id': 'BTC-USD', 'changes': [['sell', '38457.86', '0.01000000']], 'time': '2021-05-20T03:55:52.956647Z'}
{'type': 'l2update', 'product_id': 'BTC-USD', 'changes': [['sell', '38349.33', '0.47607975']], 'time': '2021-05-20T03:55:52.956905Z'}
{'type': 'l2update', 'product_id': 'BTC-USD', 'changes': [['sell', '38314.45', '0.01492000']], 'time': '2021-05-20T03:55:52.957028Z'}
{'type': 'l2update', 'product_id': 'BTC-USD', 'changes': [['sell', '38315.13', '0.00573000']], 'time': '2021-05-20T03:55:52.957059Z'}
{'type': 'l2update', 'product_id': 'BTC-USD', 'changes': [['sell', '38352.57', '0.02619082']], 'time': '2021-05-20T03:55:52.962183Z'}
{'type': 'l2update', 'product_id': 'BTC-USD', 'changes': [['sell', '38349.34', '0.16303243']], 'time': '2021-05-20T03:55:52.962183Z'}
{'type': 'l2update', 'product_id': 'BTC-USD', 'changes': [['buy', '38236.57', '0.00000000']], 'time': '2021-05-20T03:55:52.962183Z'}
{'type': 'l2update', 'product_id': 'BTC-USD', 'changes': [['buy', '38144.49', '0.13980000']], 'time': '2021-05-20T03:55:52.965490Z'}
{'type': 'l2update', 'product_id': 'BTC-USD', 'changes': [['sell', '38473.01', '0.30086518']], 'time': '2021-05-20T03:55:52.965724Z'}
{'type': 'l2update', 'product_id': 'BTC-USD', 'changes': [['buy', '38298.81', '0.04731571']], 'time': '2021-05-20T03:55:52.965927Z'}
{'type': 'l2update', 'product_id': 'BTC-USD', 'changes': [['buy', '38117.50', '0.00000000']], 'time': '2021-05-20T03:55:52.966922Z'}
{'type': 'l2update', 'product_id': 'BTC-USD', 'changes': [['sell', '38360.40', '0.07700000']], 'time': '2021-05-20T03:55:52.970744Z'}
{'type': 'l2update', 'product_id': 'BTC-USD', 'changes': [['sell', '38522.87', '0.00000000']], 'time': '2021-05-20T03:55:52.971206Z'}
{'type': 'l2update', 'product_id': 'BTC-USD', 'changes': [['sell', '38362.71', '0.00000000']], 'time': '2021-05-20T03:55:52.974918Z'}
{'type': 'l2update', 'product_id': 'BTC-USD', 'changes': [['sell', '38541.83', '0.00000000']], 'time': '2021-05-20T03:55:52.975897Z'}
{'type': 'l2update', 'product_id': 'BTC-USD', 'changes': [['sell', '38346.48', '0.00176482']], 'time': '2021-05-20T03:55:52.977543Z'}
{'type': 'l2update', 'product_id': 'BTC-USD', 'changes': [['sell', '38403.70', '0.01167778']], 'time': '2021-05-20T03:55:52.977968Z'}
{'type': 'l2update', 'product_id': 'BTC-USD', 'changes': [['sell', '38315.14', '0.13573000']], 'time': '2021-05-20T03:55:52.978411Z'}
{'type': 'l2update', 'product_id': 'BTC-USD', 'changes': [['buy', '38281.79', '0.02000000']], 'time': '2021-05-20T03:55:52.978426Z'}
{'type': 'l2update', 'product_id': 'BTC-USD', 'changes': [['buy', '38289.36', '0.02400000']], 'time': '2021-05-20T03:55:52.978696Z'}
{'type': 'l2update', 'product_id': 'BTC-USD', 'changes': [['sell', '38479.23', '0.00779641']], 'time': '2021-05-20T03:55:52.978729Z'}
{'type': 'l2update', 'product_id': 'BTC-USD', 'changes': [['sell', '38429.54', '0.00000000']], 'time': '2021-05-20T03:55:52.979394Z'}
{'type': 'l2update', 'product_id': 'BTC-USD', 'changes': [['sell', '38367.39', '0.00000000']], 'time': '2021-05-20T03:55:52.979776Z'}
{'type': 'l2update', 'product_id': 'BTC-USD', 'changes': [['sell', '38363.40', '0.03247106']], 'time': '2021-05-20T03:55:52.979776Z'}
{'type': 'l2update', 'product_id': 'BTC-USD', 'changes': [['sell', '38363.40', '0.00000000']], 'time': '2021-05-20T03:55:52.979776Z'}
{'type': 'l2update', 'product_id': 'BTC-USD', 'changes': [['buy', '38266.02', '0.00000000']], 'time': '2021-05-20T03:55:52.979776Z'}
{'type': 'l2update', 'product_id': 'BTC-USD', 'changes': [['buy', '38227.37', '2.45180000']], 'time': '2021-05-20T03:55:52.985116Z'}
{'type': 'l2update', 'product_id': 'BTC-USD', 'changes': [['buy', '38284.70', '0.00000000']], 'time': '2021-05-20T03:55:52.985176Z'}
{'type': 'l2update', 'product_id': 'BTC-USD', 'changes': [['sell', '38323.47', '0.05000000']], 'time': '2021-05-20T03:55:52.986265Z'}
{'type': 'l2update', 'product_id': 'BTC-USD', 'changes': [['buy', '38283.07', '0.00000000']], 'time': '2021-05-20T03:55:52.986607Z'}
{'type': 'l2update', 'product_id': 'BTC-USD', 'changes': [['sell', '38315.14', '0.13000000']], 'time': '2021-05-20T03:55:52.986845Z'}
{'type': 'l2update', 'product_id': 'BTC-USD', 'changes': [['sell', '38349.34', '0.00000000']], 'time': '2021-05-20T03:55:52.991333Z'}
{'type': 'l2update', 'product_id': 'BTC-USD', 'changes': [['buy', '38225.00', '0.02649031']], 'time': '2021-05-20T03:55:52.991333Z'}
{'type': 'l2update', 'product_id': 'BTC-USD', 'changes': [['sell', '38314.90', '0.00000000']], 'time': '2021-05-20T03:55:52.997011Z'}
{'type': 'l2update', 'product_id': 'BTC-USD', 'changes': [['sell', '38317.77', '0.00600000']], 'time': '2021-05-20T03:55:53.000584Z'}
{'type': 'l2update', 'product_id': 'BTC-USD', 'changes': [['sell', '38328.17', '0.00000000']], 'time': '2021-05-20T03:55:53.006789Z'}
{'type': 'l2update', 'product_id': 'BTC-USD', 'changes': [['sell', '38315.14', '0.03000000']], 'time': '2021-05-20T03:55:53.011776Z'}
{'type': 'l2update', 'product_id': 'BTC-USD', 'changes': [['sell', '38352.60', '0.01000000']], 'time': '2021-05-20T03:55:53.016231Z'}
{'type': 'l2update', 'product_id': 'BTC-USD', 'changes': [['sell', '38315.13', '0.00000000']], 'time': '2021-05-20T03:55:53.020025Z'}
{'type': 'l2update', 'product_id': 'BTC-USD', 'changes': [['sell', '38400.64', '0.09762742']], 'time': '2021-05-20T03:55:53.022584Z'}
{'type': 'l2update', 'product_id': 'BTC-USD', 'changes': [['buy', '38199.65', '0.00000000']], 'time': '2021-05-20T03:55:53.022863Z'}
{'type': 'l2update', 'product_id': 'BTC-USD', 'changes': [['sell', '38594.92', '0.00000000']], 'time': '2021-05-20T03:55:53.031469Z'}
{'type': 'l2update', 'product_id': 'BTC-USD', 'changes': [['sell', '38314.07', '0.07460000']], 'time': '2021-05-20T03:55:53.036689Z'}
{'type': 'l2update', 'product_id': 'BTC-USD', 'changes': [['buy', '38101.44', '0.01081700']], 'time': '2021-05-20T03:55:53.036733Z'}
{'type': 'l2update', 'product_id': 'BTC-USD', 'changes': [['buy', '38270.36', '0.00000000']], 'time': '2021-05-20T03:55:53.039445Z'}
{'type': 'l2update', 'product_id': 'BTC-USD', 'changes': [['sell', '38503.66', '0.00649289']], 'time': '2021-05-20T03:55:53.043233Z'}
{'type': 'l2update', 'product_id': 'BTC-USD', 'changes': [['sell', '38333.83', '0.39490432']], 'time': '2021-05-20T03:55:53.045666Z'}
{'type': 'l2update', 'product_id': 'BTC-USD', 'changes': [['buy', '38298.16', '0.07186100']], 'time': '2021-05-20T03:55:53.045684Z'}
{'type': 'l2update', 'product_id': 'BTC-USD', 'changes': [['sell', '38350.99', '0.02000000']], 'time': '2021-05-20T03:55:53.053645Z'}
{'type': 'l2update', 'product_id': 'BTC-USD', 'changes': [['sell', '38314.44', '2.48969908']], 'time': '2021-05-20T03:55:53.053788Z'}
{'type': 'l2update', 'product_id': 'BTC-USD', 'changes': [['sell', '38417.08', '0.02140935']], 'time': '2021-05-20T03:55:53.053901Z'}
{'type': 'l2update', 'product_id': 'BTC-USD', 'changes': [['sell', '38462.64', '0.00000000']], 'time': '2021-05-20T03:55:53.054964Z'}
{'type': 'l2update', 'product_id': 'BTC-USD', 'changes': [['buy', '38194.51', '0.00000000']], 'time': '2021-05-20T03:55:53.054964Z'}
{'type': 'l2update', 'product_id': 'BTC-USD', 'changes': [['buy', '38260.72', '0.00000000']], 'time': '2021-05-20T03:55:53.055508Z'}
{'type': 'l2update', 'product_id': 'BTC-USD', 'changes': [['sell', '38315.14', '0.20600000']], 'time': '2021-05-20T03:55:53.062984Z'}
{'type': 'l2update', 'product_id': 'BTC-USD', 'changes': [['sell', '38516.39', '0.02163072']], 'time': '2021-05-20T03:55:53.064227Z'}
{'type': 'l2update', 'product_id': 'BTC-USD', 'changes': [['sell', '38314.45', '0.00000000']], 'time': '2021-05-20T03:55:53.067409Z'}
{'type': 'l2update', 'product_id': 'BTC-USD', 'changes': [['sell', '38330.94', '0.00000000']], 'time': '2021-05-20T03:55:53.067676Z'}
{'type': 'l2update', 'product_id': 'BTC-USD', 'changes': [['buy', '38219.73', '0.00000000']], 'time': '2021-05-20T03:55:53.072449Z'}
{'type': 'l2update', 'product_id': 'BTC-USD', 'changes': [['sell', '38428.66', '0.00000000']], 'time': '2021-05-20T03:55:53.072663Z'}
{'type': 'l2update', 'product_id': 'BTC-USD', 'changes': [['sell', '38323.48', '0.00000000']], 'time': '2021-05-20T03:55:53.073713Z'}
{'type': 'l2update', 'product_id': 'BTC-USD', 'changes': [['sell', '38342.50', '0.10000000']], 'time': '2021-05-20T03:55:53.082897Z'}
{'type': 'l2update', 'product_id': 'BTC-USD', 'changes': [['sell', '38314.02', '1.07400000']], 'time': '2021-05-20T03:55:53.083182Z'}
{'type': 'l2update', 'product_id': 'BTC-USD', 'changes': [['buy', '38183.13', '0.00000000']], 'time': '2021-05-20T03:55:53.083494Z'}
{'type': 'l2update', 'product_id': 'BTC-USD', 'changes': [['sell', '38473.01', '0.00000000']], 'time': '2021-05-20T03:55:53.084321Z'}
{'type': 'l2update', 'product_id': 'BTC-USD', 'changes': [['sell', '38350.99', '0.05000000']], 'time': '2021-05-20T03:55:53.089981Z'}
{'type': 'l2update', 'product_id': 'BTC-USD', 'changes': [['sell', '38365.45', '0.00000000']], 'time': '2021-05-20T03:55:53.093097Z'}
{'type': 'l2update', 'product_id': 'BTC-USD', 'changes': [['buy', '38298.15', '0.00000000']], 'time': '2021-05-20T03:55:53.093702Z'}
{'type': 'l2update', 'product_id': 'BTC-USD', 'changes': [['sell', '38409.39', '0.03171410']], 'time': '2021-05-20T03:55:53.098982Z'}
{'type': 'l2update', 'product_id': 'BTC-USD', 'changes': [['buy', '38298.16', '0.00000000']], 'time': '2021-05-20T03:55:53.103153Z'}
{'type': 'l2update', 'product_id': 'BTC-USD', 'changes': [['sell', '38323.47', '0.00000000']], 'time': '2021-05-20T03:55:53.104625Z'}
{'type': 'l2update', 'product_id': 'BTC-USD', 'changes': [['sell', '38534.41', '0.00000000']], 'time': '2021-05-20T03:55:53.108435Z'}
{'type': 'l2update', 'product_id': 'BTC-USD', 'changes': [['sell', '38395.41', '0.01175486']], 'time': '2021-05-20T03:55:53.109342Z'}
{'type': 'l2update', 'product_id': 'BTC-USD', 'changes': [['buy', '38291.19', '0.00000000']], 'time': '2021-05-20T03:55:53.109931Z'}
{'type': 'l2update', 'product_id': 'BTC-USD', 'changes': [['buy', '38290.39', '0.00000000']], 'time': '2021-05-20T03:55:53.109931Z'}
{'type': 'l2update', 'product_id': 'BTC-USD', 'changes': [['buy', '38199.65', '0.01000000']], 'time': '2021-05-20T03:55:53.110062Z'}
{'type': 'l2update', 'product_id': 'BTC-USD', 'changes': [['sell', '38314.07', '0.00000000']], 'time': '2021-05-20T03:55:53.110195Z'}
{'type': 'l2update', 'product_id': 'BTC-USD', 'changes': [['buy', '38284.65', '0.00000000']], 'time': '2021-05-20T03:55:53.111353Z'}
{'type': 'l2update', 'product_id': 'BTC-USD', 'changes': [['sell', '38327.32', '0.00000000']], 'time': '2021-05-20T03:55:53.111353Z'}
{'type': 'l2update', 'product_id': 'BTC-USD', 'changes': [['sell', '38314.44', '2.98969908']], 'time': '2021-05-20T03:55:53.119263Z'}
{'type': 'l2update', 'product_id': 'BTC-USD', 'changes': [['buy', '38285.53', '0.00000000']], 'time': '2021-05-20T03:55:53.120016Z'}
{'type': 'l2update', 'product_id': 'BTC-USD', 'changes': [['sell', '38347.67', '0.00000000']], 'time': '2021-05-20T03:55:53.121026Z'}
{'type': 'l2update', 'product_id': 'BTC-USD', 'changes': [['sell', '38350.99', '0.09000000']], 'time': '2021-05-20T03:55:53.125559Z'}
{'type': 'l2update', 'product_id': 'BTC-USD', 'changes': [['sell', '38359.04', '0.36261116']], 'time': '2021-05-20T03:55:53.126081Z'}
{'type': 'l2update', 'product_id': 'BTC-USD', 'changes': [['sell', '38314.90', '0.37148000']], 'time': '2021-05-20T03:55:53.126081Z'}
{'type': 'l2update', 'product_id': 'BTC-USD', 'changes': [['sell', '38313.41', '0.01492000']], 'time': '2021-05-20T03:55:53.126145Z'}
{'type': 'l2update', 'product_id': 'BTC-USD', 'changes': [['sell', '38581.82', '0.12959472']], 'time': '2021-05-20T03:55:53.126372Z'}
{'type': 'l2update', 'product_id': 'BTC-USD', 'changes': [['buy', '38265.51', '1.20000000']], 'time': '2021-05-20T03:55:53.127751Z'}
{'type': 'l2update', 'product_id': 'BTC-USD', 'changes': [['sell', '38349.54', '0.50000000']], 'time': '2021-05-20T03:55:53.132375Z'}
{'type': 'l2update', 'product_id': 'BTC-USD', 'changes': [['buy', '38101.44', '0.00000000']], 'time': '2021-05-20T03:55:53.135349Z'}
{'type': 'l2update', 'product_id': 'BTC-USD', 'changes': [['sell', '38409.39', '0.06412522']], 'time': '2021-05-20T03:55:53.137480Z'}
{'type': 'l2update', 'product_id': 'BTC-USD', 'changes': [['sell', '38367.39', '0.03022225']], 'time': '2021-05-20T03:55:53.137480Z'}
{'type': 'l2update', 'product_id': 'BTC-USD', 'changes': [['sell', '38738.45', '0.00000000']], 'time': '2021-05-20T03:55:53.138740Z'}
{'type': 'l2update', 'product_id': 'BTC-USD', 'changes': [['sell', '38323.48', '0.05000000']], 'time': '2021-05-20T03:55:53.142537Z'}
{'type': 'l2update', 'product_id': 'BTC-USD', 'changes': [['sell', '38352.97', '0.03207306']], 'time': '2021-05-20T03:55:53.142602Z'}
{'type': 'l2update', 'product_id': 'BTC-USD', 'changes': [['sell', '38313.41', '0.00000000']], 'time': '2021-05-20T03:55:53.147407Z'}
{'type': 'l2update', 'product_id': 'BTC-USD', 'changes': [['sell', '38314.02', '1.03692000']], 'time': '2021-05-20T03:55:53.147407Z'}
{'type': 'l2update', 'product_id': 'BTC-USD', 'changes': [['sell', '38328.19', '0.00000000']], 'time': '2021-05-20T03:55:53.147918Z'}
{'type': 'l2update', 'product_id': 'BTC-USD', 'changes': [['sell', '38442.88', '0.00000000']], 'time': '2021-05-20T03:55:53.149801Z'}
{'type': 'l2update', 'product_id': 'BTC-USD', 'changes': [['sell', '38479.23', '0.00000000']], 'time': '2021-05-20T03:55:53.156479Z'}
{'type': 'l2update', 'product_id': 'BTC-USD', 'changes': [['sell', '38313.38', '0.07460000']], 'time': '2021-05-20T03:55:53.160100Z'}
{'type': 'l2update', 'product_id': 'BTC-USD', 'changes': [['sell', '38331.24', '0.05890714']], 'time': '2021-05-20T03:55:53.161033Z'}
{'type': 'l2update', 'product_id': 'BTC-USD', 'changes': [['sell', '38381.84', '0.30642800']], 'time': '2021-05-20T03:55:53.161430Z'}
{'type': 'l2update', 'product_id': 'BTC-USD', 'changes': [['buy', '38270.59', '0.05447272']], 'time': '2021-05-20T03:55:53.161558Z'}
{'type': 'l2update', 'product_id': 'BTC-USD', 'changes': [['buy', '38285.54', '0.00000000']], 'time': '2021-05-20T03:55:53.162332Z'}
{'type': 'l2update', 'product_id': 'BTC-USD', 'changes': [['buy', '38288.68', '0.02400000']], 'time': '2021-05-20T03:55:53.163285Z'}
{'type': 'l2update', 'product_id': 'BTC-USD', 'changes': [['buy', '38287.87', '0.02400000']], 'time': '2021-05-20T03:55:53.163285Z'}
{'type': 'l2update', 'product_id': 'BTC-USD', 'changes': [['sell', '38489.79', '0.00000000']], 'time': '2021-05-20T03:55:53.163485Z'}
{'type': 'l2update', 'product_id': 'BTC-USD', 'changes': [['buy', '38295.21', '0.00000000']], 'time': '2021-05-20T03:55:53.164181Z'}
{'type': 'l2update', 'product_id': 'BTC-USD', 'changes': [['buy', '38276.92', '0.05890714']], 'time': '2021-05-20T03:55:53.165783Z'}
{'type': 'l2update', 'product_id': 'BTC-USD', 'changes': [['buy', '38308.20', '0.01000000']], 'time': '2021-05-20T03:55:53.166111Z'}
{'type': 'l2update', 'product_id': 'BTC-USD', 'changes': [['sell', '38390.19', '0.00000000']], 'time': '2021-05-20T03:55:53.166247Z'}
{'type': 'l2update', 'product_id': 'BTC-USD', 'changes': [['buy', '38212.71', '0.05725529']], 'time': '2021-05-20T03:55:53.166247Z'}
{'type': 'l2update', 'product_id': 'BTC-USD', 'changes': [['sell', '38400.45', '1.20000000']], 'time': '2021-05-20T03:55:53.170915Z'}
{'type': 'l2update', 'product_id': 'BTC-USD', 'changes': [['sell', '38520.90', '0.02392950']], 'time': '2021-05-20T03:55:53.175398Z'}
{'type': 'l2update', 'product_id': 'BTC-USD', 'changes': [['buy', '38298.14', '0.00000000']], 'time': '2021-05-20T03:55:53.176982Z'}
{'type': 'l2update', 'product_id': 'BTC-USD', 'changes': [['buy', '38298.82', '0.07186100']], 'time': '2021-05-20T03:55:53.184628Z'}
{'type': 'l2update', 'product_id': 'BTC-USD', 'changes': [['sell', '38708.23', '0.01000000']], 'time': '2021-05-20T03:55:53.184909Z'}
{'type': 'l2update', 'product_id': 'BTC-USD', 'changes': [['sell', '38434.88', '0.00000000']], 'time': '2021-05-20T03:55:53.186476Z'}
{'type': 'l2update', 'product_id': 'BTC-USD', 'changes': [['sell', '38421.75', '0.00000000']], 'time': '2021-05-20T03:55:53.186476Z'}
{'type': 'l2update', 'product_id': 'BTC-USD', 'changes': [['sell', '38455.14', '0.00780129']], 'time': '2021-05-20T03:55:53.188960Z'}
{'type': 'l2update', 'product_id': 'BTC-USD', 'changes': [['sell', '38313.54', '0.01492000']], 'time': '2021-05-20T03:55:53.189445Z'}
{'type': 'l2update', 'product_id': 'BTC-USD', 'changes': [['sell', '38396.39', '0.01327200']], 'time': '2021-05-20T03:55:53.189976Z'}
{'type': 'l2update', 'product_id': 'BTC-USD', 'changes': [['buy', '38289.36', '0.00000000']], 'time': '2021-05-20T03:55:53.192059Z'}
{'type': 'l2update', 'product_id': 'BTC-USD', 'changes': [['buy', '38288.68', '0.00000000']], 'time': '2021-05-20T03:55:53.192059Z'}
{'type': 'l2update', 'product_id': 'BTC-USD', 'changes': [['buy', '38298.81', '0.00000000']], 'time': '2021-05-20T03:55:53.195481Z'}
{'type': 'l2update', 'product_id': 'BTC-USD', 'changes': [['buy', '38197.31', '0.02824212']], 'time': '2021-05-20T03:55:53.196886Z'}
{'type': 'l2update', 'product_id': 'BTC-USD', 'changes': [['sell', '38323.48', '0.00000000']], 'time': '2021-05-20T03:55:53.196977Z'}
{'type': 'l2update', 'product_id': 'BTC-USD', 'changes': [['sell', '38478.08', '0.01218739']], 'time': '2021-05-20T03:55:53.197182Z'}
{'type': 'l2update', 'product_id': 'BTC-USD', 'changes': [['buy', '38291.75', '0.84700000']], 'time': '2021-05-20T03:55:53.201541Z'}
{'type': 'l2update', 'product_id': 'BTC-USD', 'changes': [['buy', '38265.51', '0.00000000']], 'time': '2021-05-20T03:55:53.202722Z'}
{'type': 'l2update', 'product_id': 'BTC-USD', 'changes': [['buy', '38302.01', '0.02000000']], 'time': '2021-05-20T03:55:53.207310Z'}
{'type': 'l2update', 'product_id': 'BTC-USD', 'changes': [['buy', '38291.70', '0.00000000']], 'time': '2021-05-20T03:55:53.209081Z'}
{'type': 'l2update', 'product_id': 'BTC-USD', 'changes': [['buy', '38283.46', '0.99315797']], 'time': '2021-05-20T03:55:53.213142Z'}
{'type': 'l2update', 'product_id': 'BTC-USD', 'changes': [['buy', '38130.88', '0.01000000']], 'time': '2021-05-20T03:55:53.213241Z'}
{'type': 'l2update', 'product_id': 'BTC-USD', 'changes': [['sell', '43100.00', '1.09530000']], 'time': '2021-05-20T03:55:53.214930Z'}
{'type': 'l2update', 'product_id': 'BTC-USD', 'changes': [['buy', '38267.67', '0.70500000']], 'time': '2021-05-20T03:55:53.220987Z'}
{'type': 'l2update', 'product_id': 'BTC-USD', 'changes': [['sell', '38313.54', '0.00000000']], 'time': '2021-05-20T03:55:53.221994Z'}
{'type': 'l2update', 'product_id': 'BTC-USD', 'changes': [['sell', '38403.70', '0.00000000']], 'time': '2021-05-20T03:55:53.223189Z'}
{'type': 'l2update', 'product_id': 'BTC-USD', 'changes': [['sell', '38370.65', '0.35409373']], 'time': '2021-05-20T03:55:53.225966Z'}
{'type': 'l2update', 'product_id': 'BTC-USD', 'changes': [['buy', '38174.13', '0.35409373']], 'time': '2021-05-20T03:55:53.225966Z'}
{'type': 'l2update', 'product_id': 'BTC-USD', 'changes': [['sell', '38313.38', '0.00000000']], 'time': '2021-05-20T03:55:53.226297Z'}
{'type': 'l2update', 'product_id': 'BTC-USD', 'changes': [['buy', '38287.87', '0.00000000']], 'time': '2021-05-20T03:55:53.226778Z'}
{'type': 'l2update', 'product_id': 'BTC-USD', 'changes': [['sell', '38458.04', '0.00000000']], 'time': '2021-05-20T03:55:53.228076Z'}
{'type': 'l2update', 'product_id': 'BTC-USD', 'changes': [['sell', '38506.08', '0.00000000']], 'time': '2021-05-20T03:55:53.230907Z'}
{'type': 'l2update', 'product_id': 'BTC-USD', 'changes': [['buy', '38299.43', '0.01492000']], 'time': '2021-05-20T03:55:53.235048Z'}
{'type': 'l2update', 'product_id': 'BTC-USD', 'changes': [['sell', '38349.83', '0.00000000']], 'time': '2021-05-20T03:55:53.238806Z'}
{'type': 'l2update', 'product_id': 'BTC-USD', 'changes': [['sell', '38400.45', '0.00000000']], 'time': '2021-05-20T03:55:53.238918Z'}
{'type': 'l2update', 'product_id': 'BTC-USD', 'changes': [['sell', '38513.77', '0.00000000']], 'time': '2021-05-20T03:55:53.240090Z'}
{'type': 'l2update', 'product_id': 'BTC-USD', 'changes': [['buy', '38298.15', '0.00176482']], 'time': '2021-05-20T03:55:53.242883Z'}
{'type': 'l2update', 'product_id': 'BTC-USD', 'changes': [['buy', '38181.99', '0.03839292']], 'time': '2021-05-20T03:55:53.242947Z'}
{'type': 'l2update', 'product_id': 'BTC-USD', 'changes': [['sell', '38331.24', '0.10890714']], 'time': '2021-05-20T03:55:53.243054Z'}
{'type': 'l2update', 'product_id': 'BTC-USD', 'changes': [['sell', '38516.39', '0.00000000']], 'time': '2021-05-20T03:55:53.244816Z'}
{'type': 'l2update', 'product_id': 'BTC-USD', 'changes': [['buy', '38274.46', '0.00000000']], 'time': '2021-05-20T03:55:53.245052Z'}
{'type': 'l2update', 'product_id': 'BTC-USD', 'changes': [['buy', '38297.85', '0.03000000']], 'time': '2021-05-20T03:55:53.252311Z'}
{'type': 'l2update', 'product_id': 'BTC-USD', 'changes': [['sell', '38331.24', '0.05000000']], 'time': '2021-05-20T03:55:53.261617Z'}
{'type': 'l2update', 'product_id': 'BTC-USD', 'changes': [['buy', '38159.88', '0.00000000']], 'time': '2021-05-20T03:55:53.265061Z'}
{'type': 'l2update', 'product_id': 'BTC-USD', 'changes': [['buy', '38276.92', '0.00000000']], 'time': '2021-05-20T03:55:53.276194Z'}
{'type': 'l2update', 'product_id': 'BTC-USD', 'changes': [['sell', '38308.21', '0.07460000']], 'time': '2021-05-20T03:55:53.278146Z'}
{'type': 'l2update', 'product_id': 'BTC-USD', 'changes': [['sell', '38438.49', '0.01000000']], 'time': '2021-05-20T03:55:53.278235Z'}
{'type': 'l2update', 'product_id': 'BTC-USD', 'changes': [['buy', '38287.33', '0.41690000']], 'time': '2021-05-20T03:55:53.278625Z'}
{'type': 'l2update', 'product_id': 'BTC-USD', 'changes': [['sell', '38447.21', '0.00000000']], 'time': '2021-05-20T03:55:53.279589Z'}
{'type': 'l2update', 'product_id': 'BTC-USD', 'changes': [['sell', '38308.21', '0.08952000']], 'time': '2021-05-20T03:55:53.282929Z'}
{'type': 'l2update', 'product_id': 'BTC-USD', 'changes': [['sell', '38483.50', '0.01000000']], 'time': '2021-05-20T03:55:53.283174Z'}
{'type': 'l2update', 'product_id': 'BTC-USD', 'changes': [['buy', '38256.96', '0.00000000']], 'time': '2021-05-20T03:55:53.283547Z'}
{'type': 'l2update', 'product_id': 'BTC-USD', 'changes': [['buy', '38298.82', '0.00000000']], 'time': '2021-05-20T03:55:53.283781Z'}
{'type': 'l2update', 'product_id': 'BTC-USD', 'changes': [['sell', '38344.22', '0.03247839']], 'time': '2021-05-20T03:55:53.288722Z'}
{'type': 'l2update', 'product_id': 'BTC-USD', 'changes': [['sell', '38340.99', '0.01320240']], 'time': '2021-05-20T03:55:53.288722Z'}
{'type': 'l2update', 'product_id': 'BTC-USD', 'changes': [['sell', '38492.08', '0.01298968']], 'time': '2021-05-20T03:55:53.288957Z'}
{'type': 'l2update', 'product_id': 'BTC-USD', 'changes': [['buy', '38295.91', '0.04000000']], 'time': '2021-05-20T03:55:53.290104Z'}
{'type': 'l2update', 'product_id': 'BTC-USD', 'changes': [['sell', '38498.87', '0.01886400']], 'time': '2021-05-20T03:55:53.291004Z'}
{'type': 'l2update', 'product_id': 'BTC-USD', 'changes': [['sell', '38581.82', '0.00000000']], 'time': '2021-05-20T03:55:53.296227Z'}
{'type': 'l2update', 'product_id': 'BTC-USD', 'changes': [['sell', '38365.52', '0.42677869']], 'time': '2021-05-20T03:55:53.308367Z'}
{'type': 'l2update', 'product_id': 'BTC-USD', 'changes': [['buy', '38201.30', '0.17071148']], 'time': '2021-05-20T03:55:53.308367Z'}
{'type': 'l2update', 'product_id': 'BTC-USD', 'changes': [['sell', '38340.26', '0.05890714']], 'time': '2021-05-20T03:55:53.308672Z'}
{'type': 'l2update', 'product_id': 'BTC-USD', 'changes': [['sell', '38412.52', '0.01077170']], 'time': '2021-05-20T03:55:53.308847Z'}
{'type': 'l2update', 'product_id': 'BTC-USD', 'changes': [['sell', '38520.90', '0.00000000']], 'time': '2021-05-20T03:55:53.309105Z'}
{'type': 'l2update', 'product_id': 'BTC-USD', 'changes': [['sell', '38455.14', '0.00000000']], 'time': '2021-05-20T03:55:53.309462Z'}
{'type': 'l2update', 'product_id': 'BTC-USD', 'changes': [['buy', '38299.43', '0.00000000']], 'time': '2021-05-20T03:55:53.312337Z'}
{'type': 'l2update', 'product_id': 'BTC-USD', 'changes': [['buy', '38280.79', '0.02400000']], 'time': '2021-05-20T03:55:53.314613Z'}
{'type': 'l2update', 'product_id': 'BTC-USD', 'changes': [['buy', '38279.99', '0.02400000']], 'time': '2021-05-20T03:55:53.314613Z'}
{'type': 'l2update', 'product_id': 'BTC-USD', 'changes': [['buy', '38279.18', '0.02400000']], 'time': '2021-05-20T03:55:53.314613Z'}
{'type': 'l2update', 'product_id': 'BTC-USD', 'changes': [['sell', '38308.21', '0.18952000']], 'time': '2021-05-20T03:55:53.315781Z'}
{'type': 'l2update', 'product_id': 'BTC-USD', 'changes': [['sell', '38355.99', '0.00000000']], 'time': '2021-05-20T03:55:53.318602Z'}
{'type': 'l2update', 'product_id': 'BTC-USD', 'changes': [['sell', '38352.57', '0.01298842']], 'time': '2021-05-20T03:55:53.318602Z'}
{'type': 'l2update', 'product_id': 'BTC-USD', 'changes': [['sell', '38331.63', '0.42840000']], 'time': '2021-05-20T03:55:53.320125Z'}
{'type': 'l2update', 'product_id': 'BTC-USD', 'changes': [['sell', '38396.39', '0.00000000']], 'time': '2021-05-20T03:55:53.322406Z'}
{'type': 'l2update', 'product_id': 'BTC-USD', 'changes': [['buy', '38270.33', '0.04285281']], 'time': '2021-05-20T03:55:53.325667Z'}
{'type': 'l2update', 'product_id': 'BTC-USD', 'changes': [['sell', '38314.15', '0.05748860']], 'time': '2021-05-20T03:55:53.325667Z'}
{'type': 'l2update', 'product_id': 'BTC-USD', 'changes': [['buy', '38268.52', '0.05890714']], 'time': '2021-05-20T03:55:53.325722Z'}
{'type': 'l2update', 'product_id': 'BTC-USD', 'changes': [['buy', '38295.66', '0.05000000']], 'time': '2021-05-20T03:55:53.330039Z'}
{'type': 'l2update', 'product_id': 'BTC-USD', 'changes': [['sell', '38359.04', '0.00000000']], 'time': '2021-05-20T03:55:53.333329Z'}
{'type': 'l2update', 'product_id': 'BTC-USD', 'changes': [['sell', '38314.90', '0.00000000']], 'time': '2021-05-20T03:55:53.333329Z'}
{'type': 'l2update', 'product_id': 'BTC-USD', 'changes': [['buy', '38280.79', '0.00000000']], 'time': '2021-05-20T03:55:53.341371Z'}
{'type': 'l2update', 'product_id': 'BTC-USD', 'changes': [['sell', '38423.27', '0.00000000']], 'time': '2021-05-20T03:55:53.342381Z'}
{'type': 'l2update', 'product_id': 'BTC-USD', 'changes': [['buy', '38242.81', '0.19700000']], 'time': '2021-05-20T03:55:53.344545Z'}
{'type': 'l2update', 'product_id': 'BTC-USD', 'changes': [['buy', '38295.96', '0.84700000']], 'time': '2021-05-20T03:55:53.345061Z'}
{'type': 'l2update', 'product_id': 'BTC-USD', 'changes': [['sell', '38331.63', '0.00000000']], 'time': '2021-05-20T03:55:53.346304Z'}
{'type': 'l2update', 'product_id': 'BTC-USD', 'changes': [['sell', '38463.40', '0.01000000']], 'time': '2021-05-20T03:55:53.347376Z'}
{'type': 'l2update', 'product_id': 'BTC-USD', 'changes': [['sell', '38429.69', '0.03018871']], 'time': '2021-05-20T03:55:53.348752Z'}
{'type': 'l2update', 'product_id': 'BTC-USD', 'changes': [['sell', '38308.21', '0.38952000']], 'time': '2021-05-20T03:55:53.349815Z'}
{'type': 'l2update', 'product_id': 'BTC-USD', 'changes': [['sell', '38412.52', '0.00000000']], 'time': '2021-05-20T03:55:53.351694Z'}
{'type': 'l2update', 'product_id': 'BTC-USD', 'changes': [['sell', '38411.88', '0.02843395']], 'time': '2021-05-20T03:55:53.356472Z'}
{'type': 'l2update', 'product_id': 'BTC-USD', 'changes': [['buy', '38174.13', '0.38252768']], 'time': '2021-05-20T03:55:53.356472Z'}
{'type': 'l2update', 'product_id': 'BTC-USD', 'changes': [['sell', '38415.60', '0.01000000']], 'time': '2021-05-20T03:55:53.356842Z'}
{'type': 'l2update', 'product_id': 'BTC-USD', 'changes': [['sell', '38381.84', '0.00000000']], 'time': '2021-05-20T03:55:53.357919Z'}
{'type': 'l2update', 'product_id': 'BTC-USD', 'changes': [['sell', '38343.69', '0.05000000']], 'time': '2021-05-20T03:55:53.361899Z'}
{'type': 'l2update', 'product_id': 'BTC-USD', 'changes': [['sell', '38568.73', '0.12963872']], 'time': '2021-05-20T03:55:53.361941Z'}
{'type': 'l2update', 'product_id': 'BTC-USD', 'changes': [['sell', '38308.21', '0.39525000']], 'time': '2021-05-20T03:55:53.367033Z'}
{'type': 'l2update', 'product_id': 'BTC-USD', 'changes': [['sell', '38315.14', '0.03000000']], 'time': '2021-05-20T03:55:53.367932Z'}
{'type': 'l2update', 'product_id': 'BTC-USD', 'changes': [['buy', '38287.33', '0.00000000']], 'time': '2021-05-20T03:55:53.370056Z'}
{'type': 'l2update', 'product_id': 'BTC-USD', 'changes': [['sell', '38499.31', '0.02597449']], 'time': '2021-05-20T03:55:53.373777Z'}
{'type': 'l2update', 'product_id': 'BTC-USD', 'changes': [['sell', '38410.37', '0.01301731']], 'time': '2021-05-20T03:55:53.374608Z'}
{'type': 'l2update', 'product_id': 'BTC-USD', 'changes': [['buy', '38295.96', '0.00000000']], 'time': '2021-05-20T03:55:53.376458Z'}
{'type': 'l2update', 'product_id': 'BTC-USD', 'changes': [['buy', '38202.09', '0.50000000']], 'time': '2021-05-20T03:55:53.384473Z'}
{'type': 'l2update', 'product_id': 'BTC-USD', 'changes': [['sell', '38370.65', '0.00000000']], 'time': '2021-05-20T03:55:53.384928Z'}
{'type': 'l2update', 'product_id': 'BTC-USD', 'changes': [['buy', '38174.13', '0.02843395']], 'time': '2021-05-20T03:55:53.384928Z'}
{'type': 'l2update', 'product_id': 'BTC-USD', 'changes': [['sell', '38352.60', '0.00000000']], 'time': '2021-05-20T03:55:53.388309Z'}
{'type': 'l2update', 'product_id': 'BTC-USD', 'changes': [['sell', '38431.97', '0.01301000']], 'time': '2021-05-20T03:55:53.388864Z'}
{'type': 'l2update', 'product_id': 'BTC-USD', 'changes': [['buy', '38130.88', '0.00000000']], 'time': '2021-05-20T03:55:53.397632Z'}
{'type': 'l2update', 'product_id': 'BTC-USD', 'changes': [['buy', '38277.75', '0.02400000']], 'time': '2021-05-20T03:55:53.398851Z'}
{'type': 'l2update', 'product_id': 'BTC-USD', 'changes': [['sell', '38471.22', '0.30087691']], 'time': '2021-05-20T03:55:53.398956Z'}
{'type': 'l2update', 'product_id': 'BTC-USD', 'changes': [['sell', '38308.21', '0.42525000']], 'time': '2021-05-20T03:55:53.399319Z'}
{'type': 'l2update', 'product_id': 'BTC-USD', 'changes': [['sell', '38315.14', '0.00000000']], 'time': '2021-05-20T03:55:53.399872Z'}
{'type': 'l2update', 'product_id': 'BTC-USD', 'changes': [['sell', '38342.92', '0.00000000']], 'time': '2021-05-20T03:55:53.401940Z'}
{'type': 'l2update', 'product_id': 'BTC-USD', 'changes': [['buy', '38260.63', '0.20300000']], 'time': '2021-05-20T03:55:53.404544Z'}
{'type': 'l2update', 'product_id': 'BTC-USD', 'changes': [['buy', '38187.92', '0.03333426']], 'time': '2021-05-20T03:55:53.404849Z'}
{'type': 'l2update', 'product_id': 'BTC-USD', 'changes': [['buy', '38242.41', '0.03086184']], 'time': '2021-05-20T03:55:53.404849Z'}
{'type': 'l2update', 'product_id': 'BTC-USD', 'changes': [['buy', '38247.52', '0.03796869']], 'time': '2021-05-20T03:55:53.404849Z'}
{'type': 'l2update', 'product_id': 'BTC-USD', 'changes': [['buy', '38252.44', '0.01059612']], 'time': '2021-05-20T03:55:53.404849Z'}
{'type': 'l2update', 'product_id': 'BTC-USD', 'changes': [['buy', '38291.75', '0.00000000']], 'time': '2021-05-20T03:55:53.405059Z'}
{'type': 'l2update', 'product_id': 'BTC-USD', 'changes': [['buy', '38268.51', '0.00000000']], 'time': '2021-05-20T03:55:53.406691Z'}
{'type': 'l2update', 'product_id': 'BTC-USD', 'changes': [['buy', '38270.60', '0.05890714']], 'time': '2021-05-20T03:55:53.410675Z'}
{'type': 'l2update', 'product_id': 'BTC-USD', 'changes': [['sell', '38350.99', '0.07000000']], 'time': '2021-05-20T03:55:53.411667Z'}
{'type': 'l2update', 'product_id': 'BTC-USD', 'changes': [['sell', '38359.04', '0.35564862']], 'time': '2021-05-20T03:55:53.414556Z'}
{'type': 'l2update', 'product_id': 'BTC-USD', 'changes': [['buy', '38207.73', '0.14225945']], 'time': '2021-05-20T03:55:53.414556Z'}
{'type': 'l2update', 'product_id': 'BTC-USD', 'changes': [['buy', '38291.71', '0.02987350']], 'time': '2021-05-20T03:55:53.424057Z'}
{'type': 'l2update', 'product_id': 'BTC-USD', 'changes': [['sell', '38478.08', '0.00000000']], 'time': '2021-05-20T03:55:53.426262Z'}
{'type': 'l2update', 'product_id': 'BTC-USD', 'changes': [['sell', '38342.90', '0.00000000']], 'time': '2021-05-20T03:55:53.426677Z'}
{'type': 'l2update', 'product_id': 'BTC-USD', 'changes': [['sell', '38314.02', '0.00000000']], 'time': '2021-05-20T03:55:53.427888Z'}
{'type': 'l2update', 'product_id': 'BTC-USD', 'changes': [['buy', '38259.29', '0.00000000']], 'time': '2021-05-20T03:55:53.430001Z'}
{'type': 'l2update', 'product_id': 'BTC-USD', 'changes': [['buy', '38212.71', '0.02639345']], 'time': '2021-05-20T03:55:53.431268Z'}
{'type': 'l2update', 'product_id': 'BTC-USD', 'changes': [['buy', '38223.48', '0.00000000']], 'time': '2021-05-20T03:55:53.431268Z'}
{'type': 'l2update', 'product_id': 'BTC-USD', 'changes': [['buy', '38225.00', '0.00000000']], 'time': '2021-05-20T03:55:53.431268Z'}
{'type': 'l2update', 'product_id': 'BTC-USD', 'changes': [['buy', '38308.20', '0.00000000']], 'time': '2021-05-20T03:55:53.437146Z'}
{'type': 'l2update', 'product_id': 'BTC-USD', 'changes': [['buy', '38219.52', '0.02400000']], 'time': '2021-05-20T03:55:53.438768Z'}
{'type': 'l2update', 'product_id': 'BTC-USD', 'changes': [['sell', '38365.52', '0.00000000']], 'time': '2021-05-20T03:55:53.439226Z'}
{'type': 'l2update', 'product_id': 'BTC-USD', 'changes': [['buy', '38279.99', '0.00000000']], 'time': '2021-05-20T03:55:53.440086Z'}
{'type': 'l2update', 'product_id': 'BTC-USD', 'changes': [['buy', '38279.18', '0.00000000']], 'time': '2021-05-20T03:55:53.440086Z'}
{'type': 'l2update', 'product_id': 'BTC-USD', 'changes': [['buy', '38252.52', '0.10000000']], 'time': '2021-05-20T03:55:53.442739Z'}
{'type': 'l2update', 'product_id': 'BTC-USD', 'changes': [['sell', '38433.14', '0.02392611']], 'time': '2021-05-20T03:55:53.442751Z'}
{'type': 'l2update', 'product_id': 'BTC-USD', 'changes': [['sell', '38340.27', '0.00000000']], 'time': '2021-05-20T03:55:53.450581Z'}
{'type': 'l2update', 'product_id': 'BTC-USD', 'changes': [['buy', '38268.52', '0.00000000']], 'time': '2021-05-20T03:55:53.451771Z'}
{'type': 'l2update', 'product_id': 'BTC-USD', 'changes': [['sell', '38331.25', '0.00000000']], 'time': '2021-05-20T03:55:53.454090Z'}
{'type': 'l2update', 'product_id': 'BTC-USD', 'changes': [['sell', '38462.44', '0.01218739']], 'time': '2021-05-20T03:55:53.457154Z'}
{'type': 'l2update', 'product_id': 'BTC-USD', 'changes': [['sell', '38314.01', '1.21753730']], 'time': '2021-05-20T03:55:53.457309Z'}
{'type': 'l2update', 'product_id': 'BTC-USD', 'changes': [['buy', '38302.01', '0.00000000']], 'time': '2021-05-20T03:55:53.458615Z'}
{'type': 'l2update', 'product_id': 'BTC-USD', 'changes': [['sell', '38308.21', '0.35065000']], 'time': '2021-05-20T03:55:53.461690Z'}
{'type': 'l2update', 'product_id': 'BTC-USD', 'changes': [['buy', '38101.44', '0.01000000']], 'time': '2021-05-20T03:55:53.462368Z'}
{'type': 'l2update', 'product_id': 'BTC-USD', 'changes': [['sell', '38338.66', '0.44520000']], 'time': '2021-05-20T03:55:53.462642Z'}
{'type': 'l2update', 'product_id': 'BTC-USD', 'changes': [['sell', '38308.21', '0.34492000']], 'time': '2021-05-20T03:55:53.463022Z'}
{'type': 'l2update', 'product_id': 'BTC-USD', 'changes': [['sell', '38308.21', '0.33000000']], 'time': '2021-05-20T03:55:53.463305Z'}
{'type': 'l2update', 'product_id': 'BTC-USD', 'changes': [['sell', '38331.24', '0.00000000']], 'time': '2021-05-20T03:55:53.464433Z'}
{'type': 'l2update', 'product_id': 'BTC-USD', 'changes': [['sell', '38456.37', '0.00000000']], 'time': '2021-05-20T03:55:53.470279Z'}
{'type': 'l2update', 'product_id': 'BTC-USD', 'changes': [['sell', '38365.22', '0.36226296']], 'time': '2021-05-20T03:55:53.471785Z'}
{'type': 'l2update', 'product_id': 'BTC-USD', 'changes': [['buy', '38208.17', '0.14490518']], 'time': '2021-05-20T03:55:53.471785Z'}
{'type': 'l2update', 'product_id': 'BTC-USD', 'changes': [['buy', '38295.25', '0.84700000']], 'time': '2021-05-20T03:55:53.471966Z'}
{'type': 'l2update', 'product_id': 'BTC-USD', 'changes': [['sell', '38354.46', '2.16932808']], 'time': '2021-05-20T03:55:53.472294Z'}
{'type': 'l2update', 'product_id': 'BTC-USD', 'changes': [['buy', '38276.32', '0.02400000']], 'time': '2021-05-20T03:55:53.475599Z'}
{'type': 'l2update', 'product_id': 'BTC-USD', 'changes': [['buy', '38275.51', '0.02400000']], 'time': '2021-05-20T03:55:53.475599Z'}
{'type': 'l2update', 'product_id': 'BTC-USD', 'changes': [['sell', '38326.47', '0.04831565']], 'time': '2021-05-20T03:55:53.476107Z'}
{'type': 'l2update', 'product_id': 'BTC-USD', 'changes': [['buy', '38297.85', '0.00000000']], 'time': '2021-05-20T03:55:53.478687Z'}
{'type': 'l2update', 'product_id': 'BTC-USD', 'changes': [['sell', '38414.81', '0.03272633']], 'time': '2021-05-20T03:55:53.486561Z'}
{'type': 'l2update', 'product_id': 'BTC-USD', 'changes': [['sell', '38374.91', '0.03520643']], 'time': '2021-05-20T03:55:53.486561Z'}
{'type': 'l2update', 'product_id': 'BTC-USD', 'changes': [['sell', '38367.39', '0.05846437']], 'time': '2021-05-20T03:55:53.486561Z'}
{'type': 'l2update', 'product_id': 'BTC-USD', 'changes': [['sell', '38314.14', '1.35748412']], 'time': '2021-05-20T03:55:53.486816Z'}
{'type': 'l2update', 'product_id': 'BTC-USD', 'changes': [['sell', '38333.82', '0.05890714']], 'time': '2021-05-20T03:55:53.487617Z'}
{'type': 'l2update', 'product_id': 'BTC-USD', 'changes': [['buy', '38264.32', '0.42190000']], 'time': '2021-05-20T03:55:53.488624Z'}
{'type': 'l2update', 'product_id': 'BTC-USD', 'changes': [['buy', '38298.41', '0.04731571']], 'time': '2021-05-20T03:55:53.488832Z'}
{'type': 'l2update', 'product_id': 'BTC-USD', 'changes': [['sell', '38328.15', '0.05000000']], 'time': '2021-05-20T03:55:53.488971Z'}
{'type': 'l2update', 'product_id': 'BTC-USD', 'changes': [['buy', '38298.11', '0.01492000']], 'time': '2021-05-20T03:55:53.489539Z'}
{'type': 'l2update', 'product_id': 'BTC-USD', 'changes': [['buy', '38295.91', '0.00000000']], 'time': '2021-05-20T03:55:53.496962Z'}
{'type': 'l2update', 'product_id': 'BTC-USD', 'changes': [['sell', '38410.37', '0.00000000']], 'time': '2021-05-20T03:55:53.498688Z'}
{'type': 'l2update', 'product_id': 'BTC-USD', 'changes': [['sell', '38359.04', '0.75873836']], 'time': '2021-05-20T03:55:53.502593Z'}
{'type': 'l2update', 'product_id': 'BTC-USD', 'changes': [['buy', '38208.17', '0.54799492']], 'time': '2021-05-20T03:55:53.502593Z'}
{'type': 'l2update', 'product_id': 'BTC-USD', 'changes': [['sell', '38305.88', '0.05161137']], 'time': '2021-05-20T03:55:53.502735Z'}
{'type': 'l2update', 'product_id': 'BTC-USD', 'changes': [['buy', '38292.12', '0.05146949']], 'time': '2021-05-20T03:55:53.503124Z'}
{'type': 'l2update', 'product_id': 'BTC-USD', 'changes': [['sell', '38432.53', '0.01982345']], 'time': '2021-05-20T03:55:53.503665Z'}
{'type': 'l2update', 'product_id': 'BTC-USD', 'changes': [['sell', '38400.64', '0.06242099']], 'time': '2021-05-20T03:55:53.506469Z'}
{'type': 'l2update', 'product_id': 'BTC-USD', 'changes': [['sell', '38393.03', '0.00000000']], 'time': '2021-05-20T03:55:53.506469Z'}
{'type': 'l2update', 'product_id': 'BTC-USD', 'changes': [['buy', '38264.32', '0.00000000']], 'time': '2021-05-20T03:55:53.508118Z'}
{'type': 'l2update', 'product_id': 'BTC-USD', 'changes': [['sell', '38328.15', '0.00000000']], 'time': '2021-05-20T03:55:53.510074Z'}
{'type': 'l2update', 'product_id': 'BTC-USD', 'changes': [['buy', '38298.41', '0.00000000']], 'time': '2021-05-20T03:55:53.510969Z'}
{'type': 'l2update', 'product_id': 'BTC-USD', 'changes': [['sell', '38314.44', '2.48969908']], 'time': '2021-05-20T03:55:53.511552Z'}
{'type': 'l2update', 'product_id': 'BTC-USD', 'changes': [['buy', '38298.11', '0.00000000']], 'time': '2021-05-20T03:55:53.512490Z'}
{'type': 'l2update', 'product_id': 'BTC-USD', 'changes': [['buy', '38270.33', '0.00000000']], 'time': '2021-05-20T03:55:53.513577Z'}
{'type': 'l2update', 'product_id': 'BTC-USD', 'changes': [['buy', '38295.66', '0.00000000']], 'time': '2021-05-20T03:55:53.516929Z'}
{'type': 'l2update', 'product_id': 'BTC-USD', 'changes': [['buy', '38276.91', '0.00000000']], 'time': '2021-05-20T03:55:53.518374Z'}
{'type': 'l2update', 'product_id': 'BTC-USD', 'changes': [['sell', '38307.74', '0.07460000']], 'time': '2021-05-20T03:55:53.518935Z'}
{'type': 'l2update', 'product_id': 'BTC-USD', 'changes': [['sell', '38307.59', '0.01492000']], 'time': '2021-05-20T03:55:53.520700Z'}
{'type': 'l2update', 'product_id': 'BTC-USD', 'changes': [['sell', '38308.21', '0.13000000']], 'time': '2021-05-20T03:55:53.523627Z'}
{'type': 'l2update', 'product_id': 'BTC-USD', 'changes': [['buy', '38101.44', '0.00000000']], 'time': '2021-05-20T03:55:53.525174Z'}
{'type': 'l2update', 'product_id': 'BTC-USD', 'changes': [['buy', '38128.85', '0.04839540']], 'time': '2021-05-20T03:55:53.525803Z'}
{'type': 'l2update', 'product_id': 'BTC-USD', 'changes': [['buy', '38298.15', '0.00000000']], 'time': '2021-05-20T03:55:53.538402Z'}
{'type': 'l2update', 'product_id': 'BTC-USD', 'changes': [['sell', '38323.48', '0.05000000']], 'time': '2021-05-20T03:55:53.539429Z'}
{'type': 'l2update', 'product_id': 'BTC-USD', 'changes': [['sell', '38340.26', '0.00000000']], 'time': '2021-05-20T03:55:53.539724Z'}
{'type': 'l2update', 'product_id': 'BTC-USD', 'changes': [['buy', '38267.37', '0.04739019']], 'time': '2021-05-20T03:55:53.539739Z'}
{'type': 'l2update', 'product_id': 'BTC-USD', 'changes': [['buy', '38195.50', '0.03412278']], 'time': '2021-05-20T03:55:53.540385Z'}
{'type': 'l2update', 'product_id': 'BTC-USD', 'changes': [['buy', '38231.26', '0.03247839']], 'time': '2021-05-20T03:55:53.540385Z'}
{'type': 'l2update', 'product_id': 'BTC-USD', 'changes': [['sell', '38352.11', '0.14360275']], 'time': '2021-05-20T03:55:53.540421Z'}
{'type': 'l2update', 'product_id': 'BTC-USD', 'changes': [['buy', '38201.93', '0.35900687']], 'time': '2021-05-20T03:55:53.540421Z'}
{'type': 'l2update', 'product_id': 'BTC-USD', 'changes': [['sell', '38483.50', '0.00000000']], 'time': '2021-05-20T03:55:53.540777Z'}
{'type': 'l2update', 'product_id': 'BTC-USD', 'changes': [['sell', '38350.99', '0.04000000']], 'time': '2021-05-20T03:55:53.540791Z'}
{'type': 'l2update', 'product_id': 'BTC-USD', 'changes': [['buy', '38260.63', '0.00000000']], 'time': '2021-05-20T03:55:53.542073Z'}
{'type': 'l2update', 'product_id': 'BTC-USD', 'changes': [['buy', '38296.21', '0.02728429']], 'time': '2021-05-20T03:55:53.543547Z'}
{'type': 'l2update', 'product_id': 'BTC-USD', 'changes': [['buy', '38296.08', '0.01492000']], 'time': '2021-05-20T03:55:53.543672Z'}
{'type': 'l2update', 'product_id': 'BTC-USD', 'changes': [['sell', '38307.74', '0.00000000']], 'time': '2021-05-20T03:55:53.544116Z'}
{'type': 'l2update', 'product_id': 'BTC-USD', 'changes': [['buy', '38295.25', '0.00000000']], 'time': '2021-05-20T03:55:53.545179Z'}
{'type': 'l2update', 'product_id': 'BTC-USD', 'changes': [['buy', '38270.60', '0.00000000']], 'time': '2021-05-20T03:55:53.546112Z'}
{'type': 'l2update', 'product_id': 'BTC-USD', 'changes': [['sell', '38308.21', '0.03000000']], 'time': '2021-05-20T03:55:53.547508Z'}
{'type': 'l2update', 'product_id': 'BTC-USD', 'changes': [['sell', '38307.59', '0.00000000']], 'time': '2021-05-20T03:55:53.548431Z'}
{'type': 'l2update', 'product_id': 'BTC-USD', 'changes': [['buy', '38295.94', '0.04731571']], 'time': '2021-05-20T03:55:53.549162Z'}
{'type': 'l2update', 'product_id': 'BTC-USD', 'changes': [['sell', '38308.20', '0.50000000']], 'time': '2021-05-20T03:55:53.549663Z'}
{'type': 'l2update', 'product_id': 'BTC-USD', 'changes': [['sell', '38471.22', '0.00000000']], 'time': '2021-05-20T03:55:53.550226Z'}
{'type': 'l2update', 'product_id': 'BTC-USD', 'changes': [['buy', '38072.00', '0.01081700']], 'time': '2021-05-20T03:55:53.557442Z'}
{'type': 'l2update', 'product_id': 'BTC-USD', 'changes': [['sell', '38436.51', '0.01300846']], 'time': '2021-05-20T03:55:53.563082Z'}
{'type': 'l2update', 'product_id': 'BTC-USD', 'changes': [['buy', '38204.12', '0.00000000']], 'time': '2021-05-20T03:55:53.565163Z'}
{'type': 'l2update', 'product_id': 'BTC-USD', 'changes': [['buy', '38296.21', '0.00000000']], 'time': '2021-05-20T03:55:53.568305Z'}
{'type': 'l2update', 'product_id': 'BTC-USD', 'changes': [['buy', '38296.08', '0.00000000']], 'time': '2021-05-20T03:55:53.571244Z'}
{'type': 'l2update', 'product_id': 'BTC-USD', 'changes': [['buy', '38121.04', '0.00000000']], 'time': '2021-05-20T03:55:53.572098Z'}
{'type': 'l2update', 'product_id': 'BTC-USD', 'changes': [['buy', '38295.94', '0.00000000']], 'time': '2021-05-20T03:55:53.576001Z'}
{'type': 'l2update', 'product_id': 'BTC-USD', 'changes': [['sell', '38470.33', '0.01000000']], 'time': '2021-05-20T03:55:53.578323Z'}
{'type': 'l2update', 'product_id': 'BTC-USD', 'changes': [['sell', '38340.58', '0.01000000']], 'time': '2021-05-20T03:55:53.578392Z'}
{'type': 'l2update', 'product_id': 'BTC-USD', 'changes': [['sell', '38433.59', '0.00000000']], 'time': '2021-05-20T03:55:53.578508Z'}
{'type': 'l2update', 'product_id': 'BTC-USD', 'changes': [['buy', '38276.92', '0.05890714']], 'time': '2021-05-20T03:55:53.578543Z'}
{'type': 'l2update', 'product_id': 'BTC-USD', 'changes': [['sell', '38343.73', '0.00000000']], 'time': '2021-05-20T03:55:53.578783Z'}
{'type': 'l2update', 'product_id': 'BTC-USD', 'changes': [['sell', '38348.12', '0.42949806']], 'time': '2021-05-20T03:55:53.579238Z'}
{'type': 'l2update', 'product_id': 'BTC-USD', 'changes': [['sell', '38340.71', '0.14225945']], 'time': '2021-05-20T03:55:53.579238Z'}
{'type': 'l2update', 'product_id': 'BTC-USD', 'changes': [['buy', '38195.50', '0.46362084']], 'time': '2021-05-20T03:55:53.579238Z'}
{'type': 'l2update', 'product_id': 'BTC-USD', 'changes': [['buy', '38072.00', '0.00000000']], 'time': '2021-05-20T03:55:53.580959Z'}
{'type': 'l2update', 'product_id': 'BTC-USD', 'changes': [['sell', '38314.15', '0.00000000']], 'time': '2021-05-20T03:55:53.581814Z'}
{'type': 'l2update', 'product_id': 'BTC-USD', 'changes': [['sell', '38305.23', '0.07460000']], 'time': '2021-05-20T03:55:53.589092Z'}
{'type': 'l2update', 'product_id': 'BTC-USD', 'changes': [['buy', '38302.02', '0.07186395']], 'time': '2021-05-20T03:55:53.597046Z'}
{'type': 'l2update', 'product_id': 'BTC-USD', 'changes': [['buy', '38175.08', '0.03586941']], 'time': '2021-05-20T03:55:53.597074Z'}
{'type': 'l2update', 'product_id': 'BTC-USD', 'changes': [['buy', '38262.56', '0.06735169']], 'time': '2021-05-20T03:55:53.597145Z'}
{'type': 'l2update', 'product_id': 'BTC-USD', 'changes': [['buy', '38296.33', '0.02728429']], 'time': '2021-05-20T03:55:53.599681Z'}
{'type': 'l2update', 'product_id': 'BTC-USD', 'changes': [['sell', '38314.14', '0.00000000']], 'time': '2021-05-20T03:55:53.603087Z'}
{'type': 'l2update', 'product_id': 'BTC-USD', 'changes': [['sell', '38359.04', '0.40308974']], 'time': '2021-05-20T03:55:53.603159Z'}
{'type': 'l2update', 'product_id': 'BTC-USD', 'changes': [['buy', '38295.25', '0.84700000']], 'time': '2021-05-20T03:55:53.605534Z'}
{'type': 'l2update', 'product_id': 'BTC-USD', 'changes': [['sell', '38305.57', '0.01492000']], 'time': '2021-05-20T03:55:53.605873Z'}
{'type': 'l2update', 'product_id': 'BTC-USD', 'changes': [['buy', '38277.75', '0.00000000']], 'time': '2021-05-20T03:55:53.607280Z'}
{'type': 'l2update', 'product_id': 'BTC-USD', 'changes': [['sell', '38429.69', '0.00000000']], 'time': '2021-05-20T03:55:53.607769Z'}
{'type': 'l2update', 'product_id': 'BTC-USD', 'changes': [['sell', '38457.86', '0.00000000']], 'time': '2021-05-20T03:55:53.607831Z'}
{'type': 'l2update', 'product_id': 'BTC-USD', 'changes': [['buy', '38298.15', '0.00176482']], 'time': '2021-05-20T03:55:53.610636Z'}
{'type': 'l2update', 'product_id': 'BTC-USD', 'changes': [['sell', '38340.58', '0.03000000']], 'time': '2021-05-20T03:55:53.610835Z'}
{'type': 'l2update', 'product_id': 'BTC-USD', 'changes': [['buy', '38088.06', '0.01081700']], 'time': '2021-05-20T03:55:53.611183Z'}
{'type': 'l2update', 'product_id': 'BTC-USD', 'changes': [['sell', '38333.82', '0.00000000']], 'time': '2021-05-20T03:55:53.616164Z'}
{'type': 'l2update', 'product_id': 'BTC-USD', 'changes': [['sell', '38305.23', '0.00000000']], 'time': '2021-05-20T03:55:53.619301Z'}
{'type': 'l2update', 'product_id': 'BTC-USD', 'changes': [['buy', '38106.05', '0.05058399']], 'time': '2021-05-20T03:55:53.620079Z'}
{'type': 'l2update', 'product_id': 'BTC-USD', 'changes': [['buy', '38295.60', '0.04731571']], 'time': '2021-05-20T03:55:53.620317Z'}
{'type': 'l2update', 'product_id': 'BTC-USD', 'changes': [['buy', '38269.15', '0.44530000']], 'time': '2021-05-20T03:55:53.620349Z'}
{'type': 'l2update', 'product_id': 'BTC-USD', 'changes': [['sell', '38328.16', '0.00000000']], 'time': '2021-05-20T03:55:53.623204Z'}
{'type': 'l2update', 'product_id': 'BTC-USD', 'changes': [['buy', '38270.60', '0.02612972']], 'time': '2021-05-20T03:55:53.625832Z'}
{'type': 'l2update', 'product_id': 'BTC-USD', 'changes': [['buy', '38276.32', '0.00000000']], 'time': '2021-05-20T03:55:53.627521Z'}
{'type': 'l2update', 'product_id': 'BTC-USD', 'changes': [['sell', '38354.47', '0.39103232']], 'time': '2021-05-20T03:55:53.630033Z'}
{'type': 'l2update', 'product_id': 'BTC-USD', 'changes': [['buy', '38182.07', '0.39103232']], 'time': '2021-05-20T03:55:53.630033Z'}
{'type': 'l2update', 'product_id': 'BTC-USD', 'changes': [['sell', '38305.57', '0.00992000']], 'time': '2021-05-20T03:55:53.630449Z'}
{'type': 'l2update', 'product_id': 'BTC-USD', 'changes': [['sell', '38411.48', '0.03505789']], 'time': '2021-05-20T03:55:53.630888Z'}
{'type': 'l2update', 'product_id': 'BTC-USD', 'changes': [['sell', '38370.25', '0.03096335']], 'time': '2021-05-20T03:55:53.630888Z'}
{'type': 'l2update', 'product_id': 'BTC-USD', 'changes': [['sell', '38305.23', '0.20000000']], 'time': '2021-05-20T03:55:53.631046Z'}
{'type': 'l2update', 'product_id': 'BTC-USD', 'changes': [['buy', '38250.01', '0.02614378']], 'time': '2021-05-20T03:55:53.632018Z'}
{'type': 'l2update', 'product_id': 'BTC-USD', 'changes': [['buy', '38296.33', '0.00000000']], 'time': '2021-05-20T03:55:53.634170Z'}
{'type': 'l2update', 'product_id': 'BTC-USD', 'changes': [['sell', '38308.20', '0.00000000']], 'time': '2021-05-20T03:55:53.634424Z'}
{'type': 'l2update', 'product_id': 'BTC-USD', 'changes': [['sell', '38329.66', '0.04340827']], 'time': '2021-05-20T03:55:53.635290Z'}
{'type': 'l2update', 'product_id': 'BTC-USD', 'changes': [['sell', '38412.19', '0.08784000']], 'time': '2021-05-20T03:55:53.635373Z'}
{'type': 'l2update', 'product_id': 'BTC-USD', 'changes': [['buy', '38296.59', '0.01492000']], 'time': '2021-05-20T03:55:53.635667Z'}
{'type': 'l2update', 'product_id': 'BTC-USD', 'changes': [['sell', '38314.01', '0.00000000']], 'time': '2021-05-20T03:55:53.640778Z'}
{'type': 'l2update', 'product_id': 'BTC-USD', 'changes': [['sell', '38323.48', '0.00000000']], 'time': '2021-05-20T03:55:53.641579Z'}
{'type': 'l2update', 'product_id': 'BTC-USD', 'changes': [['sell', '38400.64', '0.03145764']], 'time': '2021-05-20T03:55:53.649575Z'}
{'type': 'l2update', 'product_id': 'BTC-USD', 'changes': [['sell', '38503.66', '0.00000000']], 'time': '2021-05-20T03:55:53.653690Z'}
{'type': 'l2update', 'product_id': 'BTC-USD', 'changes': [['buy', '38295.60', '0.00000000']], 'time': '2021-05-20T03:55:53.653889Z'}
{'type': 'l2update', 'product_id': 'BTC-USD', 'changes': [['sell', '38393.02', '0.02604640']], 'time': '2021-05-20T03:55:53.658151Z'}
{'type': 'l2update', 'product_id': 'BTC-USD', 'changes': [['buy', '38302.02', '0.00000000']], 'time': '2021-05-20T03:55:53.658425Z'}
{'type': 'l2update', 'product_id': 'BTC-USD', 'changes': [['buy', '38219.66', '0.00000000']], 'time': '2021-05-20T03:55:53.658445Z'}
{'type': 'l2update', 'product_id': 'BTC-USD', 'changes': [['sell', '38305.57', '0.00000000']], 'time': '2021-05-20T03:55:53.658464Z'}
{'type': 'l2update', 'product_id': 'BTC-USD', 'changes': [['sell', '38305.23', '0.30000000']], 'time': '2021-05-20T03:55:53.658881Z'}
{'type': 'l2update', 'product_id': 'BTC-USD', 'changes': [['sell', '38364.86', '0.33463993']], 'time': '2021-05-20T03:55:53.659064Z'}
{'type': 'l2update', 'product_id': 'BTC-USD', 'changes': [['buy', '38172.76', '0.33463993']], 'time': '2021-05-20T03:55:53.659064Z'}
{'type': 'l2update', 'product_id': 'BTC-USD', 'changes': [['sell', '38314.00', '0.50000000']], 'time': '2021-05-20T03:55:53.663512Z'}
{'type': 'l2update', 'product_id': 'BTC-USD', 'changes': [['buy', '38296.59', '0.00000000']], 'time': '2021-05-20T03:55:53.663740Z'}
{'type': 'l2update', 'product_id': 'BTC-USD', 'changes': [['buy', '38274.10', '0.02400000']], 'time': '2021-05-20T03:55:53.666768Z'}
{'type': 'l2update', 'product_id': 'BTC-USD', 'changes': [['buy', '38273.29', '0.02400000']], 'time': '2021-05-20T03:55:53.666768Z'}
{'type': 'l2update', 'product_id': 'BTC-USD', 'changes': [['buy', '38302.01', '0.02000000']], 'time': '2021-05-20T03:55:53.672267Z'}
{'type': 'l2update', 'product_id': 'BTC-USD', 'changes': [['sell', '38333.82', '0.05000000']], 'time': '2021-05-20T03:55:53.672519Z'}
{'type': 'l2update', 'product_id': 'BTC-USD', 'changes': [['buy', '37540.13', '0.00000000']], 'time': '2021-05-20T03:55:53.673456Z'}
{'type': 'l2update', 'product_id': 'BTC-USD', 'changes': [['buy', '38276.92', '0.00000000']], 'time': '2021-05-20T03:55:53.674977Z'}
{'type': 'l2update', 'product_id': 'BTC-USD', 'changes': [['buy', '38181.99', '0.07515296']], 'time': '2021-05-20T03:55:53.678061Z'}
{'type': 'l2update', 'product_id': 'BTC-USD', 'changes': [['sell', '38326.47', '0.00000000']], 'time': '2021-05-20T03:55:53.679651Z'}
{'type': 'l2update', 'product_id': 'BTC-USD', 'changes': [['sell', '38483.49', '0.00649629']], 'time': '2021-05-20T03:55:53.683169Z'}
{'type': 'l2update', 'product_id': 'BTC-USD', 'changes': [['sell', '38487.20', '0.01000000']], 'time': '2021-05-20T03:55:53.683449Z'}
{'type': 'l2update', 'product_id': 'BTC-USD', 'changes': [['buy', '38297.06', '0.07460000']], 'time': '2021-05-20T03:55:53.691873Z'}
{'type': 'l2update', 'product_id': 'BTC-USD', 'changes': [['buy', '38189.62', '0.01000000']], 'time': '2021-05-20T03:55:53.692156Z'}
{'type': 'l2update', 'product_id': 'BTC-USD', 'changes': [['buy', '38302.02', '0.20000000']], 'time': '2021-05-20T03:55:53.692312Z'}
{'type': 'l2update', 'product_id': 'BTC-USD', 'changes': [['sell', '38369.99', '0.38839402']], 'time': '2021-05-20T03:55:53.692431Z'}
{'type': 'l2update', 'product_id': 'BTC-USD', 'changes': [['buy', '38165.58', '0.38839402']], 'time': '2021-05-20T03:55:53.692431Z'}
{'type': 'l2update', 'product_id': 'BTC-USD', 'changes': [['buy', '38133.06', '0.04908803']], 'time': '2021-05-20T03:55:53.692587Z'}
{'type': 'l2update', 'product_id': 'BTC-USD', 'changes': [['sell', '38333.82', '0.00000000']], 'time': '2021-05-20T03:55:53.694101Z'}
{'type': 'l2update', 'product_id': 'BTC-USD', 'changes': [['sell', '38708.23', '0.00000000']], 'time': '2021-05-20T03:55:53.694360Z'}
{'type': 'l2update', 'product_id': 'BTC-USD', 'changes': [['sell', '39132.74', '0.00000000']], 'time': '2021-05-20T03:55:53.694718Z'}
{'type': 'l2update', 'product_id': 'BTC-USD', 'changes': [['buy', '38298.15', '0.03176482']], 'time': '2021-05-20T03:55:53.699953Z'}
{'type': 'l2update', 'product_id': 'BTC-USD', 'changes': [['sell', '38350.11', '0.02824212']], 'time': '2021-05-20T03:55:53.702779Z'}
{'type': 'l2update', 'product_id': 'BTC-USD', 'changes': [['sell', '38338.66', '0.00000000']], 'time': '2021-05-20T03:55:53.705758Z'}
{'type': 'l2update', 'product_id': 'BTC-USD', 'changes': [['sell', '38334.20', '0.00000000']], 'time': '2021-05-20T03:55:53.709935Z'}
{'type': 'l2update', 'product_id': 'BTC-USD', 'changes': [['buy', '38270.60', '0.06953799']], 'time': '2021-05-20T03:55:53.710279Z'}
{'type': 'l2update', 'product_id': 'BTC-USD', 'changes': [['sell', '38499.31', '0.00000000']], 'time': '2021-05-20T03:55:53.727248Z'}
{'type': 'l2update', 'product_id': 'BTC-USD', 'changes': [['sell', '38417.08', '0.00000000']], 'time': '2021-05-20T03:55:53.729088Z'}
{'type': 'l2update', 'product_id': 'BTC-USD', 'changes': [['buy', '38297.06', '0.00000000']], 'time': '2021-05-20T03:55:53.738890Z'}
{'type': 'l2update', 'product_id': 'BTC-USD', 'changes': [['sell', '38317.72', '0.55400000']], 'time': '2021-05-20T03:55:53.743857Z'}
{'type': 'l2update', 'product_id': 'BTC-USD', 'changes': [['buy', '38302.01', '0.12000000']], 'time': '2021-05-20T03:55:53.746832Z'}
{'type': 'l2update', 'product_id': 'BTC-USD', 'changes': [['buy', '38272.85', '0.05054148']], 'time': '2021-05-20T03:55:53.747653Z'}
{'type': 'l2update', 'product_id': 'BTC-USD', 'changes': [['sell', '38317.30', '0.04779972']], 'time': '2021-05-20T03:55:53.747653Z'}
{'type': 'l2update', 'product_id': 'BTC-USD', 'changes': [['sell', '38378.61', '0.34457275']], 'time': '2021-05-20T03:55:53.747679Z'}
{'type': 'l2update', 'product_id': 'BTC-USD', 'changes': [['sell', '38303.92', '0.52231158']], 'time': '2021-05-20T03:55:53.748140Z'}
{'type': 'l2update', 'product_id': 'BTC-USD', 'changes': [['sell', '38323.48', '0.05000000']], 'time': '2021-05-20T03:55:53.748212Z'}
{'type': 'l2update', 'product_id': 'BTC-USD', 'changes': [['sell', '38314.44', '0.00000000']], 'time': '2021-05-20T03:55:53.752676Z'}
{'type': 'l2update', 'product_id': 'BTC-USD', 'changes': [['sell', '38367.39', '0.03022225']], 'time': '2021-05-20T03:55:53.753253Z'}
{'type': 'l2update', 'product_id': 'BTC-USD', 'changes': [['sell', '38498.87', '0.00000000']], 'time': '2021-05-20T03:55:53.754876Z'}
{'type': 'l2update', 'product_id': 'BTC-USD', 'changes': [['sell', '38336.29', '0.46490000']], 'time': '2021-05-20T03:55:53.760262Z'}
{'type': 'l2update', 'product_id': 'BTC-USD', 'changes': [['buy', '38298.41', '0.04000000']], 'time': '2021-05-20T03:55:53.760594Z'}
{'type': 'l2update', 'product_id': 'BTC-USD', 'changes': [['sell', '38336.93', '0.10000000']], 'time': '2021-05-20T03:55:53.761035Z'}
{'type': 'l2update', 'product_id': 'BTC-USD', 'changes': [['sell', '38349.54', '0.00000000']], 'time': '2021-05-20T03:55:53.762558Z'}
{'type': 'l2update', 'product_id': 'BTC-USD', 'changes': [['buy', '38302.01', '0.02000000']], 'time': '2021-05-20T03:55:53.767194Z'}
{'type': 'l2update', 'product_id': 'BTC-USD', 'changes': [['sell', '38480.41', '0.02598725']], 'time': '2021-05-20T03:55:53.769773Z'}
{'type': 'l2update', 'product_id': 'BTC-USD', 'changes': [['sell', '38404.27', '0.01402709']], 'time': '2021-05-20T03:55:53.769899Z'}
{'type': 'l2update', 'product_id': 'BTC-USD', 'changes': [['sell', '38432.53', '0.00000000']], 'time': '2021-05-20T03:55:53.772199Z'}
{'type': 'l2update', 'product_id': 'BTC-USD', 'changes': [['sell', '38331.08', '0.05117740']], 'time': '2021-05-20T03:55:53.777109Z'}
{'type': 'l2update', 'product_id': 'BTC-USD', 'changes': [['sell', '38433.14', '0.00000000']], 'time': '2021-05-20T03:55:53.779964Z'}
{'type': 'l2update', 'product_id': 'BTC-USD', 'changes': [['sell', '38336.29', '0.00000000']], 'time': '2021-05-20T03:55:53.780522Z'}
{'type': 'l2update', 'product_id': 'BTC-USD', 'changes': [['sell', '38649.94', '0.01293663']], 'time': '2021-05-20T03:55:53.782896Z'}
{'type': 'l2update', 'product_id': 'BTC-USD', 'changes': [['buy', '38228.29', '0.02824212']], 'time': '2021-05-20T03:55:53.782958Z'}
{'type': 'l2update', 'product_id': 'BTC-USD', 'changes': [['sell', '38333.82', '0.04340827']], 'time': '2021-05-20T03:55:53.783001Z'}
{'type': 'l2update', 'product_id': 'BTC-USD', 'changes': [['sell', '38389.46', '0.33521284']], 'time': '2021-05-20T03:55:53.783674Z'}
{'type': 'l2update', 'product_id': 'BTC-USD', 'changes': [['buy', '38282.47', '0.78316168']], 'time': '2021-05-20T03:55:53.783690Z'}
{'type': 'l2update', 'product_id': 'BTC-USD', 'changes': [['sell', '38329.66', '0.00000000']], 'time': '2021-05-20T03:55:53.785257Z'}
{'type': 'l2update', 'product_id': 'BTC-USD', 'changes': [['sell', '38484.28', '0.01886100']], 'time': '2021-05-20T03:55:53.789865Z'}
{'type': 'l2update', 'product_id': 'BTC-USD', 'changes': [['sell', '38305.23', '0.20000000']], 'time': '2021-05-20T03:55:53.791281Z'}
{'type': 'l2update', 'product_id': 'BTC-USD', 'changes': [['sell', '38317.76', '2.48969908']], 'time': '2021-05-20T03:55:53.794382Z'}
{'type': 'l2update', 'product_id': 'BTC-USD', 'changes': [['sell', '38303.92', '0.51979106']], 'time': '2021-05-20T03:55:53.794890Z'}
{'type': 'l2update', 'product_id': 'BTC-USD', 'changes': [['buy', '38298.15', '0.08176482']], 'time': '2021-05-20T03:55:53.794910Z'}
{'type': 'l2update', 'product_id': 'BTC-USD', 'changes': [['buy', '38128.85', '0.00000000']], 'time': '2021-05-20T03:55:53.798032Z'}
{'type': 'l2update', 'product_id': 'BTC-USD', 'changes': [['buy', '38262.56', '0.16373860']], 'time': '2021-05-20T03:55:53.799244Z'}
{'type': 'l2update', 'product_id': 'BTC-USD', 'changes': [['buy', '38269.15', '0.00000000']], 'time': '2021-05-20T03:55:53.802539Z'}
{'type': 'l2update', 'product_id': 'BTC-USD', 'changes': [['buy', '38197.31', '0.00000000']], 'time': '2021-05-20T03:55:53.804715Z'}
{'type': 'l2update', 'product_id': 'BTC-USD', 'changes': [['buy', '38303.91', '0.00573000']], 'time': '2021-05-20T03:55:53.806672Z'}
{'type': 'l2update', 'product_id': 'BTC-USD', 'changes': [['sell', '38419.36', '0.01000000']], 'time': '2021-05-20T03:55:53.811960Z'}
{'type': 'l2update', 'product_id': 'BTC-USD', 'changes': [['sell', '38305.23', '0.00000000']], 'time': '2021-05-20T03:55:53.814350Z'}
{'type': 'l2update', 'product_id': 'BTC-USD', 'changes': [['sell', '38492.08', '0.00000000']], 'time': '2021-05-20T03:55:53.815923Z'}
{'type': 'l2update', 'product_id': 'BTC-USD', 'changes': [['sell', '38389.46', '0.75657439']], 'time': '2021-05-20T03:55:53.816149Z'}
{'type': 'l2update', 'product_id': 'BTC-USD', 'changes': [['sell', '38308.21', '0.55225932']], 'time': '2021-05-20T03:55:53.816190Z'}
{'type': 'l2update', 'product_id': 'BTC-USD', 'changes': [['sell', '38314.00', '0.00000000']], 'time': '2021-05-20T03:55:53.816417Z'}
{'type': 'l2update', 'product_id': 'BTC-USD', 'changes': [['sell', '38342.50', '0.00000000']], 'time': '2021-05-20T03:55:53.818774Z'}
{'type': 'l2update', 'product_id': 'BTC-USD', 'changes': [['sell', '38342.18', '0.03000000']], 'time': '2021-05-20T03:55:53.822896Z'}
{'type': 'l2update', 'product_id': 'BTC-USD', 'changes': [['sell', '38355.09', '0.00000000']], 'time': '2021-05-20T03:55:53.824077Z'}
{'type': 'l2update', 'product_id': 'BTC-USD', 'changes': [['sell', '38331.08', '0.00000000']], 'time': '2021-05-20T03:55:53.824508Z'}
{'type': 'l2update', 'product_id': 'BTC-USD', 'changes': [['buy', '38219.52', '0.00000000']], 'time': '2021-05-20T03:55:53.824840Z'}
{'type': 'l2update', 'product_id': 'BTC-USD', 'changes': [['sell', '38463.40', '0.00000000']], 'time': '2021-05-20T03:55:53.830282Z'}
{'type': 'l2update', 'product_id': 'BTC-USD', 'changes': [['buy', '38276.25', '0.40810000']], 'time': '2021-05-20T03:55:53.831334Z'}
{'type': 'l2update', 'product_id': 'BTC-USD', 'changes': [['sell', '38428.60', '0.03095720']], 'time': '2021-05-20T03:55:53.831797Z'}
{'type': 'l2update', 'product_id': 'BTC-USD', 'changes': [['buy', '38302.02', '0.00000000']], 'time': '2021-05-20T03:55:53.837537Z'}
{'type': 'l2update', 'product_id': 'BTC-USD', 'changes': [['sell', '38305.88', '0.00000000']], 'time': '2021-05-20T03:55:53.840216Z'}
{'type': 'l2update', 'product_id': 'BTC-USD', 'changes': [['sell', '38487.20', '0.00000000']], 'time': '2021-05-20T03:55:53.840453Z'}
{'type': 'l2update', 'product_id': 'BTC-USD', 'changes': [['buy', '38298.15', '0.08000000']], 'time': '2021-05-20T03:55:53.841937Z'}
{'type': 'l2update', 'product_id': 'BTC-USD', 'changes': [['sell', '38481.95', '0.01000000']], 'time': '2021-05-20T03:55:53.843081Z'}
{'type': 'l2update', 'product_id': 'BTC-USD', 'changes': [['sell', '38350.99', '0.00000000']], 'time': '2021-05-20T03:55:53.845138Z'}
{'type': 'l2update', 'product_id': 'BTC-USD', 'changes': [['sell', '38354.46', '0.00000000']], 'time': '2021-05-20T03:55:53.846478Z'}
{'type': 'l2update', 'product_id': 'BTC-USD', 'changes': [['buy', '38199.65', '0.00000000']], 'time': '2021-05-20T03:55:53.848928Z'}
{'type': 'l2update', 'product_id': 'BTC-USD', 'changes': [['buy', '38276.25', '0.00000000']], 'time': '2021-05-20T03:55:53.851261Z'}
{'type': 'l2update', 'product_id': 'BTC-USD', 'changes': [['sell', '38323.48', '0.55000000']], 'time': '2021-05-20T03:55:53.852146Z'}
{'type': 'l2update', 'product_id': 'BTC-USD', 'changes': [['sell', '38473.57', '0.01299593']], 'time': '2021-05-20T03:55:53.852477Z'}
{'type': 'l2update', 'product_id': 'BTC-USD', 'changes': [['buy', '38296.05', '0.05134633']], 'time': '2021-05-20T03:55:53.852764Z'}
{'type': 'l2update', 'product_id': 'BTC-USD', 'changes': [['sell', '38396.28', '0.35515298']], 'time': '2021-05-20T03:55:53.852852Z'}
{'type': 'l2update', 'product_id': 'BTC-USD', 'changes': [['buy', '38279.44', '0.78322638']], 'time': '2021-05-20T03:55:53.853350Z'}
{'type': 'l2update', 'product_id': 'BTC-USD', 'changes': [['sell', '38323.49', '0.06568516']], 'time': '2021-05-20T03:55:53.858639Z'}
{'type': 'l2update', 'product_id': 'BTC-USD', 'changes': [['sell', '38317.71', '0.18981474']], 'time': '2021-05-20T03:55:53.864266Z'}
{'type': 'l2update', 'product_id': 'BTC-USD', 'changes': [['sell', '38441.86', '0.01000000']], 'time': '2021-05-20T03:55:53.864435Z'}
{'type': 'l2update', 'product_id': 'BTC-USD', 'changes': [['buy', '38212.71', '0.06315349']], 'time': '2021-05-20T03:55:53.869741Z'}
{'type': 'l2update', 'product_id': 'BTC-USD', 'changes': [['buy', '38226.98', '0.03412278']], 'time': '2021-05-20T03:55:53.869741Z'}
{'type': 'l2update', 'product_id': 'BTC-USD', 'changes': [['buy', '38303.91', '0.01573000']], 'time': '2021-05-20T03:55:53.869961Z'}
{'type': 'l2update', 'product_id': 'BTC-USD', 'changes': [['sell', '38364.86', '0.00000000']], 'time': '2021-05-20T03:55:53.873320Z'}
{'type': 'l2update', 'product_id': 'BTC-USD', 'changes': [['sell', '38470.33', '0.00000000']], 'time': '2021-05-20T03:55:53.875486Z'}
{'type': 'l2update', 'product_id': 'BTC-USD', 'changes': [['sell', '38314.19', '0.52228071']], 'time': '2021-05-20T03:55:53.882040Z'}
{'type': 'l2update', 'product_id': 'BTC-USD', 'changes': [['buy', '38295.25', '1.36800000']], 'time': '2021-05-20T03:55:53.883135Z'}
{'type': 'l2update', 'product_id': 'BTC-USD', 'changes': [['buy', '38181.99', '0.03839292']], 'time': '2021-05-20T03:55:53.887767Z'}
{'type': 'l2update', 'product_id': 'BTC-USD', 'changes': [['buy', '38195.50', '0.42949806']], 'time': '2021-05-20T03:55:53.887767Z'}
{'type': 'l2update', 'product_id': 'BTC-USD', 'changes': [['buy', '38298.15', '0.05000000']], 'time': '2021-05-20T03:55:53.888152Z'}
{'type': 'l2update', 'product_id': 'BTC-USD', 'changes': [['sell', '38342.27', '0.44950000']], 'time': '2021-05-20T03:55:53.890927Z'}
{'type': 'l2update', 'product_id': 'BTC-USD', 'changes': [['sell', '38367.35', '0.15000000']], 'time': '2021-05-20T03:55:53.891013Z'}
{'type': 'l2update', 'product_id': 'BTC-USD', 'changes': [['sell', '38466.71', '0.01000000']], 'time': '2021-05-20T03:55:53.900095Z'}
{'type': 'l2update', 'product_id': 'BTC-USD', 'changes': [['sell', '38408.62', '0.42110282']], 'time': '2021-05-20T03:55:53.900207Z'}
{'type': 'l2update', 'product_id': 'BTC-USD', 'changes': [['buy', '38298.15', '0.00000000']], 'time': '2021-05-20T03:55:53.904180Z'}
{'type': 'l2update', 'product_id': 'BTC-USD', 'changes': [['buy', '38272.91', '0.78336105']], 'time': '2021-05-20T03:55:53.906500Z'}
{'type': 'l2update', 'product_id': 'BTC-USD', 'changes': [['buy', '38205.65', '0.01000000']], 'time': '2021-05-20T03:55:53.906814Z'}
{'type': 'l2update', 'product_id': 'BTC-USD', 'changes': [['sell', '38485.38', '0.01000000']], 'time': '2021-05-20T03:55:53.906951Z'}
{'type': 'l2update', 'product_id': 'BTC-USD', 'changes': [['buy', '38270.60', '0.02612972']], 'time': '2021-05-20T03:55:53.913236Z'}
{'type': 'l2update', 'product_id': 'BTC-USD', 'changes': [['buy', '38272.85', '0.00000000']], 'time': '2021-05-20T03:55:53.916330Z'}
{'type': 'l2update', 'product_id': 'BTC-USD', 'changes': [['sell', '38317.30', '0.00000000']], 'time': '2021-05-20T03:55:53.916330Z'}
{'type': 'l2update', 'product_id': 'BTC-USD', 'changes': [['buy', '38302.01', '0.02176482']], 'time': '2021-05-20T03:55:53.916406Z'}
{'type': 'l2update', 'product_id': 'BTC-USD', 'changes': [['sell', '38323.48', '0.05000000']], 'time': '2021-05-20T03:55:53.920833Z'}
{'type': 'l2update', 'product_id': 'BTC-USD', 'changes': [['sell', '38649.94', '0.00000000']], 'time': '2021-05-20T03:55:53.921441Z'}
{'type': 'l2update', 'product_id': 'BTC-USD', 'changes': [['buy', '38272.86', '0.04340827']], 'time': '2021-05-20T03:55:53.925078Z'}
{'type': 'l2update', 'product_id': 'BTC-USD', 'changes': [['sell', '38421.74', '0.29472316']], 'time': '2021-05-20T03:55:53.929966Z'}
{'type': 'l2update', 'product_id': 'BTC-USD', 'changes': [['sell', '38346.49', '0.04000000']], 'time': '2021-05-20T03:55:53.930009Z'}
{'type': 'l2update', 'product_id': 'BTC-USD', 'changes': [['sell', '38321.02', '0.78343891']], 'time': '2021-05-20T03:55:53.930519Z'}
{'type': 'l2update', 'product_id': 'BTC-USD', 'changes': [['buy', '38303.91', '0.04463000']], 'time': '2021-05-20T03:55:53.930727Z'}
{'type': 'l2update', 'product_id': 'BTC-USD', 'changes': [['sell', '38438.49', '0.00000000']], 'time': '2021-05-20T03:55:53.942977Z'}
{'type': 'l2update', 'product_id': 'BTC-USD', 'changes': [['sell', '38340.58', '0.02000000']], 'time': '2021-05-20T03:55:53.945027Z'}
{'type': 'l2update', 'product_id': 'BTC-USD', 'changes': [['sell', '38634.85', '0.01000000']], 'time': '2021-05-20T03:55:53.948240Z'}
{'type': 'l2update', 'product_id': 'BTC-USD', 'changes': [['buy', '38295.26', '0.40135082']], 'time': '2021-05-20T03:55:53.948746Z'}
{'type': 'l2update', 'product_id': 'BTC-USD', 'changes': [['sell', '38314.18', '0.50000000']], 'time': '2021-05-20T03:55:53.948773Z'}
{'type': 'l2update', 'product_id': 'BTC-USD', 'changes': [['sell', '38428.60', '0.32504685']], 'time': '2021-05-20T03:55:53.954807Z'}
{'type': 'l2update', 'product_id': 'BTC-USD', 'changes': [['buy', '37511.38', '0.06937187']], 'time': '2021-05-20T03:55:53.955343Z'}
{'type': 'l2update', 'product_id': 'BTC-USD', 'changes': [['sell', '38395.41', '0.00000000']], 'time': '2021-05-20T03:55:53.955570Z'}
{'type': 'l2update', 'product_id': 'BTC-USD', 'changes': [['sell', '38440.01', '0.00000000']], 'time': '2021-05-20T03:55:53.957891Z'}
{'type': 'l2update', 'product_id': 'BTC-USD', 'changes': [['sell', '38340.58', '0.00000000']], 'time': '2021-05-20T03:55:53.958932Z'}
{'type': 'l2update', 'product_id': 'BTC-USD', 'changes': [['buy', '38269.27', '0.78343891']], 'time': '2021-05-20T03:55:53.959144Z'}
{'type': 'l2update', 'product_id': 'BTC-USD', 'changes': [['buy', '38275.87', '0.43900000']], 'time': '2021-05-20T03:55:53.959407Z'}
{'type': 'l2update', 'product_id': 'BTC-USD', 'changes': [['sell', '38317.71', '0.00000000']], 'time': '2021-05-20T03:55:53.966338Z'}
{'type': 'l2update', 'product_id': 'BTC-USD', 'changes': [['sell', '38333.82', '0.00000000']], 'time': '2021-05-20T03:55:53.969232Z'}
{'type': 'l2update', 'product_id': 'BTC-USD', 'changes': [['sell', '38343.69', '0.00000000']], 'time': '2021-05-20T03:55:53.971244Z'}
{'type': 'l2update', 'product_id': 'BTC-USD', 'changes': [['buy', '37654.92', '0.00000000']], 'time': '2021-05-20T03:55:53.976238Z'}
{'type': 'l2update', 'product_id': 'BTC-USD', 'changes': [['sell', '38435.64', '0.30208559']], 'time': '2021-05-20T03:55:53.978705Z'}
{'type': 'l2update', 'product_id': 'BTC-USD', 'changes': [['sell', '38331.07', '0.04340827']], 'time': '2021-05-20T03:55:53.978791Z'}
{'type': 'l2update', 'product_id': 'BTC-USD', 'changes': [['buy', '38303.91', '0.24463000']], 'time': '2021-05-20T03:55:53.979006Z'}
{'type': 'l2update', 'product_id': 'BTC-USD', 'changes': [['sell', '39133.36', '0.06925235']], 'time': '2021-05-20T03:55:53.979574Z'}
{'type': 'l2update', 'product_id': 'BTC-USD', 'changes': [['sell', '38348.11', '0.09025653']], 'time': '2021-05-20T03:55:53.984037Z'}
{'type': 'l2update', 'product_id': 'BTC-USD', 'changes': [['sell', '38333.83', '1.70046001']], 'time': '2021-05-20T03:55:53.984268Z'}
{'type': 'l2update', 'product_id': 'BTC-USD', 'changes': [['sell', '38428.06', '0.03584250']], 'time': '2021-05-20T03:55:53.984535Z'}
{'type': 'l2update', 'product_id': 'BTC-USD', 'changes': [['buy', '38208.17', '0.14490518']], 'time': '2021-05-20T03:55:53.987577Z'}
{'type': 'l2update', 'product_id': 'BTC-USD', 'changes': [['buy', '37469.35', '0.06430000']], 'time': '2021-05-20T03:55:53.989008Z'}
{'type': 'l2update', 'product_id': 'BTC-USD', 'changes': [['buy', '37471.32', '0.04780000']], 'time': '2021-05-20T03:55:53.989008Z'}
{'type': 'l2update', 'product_id': 'BTC-USD', 'changes': [['buy', '37475.72', '0.01460000']], 'time': '2021-05-20T03:55:53.989008Z'}
{'type': 'l2update', 'product_id': 'BTC-USD', 'changes': [['buy', '37476.89', '0.00060000']], 'time': '2021-05-20T03:55:53.989008Z'}
{'type': 'l2update', 'product_id': 'BTC-USD', 'changes': [['sell', '38308.21', '0.52225932']], 'time': '2021-05-20T03:55:53.990042Z'}
{'type': 'l2update', 'product_id': 'BTC-USD', 'changes': [['sell', '38404.27', '0.00000000']], 'time': '2021-05-20T03:55:53.993869Z'}
{'type': 'l2update', 'product_id': 'BTC-USD', 'changes': [['buy', '38303.91', '0.27463000']], 'time': '2021-05-20T03:55:53.995231Z'}
{'type': 'l2update', 'product_id': 'BTC-USD', 'changes': [['buy', '38303.91', '0.37463000']], 'time': '2021-05-20T03:55:53.999358Z'}
{'type': 'l2update', 'product_id': 'BTC-USD', 'changes': [['sell', '38314.17', '0.18981474']], 'time': '2021-05-20T03:55:53.999533Z'}
{'type': 'l2update', 'product_id': 'BTC-USD', 'changes': [['buy', '38276.04', '0.05822552']], 'time': '2021-05-20T03:55:53.999677Z'}
{'type': 'l2update', 'product_id': 'BTC-USD', 'changes': [['sell', '38320.40', '0.05188826']], 'time': '2021-05-20T03:55:53.999677Z'}
{'type': 'l2update', 'product_id': 'BTC-USD', 'changes': [['buy', '38275.87', '0.00000000']], 'time': '2021-05-20T03:55:54.004190Z'}
{'type': 'l2update', 'product_id': 'BTC-USD', 'changes': [['sell', '38462.44', '0.00000000']], 'time': '2021-05-20T03:55:54.008271Z'}
{'type': 'l2update', 'product_id': 'BTC-USD', 'changes': [['sell', '38435.64', '0.62804062']], 'time': '2021-05-20T03:55:54.011844Z'}
{'type': 'l2update', 'product_id': 'BTC-USD', 'changes': [['buy', '38253.07', '2.61045697']], 'time': '2021-05-20T03:55:54.011940Z'}
{'type': 'l2update', 'product_id': 'BTC-USD', 'changes': [['buy', '38295.26', '0.00000000']], 'time': '2021-05-20T03:55:54.013713Z'}
{'type': 'l2update', 'product_id': 'BTC-USD', 'changes': [['buy', '38303.91', '0.42463000']], 'time': '2021-05-20T03:55:54.017038Z'}
{'type': 'l2update', 'product_id': 'BTC-USD', 'changes': [['sell', '38415.17', '0.01402709']], 'time': '2021-05-20T03:55:54.017120Z'}
{'type': 'l2update', 'product_id': 'BTC-USD', 'changes': [['sell', '38485.38', '0.00000000']], 'time': '2021-05-20T03:55:54.025441Z'}
{'type': 'l2update', 'product_id': 'BTC-USD', 'changes': [['buy', '38303.91', '1.07463000']], 'time': '2021-05-20T03:55:54.030705Z'}
{'type': 'l2update', 'product_id': 'BTC-USD', 'changes': [['buy', '38292.12', '0.00000000']], 'time': '2021-05-20T03:55:54.032428Z'}
{'type': 'l2update', 'product_id': 'BTC-USD', 'changes': [['buy', '38263.31', '1.20000000']], 'time': '2021-05-20T03:55:54.034653Z'}
{'type': 'l2update', 'product_id': 'BTC-USD', 'changes': [['buy', '38280.61', '0.04340827']], 'time': '2021-05-20T03:55:54.036940Z'}
{'type': 'l2update', 'product_id': 'BTC-USD', 'changes': [['sell', '38444.77', '0.34864204']], 'time': '2021-05-20T03:55:54.037017Z'}
{'type': 'l2update', 'product_id': 'BTC-USD', 'changes': [['sell', '38410.87', '0.01000000']], 'time': '2021-05-20T03:55:54.037256Z'}
{'type': 'l2update', 'product_id': 'BTC-USD', 'changes': [['sell', '38334.60', '2.61155788']], 'time': '2021-05-20T03:55:54.037379Z'}
{'type': 'l2update', 'product_id': 'BTC-USD', 'changes': [['sell', '38313.23', '0.05133330']], 'time': '2021-05-20T03:55:54.037832Z'}
{'type': 'l2update', 'product_id': 'BTC-USD', 'changes': [['sell', '38346.34', '0.01000000']], 'time': '2021-05-20T03:55:54.041129Z'}
{'type': 'l2update', 'product_id': 'BTC-USD', 'changes': [['sell', '38317.76', '0.00000000']], 'time': '2021-05-20T03:55:54.046103Z'}
{'type': 'l2update', 'product_id': 'BTC-USD', 'changes': [['buy', '38272.86', '0.00000000']], 'time': '2021-05-20T03:55:54.046256Z'}
{'type': 'l2update', 'product_id': 'BTC-USD', 'changes': [['sell', '38472.21', '0.01000000']], 'time': '2021-05-20T03:55:54.051257Z'}
{'type': 'l2update', 'product_id': 'BTC-USD', 'changes': [['buy', '38298.46', '0.52100000']], 'time': '2021-05-20T03:55:54.051291Z'}
{'type': 'l2update', 'product_id': 'BTC-USD', 'changes': [['buy', '38208.17', '0.00000000']], 'time': '2021-05-20T03:55:54.051452Z'}
{'type': 'l2update', 'product_id': 'BTC-USD', 'changes': [['sell', '38398.25', '1.20000000']], 'time': '2021-05-20T03:55:54.052281Z'}
{'type': 'l2update', 'product_id': 'BTC-USD', 'changes': [['buy', '38242.35', '2.61120350']], 'time': '2021-05-20T03:55:54.060623Z'}
{'type': 'l2update', 'product_id': 'BTC-USD', 'changes': [['sell', '38445.51', '0.01000000']], 'time': '2021-05-20T03:55:54.060813Z'}
{'type': 'l2update', 'product_id': 'BTC-USD', 'changes': [['buy', '38276.04', '0.00000000']], 'time': '2021-05-20T03:55:54.063272Z'}
{'type': 'l2update', 'product_id': 'BTC-USD', 'changes': [['sell', '38320.40', '0.00000000']], 'time': '2021-05-20T03:55:54.063272Z'}
{'type': 'l2update', 'product_id': 'BTC-USD', 'changes': [['sell', '38314.17', '0.00000000']], 'time': '2021-05-20T03:55:54.065144Z'}
{'type': 'l2update', 'product_id': 'BTC-USD', 'changes': [['sell', '38346.67', '0.02000000']], 'time': '2021-05-20T03:55:54.066536Z'}
{'type': 'l2update', 'product_id': 'BTC-USD', 'changes': [['sell', '38314.18', '0.00000000']], 'time': '2021-05-20T03:55:54.071641Z'}
{'type': 'l2update', 'product_id': 'BTC-USD', 'changes': [['buy', '38252.52', '0.00000000']], 'time': '2021-05-20T03:55:54.076701Z'}
{'type': 'l2update', 'product_id': 'BTC-USD', 'changes': [['sell', '38320.39', '2.48969908']], 'time': '2021-05-20T03:55:54.078926Z'}
{'type': 'l2update', 'product_id': 'BTC-USD', 'changes': [['sell', '38343.93', '2.61146302']], 'time': '2021-05-20T03:55:54.089931Z'}
{'type': 'l2update', 'product_id': 'BTC-USD', 'changes': [['sell', '38472.21', '0.00000000']], 'time': '2021-05-20T03:55:54.093563Z'}
{'type': 'l2update', 'product_id': 'BTC-USD', 'changes': [['buy', '38256.52', '0.10000000']], 'time': '2021-05-20T03:55:54.094806Z'}
{'type': 'l2update', 'product_id': 'BTC-USD', 'changes': [['sell', '38321.01', '0.50000000']], 'time': '2021-05-20T03:55:54.095108Z'}
{'type': 'l2update', 'product_id': 'BTC-USD', 'changes': [['buy', '38295.26', '0.40135082']], 'time': '2021-05-20T03:55:54.095308Z'}
{'type': 'l2update', 'product_id': 'BTC-USD', 'changes': [['sell', '38351.95', '0.05000000']], 'time': '2021-05-20T03:55:54.095797Z'}
{'type': 'l2update', 'product_id': 'BTC-USD', 'changes': [['sell', '38321.01', '0.68981474']], 'time': '2021-05-20T03:55:54.100121Z'}
{'type': 'l2update', 'product_id': 'BTC-USD', 'changes': [['sell', '38329.66', '0.04340827']], 'time': '2021-05-20T03:55:54.100650Z'}
{'type': 'l2update', 'product_id': 'BTC-USD', 'changes': [['sell', '38331.07', '0.00000000']], 'time': '2021-05-20T03:55:54.102228Z'}
{'type': 'l2update', 'product_id': 'BTC-USD', 'changes': [['sell', '38428.06', '0.00000000']], 'time': '2021-05-20T03:55:54.103477Z'}
{'type': 'l2update', 'product_id': 'BTC-USD', 'changes': [['buy', '38182.07', '0.74133625']], 'time': '2021-05-20T03:55:54.107188Z'}
{'type': 'l2update', 'product_id': 'BTC-USD', 'changes': [['buy', '38232.28', '0.14225945']], 'time': '2021-05-20T03:55:54.107188Z'}
{'type': 'l2update', 'product_id': 'BTC-USD', 'changes': [['sell', '38466.71', '0.00000000']], 'time': '2021-05-20T03:55:54.107331Z'}
{'type': 'l2update', 'product_id': 'BTC-USD', 'changes': [['buy', '38278.15', '0.47410000']], 'time': '2021-05-20T03:55:54.107431Z'}
{'type': 'l2update', 'product_id': 'BTC-USD', 'changes': [['sell', '38634.85', '0.00000000']], 'time': '2021-05-20T03:55:54.108855Z'}
{'type': 'l2update', 'product_id': 'BTC-USD', 'changes': [['buy', '38303.91', '1.06463000']], 'time': '2021-05-20T03:55:54.108957Z'}
{'type': 'l2update', 'product_id': 'BTC-USD', 'changes': [['buy', '38242.34', '2.61120350']], 'time': '2021-05-20T03:55:54.112353Z'}
{'type': 'l2update', 'product_id': 'BTC-USD', 'changes': [['sell', '38485.38', '0.01000000']], 'time': '2021-05-20T03:55:54.113308Z'}
{'type': 'l2update', 'product_id': 'BTC-USD', 'changes': [['buy', '38207.73', '0.00000000']], 'time': '2021-05-20T03:55:54.121709Z'}
{'type': 'l2update', 'product_id': 'BTC-USD', 'changes': [['buy', '38302.01', '0.00176482']], 'time': '2021-05-20T03:55:54.123053Z'}
{'type': 'l2update', 'product_id': 'BTC-USD', 'changes': [['sell', '38411.71', '0.01000000']], 'time': '2021-05-20T03:55:54.125614Z'}
{'type': 'l2update', 'product_id': 'BTC-USD', 'changes': [['sell', '38303.92', '0.51854537']], 'time': '2021-05-20T03:55:54.125795Z'}
{'type': 'l2update', 'product_id': 'BTC-USD', 'changes': [['sell', '38450.79', '0.01000000']], 'time': '2021-05-20T03:55:54.129625Z'}
{'type': 'l2update', 'product_id': 'BTC-USD', 'changes': [['sell', '38619.76', '0.01000000']], 'time': '2021-05-20T03:55:54.129830Z'}
{'type': 'l2update', 'product_id': 'BTC-USD', 'changes': [['buy', '38303.91', '1.03463000']], 'time': '2021-05-20T03:55:54.135465Z'}
{'type': 'l2update', 'product_id': 'BTC-USD', 'changes': [['sell', '38344.26', '2.61092506']], 'time': '2021-05-20T03:55:54.136709Z'}
{'type': 'l2update', 'product_id': 'BTC-USD', 'changes': [['buy', '38280.61', '0.00000000']], 'time': '2021-05-20T03:55:54.136784Z'}
{'type': 'l2update', 'product_id': 'BTC-USD', 'changes': [['buy', '38298.41', '0.00000000']], 'time': '2021-05-20T03:55:54.143337Z'}
{'type': 'l2update', 'product_id': 'BTC-USD', 'changes': [['sell', '38303.92', '0.00000000']], 'time': '2021-05-20T03:55:54.147836Z'}
{'type': 'l2update', 'product_id': 'BTC-USD', 'changes': [['buy', '38303.91', '0.98463000']], 'time': '2021-05-20T03:55:54.152864Z'}
{'type': 'l2update', 'product_id': 'BTC-USD', 'changes': [['buy', '38284.14', '0.04297976']], 'time': '2021-05-20T03:55:54.154278Z'}
{'type': 'l2update', 'product_id': 'BTC-USD', 'changes': [['sell', '38325.41', '0.04739940']], 'time': '2021-05-20T03:55:54.154278Z'}
{'type': 'l2update', 'product_id': 'BTC-USD', 'changes': [['buy', '38295.26', '0.00000000']], 'time': '2021-05-20T03:55:54.155170Z'}
{'type': 'l2update', 'product_id': 'BTC-USD', 'changes': [['buy', '38269.27', '0.00000000']], 'time': '2021-05-20T03:55:54.157729Z'}
{'type': 'l2update', 'product_id': 'BTC-USD', 'changes': [['buy', '38283.47', '0.04340827']], 'time': '2021-05-20T03:55:54.158769Z'}
{'type': 'l2update', 'product_id': 'BTC-USD', 'changes': [['buy', '38303.91', '0.97890000']], 'time': '2021-05-20T03:55:54.161195Z'}
{'type': 'l2update', 'product_id': 'BTC-USD', 'changes': [['sell', '38342.18', '0.00000000']], 'time': '2021-05-20T03:55:54.161277Z'}
{'type': 'l2update', 'product_id': 'BTC-USD', 'changes': [['sell', '38321.01', '0.50000000']], 'time': '2021-05-20T03:55:54.165619Z'}
{'type': 'l2update', 'product_id': 'BTC-USD', 'changes': [['buy', '38279.44', '0.00000000']], 'time': '2021-05-20T03:55:54.166687Z'}
{'type': 'l2update', 'product_id': 'BTC-USD', 'changes': [['buy', '38308.20', '0.02890000']], 'time': '2021-05-20T03:55:54.170396Z'}
{'type': 'l2update', 'product_id': 'BTC-USD', 'changes': [['buy', '38286.38', '0.17600000']], 'time': '2021-05-20T03:55:54.174332Z'}
{'type': 'l2update', 'product_id': 'BTC-USD', 'changes': [['buy', '38242.34', '0.00000000']], 'time': '2021-05-20T03:55:54.178061Z'}
{'type': 'l2update', 'product_id': 'BTC-USD', 'changes': [['buy', '38303.91', '0.87890000']], 'time': '2021-05-20T03:55:54.181757Z'}
{'type': 'l2update', 'product_id': 'BTC-USD', 'changes': [['buy', '38284.92', '0.01000000']], 'time': '2021-05-20T03:55:54.182348Z'}
{'type': 'l2update', 'product_id': 'BTC-USD', 'changes': [['buy', '38303.91', '0.85000000']], 'time': '2021-05-20T03:55:54.183068Z'}
{'type': 'l2update', 'product_id': 'BTC-USD', 'changes': [['buy', '38301.81', '0.04961074']], 'time': '2021-05-20T03:55:54.183134Z'}
{'type': 'l2update', 'product_id': 'BTC-USD', 'changes': [['buy', '38190.00', '0.00000000']], 'time': '2021-05-20T03:55:54.191110Z'}
{'type': 'l2update', 'product_id': 'BTC-USD', 'changes': [['buy', '38308.20', '0.67890000']], 'time': '2021-05-20T03:55:54.191412Z'}
{'type': 'l2update', 'product_id': 'BTC-USD', 'changes': [['sell', '38333.82', '0.04340827']], 'time': '2021-05-20T03:55:54.191479Z'}
{'type': 'l2update', 'product_id': 'BTC-USD', 'changes': [['sell', '38329.66', '0.00000000']], 'time': '2021-05-20T03:55:54.191741Z'}
{'type': 'l2update', 'product_id': 'BTC-USD', 'changes': [['sell', '38331.30', '0.00000000']], 'time': '2021-05-20T03:55:54.192186Z'}
{'type': 'l2update', 'product_id': 'BTC-USD', 'changes': [['buy', '38295.26', '0.40135082']], 'time': '2021-05-20T03:55:54.193227Z'}
{'type': 'l2update', 'product_id': 'BTC-USD', 'changes': [['sell', '38344.26', '0.00000000']], 'time': '2021-05-20T03:55:54.193807Z'}
{'type': 'l2update', 'product_id': 'BTC-USD', 'changes': [['buy', '38303.91', '0.65000000']], 'time': '2021-05-20T03:55:54.194472Z'}
{'type': 'l2update', 'product_id': 'BTC-USD', 'changes': [['sell', '38320.38', '0.18981474']], 'time': '2021-05-20T03:55:54.196487Z'}
{'type': 'l2update', 'product_id': 'BTC-USD', 'changes': [['sell', '38321.01', '0.00000000']], 'time': '2021-05-20T03:55:54.202389Z'}
{'type': 'l2update', 'product_id': 'BTC-USD', 'changes': [['sell', '38410.87', '0.00000000']], 'time': '2021-05-20T03:55:54.205279Z'}
{'type': 'l2update', 'product_id': 'BTC-USD', 'changes': [['buy', '38284.92', '0.03000000']], 'time': '2021-05-20T03:55:54.205424Z'}
{'type': 'l2update', 'product_id': 'BTC-USD', 'changes': [['sell', '38308.21', '0.00000000']], 'time': '2021-05-20T03:55:54.206739Z'}
{'type': 'l2update', 'product_id': 'BTC-USD', 'changes': [['buy', '38296.05', '0.00000000']], 'time': '2021-05-20T03:55:54.207956Z'}
{'type': 'l2update', 'product_id': 'BTC-USD', 'changes': [['sell', '38412.19', '0.00000000']], 'time': '2021-05-20T03:55:54.218349Z'}
{'type': 'l2update', 'product_id': 'BTC-USD', 'changes': [['sell', '38415.60', '0.00000000']], 'time': '2021-05-20T03:55:54.221211Z'}
{'type': 'l2update', 'product_id': 'BTC-USD', 'changes': [['buy', '38282.76', '0.03000000']], 'time': '2021-05-20T03:55:54.224457Z'}
{'type': 'l2update', 'product_id': 'BTC-USD', 'changes': [['sell', '38313.23', '0.00000000']], 'time': '2021-05-20T03:55:54.224577Z'}
{'type': 'l2update', 'product_id': 'BTC-USD', 'changes': [['buy', '38275.51', '0.00000000']], 'time': '2021-05-20T03:55:54.225442Z'}
{'type': 'l2update', 'product_id': 'BTC-USD', 'changes': [['buy', '38274.10', '0.00000000']], 'time': '2021-05-20T03:55:54.225442Z'}
{'type': 'l2update', 'product_id': 'BTC-USD', 'changes': [['buy', '38273.29', '0.00000000']], 'time': '2021-05-20T03:55:54.225442Z'}
{'type': 'l2update', 'product_id': 'BTC-USD', 'changes': [['sell', '38320.38', '0.68981474']], 'time': '2021-05-20T03:55:54.229657Z'}
{'type': 'l2update', 'product_id': 'BTC-USD', 'changes': [['buy', '38302.01', '0.00000000']], 'time': '2021-05-20T03:55:54.229818Z'}
{'type': 'l2update', 'product_id': 'BTC-USD', 'changes': [['buy', '38167.90', '0.41805408']], 'time': '2021-05-20T03:55:54.231211Z'}
{'type': 'l2update', 'product_id': 'BTC-USD', 'changes': [['sell', '38437.22', '0.01174693']], 'time': '2021-05-20T03:55:54.247504Z'}
{'type': 'l2update', 'product_id': 'BTC-USD', 'changes': [['buy', '38282.02', '0.04000000']], 'time': '2021-05-20T03:55:54.247690Z'}
{'type': 'l2update', 'product_id': 'BTC-USD', 'changes': [['buy', '37367.90', '0.04190000']], 'time': '2021-05-20T03:55:54.248031Z'}
{'type': 'l2update', 'product_id': 'BTC-USD', 'changes': [['buy', '36543.27', '0.05920000']], 'time': '2021-05-20T03:55:54.248031Z'}
{'type': 'l2update', 'product_id': 'BTC-USD', 'changes': [['sell', '38402.91', '0.01000000']], 'time': '2021-05-20T03:55:54.251265Z'}
{'type': 'l2update', 'product_id': 'BTC-USD', 'changes': [['buy', '38278.15', '0.00000000']], 'time': '2021-05-20T03:55:54.253783Z'}
{'type': 'l2update', 'product_id': 'BTC-USD', 'changes': [['buy', '38289.21', '0.02400000']], 'time': '2021-05-20T03:55:54.256560Z'}
{'type': 'l2update', 'product_id': 'BTC-USD', 'changes': [['buy', '38288.40', '0.02400000']], 'time': '2021-05-20T03:55:54.256560Z'}
{'type': 'l2update', 'product_id': 'BTC-USD', 'changes': [['buy', '38287.60', '0.02400000']], 'time': '2021-05-20T03:55:54.256560Z'}
{'type': 'l2update', 'product_id': 'BTC-USD', 'changes': [['sell', '38320.38', '0.50000000']], 'time': '2021-05-20T03:55:54.266095Z'}
{'type': 'l2update', 'product_id': 'BTC-USD', 'changes': [['buy', '38287.60', '0.00000000']], 'time': '2021-05-20T03:55:54.267969Z'}
{'type': 'l2update', 'product_id': 'BTC-USD', 'changes': [['buy', '38308.20', '0.75076082']], 'time': '2021-05-20T03:55:54.268942Z'}
{'type': 'l2update', 'product_id': 'BTC-USD', 'changes': [['buy', '38280.29', '0.43800000']], 'time': '2021-05-20T03:55:54.268969Z'}
{'type': 'l2update', 'product_id': 'BTC-USD', 'changes': [['buy', '38282.02', '0.09000000']], 'time': '2021-05-20T03:55:54.273745Z'}
{'type': 'l2update', 'product_id': 'BTC-USD', 'changes': [['sell', '38425.13', '0.01000000']], 'time': '2021-05-20T03:55:54.274221Z'}
{'type': 'l2update', 'product_id': 'BTC-USD', 'changes': [['buy', '37426.97', '0.00000000']], 'time': '2021-05-20T03:55:54.279032Z'}
{'type': 'l2update', 'product_id': 'BTC-USD', 'changes': [['buy', '36663.52', '0.00000000']], 'time': '2021-05-20T03:55:54.279032Z'}
{'type': 'l2update', 'product_id': 'BTC-USD', 'changes': [['buy', '38303.91', '0.65176482']], 'time': '2021-05-20T03:55:54.285281Z'}
{'type': 'l2update', 'product_id': 'BTC-USD', 'changes': [['buy', '38286.39', '0.04340827']], 'time': '2021-05-20T03:55:54.285956Z'}
{'type': 'l2update', 'product_id': 'BTC-USD', 'changes': [['buy', '38283.47', '0.00000000']], 'time': '2021-05-20T03:55:54.288237Z'}
{'type': 'l2update', 'product_id': 'BTC-USD', 'changes': [['sell', '38347.53', '0.03000000']], 'time': '2021-05-20T03:55:54.290999Z'}
{'type': 'l2update', 'product_id': 'BTC-USD', 'changes': [['sell', '38393.02', '0.00000000']], 'time': '2021-05-20T03:55:54.294196Z'}
{'type': 'l2update', 'product_id': 'BTC-USD', 'changes': [['sell', '38320.37', '0.18981474']], 'time': '2021-05-20T03:55:54.296783Z'}
{'type': 'l2update', 'product_id': 'BTC-USD', 'changes': [['sell', '38425.13', '0.00000000']], 'time': '2021-05-20T03:55:54.311430Z'}
{'type': 'l2update', 'product_id': 'BTC-USD', 'changes': [['sell', '38447.94', '0.01000000']], 'time': '2021-05-20T03:55:54.327387Z'}
{'type': 'l2update', 'product_id': 'BTC-USD', 'changes': [['buy', '38290.29', '0.02400000']], 'time': '2021-05-20T03:55:54.328925Z'}
{'type': 'l2update', 'product_id': 'BTC-USD', 'changes': [['sell', '38485.38', '0.00000000']], 'time': '2021-05-20T03:55:54.329661Z'}
{'type': 'l2update', 'product_id': 'BTC-USD', 'changes': [['sell', '38472.21', '0.01000000']], 'time': '2021-05-20T03:55:54.344174Z'}
{'type': 'l2update', 'product_id': 'BTC-USD', 'changes': [['sell', '38472.21', '0.00000000']], 'time': '2021-05-20T03:55:54.352984Z'}
{'type': 'l2update', 'product_id': 'BTC-USD', 'changes': [['buy', '38286.39', '0.00000000']], 'time': '2021-05-20T03:55:54.359918Z'}
{'type': 'l2update', 'product_id': 'BTC-USD', 'changes': [['sell', '38346.49', '0.00000000']], 'time': '2021-05-20T03:55:54.370257Z'}
{'type': 'l2update', 'product_id': 'BTC-USD', 'changes': [['buy', '38295.27', '0.04340827']], 'time': '2021-05-20T03:55:54.371962Z'}
{'type': 'l2update', 'product_id': 'BTC-USD', 'changes': [['sell', '38485.38', '0.01000000']], 'time': '2021-05-20T03:55:54.372402Z'}
{'type': 'l2update', 'product_id': 'BTC-USD', 'changes': [['sell', '38314.19', '0.51968605']], 'time': '2021-05-20T03:55:54.372560Z'}
{'type': 'l2update', 'product_id': 'BTC-USD', 'changes': [['sell', '38359.13', '0.50000000']], 'time': '2021-05-20T03:55:54.380027Z'}
{'type': 'l2update', 'product_id': 'BTC-USD', 'changes': [['buy', '38295.26', '0.00000000']], 'time': '2021-05-20T03:55:54.380261Z'}
{'type': 'l2update', 'product_id': 'BTC-USD', 'changes': [['sell', '38353.24', '0.04000000']], 'time': '2021-05-20T03:55:54.384810Z'}
{'type': 'l2update', 'product_id': 'BTC-USD', 'changes': [['sell', '38349.88', '0.00000000']], 'time': '2021-05-20T03:55:54.385197Z'}
{'type': 'l2update', 'product_id': 'BTC-USD', 'changes': [['buy', '38295.27', '0.00000000']], 'time': '2021-05-20T03:55:54.392362Z'}
{'type': 'l2update', 'product_id': 'BTC-USD', 'changes': [['buy', '38267.67', '0.10000000']], 'time': '2021-05-20T03:55:54.392731Z'}
{'type': 'l2update', 'product_id': 'BTC-USD', 'changes': [['buy', '38286.39', '0.04340827']], 'time': '2021-05-20T03:55:54.394352Z'}
{'type': 'l2update', 'product_id': 'BTC-USD', 'changes': [['buy', '38270.59', '0.00000000']], 'time': '2021-05-20T03:55:54.400931Z'}
{'type': 'l2update', 'product_id': 'BTC-USD', 'changes': [['buy', '38279.90', '0.58500000']], 'time': '2021-05-20T03:55:54.403796Z'}
{'type': 'l2update', 'product_id': 'BTC-USD', 'changes': [['buy', '38295.28', '0.40135082']], 'time': '2021-05-20T03:55:54.408178Z'}
{'type': 'l2update', 'product_id': 'BTC-USD', 'changes': [['buy', '38290.29', '0.00000000']], 'time': '2021-05-20T03:55:54.413566Z'}
{'type': 'l2update', 'product_id': 'BTC-USD', 'changes': [['buy', '38287.58', '0.02400000']], 'time': '2021-05-20T03:55:54.430803Z'}
{'type': 'l2update', 'product_id': 'BTC-USD', 'changes': [['sell', '38317.72', '0.00000000']], 'time': '2021-05-20T03:55:54.436581Z'}
{'type': 'l2update', 'product_id': 'BTC-USD', 'changes': [['sell', '38419.36', '0.00000000']], 'time': '2021-05-20T03:55:54.445691Z'}
{'type': 'l2update', 'product_id': 'BTC-USD', 'changes': [['sell', '38334.60', '0.00000000']], 'time': '2021-05-20T03:55:54.449740Z'}
{'type': 'l2update', 'product_id': 'BTC-USD', 'changes': [['sell', '38323.43', '0.55300000']], 'time': '2021-05-20T03:55:54.456384Z'}
{'type': 'l2update', 'product_id': 'BTC-USD', 'changes': [['sell', '38431.02', '0.01000000']], 'time': '2021-05-20T03:55:54.460789Z'}
{'type': 'l2update', 'product_id': 'BTC-USD', 'changes': [['buy', '38308.20', '0.10076082']], 'time': '2021-05-20T03:55:54.466695Z'}
{'type': 'l2update', 'product_id': 'BTC-USD', 'changes': [['sell', '38347.53', '0.00000000']], 'time': '2021-05-20T03:55:54.467867Z'}
{'type': 'l2update', 'product_id': 'BTC-USD', 'changes': [['sell', '38353.94', '0.03000000']], 'time': '2021-05-20T03:55:54.478665Z'}
{'type': 'l2update', 'product_id': 'BTC-USD', 'changes': [['sell', '38730.00', '0.00000000']], 'time': '2021-05-20T03:55:54.483616Z'}
{'type': 'l2update', 'product_id': 'BTC-USD', 'changes': [['buy', '38282.76', '0.00000000']], 'time': '2021-05-20T03:55:54.485058Z'}
{'type': 'l2update', 'product_id': 'BTC-USD', 'changes': [['sell', '38436.51', '0.00000000']], 'time': '2021-05-20T03:55:54.485535Z'}
{'type': 'l2update', 'product_id': 'BTC-USD', 'changes': [['buy', '37701.94', '0.00000000']], 'time': '2021-05-20T03:55:54.485625Z'}
{'type': 'l2update', 'product_id': 'BTC-USD', 'changes': [['buy', '37213.46', '0.00000000']], 'time': '2021-05-20T03:55:54.485625Z'}
{'type': 'l2update', 'product_id': 'BTC-USD', 'changes': [['sell', '38369.98', '0.02606204']], 'time': '2021-05-20T03:55:54.486870Z'}
{'type': 'l2update', 'product_id': 'BTC-USD', 'changes': [['buy', '37503.78', '0.06862596']], 'time': '2021-05-20T03:55:54.486911Z'}
{'type': 'l2update', 'product_id': 'BTC-USD', 'changes': [['buy', '38282.02', '0.05000000']], 'time': '2021-05-20T03:55:54.487944Z'}
{'type': 'l2update', 'product_id': 'BTC-USD', 'changes': [['buy', '38282.02', '0.00000000']], 'time': '2021-05-20T03:55:54.493937Z'}
{'type': 'l2update', 'product_id': 'BTC-USD', 'changes': [['buy', '38280.29', '0.00000000']], 'time': '2021-05-20T03:55:54.500192Z'}
{'type': 'l2update', 'product_id': 'BTC-USD', 'changes': [['sell', '39100.49', '0.06369110']], 'time': '2021-05-20T03:55:54.500294Z'}
{'type': 'l2update', 'product_id': 'BTC-USD', 'changes': [['buy', '37511.38', '0.00000000']], 'time': '2021-05-20T03:55:54.506810Z'}
{'type': 'l2update', 'product_id': 'BTC-USD', 'changes': [['buy', '38289.12', '0.03000000']], 'time': '2021-05-20T03:55:54.509101Z'}
{'type': 'l2update', 'product_id': 'BTC-USD', 'changes': [['sell', '39133.36', '0.00000000']], 'time': '2021-05-20T03:55:54.510406Z'}
{'type': 'l2update', 'product_id': 'BTC-USD', 'changes': [['sell', '38568.73', '0.00000000']], 'time': '2021-05-20T03:55:54.510739Z'}
{'type': 'l2update', 'product_id': 'BTC-USD', 'changes': [['sell', '38414.33', '0.01301597']], 'time': '2021-05-20T03:55:54.512780Z'}
{'type': 'l2update', 'product_id': 'BTC-USD', 'changes': [['buy', '38303.91', '0.65000000']], 'time': '2021-05-20T03:55:54.513749Z'}
{'type': 'l2update', 'product_id': 'BTC-USD', 'changes': [['buy', '38175.36', '0.00000000']], 'time': '2021-05-20T03:55:54.516523Z'}
{'type': 'l2update', 'product_id': 'BTC-USD', 'changes': [['sell', '38320.39', '0.00000000']], 'time': '2021-05-20T03:55:54.516928Z'}
{'type': 'l2update', 'product_id': 'BTC-USD', 'changes': [['buy', '38282.30', '0.45020000']], 'time': '2021-05-20T03:55:54.519803Z'}
{'type': 'l2update', 'product_id': 'BTC-USD', 'changes': [['sell', '38441.86', '0.00000000']], 'time': '2021-05-20T03:55:54.521323Z'}
{'type': 'l2update', 'product_id': 'BTC-USD', 'changes': [['buy', '38289.12', '0.07000000']], 'time': '2021-05-20T03:55:54.524403Z'}
{'type': 'l2update', 'product_id': 'BTC-USD', 'changes': [['sell', '38581.82', '0.01147500']], 'time': '2021-05-20T03:55:54.533048Z'}
{'type': 'l2update', 'product_id': 'BTC-USD', 'changes': [['sell', '38317.76', '2.48969908']], 'time': '2021-05-20T03:55:54.536345Z'}
{'type': 'l2update', 'product_id': 'BTC-USD', 'changes': [['sell', '38455.42', '0.01000000']], 'time': '2021-05-20T03:55:54.538787Z'}
{'type': 'l2update', 'product_id': 'BTC-USD', 'changes': [['buy', '38289.12', '0.12000000']], 'time': '2021-05-20T03:55:54.538916Z'}
{'type': 'l2update', 'product_id': 'BTC-USD', 'changes': [['sell', '38447.94', '0.00000000']], 'time': '2021-05-20T03:55:54.541015Z'}
{'type': 'l2update', 'product_id': 'BTC-USD', 'changes': [['sell', '38320.37', '0.00000000']], 'time': '2021-05-20T03:55:54.543629Z'}
{'type': 'l2update', 'product_id': 'BTC-USD', 'changes': [['sell', '38320.97', '0.55400000']], 'time': '2021-05-20T03:55:54.545845Z'}
{'type': 'l2update', 'product_id': 'BTC-USD', 'changes': [['buy', '38162.39', '0.10256400']], 'time': '2021-05-20T03:55:54.545928Z'}
{'type': 'l2update', 'product_id': 'BTC-USD', 'changes': [['sell', '38420.56', '0.01000000']], 'time': '2021-05-20T03:55:54.557390Z'}
{'type': 'l2update', 'product_id': 'BTC-USD', 'changes': [['sell', '38485.38', '0.00000000']], 'time': '2021-05-20T03:55:54.560434Z'}
{'type': 'l2update', 'product_id': 'BTC-USD', 'changes': [['buy', '38286.39', '0.00000000']], 'time': '2021-05-20T03:55:54.563124Z'}
{'type': 'l2update', 'product_id': 'BTC-USD', 'changes': [['sell', '38414.33', '0.00000000']], 'time': '2021-05-20T03:55:54.563887Z'}
{'type': 'l2update', 'product_id': 'BTC-USD', 'changes': [['sell', '38317.75', '0.18981474']], 'time': '2021-05-20T03:55:54.565787Z'}
{'type': 'l2update', 'product_id': 'BTC-USD', 'changes': [['buy', '38289.13', '0.06845011']], 'time': '2021-05-20T03:55:54.565815Z'}
{'type': 'l2update', 'product_id': 'BTC-USD', 'changes': [['sell', '38472.21', '0.01000000']], 'time': '2021-05-20T03:55:54.573367Z'}
{'type': 'l2update', 'product_id': 'BTC-USD', 'changes': [['buy', '38283.46', '0.00000000']], 'time': '2021-05-20T03:55:54.576212Z'}
{'type': 'l2update', 'product_id': 'BTC-USD', 'changes': [['sell', '38427.12', '0.01301164']], 'time': '2021-05-20T03:55:54.576954Z'}
{'type': 'l2update', 'product_id': 'BTC-USD', 'changes': [['buy', '38282.30', '0.00000000']], 'time': '2021-05-20T03:55:54.577767Z'}
{'type': 'l2update', 'product_id': 'BTC-USD', 'changes': [['sell', '38357.07', '0.01000000']], 'time': '2021-05-20T03:55:54.581122Z'}
{'type': 'l2update', 'product_id': 'BTC-USD', 'changes': [['buy', '38289.21', '0.00000000']], 'time': '2021-05-20T03:55:54.583960Z'}
{'type': 'l2update', 'product_id': 'BTC-USD', 'changes': [['buy', '37890.00', '0.19720000']], 'time': '2021-05-20T03:55:54.586743Z'}
{'type': 'l2update', 'product_id': 'BTC-USD', 'changes': [['buy', '38247.66', '0.00000000']], 'time': '2021-05-20T03:55:54.590332Z'}
{'type': 'l2update', 'product_id': 'BTC-USD', 'changes': [['buy', '38263.31', '0.00000000']], 'time': '2021-05-20T03:55:54.590825Z'}
{'type': 'l2update', 'product_id': 'BTC-USD', 'changes': [['buy', '38295.29', '0.99315797']], 'time': '2021-05-20T03:55:54.594624Z'}
{'type': 'l2update', 'product_id': 'BTC-USD', 'changes': [['buy', '38274.69', '0.01000000']], 'time': '2021-05-20T03:55:54.594806Z'}
{'type': 'l2update', 'product_id': 'BTC-USD', 'changes': [['sell', '38398.25', '0.00000000']], 'time': '2021-05-20T03:55:54.596267Z'}
{'type': 'l2update', 'product_id': 'BTC-USD', 'changes': [['buy', '38286.65', '0.02400000']], 'time': '2021-05-20T03:55:54.600022Z'}
{'type': 'l2update', 'product_id': 'BTC-USD', 'changes': [['buy', '38229.82', '0.01173710']], 'time': '2021-05-20T03:55:54.603895Z'}
{'type': 'l2update', 'product_id': 'BTC-USD', 'changes': [['buy', '38295.28', '0.00000000']], 'time': '2021-05-20T03:55:54.604193Z'}
{'type': 'l2update', 'product_id': 'BTC-USD', 'changes': [['sell', '38342.27', '0.00000000']], 'time': '2021-05-20T03:55:54.614835Z'}
{'type': 'l2update', 'product_id': 'BTC-USD', 'changes': [['buy', '38167.48', '0.00000000']], 'time': '2021-05-20T03:55:54.617540Z'}
{'type': 'l2update', 'product_id': 'BTC-USD', 'changes': [['buy', '38295.30', '0.40135082']], 'time': '2021-05-20T03:55:54.625731Z'}
{'type': 'l2update', 'product_id': 'BTC-USD', 'changes': [['sell', '38344.01', '0.49630000']], 'time': '2021-05-20T03:55:54.626157Z'}
{'type': 'l2update', 'product_id': 'BTC-USD', 'changes': [['sell', '38344.01', '0.00000000']], 'time': '2021-05-20T03:55:54.632146Z'}
{'type': 'l2update', 'product_id': 'BTC-USD', 'changes': [['buy', '38179.55', '0.01000000']], 'time': '2021-05-20T03:55:54.638608Z'}
{'type': 'l2update', 'product_id': 'BTC-USD', 'changes': [['sell', '38351.95', '0.00000000']], 'time': '2021-05-20T03:55:54.643434Z'}
{'type': 'l2update', 'product_id': 'BTC-USD', 'changes': [['sell', '38320.38', '0.00000000']], 'time': '2021-05-20T03:55:54.651680Z'}
{'type': 'l2update', 'product_id': 'BTC-USD', 'changes': [['sell', '38359.10', '0.05000000']], 'time': '2021-05-20T03:55:54.661055Z'}
{'type': 'l2update', 'product_id': 'BTC-USD', 'changes': [['buy', '38272.91', '0.00000000']], 'time': '2021-05-20T03:55:54.663312Z'}
{'type': 'l2update', 'product_id': 'BTC-USD', 'changes': [['sell', '38346.34', '0.00000000']], 'time': '2021-05-20T03:55:54.666694Z'}
{'type': 'l2update', 'product_id': 'BTC-USD', 'changes': [['sell', '38346.67', '0.00000000']], 'time': '2021-05-20T03:55:54.669164Z'}
{'type': 'l2update', 'product_id': 'BTC-USD', 'changes': [['sell', '38314.18', '0.50000000']], 'time': '2021-05-20T03:55:54.669507Z'}
{'type': 'l2update', 'product_id': 'BTC-USD', 'changes': [['buy', '38242.35', '0.00000000']], 'time': '2021-05-20T03:55:54.670138Z'}
{'type': 'l2update', 'product_id': 'BTC-USD', 'changes': [['buy', '38284.90', '0.42820000']], 'time': '2021-05-20T03:55:54.674095Z'}
{'type': 'l2update', 'product_id': 'BTC-USD', 'changes': [['sell', '38352.67', '0.01000000']], 'time': '2021-05-20T03:55:54.677815Z'}
{'type': 'l2update', 'product_id': 'BTC-USD', 'changes': [['sell', '38550.00', '0.19720000']], 'time': '2021-05-20T03:55:54.688356Z'}
{'type': 'l2update', 'product_id': 'BTC-USD', 'changes': [['sell', '38314.18', '0.00000000']], 'time': '2021-05-20T03:55:54.690186Z'}
{'type': 'l2update', 'product_id': 'BTC-USD', 'changes': [['sell', '38353.95', '0.02000000']], 'time': '2021-05-20T03:55:54.692088Z'}
{'type': 'l2update', 'product_id': 'BTC-USD', 'changes': [['buy', '38143.81', '0.04917122']], 'time': '2021-05-20T03:55:54.700388Z'}
{'type': 'l2update', 'product_id': 'BTC-USD', 'changes': [['sell', '38341.68', '0.04868100']], 'time': '2021-05-20T03:55:54.700562Z'}
{'type': 'l2update', 'product_id': 'BTC-USD', 'changes': [['buy', '38298.46', '1.36800000']], 'time': '2021-05-20T03:55:54.700761Z'}
{'type': 'l2update', 'product_id': 'BTC-USD', 'changes': [['sell', '38317.74', '0.50000000']], 'time': '2021-05-20T03:55:54.704655Z'}
{'type': 'l2update', 'product_id': 'BTC-USD', 'changes': [['buy', '38295.30', '0.00000000']], 'time': '2021-05-20T03:55:54.708371Z'}
{'type': 'l2update', 'product_id': 'BTC-USD', 'changes': [['sell', '38317.75', '0.00000000']], 'time': '2021-05-20T03:55:54.710938Z'}
{'type': 'l2update', 'product_id': 'BTC-USD', 'changes': [['sell', '38344.51', '0.41320000']], 'time': '2021-05-20T03:55:54.725500Z'}
{'type': 'l2update', 'product_id': 'BTC-USD', 'changes': [['sell', '38472.21', '0.00000000']], 'time': '2021-05-20T03:55:54.725698Z'}
{'type': 'l2update', 'product_id': 'BTC-USD', 'changes': [['sell', '38317.73', '0.18981474']], 'time': '2021-05-20T03:55:54.730607Z'}
{'type': 'l2update', 'product_id': 'BTC-USD', 'changes': [['buy', '38298.47', '0.40135082']], 'time': '2021-05-20T03:55:54.730797Z'}
{'type': 'l2update', 'product_id': 'BTC-USD', 'changes': [['sell', '38485.38', '0.01000000']], 'time': '2021-05-20T03:55:54.738471Z'}
{'type': 'l2update', 'product_id': 'BTC-USD', 'changes': [['sell', '38320.97', '0.00000000']], 'time': '2021-05-20T03:55:54.742056Z'}
{'type': 'l2update', 'product_id': 'BTC-USD', 'changes': [['buy', '38302.06', '0.52100000']], 'time': '2021-05-20T03:55:54.745864Z'}
{'type': 'l2update', 'product_id': 'BTC-USD', 'changes': [['buy', '38256.52', '0.00000000']], 'time': '2021-05-20T03:55:54.748518Z'}
{'type': 'l2update', 'product_id': 'BTC-USD', 'changes': [['sell', '38329.62', '0.55400000']], 'time': '2021-05-20T03:55:54.754585Z'}
{'type': 'l2update', 'product_id': 'BTC-USD', 'changes': [['buy', '38273.49', '2.37600000']], 'time': '2021-05-20T03:55:54.754596Z'}
{'type': 'l2update', 'product_id': 'BTC-USD', 'changes': [['sell', '38329.67', '0.00000000']], 'time': '2021-05-20T03:55:54.756911Z'}
{'type': 'l2update', 'product_id': 'BTC-USD', 'changes': [['buy', '38258.52', '0.10000000']], 'time': '2021-05-20T03:55:54.760332Z'}
{'type': 'l2update', 'product_id': 'BTC-USD', 'changes': [['sell', '38317.74', '0.00000000']], 'time': '2021-05-20T03:55:54.762940Z'}
{'type': 'l2update', 'product_id': 'BTC-USD', 'changes': [['sell', '38335.40', '0.05000000']], 'time': '2021-05-20T03:55:54.765511Z'}
{'type': 'l2update', 'product_id': 'BTC-USD', 'changes': [['sell', '38408.43', '0.02400000']], 'time': '2021-05-20T03:55:54.767721Z'}
{'type': 'l2update', 'product_id': 'BTC-USD', 'changes': [['buy', '38303.91', '0.65176482']], 'time': '2021-05-20T03:55:54.772243Z'}
{'type': 'l2update', 'product_id': 'BTC-USD', 'changes': [['sell', '38651.60', '5.00000000']], 'time': '2021-05-20T03:55:54.772782Z'}
{'type': 'l2update', 'product_id': 'BTC-USD', 'changes': [['sell', '38367.82', '0.32000000']], 'time': '2021-05-20T03:55:54.772782Z'}
{'type': 'l2update', 'product_id': 'BTC-USD', 'changes': [['sell', '38462.41', '0.80000000']], 'time': '2021-05-20T03:55:54.772782Z'}
