{'type': 'l2update', 'product_id': 'BTC-USD', 'changes': [['sell', '38297.43', '0.11492000']], 'time': '2021-05-20T03:54:40.893048Z'}
{'type': 'l2update', 'product_id': 'BTC-USD', 'changes': [['sell', '38355.85', '0.50000000']], 'time': '2021-05-20T03:54:40.893239Z'}
{'type': 'l2update', 'product_id': 'BTC-USD', 'changes': [['sell', '38319.82', '0.00000000']], 'time': '2021-05-20T03:54:40.894331Z'}
{'type': 'l2update', 'product_id': 'BTC-USD', 'changes': [['buy', '38284.19', '0.00000000']], 'time': '2021-05-20T03:54:40.895059Z'}
{'type': 'l2update', 'product_id': 'BTC-USD', 'changes': [['buy', '38279.87', '0.00091000']], 'time': '2021-05-20T03:54:40.896920Z'}
{'type': 'l2update', 'product_id': 'BTC-USD', 'changes': [['sell', '38296.78', '0.02590000']], 'time': '2021-05-20T03:54:40.898469Z'}
{'type': 'l2update', 'product_id': 'BTC-USD', 'changes': [['sell', '38296.78', '0.10050000']], 'time': '2021-05-20T03:54:40.899518Z'}
{'type': 'l2update', 'product_id': 'BTC-USD', 'changes': [['buy', '38284.68', '0.05745369']], 'time': '2021-05-20T03:54:40.900067Z'}
{'type': 'l2update', 'product_id': 'BTC-USD', 'changes': [['sell', '38332.51', '0.44210000']], 'time': '2021-05-20T03:54:40.900153Z'}
{'type': 'l2update', 'product_id': 'BTC-USD', 'changes': [['buy', '38284.86', '0.01492000']], 'time': '2021-05-20T03:54:40.900357Z'}
{'type': 'l2update', 'product_id': 'BTC-USD', 'changes': [['sell', '38297.43', '0.10000000']], 'time': '2021-05-20T03:54:40.901389Z'}
{'type': 'l2update', 'product_id': 'BTC-USD', 'changes': [['buy', '38164.81', '0.00000000']], 'time': '2021-05-20T03:54:40.902503Z'}
{'type': 'l2update', 'product_id': 'BTC-USD', 'changes': [['buy', '38270.53', '0.00000000']], 'time': '2021-05-20T03:54:40.904498Z'}
{'type': 'l2update', 'product_id': 'BTC-USD', 'changes': [['sell', '38297.43', '1.51840229']], 'time': '2021-05-20T03:54:40.904584Z'}
{'type': 'l2update', 'product_id': 'BTC-USD', 'changes': [['buy', '38269.49', '0.00000000']], 'time': '2021-05-20T03:54:40.905086Z'}
{'type': 'l2update', 'product_id': 'BTC-USD', 'changes': [['buy', '38268.56', '0.00000000']], 'time': '2021-05-20T03:54:40.905086Z'}
{'type': 'l2update', 'product_id': 'BTC-USD', 'changes': [['buy', '38273.00', '0.00000000']], 'time': '2021-05-20T03:54:40.905115Z'}
{'type': 'l2update', 'product_id': 'BTC-USD', 'changes': [['sell', '38297.43', '1.71840229']], 'time': '2021-05-20T03:54:40.906189Z'}
{'type': 'l2update', 'product_id': 'BTC-USD', 'changes': [['sell', '38413.62', '0.00000000']], 'time': '2021-05-20T03:54:40.906234Z'}
{'type': 'l2update', 'product_id': 'BTC-USD', 'changes': [['sell', '38296.78', '0.09933004']], 'time': '2021-05-20T03:54:40.906259Z'}
{'type': 'l2update', 'product_id': 'BTC-USD', 'changes': [['sell', '38306.00', '1.56024252']], 'time': '2021-05-20T03:54:40.908106Z'}
{'type': 'l2update', 'product_id': 'BTC-USD', 'changes': [['sell', '38296.78', '0.02473004']], 'time': '2021-05-20T03:54:40.908896Z'}
{'type': 'l2update', 'product_id': 'BTC-USD', 'changes': [['buy', '38284.86', '0.00000000']], 'time': '2021-05-20T03:54:40.911697Z'}
{'type': 'l2update', 'product_id': 'BTC-USD', 'changes': [['sell', '38319.19', '0.05000000']], 'time': '2021-05-20T03:54:40.914897Z'}
{'type': 'l2update', 'product_id': 'BTC-USD', 'changes': [['buy', '38267.75', '0.00000000']], 'time': '2021-05-20T03:54:40.916755Z'}
{'type': 'l2update', 'product_id': 'BTC-USD', 'changes': [['sell', '38296.78', '0.00000000']], 'time': '2021-05-20T03:54:40.918859Z'}
{'type': 'l2update', 'product_id': 'BTC-USD', 'changes': [['sell', '38332.51', '0.00000000']], 'time': '2021-05-20T03:54:40.920986Z'}
{'type': 'l2update', 'product_id': 'BTC-USD', 'changes': [['buy', '38284.68', '0.00000000']], 'time': '2021-05-20T03:54:40.921356Z'}
{'type': 'l2update', 'product_id': 'BTC-USD', 'changes': [['sell', '38296.78', '1.76625755']], 'time': '2021-05-20T03:54:40.926850Z'}
{'type': 'l2update', 'product_id': 'BTC-USD', 'changes': [['buy', '38140.09', '0.01000000']], 'time': '2021-05-20T03:54:40.927160Z'}
{'type': 'l2update', 'product_id': 'BTC-USD', 'changes': [['sell', '38438.27', '0.35659020']], 'time': '2021-05-20T03:54:40.928039Z'}
{'type': 'l2update', 'product_id': 'BTC-USD', 'changes': [['buy', '38165.03', '0.35659020']], 'time': '2021-05-20T03:54:40.928039Z'}
{'type': 'l2update', 'product_id': 'BTC-USD', 'changes': [['buy', '38280.19', '0.01714631']], 'time': '2021-05-20T03:54:40.928057Z'}
{'type': 'l2update', 'product_id': 'BTC-USD', 'changes': [['sell', '38308.91', '0.00000000']], 'time': '2021-05-20T03:54:40.928089Z'}
{'type': 'l2update', 'product_id': 'BTC-USD', 'changes': [['sell', '38297.43', '1.61840229']], 'time': '2021-05-20T03:54:40.932648Z'}
{'type': 'l2update', 'product_id': 'BTC-USD', 'changes': [['sell', '38290.81', '0.05021633']], 'time': '2021-05-20T03:54:40.933278Z'}
{'type': 'l2update', 'product_id': 'BTC-USD', 'changes': [['sell', '38290.81', '0.06513633']], 'time': '2021-05-20T03:54:40.933357Z'}
{'type': 'l2update', 'product_id': 'BTC-USD', 'changes': [['buy', '37435.21', '0.06943653']], 'time': '2021-05-20T03:54:40.933594Z'}
{'type': 'l2update', 'product_id': 'BTC-USD', 'changes': [['buy', '38274.27', '0.58716278']], 'time': '2021-05-20T03:54:40.934088Z'}
{'type': 'l2update', 'product_id': 'BTC-USD', 'changes': [['sell', '38294.86', '0.03600000']], 'time': '2021-05-20T03:54:40.934114Z'}
{'type': 'l2update', 'product_id': 'BTC-USD', 'changes': [['buy', '38262.64', '0.02400000']], 'time': '2021-05-20T03:54:40.940597Z'}
{'type': 'l2update', 'product_id': 'BTC-USD', 'changes': [['buy', '38261.83', '0.02400000']], 'time': '2021-05-20T03:54:40.940597Z'}
{'type': 'l2update', 'product_id': 'BTC-USD', 'changes': [['buy', '38261.03', '0.02400000']], 'time': '2021-05-20T03:54:40.940597Z'}
{'type': 'l2update', 'product_id': 'BTC-USD', 'changes': [['sell', '38297.43', '1.41840229']], 'time': '2021-05-20T03:54:40.941629Z'}
{'type': 'l2update', 'product_id': 'BTC-USD', 'changes': [['sell', '38290.81', '0.01492000']], 'time': '2021-05-20T03:54:40.942645Z'}
{'type': 'l2update', 'product_id': 'BTC-USD', 'changes': [['sell', '38295.51', '0.03600000']], 'time': '2021-05-20T03:54:40.943666Z'}
{'type': 'l2update', 'product_id': 'BTC-USD', 'changes': [['sell', '48217.24', '0.00216500']], 'time': '2021-05-20T03:54:40.943956Z'}
{'type': 'l2update', 'product_id': 'BTC-USD', 'changes': [['buy', '38258.75', '0.00000000']], 'time': '2021-05-20T03:54:40.944694Z'}
{'type': 'l2update', 'product_id': 'BTC-USD', 'changes': [['sell', '38294.86', '0.00000000']], 'time': '2021-05-20T03:54:40.948962Z'}
{'type': 'l2update', 'product_id': 'BTC-USD', 'changes': [['sell', '38297.42', '0.50000000']], 'time': '2021-05-20T03:54:40.958733Z'}
{'type': 'l2update', 'product_id': 'BTC-USD', 'changes': [['buy', '38277.92', '0.84700000']], 'time': '2021-05-20T03:54:40.958795Z'}
{'type': 'l2update', 'product_id': 'BTC-USD', 'changes': [['sell', '38290.81', '0.03930367']], 'time': '2021-05-20T03:54:40.959595Z'}
{'type': 'l2update', 'product_id': 'BTC-USD', 'changes': [['buy', '38278.23', '0.01492000']], 'time': '2021-05-20T03:54:40.959614Z'}
{'type': 'l2update', 'product_id': 'BTC-USD', 'changes': [['buy', '38262.64', '0.00000000']], 'time': '2021-05-20T03:54:40.959717Z'}
{'type': 'l2update', 'product_id': 'BTC-USD', 'changes': [['sell', '38313.95', '0.17100000']], 'time': '2021-05-20T03:54:40.960044Z'}
{'type': 'l2update', 'product_id': 'BTC-USD', 'changes': [['sell', '38290.81', '0.07530367']], 'time': '2021-05-20T03:54:40.960076Z'}
{'type': 'l2update', 'product_id': 'BTC-USD', 'changes': [['sell', '38295.51', '0.00000000']], 'time': '2021-05-20T03:54:40.960403Z'}
{'type': 'l2update', 'product_id': 'BTC-USD', 'changes': [['sell', '38501.95', '0.01000000']], 'time': '2021-05-20T03:54:40.962498Z'}
{'type': 'l2update', 'product_id': 'BTC-USD', 'changes': [['sell', '38290.81', '0.07497201']], 'time': '2021-05-20T03:54:40.962697Z'}
{'type': 'l2update', 'product_id': 'BTC-USD', 'changes': [['buy', '38278.23', '0.07237369']], 'time': '2021-05-20T03:54:40.963070Z'}
{'type': 'l2update', 'product_id': 'BTC-USD', 'changes': [['sell', '38290.81', '0.17497201']], 'time': '2021-05-20T03:54:40.963337Z'}
{'type': 'l2update', 'product_id': 'BTC-USD', 'changes': [['buy', '38164.74', '0.07071574']], 'time': '2021-05-20T03:54:40.963945Z'}
{'type': 'l2update', 'product_id': 'BTC-USD', 'changes': [['sell', '38290.81', '0.20087201']], 'time': '2021-05-20T03:54:40.964072Z'}
{'type': 'l2update', 'product_id': 'BTC-USD', 'changes': [['buy', '38116.55', '0.00000000']], 'time': '2021-05-20T03:54:40.964358Z'}
{'type': 'l2update', 'product_id': 'BTC-USD', 'changes': [['buy', '38290.80', '0.00006512']], 'time': '2021-05-20T03:54:40.968157Z'}
{'type': 'l2update', 'product_id': 'BTC-USD', 'changes': [['sell', '38290.81', '0.31467201']], 'time': '2021-05-20T03:54:40.971678Z'}
{'type': 'l2update', 'product_id': 'BTC-USD', 'changes': [['sell', '38290.81', '0.96467201']], 'time': '2021-05-20T03:54:40.971762Z'}
{'type': 'l2update', 'product_id': 'BTC-USD', 'changes': [['buy', '38274.27', '0.00000000']], 'time': '2021-05-20T03:54:40.973520Z'}
{'type': 'l2update', 'product_id': 'BTC-USD', 'changes': [['buy', '38268.20', '0.49510000']], 'time': '2021-05-20T03:54:40.977477Z'}
{'type': 'l2update', 'product_id': 'BTC-USD', 'changes': [['sell', '38414.37', '0.32865810']], 'time': '2021-05-20T03:54:40.981632Z'}
{'type': 'l2update', 'product_id': 'BTC-USD', 'changes': [['sell', '38373.84', '0.29784822']], 'time': '2021-05-20T03:54:40.981632Z'}
{'type': 'l2update', 'product_id': 'BTC-USD', 'changes': [['sell', '38373.84', '0.00000000']], 'time': '2021-05-20T03:54:40.981632Z'}
{'type': 'l2update', 'product_id': 'BTC-USD', 'changes': [['sell', '38362.25', '0.00000000']], 'time': '2021-05-20T03:54:40.981632Z'}
{'type': 'l2update', 'product_id': 'BTC-USD', 'changes': [['sell', '38356.74', '0.00000000']], 'time': '2021-05-20T03:54:40.981632Z'}
{'type': 'l2update', 'product_id': 'BTC-USD', 'changes': [['sell', '38346.29', '0.00000000']], 'time': '2021-05-20T03:54:40.981632Z'}
{'type': 'l2update', 'product_id': 'BTC-USD', 'changes': [['sell', '38334.48', '0.14879780']], 'time': '2021-05-20T03:54:40.981632Z'}
{'type': 'l2update', 'product_id': 'BTC-USD', 'changes': [['sell', '38334.12', '0.03415991']], 'time': '2021-05-20T03:54:40.981632Z'}
{'type': 'l2update', 'product_id': 'BTC-USD', 'changes': [['sell', '38360.90', '0.00000000']], 'time': '2021-05-20T03:54:40.982672Z'}
{'type': 'l2update', 'product_id': 'BTC-USD', 'changes': [['buy', '38278.23', '0.05745369']], 'time': '2021-05-20T03:54:40.994574Z'}
{'type': 'l2update', 'product_id': 'BTC-USD', 'changes': [['sell', '38436.09', '0.00000000']], 'time': '2021-05-20T03:54:40.996870Z'}
{'type': 'l2update', 'product_id': 'BTC-USD', 'changes': [['buy', '38277.92', '0.00000000']], 'time': '2021-05-20T03:54:40.996934Z'}
{'type': 'l2update', 'product_id': 'BTC-USD', 'changes': [['sell', '38319.20', '0.00000000']], 'time': '2021-05-20T03:54:41.008597Z'}
{'type': 'l2update', 'product_id': 'BTC-USD', 'changes': [['buy', '28750.00', '3.40306906']], 'time': '2021-05-20T03:54:41.013560Z'}
{'type': 'l2update', 'product_id': 'BTC-USD', 'changes': [['buy', '38261.83', '0.00000000']], 'time': '2021-05-20T03:54:41.013872Z'}
{'type': 'l2update', 'product_id': 'BTC-USD', 'changes': [['buy', '38261.03', '0.00000000']], 'time': '2021-05-20T03:54:41.013872Z'}
{'type': 'l2update', 'product_id': 'BTC-USD', 'changes': [['buy', '38248.09', '0.00000000']], 'time': '2021-05-20T03:54:41.014265Z'}
{'type': 'l2update', 'product_id': 'BTC-USD', 'changes': [['buy', '38280.19', '0.00000000']], 'time': '2021-05-20T03:54:41.017435Z'}
{'type': 'l2update', 'product_id': 'BTC-USD', 'changes': [['buy', '38140.09', '0.00000000']], 'time': '2021-05-20T03:54:41.018065Z'}
{'type': 'l2update', 'product_id': 'BTC-USD', 'changes': [['buy', '37435.21', '0.00000000']], 'time': '2021-05-20T03:54:41.018264Z'}
{'type': 'l2update', 'product_id': 'BTC-USD', 'changes': [['buy', '38278.23', '0.00000000']], 'time': '2021-05-20T03:54:41.024618Z'}
{'type': 'l2update', 'product_id': 'BTC-USD', 'changes': [['sell', '38313.33', '0.00000000']], 'time': '2021-05-20T03:54:41.034814Z'}
{'type': 'l2update', 'product_id': 'BTC-USD', 'changes': [['sell', '38325.29', '0.01000000']], 'time': '2021-05-20T03:54:41.035278Z'}
{'type': 'l2update', 'product_id': 'BTC-USD', 'changes': [['buy', '38251.00', '0.00000000']], 'time': '2021-05-20T03:54:41.035296Z'}
{'type': 'l2update', 'product_id': 'BTC-USD', 'changes': [['buy', '38254.79', '0.00000000']], 'time': '2021-05-20T03:54:41.035296Z'}
{'type': 'l2update', 'product_id': 'BTC-USD', 'changes': [['sell', '38290.81', '1.16467201']], 'time': '2021-05-20T03:54:41.043533Z'}
{'type': 'l2update', 'product_id': 'BTC-USD', 'changes': [['sell', '38290.81', '1.17040201']], 'time': '2021-05-20T03:54:41.047448Z'}
{'type': 'l2update', 'product_id': 'BTC-USD', 'changes': [['sell', '38297.42', '0.00000000']], 'time': '2021-05-20T03:54:41.050082Z'}
{'type': 'l2update', 'product_id': 'BTC-USD', 'changes': [['sell', '38296.78', '0.00000000']], 'time': '2021-05-20T03:54:41.073620Z'}
{'type': 'l2update', 'product_id': 'BTC-USD', 'changes': [['sell', '38411.03', '0.00000000']], 'time': '2021-05-20T03:54:41.076203Z'}
{'type': 'l2update', 'product_id': 'BTC-USD', 'changes': [['buy', '38255.23', '0.00000000']], 'time': '2021-05-20T03:54:41.083277Z'}
{'type': 'l2update', 'product_id': 'BTC-USD', 'changes': [['buy', '38265.28', '0.58716278']], 'time': '2021-05-20T03:54:41.088539Z'}
{'type': 'l2update', 'product_id': 'BTC-USD', 'changes': [['buy', '38268.20', '0.00000000']], 'time': '2021-05-20T03:54:41.089556Z'}
{'type': 'l2update', 'product_id': 'BTC-USD', 'changes': [['buy', '38269.24', '0.05379352']], 'time': '2021-05-20T03:54:41.097564Z'}
{'type': 'l2update', 'product_id': 'BTC-USD', 'changes': [['sell', '38309.82', '0.05434386']], 'time': '2021-05-20T03:54:41.097564Z'}
{'type': 'l2update', 'product_id': 'BTC-USD', 'changes': [['buy', '38290.80', '0.00000000']], 'time': '2021-05-20T03:54:41.099184Z'}
{'type': 'l2update', 'product_id': 'BTC-USD', 'changes': [['sell', '38316.64', '0.14879780']], 'time': '2021-05-20T03:54:41.114584Z'}
{'type': 'l2update', 'product_id': 'BTC-USD', 'changes': [['buy', '38139.06', '1.04725620']], 'time': '2021-05-20T03:54:41.114584Z'}
{'type': 'l2update', 'product_id': 'BTC-USD', 'changes': [['buy', '38277.87', '0.00000000']], 'time': '2021-05-20T03:54:41.118030Z'}
{'type': 'l2update', 'product_id': 'BTC-USD', 'changes': [['sell', '48220.68', '0.00216500']], 'time': '2021-05-20T03:54:41.118425Z'}
{'type': 'l2update', 'product_id': 'BTC-USD', 'changes': [['buy', '38265.32', '0.84800000']], 'time': '2021-05-20T03:54:41.125142Z'}
{'type': 'l2update', 'product_id': 'BTC-USD', 'changes': [['sell', '38422.40', '0.01000000']], 'time': '2021-05-20T03:54:41.125729Z'}
{'type': 'l2update', 'product_id': 'BTC-USD', 'changes': [['sell', '38319.19', '0.00000000']], 'time': '2021-05-20T03:54:41.126685Z'}
{'type': 'l2update', 'product_id': 'BTC-USD', 'changes': [['buy', '38280.46', '0.01492000']], 'time': '2021-05-20T03:54:41.129501Z'}
{'type': 'l2update', 'product_id': 'BTC-USD', 'changes': [['buy', '38182.08', '0.50000000']], 'time': '2021-05-20T03:54:41.135222Z'}
{'type': 'l2update', 'product_id': 'BTC-USD', 'changes': [['sell', '38290.81', '1.05660201']], 'time': '2021-05-20T03:54:41.137223Z'}
{'type': 'l2update', 'product_id': 'BTC-USD', 'changes': [['buy', '38278.17', '0.01714631']], 'time': '2021-05-20T03:54:41.142282Z'}
{'type': 'l2update', 'product_id': 'BTC-USD', 'changes': [['buy', '38278.17', '0.05745369']], 'time': '2021-05-20T03:54:41.150043Z'}
{'type': 'l2update', 'product_id': 'BTC-USD', 'changes': [['buy', '38242.85', '0.00000000']], 'time': '2021-05-20T03:54:41.154026Z'}
{'type': 'l2update', 'product_id': 'BTC-USD', 'changes': [['sell', '40000.00', '47.58305797']], 'time': '2021-05-20T03:54:41.154593Z'}
{'type': 'l2update', 'product_id': 'BTC-USD', 'changes': [['buy', '38242.98', '0.01000000']], 'time': '2021-05-20T03:54:41.161891Z'}
{'type': 'l2update', 'product_id': 'BTC-USD', 'changes': [['sell', '38290.81', '1.15660201']], 'time': '2021-05-20T03:54:41.162638Z'}
{'type': 'l2update', 'product_id': 'BTC-USD', 'changes': [['sell', '38290.80', '0.00573000']], 'time': '2021-05-20T03:54:41.165562Z'}
{'type': 'l2update', 'product_id': 'BTC-USD', 'changes': [['sell', '38290.81', '1.65660201']], 'time': '2021-05-20T03:54:41.172472Z'}
{'type': 'l2update', 'product_id': 'BTC-USD', 'changes': [['sell', '38297.43', '0.00000000']], 'time': '2021-05-20T03:54:41.186431Z'}
{'type': 'l2update', 'product_id': 'BTC-USD', 'changes': [['sell', '38310.44', '0.00000000']], 'time': '2021-05-20T03:54:41.193716Z'}
{'type': 'l2update', 'product_id': 'BTC-USD', 'changes': [['buy', '38253.66', '0.00000000']], 'time': '2021-05-20T03:54:41.195322Z'}
{'type': 'l2update', 'product_id': 'BTC-USD', 'changes': [['sell', '38393.57', '0.03675286']], 'time': '2021-05-20T03:54:41.200613Z'}
{'type': 'l2update', 'product_id': 'BTC-USD', 'changes': [['buy', '38244.83', '0.00000000']], 'time': '2021-05-20T03:54:41.202359Z'}
{'type': 'l2update', 'product_id': 'BTC-USD', 'changes': [['sell', '38290.80', '0.00000000']], 'time': '2021-05-20T03:54:41.209901Z'}
{'type': 'l2update', 'product_id': 'BTC-USD', 'changes': [['sell', '38290.81', '1.64201367']], 'time': '2021-05-20T03:54:41.209901Z'}
{'type': 'l2update', 'product_id': 'BTC-USD', 'changes': [['sell', '38290.81', '1.63671794']], 'time': '2021-05-20T03:54:41.209901Z'}
{'type': 'l2update', 'product_id': 'BTC-USD', 'changes': [['sell', '38290.81', '1.61763000']], 'time': '2021-05-20T03:54:41.215124Z'}
{'type': 'l2update', 'product_id': 'BTC-USD', 'changes': [['sell', '38282.04', '0.02590000']], 'time': '2021-05-20T03:54:41.220886Z'}
{'type': 'l2update', 'product_id': 'BTC-USD', 'changes': [['sell', '38297.38', '1.91800000']], 'time': '2021-05-20T03:54:41.224611Z'}
{'type': 'l2update', 'product_id': 'BTC-USD', 'changes': [['sell', '38313.21', '0.00000000']], 'time': '2021-05-20T03:54:41.241923Z'}
{'type': 'l2update', 'product_id': 'BTC-USD', 'changes': [['sell', '43100.00', '1.09530000']], 'time': '2021-05-20T03:54:41.242347Z'}
{'type': 'l2update', 'product_id': 'BTC-USD', 'changes': [['sell', '38414.37', '0.00000000']], 'time': '2021-05-20T03:54:41.242512Z'}
{'type': 'l2update', 'product_id': 'BTC-USD', 'changes': [['sell', '38399.91', '0.00000000']], 'time': '2021-05-20T03:54:41.242512Z'}
{'type': 'l2update', 'product_id': 'BTC-USD', 'changes': [['sell', '38380.53', '0.00000000']], 'time': '2021-05-20T03:54:41.242512Z'}
{'type': 'l2update', 'product_id': 'BTC-USD', 'changes': [['sell', '38338.47', '0.00000000']], 'time': '2021-05-20T03:54:41.242512Z'}
{'type': 'l2update', 'product_id': 'BTC-USD', 'changes': [['sell', '38334.48', '0.00000000']], 'time': '2021-05-20T03:54:41.242512Z'}
{'type': 'l2update', 'product_id': 'BTC-USD', 'changes': [['buy', '38190.83', '0.06274957']], 'time': '2021-05-20T03:54:41.242512Z'}
{'type': 'l2update', 'product_id': 'BTC-USD', 'changes': [['buy', '38200.05', '0.41309886']], 'time': '2021-05-20T03:54:41.242512Z'}
{'type': 'l2update', 'product_id': 'BTC-USD', 'changes': [['buy', '38280.46', '0.00000000']], 'time': '2021-05-20T03:54:41.254367Z'}
{'type': 'l2update', 'product_id': 'BTC-USD', 'changes': [['sell', '38319.82', '0.05000000']], 'time': '2021-05-20T03:54:41.255538Z'}
{'type': 'l2update', 'product_id': 'BTC-USD', 'changes': [['buy', '38265.32', '0.00000000']], 'time': '2021-05-20T03:54:41.255987Z'}
{'type': 'l2update', 'product_id': 'BTC-USD', 'changes': [['buy', '38152.28', '0.01000000']], 'time': '2021-05-20T03:54:41.260088Z'}
{'type': 'l2update', 'product_id': 'BTC-USD', 'changes': [['buy', '38256.79', '0.02400000']], 'time': '2021-05-20T03:54:41.260496Z'}
{'type': 'l2update', 'product_id': 'BTC-USD', 'changes': [['buy', '38255.99', '0.02400000']], 'time': '2021-05-20T03:54:41.260496Z'}
{'type': 'l2update', 'product_id': 'BTC-USD', 'changes': [['buy', '38255.18', '0.02400000']], 'time': '2021-05-20T03:54:41.260496Z'}
{'type': 'l2update', 'product_id': 'BTC-USD', 'changes': [['buy', '38160.54', '0.00000000']], 'time': '2021-05-20T03:54:41.264640Z'}
{'type': 'l2update', 'product_id': 'BTC-USD', 'changes': [['sell', '38294.47', '0.00600000']], 'time': '2021-05-20T03:54:41.268268Z'}
{'type': 'l2update', 'product_id': 'BTC-USD', 'changes': [['buy', '38278.17', '0.04030738']], 'time': '2021-05-20T03:54:41.271348Z'}
{'type': 'l2update', 'product_id': 'BTC-USD', 'changes': [['sell', '38290.49', '0.05021633']], 'time': '2021-05-20T03:54:41.271576Z'}
{'type': 'l2update', 'product_id': 'BTC-USD', 'changes': [['buy', '38278.17', '0.00000000']], 'time': '2021-05-20T03:54:41.275836Z'}
{'type': 'l2update', 'product_id': 'BTC-USD', 'changes': [['sell', '38290.81', '1.61190000']], 'time': '2021-05-20T03:54:41.278859Z'}
{'type': 'l2update', 'product_id': 'BTC-USD', 'changes': [['sell', '38316.64', '0.16246176']], 'time': '2021-05-20T03:54:41.280347Z'}
{'type': 'l2update', 'product_id': 'BTC-USD', 'changes': [['sell', '38290.80', '0.20000000']], 'time': '2021-05-20T03:54:41.281063Z'}
{'type': 'l2update', 'product_id': 'BTC-USD', 'changes': [['buy', '38261.29', '0.00000000']], 'time': '2021-05-20T03:54:41.287337Z'}
{'type': 'l2update', 'product_id': 'BTC-USD', 'changes': [['sell', '40000.00', '47.46070785']], 'time': '2021-05-20T03:54:41.289070Z'}
{'type': 'l2update', 'product_id': 'BTC-USD', 'changes': [['sell', '38290.81', '2.90505285']], 'time': '2021-05-20T03:54:41.303121Z'}
{'type': 'l2update', 'product_id': 'BTC-USD', 'changes': [['buy', '38265.28', '0.00000000']], 'time': '2021-05-20T03:54:41.304279Z'}
{'type': 'l2update', 'product_id': 'BTC-USD', 'changes': [['sell', '38325.29', '0.00000000']], 'time': '2021-05-20T03:54:41.307529Z'}
{'type': 'l2update', 'product_id': 'BTC-USD', 'changes': [['sell', '38282.04', '0.02340122']], 'time': '2021-05-20T03:54:41.348686Z'}
{'type': 'l2update', 'product_id': 'BTC-USD', 'changes': [['sell', '38347.97', '0.00000000']], 'time': '2021-05-20T03:54:41.376625Z'}
{'type': 'l2update', 'product_id': 'BTC-USD', 'changes': [['buy', '38196.88', '0.03790952']], 'time': '2021-05-20T03:54:41.379498Z'}
{'type': 'l2update', 'product_id': 'BTC-USD', 'changes': [['sell', '38290.81', '2.87915285']], 'time': '2021-05-20T03:54:41.382629Z'}
{'type': 'l2update', 'product_id': 'BTC-USD', 'changes': [['buy', '38244.53', '0.00000000']], 'time': '2021-05-20T03:54:41.383767Z'}
{'type': 'l2update', 'product_id': 'BTC-USD', 'changes': [['sell', '38319.82', '0.00000000']], 'time': '2021-05-20T03:54:41.383926Z'}
{'type': 'l2update', 'product_id': 'BTC-USD', 'changes': [['buy', '38256.79', '0.00000000']], 'time': '2021-05-20T03:54:41.387814Z'}
{'type': 'l2update', 'product_id': 'BTC-USD', 'changes': [['sell', '38290.14', '0.01492000']], 'time': '2021-05-20T03:54:41.388413Z'}
{'type': 'l2update', 'product_id': 'BTC-USD', 'changes': [['sell', '43100.00', '2.36720000']], 'time': '2021-05-20T03:54:41.389530Z'}
{'type': 'l2update', 'product_id': 'BTC-USD', 'changes': [['sell', '38370.25', '0.00000000']], 'time': '2021-05-20T03:54:41.397633Z'}
{'type': 'l2update', 'product_id': 'BTC-USD', 'changes': [['sell', '38360.91', '0.00000000']], 'time': '2021-05-20T03:54:41.397633Z'}
{'type': 'l2update', 'product_id': 'BTC-USD', 'changes': [['sell', '38355.97', '0.00000000']], 'time': '2021-05-20T03:54:41.397633Z'}
{'type': 'l2update', 'product_id': 'BTC-USD', 'changes': [['sell', '38346.66', '0.00000000']], 'time': '2021-05-20T03:54:41.397633Z'}
{'type': 'l2update', 'product_id': 'BTC-USD', 'changes': [['sell', '38342.29', '0.00000000']], 'time': '2021-05-20T03:54:41.397633Z'}
{'type': 'l2update', 'product_id': 'BTC-USD', 'changes': [['sell', '38334.12', '0.00000000']], 'time': '2021-05-20T03:54:41.397633Z'}
{'type': 'l2update', 'product_id': 'BTC-USD', 'changes': [['buy', '38229.23', '0.02817141']], 'time': '2021-05-20T03:54:41.397633Z'}
{'type': 'l2update', 'product_id': 'BTC-USD', 'changes': [['buy', '38229.23', '0.00000000']], 'time': '2021-05-20T03:54:41.397633Z'}
{'type': 'l2update', 'product_id': 'BTC-USD', 'changes': [['sell', '38290.81', '2.77915285']], 'time': '2021-05-20T03:54:41.398257Z'}
{'type': 'l2update', 'product_id': 'BTC-USD', 'changes': [['sell', '38396.18', '0.00000000']], 'time': '2021-05-20T03:54:41.399841Z'}
{'type': 'l2update', 'product_id': 'BTC-USD', 'changes': [['buy', '38274.50', '0.01714631']], 'time': '2021-05-20T03:54:41.401489Z'}
{'type': 'l2update', 'product_id': 'BTC-USD', 'changes': [['sell', '38290.49', '0.05551206']], 'time': '2021-05-20T03:54:41.401591Z'}
{'type': 'l2update', 'product_id': 'BTC-USD', 'changes': [['sell', '38413.85', '0.00000000']], 'time': '2021-05-20T03:54:41.401779Z'}
{'type': 'l2update', 'product_id': 'BTC-USD', 'changes': [['sell', '48224.13', '0.00216500']], 'time': '2021-05-20T03:54:41.404946Z'}
{'type': 'l2update', 'product_id': 'BTC-USD', 'changes': [['buy', '37654.91', '0.00000000']], 'time': '2021-05-20T03:54:41.412994Z'}
{'type': 'l2update', 'product_id': 'BTC-USD', 'changes': [['sell', '38306.00', '0.00000000']], 'time': '2021-05-20T03:54:41.413140Z'}
{'type': 'l2update', 'product_id': 'BTC-USD', 'changes': [['buy', '38242.98', '0.00000000']], 'time': '2021-05-20T03:54:41.413813Z'}
{'type': 'l2update', 'product_id': 'BTC-USD', 'changes': [['sell', '38290.81', '5.26885193']], 'time': '2021-05-20T03:54:41.417512Z'}
{'type': 'l2update', 'product_id': 'BTC-USD', 'changes': [['buy', '37500.01', '0.13350000']], 'time': '2021-05-20T03:54:41.418752Z'}
{'type': 'l2update', 'product_id': 'BTC-USD', 'changes': [['buy', '38274.26', '0.00000000']], 'time': '2021-05-20T03:54:41.428949Z'}
{'type': 'l2update', 'product_id': 'BTC-USD', 'changes': [['buy', '38184.59', '0.03247522']], 'time': '2021-05-20T03:54:41.429253Z'}
{'type': 'l2update', 'product_id': 'BTC-USD', 'changes': [['sell', '38282.04', '0.00000000']], 'time': '2021-05-20T03:54:41.429409Z'}
{'type': 'l2update', 'product_id': 'BTC-USD', 'changes': [['sell', '38290.14', '0.00000000']], 'time': '2021-05-20T03:54:41.430258Z'}
{'type': 'l2update', 'product_id': 'BTC-USD', 'changes': [['sell', '38305.99', '0.05000000']], 'time': '2021-05-20T03:54:41.434734Z'}
{'type': 'l2update', 'product_id': 'BTC-USD', 'changes': [['buy', '38189.83', '0.00000000']], 'time': '2021-05-20T03:54:41.437430Z'}
{'type': 'l2update', 'product_id': 'BTC-USD', 'changes': [['buy', '38190.83', '0.03446521']], 'time': '2021-05-20T03:54:41.437430Z'}
{'type': 'l2update', 'product_id': 'BTC-USD', 'changes': [['buy', '38221.55', '0.10000000']], 'time': '2021-05-20T03:54:41.437952Z'}
{'type': 'l2update', 'product_id': 'BTC-USD', 'changes': [['buy', '38259.17', '0.84800000']], 'time': '2021-05-20T03:54:41.438373Z'}
{'type': 'l2update', 'product_id': 'BTC-USD', 'changes': [['sell', '38290.81', '5.06885193']], 'time': '2021-05-20T03:54:41.438782Z'}
{'type': 'l2update', 'product_id': 'BTC-USD', 'changes': [['sell', '38290.49', '0.00529573']], 'time': '2021-05-20T03:54:41.443244Z'}
{'type': 'l2update', 'product_id': 'BTC-USD', 'changes': [['sell', '38290.49', '0.00000000']], 'time': '2021-05-20T03:54:41.443828Z'}
{'type': 'l2update', 'product_id': 'BTC-USD', 'changes': [['buy', '38274.50', '0.00000000']], 'time': '2021-05-20T03:54:41.444186Z'}
{'type': 'l2update', 'product_id': 'BTC-USD', 'changes': [['sell', '38357.74', '0.17490000']], 'time': '2021-05-20T03:54:41.448371Z'}
{'type': 'l2update', 'product_id': 'BTC-USD', 'changes': [['sell', '38290.81', '3.77569908']], 'time': '2021-05-20T03:54:41.450220Z'}
{'type': 'l2update', 'product_id': 'BTC-USD', 'changes': [['sell', '38443.76', '0.05202405']], 'time': '2021-05-20T03:54:41.453721Z'}
{'type': 'l2update', 'product_id': 'BTC-USD', 'changes': [['sell', '38392.08', '0.01000000']], 'time': '2021-05-20T03:54:41.453875Z'}
{'type': 'l2update', 'product_id': 'BTC-USD', 'changes': [['buy', '38259.13', '0.58716278']], 'time': '2021-05-20T03:54:41.459651Z'}
{'type': 'l2update', 'product_id': 'BTC-USD', 'changes': [['sell', '38308.94', '0.00000000']], 'time': '2021-05-20T03:54:41.460281Z'}
{'type': 'l2update', 'product_id': 'BTC-USD', 'changes': [['sell', '38417.38', '0.00000000']], 'time': '2021-05-20T03:54:41.465367Z'}
{'type': 'l2update', 'product_id': 'BTC-USD', 'changes': [['buy', '38255.99', '0.00000000']], 'time': '2021-05-20T03:54:41.465466Z'}
{'type': 'l2update', 'product_id': 'BTC-USD', 'changes': [['buy', '38255.18', '0.00000000']], 'time': '2021-05-20T03:54:41.465466Z'}
{'type': 'l2update', 'product_id': 'BTC-USD', 'changes': [['sell', '38290.09', '0.60700000']], 'time': '2021-05-20T03:54:41.470597Z'}
{'type': 'l2update', 'product_id': 'BTC-USD', 'changes': [['sell', '38305.99', '0.00000000']], 'time': '2021-05-20T03:54:41.471658Z'}
{'type': 'l2update', 'product_id': 'BTC-USD', 'changes': [['buy', '38184.59', '0.00000000']], 'time': '2021-05-20T03:54:41.474789Z'}
{'type': 'l2update', 'product_id': 'BTC-USD', 'changes': [['buy', '38274.92', '0.01492000']], 'time': '2021-05-20T03:54:41.475655Z'}
{'type': 'l2update', 'product_id': 'BTC-USD', 'changes': [['sell', '38282.04', '0.02590000']], 'time': '2021-05-20T03:54:41.475996Z'}
{'type': 'l2update', 'product_id': 'BTC-USD', 'changes': [['sell', '38380.53', '0.29485155']], 'time': '2021-05-20T03:54:41.476682Z'}
{'type': 'l2update', 'product_id': 'BTC-USD', 'changes': [['sell', '38373.40', '0.34666974']], 'time': '2021-05-20T03:54:41.476682Z'}
{'type': 'l2update', 'product_id': 'BTC-USD', 'changes': [['sell', '38367.89', '0.35659020']], 'time': '2021-05-20T03:54:41.476682Z'}
{'type': 'l2update', 'product_id': 'BTC-USD', 'changes': [['sell', '38357.44', '0.31216597']], 'time': '2021-05-20T03:54:41.476682Z'}
{'type': 'l2update', 'product_id': 'BTC-USD', 'changes': [['sell', '38352.50', '0.36887870']], 'time': '2021-05-20T03:54:41.476682Z'}
{'type': 'l2update', 'product_id': 'BTC-USD', 'changes': [['buy', '38119.97', '0.29485155']], 'time': '2021-05-20T03:54:41.476682Z'}
{'type': 'l2update', 'product_id': 'BTC-USD', 'changes': [['sell', '38290.81', '3.67569908']], 'time': '2021-05-20T03:54:41.479452Z'}
{'type': 'l2update', 'product_id': 'BTC-USD', 'changes': [['buy', '38273.39', '0.05745369']], 'time': '2021-05-20T03:54:41.488428Z'}
{'type': 'l2update', 'product_id': 'BTC-USD', 'changes': [['sell', '38393.04', '0.00000000']], 'time': '2021-05-20T03:54:41.490677Z'}
{'type': 'l2update', 'product_id': 'BTC-USD', 'changes': [['buy', '38240.51', '0.02726324']], 'time': '2021-05-20T03:54:41.491883Z'}
{'type': 'l2update', 'product_id': 'BTC-USD', 'changes': [['buy', '38273.39', '0.07460000']], 'time': '2021-05-20T03:54:41.492124Z'}
{'type': 'l2update', 'product_id': 'BTC-USD', 'changes': [['buy', '38242.90', '0.00000000']], 'time': '2021-05-20T03:54:41.498793Z'}
{'type': 'l2update', 'product_id': 'BTC-USD', 'changes': [['sell', '38393.57', '0.00000000']], 'time': '2021-05-20T03:54:41.498844Z'}
{'type': 'l2update', 'product_id': 'BTC-USD', 'changes': [['sell', '38319.83', '0.00000000']], 'time': '2021-05-20T03:54:41.498914Z'}
{'type': 'l2update', 'product_id': 'BTC-USD', 'changes': [['sell', '38282.04', '0.03163000']], 'time': '2021-05-20T03:54:41.502079Z'}
{'type': 'l2update', 'product_id': 'BTC-USD', 'changes': [['sell', '38393.92', '0.00000000']], 'time': '2021-05-20T03:54:41.502125Z'}
{'type': 'l2update', 'product_id': 'BTC-USD', 'changes': [['buy', '37427.02', '0.06475771']], 'time': '2021-05-20T03:54:41.506257Z'}
{'type': 'l2update', 'product_id': 'BTC-USD', 'changes': [['buy', '38274.92', '0.00000000']], 'time': '2021-05-20T03:54:41.511186Z'}
{'type': 'l2update', 'product_id': 'BTC-USD', 'changes': [['sell', '38421.56', '0.00000000']], 'time': '2021-05-20T03:54:41.511723Z'}
{'type': 'l2update', 'product_id': 'BTC-USD', 'changes': [['sell', '38282.04', '0.00573000']], 'time': '2021-05-20T03:54:41.512248Z'}
{'type': 'l2update', 'product_id': 'BTC-USD', 'changes': [['sell', '38308.93', '0.05000000']], 'time': '2021-05-20T03:54:41.514961Z'}
{'type': 'l2update', 'product_id': 'BTC-USD', 'changes': [['sell', '38439.00', '0.00000000']], 'time': '2021-05-20T03:54:41.515160Z'}
{'type': 'l2update', 'product_id': 'BTC-USD', 'changes': [['sell', '38438.27', '0.00000000']], 'time': '2021-05-20T03:54:41.515160Z'}
{'type': 'l2update', 'product_id': 'BTC-USD', 'changes': [['sell', '38421.12', '0.36887870']], 'time': '2021-05-20T03:54:41.515160Z'}
{'type': 'l2update', 'product_id': 'BTC-USD', 'changes': [['sell', '38421.12', '0.00000000']], 'time': '2021-05-20T03:54:41.515160Z'}
{'type': 'l2update', 'product_id': 'BTC-USD', 'changes': [['buy', '38200.05', '0.00000000']], 'time': '2021-05-20T03:54:41.515160Z'}
{'type': 'l2update', 'product_id': 'BTC-USD', 'changes': [['sell', '38493.91', '0.00000000']], 'time': '2021-05-20T03:54:41.516429Z'}
{'type': 'l2update', 'product_id': 'BTC-USD', 'changes': [['sell', '38396.69', '0.00000000']], 'time': '2021-05-20T03:54:41.516670Z'}
{'type': 'l2update', 'product_id': 'BTC-USD', 'changes': [['buy', '37999.91', '0.00000000']], 'time': '2021-05-20T03:54:41.516925Z'}
{'type': 'l2update', 'product_id': 'BTC-USD', 'changes': [['sell', '38396.49', '0.00000000']], 'time': '2021-05-20T03:54:41.516946Z'}
{'type': 'l2update', 'product_id': 'BTC-USD', 'changes': [['buy', '38246.12', '0.02400000']], 'time': '2021-05-20T03:54:41.517476Z'}
{'type': 'l2update', 'product_id': 'BTC-USD', 'changes': [['buy', '38245.32', '0.02400000']], 'time': '2021-05-20T03:54:41.517476Z'}
{'type': 'l2update', 'product_id': 'BTC-USD', 'changes': [['buy', '38244.51', '0.02400000']], 'time': '2021-05-20T03:54:41.517476Z'}
{'type': 'l2update', 'product_id': 'BTC-USD', 'changes': [['sell', '38388.49', '0.05884056']], 'time': '2021-05-20T03:54:41.517518Z'}
{'type': 'l2update', 'product_id': 'BTC-USD', 'changes': [['sell', '38289.95', '0.01492000']], 'time': '2021-05-20T03:54:41.517735Z'}
{'type': 'l2update', 'product_id': 'BTC-USD', 'changes': [['sell', '38410.52', '0.00000000']], 'time': '2021-05-20T03:54:41.521814Z'}
{'type': 'l2update', 'product_id': 'BTC-USD', 'changes': [['sell', '38282.04', '0.20573000']], 'time': '2021-05-20T03:54:41.527756Z'}
{'type': 'l2update', 'product_id': 'BTC-USD', 'changes': [['sell', '38295.56', '0.20900000']], 'time': '2021-05-20T03:54:41.528463Z'}
{'type': 'l2update', 'product_id': 'BTC-USD', 'changes': [['buy', '38269.24', '0.00000000']], 'time': '2021-05-20T03:54:41.530382Z'}
{'type': 'l2update', 'product_id': 'BTC-USD', 'changes': [['sell', '38309.82', '0.00000000']], 'time': '2021-05-20T03:54:41.530382Z'}
{'type': 'l2update', 'product_id': 'BTC-USD', 'changes': [['sell', '38336.79', '0.00000000']], 'time': '2021-05-20T03:54:41.531835Z'}
{'type': 'l2update', 'product_id': 'BTC-USD', 'changes': [['sell', '38289.82', '0.01908794']], 'time': '2021-05-20T03:54:41.533796Z'}
{'type': 'l2update', 'product_id': 'BTC-USD', 'changes': [['sell', '38379.80', '0.01000000']], 'time': '2021-05-20T03:54:41.534118Z'}
{'type': 'l2update', 'product_id': 'BTC-USD', 'changes': [['sell', '38282.04', '0.20061156']], 'time': '2021-05-20T03:54:41.539500Z'}
{'type': 'l2update', 'product_id': 'BTC-USD', 'changes': [['sell', '38289.82', '0.07460000']], 'time': '2021-05-20T03:54:41.541448Z'}
{'type': 'l2update', 'product_id': 'BTC-USD', 'changes': [['sell', '38375.59', '0.03869840']], 'time': '2021-05-20T03:54:41.544810Z'}
{'type': 'l2update', 'product_id': 'BTC-USD', 'changes': [['sell', '40000.00', '47.58836055']], 'time': '2021-05-20T03:54:41.545306Z'}
{'type': 'l2update', 'product_id': 'BTC-USD', 'changes': [['buy', '38282.03', '0.02641367']], 'time': '2021-05-20T03:54:41.549174Z'}
{'type': 'l2update', 'product_id': 'BTC-USD', 'changes': [['sell', '38282.04', '0.20000000']], 'time': '2021-05-20T03:54:41.549734Z'}
{'type': 'l2update', 'product_id': 'BTC-USD', 'changes': [['sell', '38282.04', '0.17463846']], 'time': '2021-05-20T03:54:41.549734Z'}
{'type': 'l2update', 'product_id': 'BTC-USD', 'changes': [['sell', '38308.93', '0.00000000']], 'time': '2021-05-20T03:54:41.549871Z'}
{'type': 'l2update', 'product_id': 'BTC-USD', 'changes': [['sell', '38424.35', '0.00000000']], 'time': '2021-05-20T03:54:41.552915Z'}
{'type': 'l2update', 'product_id': 'BTC-USD', 'changes': [['buy', '38190.83', '0.00000000']], 'time': '2021-05-20T03:54:41.552915Z'}
{'type': 'l2update', 'product_id': 'BTC-USD', 'changes': [['sell', '38289.95', '0.00000000']], 'time': '2021-05-20T03:54:41.553241Z'}
{'type': 'l2update', 'product_id': 'BTC-USD', 'changes': [['buy', '38259.17', '0.00000000']], 'time': '2021-05-20T03:54:41.555702Z'}
{'type': 'l2update', 'product_id': 'BTC-USD', 'changes': [['sell', '38290.81', '3.02569908']], 'time': '2021-05-20T03:54:41.556834Z'}
{'type': 'l2update', 'product_id': 'BTC-USD', 'changes': [['sell', '38421.38', '0.01000000']], 'time': '2021-05-20T03:54:41.557505Z'}
{'type': 'l2update', 'product_id': 'BTC-USD', 'changes': [['sell', '38282.04', '0.17402752']], 'time': '2021-05-20T03:54:41.557845Z'}
{'type': 'l2update', 'product_id': 'BTC-USD', 'changes': [['sell', '38434.65', '0.01000000']], 'time': '2021-05-20T03:54:41.561260Z'}
{'type': 'l2update', 'product_id': 'BTC-USD', 'changes': [['buy', '38236.76', '0.05452904']], 'time': '2021-05-20T03:54:41.561299Z'}
{'type': 'l2update', 'product_id': 'BTC-USD', 'changes': [['sell', '38396.74', '0.02240502']], 'time': '2021-05-20T03:54:41.561563Z'}
{'type': 'l2update', 'product_id': 'BTC-USD', 'changes': [['buy', '37980.59', '0.04431450']], 'time': '2021-05-20T03:54:41.561679Z'}
{'type': 'l2update', 'product_id': 'BTC-USD', 'changes': [['sell', '38367.95', '0.01303171']], 'time': '2021-05-20T03:54:41.561780Z'}
{'type': 'l2update', 'product_id': 'BTC-USD', 'changes': [['sell', '38391.07', '0.40024969']], 'time': '2021-05-20T03:54:41.561959Z'}
{'type': 'l2update', 'product_id': 'BTC-USD', 'changes': [['sell', '38475.01', '0.01113000']], 'time': '2021-05-20T03:54:41.561987Z'}
{'type': 'l2update', 'product_id': 'BTC-USD', 'changes': [['buy', '38248.73', '0.00000000']], 'time': '2021-05-20T03:54:41.564013Z'}
{'type': 'l2update', 'product_id': 'BTC-USD', 'changes': [['sell', '38289.82', '0.05551206']], 'time': '2021-05-20T03:54:41.567193Z'}
{'type': 'l2update', 'product_id': 'BTC-USD', 'changes': [['sell', '38282.04', '0.27402752']], 'time': '2021-05-20T03:54:41.568553Z'}
{'type': 'l2update', 'product_id': 'BTC-USD', 'changes': [['sell', '38430.84', '0.01000000']], 'time': '2021-05-20T03:54:41.568746Z'}
{'type': 'l2update', 'product_id': 'BTC-USD', 'changes': [['sell', '38291.81', '0.10000000']], 'time': '2021-05-20T03:54:41.569065Z'}
{'type': 'l2update', 'product_id': 'BTC-USD', 'changes': [['sell', '38313.16', '0.00000000']], 'time': '2021-05-20T03:54:41.573371Z'}
{'type': 'l2update', 'product_id': 'BTC-USD', 'changes': [['buy', '38273.90', '0.01492000']], 'time': '2021-05-20T03:54:41.574646Z'}
{'type': 'l2update', 'product_id': 'BTC-USD', 'changes': [['sell', '38289.82', '0.00000000']], 'time': '2021-05-20T03:54:41.575476Z'}
{'type': 'l2update', 'product_id': 'BTC-USD', 'changes': [['buy', '38273.39', '0.01714631']], 'time': '2021-05-20T03:54:41.575796Z'}
{'type': 'l2update', 'product_id': 'BTC-USD', 'changes': [['sell', '38290.81', '2.98969908']], 'time': '2021-05-20T03:54:41.582655Z'}
{'type': 'l2update', 'product_id': 'BTC-USD', 'changes': [['sell', '38313.15', '0.05000000']], 'time': '2021-05-20T03:54:41.591269Z'}
{'type': 'l2update', 'product_id': 'BTC-USD', 'changes': [['buy', '38265.33', '0.04424868']], 'time': '2021-05-20T03:54:41.591522Z'}
{'type': 'l2update', 'product_id': 'BTC-USD', 'changes': [['buy', '38157.73', '0.02741397']], 'time': '2021-05-20T03:54:41.591590Z'}
{'type': 'l2update', 'product_id': 'BTC-USD', 'changes': [['sell', '38296.07', '0.05173776']], 'time': '2021-05-20T03:54:41.591745Z'}
{'type': 'l2update', 'product_id': 'BTC-USD', 'changes': [['buy', '38278.29', '0.04932890']], 'time': '2021-05-20T03:54:41.592366Z'}
{'type': 'l2update', 'product_id': 'BTC-USD', 'changes': [['sell', '38297.38', '0.00000000']], 'time': '2021-05-20T03:54:41.595039Z'}
{'type': 'l2update', 'product_id': 'BTC-USD', 'changes': [['buy', '38209.23', '0.00000000']], 'time': '2021-05-20T03:54:41.595303Z'}
{'type': 'l2update', 'product_id': 'BTC-USD', 'changes': [['buy', '38272.94', '0.00000000']], 'time': '2021-05-20T03:54:41.595485Z'}
{'type': 'l2update', 'product_id': 'BTC-USD', 'changes': [['sell', '38290.80', '0.00000000']], 'time': '2021-05-20T03:54:41.599239Z'}
{'type': 'l2update', 'product_id': 'BTC-USD', 'changes': [['buy', '38178.56', '0.00000000']], 'time': '2021-05-20T03:54:41.600401Z'}
{'type': 'l2update', 'product_id': 'BTC-USD', 'changes': [['sell', '38282.04', '0.10000000']], 'time': '2021-05-20T03:54:41.603498Z'}
{'type': 'l2update', 'product_id': 'BTC-USD', 'changes': [['sell', '38282.04', '0.00000000']], 'time': '2021-05-20T03:54:41.603498Z'}
{'type': 'l2update', 'product_id': 'BTC-USD', 'changes': [['buy', '38282.04', '0.05170000']], 'time': '2021-05-20T03:54:41.603498Z'}
{'type': 'l2update', 'product_id': 'BTC-USD', 'changes': [['sell', '38397.34', '0.40649555']], 'time': '2021-05-20T03:54:41.603520Z'}
{'type': 'l2update', 'product_id': 'BTC-USD', 'changes': [['sell', '38320.97', '0.04830540']], 'time': '2021-05-20T03:54:41.604476Z'}
{'type': 'l2update', 'product_id': 'BTC-USD', 'changes': [['buy', '38258.59', '0.42280000']], 'time': '2021-05-20T03:54:41.604967Z'}
{'type': 'l2update', 'product_id': 'BTC-USD', 'changes': [['sell', '48231.03', '0.00216500']], 'time': '2021-05-20T03:54:41.605193Z'}
{'type': 'l2update', 'product_id': 'BTC-USD', 'changes': [['buy', '38207.44', '0.02400000']], 'time': '2021-05-20T03:54:41.605436Z'}
{'type': 'l2update', 'product_id': 'BTC-USD', 'changes': [['sell', '38290.09', '0.00000000']], 'time': '2021-05-20T03:54:41.605799Z'}
{'type': 'l2update', 'product_id': 'BTC-USD', 'changes': [['buy', '38273.90', '0.00000000']], 'time': '2021-05-20T03:54:41.606359Z'}
{'type': 'l2update', 'product_id': 'BTC-USD', 'changes': [['buy', '38273.39', '0.00000000']], 'time': '2021-05-20T03:54:41.609079Z'}
{'type': 'l2update', 'product_id': 'BTC-USD', 'changes': [['sell', '38287.24', '0.52260670']], 'time': '2021-05-20T03:54:41.613547Z'}
{'type': 'l2update', 'product_id': 'BTC-USD', 'changes': [['buy', '38272.99', '0.84800000']], 'time': '2021-05-20T03:54:41.614029Z'}
{'type': 'l2update', 'product_id': 'BTC-USD', 'changes': [['sell', '38328.02', '0.03207306']], 'time': '2021-05-20T03:54:41.619521Z'}
{'type': 'l2update', 'product_id': 'BTC-USD', 'changes': [['sell', '38290.81', '0.50000000']], 'time': '2021-05-20T03:54:41.628462Z'}
{'type': 'l2update', 'product_id': 'BTC-USD', 'changes': [['buy', '38260.80', '0.38000000']], 'time': '2021-05-20T03:54:41.634279Z'}
{'type': 'l2update', 'product_id': 'BTC-USD', 'changes': [['buy', '38282.03', '0.22641367']], 'time': '2021-05-20T03:54:41.634662Z'}
{'type': 'l2update', 'product_id': 'BTC-USD', 'changes': [['buy', '38220.47', '0.03790952']], 'time': '2021-05-20T03:54:41.635172Z'}
{'type': 'l2update', 'product_id': 'BTC-USD', 'changes': [['sell', '38296.07', '0.00000000']], 'time': '2021-05-20T03:54:41.641031Z'}
{'type': 'l2update', 'product_id': 'BTC-USD', 'changes': [['sell', '38388.50', '0.34949601']], 'time': '2021-05-20T03:54:41.641097Z'}
{'type': 'l2update', 'product_id': 'BTC-USD', 'changes': [['buy', '38282.29', '0.05745369']], 'time': '2021-05-20T03:54:41.641684Z'}
{'type': 'l2update', 'product_id': 'BTC-USD', 'changes': [['sell', '38313.15', '0.00000000']], 'time': '2021-05-20T03:54:41.643364Z'}
{'type': 'l2update', 'product_id': 'BTC-USD', 'changes': [['buy', '38272.99', '0.00000000']], 'time': '2021-05-20T03:54:41.644533Z'}
{'type': 'l2update', 'product_id': 'BTC-USD', 'changes': [['buy', '38282.39', '0.05122424']], 'time': '2021-05-20T03:54:41.649386Z'}
{'type': 'l2update', 'product_id': 'BTC-USD', 'changes': [['buy', '38282.39', '0.04394400']], 'time': '2021-05-20T03:54:41.650666Z'}
{'type': 'l2update', 'product_id': 'BTC-USD', 'changes': [['sell', '38342.33', '2.16932808']], 'time': '2021-05-20T03:54:41.650786Z'}
{'type': 'l2update', 'product_id': 'BTC-USD', 'changes': [['sell', '38319.14', '0.46830000']], 'time': '2021-05-20T03:54:41.651381Z'}
{'type': 'l2update', 'product_id': 'BTC-USD', 'changes': [['sell', '38290.81', '0.00000000']], 'time': '2021-05-20T03:54:41.653542Z'}
{'type': 'l2update', 'product_id': 'BTC-USD', 'changes': [['buy', '38265.04', '0.78359258']], 'time': '2021-05-20T03:54:41.655055Z'}
{'type': 'l2update', 'product_id': 'BTC-USD', 'changes': [['sell', '38421.38', '0.00000000']], 'time': '2021-05-20T03:54:41.655882Z'}
{'type': 'l2update', 'product_id': 'BTC-USD', 'changes': [['sell', '38295.56', '0.00000000']], 'time': '2021-05-20T03:54:41.656130Z'}
{'type': 'l2update', 'product_id': 'BTC-USD', 'changes': [['sell', '38434.65', '0.00000000']], 'time': '2021-05-20T03:54:41.664117Z'}
{'type': 'l2update', 'product_id': 'BTC-USD', 'changes': [['buy', '38253.83', '0.39490431']], 'time': '2021-05-20T03:54:41.665682Z'}
{'type': 'l2update', 'product_id': 'BTC-USD', 'changes': [['sell', '38314.26', '0.05038142']], 'time': '2021-05-20T03:54:41.666248Z'}
{'type': 'l2update', 'product_id': 'BTC-USD', 'changes': [['buy', '38116.53', '0.05127848']], 'time': '2021-05-20T03:54:41.666840Z'}
{'type': 'l2update', 'product_id': 'BTC-USD', 'changes': [['buy', '38196.88', '0.00000000']], 'time': '2021-05-20T03:54:41.667398Z'}
{'type': 'l2update', 'product_id': 'BTC-USD', 'changes': [['buy', '38203.87', '0.01000000']], 'time': '2021-05-20T03:54:41.672464Z'}
{'type': 'l2update', 'product_id': 'BTC-USD', 'changes': [['buy', '38282.03', '0.32641367']], 'time': '2021-05-20T03:54:41.672577Z'}
{'type': 'l2update', 'product_id': 'BTC-USD', 'changes': [['buy', '38282.29', '0.00000000']], 'time': '2021-05-20T03:54:41.673662Z'}
{'type': 'l2update', 'product_id': 'BTC-USD', 'changes': [['buy', '38235.74', '0.12268632']], 'time': '2021-05-20T03:54:41.678926Z'}
{'type': 'l2update', 'product_id': 'BTC-USD', 'changes': [['sell', '38394.96', '0.32159753']], 'time': '2021-05-20T03:54:41.679100Z'}
{'type': 'l2update', 'product_id': 'BTC-USD', 'changes': [['buy', '38287.23', '0.00573000']], 'time': '2021-05-20T03:54:41.683770Z'}
{'type': 'l2update', 'product_id': 'BTC-USD', 'changes': [['sell', '38310.49', '2.48969908']], 'time': '2021-05-20T03:54:41.683874Z'}
{'type': 'l2update', 'product_id': 'BTC-USD', 'changes': [['buy', '38287.23', '0.02287631']], 'time': '2021-05-20T03:54:41.684292Z'}
{'type': 'l2update', 'product_id': 'BTC-USD', 'changes': [['sell', '38338.45', '0.05000000']], 'time': '2021-05-20T03:54:41.684448Z'}
{'type': 'l2update', 'product_id': 'BTC-USD', 'changes': [['buy', '38287.23', '0.03779631']], 'time': '2021-05-20T03:54:41.684599Z'}
{'type': 'l2update', 'product_id': 'BTC-USD', 'changes': [['sell', '38319.14', '0.00000000']], 'time': '2021-05-20T03:54:41.685111Z'}
{'type': 'l2update', 'product_id': 'BTC-USD', 'changes': [['buy', '38278.29', '0.00000000']], 'time': '2021-05-20T03:54:41.688330Z'}
{'type': 'l2update', 'product_id': 'BTC-USD', 'changes': [['sell', '38379.54', '0.06042264']], 'time': '2021-05-20T03:54:41.688494Z'}
{'type': 'l2update', 'product_id': 'BTC-USD', 'changes': [['buy', '38152.28', '0.00000000']], 'time': '2021-05-20T03:54:41.692823Z'}
{'type': 'l2update', 'product_id': 'BTC-USD', 'changes': [['sell', '38326.28', '0.01000000']], 'time': '2021-05-20T03:54:41.694973Z'}
{'type': 'l2update', 'product_id': 'BTC-USD', 'changes': [['sell', '38291.05', '0.52255516']], 'time': '2021-05-20T03:54:41.696328Z'}
{'type': 'l2update', 'product_id': 'BTC-USD', 'changes': [['sell', '38301.69', '0.04867655']], 'time': '2021-05-20T03:54:41.696839Z'}
{'type': 'l2update', 'product_id': 'BTC-USD', 'changes': [['sell', '38388.81', '0.01000000']], 'time': '2021-05-20T03:54:41.700470Z'}
{'type': 'l2update', 'product_id': 'BTC-USD', 'changes': [['sell', '38310.49', '2.98969908']], 'time': '2021-05-20T03:54:41.700772Z'}
{'type': 'l2update', 'product_id': 'BTC-USD', 'changes': [['sell', '38446.22', '0.00000000']], 'time': '2021-05-20T03:54:41.705915Z'}
{'type': 'l2update', 'product_id': 'BTC-USD', 'changes': [['sell', '38423.06', '0.00000000']], 'time': '2021-05-20T03:54:41.708488Z'}
{'type': 'l2update', 'product_id': 'BTC-USD', 'changes': [['buy', '38213.65', '0.00000000']], 'time': '2021-05-20T03:54:41.711959Z'}
{'type': 'l2update', 'product_id': 'BTC-USD', 'changes': [['buy', '38282.03', '0.30051367']], 'time': '2021-05-20T03:54:41.712852Z'}
{'type': 'l2update', 'product_id': 'BTC-USD', 'changes': [['sell', '38338.45', '0.00000000']], 'time': '2021-05-20T03:54:41.713242Z'}
{'type': 'l2update', 'product_id': 'BTC-USD', 'changes': [['buy', '38287.23', '0.08339942']], 'time': '2021-05-20T03:54:41.713863Z'}
{'type': 'l2update', 'product_id': 'BTC-USD', 'changes': [['sell', '38370.26', '0.02906498']], 'time': '2021-05-20T03:54:41.714018Z'}
{'type': 'l2update', 'product_id': 'BTC-USD', 'changes': [['sell', '38359.05', '0.03094555']], 'time': '2021-05-20T03:54:41.714018Z'}
{'type': 'l2update', 'product_id': 'BTC-USD', 'changes': [['sell', '38348.60', '0.03118555']], 'time': '2021-05-20T03:54:41.714018Z'}
{'type': 'l2update', 'product_id': 'BTC-USD', 'changes': [['sell', '38343.66', '0.02801768']], 'time': '2021-05-20T03:54:41.714018Z'}
{'type': 'l2update', 'product_id': 'BTC-USD', 'changes': [['sell', '38334.37', '0.01435833']], 'time': '2021-05-20T03:54:41.714018Z'}
{'type': 'l2update', 'product_id': 'BTC-USD', 'changes': [['sell', '38325.84', '0.03249665']], 'time': '2021-05-20T03:54:41.714018Z'}
{'type': 'l2update', 'product_id': 'BTC-USD', 'changes': [['sell', '38321.86', '0.02864963']], 'time': '2021-05-20T03:54:41.714018Z'}
{'type': 'l2update', 'product_id': 'BTC-USD', 'changes': [['buy', '38258.59', '0.00000000']], 'time': '2021-05-20T03:54:41.715880Z'}
{'type': 'l2update', 'product_id': 'BTC-USD', 'changes': [['sell', '38401.61', '0.38007214']], 'time': '2021-05-20T03:54:41.719308Z'}
{'type': 'l2update', 'product_id': 'BTC-USD', 'changes': [['buy', '38141.83', '0.38007214']], 'time': '2021-05-20T03:54:41.719308Z'}
{'type': 'l2update', 'product_id': 'BTC-USD', 'changes': [['buy', '38175.84', '0.34113860']], 'time': '2021-05-20T03:54:41.719308Z'}
{'type': 'l2update', 'product_id': 'BTC-USD', 'changes': [['buy', '38256.82', '0.04335674']], 'time': '2021-05-20T03:54:41.720732Z'}
{'type': 'l2update', 'product_id': 'BTC-USD', 'changes': [['sell', '38297.39', '0.04624309']], 'time': '2021-05-20T03:54:41.720732Z'}
{'type': 'l2update', 'product_id': 'BTC-USD', 'changes': [['buy', '38287.23', '0.10929942']], 'time': '2021-05-20T03:54:41.720857Z'}
{'type': 'l2update', 'product_id': 'BTC-USD', 'changes': [['sell', '38419.91', '0.00000000']], 'time': '2021-05-20T03:54:41.728999Z'}
{'type': 'l2update', 'product_id': 'BTC-USD', 'changes': [['sell', '38452.36', '0.03035330']], 'time': '2021-05-20T03:54:41.731915Z'}
{'type': 'l2update', 'product_id': 'BTC-USD', 'changes': [['buy', '38262.87', '0.52258943']], 'time': '2021-05-20T03:54:41.731942Z'}
{'type': 'l2update', 'product_id': 'BTC-USD', 'changes': [['buy', '38093.15', '0.04688388']], 'time': '2021-05-20T03:54:41.732447Z'}
{'type': 'l2update', 'product_id': 'BTC-USD', 'changes': [['buy', '38180.80', '0.01000000']], 'time': '2021-05-20T03:54:41.732798Z'}
{'type': 'l2update', 'product_id': 'BTC-USD', 'changes': [['buy', '38243.96', '0.01000000']], 'time': '2021-05-20T03:54:41.732939Z'}
{'type': 'l2update', 'product_id': 'BTC-USD', 'changes': [['buy', '38282.03', '0.10051367']], 'time': '2021-05-20T03:54:41.732953Z'}
{'type': 'l2update', 'product_id': 'BTC-USD', 'changes': [['buy', '38207.44', '0.00000000']], 'time': '2021-05-20T03:54:41.737317Z'}
{'type': 'l2update', 'product_id': 'BTC-USD', 'changes': [['sell', '38443.76', '0.00000000']], 'time': '2021-05-20T03:54:41.737707Z'}
{'type': 'l2update', 'product_id': 'BTC-USD', 'changes': [['sell', '38431.15', '0.01000000']], 'time': '2021-05-20T03:54:41.740103Z'}
{'type': 'l2update', 'product_id': 'BTC-USD', 'changes': [['sell', '38399.45', '0.00000000']], 'time': '2021-05-20T03:54:41.741117Z'}
{'type': 'l2update', 'product_id': 'BTC-USD', 'changes': [['sell', '38392.80', '0.00000000']], 'time': '2021-05-20T03:54:41.741117Z'}
{'type': 'l2update', 'product_id': 'BTC-USD', 'changes': [['sell', '38388.49', '0.03082288']], 'time': '2021-05-20T03:54:41.741117Z'}
{'type': 'l2update', 'product_id': 'BTC-USD', 'changes': [['sell', '38381.30', '0.03249665']], 'time': '2021-05-20T03:54:41.741117Z'}
{'type': 'l2update', 'product_id': 'BTC-USD', 'changes': [['sell', '38381.30', '0.00000000']], 'time': '2021-05-20T03:54:41.741117Z'}
{'type': 'l2update', 'product_id': 'BTC-USD', 'changes': [['sell', '38376.14', '0.00000000']], 'time': '2021-05-20T03:54:41.741117Z'}
{'type': 'l2update', 'product_id': 'BTC-USD', 'changes': [['buy', '38139.06', '0.70611760']], 'time': '2021-05-20T03:54:41.747199Z'}
{'type': 'l2update', 'product_id': 'BTC-USD', 'changes': [['sell', '38411.38', '0.01000000']], 'time': '2021-05-20T03:54:41.747555Z'}
{'type': 'l2update', 'product_id': 'BTC-USD', 'changes': [['buy', '38190.42', '0.01039493']], 'time': '2021-05-20T03:54:41.747679Z'}
{'type': 'l2update', 'product_id': 'BTC-USD', 'changes': [['sell', '38319.13', '0.05000000']], 'time': '2021-05-20T03:54:41.747855Z'}
{'type': 'l2update', 'product_id': 'BTC-USD', 'changes': [['buy', '38268.81', '0.84700000']], 'time': '2021-05-20T03:54:41.750317Z'}
{'type': 'l2update', 'product_id': 'BTC-USD', 'changes': [['buy', '38287.23', '0.08339942']], 'time': '2021-05-20T03:54:41.751787Z'}
{'type': 'l2update', 'product_id': 'BTC-USD', 'changes': [['sell', '38321.30', '0.00000000']], 'time': '2021-05-20T03:54:41.754111Z'}
{'type': 'l2update', 'product_id': 'BTC-USD', 'changes': [['buy', '38282.03', '0.00051367']], 'time': '2021-05-20T03:54:41.763593Z'}
{'type': 'l2update', 'product_id': 'BTC-USD', 'changes': [['sell', '38326.28', '0.00000000']], 'time': '2021-05-20T03:54:41.764859Z'}
{'type': 'l2update', 'product_id': 'BTC-USD', 'changes': [['sell', '38342.33', '0.00000000']], 'time': '2021-05-20T03:54:41.768117Z'}
{'type': 'l2update', 'product_id': 'BTC-USD', 'changes': [['sell', '38295.88', '0.52258943']], 'time': '2021-05-20T03:54:41.770365Z'}
{'type': 'l2update', 'product_id': 'BTC-USD', 'changes': [['sell', '38319.13', '0.00000000']], 'time': '2021-05-20T03:54:41.774295Z'}
{'type': 'l2update', 'product_id': 'BTC-USD', 'changes': [['sell', '38404.80', '0.01000000']], 'time': '2021-05-20T03:54:41.775142Z'}
{'type': 'l2update', 'product_id': 'BTC-USD', 'changes': [['buy', '37427.02', '0.00000000']], 'time': '2021-05-20T03:54:41.779602Z'}
{'type': 'l2update', 'product_id': 'BTC-USD', 'changes': [['buy', '38171.22', '0.03036725']], 'time': '2021-05-20T03:54:41.780411Z'}
{'type': 'l2update', 'product_id': 'BTC-USD', 'changes': [['sell', '38408.45', '0.29703474']], 'time': '2021-05-20T03:54:41.781962Z'}
{'type': 'l2update', 'product_id': 'BTC-USD', 'changes': [['buy', '38216.85', '0.00000000']], 'time': '2021-05-20T03:54:41.788605Z'}
{'type': 'l2update', 'product_id': 'BTC-USD', 'changes': [['sell', '38422.40', '0.00000000']], 'time': '2021-05-20T03:54:41.790885Z'}
{'type': 'l2update', 'product_id': 'BTC-USD', 'changes': [['buy', '38243.96', '0.00000000']], 'time': '2021-05-20T03:54:41.791176Z'}
{'type': 'l2update', 'product_id': 'BTC-USD', 'changes': [['sell', '48234.97', '0.00105200']], 'time': '2021-05-20T03:54:41.796167Z'}
{'type': 'l2update', 'product_id': 'BTC-USD', 'changes': [['sell', '38475.55', '0.00000000']], 'time': '2021-05-20T03:54:41.802130Z'}
{'type': 'l2update', 'product_id': 'BTC-USD', 'changes': [['buy', '38258.62', '0.52259057']], 'time': '2021-05-20T03:54:41.803124Z'}
{'type': 'l2update', 'product_id': 'BTC-USD', 'changes': [['sell', '38325.04', '0.40290000']], 'time': '2021-05-20T03:54:41.803508Z'}
{'type': 'l2update', 'product_id': 'BTC-USD', 'changes': [['sell', '38375.59', '0.00000000']], 'time': '2021-05-20T03:54:41.806009Z'}
{'type': 'l2update', 'product_id': 'BTC-USD', 'changes': [['sell', '38338.45', '0.02608347']], 'time': '2021-05-20T03:54:41.808141Z'}
{'type': 'l2update', 'product_id': 'BTC-USD', 'changes': [['sell', '38310.48', '0.05000000']], 'time': '2021-05-20T03:54:41.808159Z'}
{'type': 'l2update', 'product_id': 'BTC-USD', 'changes': [['buy', '38190.42', '0.00000000']], 'time': '2021-05-20T03:54:41.808409Z'}
{'type': 'l2update', 'product_id': 'BTC-USD', 'changes': [['sell', '38421.64', '0.01000000']], 'time': '2021-05-20T03:54:41.817703Z'}
{'type': 'l2update', 'product_id': 'BTC-USD', 'changes': [['buy', '38164.74', '0.10605314']], 'time': '2021-05-20T03:54:41.818332Z'}
{'type': 'l2update', 'product_id': 'BTC-USD', 'changes': [['sell', '38415.49', '0.40036422']], 'time': '2021-05-20T03:54:41.818371Z'}
{'type': 'l2update', 'product_id': 'BTC-USD', 'changes': [['sell', '38313.78', '0.00170000']], 'time': '2021-05-20T03:54:41.828778Z'}
{'type': 'l2update', 'product_id': 'BTC-USD', 'changes': [['sell', '38410.71', '0.01000000']], 'time': '2021-05-20T03:54:41.829059Z'}
{'type': 'l2update', 'product_id': 'BTC-USD', 'changes': [['buy', '38259.13', '0.00000000']], 'time': '2021-05-20T03:54:41.831344Z'}
{'type': 'l2update', 'product_id': 'BTC-USD', 'changes': [['sell', '38489.45', '0.01000000']], 'time': '2021-05-20T03:54:41.835370Z'}
{'type': 'l2update', 'product_id': 'BTC-USD', 'changes': [['sell', '38302.55', '0.78391005']], 'time': '2021-05-20T03:54:41.835403Z'}
{'type': 'l2update', 'product_id': 'BTC-USD', 'changes': [['sell', '38401.50', '0.01325800']], 'time': '2021-05-20T03:54:41.837274Z'}
{'type': 'l2update', 'product_id': 'BTC-USD', 'changes': [['buy', '38287.23', '0.15582965']], 'time': '2021-05-20T03:54:41.837348Z'}
{'type': 'l2update', 'product_id': 'BTC-USD', 'changes': [['buy', '38264.05', '0.41110000']], 'time': '2021-05-20T03:54:41.837490Z'}
{'type': 'l2update', 'product_id': 'BTC-USD', 'changes': [['buy', '37980.59', '0.00000000']], 'time': '2021-05-20T03:54:41.840944Z'}
{'type': 'l2update', 'product_id': 'BTC-USD', 'changes': [['buy', '38204.86', '0.01000000']], 'time': '2021-05-20T03:54:41.841507Z'}
{'type': 'l2update', 'product_id': 'BTC-USD', 'changes': [['sell', '38330.01', '0.29485155']], 'time': '2021-05-20T03:54:41.848960Z'}
{'type': 'l2update', 'product_id': 'BTC-USD', 'changes': [['buy', '38169.41', '0.02870732']], 'time': '2021-05-20T03:54:41.853483Z'}
{'type': 'l2update', 'product_id': 'BTC-USD', 'changes': [['buy', '38000.21', '0.00320000']], 'time': '2021-05-20T03:54:41.854059Z'}
{'type': 'l2update', 'product_id': 'BTC-USD', 'changes': [['buy', '38253.60', '0.78383274']], 'time': '2021-05-20T03:54:41.861103Z'}
{'type': 'l2update', 'product_id': 'BTC-USD', 'changes': [['sell', '38297.47', '0.00000000']], 'time': '2021-05-20T03:54:41.863841Z'}
{'type': 'l2update', 'product_id': 'BTC-USD', 'changes': [['sell', '38313.95', '0.00000000']], 'time': '2021-05-20T03:54:41.867563Z'}
{'type': 'l2update', 'product_id': 'BTC-USD', 'changes': [['sell', '38301.64', '1.00400000']], 'time': '2021-05-20T03:54:41.868976Z'}
{'type': 'l2update', 'product_id': 'BTC-USD', 'changes': [['buy', '38270.04', '0.58716278']], 'time': '2021-05-20T03:54:41.869121Z'}
{'type': 'l2update', 'product_id': 'BTC-USD', 'changes': [['buy', '38203.87', '0.00000000']], 'time': '2021-05-20T03:54:41.872932Z'}
{'type': 'l2update', 'product_id': 'BTC-USD', 'changes': [['buy', '37993.47', '0.04553900']], 'time': '2021-05-20T03:54:41.874136Z'}
{'type': 'l2update', 'product_id': 'BTC-USD', 'changes': [['buy', '38256.82', '0.00000000']], 'time': '2021-05-20T03:54:41.877484Z'}
{'type': 'l2update', 'product_id': 'BTC-USD', 'changes': [['sell', '38297.39', '0.00000000']], 'time': '2021-05-20T03:54:41.877484Z'}
{'type': 'l2update', 'product_id': 'BTC-USD', 'changes': [['sell', '38371.72', '0.07700000']], 'time': '2021-05-20T03:54:41.879543Z'}
{'type': 'l2update', 'product_id': 'BTC-USD', 'changes': [['buy', '38253.83', '0.00000000']], 'time': '2021-05-20T03:54:41.884064Z'}
{'type': 'l2update', 'product_id': 'BTC-USD', 'changes': [['buy', '38162.80', '0.03747740']], 'time': '2021-05-20T03:54:41.886501Z'}
{'type': 'l2update', 'product_id': 'BTC-USD', 'changes': [['buy', '38259.14', '0.03969829']], 'time': '2021-05-20T03:54:41.887693Z'}
{'type': 'l2update', 'product_id': 'BTC-USD', 'changes': [['sell', '38330.01', '0.64152129']], 'time': '2021-05-20T03:54:41.887792Z'}
{'type': 'l2update', 'product_id': 'BTC-USD', 'changes': [['sell', '38325.84', '0.38908685']], 'time': '2021-05-20T03:54:41.887792Z'}
{'type': 'l2update', 'product_id': 'BTC-USD', 'changes': [['sell', '38309.88', '1.30651674']], 'time': '2021-05-20T03:54:41.889767Z'}
{'type': 'l2update', 'product_id': 'BTC-USD', 'changes': [['buy', '38186.81', '0.07700000']], 'time': '2021-05-20T03:54:41.889850Z'}
{'type': 'l2update', 'product_id': 'BTC-USD', 'changes': [['sell', '38328.02', '0.00000000']], 'time': '2021-05-20T03:54:41.894328Z'}
{'type': 'l2update', 'product_id': 'BTC-USD', 'changes': [['buy', '38265.33', '0.00000000']], 'time': '2021-05-20T03:54:41.895689Z'}
{'type': 'l2update', 'product_id': 'BTC-USD', 'changes': [['sell', '38489.45', '0.00000000']], 'time': '2021-05-20T03:54:41.897586Z'}
{'type': 'l2update', 'product_id': 'BTC-USD', 'changes': [['buy', '38179.71', '0.01000000']], 'time': '2021-05-20T03:54:41.901563Z'}
{'type': 'l2update', 'product_id': 'BTC-USD', 'changes': [['buy', '38246.34', '0.00000000']], 'time': '2021-05-20T03:54:41.902783Z'}
{'type': 'l2update', 'product_id': 'BTC-USD', 'changes': [['buy', '38287.23', '0.16647097']], 'time': '2021-05-20T03:54:41.909744Z'}
{'type': 'l2update', 'product_id': 'BTC-USD', 'changes': [['buy', '38186.81', '0.00000000']], 'time': '2021-05-20T03:54:41.913317Z'}
{'type': 'l2update', 'product_id': 'BTC-USD', 'changes': [['buy', '38220.47', '0.07165872']], 'time': '2021-05-20T03:54:41.917005Z'}
{'type': 'l2update', 'product_id': 'BTC-USD', 'changes': [['buy', '38230.73', '2.61224515']], 'time': '2021-05-20T03:54:41.922170Z'}
{'type': 'l2update', 'product_id': 'BTC-USD', 'changes': [['sell', '38325.84', '0.70125282']], 'time': '2021-05-20T03:54:41.923275Z'}
{'type': 'l2update', 'product_id': 'BTC-USD', 'changes': [['sell', '38501.95', '0.00000000']], 'time': '2021-05-20T03:54:41.928316Z'}
{'type': 'l2update', 'product_id': 'BTC-USD', 'changes': [['sell', '38360.27', '0.07900000']], 'time': '2021-05-20T03:54:41.931144Z'}
{'type': 'l2update', 'product_id': 'BTC-USD', 'changes': [['sell', '38293.66', '0.00970301']], 'time': '2021-05-20T03:54:41.931448Z'}
{'type': 'l2update', 'product_id': 'BTC-USD', 'changes': [['buy', '38195.43', '0.00000000']], 'time': '2021-05-20T03:54:41.936096Z'}
{'type': 'l2update', 'product_id': 'BTC-USD', 'changes': [['sell', '38310.49', '2.48969908']], 'time': '2021-05-20T03:54:41.943613Z'}
{'type': 'l2update', 'product_id': 'BTC-USD', 'changes': [['sell', '38314.38', '0.05000000']], 'time': '2021-05-20T03:54:41.948371Z'}
{'type': 'l2update', 'product_id': 'BTC-USD', 'changes': [['sell', '38316.34', '2.61312244']], 'time': '2021-05-20T03:54:41.948680Z'}
{'type': 'l2update', 'product_id': 'BTC-USD', 'changes': [['sell', '38301.63', '0.58027753']], 'time': '2021-05-20T03:54:41.949058Z'}
{'type': 'l2update', 'product_id': 'BTC-USD', 'changes': [['sell', '38380.53', '0.00000000']], 'time': '2021-05-20T03:54:41.949074Z'}
{'type': 'l2update', 'product_id': 'BTC-USD', 'changes': [['sell', '38373.40', '0.00000000']], 'time': '2021-05-20T03:54:41.949074Z'}
{'type': 'l2update', 'product_id': 'BTC-USD', 'changes': [['sell', '38367.89', '0.00000000']], 'time': '2021-05-20T03:54:41.949074Z'}
{'type': 'l2update', 'product_id': 'BTC-USD', 'changes': [['sell', '38357.44', '0.00000000']], 'time': '2021-05-20T03:54:41.949074Z'}
{'type': 'l2update', 'product_id': 'BTC-USD', 'changes': [['sell', '38352.50', '0.00000000']], 'time': '2021-05-20T03:54:41.949074Z'}
{'type': 'l2update', 'product_id': 'BTC-USD', 'changes': [['buy', '38282.04', '0.00000000']], 'time': '2021-05-20T03:54:41.955417Z'}
{'type': 'l2update', 'product_id': 'BTC-USD', 'changes': [['sell', '38316.64', '0.14879780']], 'time': '2021-05-20T03:54:41.956116Z'}
{'type': 'l2update', 'product_id': 'BTC-USD', 'changes': [['sell', '38489.45', '0.01000000']], 'time': '2021-05-20T03:54:41.957980Z'}
{'type': 'l2update', 'product_id': 'BTC-USD', 'changes': [['sell', '38451.89', '0.01000000']], 'time': '2021-05-20T03:54:41.958040Z'}
{'type': 'l2update', 'product_id': 'BTC-USD', 'changes': [['buy', '38270.04', '0.00000000']], 'time': '2021-05-20T03:54:41.961059Z'}
{'type': 'l2update', 'product_id': 'BTC-USD', 'changes': [['buy', '38251.21', '1.20000000']], 'time': '2021-05-20T03:54:41.962495Z'}
{'type': 'l2update', 'product_id': 'BTC-USD', 'changes': [['sell', '38325.04', '0.00000000']], 'time': '2021-05-20T03:54:41.963188Z'}
{'type': 'l2update', 'product_id': 'BTC-USD', 'changes': [['buy', '37903.38', '0.35360000']], 'time': '2021-05-20T03:54:41.964041Z'}
{'type': 'l2update', 'product_id': 'BTC-USD', 'changes': [['sell', '48241.36', '0.00216500']], 'time': '2021-05-20T03:54:41.968472Z'}
{'type': 'l2update', 'product_id': 'BTC-USD', 'changes': [['buy', '38125.60', '0.00000000']], 'time': '2021-05-20T03:54:41.969865Z'}
{'type': 'l2update', 'product_id': 'BTC-USD', 'changes': [['sell', '38297.64', '0.04894916']], 'time': '2021-05-20T03:54:41.972684Z'}
{'type': 'l2update', 'product_id': 'BTC-USD', 'changes': [['buy', '38260.83', '0.58230000']], 'time': '2021-05-20T03:54:41.973265Z'}
{'type': 'l2update', 'product_id': 'BTC-USD', 'changes': [['buy', '38226.12', '2.61311035']], 'time': '2021-05-20T03:54:41.976962Z'}
{'type': 'l2update', 'product_id': 'BTC-USD', 'changes': [['sell', '38295.87', '0.50000000']], 'time': '2021-05-20T03:54:41.977290Z'}
{'type': 'l2update', 'product_id': 'BTC-USD', 'changes': [['buy', '38149.01', '0.43105868']], 'time': '2021-05-20T03:54:41.977569Z'}
{'type': 'l2update', 'product_id': 'BTC-USD', 'changes': [['sell', '38591.11', '0.00000000']], 'time': '2021-05-20T03:54:41.984513Z'}
{'type': 'l2update', 'product_id': 'BTC-USD', 'changes': [['sell', '38360.27', '0.00000000']], 'time': '2021-05-20T03:54:41.987468Z'}
{'type': 'l2update', 'product_id': 'BTC-USD', 'changes': [['sell', '38386.10', '1.20000000']], 'time': '2021-05-20T03:54:41.991626Z'}
{'type': 'l2update', 'product_id': 'BTC-USD', 'changes': [['sell', '38321.44', '0.10000000']], 'time': '2021-05-20T03:54:41.991744Z'}
{'type': 'l2update', 'product_id': 'BTC-USD', 'changes': [['sell', '38325.89', '0.01000000']], 'time': '2021-05-20T03:54:41.991865Z'}
{'type': 'l2update', 'product_id': 'BTC-USD', 'changes': [['buy', '38199.17', '0.03746201']], 'time': '2021-05-20T03:54:41.993070Z'}
{'type': 'l2update', 'product_id': 'BTC-USD', 'changes': [['buy', '38239.28', '0.01516381']], 'time': '2021-05-20T03:54:41.993070Z'}
{'type': 'l2update', 'product_id': 'BTC-USD', 'changes': [['buy', '38260.80', '0.00000000']], 'time': '2021-05-20T03:54:41.994275Z'}
{'type': 'l2update', 'product_id': 'BTC-USD', 'changes': [['buy', '38268.82', '0.58716278']], 'time': '2021-05-20T03:54:41.997447Z'}
{'type': 'l2update', 'product_id': 'BTC-USD', 'changes': [['sell', '38321.77', '0.47590000']], 'time': '2021-05-20T03:54:41.998948Z'}
{'type': 'l2update', 'product_id': 'BTC-USD', 'changes': [['sell', '38489.45', '0.00000000']], 'time': '2021-05-20T03:54:42.000054Z'}
{'type': 'l2update', 'product_id': 'BTC-USD', 'changes': [['buy', '38165.03', '0.00000000']], 'time': '2021-05-20T03:54:42.005691Z'}
{'type': 'l2update', 'product_id': 'BTC-USD', 'changes': [['buy', '38251.21', '0.00000000']], 'time': '2021-05-20T03:54:42.006395Z'}
{'type': 'l2update', 'product_id': 'BTC-USD', 'changes': [['buy', '38164.74', '0.06859113']], 'time': '2021-05-20T03:54:42.012355Z'}
{'type': 'l2update', 'product_id': 'BTC-USD', 'changes': [['buy', '38220.47', '0.03374920']], 'time': '2021-05-20T03:54:42.012355Z'}
{'type': 'l2update', 'product_id': 'BTC-USD', 'changes': [['buy', '38265.71', '0.05682204']], 'time': '2021-05-20T03:54:42.012501Z'}
{'type': 'l2update', 'product_id': 'BTC-USD', 'changes': [['sell', '38306.30', '0.04167611']], 'time': '2021-05-20T03:54:42.012501Z'}
{'type': 'l2update', 'product_id': 'BTC-USD', 'changes': [['sell', '38326.70', '2.61295285']], 'time': '2021-05-20T03:54:42.013488Z'}
{'type': 'l2update', 'product_id': 'BTC-USD', 'changes': [['buy', '38146.59', '0.80000000']], 'time': '2021-05-20T03:54:42.016936Z'}
{'type': 'l2update', 'product_id': 'BTC-USD', 'changes': [['buy', '38243.57', '0.01000000']], 'time': '2021-05-20T03:54:42.017708Z'}
{'type': 'l2update', 'product_id': 'BTC-USD', 'changes': [['buy', '38268.82', '0.00000000']], 'time': '2021-05-20T03:54:42.018388Z'}
{'type': 'l2update', 'product_id': 'BTC-USD', 'changes': [['sell', '38321.77', '0.00000000']], 'time': '2021-05-20T03:54:42.020072Z'}
{'type': 'l2update', 'product_id': 'BTC-USD', 'changes': [['buy', '38204.86', '0.00000000']], 'time': '2021-05-20T03:54:42.020549Z'}
{'type': 'l2update', 'product_id': 'BTC-USD', 'changes': [['buy', '38268.87', '0.52200000']], 'time': '2021-05-20T03:54:42.023938Z'}
{'type': 'l2update', 'product_id': 'BTC-USD', 'changes': [['sell', '38316.64', '0.00000000']], 'time': '2021-05-20T03:54:42.025346Z'}
{'type': 'l2update', 'product_id': 'BTC-USD', 'changes': [['sell', '38386.10', '0.00000000']], 'time': '2021-05-20T03:54:42.025413Z'}
{'type': 'l2update', 'product_id': 'BTC-USD', 'changes': [['sell', '38464.87', '0.01000000']], 'time': '2021-05-20T03:54:42.029482Z'}
{'type': 'l2update', 'product_id': 'BTC-USD', 'changes': [['buy', '38287.23', '0.15582965']], 'time': '2021-05-20T03:54:42.035173Z'}
{'type': 'l2update', 'product_id': 'BTC-USD', 'changes': [['sell', '38325.89', '0.00000000']], 'time': '2021-05-20T03:54:42.035214Z'}
{'type': 'l2update', 'product_id': 'BTC-USD', 'changes': [['sell', '38379.54', '0.00000000']], 'time': '2021-05-20T03:54:42.038530Z'}
{'type': 'l2update', 'product_id': 'BTC-USD', 'changes': [['buy', '38264.05', '0.00000000']], 'time': '2021-05-20T03:54:42.038950Z'}
{'type': 'l2update', 'product_id': 'BTC-USD', 'changes': [['buy', '38192.20', '2.67770000']], 'time': '2021-05-20T03:54:42.042495Z'}
{'type': 'l2update', 'product_id': 'BTC-USD', 'changes': [['sell', '38413.68', '0.03295505']], 'time': '2021-05-20T03:54:42.042526Z'}
{'type': 'l2update', 'product_id': 'BTC-USD', 'changes': [['buy', '38217.22', '2.61320405']], 'time': '2021-05-20T03:54:42.043414Z'}
{'type': 'l2update', 'product_id': 'BTC-USD', 'changes': [['buy', '38192.93', '0.01000000']], 'time': '2021-05-20T03:54:42.048235Z'}
{'type': 'l2update', 'product_id': 'BTC-USD', 'changes': [['buy', '38119.97', '0.00000000']], 'time': '2021-05-20T03:54:42.048407Z'}
{'type': 'l2update', 'product_id': 'BTC-USD', 'changes': [['buy', '38139.06', '0.35403454']], 'time': '2021-05-20T03:54:42.048407Z'}
{'type': 'l2update', 'product_id': 'BTC-USD', 'changes': [['buy', '38141.83', '0.00000000']], 'time': '2021-05-20T03:54:42.048407Z'}
{'type': 'l2update', 'product_id': 'BTC-USD', 'changes': [['buy', '38175.84', '0.00000000']], 'time': '2021-05-20T03:54:42.048407Z'}
{'type': 'l2update', 'product_id': 'BTC-USD', 'changes': [['sell', '38392.08', '0.00000000']], 'time': '2021-05-20T03:54:42.056273Z'}
{'type': 'l2update', 'product_id': 'BTC-USD', 'changes': [['buy', '38265.28', '0.58716278']], 'time': '2021-05-20T03:54:42.057490Z'}
{'type': 'l2update', 'product_id': 'BTC-USD', 'changes': [['sell', '38321.86', '0.00000000']], 'time': '2021-05-20T03:54:42.061022Z'}
{'type': 'l2update', 'product_id': 'BTC-USD', 'changes': [['buy', '38221.55', '0.00000000']], 'time': '2021-05-20T03:54:42.063391Z'}
{'type': 'l2update', 'product_id': 'BTC-USD', 'changes': [['sell', '38301.69', '0.00000000']], 'time': '2021-05-20T03:54:42.065069Z'}
{'type': 'l2update', 'product_id': 'BTC-USD', 'changes': [['buy', '38270.27', '0.44530000']], 'time': '2021-05-20T03:54:42.066171Z'}
{'type': 'l2update', 'product_id': 'BTC-USD', 'changes': [['buy', '38282.39', '0.00000000']], 'time': '2021-05-20T03:54:42.066617Z'}
{'type': 'l2update', 'product_id': 'BTC-USD', 'changes': [['sell', '38327.40', '2.61244118']], 'time': '2021-05-20T03:54:42.070465Z'}
{'type': 'l2update', 'product_id': 'BTC-USD', 'changes': [['buy', '38154.19', '0.41871617']], 'time': '2021-05-20T03:54:42.076209Z'}
{'type': 'l2update', 'product_id': 'BTC-USD', 'changes': [['buy', '38270.05', '0.03969829']], 'time': '2021-05-20T03:54:42.076356Z'}
{'type': 'l2update', 'product_id': 'BTC-USD', 'changes': [['buy', '38246.12', '0.00000000']], 'time': '2021-05-20T03:54:42.079761Z'}
{'type': 'l2update', 'product_id': 'BTC-USD', 'changes': [['buy', '38245.32', '0.00000000']], 'time': '2021-05-20T03:54:42.079761Z'}
{'type': 'l2update', 'product_id': 'BTC-USD', 'changes': [['buy', '38244.51', '0.00000000']], 'time': '2021-05-20T03:54:42.079761Z'}
{'type': 'l2update', 'product_id': 'BTC-USD', 'changes': [['sell', '38295.87', '0.00000000']], 'time': '2021-05-20T03:54:42.084034Z'}
{'type': 'l2update', 'product_id': 'BTC-USD', 'changes': [['sell', '38430.84', '0.00000000']], 'time': '2021-05-20T03:54:42.085815Z'}
{'type': 'l2update', 'product_id': 'BTC-USD', 'changes': [['sell', '38287.24', '0.00000000']], 'time': '2021-05-20T03:54:42.087260Z'}
{'type': 'l2update', 'product_id': 'BTC-USD', 'changes': [['buy', '38269.87', '0.21000000']], 'time': '2021-05-20T03:54:42.087924Z'}
{'type': 'l2update', 'product_id': 'BTC-USD', 'changes': [['buy', '38270.27', '0.00000000']], 'time': '2021-05-20T03:54:42.088490Z'}
{'type': 'l2update', 'product_id': 'BTC-USD', 'changes': [['sell', '38464.87', '0.00000000']], 'time': '2021-05-20T03:54:42.091086Z'}
{'type': 'l2update', 'product_id': 'BTC-USD', 'changes': [['sell', '38393.73', '0.03485363']], 'time': '2021-05-20T03:54:42.093098Z'}
{'type': 'l2update', 'product_id': 'BTC-USD', 'changes': [['buy', '38236.54', '0.10000000']], 'time': '2021-05-20T03:54:42.093188Z'}
{'type': 'l2update', 'product_id': 'BTC-USD', 'changes': [['buy', '38265.71', '0.00000000']], 'time': '2021-05-20T03:54:42.100222Z'}
{'type': 'l2update', 'product_id': 'BTC-USD', 'changes': [['sell', '38306.30', '0.00000000']], 'time': '2021-05-20T03:54:42.100222Z'}
{'type': 'l2update', 'product_id': 'BTC-USD', 'changes': [['sell', '38391.64', '0.11064083']], 'time': '2021-05-20T03:54:42.101937Z'}
{'type': 'l2update', 'product_id': 'BTC-USD', 'changes': [['sell', '38291.05', '0.00000000']], 'time': '2021-05-20T03:54:42.102550Z'}
{'type': 'l2update', 'product_id': 'BTC-USD', 'changes': [['sell', '38415.49', '0.00000000']], 'time': '2021-05-20T03:54:42.102680Z'}
{'type': 'l2update', 'product_id': 'BTC-USD', 'changes': [['sell', '38408.45', '0.00000000']], 'time': '2021-05-20T03:54:42.102680Z'}
{'type': 'l2update', 'product_id': 'BTC-USD', 'changes': [['sell', '38401.61', '0.00000000']], 'time': '2021-05-20T03:54:42.102680Z'}
{'type': 'l2update', 'product_id': 'BTC-USD', 'changes': [['sell', '38397.34', '0.00000000']], 'time': '2021-05-20T03:54:42.102680Z'}
{'type': 'l2update', 'product_id': 'BTC-USD', 'changes': [['sell', '38394.96', '0.00000000']], 'time': '2021-05-20T03:54:42.102680Z'}
{'type': 'l2update', 'product_id': 'BTC-USD', 'changes': [['sell', '38391.07', '0.00000000']], 'time': '2021-05-20T03:54:42.102680Z'}
{'type': 'l2update', 'product_id': 'BTC-USD', 'changes': [['sell', '38388.50', '0.00000000']], 'time': '2021-05-20T03:54:42.102680Z'}
{'type': 'l2update', 'product_id': 'BTC-USD', 'changes': [['buy', '38259.14', '0.00000000']], 'time': '2021-05-20T03:54:42.103661Z'}
{'type': 'l2update', 'product_id': 'BTC-USD', 'changes': [['buy', '38287.23', '0.11022654']], 'time': '2021-05-20T03:54:42.104077Z'}
{'type': 'l2update', 'product_id': 'BTC-USD', 'changes': [['buy', '38287.23', '0.09308023']], 'time': '2021-05-20T03:54:42.104116Z'}
{'type': 'l2update', 'product_id': 'BTC-USD', 'changes': [['buy', '38287.23', '0.07816023']], 'time': '2021-05-20T03:54:42.104656Z'}
{'type': 'l2update', 'product_id': 'BTC-USD', 'changes': [['sell', '38301.68', '0.13661440']], 'time': '2021-05-20T03:54:42.105507Z'}
{'type': 'l2update', 'product_id': 'BTC-USD', 'changes': [['buy', '38287.23', '0.07243023']], 'time': '2021-05-20T03:54:42.105571Z'}
{'type': 'l2update', 'product_id': 'BTC-USD', 'changes': [['buy', '38255.80', '0.02400000']], 'time': '2021-05-20T03:54:42.111639Z'}
{'type': 'l2update', 'product_id': 'BTC-USD', 'changes': [['buy', '38255.00', '0.02400000']], 'time': '2021-05-20T03:54:42.111639Z'}
{'type': 'l2update', 'product_id': 'BTC-USD', 'changes': [['buy', '38254.19', '0.02400000']], 'time': '2021-05-20T03:54:42.111639Z'}
{'type': 'l2update', 'product_id': 'BTC-USD', 'changes': [['sell', '38420.19', '0.01301399']], 'time': '2021-05-20T03:54:42.111671Z'}
{'type': 'l2update', 'product_id': 'BTC-USD', 'changes': [['sell', '38418.72', '0.01000000']], 'time': '2021-05-20T03:54:42.111862Z'}
{'type': 'l2update', 'product_id': 'BTC-USD', 'changes': [['sell', '38293.65', '1.66031540']], 'time': '2021-05-20T03:54:42.112381Z'}
{'type': 'l2update', 'product_id': 'BTC-USD', 'changes': [['sell', '38291.04', '0.50000000']], 'time': '2021-05-20T03:54:42.112663Z'}
{'type': 'l2update', 'product_id': 'BTC-USD', 'changes': [['sell', '38325.84', '0.66875617']], 'time': '2021-05-20T03:54:42.113299Z'}
{'type': 'l2update', 'product_id': 'BTC-USD', 'changes': [['buy', '38265.04', '0.00000000']], 'time': '2021-05-20T03:54:42.121751Z'}
{'type': 'l2update', 'product_id': 'BTC-USD', 'changes': [['buy', '38054.70', '0.00000000']], 'time': '2021-05-20T03:54:42.123512Z'}
{'type': 'l2update', 'product_id': 'BTC-USD', 'changes': [['sell', '38303.46', '0.42500000']], 'time': '2021-05-20T03:54:42.127319Z'}
{'type': 'l2update', 'product_id': 'BTC-USD', 'changes': [['buy', '38254.19', '0.00000000']], 'time': '2021-05-20T03:54:42.129267Z'}
{'type': 'l2update', 'product_id': 'BTC-USD', 'changes': [['buy', '38141.83', '0.39899772']], 'time': '2021-05-20T03:54:42.133549Z'}
{'type': 'l2update', 'product_id': 'BTC-USD', 'changes': [['sell', '38291.28', '0.15000000']], 'time': '2021-05-20T03:54:42.134141Z'}
{'type': 'l2update', 'product_id': 'BTC-USD', 'changes': [['buy', '38262.87', '0.00000000']], 'time': '2021-05-20T03:54:42.137992Z'}
{'type': 'l2update', 'product_id': 'BTC-USD', 'changes': [['sell', '38474.08', '0.01000000']], 'time': '2021-05-20T03:54:42.138666Z'}
{'type': 'l2update', 'product_id': 'BTC-USD', 'changes': [['buy', '37435.20', '0.06486164']], 'time': '2021-05-20T03:54:42.139002Z'}
{'type': 'l2update', 'product_id': 'BTC-USD', 'changes': [['sell', '38291.76', '1.07800000']], 'time': '2021-05-20T03:54:42.139071Z'}
{'type': 'l2update', 'product_id': 'BTC-USD', 'changes': [['sell', '48255.15', '0.00216500']], 'time': '2021-05-20T03:54:42.139111Z'}
{'type': 'l2update', 'product_id': 'BTC-USD', 'changes': [['buy', '38255.80', '0.00000000']], 'time': '2021-05-20T03:54:42.144813Z'}
{'type': 'l2update', 'product_id': 'BTC-USD', 'changes': [['buy', '38255.00', '0.00000000']], 'time': '2021-05-20T03:54:42.144813Z'}
{'type': 'l2update', 'product_id': 'BTC-USD', 'changes': [['buy', '38111.59', '0.01000000']], 'time': '2021-05-20T03:54:42.148895Z'}
{'type': 'l2update', 'product_id': 'BTC-USD', 'changes': [['sell', '38400.19', '0.03390439']], 'time': '2021-05-20T03:54:42.149024Z'}
{'type': 'l2update', 'product_id': 'BTC-USD', 'changes': [['sell', '38301.63', '0.00000000']], 'time': '2021-05-20T03:54:42.149317Z'}
{'type': 'l2update', 'product_id': 'BTC-USD', 'changes': [['sell', '38451.89', '0.00000000']], 'time': '2021-05-20T03:54:42.152800Z'}
{'type': 'l2update', 'product_id': 'BTC-USD', 'changes': [['buy', '38258.62', '0.00000000']], 'time': '2021-05-20T03:54:42.153023Z'}
{'type': 'l2update', 'product_id': 'BTC-USD', 'changes': [['sell', '38310.49', '0.00000000']], 'time': '2021-05-20T03:54:42.156800Z'}
{'type': 'l2update', 'product_id': 'BTC-USD', 'changes': [['buy', '38149.01', '0.80294709']], 'time': '2021-05-20T03:54:42.164210Z'}
{'type': 'l2update', 'product_id': 'BTC-USD', 'changes': [['sell', '38334.37', '0.00000000']], 'time': '2021-05-20T03:54:42.168060Z'}
{'type': 'l2update', 'product_id': 'BTC-USD', 'changes': [['buy', '38243.57', '0.00000000']], 'time': '2021-05-20T03:54:42.170552Z'}
{'type': 'l2update', 'product_id': 'BTC-USD', 'changes': [['sell', '38302.55', '0.00000000']], 'time': '2021-05-20T03:54:42.170595Z'}
{'type': 'l2update', 'product_id': 'BTC-USD', 'changes': [['sell', '38431.15', '0.00000000']], 'time': '2021-05-20T03:54:42.171769Z'}
{'type': 'l2update', 'product_id': 'BTC-USD', 'changes': [['sell', '38303.46', '0.00000000']], 'time': '2021-05-20T03:54:42.175935Z'}
{'type': 'l2update', 'product_id': 'BTC-USD', 'changes': [['sell', '38310.48', '0.00000000']], 'time': '2021-05-20T03:54:42.176041Z'}
{'type': 'l2update', 'product_id': 'BTC-USD', 'changes': [['buy', '38253.60', '0.00000000']], 'time': '2021-05-20T03:54:42.185175Z'}
{'type': 'l2update', 'product_id': 'BTC-USD', 'changes': [['buy', '38251.67', '0.05661252']], 'time': '2021-05-20T03:54:42.193421Z'}
{'type': 'l2update', 'product_id': 'BTC-USD', 'changes': [['sell', '38297.38', '0.06233051']], 'time': '2021-05-20T03:54:42.193421Z'}
{'type': 'l2update', 'product_id': 'BTC-USD', 'changes': [['buy', '38154.19', '0.82801995']], 'time': '2021-05-20T03:54:42.193787Z'}
{'type': 'l2update', 'product_id': 'BTC-USD', 'changes': [['sell', '38406.84', '0.03390155']], 'time': '2021-05-20T03:54:42.195333Z'}
{'type': 'l2update', 'product_id': 'BTC-USD', 'changes': [['buy', '38210.33', '0.03036725']], 'time': '2021-05-20T03:54:42.195333Z'}
{'type': 'l2update', 'product_id': 'BTC-USD', 'changes': [['sell', '38455.64', '0.01000000']], 'time': '2021-05-20T03:54:42.195521Z'}
{'type': 'l2update', 'product_id': 'BTC-USD', 'changes': [['sell', '38316.34', '0.00000000']], 'time': '2021-05-20T03:54:42.201226Z'}
{'type': 'l2update', 'product_id': 'BTC-USD', 'changes': [['sell', '38291.03', '2.48969908']], 'time': '2021-05-20T03:54:42.201775Z'}
{'type': 'l2update', 'product_id': 'BTC-USD', 'changes': [['buy', '38251.24', '0.43680000']], 'time': '2021-05-20T03:54:42.201832Z'}
{'type': 'l2update', 'product_id': 'BTC-USD', 'changes': [['sell', '38379.80', '0.00000000']], 'time': '2021-05-20T03:54:42.202065Z'}
{'type': 'l2update', 'product_id': 'BTC-USD', 'changes': [['sell', '38316.33', '0.05000000']], 'time': '2021-05-20T03:54:42.202077Z'}
{'type': 'l2update', 'product_id': 'BTC-USD', 'changes': [['sell', '38501.40', '0.01000000']], 'time': '2021-05-20T03:54:42.202744Z'}
{'type': 'l2update', 'product_id': 'BTC-USD', 'changes': [['buy', '38251.70', '0.02400000']], 'time': '2021-05-20T03:54:42.202999Z'}
{'type': 'l2update', 'product_id': 'BTC-USD', 'changes': [['buy', '38250.89', '0.02400000']], 'time': '2021-05-20T03:54:42.202999Z'}
{'type': 'l2update', 'product_id': 'BTC-USD', 'changes': [['buy', '38250.08', '0.02400000']], 'time': '2021-05-20T03:54:42.202999Z'}
{'type': 'l2update', 'product_id': 'BTC-USD', 'changes': [['buy', '38207.44', '0.02400000']], 'time': '2021-05-20T03:54:42.203149Z'}
{'type': 'l2update', 'product_id': 'BTC-USD', 'changes': [['sell', '38291.03', '3.06997661']], 'time': '2021-05-20T03:54:42.208127Z'}
{'type': 'l2update', 'product_id': 'BTC-USD', 'changes': [['sell', '43100.00', '1.09530000']], 'time': '2021-05-20T03:54:42.215044Z'}
{'type': 'l2update', 'product_id': 'BTC-USD', 'changes': [['buy', '38171.22', '0.00000000']], 'time': '2021-05-20T03:54:42.215073Z'}
{'type': 'l2update', 'product_id': 'BTC-USD', 'changes': [['sell', '38316.33', '0.00000000']], 'time': '2021-05-20T03:54:42.221475Z'}
{'type': 'l2update', 'product_id': 'BTC-USD', 'changes': [['sell', '38325.46', '0.01000000']], 'time': '2021-05-20T03:54:42.222215Z'}
{'type': 'l2update', 'product_id': 'BTC-USD', 'changes': [['sell', '38367.95', '0.00000000']], 'time': '2021-05-20T03:54:42.222328Z'}
{'type': 'l2update', 'product_id': 'BTC-USD', 'changes': [['sell', '38387.46', '0.35126717']], 'time': '2021-05-20T03:54:42.222338Z'}
{'type': 'l2update', 'product_id': 'BTC-USD', 'changes': [['buy', '38143.43', '0.35126717']], 'time': '2021-05-20T03:54:42.222338Z'}
{'type': 'l2update', 'product_id': 'BTC-USD', 'changes': [['buy', '38251.70', '0.00000000']], 'time': '2021-05-20T03:54:42.222917Z'}
{'type': 'l2update', 'product_id': 'BTC-USD', 'changes': [['buy', '38250.89', '0.00000000']], 'time': '2021-05-20T03:54:42.222917Z'}
{'type': 'l2update', 'product_id': 'BTC-USD', 'changes': [['buy', '38250.08', '0.00000000']], 'time': '2021-05-20T03:54:42.222917Z'}
{'type': 'l2update', 'product_id': 'BTC-USD', 'changes': [['buy', '38263.89', '0.39490431']], 'time': '2021-05-20T03:54:42.231330Z'}
{'type': 'l2update', 'product_id': 'BTC-USD', 'changes': [['sell', '38364.67', '0.01000000']], 'time': '2021-05-20T03:54:42.231403Z'}
{'type': 'l2update', 'product_id': 'BTC-USD', 'changes': [['sell', '38342.33', '2.16932808']], 'time': '2021-05-20T03:54:42.231441Z'}
{'type': 'l2update', 'product_id': 'BTC-USD', 'changes': [['buy', '38217.22', '0.00000000']], 'time': '2021-05-20T03:54:42.233605Z'}
{'type': 'l2update', 'product_id': 'BTC-USD', 'changes': [['buy', '38270.05', '0.00000000']], 'time': '2021-05-20T03:54:42.233784Z'}
{'type': 'l2update', 'product_id': 'BTC-USD', 'changes': [['buy', '38228.56', '0.00000000']], 'time': '2021-05-20T03:54:42.233909Z'}
{'type': 'l2update', 'product_id': 'BTC-USD', 'changes': [['sell', '38325.83', '0.05000000']], 'time': '2021-05-20T03:54:42.241948Z'}
{'type': 'l2update', 'product_id': 'BTC-USD', 'changes': [['sell', '43100.00', '1.16920000']], 'time': '2021-05-20T03:54:42.242068Z'}
{'type': 'l2update', 'product_id': 'BTC-USD', 'changes': [['sell', '38293.65', '0.00000000']], 'time': '2021-05-20T03:54:42.243810Z'}
{'type': 'l2update', 'product_id': 'BTC-USD', 'changes': [['buy', '38243.15', '0.01000000']], 'time': '2021-05-20T03:54:42.250294Z'}
{'type': 'l2update', 'product_id': 'BTC-USD', 'changes': [['sell', '38335.22', '0.29877025']], 'time': '2021-05-20T03:54:42.250610Z'}
{'type': 'l2update', 'product_id': 'BTC-USD', 'changes': [['sell', '38401.50', '0.00000000']], 'time': '2021-05-20T03:54:42.253391Z'}
{'type': 'l2update', 'product_id': 'BTC-USD', 'changes': [['sell', '38327.40', '0.00000000']], 'time': '2021-05-20T03:54:42.253424Z'}
{'type': 'l2update', 'product_id': 'BTC-USD', 'changes': [['buy', '38235.74', '0.00000000']], 'time': '2021-05-20T03:54:42.255989Z'}
{'type': 'l2update', 'product_id': 'BTC-USD', 'changes': [['sell', '38413.68', '0.06261717']], 'time': '2021-05-20T03:54:42.256636Z'}
{'type': 'l2update', 'product_id': 'BTC-USD', 'changes': [['buy', '38287.23', '0.00000000']], 'time': '2021-05-20T03:54:42.263594Z'}
{'type': 'l2update', 'product_id': 'BTC-USD', 'changes': [['buy', '38204.36', '0.02617502']], 'time': '2021-05-20T03:54:42.266415Z'}
{'type': 'l2update', 'product_id': 'BTC-USD', 'changes': [['buy', '38269.88', '0.03969829']], 'time': '2021-05-20T03:54:42.266634Z'}
{'type': 'l2update', 'product_id': 'BTC-USD', 'changes': [['sell', '38291.76', '1.61200000']], 'time': '2021-05-20T03:54:42.274037Z'}
{'type': 'l2update', 'product_id': 'BTC-USD', 'changes': [['sell', '38325.83', '0.00000000']], 'time': '2021-05-20T03:54:42.275587Z'}
{'type': 'l2update', 'product_id': 'BTC-USD', 'changes': [['buy', '37435.20', '0.00000000']], 'time': '2021-05-20T03:54:42.279513Z'}
{'type': 'l2update', 'product_id': 'BTC-USD', 'changes': [['sell', '38383.53', '0.01302642']], 'time': '2021-05-20T03:54:42.280932Z'}
{'type': 'l2update', 'product_id': 'BTC-USD', 'changes': [['sell', '38422.13', '0.02935700']], 'time': '2021-05-20T03:54:42.280960Z'}
{'type': 'l2update', 'product_id': 'BTC-USD', 'changes': [['buy', '38239.28', '0.04891301']], 'time': '2021-05-20T03:54:42.282084Z'}
{'type': 'l2update', 'product_id': 'BTC-USD', 'changes': [['buy', '38248.56', '0.02400000']], 'time': '2021-05-20T03:54:42.285767Z'}
{'type': 'l2update', 'product_id': 'BTC-USD', 'changes': [['buy', '38247.75', '0.02400000']], 'time': '2021-05-20T03:54:42.285767Z'}
{'type': 'l2update', 'product_id': 'BTC-USD', 'changes': [['buy', '38246.94', '0.02400000']], 'time': '2021-05-20T03:54:42.285767Z'}
{'type': 'l2update', 'product_id': 'BTC-USD', 'changes': [['sell', '38313.76', '0.49500000']], 'time': '2021-05-20T03:54:42.285793Z'}
{'type': 'l2update', 'product_id': 'BTC-USD', 'changes': [['sell', '38290.45', '0.01492000']], 'time': '2021-05-20T03:54:42.286020Z'}
{'type': 'l2update', 'product_id': 'BTC-USD', 'changes': [['sell', '38339.58', '0.30330182']], 'time': '2021-05-20T03:54:42.286082Z'}
{'type': 'l2update', 'product_id': 'BTC-USD', 'changes': [['buy', '38143.43', '0.65456899']], 'time': '2021-05-20T03:54:42.286082Z'}
{'type': 'l2update', 'product_id': 'BTC-USD', 'changes': [['buy', '38191.05', '0.16748647']], 'time': '2021-05-20T03:54:42.286082Z'}
{'type': 'l2update', 'product_id': 'BTC-USD', 'changes': [['sell', '38290.39', '0.07460000']], 'time': '2021-05-20T03:54:42.286305Z'}
{'type': 'l2update', 'product_id': 'BTC-USD', 'changes': [['buy', '38270.56', '0.01492000']], 'time': '2021-05-20T03:54:42.286443Z'}
{'type': 'l2update', 'product_id': 'BTC-USD', 'changes': [['buy', '38270.11', '0.07460000']], 'time': '2021-05-20T03:54:42.286673Z'}
{'type': 'l2update', 'product_id': 'BTC-USD', 'changes': [['sell', '38418.72', '0.00000000']], 'time': '2021-05-20T03:54:42.286714Z'}
{'type': 'l2update', 'product_id': 'BTC-USD', 'changes': [['sell', '38291.03', '2.48969908']], 'time': '2021-05-20T03:54:42.290583Z'}
{'type': 'l2update', 'product_id': 'BTC-USD', 'changes': [['sell', '38493.48', '0.00000000']], 'time': '2021-05-20T03:54:42.291519Z'}
{'type': 'l2update', 'product_id': 'BTC-USD', 'changes': [['sell', '38291.76', '0.53400000']], 'time': '2021-05-20T03:54:42.294749Z'}
{'type': 'l2update', 'product_id': 'BTC-USD', 'changes': [['buy', '38220.47', '0.00000000']], 'time': '2021-05-20T03:54:42.294964Z'}
{'type': 'l2update', 'product_id': 'BTC-USD', 'changes': [['buy', '38113.53', '0.00000000']], 'time': '2021-05-20T03:54:42.297856Z'}
{'type': 'l2update', 'product_id': 'BTC-USD', 'changes': [['buy', '38251.24', '0.00000000']], 'time': '2021-05-20T03:54:42.299217Z'}
{'type': 'l2update', 'product_id': 'BTC-USD', 'changes': [['buy', '38154.19', '0.40930378']], 'time': '2021-05-20T03:54:42.301012Z'}
{'type': 'l2update', 'product_id': 'BTC-USD', 'changes': [['buy', '3550.00', '0.05908266']], 'time': '2021-05-20T03:54:42.303271Z'}
{'type': 'l2update', 'product_id': 'BTC-USD', 'changes': [['sell', '38309.87', '0.05000000']], 'time': '2021-05-20T03:54:42.303730Z'}
{'type': 'l2update', 'product_id': 'BTC-USD', 'changes': [['sell', '38290.45', '0.00000000']], 'time': '2021-05-20T03:54:42.303998Z'}
{'type': 'l2update', 'product_id': 'BTC-USD', 'changes': [['buy', '38270.11', '0.00000000']], 'time': '2021-05-20T03:54:42.304980Z'}
{'type': 'l2update', 'product_id': 'BTC-USD', 'changes': [['sell', '38442.97', '0.01300628']], 'time': '2021-05-20T03:54:42.314702Z'}
{'type': 'l2update', 'product_id': 'BTC-USD', 'changes': [['sell', '38455.64', '0.00000000']], 'time': '2021-05-20T03:54:42.316035Z'}
{'type': 'l2update', 'product_id': 'BTC-USD', 'changes': [['sell', '38628.44', '0.01294383']], 'time': '2021-05-20T03:54:42.319045Z'}
{'type': 'l2update', 'product_id': 'BTC-USD', 'changes': [['buy', '38265.29', '0.03969829']], 'time': '2021-05-20T03:54:42.319402Z'}
{'type': 'l2update', 'product_id': 'BTC-USD', 'changes': [['sell', '38348.89', '0.35646057']], 'time': '2021-05-20T03:54:42.322566Z'}
{'type': 'l2update', 'product_id': 'BTC-USD', 'changes': [['sell', '38290.38', '0.58027753']], 'time': '2021-05-20T03:54:42.323619Z'}
{'type': 'l2update', 'product_id': 'BTC-USD', 'changes': [['buy', '37868.29', '0.00000000']], 'time': '2021-05-20T03:54:42.324243Z'}
{'type': 'l2update', 'product_id': 'BTC-USD', 'changes': [['sell', '38289.91', '0.01492000']], 'time': '2021-05-20T03:54:42.326629Z'}
{'type': 'l2update', 'product_id': 'BTC-USD', 'changes': [['buy', '37993.47', '0.00000000']], 'time': '2021-05-20T03:54:42.326896Z'}
{'type': 'l2update', 'product_id': 'BTC-USD', 'changes': [['buy', '38271.04', '0.07460000']], 'time': '2021-05-20T03:54:42.327162Z'}
{'type': 'l2update', 'product_id': 'BTC-USD', 'changes': [['sell', '38400.19', '0.06897461']], 'time': '2021-05-20T03:54:42.331812Z'}
{'type': 'l2update', 'product_id': 'BTC-USD', 'changes': [['sell', '38358.96', '0.03082288']], 'time': '2021-05-20T03:54:42.331812Z'}
{'type': 'l2update', 'product_id': 'BTC-USD', 'changes': [['sell', '38348.60', '0.06025053']], 'time': '2021-05-20T03:54:42.331812Z'}
{'type': 'l2update', 'product_id': 'BTC-USD', 'changes': [['buy', '38157.73', '0.06248419']], 'time': '2021-05-20T03:54:42.331812Z'}
{'type': 'l2update', 'product_id': 'BTC-USD', 'changes': [['buy', '38251.67', '0.00000000']], 'time': '2021-05-20T03:54:42.333485Z'}
{'type': 'l2update', 'product_id': 'BTC-USD', 'changes': [['sell', '38297.38', '0.00000000']], 'time': '2021-05-20T03:54:42.333485Z'}
{'type': 'l2update', 'product_id': 'BTC-USD', 'changes': [['sell', '38628.44', '0.00000000']], 'time': '2021-05-20T03:54:42.334283Z'}
{'type': 'l2update', 'product_id': 'BTC-USD', 'changes': [['buy', '38269.88', '0.00000000']], 'time': '2021-05-20T03:54:42.336091Z'}
{'type': 'l2update', 'product_id': 'BTC-USD', 'changes': [['sell', '38313.76', '0.00000000']], 'time': '2021-05-20T03:54:42.336594Z'}
{'type': 'l2update', 'product_id': 'BTC-USD', 'changes': [['sell', '48367.02', '0.00497700']], 'time': '2021-05-20T03:54:42.337994Z'}
{'type': 'l2update', 'product_id': 'BTC-USD', 'changes': [['sell', '38450.00', '0.28518201']], 'time': '2021-05-20T03:54:42.338482Z'}
{'type': 'l2update', 'product_id': 'BTC-USD', 'changes': [['sell', '38442.46', '0.01000000']], 'time': '2021-05-20T03:54:42.338621Z'}
{'type': 'l2update', 'product_id': 'BTC-USD', 'changes': [['buy', '38192.93', '0.00000000']], 'time': '2021-05-20T03:54:42.340309Z'}
{'type': 'l2update', 'product_id': 'BTC-USD', 'changes': [['sell', '38290.39', '0.00000000']], 'time': '2021-05-20T03:54:42.342442Z'}
{'type': 'l2update', 'product_id': 'BTC-USD', 'changes': [['sell', '38353.83', '0.42646721']], 'time': '2021-05-20T03:54:42.346313Z'}
{'type': 'l2update', 'product_id': 'BTC-USD', 'changes': [['sell', '38388.49', '0.00000000']], 'time': '2021-05-20T03:54:42.347420Z'}
{'type': 'l2update', 'product_id': 'BTC-USD', 'changes': [['sell', '38370.26', '0.00000000']], 'time': '2021-05-20T03:54:42.347420Z'}
{'type': 'l2update', 'product_id': 'BTC-USD', 'changes': [['buy', '38239.28', '0.03374920']], 'time': '2021-05-20T03:54:42.347420Z'}
{'type': 'l2update', 'product_id': 'BTC-USD', 'changes': [['sell', '38291.76', '0.00000000']], 'time': '2021-05-20T03:54:42.347786Z'}
{'type': 'l2update', 'product_id': 'BTC-USD', 'changes': [['buy', '38006.35', '0.01162500']], 'time': '2021-05-20T03:54:42.350671Z'}
{'type': 'l2update', 'product_id': 'BTC-USD', 'changes': [['sell', '38404.80', '0.00000000']], 'time': '2021-05-20T03:54:42.351602Z'}
{'type': 'l2update', 'product_id': 'BTC-USD', 'changes': [['sell', '38314.26', '0.00000000']], 'time': '2021-05-20T03:54:42.359698Z'}
{'type': 'l2update', 'product_id': 'BTC-USD', 'changes': [['sell', '38613.44', '0.01294886']], 'time': '2021-05-20T03:54:42.361630Z'}
{'type': 'l2update', 'product_id': 'BTC-USD', 'changes': [['buy', '38154.19', '0.00000000']], 'time': '2021-05-20T03:54:42.362356Z'}
{'type': 'l2update', 'product_id': 'BTC-USD', 'changes': [['buy', '38270.56', '0.00000000']], 'time': '2021-05-20T03:54:42.362631Z'}
{'type': 'l2update', 'product_id': 'BTC-USD', 'changes': [['buy', '38175.35', '0.03577500']], 'time': '2021-05-20T03:54:42.365827Z'}
{'type': 'l2update', 'product_id': 'BTC-USD', 'changes': [['buy', '38121.64', '0.04987195']], 'time': '2021-05-20T03:54:42.366212Z'}
{'type': 'l2update', 'product_id': 'BTC-USD', 'changes': [['sell', '38625.79', '0.35520000']], 'time': '2021-05-20T03:54:42.369195Z'}
{'type': 'l2update', 'product_id': 'BTC-USD', 'changes': [['sell', '38393.73', '0.00000000']], 'time': '2021-05-20T03:54:42.370433Z'}
{'type': 'l2update', 'product_id': 'BTC-USD', 'changes': [['sell', '38348.60', '0.02906498']], 'time': '2021-05-20T03:54:42.370433Z'}
{'type': 'l2update', 'product_id': 'BTC-USD', 'changes': [['sell', '38343.66', '0.00000000']], 'time': '2021-05-20T03:54:42.370433Z'}
{'type': 'l2update', 'product_id': 'BTC-USD', 'changes': [['sell', '38387.46', '0.00000000']], 'time': '2021-05-20T03:54:42.378122Z'}
{'type': 'l2update', 'product_id': 'BTC-USD', 'changes': [['sell', '38422.13', '0.00000000']], 'time': '2021-05-20T03:54:42.379349Z'}
{'type': 'l2update', 'product_id': 'BTC-USD', 'changes': [['buy', '38149.01', '0.43105868']], 'time': '2021-05-20T03:54:42.388973Z'}
{'type': 'l2update', 'product_id': 'BTC-USD', 'changes': [['buy', '38197.09', '0.03533740']], 'time': '2021-05-20T03:54:42.393664Z'}
{'type': 'l2update', 'product_id': 'BTC-USD', 'changes': [['buy', '38202.95', '0.02870732']], 'time': '2021-05-20T03:54:42.393664Z'}
{'type': 'l2update', 'product_id': 'BTC-USD', 'changes': [['sell', '38423.15', '0.01000000']], 'time': '2021-05-20T03:54:42.398368Z'}
{'type': 'l2update', 'product_id': 'BTC-USD', 'changes': [['buy', '38256.86', '0.42390000']], 'time': '2021-05-20T03:54:42.398976Z'}
{'type': 'l2update', 'product_id': 'BTC-USD', 'changes': [['buy', '38164.74', '0.03325373']], 'time': '2021-05-20T03:54:42.400845Z'}
{'type': 'l2update', 'product_id': 'BTC-USD', 'changes': [['buy', '38169.41', '0.00000000']], 'time': '2021-05-20T03:54:42.400845Z'}
{'type': 'l2update', 'product_id': 'BTC-USD', 'changes': [['buy', '38271.73', '0.01492000']], 'time': '2021-05-20T03:54:42.404401Z'}
{'type': 'l2update', 'product_id': 'BTC-USD', 'changes': [['buy', '38265.29', '0.00000000']], 'time': '2021-05-20T03:54:42.406232Z'}
{'type': 'l2update', 'product_id': 'BTC-USD', 'changes': [['buy', '38282.04', '0.07240819']], 'time': '2021-05-20T03:54:42.410087Z'}
{'type': 'l2update', 'product_id': 'BTC-USD', 'changes': [['buy', '38271.04', '0.00000000']], 'time': '2021-05-20T03:54:42.410644Z'}
{'type': 'l2update', 'product_id': 'BTC-USD', 'changes': [['sell', '38394.98', '0.02937250']], 'time': '2021-05-20T03:54:42.413797Z'}
{'type': 'l2update', 'product_id': 'BTC-USD', 'changes': [['buy', '38149.01', '0.00000000']], 'time': '2021-05-20T03:54:42.414513Z'}
{'type': 'l2update', 'product_id': 'BTC-USD', 'changes': [['sell', '38290.38', '0.00000000']], 'time': '2021-05-20T03:54:42.415610Z'}
{'type': 'l2update', 'product_id': 'BTC-USD', 'changes': [['buy', '38263.90', '0.03969829']], 'time': '2021-05-20T03:54:42.420239Z'}
{'type': 'l2update', 'product_id': 'BTC-USD', 'changes': [['buy', '38258.98', '0.04084924']], 'time': '2021-05-20T03:54:42.421323Z'}
{'type': 'l2update', 'product_id': 'BTC-USD', 'changes': [['sell', '38299.57', '0.03945814']], 'time': '2021-05-20T03:54:42.421323Z'}
{'type': 'l2update', 'product_id': 'BTC-USD', 'changes': [['buy', '38271.73', '0.00000000']], 'time': '2021-05-20T03:54:42.421395Z'}
{'type': 'l2update', 'product_id': 'BTC-USD', 'changes': [['buy', '38271.78', '0.52100000']], 'time': '2021-05-20T03:54:42.421692Z'}
{'type': 'l2update', 'product_id': 'BTC-USD', 'changes': [['buy', '38116.53', '0.00000000']], 'time': '2021-05-20T03:54:42.425443Z'}
{'type': 'l2update', 'product_id': 'BTC-USD', 'changes': [['sell', '38393.73', '0.03645362']], 'time': '2021-05-20T03:54:42.428698Z'}
{'type': 'l2update', 'product_id': 'BTC-USD', 'changes': [['sell', '38370.26', '0.03390439']], 'time': '2021-05-20T03:54:42.428698Z'}
{'type': 'l2update', 'product_id': 'BTC-USD', 'changes': [['sell', '38358.96', '0.06589310']], 'time': '2021-05-20T03:54:42.428698Z'}
{'type': 'l2update', 'product_id': 'BTC-USD', 'changes': [['sell', '38338.92', '0.03082288']], 'time': '2021-05-20T03:54:42.428698Z'}
{'type': 'l2update', 'product_id': 'BTC-USD', 'changes': [['sell', '38325.84', '0.68038216']], 'time': '2021-05-20T03:54:42.428698Z'}
{'type': 'l2update', 'product_id': 'BTC-USD', 'changes': [['sell', '38289.91', '0.00000000']], 'time': '2021-05-20T03:54:42.428791Z'}
{'type': 'l2update', 'product_id': 'BTC-USD', 'changes': [['buy', '38263.90', '0.00000000']], 'time': '2021-05-20T03:54:42.433691Z'}
{'type': 'l2update', 'product_id': 'BTC-USD', 'changes': [['sell', '38400.19', '0.03507022']], 'time': '2021-05-20T03:54:42.434638Z'}
{'type': 'l2update', 'product_id': 'BTC-USD', 'changes': [['sell', '38400.19', '0.00000000']], 'time': '2021-05-20T03:54:42.434638Z'}
{'type': 'l2update', 'product_id': 'BTC-USD', 'changes': [['sell', '38358.96', '0.03507022']], 'time': '2021-05-20T03:54:42.434638Z'}
{'type': 'l2update', 'product_id': 'BTC-USD', 'changes': [['sell', '38348.60', '0.00000000']], 'time': '2021-05-20T03:54:42.434638Z'}
{'type': 'l2update', 'product_id': 'BTC-USD', 'changes': [['buy', '38143.43', '0.35126717']], 'time': '2021-05-20T03:54:42.437135Z'}
{'type': 'l2update', 'product_id': 'BTC-USD', 'changes': [['sell', '38315.08', '0.43040000']], 'time': '2021-05-20T03:54:42.440440Z'}
{'type': 'l2update', 'product_id': 'BTC-USD', 'changes': [['sell', '38319.25', '0.05015070']], 'time': '2021-05-20T03:54:42.440456Z'}
{'type': 'l2update', 'product_id': 'BTC-USD', 'changes': [['sell', '38291.02', '0.58027753']], 'time': '2021-05-20T03:54:42.444255Z'}
{'type': 'l2update', 'product_id': 'BTC-USD', 'changes': [['sell', '38290.66', '0.01492000']], 'time': '2021-05-20T03:54:42.444624Z'}
{'type': 'l2update', 'product_id': 'BTC-USD', 'changes': [['buy', '38282.47', '0.01492000']], 'time': '2021-05-20T03:54:42.444642Z'}
{'type': 'l2update', 'product_id': 'BTC-USD', 'changes': [['sell', '38290.34', '0.07460000']], 'time': '2021-05-20T03:54:42.445211Z'}
{'type': 'l2update', 'product_id': 'BTC-USD', 'changes': [['buy', '38282.50', '0.06274942']], 'time': '2021-05-20T03:54:42.445268Z'}
{'type': 'l2update', 'product_id': 'BTC-USD', 'changes': [['buy', '37436.01', '0.06558712']], 'time': '2021-05-20T03:54:42.446214Z'}
{'type': 'l2update', 'product_id': 'BTC-USD', 'changes': [['buy', '38265.29', '0.03969829']], 'time': '2021-05-20T03:54:42.449658Z'}
{'type': 'l2update', 'product_id': 'BTC-USD', 'changes': [['buy', '38170.64', '0.02606759']], 'time': '2021-05-20T03:54:42.452065Z'}
{'type': 'l2update', 'product_id': 'BTC-USD', 'changes': [['buy', '38199.17', '0.07071574']], 'time': '2021-05-20T03:54:42.452065Z'}
{'type': 'l2update', 'product_id': 'BTC-USD', 'changes': [['buy', '38265.28', '0.00000000']], 'time': '2021-05-20T03:54:42.453964Z'}
{'type': 'l2update', 'product_id': 'BTC-USD', 'changes': [['buy', '38282.50', '0.00000000']], 'time': '2021-05-20T03:54:42.456770Z'}
{'type': 'l2update', 'product_id': 'BTC-USD', 'changes': [['buy', '38282.47', '0.00000000']], 'time': '2021-05-20T03:54:42.457462Z'}
{'type': 'l2update', 'product_id': 'BTC-USD', 'changes': [['sell', '38290.66', '0.00000000']], 'time': '2021-05-20T03:54:42.457594Z'}
{'type': 'l2update', 'product_id': 'BTC-USD', 'changes': [['sell', '38410.71', '0.00000000']], 'time': '2021-05-20T03:54:42.459381Z'}
{'type': 'l2update', 'product_id': 'BTC-USD', 'changes': [['sell', '38331.86', '0.00000000']], 'time': '2021-05-20T03:54:42.459566Z'}
{'type': 'l2update', 'product_id': 'BTC-USD', 'changes': [['buy', '38164.74', '0.00000000']], 'time': '2021-05-20T03:54:42.459856Z'}
{'type': 'l2update', 'product_id': 'BTC-USD', 'changes': [['sell', '38290.34', '0.00000000']], 'time': '2021-05-20T03:54:42.465249Z'}
{'type': 'l2update', 'product_id': 'BTC-USD', 'changes': [['buy', '38265.29', '0.00000000']], 'time': '2021-05-20T03:54:42.466297Z'}
{'type': 'l2update', 'product_id': 'BTC-USD', 'changes': [['sell', '38442.46', '0.00000000']], 'time': '2021-05-20T03:54:42.470039Z'}
{'type': 'l2update', 'product_id': 'BTC-USD', 'changes': [['sell', '38394.98', '0.00000000']], 'time': '2021-05-20T03:54:42.472373Z'}
{'type': 'l2update', 'product_id': 'BTC-USD', 'changes': [['buy', '38282.58', '0.06274942']], 'time': '2021-05-20T03:54:42.473453Z'}
{'type': 'l2update', 'product_id': 'BTC-USD', 'changes': [['sell', '38359.06', '0.41206168']], 'time': '2021-05-20T03:54:42.473712Z'}
{'type': 'l2update', 'product_id': 'BTC-USD', 'changes': [['buy', '38178.37', '0.41206168']], 'time': '2021-05-20T03:54:42.473712Z'}
{'type': 'l2update', 'product_id': 'BTC-USD', 'changes': [['buy', '38184.80', '0.35403454']], 'time': '2021-05-20T03:54:42.473712Z'}
{'type': 'l2update', 'product_id': 'BTC-USD', 'changes': [['buy', '38197.09', '0.43433512']], 'time': '2021-05-20T03:54:42.473712Z'}
{'type': 'l2update', 'product_id': 'BTC-USD', 'changes': [['buy', '38282.34', '0.01492000']], 'time': '2021-05-20T03:54:42.474425Z'}
{'type': 'l2update', 'product_id': 'BTC-USD', 'changes': [['buy', '38271.79', '0.58716278']], 'time': '2021-05-20T03:54:42.474534Z'}
{'type': 'l2update', 'product_id': 'BTC-USD', 'changes': [['buy', '38258.98', '0.00000000']], 'time': '2021-05-20T03:54:42.476796Z'}
{'type': 'l2update', 'product_id': 'BTC-USD', 'changes': [['sell', '38299.57', '0.00000000']], 'time': '2021-05-20T03:54:42.476796Z'}
{'type': 'l2update', 'product_id': 'BTC-USD', 'changes': [['buy', '38263.90', '0.03969829']], 'time': '2021-05-20T03:54:42.478668Z'}
{'type': 'l2update', 'product_id': 'BTC-USD', 'changes': [['buy', '38282.34', '0.00000000']], 'time': '2021-05-20T03:54:42.482825Z'}
{'type': 'l2update', 'product_id': 'BTC-USD', 'changes': [['buy', '37436.01', '0.00000000']], 'time': '2021-05-20T03:54:42.483284Z'}
{'type': 'l2update', 'product_id': 'BTC-USD', 'changes': [['sell', '38290.48', '0.01492000']], 'time': '2021-05-20T03:54:42.483528Z'}
{'type': 'l2update', 'product_id': 'BTC-USD', 'changes': [['sell', '38338.92', '0.06589310']], 'time': '2021-05-20T03:54:42.483740Z'}
{'type': 'l2update', 'product_id': 'BTC-USD', 'changes': [['sell', '38457.52', '0.01000000']], 'time': '2021-05-20T03:54:42.483985Z'}
{'type': 'l2update', 'product_id': 'BTC-USD', 'changes': [['buy', '38271.79', '0.00000000']], 'time': '2021-05-20T03:54:42.490178Z'}
{'type': 'l2update', 'product_id': 'BTC-USD', 'changes': [['buy', '38197.09', '0.57484199']], 'time': '2021-05-20T03:54:42.490368Z'}
{'type': 'l2update', 'product_id': 'BTC-USD', 'changes': [['sell', '38358.96', '0.00000000']], 'time': '2021-05-20T03:54:42.490387Z'}
{'type': 'l2update', 'product_id': 'BTC-USD', 'changes': [['sell', '38290.61', '0.07460000']], 'time': '2021-05-20T03:54:42.490539Z'}
{'type': 'l2update', 'product_id': 'BTC-USD', 'changes': [['sell', '38432.47', '0.01000000']], 'time': '2021-05-20T03:54:42.490772Z'}
{'type': 'l2update', 'product_id': 'BTC-USD', 'changes': [['buy', '38256.86', '0.00000000']], 'time': '2021-05-20T03:54:42.490886Z'}
{'type': 'l2update', 'product_id': 'BTC-USD', 'changes': [['buy', '38139.06', '0.00000000']], 'time': '2021-05-20T03:54:42.496342Z'}
{'type': 'l2update', 'product_id': 'BTC-USD', 'changes': [['buy', '38141.83', '0.00000000']], 'time': '2021-05-20T03:54:42.496342Z'}
{'type': 'l2update', 'product_id': 'BTC-USD', 'changes': [['buy', '38143.43', '0.00000000']], 'time': '2021-05-20T03:54:42.496342Z'}
{'type': 'l2update', 'product_id': 'BTC-USD', 'changes': [['sell', '38290.61', '0.00000000']], 'time': '2021-05-20T03:54:42.497069Z'}
{'type': 'l2update', 'product_id': 'BTC-USD', 'changes': [['buy', '38268.87', '0.00000000']], 'time': '2021-05-20T03:54:42.497836Z'}
{'type': 'l2update', 'product_id': 'BTC-USD', 'changes': [['sell', '38315.08', '0.00000000']], 'time': '2021-05-20T03:54:42.498104Z'}
{'type': 'l2update', 'product_id': 'BTC-USD', 'changes': [['sell', '38374.73', '0.01567992']], 'time': '2021-05-20T03:54:42.499160Z'}
{'type': 'l2update', 'product_id': 'BTC-USD', 'changes': [['sell', '38291.02', '0.00000000']], 'time': '2021-05-20T03:54:42.499440Z'}
{'type': 'l2update', 'product_id': 'BTC-USD', 'changes': [['buy', '38271.78', '0.00000000']], 'time': '2021-05-20T03:54:42.502548Z'}
{'type': 'l2update', 'product_id': 'BTC-USD', 'changes': [['buy', '38116.54', '0.80355629']], 'time': '2021-05-20T03:54:42.511098Z'}
{'type': 'l2update', 'product_id': 'BTC-USD', 'changes': [['buy', '38270.04', '0.58716278']], 'time': '2021-05-20T03:54:42.511236Z'}
{'type': 'l2update', 'product_id': 'BTC-USD', 'changes': [['sell', '38376.16', '0.29326436']], 'time': '2021-05-20T03:54:42.511794Z'}
{'type': 'l2update', 'product_id': 'BTC-USD', 'changes': [['buy', '38143.43', '0.29326436']], 'time': '2021-05-20T03:54:42.511794Z'}
{'type': 'l2update', 'product_id': 'BTC-USD', 'changes': [['sell', '38457.52', '0.00000000']], 'time': '2021-05-20T03:54:42.514967Z'}
{'type': 'l2update', 'product_id': 'BTC-USD', 'changes': [['sell', '38393.73', '0.06684332']], 'time': '2021-05-20T03:54:42.517358Z'}
{'type': 'l2update', 'product_id': 'BTC-USD', 'changes': [['sell', '38364.57', '0.03645362']], 'time': '2021-05-20T03:54:42.517358Z'}
{'type': 'l2update', 'product_id': 'BTC-USD', 'changes': [['buy', '38164.27', '0.03038970']], 'time': '2021-05-20T03:54:42.517358Z'}
{'type': 'l2update', 'product_id': 'BTC-USD', 'changes': [['buy', '38233.48', '0.03036725']], 'time': '2021-05-20T03:54:42.517358Z'}
{'type': 'l2update', 'product_id': 'BTC-USD', 'changes': [['buy', '38268.81', '0.00000000']], 'time': '2021-05-20T03:54:42.517410Z'}
{'type': 'l2update', 'product_id': 'BTC-USD', 'changes': [['buy', '38263.90', '0.00000000']], 'time': '2021-05-20T03:54:42.517812Z'}
{'type': 'l2update', 'product_id': 'BTC-USD', 'changes': [['sell', '38291.02', '0.58027753']], 'time': '2021-05-20T03:54:42.520874Z'}
{'type': 'l2update', 'product_id': 'BTC-USD', 'changes': [['sell', '38393.73', '0.03038970']], 'time': '2021-05-20T03:54:42.522671Z'}
{'type': 'l2update', 'product_id': 'BTC-USD', 'changes': [['buy', '38210.33', '0.00000000']], 'time': '2021-05-20T03:54:42.522671Z'}
{'type': 'l2update', 'product_id': 'BTC-USD', 'changes': [['buy', '38260.84', '0.03969829']], 'time': '2021-05-20T03:54:42.524929Z'}
{'type': 'l2update', 'product_id': 'BTC-USD', 'changes': [['sell', '38376.70', '0.38337569']], 'time': '2021-05-20T03:54:42.524988Z'}
{'type': 'l2update', 'product_id': 'BTC-USD', 'changes': [['sell', '48370.48', '0.00497700']], 'time': '2021-05-20T03:54:42.527918Z'}
{'type': 'l2update', 'product_id': 'BTC-USD', 'changes': [['sell', '38440.57', '0.01000000']], 'time': '2021-05-20T03:54:42.528392Z'}
{'type': 'l2update', 'product_id': 'BTC-USD', 'changes': [['buy', '38270.04', '0.00000000']], 'time': '2021-05-20T03:54:42.529795Z'}
{'type': 'l2update', 'product_id': 'BTC-USD', 'changes': [['sell', '38309.87', '0.11061929']], 'time': '2021-05-20T03:54:42.536862Z'}
{'type': 'l2update', 'product_id': 'BTC-USD', 'changes': [['buy', '38121.64', '0.00000000']], 'time': '2021-05-20T03:54:42.547387Z'}
{'type': 'l2update', 'product_id': 'BTC-USD', 'changes': [['sell', '38293.61', '1.04100000']], 'time': '2021-05-20T03:54:42.552887Z'}
{'type': 'l2update', 'product_id': 'BTC-USD', 'changes': [['buy', '38248.67', '0.05192657']], 'time': '2021-05-20T03:54:42.561678Z'}
{'type': 'l2update', 'product_id': 'BTC-USD', 'changes': [['sell', '38299.56', '0.05463138']], 'time': '2021-05-20T03:54:42.561678Z'}
{'type': 'l2update', 'product_id': 'BTC-USD', 'changes': [['sell', '38389.05', '0.32984273']], 'time': '2021-05-20T03:54:42.561720Z'}
{'type': 'l2update', 'product_id': 'BTC-USD', 'changes': [['buy', '38164.41', '0.32984273']], 'time': '2021-05-20T03:54:42.561720Z'}
{'type': 'l2update', 'product_id': 'BTC-USD', 'changes': [['buy', '38240.52', '0.06739146']], 'time': '2021-05-20T03:54:42.561782Z'}
{'type': 'l2update', 'product_id': 'BTC-USD', 'changes': [['buy', '38265.28', '0.58716278']], 'time': '2021-05-20T03:54:42.568560Z'}
{'type': 'l2update', 'product_id': 'BTC-USD', 'changes': [['buy', '38248.56', '0.00000000']], 'time': '2021-05-20T03:54:42.570292Z'}
{'type': 'l2update', 'product_id': 'BTC-USD', 'changes': [['sell', '38402.16', '0.02904866']], 'time': '2021-05-20T03:54:42.575795Z'}
{'type': 'l2update', 'product_id': 'BTC-USD', 'changes': [['sell', '38395.51', '0.29874039']], 'time': '2021-05-20T03:54:42.579783Z'}
{'type': 'l2update', 'product_id': 'BTC-USD', 'changes': [['buy', '38157.42', '0.29874039']], 'time': '2021-05-20T03:54:42.579783Z'}
{'type': 'l2update', 'product_id': 'BTC-USD', 'changes': [['buy', '38258.73', '0.44960000']], 'time': '2021-05-20T03:54:42.588925Z'}
{'type': 'l2update', 'product_id': 'BTC-USD', 'changes': [['buy', '38231.95', '0.12268837']], 'time': '2021-05-20T03:54:42.589126Z'}
{'type': 'l2update', 'product_id': 'BTC-USD', 'changes': [['sell', '38393.73', '0.00000000']], 'time': '2021-05-20T03:54:42.592196Z'}
{'type': 'l2update', 'product_id': 'BTC-USD', 'changes': [['sell', '38359.05', '0.00000000']], 'time': '2021-05-20T03:54:42.592196Z'}
{'type': 'l2update', 'product_id': 'BTC-USD', 'changes': [['buy', '38245.81', '0.02400000']], 'time': '2021-05-20T03:54:42.592853Z'}
{'type': 'l2update', 'product_id': 'BTC-USD', 'changes': [['sell', '38402.16', '0.36371035']], 'time': '2021-05-20T03:54:42.639321Z'}
{'type': 'l2update', 'product_id': 'BTC-USD', 'changes': [['buy', '38150.24', '0.33466169']], 'time': '2021-05-20T03:54:42.639321Z'}
{'type': 'l2update', 'product_id': 'BTC-USD', 'changes': [['buy', '38282.04', '0.00000000']], 'time': '2021-05-20T03:54:42.639602Z'}
{'type': 'l2update', 'product_id': 'BTC-USD', 'changes': [['sell', '38501.40', '0.00000000']], 'time': '2021-05-20T03:54:42.642493Z'}
{'type': 'l2update', 'product_id': 'BTC-USD', 'changes': [['sell', '38313.14', '0.44250000']], 'time': '2021-05-20T03:54:42.646751Z'}
{'type': 'l2update', 'product_id': 'BTC-USD', 'changes': [['sell', '38395.51', '0.33219459']], 'time': '2021-05-20T03:54:42.654532Z'}
{'type': 'l2update', 'product_id': 'BTC-USD', 'changes': [['sell', '38370.26', '0.06295305']], 'time': '2021-05-20T03:54:42.654532Z'}
{'type': 'l2update', 'product_id': 'BTC-USD', 'changes': [['buy', '38263.89', '0.00000000']], 'time': '2021-05-20T03:54:42.657362Z'}
{'type': 'l2update', 'product_id': 'BTC-USD', 'changes': [['buy', '38282.58', '0.00000000']], 'time': '2021-05-20T03:54:42.675088Z'}
{'type': 'l2update', 'product_id': 'BTC-USD', 'changes': [['sell', '38402.16', '0.33466169']], 'time': '2021-05-20T03:54:42.682075Z'}
{'type': 'l2update', 'product_id': 'BTC-USD', 'changes': [['buy', '38269.92', '0.84800000']], 'time': '2021-05-20T03:54:42.684728Z'}
{'type': 'l2update', 'product_id': 'BTC-USD', 'changes': [['buy', '38270.30', '0.01185058']], 'time': '2021-05-20T03:54:42.684739Z'}
{'type': 'l2update', 'product_id': 'BTC-USD', 'changes': [['sell', '38489.24', '0.01000000']], 'time': '2021-05-20T03:54:42.688548Z'}
{'type': 'l2update', 'product_id': 'BTC-USD', 'changes': [['buy', '38258.74', '0.06061929']], 'time': '2021-05-20T03:54:42.688569Z'}
{'type': 'l2update', 'product_id': 'BTC-USD', 'changes': [['buy', '38282.59', '0.07240819']], 'time': '2021-05-20T03:54:42.688633Z'}
{'type': 'l2update', 'product_id': 'BTC-USD', 'changes': [['sell', '38409.00', '0.33246963']], 'time': '2021-05-20T03:54:42.688784Z'}
{'type': 'l2update', 'product_id': 'BTC-USD', 'changes': [['buy', '38270.30', '0.07460000']], 'time': '2021-05-20T03:54:42.692384Z'}
{'type': 'l2update', 'product_id': 'BTC-USD', 'changes': [['buy', '38279.54', '0.04934157']], 'time': '2021-05-20T03:54:42.695909Z'}
{'type': 'l2update', 'product_id': 'BTC-USD', 'changes': [['sell', '38289.91', '0.07460000']], 'time': '2021-05-20T03:54:42.696286Z'}
{'type': 'l2update', 'product_id': 'BTC-USD', 'changes': [['buy', '38270.35', '0.01492000']], 'time': '2021-05-20T03:54:42.696310Z'}
{'type': 'l2update', 'product_id': 'BTC-USD', 'changes': [['sell', '38314.58', '0.04847391']], 'time': '2021-05-20T03:54:42.700225Z'}
{'type': 'l2update', 'product_id': 'BTC-USD', 'changes': [['sell', '38295.88', '0.00000000']], 'time': '2021-05-20T03:54:42.703487Z'}
{'type': 'l2update', 'product_id': 'BTC-USD', 'changes': [['sell', '48373.94', '0.00497700']], 'time': '2021-05-20T03:54:42.704803Z'}
{'type': 'l2update', 'product_id': 'BTC-USD', 'changes': [['buy', '38248.67', '0.00000000']], 'time': '2021-05-20T03:54:42.707242Z'}
{'type': 'l2update', 'product_id': 'BTC-USD', 'changes': [['sell', '38299.56', '0.00000000']], 'time': '2021-05-20T03:54:42.707242Z'}
{'type': 'l2update', 'product_id': 'BTC-USD', 'changes': [['buy', '38270.30', '0.06274942']], 'time': '2021-05-20T03:54:42.708235Z'}
{'type': 'l2update', 'product_id': 'BTC-USD', 'changes': [['buy', '38270.35', '0.00000000']], 'time': '2021-05-20T03:54:42.714913Z'}
{'type': 'l2update', 'product_id': 'BTC-USD', 'changes': [['buy', '38260.84', '0.00000000']], 'time': '2021-05-20T03:54:42.717421Z'}
{'type': 'l2update', 'product_id': 'BTC-USD', 'changes': [['buy', '38270.30', '0.00000000']], 'time': '2021-05-20T03:54:42.718068Z'}
{'type': 'l2update', 'product_id': 'BTC-USD', 'changes': [['buy', '38178.56', '0.07800000']], 'time': '2021-05-20T03:54:42.718128Z'}
{'type': 'l2update', 'product_id': 'BTC-USD', 'changes': [['sell', '38319.25', '0.00000000']], 'time': '2021-05-20T03:54:42.721263Z'}
{'type': 'l2update', 'product_id': 'BTC-USD', 'changes': [['sell', '38416.04', '0.32076250']], 'time': '2021-05-20T03:54:42.722314Z'}
{'type': 'l2update', 'product_id': 'BTC-USD', 'changes': [['sell', '38395.51', '0.36695925']], 'time': '2021-05-20T03:54:42.722352Z'}
{'type': 'l2update', 'product_id': 'BTC-USD', 'changes': [['sell', '38338.92', '0.10234672']], 'time': '2021-05-20T03:54:42.722352Z'}
{'type': 'l2update', 'product_id': 'BTC-USD', 'changes': [['buy', '37436.01', '0.06613476']], 'time': '2021-05-20T03:54:42.722596Z'}
{'type': 'l2update', 'product_id': 'BTC-USD', 'changes': [['sell', '38290.48', '0.00000000']], 'time': '2021-05-20T03:54:42.730176Z'}
{'type': 'l2update', 'product_id': 'BTC-USD', 'changes': [['sell', '38289.91', '0.00000000']], 'time': '2021-05-20T03:54:42.730272Z'}
{'type': 'l2update', 'product_id': 'BTC-USD', 'changes': [['buy', '38236.54', '0.00000000']], 'time': '2021-05-20T03:54:42.730679Z'}
{'type': 'l2update', 'product_id': 'BTC-USD', 'changes': [['buy', '38160.00', '0.19720000']], 'time': '2021-05-20T03:54:42.738946Z'}
{'type': 'l2update', 'product_id': 'BTC-USD', 'changes': [['sell', '38364.57', '0.00000000']], 'time': '2021-05-20T03:54:42.740452Z'}
{'type': 'l2update', 'product_id': 'BTC-USD', 'changes': [['sell', '38423.27', '0.38374672']], 'time': '2021-05-20T03:54:42.746186Z'}
{'type': 'l2update', 'product_id': 'BTC-USD', 'changes': [['sell', '38432.47', '0.00000000']], 'time': '2021-05-20T03:54:42.750832Z'}
{'type': 'l2update', 'product_id': 'BTC-USD', 'changes': [['sell', '38290.54', '0.07460000']], 'time': '2021-05-20T03:54:42.756258Z'}
{'type': 'l2update', 'product_id': 'BTC-USD', 'changes': [['buy', '38231.54', '0.10000000']], 'time': '2021-05-20T03:54:42.756442Z'}
{'type': 'l2update', 'product_id': 'BTC-USD', 'changes': [['sell', '38290.66', '0.01492000']], 'time': '2021-05-20T03:54:42.756732Z'}
{'type': 'l2update', 'product_id': 'BTC-USD', 'changes': [['sell', '38595.63', '0.00000000']], 'time': '2021-05-20T03:54:42.760029Z'}
{'type': 'l2update', 'product_id': 'BTC-USD', 'changes': [['sell', '38291.02', '0.00000000']], 'time': '2021-05-20T03:54:42.763275Z'}
{'type': 'l2update', 'product_id': 'BTC-USD', 'changes': [['sell', '38290.66', '0.00000000']], 'time': '2021-05-20T03:54:42.763382Z'}
{'type': 'l2update', 'product_id': 'BTC-USD', 'changes': [['sell', '38470.79', '0.01000000']], 'time': '2021-05-20T03:54:42.764824Z'}
{'type': 'l2update', 'product_id': 'BTC-USD', 'changes': [['sell', '38402.17', '0.03242351']], 'time': '2021-05-20T03:54:42.765183Z'}
{'type': 'l2update', 'product_id': 'BTC-USD', 'changes': [['buy', '38258.73', '0.00000000']], 'time': '2021-05-20T03:54:42.782853Z'}
{'type': 'l2update', 'product_id': 'BTC-USD', 'changes': [['sell', '38309.87', '0.05000000']], 'time': '2021-05-20T03:54:42.783885Z'}
{'type': 'l2update', 'product_id': 'BTC-USD', 'changes': [['sell', '38313.14', '0.00000000']], 'time': '2021-05-20T03:54:42.788414Z'}
{'type': 'l2update', 'product_id': 'BTC-USD', 'changes': [['buy', '38257.12', '0.04895742']], 'time': '2021-05-20T03:54:42.788439Z'}
{'type': 'l2update', 'product_id': 'BTC-USD', 'changes': [['sell', '38297.69', '0.06301978']], 'time': '2021-05-20T03:54:42.788439Z'}
{'type': 'l2update', 'product_id': 'BTC-USD', 'changes': [['sell', '38290.53', '0.58027753']], 'time': '2021-05-20T03:54:42.788809Z'}
{'type': 'l2update', 'product_id': 'BTC-USD', 'changes': [['sell', '38313.13', '0.06061929']], 'time': '2021-05-20T03:54:42.793844Z'}
{'type': 'l2update', 'product_id': 'BTC-USD', 'changes': [['buy', '38258.74', '0.00000000']], 'time': '2021-05-20T03:54:42.794215Z'}
{'type': 'l2update', 'product_id': 'BTC-USD', 'changes': [['sell', '38290.54', '0.00000000']], 'time': '2021-05-20T03:54:42.797279Z'}
{'type': 'l2update', 'product_id': 'BTC-USD', 'changes': [['sell', '38595.61', '3.23362444']], 'time': '2021-05-20T03:54:42.803265Z'}
{'type': 'l2update', 'product_id': 'BTC-USD', 'changes': [['sell', '38440.57', '0.00000000']], 'time': '2021-05-20T03:54:42.805179Z'}
{'type': 'l2update', 'product_id': 'BTC-USD', 'changes': [['buy', '38265.33', '0.52200000']], 'time': '2021-05-20T03:54:42.809002Z'}
{'type': 'l2update', 'product_id': 'BTC-USD', 'changes': [['buy', '38250.01', '0.06061929']], 'time': '2021-05-20T03:54:42.809738Z'}
{'type': 'l2update', 'product_id': 'BTC-USD', 'changes': [['sell', '38395.51', '0.33219459']], 'time': '2021-05-20T03:54:42.810740Z'}
{'type': 'l2update', 'product_id': 'BTC-USD', 'changes': [['sell', '38321.43', '0.06061929']], 'time': '2021-05-20T03:54:42.814352Z'}
{'type': 'l2update', 'product_id': 'BTC-USD', 'changes': [['sell', '38455.64', '0.01000000']], 'time': '2021-05-20T03:54:42.821032Z'}
{'type': 'l2update', 'product_id': 'BTC-USD', 'changes': [['buy', '38258.75', '0.06061929']], 'time': '2021-05-20T03:54:42.821049Z'}
{'type': 'l2update', 'product_id': 'BTC-USD', 'changes': [['sell', '38313.13', '0.00000000']], 'time': '2021-05-20T03:54:42.826940Z'}
{'type': 'l2update', 'product_id': 'BTC-USD', 'changes': [['buy', '38258.75', '0.00000000']], 'time': '2021-05-20T03:54:42.832666Z'}
{'type': 'l2update', 'product_id': 'BTC-USD', 'changes': [['buy', '38250.01', '0.00000000']], 'time': '2021-05-20T03:54:42.839064Z'}
{'type': 'l2update', 'product_id': 'BTC-USD', 'changes': [['sell', '38402.17', '0.00000000']], 'time': '2021-05-20T03:54:42.843994Z'}
{'type': 'l2update', 'product_id': 'BTC-USD', 'changes': [['sell', '38395.51', '0.29874039']], 'time': '2021-05-20T03:54:42.843994Z'}
{'type': 'l2update', 'product_id': 'BTC-USD', 'changes': [['sell', '38370.26', '0.03390439']], 'time': '2021-05-20T03:54:42.843994Z'}
{'type': 'l2update', 'product_id': 'BTC-USD', 'changes': [['sell', '38338.92', '0.06589310']], 'time': '2021-05-20T03:54:42.843994Z'}
{'type': 'l2update', 'product_id': 'BTC-USD', 'changes': [['sell', '38290.53', '0.00000000']], 'time': '2021-05-20T03:54:42.850226Z'}
{'type': 'l2update', 'product_id': 'BTC-USD', 'changes': [['buy', '38250.01', '0.06061929']], 'time': '2021-05-20T03:54:42.852935Z'}
{'type': 'l2update', 'product_id': 'BTC-USD', 'changes': [['buy', '38290.48', '0.15000000']], 'time': '2021-05-20T03:54:42.854700Z'}
{'type': 'l2update', 'product_id': 'BTC-USD', 'changes': [['sell', '38291.28', '0.00000000']], 'time': '2021-05-20T03:54:42.860431Z'}
{'type': 'l2update', 'product_id': 'BTC-USD', 'changes': [['buy', '38250.01', '0.00000000']], 'time': '2021-05-20T03:54:42.861720Z'}
{'type': 'l2update', 'product_id': 'BTC-USD', 'changes': [['buy', '38282.86', '0.01492000']], 'time': '2021-05-20T03:54:42.865709Z'}
{'type': 'l2update', 'product_id': 'BTC-USD', 'changes': [['sell', '38290.49', '0.10000000']], 'time': '2021-05-20T03:54:42.869886Z'}
{'type': 'l2update', 'product_id': 'BTC-USD', 'changes': [['sell', '48377.40', '0.00490000']], 'time': '2021-05-20T03:54:42.870240Z'}
{'type': 'l2update', 'product_id': 'BTC-USD', 'changes': [['buy', '38260.84', '0.06061929']], 'time': '2021-05-20T03:54:42.870304Z'}
{'type': 'l2update', 'product_id': 'BTC-USD', 'changes': [['sell', '38455.64', '0.00000000']], 'time': '2021-05-20T03:54:42.870386Z'}
{'type': 'l2update', 'product_id': 'BTC-USD', 'changes': [['buy', '38282.86', '0.00000000']], 'time': '2021-05-20T03:54:42.870993Z'}
{'type': 'l2update', 'product_id': 'BTC-USD', 'changes': [['sell', '38291.02', '0.58027753']], 'time': '2021-05-20T03:54:42.873599Z'}
{'type': 'l2update', 'product_id': 'BTC-USD', 'changes': [['buy', '38256.28', '0.44940000']], 'time': '2021-05-20T03:54:42.876675Z'}
{'type': 'l2update', 'product_id': 'BTC-USD', 'changes': [['sell', '38395.51', '0.33401296']], 'time': '2021-05-20T03:54:42.877077Z'}
{'type': 'l2update', 'product_id': 'BTC-USD', 'changes': [['sell', '38290.49', '0.30000000']], 'time': '2021-05-20T03:54:42.880768Z'}
{'type': 'l2update', 'product_id': 'BTC-USD', 'changes': [['sell', '38442.46', '0.01000000']], 'time': '2021-05-20T03:54:42.884979Z'}
{'type': 'l2update', 'product_id': 'BTC-USD', 'changes': [['sell', '38290.49', '0.29812878']], 'time': '2021-05-20T03:54:42.888710Z'}
{'type': 'l2update', 'product_id': 'BTC-USD', 'changes': [['sell', '38310.59', '0.41200000']], 'time': '2021-05-20T03:54:42.888745Z'}
{'type': 'l2update', 'product_id': 'BTC-USD', 'changes': [['sell', '38352.38', '0.00000000']], 'time': '2021-05-20T03:54:42.895161Z'}
{'type': 'l2update', 'product_id': 'BTC-USD', 'changes': [['buy', '38231.77', '0.00000000']], 'time': '2021-05-20T03:54:42.895469Z'}
{'type': 'l2update', 'product_id': 'BTC-USD', 'changes': [['buy', '38278.18', '0.00389938']], 'time': '2021-05-20T03:54:42.896772Z'}
{'type': 'l2update', 'product_id': 'BTC-USD', 'changes': [['sell', '38470.79', '0.00000000']], 'time': '2021-05-20T03:54:42.902194Z'}
{'type': 'l2update', 'product_id': 'BTC-USD', 'changes': [['buy', '38256.28', '0.00000000']], 'time': '2021-05-20T03:54:42.903863Z'}
{'type': 'l2update', 'product_id': 'BTC-USD', 'changes': [['sell', '38432.32', '0.03044953']], 'time': '2021-05-20T03:54:42.912394Z'}
{'type': 'l2update', 'product_id': 'BTC-USD', 'changes': [['sell', '38310.59', '0.00000000']], 'time': '2021-05-20T03:54:42.912856Z'}
{'type': 'l2update', 'product_id': 'BTC-USD', 'changes': [['sell', '38349.00', '0.61482417']], 'time': '2021-05-20T03:54:42.916738Z'}
{'type': 'l2update', 'product_id': 'BTC-USD', 'changes': [['sell', '38322.94', '0.01402809']], 'time': '2021-05-20T03:54:42.916749Z'}
{'type': 'l2update', 'product_id': 'BTC-USD', 'changes': [['buy', '38228.40', '1.28318559']], 'time': '2021-05-20T03:54:42.916834Z'}
{'type': 'l2update', 'product_id': 'BTC-USD', 'changes': [['buy', '38269.87', '0.00000000']], 'time': '2021-05-20T03:54:42.920275Z'}
{'type': 'l2update', 'product_id': 'BTC-USD', 'changes': [['sell', '38413.68', '0.02966212']], 'time': '2021-05-20T03:54:42.921876Z'}
{'type': 'l2update', 'product_id': 'BTC-USD', 'changes': [['sell', '38413.68', '0.00000000']], 'time': '2021-05-20T03:54:42.921876Z'}
{'type': 'l2update', 'product_id': 'BTC-USD', 'changes': [['sell', '38406.84', '0.00000000']], 'time': '2021-05-20T03:54:42.921876Z'}
{'type': 'l2update', 'product_id': 'BTC-USD', 'changes': [['sell', '38370.26', '0.00000000']], 'time': '2021-05-20T03:54:42.921876Z'}
{'type': 'l2update', 'product_id': 'BTC-USD', 'changes': [['sell', '38338.92', '0.03507022']], 'time': '2021-05-20T03:54:42.921876Z'}
{'type': 'l2update', 'product_id': 'BTC-USD', 'changes': [['sell', '38338.92', '0.00000000']], 'time': '2021-05-20T03:54:42.921876Z'}
{'type': 'l2update', 'product_id': 'BTC-USD', 'changes': [['sell', '38595.60', '3.22890420']], 'time': '2021-05-20T03:54:42.929063Z'}
{'type': 'l2update', 'product_id': 'BTC-USD', 'changes': [['buy', '38282.59', '0.00000000']], 'time': '2021-05-20T03:54:42.932479Z'}
{'type': 'l2update', 'product_id': 'BTC-USD', 'changes': [['sell', '38595.62', '0.00000000']], 'time': '2021-05-20T03:54:42.935385Z'}
{'type': 'l2update', 'product_id': 'BTC-USD', 'changes': [['sell', '60000.00', '204.39801458']], 'time': '2021-05-20T03:54:42.937962Z'}
{'type': 'l2update', 'product_id': 'BTC-USD', 'changes': [['sell', '38321.44', '0.00000000']], 'time': '2021-05-20T03:54:42.942977Z'}
{'type': 'l2update', 'product_id': 'BTC-USD', 'changes': [['sell', '38321.43', '0.00000000']], 'time': '2021-05-20T03:54:42.948921Z'}
{'type': 'l2update', 'product_id': 'BTC-USD', 'changes': [['buy', '38268.81', '0.52100000']], 'time': '2021-05-20T03:54:42.950146Z'}
{'type': 'l2update', 'product_id': 'BTC-USD', 'changes': [['sell', '38325.39', '0.10000000']], 'time': '2021-05-20T03:54:42.950398Z'}
{'type': 'l2update', 'product_id': 'BTC-USD', 'changes': [['buy', '38290.48', '0.22240780']], 'time': '2021-05-20T03:54:42.955623Z'}
{'type': 'l2update', 'product_id': 'BTC-USD', 'changes': [['buy', '38285.17', '0.01192037']], 'time': '2021-05-20T03:54:42.956993Z'}
{'type': 'l2update', 'product_id': 'BTC-USD', 'changes': [['buy', '38290.48', '0.27240780']], 'time': '2021-05-20T03:54:42.957186Z'}
{'type': 'l2update', 'product_id': 'BTC-USD', 'changes': [['sell', '38334.31', '0.03222529']], 'time': '2021-05-20T03:54:42.957241Z'}
{'type': 'l2update', 'product_id': 'BTC-USD', 'changes': [['sell', '38325.84', '0.71565473']], 'time': '2021-05-20T03:54:42.957241Z'}
{'type': 'l2update', 'product_id': 'BTC-USD', 'changes': [['sell', '38325.83', '0.06061929']], 'time': '2021-05-20T03:54:42.961555Z'}
{'type': 'l2update', 'product_id': 'BTC-USD', 'changes': [['sell', '38325.38', '0.06061929']], 'time': '2021-05-20T03:54:42.965014Z'}
{'type': 'l2update', 'product_id': 'BTC-USD', 'changes': [['buy', '38185.98', '0.07800000']], 'time': '2021-05-20T03:54:42.965156Z'}
{'type': 'l2update', 'product_id': 'BTC-USD', 'changes': [['sell', '38395.51', '0.29874039']], 'time': '2021-05-20T03:54:42.965983Z'}
{'type': 'l2update', 'product_id': 'BTC-USD', 'changes': [['buy', '38260.84', '0.00000000']], 'time': '2021-05-20T03:54:42.966820Z'}
{'type': 'l2update', 'product_id': 'BTC-USD', 'changes': [['sell', '38613.44', '0.00000000']], 'time': '2021-05-20T03:54:42.969594Z'}
{'type': 'l2update', 'product_id': 'BTC-USD', 'changes': [['sell', '38355.85', '0.00000000']], 'time': '2021-05-20T03:54:42.969779Z'}
{'type': 'l2update', 'product_id': 'BTC-USD', 'changes': [['sell', '38325.83', '0.00000000']], 'time': '2021-05-20T03:54:42.971225Z'}
{'type': 'l2update', 'product_id': 'BTC-USD', 'changes': [['buy', '38265.34', '0.06061929']], 'time': '2021-05-20T03:54:42.975296Z'}
{'type': 'l2update', 'product_id': 'BTC-USD', 'changes': [['sell', '38352.17', '0.02898427']], 'time': '2021-05-20T03:54:42.980610Z'}
{'type': 'l2update', 'product_id': 'BTC-USD', 'changes': [['sell', '38598.45', '0.01295389']], 'time': '2021-05-20T03:54:42.980783Z'}
{'type': 'l2update', 'product_id': 'BTC-USD', 'changes': [['buy', '38207.44', '0.00000000']], 'time': '2021-05-20T03:54:42.994371Z'}
{'type': 'l2update', 'product_id': 'BTC-USD', 'changes': [['buy', '38261.90', '0.46310000']], 'time': '2021-05-20T03:54:42.995986Z'}
{'type': 'l2update', 'product_id': 'BTC-USD', 'changes': [['sell', '38342.33', '0.00000000']], 'time': '2021-05-20T03:54:42.997836Z'}
{'type': 'l2update', 'product_id': 'BTC-USD', 'changes': [['buy', '38261.90', '0.00000000']], 'time': '2021-05-20T03:54:42.999991Z'}
{'type': 'l2update', 'product_id': 'BTC-USD', 'changes': [['sell', '38311.96', '0.42650000']], 'time': '2021-05-20T03:54:43.009148Z'}
{'type': 'l2update', 'product_id': 'BTC-USD', 'changes': [['sell', '38347.42', '0.02935088']], 'time': '2021-05-20T03:54:43.009305Z'}
{'type': 'l2update', 'product_id': 'BTC-USD', 'changes': [['sell', '38325.38', '0.00000000']], 'time': '2021-05-20T03:54:43.022663Z'}
{'type': 'l2update', 'product_id': 'BTC-USD', 'changes': [['sell', '38311.96', '0.48711929']], 'time': '2021-05-20T03:54:43.025717Z'}
{'type': 'l2update', 'product_id': 'BTC-USD', 'changes': [['sell', '38311.96', '0.42650000']], 'time': '2021-05-20T03:54:43.031085Z'}
{'type': 'l2update', 'product_id': 'BTC-USD', 'changes': [['sell', '38364.25', '0.07800000']], 'time': '2021-05-20T03:54:43.033097Z'}
{'type': 'l2update', 'product_id': 'BTC-USD', 'changes': [['sell', '38311.95', '0.06061929']], 'time': '2021-05-20T03:54:43.033183Z'}
{'type': 'l2update', 'product_id': 'BTC-USD', 'changes': [['sell', '48380.85', '0.00505400']], 'time': '2021-05-20T03:54:43.037086Z'}
{'type': 'l2update', 'product_id': 'BTC-USD', 'changes': [['sell', '38598.45', '0.00000000']], 'time': '2021-05-20T03:54:43.060375Z'}
{'type': 'l2update', 'product_id': 'BTC-USD', 'changes': [['sell', '38583.45', '0.01295892']], 'time': '2021-05-20T03:54:43.071649Z'}
{'type': 'l2update', 'product_id': 'BTC-USD', 'changes': [['sell', '38311.96', '0.00000000']], 'time': '2021-05-20T03:54:43.075526Z'}
{'type': 'l2update', 'product_id': 'BTC-USD', 'changes': [['sell', '38374.73', '0.00000000']], 'time': '2021-05-20T03:54:43.080814Z'}
{'type': 'l2update', 'product_id': 'BTC-USD', 'changes': [['sell', '38297.69', '0.00000000']], 'time': '2021-05-20T03:54:43.081675Z'}
{'type': 'l2update', 'product_id': 'BTC-USD', 'changes': [['sell', '38311.95', '0.00000000']], 'time': '2021-05-20T03:54:43.082893Z'}
{'type': 'l2update', 'product_id': 'BTC-USD', 'changes': [['buy', '38264.12', '0.43720000']], 'time': '2021-05-20T03:54:43.091557Z'}
{'type': 'l2update', 'product_id': 'BTC-USD', 'changes': [['sell', '38325.38', '0.06061929']], 'time': '2021-05-20T03:54:43.091649Z'}
{'type': 'l2update', 'product_id': 'BTC-USD', 'changes': [['sell', '38452.36', '0.00000000']], 'time': '2021-05-20T03:54:43.092299Z'}
{'type': 'l2update', 'product_id': 'BTC-USD', 'changes': [['sell', '38297.59', '0.64900000']], 'time': '2021-05-20T03:54:43.095765Z'}
{'type': 'l2update', 'product_id': 'BTC-USD', 'changes': [['sell', '38394.98', '0.12935749']], 'time': '2021-05-20T03:54:43.099201Z'}
{'type': 'l2update', 'product_id': 'BTC-USD', 'changes': [['sell', '38438.51', '0.01000000']], 'time': '2021-05-20T03:54:43.103529Z'}
{'type': 'l2update', 'product_id': 'BTC-USD', 'changes': [['sell', '38300.86', '0.05627195']], 'time': '2021-05-20T03:54:43.108528Z'}
{'type': 'l2update', 'product_id': 'BTC-USD', 'changes': [['sell', '38442.46', '0.00000000']], 'time': '2021-05-20T03:54:43.117984Z'}
{'type': 'l2update', 'product_id': 'BTC-USD', 'changes': [['sell', '38455.64', '0.01000000']], 'time': '2021-05-20T03:54:43.130284Z'}
{'type': 'l2update', 'product_id': 'BTC-USD', 'changes': [['sell', '38325.38', '0.00000000']], 'time': '2021-05-20T03:54:43.138532Z'}
{'type': 'l2update', 'product_id': 'BTC-USD', 'changes': [['sell', '38310.49', '0.06061929']], 'time': '2021-05-20T03:54:43.151116Z'}
{'type': 'l2update', 'product_id': 'BTC-USD', 'changes': [['buy', '38251.21', '1.20000000']], 'time': '2021-05-20T03:54:43.155071Z'}
{'type': 'l2update', 'product_id': 'BTC-USD', 'changes': [['sell', '38357.11', '0.03875191']], 'time': '2021-05-20T03:54:43.164865Z'}
{'type': 'l2update', 'product_id': 'BTC-USD', 'changes': [['sell', '38386.10', '1.20000000']], 'time': '2021-05-20T03:54:43.168612Z'}
{'type': 'l2update', 'product_id': 'BTC-USD', 'changes': [['sell', '38310.77', '0.48300000']], 'time': '2021-05-20T03:54:43.170238Z'}
{'type': 'l2update', 'product_id': 'BTC-USD', 'changes': [['buy', '38269.51', '0.52254763']], 'time': '2021-05-20T03:54:43.170450Z'}
{'type': 'l2update', 'product_id': 'BTC-USD', 'changes': [['buy', '38265.28', '0.00000000']], 'time': '2021-05-20T03:54:43.175262Z'}
{'type': 'l2update', 'product_id': 'BTC-USD', 'changes': [['buy', '38246.94', '0.00000000']], 'time': '2021-05-20T03:54:43.176419Z'}
{'type': 'l2update', 'product_id': 'BTC-USD', 'changes': [['buy', '38245.81', '0.00000000']], 'time': '2021-05-20T03:54:43.176419Z'}
{'type': 'l2update', 'product_id': 'BTC-USD', 'changes': [['buy', '38247.75', '0.00000000']], 'time': '2021-05-20T03:54:43.181016Z'}
{'type': 'l2update', 'product_id': 'BTC-USD', 'changes': [['sell', '38292.99', '0.52252181']], 'time': '2021-05-20T03:54:43.184005Z'}
{'type': 'l2update', 'product_id': 'BTC-USD', 'changes': [['sell', '38310.49', '0.00000000']], 'time': '2021-05-20T03:54:43.184844Z'}
{'type': 'l2update', 'product_id': 'BTC-USD', 'changes': [['buy', '38268.77', '0.06061929']], 'time': '2021-05-20T03:54:43.189717Z'}
{'type': 'l2update', 'product_id': 'BTC-USD', 'changes': [['buy', '38265.34', '0.00000000']], 'time': '2021-05-20T03:54:43.192624Z'}
{'type': 'l2update', 'product_id': 'BTC-USD', 'changes': [['buy', '38270.04', '0.58716278']], 'time': '2021-05-20T03:54:43.193335Z'}
{'type': 'l2update', 'product_id': 'BTC-USD', 'changes': [['sell', '38309.88', '1.36713603']], 'time': '2021-05-20T03:54:43.193471Z'}
{'type': 'l2update', 'product_id': 'BTC-USD', 'changes': [['buy', '38266.81', '0.52258573']], 'time': '2021-05-20T03:54:43.193490Z'}
{'type': 'l2update', 'product_id': 'BTC-USD', 'changes': [['buy', '38253.18', '0.02400000']], 'time': '2021-05-20T03:54:43.198203Z'}
{'type': 'l2update', 'product_id': 'BTC-USD', 'changes': [['buy', '38252.37', '0.02400000']], 'time': '2021-05-20T03:54:43.198203Z'}
{'type': 'l2update', 'product_id': 'BTC-USD', 'changes': [['buy', '38251.57', '0.02400000']], 'time': '2021-05-20T03:54:43.198203Z'}
{'type': 'l2update', 'product_id': 'BTC-USD', 'changes': [['buy', '38268.77', '0.00000000']], 'time': '2021-05-20T03:54:43.198423Z'}
{'type': 'l2update', 'product_id': 'BTC-USD', 'changes': [['sell', '38309.87', '0.11061929']], 'time': '2021-05-20T03:54:43.198547Z'}
{'type': 'l2update', 'product_id': 'BTC-USD', 'changes': [['sell', '38309.88', '1.30651674']], 'time': '2021-05-20T03:54:43.200074Z'}
{'type': 'l2update', 'product_id': 'BTC-USD', 'changes': [['buy', '38253.18', '0.00000000']], 'time': '2021-05-20T03:54:43.203763Z'}
{'type': 'l2update', 'product_id': 'BTC-USD', 'changes': [['sell', '38297.12', '0.52256848']], 'time': '2021-05-20T03:54:43.207326Z'}
{'type': 'l2update', 'product_id': 'BTC-USD', 'changes': [['buy', '38268.82', '0.06061929']], 'time': '2021-05-20T03:54:43.207348Z'}
{'type': 'l2update', 'product_id': 'BTC-USD', 'changes': [['sell', '43100.00', '1.09530000']], 'time': '2021-05-20T03:54:43.214953Z'}
{'type': 'l2update', 'product_id': 'BTC-USD', 'changes': [['buy', '38269.52', '0.06061929']], 'time': '2021-05-20T03:54:43.217324Z'}
{'type': 'l2update', 'product_id': 'BTC-USD', 'changes': [['buy', '38263.89', '0.52257376']], 'time': '2021-05-20T03:54:43.217344Z'}
{'type': 'l2update', 'product_id': 'BTC-USD', 'changes': [['sell', '38367.56', '0.02727883']], 'time': '2021-05-20T03:54:43.217635Z'}
{'type': 'l2update', 'product_id': 'BTC-USD', 'changes': [['sell', '48387.77', '0.00497700']], 'time': '2021-05-20T03:54:43.217827Z'}
{'type': 'l2update', 'product_id': 'BTC-USD', 'changes': [['buy', '38268.82', '0.00000000']], 'time': '2021-05-20T03:54:43.218205Z'}
{'type': 'l2update', 'product_id': 'BTC-USD', 'changes': [['sell', '38304.51', '0.78386064']], 'time': '2021-05-20T03:54:43.228675Z'}
{'type': 'l2update', 'product_id': 'BTC-USD', 'changes': [['sell', '43100.00', '1.43430000']], 'time': '2021-05-20T03:54:43.228748Z'}
{'type': 'l2update', 'product_id': 'BTC-USD', 'changes': [['buy', '38254.20', '0.78382144']], 'time': '2021-05-20T03:54:43.241964Z'}
{'type': 'l2update', 'product_id': 'BTC-USD', 'changes': [['buy', '32000.00', '202.53552397']], 'time': '2021-05-20T03:54:43.242572Z'}
{'type': 'l2update', 'product_id': 'BTC-USD', 'changes': [['buy', '38269.93', '0.06061929']], 'time': '2021-05-20T03:54:43.247098Z'}
{'type': 'l2update', 'product_id': 'BTC-USD', 'changes': [['buy', '38269.52', '0.00000000']], 'time': '2021-05-20T03:54:43.252666Z'}
{'type': 'l2update', 'product_id': 'BTC-USD', 'changes': [['buy', '38269.93', '0.00000000']], 'time': '2021-05-20T03:54:43.255992Z'}
{'type': 'l2update', 'product_id': 'BTC-USD', 'changes': [['sell', '38316.30', '2.61310305']], 'time': '2021-05-20T03:54:43.257068Z'}
{'type': 'l2update', 'product_id': 'BTC-USD', 'changes': [['buy', '38250.44', '0.02400000']], 'time': '2021-05-20T03:54:43.257669Z'}
{'type': 'l2update', 'product_id': 'BTC-USD', 'changes': [['sell', '38309.87', '0.06061929']], 'time': '2021-05-20T03:54:43.265311Z'}
{'type': 'l2update', 'product_id': 'BTC-USD', 'changes': [['buy', '38248.15', '1.30632449']], 'time': '2021-05-20T03:54:43.268265Z'}
{'type': 'l2update', 'product_id': 'BTC-USD', 'changes': [['buy', '38270.05', '0.06061929']], 'time': '2021-05-20T03:54:43.274533Z'}
{'type': 'l2update', 'product_id': 'BTC-USD', 'changes': [['sell', '38336.94', '2.61273812']], 'time': '2021-05-20T03:54:43.279578Z'}
{'type': 'l2update', 'product_id': 'BTC-USD', 'changes': [['sell', '38316.29', '0.05000000']], 'time': '2021-05-20T03:54:43.279725Z'}
{'type': 'l2update', 'product_id': 'BTC-USD', 'changes': [['buy', '38175.35', '0.00000000']], 'time': '2021-05-20T03:54:43.283006Z'}
{'type': 'l2update', 'product_id': 'BTC-USD', 'changes': [['buy', '38231.54', '0.00000000']], 'time': '2021-05-20T03:54:43.287608Z'}
{'type': 'l2update', 'product_id': 'BTC-USD', 'changes': [['sell', '38293.61', '0.00000000']], 'time': '2021-05-20T03:54:43.290046Z'}
{'type': 'l2update', 'product_id': 'BTC-USD', 'changes': [['sell', '38309.88', '0.00000000']], 'time': '2021-05-20T03:54:43.292600Z'}
{'type': 'l2update', 'product_id': 'BTC-USD', 'changes': [['buy', '38187.91', '0.03577500']], 'time': '2021-05-20T03:54:43.297480Z'}
{'type': 'l2update', 'product_id': 'BTC-USD', 'changes': [['sell', '38300.81', '1.32500000']], 'time': '2021-05-20T03:54:43.301445Z'}
{'type': 'l2update', 'product_id': 'BTC-USD', 'changes': [['buy', '38229.54', '0.10000000']], 'time': '2021-05-20T03:54:43.301604Z'}
{'type': 'l2update', 'product_id': 'BTC-USD', 'changes': [['sell', '38438.51', '0.00000000']], 'time': '2021-05-20T03:54:43.314984Z'}
{'type': 'l2update', 'product_id': 'BTC-USD', 'changes': [['sell', '38455.64', '0.00000000']], 'time': '2021-05-20T03:54:43.321169Z'}
{'type': 'l2update', 'product_id': 'BTC-USD', 'changes': [['sell', '38378.77', '0.03269623']], 'time': '2021-05-20T03:54:43.327080Z'}
{'type': 'l2update', 'product_id': 'BTC-USD', 'changes': [['sell', '38436.80', '0.01000000']], 'time': '2021-05-20T03:54:43.333598Z'}
{'type': 'l2update', 'product_id': 'BTC-USD', 'changes': [['sell', '38451.61', '0.01000000']], 'time': '2021-05-20T03:54:43.337659Z'}
{'type': 'l2update', 'product_id': 'BTC-USD', 'changes': [['sell', '38297.07', '1.17300000']], 'time': '2021-05-20T03:54:43.337764Z'}
{'type': 'l2update', 'product_id': 'BTC-USD', 'changes': [['buy', '37506.50', '0.00000000']], 'time': '2021-05-20T03:54:43.340547Z'}
{'type': 'l2update', 'product_id': 'BTC-USD', 'changes': [['buy', '37506.22', '0.00000000']], 'time': '2021-05-20T03:54:43.340547Z'}
{'type': 'l2update', 'product_id': 'BTC-USD', 'changes': [['sell', '39249.99', '0.07360000']], 'time': '2021-05-20T03:54:43.340547Z'}
{'type': 'l2update', 'product_id': 'BTC-USD', 'changes': [['buy', '37505.01', '0.00000000']], 'time': '2021-05-20T03:54:43.340547Z'}
{'type': 'l2update', 'product_id': 'BTC-USD', 'changes': [['buy', '37500.01', '0.20160000']], 'time': '2021-05-20T03:54:43.349522Z'}
{'type': 'l2update', 'product_id': 'BTC-USD', 'changes': [['buy', '37500.02', '0.00170000']], 'time': '2021-05-20T03:54:43.349522Z'}
{'type': 'l2update', 'product_id': 'BTC-USD', 'changes': [['sell', '39499.99', '0.07960000']], 'time': '2021-05-20T03:54:43.349522Z'}
{'type': 'l2update', 'product_id': 'BTC-USD', 'changes': [['sell', '38520.00', '0.00000000']], 'time': '2021-05-20T03:54:43.368118Z'}
{'type': 'l2update', 'product_id': 'BTC-USD', 'changes': [['sell', '38293.66', '0.00000000']], 'time': '2021-05-20T03:54:43.377211Z'}
{'type': 'l2update', 'product_id': 'BTC-USD', 'changes': [['buy', '37436.01', '0.00000000']], 'time': '2021-05-20T03:54:43.379269Z'}
{'type': 'l2update', 'product_id': 'BTC-USD', 'changes': [['sell', '48398.14', '0.00497700']], 'time': '2021-05-20T03:54:43.385821Z'}
{'type': 'l2update', 'product_id': 'BTC-USD', 'changes': [['buy', '36256.00', '0.07861105']], 'time': '2021-05-20T03:54:43.402901Z'}
{'type': 'l2update', 'product_id': 'BTC-USD', 'changes': [['sell', '38325.46', '0.00000000']], 'time': '2021-05-20T03:54:43.423845Z'}
{'type': 'l2update', 'product_id': 'BTC-USD', 'changes': [['buy', '38243.15', '0.00000000']], 'time': '2021-05-20T03:54:43.428982Z'}
{'type': 'l2update', 'product_id': 'BTC-USD', 'changes': [['sell', '38364.67', '0.00000000']], 'time': '2021-05-20T03:54:43.430635Z'}
{'type': 'l2update', 'product_id': 'BTC-USD', 'changes': [['sell', '38325.84', '0.70402874']], 'time': '2021-05-20T03:54:43.431398Z'}
{'type': 'l2update', 'product_id': 'BTC-USD', 'changes': [['sell', '38382.32', '0.01589000']], 'time': '2021-05-20T03:54:43.444547Z'}
{'type': 'l2update', 'product_id': 'BTC-USD', 'changes': [['buy', '38118.20', '0.05032704']], 'time': '2021-05-20T03:54:43.452684Z'}
{'type': 'l2update', 'product_id': 'BTC-USD', 'changes': [['sell', '38340.86', '0.05287745']], 'time': '2021-05-20T03:54:43.452875Z'}
{'type': 'l2update', 'product_id': 'BTC-USD', 'changes': [['sell', '38300.86', '0.00000000']], 'time': '2021-05-20T03:54:43.462364Z'}
{'type': 'l2update', 'product_id': 'BTC-USD', 'changes': [['sell', '38583.45', '0.00000000']], 'time': '2021-05-20T03:54:43.464521Z'}
{'type': 'l2update', 'product_id': 'BTC-USD', 'changes': [['sell', '38384.66', '0.03882824']], 'time': '2021-05-20T03:54:43.464576Z'}
{'type': 'l2update', 'product_id': 'BTC-USD', 'changes': [['sell', '38568.45', '0.01296396']], 'time': '2021-05-20T03:54:43.475997Z'}
{'type': 'l2update', 'product_id': 'BTC-USD', 'changes': [['sell', '38390.74', '0.03534523']], 'time': '2021-05-20T03:54:43.491464Z'}
{'type': 'l2update', 'product_id': 'BTC-USD', 'changes': [['sell', '38297.69', '0.06509016']], 'time': '2021-05-20T03:54:43.491689Z'}
{'type': 'l2update', 'product_id': 'BTC-USD', 'changes': [['buy', '38264.12', '0.00000000']], 'time': '2021-05-20T03:54:43.502169Z'}
{'type': 'l2update', 'product_id': 'BTC-USD', 'changes': [['buy', '38285.17', '0.00000000']], 'time': '2021-05-20T03:54:43.515733Z'}
{'type': 'l2update', 'product_id': 'BTC-USD', 'changes': [['sell', '38397.01', '0.03291880']], 'time': '2021-05-20T03:54:43.520323Z'}
{'type': 'l2update', 'product_id': 'BTC-USD', 'changes': [['sell', '38294.42', '0.64600000']], 'time': '2021-05-20T03:54:43.528129Z'}
{'type': 'l2update', 'product_id': 'BTC-USD', 'changes': [['sell', '38394.98', '0.00000000']], 'time': '2021-05-20T03:54:43.533948Z'}
{'type': 'l2update', 'product_id': 'BTC-USD', 'changes': [['sell', '38436.80', '0.00000000']], 'time': '2021-05-20T03:54:43.534746Z'}
{'type': 'l2update', 'product_id': 'BTC-USD', 'changes': [['sell', '38457.52', '0.01000000']], 'time': '2021-05-20T03:54:43.547729Z'}
{'type': 'l2update', 'product_id': 'BTC-USD', 'changes': [['sell', '38403.47', '0.02642858']], 'time': '2021-05-20T03:54:43.551961Z'}
{'type': 'l2update', 'product_id': 'BTC-USD', 'changes': [['buy', '38262.42', '0.42880000']], 'time': '2021-05-20T03:54:43.552292Z'}
{'type': 'l2update', 'product_id': 'BTC-USD', 'changes': [['sell', '38457.52', '0.00000000']], 'time': '2021-05-20T03:54:43.560204Z'}
{'type': 'l2update', 'product_id': 'BTC-USD', 'changes': [['sell', '38382.66', '0.01000000']], 'time': '2021-05-20T03:54:43.562849Z'}
{'type': 'l2update', 'product_id': 'BTC-USD', 'changes': [['sell', '48411.97', '0.00497700']], 'time': '2021-05-20T03:54:43.565845Z'}
{'type': 'l2update', 'product_id': 'BTC-USD', 'changes': [['sell', '38310.77', '0.00000000']], 'time': '2021-05-20T03:54:43.566916Z'}
{'type': 'l2update', 'product_id': 'BTC-USD', 'changes': [['sell', '38436.80', '0.01000000']], 'time': '2021-05-20T03:54:43.574357Z'}
{'type': 'l2update', 'product_id': 'BTC-USD', 'changes': [['sell', '38568.45', '0.00000000']], 'time': '2021-05-20T03:54:43.577493Z'}
{'type': 'l2update', 'product_id': 'BTC-USD', 'changes': [['sell', '38309.20', '0.41050000']], 'time': '2021-05-20T03:54:43.578527Z'}
{'type': 'l2update', 'product_id': 'BTC-USD', 'changes': [['sell', '38410.12', '0.03210155']], 'time': '2021-05-20T03:54:43.582209Z'}
{'type': 'l2update', 'product_id': 'BTC-USD', 'changes': [['sell', '38309.87', '0.00000000']], 'time': '2021-05-20T03:54:43.590312Z'}
{'type': 'l2update', 'product_id': 'BTC-USD', 'changes': [['sell', '38553.46', '0.01296900']], 'time': '2021-05-20T03:54:43.590496Z'}
{'type': 'l2update', 'product_id': 'BTC-USD', 'changes': [['sell', '38304.50', '0.05541309']], 'time': '2021-05-20T03:54:43.590720Z'}
{'type': 'l2update', 'product_id': 'BTC-USD', 'changes': [['sell', '38290.49', '0.28943570']], 'time': '2021-05-20T03:54:43.603309Z'}
{'type': 'l2update', 'product_id': 'BTC-USD', 'changes': [['sell', '38294.42', '1.78900000']], 'time': '2021-05-20T03:54:43.606601Z'}
{'type': 'l2update', 'product_id': 'BTC-USD', 'changes': [['sell', '38301.64', '0.00000000']], 'time': '2021-05-20T03:54:43.612300Z'}
{'type': 'l2update', 'product_id': 'BTC-USD', 'changes': [['sell', '38309.19', '0.05541309']], 'time': '2021-05-20T03:54:43.618824Z'}
{'type': 'l2update', 'product_id': 'BTC-USD', 'changes': [['buy', '38118.20', '0.00000000']], 'time': '2021-05-20T03:54:43.619629Z'}
{'type': 'l2update', 'product_id': 'BTC-USD', 'changes': [['sell', '38304.50', '0.00000000']], 'time': '2021-05-20T03:54:43.622520Z'}
{'type': 'l2update', 'product_id': 'BTC-USD', 'changes': [['sell', '38309.44', '0.04824969']], 'time': '2021-05-20T03:54:43.627628Z'}
{'type': 'l2update', 'product_id': 'BTC-USD', 'changes': [['sell', '38489.24', '0.00000000']], 'time': '2021-05-20T03:54:43.628161Z'}
{'type': 'l2update', 'product_id': 'BTC-USD', 'changes': [['sell', '38336.08', '0.50000000']], 'time': '2021-05-20T03:54:43.630795Z'}
{'type': 'l2update', 'product_id': 'BTC-USD', 'changes': [['sell', '38314.58', '0.00000000']], 'time': '2021-05-20T03:54:43.649216Z'}
{'type': 'l2update', 'product_id': 'BTC-USD', 'changes': [['buy', '38111.77', '0.05197401']], 'time': '2021-05-20T03:54:43.656859Z'}
{'type': 'l2update', 'product_id': 'BTC-USD', 'changes': [['sell', '38478.55', '0.01000000']], 'time': '2021-05-20T03:54:43.666101Z'}
{'type': 'l2update', 'product_id': 'BTC-USD', 'changes': [['sell', '38320.03', '0.10000000']], 'time': '2021-05-20T03:54:43.670198Z'}
{'type': 'l2update', 'product_id': 'BTC-USD', 'changes': [['buy', '38133.98', '0.00000000']], 'time': '2021-05-20T03:54:43.721244Z'}
{'type': 'l2update', 'product_id': 'BTC-USD', 'changes': [['buy', '38263.89', '0.52407376']], 'time': '2021-05-20T03:54:43.721812Z'}
{'type': 'l2update', 'product_id': 'BTC-USD', 'changes': [['sell', '48442.62', '0.00700800']], 'time': '2021-05-20T03:54:43.733402Z'}
{'type': 'l2update', 'product_id': 'BTC-USD', 'changes': [['sell', '38290.49', '0.21262331']], 'time': '2021-05-20T03:54:43.766514Z'}
{'type': 'l2update', 'product_id': 'BTC-USD', 'changes': [['buy', '38192.20', '0.00000000']], 'time': '2021-05-20T03:54:43.814423Z'}
{'type': 'l2update', 'product_id': 'BTC-USD', 'changes': [['buy', '38252.37', '0.00000000']], 'time': '2021-05-20T03:54:43.823905Z'}
{'type': 'l2update', 'product_id': 'BTC-USD', 'changes': [['buy', '38251.57', '0.00000000']], 'time': '2021-05-20T03:54:43.823905Z'}
{'type': 'l2update', 'product_id': 'BTC-USD', 'changes': [['buy', '38250.44', '0.00000000']], 'time': '2021-05-20T03:54:43.823905Z'}
{'type': 'l2update', 'product_id': 'BTC-USD', 'changes': [['buy', '38255.01', '0.02400000']], 'time': '2021-05-20T03:54:43.839039Z'}
{'type': 'l2update', 'product_id': 'BTC-USD', 'changes': [['buy', '38254.21', '0.02400000']], 'time': '2021-05-20T03:54:43.839039Z'}
{'type': 'l2update', 'product_id': 'BTC-USD', 'changes': [['buy', '38253.40', '0.02400000']], 'time': '2021-05-20T03:54:43.839039Z'}
{'type': 'l2update', 'product_id': 'BTC-USD', 'changes': [['buy', '38262.42', '0.00000000']], 'time': '2021-05-20T03:54:43.873882Z'}
{'type': 'l2update', 'product_id': 'BTC-USD', 'changes': [['sell', '38309.20', '0.00000000']], 'time': '2021-05-20T03:54:43.878810Z'}
{'type': 'l2update', 'product_id': 'BTC-USD', 'changes': [['buy', '38255.01', '0.00000000']], 'time': '2021-05-20T03:54:43.881638Z'}
{'type': 'l2update', 'product_id': 'BTC-USD', 'changes': [['sell', '38309.19', '0.00000000']], 'time': '2021-05-20T03:54:43.886190Z'}
{'type': 'l2update', 'product_id': 'BTC-USD', 'changes': [['sell', '38310.49', '0.05541309']], 'time': '2021-05-20T03:54:43.893390Z'}
{'type': 'l2update', 'product_id': 'BTC-USD', 'changes': [['buy', '37436.01', '0.06953501']], 'time': '2021-05-20T03:54:43.893426Z'}
{'type': 'l2update', 'product_id': 'BTC-USD', 'changes': [['buy', '38252.12', '0.02400000']], 'time': '2021-05-20T03:54:43.901478Z'}
{'type': 'l2update', 'product_id': 'BTC-USD', 'changes': [['sell', '48446.08', '0.00700800']], 'time': '2021-05-20T03:54:43.901514Z'}
{'type': 'l2update', 'product_id': 'BTC-USD', 'changes': [['buy', '38229.54', '0.00000000']], 'time': '2021-05-20T03:54:43.928279Z'}
{'type': 'l2update', 'product_id': 'BTC-USD', 'changes': [['buy', '38228.54', '0.10000000']], 'time': '2021-05-20T03:54:43.938670Z'}
{'type': 'l2update', 'product_id': 'BTC-USD', 'changes': [['sell', '38553.46', '0.00000000']], 'time': '2021-05-20T03:54:43.940501Z'}
{'type': 'l2update', 'product_id': 'BTC-USD', 'changes': [['buy', '38111.59', '0.00000000']], 'time': '2021-05-20T03:54:43.944330Z'}
{'type': 'l2update', 'product_id': 'BTC-USD', 'changes': [['sell', '38613.44', '0.01000000']], 'time': '2021-05-20T03:54:43.954802Z'}
{'type': 'l2update', 'product_id': 'BTC-USD', 'changes': [['sell', '38467.05', '0.00000000']], 'time': '2021-05-20T03:54:43.960162Z'}
{'type': 'l2update', 'product_id': 'BTC-USD', 'changes': [['sell', '38290.49', '0.21835331']], 'time': '2021-05-20T03:54:43.962375Z'}
{'type': 'l2update', 'product_id': 'BTC-USD', 'changes': [['buy', '38263.89', '0.52257376']], 'time': '2021-05-20T03:54:43.964312Z'}
{'type': 'l2update', 'product_id': 'BTC-USD', 'changes': [['buy', '38263.30', '0.44500000']], 'time': '2021-05-20T03:54:43.966446Z'}
{'type': 'l2update', 'product_id': 'BTC-USD', 'changes': [['buy', '38096.67', '0.01000000']], 'time': '2021-05-20T03:54:43.969765Z'}
{'type': 'l2update', 'product_id': 'BTC-USD', 'changes': [['sell', '38482.94', '0.01000000']], 'time': '2021-05-20T03:54:43.973092Z'}
{'type': 'l2update', 'product_id': 'BTC-USD', 'changes': [['sell', '38308.96', '0.45910000']], 'time': '2021-05-20T03:54:43.977280Z'}
{'type': 'l2update', 'product_id': 'BTC-USD', 'changes': [['sell', '38304.51', '0.83927373']], 'time': '2021-05-20T03:54:43.993954Z'}
{'type': 'l2update', 'product_id': 'BTC-USD', 'changes': [['buy', '38178.55', '0.00000000']], 'time': '2021-05-20T03:54:43.997972Z'}
{'type': 'l2update', 'product_id': 'BTC-USD', 'changes': [['sell', '38482.94', '0.00000000']], 'time': '2021-05-20T03:54:44.004875Z'}
{'type': 'l2update', 'product_id': 'BTC-USD', 'changes': [['buy', '38166.80', '0.01000000']], 'time': '2021-05-20T03:54:44.013763Z'}
{'type': 'l2update', 'product_id': 'BTC-USD', 'changes': [['buy', '38219.13', '2.70270000']], 'time': '2021-05-20T03:54:44.017627Z'}
{'type': 'l2update', 'product_id': 'BTC-USD', 'changes': [['sell', '38464.19', '0.01000000']], 'time': '2021-05-20T03:54:44.025376Z'}
{'type': 'l2update', 'product_id': 'BTC-USD', 'changes': [['sell', '48449.54', '0.00700800']], 'time': '2021-05-20T03:54:44.053644Z'}
{'type': 'l2update', 'product_id': 'BTC-USD', 'changes': [['sell', '38309.44', '0.00000000']], 'time': '2021-05-20T03:54:44.060133Z'}
{'type': 'l2update', 'product_id': 'BTC-USD', 'changes': [['buy', '38117.11', '0.05135028']], 'time': '2021-05-20T03:54:44.062042Z'}
{'type': 'l2update', 'product_id': 'BTC-USD', 'changes': [['sell', '38613.44', '0.00000000']], 'time': '2021-05-20T03:54:44.084308Z'}
{'type': 'l2update', 'product_id': 'BTC-USD', 'changes': [['buy', '38263.30', '0.00000000']], 'time': '2021-05-20T03:54:44.094269Z'}
{'type': 'l2update', 'product_id': 'BTC-USD', 'changes': [['sell', '38523.47', '0.01000000']], 'time': '2021-05-20T03:54:44.096212Z'}
{'type': 'l2update', 'product_id': 'BTC-USD', 'changes': [['buy', '38096.67', '0.00000000']], 'time': '2021-05-20T03:54:44.101930Z'}
{'type': 'l2update', 'product_id': 'BTC-USD', 'changes': [['buy', '38261.87', '0.41920000']], 'time': '2021-05-20T03:54:44.104710Z'}
{'type': 'l2update', 'product_id': 'BTC-USD', 'changes': [['buy', '37933.35', '0.00000000']], 'time': '2021-05-20T03:54:44.106020Z'}
{'type': 'l2update', 'product_id': 'BTC-USD', 'changes': [['sell', '38304.51', '0.78386064']], 'time': '2021-05-20T03:54:44.107203Z'}
{'type': 'l2update', 'product_id': 'BTC-USD', 'changes': [['buy', '38240.39', '0.00000000']], 'time': '2021-05-20T03:54:44.109681Z'}
{'type': 'l2update', 'product_id': 'BTC-USD', 'changes': [['buy', '38111.59', '0.01000000']], 'time': '2021-05-20T03:54:44.111502Z'}
{'type': 'l2update', 'product_id': 'BTC-USD', 'changes': [['buy', '38146.59', '0.00000000']], 'time': '2021-05-20T03:54:44.113179Z'}
{'type': 'l2update', 'product_id': 'BTC-USD', 'changes': [['sell', '38308.95', '0.05541309']], 'time': '2021-05-20T03:54:44.119784Z'}
{'type': 'l2update', 'product_id': 'BTC-USD', 'changes': [['buy', '38086.15', '0.00000000']], 'time': '2021-05-20T03:54:44.120929Z'}
{'type': 'l2update', 'product_id': 'BTC-USD', 'changes': [['buy', '38265.27', '0.00000000']], 'time': '2021-05-20T03:54:44.128624Z'}
{'type': 'l2update', 'product_id': 'BTC-USD', 'changes': [['sell', '38514.26', '0.00000000']], 'time': '2021-05-20T03:54:44.131567Z'}
{'type': 'l2update', 'product_id': 'BTC-USD', 'changes': [['buy', '38290.48', '0.12240780']], 'time': '2021-05-20T03:54:44.133266Z'}
{'type': 'l2update', 'product_id': 'BTC-USD', 'changes': [['buy', '38187.91', '0.00000000']], 'time': '2021-05-20T03:54:44.141995Z'}
{'type': 'l2update', 'product_id': 'BTC-USD', 'changes': [['buy', '38201.09', '0.03577500']], 'time': '2021-05-20T03:54:44.152200Z'}
{'type': 'l2update', 'product_id': 'BTC-USD', 'changes': [['sell', '38320.03', '0.00000000']], 'time': '2021-05-20T03:54:44.152402Z'}
{'type': 'l2update', 'product_id': 'BTC-USD', 'changes': [['buy', '38111.77', '0.00000000']], 'time': '2021-05-20T03:54:44.181216Z'}
{'type': 'l2update', 'product_id': 'BTC-USD', 'changes': [['sell', '38436.80', '0.00000000']], 'time': '2021-05-20T03:54:44.186262Z'}
{'type': 'l2update', 'product_id': 'BTC-USD', 'changes': [['sell', '38457.52', '0.01000000']], 'time': '2021-05-20T03:54:44.195946Z'}
{'type': 'l2update', 'product_id': 'BTC-USD', 'changes': [['sell', '38290.49', '0.20573000']], 'time': '2021-05-20T03:54:44.203711Z'}
{'type': 'l2update', 'product_id': 'BTC-USD', 'changes': [['sell', '38290.49', '0.19274918']], 'time': '2021-05-20T03:54:44.203711Z'}
{'type': 'l2update', 'product_id': 'BTC-USD', 'changes': [['sell', '43100.00', '1.09530000']], 'time': '2021-05-20T03:54:44.214965Z'}
{'type': 'l2update', 'product_id': 'BTC-USD', 'changes': [['sell', '38336.83', '0.00000000']], 'time': '2021-05-20T03:54:44.219750Z'}
{'type': 'l2update', 'product_id': 'BTC-USD', 'changes': [['sell', '38290.49', '0.29274918']], 'time': '2021-05-20T03:54:44.220618Z'}
{'type': 'l2update', 'product_id': 'BTC-USD', 'changes': [['sell', '48453.01', '0.00700800']], 'time': '2021-05-20T03:54:44.220924Z'}
{'type': 'l2update', 'product_id': 'BTC-USD', 'changes': [['sell', '38290.49', '0.27993433']], 'time': '2021-05-20T03:54:44.228117Z'}
{'type': 'l2update', 'product_id': 'BTC-USD', 'changes': [['sell', '43100.00', '2.46450000']], 'time': '2021-05-20T03:54:44.232191Z'}
{'type': 'l2update', 'product_id': 'BTC-USD', 'changes': [['buy', '38261.87', '0.00000000']], 'time': '2021-05-20T03:54:44.268206Z'}
{'type': 'l2update', 'product_id': 'BTC-USD', 'changes': [['sell', '38308.96', '0.00000000']], 'time': '2021-05-20T03:54:44.272607Z'}
{'type': 'l2update', 'product_id': 'BTC-USD', 'changes': [['sell', '38382.66', '0.00000000']], 'time': '2021-05-20T03:54:44.273345Z'}
{'type': 'l2update', 'product_id': 'BTC-USD', 'changes': [['sell', '38393.75', '0.02938800']], 'time': '2021-05-20T03:54:44.284900Z'}
{'type': 'l2update', 'product_id': 'BTC-USD', 'changes': [['sell', '38294.42', '0.64600000']], 'time': '2021-05-20T03:54:44.311460Z'}
{'type': 'l2update', 'product_id': 'BTC-USD', 'changes': [['sell', '38301.63', '1.33100000']], 'time': '2021-05-20T03:54:44.322490Z'}
{'type': 'l2update', 'product_id': 'BTC-USD', 'changes': [['buy', '38201.09', '0.00000000']], 'time': '2021-05-20T03:54:44.340608Z'}
{'type': 'l2update', 'product_id': 'BTC-USD', 'changes': [['buy', '38178.49', '0.01000000']], 'time': '2021-05-20T03:54:44.351639Z'}
{'type': 'l2update', 'product_id': 'BTC-USD', 'changes': [['buy', '38257.12', '0.00000000']], 'time': '2021-05-20T03:54:44.361015Z'}
{'type': 'l2update', 'product_id': 'BTC-USD', 'changes': [['sell', '38297.69', '0.00000000']], 'time': '2021-05-20T03:54:44.361015Z'}
{'type': 'l2update', 'product_id': 'BTC-USD', 'changes': [['buy', '38261.82', '0.46920000']], 'time': '2021-05-20T03:54:44.361530Z'}
{'type': 'l2update', 'product_id': 'BTC-USD', 'changes': [['sell', '38309.19', '0.45810000']], 'time': '2021-05-20T03:54:44.372911Z'}
{'type': 'l2update', 'product_id': 'BTC-USD', 'changes': [['sell', '38309.19', '0.00000000']], 'time': '2021-05-20T03:54:44.377432Z'}
{'type': 'l2update', 'product_id': 'BTC-USD', 'changes': [['sell', '38297.07', '0.00000000']], 'time': '2021-05-20T03:54:44.380958Z'}
{'type': 'l2update', 'product_id': 'BTC-USD', 'changes': [['sell', '38442.97', '0.00000000']], 'time': '2021-05-20T03:54:44.382298Z'}
{'type': 'l2update', 'product_id': 'BTC-USD', 'changes': [['buy', '37436.01', '0.00000000']], 'time': '2021-05-20T03:54:44.382953Z'}
{'type': 'l2update', 'product_id': 'BTC-USD', 'changes': [['sell', '38294.47', '0.00000000']], 'time': '2021-05-20T03:54:44.384552Z'}
{'type': 'l2update', 'product_id': 'BTC-USD', 'changes': [['sell', '38294.42', '0.00000000']], 'time': '2021-05-20T03:54:44.389926Z'}
{'type': 'l2update', 'product_id': 'BTC-USD', 'changes': [['buy', '38290.48', '0.27240780']], 'time': '2021-05-20T03:54:44.390787Z'}
{'type': 'l2update', 'product_id': 'BTC-USD', 'changes': [['buy', '37466.13', '0.00905385']], 'time': '2021-05-20T03:54:44.396346Z'}
{'type': 'l2update', 'product_id': 'BTC-USD', 'changes': [['sell', '38301.63', '2.52400000']], 'time': '2021-05-20T03:54:44.396381Z'}
{'type': 'l2update', 'product_id': 'BTC-USD', 'changes': [['sell', '38430.84', '0.01000000']], 'time': '2021-05-20T03:54:44.396430Z'}
{'type': 'l2update', 'product_id': 'BTC-USD', 'changes': [['sell', '48456.47', '0.00700800']], 'time': '2021-05-20T03:54:44.396441Z'}
{'type': 'l2update', 'product_id': 'BTC-USD', 'changes': [['buy', '38258.18', '0.05293821']], 'time': '2021-05-20T03:54:44.396482Z'}
{'type': 'l2update', 'product_id': 'BTC-USD', 'changes': [['sell', '38298.75', '0.05767308']], 'time': '2021-05-20T03:54:44.396482Z'}
{'type': 'l2update', 'product_id': 'BTC-USD', 'changes': [['sell', '38308.95', '0.00000000']], 'time': '2021-05-20T03:54:44.397958Z'}
{'type': 'l2update', 'product_id': 'BTC-USD', 'changes': [['sell', '38457.52', '0.00000000']], 'time': '2021-05-20T03:54:44.404104Z'}
{'type': 'l2update', 'product_id': 'BTC-USD', 'changes': [['sell', '38301.63', '3.15700000']], 'time': '2021-05-20T03:54:44.408542Z'}
{'type': 'l2update', 'product_id': 'BTC-USD', 'changes': [['sell', '38328.70', '0.01000000']], 'time': '2021-05-20T03:54:44.418140Z'}
{'type': 'l2update', 'product_id': 'BTC-USD', 'changes': [['sell', '38308.94', '0.05541309']], 'time': '2021-05-20T03:54:44.418228Z'}
{'type': 'l2update', 'product_id': 'BTC-USD', 'changes': [['sell', '38444.34', '0.01000000']], 'time': '2021-05-20T03:54:44.418926Z'}
{'type': 'l2update', 'product_id': 'BTC-USD', 'changes': [['buy', '38246.38', '0.01000000']], 'time': '2021-05-20T03:54:44.431216Z'}
{'type': 'l2update', 'product_id': 'BTC-USD', 'changes': [['sell', '38308.94', '0.00000000']], 'time': '2021-05-20T03:54:44.431559Z'}
{'type': 'l2update', 'product_id': 'BTC-USD', 'changes': [['buy', '30300.00', '9.15433517']], 'time': '2021-05-20T03:54:44.435490Z'}
{'type': 'l2update', 'product_id': 'BTC-USD', 'changes': [['buy', '38290.48', '0.12240780']], 'time': '2021-05-20T03:54:44.440854Z'}
{'type': 'l2update', 'product_id': 'BTC-USD', 'changes': [['buy', '38228.90', '0.02870732']], 'time': '2021-05-20T03:54:44.442982Z'}
{'type': 'l2update', 'product_id': 'BTC-USD', 'changes': [['sell', '38308.93', '0.05541309']], 'time': '2021-05-20T03:54:44.448171Z'}
{'type': 'l2update', 'product_id': 'BTC-USD', 'changes': [['buy', '38202.95', '0.00000000']], 'time': '2021-05-20T03:54:44.448647Z'}
{'type': 'l2update', 'product_id': 'BTC-USD', 'changes': [['sell', '38444.34', '0.00000000']], 'time': '2021-05-20T03:54:44.455494Z'}
{'type': 'l2update', 'product_id': 'BTC-USD', 'changes': [['buy', '38111.59', '0.00000000']], 'time': '2021-05-20T03:54:44.455715Z'}
{'type': 'l2update', 'product_id': 'BTC-USD', 'changes': [['buy', '38122.63', '0.04830289']], 'time': '2021-05-20T03:54:44.456134Z'}
{'type': 'l2update', 'product_id': 'BTC-USD', 'changes': [['sell', '38291.03', '0.00000000']], 'time': '2021-05-20T03:54:44.457641Z'}
{'type': 'l2update', 'product_id': 'BTC-USD', 'changes': [['buy', '38261.82', '0.00000000']], 'time': '2021-05-20T03:54:44.457821Z'}
{'type': 'l2update', 'product_id': 'BTC-USD', 'changes': [['sell', '38308.93', '0.00000000']], 'time': '2021-05-20T03:54:44.460612Z'}
{'type': 'l2update', 'product_id': 'BTC-USD', 'changes': [['sell', '38297.59', '0.00000000']], 'time': '2021-05-20T03:54:44.462947Z'}
{'type': 'l2update', 'product_id': 'BTC-USD', 'changes': [['sell', '38457.52', '0.01000000']], 'time': '2021-05-20T03:54:44.468374Z'}
{'type': 'l2update', 'product_id': 'BTC-USD', 'changes': [['buy', '38054.70', '0.01000000']], 'time': '2021-05-20T03:54:44.468592Z'}
{'type': 'l2update', 'product_id': 'BTC-USD', 'changes': [['sell', '38322.94', '0.00000000']], 'time': '2021-05-20T03:54:44.470086Z'}
{'type': 'l2update', 'product_id': 'BTC-USD', 'changes': [['buy', '38260.66', '0.43090000']], 'time': '2021-05-20T03:54:44.471409Z'}
{'type': 'l2update', 'product_id': 'BTC-USD', 'changes': [['sell', '38301.58', '0.63000000']], 'time': '2021-05-20T03:54:44.475042Z'}
{'type': 'l2update', 'product_id': 'BTC-USD', 'changes': [['sell', '38292.98', '2.48969908']], 'time': '2021-05-20T03:54:44.479618Z'}
{'type': 'l2update', 'product_id': 'BTC-USD', 'changes': [['sell', '38318.24', '0.49870000']], 'time': '2021-05-20T03:54:44.482891Z'}
{'type': 'l2update', 'product_id': 'BTC-USD', 'changes': [['buy', '38253.40', '0.00000000']], 'time': '2021-05-20T03:54:44.487695Z'}
{'type': 'l2update', 'product_id': 'BTC-USD', 'changes': [['buy', '38252.12', '0.00000000']], 'time': '2021-05-20T03:54:44.487695Z'}
{'type': 'l2update', 'product_id': 'BTC-USD', 'changes': [['sell', '38304.50', '0.05541309']], 'time': '2021-05-20T03:54:44.498371Z'}
{'type': 'l2update', 'product_id': 'BTC-USD', 'changes': [['sell', '38457.52', '0.00000000']], 'time': '2021-05-20T03:54:44.500582Z'}
{'type': 'l2update', 'product_id': 'BTC-USD', 'changes': [['buy', '38255.10', '0.02400000']], 'time': '2021-05-20T03:54:44.503087Z'}
{'type': 'l2update', 'product_id': 'BTC-USD', 'changes': [['buy', '38253.49', '0.02400000']], 'time': '2021-05-20T03:54:44.503087Z'}
{'type': 'l2update', 'product_id': 'BTC-USD', 'changes': [['buy', '38223.98', '0.03325373']], 'time': '2021-05-20T03:54:44.507302Z'}
{'type': 'l2update', 'product_id': 'BTC-USD', 'changes': [['sell', '38444.34', '0.01000000']], 'time': '2021-05-20T03:54:44.510753Z'}
{'type': 'l2update', 'product_id': 'BTC-USD', 'changes': [['buy', '38199.17', '0.03746201']], 'time': '2021-05-20T03:54:44.512877Z'}
{'type': 'l2update', 'product_id': 'BTC-USD', 'changes': [['sell', '38444.34', '0.00000000']], 'time': '2021-05-20T03:54:44.519322Z'}
{'type': 'l2update', 'product_id': 'BTC-USD', 'changes': [['buy', '38287.49', '0.01148006']], 'time': '2021-05-20T03:54:44.530419Z'}
{'type': 'l2update', 'product_id': 'BTC-USD', 'changes': [['sell', '38442.46', '0.01000000']], 'time': '2021-05-20T03:54:44.530477Z'}
{'type': 'l2update', 'product_id': 'BTC-USD', 'changes': [['sell', '38293.73', '0.01014267']], 'time': '2021-05-20T03:54:44.534936Z'}
{'type': 'l2update', 'product_id': 'BTC-USD', 'changes': [['sell', '38442.46', '0.00000000']], 'time': '2021-05-20T03:54:44.546472Z'}
{'type': 'l2update', 'product_id': 'BTC-USD', 'changes': [['sell', '38328.70', '0.00000000']], 'time': '2021-05-20T03:54:44.555851Z'}
{'type': 'l2update', 'product_id': 'BTC-USD', 'changes': [['sell', '38304.50', '0.00000000']], 'time': '2021-05-20T03:54:44.557928Z'}
{'type': 'l2update', 'product_id': 'BTC-USD', 'changes': [['buy', '38246.38', '0.00000000']], 'time': '2021-05-20T03:54:44.559291Z'}
{'type': 'l2update', 'product_id': 'BTC-USD', 'changes': [['sell', '38455.64', '0.01000000']], 'time': '2021-05-20T03:54:44.561926Z'}
{'type': 'l2update', 'product_id': 'BTC-USD', 'changes': [['sell', '48463.39', '0.00700800']], 'time': '2021-05-20T03:54:44.562834Z'}
{'type': 'l2update', 'product_id': 'BTC-USD', 'changes': [['buy', '38196.55', '0.03038970']], 'time': '2021-05-20T03:54:44.571550Z'}
{'type': 'l2update', 'product_id': 'BTC-USD', 'changes': [['buy', '38202.41', '0.02606759']], 'time': '2021-05-20T03:54:44.571550Z'}
{'type': 'l2update', 'product_id': 'BTC-USD', 'changes': [['buy', '38182.08', '0.00000000']], 'time': '2021-05-20T03:54:44.575288Z'}
{'type': 'l2update', 'product_id': 'BTC-USD', 'changes': [['buy', '38164.27', '0.00000000']], 'time': '2021-05-20T03:54:44.579272Z'}
{'type': 'l2update', 'product_id': 'BTC-USD', 'changes': [['buy', '38170.64', '0.00000000']], 'time': '2021-05-20T03:54:44.579272Z'}
{'type': 'l2update', 'product_id': 'BTC-USD', 'changes': [['sell', '38330.43', '0.01000000']], 'time': '2021-05-20T03:54:44.594829Z'}
{'type': 'l2update', 'product_id': 'BTC-USD', 'changes': [['sell', '38293.73', '0.00000000']], 'time': '2021-05-20T03:54:44.605064Z'}
{'type': 'l2update', 'product_id': 'BTC-USD', 'changes': [['buy', '38248.11', '0.01000000']], 'time': '2021-05-20T03:54:44.607682Z'}
{'type': 'l2update', 'product_id': 'BTC-USD', 'changes': [['sell', '38314.38', '0.00000000']], 'time': '2021-05-20T03:54:44.612640Z'}
{'type': 'l2update', 'product_id': 'BTC-USD', 'changes': [['sell', '38455.64', '0.00000000']], 'time': '2021-05-20T03:54:44.624772Z'}
{'type': 'l2update', 'product_id': 'BTC-USD', 'changes': [['sell', '38292.98', '0.00000000']], 'time': '2021-05-20T03:54:44.626951Z'}
{'type': 'l2update', 'product_id': 'BTC-USD', 'changes': [['sell', '38442.46', '0.01000000']], 'time': '2021-05-20T03:54:44.635863Z'}
{'type': 'l2update', 'product_id': 'BTC-USD', 'changes': [['buy', '38228.54', '0.00000000']], 'time': '2021-05-20T03:54:44.637638Z'}
{'type': 'l2update', 'product_id': 'BTC-USD', 'changes': [['buy', '38290.48', '0.07240780']], 'time': '2021-05-20T03:54:44.640664Z'}
{'type': 'l2update', 'product_id': 'BTC-USD', 'changes': [['sell', '38297.11', '2.48969908']], 'time': '2021-05-20T03:54:44.643559Z'}
{'type': 'l2update', 'product_id': 'BTC-USD', 'changes': [['buy', '38279.55', '0.05000000']], 'time': '2021-05-20T03:54:44.647969Z'}
{'type': 'l2update', 'product_id': 'BTC-USD', 'changes': [['buy', '38236.54', '0.10000000']], 'time': '2021-05-20T03:54:44.650965Z'}
{'type': 'l2update', 'product_id': 'BTC-USD', 'changes': [['buy', '38178.49', '0.00000000']], 'time': '2021-05-20T03:54:44.658730Z'}
{'type': 'l2update', 'product_id': 'BTC-USD', 'changes': [['buy', '38283.94', '0.05145037']], 'time': '2021-05-20T03:54:44.660248Z'}
{'type': 'l2update', 'product_id': 'BTC-USD', 'changes': [['buy', '38117.11', '0.00000000']], 'time': '2021-05-20T03:54:44.666424Z'}
{'type': 'l2update', 'product_id': 'BTC-USD', 'changes': [['buy', '38190.42', '0.03577500']], 'time': '2021-05-20T03:54:44.671945Z'}
{'type': 'l2update', 'product_id': 'BTC-USD', 'changes': [['sell', '38304.51', '0.00000000']], 'time': '2021-05-20T03:54:44.672730Z'}
{'type': 'l2update', 'product_id': 'BTC-USD', 'changes': [['sell', '38322.93', '0.05016373']], 'time': '2021-05-20T03:54:44.677117Z'}
{'type': 'l2update', 'product_id': 'BTC-USD', 'changes': [['buy', '38263.89', '0.00000000']], 'time': '2021-05-20T03:54:44.678665Z'}
{'type': 'l2update', 'product_id': 'BTC-USD', 'changes': [['sell', '38316.30', '0.00000000']], 'time': '2021-05-20T03:54:44.682160Z'}
{'type': 'l2update', 'product_id': 'BTC-USD', 'changes': [['sell', '38442.46', '0.00000000']], 'time': '2021-05-20T03:54:44.684602Z'}
{'type': 'l2update', 'product_id': 'BTC-USD', 'changes': [['sell', '38316.29', '0.00000000']], 'time': '2021-05-20T03:54:44.690533Z'}
{'type': 'l2update', 'product_id': 'BTC-USD', 'changes': [['buy', '38290.48', '0.22240780']], 'time': '2021-05-20T03:54:44.697087Z'}
{'type': 'l2update', 'product_id': 'BTC-USD', 'changes': [['sell', '38453.76', '0.01000000']], 'time': '2021-05-20T03:54:44.700939Z'}
{'type': 'l2update', 'product_id': 'BTC-USD', 'changes': [['sell', '38318.23', '0.05000000']], 'time': '2021-05-20T03:54:44.701019Z'}
{'type': 'l2update', 'product_id': 'BTC-USD', 'changes': [['buy', '38273.43', '0.52249456']], 'time': '2021-05-20T03:54:44.701226Z'}
{'type': 'l2update', 'product_id': 'BTC-USD', 'changes': [['buy', '38166.80', '0.00000000']], 'time': '2021-05-20T03:54:44.705395Z'}
{'type': 'l2update', 'product_id': 'BTC-USD', 'changes': [['sell', '39767.56', '0.22800000']], 'time': '2021-05-20T03:54:44.709953Z'}
{'type': 'l2update', 'product_id': 'BTC-USD', 'changes': [['buy', '38270.05', '0.00000000']], 'time': '2021-05-20T03:54:44.711312Z'}
{'type': 'l2update', 'product_id': 'BTC-USD', 'changes': [['sell', '38325.39', '0.00000000']], 'time': '2021-05-20T03:54:44.713332Z'}
{'type': 'l2update', 'product_id': 'BTC-USD', 'changes': [['buy', '38290.48', '0.27240780']], 'time': '2021-05-20T03:54:44.715087Z'}
{'type': 'l2update', 'product_id': 'BTC-USD', 'changes': [['buy', '38122.63', '0.00000000']], 'time': '2021-05-20T03:54:44.717608Z'}
{'type': 'l2update', 'product_id': 'BTC-USD', 'changes': [['buy', '38180.66', '0.01000000']], 'time': '2021-05-20T03:54:44.720662Z'}
{'type': 'l2update', 'product_id': 'BTC-USD', 'changes': [['buy', '38273.48', '0.84700000']], 'time': '2021-05-20T03:54:44.720841Z'}
{'type': 'l2update', 'product_id': 'BTC-USD', 'changes': [['buy', '38273.44', '0.05299136']], 'time': '2021-05-20T03:54:44.721461Z'}
{'type': 'l2update', 'product_id': 'BTC-USD', 'changes': [['sell', '48473.79', '0.00700800']], 'time': '2021-05-20T03:54:44.725554Z'}
{'type': 'l2update', 'product_id': 'BTC-USD', 'changes': [['buy', '38273.48', '1.36800000']], 'time': '2021-05-20T03:54:44.725915Z'}
{'type': 'l2update', 'product_id': 'BTC-USD', 'changes': [['sell', '38316.03', '0.04922351']], 'time': '2021-05-20T03:54:44.725954Z'}
{'type': 'l2update', 'product_id': 'BTC-USD', 'changes': [['sell', '38291.02', '0.00000000']], 'time': '2021-05-20T03:54:44.727958Z'}
{'type': 'l2update', 'product_id': 'BTC-USD', 'changes': [['sell', '38298.75', '0.00000000']], 'time': '2021-05-20T03:54:44.729380Z'}
{'type': 'l2update', 'product_id': 'BTC-USD', 'changes': [['buy', '38290.48', '0.22240780']], 'time': '2021-05-20T03:54:44.729591Z'}
{'type': 'l2update', 'product_id': 'BTC-USD', 'changes': [['buy', '38273.44', '0.00000000']], 'time': '2021-05-20T03:54:44.730357Z'}
{'type': 'l2update', 'product_id': 'BTC-USD', 'changes': [['buy', '38279.55', '0.00000000']], 'time': '2021-05-20T03:54:44.733471Z'}
{'type': 'l2update', 'product_id': 'BTC-USD', 'changes': [['buy', '38273.49', '0.05299136']], 'time': '2021-05-20T03:54:44.738697Z'}
{'type': 'l2update', 'product_id': 'BTC-USD', 'changes': [['sell', '38291.04', '0.00000000']], 'time': '2021-05-20T03:54:44.743776Z'}
{'type': 'l2update', 'product_id': 'BTC-USD', 'changes': [['sell', '38393.75', '0.00000000']], 'time': '2021-05-20T03:54:44.745175Z'}
{'type': 'l2update', 'product_id': 'BTC-USD', 'changes': [['sell', '38322.93', '0.00000000']], 'time': '2021-05-20T03:54:44.750436Z'}
{'type': 'l2update', 'product_id': 'BTC-USD', 'changes': [['sell', '38297.10', '0.58027753']], 'time': '2021-05-20T03:54:44.751351Z'}
{'type': 'l2update', 'product_id': 'BTC-USD', 'changes': [['sell', '38305.78', '0.04531991']], 'time': '2021-05-20T03:54:44.756704Z'}
{'type': 'l2update', 'product_id': 'BTC-USD', 'changes': [['sell', '38297.10', '1.08027753']], 'time': '2021-05-20T03:54:44.760844Z'}
{'type': 'l2update', 'product_id': 'BTC-USD', 'changes': [['buy', '38258.18', '0.00000000']], 'time': '2021-05-20T03:54:44.771892Z'}
{'type': 'l2update', 'product_id': 'BTC-USD', 'changes': [['sell', '38330.43', '0.00000000']], 'time': '2021-05-20T03:54:44.793290Z'}
{'type': 'l2update', 'product_id': 'BTC-USD', 'changes': [['buy', '38248.11', '0.00000000']], 'time': '2021-05-20T03:54:44.797235Z'}
{'type': 'l2update', 'product_id': 'BTC-USD', 'changes': [['buy', '38287.49', '0.00000000']], 'time': '2021-05-20T03:54:44.805100Z'}
{'type': 'l2update', 'product_id': 'BTC-USD', 'changes': [['buy', '38260.29', '0.06305154']], 'time': '2021-05-20T03:54:44.811989Z'}
{'type': 'l2update', 'product_id': 'BTC-USD', 'changes': [['sell', '38328.41', '0.01000000']], 'time': '2021-05-20T03:54:44.812071Z'}
{'type': 'l2update', 'product_id': 'BTC-USD', 'changes': [['sell', '38297.10', '0.50000000']], 'time': '2021-05-20T03:54:44.812600Z'}
{'type': 'l2update', 'product_id': 'BTC-USD', 'changes': [['sell', '38305.78', '0.00000000']], 'time': '2021-05-20T03:54:44.820184Z'}
{'type': 'l2update', 'product_id': 'BTC-USD', 'changes': [['buy', '38279.54', '0.00000000']], 'time': '2021-05-20T03:54:44.833147Z'}
{'type': 'l2update', 'product_id': 'BTC-USD', 'changes': [['sell', '38318.24', '0.00000000']], 'time': '2021-05-20T03:54:44.833319Z'}
{'type': 'l2update', 'product_id': 'BTC-USD', 'changes': [['sell', '38297.09', '0.58027753']], 'time': '2021-05-20T03:54:44.834883Z'}
{'type': 'l2update', 'product_id': 'BTC-USD', 'changes': [['sell', '38420.19', '0.00000000']], 'time': '2021-05-20T03:54:44.841513Z'}
{'type': 'l2update', 'product_id': 'BTC-USD', 'changes': [['sell', '38316.80', '0.48260000']], 'time': '2021-05-20T03:54:44.843155Z'}
{'type': 'l2update', 'product_id': 'BTC-USD', 'changes': [['buy', '38265.25', '0.39490431']], 'time': '2021-05-20T03:54:44.847511Z'}
{'type': 'l2update', 'product_id': 'BTC-USD', 'changes': [['buy', '37500.01', '0.16980000']], 'time': '2021-05-20T03:54:44.850018Z'}
{'type': 'l2update', 'product_id': 'BTC-USD', 'changes': [['sell', '39499.99', '0.04310000']], 'time': '2021-05-20T03:54:44.850018Z'}
{'type': 'l2update', 'product_id': 'BTC-USD', 'changes': [['buy', '37500.01', '0.13010000']], 'time': '2021-05-20T03:54:44.850018Z'}
{'type': 'l2update', 'product_id': 'BTC-USD', 'changes': [['sell', '38318.23', '0.00000000']], 'time': '2021-05-20T03:54:44.850080Z'}
{'type': 'l2update', 'product_id': 'BTC-USD', 'changes': [['sell', '38304.07', '0.05156991']], 'time': '2021-05-20T03:54:44.855470Z'}
{'type': 'l2update', 'product_id': 'BTC-USD', 'changes': [['buy', '37500.01', '0.19130000']], 'time': '2021-05-20T03:54:44.859961Z'}
{'type': 'l2update', 'product_id': 'BTC-USD', 'changes': [['sell', '39236.99', '0.02840000']], 'time': '2021-05-20T03:54:44.859961Z'}
{'type': 'l2update', 'product_id': 'BTC-USD', 'changes': [['sell', '38316.79', '0.05000000']], 'time': '2021-05-20T03:54:44.860089Z'}
{'type': 'l2update', 'product_id': 'BTC-USD', 'changes': [['sell', '38399.41', '0.01302103']], 'time': '2021-05-20T03:54:44.864694Z'}
{'type': 'l2update', 'product_id': 'BTC-USD', 'changes': [['sell', '38297.04', '0.62500000']], 'time': '2021-05-20T03:54:44.871624Z'}
{'type': 'l2update', 'product_id': 'BTC-USD', 'changes': [['buy', '38260.29', '0.00000000']], 'time': '2021-05-20T03:54:44.876458Z'}
{'type': 'l2update', 'product_id': 'BTC-USD', 'changes': [['sell', '38297.09', '0.00000000']], 'time': '2021-05-20T03:54:44.878593Z'}
{'type': 'l2update', 'product_id': 'BTC-USD', 'changes': [['sell', '48487.64', '0.00700800']], 'time': '2021-05-20T03:54:44.889059Z'}
{'type': 'l2update', 'product_id': 'BTC-USD', 'changes': [['sell', '38423.15', '0.00000000']], 'time': '2021-05-20T03:54:44.891744Z'}
{'type': 'l2update', 'product_id': 'BTC-USD', 'changes': [['buy', '37436.01', '0.06425523']], 'time': '2021-05-20T03:54:44.892754Z'}
{'type': 'l2update', 'product_id': 'BTC-USD', 'changes': [['sell', '38297.03', '0.58027753']], 'time': '2021-05-20T03:54:44.896405Z'}
{'type': 'l2update', 'product_id': 'BTC-USD', 'changes': [['sell', '38304.07', '0.00000000']], 'time': '2021-05-20T03:54:44.898090Z'}
{'type': 'l2update', 'product_id': 'BTC-USD', 'changes': [['sell', '38338.46', '0.00000000']], 'time': '2021-05-20T03:54:44.898444Z'}
{'type': 'l2update', 'product_id': 'BTC-USD', 'changes': [['buy', '37466.13', '0.00000000']], 'time': '2021-05-20T03:54:44.900836Z'}
{'type': 'l2update', 'product_id': 'BTC-USD', 'changes': [['sell', '38410.02', '0.01000000']], 'time': '2021-05-20T03:54:44.908849Z'}
{'type': 'l2update', 'product_id': 'BTC-USD', 'changes': [['sell', '38316.80', '0.00000000']], 'time': '2021-05-20T03:54:44.916774Z'}
{'type': 'l2update', 'product_id': 'BTC-USD', 'changes': [['buy', '38290.48', '0.07240780']], 'time': '2021-05-20T03:54:44.927953Z'}
{'type': 'l2update', 'product_id': 'BTC-USD', 'changes': [['buy', '38258.76', '0.05943482']], 'time': '2021-05-20T03:54:44.933860Z'}
{'type': 'l2update', 'product_id': 'BTC-USD', 'changes': [['sell', '38299.40', '0.05017573']], 'time': '2021-05-20T03:54:44.933860Z'}
{'type': 'l2update', 'product_id': 'BTC-USD', 'changes': [['sell', '38296.98', '1.12400000']], 'time': '2021-05-20T03:54:44.936902Z'}
{'type': 'l2update', 'product_id': 'BTC-USD', 'changes': [['sell', '38292.98', '1.77301034']], 'time': '2021-05-20T03:54:44.937015Z'}
{'type': 'l2update', 'product_id': 'BTC-USD', 'changes': [['sell', '38331.14', '0.18000000']], 'time': '2021-05-20T03:54:44.940486Z'}
{'type': 'l2update', 'product_id': 'BTC-USD', 'changes': [['sell', '38301.63', '1.96400000']], 'time': '2021-05-20T03:54:44.945493Z'}
{'type': 'l2update', 'product_id': 'BTC-USD', 'changes': [['buy', '38273.49', '0.00000000']], 'time': '2021-05-20T03:54:44.946208Z'}
{'type': 'l2update', 'product_id': 'BTC-USD', 'changes': [['sell', '38410.02', '0.00000000']], 'time': '2021-05-20T03:54:44.948888Z'}
{'type': 'l2update', 'product_id': 'BTC-USD', 'changes': [['sell', '38297.10', '0.00000000']], 'time': '2021-05-20T03:54:44.949811Z'}
{'type': 'l2update', 'product_id': 'BTC-USD', 'changes': [['sell', '38297.03', '0.00000000']], 'time': '2021-05-20T03:54:44.951317Z'}
{'type': 'l2update', 'product_id': 'BTC-USD', 'changes': [['buy', '38270.05', '0.05299136']], 'time': '2021-05-20T03:54:44.953219Z'}
{'type': 'l2update', 'product_id': 'BTC-USD', 'changes': [['buy', '38283.94', '0.00000000']], 'time': '2021-05-20T03:54:44.962387Z'}
{'type': 'l2update', 'product_id': 'BTC-USD', 'changes': [['sell', '38290.49', '0.77993433']], 'time': '2021-05-20T03:54:44.966247Z'}
{'type': 'l2update', 'product_id': 'BTC-USD', 'changes': [['sell', '38397.70', '0.01000000']], 'time': '2021-05-20T03:54:44.977548Z'}
{'type': 'l2update', 'product_id': 'BTC-USD', 'changes': [['sell', '38292.97', '0.58027753']], 'time': '2021-05-20T03:54:44.977688Z'}
{'type': 'l2update', 'product_id': 'BTC-USD', 'changes': [['buy', '38201.43', '0.07800000']], 'time': '2021-05-20T03:54:44.987672Z'}
{'type': 'l2update', 'product_id': 'BTC-USD', 'changes': [['sell', '38310.49', '0.00000000']], 'time': '2021-05-20T03:54:44.987796Z'}
{'type': 'l2update', 'product_id': 'BTC-USD', 'changes': [['buy', '38258.76', '0.00000000']], 'time': '2021-05-20T03:54:44.989246Z'}
{'type': 'l2update', 'product_id': 'BTC-USD', 'changes': [['sell', '38299.40', '0.00000000']], 'time': '2021-05-20T03:54:44.989246Z'}
{'type': 'l2update', 'product_id': 'BTC-USD', 'changes': [['sell', '38290.49', '0.77481694']], 'time': '2021-05-20T03:54:44.990600Z'}
{'type': 'l2update', 'product_id': 'BTC-USD', 'changes': [['sell', '38325.83', '0.45856073']], 'time': '2021-05-20T03:54:44.990853Z'}
{'type': 'l2update', 'product_id': 'BTC-USD', 'changes': [['buy', '38290.48', '0.00000000']], 'time': '2021-05-20T03:54:44.994038Z'}
{'type': 'l2update', 'product_id': 'BTC-USD', 'changes': [['sell', '38292.96', '1.53555360']], 'time': '2021-05-20T03:54:44.994434Z'}
{'type': 'l2update', 'product_id': 'BTC-USD', 'changes': [['sell', '38290.49', '0.76908694']], 'time': '2021-05-20T03:54:45.001383Z'}
{'type': 'l2update', 'product_id': 'BTC-USD', 'changes': [['sell', '38316.79', '0.00000000']], 'time': '2021-05-20T03:54:45.001947Z'}
{'type': 'l2update', 'product_id': 'BTC-USD', 'changes': [['buy', '37436.01', '0.00000000']], 'time': '2021-05-20T03:54:45.003744Z'}
{'type': 'l2update', 'product_id': 'BTC-USD', 'changes': [['buy', '38273.87', '0.07460000']], 'time': '2021-05-20T03:54:45.006485Z'}
{'type': 'l2update', 'product_id': 'BTC-USD', 'changes': [['buy', '38273.93', '0.01492000']], 'time': '2021-05-20T03:54:45.006516Z'}
{'type': 'l2update', 'product_id': 'BTC-USD', 'changes': [['buy', '38278.05', '0.05046457']], 'time': '2021-05-20T03:54:45.006659Z'}
{'type': 'l2update', 'product_id': 'BTC-USD', 'changes': [['sell', '38325.82', '0.05000000']], 'time': '2021-05-20T03:54:45.011873Z'}
{'type': 'l2update', 'product_id': 'BTC-USD', 'changes': [['buy', '38268.82', '0.05299136']], 'time': '2021-05-20T03:54:45.011917Z'}
{'type': 'l2update', 'product_id': 'BTC-USD', 'changes': [['sell', '38317.30', '0.43830000']], 'time': '2021-05-20T03:54:45.011943Z'}
{'type': 'l2update', 'product_id': 'BTC-USD', 'changes': [['sell', '38289.95', '0.01492000']], 'time': '2021-05-20T03:54:45.011980Z'}
{'type': 'l2update', 'product_id': 'BTC-USD', 'changes': [['buy', '38273.87', '0.00000000']], 'time': '2021-05-20T03:54:45.012531Z'}
{'type': 'l2update', 'product_id': 'BTC-USD', 'changes': [['buy', '38144.90', '0.00000000']], 'time': '2021-05-20T03:54:45.012584Z'}
{'type': 'l2update', 'product_id': 'BTC-USD', 'changes': [['sell', '38290.00', '0.07460000']], 'time': '2021-05-20T03:54:45.016128Z'}
{'type': 'l2update', 'product_id': 'BTC-USD', 'changes': [['buy', '38230.74', '0.09013618']], 'time': '2021-05-20T03:54:45.016299Z'}
{'type': 'l2update', 'product_id': 'BTC-USD', 'changes': [['buy', '38268.82', '0.00000000']], 'time': '2021-05-20T03:54:45.017479Z'}
{'type': 'l2update', 'product_id': 'BTC-USD', 'changes': [['buy', '38270.05', '0.00000000']], 'time': '2021-05-20T03:54:45.018088Z'}
{'type': 'l2update', 'product_id': 'BTC-USD', 'changes': [['sell', '38325.82', '0.00000000']], 'time': '2021-05-20T03:54:45.018411Z'}
{'type': 'l2update', 'product_id': 'BTC-USD', 'changes': [['sell', '38290.49', '0.66908694']], 'time': '2021-05-20T03:54:45.018495Z'}
{'type': 'l2update', 'product_id': 'BTC-USD', 'changes': [['buy', '38273.93', '0.00000000']], 'time': '2021-05-20T03:54:45.019775Z'}
{'type': 'l2update', 'product_id': 'BTC-USD', 'changes': [['sell', '38383.53', '0.00000000']], 'time': '2021-05-20T03:54:45.020546Z'}
{'type': 'l2update', 'product_id': 'BTC-USD', 'changes': [['sell', '38290.00', '0.00000000']], 'time': '2021-05-20T03:54:45.021575Z'}
{'type': 'l2update', 'product_id': 'BTC-USD', 'changes': [['buy', '38283.95', '0.07238719']], 'time': '2021-05-20T03:54:45.023858Z'}
{'type': 'l2update', 'product_id': 'BTC-USD', 'changes': [['sell', '38290.49', '0.50000000']], 'time': '2021-05-20T03:54:45.024956Z'}
{'type': 'l2update', 'product_id': 'BTC-USD', 'changes': [['sell', '38292.97', '0.00000000']], 'time': '2021-05-20T03:54:45.025756Z'}
{'type': 'l2update', 'product_id': 'BTC-USD', 'changes': [['buy', '38278.42', '0.06274942']], 'time': '2021-05-20T03:54:45.028577Z'}
{'type': 'l2update', 'product_id': 'BTC-USD', 'changes': [['sell', '38289.95', '0.00000000']], 'time': '2021-05-20T03:54:45.030360Z'}
{'type': 'l2update', 'product_id': 'BTC-USD', 'changes': [['buy', '38278.42', '0.00000000']], 'time': '2021-05-20T03:54:45.033221Z'}
{'type': 'l2update', 'product_id': 'BTC-USD', 'changes': [['sell', '38317.29', '0.05000000']], 'time': '2021-05-20T03:54:45.034331Z'}
{'type': 'l2update', 'product_id': 'BTC-USD', 'changes': [['sell', '38406.08', '0.01301877']], 'time': '2021-05-20T03:54:45.034537Z'}
{'type': 'l2update', 'product_id': 'BTC-USD', 'changes': [['buy', '38266.82', '0.05299136']], 'time': '2021-05-20T03:54:45.034628Z'}
{'type': 'l2update', 'product_id': 'BTC-USD', 'changes': [['buy', '38270.05', '0.05299136']], 'time': '2021-05-20T03:54:45.040981Z'}
{'type': 'l2update', 'product_id': 'BTC-USD', 'changes': [['buy', '38258.38', '0.15900000']], 'time': '2021-05-20T03:54:45.041049Z'}
{'type': 'l2update', 'product_id': 'BTC-USD', 'changes': [['buy', '38201.44', '0.64241341']], 'time': '2021-05-20T03:54:45.044977Z'}
{'type': 'l2update', 'product_id': 'BTC-USD', 'changes': [['sell', '38290.48', '0.58027753']], 'time': '2021-05-20T03:54:45.045221Z'}
{'type': 'l2update', 'product_id': 'BTC-USD', 'changes': [['buy', '38266.82', '0.00000000']], 'time': '2021-05-20T03:54:45.047675Z'}
{'type': 'l2update', 'product_id': 'BTC-USD', 'changes': [['sell', '38294.52', '0.00600000']], 'time': '2021-05-20T03:54:45.048997Z'}
{'type': 'l2update', 'product_id': 'BTC-USD', 'changes': [['buy', '38273.48', '0.84700000']], 'time': '2021-05-20T03:54:45.051913Z'}
{'type': 'l2update', 'product_id': 'BTC-USD', 'changes': [['sell', '39249.98', '0.00000000']], 'time': '2021-05-20T03:54:45.059094Z'}
{'type': 'l2update', 'product_id': 'BTC-USD', 'changes': [['sell', '39249.99', '0.00000000']], 'time': '2021-05-20T03:54:45.059094Z'}
{'type': 'l2update', 'product_id': 'BTC-USD', 'changes': [['buy', '38270.09', '0.52200000']], 'time': '2021-05-20T03:54:45.062091Z'}
{'type': 'l2update', 'product_id': 'BTC-USD', 'changes': [['buy', '38273.43', '0.00000000']], 'time': '2021-05-20T03:54:45.065393Z'}
{'type': 'l2update', 'product_id': 'BTC-USD', 'changes': [['sell', '39236.99', '0.08970000']], 'time': '2021-05-20T03:54:45.066073Z'}
{'type': 'l2update', 'product_id': 'BTC-USD', 'changes': [['buy', '37500.01', '0.20160000']], 'time': '2021-05-20T03:54:45.066073Z'}
{'type': 'l2update', 'product_id': 'BTC-USD', 'changes': [['sell', '39236.98', '0.03960000']], 'time': '2021-05-20T03:54:45.066073Z'}
{'type': 'l2update', 'product_id': 'BTC-USD', 'changes': [['buy', '38273.48', '0.00000000']], 'time': '2021-05-20T03:54:45.073144Z'}
{'type': 'l2update', 'product_id': 'BTC-USD', 'changes': [['sell', '48877.58', '0.00241400']], 'time': '2021-05-20T03:54:45.074364Z'}
{'type': 'l2update', 'product_id': 'BTC-USD', 'changes': [['buy', '38109.84', '0.04939172']], 'time': '2021-05-20T03:54:45.074564Z'}
{'type': 'l2update', 'product_id': 'BTC-USD', 'changes': [['buy', '38270.10', '0.05299136']], 'time': '2021-05-20T03:54:45.079516Z'}
{'type': 'l2update', 'product_id': 'BTC-USD', 'changes': [['buy', '38270.05', '0.00000000']], 'time': '2021-05-20T03:54:45.082866Z'}
{'type': 'l2update', 'product_id': 'BTC-USD', 'changes': [['buy', '38270.10', '0.89999136']], 'time': '2021-05-20T03:54:45.086415Z'}
{'type': 'l2update', 'product_id': 'BTC-USD', 'changes': [['buy', '38270.11', '0.05299136']], 'time': '2021-05-20T03:54:45.102880Z'}
{'type': 'l2update', 'product_id': 'BTC-USD', 'changes': [['buy', '38270.10', '0.84700000']], 'time': '2021-05-20T03:54:45.108309Z'}
{'type': 'l2update', 'product_id': 'BTC-USD', 'changes': [['sell', '38396.74', '0.00000000']], 'time': '2021-05-20T03:54:45.120018Z'}
{'type': 'l2update', 'product_id': 'BTC-USD', 'changes': [['buy', '38185.56', '0.50000000']], 'time': '2021-05-20T03:54:45.135279Z'}
{'type': 'l2update', 'product_id': 'BTC-USD', 'changes': [['sell', '38412.09', '0.01000000']], 'time': '2021-05-20T03:54:45.135554Z'}
{'type': 'l2update', 'product_id': 'BTC-USD', 'changes': [['sell', '38292.98', '0.00000000']], 'time': '2021-05-20T03:54:45.158312Z'}
{'type': 'l2update', 'product_id': 'BTC-USD', 'changes': [['sell', '38292.96', '0.00000000']], 'time': '2021-05-20T03:54:45.162701Z'}
{'type': 'l2update', 'product_id': 'BTC-USD', 'changes': [['sell', '38500.42', '0.01970000']], 'time': '2021-05-20T03:54:45.164761Z'}
{'type': 'l2update', 'product_id': 'BTC-USD', 'changes': [['sell', '38293.33', '0.04920907']], 'time': '2021-05-20T03:54:45.167282Z'}
{'type': 'l2update', 'product_id': 'BTC-USD', 'changes': [['sell', '38297.11', '0.00000000']], 'time': '2021-05-20T03:54:45.168632Z'}
{'type': 'l2update', 'product_id': 'BTC-USD', 'changes': [['sell', '38290.47', '2.48969908']], 'time': '2021-05-20T03:54:45.182211Z'}
{'type': 'l2update', 'product_id': 'BTC-USD', 'changes': [['sell', '38289.22', '0.15000000']], 'time': '2021-05-20T03:54:45.183420Z'}
{'type': 'l2update', 'product_id': 'BTC-USD', 'changes': [['sell', '38289.22', '0.11095378']], 'time': '2021-05-20T03:54:45.186424Z'}
{'type': 'l2update', 'product_id': 'BTC-USD', 'changes': [['sell', '38290.48', '0.00000000']], 'time': '2021-05-20T03:54:45.188615Z'}
{'type': 'l2update', 'product_id': 'BTC-USD', 'changes': [['sell', '38289.22', '0.00000000']], 'time': '2021-05-20T03:54:45.189643Z'}
{'type': 'l2update', 'product_id': 'BTC-USD', 'changes': [['sell', '38297.64', '0.00000000']], 'time': '2021-05-20T03:54:45.195708Z'}
{'type': 'l2update', 'product_id': 'BTC-USD', 'changes': [['sell', '38382.32', '0.00000000']], 'time': '2021-05-20T03:54:45.199523Z'}
{'type': 'l2update', 'product_id': 'BTC-USD', 'changes': [['sell', '38294.47', '0.58800000']], 'time': '2021-05-20T03:54:45.202099Z'}
{'type': 'l2update', 'product_id': 'BTC-USD', 'changes': [['sell', '38307.75', '0.05022245']], 'time': '2021-05-20T03:54:45.202495Z'}
{'type': 'l2update', 'product_id': 'BTC-USD', 'changes': [['sell', '38290.46', '0.58027753']], 'time': '2021-05-20T03:54:45.209454Z'}
{'type': 'l2update', 'product_id': 'BTC-USD', 'changes': [['sell', '38370.35', '0.01000000']], 'time': '2021-05-20T03:54:45.213251Z'}
{'type': 'l2update', 'product_id': 'BTC-USD', 'changes': [['sell', '43100.00', '1.09530000']], 'time': '2021-05-20T03:54:45.215098Z'}
{'type': 'l2update', 'product_id': 'BTC-USD', 'changes': [['sell', '38301.63', '1.33100000']], 'time': '2021-05-20T03:54:45.218319Z'}
{'type': 'l2update', 'product_id': 'BTC-USD', 'changes': [['buy', '38072.38', '0.00600000']], 'time': '2021-05-20T03:54:45.224657Z'}
{'type': 'l2update', 'product_id': 'BTC-USD', 'changes': [['sell', '43100.00', '1.22350000']], 'time': '2021-05-20T03:54:45.228902Z'}
{'type': 'l2update', 'product_id': 'BTC-USD', 'changes': [['sell', '48894.45', '0.00241400']], 'time': '2021-05-20T03:54:45.242308Z'}
{'type': 'l2update', 'product_id': 'BTC-USD', 'changes': [['buy', '38257.11', '0.04873693']], 'time': '2021-05-20T03:54:45.273066Z'}
{'type': 'l2update', 'product_id': 'BTC-USD', 'changes': [['sell', '38297.68', '0.03935023']], 'time': '2021-05-20T03:54:45.273066Z'}
{'type': 'l2update', 'product_id': 'BTC-USD', 'changes': [['sell', '38399.41', '0.00000000']], 'time': '2021-05-20T03:54:45.293551Z'}
{'type': 'l2update', 'product_id': 'BTC-USD', 'changes': [['buy', '38260.66', '0.00000000']], 'time': '2021-05-20T03:54:45.307602Z'}
{'type': 'l2update', 'product_id': 'BTC-USD', 'changes': [['buy', '38228.40', '0.00000000']], 'time': '2021-05-20T03:54:45.315319Z'}
{'type': 'l2update', 'product_id': 'BTC-USD', 'changes': [['sell', '38433.19', '0.01300959']], 'time': '2021-05-20T03:54:45.316238Z'}
{'type': 'l2update', 'product_id': 'BTC-USD', 'changes': [['sell', '38349.00', '0.00000000']], 'time': '2021-05-20T03:54:45.316387Z'}
{'type': 'l2update', 'product_id': 'BTC-USD', 'changes': [['buy', '38262.06', '0.47550000']], 'time': '2021-05-20T03:54:45.320581Z'}
{'type': 'l2update', 'product_id': 'BTC-USD', 'changes': [['sell', '38345.97', '0.61482416']], 'time': '2021-05-20T03:54:45.328606Z'}
{'type': 'l2update', 'product_id': 'BTC-USD', 'changes': [['buy', '38225.38', '1.28313649']], 'time': '2021-05-20T03:54:45.328691Z'}
{'type': 'l2update', 'product_id': 'BTC-USD', 'changes': [['buy', '38236.54', '0.00000000']], 'time': '2021-05-20T03:54:45.348443Z'}
{'type': 'l2update', 'product_id': 'BTC-USD', 'changes': [['sell', '38317.30', '0.00000000']], 'time': '2021-05-20T03:54:45.395339Z'}
{'type': 'l2update', 'product_id': 'BTC-USD', 'changes': [['buy', '38230.54', '0.10000000']], 'time': '2021-05-20T03:54:45.401939Z'}
{'type': 'l2update', 'product_id': 'BTC-USD', 'changes': [['sell', '48938.17', '0.00310000']], 'time': '2021-05-20T03:54:45.414158Z'}
{'type': 'l2update', 'product_id': 'BTC-USD', 'changes': [['sell', '38315.31', '0.45300000']], 'time': '2021-05-20T03:54:45.414176Z'}
{'type': 'l2update', 'product_id': 'BTC-USD', 'changes': [['sell', '38317.29', '0.00000000']], 'time': '2021-05-20T03:54:45.423071Z'}
{'type': 'l2update', 'product_id': 'BTC-USD', 'changes': [['sell', '38451.61', '0.00000000']], 'time': '2021-05-20T03:54:45.435985Z'}
{'type': 'l2update', 'product_id': 'BTC-USD', 'changes': [['sell', '38315.30', '0.05000000']], 'time': '2021-05-20T03:54:45.438757Z'}
{'type': 'l2update', 'product_id': 'BTC-USD', 'changes': [['buy', '38257.11', '0.06179861']], 'time': '2021-05-20T03:54:45.451024Z'}
{'type': 'l2update', 'product_id': 'BTC-USD', 'changes': [['sell', '38437.76', '0.01000000']], 'time': '2021-05-20T03:54:45.451055Z'}
{'type': 'l2update', 'product_id': 'BTC-USD', 'changes': [['sell', '38316.03', '0.00000000']], 'time': '2021-05-20T03:54:45.464637Z'}
{'type': 'l2update', 'product_id': 'BTC-USD', 'changes': [['buy', '38262.06', '0.00000000']], 'time': '2021-05-20T03:54:45.477863Z'}
{'type': 'l2update', 'product_id': 'BTC-USD', 'changes': [['sell', '38315.31', '0.00000000']], 'time': '2021-05-20T03:54:45.481349Z'}
{'type': 'l2update', 'product_id': 'BTC-USD', 'changes': [['sell', '38388.81', '0.00000000']], 'time': '2021-05-20T03:54:45.498988Z'}
{'type': 'l2update', 'product_id': 'BTC-USD', 'changes': [['sell', '38422.31', '0.01000000']], 'time': '2021-05-20T03:54:45.508115Z'}
{'type': 'l2update', 'product_id': 'BTC-USD', 'changes': [['buy', '38201.43', '0.00000000']], 'time': '2021-05-20T03:54:45.523499Z'}
{'type': 'l2update', 'product_id': 'BTC-USD', 'changes': [['sell', '39035.61', '0.00175899']], 'time': '2021-05-20T03:54:45.563714Z'}
{'type': 'l2update', 'product_id': 'BTC-USD', 'changes': [['buy', '38261.58', '0.40630000']], 'time': '2021-05-20T03:54:45.567983Z'}
{'type': 'l2update', 'product_id': 'BTC-USD', 'changes': [['sell', '38310.49', '0.05488740']], 'time': '2021-05-20T03:54:45.568077Z'}
{'type': 'l2update', 'product_id': 'BTC-USD', 'changes': [['sell', '38290.46', '0.37541165']], 'time': '2021-05-20T03:54:45.574833Z'}
{'type': 'l2update', 'product_id': 'BTC-USD', 'changes': [['sell', '38293.33', '0.00000000']], 'time': '2021-05-20T03:54:45.575589Z'}
{'type': 'l2update', 'product_id': 'BTC-USD', 'changes': [['sell', '38315.03', '0.47020000']], 'time': '2021-05-20T03:54:45.578187Z'}
{'type': 'l2update', 'product_id': 'BTC-USD', 'changes': [['sell', '48952.16', '0.00323600']], 'time': '2021-05-20T03:54:45.578532Z'}
{'type': 'l2update', 'product_id': 'BTC-USD', 'changes': [['sell', '38290.46', '0.00000000']], 'time': '2021-05-20T03:54:45.579937Z'}
{'type': 'l2update', 'product_id': 'BTC-USD', 'changes': [['buy', '38270.11', '0.00000000']], 'time': '2021-05-20T03:54:45.581290Z'}
{'type': 'l2update', 'product_id': 'BTC-USD', 'changes': [['sell', '38310.49', '0.00000000']], 'time': '2021-05-20T03:54:45.581311Z'}
{'type': 'l2update', 'product_id': 'BTC-USD', 'changes': [['sell', '38315.30', '0.00000000']], 'time': '2021-05-20T03:54:45.584845Z'}
{'type': 'l2update', 'product_id': 'BTC-USD', 'changes': [['buy', '38270.12', '0.21575391']], 'time': '2021-05-20T03:54:45.586549Z'}
{'type': 'l2update', 'product_id': 'BTC-USD', 'changes': [['sell', '38301.57', '0.05488740']], 'time': '2021-05-20T03:54:45.586596Z'}
{'type': 'l2update', 'product_id': 'BTC-USD', 'changes': [['buy', '38268.82', '0.05488740']], 'time': '2021-05-20T03:54:45.590017Z'}
{'type': 'l2update', 'product_id': 'BTC-USD', 'changes': [['sell', '38315.02', '0.05000000']], 'time': '2021-05-20T03:54:45.593714Z'}
{'type': 'l2update', 'product_id': 'BTC-USD', 'changes': [['sell', '38297.39', '0.05077691']], 'time': '2021-05-20T03:54:45.593742Z'}
{'type': 'l2update', 'product_id': 'BTC-USD', 'changes': [['buy', '38269.52', '0.05488740']], 'time': '2021-05-20T03:54:45.593841Z'}
{'type': 'l2update', 'product_id': 'BTC-USD', 'changes': [['sell', '38301.57', '0.00000000']], 'time': '2021-05-20T03:54:45.593919Z'}
{'type': 'l2update', 'product_id': 'BTC-USD', 'changes': [['buy', '38268.82', '0.00000000']], 'time': '2021-05-20T03:54:45.595765Z'}
{'type': 'l2update', 'product_id': 'BTC-USD', 'changes': [['buy', '38269.52', '0.00000000']], 'time': '2021-05-20T03:54:45.600642Z'}
{'type': 'l2update', 'product_id': 'BTC-USD', 'changes': [['sell', '38290.46', '0.37541165']], 'time': '2021-05-20T03:54:45.601002Z'}
