{'type': 'l2update', 'product_id': 'BTC-USD', 'changes': [['sell', '38341.86', '0.05000000']], 'time': '2021-05-20T03:55:57.944620Z'}
{'type': 'l2update', 'product_id': 'BTC-USD', 'changes': [['sell', '38497.71', '0.01000000']], 'time': '2021-05-20T03:55:57.947714Z'}
{'type': 'l2update', 'product_id': 'BTC-USD', 'changes': [['sell', '38352.02', '0.01113434']], 'time': '2021-05-20T03:55:57.947766Z'}
{'type': 'l2update', 'product_id': 'BTC-USD', 'changes': [['buy', '38193.22', '0.03130160']], 'time': '2021-05-20T03:55:57.947766Z'}
{'type': 'l2update', 'product_id': 'BTC-USD', 'changes': [['buy', '38312.31', '0.04341146']], 'time': '2021-05-20T03:55:57.947981Z'}
{'type': 'l2update', 'product_id': 'BTC-USD', 'changes': [['buy', '38289.12', '0.00000000']], 'time': '2021-05-20T03:55:57.949928Z'}
{'type': 'l2update', 'product_id': 'BTC-USD', 'changes': [['buy', '38310.56', '0.00000000']], 'time': '2021-05-20T03:55:57.954872Z'}
{'type': 'l2update', 'product_id': 'BTC-USD', 'changes': [['buy', '38317.91', '0.00000000']], 'time': '2021-05-20T03:55:57.956107Z'}
{'type': 'l2update', 'product_id': 'BTC-USD', 'changes': [['sell', '38358.51', '2.60995216']], 'time': '2021-05-20T03:55:57.956708Z'}
{'type': 'l2update', 'product_id': 'BTC-USD', 'changes': [['sell', '38649.94', '0.01293663']], 'time': '2021-05-20T03:55:57.956783Z'}
{'type': 'l2update', 'product_id': 'BTC-USD', 'changes': [['sell', '38326.54', '0.27460000']], 'time': '2021-05-20T03:55:57.957810Z'}
{'type': 'l2update', 'product_id': 'BTC-USD', 'changes': [['sell', '38333.62', '2.98969908']], 'time': '2021-05-20T03:55:57.958970Z'}
{'type': 'l2update', 'product_id': 'BTC-USD', 'changes': [['buy', '38291.67', '0.40620000']], 'time': '2021-05-20T03:55:57.962065Z'}
{'type': 'l2update', 'product_id': 'BTC-USD', 'changes': [['sell', '38341.86', '0.00000000']], 'time': '2021-05-20T03:55:57.963693Z'}
{'type': 'l2update', 'product_id': 'BTC-USD', 'changes': [['sell', '38366.77', '0.00000000']], 'time': '2021-05-20T03:55:57.965543Z'}
{'type': 'l2update', 'product_id': 'BTC-USD', 'changes': [['sell', '38424.22', '0.33363081']], 'time': '2021-05-20T03:55:57.966324Z'}
{'type': 'l2update', 'product_id': 'BTC-USD', 'changes': [['sell', '38417.94', '0.29956217']], 'time': '2021-05-20T03:55:57.966324Z'}
{'type': 'l2update', 'product_id': 'BTC-USD', 'changes': [['sell', '38326.54', '0.22979922']], 'time': '2021-05-20T03:55:57.966461Z'}
{'type': 'l2update', 'product_id': 'BTC-USD', 'changes': [['sell', '38333.61', '0.18981474']], 'time': '2021-05-20T03:55:57.966720Z'}
{'type': 'l2update', 'product_id': 'BTC-USD', 'changes': [['sell', '38327.22', '0.00000000']], 'time': '2021-05-20T03:55:57.967291Z'}
{'type': 'l2update', 'product_id': 'BTC-USD', 'changes': [['buy', '38291.22', '0.00000000']], 'time': '2021-05-20T03:55:57.967712Z'}
{'type': 'l2update', 'product_id': 'BTC-USD', 'changes': [['sell', '38436.15', '0.01300858']], 'time': '2021-05-20T03:55:57.971382Z'}
{'type': 'l2update', 'product_id': 'BTC-USD', 'changes': [['sell', '38326.54', '0.32979922']], 'time': '2021-05-20T03:55:57.971652Z'}
{'type': 'l2update', 'product_id': 'BTC-USD', 'changes': [['sell', '38333.21', '0.00000000']], 'time': '2021-05-20T03:55:57.974137Z'}
{'type': 'l2update', 'product_id': 'BTC-USD', 'changes': [['sell', '38326.54', '0.35979922']], 'time': '2021-05-20T03:55:57.974699Z'}
{'type': 'l2update', 'product_id': 'BTC-USD', 'changes': [['sell', '38428.09', '0.00000000']], 'time': '2021-05-20T03:55:57.974764Z'}
{'type': 'l2update', 'product_id': 'BTC-USD', 'changes': [['buy', '38326.53', '0.04974422']], 'time': '2021-05-20T03:55:57.976279Z'}
{'type': 'l2update', 'product_id': 'BTC-USD', 'changes': [['sell', '38491.62', '0.00000000']], 'time': '2021-05-20T03:55:57.983387Z'}
{'type': 'l2update', 'product_id': 'BTC-USD', 'changes': [['buy', '38241.71', '0.00000000']], 'time': '2021-05-20T03:55:57.985091Z'}
{'type': 'l2update', 'product_id': 'BTC-USD', 'changes': [['sell', '38476.21', '0.00000000']], 'time': '2021-05-20T03:55:57.985234Z'}
{'type': 'l2update', 'product_id': 'BTC-USD', 'changes': [['buy', '38294.11', '0.00000000']], 'time': '2021-05-20T03:55:57.985861Z'}
{'type': 'l2update', 'product_id': 'BTC-USD', 'changes': [['buy', '38293.31', '0.00000000']], 'time': '2021-05-20T03:55:57.985861Z'}
{'type': 'l2update', 'product_id': 'BTC-USD', 'changes': [['sell', '38347.69', '0.11323880']], 'time': '2021-05-20T03:55:57.988981Z'}
{'type': 'l2update', 'product_id': 'BTC-USD', 'changes': [['sell', '38326.54', '0.60979922']], 'time': '2021-05-20T03:55:57.989334Z'}
{'type': 'l2update', 'product_id': 'BTC-USD', 'changes': [['sell', '38456.68', '0.03085440']], 'time': '2021-05-20T03:55:57.989574Z'}
{'type': 'l2update', 'product_id': 'BTC-USD', 'changes': [['buy', '38307.10', '0.99440510']], 'time': '2021-05-20T03:55:57.989734Z'}
{'type': 'l2update', 'product_id': 'BTC-USD', 'changes': [['buy', '38297.63', '0.78285335']], 'time': '2021-05-20T03:55:57.989761Z'}
{'type': 'l2update', 'product_id': 'BTC-USD', 'changes': [['sell', '38479.28', '0.00000000']], 'time': '2021-05-20T03:55:57.992940Z'}
{'type': 'l2update', 'product_id': 'BTC-USD', 'changes': [['sell', '38367.42', '0.05000000']], 'time': '2021-05-20T03:55:57.993762Z'}
{'type': 'l2update', 'product_id': 'BTC-USD', 'changes': [['sell', '38352.02', '0.04220915']], 'time': '2021-05-20T03:55:57.996504Z'}
{'type': 'l2update', 'product_id': 'BTC-USD', 'changes': [['buy', '38291.67', '0.00000000']], 'time': '2021-05-20T03:55:57.998049Z'}
{'type': 'l2update', 'product_id': 'BTC-USD', 'changes': [['buy', '38307.15', '0.00000000']], 'time': '2021-05-20T03:55:58.003452Z'}
{'type': 'l2update', 'product_id': 'BTC-USD', 'changes': [['buy', '37525.42', '0.00000000']], 'time': '2021-05-20T03:55:58.004082Z'}
{'type': 'l2update', 'product_id': 'BTC-USD', 'changes': [['buy', '38303.72', '0.84700000']], 'time': '2021-05-20T03:55:58.010082Z'}
{'type': 'l2update', 'product_id': 'BTC-USD', 'changes': [['sell', '38435.64', '0.32380624']], 'time': '2021-05-20T03:55:58.010363Z'}
{'type': 'l2update', 'product_id': 'BTC-USD', 'changes': [['sell', '38348.60', '0.36226296']], 'time': '2021-05-20T03:55:58.010363Z'}
{'type': 'l2update', 'product_id': 'BTC-USD', 'changes': [['buy', '38316.10', '0.00000000']], 'time': '2021-05-20T03:55:58.011706Z'}
{'type': 'l2update', 'product_id': 'BTC-USD', 'changes': [['sell', '38515.51', '0.00000000']], 'time': '2021-05-20T03:55:58.013471Z'}
{'type': 'l2update', 'product_id': 'BTC-USD', 'changes': [['buy', '38281.32', '0.01000000']], 'time': '2021-05-20T03:55:58.018841Z'}
{'type': 'l2update', 'product_id': 'BTC-USD', 'changes': [['buy', '38291.22', '0.02400000']], 'time': '2021-05-20T03:55:58.018990Z'}
{'type': 'l2update', 'product_id': 'BTC-USD', 'changes': [['buy', '38290.42', '0.02400000']], 'time': '2021-05-20T03:55:58.018990Z'}
{'type': 'l2update', 'product_id': 'BTC-USD', 'changes': [['buy', '38240.70', '0.02400000']], 'time': '2021-05-20T03:55:58.019600Z'}
{'type': 'l2update', 'product_id': 'BTC-USD', 'changes': [['sell', '38359.04', '0.02890157']], 'time': '2021-05-20T03:55:58.022552Z'}
{'type': 'l2update', 'product_id': 'BTC-USD', 'changes': [['buy', '38310.55', '0.02610247']], 'time': '2021-05-20T03:55:58.022945Z'}
{'type': 'l2update', 'product_id': 'BTC-USD', 'changes': [['sell', '38347.69', '0.05000000']], 'time': '2021-05-20T03:55:58.023947Z'}
{'type': 'l2update', 'product_id': 'BTC-USD', 'changes': [['buy', '38302.46', '0.00000000']], 'time': '2021-05-20T03:55:58.025904Z'}
{'type': 'l2update', 'product_id': 'BTC-USD', 'changes': [['buy', '38291.11', '1.30471597']], 'time': '2021-05-20T03:55:58.027187Z'}
{'type': 'l2update', 'product_id': 'BTC-USD', 'changes': [['sell', '38333.62', '2.48969908']], 'time': '2021-05-20T03:55:58.029278Z'}
{'type': 'l2update', 'product_id': 'BTC-USD', 'changes': [['sell', '38334.25', '0.00000000']], 'time': '2021-05-20T03:55:58.030419Z'}
{'type': 'l2update', 'product_id': 'BTC-USD', 'changes': [['buy', '38312.31', '0.00000000']], 'time': '2021-05-20T03:55:58.030738Z'}
{'type': 'l2update', 'product_id': 'BTC-USD', 'changes': [['sell', '38447.31', '0.01000000']], 'time': '2021-05-20T03:55:58.033483Z'}
{'type': 'l2update', 'product_id': 'BTC-USD', 'changes': [['buy', '38229.82', '0.01307879']], 'time': '2021-05-20T03:55:58.033810Z'}
{'type': 'l2update', 'product_id': 'BTC-USD', 'changes': [['sell', '38418.85', '0.00000000']], 'time': '2021-05-20T03:55:58.033942Z'}
{'type': 'l2update', 'product_id': 'BTC-USD', 'changes': [['buy', '38307.10', '0.00000000']], 'time': '2021-05-20T03:55:58.037242Z'}
{'type': 'l2update', 'product_id': 'BTC-USD', 'changes': [['sell', '38348.60', '0.51762057']], 'time': '2021-05-20T03:55:58.037587Z'}
{'type': 'l2update', 'product_id': 'BTC-USD', 'changes': [['sell', '38326.54', '0.61552922']], 'time': '2021-05-20T03:55:58.037637Z'}
{'type': 'l2update', 'product_id': 'BTC-USD', 'changes': [['sell', '38478.45', '0.01000000']], 'time': '2021-05-20T03:55:58.037669Z'}
{'type': 'l2update', 'product_id': 'BTC-USD', 'changes': [['buy', '38326.53', '0.00000000']], 'time': '2021-05-20T03:55:58.041344Z'}
{'type': 'l2update', 'product_id': 'BTC-USD', 'changes': [['sell', '38563.59', '0.01000000']], 'time': '2021-05-20T03:55:58.046216Z'}
{'type': 'l2update', 'product_id': 'BTC-USD', 'changes': [['buy', '38281.32', '0.03000000']], 'time': '2021-05-20T03:55:58.046311Z'}
{'type': 'l2update', 'product_id': 'BTC-USD', 'changes': [['buy', '38267.27', '0.21800000']], 'time': '2021-05-20T03:55:58.046546Z'}
{'type': 'l2update', 'product_id': 'BTC-USD', 'changes': [['sell', '38502.01', '0.01113000']], 'time': '2021-05-20T03:55:58.046717Z'}
{'type': 'l2update', 'product_id': 'BTC-USD', 'changes': [['sell', '38353.11', '0.06323880']], 'time': '2021-05-20T03:55:58.047307Z'}
{'type': 'l2update', 'product_id': 'BTC-USD', 'changes': [['sell', '38375.71', '2.16932808']], 'time': '2021-05-20T03:55:58.047326Z'}
{'type': 'l2update', 'product_id': 'BTC-USD', 'changes': [['buy', '38307.11', '0.40135082']], 'time': '2021-05-20T03:55:58.047353Z'}
{'type': 'l2update', 'product_id': 'BTC-USD', 'changes': [['buy', '38282.17', '2.60951124']], 'time': '2021-05-20T03:55:58.051547Z'}
{'type': 'l2update', 'product_id': 'BTC-USD', 'changes': [['sell', '38362.65', '0.03477275']], 'time': '2021-05-20T03:55:58.053250Z'}
{'type': 'l2update', 'product_id': 'BTC-USD', 'changes': [['buy', '38291.24', '0.45800000']], 'time': '2021-05-20T03:55:58.053272Z'}
{'type': 'l2update', 'product_id': 'BTC-USD', 'changes': [['buy', '38194.80', '0.00000000']], 'time': '2021-05-20T03:55:58.053396Z'}
{'type': 'l2update', 'product_id': 'BTC-USD', 'changes': [['sell', '38365.22', '0.00000000']], 'time': '2021-05-20T03:55:58.055367Z'}
{'type': 'l2update', 'product_id': 'BTC-USD', 'changes': [['sell', '38359.03', '0.00000000']], 'time': '2021-05-20T03:55:58.055367Z'}
{'type': 'l2update', 'product_id': 'BTC-USD', 'changes': [['sell', '38456.68', '0.00000000']], 'time': '2021-05-20T03:55:58.055525Z'}
{'type': 'l2update', 'product_id': 'BTC-USD', 'changes': [['sell', '38326.54', '0.54092922']], 'time': '2021-05-20T03:55:58.059006Z'}
{'type': 'l2update', 'product_id': 'BTC-USD', 'changes': [['sell', '38333.60', '1.22695878']], 'time': '2021-05-20T03:55:58.059773Z'}
{'type': 'l2update', 'product_id': 'BTC-USD', 'changes': [['sell', '38494.08', '0.00000000']], 'time': '2021-05-20T03:55:58.063936Z'}
{'type': 'l2update', 'product_id': 'BTC-USD', 'changes': [['sell', '38326.53', '0.00573000']], 'time': '2021-05-20T03:55:58.064449Z'}
{'type': 'l2update', 'product_id': 'BTC-USD', 'changes': [['sell', '38319.52', '0.02890000']], 'time': '2021-05-20T03:55:58.064468Z'}
{'type': 'l2update', 'product_id': 'BTC-USD', 'changes': [['sell', '38326.54', '1.04092922']], 'time': '2021-05-20T03:55:58.064799Z'}
{'type': 'l2update', 'product_id': 'BTC-USD', 'changes': [['buy', '38295.21', '0.00000000']], 'time': '2021-05-20T03:55:58.065946Z'}
{'type': 'l2update', 'product_id': 'BTC-USD', 'changes': [['buy', '38319.51', '0.00000000']], 'time': '2021-05-20T03:55:58.066560Z'}
{'type': 'l2update', 'product_id': 'BTC-USD', 'changes': [['sell', '38333.61', '0.00000000']], 'time': '2021-05-20T03:55:58.067605Z'}
{'type': 'l2update', 'product_id': 'BTC-USD', 'changes': [['buy', '38263.27', '2.60976134']], 'time': '2021-05-20T03:55:58.072939Z'}
{'type': 'l2update', 'product_id': 'BTC-USD', 'changes': [['sell', '38363.70', '0.01000000']], 'time': '2021-05-20T03:55:58.073013Z'}
{'type': 'l2update', 'product_id': 'BTC-USD', 'changes': [['buy', '38281.32', '0.06000000']], 'time': '2021-05-20T03:55:58.073334Z'}
{'type': 'l2update', 'product_id': 'BTC-USD', 'changes': [['buy', '38303.68', '0.99440510']], 'time': '2021-05-20T03:55:58.077405Z'}
{'type': 'l2update', 'product_id': 'BTC-USD', 'changes': [['sell', '38359.01', '0.00000000']], 'time': '2021-05-20T03:55:58.081638Z'}
{'type': 'l2update', 'product_id': 'BTC-USD', 'changes': [['sell', '38326.54', '0.94092922']], 'time': '2021-05-20T03:55:58.081916Z'}
{'type': 'l2update', 'product_id': 'BTC-USD', 'changes': [['sell', '38326.54', '0.93519922']], 'time': '2021-05-20T03:55:58.081951Z'}
{'type': 'l2update', 'product_id': 'BTC-USD', 'changes': [['buy', '38181.84', '0.02048200']], 'time': '2021-05-20T03:55:58.082217Z'}
{'type': 'l2update', 'product_id': 'BTC-USD', 'changes': [['sell', '38374.62', '0.03755109']], 'time': '2021-05-20T03:55:58.082311Z'}
{'type': 'l2update', 'product_id': 'BTC-USD', 'changes': [['sell', '38374.62', '0.47324808']], 'time': '2021-05-20T03:55:58.082526Z'}
{'type': 'l2update', 'product_id': 'BTC-USD', 'changes': [['buy', '38310.56', '0.02010522']], 'time': '2021-05-20T03:55:58.083828Z'}
{'type': 'l2update', 'product_id': 'BTC-USD', 'changes': [['buy', '38238.59', '0.00000000']], 'time': '2021-05-20T03:55:58.084550Z'}
{'type': 'l2update', 'product_id': 'BTC-USD', 'changes': [['sell', '38347.69', '0.00000000']], 'time': '2021-05-20T03:55:58.087028Z'}
{'type': 'l2update', 'product_id': 'BTC-USD', 'changes': [['buy', '38310.95', '0.05335487']], 'time': '2021-05-20T03:55:58.090938Z'}
{'type': 'l2update', 'product_id': 'BTC-USD', 'changes': [['buy', '38317.60', '0.07153612']], 'time': '2021-05-20T03:55:58.092132Z'}
{'type': 'l2update', 'product_id': 'BTC-USD', 'changes': [['sell', '38474.79', '0.01000000']], 'time': '2021-05-20T03:55:58.092397Z'}
{'type': 'l2update', 'product_id': 'BTC-USD', 'changes': [['buy', '38291.24', '0.52123880']], 'time': '2021-05-20T03:55:58.097796Z'}
{'type': 'l2update', 'product_id': 'BTC-USD', 'changes': [['buy', '38156.56', '0.04956160']], 'time': '2021-05-20T03:55:58.097911Z'}
{'type': 'l2update', 'product_id': 'BTC-USD', 'changes': [['sell', '38319.04', '0.01492000']], 'time': '2021-05-20T03:55:58.097985Z'}
{'type': 'l2update', 'product_id': 'BTC-USD', 'changes': [['buy', '38277.70', '0.09293895']], 'time': '2021-05-20T03:55:58.098173Z'}
{'type': 'l2update', 'product_id': 'BTC-USD', 'changes': [['sell', '38349.05', '0.06381755']], 'time': '2021-05-20T03:55:58.098326Z'}
{'type': 'l2update', 'product_id': 'BTC-USD', 'changes': [['buy', '38311.03', '0.00315085']], 'time': '2021-05-20T03:55:58.098565Z'}
{'type': 'l2update', 'product_id': 'BTC-USD', 'changes': [['buy', '38281.31', '0.01000000']], 'time': '2021-05-20T03:55:58.098597Z'}
{'type': 'l2update', 'product_id': 'BTC-USD', 'changes': [['sell', '38326.54', '0.78000000']], 'time': '2021-05-20T03:55:58.098999Z'}
{'type': 'l2update', 'product_id': 'BTC-USD', 'changes': [['buy', '38310.95', '0.07460000']], 'time': '2021-05-20T03:55:58.100200Z'}
{'type': 'l2update', 'product_id': 'BTC-USD', 'changes': [['sell', '38326.53', '0.00000000']], 'time': '2021-05-20T03:55:58.100417Z'}
{'type': 'l2update', 'product_id': 'BTC-USD', 'changes': [['sell', '38594.92', '0.00000000']], 'time': '2021-05-20T03:55:58.102755Z'}
{'type': 'l2update', 'product_id': 'BTC-USD', 'changes': [['buy', '38261.48', '2.60986820']], 'time': '2021-05-20T03:55:58.103276Z'}
{'type': 'l2update', 'product_id': 'BTC-USD', 'changes': [['buy', '38281.32', '0.10000000']], 'time': '2021-05-20T03:55:58.103714Z'}
{'type': 'l2update', 'product_id': 'BTC-USD', 'changes': [['buy', '38311.03', '0.01492000']], 'time': '2021-05-20T03:55:58.104148Z'}
{'type': 'l2update', 'product_id': 'BTC-USD', 'changes': [['sell', '38326.53', '0.18981474']], 'time': '2021-05-20T03:55:58.104167Z'}
{'type': 'l2update', 'product_id': 'BTC-USD', 'changes': [['sell', '38497.71', '0.00000000']], 'time': '2021-05-20T03:55:58.106026Z'}
{'type': 'l2update', 'product_id': 'BTC-USD', 'changes': [['buy', '38310.55', '0.00000000']], 'time': '2021-05-20T03:55:58.106229Z'}
{'type': 'l2update', 'product_id': 'BTC-USD', 'changes': [['sell', '38335.37', '0.00000000']], 'time': '2021-05-20T03:55:58.110795Z'}
{'type': 'l2update', 'product_id': 'BTC-USD', 'changes': [['buy', '38310.95', '0.02124513']], 'time': '2021-05-20T03:55:58.110888Z'}
{'type': 'l2update', 'product_id': 'BTC-USD', 'changes': [['sell', '38388.30', '0.31382529']], 'time': '2021-05-20T03:55:58.111573Z'}
{'type': 'l2update', 'product_id': 'BTC-USD', 'changes': [['sell', '38440.83', '0.02961957']], 'time': '2021-05-20T03:55:58.111738Z'}
{'type': 'l2update', 'product_id': 'BTC-USD', 'changes': [['buy', '37516.54', '0.06952551']], 'time': '2021-05-20T03:55:58.112356Z'}
{'type': 'l2update', 'product_id': 'BTC-USD', 'changes': [['sell', '38319.20', '0.07460000']], 'time': '2021-05-20T03:55:58.112834Z'}
{'type': 'l2update', 'product_id': 'BTC-USD', 'changes': [['sell', '38333.59', '0.05000000']], 'time': '2021-05-20T03:55:58.112869Z'}
{'type': 'l2update', 'product_id': 'BTC-USD', 'changes': [['sell', '38378.99', '0.02668263']], 'time': '2021-05-20T03:55:58.112881Z'}
{'type': 'l2update', 'product_id': 'BTC-USD', 'changes': [['buy', '38242.24', '0.01000000']], 'time': '2021-05-20T03:55:58.112990Z'}
{'type': 'l2update', 'product_id': 'BTC-USD', 'changes': [['sell', '38319.04', '0.00000000']], 'time': '2021-05-20T03:55:58.117051Z'}
{'type': 'l2update', 'product_id': 'BTC-USD', 'changes': [['sell', '38319.52', '0.00000000']], 'time': '2021-05-20T03:55:58.118616Z'}
{'type': 'l2update', 'product_id': 'BTC-USD', 'changes': [['buy', '38311.03', '0.01176915']], 'time': '2021-05-20T03:55:58.119565Z'}
{'type': 'l2update', 'product_id': 'BTC-USD', 'changes': [['sell', '38368.15', '0.00000000']], 'time': '2021-05-20T03:55:58.119787Z'}
{'type': 'l2update', 'product_id': 'BTC-USD', 'changes': [['sell', '38369.33', '0.00000000']], 'time': '2021-05-20T03:55:58.122226Z'}
{'type': 'l2update', 'product_id': 'BTC-USD', 'changes': [['sell', '38352.31', '0.06323880']], 'time': '2021-05-20T03:55:58.123348Z'}
{'type': 'l2update', 'product_id': 'BTC-USD', 'changes': [['buy', '38310.95', '0.00000000']], 'time': '2021-05-20T03:55:58.124002Z'}
{'type': 'l2update', 'product_id': 'BTC-USD', 'changes': [['buy', '38311.03', '0.00000000']], 'time': '2021-05-20T03:55:58.124414Z'}
{'type': 'l2update', 'product_id': 'BTC-USD', 'changes': [['sell', '38337.06', '0.00000000']], 'time': '2021-05-20T03:55:58.125543Z'}
{'type': 'l2update', 'product_id': 'BTC-USD', 'changes': [['sell', '38319.52', '0.10000000']], 'time': '2021-05-20T03:55:58.131471Z'}
{'type': 'l2update', 'product_id': 'BTC-USD', 'changes': [['sell', '38319.20', '0.00000000']], 'time': '2021-05-20T03:55:58.131899Z'}
{'type': 'l2update', 'product_id': 'BTC-USD', 'changes': [['buy', '38307.11', '0.00000000']], 'time': '2021-05-20T03:55:58.132188Z'}
{'type': 'l2update', 'product_id': 'BTC-USD', 'changes': [['sell', '38333.59', '0.00000000']], 'time': '2021-05-20T03:55:58.132209Z'}
{'type': 'l2update', 'product_id': 'BTC-USD', 'changes': [['sell', '38368.24', '0.07000000']], 'time': '2021-05-20T03:55:58.138193Z'}
{'type': 'l2update', 'product_id': 'BTC-USD', 'changes': [['sell', '38393.24', '0.42835230']], 'time': '2021-05-20T03:55:58.139503Z'}
{'type': 'l2update', 'product_id': 'BTC-USD', 'changes': [['sell', '38370.44', '0.33363081']], 'time': '2021-05-20T03:55:58.139503Z'}
{'type': 'l2update', 'product_id': 'BTC-USD', 'changes': [['sell', '38362.65', '0.33433492']], 'time': '2021-05-20T03:55:58.139503Z'}
{'type': 'l2update', 'product_id': 'BTC-USD', 'changes': [['buy', '38290.42', '0.05011619']], 'time': '2021-05-20T03:55:58.140394Z'}
{'type': 'l2update', 'product_id': 'BTC-USD', 'changes': [['buy', '38291.23', '0.00000000']], 'time': '2021-05-20T03:55:58.141163Z'}
{'type': 'l2update', 'product_id': 'BTC-USD', 'changes': [['sell', '38352.33', '0.00000000']], 'time': '2021-05-20T03:55:58.142052Z'}
{'type': 'l2update', 'product_id': 'BTC-USD', 'changes': [['sell', '38380.49', '0.00000000']], 'time': '2021-05-20T03:55:58.142213Z'}
{'type': 'l2update', 'product_id': 'BTC-USD', 'changes': [['sell', '38367.81', '0.00000000']], 'time': '2021-05-20T03:55:58.142956Z'}
{'type': 'l2update', 'product_id': 'BTC-USD', 'changes': [['sell', '38326.48', '0.55300000']], 'time': '2021-05-20T03:55:58.144750Z'}
{'type': 'l2update', 'product_id': 'BTC-USD', 'changes': [['sell', '38581.82', '0.12959472']], 'time': '2021-05-20T03:55:58.145897Z'}
{'type': 'l2update', 'product_id': 'BTC-USD', 'changes': [['sell', '38358.07', '0.00000000']], 'time': '2021-05-20T03:55:58.146531Z'}
{'type': 'l2update', 'product_id': 'BTC-USD', 'changes': [['buy', '38156.56', '0.00000000']], 'time': '2021-05-20T03:55:58.147907Z'}
{'type': 'l2update', 'product_id': 'BTC-USD', 'changes': [['sell', '38485.74', '0.01000000']], 'time': '2021-05-20T03:55:58.149190Z'}
{'type': 'l2update', 'product_id': 'BTC-USD', 'changes': [['sell', '38326.53', '0.00000000']], 'time': '2021-05-20T03:55:58.149899Z'}
{'type': 'l2update', 'product_id': 'BTC-USD', 'changes': [['sell', '38368.24', '0.04000000']], 'time': '2021-05-20T03:55:58.151226Z'}
{'type': 'l2update', 'product_id': 'BTC-USD', 'changes': [['sell', '38424.22', '0.00000000']], 'time': '2021-05-20T03:55:58.153506Z'}
{'type': 'l2update', 'product_id': 'BTC-USD', 'changes': [['sell', '38417.94', '0.00000000']], 'time': '2021-05-20T03:55:58.153506Z'}
{'type': 'l2update', 'product_id': 'BTC-USD', 'changes': [['sell', '38388.30', '0.35192646']], 'time': '2021-05-20T03:55:58.154751Z'}
{'type': 'l2update', 'product_id': 'BTC-USD', 'changes': [['sell', '38649.94', '0.00000000']], 'time': '2021-05-20T03:55:58.157747Z'}
{'type': 'l2update', 'product_id': 'BTC-USD', 'changes': [['sell', '38414.80', '0.00000000']], 'time': '2021-05-20T03:55:58.158971Z'}
{'type': 'l2update', 'product_id': 'BTC-USD', 'changes': [['sell', '38319.52', '0.30000000']], 'time': '2021-05-20T03:55:58.159059Z'}
{'type': 'l2update', 'product_id': 'BTC-USD', 'changes': [['sell', '38334.25', '0.05000000']], 'time': '2021-05-20T03:55:58.159914Z'}
{'type': 'l2update', 'product_id': 'BTC-USD', 'changes': [['buy', '38307.09', '0.00000000']], 'time': '2021-05-20T03:55:58.160531Z'}
{'type': 'l2update', 'product_id': 'BTC-USD', 'changes': [['buy', '38240.70', '0.00000000']], 'time': '2021-05-20T03:55:58.160677Z'}
{'type': 'l2update', 'product_id': 'BTC-USD', 'changes': [['buy', '38303.72', '0.00000000']], 'time': '2021-05-20T03:55:58.161168Z'}
{'type': 'l2update', 'product_id': 'BTC-USD', 'changes': [['sell', '38368.24', '0.00000000']], 'time': '2021-05-20T03:55:58.168757Z'}
{'type': 'l2update', 'product_id': 'BTC-USD', 'changes': [['sell', '38353.11', '0.00000000']], 'time': '2021-05-20T03:55:58.170183Z'}
{'type': 'l2update', 'product_id': 'BTC-USD', 'changes': [['buy', '38303.73', '0.40135082']], 'time': '2021-05-20T03:55:58.170879Z'}
{'type': 'l2update', 'product_id': 'BTC-USD', 'changes': [['buy', '38303.68', '0.00000000']], 'time': '2021-05-20T03:55:58.172067Z'}
{'type': 'l2update', 'product_id': 'BTC-USD', 'changes': [['sell', '38319.52', '0.20000000']], 'time': '2021-05-20T03:55:58.175385Z'}
{'type': 'l2update', 'product_id': 'BTC-USD', 'changes': [['sell', '38342.21', '0.00000000']], 'time': '2021-05-20T03:55:58.175437Z'}
{'type': 'l2update', 'product_id': 'BTC-USD', 'changes': [['sell', '38375.71', '0.00000000']], 'time': '2021-05-20T03:55:58.179029Z'}
{'type': 'l2update', 'product_id': 'BTC-USD', 'changes': [['sell', '38409.20', '0.39633275']], 'time': '2021-05-20T03:55:58.179984Z'}
{'type': 'l2update', 'product_id': 'BTC-USD', 'changes': [['sell', '38634.85', '0.01294168']], 'time': '2021-05-20T03:55:58.181637Z'}
{'type': 'l2update', 'product_id': 'BTC-USD', 'changes': [['buy', '37516.54', '0.00000000']], 'time': '2021-05-20T03:55:58.182349Z'}
{'type': 'l2update', 'product_id': 'BTC-USD', 'changes': [['buy', '38281.32', '0.09000000']], 'time': '2021-05-20T03:55:58.185437Z'}
{'type': 'l2update', 'product_id': 'BTC-USD', 'changes': [['sell', '38435.00', '0.00000000']], 'time': '2021-05-20T03:55:58.185926Z'}
{'type': 'l2update', 'product_id': 'BTC-USD', 'changes': [['buy', '38295.22', '0.06323880']], 'time': '2021-05-20T03:55:58.188046Z'}
{'type': 'l2update', 'product_id': 'BTC-USD', 'changes': [['sell', '38393.22', '0.03787810']], 'time': '2021-05-20T03:55:58.188163Z'}
{'type': 'l2update', 'product_id': 'BTC-USD', 'changes': [['buy', '37002.00', '0.09355921']], 'time': '2021-05-20T03:55:58.192063Z'}
{'type': 'l2update', 'product_id': 'BTC-USD', 'changes': [['sell', '38568.14', '0.00000000']], 'time': '2021-05-20T03:55:58.193729Z'}
{'type': 'l2update', 'product_id': 'BTC-USD', 'changes': [['buy', '38291.11', '0.00000000']], 'time': '2021-05-20T03:55:58.195491Z'}
{'type': 'l2update', 'product_id': 'BTC-USD', 'changes': [['sell', '38352.31', '0.00000000']], 'time': '2021-05-20T03:55:58.197881Z'}
{'type': 'l2update', 'product_id': 'BTC-USD', 'changes': [['sell', '38326.47', '0.18981474']], 'time': '2021-05-20T03:55:58.198323Z'}
{'type': 'l2update', 'product_id': 'BTC-USD', 'changes': [['sell', '38400.96', '0.00000000']], 'time': '2021-05-20T03:55:58.199413Z'}
{'type': 'l2update', 'product_id': 'BTC-USD', 'changes': [['sell', '38367.42', '0.00000000']], 'time': '2021-05-20T03:55:58.200193Z'}
{'type': 'l2update', 'product_id': 'BTC-USD', 'changes': [['sell', '38317.61', '0.07460000']], 'time': '2021-05-20T03:55:58.203741Z'}
{'type': 'l2update', 'product_id': 'BTC-USD', 'changes': [['sell', '38317.61', '0.17460000']], 'time': '2021-05-20T03:55:58.203886Z'}
{'type': 'l2update', 'product_id': 'BTC-USD', 'changes': [['sell', '38317.61', '0.18952000']], 'time': '2021-05-20T03:55:58.207373Z'}
{'type': 'l2update', 'product_id': 'BTC-USD', 'changes': [['sell', '38420.80', '0.38384211']], 'time': '2021-05-20T03:55:58.207968Z'}
{'type': 'l2update', 'product_id': 'BTC-USD', 'changes': [['buy', '38291.24', '0.45800000']], 'time': '2021-05-20T03:55:58.210261Z'}
{'type': 'l2update', 'product_id': 'BTC-USD', 'changes': [['sell', '38334.27', '0.18300000']], 'time': '2021-05-20T03:55:58.211157Z'}
{'type': 'l2update', 'product_id': 'BTC-USD', 'changes': [['buy', '38297.64', '0.99440510']], 'time': '2021-05-20T03:55:58.211812Z'}
{'type': 'l2update', 'product_id': 'BTC-USD', 'changes': [['sell', '38465.47', '0.01000000']], 'time': '2021-05-20T03:55:58.213622Z'}
{'type': 'l2update', 'product_id': 'BTC-USD', 'changes': [['sell', '38404.81', '0.03843789']], 'time': '2021-05-20T03:55:58.213991Z'}
{'type': 'l2update', 'product_id': 'BTC-USD', 'changes': [['sell', '43100.00', '1.09530000']], 'time': '2021-05-20T03:55:58.214709Z'}
{'type': 'l2update', 'product_id': 'BTC-USD', 'changes': [['buy', '38317.60', '0.00000000']], 'time': '2021-05-20T03:55:58.215340Z'}
{'type': 'l2update', 'product_id': 'BTC-USD', 'changes': [['sell', '38326.54', '0.75000000']], 'time': '2021-05-20T03:55:58.219239Z'}
{'type': 'l2update', 'product_id': 'BTC-USD', 'changes': [['buy', '38117.50', '0.00000000']], 'time': '2021-05-20T03:55:58.221633Z'}
{'type': 'l2update', 'product_id': 'BTC-USD', 'changes': [['sell', '38484.36', '0.30084803']], 'time': '2021-05-20T03:55:58.222407Z'}
{'type': 'l2update', 'product_id': 'BTC-USD', 'changes': [['sell', '38355.37', '0.01000000']], 'time': '2021-05-20T03:55:58.222602Z'}
{'type': 'l2update', 'product_id': 'BTC-USD', 'changes': [['buy', '38303.67', '0.00000000']], 'time': '2021-05-20T03:55:58.223512Z'}
{'type': 'l2update', 'product_id': 'BTC-USD', 'changes': [['buy', '38181.84', '0.00000000']], 'time': '2021-05-20T03:55:58.225638Z'}
{'type': 'l2update', 'product_id': 'BTC-USD', 'changes': [['buy', '38231.55', '0.00000000']], 'time': '2021-05-20T03:55:58.226013Z'}
{'type': 'l2update', 'product_id': 'BTC-USD', 'changes': [['sell', '38426.89', '0.43427502']], 'time': '2021-05-20T03:55:58.227047Z'}
{'type': 'l2update', 'product_id': 'BTC-USD', 'changes': [['sell', '38317.61', '0.38952000']], 'time': '2021-05-20T03:55:58.227760Z'}
{'type': 'l2update', 'product_id': 'BTC-USD', 'changes': [['sell', '38317.61', '0.41952000']], 'time': '2021-05-20T03:55:58.228107Z'}
{'type': 'l2update', 'product_id': 'BTC-USD', 'changes': [['sell', '38417.95', '0.02892186']], 'time': '2021-05-20T03:55:58.236875Z'}
{'type': 'l2update', 'product_id': 'BTC-USD', 'changes': [['buy', '38270.85', '0.00000000']], 'time': '2021-05-20T03:55:58.237193Z'}
{'type': 'l2update', 'product_id': 'BTC-USD', 'changes': [['sell', '38329.14', '0.00000000']], 'time': '2021-05-20T03:55:58.238266Z'}
{'type': 'l2update', 'product_id': 'BTC-USD', 'changes': [['sell', '38363.70', '0.00000000']], 'time': '2021-05-20T03:55:58.240922Z'}
{'type': 'l2update', 'product_id': 'BTC-USD', 'changes': [['sell', '38317.61', '0.34492000']], 'time': '2021-05-20T03:55:58.242101Z'}
{'type': 'l2update', 'product_id': 'BTC-USD', 'changes': [['sell', '38334.25', '0.00000000']], 'time': '2021-05-20T03:55:58.242190Z'}
{'type': 'l2update', 'product_id': 'BTC-USD', 'changes': [['sell', '38633.58', '0.01000000']], 'time': '2021-05-20T03:55:58.243942Z'}
{'type': 'l2update', 'product_id': 'BTC-USD', 'changes': [['sell', '43100.00', '2.25120000']], 'time': '2021-05-20T03:55:58.244033Z'}
{'type': 'l2update', 'product_id': 'BTC-USD', 'changes': [['sell', '38317.61', '0.33000000']], 'time': '2021-05-20T03:55:58.244241Z'}
{'type': 'l2update', 'product_id': 'BTC-USD', 'changes': [['sell', '38319.52', '0.00000000']], 'time': '2021-05-20T03:55:58.245275Z'}
{'type': 'l2update', 'product_id': 'BTC-USD', 'changes': [['sell', '38317.60', '0.07150000']], 'time': '2021-05-20T03:55:58.245313Z'}
{'type': 'l2update', 'product_id': 'BTC-USD', 'changes': [['sell', '38317.60', '0.07723000']], 'time': '2021-05-20T03:55:58.245334Z'}
{'type': 'l2update', 'product_id': 'BTC-USD', 'changes': [['sell', '38357.58', '0.02000000']], 'time': '2021-05-20T03:55:58.245615Z'}
{'type': 'l2update', 'product_id': 'BTC-USD', 'changes': [['sell', '38341.86', '0.06323880']], 'time': '2021-05-20T03:55:58.246079Z'}
{'type': 'l2update', 'product_id': 'BTC-USD', 'changes': [['sell', '38424.22', '0.36085961']], 'time': '2021-05-20T03:55:58.251129Z'}
{'type': 'l2update', 'product_id': 'BTC-USD', 'changes': [['sell', '38369.30', '0.00000000']], 'time': '2021-05-20T03:55:58.251358Z'}
{'type': 'l2update', 'product_id': 'BTC-USD', 'changes': [['buy', '38281.31', '0.00000000']], 'time': '2021-05-20T03:55:58.252068Z'}
{'type': 'l2update', 'product_id': 'BTC-USD', 'changes': [['sell', '38347.69', '0.48458600']], 'time': '2021-05-20T03:55:58.253201Z'}
{'type': 'l2update', 'product_id': 'BTC-USD', 'changes': [['buy', '38168.87', '0.07692300']], 'time': '2021-05-20T03:55:58.253512Z'}
{'type': 'l2update', 'product_id': 'BTC-USD', 'changes': [['buy', '38218.41', '0.01000000']], 'time': '2021-05-20T03:55:58.253751Z'}
{'type': 'l2update', 'product_id': 'BTC-USD', 'changes': [['sell', '38347.69', '0.58253341']], 'time': '2021-05-20T03:55:58.254498Z'}
{'type': 'l2update', 'product_id': 'BTC-USD', 'changes': [['sell', '38317.61', '0.23000000']], 'time': '2021-05-20T03:55:58.261140Z'}
{'type': 'l2update', 'product_id': 'BTC-USD', 'changes': [['sell', '38465.47', '0.00000000']], 'time': '2021-05-20T03:55:58.261893Z'}
{'type': 'l2update', 'product_id': 'BTC-USD', 'changes': [['buy', '38180.12', '0.00000000']], 'time': '2021-05-20T03:55:58.266505Z'}
{'type': 'l2update', 'product_id': 'BTC-USD', 'changes': [['buy', '38303.73', '0.00000000']], 'time': '2021-05-20T03:55:58.266553Z'}
{'type': 'l2update', 'product_id': 'BTC-USD', 'changes': [['sell', '38317.61', '0.23573000']], 'time': '2021-05-20T03:55:58.267114Z'}
{'type': 'l2update', 'product_id': 'BTC-USD', 'changes': [['sell', '38357.92', '0.03000000']], 'time': '2021-05-20T03:55:58.267251Z'}
{'type': 'l2update', 'product_id': 'BTC-USD', 'changes': [['buy', '38291.25', '0.06323880']], 'time': '2021-05-20T03:55:58.267464Z'}
{'type': 'l2update', 'product_id': 'BTC-USD', 'changes': [['sell', '38326.46', '1.40821406']], 'time': '2021-05-20T03:55:58.267792Z'}
{'type': 'l2update', 'product_id': 'BTC-USD', 'changes': [['sell', '38352.32', '0.00000000']], 'time': '2021-05-20T03:55:58.267811Z'}
{'type': 'l2update', 'product_id': 'BTC-USD', 'changes': [['buy', '38310.56', '0.09165188']], 'time': '2021-05-20T03:55:58.268021Z'}
{'type': 'l2update', 'product_id': 'BTC-USD', 'changes': [['sell', '38333.59', '0.05000000']], 'time': '2021-05-20T03:55:58.268074Z'}
{'type': 'l2update', 'product_id': 'BTC-USD', 'changes': [['sell', '38424.23', '0.02836959']], 'time': '2021-05-20T03:55:58.268770Z'}
{'type': 'l2update', 'product_id': 'BTC-USD', 'changes': [['buy', '37507.14', '0.06619636']], 'time': '2021-05-20T03:55:58.268855Z'}
{'type': 'l2update', 'product_id': 'BTC-USD', 'changes': [['buy', '38080.03', '0.02626047']], 'time': '2021-05-20T03:55:58.269057Z'}
{'type': 'l2update', 'product_id': 'BTC-USD', 'changes': [['sell', '38447.31', '0.00000000']], 'time': '2021-05-20T03:55:58.272131Z'}
{'type': 'l2update', 'product_id': 'BTC-USD', 'changes': [['sell', '38326.54', '0.25000000']], 'time': '2021-05-20T03:55:58.272263Z'}
{'type': 'l2update', 'product_id': 'BTC-USD', 'changes': [['sell', '38317.61', '0.03573000']], 'time': '2021-05-20T03:55:58.274448Z'}
{'type': 'l2update', 'product_id': 'BTC-USD', 'changes': [['buy', '38261.48', '0.00000000']], 'time': '2021-05-20T03:55:58.275983Z'}
{'type': 'l2update', 'product_id': 'BTC-USD', 'changes': [['sell', '38435.64', '0.61997676']], 'time': '2021-05-20T03:55:58.276992Z'}
{'type': 'l2update', 'product_id': 'BTC-USD', 'changes': [['buy', '38295.27', '0.84700000']], 'time': '2021-05-20T03:55:58.277275Z'}
{'type': 'l2update', 'product_id': 'BTC-USD', 'changes': [['sell', '38317.60', '0.07150000']], 'time': '2021-05-20T03:55:58.278204Z'}
{'type': 'l2update', 'product_id': 'BTC-USD', 'changes': [['buy', '38292.50', '0.00000000']], 'time': '2021-05-20T03:55:58.282634Z'}
{'type': 'l2update', 'product_id': 'BTC-USD', 'changes': [['sell', '38478.45', '0.00000000']], 'time': '2021-05-20T03:55:58.282977Z'}
{'type': 'l2update', 'product_id': 'BTC-USD', 'changes': [['sell', '38326.47', '0.00000000']], 'time': '2021-05-20T03:55:58.283302Z'}
{'type': 'l2update', 'product_id': 'BTC-USD', 'changes': [['sell', '38357.92', '0.07000000']], 'time': '2021-05-20T03:55:58.287926Z'}
{'type': 'l2update', 'product_id': 'BTC-USD', 'changes': [['sell', '38368.16', '0.00000000']], 'time': '2021-05-20T03:55:58.290238Z'}
{'type': 'l2update', 'product_id': 'BTC-USD', 'changes': [['sell', '38317.61', '0.03000000']], 'time': '2021-05-20T03:55:58.291523Z'}
{'type': 'l2update', 'product_id': 'BTC-USD', 'changes': [['sell', '38341.86', '0.00000000']], 'time': '2021-05-20T03:55:58.292022Z'}
{'type': 'l2update', 'product_id': 'BTC-USD', 'changes': [['sell', '38427.75', '0.06419094']], 'time': '2021-05-20T03:55:58.294954Z'}
{'type': 'l2update', 'product_id': 'BTC-USD', 'changes': [['buy', '38295.22', '0.00000000']], 'time': '2021-05-20T03:55:58.297070Z'}
{'type': 'l2update', 'product_id': 'BTC-USD', 'changes': [['sell', '38317.59', '0.50000000']], 'time': '2021-05-20T03:55:58.300218Z'}
{'type': 'l2update', 'product_id': 'BTC-USD', 'changes': [['sell', '38444.21', '0.30183056']], 'time': '2021-05-20T03:55:58.300293Z'}
{'type': 'l2update', 'product_id': 'BTC-USD', 'changes': [['sell', '38357.52', '0.43569699']], 'time': '2021-05-20T03:55:58.300293Z'}
{'type': 'l2update', 'product_id': 'BTC-USD', 'changes': [['buy', '38282.17', '0.00000000']], 'time': '2021-05-20T03:55:58.300875Z'}
{'type': 'l2update', 'product_id': 'BTC-USD', 'changes': [['buy', '38291.25', '0.00000000']], 'time': '2021-05-20T03:55:58.302206Z'}
{'type': 'l2update', 'product_id': 'BTC-USD', 'changes': [['sell', '38430.70', '0.02781061']], 'time': '2021-05-20T03:55:58.302606Z'}
{'type': 'l2update', 'product_id': 'BTC-USD', 'changes': [['sell', '38310.57', '0.00676799']], 'time': '2021-05-20T03:55:58.307712Z'}
{'type': 'l2update', 'product_id': 'BTC-USD', 'changes': [['sell', '38310.57', '0.08136799']], 'time': '2021-05-20T03:55:58.308006Z'}
{'type': 'l2update', 'product_id': 'BTC-USD', 'changes': [['buy', '38288.18', '0.01000000']], 'time': '2021-05-20T03:55:58.308022Z'}
{'type': 'l2update', 'product_id': 'BTC-USD', 'changes': [['sell', '38465.29', '0.01000000']], 'time': '2021-05-20T03:55:58.308281Z'}
{'type': 'l2update', 'product_id': 'BTC-USD', 'changes': [['buy', '38289.60', '0.02400000']], 'time': '2021-05-20T03:55:58.308651Z'}
{'type': 'l2update', 'product_id': 'BTC-USD', 'changes': [['sell', '38336.97', '0.06323880']], 'time': '2021-05-20T03:55:58.308950Z'}
{'type': 'l2update', 'product_id': 'BTC-USD', 'changes': [['sell', '38374.62', '0.03755109']], 'time': '2021-05-20T03:55:58.313404Z'}
{'type': 'l2update', 'product_id': 'BTC-USD', 'changes': [['sell', '38440.83', '0.00000000']], 'time': '2021-05-20T03:55:58.314092Z'}
{'type': 'l2update', 'product_id': 'BTC-USD', 'changes': [['sell', '38447.94', '0.01000000']], 'time': '2021-05-20T03:55:58.314286Z'}
{'type': 'l2update', 'product_id': 'BTC-USD', 'changes': [['buy', '38297.65', '0.40135082']], 'time': '2021-05-20T03:55:58.314944Z'}
{'type': 'l2update', 'product_id': 'BTC-USD', 'changes': [['buy', '38295.27', '0.00000000']], 'time': '2021-05-20T03:55:58.315165Z'}
{'type': 'l2update', 'product_id': 'BTC-USD', 'changes': [['buy', '38297.63', '0.00000000']], 'time': '2021-05-20T03:55:58.315178Z'}
{'type': 'l2update', 'product_id': 'BTC-USD', 'changes': [['sell', '38310.57', '0.07460000']], 'time': '2021-05-20T03:55:58.321755Z'}
{'type': 'l2update', 'product_id': 'BTC-USD', 'changes': [['sell', '38317.61', '0.00000000']], 'time': '2021-05-20T03:55:58.322983Z'}
{'type': 'l2update', 'product_id': 'BTC-USD', 'changes': [['sell', '38430.70', '0.05601847']], 'time': '2021-05-20T03:55:58.324969Z'}
{'type': 'l2update', 'product_id': 'BTC-USD', 'changes': [['buy', '38277.69', '0.00000000']], 'time': '2021-05-20T03:55:58.326997Z'}
{'type': 'l2update', 'product_id': 'BTC-USD', 'changes': [['sell', '38387.75', '0.00000000']], 'time': '2021-05-20T03:55:58.326997Z'}
{'type': 'l2update', 'product_id': 'BTC-USD', 'changes': [['buy', '38289.13', '0.00000000']], 'time': '2021-05-20T03:55:58.327603Z'}
{'type': 'l2update', 'product_id': 'BTC-USD', 'changes': [['sell', '38333.62', '0.00000000']], 'time': '2021-05-20T03:55:58.329061Z'}
{'type': 'l2update', 'product_id': 'BTC-USD', 'changes': [['sell', '38347.70', '0.00000000']], 'time': '2021-05-20T03:55:58.329839Z'}
{'type': 'l2update', 'product_id': 'BTC-USD', 'changes': [['buy', '38289.85', '0.00000000']], 'time': '2021-05-20T03:55:58.331269Z'}
{'type': 'l2update', 'product_id': 'BTC-USD', 'changes': [['sell', '38451.25', '0.43508813']], 'time': '2021-05-20T03:55:58.332471Z'}
{'type': 'l2update', 'product_id': 'BTC-USD', 'changes': [['sell', '38360.26', '0.05000000']], 'time': '2021-05-20T03:55:58.333074Z'}
{'type': 'l2update', 'product_id': 'BTC-USD', 'changes': [['sell', '38310.57', '0.10460000']], 'time': '2021-05-20T03:55:58.333243Z'}
{'type': 'l2update', 'product_id': 'BTC-USD', 'changes': [['sell', '38310.57', '0.20460000']], 'time': '2021-05-20T03:55:58.333545Z'}
{'type': 'l2update', 'product_id': 'BTC-USD', 'changes': [['sell', '38310.57', '0.23350000']], 'time': '2021-05-20T03:55:58.333599Z'}
{'type': 'l2update', 'product_id': 'BTC-USD', 'changes': [['buy', '38289.14', '0.06323880']], 'time': '2021-05-20T03:55:58.333902Z'}
{'type': 'l2update', 'product_id': 'BTC-USD', 'changes': [['buy', '38080.03', '0.00000000']], 'time': '2021-05-20T03:55:58.339645Z'}
{'type': 'l2update', 'product_id': 'BTC-USD', 'changes': [['buy', '38229.82', '0.00000000']], 'time': '2021-05-20T03:55:58.341448Z'}
{'type': 'l2update', 'product_id': 'BTC-USD', 'changes': [['sell', '38362.85', '0.00000000']], 'time': '2021-05-20T03:55:58.341498Z'}
{'type': 'l2update', 'product_id': 'BTC-USD', 'changes': [['buy', '38302.59', '0.00000000']], 'time': '2021-05-20T03:55:58.341498Z'}
{'type': 'l2update', 'product_id': 'BTC-USD', 'changes': [['buy', '38297.64', '0.00000000']], 'time': '2021-05-20T03:55:58.342218Z'}
{'type': 'l2update', 'product_id': 'BTC-USD', 'changes': [['buy', '38310.56', '0.07154666']], 'time': '2021-05-20T03:55:58.347621Z'}
{'type': 'l2update', 'product_id': 'BTC-USD', 'changes': [['sell', '38459.16', '0.00000000']], 'time': '2021-05-20T03:55:58.347832Z'}
{'type': 'l2update', 'product_id': 'BTC-USD', 'changes': [['buy', '38291.22', '0.00000000']], 'time': '2021-05-20T03:55:58.347859Z'}
{'type': 'l2update', 'product_id': 'BTC-USD', 'changes': [['buy', '38290.42', '0.02611619']], 'time': '2021-05-20T03:55:58.347859Z'}
{'type': 'l2update', 'product_id': 'BTC-USD', 'changes': [['buy', '38289.60', '0.00000000']], 'time': '2021-05-20T03:55:58.347859Z'}
{'type': 'l2update', 'product_id': 'BTC-USD', 'changes': [['sell', '38357.58', '0.00000000']], 'time': '2021-05-20T03:55:58.348958Z'}
{'type': 'l2update', 'product_id': 'BTC-USD', 'changes': [['sell', '38429.30', '0.05272600']], 'time': '2021-05-20T03:55:58.349107Z'}
{'type': 'l2update', 'product_id': 'BTC-USD', 'changes': [['buy', '38269.53', '1.20000000']], 'time': '2021-05-20T03:55:58.349599Z'}
{'type': 'l2update', 'product_id': 'BTC-USD', 'changes': [['sell', '38420.80', '0.00000000']], 'time': '2021-05-20T03:55:58.350766Z'}
{'type': 'l2update', 'product_id': 'BTC-USD', 'changes': [['sell', '38409.20', '0.00000000']], 'time': '2021-05-20T03:55:58.350766Z'}
{'type': 'l2update', 'product_id': 'BTC-USD', 'changes': [['sell', '38388.30', '0.03810117']], 'time': '2021-05-20T03:55:58.350766Z'}
{'type': 'l2update', 'product_id': 'BTC-USD', 'changes': [['sell', '38370.44', '0.00000000']], 'time': '2021-05-20T03:55:58.350766Z'}
{'type': 'l2update', 'product_id': 'BTC-USD', 'changes': [['sell', '38367.76', '0.00000000']], 'time': '2021-05-20T03:55:58.352285Z'}
{'type': 'l2update', 'product_id': 'BTC-USD', 'changes': [['buy', '37500.01', '0.00080000']], 'time': '2021-05-20T03:55:58.353379Z'}
{'type': 'l2update', 'product_id': 'BTC-USD', 'changes': [['buy', '38310.56', '0.00000000']], 'time': '2021-05-20T03:55:58.357843Z'}
{'type': 'l2update', 'product_id': 'BTC-USD', 'changes': [['sell', '38310.57', '0.43350000']], 'time': '2021-05-20T03:55:58.358842Z'}
{'type': 'l2update', 'product_id': 'BTC-USD', 'changes': [['sell', '38339.40', '0.39490432']], 'time': '2021-05-20T03:55:58.359413Z'}
{'type': 'l2update', 'product_id': 'BTC-USD', 'changes': [['sell', '38357.92', '0.04000000']], 'time': '2021-05-20T03:55:58.361945Z'}
{'type': 'l2update', 'product_id': 'BTC-USD', 'changes': [['sell', '38317.58', '2.48969908']], 'time': '2021-05-20T03:55:58.364246Z'}
{'type': 'l2update', 'product_id': 'BTC-USD', 'changes': [['sell', '38369.09', '0.00000000']], 'time': '2021-05-20T03:55:58.364990Z'}
{'type': 'l2update', 'product_id': 'BTC-USD', 'changes': [['sell', '38447.50', '0.01219214']], 'time': '2021-05-20T03:55:58.365465Z'}
{'type': 'l2update', 'product_id': 'BTC-USD', 'changes': [['sell', '38359.04', '0.00000000']], 'time': '2021-05-20T03:55:58.367679Z'}
{'type': 'l2update', 'product_id': 'BTC-USD', 'changes': [['buy', '38268.66', '0.00000000']], 'time': '2021-05-20T03:55:58.367679Z'}
{'type': 'l2update', 'product_id': 'BTC-USD', 'changes': [['sell', '38461.39', '0.00000000']], 'time': '2021-05-20T03:55:58.367846Z'}
{'type': 'l2update', 'product_id': 'BTC-USD', 'changes': [['buy', '38289.14', '0.00000000']], 'time': '2021-05-20T03:55:58.372295Z'}
{'type': 'l2update', 'product_id': 'BTC-USD', 'changes': [['sell', '38357.92', '0.00000000']], 'time': '2021-05-20T03:55:58.374040Z'}
{'type': 'l2update', 'product_id': 'BTC-USD', 'changes': [['sell', '38333.59', '0.00000000']], 'time': '2021-05-20T03:55:58.375345Z'}
{'type': 'l2update', 'product_id': 'BTC-USD', 'changes': [['buy', '38297.65', '0.00000000']], 'time': '2021-05-20T03:55:58.379362Z'}
{'type': 'l2update', 'product_id': 'BTC-USD', 'changes': [['sell', '38348.60', '0.81718274']], 'time': '2021-05-20T03:55:58.382157Z'}
{'type': 'l2update', 'product_id': 'BTC-USD', 'changes': [['sell', '38432.50', '1.20000000']], 'time': '2021-05-20T03:55:58.382359Z'}
{'type': 'l2update', 'product_id': 'BTC-USD', 'changes': [['buy', '38288.45', '0.02400000']], 'time': '2021-05-20T03:55:58.382570Z'}
{'type': 'l2update', 'product_id': 'BTC-USD', 'changes': [['buy', '38287.64', '0.02400000']], 'time': '2021-05-20T03:55:58.382570Z'}
{'type': 'l2update', 'product_id': 'BTC-USD', 'changes': [['buy', '38286.83', '0.02400000']], 'time': '2021-05-20T03:55:58.382570Z'}
{'type': 'l2update', 'product_id': 'BTC-USD', 'changes': [['buy', '38297.93', '0.07460000']], 'time': '2021-05-20T03:55:58.383435Z'}
{'type': 'l2update', 'product_id': 'BTC-USD', 'changes': [['sell', '38336.97', '0.00000000']], 'time': '2021-05-20T03:55:58.386509Z'}
{'type': 'l2update', 'product_id': 'BTC-USD', 'changes': [['sell', '38360.26', '0.00000000']], 'time': '2021-05-20T03:55:58.387200Z'}
{'type': 'l2update', 'product_id': 'BTC-USD', 'changes': [['sell', '38358.51', '0.00000000']], 'time': '2021-05-20T03:55:58.388467Z'}
{'type': 'l2update', 'product_id': 'BTC-USD', 'changes': [['sell', '38362.65', '0.03477275']], 'time': '2021-05-20T03:55:58.394793Z'}
{'type': 'l2update', 'product_id': 'BTC-USD', 'changes': [['sell', '38485.74', '0.00000000']], 'time': '2021-05-20T03:55:58.394922Z'}
{'type': 'l2update', 'product_id': 'BTC-USD', 'changes': [['buy', '38269.53', '0.00000000']], 'time': '2021-05-20T03:55:58.396085Z'}
{'type': 'l2update', 'product_id': 'BTC-USD', 'changes': [['buy', '38297.93', '0.00000000']], 'time': '2021-05-20T03:55:58.396318Z'}
{'type': 'l2update', 'product_id': 'BTC-USD', 'changes': [['buy', '38288.45', '0.00000000']], 'time': '2021-05-20T03:55:58.397136Z'}
{'type': 'l2update', 'product_id': 'BTC-USD', 'changes': [['buy', '38287.64', '0.00000000']], 'time': '2021-05-20T03:55:58.397136Z'}
{'type': 'l2update', 'product_id': 'BTC-USD', 'changes': [['buy', '38286.83', '0.00000000']], 'time': '2021-05-20T03:55:58.397136Z'}
{'type': 'l2update', 'product_id': 'BTC-USD', 'changes': [['sell', '38445.97', '0.00000000']], 'time': '2021-05-20T03:55:58.397232Z'}
{'type': 'l2update', 'product_id': 'BTC-USD', 'changes': [['buy', '38277.70', '0.00000000']], 'time': '2021-05-20T03:55:58.397796Z'}
{'type': 'l2update', 'product_id': 'BTC-USD', 'changes': [['sell', '38326.45', '0.05000000']], 'time': '2021-05-20T03:55:58.400281Z'}
{'type': 'l2update', 'product_id': 'BTC-USD', 'changes': [['buy', '38093.41', '0.01081700']], 'time': '2021-05-20T03:55:58.400695Z'}
{'type': 'l2update', 'product_id': 'BTC-USD', 'changes': [['sell', '38448.18', '0.03584250']], 'time': '2021-05-20T03:55:58.400756Z'}
{'type': 'l2update', 'product_id': 'BTC-USD', 'changes': [['buy', '38256.16', '0.01000000']], 'time': '2021-05-20T03:55:58.400854Z'}
{'type': 'l2update', 'product_id': 'BTC-USD', 'changes': [['sell', '38432.50', '0.00000000']], 'time': '2021-05-20T03:55:58.401165Z'}
{'type': 'l2update', 'product_id': 'BTC-USD', 'changes': [['sell', '38310.06', '0.01492000']], 'time': '2021-05-20T03:55:58.401433Z'}
{'type': 'l2update', 'product_id': 'BTC-USD', 'changes': [['buy', '38298.25', '0.00938915']], 'time': '2021-05-20T03:55:58.401558Z'}
{'type': 'l2update', 'product_id': 'BTC-USD', 'changes': [['buy', '38291.25', '0.99440510']], 'time': '2021-05-20T03:55:58.403237Z'}
{'type': 'l2update', 'product_id': 'BTC-USD', 'changes': [['buy', '38291.24', '0.00000000']], 'time': '2021-05-20T03:55:58.407911Z'}
{'type': 'l2update', 'product_id': 'BTC-USD', 'changes': [['buy', '38295.67', '0.07460000']], 'time': '2021-05-20T03:55:58.411463Z'}
{'type': 'l2update', 'product_id': 'BTC-USD', 'changes': [['sell', '38315.23', '0.00600000']], 'time': '2021-05-20T03:55:58.412621Z'}
{'type': 'l2update', 'product_id': 'BTC-USD', 'changes': [['buy', '38288.50', '0.84800000']], 'time': '2021-05-20T03:55:58.412798Z'}
{'type': 'l2update', 'product_id': 'BTC-USD', 'changes': [['sell', '38351.55', '0.02000000']], 'time': '2021-05-20T03:55:58.413336Z'}
{'type': 'l2update', 'product_id': 'BTC-USD', 'changes': [['sell', '38334.25', '0.06323880']], 'time': '2021-05-20T03:55:58.413730Z'}
{'type': 'l2update', 'product_id': 'BTC-USD', 'changes': [['buy', '38298.25', '0.01492000']], 'time': '2021-05-20T03:55:58.414450Z'}
{'type': 'l2update', 'product_id': 'BTC-USD', 'changes': [['buy', '38282.04', '0.06323880']], 'time': '2021-05-20T03:55:58.414932Z'}
{'type': 'l2update', 'product_id': 'BTC-USD', 'changes': [['buy', '38298.25', '0.00553085']], 'time': '2021-05-20T03:55:58.415464Z'}
{'type': 'l2update', 'product_id': 'BTC-USD', 'changes': [['sell', '38310.57', '0.35890000']], 'time': '2021-05-20T03:55:58.415610Z'}
{'type': 'l2update', 'product_id': 'BTC-USD', 'changes': [['buy', '37507.14', '0.00000000']], 'time': '2021-05-20T03:55:58.415846Z'}
{'type': 'l2update', 'product_id': 'BTC-USD', 'changes': [['sell', '38310.57', '0.33000000']], 'time': '2021-05-20T03:55:58.416257Z'}
{'type': 'l2update', 'product_id': 'BTC-USD', 'changes': [['sell', '38310.57', '0.23000000']], 'time': '2021-05-20T03:55:58.417140Z'}
{'type': 'l2update', 'product_id': 'BTC-USD', 'changes': [['buy', '38288.50', '0.00000000']], 'time': '2021-05-20T03:55:58.423089Z'}
{'type': 'l2update', 'product_id': 'BTC-USD', 'changes': [['sell', '38339.65', '0.01242992']], 'time': '2021-05-20T03:55:58.424798Z'}
{'type': 'l2update', 'product_id': 'BTC-USD', 'changes': [['buy', '38177.43', '0.03353501']], 'time': '2021-05-20T03:55:58.424798Z'}
{'type': 'l2update', 'product_id': 'BTC-USD', 'changes': [['buy', '38259.15', '0.32000000']], 'time': '2021-05-20T03:55:58.425234Z'}
{'type': 'l2update', 'product_id': 'BTC-USD', 'changes': [['sell', '38368.18', '0.32000000']], 'time': '2021-05-20T03:55:58.425234Z'}
{'type': 'l2update', 'product_id': 'BTC-USD', 'changes': [['buy', '38298.25', '0.00000000']], 'time': '2021-05-20T03:55:58.425974Z'}
{'type': 'l2update', 'product_id': 'BTC-USD', 'changes': [['buy', '38285.73', '0.06419024']], 'time': '2021-05-20T03:55:58.426078Z'}
{'type': 'l2update', 'product_id': 'BTC-USD', 'changes': [['sell', '38327.93', '0.04377129']], 'time': '2021-05-20T03:55:58.426078Z'}
{'type': 'l2update', 'product_id': 'BTC-USD', 'changes': [['buy', '38223.13', '0.00000000']], 'time': '2021-05-20T03:55:58.426410Z'}
{'type': 'l2update', 'product_id': 'BTC-USD', 'changes': [['buy', '38278.73', '0.58400000']], 'time': '2021-05-20T03:55:58.427369Z'}
{'type': 'l2update', 'product_id': 'BTC-USD', 'changes': [['buy', '38277.50', '0.00000000']], 'time': '2021-05-20T03:55:58.428338Z'}
{'type': 'l2update', 'product_id': 'BTC-USD', 'changes': [['sell', '38447.94', '0.00000000']], 'time': '2021-05-20T03:55:58.428843Z'}
{'type': 'l2update', 'product_id': 'BTC-USD', 'changes': [['buy', '38291.25', '0.00000000']], 'time': '2021-05-20T03:55:58.430436Z'}
{'type': 'l2update', 'product_id': 'BTC-USD', 'changes': [['sell', '38310.57', '0.03000000']], 'time': '2021-05-20T03:55:58.431249Z'}
{'type': 'l2update', 'product_id': 'BTC-USD', 'changes': [['sell', '38469.79', '0.01000000']], 'time': '2021-05-20T03:55:58.431842Z'}
{'type': 'l2update', 'product_id': 'BTC-USD', 'changes': [['buy', '38289.06', '0.00300000']], 'time': '2021-05-20T03:55:58.432410Z'}
{'type': 'l2update', 'product_id': 'BTC-USD', 'changes': [['sell', '38351.55', '0.05000000']], 'time': '2021-05-20T03:55:58.438019Z'}
{'type': 'l2update', 'product_id': 'BTC-USD', 'changes': [['sell', '38388.30', '0.00000000']], 'time': '2021-05-20T03:55:58.438105Z'}
{'type': 'l2update', 'product_id': 'BTC-USD', 'changes': [['sell', '38374.62', '0.00000000']], 'time': '2021-05-20T03:55:58.438105Z'}
{'type': 'l2update', 'product_id': 'BTC-USD', 'changes': [['sell', '38362.65', '0.00000000']], 'time': '2021-05-20T03:55:58.438105Z'}
{'type': 'l2update', 'product_id': 'BTC-USD', 'changes': [['sell', '38352.02', '0.03107481']], 'time': '2021-05-20T03:55:58.438105Z'}
{'type': 'l2update', 'product_id': 'BTC-USD', 'changes': [['sell', '38352.02', '0.00000000']], 'time': '2021-05-20T03:55:58.438105Z'}
{'type': 'l2update', 'product_id': 'BTC-USD', 'changes': [['buy', '38259.37', '0.00000000']], 'time': '2021-05-20T03:55:58.438105Z'}
{'type': 'l2update', 'product_id': 'BTC-USD', 'changes': [['buy', '38246.55', '0.00000000']], 'time': '2021-05-20T03:55:58.439730Z'}
{'type': 'l2update', 'product_id': 'BTC-USD', 'changes': [['sell', '38468.36', '0.00000000']], 'time': '2021-05-20T03:55:58.444875Z'}
{'type': 'l2update', 'product_id': 'BTC-USD', 'changes': [['sell', '38343.07', '0.17427880']], 'time': '2021-05-20T03:55:58.448139Z'}
{'type': 'l2update', 'product_id': 'BTC-USD', 'changes': [['sell', '38309.77', '0.07460000']], 'time': '2021-05-20T03:55:58.448594Z'}
{'type': 'l2update', 'product_id': 'BTC-USD', 'changes': [['buy', '38284.04', '0.02000000']], 'time': '2021-05-20T03:55:58.453342Z'}
{'type': 'l2update', 'product_id': 'BTC-USD', 'changes': [['sell', '38343.28', '0.02000000']], 'time': '2021-05-20T03:55:58.453342Z'}
{'type': 'l2update', 'product_id': 'BTC-USD', 'changes': [['buy', '38296.00', '0.00315085']], 'time': '2021-05-20T03:55:58.453593Z'}
{'type': 'l2update', 'product_id': 'BTC-USD', 'changes': [['sell', '38465.29', '0.00000000']], 'time': '2021-05-20T03:55:58.456997Z'}
{'type': 'l2update', 'product_id': 'BTC-USD', 'changes': [['sell', '38447.50', '0.00000000']], 'time': '2021-05-20T03:55:58.457751Z'}
{'type': 'l2update', 'product_id': 'BTC-USD', 'changes': [['sell', '38421.21', '0.01000000']], 'time': '2021-05-20T03:55:58.458205Z'}
{'type': 'l2update', 'product_id': 'BTC-USD', 'changes': [['buy', '38256.52', '0.10000000']], 'time': '2021-05-20T03:55:58.458625Z'}
{'type': 'l2update', 'product_id': 'BTC-USD', 'changes': [['buy', '38252.44', '0.00000000']], 'time': '2021-05-20T03:55:58.458865Z'}
{'type': 'l2update', 'product_id': 'BTC-USD', 'changes': [['sell', '38430.44', '0.01000000']], 'time': '2021-05-20T03:55:58.458924Z'}
{'type': 'l2update', 'product_id': 'BTC-USD', 'changes': [['sell', '38357.52', '0.00000000']], 'time': '2021-05-20T03:55:58.460766Z'}
{'type': 'l2update', 'product_id': 'BTC-USD', 'changes': [['buy', '38237.64', '0.00000000']], 'time': '2021-05-20T03:55:58.460766Z'}
{'type': 'l2update', 'product_id': 'BTC-USD', 'changes': [['buy', '38283.46', '0.99440510']], 'time': '2021-05-20T03:55:58.463333Z'}
{'type': 'l2update', 'product_id': 'BTC-USD', 'changes': [['sell', '38351.55', '0.09000000']], 'time': '2021-05-20T03:55:58.463938Z'}
{'type': 'l2update', 'product_id': 'BTC-USD', 'changes': [['buy', '38296.00', '0.01492000']], 'time': '2021-05-20T03:55:58.464003Z'}
{'type': 'l2update', 'product_id': 'BTC-USD', 'changes': [['sell', '38484.36', '0.00000000']], 'time': '2021-05-20T03:55:58.465830Z'}
{'type': 'l2update', 'product_id': 'BTC-USD', 'changes': [['buy', '38283.87', '0.02400000']], 'time': '2021-05-20T03:55:58.467239Z'}
{'type': 'l2update', 'product_id': 'BTC-USD', 'changes': [['buy', '38283.07', '0.02400000']], 'time': '2021-05-20T03:55:58.467239Z'}
{'type': 'l2update', 'product_id': 'BTC-USD', 'changes': [['buy', '38282.26', '0.02400000']], 'time': '2021-05-20T03:55:58.467239Z'}
{'type': 'l2update', 'product_id': 'BTC-USD', 'changes': [['sell', '38455.05', '0.01175447']], 'time': '2021-05-20T03:55:58.467812Z'}
{'type': 'l2update', 'product_id': 'BTC-USD', 'changes': [['sell', '38393.24', '0.00000000']], 'time': '2021-05-20T03:55:58.472545Z'}
{'type': 'l2update', 'product_id': 'BTC-USD', 'changes': [['buy', '38232.28', '0.17071148']], 'time': '2021-05-20T03:55:58.472545Z'}
{'type': 'l2update', 'product_id': 'BTC-USD', 'changes': [['sell', '38452.12', '0.01000000']], 'time': '2021-05-20T03:55:58.475840Z'}
{'type': 'l2update', 'product_id': 'BTC-USD', 'changes': [['sell', '38310.06', '0.00000000']], 'time': '2021-05-20T03:55:58.478233Z'}
{'type': 'l2update', 'product_id': 'BTC-USD', 'changes': [['sell', '38460.56', '0.01218739']], 'time': '2021-05-20T03:55:58.482503Z'}
{'type': 'l2update', 'product_id': 'BTC-USD', 'changes': [['buy', '38283.87', '0.00000000']], 'time': '2021-05-20T03:55:58.485601Z'}
{'type': 'l2update', 'product_id': 'BTC-USD', 'changes': [['sell', '38351.55', '0.14000000']], 'time': '2021-05-20T03:55:58.486306Z'}
{'type': 'l2update', 'product_id': 'BTC-USD', 'changes': [['buy', '38295.67', '0.00000000']], 'time': '2021-05-20T03:55:58.486523Z'}
{'type': 'l2update', 'product_id': 'BTC-USD', 'changes': [['sell', '38451.25', '0.00000000']], 'time': '2021-05-20T03:55:58.486584Z'}
{'type': 'l2update', 'product_id': 'BTC-USD', 'changes': [['sell', '38444.21', '0.00000000']], 'time': '2021-05-20T03:55:58.486584Z'}
{'type': 'l2update', 'product_id': 'BTC-USD', 'changes': [['sell', '38435.64', '0.29617052']], 'time': '2021-05-20T03:55:58.486584Z'}
{'type': 'l2update', 'product_id': 'BTC-USD', 'changes': [['sell', '38435.64', '0.00000000']], 'time': '2021-05-20T03:55:58.486584Z'}
{'type': 'l2update', 'product_id': 'BTC-USD', 'changes': [['sell', '38426.89', '0.00000000']], 'time': '2021-05-20T03:55:58.486584Z'}
{'type': 'l2update', 'product_id': 'BTC-USD', 'changes': [['sell', '38424.22', '0.00000000']], 'time': '2021-05-20T03:55:58.486584Z'}
{'type': 'l2update', 'product_id': 'BTC-USD', 'changes': [['buy', '38220.60', '0.00000000']], 'time': '2021-05-20T03:55:58.486584Z'}
{'type': 'l2update', 'product_id': 'BTC-USD', 'changes': [['sell', '38317.59', '0.00000000']], 'time': '2021-05-20T03:55:58.487229Z'}
{'type': 'l2update', 'product_id': 'BTC-USD', 'changes': [['sell', '38430.70', '0.02820786']], 'time': '2021-05-20T03:55:58.487466Z'}
{'type': 'l2update', 'product_id': 'BTC-USD', 'changes': [['sell', '38430.70', '0.00000000']], 'time': '2021-05-20T03:55:58.487466Z'}
{'type': 'l2update', 'product_id': 'BTC-USD', 'changes': [['sell', '38424.23', '0.00000000']], 'time': '2021-05-20T03:55:58.487466Z'}
{'type': 'l2update', 'product_id': 'BTC-USD', 'changes': [['sell', '38417.95', '0.00000000']], 'time': '2021-05-20T03:55:58.487466Z'}
{'type': 'l2update', 'product_id': 'BTC-USD', 'changes': [['sell', '38404.81', '0.00000000']], 'time': '2021-05-20T03:55:58.487466Z'}
{'type': 'l2update', 'product_id': 'BTC-USD', 'changes': [['sell', '38393.22', '0.00000000']], 'time': '2021-05-20T03:55:58.487466Z'}
{'type': 'l2update', 'product_id': 'BTC-USD', 'changes': [['sell', '38378.99', '0.00000000']], 'time': '2021-05-20T03:55:58.487466Z'}
{'type': 'l2update', 'product_id': 'BTC-USD', 'changes': [['buy', '38218.41', '0.00000000']], 'time': '2021-05-20T03:55:58.489345Z'}
{'type': 'l2update', 'product_id': 'BTC-USD', 'changes': [['sell', '38354.83', '0.01000000']], 'time': '2021-05-20T03:55:58.491043Z'}
{'type': 'l2update', 'product_id': 'BTC-USD', 'changes': [['sell', '38348.60', '0.66182513']], 'time': '2021-05-20T03:55:58.501269Z'}
{'type': 'l2update', 'product_id': 'BTC-USD', 'changes': [['sell', '38348.60', '0.29956217']], 'time': '2021-05-20T03:55:58.501269Z'}
{'type': 'l2update', 'product_id': 'BTC-USD', 'changes': [['sell', '38348.60', '0.00000000']], 'time': '2021-05-20T03:55:58.501269Z'}
{'type': 'l2update', 'product_id': 'BTC-USD', 'changes': [['buy', '38226.47', '0.00000000']], 'time': '2021-05-20T03:55:58.501269Z'}
{'type': 'l2update', 'product_id': 'BTC-USD', 'changes': [['buy', '38232.28', '0.00000000']], 'time': '2021-05-20T03:55:58.501269Z'}
{'type': 'l2update', 'product_id': 'BTC-USD', 'changes': [['sell', '38355.37', '0.00000000']], 'time': '2021-05-20T03:55:58.501778Z'}
{'type': 'l2update', 'product_id': 'BTC-USD', 'changes': [['sell', '38334.25', '0.00000000']], 'time': '2021-05-20T03:55:58.509055Z'}
{'type': 'l2update', 'product_id': 'BTC-USD', 'changes': [['sell', '38326.45', '0.11323880']], 'time': '2021-05-20T03:55:58.510029Z'}
{'type': 'l2update', 'product_id': 'BTC-USD', 'changes': [['buy', '38296.23', '0.07460000']], 'time': '2021-05-20T03:55:58.510053Z'}
{'type': 'l2update', 'product_id': 'BTC-USD', 'changes': [['buy', '38195.25', '0.01000000']], 'time': '2021-05-20T03:55:58.510114Z'}
{'type': 'l2update', 'product_id': 'BTC-USD', 'changes': [['buy', '38272.59', '0.06323880']], 'time': '2021-05-20T03:55:58.510233Z'}
{'type': 'l2update', 'product_id': 'BTC-USD', 'changes': [['buy', '38272.58', '0.00000000']], 'time': '2021-05-20T03:55:58.510301Z'}
{'type': 'l2update', 'product_id': 'BTC-USD', 'changes': [['buy', '38214.70', '0.02868087']], 'time': '2021-05-20T03:55:58.513832Z'}
{'type': 'l2update', 'product_id': 'BTC-USD', 'changes': [['sell', '38309.76', '0.50000000']], 'time': '2021-05-20T03:55:58.514544Z'}
{'type': 'l2update', 'product_id': 'BTC-USD', 'changes': [['buy', '38272.45', '0.01000000']], 'time': '2021-05-20T03:55:58.515002Z'}
{'type': 'l2update', 'product_id': 'BTC-USD', 'changes': [['sell', '38309.42', '0.01492000']], 'time': '2021-05-20T03:55:58.515019Z'}
{'type': 'l2update', 'product_id': 'BTC-USD', 'changes': [['buy', '38282.04', '0.00000000']], 'time': '2021-05-20T03:55:58.519197Z'}
{'type': 'l2update', 'product_id': 'BTC-USD', 'changes': [['sell', '38477.51', '0.30086155']], 'time': '2021-05-20T03:55:58.523810Z'}
{'type': 'l2update', 'product_id': 'BTC-USD', 'changes': [['buy', '38280.78', '0.02400000']], 'time': '2021-05-20T03:55:58.523989Z'}
{'type': 'l2update', 'product_id': 'BTC-USD', 'changes': [['buy', '38208.27', '0.10524355']], 'time': '2021-05-20T03:55:58.526728Z'}
{'type': 'l2update', 'product_id': 'BTC-USD', 'changes': [['buy', '38296.00', '0.00315085']], 'time': '2021-05-20T03:55:58.527474Z'}
{'type': 'l2update', 'product_id': 'BTC-USD', 'changes': [['buy', '38296.00', '0.00000000']], 'time': '2021-05-20T03:55:58.527622Z'}
{'type': 'l2update', 'product_id': 'BTC-USD', 'changes': [['sell', '38326.52', '0.06436034']], 'time': '2021-05-20T03:55:58.528730Z'}
{'type': 'l2update', 'product_id': 'BTC-USD', 'changes': [['sell', '38347.53', '0.01000000']], 'time': '2021-05-20T03:55:58.528751Z'}
{'type': 'l2update', 'product_id': 'BTC-USD', 'changes': [['sell', '38309.77', '0.00000000']], 'time': '2021-05-20T03:55:58.529226Z'}
{'type': 'l2update', 'product_id': 'BTC-USD', 'changes': [['sell', '38310.57', '0.00000000']], 'time': '2021-05-20T03:55:58.530635Z'}
{'type': 'l2update', 'product_id': 'BTC-USD', 'changes': [['sell', '38307.84', '0.03000000']], 'time': '2021-05-20T03:55:58.539137Z'}
{'type': 'l2update', 'product_id': 'BTC-USD', 'changes': [['buy', '38283.07', '0.00000000']], 'time': '2021-05-20T03:55:58.539351Z'}
{'type': 'l2update', 'product_id': 'BTC-USD', 'changes': [['buy', '38282.26', '0.00000000']], 'time': '2021-05-20T03:55:58.539351Z'}
{'type': 'l2update', 'product_id': 'BTC-USD', 'changes': [['buy', '38296.23', '0.00000000']], 'time': '2021-05-20T03:55:58.541642Z'}
{'type': 'l2update', 'product_id': 'BTC-USD', 'changes': [['buy', '38165.58', '0.00000000']], 'time': '2021-05-20T03:55:58.542345Z'}
{'type': 'l2update', 'product_id': 'BTC-USD', 'changes': [['buy', '38285.78', '0.52200000']], 'time': '2021-05-20T03:55:58.543576Z'}
{'type': 'l2update', 'product_id': 'BTC-USD', 'changes': [['buy', '37507.14', '0.06741088']], 'time': '2021-05-20T03:55:58.543791Z'}
{'type': 'l2update', 'product_id': 'BTC-USD', 'changes': [['sell', '38477.51', '0.00000000']], 'time': '2021-05-20T03:55:58.547980Z'}
{'type': 'l2update', 'product_id': 'BTC-USD', 'changes': [['sell', '38309.42', '0.00000000']], 'time': '2021-05-20T03:55:58.550190Z'}
{'type': 'l2update', 'product_id': 'BTC-USD', 'changes': [['sell', '38308.87', '0.07460000']], 'time': '2021-05-20T03:55:58.553683Z'}
{'type': 'l2update', 'product_id': 'BTC-USD', 'changes': [['sell', '38309.76', '0.00000000']], 'time': '2021-05-20T03:55:58.557600Z'}
{'type': 'l2update', 'product_id': 'BTC-USD', 'changes': [['buy', '38285.78', '0.00000000']], 'time': '2021-05-20T03:55:58.557767Z'}
{'type': 'l2update', 'product_id': 'BTC-USD', 'changes': [['sell', '38308.87', '0.00000000']], 'time': '2021-05-20T03:55:58.559161Z'}
{'type': 'l2update', 'product_id': 'BTC-USD', 'changes': [['buy', '38295.41', '0.26100000']], 'time': '2021-05-20T03:55:58.560255Z'}
{'type': 'l2update', 'product_id': 'BTC-USD', 'changes': [['buy', '38295.21', '0.07152856']], 'time': '2021-05-20T03:55:58.560451Z'}
{'type': 'l2update', 'product_id': 'BTC-USD', 'changes': [['buy', '38267.28', '0.09962976']], 'time': '2021-05-20T03:55:58.560537Z'}
{'type': 'l2update', 'product_id': 'BTC-USD', 'changes': [['buy', '38296.58', '0.00315085']], 'time': '2021-05-20T03:55:58.560554Z'}
{'type': 'l2update', 'product_id': 'BTC-USD', 'changes': [['sell', '38326.45', '0.05000000']], 'time': '2021-05-20T03:55:58.560881Z'}
{'type': 'l2update', 'product_id': 'BTC-USD', 'changes': [['buy', '38272.59', '0.00000000']], 'time': '2021-05-20T03:55:58.562983Z'}
{'type': 'l2update', 'product_id': 'BTC-USD', 'changes': [['buy', '38295.83', '0.00315085']], 'time': '2021-05-20T03:55:58.565180Z'}
{'type': 'l2update', 'product_id': 'BTC-USD', 'changes': [['buy', '38268.84', '0.03908650']], 'time': '2021-05-20T03:55:58.565770Z'}
{'type': 'l2update', 'product_id': 'BTC-USD', 'changes': [['buy', '37507.14', '0.00000000']], 'time': '2021-05-20T03:55:58.568488Z'}
{'type': 'l2update', 'product_id': 'BTC-USD', 'changes': [['buy', '38279.39', '0.02400000']], 'time': '2021-05-20T03:55:58.569313Z'}
{'type': 'l2update', 'product_id': 'BTC-USD', 'changes': [['buy', '38278.58', '0.02400000']], 'time': '2021-05-20T03:55:58.569313Z'}
{'type': 'l2update', 'product_id': 'BTC-USD', 'changes': [['buy', '38219.52', '0.02400000']], 'time': '2021-05-20T03:55:58.569810Z'}
{'type': 'l2update', 'product_id': 'BTC-USD', 'changes': [['buy', '38296.58', '0.00000000']], 'time': '2021-05-20T03:55:58.570089Z'}
{'type': 'l2update', 'product_id': 'BTC-USD', 'changes': [['sell', '38334.27', '0.00000000']], 'time': '2021-05-20T03:55:58.570748Z'}
{'type': 'l2update', 'product_id': 'BTC-USD', 'changes': [['sell', '38351.55', '0.12000000']], 'time': '2021-05-20T03:55:58.571986Z'}
{'type': 'l2update', 'product_id': 'BTC-USD', 'changes': [['sell', '38307.37', '0.07460000']], 'time': '2021-05-20T03:55:58.573734Z'}
{'type': 'l2update', 'product_id': 'BTC-USD', 'changes': [['sell', '38315.22', '0.50000000']], 'time': '2021-05-20T03:55:58.573807Z'}
{'type': 'l2update', 'product_id': 'BTC-USD', 'changes': [['sell', '38307.50', '0.01492000']], 'time': '2021-05-20T03:55:58.574252Z'}
{'type': 'l2update', 'product_id': 'BTC-USD', 'changes': [['buy', '38295.98', '0.00547240']], 'time': '2021-05-20T03:55:58.578445Z'}
{'type': 'l2update', 'product_id': 'BTC-USD', 'changes': [['buy', '38292.51', '0.03297586']], 'time': '2021-05-20T03:55:58.581564Z'}
{'type': 'l2update', 'product_id': 'BTC-USD', 'changes': [['buy', '38214.42', '0.00000000']], 'time': '2021-05-20T03:55:58.581802Z'}
{'type': 'l2update', 'product_id': 'BTC-USD', 'changes': [['buy', '38133.06', '0.00000000']], 'time': '2021-05-20T03:55:58.582457Z'}
{'type': 'l2update', 'product_id': 'BTC-USD', 'changes': [['sell', '38351.55', '0.09000000']], 'time': '2021-05-20T03:55:58.582720Z'}
{'type': 'l2update', 'product_id': 'BTC-USD', 'changes': [['buy', '38285.73', '0.00000000']], 'time': '2021-05-20T03:55:58.586877Z'}
{'type': 'l2update', 'product_id': 'BTC-USD', 'changes': [['sell', '38327.93', '0.00000000']], 'time': '2021-05-20T03:55:58.586877Z'}
{'type': 'l2update', 'product_id': 'BTC-USD', 'changes': [['sell', '38307.50', '0.00000000']], 'time': '2021-05-20T03:55:58.588455Z'}
{'type': 'l2update', 'product_id': 'BTC-USD', 'changes': [['sell', '38354.46', '2.16932808']], 'time': '2021-05-20T03:55:58.591250Z'}
{'type': 'l2update', 'product_id': 'BTC-USD', 'changes': [['sell', '38351.55', '0.05000000']], 'time': '2021-05-20T03:55:58.593566Z'}
{'type': 'l2update', 'product_id': 'BTC-USD', 'changes': [['buy', '38295.98', '0.07460000']], 'time': '2021-05-20T03:55:58.595801Z'}
{'type': 'l2update', 'product_id': 'BTC-USD', 'changes': [['buy', '38093.41', '0.00000000']], 'time': '2021-05-20T03:55:58.600179Z'}
{'type': 'l2update', 'product_id': 'BTC-USD', 'changes': [['sell', '38469.79', '0.00000000']], 'time': '2021-05-20T03:55:58.600457Z'}
{'type': 'l2update', 'product_id': 'BTC-USD', 'changes': [['buy', '37505.64', '0.06484641']], 'time': '2021-05-20T03:55:58.601498Z'}
{'type': 'l2update', 'product_id': 'BTC-USD', 'changes': [['buy', '35580.00', '0.08500000']], 'time': '2021-05-20T03:55:58.601657Z'}
{'type': 'l2update', 'product_id': 'BTC-USD', 'changes': [['buy', '38198.22', '0.01000000']], 'time': '2021-05-20T03:55:58.602324Z'}
{'type': 'l2update', 'product_id': 'BTC-USD', 'changes': [['buy', '38295.21', '0.00000000']], 'time': '2021-05-20T03:55:58.604343Z'}
{'type': 'l2update', 'product_id': 'BTC-USD', 'changes': [['sell', '38344.03', '0.02000000']], 'time': '2021-05-20T03:55:58.609273Z'}
{'type': 'l2update', 'product_id': 'BTC-USD', 'changes': [['sell', '38306.87', '0.01492000']], 'time': '2021-05-20T03:55:58.609969Z'}
{'type': 'l2update', 'product_id': 'BTC-USD', 'changes': [['sell', '38354.83', '0.00000000']], 'time': '2021-05-20T03:55:58.610881Z'}
{'type': 'l2update', 'product_id': 'BTC-USD', 'changes': [['buy', '38268.84', '0.00000000']], 'time': '2021-05-20T03:55:58.614501Z'}
{'type': 'l2update', 'product_id': 'BTC-USD', 'changes': [['buy', '38265.94', '0.03908650']], 'time': '2021-05-20T03:55:58.616082Z'}
{'type': 'l2update', 'product_id': 'BTC-USD', 'changes': [['sell', '38633.58', '0.00000000']], 'time': '2021-05-20T03:55:58.617270Z'}
{'type': 'l2update', 'product_id': 'BTC-USD', 'changes': [['sell', '38563.59', '0.00000000']], 'time': '2021-05-20T03:55:58.618251Z'}
{'type': 'l2update', 'product_id': 'BTC-USD', 'changes': [['sell', '38307.37', '0.00000000']], 'time': '2021-05-20T03:55:58.618806Z'}
{'type': 'l2update', 'product_id': 'BTC-USD', 'changes': [['buy', '38272.45', '0.00000000']], 'time': '2021-05-20T03:55:58.619854Z'}
{'type': 'l2update', 'product_id': 'BTC-USD', 'changes': [['buy', '38295.83', '0.00000000']], 'time': '2021-05-20T03:55:58.620360Z'}
{'type': 'l2update', 'product_id': 'BTC-USD', 'changes': [['sell', '38344.03', '0.05000000']], 'time': '2021-05-20T03:55:58.621048Z'}
{'type': 'l2update', 'product_id': 'BTC-USD', 'changes': [['buy', '38106.80', '0.01000000']], 'time': '2021-05-20T03:55:58.621905Z'}
{'type': 'l2update', 'product_id': 'BTC-USD', 'changes': [['sell', '38446.65', '0.01000000']], 'time': '2021-05-20T03:55:58.622055Z'}
{'type': 'l2update', 'product_id': 'BTC-USD', 'changes': [['buy', '38278.73', '0.00000000']], 'time': '2021-05-20T03:55:58.628296Z'}
{'type': 'l2update', 'product_id': 'BTC-USD', 'changes': [['buy', '37505.64', '0.00000000']], 'time': '2021-05-20T03:55:58.631511Z'}
{'type': 'l2update', 'product_id': 'BTC-USD', 'changes': [['buy', '38265.94', '0.00000000']], 'time': '2021-05-20T03:55:58.632087Z'}
{'type': 'l2update', 'product_id': 'BTC-USD', 'changes': [['buy', '38263.28', '0.03908650']], 'time': '2021-05-20T03:55:58.633713Z'}
{'type': 'l2update', 'product_id': 'BTC-USD', 'changes': [['sell', '38349.76', '0.17800000']], 'time': '2021-05-20T03:55:58.633951Z'}
{'type': 'l2update', 'product_id': 'BTC-USD', 'changes': [['buy', '38296.24', '0.07152856']], 'time': '2021-05-20T03:55:58.634150Z'}
{'type': 'l2update', 'product_id': 'BTC-USD', 'changes': [['buy', '38296.32', '0.00315085']], 'time': '2021-05-20T03:55:58.634191Z'}
{'type': 'l2update', 'product_id': 'BTC-USD', 'changes': [['sell', '38539.88', '0.01000000']], 'time': '2021-05-20T03:55:58.638504Z'}
{'type': 'l2update', 'product_id': 'BTC-USD', 'changes': [['sell', '38306.27', '0.07460000']], 'time': '2021-05-20T03:55:58.638612Z'}
{'type': 'l2update', 'product_id': 'BTC-USD', 'changes': [['buy', '38280.78', '0.00000000']], 'time': '2021-05-20T03:55:58.640423Z'}
{'type': 'l2update', 'product_id': 'BTC-USD', 'changes': [['buy', '38295.98', '0.00547240']], 'time': '2021-05-20T03:55:58.644117Z'}
{'type': 'l2update', 'product_id': 'BTC-USD', 'changes': [['buy', '38276.04', '0.04188310']], 'time': '2021-05-20T03:55:58.647046Z'}
{'type': 'l2update', 'product_id': 'BTC-USD', 'changes': [['sell', '38317.31', '0.06265243']], 'time': '2021-05-20T03:55:58.647046Z'}
{'type': 'l2update', 'product_id': 'BTC-USD', 'changes': [['buy', '38295.98', '0.00000000']], 'time': '2021-05-20T03:55:58.649099Z'}
{'type': 'l2update', 'product_id': 'BTC-USD', 'changes': [['buy', '38265.44', '0.00000000']], 'time': '2021-05-20T03:55:58.651157Z'}
{'type': 'l2update', 'product_id': 'BTC-USD', 'changes': [['sell', '38306.87', '0.00000000']], 'time': '2021-05-20T03:55:58.651262Z'}
{'type': 'l2update', 'product_id': 'BTC-USD', 'changes': [['sell', '38430.44', '0.00000000']], 'time': '2021-05-20T03:55:58.652516Z'}
{'type': 'l2update', 'product_id': 'BTC-USD', 'changes': [['buy', '38263.28', '0.00000000']], 'time': '2021-05-20T03:55:58.653757Z'}
{'type': 'l2update', 'product_id': 'BTC-USD', 'changes': [['buy', '38194.84', '0.00000000']], 'time': '2021-05-20T03:55:58.655894Z'}
{'type': 'l2update', 'product_id': 'BTC-USD', 'changes': [['buy', '38198.22', '0.00000000']], 'time': '2021-05-20T03:55:58.659457Z'}
{'type': 'l2update', 'product_id': 'BTC-USD', 'changes': [['buy', '38278.15', '0.02400000']], 'time': '2021-05-20T03:55:58.661963Z'}
{'type': 'l2update', 'product_id': 'BTC-USD', 'changes': [['buy', '38225.73', '2.50560000']], 'time': '2021-05-20T03:55:58.662591Z'}
{'type': 'l2update', 'product_id': 'BTC-USD', 'changes': [['buy', '37505.64', '0.06537796']], 'time': '2021-05-20T03:55:58.662614Z'}
{'type': 'l2update', 'product_id': 'BTC-USD', 'changes': [['sell', '38620.55', '0.01000000']], 'time': '2021-05-20T03:55:58.662963Z'}
{'type': 'l2update', 'product_id': 'BTC-USD', 'changes': [['sell', '38306.27', '0.00000000']], 'time': '2021-05-20T03:55:58.664849Z'}
{'type': 'l2update', 'product_id': 'BTC-USD', 'changes': [['buy', '38260.84', '0.03908650']], 'time': '2021-05-20T03:55:58.675322Z'}
{'type': 'l2update', 'product_id': 'BTC-USD', 'changes': [['sell', '38306.04', '0.01492000']], 'time': '2021-05-20T03:55:58.675616Z'}
{'type': 'l2update', 'product_id': 'BTC-USD', 'changes': [['buy', '38284.09', '0.52100000']], 'time': '2021-05-20T03:55:58.675718Z'}
{'type': 'l2update', 'product_id': 'BTC-USD', 'changes': [['buy', '38214.42', '0.01000000']], 'time': '2021-05-20T03:55:58.676053Z'}
{'type': 'l2update', 'product_id': 'BTC-USD', 'changes': [['buy', '38256.17', '0.02613957']], 'time': '2021-05-20T03:55:58.680573Z'}
{'type': 'l2update', 'product_id': 'BTC-USD', 'changes': [['sell', '38306.04', '0.00000000']], 'time': '2021-05-20T03:55:58.683417Z'}
{'type': 'l2update', 'product_id': 'BTC-USD', 'changes': [['buy', '37505.64', '0.00000000']], 'time': '2021-05-20T03:55:58.683962Z'}
{'type': 'l2update', 'product_id': 'BTC-USD', 'changes': [['buy', '38296.63', '0.07460000']], 'time': '2021-05-20T03:55:58.685280Z'}
{'type': 'l2update', 'product_id': 'BTC-USD', 'changes': [['sell', '38307.33', '0.07460000']], 'time': '2021-05-20T03:55:58.689314Z'}
{'type': 'l2update', 'product_id': 'BTC-USD', 'changes': [['sell', '38412.94', '0.01000000']], 'time': '2021-05-20T03:55:58.689743Z'}
{'type': 'l2update', 'product_id': 'BTC-USD', 'changes': [['sell', '38539.88', '0.00000000']], 'time': '2021-05-20T03:55:58.693154Z'}
{'type': 'l2update', 'product_id': 'BTC-USD', 'changes': [['buy', '38296.32', '0.01492000']], 'time': '2021-05-20T03:55:58.697320Z'}
{'type': 'l2update', 'product_id': 'BTC-USD', 'changes': [['sell', '38307.33', '0.00000000']], 'time': '2021-05-20T03:55:58.697973Z'}
{'type': 'l2update', 'product_id': 'BTC-USD', 'changes': [['buy', '38296.32', '0.00315085']], 'time': '2021-05-20T03:55:58.703651Z'}
{'type': 'l2update', 'product_id': 'BTC-USD', 'changes': [['sell', '38328.95', '0.05000000']], 'time': '2021-05-20T03:55:58.707421Z'}
{'type': 'l2update', 'product_id': 'BTC-USD', 'changes': [['sell', '38307.20', '0.01492000']], 'time': '2021-05-20T03:55:58.707565Z'}
{'type': 'l2update', 'product_id': 'BTC-USD', 'changes': [['sell', '38307.36', '0.07460000']], 'time': '2021-05-20T03:55:58.713372Z'}
{'type': 'l2update', 'product_id': 'BTC-USD', 'changes': [['buy', '37505.64', '0.06934691']], 'time': '2021-05-20T03:55:58.713409Z'}
{'type': 'l2update', 'product_id': 'BTC-USD', 'changes': [['sell', '38336.72', '0.10000000']], 'time': '2021-05-20T03:55:58.713929Z'}
{'type': 'l2update', 'product_id': 'BTC-USD', 'changes': [['buy', '38296.32', '0.00000000']], 'time': '2021-05-20T03:55:58.714171Z'}
{'type': 'l2update', 'product_id': 'BTC-USD', 'changes': [['sell', '38307.36', '0.00000000']], 'time': '2021-05-20T03:55:58.718731Z'}
{'type': 'l2update', 'product_id': 'BTC-USD', 'changes': [['buy', '38297.18', '0.00315085']], 'time': '2021-05-20T03:55:58.724280Z'}
{'type': 'l2update', 'product_id': 'BTC-USD', 'changes': [['buy', '37505.64', '0.00000000']], 'time': '2021-05-20T03:55:58.724563Z'}
{'type': 'l2update', 'product_id': 'BTC-USD', 'changes': [['sell', '38474.79', '0.00000000']], 'time': '2021-05-20T03:55:58.732806Z'}
{'type': 'l2update', 'product_id': 'BTC-USD', 'changes': [['sell', '38339.40', '0.00000000']], 'time': '2021-05-20T03:55:58.733438Z'}
{'type': 'l2update', 'product_id': 'BTC-USD', 'changes': [['sell', '38521.00', '0.01000000']], 'time': '2021-05-20T03:55:58.736151Z'}
{'type': 'l2update', 'product_id': 'BTC-USD', 'changes': [['sell', '38306.73', '0.07460000']], 'time': '2021-05-20T03:55:58.738116Z'}
{'type': 'l2update', 'product_id': 'BTC-USD', 'changes': [['buy', '38268.83', '0.00000000']], 'time': '2021-05-20T03:55:58.745785Z'}
{'type': 'l2update', 'product_id': 'BTC-USD', 'changes': [['sell', '38455.51', '0.01000000']], 'time': '2021-05-20T03:55:58.745842Z'}
{'type': 'l2update', 'product_id': 'BTC-USD', 'changes': [['buy', '38271.05', '0.00000000']], 'time': '2021-05-20T03:55:58.746532Z'}
{'type': 'l2update', 'product_id': 'BTC-USD', 'changes': [['sell', '38307.20', '0.00000000']], 'time': '2021-05-20T03:55:58.746989Z'}
{'type': 'l2update', 'product_id': 'BTC-USD', 'changes': [['sell', '38452.12', '0.00000000']], 'time': '2021-05-20T03:55:58.750862Z'}
{'type': 'l2update', 'product_id': 'BTC-USD', 'changes': [['buy', '38296.24', '0.00000000']], 'time': '2021-05-20T03:55:58.758283Z'}
{'type': 'l2update', 'product_id': 'BTC-USD', 'changes': [['buy', '37505.64', '0.06730876']], 'time': '2021-05-20T03:55:58.761489Z'}
{'type': 'l2update', 'product_id': 'BTC-USD', 'changes': [['sell', '38346.00', '0.01000000']], 'time': '2021-05-20T03:55:58.761808Z'}
{'type': 'l2update', 'product_id': 'BTC-USD', 'changes': [['sell', '38474.69', '0.01000000']], 'time': '2021-05-20T03:55:58.767002Z'}
{'type': 'l2update', 'product_id': 'BTC-USD', 'changes': [['sell', '38401.19', '0.00000000']], 'time': '2021-05-20T03:55:58.767236Z'}
{'type': 'l2update', 'product_id': 'BTC-USD', 'changes': [['buy', '38296.63', '0.00000000']], 'time': '2021-05-20T03:55:58.769882Z'}
{'type': 'l2update', 'product_id': 'BTC-USD', 'changes': [['sell', '38326.46', '0.00000000']], 'time': '2021-05-20T03:55:58.771664Z'}
{'type': 'l2update', 'product_id': 'BTC-USD', 'changes': [['buy', '38263.65', '0.01000000']], 'time': '2021-05-20T03:55:58.774465Z'}
{'type': 'l2update', 'product_id': 'BTC-USD', 'changes': [['sell', '38333.60', '0.00000000']], 'time': '2021-05-20T03:55:58.775921Z'}
{'type': 'l2update', 'product_id': 'BTC-USD', 'changes': [['buy', '38297.18', '0.00000000']], 'time': '2021-05-20T03:55:58.778050Z'}
{'type': 'l2update', 'product_id': 'BTC-USD', 'changes': [['sell', '38336.98', '0.00000000']], 'time': '2021-05-20T03:55:58.780071Z'}
{'type': 'l2update', 'product_id': 'BTC-USD', 'changes': [['sell', '38326.45', '0.00000000']], 'time': '2021-05-20T03:55:58.780679Z'}
{'type': 'l2update', 'product_id': 'BTC-USD', 'changes': [['sell', '38306.43', '0.01492000']], 'time': '2021-05-20T03:55:58.780762Z'}
{'type': 'l2update', 'product_id': 'BTC-USD', 'changes': [['buy', '38296.33', '0.07152856']], 'time': '2021-05-20T03:55:58.786040Z'}
{'type': 'l2update', 'product_id': 'BTC-USD', 'changes': [['buy', '38295.96', '0.01176915']], 'time': '2021-05-20T03:55:58.786182Z'}
{'type': 'l2update', 'product_id': 'BTC-USD', 'changes': [['buy', '38295.64', '0.07460000']], 'time': '2021-05-20T03:55:58.790478Z'}
{'type': 'l2update', 'product_id': 'BTC-USD', 'changes': [['buy', '38296.00', '0.00176483']], 'time': '2021-05-20T03:55:58.791068Z'}
{'type': 'l2update', 'product_id': 'BTC-USD', 'changes': [['buy', '38295.96', '0.00000000']], 'time': '2021-05-20T03:55:58.793625Z'}
{'type': 'l2update', 'product_id': 'BTC-USD', 'changes': [['buy', '38295.96', '0.00315085']], 'time': '2021-05-20T03:55:58.796941Z'}
{'type': 'l2update', 'product_id': 'BTC-USD', 'changes': [['sell', '38326.47', '0.05000000']], 'time': '2021-05-20T03:55:58.797037Z'}
{'type': 'l2update', 'product_id': 'BTC-USD', 'changes': [['buy', '38295.64', '0.00000000']], 'time': '2021-05-20T03:55:58.797890Z'}
{'type': 'l2update', 'product_id': 'BTC-USD', 'changes': [['sell', '38306.73', '0.00000000']], 'time': '2021-05-20T03:55:58.798111Z'}
{'type': 'l2update', 'product_id': 'BTC-USD', 'changes': [['sell', '38437.18', '0.00000000']], 'time': '2021-05-20T03:55:58.800440Z'}
{'type': 'l2update', 'product_id': 'BTC-USD', 'changes': [['sell', '38307.79', '0.55400000']], 'time': '2021-05-20T03:55:58.802924Z'}
{'type': 'l2update', 'product_id': 'BTC-USD', 'changes': [['buy', '38295.96', '0.00000000']], 'time': '2021-05-20T03:55:58.804346Z'}
{'type': 'l2update', 'product_id': 'BTC-USD', 'changes': [['sell', '38343.50', '0.43406072']], 'time': '2021-05-20T03:55:58.807617Z'}
{'type': 'l2update', 'product_id': 'BTC-USD', 'changes': [['buy', '38223.99', '0.17362429']], 'time': '2021-05-20T03:55:58.807617Z'}
{'type': 'l2update', 'product_id': 'BTC-USD', 'changes': [['sell', '38317.58', '0.00000000']], 'time': '2021-05-20T03:55:58.808512Z'}
{'type': 'l2update', 'product_id': 'BTC-USD', 'changes': [['buy', '38284.09', '0.00000000']], 'time': '2021-05-20T03:55:58.809620Z'}
{'type': 'l2update', 'product_id': 'BTC-USD', 'changes': [['sell', '38474.69', '0.00000000']], 'time': '2021-05-20T03:55:58.809853Z'}
{'type': 'l2update', 'product_id': 'BTC-USD', 'changes': [['sell', '38521.00', '0.00000000']], 'time': '2021-05-20T03:55:58.811334Z'}
{'type': 'l2update', 'product_id': 'BTC-USD', 'changes': [['buy', '38296.88', '0.01176915']], 'time': '2021-05-20T03:55:58.811350Z'}
{'type': 'l2update', 'product_id': 'BTC-USD', 'changes': [['sell', '38341.87', '0.00000000']], 'time': '2021-05-20T03:55:58.811981Z'}
{'type': 'l2update', 'product_id': 'BTC-USD', 'changes': [['buy', '37505.64', '0.00000000']], 'time': '2021-05-20T03:55:58.813570Z'}
{'type': 'l2update', 'product_id': 'BTC-USD', 'changes': [['buy', '38296.33', '0.00000000']], 'time': '2021-05-20T03:55:58.815919Z'}
{'type': 'l2update', 'product_id': 'BTC-USD', 'changes': [['sell', '38450.50', '0.00000000']], 'time': '2021-05-20T03:55:58.817662Z'}
{'type': 'l2update', 'product_id': 'BTC-USD', 'changes': [['buy', '38185.63', '0.00000000']], 'time': '2021-05-20T03:55:58.818175Z'}
{'type': 'l2update', 'product_id': 'BTC-USD', 'changes': [['sell', '38306.43', '0.00000000']], 'time': '2021-05-20T03:55:58.819250Z'}
{'type': 'l2update', 'product_id': 'BTC-USD', 'changes': [['sell', '38419.34', '0.01000000']], 'time': '2021-05-20T03:55:58.819339Z'}
{'type': 'l2update', 'product_id': 'BTC-USD', 'changes': [['sell', '38473.53', '0.30087173']], 'time': '2021-05-20T03:55:58.820125Z'}
{'type': 'l2update', 'product_id': 'BTC-USD', 'changes': [['buy', '38219.52', '0.00000000']], 'time': '2021-05-20T03:55:58.822101Z'}
{'type': 'l2update', 'product_id': 'BTC-USD', 'changes': [['buy', '38297.20', '0.07460000']], 'time': '2021-05-20T03:55:58.824198Z'}
{'type': 'l2update', 'product_id': 'BTC-USD', 'changes': [['sell', '38500.11', '0.01000000']], 'time': '2021-05-20T03:55:58.824389Z'}
{'type': 'l2update', 'product_id': 'BTC-USD', 'changes': [['buy', '38130.15', '0.04882890']], 'time': '2021-05-20T03:55:58.824468Z'}
{'type': 'l2update', 'product_id': 'BTC-USD', 'changes': [['sell', '38461.52', '0.01000000']], 'time': '2021-05-20T03:55:58.824587Z'}
{'type': 'l2update', 'product_id': 'BTC-USD', 'changes': [['buy', '38296.88', '0.00000000']], 'time': '2021-05-20T03:55:58.828222Z'}
{'type': 'l2update', 'product_id': 'BTC-USD', 'changes': [['sell', '38354.46', '0.00000000']], 'time': '2021-05-20T03:55:58.828675Z'}
{'type': 'l2update', 'product_id': 'BTC-USD', 'changes': [['sell', '38306.00', '0.00972202']], 'time': '2021-05-20T03:55:58.830985Z'}
{'type': 'l2update', 'product_id': 'BTC-USD', 'changes': [['sell', '38315.21', '2.48969908']], 'time': '2021-05-20T03:55:58.831497Z'}
{'type': 'l2update', 'product_id': 'BTC-USD', 'changes': [['buy', '38242.24', '0.00000000']], 'time': '2021-05-20T03:55:58.834655Z'}
{'type': 'l2update', 'product_id': 'BTC-USD', 'changes': [['buy', '38294.30', '0.05074248']], 'time': '2021-05-20T03:55:58.834841Z'}
{'type': 'l2update', 'product_id': 'BTC-USD', 'changes': [['sell', '38429.02', '0.01166988']], 'time': '2021-05-20T03:55:58.835211Z'}
{'type': 'l2update', 'product_id': 'BTC-USD', 'changes': [['sell', '38308.27', '0.04880575']], 'time': '2021-05-20T03:55:58.835329Z'}
{'type': 'l2update', 'product_id': 'BTC-USD', 'changes': [['buy', '38295.70', '0.00315085']], 'time': '2021-05-20T03:55:58.835490Z'}
{'type': 'l2update', 'product_id': 'BTC-USD', 'changes': [['buy', '38297.20', '0.00000000']], 'time': '2021-05-20T03:55:58.836662Z'}
{'type': 'l2update', 'product_id': 'BTC-USD', 'changes': [['sell', '38306.00', '0.00000000']], 'time': '2021-05-20T03:55:58.836726Z'}
{'type': 'l2update', 'product_id': 'BTC-USD', 'changes': [['sell', '38306.00', '0.05798529']], 'time': '2021-05-20T03:55:58.838777Z'}
{'type': 'l2update', 'product_id': 'BTC-USD', 'changes': [['sell', '38328.11', '0.04886552']], 'time': '2021-05-20T03:55:58.838981Z'}
{'type': 'l2update', 'product_id': 'BTC-USD', 'changes': [['buy', '38297.55', '0.01176915']], 'time': '2021-05-20T03:55:58.841113Z'}
{'type': 'l2update', 'product_id': 'BTC-USD', 'changes': [['buy', '38297.19', '0.07148434']], 'time': '2021-05-20T03:55:58.841260Z'}
{'type': 'l2update', 'product_id': 'BTC-USD', 'changes': [['buy', '38295.70', '0.00000000']], 'time': '2021-05-20T03:55:58.843010Z'}
{'type': 'l2update', 'product_id': 'BTC-USD', 'changes': [['sell', '38344.97', '0.38587636']], 'time': '2021-05-20T03:55:58.843106Z'}
{'type': 'l2update', 'product_id': 'BTC-USD', 'changes': [['buy', '38223.99', '0.55950065']], 'time': '2021-05-20T03:55:58.843106Z'}
{'type': 'l2update', 'product_id': 'BTC-USD', 'changes': [['buy', '38269.38', '0.04976740']], 'time': '2021-05-20T03:55:58.843150Z'}
{'type': 'l2update', 'product_id': 'BTC-USD', 'changes': [['sell', '38306.00', '0.00000000']], 'time': '2021-05-20T03:55:58.844888Z'}
{'type': 'l2update', 'product_id': 'BTC-USD', 'changes': [['sell', '38473.53', '0.00000000']], 'time': '2021-05-20T03:55:58.846539Z'}
{'type': 'l2update', 'product_id': 'BTC-USD', 'changes': [['sell', '38337.00', '0.00000000']], 'time': '2021-05-20T03:55:58.846592Z'}
{'type': 'l2update', 'product_id': 'BTC-USD', 'changes': [['sell', '38461.52', '0.00000000']], 'time': '2021-05-20T03:55:58.847164Z'}
{'type': 'l2update', 'product_id': 'BTC-USD', 'changes': [['sell', '38307.17', '0.01492000']], 'time': '2021-05-20T03:55:58.849358Z'}
{'type': 'l2update', 'product_id': 'BTC-USD', 'changes': [['sell', '38348.79', '0.03439766']], 'time': '2021-05-20T03:55:58.849564Z'}
{'type': 'l2update', 'product_id': 'BTC-USD', 'changes': [['buy', '38193.72', '0.03439766']], 'time': '2021-05-20T03:55:58.849564Z'}
{'type': 'l2update', 'product_id': 'BTC-USD', 'changes': [['sell', '38307.40', '0.00689269']], 'time': '2021-05-20T03:55:58.849681Z'}
{'type': 'l2update', 'product_id': 'BTC-USD', 'changes': [['buy', '38260.84', '0.00000000']], 'time': '2021-05-20T03:55:58.850177Z'}
{'type': 'l2update', 'product_id': 'BTC-USD', 'changes': [['sell', '38326.48', '0.00000000']], 'time': '2021-05-20T03:55:58.850666Z'}
{'type': 'l2update', 'product_id': 'BTC-USD', 'changes': [['buy', '38267.00', '0.01000000']], 'time': '2021-05-20T03:55:58.853647Z'}
{'type': 'l2update', 'product_id': 'BTC-USD', 'changes': [['buy', '38297.55', '0.00000000']], 'time': '2021-05-20T03:55:58.855459Z'}
{'type': 'l2update', 'product_id': 'BTC-USD', 'changes': [['sell', '38351.55', '0.00000000']], 'time': '2021-05-20T03:55:58.856823Z'}
{'type': 'l2update', 'product_id': 'BTC-USD', 'changes': [['sell', '38307.40', '0.01661471']], 'time': '2021-05-20T03:55:58.857906Z'}
{'type': 'l2update', 'product_id': 'BTC-USD', 'changes': [['sell', '38474.69', '0.01000000']], 'time': '2021-05-20T03:55:58.858165Z'}
{'type': 'l2update', 'product_id': 'BTC-USD', 'changes': [['buy', '38297.76', '0.00315085']], 'time': '2021-05-20T03:55:58.858237Z'}
{'type': 'l2update', 'product_id': 'BTC-USD', 'changes': [['sell', '38307.79', '0.00000000']], 'time': '2021-05-20T03:55:58.858727Z'}
{'type': 'l2update', 'product_id': 'BTC-USD', 'changes': [['buy', '38282.03', '0.00000000']], 'time': '2021-05-20T03:55:58.860572Z'}
{'type': 'l2update', 'product_id': 'BTC-USD', 'changes': [['sell', '38307.17', '0.00000000']], 'time': '2021-05-20T03:55:58.861303Z'}
{'type': 'l2update', 'product_id': 'BTC-USD', 'changes': [['sell', '38326.47', '0.00000000']], 'time': '2021-05-20T03:55:58.862291Z'}
{'type': 'l2update', 'product_id': 'BTC-USD', 'changes': [['sell', '38307.40', '0.00689269']], 'time': '2021-05-20T03:55:58.862330Z'}
{'type': 'l2update', 'product_id': 'BTC-USD', 'changes': [['buy', '38296.04', '0.05024694']], 'time': '2021-05-20T03:55:58.862445Z'}
{'type': 'l2update', 'product_id': 'BTC-USD', 'changes': [['sell', '38307.40', '0.06487798']], 'time': '2021-05-20T03:55:58.862797Z'}
{'type': 'l2update', 'product_id': 'BTC-USD', 'changes': [['sell', '38405.84', '0.00000000']], 'time': '2021-05-20T03:55:58.863225Z'}
{'type': 'l2update', 'product_id': 'BTC-USD', 'changes': [['sell', '38347.53', '0.00000000']], 'time': '2021-05-20T03:55:58.864501Z'}
{'type': 'l2update', 'product_id': 'BTC-USD', 'changes': [['sell', '38307.40', '0.05798529']], 'time': '2021-05-20T03:55:58.865609Z'}
{'type': 'l2update', 'product_id': 'BTC-USD', 'changes': [['sell', '38307.40', '0.00000000']], 'time': '2021-05-20T03:55:58.867816Z'}
{'type': 'l2update', 'product_id': 'BTC-USD', 'changes': [['buy', '38257.66', '0.03908650']], 'time': '2021-05-20T03:55:58.872865Z'}
{'type': 'l2update', 'product_id': 'BTC-USD', 'changes': [['sell', '38354.22', '0.02686816']], 'time': '2021-05-20T03:55:58.873267Z'}
{'type': 'l2update', 'product_id': 'BTC-USD', 'changes': [['buy', '38186.68', '0.04587116']], 'time': '2021-05-20T03:55:58.873267Z'}
{'type': 'l2update', 'product_id': 'BTC-USD', 'changes': [['buy', '38297.76', '0.01492000']], 'time': '2021-05-20T03:55:58.877163Z'}
{'type': 'l2update', 'product_id': 'BTC-USD', 'changes': [['sell', '38307.33', '0.00972202']], 'time': '2021-05-20T03:55:58.877347Z'}
{'type': 'l2update', 'product_id': 'BTC-USD', 'changes': [['sell', '38350.01', '0.36648521']], 'time': '2021-05-20T03:55:58.877372Z'}
{'type': 'l2update', 'product_id': 'BTC-USD', 'changes': [['buy', '38213.80', '0.36648521']], 'time': '2021-05-20T03:55:58.877372Z'}
{'type': 'l2update', 'product_id': 'BTC-USD', 'changes': [['buy', '38282.43', '0.43990000']], 'time': '2021-05-20T03:55:58.877551Z'}
{'type': 'l2update', 'product_id': 'BTC-USD', 'changes': [['sell', '38342.31', '0.04000000']], 'time': '2021-05-20T03:55:58.878057Z'}
{'type': 'l2update', 'product_id': 'BTC-USD', 'changes': [['sell', '38326.53', '0.05000000']], 'time': '2021-05-20T03:55:58.878140Z'}
{'type': 'l2update', 'product_id': 'BTC-USD', 'changes': [['buy', '38297.84', '0.02435306']], 'time': '2021-05-20T03:55:58.878242Z'}
{'type': 'l2update', 'product_id': 'BTC-USD', 'changes': [['sell', '38371.72', '0.07800000']], 'time': '2021-05-20T03:55:58.878263Z'}
{'type': 'l2update', 'product_id': 'BTC-USD', 'changes': [['buy', '38257.66', '0.00000000']], 'time': '2021-05-20T03:55:58.880350Z'}
{'type': 'l2update', 'product_id': 'BTC-USD', 'changes': [['buy', '38139.83', '0.17510000']], 'time': '2021-05-20T03:55:58.881954Z'}
{'type': 'l2update', 'product_id': 'BTC-USD', 'changes': [['sell', '38307.33', '0.01661471']], 'time': '2021-05-20T03:55:58.882077Z'}
{'type': 'l2update', 'product_id': 'BTC-USD', 'changes': [['sell', '38346.85', '0.50000000']], 'time': '2021-05-20T03:55:58.882214Z'}
{'type': 'l2update', 'product_id': 'BTC-USD', 'changes': [['sell', '38364.29', '0.07800000']], 'time': '2021-05-20T03:55:58.882405Z'}
{'type': 'l2update', 'product_id': 'BTC-USD', 'changes': [['buy', '38259.16', '0.03908650']], 'time': '2021-05-20T03:55:58.882468Z'}
{'type': 'l2update', 'product_id': 'BTC-USD', 'changes': [['buy', '38140.12', '0.01891050']], 'time': '2021-05-20T03:55:58.883554Z'}
{'type': 'l2update', 'product_id': 'BTC-USD', 'changes': [['sell', '38386.58', '0.07800000']], 'time': '2021-05-20T03:55:58.887712Z'}
{'type': 'l2update', 'product_id': 'BTC-USD', 'changes': [['buy', '38296.04', '0.00000000']], 'time': '2021-05-20T03:55:58.890477Z'}
{'type': 'l2update', 'product_id': 'BTC-USD', 'changes': [['buy', '38297.76', '0.01176915']], 'time': '2021-05-20T03:55:58.890562Z'}
{'type': 'l2update', 'product_id': 'BTC-USD', 'changes': [['sell', '38307.48', '0.01492000']], 'time': '2021-05-20T03:55:58.891612Z'}
{'type': 'l2update', 'product_id': 'BTC-USD', 'changes': [['sell', '38307.33', '0.07460000']], 'time': '2021-05-20T03:55:58.891929Z'}
{'type': 'l2update', 'product_id': 'BTC-USD', 'changes': [['sell', '38358.96', '0.03701832']], 'time': '2021-05-20T03:55:58.891998Z'}
{'type': 'l2update', 'product_id': 'BTC-USD', 'changes': [['sell', '38328.11', '0.00000000']], 'time': '2021-05-20T03:55:58.892721Z'}
{'type': 'l2update', 'product_id': 'BTC-USD', 'changes': [['buy', '38259.16', '0.00000000']], 'time': '2021-05-20T03:55:58.892889Z'}
{'type': 'l2update', 'product_id': 'BTC-USD', 'changes': [['buy', '38260.84', '0.03908650']], 'time': '2021-05-20T03:55:58.895956Z'}
{'type': 'l2update', 'product_id': 'BTC-USD', 'changes': [['sell', '38350.01', '0.79135025']], 'time': '2021-05-20T03:55:58.896109Z'}
{'type': 'l2update', 'product_id': 'BTC-USD', 'changes': [['buy', '38207.36', '0.42486504']], 'time': '2021-05-20T03:55:58.896109Z'}
{'type': 'l2update', 'product_id': 'BTC-USD', 'changes': [['sell', '38342.56', '0.05000000']], 'time': '2021-05-20T03:55:58.896391Z'}
{'type': 'l2update', 'product_id': 'BTC-USD', 'changes': [['buy', '38297.76', '0.00000000']], 'time': '2021-05-20T03:55:58.898150Z'}
{'type': 'l2update', 'product_id': 'BTC-USD', 'changes': [['sell', '38474.69', '0.00000000']], 'time': '2021-05-20T03:55:58.900607Z'}
{'type': 'l2update', 'product_id': 'BTC-USD', 'changes': [['buy', '38214.73', '0.50000000']], 'time': '2021-05-20T03:55:58.900900Z'}
{'type': 'l2update', 'product_id': 'BTC-USD', 'changes': [['sell', '38634.85', '0.00000000']], 'time': '2021-05-20T03:55:58.902543Z'}
{'type': 'l2update', 'product_id': 'BTC-USD', 'changes': [['sell', '38307.48', '0.00000000']], 'time': '2021-05-20T03:55:58.902787Z'}
{'type': 'l2update', 'product_id': 'BTC-USD', 'changes': [['buy', '38275.50', '0.05000000']], 'time': '2021-05-20T03:55:58.910903Z'}
{'type': 'l2update', 'product_id': 'BTC-USD', 'changes': [['buy', '38298.33', '0.00315085']], 'time': '2021-05-20T03:55:58.911050Z'}
{'type': 'l2update', 'product_id': 'BTC-USD', 'changes': [['sell', '38461.52', '0.01000000']], 'time': '2021-05-20T03:55:58.913022Z'}
{'type': 'l2update', 'product_id': 'BTC-USD', 'changes': [['sell', '38328.47', '0.46600000']], 'time': '2021-05-20T03:55:58.916216Z'}
{'type': 'l2update', 'product_id': 'BTC-USD', 'changes': [['buy', '38275.32', '0.37300000']], 'time': '2021-05-20T03:55:58.916844Z'}
{'type': 'l2update', 'product_id': 'BTC-USD', 'changes': [['sell', '38680.11', '0.01292654']], 'time': '2021-05-20T03:55:58.916879Z'}
{'type': 'l2update', 'product_id': 'BTC-USD', 'changes': [['buy', '38276.04', '0.00000000']], 'time': '2021-05-20T03:55:58.916956Z'}
{'type': 'l2update', 'product_id': 'BTC-USD', 'changes': [['sell', '38620.55', '0.00000000']], 'time': '2021-05-20T03:55:58.919021Z'}
{'type': 'l2update', 'product_id': 'BTC-USD', 'changes': [['sell', '38461.52', '0.00000000']], 'time': '2021-05-20T03:55:58.922467Z'}
{'type': 'l2update', 'product_id': 'BTC-USD', 'changes': [['buy', '38282.43', '0.00000000']], 'time': '2021-05-20T03:55:58.923832Z'}
{'type': 'l2update', 'product_id': 'BTC-USD', 'changes': [['sell', '38341.91', '0.01000000']], 'time': '2021-05-20T03:55:58.924798Z'}
{'type': 'l2update', 'product_id': 'BTC-USD', 'changes': [['sell', '38306.66', '0.01492000']], 'time': '2021-05-20T03:55:58.925037Z'}
{'type': 'l2update', 'product_id': 'BTC-USD', 'changes': [['sell', '38328.47', '0.00000000']], 'time': '2021-05-20T03:55:58.927821Z'}
{'type': 'l2update', 'product_id': 'BTC-USD', 'changes': [['sell', '38342.56', '0.00000000']], 'time': '2021-05-20T03:55:58.929026Z'}
{'type': 'l2update', 'product_id': 'BTC-USD', 'changes': [['sell', '38307.33', '0.06770731']], 'time': '2021-05-20T03:55:58.930741Z'}
{'type': 'l2update', 'product_id': 'BTC-USD', 'changes': [['sell', '38307.33', '0.05798529']], 'time': '2021-05-20T03:55:58.930939Z'}
{'type': 'l2update', 'product_id': 'BTC-USD', 'changes': [['sell', '38359.61', '0.29224985']], 'time': '2021-05-20T03:55:58.933203Z'}
{'type': 'l2update', 'product_id': 'BTC-USD', 'changes': [['buy', '38194.62', '0.29224985']], 'time': '2021-05-20T03:55:58.933203Z'}
{'type': 'l2update', 'product_id': 'BTC-USD', 'changes': [['buy', '38276.06', '0.06508047']], 'time': '2021-05-20T03:55:58.933283Z'}
{'type': 'l2update', 'product_id': 'BTC-USD', 'changes': [['buy', '37505.43', '0.06573829']], 'time': '2021-05-20T03:55:58.933329Z'}
{'type': 'l2update', 'product_id': 'BTC-USD', 'changes': [['buy', '38220.94', '0.02922346']], 'time': '2021-05-20T03:55:58.933396Z'}
{'type': 'l2update', 'product_id': 'BTC-USD', 'changes': [['buy', '38228.29', '0.00000000']], 'time': '2021-05-20T03:55:58.933396Z'}
{'type': 'l2update', 'product_id': 'BTC-USD', 'changes': [['buy', '38238.55', '0.00000000']], 'time': '2021-05-20T03:55:58.933396Z'}
{'type': 'l2update', 'product_id': 'BTC-USD', 'changes': [['buy', '38244.04', '0.00000000']], 'time': '2021-05-20T03:55:58.933396Z'}
{'type': 'l2update', 'product_id': 'BTC-USD', 'changes': [['sell', '38605.75', '0.01000000']], 'time': '2021-05-20T03:55:58.933445Z'}
{'type': 'l2update', 'product_id': 'BTC-USD', 'changes': [['sell', '38307.33', '0.00000000']], 'time': '2021-05-20T03:55:58.934530Z'}
{'type': 'l2update', 'product_id': 'BTC-USD', 'changes': [['sell', '38419.34', '0.00000000']], 'time': '2021-05-20T03:55:58.935431Z'}
{'type': 'l2update', 'product_id': 'BTC-USD', 'changes': [['sell', '38474.69', '0.01000000']], 'time': '2021-05-20T03:55:58.936410Z'}
{'type': 'l2update', 'product_id': 'BTC-USD', 'changes': [['sell', '38306.66', '0.00000000']], 'time': '2021-05-20T03:55:58.943736Z'}
{'type': 'l2update', 'product_id': 'BTC-USD', 'changes': [['sell', '38348.80', '0.05000000']], 'time': '2021-05-20T03:55:58.944665Z'}
{'type': 'l2update', 'product_id': 'BTC-USD', 'changes': [['buy', '38294.30', '0.57274248']], 'time': '2021-05-20T03:55:58.944702Z'}
{'type': 'l2update', 'product_id': 'BTC-USD', 'changes': [['sell', '38307.84', '0.02949360']], 'time': '2021-05-20T03:55:58.947729Z'}
{'type': 'l2update', 'product_id': 'BTC-USD', 'changes': [['sell', '38404.69', '0.01000000']], 'time': '2021-05-20T03:55:58.947778Z'}
{'type': 'l2update', 'product_id': 'BTC-USD', 'changes': [['sell', '38306.24', '0.07460000']], 'time': '2021-05-20T03:55:58.948221Z'}
{'type': 'l2update', 'product_id': 'BTC-USD', 'changes': [['sell', '38306.24', '0.00000000']], 'time': '2021-05-20T03:55:58.953561Z'}
{'type': 'l2update', 'product_id': 'BTC-USD', 'changes': [['sell', '38307.52', '0.01492000']], 'time': '2021-05-20T03:55:58.955725Z'}
{'type': 'l2update', 'product_id': 'BTC-USD', 'changes': [['sell', '38446.65', '0.00000000']], 'time': '2021-05-20T03:55:58.956897Z'}
{'type': 'l2update', 'product_id': 'BTC-USD', 'changes': [['sell', '38331.73', '0.39490432']], 'time': '2021-05-20T03:55:58.959353Z'}
{'type': 'l2update', 'product_id': 'BTC-USD', 'changes': [['buy', '38306.66', '0.00367349']], 'time': '2021-05-20T03:55:58.959498Z'}
{'type': 'l2update', 'product_id': 'BTC-USD', 'changes': [['sell', '38315.22', '0.00000000']], 'time': '2021-05-20T03:55:58.966818Z'}
{'type': 'l2update', 'product_id': 'BTC-USD', 'changes': [['sell', '38307.52', '0.00000000']], 'time': '2021-05-20T03:55:58.967370Z'}
{'type': 'l2update', 'product_id': 'BTC-USD', 'changes': [['buy', '38297.19', '0.00000000']], 'time': '2021-05-20T03:55:58.967565Z'}
{'type': 'l2update', 'product_id': 'BTC-USD', 'changes': [['sell', '38307.61', '0.07460000']], 'time': '2021-05-20T03:55:58.968529Z'}
{'type': 'l2update', 'product_id': 'BTC-USD', 'changes': [['sell', '38326.53', '0.00000000']], 'time': '2021-05-20T03:55:58.968809Z'}
{'type': 'l2update', 'product_id': 'BTC-USD', 'changes': [['sell', '38470.46', '0.01000000']], 'time': '2021-05-20T03:55:58.973009Z'}
{'type': 'l2update', 'product_id': 'BTC-USD', 'changes': [['sell', '38370.17', '0.37661801']], 'time': '2021-05-20T03:55:58.973093Z'}
{'type': 'l2update', 'product_id': 'BTC-USD', 'changes': [['buy', '38194.62', '0.66886786']], 'time': '2021-05-20T03:55:58.973093Z'}
{'type': 'l2update', 'product_id': 'BTC-USD', 'changes': [['sell', '38307.61', '0.00000000']], 'time': '2021-05-20T03:55:58.973290Z'}
{'type': 'l2update', 'product_id': 'BTC-USD', 'changes': [['sell', '38370.17', '0.40414289']], 'time': '2021-05-20T03:55:58.973392Z'}
{'type': 'l2update', 'product_id': 'BTC-USD', 'changes': [['buy', '38218.54', '0.02752488']], 'time': '2021-05-20T03:55:58.973392Z'}
{'type': 'l2update', 'product_id': 'BTC-USD', 'changes': [['buy', '38224.22', '0.03353501']], 'time': '2021-05-20T03:55:58.973392Z'}
{'type': 'l2update', 'product_id': 'BTC-USD', 'changes': [['buy', '38229.71', '0.02686816']], 'time': '2021-05-20T03:55:58.973392Z'}
{'type': 'l2update', 'product_id': 'BTC-USD', 'changes': [['buy', '38240.12', '0.03130160']], 'time': '2021-05-20T03:55:58.973392Z'}
{'type': 'l2update', 'product_id': 'BTC-USD', 'changes': [['buy', '38245.04', '0.03439766']], 'time': '2021-05-20T03:55:58.973392Z'}
{'type': 'l2update', 'product_id': 'BTC-USD', 'changes': [['buy', '38249.77', '0.02724355']], 'time': '2021-05-20T03:55:58.973392Z'}
{'type': 'l2update', 'product_id': 'BTC-USD', 'changes': [['buy', '38258.68', '0.02868087']], 'time': '2021-05-20T03:55:58.973392Z'}
{'type': 'l2update', 'product_id': 'BTC-USD', 'changes': [['buy', '38297.84', '0.00000000']], 'time': '2021-05-20T03:55:58.974318Z'}
{'type': 'l2update', 'product_id': 'BTC-USD', 'changes': [['buy', '38298.33', '0.01492000']], 'time': '2021-05-20T03:55:58.981025Z'}
{'type': 'l2update', 'product_id': 'BTC-USD', 'changes': [['sell', '38331.72', '0.05000000']], 'time': '2021-05-20T03:55:58.981286Z'}
{'type': 'l2update', 'product_id': 'BTC-USD', 'changes': [['sell', '38326.51', '0.50000000']], 'time': '2021-05-20T03:55:58.981897Z'}
{'type': 'l2update', 'product_id': 'BTC-USD', 'changes': [['buy', '38260.84', '0.00000000']], 'time': '2021-05-20T03:55:58.983706Z'}
{'type': 'l2update', 'product_id': 'BTC-USD', 'changes': [['buy', '38263.31', '1.20000000']], 'time': '2021-05-20T03:55:58.990171Z'}
{'type': 'l2update', 'product_id': 'BTC-USD', 'changes': [['buy', '38258.68', '0.04037025']], 'time': '2021-05-20T03:55:58.990221Z'}
{'type': 'l2update', 'product_id': 'BTC-USD', 'changes': [['buy', '38295.89', '0.05024694']], 'time': '2021-05-20T03:55:58.990250Z'}
{'type': 'l2update', 'product_id': 'BTC-USD', 'changes': [['buy', '38263.28', '0.03908650']], 'time': '2021-05-20T03:55:58.994035Z'}
{'type': 'l2update', 'product_id': 'BTC-USD', 'changes': [['buy', '38245.34', '0.12262325']], 'time': '2021-05-20T03:55:58.994072Z'}
{'type': 'l2update', 'product_id': 'BTC-USD', 'changes': [['sell', '38375.49', '0.31708344']], 'time': '2021-05-20T03:55:58.997212Z'}
{'type': 'l2update', 'product_id': 'BTC-USD', 'changes': [['buy', '38181.38', '0.31708344']], 'time': '2021-05-20T03:55:58.997212Z'}
{'type': 'l2update', 'product_id': 'BTC-USD', 'changes': [['buy', '38177.43', '0.00000000']], 'time': '2021-05-20T03:55:58.997856Z'}
{'type': 'l2update', 'product_id': 'BTC-USD', 'changes': [['buy', '38186.68', '0.01900300']], 'time': '2021-05-20T03:55:58.997856Z'}
{'type': 'l2update', 'product_id': 'BTC-USD', 'changes': [['buy', '38193.22', '0.00000000']], 'time': '2021-05-20T03:55:58.997856Z'}
{'type': 'l2update', 'product_id': 'BTC-USD', 'changes': [['buy', '38193.72', '0.00000000']], 'time': '2021-05-20T03:55:58.997856Z'}
{'type': 'l2update', 'product_id': 'BTC-USD', 'changes': [['buy', '38208.27', '0.07800000']], 'time': '2021-05-20T03:55:58.997856Z'}
{'type': 'l2update', 'product_id': 'BTC-USD', 'changes': [['buy', '38214.70', '0.00000000']], 'time': '2021-05-20T03:55:58.997856Z'}
{'type': 'l2update', 'product_id': 'BTC-USD', 'changes': [['buy', '38220.94', '0.00000000']], 'time': '2021-05-20T03:55:58.997856Z'}
{'type': 'l2update', 'product_id': 'BTC-USD', 'changes': [['buy', '38248.49', '0.05449922']], 'time': '2021-05-20T03:55:58.997886Z'}
{'type': 'l2update', 'product_id': 'BTC-USD', 'changes': [['buy', '38298.33', '0.01176915']], 'time': '2021-05-20T03:55:58.999822Z'}
{'type': 'l2update', 'product_id': 'BTC-USD', 'changes': [['buy', '38298.33', '0.00000000']], 'time': '2021-05-20T03:55:58.999946Z'}
{'type': 'l2update', 'product_id': 'BTC-USD', 'changes': [['buy', '38263.28', '0.00000000']], 'time': '2021-05-20T03:55:59.002289Z'}
{'type': 'l2update', 'product_id': 'BTC-USD', 'changes': [['sell', '38500.11', '0.00000000']], 'time': '2021-05-20T03:55:59.003256Z'}
{'type': 'l2update', 'product_id': 'BTC-USD', 'changes': [['sell', '38474.69', '0.00000000']], 'time': '2021-05-20T03:55:59.006326Z'}
{'type': 'l2update', 'product_id': 'BTC-USD', 'changes': [['buy', '38263.32', '0.03908650']], 'time': '2021-05-20T03:55:59.007924Z'}
{'type': 'l2update', 'product_id': 'BTC-USD', 'changes': [['sell', '38398.25', '1.20000000']], 'time': '2021-05-20T03:55:59.007954Z'}
{'type': 'l2update', 'product_id': 'BTC-USD', 'changes': [['buy', '38259.93', '0.02724961']], 'time': '2021-05-20T03:55:59.008235Z'}
{'type': 'l2update', 'product_id': 'BTC-USD', 'changes': [['buy', '38195.25', '0.00000000']], 'time': '2021-05-20T03:55:59.009057Z'}
{'type': 'l2update', 'product_id': 'BTC-USD', 'changes': [['buy', '38297.77', '0.07148434']], 'time': '2021-05-20T03:55:59.009422Z'}
{'type': 'l2update', 'product_id': 'BTC-USD', 'changes': [['sell', '38342.31', '0.00000000']], 'time': '2021-05-20T03:55:59.011240Z'}
{'type': 'l2update', 'product_id': 'BTC-USD', 'changes': [['buy', '38265.94', '0.03908650']], 'time': '2021-05-20T03:55:59.013566Z'}
{'type': 'l2update', 'product_id': 'BTC-USD', 'changes': [['sell', '38373.37', '0.03256594']], 'time': '2021-05-20T03:55:59.013701Z'}
{'type': 'l2update', 'product_id': 'BTC-USD', 'changes': [['buy', '38263.32', '0.00000000']], 'time': '2021-05-20T03:55:59.015978Z'}
{'type': 'l2update', 'product_id': 'BTC-USD', 'changes': [['sell', '38461.52', '0.01000000']], 'time': '2021-05-20T03:55:59.017127Z'}
{'type': 'l2update', 'product_id': 'BTC-USD', 'changes': [['buy', '38283.73', '0.41560000']], 'time': '2021-05-20T03:55:59.017938Z'}
{'type': 'l2update', 'product_id': 'BTC-USD', 'changes': [['sell', '38404.69', '0.00000000']], 'time': '2021-05-20T03:55:59.020880Z'}
{'type': 'l2update', 'product_id': 'BTC-USD', 'changes': [['buy', '38208.39', '0.02731687']], 'time': '2021-05-20T03:55:59.021433Z'}
{'type': 'l2update', 'product_id': 'BTC-USD', 'changes': [['sell', '38383.82', '0.41419655']], 'time': '2021-05-20T03:55:59.021600Z'}
{'type': 'l2update', 'product_id': 'BTC-USD', 'changes': [['buy', '38174.71', '0.41419655']], 'time': '2021-05-20T03:55:59.021600Z'}
{'type': 'l2update', 'product_id': 'BTC-USD', 'changes': [['buy', '38265.94', '0.00000000']], 'time': '2021-05-20T03:55:59.021701Z'}
{'type': 'l2update', 'product_id': 'BTC-USD', 'changes': [['sell', '38348.14', '0.04000000']], 'time': '2021-05-20T03:55:59.025327Z'}
{'type': 'l2update', 'product_id': 'BTC-USD', 'changes': [['buy', '37505.43', '0.00000000']], 'time': '2021-05-20T03:55:59.026111Z'}
{'type': 'l2update', 'product_id': 'BTC-USD', 'changes': [['sell', '38332.82', '0.45670000']], 'time': '2021-05-20T03:55:59.029986Z'}
{'type': 'l2update', 'product_id': 'BTC-USD', 'changes': [['sell', '38538.06', '0.01297418']], 'time': '2021-05-20T03:55:59.030272Z'}
{'type': 'l2update', 'product_id': 'BTC-USD', 'changes': [['buy', '38295.89', '0.00000000']], 'time': '2021-05-20T03:55:59.030471Z'}
{'type': 'l2update', 'product_id': 'BTC-USD', 'changes': [['buy', '38267.68', '0.03908650']], 'time': '2021-05-20T03:55:59.036522Z'}
{'type': 'l2update', 'product_id': 'BTC-USD', 'changes': [['buy', '38298.27', '0.02435306']], 'time': '2021-05-20T03:55:59.037429Z'}
{'type': 'l2update', 'product_id': 'BTC-USD', 'changes': [['buy', '38298.39', '0.01492000']], 'time': '2021-05-20T03:55:59.037452Z'}
{'type': 'l2update', 'product_id': 'BTC-USD', 'changes': [['sell', '38416.87', '0.01000000']], 'time': '2021-05-20T03:55:59.037503Z'}
{'type': 'l2update', 'product_id': 'BTC-USD', 'changes': [['buy', '38269.39', '0.03908650']], 'time': '2021-05-20T03:55:59.040995Z'}
{'type': 'l2update', 'product_id': 'BTC-USD', 'changes': [['buy', '38267.68', '0.00000000']], 'time': '2021-05-20T03:55:59.043246Z'}
{'type': 'l2update', 'product_id': 'BTC-USD', 'changes': [['sell', '38429.30', '0.00000000']], 'time': '2021-05-20T03:55:59.044811Z'}
{'type': 'l2update', 'product_id': 'BTC-USD', 'changes': [['sell', '38395.03', '0.37247194']], 'time': '2021-05-20T03:55:59.046012Z'}
{'type': 'l2update', 'product_id': 'BTC-USD', 'changes': [['sell', '38383.82', '0.44576480']], 'time': '2021-05-20T03:55:59.046082Z'}
{'type': 'l2update', 'product_id': 'BTC-USD', 'changes': [['buy', '38207.80', '0.03156825']], 'time': '2021-05-20T03:55:59.046082Z'}
{'type': 'l2update', 'product_id': 'BTC-USD', 'changes': [['sell', '38391.58', '0.00000000']], 'time': '2021-05-20T03:55:59.051668Z'}
{'type': 'l2update', 'product_id': 'BTC-USD', 'changes': [['buy', '38270.84', '0.00000000']], 'time': '2021-05-20T03:55:59.052430Z'}
{'type': 'l2update', 'product_id': 'BTC-USD', 'changes': [['sell', '38307.84', '0.14259986']], 'time': '2021-05-20T03:55:59.056317Z'}
{'type': 'l2update', 'product_id': 'BTC-USD', 'changes': [['sell', '38412.73', '0.01402491']], 'time': '2021-05-20T03:55:59.056666Z'}
{'type': 'l2update', 'product_id': 'BTC-USD', 'changes': [['sell', '38389.33', '0.03291307']], 'time': '2021-05-20T03:55:59.060950Z'}
{'type': 'l2update', 'product_id': 'BTC-USD', 'changes': [['buy', '38201.56', '0.03291307']], 'time': '2021-05-20T03:55:59.060950Z'}
{'type': 'l2update', 'product_id': 'BTC-USD', 'changes': [['sell', '38400.92', '0.30369653']], 'time': '2021-05-20T03:55:59.064727Z'}
{'type': 'l2update', 'product_id': 'BTC-USD', 'changes': [['buy', '38297.77', '0.00000000']], 'time': '2021-05-20T03:55:59.065084Z'}
{'type': 'l2update', 'product_id': 'BTC-USD', 'changes': [['buy', '38298.27', '0.00000000']], 'time': '2021-05-20T03:55:59.071815Z'}
{'type': 'l2update', 'product_id': 'BTC-USD', 'changes': [['buy', '38295.46', '0.84800000']], 'time': '2021-05-20T03:55:59.073139Z'}
{'type': 'l2update', 'product_id': 'BTC-USD', 'changes': [['sell', '38326.51', '0.00000000']], 'time': '2021-05-20T03:55:59.073698Z'}
{'type': 'l2update', 'product_id': 'BTC-USD', 'changes': [['sell', '38448.18', '0.00000000']], 'time': '2021-05-20T03:55:59.075942Z'}
{'type': 'l2update', 'product_id': 'BTC-USD', 'changes': [['sell', '38347.69', '0.09794741']], 'time': '2021-05-20T03:55:59.081102Z'}
{'type': 'l2update', 'product_id': 'BTC-USD', 'changes': [['buy', '38298.83', '0.05024694']], 'time': '2021-05-20T03:55:59.084200Z'}
{'type': 'l2update', 'product_id': 'BTC-USD', 'changes': [['buy', '38246.15', '1.28245666']], 'time': '2021-05-20T03:55:59.084680Z'}
{'type': 'l2update', 'product_id': 'BTC-USD', 'changes': [['sell', '38431.83', '0.01000000']], 'time': '2021-05-20T03:55:59.085446Z'}
{'type': 'l2update', 'product_id': 'BTC-USD', 'changes': [['sell', '38395.03', '0.40169307']], 'time': '2021-05-20T03:55:59.085694Z'}
{'type': 'l2update', 'product_id': 'BTC-USD', 'changes': [['buy', '38195.13', '0.02922113']], 'time': '2021-05-20T03:55:59.085694Z'}
{'type': 'l2update', 'product_id': 'BTC-USD', 'changes': [['sell', '38470.46', '0.00000000']], 'time': '2021-05-20T03:55:59.086486Z'}
{'type': 'l2update', 'product_id': 'BTC-USD', 'changes': [['sell', '38315.20', '0.50000000']], 'time': '2021-05-20T03:55:59.090443Z'}
{'type': 'l2update', 'product_id': 'BTC-USD', 'changes': [['buy', '38298.83', '0.07460000']], 'time': '2021-05-20T03:55:59.093466Z'}
{'type': 'l2update', 'product_id': 'BTC-USD', 'changes': [['sell', '38407.00', '0.37919212']], 'time': '2021-05-20T03:55:59.093985Z'}
{'type': 'l2update', 'product_id': 'BTC-USD', 'changes': [['sell', '38450.79', '0.00000000']], 'time': '2021-05-20T03:55:59.095870Z'}
{'type': 'l2update', 'product_id': 'BTC-USD', 'changes': [['sell', '38483.22', '0.00779560']], 'time': '2021-05-20T03:55:59.098130Z'}
{'type': 'l2update', 'product_id': 'BTC-USD', 'changes': [['buy', '38306.67', '0.07148442']], 'time': '2021-05-20T03:55:59.102606Z'}
{'type': 'l2update', 'product_id': 'BTC-USD', 'changes': [['sell', '38435.12', '0.06109082']], 'time': '2021-05-20T03:55:59.107040Z'}
{'type': 'l2update', 'product_id': 'BTC-USD', 'changes': [['sell', '38315.20', '0.00000000']], 'time': '2021-05-20T03:55:59.109108Z'}
{'type': 'l2update', 'product_id': 'BTC-USD', 'changes': [['buy', '38298.39', '0.00000000']], 'time': '2021-05-20T03:55:59.110253Z'}
{'type': 'l2update', 'product_id': 'BTC-USD', 'changes': [['buy', '38298.83', '0.02435306']], 'time': '2021-05-20T03:55:59.110461Z'}
{'type': 'l2update', 'product_id': 'BTC-USD', 'changes': [['buy', '38298.83', '0.00000000']], 'time': '2021-05-20T03:55:59.110522Z'}
{'type': 'l2update', 'product_id': 'BTC-USD', 'changes': [['sell', '38400.92', '0.33724726']], 'time': '2021-05-20T03:55:59.112883Z'}
{'type': 'l2update', 'product_id': 'BTC-USD', 'changes': [['buy', '38188.51', '0.03355073']], 'time': '2021-05-20T03:55:59.112883Z'}
{'type': 'l2update', 'product_id': 'BTC-USD', 'changes': [['buy', '38296.00', '0.00000000']], 'time': '2021-05-20T03:55:59.116217Z'}
{'type': 'l2update', 'product_id': 'BTC-USD', 'changes': [['sell', '38343.06', '0.45322515']], 'time': '2021-05-20T03:55:59.120407Z'}
{'type': 'l2update', 'product_id': 'BTC-USD', 'changes': [['buy', '37510.55', '0.06512352']], 'time': '2021-05-20T03:55:59.125727Z'}
{'type': 'l2update', 'product_id': 'BTC-USD', 'changes': [['sell', '38326.51', '0.50000000']], 'time': '2021-05-20T03:55:59.125771Z'}
{'type': 'l2update', 'product_id': 'BTC-USD', 'changes': [['buy', '38135.91', '0.05023310']], 'time': '2021-05-20T03:55:59.126169Z'}
{'type': 'l2update', 'product_id': 'BTC-USD', 'changes': [['sell', '38386.57', '0.02605078']], 'time': '2021-05-20T03:55:59.126374Z'}
{'type': 'l2update', 'product_id': 'BTC-USD', 'changes': [['sell', '38419.74', '0.33314703']], 'time': '2021-05-20T03:55:59.127186Z'}
{'type': 'l2update', 'product_id': 'BTC-USD', 'changes': [['sell', '38421.21', '0.00000000']], 'time': '2021-05-20T03:55:59.127516Z'}
{'type': 'l2update', 'product_id': 'BTC-USD', 'changes': [['sell', '38407.00', '0.41136967']], 'time': '2021-05-20T03:55:59.139745Z'}
{'type': 'l2update', 'product_id': 'BTC-USD', 'changes': [['sell', '38408.82', '0.01000000']], 'time': '2021-05-20T03:55:59.143195Z'}
{'type': 'l2update', 'product_id': 'BTC-USD', 'changes': [['sell', '38461.52', '0.00000000']], 'time': '2021-05-20T03:55:59.143624Z'}
{'type': 'l2update', 'product_id': 'BTC-USD', 'changes': [['sell', '38426.41', '0.41428815']], 'time': '2021-05-20T03:55:59.154698Z'}
{'type': 'l2update', 'product_id': 'BTC-USD', 'changes': [['sell', '38450.26', '0.00000000']], 'time': '2021-05-20T03:55:59.155210Z'}
{'type': 'l2update', 'product_id': 'BTC-USD', 'changes': [['sell', '38474.69', '0.01000000']], 'time': '2021-05-20T03:55:59.163942Z'}
{'type': 'l2update', 'product_id': 'BTC-USD', 'changes': [['sell', '38332.82', '0.00000000']], 'time': '2021-05-20T03:55:59.168684Z'}
{'type': 'l2update', 'product_id': 'BTC-USD', 'changes': [['sell', '38435.82', '0.01000000']], 'time': '2021-05-20T03:55:59.169794Z'}
{'type': 'l2update', 'product_id': 'BTC-USD', 'changes': [['buy', '38297.55', '0.00176483']], 'time': '2021-05-20T03:55:59.171176Z'}
{'type': 'l2update', 'product_id': 'BTC-USD', 'changes': [['sell', '38419.75', '0.02832823']], 'time': '2021-05-20T03:55:59.171236Z'}
{'type': 'l2update', 'product_id': 'BTC-USD', 'changes': [['buy', '38256.52', '0.00000000']], 'time': '2021-05-20T03:55:59.171685Z'}
{'type': 'l2update', 'product_id': 'BTC-USD', 'changes': [['sell', '38680.11', '0.00000000']], 'time': '2021-05-20T03:55:59.173340Z'}
{'type': 'l2update', 'product_id': 'BTC-USD', 'changes': [['sell', '38460.56', '0.00000000']], 'time': '2021-05-20T03:55:59.173777Z'}
{'type': 'l2update', 'product_id': 'BTC-USD', 'changes': [['sell', '38334.63', '0.43920000']], 'time': '2021-05-20T03:55:59.180410Z'}
{'type': 'l2update', 'product_id': 'BTC-USD', 'changes': [['sell', '38433.26', '0.36179905']], 'time': '2021-05-20T03:55:59.183946Z'}
{'type': 'l2update', 'product_id': 'BTC-USD', 'changes': [['sell', '38665.02', '0.01293158']], 'time': '2021-05-20T03:55:59.184234Z'}
{'type': 'l2update', 'product_id': 'BTC-USD', 'changes': [['buy', '38130.15', '0.00000000']], 'time': '2021-05-20T03:55:59.184666Z'}
{'type': 'l2update', 'product_id': 'BTC-USD', 'changes': [['sell', '38330.94', '0.05045609']], 'time': '2021-05-20T03:55:59.188505Z'}
{'type': 'l2update', 'product_id': 'BTC-USD', 'changes': [['sell', '38446.83', '0.01218739']], 'time': '2021-05-20T03:55:59.188852Z'}
{'type': 'l2update', 'product_id': 'BTC-USD', 'changes': [['sell', '38538.06', '0.00000000']], 'time': '2021-05-20T03:55:59.197028Z'}
{'type': 'l2update', 'product_id': 'BTC-USD', 'changes': [['sell', '38426.41', '0.44547797']], 'time': '2021-05-20T03:55:59.205838Z'}
{'type': 'l2update', 'product_id': 'BTC-USD', 'changes': [['buy', '38253.52', '0.10000000']], 'time': '2021-05-20T03:55:59.206040Z'}
{'type': 'l2update', 'product_id': 'BTC-USD', 'changes': [['sell', '38317.26', '0.55400000']], 'time': '2021-05-20T03:55:59.206241Z'}
{'type': 'l2update', 'product_id': 'BTC-USD', 'changes': [['buy', '38230.56', '0.07800000']], 'time': '2021-05-20T03:55:59.209521Z'}
{'type': 'l2update', 'product_id': 'BTC-USD', 'changes': [['sell', '38518.17', '0.01000000']], 'time': '2021-05-20T03:55:59.209656Z'}
{'type': 'l2update', 'product_id': 'BTC-USD', 'changes': [['sell', '43100.00', '1.09530000']], 'time': '2021-05-20T03:55:59.216037Z'}
{'type': 'l2update', 'product_id': 'BTC-USD', 'changes': [['sell', '38416.87', '0.00000000']], 'time': '2021-05-20T03:55:59.217196Z'}
{'type': 'l2update', 'product_id': 'BTC-USD', 'changes': [['sell', '38440.30', '0.33508741']], 'time': '2021-05-20T03:55:59.217228Z'}
{'type': 'l2update', 'product_id': 'BTC-USD', 'changes': [['sell', '38307.84', '0.13259986']], 'time': '2021-05-20T03:55:59.228684Z'}
{'type': 'l2update', 'product_id': 'BTC-USD', 'changes': [['buy', '37510.55', '0.00000000']], 'time': '2021-05-20T03:55:59.232945Z'}
{'type': 'l2update', 'product_id': 'BTC-USD', 'changes': [['sell', '39090.90', '0.00175897']], 'time': '2021-05-20T03:55:59.236510Z'}
{'type': 'l2update', 'product_id': 'BTC-USD', 'changes': [['sell', '38437.21', '0.01000000']], 'time': '2021-05-20T03:55:59.236741Z'}
{'type': 'l2update', 'product_id': 'BTC-USD', 'changes': [['buy', '38269.39', '0.00000000']], 'time': '2021-05-20T03:55:59.241577Z'}
{'type': 'l2update', 'product_id': 'BTC-USD', 'changes': [['buy', '38278.15', '0.00000000']], 'time': '2021-05-20T03:55:59.243561Z'}
{'type': 'l2update', 'product_id': 'BTC-USD', 'changes': [['sell', '38665.02', '0.00000000']], 'time': '2021-05-20T03:55:59.247115Z'}
{'type': 'l2update', 'product_id': 'BTC-USD', 'changes': [['buy', '38108.76', '0.05000931']], 'time': '2021-05-20T03:55:59.249432Z'}
{'type': 'l2update', 'product_id': 'BTC-USD', 'changes': [['buy', '38278.58', '0.00000000']], 'time': '2021-05-20T03:55:59.249517Z'}
{'type': 'l2update', 'product_id': 'BTC-USD', 'changes': [['buy', '38275.51', '0.03908650']], 'time': '2021-05-20T03:55:59.249784Z'}
{'type': 'l2update', 'product_id': 'BTC-USD', 'changes': [['buy', '38279.39', '0.00000000']], 'time': '2021-05-20T03:55:59.256206Z'}
{'type': 'l2update', 'product_id': 'BTC-USD', 'changes': [['sell', '38649.94', '0.01293663']], 'time': '2021-05-20T03:55:59.256416Z'}
{'type': 'l2update', 'product_id': 'BTC-USD', 'changes': [['buy', '38275.51', '0.00000000']], 'time': '2021-05-20T03:55:59.256543Z'}
{'type': 'l2update', 'product_id': 'BTC-USD', 'changes': [['buy', '38276.07', '0.03908650']], 'time': '2021-05-20T03:55:59.274376Z'}
{'type': 'l2update', 'product_id': 'BTC-USD', 'changes': [['buy', '38286.94', '0.02400000']], 'time': '2021-05-20T03:55:59.279150Z'}
{'type': 'l2update', 'product_id': 'BTC-USD', 'changes': [['buy', '38286.14', '0.02400000']], 'time': '2021-05-20T03:55:59.279150Z'}
{'type': 'l2update', 'product_id': 'BTC-USD', 'changes': [['buy', '38285.33', '0.02400000']], 'time': '2021-05-20T03:55:59.279150Z'}
{'type': 'l2update', 'product_id': 'BTC-USD', 'changes': [['sell', '38437.21', '0.00000000']], 'time': '2021-05-20T03:55:59.286259Z'}
{'type': 'l2update', 'product_id': 'BTC-USD', 'changes': [['sell', '38334.63', '0.00000000']], 'time': '2021-05-20T03:55:59.286466Z'}
{'type': 'l2update', 'product_id': 'BTC-USD', 'changes': [['buy', '38285.33', '0.00000000']], 'time': '2021-05-20T03:55:59.287543Z'}
{'type': 'l2update', 'product_id': 'BTC-USD', 'changes': [['buy', '38283.46', '0.00000000']], 'time': '2021-05-20T03:55:59.292647Z'}
{'type': 'l2update', 'product_id': 'BTC-USD', 'changes': [['buy', '38230.56', '0.00000000']], 'time': '2021-05-20T03:55:59.297854Z'}
{'type': 'l2update', 'product_id': 'BTC-USD', 'changes': [['buy', '38276.07', '0.00000000']], 'time': '2021-05-20T03:55:59.298149Z'}
{'type': 'l2update', 'product_id': 'BTC-USD', 'changes': [['sell', '38326.51', '0.00000000']], 'time': '2021-05-20T03:55:59.298798Z'}
{'type': 'l2update', 'product_id': 'BTC-USD', 'changes': [['sell', '38412.81', '0.01000000']], 'time': '2021-05-20T03:55:59.304135Z'}
{'type': 'l2update', 'product_id': 'BTC-USD', 'changes': [['sell', '38329.57', '0.44260000']], 'time': '2021-05-20T03:55:59.304152Z'}
{'type': 'l2update', 'product_id': 'BTC-USD', 'changes': [['buy', '38290.43', '0.99440510']], 'time': '2021-05-20T03:55:59.307655Z'}
{'type': 'l2update', 'product_id': 'BTC-USD', 'changes': [['buy', '38276.81', '0.03908650']], 'time': '2021-05-20T03:55:59.308137Z'}
{'type': 'l2update', 'product_id': 'BTC-USD', 'changes': [['sell', '38329.57', '0.00000000']], 'time': '2021-05-20T03:55:59.311795Z'}
{'type': 'l2update', 'product_id': 'BTC-USD', 'changes': [['sell', '38315.20', '0.50000000']], 'time': '2021-05-20T03:55:59.313081Z'}
{'type': 'l2update', 'product_id': 'BTC-USD', 'changes': [['buy', '38288.18', '0.00000000']], 'time': '2021-05-20T03:55:59.316913Z'}
{'type': 'l2update', 'product_id': 'BTC-USD', 'changes': [['buy', '38281.32', '0.07000000']], 'time': '2021-05-20T03:55:59.319714Z'}
{'type': 'l2update', 'product_id': 'BTC-USD', 'changes': [['buy', '38290.43', '0.00000000']], 'time': '2021-05-20T03:55:59.319994Z'}
{'type': 'l2update', 'product_id': 'BTC-USD', 'changes': [['buy', '38281.32', '0.04000000']], 'time': '2021-05-20T03:55:59.323046Z'}
{'type': 'l2update', 'product_id': 'BTC-USD', 'changes': [['sell', '38315.20', '0.68981474']], 'time': '2021-05-20T03:55:59.323982Z'}
{'type': 'l2update', 'product_id': 'BTC-USD', 'changes': [['buy', '38295.47', '0.40135082']], 'time': '2021-05-20T03:55:59.324354Z'}
{'type': 'l2update', 'product_id': 'BTC-USD', 'changes': [['buy', '38281.32', '0.00000000']], 'time': '2021-05-20T03:55:59.326342Z'}
{'type': 'l2update', 'product_id': 'BTC-USD', 'changes': [['buy', '38275.50', '0.00000000']], 'time': '2021-05-20T03:55:59.332055Z'}
{'type': 'l2update', 'product_id': 'BTC-USD', 'changes': [['buy', '37510.00', '0.06695788']], 'time': '2021-05-20T03:55:59.332468Z'}
{'type': 'l2update', 'product_id': 'BTC-USD', 'changes': [['buy', '38289.07', '0.99440510']], 'time': '2021-05-20T03:55:59.336638Z'}
{'type': 'l2update', 'product_id': 'BTC-USD', 'changes': [['sell', '38649.94', '0.00000000']], 'time': '2021-05-20T03:55:59.336922Z'}
{'type': 'l2update', 'product_id': 'BTC-USD', 'changes': [['sell', '38315.15', '0.55400000']], 'time': '2021-05-20T03:55:59.340554Z'}
{'type': 'l2update', 'product_id': 'BTC-USD', 'changes': [['buy', '38294.42', '0.01000000']], 'time': '2021-05-20T03:55:59.345041Z'}
{'type': 'l2update', 'product_id': 'BTC-USD', 'changes': [['buy', '38263.31', '1.23698086']], 'time': '2021-05-20T03:55:59.345058Z'}
{'type': 'l2update', 'product_id': 'BTC-USD', 'changes': [['buy', '38287.88', '0.02400000']], 'time': '2021-05-20T03:55:59.345111Z'}
{'type': 'l2update', 'product_id': 'BTC-USD', 'changes': [['sell', '38634.85', '0.01000000']], 'time': '2021-05-20T03:55:59.349873Z'}
{'type': 'l2update', 'product_id': 'BTC-USD', 'changes': [['buy', '38286.14', '0.00000000']], 'time': '2021-05-20T03:55:59.352869Z'}
{'type': 'l2update', 'product_id': 'BTC-USD', 'changes': [['buy', '38287.88', '0.00000000']], 'time': '2021-05-20T03:55:59.357562Z'}
{'type': 'l2update', 'product_id': 'BTC-USD', 'changes': [['buy', '38286.94', '0.00000000']], 'time': '2021-05-20T03:55:59.357562Z'}
{'type': 'l2update', 'product_id': 'BTC-USD', 'changes': [['buy', '38293.86', '0.02000000']], 'time': '2021-05-20T03:55:59.358901Z'}
{'type': 'l2update', 'product_id': 'BTC-USD', 'changes': [['buy', '38293.12', '0.03000000']], 'time': '2021-05-20T03:55:59.370870Z'}
{'type': 'l2update', 'product_id': 'BTC-USD', 'changes': [['buy', '38286.64', '0.02400000']], 'time': '2021-05-20T03:55:59.378125Z'}
{'type': 'l2update', 'product_id': 'BTC-USD', 'changes': [['buy', '38285.83', '0.02400000']], 'time': '2021-05-20T03:55:59.378125Z'}
{'type': 'l2update', 'product_id': 'BTC-USD', 'changes': [['buy', '38285.03', '0.02400000']], 'time': '2021-05-20T03:55:59.378125Z'}
{'type': 'l2update', 'product_id': 'BTC-USD', 'changes': [['buy', '38293.12', '0.07000000']], 'time': '2021-05-20T03:55:59.382347Z'}
{'type': 'l2update', 'product_id': 'BTC-USD', 'changes': [['buy', '37476.89', '0.00000000']], 'time': '2021-05-20T03:55:59.383323Z'}
{'type': 'l2update', 'product_id': 'BTC-USD', 'changes': [['buy', '37475.72', '0.00000000']], 'time': '2021-05-20T03:55:59.383323Z'}
{'type': 'l2update', 'product_id': 'BTC-USD', 'changes': [['buy', '37471.32', '0.00000000']], 'time': '2021-05-20T03:55:59.383323Z'}
{'type': 'l2update', 'product_id': 'BTC-USD', 'changes': [['buy', '38300.00', '0.18000000']], 'time': '2021-05-20T03:55:59.386152Z'}
{'type': 'l2update', 'product_id': 'BTC-USD', 'changes': [['sell', '38315.20', '0.50000000']], 'time': '2021-05-20T03:55:59.388700Z'}
{'type': 'l2update', 'product_id': 'BTC-USD', 'changes': [['sell', '38474.69', '0.00000000']], 'time': '2021-05-20T03:55:59.389407Z'}
{'type': 'l2update', 'product_id': 'BTC-USD', 'changes': [['buy', '37469.35', '0.12740000']], 'time': '2021-05-20T03:55:59.391027Z'}
{'type': 'l2update', 'product_id': 'BTC-USD', 'changes': [['buy', '38293.12', '0.12000000']], 'time': '2021-05-20T03:55:59.395320Z'}
{'type': 'l2update', 'product_id': 'BTC-USD', 'changes': [['sell', '38461.52', '0.01000000']], 'time': '2021-05-20T03:55:59.402629Z'}
{'type': 'l2update', 'product_id': 'BTC-USD', 'changes': [['sell', '38329.56', '0.40400000']], 'time': '2021-05-20T03:55:59.402748Z'}
{'type': 'l2update', 'product_id': 'BTC-USD', 'changes': [['sell', '38315.14', '0.18981474']], 'time': '2021-05-20T03:55:59.406603Z'}
{'type': 'l2update', 'product_id': 'BTC-USD', 'changes': [['buy', '38275.32', '0.00000000']], 'time': '2021-05-20T03:55:59.410422Z'}
{'type': 'l2update', 'product_id': 'BTC-USD', 'changes': [['sell', '38461.52', '0.00000000']], 'time': '2021-05-20T03:55:59.410851Z'}
{'type': 'l2update', 'product_id': 'BTC-USD', 'changes': [['sell', '38412.81', '0.00000000']], 'time': '2021-05-20T03:55:59.417639Z'}
{'type': 'l2update', 'product_id': 'BTC-USD', 'changes': [['buy', '38288.50', '0.33200000']], 'time': '2021-05-20T03:55:59.419220Z'}
{'type': 'l2update', 'product_id': 'BTC-USD', 'changes': [['buy', '37510.00', '0.00000000']], 'time': '2021-05-20T03:55:59.420896Z'}
{'type': 'l2update', 'product_id': 'BTC-USD', 'changes': [['sell', '38474.69', '0.01000000']], 'time': '2021-05-20T03:55:59.423396Z'}
{'type': 'l2update', 'product_id': 'BTC-USD', 'changes': [['sell', '38429.07', '0.01000000']], 'time': '2021-05-20T03:55:59.427896Z'}
{'type': 'l2update', 'product_id': 'BTC-USD', 'changes': [['sell', '38474.69', '0.00000000']], 'time': '2021-05-20T03:55:59.436449Z'}
{'type': 'l2update', 'product_id': 'BTC-USD', 'changes': [['sell', '38461.52', '0.01000000']], 'time': '2021-05-20T03:55:59.451237Z'}
{'type': 'l2update', 'product_id': 'BTC-USD', 'changes': [['sell', '38461.52', '0.00000000']], 'time': '2021-05-20T03:55:59.463093Z'}
{'type': 'l2update', 'product_id': 'BTC-USD', 'changes': [['buy', '38297.55', '0.00000000']], 'time': '2021-05-20T03:55:59.469802Z'}
{'type': 'l2update', 'product_id': 'BTC-USD', 'changes': [['buy', '38306.67', '0.04272773']], 'time': '2021-05-20T03:55:59.476615Z'}
{'type': 'l2update', 'product_id': 'BTC-USD', 'changes': [['sell', '38474.69', '0.01000000']], 'time': '2021-05-20T03:55:59.476635Z'}
{'type': 'l2update', 'product_id': 'BTC-USD', 'changes': [['sell', '38349.05', '0.01303180']], 'time': '2021-05-20T03:55:59.497664Z'}
{'type': 'l2update', 'product_id': 'BTC-USD', 'changes': [['sell', '38605.75', '0.00000000']], 'time': '2021-05-20T03:55:59.516195Z'}
{'type': 'l2update', 'product_id': 'BTC-USD', 'changes': [['buy', '38306.66', '0.00543832']], 'time': '2021-05-20T03:55:59.518062Z'}
{'type': 'l2update', 'product_id': 'BTC-USD', 'changes': [['buy', '38263.31', '0.03698086']], 'time': '2021-05-20T03:55:59.542200Z'}
{'type': 'l2update', 'product_id': 'BTC-USD', 'changes': [['buy', '38294.42', '0.00000000']], 'time': '2021-05-20T03:55:59.624652Z'}
{'type': 'l2update', 'product_id': 'BTC-USD', 'changes': [['sell', '38398.25', '0.00000000']], 'time': '2021-05-20T03:55:59.633854Z'}
{'type': 'l2update', 'product_id': 'BTC-USD', 'changes': [['sell', '38634.85', '0.00000000']], 'time': '2021-05-20T03:55:59.636081Z'}
{'type': 'l2update', 'product_id': 'BTC-USD', 'changes': [['sell', '38593.70', '0.01000000']], 'time': '2021-05-20T03:55:59.641362Z'}
{'type': 'l2update', 'product_id': 'BTC-USD', 'changes': [['buy', '38283.73', '0.00000000']], 'time': '2021-05-20T03:55:59.688419Z'}
{'type': 'l2update', 'product_id': 'BTC-USD', 'changes': [['sell', '38307.84', '0.13135397']], 'time': '2021-05-20T03:55:59.688486Z'}
{'type': 'l2update', 'product_id': 'BTC-USD', 'changes': [['buy', '38253.52', '0.00000000']], 'time': '2021-05-20T03:55:59.689754Z'}
{'type': 'l2update', 'product_id': 'BTC-USD', 'changes': [['sell', '38306.68', '0.04046054']], 'time': '2021-05-20T03:55:59.735572Z'}
{'type': 'l2update', 'product_id': 'BTC-USD', 'changes': [['buy', '38306.67', '0.24272773']], 'time': '2021-05-20T03:55:59.802355Z'}
{'type': 'l2update', 'product_id': 'BTC-USD', 'changes': [['sell', '38306.68', '0.07460000']], 'time': '2021-05-20T03:55:59.810752Z'}
{'type': 'l2update', 'product_id': 'BTC-USD', 'changes': [['sell', '38306.68', '0.08952000']], 'time': '2021-05-20T03:55:59.810787Z'}
{'type': 'l2update', 'product_id': 'BTC-USD', 'changes': [['sell', '38330.94', '0.00000000']], 'time': '2021-05-20T03:55:59.824174Z'}
{'type': 'l2update', 'product_id': 'BTC-USD', 'changes': [['buy', '38289.07', '0.00000000']], 'time': '2021-05-20T03:55:59.835756Z'}
{'type': 'l2update', 'product_id': 'BTC-USD', 'changes': [['buy', '38306.66', '0.00367349']], 'time': '2021-05-20T03:55:59.866989Z'}
{'type': 'l2update', 'product_id': 'BTC-USD', 'changes': [['sell', '38361.66', '0.05018696']], 'time': '2021-05-20T03:55:59.870641Z'}
{'type': 'l2update', 'product_id': 'BTC-USD', 'changes': [['sell', '38377.24', '0.12860000']], 'time': '2021-05-20T03:55:59.877135Z'}
{'type': 'l2update', 'product_id': 'BTC-USD', 'changes': [['buy', '38286.64', '0.00000000']], 'time': '2021-05-20T03:55:59.971880Z'}
{'type': 'l2update', 'product_id': 'BTC-USD', 'changes': [['buy', '38285.83', '0.00000000']], 'time': '2021-05-20T03:55:59.971880Z'}
{'type': 'l2update', 'product_id': 'BTC-USD', 'changes': [['buy', '38285.03', '0.00000000']], 'time': '2021-05-20T03:55:59.971880Z'}
{'type': 'l2update', 'product_id': 'BTC-USD', 'changes': [['buy', '38293.86', '0.00000000']], 'time': '2021-05-20T03:55:59.979953Z'}
{'type': 'l2update', 'product_id': 'BTC-USD', 'changes': [['sell', '38329.56', '0.00000000']], 'time': '2021-05-20T03:55:59.986708Z'}
{'type': 'l2update', 'product_id': 'BTC-USD', 'changes': [['sell', '38619.76', '0.01042688']], 'time': '2021-05-20T03:55:59.990803Z'}
{'type': 'l2update', 'product_id': 'BTC-USD', 'changes': [['buy', '37502.33', '0.06895731']], 'time': '2021-05-20T03:55:59.991474Z'}
{'type': 'l2update', 'product_id': 'BTC-USD', 'changes': [['sell', '38307.84', '0.11310626']], 'time': '2021-05-20T03:55:59.992271Z'}
{'type': 'l2update', 'product_id': 'BTC-USD', 'changes': [['sell', '38308.27', '0.00000000']], 'time': '2021-05-20T03:55:59.995843Z'}
{'type': 'l2update', 'product_id': 'BTC-USD', 'changes': [['buy', '38251.52', '0.10000000']], 'time': '2021-05-20T03:55:59.997267Z'}
{'type': 'l2update', 'product_id': 'BTC-USD', 'changes': [['sell', '38306.68', '0.07460000']], 'time': '2021-05-20T03:55:59.997395Z'}
{'type': 'l2update', 'product_id': 'BTC-USD', 'changes': [['sell', '38429.07', '0.00000000']], 'time': '2021-05-20T03:55:59.998501Z'}
{'type': 'l2update', 'product_id': 'BTC-USD', 'changes': [['buy', '38142.09', '0.05110584']], 'time': '2021-05-20T03:56:00.000549Z'}
{'type': 'l2update', 'product_id': 'BTC-USD', 'changes': [['buy', '38298.26', '0.04869064']], 'time': '2021-05-20T03:56:00.000646Z'}
{'type': 'l2update', 'product_id': 'BTC-USD', 'changes': [['buy', '38289.63', '0.19300000']], 'time': '2021-05-20T03:56:00.000853Z'}
{'type': 'l2update', 'product_id': 'BTC-USD', 'changes': [['buy', '38306.67', '0.34272773']], 'time': '2021-05-20T03:56:00.009649Z'}
{'type': 'l2update', 'product_id': 'BTC-USD', 'changes': [['buy', '38295.21', '0.99440510']], 'time': '2021-05-20T03:56:00.009858Z'}
{'type': 'l2update', 'product_id': 'BTC-USD', 'changes': [['buy', '35000.00', '210.96219861']], 'time': '2021-05-20T03:56:00.026914Z'}
{'type': 'l2update', 'product_id': 'BTC-USD', 'changes': [['buy', '38306.66', '0.00543832']], 'time': '2021-05-20T03:56:00.041493Z'}
{'type': 'l2update', 'product_id': 'BTC-USD', 'changes': [['sell', '38346.85', '0.00000000']], 'time': '2021-05-20T03:56:00.105356Z'}
{'type': 'l2update', 'product_id': 'BTC-USD', 'changes': [['buy', '38263.31', '1.23698086']], 'time': '2021-05-20T03:56:00.140081Z'}
{'type': 'l2update', 'product_id': 'BTC-USD', 'changes': [['buy', '38190.00', '0.19720000']], 'time': '2021-05-20T03:56:00.143852Z'}
{'type': 'l2update', 'product_id': 'BTC-USD', 'changes': [['sell', '38315.23', '0.00000000']], 'time': '2021-05-20T03:56:00.150382Z'}
{'type': 'l2update', 'product_id': 'BTC-USD', 'changes': [['sell', '38348.14', '0.00000000']], 'time': '2021-05-20T03:56:00.157665Z'}
{'type': 'l2update', 'product_id': 'BTC-USD', 'changes': [['sell', '38433.26', '0.39303419']], 'time': '2021-05-20T03:56:00.158295Z'}
{'type': 'l2update', 'product_id': 'BTC-USD', 'changes': [['sell', '38317.60', '0.00000000']], 'time': '2021-05-20T03:56:00.159284Z'}
{'type': 'l2update', 'product_id': 'BTC-USD', 'changes': [['buy', '38302.17', '0.04983633']], 'time': '2021-05-20T03:56:00.168983Z'}
{'type': 'l2update', 'product_id': 'BTC-USD', 'changes': [['buy', '38224.50', '0.07800000']], 'time': '2021-05-20T03:56:00.169752Z'}
{'type': 'l2update', 'product_id': 'BTC-USD', 'changes': [['sell', '38416.87', '0.01000000']], 'time': '2021-05-20T03:56:00.170066Z'}
{'type': 'l2update', 'product_id': 'BTC-USD', 'changes': [['sell', '38455.05', '0.00000000']], 'time': '2021-05-20T03:56:00.170834Z'}
{'type': 'l2update', 'product_id': 'BTC-USD', 'changes': [['sell', '38315.15', '0.00000000']], 'time': '2021-05-20T03:56:00.179220Z'}
{'type': 'l2update', 'product_id': 'BTC-USD', 'changes': [['sell', '38315.21', '0.00000000']], 'time': '2021-05-20T03:56:00.179854Z'}
{'type': 'l2update', 'product_id': 'BTC-USD', 'changes': [['sell', '38331.73', '0.00000000']], 'time': '2021-05-20T03:56:00.181793Z'}
{'type': 'l2update', 'product_id': 'BTC-USD', 'changes': [['sell', '38315.20', '0.00000000']], 'time': '2021-05-20T03:56:00.187208Z'}
{'type': 'l2update', 'product_id': 'BTC-USD', 'changes': [['buy', '38300.05', '0.84700000']], 'time': '2021-05-20T03:56:00.187226Z'}
{'type': 'l2update', 'product_id': 'BTC-USD', 'changes': [['buy', '38135.91', '0.00000000']], 'time': '2021-05-20T03:56:00.189352Z'}
{'type': 'l2update', 'product_id': 'BTC-USD', 'changes': [['buy', '38306.67', '0.40272773']], 'time': '2021-05-20T03:56:00.233993Z'}
{'type': 'l2update', 'product_id': 'BTC-USD', 'changes': [['sell', '38306.68', '0.07398978']], 'time': '2021-05-20T03:56:00.261976Z'}
{'type': 'l2update', 'product_id': 'BTC-USD', 'changes': [['sell', '38346.00', '0.00000000']], 'time': '2021-05-20T03:56:00.330047Z'}
{'type': 'l2update', 'product_id': 'BTC-USD', 'changes': [['sell', '38474.69', '0.00000000']], 'time': '2021-05-20T03:56:00.347877Z'}
{'type': 'l2update', 'product_id': 'BTC-USD', 'changes': [['buy', '38251.52', '0.00000000']], 'time': '2021-05-20T03:56:00.363793Z'}
{'type': 'l2update', 'product_id': 'BTC-USD', 'changes': [['sell', '38317.31', '0.00000000']], 'time': '2021-05-20T03:56:00.375219Z'}
{'type': 'l2update', 'product_id': 'BTC-USD', 'changes': [['buy', '38293.12', '0.09000000']], 'time': '2021-05-20T03:56:00.375544Z'}
{'type': 'l2update', 'product_id': 'BTC-USD', 'changes': [['buy', '38224.50', '0.00000000']], 'time': '2021-05-20T03:56:00.376381Z'}
{'type': 'l2update', 'product_id': 'BTC-USD', 'changes': [['sell', '38339.65', '0.00000000']], 'time': '2021-05-20T03:56:00.376442Z'}
{'type': 'l2update', 'product_id': 'BTC-USD', 'changes': [['sell', '38593.70', '0.00000000']], 'time': '2021-05-20T03:56:00.377139Z'}
{'type': 'l2update', 'product_id': 'BTC-USD', 'changes': [['sell', '38518.17', '0.00000000']], 'time': '2021-05-20T03:56:00.377509Z'}
{'type': 'l2update', 'product_id': 'BTC-USD', 'changes': [['buy', '38295.21', '0.00000000']], 'time': '2021-05-20T03:56:00.379061Z'}
{'type': 'l2update', 'product_id': 'BTC-USD', 'changes': [['buy', '38263.65', '0.00000000']], 'time': '2021-05-20T03:56:00.380006Z'}
{'type': 'l2update', 'product_id': 'BTC-USD', 'changes': [['buy', '38298.26', '0.00000000']], 'time': '2021-05-20T03:56:00.393930Z'}
{'type': 'l2update', 'product_id': 'BTC-USD', 'changes': [['buy', '38283.45', '0.00000000']], 'time': '2021-05-20T03:56:00.396395Z'}
{'type': 'l2update', 'product_id': 'BTC-USD', 'changes': [['buy', '38298.31', '0.52100000']], 'time': '2021-05-20T03:56:00.398514Z'}
{'type': 'l2update', 'product_id': 'BTC-USD', 'changes': [['buy', '38149.03', '0.05063272']], 'time': '2021-05-20T03:56:00.399163Z'}
{'type': 'l2update', 'product_id': 'BTC-USD', 'changes': [['sell', '38346.94', '0.05131161']], 'time': '2021-05-20T03:56:00.399772Z'}
{'type': 'l2update', 'product_id': 'BTC-USD', 'changes': [['sell', '38326.47', '0.55400000']], 'time': '2021-05-20T03:56:00.400547Z'}
{'type': 'l2update', 'product_id': 'BTC-USD', 'changes': [['sell', '38326.51', '0.50000000']], 'time': '2021-05-20T03:56:00.400693Z'}
{'type': 'l2update', 'product_id': 'BTC-USD', 'changes': [['buy', '38279.01', '0.39490431']], 'time': '2021-05-20T03:56:00.400821Z'}
{'type': 'l2update', 'product_id': 'BTC-USD', 'changes': [['sell', '38435.64', '0.01248234']], 'time': '2021-05-20T03:56:00.400988Z'}
{'type': 'l2update', 'product_id': 'BTC-USD', 'changes': [['sell', '38398.25', '1.20000000']], 'time': '2021-05-20T03:56:00.400998Z'}
{'type': 'l2update', 'product_id': 'BTC-USD', 'changes': [['sell', '38375.22', '0.19200000']], 'time': '2021-05-20T03:56:00.401603Z'}
{'type': 'l2update', 'product_id': 'BTC-USD', 'changes': [['sell', '38306.68', '0.07149387']], 'time': '2021-05-20T03:56:00.401907Z'}
{'type': 'l2update', 'product_id': 'BTC-USD', 'changes': [['buy', '38306.67', '0.40845773']], 'time': '2021-05-20T03:56:00.408577Z'}
{'type': 'l2update', 'product_id': 'BTC-USD', 'changes': [['buy', '37510.50', '0.00000000']], 'time': '2021-05-20T03:56:00.418120Z'}
{'type': 'l2update', 'product_id': 'BTC-USD', 'changes': [['sell', '38306.68', '0.07088367']], 'time': '2021-05-20T03:56:00.425370Z'}
{'type': 'l2update', 'product_id': 'BTC-USD', 'changes': [['buy', '38225.73', '0.00000000']], 'time': '2021-05-20T03:56:00.441732Z'}
{'type': 'l2update', 'product_id': 'BTC-USD', 'changes': [['sell', '38580.00', '1.19720000']], 'time': '2021-05-20T03:56:00.472702Z'}
{'type': 'l2update', 'product_id': 'BTC-USD', 'changes': [['buy', '38294.30', '0.52200000']], 'time': '2021-05-20T03:56:00.487351Z'}
{'type': 'l2update', 'product_id': 'BTC-USD', 'changes': [['buy', '38259.52', '0.10000000']], 'time': '2021-05-20T03:56:00.491406Z'}
{'type': 'l2update', 'product_id': 'BTC-USD', 'changes': [['sell', '38461.52', '0.01000000']], 'time': '2021-05-20T03:56:00.494866Z'}
{'type': 'l2update', 'product_id': 'BTC-USD', 'changes': [['buy', '38290.59', '0.45910000']], 'time': '2021-05-20T03:56:00.516093Z'}
{'type': 'l2update', 'product_id': 'BTC-USD', 'changes': [['buy', '38293.12', '0.05000000']], 'time': '2021-05-20T03:56:00.539609Z'}
{'type': 'l2update', 'product_id': 'BTC-USD', 'changes': [['sell', '38306.68', '0.03413946']], 'time': '2021-05-20T03:56:00.540962Z'}
{'type': 'l2update', 'product_id': 'BTC-USD', 'changes': [['sell', '38306.68', '0.00000000']], 'time': '2021-05-20T03:56:00.540962Z'}
{'type': 'l2update', 'product_id': 'BTC-USD', 'changes': [['sell', '38349.76', '0.00000000']], 'time': '2021-05-20T03:56:00.541235Z'}
{'type': 'l2update', 'product_id': 'BTC-USD', 'changes': [['sell', '38317.27', '0.04871429']], 'time': '2021-05-20T03:56:00.546815Z'}
{'type': 'l2update', 'product_id': 'BTC-USD', 'changes': [['sell', '38593.70', '0.01000000']], 'time': '2021-05-20T03:56:00.547021Z'}
{'type': 'l2update', 'product_id': 'BTC-USD', 'changes': [['sell', '38499.89', '0.01000000']], 'time': '2021-05-20T03:56:00.551563Z'}
{'type': 'l2update', 'product_id': 'BTC-USD', 'changes': [['sell', '38375.48', '0.02605831']], 'time': '2021-05-20T03:56:00.551629Z'}
{'type': 'l2update', 'product_id': 'BTC-USD', 'changes': [['sell', '38326.51', '2.98969908']], 'time': '2021-05-20T03:56:00.551902Z'}
{'type': 'l2update', 'product_id': 'BTC-USD', 'changes': [['sell', '38483.22', '0.00000000']], 'time': '2021-05-20T03:56:00.584136Z'}
{'type': 'l2update', 'product_id': 'BTC-USD', 'changes': [['sell', '38307.84', '0.11249606']], 'time': '2021-05-20T03:56:00.588310Z'}
{'type': 'l2update', 'product_id': 'BTC-USD', 'changes': [['buy', '38295.47', '0.00000000']], 'time': '2021-05-20T03:56:00.594337Z'}
{'type': 'l2update', 'product_id': 'BTC-USD', 'changes': [['buy', '37654.91', '0.00000000']], 'time': '2021-05-20T03:56:00.595924Z'}
{'type': 'l2update', 'product_id': 'BTC-USD', 'changes': [['buy', '37469.35', '0.06310000']], 'time': '2021-05-20T03:56:00.595924Z'}
{'type': 'l2update', 'product_id': 'BTC-USD', 'changes': [['sell', '39495.99', '0.05890000']], 'time': '2021-05-20T03:56:00.595924Z'}
{'type': 'l2update', 'product_id': 'BTC-USD', 'changes': [['sell', '38446.83', '0.00000000']], 'time': '2021-05-20T03:56:00.596690Z'}
{'type': 'l2update', 'product_id': 'BTC-USD', 'changes': [['sell', '38341.20', '0.42430000']], 'time': '2021-05-20T03:56:00.603500Z'}
{'type': 'l2update', 'product_id': 'BTC-USD', 'changes': [['buy', '38306.68', '0.00573000']], 'time': '2021-05-20T03:56:00.603658Z'}
{'type': 'l2update', 'product_id': 'BTC-USD', 'changes': [['buy', '38283.37', '0.52230457']], 'time': '2021-05-20T03:56:00.606577Z'}
{'type': 'l2update', 'product_id': 'BTC-USD', 'changes': [['buy', '38306.68', '0.08033000']], 'time': '2021-05-20T03:56:00.611003Z'}
{'type': 'l2update', 'product_id': 'BTC-USD', 'changes': [['buy', '38306.66', '0.00367349']], 'time': '2021-05-20T03:56:00.660390Z'}
{'type': 'l2update', 'product_id': 'BTC-USD', 'changes': [['buy', '38276.06', '0.00000000']], 'time': '2021-05-20T03:56:00.677690Z'}
{'type': 'l2update', 'product_id': 'BTC-USD', 'changes': [['buy', '38293.12', '0.00000000']], 'time': '2021-05-20T03:56:00.678290Z'}
{'type': 'l2update', 'product_id': 'BTC-USD', 'changes': [['buy', '38267.00', '0.00000000']], 'time': '2021-05-20T03:56:00.678637Z'}
{'type': 'l2update', 'product_id': 'BTC-USD', 'changes': [['sell', '38328.95', '0.00000000']], 'time': '2021-05-20T03:56:00.679492Z'}
{'type': 'l2update', 'product_id': 'BTC-USD', 'changes': [['buy', '38307.83', '0.04046054']], 'time': '2021-05-20T03:56:00.682853Z'}
{'type': 'l2update', 'product_id': 'BTC-USD', 'changes': [['buy', '38307.83', '0.04361139']], 'time': '2021-05-20T03:56:00.683004Z'}
{'type': 'l2update', 'product_id': 'BTC-USD', 'changes': [['buy', '38307.83', '0.08691139']], 'time': '2021-05-20T03:56:00.683161Z'}
{'type': 'l2update', 'product_id': 'BTC-USD', 'changes': [['buy', '37540.54', '0.00125709']], 'time': '2021-05-20T03:56:00.683598Z'}
{'type': 'l2update', 'product_id': 'BTC-USD', 'changes': [['buy', '38307.83', '0.09868054']], 'time': '2021-05-20T03:56:00.685680Z'}
{'type': 'l2update', 'product_id': 'BTC-USD', 'changes': [['buy', '37500.01', '0.06420000']], 'time': '2021-05-20T03:56:00.686729Z'}
{'type': 'l2update', 'product_id': 'BTC-USD', 'changes': [['sell', '39399.99', '0.04740000']], 'time': '2021-05-20T03:56:00.686729Z'}
{'type': 'l2update', 'product_id': 'BTC-USD', 'changes': [['buy', '37500.02', '0.00790000']], 'time': '2021-05-20T03:56:00.686729Z'}
{'type': 'l2update', 'product_id': 'BTC-USD', 'changes': [['buy', '38155.21', '0.04983131']], 'time': '2021-05-20T03:56:00.686780Z'}
{'type': 'l2update', 'product_id': 'BTC-USD', 'changes': [['buy', '38307.83', '0.13282000']], 'time': '2021-05-20T03:56:00.693238Z'}
{'type': 'l2update', 'product_id': 'BTC-USD', 'changes': [['sell', '38348.93', '0.01000000']], 'time': '2021-05-20T03:56:00.724778Z'}
{'type': 'l2update', 'product_id': 'BTC-USD', 'changes': [['buy', '38290.59', '0.00000000']], 'time': '2021-05-20T03:56:00.764388Z'}
{'type': 'l2update', 'product_id': 'BTC-USD', 'changes': [['buy', '38306.67', '0.40272773']], 'time': '2021-05-20T03:56:00.765815Z'}
{'type': 'l2update', 'product_id': 'BTC-USD', 'changes': [['sell', '38333.63', '0.00000000']], 'time': '2021-05-20T03:56:00.766703Z'}
{'type': 'l2update', 'product_id': 'BTC-USD', 'changes': [['buy', '38306.43', '0.04840289']], 'time': '2021-05-20T03:56:00.772670Z'}
{'type': 'l2update', 'product_id': 'BTC-USD', 'changes': [['buy', '38307.83', '0.23282000']], 'time': '2021-05-20T03:56:00.772747Z'}
{'type': 'l2update', 'product_id': 'BTC-USD', 'changes': [['buy', '38302.18', '0.99440510']], 'time': '2021-05-20T03:56:00.781623Z'}
{'type': 'l2update', 'product_id': 'BTC-USD', 'changes': [['sell', '38467.39', '0.01000000']], 'time': '2021-05-20T03:56:00.785855Z'}
{'type': 'l2update', 'product_id': 'BTC-USD', 'changes': [['buy', '38241.64', '1.66480000']], 'time': '2021-05-20T03:56:00.791127Z'}
{'type': 'l2update', 'product_id': 'BTC-USD', 'changes': [['buy', '38306.66', '0.00543852']], 'time': '2021-05-20T03:56:00.815706Z'}
{'type': 'l2update', 'product_id': 'BTC-USD', 'changes': [['sell', '38593.70', '0.00000000']], 'time': '2021-05-20T03:56:00.818912Z'}
{'type': 'l2update', 'product_id': 'BTC-USD', 'changes': [['sell', '38341.20', '0.00000000']], 'time': '2021-05-20T03:56:00.821106Z'}
{'type': 'l2update', 'product_id': 'BTC-USD', 'changes': [['buy', '38142.09', '0.00000000']], 'time': '2021-05-20T03:56:00.821342Z'}
{'type': 'l2update', 'product_id': 'BTC-USD', 'changes': [['sell', '38336.72', '0.00000000']], 'time': '2021-05-20T03:56:00.821533Z'}
{'type': 'l2update', 'product_id': 'BTC-USD', 'changes': [['sell', '38315.14', '0.00000000']], 'time': '2021-05-20T03:56:00.821640Z'}
{'type': 'l2update', 'product_id': 'BTC-USD', 'changes': [['buy', '38266.57', '0.01000000']], 'time': '2021-05-20T03:56:00.829530Z'}
{'type': 'l2update', 'product_id': 'BTC-USD', 'changes': [['buy', '38302.22', '0.84700000']], 'time': '2021-05-20T03:56:00.829919Z'}
{'type': 'l2update', 'product_id': 'BTC-USD', 'changes': [['buy', '38306.67', '0.41272773']], 'time': '2021-05-20T03:56:00.830114Z'}
{'type': 'l2update', 'product_id': 'BTC-USD', 'changes': [['buy', '38302.18', '0.00000000']], 'time': '2021-05-20T03:56:00.867808Z'}
{'type': 'l2update', 'product_id': 'BTC-USD', 'changes': [['sell', '38619.76', '0.00000000']], 'time': '2021-05-20T03:56:00.868122Z'}
{'type': 'l2update', 'product_id': 'BTC-USD', 'changes': [['sell', '38461.52', '0.00000000']], 'time': '2021-05-20T03:56:00.869959Z'}
{'type': 'l2update', 'product_id': 'BTC-USD', 'changes': [['sell', '38412.73', '0.00000000']], 'time': '2021-05-20T03:56:00.870273Z'}
{'type': 'l2update', 'product_id': 'BTC-USD', 'changes': [['sell', '38346.94', '0.00000000']], 'time': '2021-05-20T03:56:00.870687Z'}
{'type': 'l2update', 'product_id': 'BTC-USD', 'changes': [['sell', '38429.02', '0.00000000']], 'time': '2021-05-20T03:56:00.877564Z'}
{'type': 'l2update', 'product_id': 'BTC-USD', 'changes': [['buy', '38307.83', '0.43282000']], 'time': '2021-05-20T03:56:00.878964Z'}
{'type': 'l2update', 'product_id': 'BTC-USD', 'changes': [['buy', '38307.83', '0.43855000']], 'time': '2021-05-20T03:56:00.879617Z'}
{'type': 'l2update', 'product_id': 'BTC-USD', 'changes': [['buy', '38242.24', '0.01000000']], 'time': '2021-05-20T03:56:00.880755Z'}
{'type': 'l2update', 'product_id': 'BTC-USD', 'changes': [['sell', '38459.59', '0.01213586']], 'time': '2021-05-20T03:56:00.880815Z'}
{'type': 'l2update', 'product_id': 'BTC-USD', 'changes': [['sell', '38333.94', '0.05000000']], 'time': '2021-05-20T03:56:00.881239Z'}
{'type': 'l2update', 'product_id': 'BTC-USD', 'changes': [['sell', '38363.76', '0.50000000']], 'time': '2021-05-20T03:56:00.881695Z'}
{'type': 'l2update', 'product_id': 'BTC-USD', 'changes': [['buy', '38155.21', '0.00000000']], 'time': '2021-05-20T03:56:00.882212Z'}
{'type': 'l2update', 'product_id': 'BTC-USD', 'changes': [['buy', '38298.31', '0.00000000']], 'time': '2021-05-20T03:56:00.882652Z'}
{'type': 'l2update', 'product_id': 'BTC-USD', 'changes': [['buy', '38306.67', '0.43272773']], 'time': '2021-05-20T03:56:00.889495Z'}
{'type': 'l2update', 'product_id': 'BTC-USD', 'changes': [['sell', '38342.12', '0.10000000']], 'time': '2021-05-20T03:56:00.889599Z'}
{'type': 'l2update', 'product_id': 'BTC-USD', 'changes': [['buy', '38300.06', '0.40135082']], 'time': '2021-05-20T03:56:00.889786Z'}
{'type': 'l2update', 'product_id': 'BTC-USD', 'changes': [['buy', '38149.03', '0.00000000']], 'time': '2021-05-20T03:56:00.891353Z'}
{'type': 'l2update', 'product_id': 'BTC-USD', 'changes': [['buy', '38280.20', '0.78320324']], 'time': '2021-05-20T03:56:00.895635Z'}
{'type': 'l2update', 'product_id': 'BTC-USD', 'changes': [['sell', '38317.26', '0.00000000']], 'time': '2021-05-20T03:56:00.898473Z'}
{'type': 'l2update', 'product_id': 'BTC-USD', 'changes': [['buy', '38306.67', '0.23272773']], 'time': '2021-05-20T03:56:00.898509Z'}
{'type': 'l2update', 'product_id': 'BTC-USD', 'changes': [['sell', '38604.68', '0.01295179']], 'time': '2021-05-20T03:56:00.900871Z'}
{'type': 'l2update', 'product_id': 'BTC-USD', 'changes': [['buy', '38288.51', '0.02355511']], 'time': '2021-05-20T03:56:00.900904Z'}
{'type': 'l2update', 'product_id': 'BTC-USD', 'changes': [['sell', '38424.94', '0.06578391']], 'time': '2021-05-20T03:56:00.901211Z'}
{'type': 'l2update', 'product_id': 'BTC-USD', 'changes': [['sell', '38474.69', '0.01000000']], 'time': '2021-05-20T03:56:00.901402Z'}
{'type': 'l2update', 'product_id': 'BTC-USD', 'changes': [['buy', '38307.83', '1.08855000']], 'time': '2021-05-20T03:56:00.902040Z'}
{'type': 'l2update', 'product_id': 'BTC-USD', 'changes': [['buy', '38295.47', '0.99440510']], 'time': '2021-05-20T03:56:00.902208Z'}
{'type': 'l2update', 'product_id': 'BTC-USD', 'changes': [['buy', '38306.68', '0.07460000']], 'time': '2021-05-20T03:56:00.904518Z'}
{'type': 'l2update', 'product_id': 'BTC-USD', 'changes': [['sell', '38451.64', '0.01166672']], 'time': '2021-05-20T03:56:00.907349Z'}
{'type': 'l2update', 'product_id': 'BTC-USD', 'changes': [['sell', '38348.93', '0.00000000']], 'time': '2021-05-20T03:56:00.909889Z'}
{'type': 'l2update', 'product_id': 'BTC-USD', 'changes': [['sell', '39090.90', '0.00000000']], 'time': '2021-05-20T03:56:00.914731Z'}
{'type': 'l2update', 'product_id': 'BTC-USD', 'changes': [['sell', '38341.91', '0.00000000']], 'time': '2021-05-20T03:56:00.916322Z'}
{'type': 'l2update', 'product_id': 'BTC-USD', 'changes': [['buy', '38306.67', '0.13272773']], 'time': '2021-05-20T03:56:00.924830Z'}
{'type': 'l2update', 'product_id': 'BTC-USD', 'changes': [['sell', '38314.67', '0.52227170']], 'time': '2021-05-20T03:56:00.926248Z'}
{'type': 'l2update', 'product_id': 'BTC-USD', 'changes': [['buy', '38300.05', '0.00000000']], 'time': '2021-05-20T03:56:00.928596Z'}
{'type': 'l2update', 'product_id': 'BTC-USD', 'changes': [['buy', '38276.81', '0.00000000']], 'time': '2021-05-20T03:56:00.932069Z'}
{'type': 'l2update', 'product_id': 'BTC-USD', 'changes': [['buy', '38266.57', '0.00000000']], 'time': '2021-05-20T03:56:00.935715Z'}
{'type': 'l2update', 'product_id': 'BTC-USD', 'changes': [['buy', '38302.22', '0.00000000']], 'time': '2021-05-20T03:56:00.957490Z'}
{'type': 'l2update', 'product_id': 'BTC-USD', 'changes': [['sell', '38307.84', '0.00009606']], 'time': '2021-05-20T03:56:00.966026Z'}
{'type': 'l2update', 'product_id': 'BTC-USD', 'changes': [['sell', '38349.42', '0.04000000']], 'time': '2021-05-20T03:56:00.966041Z'}
{'type': 'l2update', 'product_id': 'BTC-USD', 'changes': [['sell', '38307.84', '0.00000000']], 'time': '2021-05-20T03:56:00.967672Z'}
{'type': 'l2update', 'product_id': 'BTC-USD', 'changes': [['sell', '38326.46', '0.18981474']], 'time': '2021-05-20T03:56:00.968252Z'}
{'type': 'l2update', 'product_id': 'BTC-USD', 'changes': [['buy', '38292.56', '0.52100000']], 'time': '2021-05-20T03:56:00.968650Z'}
{'type': 'l2update', 'product_id': 'BTC-USD', 'changes': [['buy', '37500.01', '0.06430000']], 'time': '2021-05-20T03:56:00.969041Z'}
{'type': 'l2update', 'product_id': 'BTC-USD', 'changes': [['buy', '37502.33', '0.00000000']], 'time': '2021-05-20T03:56:00.970154Z'}
{'type': 'l2update', 'product_id': 'BTC-USD', 'changes': [['buy', '38287.64', '0.41480000']], 'time': '2021-05-20T03:56:00.971688Z'}
{'type': 'l2update', 'product_id': 'BTC-USD', 'changes': [['buy', '38274.82', '0.78331682']], 'time': '2021-05-20T03:56:00.971731Z'}
{'type': 'l2update', 'product_id': 'BTC-USD', 'changes': [['buy', '38300.06', '0.00000000']], 'time': '2021-05-20T03:56:00.972468Z'}
{'type': 'l2update', 'product_id': 'BTC-USD', 'changes': [['sell', '38348.80', '0.00000000']], 'time': '2021-05-20T03:56:00.976253Z'}
{'type': 'l2update', 'product_id': 'BTC-USD', 'changes': [['sell', '38581.82', '0.00000000']], 'time': '2021-05-20T03:56:00.978129Z'}
{'type': 'l2update', 'product_id': 'BTC-USD', 'changes': [['buy', '38302.17', '0.00000000']], 'time': '2021-05-20T03:56:00.980512Z'}
{'type': 'l2update', 'product_id': 'BTC-USD', 'changes': [['buy', '38307.83', '1.05441054']], 'time': '2021-05-20T03:56:00.980984Z'}
{'type': 'l2update', 'product_id': 'BTC-USD', 'changes': [['buy', '38307.83', '1.01395000']], 'time': '2021-05-20T03:56:00.982126Z'}
{'type': 'l2update', 'product_id': 'BTC-USD', 'changes': [['buy', '38307.83', '1.00218085']], 'time': '2021-05-20T03:56:00.982341Z'}
{'type': 'l2update', 'product_id': 'BTC-USD', 'changes': [['buy', '38307.83', '0.99903000']], 'time': '2021-05-20T03:56:00.983521Z'}
{'type': 'l2update', 'product_id': 'BTC-USD', 'changes': [['buy', '38307.84', '0.00573000']], 'time': '2021-05-20T03:56:00.987338Z'}
{'type': 'l2update', 'product_id': 'BTC-USD', 'changes': [['sell', '38317.27', '0.00000000']], 'time': '2021-05-20T03:56:00.988033Z'}
{'type': 'l2update', 'product_id': 'BTC-USD', 'changes': [['buy', '38295.46', '1.69500000']], 'time': '2021-05-20T03:56:00.990437Z'}
{'type': 'l2update', 'product_id': 'BTC-USD', 'changes': [['sell', '38326.46', '0.74281474']], 'time': '2021-05-20T03:56:00.998519Z'}
{'type': 'l2update', 'product_id': 'BTC-USD', 'changes': [['sell', '38320.03', '0.78345501']], 'time': '2021-05-20T03:56:00.999302Z'}
{'type': 'l2update', 'product_id': 'BTC-USD', 'changes': [['sell', '38340.26', '0.48170000']], 'time': '2021-05-20T03:56:00.999556Z'}
{'type': 'l2update', 'product_id': 'BTC-USD', 'changes': [['buy', '38306.67', '0.16272773']], 'time': '2021-05-20T03:56:00.999575Z'}
{'type': 'l2update', 'product_id': 'BTC-USD', 'changes': [['buy', '38307.84', '0.65573000']], 'time': '2021-05-20T03:56:01.003214Z'}
{'type': 'l2update', 'product_id': 'BTC-USD', 'changes': [['sell', '38601.46', '0.03442500']], 'time': '2021-05-20T03:56:01.007223Z'}
{'type': 'l2update', 'product_id': 'BTC-USD', 'changes': [['buy', '38307.83', '0.99330000']], 'time': '2021-05-20T03:56:01.008586Z'}
{'type': 'l2update', 'product_id': 'BTC-USD', 'changes': [['buy', '38307.83', '0.89330000']], 'time': '2021-05-20T03:56:01.009629Z'}
{'type': 'l2update', 'product_id': 'BTC-USD', 'changes': [['buy', '38314.66', '0.07460000']], 'time': '2021-05-20T03:56:01.018039Z'}
{'type': 'l2update', 'product_id': 'BTC-USD', 'changes': [['buy', '38263.31', '0.03698086']], 'time': '2021-05-20T03:56:01.021392Z'}
{'type': 'l2update', 'product_id': 'BTC-USD', 'changes': [['buy', '38300.05', '0.84700000']], 'time': '2021-05-20T03:56:01.024202Z'}
{'type': 'l2update', 'product_id': 'BTC-USD', 'changes': [['buy', '38314.66', '0.07775085']], 'time': '2021-05-20T03:56:01.024293Z'}
{'type': 'l2update', 'product_id': 'BTC-USD', 'changes': [['sell', '38333.94', '0.00000000']], 'time': '2021-05-20T03:56:01.026007Z'}
{'type': 'l2update', 'product_id': 'BTC-USD', 'changes': [['buy', '38287.64', '0.00000000']], 'time': '2021-05-20T03:56:01.026242Z'}
{'type': 'l2update', 'product_id': 'BTC-USD', 'changes': [['buy', '38168.87', '0.00000000']], 'time': '2021-05-20T03:56:01.028083Z'}
{'type': 'l2update', 'product_id': 'BTC-USD', 'changes': [['buy', '38306.67', '0.20272773']], 'time': '2021-05-20T03:56:01.028491Z'}
{'type': 'l2update', 'product_id': 'BTC-USD', 'changes': [['buy', '38288.79', '0.05941468']], 'time': '2021-05-20T03:56:01.028660Z'}
{'type': 'l2update', 'product_id': 'BTC-USD', 'changes': [['sell', '38330.07', '0.05168181']], 'time': '2021-05-20T03:56:01.028660Z'}
{'type': 'l2update', 'product_id': 'BTC-USD', 'changes': [['buy', '38307.84', '0.65000000']], 'time': '2021-05-20T03:56:01.028759Z'}
{'type': 'l2update', 'product_id': 'BTC-USD', 'changes': [['sell', '38436.15', '0.00000000']], 'time': '2021-05-20T03:56:01.028966Z'}
{'type': 'l2update', 'product_id': 'BTC-USD', 'changes': [['buy', '38298.70', '0.02400000']], 'time': '2021-05-20T03:56:01.029046Z'}
{'type': 'l2update', 'product_id': 'BTC-USD', 'changes': [['buy', '38297.89', '0.02400000']], 'time': '2021-05-20T03:56:01.029046Z'}
{'type': 'l2update', 'product_id': 'BTC-USD', 'changes': [['buy', '38297.08', '0.02400000']], 'time': '2021-05-20T03:56:01.029046Z'}
{'type': 'l2update', 'product_id': 'BTC-USD', 'changes': [['buy', '38307.83', '0.69330000']], 'time': '2021-05-20T03:56:01.029667Z'}
{'type': 'l2update', 'product_id': 'BTC-USD', 'changes': [['sell', '38604.68', '0.00000000']], 'time': '2021-05-20T03:56:01.030475Z'}
{'type': 'l2update', 'product_id': 'BTC-USD', 'changes': [['buy', '38269.36', '0.78342947']], 'time': '2021-05-20T03:56:01.034404Z'}
{'type': 'l2update', 'product_id': 'BTC-USD', 'changes': [['buy', '38289.06', '0.00000000']], 'time': '2021-05-20T03:56:01.035885Z'}
{'type': 'l2update', 'product_id': 'BTC-USD', 'changes': [['buy', '38307.83', '0.65000000']], 'time': '2021-05-20T03:56:01.037680Z'}
{'type': 'l2update', 'product_id': 'BTC-USD', 'changes': [['sell', '38451.64', '0.00000000']], 'time': '2021-05-20T03:56:01.038272Z'}
{'type': 'l2update', 'product_id': 'BTC-USD', 'changes': [['sell', '38331.72', '0.00000000']], 'time': '2021-05-20T03:56:01.038377Z'}
{'type': 'l2update', 'product_id': 'BTC-USD', 'changes': [['buy', '38300.05', '1.36700000']], 'time': '2021-05-20T03:56:01.038635Z'}
{'type': 'l2update', 'product_id': 'BTC-USD', 'changes': [['buy', '38288.51', '0.00000000']], 'time': '2021-05-20T03:56:01.038882Z'}
{'type': 'l2update', 'product_id': 'BTC-USD', 'changes': [['sell', '38398.25', '0.00000000']], 'time': '2021-05-20T03:56:01.039790Z'}
{'type': 'l2update', 'product_id': 'BTC-USD', 'changes': [['buy', '38230.89', '0.07600000']], 'time': '2021-05-20T03:56:01.049757Z'}
{'type': 'l2update', 'product_id': 'BTC-USD', 'changes': [['sell', '38323.15', '0.05047853']], 'time': '2021-05-20T03:56:01.049912Z'}
{'type': 'l2update', 'product_id': 'BTC-USD', 'changes': [['sell', '38368.13', '2.54500000']], 'time': '2021-05-20T03:56:01.050119Z'}
{'type': 'l2update', 'product_id': 'BTC-USD', 'changes': [['buy', '38298.70', '0.00000000']], 'time': '2021-05-20T03:56:01.052400Z'}
{'type': 'l2update', 'product_id': 'BTC-USD', 'changes': [['buy', '38297.89', '0.00000000']], 'time': '2021-05-20T03:56:01.052400Z'}
{'type': 'l2update', 'product_id': 'BTC-USD', 'changes': [['buy', '38307.88', '0.84600000']], 'time': '2021-05-20T03:56:01.055060Z'}
{'type': 'l2update', 'product_id': 'BTC-USD', 'changes': [['buy', '38314.66', '0.72775085']], 'time': '2021-05-20T03:56:01.055083Z'}
{'type': 'l2update', 'product_id': 'BTC-USD', 'changes': [['buy', '38307.83', '0.00000000']], 'time': '2021-05-20T03:56:01.056786Z'}
{'type': 'l2update', 'product_id': 'BTC-USD', 'changes': [['buy', '38306.68', '0.00000000']], 'time': '2021-05-20T03:56:01.058571Z'}
{'type': 'l2update', 'product_id': 'BTC-USD', 'changes': [['buy', '38305.26', '0.20000000']], 'time': '2021-05-20T03:56:01.059186Z'}
{'type': 'l2update', 'product_id': 'BTC-USD', 'changes': [['buy', '38306.68', '0.05000000']], 'time': '2021-05-20T03:56:01.059675Z'}
{'type': 'l2update', 'product_id': 'BTC-USD', 'changes': [['sell', '38326.46', '0.55300000']], 'time': '2021-05-20T03:56:01.061044Z'}
{'type': 'l2update', 'product_id': 'BTC-USD', 'changes': [['sell', '38427.75', '0.00000000']], 'time': '2021-05-20T03:56:01.061809Z'}
{'type': 'l2update', 'product_id': 'BTC-USD', 'changes': [['sell', '38327.65', '1.30575834']], 'time': '2021-05-20T03:56:01.062060Z'}
{'type': 'l2update', 'product_id': 'BTC-USD', 'changes': [['buy', '38279.01', '0.00000000']], 'time': '2021-05-20T03:56:01.064159Z'}
{'type': 'l2update', 'product_id': 'BTC-USD', 'changes': [['sell', '38340.26', '0.00000000']], 'time': '2021-05-20T03:56:01.066463Z'}
{'type': 'l2update', 'product_id': 'BTC-USD', 'changes': [['sell', '38340.25', '0.05000000']], 'time': '2021-05-20T03:56:01.070903Z'}
{'type': 'l2update', 'product_id': 'BTC-USD', 'changes': [['sell', '38350.01', '0.42486504']], 'time': '2021-05-20T03:56:01.075024Z'}
{'type': 'l2update', 'product_id': 'BTC-USD', 'changes': [['buy', '38181.84', '0.03465000']], 'time': '2021-05-20T03:56:01.083592Z'}
{'type': 'l2update', 'product_id': 'BTC-USD', 'changes': [['sell', '38314.67', '0.51453554']], 'time': '2021-05-20T03:56:01.083731Z'}
{'type': 'l2update', 'product_id': 'BTC-USD', 'changes': [['sell', '38323.15', '0.00000000']], 'time': '2021-05-20T03:56:01.090145Z'}
{'type': 'l2update', 'product_id': 'BTC-USD', 'changes': [['sell', '38349.42', '0.05000000']], 'time': '2021-05-20T03:56:01.092956Z'}
{'type': 'l2update', 'product_id': 'BTC-USD', 'changes': [['sell', '38546.63', '0.01000000']], 'time': '2021-05-20T03:56:01.093854Z'}
{'type': 'l2update', 'product_id': 'BTC-USD', 'changes': [['buy', '38314.66', '0.92775085']], 'time': '2021-05-20T03:56:01.093952Z'}
{'type': 'l2update', 'product_id': 'BTC-USD', 'changes': [['sell', '38429.51', '0.01301083']], 'time': '2021-05-20T03:56:01.093972Z'}
{'type': 'l2update', 'product_id': 'BTC-USD', 'changes': [['sell', '38340.25', '0.00000000']], 'time': '2021-05-20T03:56:01.094905Z'}
{'type': 'l2update', 'product_id': 'BTC-USD', 'changes': [['sell', '38416.24', '0.01301533']], 'time': '2021-05-20T03:56:01.097604Z'}
{'type': 'l2update', 'product_id': 'BTC-USD', 'changes': [['buy', '38307.89', '0.40135082']], 'time': '2021-05-20T03:56:01.097759Z'}
{'type': 'l2update', 'product_id': 'BTC-USD', 'changes': [['buy', '38251.41', '2.61056238']], 'time': '2021-05-20T03:56:01.098242Z'}
{'type': 'l2update', 'product_id': 'BTC-USD', 'changes': [['sell', '38314.67', '0.45356480']], 'time': '2021-05-20T03:56:01.108774Z'}
{'type': 'l2update', 'product_id': 'BTC-USD', 'changes': [['buy', '38314.66', '0.98775085']], 'time': '2021-05-20T03:56:01.110135Z'}
{'type': 'l2update', 'product_id': 'BTC-USD', 'changes': [['sell', '38326.54', '0.00000000']], 'time': '2021-05-20T03:56:01.113164Z'}
{'type': 'l2update', 'product_id': 'BTC-USD', 'changes': [['sell', '38451.49', '0.00000000']], 'time': '2021-05-20T03:56:01.115784Z'}
{'type': 'l2update', 'product_id': 'BTC-USD', 'changes': [['sell', '38349.49', '0.05000000']], 'time': '2021-05-20T03:56:01.119767Z'}
{'type': 'l2update', 'product_id': 'BTC-USD', 'changes': [['sell', '38342.90', '0.05000000']], 'time': '2021-05-20T03:56:01.119877Z'}
{'type': 'l2update', 'product_id': 'BTC-USD', 'changes': [['buy', '38306.67', '0.16000000']], 'time': '2021-05-20T03:56:01.120036Z'}
{'type': 'l2update', 'product_id': 'BTC-USD', 'changes': [['sell', '38342.12', '0.00000000']], 'time': '2021-05-20T03:56:01.120280Z'}
{'type': 'l2update', 'product_id': 'BTC-USD', 'changes': [['buy', '38314.66', '1.08775085']], 'time': '2021-05-20T03:56:01.124508Z'}
{'type': 'l2update', 'product_id': 'BTC-USD', 'changes': [['sell', '38326.45', '0.18981474']], 'time': '2021-05-20T03:56:01.124560Z'}
{'type': 'l2update', 'product_id': 'BTC-USD', 'changes': [['sell', '38343.05', '0.05000000']], 'time': '2021-05-20T03:56:01.124833Z'}
{'type': 'l2update', 'product_id': 'BTC-USD', 'changes': [['buy', '38259.52', '0.00000000']], 'time': '2021-05-20T03:56:01.126618Z'}
{'type': 'l2update', 'product_id': 'BTC-USD', 'changes': [['sell', '38326.51', '0.50000000']], 'time': '2021-05-20T03:56:01.127452Z'}
{'type': 'l2update', 'product_id': 'BTC-USD', 'changes': [['sell', '38350.67', '0.10000000']], 'time': '2021-05-20T03:56:01.129225Z'}
{'type': 'l2update', 'product_id': 'BTC-USD', 'changes': [['buy', '38295.48', '0.02355511']], 'time': '2021-05-20T03:56:01.129449Z'}
{'type': 'l2update', 'product_id': 'BTC-USD', 'changes': [['buy', '38306.73', '0.52100000']], 'time': '2021-05-20T03:56:01.129718Z'}
{'type': 'l2update', 'product_id': 'BTC-USD', 'changes': [['sell', '38338.05', '2.61133555']], 'time': '2021-05-20T03:56:01.129871Z'}
{'type': 'l2update', 'product_id': 'BTC-USD', 'changes': [['sell', '38411.18', '0.01000000']], 'time': '2021-05-20T03:56:01.129929Z'}
{'type': 'l2update', 'product_id': 'BTC-USD', 'changes': [['buy', '38306.67', '0.10000000']], 'time': '2021-05-20T03:56:01.129968Z'}
{'type': 'l2update', 'product_id': 'BTC-USD', 'changes': [['sell', '38424.94', '0.00000000']], 'time': '2021-05-20T03:56:01.135405Z'}
{'type': 'l2update', 'product_id': 'BTC-USD', 'changes': [['buy', '38295.53', '0.02400000']], 'time': '2021-05-20T03:56:01.135588Z'}
{'type': 'l2update', 'product_id': 'BTC-USD', 'changes': [['buy', '38294.72', '0.02400000']], 'time': '2021-05-20T03:56:01.135588Z'}
{'type': 'l2update', 'product_id': 'BTC-USD', 'changes': [['buy', '38295.46', '0.84800000']], 'time': '2021-05-20T03:56:01.135692Z'}
{'type': 'l2update', 'product_id': 'BTC-USD', 'changes': [['sell', '38344.03', '0.02000000']], 'time': '2021-05-20T03:56:01.137891Z'}
{'type': 'l2update', 'product_id': 'BTC-USD', 'changes': [['buy', '38299.83', '0.40570000']], 'time': '2021-05-20T03:56:01.139266Z'}
{'type': 'l2update', 'product_id': 'BTC-USD', 'changes': [['buy', '37514.61', '0.06293083']], 'time': '2021-05-20T03:56:01.140228Z'}
{'type': 'l2update', 'product_id': 'BTC-USD', 'changes': [['sell', '38441.26', '0.40694795']], 'time': '2021-05-20T03:56:01.141076Z'}
{'type': 'l2update', 'product_id': 'BTC-USD', 'changes': [['sell', '38393.56', '0.00000000']], 'time': '2021-05-20T03:56:01.141648Z'}
{'type': 'l2update', 'product_id': 'BTC-USD', 'changes': [['buy', '38288.50', '0.00000000']], 'time': '2021-05-20T03:56:01.142808Z'}
{'type': 'l2update', 'product_id': 'BTC-USD', 'changes': [['sell', '38469.52', '0.01299730']], 'time': '2021-05-20T03:56:01.144437Z'}
{'type': 'l2update', 'product_id': 'BTC-USD', 'changes': [['sell', '38326.51', '0.00000000']], 'time': '2021-05-20T03:56:01.144492Z'}
{'type': 'l2update', 'product_id': 'BTC-USD', 'changes': [['buy', '38108.76', '0.00000000']], 'time': '2021-05-20T03:56:01.149445Z'}
{'type': 'l2update', 'product_id': 'BTC-USD', 'changes': [['buy', '38255.52', '0.10000000']], 'time': '2021-05-20T03:56:01.152379Z'}
{'type': 'l2update', 'product_id': 'BTC-USD', 'changes': [['sell', '38343.05', '0.00000000']], 'time': '2021-05-20T03:56:01.154297Z'}
{'type': 'l2update', 'product_id': 'BTC-USD', 'changes': [['sell', '38342.90', '0.00000000']], 'time': '2021-05-20T03:56:01.154539Z'}
{'type': 'l2update', 'product_id': 'BTC-USD', 'changes': [['sell', '38349.42', '0.01000000']], 'time': '2021-05-20T03:56:01.157515Z'}
{'type': 'l2update', 'product_id': 'BTC-USD', 'changes': [['sell', '38342.89', '2.48969908']], 'time': '2021-05-20T03:56:01.159152Z'}
{'type': 'l2update', 'product_id': 'BTC-USD', 'changes': [['sell', '38326.46', '0.00000000']], 'time': '2021-05-20T03:56:01.163069Z'}
{'type': 'l2update', 'product_id': 'BTC-USD', 'changes': [['buy', '38288.79', '0.00000000']], 'time': '2021-05-20T03:56:01.164750Z'}
{'type': 'l2update', 'product_id': 'BTC-USD', 'changes': [['sell', '38330.07', '0.00000000']], 'time': '2021-05-20T03:56:01.164750Z'}
{'type': 'l2update', 'product_id': 'BTC-USD', 'changes': [['sell', '38343.50', '0.00000000']], 'time': '2021-05-20T03:56:01.165002Z'}
{'type': 'l2update', 'product_id': 'BTC-USD', 'changes': [['buy', '38240.23', '2.61133555']], 'time': '2021-05-20T03:56:01.165160Z'}
{'type': 'l2update', 'product_id': 'BTC-USD', 'changes': [['sell', '38326.47', '0.00000000']], 'time': '2021-05-20T03:56:01.165835Z'}
{'type': 'l2update', 'product_id': 'BTC-USD', 'changes': [['buy', '38306.66', '0.00367349']], 'time': '2021-05-20T03:56:01.170326Z'}
{'type': 'l2update', 'product_id': 'BTC-USD', 'changes': [['sell', '38344.95', '0.07700000']], 'time': '2021-05-20T03:56:01.173252Z'}
{'type': 'l2update', 'product_id': 'BTC-USD', 'changes': [['sell', '38314.67', '0.15356480']], 'time': '2021-05-20T03:56:01.173437Z'}
{'type': 'l2update', 'product_id': 'BTC-USD', 'changes': [['sell', '38348.79', '0.00000000']], 'time': '2021-05-20T03:56:01.176955Z'}
{'type': 'l2update', 'product_id': 'BTC-USD', 'changes': [['buy', '38249.77', '0.00000000']], 'time': '2021-05-20T03:56:01.176955Z'}
{'type': 'l2update', 'product_id': 'BTC-USD', 'changes': [['buy', '38258.68', '0.01168938']], 'time': '2021-05-20T03:56:01.176955Z'}
{'type': 'l2update', 'product_id': 'BTC-USD', 'changes': [['sell', '38344.03', '0.00000000']], 'time': '2021-05-20T03:56:01.177909Z'}
{'type': 'l2update', 'product_id': 'BTC-USD', 'changes': [['sell', '38342.89', '2.98969908']], 'time': '2021-05-20T03:56:01.180081Z'}
{'type': 'l2update', 'product_id': 'BTC-USD', 'changes': [['sell', '38345.75', '0.43160000']], 'time': '2021-05-20T03:56:01.180696Z'}
{'type': 'l2update', 'product_id': 'BTC-USD', 'changes': [['buy', '38314.66', '1.09348085']], 'time': '2021-05-20T03:56:01.180985Z'}
{'type': 'l2update', 'product_id': 'BTC-USD', 'changes': [['sell', '38314.67', '0.00000000']], 'time': '2021-05-20T03:56:01.181231Z'}
{'type': 'l2update', 'product_id': 'BTC-USD', 'changes': [['buy', '38300.96', '0.55000000']], 'time': '2021-05-20T03:56:01.181248Z'}
{'type': 'l2update', 'product_id': 'BTC-USD', 'changes': [['sell', '38338.04', '0.05000000']], 'time': '2021-05-20T03:56:01.185201Z'}
{'type': 'l2update', 'product_id': 'BTC-USD', 'changes': [['buy', '38314.67', '0.05000000']], 'time': '2021-05-20T03:56:01.185833Z'}
{'type': 'l2update', 'product_id': 'BTC-USD', 'changes': [['sell', '38344.97', '0.00000000']], 'time': '2021-05-20T03:56:01.186143Z'}
{'type': 'l2update', 'product_id': 'BTC-USD', 'changes': [['sell', '38343.07', '0.00000000']], 'time': '2021-05-20T03:56:01.186143Z'}
{'type': 'l2update', 'product_id': 'BTC-USD', 'changes': [['sell', '38350.67', '0.00000000']], 'time': '2021-05-20T03:56:01.189959Z'}
{'type': 'l2update', 'product_id': 'BTC-USD', 'changes': [['sell', '38347.94', '2.61067745']], 'time': '2021-05-20T03:56:01.190742Z'}
{'type': 'l2update', 'product_id': 'BTC-USD', 'changes': [['buy', '38307.84', '0.00000000']], 'time': '2021-05-20T03:56:01.193812Z'}
{'type': 'l2update', 'product_id': 'BTC-USD', 'changes': [['sell', '38326.45', '0.00000000']], 'time': '2021-05-20T03:56:01.194494Z'}
{'type': 'l2update', 'product_id': 'BTC-USD', 'changes': [['buy', '38314.66', '1.03348085']], 'time': '2021-05-20T03:56:01.194527Z'}
{'type': 'l2update', 'product_id': 'BTC-USD', 'changes': [['buy', '38306.67', '0.09000000']], 'time': '2021-05-20T03:56:01.194725Z'}
{'type': 'l2update', 'product_id': 'BTC-USD', 'changes': [['sell', '38413.30', '0.11577600']], 'time': '2021-05-20T03:56:01.199633Z'}
{'type': 'l2update', 'product_id': 'BTC-USD', 'changes': [['buy', '38292.56', '0.00000000']], 'time': '2021-05-20T03:56:01.202152Z'}
{'type': 'l2update', 'product_id': 'BTC-USD', 'changes': [['buy', '38316.58', '0.06000000']], 'time': '2021-05-20T03:56:01.203044Z'}
{'type': 'l2update', 'product_id': 'BTC-USD', 'changes': [['buy', '38167.42', '0.04966999']], 'time': '2021-05-20T03:56:01.203142Z'}
{'type': 'l2update', 'product_id': 'BTC-USD', 'changes': [['buy', '38320.02', '0.04330000']], 'time': '2021-05-20T03:56:01.203154Z'}
{'type': 'l2update', 'product_id': 'BTC-USD', 'changes': [['buy', '38314.66', '0.95888085']], 'time': '2021-05-20T03:56:01.203583Z'}
{'type': 'l2update', 'product_id': 'BTC-USD', 'changes': [['buy', '38314.66', '0.95573000']], 'time': '2021-05-20T03:56:01.203746Z'}
{'type': 'l2update', 'product_id': 'BTC-USD', 'changes': [['sell', '38350.01', '0.00000000']], 'time': '2021-05-20T03:56:01.207487Z'}
{'type': 'l2update', 'product_id': 'BTC-USD', 'changes': [['sell', '38345.75', '0.00000000']], 'time': '2021-05-20T03:56:01.209398Z'}
{'type': 'l2update', 'product_id': 'BTC-USD', 'changes': [['sell', '38375.22', '0.00000000']], 'time': '2021-05-20T03:56:01.209674Z'}
{'type': 'l2update', 'product_id': 'BTC-USD', 'changes': [['buy', '38142.61', '0.05077861']], 'time': '2021-05-20T03:56:01.212302Z'}
{'type': 'l2update', 'product_id': 'BTC-USD', 'changes': [['sell', '38330.02', '0.55400000']], 'time': '2021-05-20T03:56:01.212831Z'}
{'type': 'l2update', 'product_id': 'BTC-USD', 'changes': [['buy', '38314.67', '0.05573000']], 'time': '2021-05-20T03:56:01.212907Z'}
{'type': 'l2update', 'product_id': 'BTC-USD', 'changes': [['buy', '38320.02', '0.05506915']], 'time': '2021-05-20T03:56:01.213110Z'}
{'type': 'l2update', 'product_id': 'BTC-USD', 'changes': [['buy', '38306.67', '0.07000000']], 'time': '2021-05-20T03:56:01.213829Z'}
{'type': 'l2update', 'product_id': 'BTC-USD', 'changes': [['sell', '38362.68', '0.01000000']], 'time': '2021-05-20T03:56:01.221745Z'}
{'type': 'l2update', 'product_id': 'BTC-USD', 'changes': [['buy', '38238.80', '2.61143156']], 'time': '2021-05-20T03:56:01.221874Z'}
{'type': 'l2update', 'product_id': 'BTC-USD', 'changes': [['sell', '38448.30', '0.03157048']], 'time': '2021-05-20T03:56:01.223109Z'}
{'type': 'l2update', 'product_id': 'BTC-USD', 'changes': [['sell', '38320.03', '0.00000000']], 'time': '2021-05-20T03:56:01.223246Z'}
{'type': 'l2update', 'product_id': 'BTC-USD', 'changes': [['sell', '38549.87', '0.00648510']], 'time': '2021-05-20T03:56:01.227208Z'}
{'type': 'l2update', 'product_id': 'BTC-USD', 'changes': [['sell', '38338.04', '0.00000000']], 'time': '2021-05-20T03:56:01.227625Z'}
{'type': 'l2update', 'product_id': 'BTC-USD', 'changes': [['buy', '38316.58', '0.00000000']], 'time': '2021-05-20T03:56:01.232124Z'}
{'type': 'l2update', 'product_id': 'BTC-USD', 'changes': [['buy', '38314.66', '0.95000000']], 'time': '2021-05-20T03:56:01.232223Z'}
{'type': 'l2update', 'product_id': 'BTC-USD', 'changes': [['buy', '38306.66', '0.00543852']], 'time': '2021-05-20T03:56:01.232418Z'}
{'type': 'l2update', 'product_id': 'BTC-USD', 'changes': [['buy', '38306.67', '0.04000000']], 'time': '2021-05-20T03:56:01.232444Z'}
{'type': 'l2update', 'product_id': 'BTC-USD', 'changes': [['buy', '38275.20', '1.20000000']], 'time': '2021-05-20T03:56:01.234032Z'}
{'type': 'l2update', 'product_id': 'BTC-USD', 'changes': [['sell', '38462.95', '0.43679246']], 'time': '2021-05-20T03:56:01.241445Z'}
{'type': 'l2update', 'product_id': 'BTC-USD', 'changes': [['buy', '38188.52', '0.43679246']], 'time': '2021-05-20T03:56:01.241445Z'}
{'type': 'l2update', 'product_id': 'BTC-USD', 'changes': [['buy', '38248.12', '0.15435054']], 'time': '2021-05-20T03:56:01.241445Z'}
{'type': 'l2update', 'product_id': 'BTC-USD', 'changes': [['buy', '38320.02', '0.11506915']], 'time': '2021-05-20T03:56:01.241535Z'}
{'type': 'l2update', 'product_id': 'BTC-USD', 'changes': [['buy', '38160.65', '0.14960000']], 'time': '2021-05-20T03:56:01.242014Z'}
{'type': 'l2update', 'product_id': 'BTC-USD', 'changes': [['sell', '38502.01', '0.00000000']], 'time': '2021-05-20T03:56:01.247153Z'}
{'type': 'l2update', 'product_id': 'BTC-USD', 'changes': [['sell', '38354.22', '0.00000000']], 'time': '2021-05-20T03:56:01.248530Z'}
{'type': 'l2update', 'product_id': 'BTC-USD', 'changes': [['sell', '38348.34', '2.61115183']], 'time': '2021-05-20T03:56:01.249908Z'}
{'type': 'l2update', 'product_id': 'BTC-USD', 'changes': [['buy', '38280.29', '0.01000000']], 'time': '2021-05-20T03:56:01.250055Z'}
{'type': 'l2update', 'product_id': 'BTC-USD', 'changes': [['buy', '38314.67', '0.15923000']], 'time': '2021-05-20T03:56:01.253482Z'}
{'type': 'l2update', 'product_id': 'BTC-USD', 'changes': [['buy', '38314.71', '0.52100000']], 'time': '2021-05-20T03:56:01.253869Z'}
{'type': 'l2update', 'product_id': 'BTC-USD', 'changes': [['buy', '38242.24', '0.00000000']], 'time': '2021-05-20T03:56:01.254361Z'}
{'type': 'l2update', 'product_id': 'BTC-USD', 'changes': [['buy', '38299.83', '0.00000000']], 'time': '2021-05-20T03:56:01.254941Z'}
{'type': 'l2update', 'product_id': 'BTC-USD', 'changes': [['buy', '38214.42', '0.00000000']], 'time': '2021-05-20T03:56:01.254994Z'}
{'type': 'l2update', 'product_id': 'BTC-USD', 'changes': [['buy', '38320.02', '0.10330000']], 'time': '2021-05-20T03:56:01.256161Z'}
{'type': 'l2update', 'product_id': 'BTC-USD', 'changes': [['buy', '38140.12', '0.00000000']], 'time': '2021-05-20T03:56:01.257677Z'}
{'type': 'l2update', 'product_id': 'BTC-USD', 'changes': [['buy', '38306.67', '0.00000000']], 'time': '2021-05-20T03:56:01.258635Z'}
{'type': 'l2update', 'product_id': 'BTC-USD', 'changes': [['sell', '38347.69', '0.00000000']], 'time': '2021-05-20T03:56:01.259870Z'}
{'type': 'l2update', 'product_id': 'BTC-USD', 'changes': [['buy', '37514.61', '0.00000000']], 'time': '2021-05-20T03:56:01.259895Z'}
{'type': 'l2update', 'product_id': 'BTC-USD', 'changes': [['sell', '38342.88', '0.05000000']], 'time': '2021-05-20T03:56:01.260916Z'}
{'type': 'l2update', 'product_id': 'BTC-USD', 'changes': [['sell', '38342.89', '2.48969908']], 'time': '2021-05-20T03:56:01.267832Z'}
{'type': 'l2update', 'product_id': 'BTC-USD', 'changes': [['buy', '38320.02', '0.10903000']], 'time': '2021-05-20T03:56:01.268042Z'}
{'type': 'l2update', 'product_id': 'BTC-USD', 'changes': [['buy', '38223.99', '0.17362429']], 'time': '2021-05-20T03:56:01.268312Z'}
{'type': 'l2update', 'product_id': 'BTC-USD', 'changes': [['sell', '38413.17', '1.20000000']], 'time': '2021-05-20T03:56:01.268565Z'}
{'type': 'l2update', 'product_id': 'BTC-USD', 'changes': [['sell', '38330.02', '0.00000000']], 'time': '2021-05-20T03:56:01.269605Z'}
{'type': 'l2update', 'product_id': 'BTC-USD', 'changes': [['sell', '38338.03', '0.18981474']], 'time': '2021-05-20T03:56:01.269673Z'}
{'type': 'l2update', 'product_id': 'BTC-USD', 'changes': [['sell', '38377.24', '0.00000000']], 'time': '2021-05-20T03:56:01.269909Z'}
{'type': 'l2update', 'product_id': 'BTC-USD', 'changes': [['sell', '38326.52', '0.00000000']], 'time': '2021-05-20T03:56:01.271820Z'}
{'type': 'l2update', 'product_id': 'BTC-USD', 'changes': [['buy', '38326.51', '0.07460000']], 'time': '2021-05-20T03:56:01.273298Z'}
{'type': 'l2update', 'product_id': 'BTC-USD', 'changes': [['buy', '38326.51', '0.07775085']], 'time': '2021-05-20T03:56:01.274163Z'}
{'type': 'l2update', 'product_id': 'BTC-USD', 'changes': [['sell', '38334.26', '0.00000000']], 'time': '2021-05-20T03:56:01.276513Z'}
{'type': 'l2update', 'product_id': 'BTC-USD', 'changes': [['buy', '38306.68', '0.00000000']], 'time': '2021-05-20T03:56:01.280125Z'}
{'type': 'l2update', 'product_id': 'BTC-USD', 'changes': [['sell', '38488.51', '0.02598178']], 'time': '2021-05-20T03:56:01.280888Z'}
{'type': 'l2update', 'product_id': 'BTC-USD', 'changes': [['buy', '38267.28', '0.00000000']], 'time': '2021-05-20T03:56:01.284294Z'}
{'type': 'l2update', 'product_id': 'BTC-USD', 'changes': [['buy', '38302.82', '0.48150000']], 'time': '2021-05-20T03:56:01.285785Z'}
{'type': 'l2update', 'product_id': 'BTC-USD', 'changes': [['buy', '38280.18', '0.03439766']], 'time': '2021-05-20T03:56:01.285854Z'}
{'type': 'l2update', 'product_id': 'BTC-USD', 'changes': [['sell', '38362.68', '0.00000000']], 'time': '2021-05-20T03:56:01.288246Z'}
{'type': 'l2update', 'product_id': 'BTC-USD', 'changes': [['buy', '38151.72', '0.01000000']], 'time': '2021-05-20T03:56:01.290686Z'}
{'type': 'l2update', 'product_id': 'BTC-USD', 'changes': [['buy', '38275.20', '0.00000000']], 'time': '2021-05-20T03:56:01.292453Z'}
{'type': 'l2update', 'product_id': 'BTC-USD', 'changes': [['sell', '38368.13', '0.00000000']], 'time': '2021-05-20T03:56:01.292808Z'}
{'type': 'l2update', 'product_id': 'BTC-USD', 'changes': [['buy', '38326.51', '0.00315085']], 'time': '2021-05-20T03:56:01.295767Z'}
{'type': 'l2update', 'product_id': 'BTC-USD', 'changes': [['buy', '38320.02', '0.06573000']], 'time': '2021-05-20T03:56:01.296936Z'}
{'type': 'l2update', 'product_id': 'BTC-USD', 'changes': [['sell', '38342.88', '0.00000000']], 'time': '2021-05-20T03:56:01.299228Z'}
{'type': 'l2update', 'product_id': 'BTC-USD', 'changes': [['sell', '38343.06', '0.00000000']], 'time': '2021-05-20T03:56:01.299789Z'}
{'type': 'l2update', 'product_id': 'BTC-USD', 'changes': [['sell', '38334.25', '0.50000000']], 'time': '2021-05-20T03:56:01.301471Z'}
{'type': 'l2update', 'product_id': 'BTC-USD', 'changes': [['buy', '38320.03', '0.00573000']], 'time': '2021-05-20T03:56:01.301993Z'}
{'type': 'l2update', 'product_id': 'BTC-USD', 'changes': [['sell', '38453.67', '0.40368717']], 'time': '2021-05-20T03:56:01.302166Z'}
{'type': 'l2update', 'product_id': 'BTC-USD', 'changes': [['buy', '38269.38', '0.00000000']], 'time': '2021-05-20T03:56:01.304266Z'}
{'type': 'l2update', 'product_id': 'BTC-USD', 'changes': [['sell', '38394.01', '0.00000000']], 'time': '2021-05-20T03:56:01.305645Z'}
{'type': 'l2update', 'product_id': 'BTC-USD', 'changes': [['buy', '38302.82', '0.00000000']], 'time': '2021-05-20T03:56:01.309153Z'}
{'type': 'l2update', 'product_id': 'BTC-USD', 'changes': [['sell', '38396.22', '0.00000000']], 'time': '2021-05-20T03:56:01.310005Z'}
{'type': 'l2update', 'product_id': 'BTC-USD', 'changes': [['buy', '38195.56', '0.01000000']], 'time': '2021-05-20T03:56:01.310450Z'}
{'type': 'l2update', 'product_id': 'BTC-USD', 'changes': [['buy', '38327.64', '0.00315085']], 'time': '2021-05-20T03:56:01.311555Z'}
{'type': 'l2update', 'product_id': 'BTC-USD', 'changes': [['buy', '38280.29', '0.00000000']], 'time': '2021-05-20T03:56:01.311576Z'}
{'type': 'l2update', 'product_id': 'BTC-USD', 'changes': [['sell', '38413.17', '0.00000000']], 'time': '2021-05-20T03:56:01.315709Z'}
{'type': 'l2update', 'product_id': 'BTC-USD', 'changes': [['buy', '38181.84', '0.00000000']], 'time': '2021-05-20T03:56:01.319025Z'}
{'type': 'l2update', 'product_id': 'BTC-USD', 'changes': [['sell', '38411.18', '0.00000000']], 'time': '2021-05-20T03:56:01.319321Z'}
{'type': 'l2update', 'product_id': 'BTC-USD', 'changes': [['sell', '38361.66', '0.00000000']], 'time': '2021-05-20T03:56:01.319520Z'}
{'type': 'l2update', 'product_id': 'BTC-USD', 'changes': [['buy', '38280.18', '0.04608704']], 'time': '2021-05-20T03:56:01.322892Z'}
{'type': 'l2update', 'product_id': 'BTC-USD', 'changes': [['sell', '43100.00', '4.40920000']], 'time': '2021-05-20T03:56:01.323363Z'}
{'type': 'l2update', 'product_id': 'BTC-USD', 'changes': [['buy', '38212.10', '0.01000000']], 'time': '2021-05-20T03:56:01.323711Z'}
{'type': 'l2update', 'product_id': 'BTC-USD', 'changes': [['buy', '38298.14', '0.04708759']], 'time': '2021-05-20T03:56:01.323735Z'}
{'type': 'l2update', 'product_id': 'BTC-USD', 'changes': [['sell', '38341.46', '0.05227605']], 'time': '2021-05-20T03:56:01.323735Z'}
{'type': 'l2update', 'product_id': 'BTC-USD', 'changes': [['buy', '38314.67', '0.35923000']], 'time': '2021-05-20T03:56:01.323796Z'}
{'type': 'l2update', 'product_id': 'BTC-USD', 'changes': [['buy', '38300.06', '0.02355511']], 'time': '2021-05-20T03:56:01.324138Z'}
{'type': 'l2update', 'product_id': 'BTC-USD', 'changes': [['sell', '38334.25', '0.00000000']], 'time': '2021-05-20T03:56:01.324525Z'}
{'type': 'l2update', 'product_id': 'BTC-USD', 'changes': [['buy', '38314.67', '0.35350000']], 'time': '2021-05-20T03:56:01.325963Z'}
{'type': 'l2update', 'product_id': 'BTC-USD', 'changes': [['sell', '38359.61', '0.00000000']], 'time': '2021-05-20T03:56:01.326161Z'}
{'type': 'l2update', 'product_id': 'BTC-USD', 'changes': [['buy', '38327.64', '0.07775085']], 'time': '2021-05-20T03:56:01.327540Z'}
{'type': 'l2update', 'product_id': 'BTC-USD', 'changes': [['sell', '38359.60', '0.05000000']], 'time': '2021-05-20T03:56:01.327715Z'}
{'type': 'l2update', 'product_id': 'BTC-USD', 'changes': [['buy', '38326.51', '0.00000000']], 'time': '2021-05-20T03:56:01.334640Z'}
{'type': 'l2update', 'product_id': 'BTC-USD', 'changes': [['sell', '38508.51', '0.30081691']], 'time': '2021-05-20T03:56:01.334781Z'}
{'type': 'l2update', 'product_id': 'BTC-USD', 'changes': [['sell', '38327.65', '1.30451220']], 'time': '2021-05-20T03:56:01.345100Z'}
{'type': 'l2update', 'product_id': 'BTC-USD', 'changes': [['sell', '38358.96', '0.00000000']], 'time': '2021-05-20T03:56:01.345266Z'}
{'type': 'l2update', 'product_id': 'BTC-USD', 'changes': [['buy', '38188.51', '0.00000000']], 'time': '2021-05-20T03:56:01.345266Z'}
{'type': 'l2update', 'product_id': 'BTC-USD', 'changes': [['buy', '38195.13', '0.00000000']], 'time': '2021-05-20T03:56:01.345266Z'}
{'type': 'l2update', 'product_id': 'BTC-USD', 'changes': [['buy', '38201.56', '0.00000000']], 'time': '2021-05-20T03:56:01.345266Z'}
{'type': 'l2update', 'product_id': 'BTC-USD', 'changes': [['buy', '38207.80', '0.00000000']], 'time': '2021-05-20T03:56:01.345266Z'}
{'type': 'l2update', 'product_id': 'BTC-USD', 'changes': [['buy', '38218.54', '0.00000000']], 'time': '2021-05-20T03:56:01.345266Z'}
{'type': 'l2update', 'product_id': 'BTC-USD', 'changes': [['buy', '38224.22', '0.00000000']], 'time': '2021-05-20T03:56:01.345266Z'}
{'type': 'l2update', 'product_id': 'BTC-USD', 'changes': [['buy', '38229.71', '0.00000000']], 'time': '2021-05-20T03:56:01.345266Z'}
{'type': 'l2update', 'product_id': 'BTC-USD', 'changes': [['buy', '38240.12', '0.00000000']], 'time': '2021-05-20T03:56:01.345266Z'}
{'type': 'l2update', 'product_id': 'BTC-USD', 'changes': [['buy', '38245.04', '0.00000000']], 'time': '2021-05-20T03:56:01.345266Z'}
{'type': 'l2update', 'product_id': 'BTC-USD', 'changes': [['sell', '38416.87', '0.00000000']], 'time': '2021-05-20T03:56:01.346305Z'}
{'type': 'l2update', 'product_id': 'BTC-USD', 'changes': [['buy', '38320.02', '0.06000000']], 'time': '2021-05-20T03:56:01.349223Z'}
{'type': 'l2update', 'product_id': 'BTC-USD', 'changes': [['buy', '38139.83', '0.00000000']], 'time': '2021-05-20T03:56:01.350585Z'}
{'type': 'l2update', 'product_id': 'BTC-USD', 'changes': [['sell', '38359.60', '0.00000000']], 'time': '2021-05-20T03:56:01.356277Z'}
{'type': 'l2update', 'product_id': 'BTC-USD', 'changes': [['buy', '38214.73', '0.00000000']], 'time': '2021-05-20T03:56:01.359954Z'}
{'type': 'l2update', 'product_id': 'BTC-USD', 'changes': [['buy', '38258.68', '0.00000000']], 'time': '2021-05-20T03:56:01.368011Z'}
{'type': 'l2update', 'product_id': 'BTC-USD', 'changes': [['buy', '38320.03', '0.00000000']], 'time': '2021-05-20T03:56:01.371276Z'}
{'type': 'l2update', 'product_id': 'BTC-USD', 'changes': [['buy', '38307.86', '0.01000000']], 'time': '2021-05-20T03:56:01.381833Z'}
{'type': 'l2update', 'product_id': 'BTC-USD', 'changes': [['sell', '38437.01', '0.01000000']], 'time': '2021-05-20T03:56:01.382211Z'}
{'type': 'l2update', 'product_id': 'BTC-USD', 'changes': [['sell', '38475.95', '0.35529040']], 'time': '2021-05-20T03:56:01.382416Z'}
{'type': 'l2update', 'product_id': 'BTC-USD', 'changes': [['buy', '38244.03', '0.36648521']], 'time': '2021-05-20T03:56:01.382416Z'}
{'type': 'l2update', 'product_id': 'BTC-USD', 'changes': [['buy', '38283.37', '0.00000000']], 'time': '2021-05-20T03:56:01.382494Z'}
{'type': 'l2update', 'product_id': 'BTC-USD', 'changes': [['buy', '37529.63', '0.06810261']], 'time': '2021-05-20T03:56:01.382559Z'}
{'type': 'l2update', 'product_id': 'BTC-USD', 'changes': [['buy', '38320.02', '0.13125474']], 'time': '2021-05-20T03:56:01.382883Z'}
{'type': 'l2update', 'product_id': 'BTC-USD', 'changes': [['sell', '38375.48', '0.52387285']], 'time': '2021-05-20T03:56:01.382920Z'}
{'type': 'l2update', 'product_id': 'BTC-USD', 'changes': [['sell', '38338.02', '0.50000000']], 'time': '2021-05-20T03:56:01.382957Z'}
{'type': 'l2update', 'product_id': 'BTC-USD', 'changes': [['buy', '38314.67', '0.45350000']], 'time': '2021-05-20T03:56:01.383851Z'}
{'type': 'l2update', 'product_id': 'BTC-USD', 'changes': [['buy', '38327.64', '0.10665085']], 'time': '2021-05-20T03:56:01.383928Z'}
{'type': 'l2update', 'product_id': 'BTC-USD', 'changes': [['sell', '38368.13', '2.14100000']], 'time': '2021-05-20T03:56:01.384065Z'}
{'type': 'l2update', 'product_id': 'BTC-USD', 'changes': [['sell', '38368.12', '0.09184966']], 'time': '2021-05-20T03:56:01.386551Z'}
{'type': 'l2update', 'product_id': 'BTC-USD', 'changes': [['sell', '38363.75', '0.05000000']], 'time': '2021-05-20T03:56:01.386627Z'}
{'type': 'l2update', 'product_id': 'BTC-USD', 'changes': [['buy', '38314.67', '0.75350000']], 'time': '2021-05-20T03:56:01.389271Z'}
{'type': 'l2update', 'product_id': 'BTC-USD', 'changes': [['buy', '38213.80', '0.00000000']], 'time': '2021-05-20T03:56:01.394914Z'}
{'type': 'l2update', 'product_id': 'BTC-USD', 'changes': [['buy', '38301.49', '0.02000000']], 'time': '2021-05-20T03:56:01.395233Z'}
{'type': 'l2update', 'product_id': 'BTC-USD', 'changes': [['buy', '38280.20', '0.00000000']], 'time': '2021-05-20T03:56:01.396288Z'}
{'type': 'l2update', 'product_id': 'BTC-USD', 'changes': [['buy', '38295.48', '0.00000000']], 'time': '2021-05-20T03:56:01.398008Z'}
{'type': 'l2update', 'product_id': 'BTC-USD', 'changes': [['buy', '38327.64', '0.07775085']], 'time': '2021-05-20T03:56:01.400297Z'}
{'type': 'l2update', 'product_id': 'BTC-USD', 'changes': [['buy', '38320.02', '0.06000000']], 'time': '2021-05-20T03:56:01.401456Z'}
{'type': 'l2update', 'product_id': 'BTC-USD', 'changes': [['buy', '38194.80', '0.13090784']], 'time': '2021-05-20T03:56:01.404362Z'}
{'type': 'l2update', 'product_id': 'BTC-USD', 'changes': [['sell', '38368.13', '0.00000000']], 'time': '2021-05-20T03:56:01.408886Z'}
{'type': 'l2update', 'product_id': 'BTC-USD', 'changes': [['buy', '38274.83', '0.09033981']], 'time': '2021-05-20T03:56:01.410251Z'}
{'type': 'l2update', 'product_id': 'BTC-USD', 'changes': [['sell', '38508.51', '0.00000000']], 'time': '2021-05-20T03:56:01.414399Z'}
{'type': 'l2update', 'product_id': 'BTC-USD', 'changes': [['buy', '38307.89', '0.00000000']], 'time': '2021-05-20T03:56:01.416752Z'}
{'type': 'l2update', 'product_id': 'BTC-USD', 'changes': [['buy', '38295.47', '0.00000000']], 'time': '2021-05-20T03:56:01.417487Z'}
{'type': 'l2update', 'product_id': 'BTC-USD', 'changes': [['sell', '38446.05', '0.01000000']], 'time': '2021-05-20T03:56:01.420352Z'}
{'type': 'l2update', 'product_id': 'BTC-USD', 'changes': [['buy', '38250.65', '0.17362429']], 'time': '2021-05-20T03:56:01.420673Z'}
{'type': 'l2update', 'product_id': 'BTC-USD', 'changes': [['sell', '38460.90', '0.02761322']], 'time': '2021-05-20T03:56:01.421682Z'}
{'type': 'l2update', 'product_id': 'BTC-USD', 'changes': [['buy', '38293.20', '0.03000000']], 'time': '2021-05-20T03:56:01.422171Z'}
{'type': 'l2update', 'product_id': 'BTC-USD', 'changes': [['buy', '38256.17', '0.00000000']], 'time': '2021-05-20T03:56:01.427894Z'}
{'type': 'l2update', 'product_id': 'BTC-USD', 'changes': [['buy', '38256.16', '0.00000000']], 'time': '2021-05-20T03:56:01.428376Z'}
{'type': 'l2update', 'product_id': 'BTC-USD', 'changes': [['buy', '38195.56', '0.00000000']], 'time': '2021-05-20T03:56:01.430766Z'}
{'type': 'l2update', 'product_id': 'BTC-USD', 'changes': [['sell', '38413.30', '0.00000000']], 'time': '2021-05-20T03:56:01.435769Z'}
{'type': 'l2update', 'product_id': 'BTC-USD', 'changes': [['buy', '38269.36', '0.00000000']], 'time': '2021-05-20T03:56:01.436163Z'}
{'type': 'l2update', 'product_id': 'BTC-USD', 'changes': [['buy', '38314.66', '0.85000000']], 'time': '2021-05-20T03:56:01.438161Z'}
{'type': 'l2update', 'product_id': 'BTC-USD', 'changes': [['buy', '38208.39', '0.00000000']], 'time': '2021-05-20T03:56:01.440166Z'}
{'type': 'l2update', 'product_id': 'BTC-USD', 'changes': [['buy', '38223.99', '0.00000000']], 'time': '2021-05-20T03:56:01.440657Z'}
{'type': 'l2update', 'product_id': 'BTC-USD', 'changes': [['sell', '38373.37', '0.00000000']], 'time': '2021-05-20T03:56:01.443078Z'}
{'type': 'l2update', 'product_id': 'BTC-USD', 'changes': [['sell', '38370.17', '0.37661801']], 'time': '2021-05-20T03:56:01.443078Z'}
{'type': 'l2update', 'product_id': 'BTC-USD', 'changes': [['buy', '38290.04', '0.42600000']], 'time': '2021-05-20T03:56:01.447378Z'}
{'type': 'l2update', 'product_id': 'BTC-USD', 'changes': [['sell', '38353.43', '0.05447341']], 'time': '2021-05-20T03:56:01.447516Z'}
{'type': 'l2update', 'product_id': 'BTC-USD', 'changes': [['sell', '38338.03', '0.00000000']], 'time': '2021-05-20T03:56:01.449629Z'}
{'type': 'l2update', 'product_id': 'BTC-USD', 'changes': [['buy', '38298.14', '0.00000000']], 'time': '2021-05-20T03:56:01.452091Z'}
{'type': 'l2update', 'product_id': 'BTC-USD', 'changes': [['sell', '38341.46', '0.00000000']], 'time': '2021-05-20T03:56:01.452091Z'}
{'type': 'l2update', 'product_id': 'BTC-USD', 'changes': [['buy', '38274.82', '0.00000000']], 'time': '2021-05-20T03:56:01.456212Z'}
{'type': 'l2update', 'product_id': 'BTC-USD', 'changes': [['buy', '38314.72', '0.99440510']], 'time': '2021-05-20T03:56:01.456897Z'}
{'type': 'l2update', 'product_id': 'BTC-USD', 'changes': [['buy', '38274.83', '0.11646664']], 'time': '2021-05-20T03:56:01.457100Z'}
{'type': 'l2update', 'product_id': 'BTC-USD', 'changes': [['buy', '38291.66', '0.04000000']], 'time': '2021-05-20T03:56:01.457371Z'}
{'type': 'l2update', 'product_id': 'BTC-USD', 'changes': [['sell', '38327.65', '1.30134213']], 'time': '2021-05-20T03:56:01.457763Z'}
{'type': 'l2update', 'product_id': 'BTC-USD', 'changes': [['buy', '38314.66', '0.65000000']], 'time': '2021-05-20T03:56:01.457936Z'}
{'type': 'l2update', 'product_id': 'BTC-USD', 'changes': [['sell', '38389.33', '0.00000000']], 'time': '2021-05-20T03:56:01.460877Z'}
{'type': 'l2update', 'product_id': 'BTC-USD', 'changes': [['sell', '38383.82', '0.41419655']], 'time': '2021-05-20T03:56:01.460877Z'}
{'type': 'l2update', 'product_id': 'BTC-USD', 'changes': [['buy', '38275.28', '0.01213413']], 'time': '2021-05-20T03:56:01.462660Z'}
{'type': 'l2update', 'product_id': 'BTC-USD', 'changes': [['buy', '38167.93', '0.01000000']], 'time': '2021-05-20T03:56:01.462791Z'}
{'type': 'l2update', 'product_id': 'BTC-USD', 'changes': [['sell', '38426.64', '0.01000000']], 'time': '2021-05-20T03:56:01.464093Z'}
{'type': 'l2update', 'product_id': 'BTC-USD', 'changes': [['buy', '38224.67', '0.01136687']], 'time': '2021-05-20T03:56:01.468995Z'}
{'type': 'l2update', 'product_id': 'BTC-USD', 'changes': [['sell', '38475.95', '0.65246532']], 'time': '2021-05-20T03:56:01.469992Z'}
{'type': 'l2update', 'product_id': 'BTC-USD', 'changes': [['buy', '38295.41', '0.00000000']], 'time': '2021-05-20T03:56:01.470102Z'}
{'type': 'l2update', 'product_id': 'BTC-USD', 'changes': [['buy', '38314.72', '1.39575592']], 'time': '2021-05-20T03:56:01.473642Z'}
{'type': 'l2update', 'product_id': 'BTC-USD', 'changes': [['buy', '38314.71', '1.36700000']], 'time': '2021-05-20T03:56:01.481137Z'}
{'type': 'l2update', 'product_id': 'BTC-USD', 'changes': [['buy', '38290.75', '0.05000000']], 'time': '2021-05-20T03:56:01.484739Z'}
{'type': 'l2update', 'product_id': 'BTC-USD', 'changes': [['buy', '38320.02', '0.16000000']], 'time': '2021-05-20T03:56:01.484770Z'}
{'type': 'l2update', 'product_id': 'BTC-USD', 'changes': [['sell', '38468.33', '0.02811475']], 'time': '2021-05-20T03:56:01.485227Z'}
{'type': 'l2update', 'product_id': 'BTC-USD', 'changes': [['sell', '38368.07', '0.46070000']], 'time': '2021-05-20T03:56:01.485428Z'}
{'type': 'l2update', 'product_id': 'BTC-USD', 'changes': [['buy', '38326.52', '0.09212521']], 'time': '2021-05-20T03:56:01.485666Z'}
{'type': 'l2update', 'product_id': 'BTC-USD', 'changes': [['buy', '38307.90', '0.02355511']], 'time': '2021-05-20T03:56:01.486297Z'}
{'type': 'l2update', 'product_id': 'BTC-USD', 'changes': [['sell', '38327.65', '0.00000000']], 'time': '2021-05-20T03:56:01.488346Z'}
{'type': 'l2update', 'product_id': 'BTC-USD', 'changes': [['buy', '38325.80', '0.04947106']], 'time': '2021-05-20T03:56:01.490749Z'}
{'type': 'l2update', 'product_id': 'BTC-USD', 'changes': [['buy', '38314.66', '0.91000000']], 'time': '2021-05-20T03:56:01.490944Z'}
{'type': 'l2update', 'product_id': 'BTC-USD', 'changes': [['sell', '38338.01', '0.18981474']], 'time': '2021-05-20T03:56:01.496716Z'}
{'type': 'l2update', 'product_id': 'BTC-USD', 'changes': [['sell', '38431.83', '0.00000000']], 'time': '2021-05-20T03:56:01.497280Z'}
{'type': 'l2update', 'product_id': 'BTC-USD', 'changes': [['buy', '38283.51', '1.20000000']], 'time': '2021-05-20T03:56:01.501197Z'}
{'type': 'l2update', 'product_id': 'BTC-USD', 'changes': [['sell', '38375.49', '0.68955538']], 'time': '2021-05-20T03:56:01.502993Z'}
{'type': 'l2update', 'product_id': 'BTC-USD', 'changes': [['sell', '38395.03', '0.37247194']], 'time': '2021-05-20T03:56:01.503254Z'}
{'type': 'l2update', 'product_id': 'BTC-USD', 'changes': [['buy', '38290.04', '0.00000000']], 'time': '2021-05-20T03:56:01.503727Z'}
{'type': 'l2update', 'product_id': 'BTC-USD', 'changes': [['buy', '37529.63', '0.00000000']], 'time': '2021-05-20T03:56:01.504518Z'}
{'type': 'l2update', 'product_id': 'BTC-USD', 'changes': [['sell', '38338.05', '0.00000000']], 'time': '2021-05-20T03:56:01.504923Z'}
{'type': 'l2update', 'product_id': 'BTC-USD', 'changes': [['buy', '38320.02', '0.36000000']], 'time': '2021-05-20T03:56:01.506542Z'}
{'type': 'l2update', 'product_id': 'BTC-USD', 'changes': [['buy', '38327.64', '0.00315085']], 'time': '2021-05-20T03:56:01.506686Z'}
{'type': 'l2update', 'product_id': 'BTC-USD', 'changes': [['sell', '38368.22', '0.02000000']], 'time': '2021-05-20T03:56:01.508092Z'}
